File: dataset/precursor_mixture/Cr2O3_Fe3O4_HfO2_In2O3.12-min.xrdml
<?xml version="1.0"?>
<xrdMeasurements xmlns="http://www.xrdml.com/XRDMeasurement/2.2" xmlns:xsi="http://www.w3.org/2001/XMLSchema-instance" xsi:schemaLocation="http://www.xrdml.com/XRDMeasurement/2.2 http://www.xrdml.com/XRDMeasurement/2.2/XRDMeasurement.xsd" status="Completed" recordIdentifier="{F5E428E5-A97A-4D35-8008-316A54C7F41D}">
	<comment>
		<entry/>
	</comment>
	<sample type="To be analyzed">
		<id>dara-19-2</id>
		<name></name>
		<preparedBy></preparedBy>
	</sample>
	<xrdMeasurement measurementType="Scan" status="Completed" sampleMode="Reflection">
		<usedWavelength intended="K-Alpha 1">
			<kAlpha1 unit="Angstrom">1.5405980</kAlpha1>
			<kAlpha2 unit="Angstrom">1.5444260</kAlpha2>
			<kBeta unit="Angstrom">1.3922500</kBeta>
			<ratioKAlpha2KAlpha1>0.5000</ratioKAlpha2KAlpha1>
		</usedWavelength>
		<incidentBeamPath>
			<radius unit="mm">145.00</radius>
			<xRayTube id="1010048" name="Empyrean Cu LFF HR (9430 033 7310x) DK437873">
				<tension unit="kV">40.0</tension>
				<current unit="mA">15.0</current>
				<anodeMaterial>Cu</anodeMaterial>
				<focus type="Line">
					<length unit="mm">12.0</length>
					<width unit="mm">0.4</width>
					<takeOffAngle unit="deg">6.0</takeOffAngle>
				</focus>
			</xRayTube>
			<filter id="20010004" name="Beta-filter Nickel">
				<material>Ni</material>
				<thickness unit="mm">0.020</thickness>
			</filter>
			<sollerSlit id="21010002" name="Soller slits 0.04 rad.">
				<opening unit="rad">0.0400</opening>
			</sollerSlit>
			<mask id="22031000" name="Fixed mask 13 mm">
				<width unit="mm">9.00</width>
			</mask>
			<divergenceSlit id="22120001" name="Divergence slit 1°" xsi:type="fixedDivergenceSlitType">
				<distanceToSample unit="mm">50.00</distanceToSample>
				<height unit="mm">1.52</height>
			</divergenceSlit>
		</incidentBeamPath>
		<beamKnife id="29030100" name="Beam knife low"/>
		<sampleMovement xsi:type="spinningSampleMovementType">
			<spinnerRevolutionTime unit="seconds">1.0</spinnerRevolutionTime>
		</sampleMovement>
		<diffractedBeamPath>
			<radius unit="mm">145.00</radius>
			<antiScatterSlit id="22090040" name="AS slit 9 mm" xsi:type="fixedAntiScatterSlitType">
				<height unit="mm">9.00</height>
			</antiScatterSlit>
			<sollerSlit id="21020003" name="Large Soller slits 0.04 rad.">
				<opening unit="rad">0.0400</opening>
			</sollerSlit>
			<filter id="20030001" name="Large beta-filter Nickel">
				<material>Ni</material>
				<thickness unit="mm">0.020</thickness>
			</filter>
			<detector id="7010019" name="PIXcel1D-Medipix3 detector" xsi:type="rtmsDetectorType">
				<phd unit="keV">
					<lowerLevel>4.0</lowerLevel>
					<upperLevel>11.3</upperLevel>
				</phd>
				<mode>Scanning</mode>
				<activeLength unit="deg">5.020</activeLength>
			</detector>
		</diffractedBeamPath>
		<scan appendNumber="0" mode="Continuous" scanAxis="Gonio" status="Completed">
			<header>
				<startTimeStamp>2024-03-24T16:10:42-07:00</startTimeStamp>
				<endTimeStamp>2024-03-24T16:23:10-07:00</endTimeStamp>
				<author>
					<name>AutomatedUser</name>
				</author>
				<source>
					<applicationSoftware version="1.6 (94)">PANalytical Aeris Instrument Suite</applicationSoftware>
					<instrumentControlSoftware version="3.0.0 20211014">AERIS</instrumentControlSoftware>
					<instrumentID>2879380</instrumentID>
				</source>
			</header>
			<dataPoints>
				<positions axis="2Theta" unit="deg">
					<startPosition>9.99043322</startPosition>
					<endPosition>100.09495370</endPosition>
				</positions>
				<positions axis="Omega" unit="deg">
					<startPosition>4.99521661</startPosition>
					<endPosition>50.04747685</endPosition>
				</positions>
				<commonCountingTime unit="seconds">18.249</commonCountingTime>
				<counts unit="counts">4806 4993 4932 4844 4921 4889 4910 4992 4865 4781 5018 4943 5022 4764 4852 4830 4751 4872 4835 4846 4840 4759 4823 4818 4847 4738 4976 4813 4839 4804 4825 4702 4937 4727 4733 4683 4777 4865 4758 4789 4900 4759 4772 4641 4881 4700 4671 4731 4742 4660 4762 4571 4687 4568 4756 4710 4674 4634 4765 4803 4715 4548 4746 4653 4597 4697 4636 4708 4645 4506 4744 4705 4749 4673 4771 4554 4710 4626 4788 4605 4723 4613 4579 4630 4571 4530 4694 4580 4628 4394 4533 4633 4570 4608 4516 4556 4573 4623 4495 4563 4678 4614 4614 4543 4491 4613 4457 4639 4596 4565 4563 4452 4525 4464 4598 4475 4544 4527 4375 4370 4455 4470 4549 4512 4527 4444 4481 4439 4439 4384 4498 4355 4382 4392 4260 4499 4528 4449 4392 4442 4444 4497 4478 4559 4550 4484 4505 4426 4449 4387 4377 4503 4448 4446 4452 4341 4421 4366 4523 4374 4462 4263 4461 4381 4384 4361 4259 4349 4345 4290 4287 4360 4308 4264 4357 4388 4289 4326 4324 4391 4396 4253 4363 4193 4277 4126 4315 4271 4418 4187 4252 4382 4412 4286 4282 4237 4213 4325 4290 4213 4416 4198 4315 4281 4121 4362 4181 4309 4158 4289 4274 4243 4116 4136 4175 4233 4271 4323 4176 4241 4192 4335 4221 4071 4125 4241 4322 4319 4189 4268 4232 4274 4127 4246 4260 4236 4368 4180 4221 4282 4238 4260 4159 4147 4172 4180 4065 4332 4121 4197 4070 4248 4115 4178 4112 4239 4165 4208 4144 4233 4079 4206 4217 4227 4136 4156 4146 4164 4136 4109 4135 4086 4077 4150 4100 4190 4156 4065 4071 4100 4177 4277 4239 4199 4130 4080 3974 4065 4074 4186 4146 4018 4166 4093 4146 4117 4015 4018 4078 4088 4036 3874 4023 4002 4099 3980 4046 4122 4204 4056 4062 4128 4036 4040 4023 4094 4036 4143 4158 4059 4048 3984 4110 4012 3933 4010 3962 4076 4026 4110 4101 4108 4100 4033 4020 3974 3979 3903 4044 3868 4049 4137 3989 4126 3920 4091 3956 4027 3946 4151 4070 4043 3936 3918 3945 4134 4037 3968 3985 3938 3963 3988 3907 3946 4006 3903 3971 3941 4024 3828 3993 3967 3919 3946 4064 3925 3948 3883 4091 3809 4026 3868 4016 3871 4004 3941 4005 3895 4010 3943 3919 3971 3949 3968 4033 3973 3982 3935 3855 3856 4055 3964 3908 3911 3997 3993 3867 3784 3873 3939 4001 3829 3986 3972 3852 3987 3876 3910 4033 3961 3934 3886 3835 3951 3994 3952 4038 3877 3923 3943 3873 3856 3929 3986 3821 3876 4008 3937 3867 3875 3904 3884 3765 3919 3904 3910 3897 3874 3976 3841 3872 3916 4051 3914 3917 3911 3981 3908 3891 3884 3989 3932 3986 3809 4033 3887 4054 3921 3784 3865 4032 3792 3914 3887 3894 3874 3934 3850 3851 3844 3744 3886 3955 3953 3946 3845 3773 3829 3856 3894 3909 3810 3870 3900 3857 3952 3868 3889 3781 4015 3937 3925 3850 3903 3825 4015 3860 3851 3922 3997 3859 3856 3905 3837 3946 3771 3796 3886 3902 3890 3922 3871 3950 3968 3771 3861 3881 3837 3959 3821 4014 3905 3909 3944 4021 3888 3988 3940 3862 3962 3845 3972 3901 3859 3856 3971 3830 3915 3953 3911 3812 3969 3835 3940 3851 3900 3766 3930 3845 3928 3991 3715 3781 3881 3882 3808 3984 3850 3900 3785 3806 3870 3930 3740 3801 3801 3823 3847 3839 3796 3742 3847 3906 3815 3741 3709 3843 3762 3754 3850 3860 3836 3846 3917 3862 3929 3891 3897 3838 4008 3876 3883 3768 3937 3753 3809 3741 3898 3779 3936 3894 3800 3914 3896 4031 3820 3780 3891 3866 3877 3806 3848 3715 3848 3842 3854 3862 3827 3801 3803 3908 3933 3741 3905 3904 3757 3887 3818 3871 3765 3827 3822 3901 3903 3884 3931 3909 3851 3874 3829 3844 3998 3937 3796 3831 3869 3839 3875 3960 3781 3856 3887 3846 3690 3860 3783 3820 3984 3964 3819 3980 3969 3905 3767 3905 4020 3807 3834 3820 3837 3974 4019 4018 4059 3972 4086 3955 3905 4102 4130 4154 4125 4198 4124 4097 4113 4227 4450 4223 4399 4372 4392 4413 4399 4372 4269 4234 4231 4280 4142 4157 4019 4094 4029 3960 4043 4084 3878 3932 3828 3840 3912 3802 3785 3866 3759 3895 3936 3792 3735 3808 3796 3998 3949 3820 3929 3983 3883 3858 3844 3808 3833 3789 3958 3882 3829 3914 3789 3874 3939 3845 3907 3921 3840 3936 3984 3891 3949 4059 4082 3905 4020 4107 4049 4184 4077 4215 4237 4320 4194 4328 4268 4235 4178 4190 4156 4192 4051 3993 4036 3915 4030 3920 3840 3902 3774 3799 3972 3775 3861 3756 3819 3780 3795 3742 3819 3913 3827 3797 3861 3707 3834 3805 3791 3766 3827 3723 3834 3800 3823 3690 3591 3792 3736 3706 3701 3673 3663 3775 3774 3667 3834 3733 3729 3747 3753 3664 3681 3775 3823 3704 3751 3775 3780 3796 3717 3790 3647 3727 3657 3815 3696 3670 3743 3758 3718 3735 3789 3701 3741 3796 3702 3694 3678 3857 3822 3649 3683 3769 3832 3782 3717 3674 3713 3680 3699 3624 3757 3568 3767 3721 3677 3709 3721 3649 3713 3821 3790 3567 3625 3654 3602 3748 3704 3717 3676 3736 3693 3724 3700 3685 3778 3775 3729 3655 3821 3634 3626 3742 3815 3707 3726 3562 3612 3731 3675 3776 3733 3664 3708 3692 3633 3778 3650 3730 3757 3642 3631 3722 3596 3774 3651 3658 3616 3627 3729 3607 3651 3648 3635 3716 3707 3620 3575 3721 3664 3678 3650 3663 3651 3687 3621 3708 3640 3764 3584 3522 3674 3679 3606 3721 3624 3529 3648 3757 3692 3625 3684 3639 3624 3711 3671 3554 3648 3651 3642 3761 3630 3639 3622 3638 3634 3718 3718 3663 3658 3599 3664 3751 3656 3672 3687 3694 3613 3637 3684 3615 3511 3610 3628 3678 3754 3633 3575 3612 3550 3639 3683 3552 3685 3701 3774 3653 3598 3618 3654 3609 3598 3621 3586 3624 3564 3743 3574 3645 3699 3583 3537 3616 3701 3754 3629 3601 3779 3591 3716 3570 3674 3719 3621 3786 3588 3726 3602 3680 3705 3729 3566 3572 3642 3659 3709 3682 3648 3653 3756 3748 3819 3784 3786 3759 3803 3961 3901 4031 4128 4125 4241 4256 4300 4396 4516 4550 4699 4806 4865 5046 5029 4790 4650 4601 4382 4342 4158 4067 3967 3866 3650 3615 3824 3703 3672 3685 3566 3637 3617 3650 3677 3650 3583 3570 3501 3616 3524 3504 3533 3595 3574 3497 3593 3623 3620 3586 3566 3583 3509 3478 3560 3524 3491 3643 3610 3681 3535 3578 3585 3539 3565 3478 3565 3545 3593 3642 3611 3543 3565 3545 3518 3574 3378 3585 3563 3608 3416 3545 3606 3592 3643 3500 3423 3508 3600 3619 3650 3658 3421 3568 3514 3472 3611 3562 3618 3580 3448 3576 3510 3592 3354 3663 3501 3487 3536 3483 3489 3548 3599 3459 3505 3509 3374 3418 3414 3534 3480 3484 3470 3530 3494 3464 3523 3483 3418 3582 3607 3469 3472 3541 3477 3431 3449 3355 3463 3566 3567 3542 3531 3499 3444 3425 3395 3435 3518 3441 3531 3521 3470 3475 3425 3510 3469 3452 3545 3512 3495 3524 3469 3646 3512 3414 3479 3593 3472 3479 3549 3497 3398 3561 3425 3420 3580 3477 3414 3490 3550 3563 3556 3433 3529 3523 3635 3570 3482 3539 3549 3497 3541 3361 3419 3623 3475 3437 3494 3443 3487 3539 3369 3503 3510 3474 3505 3505 3553 3567 3533 3500 3551 3485 3671 3491 3469 3579 3527 3527 3582 3611 3569 3611 3553 3626 3466 3685 3537 3642 3583 3648 3546 3538 3696 3637 3647 3784 3608 3796 3770 3720 3816 3874 3825 3901 4059 4044 4044 4317 4178 4450 4507 4634 4693 4838 4844 4989 5071 5210 5355 5331 5246 5374 5162 5119 5149 4907 4799 4857 4810 4713 4754 4795 4714 4634 4688 4866 5075 5202 5376 5535 5816 6063 6412 6606 6925 7221 7404 7596 7647 7601 7663 7267 6972 6983 6730 6276 6145 5934 5663 5417 5128 5009 4805 4711 4510 4405 4290 4182 4053 4008 3830 3791 3861 3668 3667 3662 3691 3633 3641 3599 3650 3651 3560 3499 3441 3517 3418 3519 3457 3587 3481 3424 3466 3462 3538 3563 3484 3502 3520 3430 3415 3447 3502 3347 3467 3450 3443 3472 3460 3380 3453 3390 3356 3478 3341 3482 3446 3354 3461 3404 3458 3364 3475 3426 3520 3401 3328 3266 3377 3314 3454 3375 3395 3472 3422 3382 3362 3275 3366 3445 3414 3428 3461 3455 3367 3323 3395 3480 3398 3456 3429 3338 3395 3385 3351 3408 3336 3293 3351 3404 3272 3411 3325 3352 3346 3300 3389 3408 3352 3378 3403 3364 3347 3438 3263 3410 3353 3470 3329 3398 3419 3406 3388 3430 3430 3382 3270 3372 3353 3448 3397 3321 3367 3347 3317 3361 3349 3303 3269 3170 3304 3391 3335 3280 3366 3351 3472 3292 3379 3397 3362 3403 3518 3257 3280 3272 3277 3350 3334 3357 3443 3244 3319 3340 3396 3359 3314 3400 3394 3356 3337 3357 3318 3365 3426 3358 3449 3353 3382 3365 3350 3350 3213 3405 3342 3352 3231 3313 3335 3281 3331 3276 3298 3325 3357 3352 3502 3346 3337 3298 3368 3361 3311 3346 3327 3242 3324 3426 3261 3286 3372 3302 3295 3263 3342 3386 3372 3401 3302 3339 3400 3452 3324 3365 3231 3286 3446 3411 3400 3360 3266 3464 3365 3318 3378 3348 3371 3258 3308 3273 3283 3371 3259 3307 3341 3298 3411 3470 3354 3459 3342 3361 3411 3403 3396 3474 3589 3380 3469 3451 3372 3340 3397 3496 3355 3502 3402 3401 3448 3447 3504 3654 3498 3455 3430 3473 3449 3462 3471 3449 3482 3464 3445 3459 3530 3485 3624 3524 3489 3527 3564 3597 3639 3718 3603 3588 3658 3720 3665 3680 3708 3748 3877 3741 3885 3842 3865 3931 3929 3947 4094 4069 4223 4244 4266 4333 4324 4603 4739 4880 4962 5030 5293 5540 5854 6027 6396 6826 7152 7511 8033 8525 9082 9651 10214 10753 11523 12149 12543 13158 13294 13371 13353 13168 12804 12259 11840 11216 10729 9991 9335 8670 8218 7590 7003 6464 6214 5857 5428 5385 5129 4856 4853 4639 4659 4334 4419 4327 4220 4157 4101 4023 3841 3964 3801 3878 3861 3853 3767 3801 3758 3662 3694 3585 3602 3674 3574 3585 3659 3565 3488 3501 3558 3494 3617 3562 3543 3482 3432 3600 3381 3483 3420 3440 3578 3433 3391 3373 3410 3445 3404 3399 3451 3331 3404 3281 3473 3402 3413 3342 3432 3416 3358 3413 3481 3350 3350 3280 3402 3476 3349 3363 3280 3457 3380 3253 3410 3313 3270 3374 3293 3424 3329 3292 3261 3370 3310 3411 3335 3431 3394 3412 3472 3349 3502 3351 3345 3394 3478 3415 3342 3408 3419 3401 3366 3393 3334 3537 3319 3388 3350 3487 3400 3372 3442 3451 3461 3379 3518 3454 3506 3461 3632 3620 3571 3666 3754 3827 3970 4027 4051 4138 4256 4431 4595 4790 4836 4926 5203 5270 5320 5304 5431 5256 5250 5269 5082 5099 4993 4673 4568 4553 4488 4370 4232 4085 3964 4040 3995 3998 3925 3951 3977 3867 4210 4084 4177 4345 4493 4455 4707 4998 5163 5561 5960 6378 6934 7621 8346 9332 10384 11600 12696 14284 15336 16575 17516 18008 17692 16662 15489 14206 13095 12217 11263 10516 9600 8142 7164 6432 5659 5071 4765 4573 4253 4240 3985 3900 3871 3806 3863 3749 3788 3880 3764 3700 3602 3721 3658 3709 3758 3604 3501 3558 3479 3636 3492 3532 3529 3614 3579 3542 3621 3543 3607 3571 3556 3564 3586 3533 3574 3553 3612 3632 3665 3669 3757 3725 3591 3758 3778 3636 3740 3880 3918 3850 3941 4048 3994 4057 4122 4290 4418 4496 4428 4747 4803 4969 5003 5239 5366 5583 5888 6242 6682 6928 7191 7657 8106 8730 8925 9496 9769 10249 10776 10786 10689 10899 10737 10466 10275 9578 9238 9013 8495 8024 7640 7033 6671 6286 5952 5657 5234 5067 4894 4854 4529 4514 4409 4174 4117 4000 4108 3934 3957 3921 3972 3766 3753 3786 3614 3713 3550 3539 3555 3595 3510 3497 3558 3482 3476 3401 3317 3390 3290 3365 3353 3372 3337 3412 3293 3280 3209 3372 3231 3369 3185 3365 3245 3225 3323 3244 3243 3345 3240 3217 3234 3351 3230 3122 3218 3322 3326 3312 3169 3258 3194 3091 3255 3377 3200 3229 3220 3260 3254 3135 3252 3229 3326 3252 3188 3130 3244 3244 3294 3152 3188 3051 3294 3260 3243 3164 3090 3267 3214 3150 3311 3223 3218 3149 3116 3221 3288 3166 3335 3180 3087 3195 3142 3179 3247 3359 3288 3388 3473 3344 3396 3391 3486 3434 3389 3460 3419 3390 3297 3376 3395 3396 3395 3337 3374 3414 3295 3329 3178 3212 3286 3249 3397 3389 3344 3386 3397 3505 3439 3516 3506 3589 3606 3841 3912 4046 4208 4321 4596 4759 5047 5325 5629 6214 6527 6865 7364 7598 7924 8043 7743 7692 7222 6934 6570 6309 6080 5860 5490 5332 4925 4645 4357 4208 3963 3745 3745 3609 3405 3508 3405 3420 3473 3362 3377 3345 3402 3344 3315 3398 3377 3452 3326 3388 3352 3460 3343 3388 3416 3548 3528 3430 3451 3518 3496 3456 3668 3577 3671 3803 3860 3930 4002 4118 4378 4281 4602 4639 4659 5105 5065 5067 5588 5460 5772 5810 5867 5903 5741 5958 5759 5805 5503 5427 5267 5297 5060 5076 4959 4750 4775 4745 4826 4924 4930 5058 5036 5173 5207 5415 5529 5619 5567 5523 5406 5461 5432 5290 5146 4943 4891 4754 4567 4434 4281 4177 4052 4003 3879 3822 3779 3633 3609 3637 3528 3578 3577 3443 3439 3457 3386 3338 3389 3401 3401 3505 3444 3585 3520 3558 3461 3408 3358 3496 3431 3455 3452 3532 3587 3686 3669 3643 3662 3602 3695 3846 3987 3964 4090 4195 4444 4674 4813 5207 5323 5860 6238 6629 7490 8013 8726 9277 10583 11537 12412 13285 13720 14589 15050 15373 15169 15408 14914 14288 13811 13204 12666 12048 11438 10693 9875 9198 8397 7485 7036 6571 6179 5760 5403 5087 4885 4675 4440 4337 4333 4026 4080 3796 3939 3859 3752 3715 3791 3695 3671 3770 3728 3653 3672 3728 3746 3775 3684 3691 3812 3789 3855 3841 3878 3897 4130 4195 4217 4389 4367 4532 4818 4856 5087 5226 5653 5854 6084 6333 6725 6996 7155 7171 7257 7184 6837 6526 6444 6070 6120 5795 5550 5301 5072 4825 4536 4228 4030 3842 3778 3675 3523 3457 3426 3395 3267 3364 3285 3228 3390 3264 3203 3192 3197 3217 3178 3181 3245 3181 3260 3086 3139 3003 3135 3080 3141 3142 3035 3172 3000 3109 3014 3087 3081 3056 3159 3161 3112 3108 3144 3167 3056 3118 3106 3111 3049 3052 3082 3132 3160 3179 3172 3114 3161 3197 3226 3259 3273 3329 3316 3401 3298 3453 3370 3374 3453 3355 3391 3345 3294 3272 3200 3244 3134 3197 3258 3206 3198 3104 3190 3095 3021 2994 3039 3103 3110 3032 3082 3006 3077 3048 2973 3061 3056 2954 2982 3029 3049 3070 3116 3071 3048 3129 3024 3109 3062 3188 3131 3036 3188 3210 3302 3342 3355 3380 3570 3639 3638 3798 3790 3862 3830 3742 3682 3559 3444 3515 3347 3446 3317 3333 3340 3301 3148 3166 3115 3109 3092 3075 2972 3067 3043 3014 2949 2981 2937 2960 3006 3048 2964 3003 3025 2926 3014 2936 2946 3093 2969 3011 2981 2885 2876 2927 3028 2965 2909 3027 2911 2915 2983 2990 2900 3030 2981 3017 2942 2967 2888 2990 2970 3055 2949 2873 2939 3000 3075 2962 3024 3085 2856 3070 2992 2916 3078 2990 3030 3107 3125 2962 3051 3042 3209 3042 3130 3207 3084 3179 3163 3241 3259 3339 3332 3358 3437 3477 3620 3573 3804 3688 3702 3789 3828 3886 3842 3860 3852 3746 3639 3576 3621 3616 3625 3454 3427 3413 3298 3332 3235 3193 3238 3131 3175 3074 3112 3129 3130 3092 3019 3044 3010 3085 3057 3084 3001 3093 3015 2970 3023 2901 2869 2962 2981 3014 2953 2885 2947 3032 3035 3002 2936 2975 2934 2943 3084 2877 2917 3042 2964 2915 2907 3031 2952 3003 2978 2939 2954 2924 3021 2993 2955 2931 2982 2941 2988 3097 2925 2993 2864 3035 3025 3077 3090 3119 3055 3190 3137 3126 3218 3301 3392 3260 3290 3246 3342 3408 3339 3333 3212 3320 3213 3192 3117 3123 3208 3064 2950 3012 3009 3091 2917 3059 2993 3015 2988 2917 3036 3046 2967 2992 3062 3007 2948 2918 3006 3036 2876 3029 2933 2967 2931 3008 3032 3037 3028 2938 2951 3027 2950 3087 2942 3006 2846 2928 2988 3035 2987 2971 2991 2963 2947 2970 2924 2990 2986 2979 2950 3000 2954 3052 2941 2957 3023 3032 2989 3051 2936 3082 3040 3045 3013 3064 2983 3084 2995 3036 3016 3119 3117 3130 3104 3087 3137 3128 3233 3207 3197 3223 3351 3486 3389 3376 3458 3649 3676 3633 3800 3793 3960 4048 4071 4045 4089 4116 4263 4207 4045 4076 4048 3949 3964 4127 3936 3867 3862 3764 3620 3647 3683 3605 3380 3524 3414 3341 3359 3462 3310 3345 3401 3231 3518 3443 3431 3496 3508 3528 3603 3606 3772 3828 3838 4053 4042 4041 4218 4254 4424 4565 4769 4701 4752 4727 4631 4497 4389 4343 4183 4324 4324 4167 4163 4011 3958 3900 3824 3730 3725 3554 3496 3510 3563 3528 3580 3422 3493 3500 3574 3596 3610 3645 3842 3802 3810 3818 3720 3627 3569 3461 3469 3390 3342 3364 3339 3327 3261 3293 3167 3058 3128 3104 2935 2931 3003 2960 2996 2859 2920 2859 2962 2918 2836 2857 2884 2912 2892 2863 2921 3008 2878 2905 2834 3010 2961 2897 2874 2929 2824 2870 2924 2889 2886 2968 2792 2933 2844 2878 2933 2827 2835 2873 2779 2824 2867 2866 2899 2911 2961 2870 2827 2839 2826 2911 2887 2870 2880 2785 2865 2854 2957 2890 2940 2773 2923 2818 2896 2912 2872 2878 2837 2830 2903 2953 3009 2967 3043 3098 2982 3038 2975 3036 3108 3085 3118 3240 3388 3370 3442 3629 3594 3794 3948 3978 4133 4119 3983 4139 4089 4152 4031 4060 4029 4052 3947 3896 3764 3796 3752 3593 3445 3436 3423 3456 3322 3254 3294 3184 2951 3139 2926 3083 3102 2994 2963 2872 2908 2949 2936 3067 2930 2915 2848 2958 2940 2893 2945 2935 2895 2897 2903 2960 2824 2906 2818 2952 2863 2890 2924 2831 2873 2863 2884 2947 2880 2841 3102 2952 2872 2944 3044 2872 3051 3076 3047 2953 2997 2877 2884 3015 2896 2901 2990 2811 2914 2986 2847 2902 2926 2818 2876 2868 2837 2983 2909 2884 2885 2827 2830 2915 2903 2885 2940 2956 2955 3019 2992 2947 3055 2997 3059 2963 3169 3045 3074 3063 3012 2912 3095 2971 2980 3009 2907 2899 2860 2861 2981 2845 2960 2835 2767 2908 2765 2874 2853 2851 2851 2935 2841 2905 2791 2730 2826 2882 2813 2886 2896 2897 2835 2899 2886 2813 2888 2912 2895 2890 2811 2829 2769 2866 2987 2848 2852 2877 2829 2868 2853 2832 2895 2929 2860 2866 2881 2922 2929 3008 2948 2932 2996 2990 2994 3030 2968 3105 3120 3081 3091 3112 3246 3179 3254 3199 3319 3360 3242 3299 3322 3248 3325 3321 3218 3118 3169 3189 3173 3136 3204 3184 2980 3110 3067 2982 3077 3078 2936 2967 2955 3003 2896 3030 3054 2901 2929 3026 2912 2946 2907 2973 2945 3104 2975 2992 3012 3093 3097 3073 3114 3167 3189 3394 3420 3611 3738 3864 4080 4155 4301 4540 4719 4571 4453 4363 4237 4360 4193 4072 4118 4042 4155 4145 4202 4049 3908 3735 3595 3318 3412 3487 3341 3359 3384 3348 3189 3106 3065 3119 3148 3081 3049 3042 3006 2991 2989 2898 2957 2889 2915 2969 2849 3014 2925 2909 2821 2924 2851 2904 2848 2875 2929 2880 2866 2834 2821 2745 2833 2782 2782 2759 2803 2766 2879 2861 2867 2809 2890 2746 2867 2854 2837 2834 2685 2808 2817 2824 2791 2872 2839 2760 2845 2778 2832 2829 2825 2810 2739 2787 2760 2923 2820 2707 2905 2795 2726 2771 2656 2756 2801 2830 2803 2732 2794 2805 2758 2788 2704 2816 2776 2852 2862 2753 2760 2803 2770 2680 2753 2806 2821 2743 2840 2776 2864 2800 2825 2844 2733 2827 2806 2807 2749 2802 2727 2767 2808 2799 2839 2828 2765 2758 2787 2737 2822 2838 2915 2790 2810 2852 2791 2777 2769 2842 2691 2805 2743 2782 2740 2791 2735 2776 2738 2810 2689 2755 2694 2850 2735 2691 2769 2830 2789 2831 2726 2778 2759 2789 2798 2815 2789 2708 2799 2678 2742 2804 2760 2720 2725 2820 2749 2761 2676 2764 2755 2811 2752 2750 2714 2745 2784 2700 2807 2797 2746 2707 2806 2804 2760 2622 2703 2865 2761 2791 2879 2809 2692 2760 2821 2817 2849 2733 2796 2762 2801 2733 2727 2786 2749 2756 2740 2764 2720 2834 2708 2746 2666 2738 2690 2765 2783 2711 2872 2731 2788 2844 2729 2738 2741 2757 2734 2760 2737 2735 2749 2752 2801 2742 2681 2860 2839 2731 2711 2755 2764 2733 2842 2797 2801 2794 2780 2762 2692 2792 2755 2813 2790 2756 2728 2800 2812 2856 2820 2847 2779 2899 2760 2791 2820 2831 2784 2816 2757 2874 2780 2824 2813 2740 2999 2789 2912 2811 2871 2775 2883 2775 2887 2783 2894 2833 2809 2845 2992 2883 3012 2879 2915 2881 3044 3026 3094 3027 3011 2982 3065 3166 3163 3180 3297 3269 3343 3454 3426 3422 3517 3301 3455 3337 3428 3491 3385 3324 3538 3503 3500 3557 3640 3596 3770 3874 3947 3884 4126 4170 4373 4517 4545 4744 4816 4804 4703 4618 4541 4452 4226 4319 4404 4292 4229 4115 4077 4057 3919 3876 3737 3726 3623 3527 3460 3433 3205 3308 3295 3209 3077 3161 3104 3016 3008 3037 3023 3185 3063 2986 3089 3145 3105 2943 3056 2946 3073 3069 3118 3077 3107 3140 3270 3244 3397 3325 3422 3566 3757 3853 3953 4193 4215 4432 4550 4608 4804 4512 4460 4438 4375 4263 4376 4308 4397 4579 4621 4803 4922 5096 5230 5185 5453 5486 5505 5481 5769 5484 5289 5139 5129 4992 4805 4779 4893 4670 4705 4497 4454 4371 4419 4269 4314 4145 3923 3823 3716 3654 3638 3503 3573 3590 3656 3561 3703 3824 3849 3840 4020 3894 4142 4153 4440 4396 4493 4610 4622 4851 5007 5164 5365 5596 5995 6508 7205 7776 8298 9044 9367 9556 8850 8212 7617 6877 6265 5963 5804 5808 6040 6137 6135 6267 6067 5572 5227 4700 4371 4020 3789 3588 3514 3322 3447 3287 3267 3129 3098 3196 3220 3140 3109 3108 3242 3178 3118 3214 3216 3100 3145 3144 3284 3209 3285 3194 3282 3197 3193 3232 3309 3243 3290 3186 3194 3233 3221 3137 3129 3194 3123 3024 3146 2925 3006 3035 3020 3045 2993 2838 2866 2955 2876 2871 2849 2926 2793 2892 2923 2914 2835 2774 2823 2837 2819 2714 2758 2755 2826 2777 2933 2831 2826 2805 2778 2781 2806 2886 2750 2821 2808 2785 2795 2722 2732 2733 2851 2720 2871 2758 2805 2788 2745 2853 2689 2826 2843 2877 2790 2780 2899 2750 2806 2703 2754 2755 2696 2856 2724 2813 2799 2842 2879 2718 2821 2753 2834 2888 2724 2772 2760 2776 2864 2753 2897 2814 2808 2942 2857 2762 3011 2978 2933 2990 3066 3168 3079 3140 3167 2966 2969 2978 3027 2914 3007 3015 2906 2947 2949 3009 2967 3041 2931 2974 2903 2825 2842 2760 2772 2833 2837 2861 2790 2865 2739 2861 2851 2816 2814 2789 2863 2942 2882 2862 2715 2838 2767 2871 2797 2912 2754 2802 2770 2889 2755 2875 2840 2819 2777 2965 2896 2986 3052 3002 3025 3159 3117 3130 3241 3258 3205 3210 3170 3299 3241 3178 3188 3303 3209 3141 3168 3191 3261 3142 3105 3112 3143 3090 3050 2970 3092 3038 2995 3065 2953 2915 2902 3016 2841 2886 2788 2901 3003 2807 2751 2931 2854 2974 2829 2866 2876 2799 2731 2888 2866 2837 2896 2806 2817 2753 2881 2842 2887 2922 2809 2851 2882 2966 2877 2885 2873 2860 2937 2877 2991 2974 2883 2897 2936 2969 2983 2962 3096 3083 2998 3126 3007 3104 3154 3150 3229 3322 3411 3462 3541 3442 3562 3684 3639 3691 3784 3665 3931 3818 3809 3941 3825 3885 3934 3962 3813 3891 3880 3768 3827 3826 3795 3576 3709 3705 3763 3608 3701 3495 3536 3674 3428 3604 3644 3733 3589 3673 3931 4007 4082 4371 4693 4854 5277 5715 5909 6305 6457 6548 6447 6162 5978 5543 5266 5042 4990 4856 4928 4846 5095 5004 4866 4948 4775 4501 4250 4184 4058 3690 3680 3464 3407 3447 3290 3302 3242 3064 3141 3129 3120 3109 3027 3036 3004 2965 3010 3134 3035 3043 3068 2967 2967 3101 2953 3043 2972 3085 3001 3075 3013 3045 3063 3106 3071 3049 3190 3275 3056 3199 3195 3258 3241 3422 3409 3481 3577 3714 3614 3737 3759 3945 3976 4126 4084 4009 4241 4095 4198 4183 4061 4114 4123 4157 4135 4121 4127 4155 4006 4084 3990 4181 4107 4169 4241 4298 4213 4297 4404 4337 4295 4340 4304 4401 4298 4237 4178 3819 3813 3738 3586 3740 3666 3738 3762 3703 3814 3803 3664 3670 3571 3578 3510 3616 3661 3695 3701 3766 3697 3724 3668 3670 3795 3711 3567 3624 3699 3454 3589 3490 3477 3490 3476 3507 3308 3374 3397 3145 3249 3173 3162 3099 3195 3167 3046 3047 3009 2984 3042 2942 3033 2969 2986 2939 2958 2908 3019 2962 3024 3002 2842 3052 2959 3057 3019 3115 3055 3088 3304 3242 3329 3448 3564 3689 3679 3894 3945 3817 3994 4109 4020 4103 4024 4022 4200 4161 4243 4358 4089 4045 4131 4117 3972 4082 3981 3978 3901 3740 3846 3757 3669 3489 3466 3609 3416 3385 3375 3375 3267 3252 3271 3173 3172 3196 3176 3127 3095 3164 3159 3105 3079 3283 3079 3221 3285 3236 3309 3345 3359 3380 3431 3433 3636 3576 3666 3777 3586 3812 3682 3697 3651 3638 3630 3469 3585 3421 3350 3406 3394 3413 3398 3371 3461 3363 3340 3235 3250 3139 3082 3040 3035 3096 2954 2933 3047 3032 2946 3056 2927 2914 2918 2933 2848 2986 2804 2827 2914 2883 2952 2966 2916 2846 2903 2939 2968 3041 3025 2907 3007 2991 3002 3061 3080 3073 3124 3225 3224 3340 3239 3376 3307 3367 3358 3424 3391 3397 3478 3366 3484 3560 3449 3457 3335 3673 3543 3442 3534 3493 3476 3394 3378 3336 3337 3339 3256 3332 3236 3263 3146 3239 3228 3281 3316 3273 3289 3264 3282 3218 3251 3172 3266 3287 3232 3120 3056 3108 3121 3106 3045 3098 3088 3163 3048 3159 2987 3072 2983 3022 2901 2903 2940 2862 2901 2914 2930 2974 2824 2915 2940 2947 2859 2883 2942 3016 2836 3023 2989 3179 3260 3268 3492 3459 3445 3446 3473 3198 3224 3157 3046 3038 3014 3058 3035 3109 3150 3109 3166 3169 3090 3122 2969 3018 2963 2872 2924 2824 2807 2816 2730 2855 2790 2803 2860 2823 2837 2763 2737 2810 2825 2765 2855 2754 2776 2828 2804 2796 2736 2818 2809 2697 2807 2794 2797 2811 2825 2756 2807 2822 2859 2838 2885 2738 2842 2813 2850 2808 2757 2806 2953 2748 2857 2769 2849 2930 2927 3001 2897 2934 2967 2886 2978 2884 2956 2875 3012 3070 3160 3156 3090 3105 3208 3274 3351 3381 3405 3563 3474 3611 3632 3684 3588 3652 3651 3706 3637 3687 3680 3659 3623 3703 3733 3834 3653 3768 3761 3714 3749 3802 3796 3796 3726 3774 3805 3631 3660 3742 3649 3575 3760 3822 3868 3753 3943 3830 4110 4190 4550 4803 5266 5739 6254 6533 7120 7422 7217 6775 6414 5749 5379 4842 4648 4355 4392 4475 4462 4545 4927 4896 5146 5032 4979 4747 4342 4096 3822 3652 3521 3353 3264 3149 3144 3053 3041 3039 2986 3043 2953 2873 2889 2878 2828 2954 2756 2805 2774 2818 2820 2893 2896 2839 2882 2824 2918 2835 2963 2888 2809 2879 2840 2862 2969 2888 2731 2755 2907 2814 2794 2940 2807 2820 2809 2830 2880 2893 2867 2948 2828 2826 2950 2895 2820 2817 2844 2947 2836 3001 2875 2996 3088 3152 2943 3068 3067 3112 3045 3208 3178 3260 3310 3250 3338 3454 3544 3373 3406 3436 3347 3428 3312 3266 3351 3286 3128 3284 3235 3358 3234 3270 3302 3284 3299 3143 3301 3129 3252 3209 3118 3244 3176 3271 3240 3114 3165 3263 3352 3319 3410 3489 3629 3686 3890 3983 4113 3996 4062 3906 4006 3808 3736 3604 3721 3814 3852 3774 4005 4078 4128 4187 4246 4275 4314 4307 4445 4415 4296 4438 4546 4504 4645 4712 4773 4755 4694 4815 4845 4902 4841 4921 4734 4924 4970 4857 4732 4569 4682 4615 4448 4462 4303 4222 4269 4197 4134 4161 4077 3907 3860 3815 3799 3855 3695 3559 3564 3483 3526 3448 3398 3319 3355 3254 3203 3194 3261 3165 3153 3186 3138 3239 3124 3191 3094 3136 3057 3045 3058 3097 3171 3127 3193 3197 3240 3307 3306 3501 3481 3363 3599 3518 3567 3625 3795 3608 3769 3592 3689 3881 3803 3783 3740 3807 3722 3912 3851 3993 3851 4076 3917 4162 4178 4352 4367 4389 4303 4214 3988 4116 3790 3848 3703 3647 3701 3700 3762 3707 3874 3985 4175 4042 4150 4198 4151 4107 3953 3704 3631 3550 3383 3340 3070 3220 3161 3316 3115 3338 3267 3233 3259 3245 3028 3082 3009 3035 3048 2912 2870 2928 3000 2946 2871 2825 2843 2807 2886 2878 2811 2847 2756 2732 2777 2776 2726 2777 2871 2630 2875 2921 2758 2757 2800 2771 2804 2716 2757 2807 2742 2780 2674 2726 2836 2765 2754 2842 2786 2801 2858 2802 2841 2828 2836 2837 2786 2933 2839 2931 3013 2834 2886 2944 2944 2908 2854 2877 2989 2977 3032 2981 2987 3074 3016 3009 3076 3119 2993 3159 2957 3136 3031 3180 3062 3002 3011 2998 3085 3101 3002 3056 3083 2986 3006 3039 3002 3023 3066 3129 2961 3091 3020 3063 2964 3171 3072 3123 3187 3254 3267 3418 3420 3590 3656 3858 3996 4171 4174 4273 4283 4244 4181 4002 3816 3816 3761 3602 3633 3447 3586 3516 3566 3484 3568 3539 3614 3551 3488 3586 3272 3350 3279 3178 3104 3046 3087 3047 3000 2946 2929 2983 2933 2979 2892 2836 2924 2898 2927 2875 2901 2921 2906 2884 2936 2888 2867 2917 2923 3003 2901 2894 2943 3032 2902 2933 2972 3039 3084 3060 3039 3048 3015 3053 3070 3073 3073 3067 3085 3035 3034 3048 3140 3128 3076 3147 3131 3170 3054 3112 3136 3137 3166 3240 3280 3273 3245 3334 3362 3419 3390 3478 3507 3466 3419 3412 3408 3421 3460 3403 3301 3381 3201 3362 3303 3138 3235 3303 3172 3295 3309 3313 3308 3197 3125 3247 3138 3082 3095 3125 3073 3077 3050 2935 3001 2884 2975 3029 2948 2941 3038 3000 3115 3081 3092 3090 2956 2988 2967 2988 2842 2794 2812 2908 2791 2839 2817 2841 2836 2893 2799 2865 2864 2879 2754 2848 2690 2721 2750 2735 2680 2793 2672 2801 2753 2809 2683 2690 2720 2730 2739 2686 2675 2737 2718 2646 2721 2725 2698 2757 2719 2718 2758 2686 2729 2753 2649 2766 2703 2638 2705 2648 2687 2703 2640 2785 2666 2684 2692 2743 2707 2622 2700 2672 2728 2800 2614 2600 2694 2624 2612 2752 2708 2698 2732 2658 2826 2658 2660 2686 2750 2607 2727 2677 2727 2659 2717 2705 2664 2711 2799 2720 2716 2698 2675 2630 2737 2670 2692 2644 2672 2695 2811 2733 2701 2690 2634 2648 2744 2614 2731 2709 2679 2817 2726 2788 2749 2770 2784 2807 2837 2974 2916 2962 3037 3104 3118 3209 3107 3104 3072 3039 2957 2785 2974 2833 2817 2793 2774 2788 2822 2925 2844 2808 2844 2801 2919 2841 2887 2807 2801 2770 2697 2753 2670 2689 2566 2650 2689 2707 2696 2736 2698 2704 2800 2709 2574 2590 2709 2594 2642 2656 2630 2554 2628 2691 2747 2734 2664 2687 2641 2628 2636 2639 2640 2657 2607 2718 2586 2661 2681 2798 2634 2710 2765 2720 2575 2637 2616 2585 2721 2610 2729 2659 2671 2772 2746 2654 2664 2661 2584 2687 2658 2594 2722 2611 2752 2668 2699 2666 2572 2760 2728 2736 2693 2717 2766 2770 2730 2741 2793 2729 2833 2723 2686 2690 2723 2726 2737 2835 2743 2812 2782 2761 2775 2925 2938 2841 2946 2976 2977 2979 3049 3054 3080 2966 3049 3106 3110 3035 3155 3006 3065 3104 2874 2940 2959 2945 2915 2942 2852 2855 2815 2944 2969 2914 3023 2899 2902 2906 2840 2819 2806 2859 2856 2712 2705 2635 2701 2634 2696 2766 2683 2697 2733 2616 2653 2769 2681 2690 2601 2721 2709 2670 2799 2778 2803 2830 2833 2754 2729 2724 2734 2747 2761 2829 2736 2764 2774 2678 2686 2785 2726 2785 2758 2749 2818 2757 2832 2767 2700 2649 2722 2723 2781 2764 2638 2702 2761 2854 2721 2667 2677 2601 2668 2673 2598 2765 2724 2771 2617 2690 2685 2597 2702 2689 2604 2695 2752 2703 2756 2710 2781 2777 2695 2719 2601 2701 2624 2835 2715 2702 2761 2706 2740 2794 2684 2690 2673 2703 2776 2840 2714 2748 2763 2782 2805 2684 2960 2841 2795 2874 2829 2797 2866 2867 2771 2746 2851 2770 2799 2831 2874 2866 2680 2746 2820 2724 2786 2685 2863 2806 2822 2817 2761 2815 2831 2714 2824 2794 2833 2794 2736 2686 2811 2746 2893 2693 2839 2824 2862 2783 2779 2811 2774 2767 2907 2848 2900 2857 2967 2944 2942 3003 2974 2903 3015 3035 3067 3061 3035 3139 3100 3090 3175 3199 3089 3072 3122 3209 3058 3019 3152 3077 3191 3108 3191 3136 3187 3179 3188 3080 3006 3046 3169 2990 2924 3027 2997 2986 2985 2886 2920 2960 2968 2906 2983 2860 2993 2863 2839 2854 2783 2821 2737 2896 2836 2770 2752 2735 2831 2726 2791 2760 2756 2788 2782 2708 2806 2710 2732 2711 2718 2740 2806 2799 2767 2723 2723 2700 2758 2773 2806 2677 2701 2766 2754 2759 2868 2915 2763 2840 2737 2773 2730 2841 2770 2827 2782 2827 2892 2783 2905 2815 2890 2759 2854 2863 2894 2894 2808 2852 2809 2914 2924 2786 2982 2800 2768 2933 2835 2850 2905 2868 2948 2918 2942 2961 2997 2937 3025 3037 3175 3165 3125 3107 3153 3270 3316 3274 3284 3216 3255 3194 3258 3184 3098 3065 3077 2915 3168 3081 3070 2998 3183 3094 3102 3051 3179 3046 3095 3083 3017 3001 3122 3026 2878 2973 2957 2913 3031 3043 2776 2948 2910 2829 2851 2852 2883 2820 2828 2776 2789 2881 2770 2797 2806 2885 2735 2792 2800 2849 2820 2734 2860 2861 2862 2862 2862 2898 2899 3007 3046 3054 3007 3043 2970 2937 2974 3086 2897 2864 2819 2847 2875 2858 2947 2957 2896 2937 2992 2974 2933 3038 2992 3102 3148 3040 3034 3007 2996 2941 3024 2934 3022 3089 3036 3028 3029 3041 2918 2968 2998 2966 2912 2983 2848 3019 2988 2890 2955 2892 2804 2952 2890 2905 2948 2920 2851 2796 2794 2864 2806 2847 2731 2835 2779 2783 2828 2832 2756 2734 2697 2735 2663 2722 2715 2815 2765 2693 2792 2705 2736 2825 2743 2709 2823 2762 2648 2651 2762 2697 2752 2716 2718 2779 2691 2766 2652 2745 2793 2739 2752 2741 2643 2748 2658 2705 2790 2776 2771 2770 2847 2740 2809 2707 2865 2829 2869 2805 2860 2869 2869 2963 2865 3064 3108 3049 3192 3263 3348 3388 3339 3373 3293 3223 3198 3153 3114 3091 3078 3050 3050 3138 3217 3104 3045 3178 3220 3199 3138 3193 3171 3174 3090 2986 3038 3015 3018 2854 2909 2924 2929 2932 2936 2873 2879 2848 2879 2871 2918 2820 2830 2835 2866 2923 2858 3037 2966 3023 3033 3043 2987 3133 3188 3102 2968 3013 3036 2967 2968 3037 3043 2880 2988 2885 2917 2971 2991 2875 2868 3058 2954 2990 2904 2865 2867 2912 2882 2798 2902 2791 2815 2780 2847 2840 2806 2793 2755 2786 2752 2800 2761 2777 2650 2748 2730 2706 2701 2738 2640 2652 2668 2656 2549 2639 2629 2775 2723 2727 2695 2715 2805 2774 2765 2749 2716 2797 2791 2853 2814 2914 2952 2868 2967 2985 3234 3212 3213 3302 3063 3088 3063 2979 2900 2963 2912 2863 2865 2769 2882 2914 2854 2902 2953 2971 2938 3026 3012 3048 3073 2955 2920 2925 2945 2833 2870 2854 2813 2859 2793 2891 2861 2980 2957 2906 3001 2901 3045 3033 2941 2996 3011 2983 2968 3008 2893 2919 2916 2950 2952 3078 2950 3044 3026 3037 2873 2922 2900 3028 2888 2796 2915 2934 2792 2851 2941 2817 2883 2881 2910 2800 2676 2787 2733 2760 2714 2824 2788 2831 2728 2773 2786 2787 2812 2675 2670 2680 2700 2698 2730 2698 2844 2753 2729 2717 2697 2727 2592 2823 2809 2722 2835 2633 2718 2666 2670 2735 2780 2686 2729 2679 2722 2787 2906 2833 2824 2905 2859 3037 3031 3001 3037 3065 3006 3041 3064 3001 2968 3041 2940 2879 2961 2859 2935 2980 2784 2832 2852 2886 2942 2914 2993 2841 2953 2903 2929 2867 2942 2858 2935 2934 2865 2854 2885 2779 2892 2846 2815 2801 2821 2676 2674 2642 2815 2751 2772 2842 2699 2848 2802 2764 2754 2773 2767 2711 2725 2851 2733 2702 2738 2727 2725 2760 2747 2844 2606 2820 2746 2744 2745 2718 2710 2729 2766 2755 2833 2712 2827 2648 2725 2727 2676 2706 2776 2723 2820 2728 2768 2890 2853 2598 2755 2815 2784 2781 2807 2747 2852 2851 2884 2824 2801 2779 2763 2820 2807 2781 2820 2899 2873 2796 2876 2948 2896 2935 2964 2952 3027 3009 3013 3126 3115 3082 3209 3108 3280 3258 3174 3159 3120 3117 2975 2997 2862 3024 2932 2931 2971 2970 2919 3019 2958 2944 3069 2882 3110 3001 3189 3054 3031 2988 3074 3031 3005 3040 2964 3052 2978 3031 3029 2903 2896 2981 2939 2924 2844 2879 2781 2838 2820 2753 2844 2719 2916 2790 2962 2906 2738 2854 2864 2838 2742 2823 2814 2788 2632 2807 2695 2763 2649 2829 2778 2699 2729 2718 2729 2699 2822 2629 2734 2681 2655 2715 2615 2703 2614 2686 2626 2673 2706 2660 2644 2669 2692 2649 2627 2651 2732 2704 2665 2702 2734 2675 2676 2646 2774 2658 2611 2735 2705 2656 2588 2653 2752 2610 2611 2629 2616 2574 2647 2758 2726 2647 2660 2711 2648 2786 2803 2821 2840 2896 2820 2775 2866 2779 2761 2763 2787 2789 2825 2766 2773 2769 2683 2681 2748 2682 2689 2696 2744 2755 2807 2720 2701 2753 2727 2752 2638 2711 2643 2617 2697 2721 2720 2712 2627 2633 2687 2682 2685 2791 2706 2746 2629 2787 2761 2757 2667 2596 2685 2672 2713 2751 2689 2736 2679 2692 2792 2669 2715 2660 2675 2633 2698 2684 2682 2690 2768 2785 2718 2712 2737 2757 2702 2664 2641 2623 2678 2733 2733 2742 2738 2697 2659 2716 2599 2700 2762 2716 2726 2744 2700 2764 2741 2763 2638 2668 2619 2660 2715 2643 2663 2688 2656 2708 2707 2768 2737 2740 2772 2731 2786 2712 2760 2970 2866 2850 2962 2840 2994 3055 3094 3145 3137 3284 3089 3150 3114 3069 3079 2932 3013 3007 3049 2886 2928 2962 2896 2975 2901 2964 3027 3057 3140 3208 3091 3233 3221 3289 3236 3242 3182 3099 2981 3069 3036 2999 2979 2936 2988 2920 2912 2831 2875 2851 2935 2820 2784 2925 2834 2959 2919 2797 2869 2789 2757 2813 2887 2808 2809 2814 2681 2784 2783 2749 2754 2713 2804 2713 2748 2795 2708 2659 2701 2709 2703 2735 2687 2684 2784 2813 2664 2633 2751 2676 2701 2663 2785 2734 2731 2794 2706 2729 2647 2815 2792 2805 2772 2738 2729 2779 2777 2833 2727 2725 2756 2693 2807 2766 2892 2823 2776 2827 2880 2973 2959 2934 3054 3001 3098 3206 3288 3310 3383 3487 3545 3775 3809 3972 3845 3700 3628 3462 3294 3203 3265 3245 3166 3074 3100 3039 3000 2964 2948 3093 3129 3197 3222 3204 3231 3441 3347 3370 3262 3197 3159 3131 3037 2990 2971 2821 2921 2948 2924 2852 2811 2863 2901 2970 3030 2862 2914 2994 2943 2876 2969 2947 2866 2908 2974 2932 2847 2933 2832 2855 2896 2872 2945 2810 3011 2915 2982 2904 2909 2960 2900 2969 2844 2872 2859 2832 2942 2817 2823 2848 2821 2886 2788 2756 2856 2834 2815 2781 2768 2907 2886 2812 2867 2894 2833 2969 2907 3013 2953 2954 2959 3021 2915 2937 3006 3030 2898 2981 2957 2934 2917 2983 2849 2853 2975 2822 2950 2948 2917 2910 3000 2965 2958 2969 2996 3093 2998 3020 2902 3075 2903 3002 3048 2927 2874 2905 2847 2875 3007 2933 2931 2915 2869 3046 2931 2995 2898 3001 2933 2821 2920 2790 2924 2880 3012 2870 2926 2817 2919 2927 2926 2845 2766 2839 2749 2806 2706 2845 2775 2737 2832 2862 2751 2723 2772 2831 2755 2845 2729 2782 2699 2768 2730 2864 2669 2697 2694 2800 2665 2643 2706 2746 2661 2666 2710 2715 2769 2656 2791 2743 2603 2706 2689 2714 2836 2694 2774 2823 2661 2763 2880 2815 2779 2854 2869 2834 2817 2835 2897 2846 2808 2858 2961 2824 2780 2896 2828 2878 2851 2793 2823 2930 2841 2821 2943 2927 2939 2980 3040 2995 3082 3019 3121 3093 3117 3297 3413 3423 3467 3305 3395 3280 3253 3193 3049 3026 3013 2887 2914 2895 2939 2881 2838 2780 2823 2831 2894 2978 2958 2919 3032 3038 2990 3055 2944 3005 2928 2916 2960 2912 2878 2856 2792 2773 2779 2682 2786 2723 2713 2740 2716 2700 2651 2771 2681 2688 2665 2721 2705 2757 2786 2751 2811 2829 2807 2864 2954 2865 2831 2842 3008 2990 3025 3123 2991 2965 2987 2923 2895 2944 3018 2933 2962 3005 2894 2950 2933 3003 2977 3000 2952 3075 2874 3002 2990 2978 3037 2988 2875 2976 2908 3069 2989 2977 2897 2918 2837 2915 2883 2867 2768 2867 2818 2879 2965 2889 2819 2900 2834 2898 2769 2851 2803 2793 2836 2797 2862 2814 2888 2927 2753 2836 2845 2771 2666 2772 2758 2767 2778 2746 2799 2721 2607 2632 2744 2753 2665 2683 2747 2628 2668 2800 2758 2693 2733 2798 2780 2688 2686 2699 2728 2752 2621 2637 2689 2719 2763 2711 2511 2679 2630 2717 2682 2717 2694 2645 2680 2735 2731 2700 2623 2719 2655 2712 2612 2692 2713 2811 2632 2670 2694 2704 2715 2694 2705 2634 2674 2723 2647 2693 2665 2643 2751 2818 2709 2745 2827 2770 2771 2775 2811 2931 2845 2811 2844 2893 2783 2774 2810 2857 2824 2821 2816 2895 2886 2816 2778 2806 2793 2817 2758 2705 2815 2878 2778 2769 2830 2824 2814 2783 2872 2777 2801 2778 2897 2849 2789 2784 2827 2969 2939 2974 2961 2944 2937 2858 2874 2873 2921 2847 2818 2693 2742 2841 2768 2757 2800 2840 2784 2795 2756 2828 2878 2825 2943 2812 2907 2967 2844 2943 2959 2941 2896 2876 2878 2835 2937 2916 2917 2942 2930 2836 2780 2775 2939 2895 2837 2855 2771 2810 2889 2822 2911 2935 2846 2804 2962 2849 2940 2945 2815 2994 2903 2893 2956 2984 2877 2910 2941 2847 2820 2928 3005 2914 2867 2916 2992 2926 2890 2875 2804 2870 2984 2924 2919 2902 3000 2934 2958 2977 3080 3056 2952 3048 3025 2973 3006 2941 3022 2973 3059 3048 3010 3083 3090 3072 3239 3128 3064 3124 3115 3059 3198 3140 3185 3172 3124 3191 3167 3267 3264 3368 3317 3417 3331 3306 3345 3342 3388 3225 3251 3203 3244 3223 3135 3175 3059 3070 3009 3103 3148 3103 3183 3157 3218 3193 3072 3172 3163 3206 3260 3127 3276 3276 3376 3353 3284 3434 3377 3368 3315 3286 3299 3196 3211 3203 3139 3127 3088 3175 3069 3125 3104 2915 3025 3049 2998 3173 3149 3068 2969 3112 3109 3150 3182 3143 3133 3164 3089 2996 3134 3024 3068 2939 3009 2947 3052 3010 3020 2865 2933 2911 2883 2932 2844 2771 2811 2892 2734 2948 2808 2844 2769 2668 2800 2695 2813 2807 2856 2750 2750 2821 2733 2669 2757 2765 2657 2736 2716 2632 2662 2680 2674 2644 2638 2751 2692 2702 2692 2768 2667 2757 2749 2761 2717 2710 2664 2599 2662 2797 2798 2686 2756 2718 2655 2686 2644 2719 2700 2730 2689 2725 2866 2676 2650 2673 2637 2759 2691 2796 2688 2625 2685 2658 2653 2692 2717 2607 2724 2635 2679 2717 2687 2676 2721 2712 2713 2725 2766 2763 2712 2738 2706 2811 2668 2790 2641 2619 2752 2709 2648 2635 2725 2669 2662 2702 2645 2801 2720 2686 2750 2690 2650 2688 2648 2702 2794 2743 2688 2831 2807 2777 2780 2854 2708 2757 2678 2788 2739 2810 2749 2789 2723 2721 2628 2638 2742 2752 2768 2704 2737 2692 2760 2645 2693 2710 2789 2744 2707 2759 2720 2644 2719 2859 2739 2730 2776 2821 2793 2757 2734 2767 2745 2901 2880 2828 2926 2968 2970 3045 2995 2952 2822 2798 2918 2871 2802 2781 2791 2820 2709 2698 2897 2639 2697 2697 2712 2688 2690 2762 2748 2813 2787 2729 2782 2711 2814 2855 2813 2675 2723 2646 2711 2698 2721 2664 2596 2680 2644 2629 2654 2704 2688 2655 2732 2593 2630 2647 2676 2699 2700 2620 2722 2637 2597 2614 2742 2679 2570 2636 2634 2645 2763 2587 2622 2701 2720 2613 2726 2741 2651 2712 2656 2700 2551 2704 2684 2612 2697 2673 2592 2738 2676 2748 2721 2671 2667 2638 2686 2732 2738 2667 2679 2692 2714 2672 2683 2769 2718 2645 2618 2640 2646 2642 2637 2709 2624 2696 2717 2743 2639 2649 2573 2631 2757 2755 2684 2643 2731 2704 2786 2635 2765 2565 2674 2564 2690 2656 2632 2666 2608 2720 2645 2653 2580 2677 2791 2645 2680 2735 2643 2685 2770 2710 2599 2633 2643 2669 2623 2683 2523 2660 2588 2804 2708 2742 2710 2687 2709 2652 2765 2823 2771 2758 2720 2782 2736 2792 2850 2858 2740 2851 2795 2823 2870 2839 2803 2782 2789 2797 2815 2886 2887 2900 2936 2879 2908 2932 2819 2939 2839 2924 2832 2790 2879 2862 2901 2858 2844 2833 2795 2810 2810 2880 2888 2872 2806 2820 2881 2879 2836 2872 2810 2757 2820 2871 2776 2820 2840 2802 2792 2823 2905 2801 2821 2824 2760 2751 2810 2808 2731 2789 2787 2882 2820 2883 2930 2949 2881 2973 3077 3004 3095 3055 3138 3058 3079 3140 2945 2938 2947 2943 3000 2947 2967 3045 3011 3005 3077 3168 3032 3048 3050 3101 3210 3099 3023 2987 3069 3081 3087 3107 3045 3117 2945 3049 2925 3031 3065 2998 2968 2969 2982 2866 2904 2924 2924 2909 3028 2917 2939 3010 2934 3049 3043 2915 2920 2949 2966 2851 2962 2945 2930 2888 2893 2923 2854 2973 2876 2879 2890 2866 2854 2926 2816 2878 2896 2849 2801 2828 2817 2893 2894 2784 2802 2783 2777 2898 2844 2825 2795 2762 2874 2795 2729 2861 2689 2746 2797 2853 2868 2761 2821 2796 2777 2825 2718 2744 2758 2793 2784 2843 2745 2850 2806 2805 2831 2916 2832 2894 2864 2982 3107 3122 3177 3124 3286 3236 3208 3273 3226 3147 3046 3060 2916 3019 2883 2815 2879 2751 2818 2839 2930 2829 2867 2920 2896 2873 2880 3042 3007 3052 3024 3042 3093 3153 3064 3190 3074 3078 3118 3085 3045 3014 2995 3000 3010 2971 2930 2950 2997 2975 2783 2894 2932 2810 2782 2781 2784 2901 2866 2867 2840 2853 2912 2840 2932 2895 2814 2904 2873 2872 2956 2992 2865 3010 2914 2923 3029 2930 2953 3028 2964 3008 2994 3025 3002 3049 2978 2889 2874 2951 2914 2881 2907 2943 2966 2970 2964 2831 2850 2990 3065 2930 2929 2913 2941 3033 3001 2994 3000 3097 3103 3027 3044 3066 3064 3070 3079 3062 2921 3029 3171 3155 3157 3195 3199 3202 3078 3252 3169 3260 3232 3215 3135 2998 2971 2923 2903 2884 3035 2917 2955 2897 2801 2855 2897 2874 2842 2768 2935 2888 2931 2856 2858 2843 2815 2871 2885 2965 2999 2956 2822 2826 2881 2772 2854 2838 2745 2851 2719 2737 2789 2768 2781 2646 2804 2695 2724 2802 2713 2664 2670 2739 2725 2684 2645 2620 2738 2720 2636 2728 2653 2634 2661 2659 2650 2739 2684 2723 2675 2867 2741 2751 2681 2778 2782 2818 2809 2682 2836 2783 2783 2767 2814 2892 2861 2868 2800 2751 2897 2928 2892 2788 2820 2740 2779 2767 2775 2697 2696 2812 2822 2740 2826 2826 2788 2797 2803 2825 2853 2847 2790 2788 2915 2851 2864 2837 2871 2842 2948 2925 2912 3015 2968 2908 2877 2925 2852 2982 2749 2960 2906 2805 2852 2782 2820 2707 2763 2895 2846 2900 2806 2761 2774 2837 2847 2827 2955 2869 2933 2935 2910 2903 2892 2941 3012 2910 2873 2891 2817 2903 2860 2870 2807 2863 2786 2922 2861 2937 2708 2707 2874 2807 2806 2794 2858 2778 2813 2886 2825 2819 2786 2825 2834 2912 2819 2826 2838 2872 2823 2814 2889 2763 2839 2882 2848 2843 2781 2885 2865 2809 2868 2922 2797 2928 2897 2900</counts>
			</dataPoints>
		</scan>
	</xrdMeasurement>
</xrdMeasurements>