File: dataset/precursor_mixture/Cr2O3_Fe3O4_Y2O3.2-min.xrdml
<?xml version="1.0"?>
<xrdMeasurements xmlns="http://www.xrdml.com/XRDMeasurement/2.2" xmlns:xsi="http://www.w3.org/2001/XMLSchema-instance" xsi:schemaLocation="http://www.xrdml.com/XRDMeasurement/2.2 http://www.xrdml.com/XRDMeasurement/2.2/XRDMeasurement.xsd" status="Completed" recordIdentifier="{85AC3617-DB64-440C-A25B-0BB87E7810D8}">
	<comment>
		<entry/>
	</comment>
	<sample type="To be analyzed">
		<id></id>
		<name></name>
		<preparedBy></preparedBy>
	</sample>
	<xrdMeasurement measurementType="Scan" status="Completed" sampleMode="Reflection">
		<usedWavelength intended="K-Alpha 1">
			<kAlpha1 unit="Angstrom">1.5405980</kAlpha1>
			<kAlpha2 unit="Angstrom">1.5444260</kAlpha2>
			<kBeta unit="Angstrom">1.3922500</kBeta>
			<ratioKAlpha2KAlpha1>0.5000</ratioKAlpha2KAlpha1>
		</usedWavelength>
		<incidentBeamPath>
			<radius unit="mm">145.00</radius>
			<xRayTube id="1010048" name="Empyrean Cu LFF HR (9430 033 7310x) DK437873">
				<tension unit="kV">40.0</tension>
				<current unit="mA">15.0</current>
				<anodeMaterial>Cu</anodeMaterial>
				<focus type="Line">
					<length unit="mm">12.0</length>
					<width unit="mm">0.4</width>
					<takeOffAngle unit="deg">6.0</takeOffAngle>
				</focus>
			</xRayTube>
			<filter id="20010004" name="Beta-filter Nickel">
				<material>Ni</material>
				<thickness unit="mm">0.020</thickness>
			</filter>
			<sollerSlit id="21010002" name="Soller slits 0.04 rad.">
				<opening unit="rad">0.0400</opening>
			</sollerSlit>
			<mask id="22031000" name="Fixed mask 13 mm">
				<width unit="mm">9.00</width>
			</mask>
			<divergenceSlit id="22120001" name="Divergence slit 1°" xsi:type="fixedDivergenceSlitType">
				<distanceToSample unit="mm">50.00</distanceToSample>
				<height unit="mm">1.52</height>
			</divergenceSlit>
		</incidentBeamPath>
		<beamKnife id="29030100" name="Beam knife low"/>
		<sampleMovement xsi:type="spinningSampleMovementType">
			<spinnerRevolutionTime unit="seconds">1.0</spinnerRevolutionTime>
		</sampleMovement>
		<diffractedBeamPath>
			<radius unit="mm">145.00</radius>
			<antiScatterSlit id="22090040" name="AS slit 9 mm" xsi:type="fixedAntiScatterSlitType">
				<height unit="mm">9.00</height>
			</antiScatterSlit>
			<sollerSlit id="21020003" name="Large Soller slits 0.04 rad.">
				<opening unit="rad">0.0400</opening>
			</sollerSlit>
			<filter id="20030001" name="Large beta-filter Nickel">
				<material>Ni</material>
				<thickness unit="mm">0.020</thickness>
			</filter>
			<detector id="7010019" name="PIXcel1D-Medipix3 detector" xsi:type="rtmsDetectorType">
				<phd unit="keV">
					<lowerLevel>4.0</lowerLevel>
					<upperLevel>11.3</upperLevel>
				</phd>
				<mode>Scanning</mode>
				<activeLength unit="deg">1.021</activeLength>
			</detector>
		</diffractedBeamPath>
		<scan appendNumber="0" mode="Continuous" scanAxis="Gonio" status="Completed">
			<header>
				<startTimeStamp>2024-03-22T20:51:27-07:00</startTimeStamp>
				<endTimeStamp>2024-03-22T20:53:49-07:00</endTimeStamp>
				<author>
					<name>Instrument</name>
				</author>
				<source>
					<applicationSoftware version="1.6 (94)">PANalytical Aeris Instrument Suite</applicationSoftware>
					<instrumentControlSoftware version="3.0.0 20211014">AERIS</instrumentControlSoftware>
					<instrumentID>2879380</instrumentID>
				</source>
			</header>
			<dataPoints>
				<positions axis="2Theta" unit="deg">
					<startPosition>10.02173288</startPosition>
					<endPosition>139.98435528</endPosition>
				</positions>
				<positions axis="Omega" unit="deg">
					<startPosition>5.01086644</startPosition>
					<endPosition>69.99217764</endPosition>
				</positions>
				<commonCountingTime unit="seconds">1.551</commonCountingTime>
				<counts unit="counts">501 528 534 477 490 481 527 523 524 500 495 529 502 483 503 505 514 473 501 473 443 568 466 516 521 472 437 520 470 472 467 508 497 487 453 509 514 442 449 486 456 516 455 504 482 479 484 435 444 439 446 471 454 472 490 432 441 448 426 425 456 463 460 435 464 441 420 514 424 446 441 458 418 481 432 443 460 458 428 419 386 459 399 456 444 453 420 428 456 445 415 467 465 462 419 418 451 439 441 428 421 416 430 434 432 434 413 459 415 467 409 416 394 412 444 420 415 388 389 397 430 406 382 420 464 444 395 408 418 414 430 434 377 438 412 412 380 437 452 420 398 390 415 396 468 413 442 419 416 401 441 433 390 381 397 410 443 430 439 393 390 413 430 455 398 442 406 394 437 426 420 409 410 411 419 394 386 449 401 430 378 414 402 415 460 414 470 474 445 480 384 391 350 420 415 444 489 417 423 413 393 454 470 358 403 411 411 403 399 407 440 448 412 424 422 422 402 444 421 413 437 386 400 465 427 457 411 408 415 442 473 449 468 483 555 572 583 530 446 441 431 456 451 429 423 443 420 397 413 404 422 419 409 425 396 455 431 408 408 402 386 426 435 405 429 429 396 442 402 408 390 405 365 417 379 410 406 403 417 394 425 437 377 434 418 413 392 403 384 409 402 377 408 413 397 403 402 420 446 411 369 420 424 418 367 422 416 378 444 408 444 407 444 365 404 379 448 434 393 388 436 462 470 531 563 729 777 638 527 459 413 406 420 420 423 414 402 392 405 371 370 401 424 431 392 399 427 415 407 389 382 417 388 422 392 379 423 422 417 434 408 425 374 403 364 417 437 378 401 423 398 410 421 408 393 408 408 418 403 391 411 417 381 427 385 389 477 400 387 401 453 366 375 397 390 406 416 395 428 373 408 422 419 407 407 422 408 430 412 373 439 465 411 393 484 426 417 437 425 427 467 471 477 493 583 502 656 763 1032 1620 2162 2032 1573 1061 761 592 515 457 430 454 450 422 448 435 416 422 455 426 415 486 563 634 674 614 537 430 438 411 443 399 459 437 463 387 411 380 460 448 410 403 433 367 386 404 376 373 404 376 421 427 357 410 453 375 403 386 411 388 405 408 379 395 417 388 395 373 421 386 408 380 385 428 418 385 376 376 399 415 397 399 392 360 415 388 379 403 389 398 422 425 406 402 407 441 435 450 464 466 512 689 930 989 865 879 829 768 718 600 531 468 445 405 438 408 420 390 413 447 403 422 390 410 391 400 426 406 397 414 423 403 395 416 394 404 444 403 385 526 509 620 888 1034 1166 1151 928 733 620 503 504 460 486 502 525 503 496 459 468 500 696 800 785 639 540 485 435 382 384 368 419 407 389 367 365 369 416 442 419 449 396 463 403 403 389 381 405 400 351 356 366 370 425 353 407 381 370 362 392 381 425 375 376 411 383 399 374 402 358 357 371 373 370 396 338 385 347 372 388 392 373 391 398 346 421 367 384 395 375 413 405 461 390 381 371 432 406 402 401 390 435 421 436 557 454 407 415 400 373 360 405 345 400 381 386 388 382 385 427 394 395 365 395 388 393 386 355 399 373 399 400 388 413 355 390 376 426 467 433 450 537 502 482 470 427 425 414 395 355 382 389 339 382 385 370 387 381 386 362 387 364 370 409 366 380 385 384 379 368 381 387 426 452 424 477 555 531 533 532 482 435 415 425 435 448 528 475 457 436 405 381 420 409 361 421 352 367 420 383 391 370 386 414 362 404 361 366 369 386 381 414 355 338 380 425 363 389 360 374 358 359 368 349 396 385 357 339 387 361 354 352 362 362 408 358 376 401 384 392 401 340 359 420 374 373 358 392 336 389 372 390 380 351 372 364 331 360 376 368 421 398 416 447 404 420 428 376 392 376 377 373 374 382 370 391 376 389 369 377 348 331 372 368 400 381 388 368 419 383 371 384 397 395 405 451 459 562 809 1032 998 807 787 702 513 469 413 391 430 417 396 401 357 409 415 375 341 387 393 383 391 379 372 339 387 359 384 379 374 393 373 413 407 394 495 467 473 541 589 445 491 478 459 381 429 372 384 373 394 355 385 362 366 320 368 374 383 402 335 379 375 417 381 392 407 355 340 360 395 395 383 345 365 410 354 334 387 366 393 371 399 386 392 347 342 369 377 374 378 369 384 391 326 382 376 370 333 374 383 377 369 398 392 439 454 507 434 415 427 481 466 423 434 401 399 389 377 372 386 335 362 388 349 383 367 357 399 409 394 385 383 360 370 355 383 395 410 391 432 461 563 672 749 638 550 585 529 446 418 362 379 351 366 358 412 382 380 426 377 366 323 383 380 359 413 372 337 392 377 396 415 426 464 432 445 432 453 396 363 360 409 394 354 419 413 443 459 458 556 540 509 502 510 487 493 433 446 429 418 421 432 503 587 720 821 699 629 578 587 497 482 440 399 418 396 370 357 391 404 412 386 403 384 405 396 402 350 382 405 403 354 424 353 374 435 420 464 421 432 375 436 380 354 349 351 396 365 399 367 389 390 373 354 368 386 396 388 375 387 348 354 373 376 397 395 336 401 461 406 397 401 406 372 411 347 391 358 361 358 392 355 359 384 355 396 391 363 336 378 337 366 392 399 385 382 372 361 382 404 401 396 390 388 380 388 409 403 393 432 377 400 429 469 500 577 565 605 582 543 531 470 472 440 424 401 357 381 387 372 397 368 408 364 424 459 471 500 396 468 440 414 399 392 362 394 360 386 344 326 352 396 406 350 337 377 345 370 376 369 417 388 405 376 371 401 350 369 371 383 417 445 439 532 493 440 421 436 437 435 408 381 342 397 390 355 370 387 382 392 373 389 373 373 363 382 384 346 390 352 365 363 372 390 373 357 347 325 367 359 349 382 367 364 380 356 352 363 372 372 393 370 335 371 348 342 368 362 388 340 359 339 327 341 374 335 365 384 344 390 359 366 382 331 346 378 384 366 353 390 356 383 375 382 343 362 368 365 392 367 392 383 353 382 341 304 383 363 349 347 352 344 364 355 350 349 373 368 361 365 336 368 414 376 352 364 397 417 349 388 322 341 357 378 352 374 367 359 357 346 395 379 332 394 375 391 388 425 417 406 390 394 415 396 326 373 387 365 352 340 359 359 401 378 381 371 394 379 357 387 399 357 422 378 419 400 407 429 343 410 392 426 418 377 386 437 404 356 398 379 396 406 395 401 431 331 388 345 366 373 348 332 358 407 409 399 397 393 403 410 375 388 395 381 383 373 389 375 358 365 400 401 382 356 384 360 318 366 375 389 392 384 359 383 395 405 379 429 400 399 415 354 359 378 391 384 360 328 337 386 321 347 355 365 359 385 383 378 355 335 401 405 340 352 363 373 371 343 337 354 363 392 378 373 384 389 368 368 414 392 414 380 369 418 398 355 342 375 429 410 434 383 399 416 368 395 388 368 376 323 377 357 337 343 340 348 338 342 357 370 339 364 371 373 372 417 459 457 402 373 412 421 439 406 401 384 373 410 387 352 383 391 382 411 374 352 358 349 355 363 378 340 333 383 353 380 346 347 380 375 383 365 372 339 360 351 351 351 330 376 350 347 359 349 373 434 383 351 403 394 397 410 409 407 385 396 385 370 349 375 378 360 360 336 363 348 346 359 383 378 366 410 369 363 374 364 348 395 368 363 323 355 397 354 361 332 335 341 362 353 331 347 373 411 349 357 336 356 340 350 347 346 398 359 342 367 371 355 406 369 353 349 373 357 353 327 373 371 373 362 368 373 390 412 361 365 392 383 379 382 417 401 363 341 389 382 371 368 374 357 372 364 352 367 401 354 346 353 381 351 362 334 340 361 351 364 349 341 356 324 367 338 394 368 381 366 339 387 399 354 352 379 340 378 371 401 375 379 417 376 377 370 370 374 383 380 361 386 369 368 387 348 395 410 385 361 344 359 384 371 375 373 372 380 360 365 320 306 388 349 340 313 398 353 373 334 365 377 336 362 360 368 373 328 345 338 341 368 365 366 383 345 360 343 329 346 365 354 366 397 377 382 454 387 444 384 435 401 415 412 374 414 413 365 408 388 397 392 408 382 406 404 371 411 392 396 416 427 341 433 430 413 378 372 374 373 375 394 404 359 376 386 377 347 374 344 315 349 367 373 383 354 354 334 410 387 384 435 436 425 378 369 341 348 433 376 333 369 300 353 349 361 381 365 416 355 351 341 346 349 355 321 367 357 362 327 350 384 378 378 393 365 371 370 355 377 354 350 318 359 389 363 369 335 379 350 350 392 366 367 377 401 375 406 377 363 340 368 345 372 388 398 357 369 358 369 377 374 361 336 343 401 404 431 375 408 372 384 420 426 417 392 354 404 367 370 383 374 384 354 381 357 347 325 350 362 364 367 381 412 389 370 363 357 379 379 299 394 392 399 371 354 406 327 386 397 372 403 378 359 370 403 355 370 357 368 370 360 344 369 375 370 356 373 460 380 402 363 396 386 381 402 381 399 358 382 373 355 329 376 393 356 343 357 356 373 393 325 345 356 379 405 373 394 407 366 360 379 369 412 354 386 341 358 377 362 347 359 381 333 359 356 339 400 370 359 343 357 351 344 383 389 341 383 359 369 322 365 343 336 398 336 387 352 327 359 376 334 343 338 358 352 374 350 352 378 383 410 401 382 361 344 377 359 344 387 362 384 349 384 375 388 369 344 338 348 383 363 349 355 377 388 362 362 392 363 378 344 374 345 348 386 406 379 399 406 369 362 339 372 357 378 353 385 353 342 345 408 338 346 383 342 362 416 406 361 381 367 371 349 389 368 343 371 350 371 371 352 368 384 375 383 376 370 380 371 395 418 405 428 455 429 355 410 397 346 377 407 404 393 383 374 369 377 375 375 374 362 365 388 351 377 362 332 409 362 391 385 411 397 347 394 358 348 387 364 380 358 387 378 346 404 365 351 351 345 363 407 325 337 314 349 365 325 340 371 364 361 325 373 338 392 366 350 366 377 323 405 357 324 392 342 359 328 364 410 368 385 376 377 353 386 366 398 391 393 411 359 392 360 367 335 399 380 330 397 385 374 372 334 400 366 377 354 389 372 403 406 353 371 360 359 342 408 412 376 405 406 435 387 364 360 369 382 356 389 392 386 345 361 362 373 379 351 361 332 384 364 347 343 356 387 341 357 353 352 350 349 334 354 355 352 371 375 386 351 329 384 361 369 354 365 338 372 377 361 377 351 347 368 344 395 381 376 388 324 399 327 344 353 351 383 387 356 339 353 333 344 342 332 323 326 395 321 346 353 346 373 372 369 354 355 362 396 371 339 362 355 380 373 347 362 365 356 375 334 364 353 352 362 382 367 332 368 378 365 328 396 387 375 351 348 356 361 373 334 343 371 357 388 349 383 366 374 382 401 398 374 374 360 340 330 348 396 377 369 368 348 389 384 376 355 325 374 375 362 387 336 387 363 391 357 384 355 359 377 346 379 381 337 336 348 344 381 386 361 323 367 355 369 357 415 384 391 435 414 411 370 418 366 357 339 372 378 385 426 386 361 395 387 357 347 352 373 357 369 369 346 365 380 376 391 380 367 390 381 392 350 369 364 380 359 364 401 366 369 342 328 359 358 369 359 361 366 358 387 398 405 359 343 347 360 382 388 381 397 377 327 395 412 346 327 376 318 382 364 331 399 375 405 357 391 367 331 399 372 404 380 374 395 379 381 381 395 392 375 364 396 387 422 414 405 370 391 377 372 403 374 380 406 399 372 359 358 386 371 335 383 376 382 363 378 339 372 363 347 365 369 345 328 361 382 373 374 339 367 356 377 355 346 374 349 375 376 367 364 351 370 358 355 403 358 349 360 355 384 355 345 385 357 380 351 403 340 415 413 413 418 347 364 362 383 363 381 377 363 332 379 398 393 414 418 423 405 386 394 352 359 348 339 306 327 376 340 404 350 350 400 381 376 379 364 349 378 370 402 366 342 381 383 397 387 406 382 381 369 420 391 356 378 371 381 417 420 381 406 396 434 399 392 397 378 374 398 377 368 362 380 370 385 354 366 387 360 378 414 377 365 352 382 377 360 382 367 384 337 326 358 332 381 354 350 357 338 343 363 394 388 348 341 368 382 404 376 420 367 362 326 345 388 370 335 342 369 360 343 373 401 359 376 360 359 352 366 354 370 350 350 354 396 347 359 356 400 356 391 400 379 368 366 402 362 386 392 360 354 394 373 381 341 383 360 376 379 369 366 391 358 376 349 367 357 377 357 354 348 352 376 377 384 396 396 391 380 380 412 344 380 345 416 365 374 372 393 385 396 386 371 355 379 376 415 358 376 378 366 400 425 355 366 387 357 342 364 379 395 415 375 417 386 368 374 373 381 401 372 357 395 366 349 375 394 364 383 406 426 336 364 400 381 377 347 344 340 327 374 384 358 370 378 337 383 359 390 383 399 374 405 385 398 417 370 384 377 373 411 359 385 380 364 385 369 418 393 375 398 395 369 412 385 395 355 387 364 352 376 335 337 420 389 384 375 372 392 396 402 404 379 379 395 383 409 348 384 367 399 372 367 357 342 388 376 381 396 402 413 399 400 364 432 323 385 385 358 337 357 346 346 382 379 351 356 364 407 378 389 374 350 327 389 372 344 407 347 378 356 389 390 401 362 364 373 396 384 372 403 370 377 381 413 388 357 371 377 381 365 372 385 387 406 402 374 366 367 404 383 381 363 386 394 382 375 370 369 347 384 353 398 416 367 393 336 377 390 364</counts>
			</dataPoints>
		</scan>
	</xrdMeasurement>
</xrdMeasurements>