File: dataset/precursor_mixture/Cr2O3_Fe3O4_HfO2_In2O3.2-min.xrdml
<?xml version="1.0"?>
<xrdMeasurements xmlns="http://www.xrdml.com/XRDMeasurement/2.2" xmlns:xsi="http://www.w3.org/2001/XMLSchema-instance" xsi:schemaLocation="http://www.xrdml.com/XRDMeasurement/2.2 http://www.xrdml.com/XRDMeasurement/2.2/XRDMeasurement.xsd" status="Completed" recordIdentifier="{03195F1C-CFCE-4502-ACA2-E7A20C2C7105}">
	<comment>
		<entry/>
	</comment>
	<sample type="To be analyzed">
		<id>dara-19-1</id>
		<name></name>
		<preparedBy></preparedBy>
	</sample>
	<xrdMeasurement measurementType="Scan" status="Completed" sampleMode="Reflection">
		<usedWavelength intended="K-Alpha 1">
			<kAlpha1 unit="Angstrom">1.5405980</kAlpha1>
			<kAlpha2 unit="Angstrom">1.5444260</kAlpha2>
			<kBeta unit="Angstrom">1.3922500</kBeta>
			<ratioKAlpha2KAlpha1>0.5000</ratioKAlpha2KAlpha1>
		</usedWavelength>
		<incidentBeamPath>
			<radius unit="mm">145.00</radius>
			<xRayTube id="1010048" name="Empyrean Cu LFF HR (9430 033 7310x) DK437873">
				<tension unit="kV">40.0</tension>
				<current unit="mA">15.0</current>
				<anodeMaterial>Cu</anodeMaterial>
				<focus type="Line">
					<length unit="mm">12.0</length>
					<width unit="mm">0.4</width>
					<takeOffAngle unit="deg">6.0</takeOffAngle>
				</focus>
			</xRayTube>
			<filter id="20010004" name="Beta-filter Nickel">
				<material>Ni</material>
				<thickness unit="mm">0.020</thickness>
			</filter>
			<sollerSlit id="21010002" name="Soller slits 0.04 rad.">
				<opening unit="rad">0.0400</opening>
			</sollerSlit>
			<mask id="22031000" name="Fixed mask 13 mm">
				<width unit="mm">9.00</width>
			</mask>
			<divergenceSlit id="22120001" name="Divergence slit 1°" xsi:type="fixedDivergenceSlitType">
				<distanceToSample unit="mm">50.00</distanceToSample>
				<height unit="mm">1.52</height>
			</divergenceSlit>
		</incidentBeamPath>
		<beamKnife id="29030100" name="Beam knife low"/>
		<sampleMovement xsi:type="spinningSampleMovementType">
			<spinnerRevolutionTime unit="seconds">1.0</spinnerRevolutionTime>
		</sampleMovement>
		<diffractedBeamPath>
			<radius unit="mm">145.00</radius>
			<antiScatterSlit id="22090040" name="AS slit 9 mm" xsi:type="fixedAntiScatterSlitType">
				<height unit="mm">9.00</height>
			</antiScatterSlit>
			<sollerSlit id="21020003" name="Large Soller slits 0.04 rad.">
				<opening unit="rad">0.0400</opening>
			</sollerSlit>
			<filter id="20030001" name="Large beta-filter Nickel">
				<material>Ni</material>
				<thickness unit="mm">0.020</thickness>
			</filter>
			<detector id="7010019" name="PIXcel1D-Medipix3 detector" xsi:type="rtmsDetectorType">
				<phd unit="keV">
					<lowerLevel>4.0</lowerLevel>
					<upperLevel>11.3</upperLevel>
				</phd>
				<mode>Scanning</mode>
				<activeLength unit="deg">1.021</activeLength>
			</detector>
		</diffractedBeamPath>
		<scan appendNumber="0" mode="Continuous" scanAxis="Gonio" status="Completed">
			<header>
				<startTimeStamp>2024-03-24T16:07:55-07:00</startTimeStamp>
				<endTimeStamp>2024-03-24T16:10:17-07:00</endTimeStamp>
				<author>
					<name>AutomatedUser</name>
				</author>
				<source>
					<applicationSoftware version="1.6 (94)">PANalytical Aeris Instrument Suite</applicationSoftware>
					<instrumentControlSoftware version="3.0.0 20211014">AERIS</instrumentControlSoftware>
					<instrumentID>2879380</instrumentID>
				</source>
			</header>
			<dataPoints>
				<positions axis="2Theta" unit="deg">
					<startPosition>10.02173288</startPosition>
					<endPosition>139.98435528</endPosition>
				</positions>
				<positions axis="Omega" unit="deg">
					<startPosition>5.01086644</startPosition>
					<endPosition>69.99217764</endPosition>
				</positions>
				<commonCountingTime unit="seconds">1.551</commonCountingTime>
				<counts unit="counts">481 465 469 498 511 467 428 502 438 473 471 495 427 450 469 476 453 465 476 451 474 488 447 407 472 466 446 458 454 416 425 434 463 427 435 416 413 443 438 466 431 420 424 440 412 384 429 417 423 400 376 395 399 388 433 399 394 396 380 382 391 383 384 384 375 399 420 384 378 376 362 364 378 402 381 338 373 332 345 344 357 299 336 380 367 359 350 342 379 344 363 359 326 367 350 350 398 360 340 377 354 363 330 345 350 376 319 328 371 367 355 335 337 346 332 351 321 364 354 334 314 365 349 332 338 344 342 339 340 332 357 351 351 340 364 323 352 323 311 357 327 312 327 316 353 311 328 321 323 293 297 308 328 316 320 312 351 306 309 313 329 306 350 329 345 335 338 355 352 376 348 393 339 327 322 322 319 363 338 323 329 323 297 346 298 367 343 381 370 321 344 344 332 340 324 281 311 366 336 331 347 344 309 318 296 334 309 307 330 340 323 314 322 267 298 312 320 285 321 297 325 318 344 319 278 293 326 318 313 334 315 324 334 302 337 327 330 301 298 298 294 307 327 297 308 327 288 306 313 314 334 324 306 305 329 327 325 325 369 384 425 383 338 314 302 290 316 289 298 297 320 345 263 306 309 321 303 317 282 311 310 265 275 271 293 279 320 314 298 263 294 264 305 325 285 257 302 308 303 299 319 297 305 330 311 293 299 282 313 270 293 283 290 337 340 333 318 346 370 423 433 457 425 386 389 444 544 635 646 532 479 430 367 335 275 287 299 298 280 326 272 282 304 281 269 281 282 299 292 304 317 311 301 251 286 259 298 295 303 263 301 305 279 296 311 270 304 290 283 269 306 304 278 282 288 291 284 282 299 277 266 269 298 276 274 276 273 299 259 294 270 302 310 285 295 282 324 310 300 299 275 297 277 337 315 333 348 340 398 452 545 637 877 1148 1110 1007 884 616 478 421 383 354 356 331 324 307 294 301 287 261 326 248 254 274 285 301 309 307 312 258 279 300 295 267 264 316 301 300 281 334 316 372 437 457 461 371 351 371 315 377 421 466 673 1037 1645 1310 948 593 434 336 308 307 332 328 337 316 320 304 311 332 327 331 336 369 430 487 634 774 984 907 807 656 486 423 372 342 333 328 305 294 286 284 282 294 265 235 271 292 303 262 280 224 233 251 264 270 278 263 298 282 269 324 282 264 300 292 275 267 317 339 404 511 740 593 555 389 350 325 278 310 252 261 302 305 321 365 364 454 472 553 476 418 404 449 462 448 466 401 384 307 280 309 281 316 312 321 273 298 317 349 425 587 864 1196 1403 1166 1035 694 566 403 325 346 384 335 345 314 332 369 414 509 614 587 483 504 319 288 288 270 265 275 261 298 284 242 259 249 287 293 272 276 293 292 267 265 314 266 247 259 274 217 237 280 298 290 335 298 306 277 280 247 255 231 270 253 259 266 268 269 253 273 256 268 270 249 238 248 294 299 307 336 359 338 313 292 272 274 250 261 252 251 263 267 250 254 269 259 250 256 252 251 261 323 299 277 275 231 258 268 241 256 259 277 251 269 247 253 259 279 260 239 242 262 249 270 259 304 313 328 363 362 326 334 315 308 266 270 312 332 354 397 384 350 332 319 294 310 285 353 326 265 312 282 240 246 259 211 268 239 297 231 241 247 278 255 288 233 264 233 253 263 256 254 273 282 352 343 361 367 302 286 261 277 284 255 259 257 268 249 262 262 267 266 250 246 266 235 233 219 242 260 250 255 269 249 256 237 235 244 262 255 256 238 249 245 213 218 249 274 262 239 286 277 294 279 250 242 240 223 246 264 220 268 303 352 363 378 371 375 331 258 277 233 263 245 228 229 235 242 219 219 227 254 246 219 224 288 250 238 234 245 244 256 264 220 230 251 241 247 211 231 239 214 252 248 268 247 253 239 237 241 221 256 226 235 226 265 225 266 239 221 244 264 213 208 232 234 248 234 235 210 244 235 230 231 231 193 233 241 236 275 267 278 257 258 284 301 300 294 282 359 353 389 389 368 349 323 253 272 276 255 259 262 256 265 303 322 406 361 378 400 465 490 424 414 388 360 312 307 275 344 351 375 471 650 837 586 469 532 400 339 284 269 284 280 319 306 256 260 247 321 244 255 222 249 242 269 197 204 247 243 242 233 229 221 271 258 234 258 231 251 277 277 267 248 241 226 248 226 226 266 211 247 244 261 244 243 250 271 264 314 290 259 268 277 258 248 264 230 215 224 257 222 234 231 270 263 249 270 285 308 326 349 318 306 326 321 277 286 353 465 566 496 421 440 436 325 307 282 278 269 287 261 268 276 253 253 296 333 314 372 347 346 372 338 353 388 365 331 338 367 298 309 304 335 309 295 300 250 286 253 281 249 236 256 281 275 330 364 351 384 380 360 326 302 291 286 227 280 269 301 307 316 282 300 285 299 248 244 252 230 236 250 266 236 237 260 277 263 310 316 296 304 312 305 273 271 262 302 280 261 252 227 273 232 215 297 305 316 260 257 259 210 249 269 256 232 249 219 252 249 264 211 234 227 232 253 265 262 241 300 342 303 326 297 314 316 293 322 319 361 516 618 448 356 436 464 320 277 269 259 250 243 240 241 254 260 246 217 271 276 269 263 270 249 264 308 321 298 268 264 270 272 268 306 270 341 324 363 338 361 346 404 416 424 436 393 367 370 306 313 275 300 295 254 292 273 267 253 295 307 309 304 334 337 374 351 313 319 369 320 299 271 266 253 259 248 265 214 238 207 246 202 230 231 263 275 251 250 255 238 267 256 252 280 277 280 246 285 293 307 319 376 351 303 271 295 297 297 259 246 217 226 248 258 255 264 237 277 252 299 236 284 254 274 293 317 307 250 299 255 264 275 255 266 243 281 271 270 257 250 236 222 231 240 224 247 248 239 201 232 226 262 234 230 205 251 231 225 235 231 224 263 242 230 211 264 252 240 252 222 248 234 247 221 211 254 221 243 236 230 211 210 223 214 212 223 260 222 244 225 243 252 219 229 238 238 229 248 272 251 226 247 252 250 252 209 242 211 234 217 246 255 244 245 252 223 245 241 231 263 210 226 244 233 230 253 246 220 246 224 223 203 241 235 246 204 246 247 229 233 247 249 240 273 299 236 247 292 220 256 250 265 264 253 241 253 232 256 260 226 213 253 288 246 223 239 247 244 283 258 241 243 255 258 247 253 287 272 242 260 274 257 263 274 271 248 230 243 246 244 235 234 256 260 276 254 227 253 250 234 249 253 238 257 266 207 259 246 243 222 222 215 223 228 227 232 220 237 254 213 233 231 256 249 304 304 238 267 256 285 258 250 213 246 247 223 245 280 266 240 258 250 255 217 217 215 193 260 236 268 230 235 232 261 260 303 257 233 230 236 270 268 224 277 252 268 286 261 275 282 269 250 244 246 223 227 268 246 213 244 206 232 221 228 258 273 255 239 255 256 247 240 270 232 249 216 237 222 225 235 238 231 212 229 245 248 229 246 247 258 255 248 258 242 281 283 282 295 272 281 237 232 251 240 247 223 257 235 220 193 240 238 234 209 246 225 235 204 207 240 218 242 237 208 245 229 241 213 249 222 205 254 256 263 228 250 229 216 221 228 217 227 208 226 199 224 203 227 228 222 222 201 249 258 212 241 268 269 288 282 225 260 270 291 256 267 255 290 246 225 219 245 232 235 233 240 248 195 232 243 227 211 260 249 229 269 265 344 308 267 242 254 278 288 269 244 283 252 224 234 239 254 243 234 228 243 264 240 250 260 239 243 258 249 256 268 254 253 267 249 279 248 276 256 208 244 211 234 247 232 230 243 255 231 194 270 208 247 257 223 251 257 238 218 237 244 277 302 281 251 250 244 256 289 271 235 226 220 243 226 216 245 263 236 265 240 240 234 269 270 265 216 260 222 253 243 233 262 216 231 260 215 244 232 261 222 213 222 222 238 232 230 204 224 264 213 238 254 245 250 242 214 218 241 240 223 237 277 260 286 267 224 218 288 260 247 245 251 265 246 249 283 266 270 263 236 245 256 239 239 277 259 280 264 269 280 293 291 308 293 292 295 248 255 266 281 264 275 226 272 273 259 296 246 243 246 273 251 258 218 244 238 229 244 267 221 227 220 228 249 208 270 252 253 215 239 200 215 231 219 245 234 233 265 242 269 220 235 204 251 206 210 209 222 238 230 290 219 232 205 220 222 208 283 242 218 229 223 225 228 241 228 239 236 220 235 233 226 210 236 233 239 222 241 212 213 225 208 210 210 232 253 230 248 206 219 253 224 215 248 226 236 268 243 239 222 261 243 269 214 255 216 233 239 257 239 246 286 251 258 219 255 257 272 245 258 262 246 244 252 236 198 260 233 273 268 235 222 217 222 275 229 240 245 237 252 301 267 251 233 256 221 243 262 271 277 243 261 256 243 228 239 261 249 275 272 268 235 208 252 269 252 245 247 245 279 262 284 284 268 231 244 252 256 233 240 222 261 218 205 234 224 238 231 226 208 256 245 252 226 239 243 210 230 241 230 233 248 253 261 230 216 260 244 248 256 239 227 227 230 251 254 244 247 205 241 257 268 224 263 286 240 258 260 223 258 260 267 245 231 234 239 229 221 207 243 228 257 243 238 244 229 237 257 256 267 249 214 223 230 269 244 228 255 254 266 260 271 268 245 249 246 228 247 254 243 280 266 225 235 265 278 247 253 248 243 248 247 248 236 253 238 221 210 203 249 227 230 253 238 211 237 191 227 226 218 232 235 239 235 268 236 236 243 209 224 220 242 244 211 243 261 226 238 215 231 266 235 283 289 271 234 245 234 233 243 267 265 248 251 254 259 221 248 266 251 239 264 219 256 236 284 280 212 218 249 244 253 230 258 249 272 257 252 215 258 210 234 242 224 234 247 236 224 237 224 239 237 236 221 224 213 228 210 258 219 242 244 236 248 235 249 225 249 249 269 203 204 213 257 221 235 244 248 250 225 235 245 233 232 214 229 217 249 261 254 242 216 247 249 248 240 266 250 240 245 233 261 259 279 235 273 241 254 256 296 257 266 237 234 212 223 219 237 245 214 251 248 248 234 245 259 232 273 300 259 250 242 234 229 287 240 315 263 248 256 252 269 297 249 230 266 273 265 227 219 250 262 261 259 277 236 262 238 231 261 262 253 230 220 236 262 244 263 245 265 251 257 243 262 250 244 223 241 223 246 228 255 231 250 216 204 246 207 231 252 234 264 237 240 257 258 224 265 220 208 239 207 260 256 224 245 244 254 209 215 224 214 253 233 248 230 225 226 244 217 231 253 258 262 232 251 242 247 254 213 227 249 202 227 211 267 211 206 223 217 242 222 246 235 249 234 219 215 244 244 219 227 254 238 221 248 243 233 239 219 246 218 224 222 220 212 229 234 218 239 213 236 211 223 229 203 234 225 205 233 232 202 247 206 249 246 235 207 246 227 258 253 263 237 236 227 258 259 235 256 235 264 252 248 227 250 210 221 242 238 232 246 238 242 208 244 215 250 236 259 286 245 239 251 254 265 258 236 267 269 252 216 245 246 258 255 237 241 237 255 263 251 236 213 251 239 245 240 240 221 233 240 222 216 268 234 278 252 237 200 232 266 251 253 240 240 251 233 244 241 233 235 223 217 249 219 255 232 240 249 230 252 249 255 224 216 247 241 274 250 259 254 285 289 252 260 248 260 244 265 258 276 218 239 269 282 261 254 247 253 232 257 220 243 229 236 248 226 237 237 257 234 232 247 242 230 218 240 250 257 261 248 288 272 256 219 234 234 244 233 250 248 244 250 248 215 231 243 241 237 237 203 223 204 229 259 221 228 250 251 241 268 217 251 259 255 237 249 248 248 241 242 223 257 251 260 240 293 268 252 274 271 242 278 265 247 218 246 256 245 277 219 246 223 247 225 261 226 260 247 243 244 269 280 258 225 260 236 245 251 245 218 237 238 287 235 244 244 255 237 274 249 231 222 248 264 251 271 257 269 269 239 245 291 250 247 266 273 240 257 266 299 271 278 241 273 253 238 237 247 268 249 260 242 236 251 264 245 234 260 240 241 231 275 260 228 253 256 228 206 255 238 209 236 223 224 235 260 238 245 239 236 250 253 224 237 222 257 227 222 235 231 242 249 229 215 241 242 213 213 249 236 233 227 232 235 216 242 208 221 225 263 200 258 232 259 235 231 252 239 252 244 232 275 290 278 266 277 249 238 246 252 236 241 264 257 285 286 261 260 232 243 234 247 224 246 240 249 245 251 234 236 251 247 221 245 234 267 260 278 286 245 245 230 252 236 237 255 258 223 257 230 236 268 281 269 277 249 241 264 262 255 252 249 271 252 259 264 252 240 250 266 276 215 263 245 247 262 255 257 255 257 235 247 285 243 250 241 262 232 236 266 236 252 234 232 255 254 269 253 226 256 245 228 261 187 232 235 227 241 236 254 247 238 234 224 241 235 223 239 274 263 232 260 289 249 258 247 259 277 268 230 229 206 252 236 255 207 224 263 248 280 250 253 256 250 261 251 277 258 269 229 268 230 247 227 229 253 278 236 264 246 214 222 231 268 267 244 251 257 272 300 266 286 243 235 260 243 264 227 232 282 231 256 233 233 267 227 282 237 255 253 254 239 244 255 232 258 273 270 244 259 272 206 246 241 253 261 239 263 298 257 253 213 239 246 238 250 248 243 243 238 269 224 246 258 262 238 229 262 234 266 229 238 239 241 267 253 241 245 255 228 235 248 231</counts>
			</dataPoints>
		</scan>
	</xrdMeasurement>
</xrdMeasurements>