File: dataset/precursor_mixture/Cr2O3_Li2TiO3_LiCoO2_K2SO4.12-min.xrdml
<?xml version="1.0"?>
<xrdMeasurements xmlns="http://www.xrdml.com/XRDMeasurement/2.2" xmlns:xsi="http://www.w3.org/2001/XMLSchema-instance" xsi:schemaLocation="http://www.xrdml.com/XRDMeasurement/2.2 http://www.xrdml.com/XRDMeasurement/2.2/XRDMeasurement.xsd" status="Completed" recordIdentifier="{3AF95C3C-CBA5-4E75-8C86-E76627950B72}">
	<comment>
		<entry/>
	</comment>
	<sample type="To be analyzed">
		<id>dara-44-2</id>
		<name></name>
		<preparedBy></preparedBy>
	</sample>
	<xrdMeasurement measurementType="Scan" status="Completed" sampleMode="Reflection">
		<usedWavelength intended="K-Alpha 1">
			<kAlpha1 unit="Angstrom">1.5405980</kAlpha1>
			<kAlpha2 unit="Angstrom">1.5444260</kAlpha2>
			<kBeta unit="Angstrom">1.3922500</kBeta>
			<ratioKAlpha2KAlpha1>0.5000</ratioKAlpha2KAlpha1>
		</usedWavelength>
		<incidentBeamPath>
			<radius unit="mm">145.00</radius>
			<xRayTube id="1010048" name="Empyrean Cu LFF HR (9430 033 7310x) DK437873">
				<tension unit="kV">40.0</tension>
				<current unit="mA">15.0</current>
				<anodeMaterial>Cu</anodeMaterial>
				<focus type="Line">
					<length unit="mm">12.0</length>
					<width unit="mm">0.4</width>
					<takeOffAngle unit="deg">6.0</takeOffAngle>
				</focus>
			</xRayTube>
			<filter id="20010004" name="Beta-filter Nickel">
				<material>Ni</material>
				<thickness unit="mm">0.020</thickness>
			</filter>
			<sollerSlit id="21010002" name="Soller slits 0.04 rad.">
				<opening unit="rad">0.0400</opening>
			</sollerSlit>
			<mask id="22031000" name="Fixed mask 13 mm">
				<width unit="mm">9.00</width>
			</mask>
			<divergenceSlit id="22120001" name="Divergence slit 1°" xsi:type="fixedDivergenceSlitType">
				<distanceToSample unit="mm">50.00</distanceToSample>
				<height unit="mm">1.52</height>
			</divergenceSlit>
		</incidentBeamPath>
		<beamKnife id="29030100" name="Beam knife low"/>
		<sampleMovement xsi:type="spinningSampleMovementType">
			<spinnerRevolutionTime unit="seconds">1.0</spinnerRevolutionTime>
		</sampleMovement>
		<diffractedBeamPath>
			<radius unit="mm">145.00</radius>
			<antiScatterSlit id="22090040" name="AS slit 9 mm" xsi:type="fixedAntiScatterSlitType">
				<height unit="mm">9.00</height>
			</antiScatterSlit>
			<sollerSlit id="21020003" name="Large Soller slits 0.04 rad.">
				<opening unit="rad">0.0400</opening>
			</sollerSlit>
			<filter id="20030001" name="Large beta-filter Nickel">
				<material>Ni</material>
				<thickness unit="mm">0.020</thickness>
			</filter>
			<detector id="7010019" name="PIXcel1D-Medipix3 detector" xsi:type="rtmsDetectorType">
				<phd unit="keV">
					<lowerLevel>4.0</lowerLevel>
					<upperLevel>11.3</upperLevel>
				</phd>
				<mode>Scanning</mode>
				<activeLength unit="deg">5.020</activeLength>
			</detector>
		</diffractedBeamPath>
		<scan appendNumber="0" mode="Continuous" scanAxis="Gonio" status="Completed">
			<header>
				<startTimeStamp>2024-03-24T15:05:25-07:00</startTimeStamp>
				<endTimeStamp>2024-03-24T15:17:53-07:00</endTimeStamp>
				<author>
					<name>AutomatedUser</name>
				</author>
				<source>
					<applicationSoftware version="1.6 (94)">PANalytical Aeris Instrument Suite</applicationSoftware>
					<instrumentControlSoftware version="3.0.0 20211014">AERIS</instrumentControlSoftware>
					<instrumentID>2879380</instrumentID>
				</source>
			</header>
			<dataPoints>
				<positions axis="2Theta" unit="deg">
					<startPosition>9.99043322</startPosition>
					<endPosition>100.09495370</endPosition>
				</positions>
				<positions axis="Omega" unit="deg">
					<startPosition>4.99521661</startPosition>
					<endPosition>50.04747685</endPosition>
				</positions>
				<commonCountingTime unit="seconds">18.249</commonCountingTime>
				<counts unit="counts">6603 6546 6576 6594 6450 6580 6579 6584 6570 6514 6541 6567 6610 6542 6493 6567 6692 6464 6450 6470 6430 6407 6396 6524 6486 6329 6690 6540 6495 6526 6647 6480 6619 6496 6560 6589 6433 6458 6526 6326 6517 6400 6522 6655 6373 6643 6443 6513 6493 6557 6458 6417 6579 6603 6458 6447 6400 6486 6506 6402 6437 6211 6348 6411 6503 6563 6503 6573 6519 6463 6393 6445 6249 6372 6410 6570 6528 6390 6460 6496 6430 6329 6308 6499 6482 6520 6375 6357 6432 6420 6406 6369 6320 6306 6417 6315 6417 6478 6380 6447 6458 6316 6441 6359 6407 6244 6453 6371 6415 6356 6365 6280 6281 6362 6429 6348 6322 6321 6432 6307 6274 6335 6335 6447 6409 6399 6190 6547 6309 6426 6294 6261 6360 6364 6315 6345 6329 6307 6397 6312 6167 6293 6380 6415 6256 6452 6205 6227 6497 6297 6302 6139 6261 6295 6293 6294 6239 6293 6289 6258 6303 6343 6212 6283 6148 6233 6275 6395 6368 6341 6433 6256 6336 6433 6192 6251 6271 6326 6264 6202 6193 6116 6307 6258 6332 6154 6362 6253 6225 6219 6283 6097 6228 6282 6205 6219 6406 6291 6180 6275 6249 6172 6140 6256 6274 6251 6278 6239 6174 6206 6039 6077 6269 6339 6348 6157 6137 6196 6229 6130 6344 6243 6258 6106 6255 5995 6186 6156 6233 6267 6242 6226 6268 6240 6202 6162 6189 6093 6232 6129 6155 6216 6081 6268 6227 6201 6018 6306 6241 6260 6181 6058 6140 6142 6159 6149 6251 6201 6228 6220 6128 6109 6058 6123 6034 6088 6174 6256 6233 6238 6312 6291 6255 6119 6311 6201 6092 6147 6172 6150 6027 6251 6417 6290 6129 6230 6265 6258 6055 6073 5978 6079 6208 6175 6162 6277 6008 6150 6256 6172 6110 6239 6420 6206 6144 6130 6099 6203 6066 6114 6153 6163 6097 6168 6044 6269 6172 6052 6017 6126 6145 6093 5991 6219 6126 6103 6069 6146 6123 6178 6179 6145 6073 6174 6047 6141 6185 6209 6145 6035 6213 6109 6140 6129 6339 6123 6164 6183 6095 6067 6083 6333 6152 6132 6066 6205 6143 6137 6191 5989 6187 6170 6266 6095 6128 6045 6128 6234 6108 6041 6227 6241 5960 6243 6123 6091 6144 6083 6077 6114 5953 6067 6075 6094 6038 6228 6176 6188 6169 6122 6223 6201 6250 5963 6316 6138 6109 6271 5947 6114 6249 6001 6146 6251 6219 6232 6122 5985 6122 6019 5997 6133 6120 6201 6198 6152 6137 6216 6236 6188 6074 6207 6094 5993 6108 6072 6311 6084 6065 6160 6136 6336 6231 6120 6090 6204 6148 6251 6109 6072 6128 5977 6225 6184 6166 6136 6095 6195 6093 6307 6103 5986 6222 6158 6164 6334 6334 6154 6202 6257 6184 6256 6051 6087 6246 6085 6125 6121 6042 6193 6275 6236 6162 6282 6040 6326 6253 6130 6196 6277 6122 6119 6236 6216 6266 6228 6239 6335 6218 6422 6195 6290 6155 6165 6261 6270 6053 6167 5997 6168 6221 6274 6278 6296 6426 6258 6282 6286 6305 6220 6250 6319 6283 6246 6277 6247 6139 6220 6302 6282 6176 6170 6263 6235 6223 6309 6380 6147 6411 6271 6321 6198 6213 6255 6161 6286 6320 6270 6319 6242 6316 6185 6251 6370 6260 6260 6282 6245 6136 6232 6292 6225 6308 6355 6214 6136 6215 6354 6194 6247 6255 6179 6017 6290 6223 6170 6451 6427 6216 6310 6225 6364 6338 6195 6263 6200 6314 6340 6237 6321 6201 6102 6208 6386 6318 6239 6338 6391 6232 6242 6312 6176 6294 6296 6388 6204 6400 6283 6175 6289 6329 6310 6471 6365 6323 6224 6179 6365 6441 6136 6276 6281 6465 6252 6437 6323 6386 6227 6225 6502 6142 6253 6394 6343 6304 6234 6405 6364 6347 6096 6279 6296 6345 6394 6487 6230 6465 6369 6378 6145 6300 6446 6377 6199 6453 6423 6435 6464 6464 6353 6356 6454 6419 6503 6530 6386 6662 6653 6593 6705 6796 6843 6709 6879 6754 6689 6581 6442 6549 6440 6411 6413 6412 6361 6393 6226 6438 6272 6392 6367 6468 6501 6243 6359 6385 6383 6443 6362 6376 6378 6408 6509 6583 6566 6400 6547 6551 6490 6581 6703 6478 6422 6805 6588 6713 6664 6798 6836 6794 6926 6870 6805 6803 6767 6812 6700 6563 6558 6552 6543 6453 6538 6652 6347 6452 6418 6445 6340 6261 6565 6356 6512 6494 6480 6454 6274 6332 6480 6435 6556 6353 6457 6423 6428 6502 6485 6452 6477 6567 6488 6472 6446 6580 6633 6529 6597 6569 6603 6662 6523 6686 6689 6666 6621 6890 6746 6788 6806 6950 6870 6916 7094 7176 7277 7170 7253 7269 7491 7440 7568 7586 7670 7636 7742 8042 7835 7992 7834 8134 8147 8058 8278 8245 8473 8434 8485 8619 8400 8812 9058 9216 9311 9462 9790 9902 10290 10610 11309 11937 12248 12994 13875 15184 16444 17886 19966 22192 25003 28413 32325 37021 42513 48141 55579 63015 71307 80753 91283 102742 114711 125701 135323 138909 134348 122769 107886 92063 77226 62807 48236 35710 26589 20528 16140 13515 11649 10475 9822 9215 9013 8701 8661 8467 8332 8507 8496 8454 8178 8120 8058 8078 8062 7959 7921 7718 7575 7862 7583 7570 7453 7239 7152 7153 7188 7160 7181 6969 7007 6909 6813 6830 7002 6789 6676 6801 6741 6715 6828 6770 6864 6821 6848 6831 6677 6675 6724 6576 6698 6696 6711 6771 6925 6925 6844 6877 6898 6947 6876 6984 7004 6974 7071 6997 7128 7133 7046 7154 7137 7110 7064 7099 6970 7071 7110 7137 7205 7015 7082 7277 7135 7071 7125 6980 7103 7043 7049 7043 6949 7039 7096 7017 7144 7086 7041 7070 7164 7173 7088 7167 7037 7019 7210 7103 7080 7031 7024 7190 7052 7114 7178 6972 7076 7050 7051 7029 7070 7124 7080 6948 7001 6982 6996 7008 6967 7082 7144 6935 7014 6888 7119 7125 6961 7059 7104 7112 7093 7012 7002 7048 7027 6963 6825 6833 7015 7005 6896 6950 6949 6979 6991 6883 7027 6973 6995 7216 7062 7056 6994 7135 7011 7003 6976 6967 6889 7107 7034 6992 7142 6999 7022 7012 6965 7004 6831 6884 6800 6914 6970 7082 6922 7015 7119 7128 7022 7222 7108 7126 7256 7220 7279 7521 7592 7782 7729 7883 7746 8120 8028 7882 7845 7893 7819 7854 7531 7632 7539 7626 7389 7179 7051 7043 7153 7049 7051 6970 6877 6958 6766 6889 6842 6779 6889 6657 6899 6848 6753 6837 6808 6745 6700 6797 6770 6720 6698 6636 6867 6624 6709 6653 6829 6878 6820 6703 6855 6688 6877 6711 6742 6850 6802 6760 6741 6765 6889 6770 6691 6933 6863 6562 6710 6727 6662 6816 6707 6708 6945 6610 6648 6650 6551 6840 6648 6681 6774 6587 6691 6757 6584 6565 6637 6616 6636 6677 6534 6660 6534 6619 6756 6594 6704 6580 6668 6722 6762 6645 6491 6579 6545 6432 6480 6557 6574 6563 6663 6784 6624 6474 6563 6591 6530 6681 6709 6561 6755 6575 6617 6605 6600 6678 6538 6653 6563 6612 6575 6663 6585 6635 6422 6652 6533 6377 6602 6409 6449 6464 6636 6532 6685 6492 6588 6675 6433 6479 6508 6364 6561 6536 6549 6605 6557 6651 6519 6578 6317 6344 6528 6424 6402 6532 6492 6185 6582 6451 6532 6426 6544 6597 6582 6399 6401 6393 6438 6405 6520 6474 6492 6429 6569 6406 6487 6336 6358 6477 6452 6384 6518 6470 6453 6513 6531 6395 6511 6463 6382 6437 6552 6382 6525 6633 6502 6540 6593 6494 6541 6635 6521 6483 6490 6470 6592 6642 6512 6556 6599 6686 6681 6670 6867 6715 6898 7101 7073 7045 7192 7314 7340 7292 7415 7337 7228 7077 6997 7069 6811 6885 6658 6745 6493 6549 6329 6571 6317 6442 6360 6410 6436 6392 6330 6332 6453 6466 6442 6449 6447 6361 6413 6321 6314 6410 6342 6442 6397 6308 6526 6559 6515 6456 6602 6555 6481 6605 6708 6649 6589 6817 6858 6998 7025 7268 7483 7405 7612 7759 8084 8345 8700 8916 9277 9509 9923 10320 10724 10771 10809 11138 10772 10357 10038 9761 9229 8942 8460 8188 7817 7313 7025 7087 6858 6650 6677 6556 6678 6597 6580 6483 6427 6467 6433 6287 6632 6287 6404 6292 6378 6430 6342 6581 6196 6447 6141 6320 6332 6417 6334 6265 6513 6293 6314 6281 6193 6100 6312 6225 6229 6336 6156 6253 6219 6234 6250 6316 6249 6177 6213 6375 6426 6310 6311 6262 6278 6453 6488 6246 6368 6386 6370 6466 6457 6483 6532 6605 6596 6499 6665 6492 6533 6564 6517 6452 6373 6514 6421 6246 6309 6375 6271 6273 6177 6285 6270 6199 6215 6300 6186 6326 6178 6352 6238 6197 6211 6251 6170 6216 6148 6166 6211 6241 6192 6178 6127 6344 6219 6237 6304 6278 6082 6118 6265 6356 6204 6314 6375 6403 6371 6351 6296 6347 6346 6368 6335 6283 6307 6346 6395 6157 6187 6302 6220 6153 6316 6144 6263 6243 6122 6316 6086 6206 6244 6342 6327 6357 6269 6317 6172 6352 6227 6441 6338 6323 6391 6386 6337 6412 6247 6214 6365 6212 6156 6154 6333 6201 6261 6238 6100 6222 6112 6178 6256 6061 6243 6153 6140 6199 5934 6073 6003 6084 6150 6106 6017 6104 6132 6070 6049 6087 6202 6007 6146 6044 6107 6213 6099 6204 6017 6172 6017 6183 6138 6027 6075 6269 6071 6103 6163 6013 6222 6167 6151 6133 5924 6107 6097 5993 6182 6028 6110 6203 6013 6002 6141 6111 6162 5920 6116 6093 6051 6134 6001 6015 6038 6149 5938 6201 6050 6199 6104 6070 6034 6165 6098 6079 5913 6127 6096 6026 5982 6066 6038 6039 6050 5952 6007 6079 6137 6029 6008 6097 6001 5996 5926 6130 6065 6114 5985 6141 6086 6006 6062 6083 6149 6072 6004 6062 6015 6132 5958 5847 6036 5836 6016 5958 6003 6027 5974 5985 6063 6054 6017 6028 6115 5908 6047 6101 6197 6058 5941 6052 6096 6167 6124 5818 6121 5913 6203 5909 6000 5950 5985 5956 5913 6034 5919 6002 5977 6034 6093 6157 5881 6109 6052 5862 5981 5999 6054 6071 5941 6079 6090 6006 6034 6096 6168 6055 5963 6067 6211 6135 5979 6056 6032 6055 6047 6304 5993 6039 6190 6128 5995 6167 6040 5957 6029 6045 5918 6073 6040 5916 6030 5939 5934 5905 5948 5954 5892 6066 6107 5920 5932 6008 6036 5935 5965 5955 5991 6001 5947 5955 5963 6014 6061 5939 5887 5907 5974 5977 5986 5974 6002 5962 5931 5951 6029 5983 6018 6088 5844 5966 5898 5942 6186 5877 6148 5932 6010 6177 6063 6209 6283 6217 6167 6064 6103 6132 6072 6167 6164 5993 6046 5970 6125 6040 5932 6028 5983 6000 5975 6010 6036 6006 5958 6021 5885 6054 6151 5879 6035 5922 6004 6056 5890 6095 5966 5952 6139 6052 5994 6050 6112 6028 6061 6153 6214 6241 6221 6335 6268 6386 6635 6644 6806 6814 6990 7117 7330 7546 7650 7735 7750 7738 7868 7887 7697 7593 7432 7328 7116 6953 6822 6723 6589 6382 6306 6356 6125 6281 6087 6035 5988 6056 6141 5983 5916 5961 6024 6003 5982 5949 5998 5978 5861 5929 5954 5804 6020 5918 6015 5894 5957 5962 5993 5881 5964 5992 6141 5752 5887 6029 5926 6063 5931 6014 5806 6199 5983 5852 5968 5922 5954 6081 6056 5978 5970 5976 6132 5970 6070 6029 6211 6174 6209 6364 6391 6273 6500 6429 6489 6630 6803 6857 7099 7142 7491 7682 7863 8213 8698 9228 9924 10667 11595 11843 11541 11724 11150 10693 10359 10099 9917 9529 9164 9000 8607 8504 8252 7995 7848 7904 7880 7699 7673 7555 7437 7202 7117 7093 6804 6730 6637 6545 6413 6396 6137 6272 6323 6045 6097 6070 5976 6153 6058 6021 5973 5906 5857 5900 6150 5852 6063 5910 5825 5897 5937 5890 5774 5871 5794 5969 5921 5968 5855 5865 5843 5911 6004 5951 5985 5842 5790 5829 5813 5929 5920 5813 5880 5736 5899 5849 5811 5924 5921 5966 5752 5809 5810 5843 5724 5683 5797 5929 5854 5772 5894 5741 5851 6019 5811 5905 5704 5929 5810 5857 5825 5913 5899 5957 5888 5889 5883 5896 5798 5947 5875 5879 5842 5824 5857 5741 5860 5852 5756 5831 5796 5863 5782 5760 5817 5718 5841 5780 5878 5859 5981 5807 5795 5855 5836 5736 5915 5768 5843 5860 5883 5793 5748 5877 5702 5852 5717 5886 5842 5920 5952 5809 5748 5757 5810 5759 5845 5681 5810 5910 5928 5969 5851 5877 5872 5844 5847 5955 5862 5926 5858 5749 5746 5814 5892 5928 5791 6027 5851 5986 5877 5834 5833 5953 5778 5874 5856 5789 5880 5815 5779 5779 5816 5830 5843 5750 5788 5864 5828 5776 5846 5722 5849 5853 5868 5741 5812 5825 5781 5951 5878 5814 5853 5893 5894 5846 5987 5876 5867 5891 5960 5812 5903 5852 5856 5933 5890 5871 5893 5902 5763 5980 6029 5986 5910 5985 6184 6183 6070 6035 6235 6388 6204 6361 6602 6835 6889 7297 7467 7529 8010 8453 9062 9417 9749 10369 10850 11274 12028 12081 12251 12114 11721 11351 10751 10446 10068 9800 9277 8974 8581 8107 7628 7281 7247 6768 6703 6338 6289 6184 6231 6264 6013 6255 6098 5814 5893 5992 5882 5846 6031 5932 6013 5901 5929 5907 5800 5869 5824 5953 5792 5700 5842 5767 5719 5883 5852 5790 5777 5913 5969 5768 5589 5738 5806 5856 5831 5808 5686 5769 5685 5722 5752 5797 5767 5687 5819 5756 5662 5774 5718 5716 5807 5825 5713 5833 5729 5779 5842 5727 5732 5744 5780 5859 5807 5590 5727 5776 5613 5847 5713 5754 5724 5749 5839 5860 5751 5660 5677 5918 5794 5689 5713 5813 5614 5825 5787 5666 5745 5699 5884 5823 5907 5850 5791 5809 5712 5620 5788 5828 5792 5750 5683 5810 5801 5798 5657 5827 5673 5698 5750 5863 5811 5768 5651 5708 5887 5883 5682 5712 5792 5782 5921 5777 5911 5744 5610 5847 5699 5729 5687 5714 5711 5637 5851 5768 5742 5734 5753 5836 5952 5794 5773 5853 5743 5776 5848 5929 5879 5899 5890 5908 5877 5788 5971 6195 6125 6144 6401 6400 6454 6533 7127 7294 7480 7466 7602 7478 7071 7077 6771 6835 6831 6868 6749 6751 6497 6465 6315 6411 6252 6195 6326 6270 6450 6521 6509 6607 6388 6528 6524 6406 6660 6644 6609 6493 6586 6575 6449 6466 6424 6599 6674 6678 6797 6657 6997 7250 7338 7773 7815 8299 8713 9169 9617 10107 10484 10867 11039 11134 11143 10814 10485 10053 9820 9401 9168 9049 8673 8367 8099 7626 7175 7064 6862 6630 6471 6279 6251 6180 6063 6047 5834 6045 5782 6055 5943 5968 5860 5735 5844 5809 5938 5828 5744 5687 5774 5813 5776 5823 5778 5848 5907 5775 5637 5645 5819 5901 5861 5751 5834 5639 5795 5841 5755 5731 5860 5802 5808 5789 5723 5826 5882 5763 5737 5844 5857 5823 5778 5837 5806 6010 5944 5895 6037 6187 6242 6495 6519 6722 6925 7078 7173 7497 7361 7245 6988 6748 6784 6565 6639 6611 6687 6462 6471 6453 6305 6181 6192 6133 6297 6388 6713 6884 6941 7141 7352 7488 7508 7589 7512 7559 7217 7068 6859 6985 6629 6787 6651 6603 6482 6282 6055 6107 5922 5968 5879 5971 6002 6035 5990 5999 6100 5852 6096 6058 5789 5918 5889 5869 6025 5944 5989 5893 6082 5987 6006 5950 6008 6072 6132 6064 6006 6138 5959 6033 6019 5827 5948 5857 5824 5730 5825 5638 5741 5952 5868 5705 5770 5812 5810 5791 5791 5751 5813 5745 5768 5808 5872 5837 5676 5927 5744 5707 5919 6009 6027 5951 6045 6144 6340 6483 6604 7001 7354 7826 8403 8982 9915 10810 11699 12463 13130 12841 12110 11146 10067 9407 9105 9023 9103 9058 9145 8763 7951 7381 6894 6307 6168 6091 5806 5750 5896 5779 5639 5673 5723 5696 5863 5795 5779 5669 5705 5752 5670 5817 5758 5754 5647 5687 5716 5571 5701 5661 5639 5661 5769 5656 5841 5644 5769 5750 5868 5641 5882 5870 5870 6028 6004 6122 6085 6375 6345 6324 6240 6275 6063 6060 6085 6071 6023 6076 5848 5991 5906 5802 5842 5612 5769 5797 5581 5717 5585 5658 5550 5548 5615 5617 5677 5549 5652 5709 5591 5679 5729 5655 5754 5680 5659 5690 5642 5603 5737 5565 5657 5626 5668 5532 5659 5792 5534 5699 5720 5755 5630 5576 5757 5856 5804 5818 5770 5973 5913 6008 5792 6007 5911 6006 6038 5843 5904 5993 5700 5728 5875 5747 5867 5922 5801 5667 5726 5665 5629 5617 5672 5613 5563 5568 5689 5574 5685 5651 5552 5633 5602 5563 5558 5624 5529 5596 5552 5702 5587 5708 5544 5739 5698 5466 5493 5641 5626 5605 5660 5589 5659 5722 5671 5557 5740 5706 5734 5866 5871 5871 6000 5973 5928 5741 5944 5966 6035 6033 5815 5876 5732 5841 5709 5827 5780 5587 5808 5719 5517 5698 5624 5710 5530 5697 5629 5790 5681 5790 5587 5610 5638 5663 5635 5794 5644 5788 5770 5708 5812 5749 5980 5911 6017 6060 6021 6024 6139 6257 6029 5962 5776 5841 5895 5939 5858 5828 5958 5830 5813 5697 5568 5572 5535 5506 5475 5547 5469 5677 5622 5556 5589 5612 5614 5584 5639 5557 5624 5645 5610 5800 5743 5742 5738 5688 5715 5671 5767 5955 5783 5983 6091 6227 6181 6403 6503 6707 6871 7025 7343 7314 7467 7435 7405 7364 7298 6939 6791 6792 6687 6556 6592 6670 6463 6362 6184 6216 6116 5845 5628 5755 5598 5714 5846 5779 5522 5611 5655 5441 5676 5474 5465 5501 5662 5571 5561 5628 5523 5593 5555 5722 5598 5556 5611 5649 5593 5552 5553 5533 5606 5491 5592 5610 5669 5653 5493 5628 5394 5481 5588 5579 5641 5571 5588 5494 5610 5465 5535 5632 5614 5573 5481 5619 5424 5632 5561 5492 5470 5560 5608 5635 5413 5581 5503 5551 5499 5511 5591 5717 5542 5483 5616 5603 5544 5495 5766 5741 5571 5474 5679 5415 5548 5452 5466 5609 5512 5716 5762 5574 5504 5504 5735 5546 5679 5608 5658 5600 5772 5527 5693 5681 5520 5648 5601 5595 5598 5560 5701 5706 5535 5594 5639 5668 5583 5699 5616 5517 5714 5758 5698 5855 5731 5766 5772 5761 5720 5694 5854 5689 5717 5855 5779 5901 5815 5802 5954 5645 5990 5948 5985 5971 6087 6244 6490 6609 6769 6853 7064 7163 6774 6851 6645 6447 6514 6580 6701 6832 6973 7000 7137 7101 7311 7194 7499 7492 7959 7186 7088 6931 6870 6739 6871 7020 7114 7298 7367 7252 7126 7027 7072 6778 6870 6884 6832 6767 6888 6622 6846 6718 6743 6604 6669 6607 6497 6478 6506 6350 6410 6218 6241 6306 6081 6121 6119 5928 5911 5863 5854 5887 5888 5958 5965 5929 5925 5752 5691 5781 5732 5785 5726 5795 5782 5680 5824 5714 5816 5764 5947 5962 5786 5913 5797 5857 5958 5852 5880 5728 5721 5765 5838 5827 5676 5788 5859 5830 5617 5667 5644 5694 5682 5547 5533 5645 5613 5556 5574 5630 5584 5486 5621 5493 5614 5479 5438 5623 5471 5611 5491 5505 5493 5531 5527 5576 5549 5616 5616 5515 5543 5576 5567 5594 5480 5603 5501 5567 5549 5675 5602 5545 5514 5511 5600 5629 5502 5615 5631 5630 5476 5625 5486 5593 5616 5777 5713 5714 5764 5649 5715 5797 5708 5978 6081 5865 6125 6188 6378 6474 6619 6891 7416 7829 8177 8924 9183 9791 10285 10442 10283 9938 9513 8967 8538 8183 8261 8184 8127 8080 8199 7868 7642 7306 6957 6559 6310 6068 5915 5813 5822 5826 5758 5752 5751 5619 5637 5609 5461 5581 5556 5550 5424 5558 5523 5460 5519 5633 5514 5453 5649 5456 5515 5520 5394 5500 5489 5458 5532 5532 5441 5408 5451 5572 5441 5440 5558 5557 5467 5488 5442 5395 5405 5468 5451 5568 5421 5445 5509 5425 5328 5550 5324 5371 5423 5634 5505 5453 5569 5537 5362 5489 5554 5511 5503 5573 5503 5347 5574 5451 5598 5559 5416 5543 5595 5455 5604 5471 5539 5557 5391 5532 5482 5325 5347 5332 5443 5568 5360 5451 5553 5419 5498 5464 5448 5534 5426 5406 5521 5564 5389 5560 5616 5480 5670 5590 5681 5839 5589 5659 5743 5567 5701 5566 5611 5481 5538 5578 5524 5704 5495 5708 5626 5433 5619 5462 5538 5468 5486 5441 5325 5446 5432 5466 5424 5359 5453 5353 5389 5459 5490 5258 5402 5475 5377 5513 5441 5356 5430 5542 5465 5468 5423 5477 5399 5443 5470 5486 5520 5437 5430 5498 5414 5494 5460 5349 5493 5495 5534 5569 5462 5346 5561 5436 5490 5399 5392 5445 5470 5501 5358 5403 5444 5304 5425 5496 5395 5327 5386 5381 5468 5452 5548 5517 5499 5523 5420 5552 5454 5453 5436 5505 5466 5379 5447 5290 5557 5408 5274 5393 5523 5410 5492 5538 5430 5520 5438 5377 5475 5395 5573 5394 5442 5380 5396 5471 5390 5673 5554 5335 5516 5396 5448 5561 5470 5547 5600 5388 5741 5412 5723 5573 5638 5601 5671 5874 5621 5634 5648 5718 5627 5561 5580 5535 5631 5433 5555 5620 5451 5661 5597 5520 5484 5543 5558 5433 5549 5654 5395 5428 5408 5448 5535 5433 5507 5417 5541 5436 5328 5333 5448 5407 5477 5530 5501 5390 5517 5504 5496 5676 5748 5754 5685 5848 5858 5896 5701 5747 5591 5529 5426 5640 5603 5396 5646 5518 5534 5681 5590 5525 5522 5470 5416 5519 5490 5324 5522 5401 5531 5475 5402 5433 5378 5466 5523 5473 5452 5554 5429 5435 5381 5552 5567 5609 5571 5482 5469 5523 5401 5530 5548 5460 5411 5517 5550 5556 5398 5489 5439 5500 5458 5456 5638 5555 5512 5684 5450 5563 5644 5651 5742 5776 6058 6042 5949 6147 6186 6239 6288 6293 6024 5990 5853 5868 5796 5653 5860 5737 5873 5708 5906 5830 5748 5527 5473 5515 5583 5601 5383 5280 5548 5464 5451 5372 5419 5466 5476 5492 5399 5480 5384 5424 5347 5396 5500 5440 5414 5427 5398 5401 5542 5526 5621 5478 5545 5391 5444 5399 5614 5548 5523 5629 5718 5618 5632 5613 5683 5879 6018 6123 6217 6436 6650 6731 6791 7083 7278 7475 7330 7461 7285 7162 7021 6815 6648 6712 6542 6677 6682 6614 6597 6444 6344 6132 6244 6171 5924 5865 5725 5625 5593 5631 5606 5557 5477 5451 5599 5556 5512 5566 5437 5374 5445 5337 5430 5424 5410 5346 5207 5467 5334 5315 5405 5401 5416 5440 5352 5471 5246 5336 5321 5398 5494 5244 5303 5315 5213 5307 5324 5360 5459 5444 5289 5480 5377 5237 5332 5213 5401 5428 5121 5474 5415 5367 5136 5249 5434 5499 5459 5508 5315 5272 5259 5277 5402 5371 5280 5409 5399 5458 5415 5464 5374 5415 5394 5423 5376 5225 5322 5379 5448 5355 5400 5512 5326 5304 5478 5363 5397 5511 5553 5492 5632 5588 5424 5430 5509 5352 5349 5383 5339 5497 5409 5410 5371 5634 5319 5315 5436 5405 5423 5526 5502 5358 5289 5420 5421 5317 5350 5504 5323 5368 5401 5252 5430 5372 5378 5351 5404 5295 5308 5325 5443 5238 5358 5270 5322 5245 5267 5209 5325 5499 5294 5210 5441 5377 5307 5322 5358 5335 5386 5486 5465 5337 5315 5423 5367 5422 5376 5406 5339 5342 5369 5391 5300 5403 5421 5361 5484 5417 5348 5432 5573 5189 5331 5299 5371 5349 5228 5430 5330 5469 5372 5266 5411 5399 5350 5552 5274 5276 5381 5351 5492 5262 5402 5291 5335 5429 5317 5228 5388 5251 5250 5423 5449 5382 5348 5338 5354 5275 5402 5411 5366 5187 5234 5259 5318 5335 5410 5355 5481 5385 5294 5301 5329 5316 5292 5264 5275 5303 5324 5291 5367 5408 5367 5448 5258 5331 5302 5240 5190 5381 5297 5294 5455 5218 5419 5275 5475 5310 5359 5235 5430 5333 5338 5284 5331 5369 5433 5321 5403 5347 5408 5360 5440 5288 5362 5311 5468 5225 5249 5363 5300 5373 5429 5394 5342 5420 5405 5342 5385 5356 5291 5417 5358 5356 5416 5303 5219 5488 5364 5349 5280 5377 5445 5425 5450 5336 5298 5370 5282 5344 5208 5268 5214 5145 5319 5385 5349 5438 5236 5400 5337 5312 5358 5327 5391 5423 5297 5526 5395 5432 5531 5450 5301 5418 5514 5404 5400 5441 5414 5566 5426 5527 5534 5801 5552 5393 5549 5396 5501 5554 5441 5382 5489 5464 5544 5385 5513 5529 5512 5617 5441 5459 5526 5466 5537 5534 5501 5536 5586 5511 5420 5517 5415 5492 5536 5513 5469 5615 5534 5753 5605 5669 5736 5762 5698 5653 5873 5997 6195 6098 6197 6167 6209 6148 6131 5843 6055 6097 6197 6553 6635 6908 7084 7200 7713 7959 8277 8792 9172 9689 10033 10056 10126 10137 9897 9604 9310 8934 8618 8558 8686 8781 8776 8697 8504 8566 8402 8047 7808 7703 7113 6878 6840 6687 6510 6507 6333 6348 6165 6055 5836 5628 5620 5614 5653 5698 5629 5513 5457 5536 5476 5532 5498 5565 5344 5498 5426 5316 5431 5427 5397 5565 5422 5353 5399 5401 5353 5394 5343 5293 5316 5415 5433 5316 5406 5379 5210 5439 5345 5423 5359 5358 5325 5413 5201 5308 5318 5388 5321 5414 5306 5313 5237 5341 5355 5253 5308 5349 5232 5268 5318 5461 5299 5319 5293 5278 5239 5218 5305 5328 5312 5342 5250 5353 5300 5353 5196 5350 5281 5352 5344 5402 5385 5354 5413 5222 5323 5500 5346 5398 5380 5299 5266 5371 5341 5415 5482 5345 5364 5403 5319 5505 5433 5218 5466 5395 5293 5400 5310 5442 5304 5398 5367 5397 5361 5436 5342 5363 5389 5389 5428 5444 5133 5204 5293 5255 5283 5519 5436 5315 5270 5259 5346 5382 5252 5259 5367 5345 5321 5273 5244 5287 5276 5198 5312 5319 5288 5288 5213 5176 5206 5389 5318 5295 5500 5229 5341 5353 5471 5284 5362 5229 5384 5345 5348 5398 5378 5454 5322 5416 5265 5471 5473 5291 5451 5476 5508 5550 5480 5411 5525 5424 5454 5463 5354 5508 5457 5526 5356 5403 5299 5400 5290 5334 5376 5245 5420 5323 5300 5346 5207 5325 5203 5214 5198 5370 5367 5410 5332 5388 5349 5258 5253 5173 5327 5355 5282 5237 5321 5358 5406 5315 5188 5389 5263 5267 5329 5315 5360 5321 5300 5290 5219 5390 5231 5363 5330 5283 5291 5336 5283 5348 5234 5311 5345 5478 5383 5238 5241 5265 5372 5448 5253 5306 5209 5294 5429 5412 5330 5220 5326 5418 5367 5265 5243 5232 5230 5299 5224 5396 5354 5387 5402 5253 5308 5264 5338 5325 5413 5314 5352 5448 5220 5383 5503 5441 5314 5412 5443 5497 5313 5380 5430 5587 5564 5631 5628 5540 5691 5591 5655 5637 5713 5528 5710 5626 5503 5531 5657 5686 5659 5658 5495 5481 5512 5514 5529 5454 5477 5444 5705 5564 5426 5495 5453 5603 5419 5443 5473 5181 5478 5412 5265 5427 5425 5393 5538 5450 5451 5448 5334 5459 5246 5456 5434 5401 5321 5339 5340 5406 5467 5545 5434 5334 5504 5537 5448 5580 5694 5761 5874 6088 6459 6502 6926 7344 7575 7405 7121 6577 6393 6030 5928 5783 5696 5800 5845 5911 6032 6299 6439 6349 6322 6132 6051 5752 5669 5420 5566 5369 5463 5402 5471 5471 5531 5501 5466 5503 5424 5622 5457 5582 5766 5807 5860 5977 6092 6250 6467 6342 6396 6239 6251 6113 6021 5832 5798 5595 5743 5583 5676 5630 5751 5797 5935 5836 5787 5901 5783 5550 5518 5466 5381 5330 5329 5328 5322 5326 5312 5324 5264 5329 5258 5380 5269 5213 5185 5228 5318 5383 5284 5203 5279 5320 5256 5321 5289 5117 5251 5238 5327 5337 5296 5252 5303 5288 5266 5273 5152 5311 5190 5122 5180 5207 5199 5181 5358 5173 5275 5272 5300 5372 5378 5373 5313 5282 5305 5310 5263 5263 5223 5179 5281 5196 5252 5240 5283 5178 5178 5312 5237 5341 5267 5204 5252 5236 5178 5283 5342 5048 5119 5263 5207 5225 5240 5182 5170 5256 5227 5194 5200 5300 5142 5236 5316 5111 5275 5142 5177 5176 5303 5223 5268 5253 5271 5236 5138 5216 5113 5260 5279 5180 5285 5280 5249 5167 5330 5309 5175 5226 5312 5193 5272 5158 5103 5258 5226 5305 5152 5104 5254 5050 5178 5292 5323 5325 5159 5341 5189 5347 5184 5219 5242 5278 5258 5244 5196 5185 5278 5225 5253 5345 5418 5300 5273 5259 5231 5142 5287 5145 5247 5237 5241 5278 5192 5332 5214 5170 5192 5266 5234 5169 5266 5199 5207 5137 5221 5164 5263 5272 5199 5290 5191 5235 5186 5281 5263 5165 5246 5176 5373 5200 5243 5184 5314 5220 5321 5227 5155 5322 5259 5222 5277 5293 5244 5359 5234 5204 5265 5187 5216 5055 5294 5303 5222 5090 5329 5203 5235 5212 5263 5155 5215 5191 5224 5325 5351 5257 5099 5076 5199 5264 5395 5186 5164 5357 5327 5246 5159 5158 5279 5348 5337 5302 5323 5354 5305 5279 5241 5207 5291 5156 5159 5266 5377 5311 5339 5313 5322 5281 5191 5484 5353 5361 5387 5355 5279 5332 5366 5232 5285 5256 5344 5178 5278 5175 5399 5311 5267 5365 5433 5275 5310 5286 5351 5319 5450 5332 5283 5283 5223 5320 5450 5430 5259 5234 5388 5447 5443 5321 5367 5470 5418 5446 5350 5427 5433 5462 5305 5529 5589 5557 5549 5522 5583 5665 5751 5534 5614 5828 5819 5890 5941 5998 6115 6174 6333 6244 6456 6628 6817 7029 7094 6952 7204 7147 7013 6951 6698 6803 6646 6530 6425 6293 6427 6543 6540 6481 6392 6555 6302 6161 6249 6134 6304 6068 5960 5966 5855 5645 5773 5663 5630 5594 5648 5445 5509 5515 5433 5552 5570 5363 5521 5464 5413 5450 5475 5334 5509 5407 5377 5398 5448 5260 5459 5459 5490 5614 5450 5566 5633 5622 5743 5787 5784 5672 5583 5572 5510 5430 5376 5444 5350 5486 5408 5437 5543 5392 5500 5465 5500 5392 5237 5380 5389 5480 5382 5256 5339 5319 5322 5240 5247 5302 5439 5235 5451 5401 5382 5365 5336 5362 5411 5427 5412 5255 5493 5298 5295 5265 5189 5415 5400 5489 5223 5357 5294 5335 5387 5298 5340 5291 5273 5349 5336 5322 5304 5138 5344 5422 5195 5434 5263 5392 5533 5479 5464 5514 5587 5731 5768 5717 5681 6093 6150 6215 6257 6396 6506 6495 6531 6636 6772 6868 7014 7007 7198 6939 7011 6787 6812 6594 6455 6446 6607 6359 6330 6307 6287 6323 6557 6263 6426 6518 6356 6405 6266 6365 6319 6363 6280 6519 6667 6723 6926 6937 7080 7080 6668 6381 6324 6101 5989 5926 5784 5745 5874 5894 6002 5917 6109 6140 6123 6101 6055 5953 5904 5639 5560 5534 5468 5413 5329 5396 5391 5255 5366 5405 5415 5286 5286 5208 5204 5299 5278 5224 5219 5188 5331 5367 5449 5223 5266 5248 5253 5256 5389 5310 5445 5346 5441 5351 5315 5324 5172 5360 5128 5327 5219 5183 5072 5156 5192 5269 5285 5259 5364 5316 5342 5427 5393 5319 5381 5540 5480 5586 5810 5847 5888 6036 5690 5999 5660 5668 5431 5546 5492 5335 5395 5411 5453 5497 5603 5583 5432 5583 5598 5607 5646 5664 5396 5334 5314 5395 5339 5318 5323 5328 5203 5314 5248 5210 5096 5196 5167 5240 5317 5198 5205 5244 5240 5118 5198 5276 5306 5079 5337 5159 5300 5237 5233 5245 5200 5275 5418 5329 5419 5370 5303 5335 5250 5180 5292 5202 5211 5304 5287 5290 5319 5242 5122 5269 5348 5270 5335 5246 5339 5241 5210 5227 5488 5136 5232 5177 5239 5089 5255 5243 5366 5247 5237 5197 5253 5292 5177 5232 5330 5180 5280 5225 5302 5280 5255 5149 5102 5112 5243 5088 5140 5161 5174 5185 5226 5222 5276 5244 5072 5264 5135 5095 5100 5131 5170 5232 5146 5195 5120 5173 5034 5048 5201 5224 5255 5161 5242 5211 5176 5261 5202 5092 4986 5189 5155 5038 5053 5032 5145 5199 5250 5204 5300 5141 5113 5114 5173 4980 5074 5078 5162 5122 5091 5096 5082 4991 5125 5086 5155 5055 5247 5120 5128 5160 5194 5117 5123 5156 5105 5212 5078 5212 5116 5142 5112 5234 5102 5121 5136 5189 5203 5197 5205 5154 5261 5251 5163 5101 5228 5214 5259 5217 5081 5158 5264 5257 5013 5143 5097 5173 5125 5158 5137 5219 5155 5087 5180 5081 5162 5106 5135 5189 5214 5171 5211 5196 5088 5177 5074 5126 5106 5255 5042 5156 5019 5059 5134 5061 5248 5223 5219 5208 5213 5157 5291 5032 5121 5212 5053 5377 5169 5110 5171 5254 5318 5194 5077 5065 5036 5224 5170 5253 5130 5035 5228 5099 5018 5169 5029 5222 5292 5036 5212 5174 5286 5243 5370 5357 5344 5345 5381 5270 5222 5233 5220 5271 5272 5295 5229 5242 5334 5393 5267 5258 5395 5376 5392 5296 5337 5329 5365 5414 5247 5388 5501 5556 5619 5709 5733 5682 5669 5416 5618 5584 5431 5444 5502 5293 5407 5278 5306 5219 5271 5400 5374 5243 5386 5391 5348 5383 5339 5225 5275 5272 5273 5237 5290 5190 5239 5247 5168 5090 5225 5178 5365 5080 5250 5189 5192 5201 5155 5153 5160 5147 5048 5098 5195 5097 5191 5185 5147 5102 5160 5184 5259 5211 5145 5047 5240 5158 5223 5175 5162 5062 5227 5045 5154 5030 5220 5102 5244 5253 5208 5241 5157 5100 5252 5107 5172 5117 5269 5222 5194 5097 5251 5102 5330 5149 5133 5147 5132 5155 5165 5236 5190 4993 5178 5170 5157 5147 5109 5091 5222 5126 5142 5292 5153 5147 5120 5160 5108 5111 5146 5087 5176 5260 5159 5259 5135 5017 5079 5133 5042 5198 5030 5212 4961 5169 5054 5143 5088 5178 5154 4934 5220 5085 5004 5069 5197 5188 5275 5150 5216 5003 5100 5226 5041 5067 5073 4959 5179 5061 5072 5170 5213 5189 5053 5195 5074 5202 5202 5157 5018 5163 4980 5149 5127 5119 5143 5175 5132 5131 5084 5114 5093 5179 5073 5188 5184 5188 5206 4993 5044 5036 5193 5177 5166 5154 5154 5135 5044 5263 5111 5013 5079 5181 4994 5067 5199 5033 5033 5027 5139 5107 5054 5185 5121 5036 5050 5098 5144 5063 5212 5250 5099 5111 5137 4965 5066 4987 5141 5172 5125 5045 5098 5036 5057 5122 5160 5238 5183 5105 5145 5056 5077 5020 5131 5294 5116 5103 5085 5081 5016 5164 5021 5176 5059 5216 5319 5347 5218 5232 5228 5161 5063 5122 5172 5136 5277 5177 5230 5137 5243 5203 5207 5372 5186 5283 5252 5333 5197 5317 5182 5198 5258 5231 5160 5233 5150 5305 5222 5239 5220 5189 5205 5439 5298 5273 5442 5350 5502 5568 5626 5588 5628 5586 5628 5724 5827 5645 5607 5599 5685 5501 5506 5449 5514 5341 5347 5485 5330 5416 5300 5520 5485 5478 5508 5544 5485 5353 5574 5374 5472 5286 5386 5244 5330 5346 5297 5198 5383 5320 5350 5307 5287 5295 5136 5393 5148 5106 5337 5140 5180 5036 5198 5108 5088 5206 5168 5114 5225 5275 5336 5107 5208 5194 5141 5226 5182 5186 5014 5172 5089 5204 5294 5181 5164 5150 5257 5275 5178 5246 5150 5138 5230 5196 5205 5112 5170 5142 5117 5099 5025 5197 5156 5033 5102 5077 5145 5175 5144 5143 5264 5049 5063 5041 5120 5204 5055 5203 5168 5141 5058 5131 5126 5094 5054 5088 5071 5041 4997 4963 5074 5175 5220 5095 5038 5016 5148 4987 5102 5094 4967 5078 4956 5025 5036 5089 5097 5093 5079 5088 5118 5141 5052 5221 5006 5107 5004 5127 5059 5092 5132 5198 5166 4938 5116 4980 5122 5167 5033 5022 5158 5095 5200 5138 5112 5092 5163 5080 5165 5168 4962 5027 4905 5029 5134 5074 5034 5044 5055 5005 5048 5164 5352 5124 5063 5036 5102 5088 5085 5062 5132 5109 5002 5016 5020 5104 5121 5041 5266 5059 5187 5089 5165 5051 5090 5049 5086 5118 5040 5164 5073 5170 5111 4964 5085 5216 5121 4987 5220 5148 5054 5164 5016 5090 5155 5128 5240 5129 5204 5131 5333 5283 5235 5281 5367 5106 5186 5100 5207 5076 5136 5130 5153 5062 5203 5179 5000 4956 5075 5123 5071 5189 5202 5186 5282 5228 5205 5153 5177 5199 5087 5162 5150 5191 5229 5137 5184 5091 4939 5206 5046 5091 5005 5036 5100 5191 5235 4981 5272 5205 5089 5125 5144 5241 5255 5208 5132 5119 5186 5103 5075 5107 5010 5094 5068 5096 5139 5211 5114 5206 5173 5091 5139 5072 5102 5026 5185 5098 5102 5135 5274 5211 5230 5162 5203 5217 5259 5089 5244 5217 5285 5133 5100 5275 5057 5283 5200 5108 5119 5194 4971 5132 5164 5240 5040 5169 5279 5027 5237 5175 5122 5217 5258 5203 5110 5180 5169 5177 5090 5125 5034 5187 5111 5197 5269 5333 5207 5313 5374 5424 5491 5425 5534 5413 5535 5452 5433 5520 5331 5286 5232 5310 5293 5156 5129 5139 5203 5214 5191 5241 5294 5168 5326 5276 5329 5362 5299 5430 5334 5243 5089 5245 5201 5236 5074 5157 5086 5071 5163 5209 5032 5111 5004 5079 5215 5137 5077 5126 5163 5024 5123 4970 5118 5002 5106 5111 5091 4953 5108 5062 5177 5151 5108 4942 5081 5028 4927 5042 5064 5097 5134 5068 5067 5111 5150 5070 5132 5164 4987 4975 5068 4941 4983 5148 5088 5165 5026 5188 5008 5130 5094 5134 5058 5088 5194 5011 5247 5099 4994 5109 4942 5070 5112 5087 5083 4953 5122 5057 4987 5099 5026 5079 5140 5078 5003 5126 4941 5153 5030 5004 5079 5075 4972 5084 4995 5092 5057 5039 5156 5076 5127 5077 5151 5071 5132 4979 5066 5181 5059 5185 5128 4930 5101 5080 5092 5079 5215 5133 5136 5310 5112 5128 5277 5291 5395 5360 5264 5299 5285 5387 5403 5165 5260 5247 5117 5188 5119 5217 5142 5191 5180 5150 5156 5276 5286 5247 5271 5482 5266 5293 5361 5321 5276 5245 5216 5235 5217 5260 5194 5216 5046 5171 5142 5179 5295 5083 5314 5287 5176 5120 5186 5413 5153 5255 5315 5301 5372 5231 5374 5358 5295 5384 5474 5303 5294 5221 5144 5170 5138 5068 5162 5286 5084 5216 5260 5248 5131 5379 5384 5306 5290 5438 5417 5327 5438 5305 5284 5220 5225 5292 5157 5115 5174 5193 5203 5114 5116 5179 5121 5184 5179 5163 5321 5159 5228 5295 5216 5177 5132 5257 5123 5218 5177 5069 5145 5090 5198 5124 5231 4997 5164 5168 5245 5188 5278 5169 5152 5183 4972 5187 5201 5045 5193 5107 5037 5145 5212 5154 5051 5170 5126 5210 5215 5151 5095 5139 5207 5121 5225 5317 5165 5319 5119 5189 5188 5227 5195 5295 5190 5210 5158 5113 5165 5202 5199 5135 5356 5266 5274 5280 5246 5283 5322 5131 5259 5212 5243 5077 5065 5304 5200 5204 5281 5262 5103 5168 5073 5053 5203 5275 5108 5118 5102 5160 5146 5105 5127 5136 5075 5058 5169 5100 5239 5113 5150 5130 5124 4910 5100 5016 4943 5152 5081 5138 4995 5064 5068 5093 5150 5099 5132 5031 5109 5117 4990 5027 5230 5137 5050 5217 5025 5138 5057 5192 5087 5005 5168 5014 5110 5170 5117 5002 4977 5022 4991 4987 5162 5011 5169 5077 5216 5115 5112 5124 5161 5069 5007 5057 5234 5144 5160 5102 5042 4971 4974 5044 4922 5131 5088 4992 5015 5025 5070 5052 5007 5130 5136 5176 5065 5126 5090 5056 5140 4959 5101 4953 5107 5067 5028 5057 5026 5082 5015 4975 4983 5050 5058 5013 5026 5095 5000 5020 5103 5092 5139 5118 5185 5074 5091 5032 5087 5144 5176 5100 5162 5234 5184 5231 5262 5161 5188 5125 5211 5119 5237 5253 5126 5196 5184 5304 5335 5309 5290 5511 5346 5448 5305 5430 5483 5353 5506 5359 5342 5509 5463 5504 5476 5588 5737 5798 6060 6522 6804 7151 7549 7895 7855 7431 6889 6557 6312 5838 5620 5507 5573 5582 5386 5461 5283 5450 5512 5498 5419 5648 5810 6034 6222 6287 6389 6391 6303 6060 5786 5744 5560 5358 5297 5326 5291 5198 5189 5157 5008 5036 5114 5004 5060 5192 4974 5103 5003 5111 5141 5078 4978 5090 4960 5111 5058 4997 5020 5022 5008 5173 5003 5098 5054 5088 5059 5107 5096 5055 5101 5051 5033 5139 4880 5048 5205 4973 5056 4963 5173 5124 5060 5174 4918 4973 5140 4990 5097 4997 5099 5021 5057 5074 5059 5108 5185 5114 5015 5061 4986 5055 5021 5030 5056 4931 5050 5074 4967 5006 5127 5101 5064 5089 5132 4976 5054 5089 5062 5095 4968 5052 5224 5101 4983 5043 5044 5155 5072 5127 5224 5066 5191 5069 5013 5160 5132 5075 5173 5012 5141 5077 5011 5220 5194 5156 5085 5260 5237 5129 5274 5287 5451 5363 5403 5507 5483 5492 5360 5463 5420 5400 5300 5343 5147 5246 5193 5111 5166 5232 5332 5282 5303 5253 5250 5436 5415 5395 5564 5543 5435 5470 5474 5401 5508 5461 5341 5333 5340 5230 5190 5178 5246 5152 5122 5051 5144 5175 5160 5125 5289 5181 5375 5051 5069 5207 5205 5271 5318 5022 5184 5127 5203 5237 5186 5300 5148 5217 5175 5130 5161 5050 5100 5084 5066 5104 5023 5036 5126 5097 5003 5068 5085 5064 5065 5042 5084 5060 5014 5261 4979 5021 5089 5128 4908 5135 4970 4959 4861 5038 4927 4951 4977 5134 5105 5079 5075 5004 5147 5111 4969 5013 5052 5112 5024 4877 5034 4980 5050 5128 5197 4937 5001 5131 4987 5069 4930 5072 5051 5031 5120 5017 5127 5026 5055 5036 5016 5111 5099 5031 4982 5050 5049 4911 5030 5015 5118 5018 5148 4915 5066 5085 5104 5205 5131 4980 5147 5167 5178 5147 5117 5191 5136 5219 5066 5047 5062 5172 5212 5099 5208 5257 5331 5387 5340 5484 5506 5533 5507 5533 5415 5297 5271 5100 5157 5181 5239 5122 5185 5204 5247 5110 5236 5115 5190 5117 5278 5184 5310 5341 5325 5185 5183 5293 5243 5251 5145 5271 5251 5153 5156 4996 5118 5183 5070 5007 5089 5099 5084 5195 5040 5021 5125 5127 5011 5050 4929 5160 5080 5119 5072 5153 5109 5172 5285 5174 5297 5221 5325 5220 5212 5304 5234 5378 5297 5198 5279 5217 5182 5198 5084 5239 5058 5115 5085 5055 5194 5056 5089 5231 5095 5138 5182 5155 5189 5306 5094 5204 5046 5170 5156 5201 5126 5158 5114 5206 5089 5085 5065 5059 5039 5156 5146 5080 5082 5023 5211 5092 5107 5016 5098 5242 5139 5227 5150 5108 5071 5091 5051 5055 5146 4879 5067 4920 4984 5042 5090 4996 4956 4851 4951 5029 5044 5066 4921 5102 4896 5162 4931 5040 4943 4992 5036 5059 4965 5128 4982 5026 4913 5061 5048 5025 5008 4989 4979 4973 5034 5044 5028 5016 4951 5061 5064 4945 5027 4969 5003 4960 5084 5100 5002 4993 5091 4990 4915 4951 4938 4971 5018 4985 4899 5007 4982 5057 4925 5066 5134 5071 4907 5095 4932 4969 5083 4870 5035 4939 5002 4938 5050 5053 5128 4956 4946 4883 4869 4942 5033 4950 4993 5055 4983 5099 5021 5044 4898 4933 4940 5022 5023 4927 5045 4998 5010 5033 4899 4955 5040 4900 5094 4911 5058 4887 5042 4873 5070 5134 5006 4936 5016 4989 4984 4978 4979 4976 4972 5054 4979 5040 5029 5017 4955 4964 5047 4878 5005 4964 4926 4922 5102 4996 4962 5052 5020 5010 4979 4996 4985 5125 5086 5046 4988 5079 4957 5007 5056 5088 5013 5083 5052 5038 5005 5048 4937 5061 4924 4937 5095 5005 4863 5004 4958 5018 4971 4852 4922 4934 5137 5062 4919 4983 5016 5061 5103 4984 5020 4989 4981 4856 5033 4965 4933 4963 5008 5143 5138 5103 4952 4983 4861 5030 5022 5087 5003 4904 4995 4973 5073 5102 5038 4988 5033 5067 5089 5066 5201 5075 5037 5029 5037 5117 5058 5056 5083 5018 4957 5037 5065 5028 5207 5120 4891 5087 5026 5018 5142 5134 5121 5060 5083 5203 5201 5185 5045 5120 5142 5106 5099 5105 5042 5089 5109 5044 5093 5143 5065 4983 5073 5164 5197 5073 5265 5112 5212 5200 5123 5183 5112 5083 5263 5308 5225 5348 5133 5316 5413 5493 5517 5362 5525 5549 5593 5487 5571 5458 5427 5314 5328 5339 5247 5208 5246 5306 5227 5275 5168 5114 5129 5152 5217 5258 5280 5277 5367 5311 5234 5278 5234 5376 5193 5297 5198 5193 5108 5101 5125 5134 5240 5209 5151 5303 5067 5151 5091 4939 5140 5209 5072 4955 5067 5104 5045 5207 5049 4976 4987 5071 5019 5092 5038 4961 4956 5110 4970 4875 5150 4979 5024 4987 4965 5066 4980 4920 5054 5053 5156 4916 4986 4975 5003 4986 5032 5055 4984 4931 4983 5033 5046 5039 4990 5059 4950 5128 4883 5082 4967 4976 4884 5015 4999 4892 4913 4960 4816 5008 4944 5086 5007 5017 4976 5078 4988 4935 4928 4976 5026 4987 5014 5005 4981 5088 4977 4978 4888 4957 5085 5003 5046 5066 4966 5031 4941 4994 5080 5070 4939 4919 4849 4921 5040 4913 5057 5028 4994 4977 5091 5109 4946 5053 4925 4992 5042 4911 4983 5057 5040 4931 5045 5024 4964 4919 4870 4925 4994 4963 5007 4943 5157 5048 4997 4904 5014 5057 5159 5030 4993 5072 5090 5071 4915 4973 4977 4994 4909 4944 5048 5051 5000 4958 5025 5038 4880 4938 5020 4980 5012 4929 4882 4999 4984 4874 4963 5007 4965 5000 5020 4909 4950 5024 4890 4871 5009 5054 4863 5003 4983 4973 4851 4912 4911 5046 5013 4985 4921 4933 4880 4937 5061 4986 4907 4927 4934 5011 4885 4943 4898 5026 4830 4899 5011 5079 4895 4920 4910 4949 4835 4991 5065 4899 5090 4995 4982 4895 4901 4956 5015 4972 4968 4926 4798 4980 4983 4907 4957 5027 5018 5004 4922 4986 5010 5125 5017 5027 4919 4943 5041 5051 5098 5044 5041 5054 4964 4911 5063 5063 4986 5085 5006 4970 5011 5010 5047 5017 4965 5049 4934 5109 4971 4935 5156 4997 5071 5043 5004 5048 5033 5046 4989 5116 4954 5027 5040 4961 4987 4905 5105 4978 5028 5053 4893 4952 4961 5008 4977 4979 4905 5054 5014 4864 4892 4939 5177 4936 4953 5066 4931 5086 4966 5028 5004 5055 4982 5086 4962 5007 4974 5002 5022 5044 4963 5121 5064 4950 4908 4918 4951 4920 5130 5060 5065 4935 4979 5018 5001 5025 5037 4988 5120 5017 4984 5035 5041 4917 4984 4983 4882 4977 5031 5023 5011 5183 5032 5038 5077 5006 5116 5040 4962 4972 5015 4900 5080 5025 5050 4936 5004 5013 5052 4860 5017 4998 4827 4916 5047 4975 4967 5077 4912 5016 4946 5096 5038 5031 5050 5024 4970 5007 4906 4915 5003 4988 4951 5068 4987 5039 4911 5183 5031 5086 4988 5067 5162 5071 5143 5040 5072 5174 5069 5141 5314 5037 5022 5185 5184 4992 5132 5281 5116 5290 4980 5182 5078 5255 5113 5180 5122 5296 5116 5174 5326 5283 5212 5351 5265 5160 5441 5314 5544 5421 5575 5403 5528 5685 5505 5525 5610 5463 5554 5387 5288 5418 5326 5434 5201 5206 5260 5264 5068 5168 5222 5123 5279 5256 5213 5202 5241 5327 5353 5191 5366 5239 5337 5255 5252 5314 5199 5223 5218 5247 5213 5082 5249 5137 5027 5132 5083 5153 4966 5125 5007 4965 5096 5022 5060 5206 5082 5053 5000 5133 5048 4979 4992 4988 5103 5077 4968 5052 5021 4932 4960 5052 4943 4990 5014 5053 5026 4870 4986 4898 4990 5057 5020 4961 5011 5028 4997 5095 4882 5038 4978 4948 4830 5001 4974 5079 4968 4950 5006 5037 5013 5135 4967 5009 4936 4960 4982 4986 5046 4957 5036 5006 5081 5121 5155 5026 5010 4958 5037 4960 4862 5097 5034 5021 5041 5023 4979 5019 5019 5054 5021 5022 4986 5020 4847 4995 4978 4970 4931 5095 4902 4932 5037 5004 5068 5019 4935 4931 4954 5011 5009 5032 5058 5062 4947 5048 5096 4987 4917 5025 5177 5019 5006 5186 5087 4978 5098 5031 5038 5012 4971 5013 4964 4947 4845 5056 5001 4975 4930 4978 5015 5059 5113 4965 4935 4998 4967 5022 5062 4969 4943 4929 4983 4955 4904 4987 5059 4934 4879 4928 5024 4970 4964 5027 4992 4950 4947 4987 5014 5076 5030 5023 5043 5067 4992 5020 4913 4949 5029 4987 4896 4902 4915 4886 5052 5079 5021 5043 4840 4938 4811 4960 5034 5026 4943 5080 5038 4992 4866 4997 4992 5048 4912 4939 5045 4964 4995 4987 5063 5040 4923 4903 4981 4905 5031 5031 5011 4912 5084 4944 5013 4902 4999 4846 4861 5082 5127 5056 5045 4988 4989 5036 5079 5055 4950 5095 5051 5105 4876 4870 5015 4980 5012 5115 4842 5046 4849 4959 4875 5018 4985 4982 4912 5004 5021 4926 4997 4908 4870 4942 4898 4982 4991 4796 4882 5016 5019 4925 5003 4886 5003 4914 4940 5035 4975 4909 4915 4898 4936 4919 5001 5055 5000 4873 4943 4875 4960 4966 4987 4840 5008 4901 4907 4801 4955 4828 4993 4829 4886 5020 4841 4955 5009 5012 4975 4952 5012 5020 4775 4941 4954 5017 4984 4986 4985 4985 4979 4995 4982 4822 4867 4857 4949 5010 4973 5017 4918 4823 4925 4968 4951 4948 4989 5011 4993 5003 4853 4903 5059 4950 5025 4837 4994 4895 4904 5040 4909 4934 4965 4792 4840 4988 4858 4847 4942 4874 5064 5120 4936 4863 4858 5068 4983 5013 4915 5035 5109 4914 4942 5025 4960 4911 5039 4920 5030 5072 4958 5020 4924 4941 4830 5004 4912 5008 4953 4933 4922 4966 4907 4968 4705 4899 4957 5016 4879 5027 5010 4984 4967 4961</counts>
			</dataPoints>
		</scan>
	</xrdMeasurement>
</xrdMeasurements>