File: dataset/precursor_mixture/Cr2O3_Fe3O4_Y2O3.12-min.xrdml
<?xml version="1.0"?>
<xrdMeasurements xmlns="http://www.xrdml.com/XRDMeasurement/2.2" xmlns:xsi="http://www.w3.org/2001/XMLSchema-instance" xsi:schemaLocation="http://www.xrdml.com/XRDMeasurement/2.2 http://www.xrdml.com/XRDMeasurement/2.2/XRDMeasurement.xsd" status="Completed" recordIdentifier="{50B6A67F-207B-422D-A97A-906BCCEDF54E}">
	<comment>
		<entry/>
	</comment>
	<sample type="To be analyzed">
		<id></id>
		<name></name>
		<preparedBy></preparedBy>
	</sample>
	<xrdMeasurement measurementType="Scan" status="Completed" sampleMode="Reflection">
		<usedWavelength intended="K-Alpha 1">
			<kAlpha1 unit="Angstrom">1.5405980</kAlpha1>
			<kAlpha2 unit="Angstrom">1.5444260</kAlpha2>
			<kBeta unit="Angstrom">1.3922500</kBeta>
			<ratioKAlpha2KAlpha1>0.5000</ratioKAlpha2KAlpha1>
		</usedWavelength>
		<incidentBeamPath>
			<radius unit="mm">145.00</radius>
			<xRayTube id="1010048" name="Empyrean Cu LFF HR (9430 033 7310x) DK437873">
				<tension unit="kV">40.0</tension>
				<current unit="mA">15.0</current>
				<anodeMaterial>Cu</anodeMaterial>
				<focus type="Line">
					<length unit="mm">12.0</length>
					<width unit="mm">0.4</width>
					<takeOffAngle unit="deg">6.0</takeOffAngle>
				</focus>
			</xRayTube>
			<filter id="20010004" name="Beta-filter Nickel">
				<material>Ni</material>
				<thickness unit="mm">0.020</thickness>
			</filter>
			<sollerSlit id="21010002" name="Soller slits 0.04 rad.">
				<opening unit="rad">0.0400</opening>
			</sollerSlit>
			<mask id="22031000" name="Fixed mask 13 mm">
				<width unit="mm">9.00</width>
			</mask>
			<divergenceSlit id="22120001" name="Divergence slit 1°" xsi:type="fixedDivergenceSlitType">
				<distanceToSample unit="mm">50.00</distanceToSample>
				<height unit="mm">1.52</height>
			</divergenceSlit>
		</incidentBeamPath>
		<beamKnife id="29030100" name="Beam knife low"/>
		<sampleMovement xsi:type="spinningSampleMovementType">
			<spinnerRevolutionTime unit="seconds">1.0</spinnerRevolutionTime>
		</sampleMovement>
		<diffractedBeamPath>
			<radius unit="mm">145.00</radius>
			<antiScatterSlit id="22090040" name="AS slit 9 mm" xsi:type="fixedAntiScatterSlitType">
				<height unit="mm">9.00</height>
			</antiScatterSlit>
			<sollerSlit id="21020003" name="Large Soller slits 0.04 rad.">
				<opening unit="rad">0.0400</opening>
			</sollerSlit>
			<filter id="20030001" name="Large beta-filter Nickel">
				<material>Ni</material>
				<thickness unit="mm">0.020</thickness>
			</filter>
			<detector id="7010019" name="PIXcel1D-Medipix3 detector" xsi:type="rtmsDetectorType">
				<phd unit="keV">
					<lowerLevel>4.0</lowerLevel>
					<upperLevel>11.3</upperLevel>
				</phd>
				<mode>Scanning</mode>
				<activeLength unit="deg">5.020</activeLength>
			</detector>
		</diffractedBeamPath>
		<scan appendNumber="0" mode="Continuous" scanAxis="Gonio" status="Completed">
			<header>
				<startTimeStamp>2024-03-22T21:30:13-07:00</startTimeStamp>
				<endTimeStamp>2024-03-22T21:42:40-07:00</endTimeStamp>
				<author>
					<name>Instrument</name>
				</author>
				<source>
					<applicationSoftware version="1.6 (94)">PANalytical Aeris Instrument Suite</applicationSoftware>
					<instrumentControlSoftware version="3.0.0 20211014">AERIS</instrumentControlSoftware>
					<instrumentID>2879380</instrumentID>
				</source>
			</header>
			<dataPoints>
				<positions axis="2Theta" unit="deg">
					<startPosition>9.99043322</startPosition>
					<endPosition>100.09495370</endPosition>
				</positions>
				<positions axis="Omega" unit="deg">
					<startPosition>4.99521661</startPosition>
					<endPosition>50.04747685</endPosition>
				</positions>
				<commonCountingTime unit="seconds">18.249</commonCountingTime>
				<counts unit="counts">5479 5495 5485 5432 5430 5307 5411 5409 5427 5481 5493 5398 5435 5367 5452 5316 5395 5435 5411 5427 5366 5333 5321 5420 5461 5459 5351 5346 5386 5391 5372 5373 5333 5513 5372 5383 5324 5307 5290 5272 5324 5305 5474 5404 5315 5427 5274 5186 5326 5348 5251 5334 5282 5418 5295 5329 5331 5319 5309 5250 5310 5145 5296 5224 5278 5334 5184 5301 5179 5319 5282 5180 5276 5231 5373 5186 5140 5174 5145 5268 5237 5314 5245 5075 5200 5236 5211 5230 5150 5175 5216 5135 5199 5187 5114 5235 5225 5328 5094 5089 5181 5139 5098 5126 5118 5253 5184 5084 5029 5094 5107 5029 5170 5157 4935 5074 5095 5106 5136 5254 5134 5035 5065 5033 4990 5203 5119 5028 5036 4983 5017 5057 5175 5003 4946 4971 4967 5088 5053 5147 5030 4975 5049 4947 4981 4993 5080 5157 5042 5103 4967 5153 4984 5102 4979 5025 5067 5124 5108 5041 5040 5025 5026 4852 5233 5016 5162 5009 5009 4953 4897 4914 4982 5034 4936 4978 4971 4844 5052 4833 4848 5072 5083 4986 4981 4913 4928 4981 4954 4970 5026 4894 5132 5060 5019 4943 4846 4835 5134 5067 4937 4972 4798 4962 4942 5033 4958 5005 4933 4892 4866 4951 4823 4933 4973 5039 5005 4849 4871 4902 4854 4782 4942 4981 5003 4865 4870 4792 4925 4927 4875 4950 4993 4872 4943 4862 5013 4874 4787 4919 4840 4867 4917 4812 4805 4967 4842 4946 4877 4876 4807 4798 5014 4948 4882 4938 4785 4767 4790 4783 4979 4817 4873 4920 4808 4872 4736 4963 4811 4880 5022 4712 4876 4905 4865 4878 4873 4770 4696 4786 4768 4680 4817 4700 4775 4827 4706 4827 4800 4901 4734 4855 4724 4807 4769 4838 4788 4824 4902 4728 4841 4728 4663 4668 4746 4794 4818 4674 4777 4928 4844 4782 4890 4689 4721 4831 4889 4788 4734 4803 4873 4752 4734 4841 4793 4856 4754 4747 4745 4788 4780 4794 4926 4854 4850 4768 4733 4983 4914 4701 4716 4746 4770 4743 4889 4734 4691 4710 4789 4954 4808 4683 4831 4741 4856 4839 4832 4965 4575 4809 4812 4735 4863 4735 4879 4825 4830 4690 4816 4750 4779 4736 4837 4764 4665 4660 4699 4725 4796 4804 4843 4714 4685 4809 4798 4750 4957 4634 4834 4715 4736 4726 4765 4756 4792 4642 4741 4674 4740 4628 4862 4824 4795 4725 4731 4762 4710 4817 4727 4805 4797 4725 4695 4728 4774 4832 4814 4760 4830 4910 4805 4759 4732 4826 4704 4718 4776 4815 4707 4672 4741 4827 4890 4793 4791 4860 4610 4667 4690 4774 4726 4788 4816 4783 4809 4887 4846 4850 4739 4843 4777 4827 4885 4805 4728 4754 4734 4796 4766 4767 4839 4660 4777 4885 4749 4897 4684 4664 4731 4613 4790 4801 4660 4683 4724 4767 4676 4918 4696 4750 4698 4687 4800 4709 4800 4760 4730 4700 4812 4747 4726 4757 4736 4848 4828 4756 4799 4699 4857 4660 4857 4826 4882 4710 4775 4702 4764 4910 4845 4769 4643 4663 4825 4678 4752 4743 4931 4656 4848 4801 4725 4771 4708 4814 4787 4781 4811 4816 4879 4880 4920 4884 4726 4963 4778 4873 4792 4846 4761 4834 4759 4820 4856 4897 4774 4746 4706 4776 4668 4829 4892 4801 4750 4727 4866 4872 4798 4837 4920 4787 4850 4793 4897 4992 4670 4872 4865 4745 4666 4880 4829 4765 4749 4821 4894 4735 4937 4771 4845 4733 4750 4764 4831 4750 4747 4867 4782 4907 4792 4691 4824 4891 4825 4872 4869 4890 4773 4843 4766 4724 4882 4754 4759 4932 4903 4868 4845 4798 4794 4833 4870 4838 4863 4879 4889 4795 4823 5053 4921 4766 4733 4940 4916 4849 4915 4929 4979 4842 4924 4842 4843 4765 4913 4808 4800 4788 4784 4912 4767 4868 4767 4959 4932 4848 4772 4804 4905 4882 4788 4803 4916 4841 4846 4838 4972 4778 4888 4915 4895 4788 4928 4992 4826 4964 4879 5052 4815 4948 4756 4933 4916 4802 4875 4908 4878 4909 4911 4852 4818 4869 4773 4793 4944 4930 4906 4863 4854 4829 4805 4800 4859 4719 4897 5080 4875 4912 4942 4851 5099 4698 4767 4871 4891 4776 4980 4938 4773 4948 4916 4880 4922 4912 4911 4834 4979 4843 4714 4862 4885 4893 4819 4805 4891 4930 4941 4812 4904 4874 4851 4882 4942 4950 4939 4912 4951 4888 4917 4913 4780 4866 5010 4908 4945 4975 5050 5013 4916 4944 4982 5067 4940 5042 5160 5149 5061 5244 5205 5240 5393 5373 5358 5455 5430 5374 5512 5405 5384 5410 5313 5328 5147 5227 5213 5126 5163 5108 4990 5007 4917 4911 4910 4948 5026 4853 4799 4987 4945 4848 4905 4983 4937 4811 4833 4769 4882 4818 4782 4890 4840 4886 4846 4860 5014 4908 4784 4934 4997 4848 4769 4818 4925 4912 4943 4829 4866 4816 4872 4723 4959 4888 4772 4925 4891 4996 4825 4889 5007 4770 4765 4824 4872 4850 4979 4808 4870 4813 4893 4742 4803 4850 4761 4822 4793 4805 4779 4758 4860 4797 4766 4775 4869 4859 4820 4788 4853 4776 4797 4776 4751 4929 4769 4810 4810 4828 4858 4827 4840 4936 4706 4951 4808 4897 4895 4779 4834 4939 4812 4780 4693 4727 4745 4758 4947 4750 4856 4728 4862 4928 4807 4768 4837 4856 4948 4807 4907 4830 4762 4817 4792 4814 4790 4767 4868 4794 4882 4840 4943 4916 4865 4972 4805 4906 4881 4901 4772 4770 4932 4860 4986 4796 4908 4826 4897 4794 4916 4896 4882 4803 4837 4907 4755 4934 4931 4860 5002 4972 5015 4925 5047 5084 5066 5007 4959 5058 5063 4993 5181 4983 5280 5146 5205 5225 5321 5334 5458 5514 5640 5771 5901 5750 5946 6080 6299 6453 6577 6590 6789 6840 6834 6824 6693 6528 6366 6169 6199 5862 5775 5476 5353 5446 5219 5122 5109 5027 5063 4959 5013 5013 4951 4999 5073 5021 4940 4948 5091 4780 5000 4939 4953 4921 4879 4836 4853 4711 4866 4829 4952 4771 4826 4875 4749 4701 4759 4827 4840 4803 4915 4849 4777 4825 4967 4890 4853 4739 4771 4771 4623 4902 4743 4887 4889 4814 4808 4832 4869 4912 4832 4914 4748 4894 4875 4824 4846 4864 4893 4821 4813 4859 4910 4739 4866 4716 4818 4775 4851 4841 4833 4635 4885 4810 4743 4798 4710 4843 4753 4795 4731 4831 4820 4749 4835 4819 4753 4870 4967 4803 4788 4764 4856 4651 4837 4700 4726 4811 4907 4891 4698 4852 4862 4798 4765 4822 4769 4887 4876 4741 4655 4741 4729 4741 4846 4838 4725 4757 4670 4821 4864 4863 4828 4754 4993 4836 4805 4739 4894 4737 4849 4756 4756 4778 4731 4893 4838 4928 4795 4837 4777 4736 4886 4784 4905 4771 4819 4774 4783 4687 4801 4621 4722 4748 4810 4767 4821 4718 4768 4850 4753 4791 4826 4860 4735 4837 4733 4632 4865 4711 4699 4854 4747 4792 4785 4781 4885 4799 4749 4804 4539 4860 4739 4690 4697 4738 4806 4680 4775 4825 4718 4795 4788 4749 4811 4806 4882 4746 4755 4720 4690 4711 4751 4788 4852 4756 4955 4752 4716 4844 4791 4938 4705 4926 4710 4669 4636 4848 4767 4717 4792 4791 4913 4777 4800 4760 4689 4827 4691 4636 4839 4755 4786 4898 4684 4774 4855 4818 4731 4756 4850 4732 4833 4710 4860 4733 4897 4745 4830 4781 4781 4742 4704 4761 4663 4809 4704 4605 4777 4785 4734 4718 4818 4833 4831 4861 4808 4830 4800 4807 4929 4675 4853 4768 4895 4723 4767 4734 4802 4806 4800 4835 4890 4789 4745 4875 4776 4834 4825 4886 4861 4836 4736 4908 4709 4918 4687 4810 4862 4733 4705 4786 4591 4971 4828 4874 4647 4842 4862 4659 4701 4882 4891 4823 4879 4810 4814 4689 4748 4870 4774 4896 5015 4911 4839 5005 4882 4886 4964 4975 5178 5114 5292 5329 5421 5365 5668 5756 5812 5950 6245 6402 6700 7062 7452 7330 7806 8164 8460 8551 8664 8706 8615 8159 7914 7661 7226 6814 6694 6142 5790 5655 5591 5176 5256 5097 5144 4928 5006 4974 4968 4938 4885 4900 4883 4933 4744 4722 4811 4947 4788 4759 4837 4827 4807 4756 4729 4652 4788 4903 4694 4742 4815 4686 4887 4655 4708 4678 4711 4764 4673 4632 4773 4684 4807 4730 4791 4614 4761 4736 4783 4686 4707 4692 4740 4677 4815 4607 4758 4869 4735 4820 4617 4645 4818 4739 4767 4661 4685 4732 4625 4680 4748 4844 4862 4701 4639 4588 4629 4801 4827 4656 4671 4633 4750 4673 4559 4695 4861 4687 4675 4730 4787 4725 4628 4692 4670 4656 4710 4749 4708 4754 4728 4822 4611 4757 4833 4734 4768 4748 4695 4792 4740 4718 4716 4876 4693 4680 4708 4685 4711 4578 4749 4799 4685 4664 4756 4707 4740 4896 4681 4672 4799 4645 4762 4790 4605 4711 4721 4776 4770 4691 4799 4614 4754 4763 4799 4709 4728 4727 4859 4947 4914 4832 4690 4706 4908 4864 4804 4742 4685 4817 4801 4666 4676 4829 4808 4669 4723 4573 4671 4788 4669 4812 4621 4691 4799 4751 4704 4652 4733 4627 4717 4657 4677 4650 4534 4800 4719 4704 4749 4568 4676 4691 4730 4595 4670 4624 4705 4640 4639 4661 4740 4698 4626 4639 4849 4682 4778 4769 4761 4550 4710 4642 4764 4556 4790 4635 4798 4651 4662 4650 4705 4741 4531 4779 4792 4812 4826 4704 4634 4706 4611 4685 4694 4663 4729 4605 4663 4671 4738 4592 4697 4508 4769 4694 4562 4652 4670 4626 4706 4772 4757 4748 4713 4571 4664 4488 4609 4582 4683 4677 4617 4666 4842 4758 4712 4604 4784 4794 4529 4604 4737 4585 4667 4685 4573 4640 4667 4748 4621 4667 4838 4612 4711 4526 4779 4629 4676 4701 4686 4629 4620 4710 4656 4798 4613 4815 4636 4703 4685 4750 4767 4710 4700 4704 4794 4856 4816 4732 4609 4690 4713 4691 4628 4649 4656 4680 4682 4708 4651 4747 4732 4757 4758 4758 4815 4843 4811 4706 4708 4796 4741 4814 4864 4794 4735 4969 4794 4916 4759 4748 4716 4858 4863 4764 4844 4910 4828 4844 4862 4846 4877 4782 4917 4931 4838 4873 5008 4815 4938 4895 5093 4865 5045 4856 4950 5086 5120 4919 5000 5076 5259 5128 5201 5106 5205 5188 5203 5075 5200 5287 5367 5402 5392 5372 5482 5352 5486 5627 5830 5813 5923 6008 6140 6253 6459 6608 6946 7224 7555 8029 8439 8804 9425 10144 10950 11967 12798 14088 14995 16749 18074 19323 20604 21842 23284 24161 24509 24322 23601 22526 21163 19914 18741 17197 15863 14619 13172 11517 10562 9426 8672 7946 7531 7116 6685 6651 6348 6179 6000 5979 5926 5839 5686 5645 5482 5458 5431 5399 5360 5362 5365 5444 5162 5219 5180 5092 5079 5070 5022 5089 4966 4974 5028 4966 4874 4907 5072 4884 4974 5088 4966 5055 5079 4986 4930 4980 4972 5037 5023 5060 5008 5196 5066 5184 5256 5197 5232 5285 5380 5479 5556 5730 5753 6148 6244 6525 6718 7089 7226 7310 7420 7388 7445 7545 7408 7404 7166 6993 6826 6677 6555 6312 6036 6127 5832 5608 5509 5545 5223 5303 5258 5100 5049 4967 5051 4974 5109 5004 4982 4951 4838 4876 4784 4832 4784 4751 4832 4789 4876 4856 4780 4721 4841 4812 4709 4721 4605 4786 4691 4837 4794 4734 4509 4829 4725 4801 4757 4709 4791 4483 4620 4783 4774 4567 4638 4748 4777 4720 4714 4609 4616 4577 4618 4542 4815 4694 4579 4627 4628 4627 4724 4642 4685 4699 4653 4675 4665 4645 4738 4533 4824 4841 4754 4518 4569 4733 4752 4531 4695 4699 4643 4748 4505 4645 4738 4772 4751 4627 4481 4643 4730 4650 4486 4596 4641 4747 4622 4597 4738 4602 4719 4703 4684 4615 4698 4465 4604 4728 4590 4623 4531 4762 4745 4880 4781 4596 4712 4609 4717 4615 4726 4678 4546 4676 4735 4713 4545 4585 4592 4611 4688 4605 4631 4602 4649 4726 4689 4535 4565 4650 4622 4645 4650 4472 4652 4576 4684 4741 4666 4642 4696 4693 4751 4696 4695 4640 4631 4772 4544 4704 4619 4766 4717 4589 4547 4668 4701 4498 4619 4548 4701 4639 4428 4579 4538 4723 4612 4568 4697 4646 4604 4605 4606 4616 4608 4621 4553 4633 4572 4638 4529 4552 4510 4648 4662 4615 4594 4625 4519 4796 4603 4625 4610 4733 4520 4564 4779 4562 4505 4582 4558 4583 4602 4514 4620 4838 4711 4532 4646 4570 4629 4646 4593 4621 4606 4632 4672 4684 4660 4567 4562 4678 4611 4708 4588 4661 4640 4725 4643 4736 4641 4664 4483 4666 4648 4695 4640 4627 4730 4805 4625 4787 4673 4645 4812 4632 4678 4740 4755 4808 4622 4778 4770 4726 4866 4688 4903 4871 4731 4746 4895 4754 4888 4872 4808 4801 4910 4877 4712 4972 5032 5053 5094 4926 4994 4970 5122 5166 5318 5418 5475 5599 5673 5950 6236 6353 6694 7060 7461 7819 8375 8830 9399 9948 10586 10777 10879 11012 10792 10429 10071 10038 9949 9789 9897 10066 9801 9732 9388 9705 9672 9681 9589 9715 9218 9019 8871 8502 8150 8092 7329 7326 7033 6826 6423 6167 5942 5662 5619 5420 5322 5185 5128 5278 5179 4964 4848 4972 4894 5012 4746 4783 4822 4845 4684 4753 4704 4933 4791 4741 4721 4889 4655 4744 4880 4668 4657 4711 4636 4679 4709 4714 4636 4710 4735 4611 4556 4678 4578 4691 4737 4621 4692 4656 4612 4624 4714 4653 4674 4717 4675 4726 4642 4625 4680 4605 4569 4694 4708 4571 4716 4560 4715 4653 4639 4724 4640 4652 4556 4682 4585 4746 4841 4713 4670 4680 4621 4739 4788 4734 4831 4647 4726 4665 4737 4566 4687 4765 4687 4729 4799 4808 4746 4750 4828 4808 4919 4912 4801 4939 4986 4893 4873 4767 4898 4985 4967 5035 5014 5095 5092 5367 5175 5381 5499 5516 5686 5785 6075 6163 6532 6748 7074 7610 8151 8795 9618 10124 10970 11818 12355 12906 13380 13527 13641 13349 13721 13295 12928 12744 12231 11767 11275 10728 10006 9539 9154 8637 8078 7672 7358 6858 6791 6489 6303 6051 5859 5903 5800 5818 5690 5547 5676 5423 5569 5542 5485 5559 5492 5614 5548 5505 5765 5645 5766 5800 5868 5855 5930 5869 5715 5820 5768 5687 5706 5782 5631 5455 5627 5493 5584 5649 5811 5848 6225 6213 6630 6745 7036 7590 7880 8187 8604 8767 9133 9331 9297 9022 8444 8183 7853 7770 7593 7186 7128 6838 6485 6105 5923 5844 5349 5273 5131 5106 5043 4929 4819 4768 4740 4774 4766 4694 4669 4653 4704 4689 4578 4702 4763 4532 4458 4627 4634 4662 4560 4550 4623 4640 4526 4706 4588 4580 4537 4546 4449 4626 4514 4551 4667 4647 4574 4520 4605 4645 4630 4579 4523 4661 4716 4653 4695 4652 4724 4683 4648 4657 4726 4756 4851 4982 5000 4902 5064 5055 5079 4903 4904 4987 4894 4981 4790 4889 4773 4809 4825 4669 4819 4748 4681 4598 4629 4633 4593 4600 4645 4549 4576 4499 4532 4521 4598 4568 4461 4501 4520 4588 4573 4516 4563 4529 4496 4540 4588 4553 4504 4505 4481 4397 4441 4526 4433 4455 4520 4440 4472 4477 4348 4547 4656 4425 4411 4551 4506 4491 4515 4467 4554 4489 4520 4691 4565 4514 4605 4561 4607 4597 4586 4511 4705 4648 4498 4713 4627 4694 4679 4610 4585 4594 4543 4607 4713 4685 4521 4659 4545 4622 4485 4329 4456 4577 4546 4545 4493 4450 4620 4543 4498 4563 4458 4524 4511 4363 4501 4449 4555 4496 4380 4504 4460 4410 4611 4448 4487 4369 4419 4441 4396 4382 4460 4507 4520 4334 4458 4474 4400 4396 4468 4449 4551 4443 4552 4390 4457 4511 4512 4340 4497 4469 4495 4464 4300 4408 4581 4451 4456 4484 4468 4463 4447 4372 4465 4420 4556 4373 4322 4410 4403 4425 4425 4543 4415 4501 4481 4487 4555 4385 4432 4424 4416 4533 4429 4550 4405 4402 4511 4433 4484 4454 4292 4438 4449 4469 4379 4622 4551 4388 4351 4384 4357 4451 4460 4370 4356 4344 4384 4398 4517 4366 4390 4422 4422 4489 4425 4449 4542 4405 4565 4521 4469 4482 4483 4416 4374 4483 4402 4515 4445 4374 4495 4415 4479 4453 4493 4484 4516 4593 4673 4580 4580 4633 4621 4661 4659 4711 4768 4712 4873 4779 4982 5151 5173 5227 5290 5304 5429 5462 5557 5756 5630 5900 5918 5801 5818 5614 5525 5591 5211 5354 5221 5185 5045 4992 5034 4931 4847 4790 4613 4728 4581 4495 4567 4505 4521 4521 4431 4508 4605 4518 4474 4405 4514 4472 4437 4363 4389 4428 4499 4453 4505 4395 4562 4464 4425 4456 4309 4438 4515 4375 4400 4334 4313 4344 4445 4528 4317 4380 4279 4293 4408 4408 4579 4486 4551 4511 4378 4382 4458 4429 4396 4426 4376 4473 4316 4416 4402 4431 4357 4455 4364 4444 4407 4477 4448 4240 4477 4481 4478 4517 4509 4470 4316 4513 4367 4402 4445 4433 4304 4362 4448 4438 4442 4568 4574 4433 4518 4497 4442 4402 4415 4417 4382 4332 4394 4317 4479 4418 4360 4353 4429 4443 4430 4411 4438 4555 4372 4396 4471 4551 4410 4604 4542 4629 4587 4462 4596 4618 4546 4620 4869 4684 4902 4962 4837 5097 5306 5441 5443 5748 5982 6043 6093 6096 5980 6043 6026 5715 5489 5660 5524 5475 5495 5327 5355 5186 5103 4995 4966 4928 4779 4761 4704 4809 4720 4771 4642 4599 4553 4601 4550 4699 4512 4512 4587 4576 4514 4591 4518 4497 4371 4381 4496 4461 4520 4537 4479 4340 4317 4479 4578 4381 4427 4399 4402 4320 4371 4418 4397 4396 4376 4412 4381 4304 4368 4459 4436 4388 4532 4305 4397 4440 4465 4407 4429 4388 4399 4428 4455 4541 4446 4439 4400 4313 4374 4499 4411 4311 4388 4440 4349 4474 4426 4482 4249 4419 4464 4379 4428 4407 4436 4541 4621 4284 4384 4429 4448 4403 4382 4406 4417 4435 4446 4365 4481 4458 4463 4462 4522 4549 4507 4489 4559 4379 4538 4367 4463 4497 4601 4561 4609 4563 4663 4833 4725 5016 4935 5096 5149 5362 5450 5600 5742 5800 6100 6095 6277 6229 6245 6308 6274 6275 6126 6125 6063 6157 5806 5898 5724 5717 5808 5609 5415 5530 5218 5259 5102 5067 4946 5055 4926 5007 4960 4931 5093 5096 5065 5170 5268 5410 5590 5574 5678 5641 5939 6108 6051 6034 6145 5979 5823 5628 5506 5477 5445 5451 5536 5531 5341 5158 5030 5003 4805 4722 4840 4597 4675 4596 4481 4351 4410 4576 4610 4515 4548 4417 4415 4519 4389 4388 4476 4442 4293 4354 4504 4492 4369 4424 4422 4508 4425 4399 4354 4384 4437 4471 4523 4450 4338 4385 4372 4405 4331 4533 4483 4368 4519 4521 4520 4559 4457 4629 4597 4541 4554 4637 4599 4659 4537 4618 4539 4562 4540 4581 4426 4498 4529 4624 4438 4541 4385 4388 4422 4479 4493 4325 4446 4257 4442 4387 4342 4389 4371 4304 4395 4351 4399 4261 4283 4297 4425 4458 4474 4289 4318 4447 4316 4321 4270 4292 4341 4366 4610 4529 4382 4301 4345 4450 4295 4386 4277 4370 4438 4328 4446 4350 4343 4274 4315 4349 4213 4221 4488 4379 4456 4332 4312 4330 4403 4345 4347 4257 4459 4289 4291 4306 4445 4330 4387 4410 4307 4245 4342 4341 4261 4289 4343 4440 4307 4436 4256 4372 4380 4342 4358 4327 4465 4376 4317 4246 4410 4351 4423 4414 4276 4460 4428 4287 4336 4310 4243 4377 4443 4340 4404 4408 4388 4435 4352 4504 4369 4339 4316 4465 4275 4311 4316 4312 4179 4515 4374 4443 4297 4313 4330 4305 4404 4411 4344 4227 4383 4397 4377 4298 4304 4353 4506 4269 4427 4292 4427 4363 4338 4242 4257 4367 4406 4349 4315 4394 4160 4331 4353 4305 4348 4286 4365 4507 4341 4340 4379 4260 4323 4346 4250 4422 4404 4300 4285 4443 4206 4347 4403 4277 4281 4341 4364 4352 4464 4259 4302 4269 4411 4318 4352 4408 4405 4308 4407 4354 4313 4395 4324 4282 4295 4331 4285 4282 4424 4438 4404 4405 4303 4351 4435 4357 4347 4250 4408 4345 4415 4427 4446 4367 4430 4496 4454 4420 4472 4427 4527 4556 4580 4564 4665 4536 4565 4869 4781 4829 4741 4950 4667 4696 4855 4627 4667 4515 4673 4635 4610 4524 4710 4744 4564 4550 4492 4608 4512 4484 4502 4486 4435 4480 4383 4569 4539 4584 4445 4452 4502 4395 4399 4197 4377 4348 4590 4419 4410 4434 4315 4335 4418 4336 4547 4397 4478 4336 4468 4510 4403 4413 4279 4485 4301 4467 4405 4410 4370 4266 4311 4553 4385 4379 4339 4383 4326 4347 4296 4370 4276 4260 4436 4388 4318 4377 4427 4284 4352 4399 4416 4343 4377 4405 4422 4375 4441 4462 4348 4517 4554 4284 4415 4408 4315 4471 4491 4414 4386 4512 4354 4382 4435 4485 4485 4458 4570 4546 4483 4404 4616 4637 4438 4567 4612 4672 4524 4606 4723 4610 4690 4639 4572 4759 4867 4866 4741 4846 4975 4983 5115 5135 5294 5193 5508 5589 5706 5837 6020 6422 6672 6948 7526 8003 8687 9290 10109 10928 11336 11908 12199 12163 12039 11448 11055 10510 9948 9496 9228 9329 9326 9188 9158 8972 8345 7962 7531 7015 6510 6262 5982 5616 5631 5372 5182 5185 5147 4936 4959 4978 4789 4704 4803 4713 4721 4596 4660 4646 4604 4740 4715 4681 4515 4509 4583 4732 4519 4428 4518 4412 4548 4512 4530 4520 4477 4492 4567 4431 4458 4393 4308 4468 4279 4341 4377 4349 4383 4379 4360 4493 4418 4384 4461 4455 4366 4397 4353 4371 4392 4240 4431 4491 4377 4336 4254 4285 4258 4290 4320 4288 4400 4318 4443 4363 4465 4352 4440 4356 4235 4372 4358 4340 4306 4384 4326 4393 4344 4425 4280 4237 4298 4404 4417 4283 4257 4367 4475 4507 4421 4448 4393 4507 4495 4336 4392 4464 4411 4334 4450 4460 4514 4488 4411 4451 4484 4435 4637 4478 4589 4610 4856 4713 4708 4996 5052 5072 5306 5515 5374 5552 5701 5754 5989 6254 6286 6620 6466 6492 6428 6209 6029 5898 5741 5589 5369 5665 5512 5523 5623 5512 5389 5269 5120 4883 4800 4800 4600 4597 4694 4557 4676 4623 4521 4390 4422 4377 4369 4370 4449 4518 4483 4420 4343 4412 4406 4383 4330 4275 4241 4364 4559 4341 4376 4258 4272 4347 4343 4387 4275 4349 4377 4390 4402 4313 4321 4156 4221 4287 4402 4321 4412 4365 4299 4378 4379 4405 4389 4226 4274 4346 4359 4365 4402 4353 4281 4347 4334 4321 4306 4330 4242 4189 4198 4406 4397 4191 4289 4299 4342 4209 4247 4231 4348 4372 4399 4460 4377 4316 4301 4365 4360 4316 4259 4386 4439 4298 4349 4422 4311 4360 4339 4307 4394 4364 4416 4337 4219 4239 4400 4212 4293 4271 4339 4295 4430 4319 4390 4285 4499 4358 4408 4361 4392 4199 4365 4313 4386 4380 4387 4266 4457 4349 4435 4339 4294 4386 4335 4293 4284 4295 4318 4389 4378 4394 4257 4399 4417 4331 4410 4281 4305 4265 4326 4176 4377 4241 4263 4368 4292 4432 4309 4316 4340 4318 4351 4277 4386 4334 4405 4341 4369 4381 4267 4422 4291 4198 4269 4304 4262 4283 4243 4365 4238 4324 4336 4324 4282 4311 4282 4268 4387 4210 4156 4260 4332 4235 4317 4371 4275 4203 4233 4272 4226 4233 4209 4346 4400 4280 4295 4330 4293 4345 4288 4425 4250 4376 4361 4316 4328 4362 4327 4400 4338 4437 4300 4328 4304 4367 4371 4367 4237 4277 4329 4279 4357 4452 4390 4576 4350 4311 4410 4431 4455 4435 4402 4546 4435 4386 4497 4499 4598 4596 4644 4785 4819 4961 5035 5025 5127 5249 5346 5404 5194 5515 5092 5264 5085 5129 5095 5183 5178 5162 5383 5325 5251 5360 5358 5176 5279 5066 5237 5200 5205 5084 5129 5177 4900 5123 5010 5050 4943 4836 4948 4857 4730 4833 4939 4792 4746 4634 4656 4644 4658 4626 4634 4568 4551 4429 4505 4540 4546 4489 4446 4476 4420 4443 4434 4418 4625 4434 4388 4386 4386 4339 4319 4355 4297 4341 4328 4404 4377 4346 4339 4294 4436 4349 4366 4377 4334 4358 4235 4288 4337 4582 4326 4310 4394 4171 4287 4346 4327 4300 4346 4315 4373 4228 4414 4419 4404 4270 4357 4380 4520 4286 4458 4338 4374 4303 4255 4362 4353 4373 4317 4269 4460 4357 4547 4505 4456 4273 4412 4508 4434 4488 4562 4557 4459 4658 4531 4592 4755 4716 4670 4736 4763 4843 4958 5046 5048 5163 5183 5423 5686 5956 6034 6320 6680 6949 7528 8035 8325 8640 8762 8842 8602 8226 7884 7319 7214 6960 6856 6696 6792 6765 6885 6908 6809 6746 6532 6231 6013 5732 5426 5259 5128 4923 4790 4818 4770 4698 4675 4635 4484 4567 4473 4517 4442 4456 4363 4542 4449 4459 4415 4385 4395 4295 4471 4391 4411 4321 4361 4455 4303 4411 4299 4460 4262 4379 4324 4418 4270 4330 4282 4335 4256 4528 4417 4470 4315 4415 4314 4295 4453 4346 4376 4349 4303 4287 4297 4424 4435 4397 4373 4353 4484 4347 4369 4352 4360 4381 4309 4296 4302 4393 4421 4350 4308 4311 4381 4344 4289 4359 4457 4368 4507 4370 4389 4595 4354 4515 4401 4575 4544 4477 4539 4611 4728 4674 4806 4836 5128 5010 5093 4980 5115 5009 5032 4941 5030 4932 4802 4720 4611 4789 4848 4649 4681 4694 4728 4770 4783 4707 4770 4627 4491 4530 4520 4460 4519 4393 4372 4476 4292 4479 4353 4461 4355 4466 4421 4370 4344 4456 4444 4465 4523 4385 4417 4426 4578 4569 4511 4505 4420 4642 4703 4657 4670 4740 4741 4852 4845 5052 5110 5089 5300 5238 5638 5742 5630 5721 5905 6091 6260 6127 6118 6165 6366 6241 6266 6198 6396 6260 6286 6312 6379 6186 6130 6055 5962 5859 5817 5886 5659 5713 5676 5466 5314 5486 5268 5331 5237 5142 5171 5034 5030 5010 4858 5126 4910 4858 4958 4933 4824 5001 5018 4958 4968 4952 5002 5010 5211 5183 5319 5367 5523 5557 5777 5991 6324 6768 7064 7609 7851 8418 8708 9347 9332 9413 9070 8771 8364 8006 7662 7472 7243 7023 6979 7193 7294 7177 7324 7192 7076 6820 6667 6330 6065 5648 5572 5362 5236 4980 4989 4987 4991 4927 4842 4831 4673 4647 4690 4655 4622 4633 4560 4525 4637 4410 4513 4393 4412 4470 4505 4426 4450 4506 4540 4558 4487 4446 4358 4358 4475 4444 4390 4409 4401 4440 4509 4522 4587 4519 4518 4524 4565 4595 4583 4661 4640 4473 4697 4599 4607 4609 4626 4535 4566 4565 4511 4482 4607 4627 4579 4606 4344 4588 4581 4502 4498 4449 4468 4434 4307 4461 4422 4452 4367 4289 4358 4409 4273 4465 4311 4485 4361 4491 4457 4490 4475 4423 4422 4428 4419 4520 4438 4596 4649 4666 4718 4802 4855 4996 4953 5028 5320 5226 5451 5354 5523 5363 5220 5165 5046 4978 4871 4898 4809 4950 4776 4845 4966 4811 4889 4866 4814 4748 4662 4506 4575 4630 4455 4595 4469 4452 4319 4439 4292 4376 4372 4427 4428 4388 4321 4363 4463 4424 4221 4358 4351 4403 4224 4314 4459 4312 4346 4182 4304 4236 4304 4359 4427 4321 4333 4243 4198 4068 4529 4315 4140 4259 4201 4317 4254 4315 4241 4263 4246 4339 4456 4297 4416 4342 4271 4293 4315 4395 4415 4381 4362 4377 4416 4347 4245 4248 4253 4325 4250 4449 4347 4302 4477 4257 4162 4281 4270 4327 4275 4293 4372 4288 4328 4327 4229 4290 4391 4348 4329 4435 4361 4369 4360 4393 4361 4406 4437 4519 4568 4617 4610 4644 4790 4859 5053 4972 5042 5060 5310 5076 5011 4951 4997 4979 4747 4873 4716 4658 4654 4633 4841 4775 4763 4805 4646 4719 4649 4531 4617 4556 4340 4421 4479 4508 4459 4458 4376 4381 4286 4298 4361 4314 4378 4372 4295 4303 4334 4435 4498 4167 4311 4273 4300 4289 4238 4350 4366 4238 4343 4249 4191 4239 4272 4320 4344 4262 4382 4181 4164 4267 4242 4241 4306 4294 4323 4298 4341 4296 4330 4285 4346 4307 4174 4297 4371 4228 4214 4425 4288 4323 4396 4222 4285 4221 4171 4237 4185 4226 4365 4360 4299 4352 4210 4288 4291 4387 4252 4148 4351 4307 4323 4299 4434 4352 4390 4402 4316 4376 4373 4350 4411 4269 4410 4413 4378 4532 4351 4367 4388 4571 4476 4704 4532 4608 4694 4740 4631 4601 4611 4559 4450 4503 4420 4546 4393 4470 4560 4551 4439 4405 4463 4571 4577 4557 4480 4479 4527 4381 4404 4562 4492 4362 4510 4427 4528 4437 4406 4480 4445 4407 4607 4351 4411 4475 4451 4408 4574 4495 4517 4497 4508 4607 4774 4815 4838 4968 4995 5110 5253 5352 5472 5730 5836 6057 6152 6095 6299 6396 6409 6560 6590 6538 6623 6751 6835 6755 6674 6747 6807 6639 6619 6689 6394 6420 6401 6382 6143 6133 6128 6031 5722 5696 5677 5588 5562 5451 5386 5266 5226 5171 5090 4950 4888 4992 4827 4860 4657 4770 4607 4628 4669 4560 4613 4544 4446 4588 4551 4636 4530 4560 4676 4395 4508 4605 4476 4590 4651 4649 4521 4639 4754 4590 4561 4637 4632 4594 4574 4681 4535 4664 4637 4601 4611 4630 4737 4657 4813 4748 4953 4923 5061 5166 5364 5348 5305 5578 5485 5671 5512 5510 5367 5162 5156 5142 4834 5059 4848 4872 4973 4867 5039 5086 4971 4858 4978 4848 4917 4684 4690 4694 4500 4536 4462 4513 4433 4432 4376 4304 4457 4281 4436 4319 4315 4243 4362 4373 4442 4370 4387 4238 4434 4372 4288 4350 4338 4400 4224 4335 4223 4246 4318 4322 4271 4213 4359 4239 4340 4341 4335 4224 4388 4370 4169 4256 4198 4278 4264 4290 4298 4351 4401 4456 4220 4256 4233 4309 4423 4398 4384 4382 4396 4357 4311 4461 4477 4520 4474 4481 4691 4785 4673 4642 4776 4771 4754 4812 4847 4755 4691 4682 4554 4532 4593 4570 4576 4533 4512 4562 4465 4573 4584 4650 4569 4485 4602 4593 4520 4370 4477 4378 4356 4501 4365 4490 4344 4368 4430 4505 4325 4455 4548 4461 4606 4432 4684 4630 4693 4835 4732 4748 4773 5068 4927 5241 5424 5630 5706 5763 5843 5904 5668 5625 5528 5471 5300 5276 5191 4987 5048 5104 5032 5122 5010 5190 5150 5101 5124 5028 4925 4960 4928 4778 4616 4628 4811 4457 4566 4492 4370 4398 4456 4341 4426 4332 4269 4342 4359 4350 4269 4442 4282 4298 4341 4275 4368 4362 4286 4452 4414 4277 4410 4332 4372 4399 4539 4342 4451 4298 4509 4568 4469 4483 4608 4432 4580 4488 4514 4490 4500 4479 4517 4489 4427 4399 4309 4464 4440 4355 4405 4491 4376 4416 4393 4416 4415 4317 4417 4437 4434 4332 4339 4495 4338 4314 4393 4307 4491 4194 4374 4303 4333 4385 4300 4353 4267 4316 4255 4274 4343 4180 4350 4331 4345 4223 4145 4247 4192 4187 4047 4207 4301 4168 4251 4205 4161 4176 4221 4181 4129 4268 4326 4176 4282 4299 4193 4252 4317 4162 4229 4253 4254 4225 4345 4212 4147 4294 4395 4290 4347 4313 4196 4236 4172 4273 4204 4320 4156 4253 4287 4119 4255 4278 4207 4204 4215 4181 4221 4263 4171 4311 4207 4272 4152 4204 4229 4213 4219 4231 4180 4224 4202 4147 4208 4306 4289 4253 4344 4231 4254 4088 4242 4260 4108 4241 4080 4224 4246 4322 4287 4325 4183 4102 4231 4220 4324 4108 4161 4301 4228 4178 4235 4186 4279 4290 4268 4157 4265 4216 4123 4302 4174 4356 4210 4119 4168 4277 4262 4165 4192 4172 4203 4343 4280 4212 4245 4326 4168 4098 4137 4162 4219 4139 4377 4223 4322 4136 4248 4241 4224 4122 4185 4242 4162 4314 4173 4121 4263 4306 4155 4272 4284 4142 4240 4200 4246 4203 4212 4317 4203 4167 4214 4208 4115 4040 4221 4253 4223 4141 4212 4208 4225 4314 4241 4238 4212 4197 4256 4218 4195 4213 4197 4177 4161 4273 4200 4303 4116 4215 4166 4201 4247 4197 4182 4207 4280 4101 4149 4238 4195 4156 4292 4338 4168 4256 4310 4217 4193 4153 4213 4156 4114 4258 4276 4257 4149 4185 4232 4258 4239 4292 4280 4133 4218 4230 4212 4182 4155 4154 4205 4287 4249 4191 4261 4217 4342 4276 4190 4218 4213 4027 4210 4281 4083 4240 4249 4253 4139 4223 4222 4235 4196 4097 4293 4205 4236 4257 4296 4245 4154 4242 4203 4258 4135 4118 4199 4339 4205 4201 4260 4238 4192 4146 4272 4251 4152 4183 4160 4290 4278 4266 4072 4381 4233 4112 4119 4209 4220 4234 4148 4285 4238 4299 4239 4255 4280 4321 4228 4326 4286 4454 4232 4341 4234 4274 4298 4380 4370 4261 4247 4491 4301 4388 4464 4369 4423 4504 4467 4401 4623 4539 4608 4460 4413 4472 4377 4370 4359 4365 4405 4358 4480 4354 4271 4246 4458 4509 4464 4467 4364 4352 4421 4231 4318 4324 4268 4363 4276 4325 4245 4250 4184 4290 4228 4212 4126 4175 4316 4206 4276 4191 4208 4063 4283 4184 4161 4281 4211 4140 4167 4130 4111 4206 4234 4190 4193 4242 4196 4238 4209 4238 4206 4240 4204 4307 4188 4236 4213 4299 4222 4334 4152 4182 4127 4305 4218 4185 4253 4269 4377 4255 4101 4300 4313 4291 4120 4353 4201 4301 4252 4365 4340 4408 4369 4316 4446 4259 4500 4468 4535 4433 4520 4515 4425 4605 4512 4582 4673 4695 4757 5001 4733 5087 4967 5059 5048 5211 5116 5073 4970 4890 4801 4740 4754 4717 4652 4676 4715 4389 4630 4538 4582 4596 4591 4639 4702 4546 4775 4540 4575 4379 4590 4442 4370 4375 4386 4238 4318 4359 4251 4226 4368 4369 4354 4287 4249 4248 4172 4164 4269 4208 4191 4196 4276 4091 4256 4256 4215 4311 4282 4332 4220 4133 4223 4267 4157 4194 4121 4139 4292 4277 4260 4193 4207 4152 4219 4158 4329 4243 4264 4273 4288 4284 4351 4193 4279 4112 4170 4198 4184 4226 4320 4210 4280 4271 4207 4290 4369 4305 4166 4164 4243 4286 4282 4300 4308 4337 4434 4327 4224 4313 4402 4350 4509 4406 4488 4527 4495 4549 4639 4613 4843 4884 4813 4782 4808 4859 4837 4621 4476 4500 4599 4488 4489 4503 4429 4406 4574 4464 4502 4439 4563 4497 4487 4586 4632 4444 4325 4449 4544 4398 4348 4345 4306 4249 4409 4431 4333 4299 4306 4401 4447 4398 4219 4326 4395 4480 4327 4422 4514 4413 4438 4455 4564 4655 4592 4675 4762 4921 4775 4810 4684 4757 4724 4719 4687 4619 4426 4625 4607 4393 4570 4426 4550 4481 4514 4634 4526 4596 4675 4589 4618 4462 4571 4408 4521 4396 4455 4313 4494 4364 4390 4510 4361 4411 4466 4350 4386 4389 4349 4399 4465 4304 4395 4355 4384 4308 4327 4361 4412 4426 4462 4264 4340 4497 4540 4650 4515 4526 4516 4673 4584 4492 4560 4536 4458 4559 4467 4436 4380 4354 4440 4393 4467 4507 4484 4465 4424 4525 4542 4561 4529 4455 4617 4542 4576 4522 4594 4557 4663 4605 4595 4570 4680 4415 4614 4462 4606 4473 4631 4691 4666 4762 4657 4760 4551 4677 4474 4548 4696 4641 4591 4448 4497 4408 4556 4378 4550 4382 4412 4464 4506 4370 4418 4398 4397 4583 4347 4333 4505 4315 4356 4360 4227 4289 4229 4235 4273 4259 4315 4261 4384 4333 4361 4331 4325 4433 4347 4361 4277 4187 4293 4312 4260 4341 4160 4215 4288 4356 4255 4262 4317 4285 4212 4208 4345 4291 4311 4351 4366 4365 4594 4549 4633 4493 4617 4509 4630 4708 4605 4557 4601 4526 4552 4474 4381 4401 4449 4346 4492 4514 4493 4621 4498 4581 4422 4399 4482 4547 4524 4558 4446 4491 4441 4504 4387 4219 4396 4374 4277 4336 4456 4240 4247 4279 4356 4304 4213 4265 4375 4364 4170 4390 4177 4231 4315 4192 4091 4291 4296 4273 4360 4260 4175 4294 4258 4154 4251 4185 4146 4318 4231 4216 4264 4143 4237 4268 4194 4242 4233 4183 4259 4258 4257 4238 4303 4064 4263 4251 4308 4219 4184 4156 4190 4301 4161 4252 4228 4125 4300 4320 4233 4081 4203 4128 4245 4359 4199 4383 4260 4215 4123 4402 4311 4345 4348 4333 4387 4324 4385 4414 4412 4366 4337 4384 4303 4492 4358 4347 4346 4343 4424 4152 4393 4391 4316 4316 4357 4234 4263 4319 4380 4264 4205 4297 4248 4327 4312 4223 4382 4241 4257 4204 4134 4246 4271 4272 4294 4188 4208 4067 4179 4126 4211 4263 4264 4290 4234 4200 4357 4197 4316 4376 4145 4324 4184 4215 4270 4155 4306 4350 4309 4357 4394 4486 4453 4463 4506 4513 4535 4417 4531 4424 4444 4498 4327 4335 4406 4310 4391 4398 4423 4306 4436 4354 4333 4475 4434 4446 4479 4532 4388 4468 4520 4388 4407 4343 4241 4449 4232 4465 4460 4396 4193 4382 4326 4475 4346 4465 4539 4665 4504 4701 4563 4771 4692 4734 4784 4683 4538 4638 4608 4425 4391 4422 4372 4433 4416 4382 4411 4544 4455 4513 4465 4578 4527 4486 4580 4469 4487 4442 4296 4256 4319 4296 4262 4237 4302 4263 4350 4380 4383 4122 4277 4329 4221 4266 4314 4133 4207 4351 4294 4174 4302 4226 4056 4229 4309 4278 4076 4250 4199 4184 4182 4193 4263 4218 4197 4125 4283 4212 4192 4104 4196 4235 4152 4206 4144 4309 4260 4101 4380 4259 4173 4309 4256 4267 4284 4323 4273 4175 4214 4337 4221 4217 4284 4279 4278 4329 4205 4289 4330 4303 4424 4506 4440 4494 4585 4577 4547 4673 4785 4791 4997 4980 5210 5306 5338 5266 5372 5453 5249 5144 4995 4988 4887 4873 4790 4896 4757 4616 4701 4691 4770 4706 4791 4794 4949 4885 4878 5034 4869 4767 4869 4787 4694 4692 4737 4593 4460 4617 4446 4463 4544 4575 4532 4498 4646 4592 4660 4593 4665 4562 4586 4532 4547 4498 4531 4459 4398 4477 4492 4354 4498 4422 4497 4389 4383 4404 4302 4411 4395 4366 4566 4331 4334 4419 4365 4302 4394 4412 4244 4346 4361 4201 4282 4212 4350 4251 4309 4244 4266 4265 4142 4172 4202 4198 4206 4157 4217 4249 4184 4167 4213 4150 4218 4145 4265 4265 4179 4107 4133 4237 4143 4159 4303 4325 4011 4311 4249 4268 4172 4163 4212 4221 4119 4201 4276 4171 4225 4261 4187 4253 4235 4288 4266 4117 4326 4076 4237 4159 4167 4364 4222 4301 4327 4193 4163 4220 4145 4210 4165 4217 4103 4215 4184 4330 4196 4144 4177 4138 4331 4147 4189 4293 4206 4243 4215 4216 4215 4281 4191 4209 4228 4297 4114 4236 4337 4212 4316 4191 4273 4297 4262 4302 4235 4271 4195 4164 4149 4187 4275 4103 4091 4221 4250 4366 4237 4246 4205 4237 4166 4226 4280 4328 4184 4187 4172 4323 4189 4326 4285 4281 4272 4149 4301 4332 4258 4311 4384 4281 4345 4451 4262 4292 4474 4463 4551 4507 4672 4781 4734 4889 4885 4842 4907 4758 4974 4764 4716 4601 4628 4565 4613 4588 4429 4465 4529 4491 4540 4402 4519 4576 4496 4520 4460 4580 4695 4517 4634 4419 4517 4487 4488 4427 4438 4398 4334 4230 4317 4350 4227 4321 4333 4330 4245 4297 4202 4158 4281 4157 4223 4258 4161 4136 4330 4269 4237 4132 4189 4242 4153 4251 4176 4197 4197 4183 4256 4199 4174 4244 4178 4216 4285 4205 4238 4263 4184 4217 4258 4107 4180 4281 4315 4241 4240 4289 4242 4283 4191 4350 4425 4310 4413 4170 4349 4255 4420 4221 4349 4302 4234 4319 4425 4383 4357 4482 4415 4361 4168 4271 4338 4467 4384 4429 4277 4418 4426 4389 4373 4239 4268 4307 4329 4390 4315 4374 4242 4223 4324 4270 4252 4222 4284 4339 4365 4283 4295 4240 4241 4238 4241 4209 4307 4196 4228 4243 4237 4247 4132 4225 4292 4229 4185 4187 4285 4164 4159 4284 4173 4195 4116 4162 4120 4097 4265 4187 4139 4293 4143 4167 4245 4161 4191 4161 4203 4188 4201 4202 4173 4171 4074 4319 4135 4189 4199 4237 4233 4286 4231 4309 4210 4222 4193 4061 4209 4212 4231 4140 4184 4096 4199 4271 4287 4117 4159 4086 4171 4123 4211 4171 4110 4207 4171 4171 4136 4167 4163 4296 4191 4314 4264 4223 4421 4368 4287 4246 4490 4307 4476 4363 4257 4314 4212 4320 4283 4418 4296 4333 4208 4300 4359 4268 4263 4256 4245 4374 4254 4262 4241 4334 4289 4273 4207 4215 4270 4280 4175 4175 4163 4247 4222 4261 4090 4179 4184 4116 4148 4114 4166 4232 4175 4152 4206 4224 4260 4215 4268 4155 4186 4269 4198 4132 4257 4290 4263 4222 4261 4321 4315 4204 4251 4497 4187 4347 4443 4465 4324 4399 4485 4653 4363 4458 4354 4428 4399 4378 4368 4390 4280 4281 4271 4241 4335 4450 4327 4344 4354 4200 4400 4284 4443 4373 4490 4398 4461 4241 4368 4448 4334 4336 4393 4322 4366 4284 4354 4370 4570 4503 4510 4437 4612 4568 4400 4567 4290 4417 4357 4301 4327 4314 4434 4368 4358 4325 4367 4364 4293 4442 4483 4396 4298 4356 4318 4371 4445 4349 4249 4391 4271 4356 4314 4342 4263 4207 4202 4284 4242 4173 4186 4214 4176 4211 4287 4303 4244 4260 4258 4093 4109 4232 4149 4181 4240 4191 4158 4287 4207 4234 4245 4259 4154 4245 4127 4092 4297 4143 4191 4040 4123 4175 4032 4155 4136 4213 4102 4221 4174 4206 4120 4150 4208 4281 4110 4266 4252 4142 4252 4202 4270 4188 4252 4320 4263 4344 4277 4242 4234 4253 4209 4194 4125 4127 4196 4190 4201 4247 4117 4068 4242 4240 4204 4352 4240 4313 4322 4247 4313 4243 4152 4248 4266 4235 4225 4322 4300 4163 4206 4220 4326 4171 4270 4214 4249 4143 4123 4221 4267 4341 4124 4204 4196 4157 4159 4237 4198 4306 4180 4410 4253 4355 4236 4384 4169 4310 4267 4382 4331 4362 4304 4200 4229 4242 4404 4482 4438 4486 4420 4525 4540 4724 4316 4470 4445 4454 4383 4489 4396 4359 4325 4443 4426 4395 4572 4373 4475 4548 4455 4473 4426 4580 4501 4555 4509 4448 4552 4496 4340 4529 4453 4452 4510 4440 4309 4491 4357 4462 4413 4252 4407 4348 4419 4491 4285 4457 4407 4393 4362 4475 4495 4524 4631 4574 4716 4640 4631 4507 4612 4519 4366 4458 4559 4533 4482 4349 4330 4363 4318 4276 4494 4309 4354 4345 4330 4308 4367 4327 4340 4379 4401 4369 4300 4394 4249 4226 4353 4386 4283 4417 4393 4075 4211 4223 4317 4241 4278 4183 4160 4146 4127 4190 4145 4303 4139 4144 4131 4273 4278 4174 4258 4186 4294 4105 4263 4160 4205 4064 4249 4254 4230 4372 4180 4131 4335 4215 4297 4158 4245 4211 4195 4227 4157 4292 4128 4266 4184 4152 4123 4173 4081 4165 4163 4237 4206 4192 4161 4045 4160 4139 4147 4241 4143 4173 4055 4141 4177 4175 4140 4139 4131 4155 4150 4234 4276 4118 4214 4240 4225 4215 4270 4193 4202 4063 4142 4251 4213 4115 4100 4155 4154 4096 4116 4049 4168 4127 4137 4197 4097 4084 4132 4033 4123 4338 4144 4140 4200 4224 4202 4079 4168 4066 4138 4266 4199 4251 4163 4140 4061 4190 4218 4175 4204 4200 4198 4217 4200 4112 4229 4224 4292 4073 4208 4127 4188 4214 4285 4132 4278 4235 4279 4287 4227 4123 4309 4045 4332 4142 4292 4296 4229 4264 4334 4241 4315 4129 4096 4237 4197 4285 4323 4350 4266 4315 4266 4253 4241 4261 4159 4494 4369 4367 4410 4360 4441 4542 4466 4690 4546 4610 4540 4689 4737 4816 4906 4846 4931 4919 4985 4936 5109 4932 4953 4921 4790 4912 4879 4899 4780 4772 4730 4633 4924 4764 4890 4795 4771 4898 5009 4821 4917 4772 4757 4804 4912 4823 4852 4890 4643 4765 4740 4794 4665 4658 4709 4669 4647 4651 4544 4533 4674 4567 4722 4612 4737 4601 4639 4529 4680 4672 4755 4544 4707 4711 4844 4861 4713 4945 4921 4789 4762 4834 4782 4725 4730 4670 4548 4519 4540 4437 4452 4453 4511 4460 4470 4644 4519 4433 4591 4508 4431 4549 4658 4416 4638 4616 4566 4588 4615 4577 4461 4612 4526 4339 4455 4547 4572 4517 4541 4561 4563 4585 4598 4796 4798 4884 4832 4761 4881 4990 4929 4926 4894 4888 4801 4645 4583 4641 4580 4564 4556 4341 4508 4417 4376 4472 4433 4331 4352 4556 4392 4481 4600 4587 4625 4695 4687 4641 4530 4577 4535 4392 4431 4409 4327 4436 4412 4263 4273 4181 4180 4231 4402 4260 4276 4277 4097 4255 4193 4245 4180 4047 4249 4091 4283 4178 4234 4240 4422 4315 4333 4119 4227 4238 4229 4315 4246 4141 4147 4254 4318 4190 4294 4221 4121 4159 4307 4117 4108 4188 4233 4282 4155 4249 4168 4080 4129 4261 4248 4239 4177 4149 4260 4262 4113 4200 4181 4112 4330 4247 4276 4281 4350 4316 4261 4262 4467 4459 4485 4484 4514 4538 4510 4504 4415 4347 4497 4356 4455 4339 4443 4336 4396 4372 4204 4377 4378 4230 4255 4235 4314 4383 4485 4281 4309 4299 4296 4303 4389 4362 4434 4479 4251 4364 4334 4358 4303 4222 4286 4150 4238 4234 4149 4208 4201 4235 4099 4349 4173 4214 4223 4231 4220 4155 4276 4283 4105 4095 4198 4191 4069 4280 4086 4322 4240 4146 4099 4201 4162 4163 4064 4143 4181 4328 4212 4349 4042 4276 4145 4291 4112 4222 4157 4192 4222 4327 4163 4233 4248 4273 4253 4347 4126 4243 4154 4241 4236 4202 4353 4181 4194 4263 4309 4310 4372 4482 4590 4230 4380 4305 4462 4517 4309 4564 4403 4303 4295 4254 4321 4382 4339 4411 4340 4228 4241 4397 4288 4206 4360 4280 4199 4365 4302 4293 4254 4274 4249 4344 4348 4224 4378 4175 4357 4312 4235 4238 4350 4215 4392 4185 4244 4224 4272 4307 4214 4166 4228 4135 4150 4233 4138 4246 4206 4283 4211 4179 4217 4174 4247 4033 4072 4180 4271 4166 4166 4176 4243 4163 4129 4228 4141 4175 4091 4266 4035 4202 4211 4260 4243 4209 4200 4214 4270 4319 4153 4182 4114 4151 4236 4220 4223 4278 4190 4281 4367 4121 4261 4235 4262 4228 4346 4225 4297 4391 4329 4397 4378 4379 4420 4415 4474 4471 4400 4406 4509 4489 4469 4390 4482 4413 4453 4365 4363 4377 4303 4424 4370 4265 4357 4297 4427 4286 4296 4402 4270 4489 4400 4457 4387 4351 4405 4435 4490 4331 4447 4280 4413 4459 4360 4455 4359 4267 4434 4401 4221 4227 4268 4405 4421 4361 4303 4321 4075 4240 4284 4191 4333 4298 4196 4228 4157 4308 4215 4284 4206 4167 4236 4195 4309 4267 4428 4283 4268 4172 4360 4318 4337 4347 4419 4423 4500 4437 4524 4511 4489 4544 4621 4601 4643 4644 4569 4527 4646 4509 4573 4588 4641 4503 4482 4446 4444 4557 4486 4601 4502 4601 4457 4641 4614 4736 4517 4496 4752 4859 4615 4897 4865 4864 4844 4785 4630 4727 4600 4543 4517 4503 4478 4336 4376 4406 4415 4387 4427 4451 4309 4461 4454 4421 4384 4293 4316 4423 4398 4416 4317 4420 4356 4267 4486 4387 4393 4285 4304 4250 4169 4215 4191 4217 4317 4204 4264 4150 4280 4303 4323 4137 4389 4294 4249 4274 4141 4259 4232 4164 4197 4181 4246 4278 4204 4238 4196 4359 4047 4264 4185 4171 4186 4274 4119 4131 4123 4221 4228 4217 4198 4169 4254 4209 4261 4214 3996 4197 4108 4108 4339 4173 4255 4065 4287 4164 4310 4271 4262 4243 4186 4271 4236 4311 4316 4222 4312 4264 4398 4304 4315 4402 4354 4329 4362 4354 4224 4229 4299 4333 4046 4279 4305 4272 4250 4209 4260 4308 4314 4205 4277 4369 4152 4232 4104 4237 4276 4119 4103 4235 4307 4242 4240 4179 4308 4241 4210 4206 4350 4245 4298 4220 4155 4228 4107 4199 4138 4260 4198 4274 4257 4301 4179 4262 4252 4195 4200 4164 4063 4131 4250 4181 4167 4097 4288 4110 4183 4219 4176 4254 4254 4305 4146 4371 4242 4211 4192 4228 4095 4213 4230 4303 4332 4244 4302 4077 4217 4198 4295 4233 4201 4224 4316 4160 4174 4310 4247 4249 4209 4373 4288 4413 4454 4477 4366 4457 4430 4508 4523 4735 4639 4682 4709 4826 4690 4623 4764 4665 4771 4641 4564 4617 4573 4509 4486 4423 4460 4310 4350 4409 4411 4372 4397 4416 4462 4360 4355 4461 4425 4499 4527 4468 4493 4361 4375 4567 4501 4505 4336 4540 4568 4270 4414 4301 4281 4266 4429 4283 4330 4166 4328 4277 4247 4308 4289 4240 4197 4273 4195 4264 4257 4284 4206 4172 4204 4179 4193 4217 4227 4260 4067 4114 4241 4244 4184 4182 4309 4244 4094 4069 4237 4241 4267 4170 4338 4165 4093 4196 4140 4211 4251 4194 4221 4249 4292 4280 4091 4130 4379 4184 4253 4318 4187 4249 4175 4381 4373 4176 4185 4284 4397 4504 4445 4429 4495 4661 4508 4476 4620 4594 4623 4575 4518 4422 4463 4376 4328 4315 4296 4313 4448 4108 4278 4202 4264 4386 4283 4137 4223 4268 4268 4062 4224 4275 4370 4340 4357 4257 4420 4387 4365 4463 4260 4256 4299 4271 4381 4299 4235 4145 4270 4284 4277 4193 4235 4136 4321 4196 4180 4230 4247 4170 4305 4130 4162 4177 4181 4178 4246 4315 4164 4243 4189 4008 4178 4151 4211 4060 4213 4136 4288 4056 4240 4174 4143 4104 4146</counts>
			</dataPoints>
		</scan>
	</xrdMeasurement>
</xrdMeasurements>