File: dataset/precursor_mixture/Cr2O3_Li2TiO3_LiCoO2_K2SO4.2-min.xrdml
<?xml version="1.0"?>
<xrdMeasurements xmlns="http://www.xrdml.com/XRDMeasurement/2.2" xmlns:xsi="http://www.w3.org/2001/XMLSchema-instance" xsi:schemaLocation="http://www.xrdml.com/XRDMeasurement/2.2 http://www.xrdml.com/XRDMeasurement/2.2/XRDMeasurement.xsd" status="Completed" recordIdentifier="{603D66CD-DFF0-4334-9931-04C0B9D23FFE}">
	<comment>
		<entry/>
	</comment>
	<sample type="To be analyzed">
		<id>dara-44-1</id>
		<name></name>
		<preparedBy></preparedBy>
	</sample>
	<xrdMeasurement measurementType="Scan" status="Completed" sampleMode="Reflection">
		<usedWavelength intended="K-Alpha 1">
			<kAlpha1 unit="Angstrom">1.5405980</kAlpha1>
			<kAlpha2 unit="Angstrom">1.5444260</kAlpha2>
			<kBeta unit="Angstrom">1.3922500</kBeta>
			<ratioKAlpha2KAlpha1>0.5000</ratioKAlpha2KAlpha1>
		</usedWavelength>
		<incidentBeamPath>
			<radius unit="mm">145.00</radius>
			<xRayTube id="1010048" name="Empyrean Cu LFF HR (9430 033 7310x) DK437873">
				<tension unit="kV">40.0</tension>
				<current unit="mA">15.0</current>
				<anodeMaterial>Cu</anodeMaterial>
				<focus type="Line">
					<length unit="mm">12.0</length>
					<width unit="mm">0.4</width>
					<takeOffAngle unit="deg">6.0</takeOffAngle>
				</focus>
			</xRayTube>
			<filter id="20010004" name="Beta-filter Nickel">
				<material>Ni</material>
				<thickness unit="mm">0.020</thickness>
			</filter>
			<sollerSlit id="21010002" name="Soller slits 0.04 rad.">
				<opening unit="rad">0.0400</opening>
			</sollerSlit>
			<mask id="22031000" name="Fixed mask 13 mm">
				<width unit="mm">9.00</width>
			</mask>
			<divergenceSlit id="22120001" name="Divergence slit 1°" xsi:type="fixedDivergenceSlitType">
				<distanceToSample unit="mm">50.00</distanceToSample>
				<height unit="mm">1.52</height>
			</divergenceSlit>
		</incidentBeamPath>
		<beamKnife id="29030100" name="Beam knife low"/>
		<sampleMovement xsi:type="spinningSampleMovementType">
			<spinnerRevolutionTime unit="seconds">1.0</spinnerRevolutionTime>
		</sampleMovement>
		<diffractedBeamPath>
			<radius unit="mm">145.00</radius>
			<antiScatterSlit id="22090040" name="AS slit 9 mm" xsi:type="fixedAntiScatterSlitType">
				<height unit="mm">9.00</height>
			</antiScatterSlit>
			<sollerSlit id="21020003" name="Large Soller slits 0.04 rad.">
				<opening unit="rad">0.0400</opening>
			</sollerSlit>
			<filter id="20030001" name="Large beta-filter Nickel">
				<material>Ni</material>
				<thickness unit="mm">0.020</thickness>
			</filter>
			<detector id="7010019" name="PIXcel1D-Medipix3 detector" xsi:type="rtmsDetectorType">
				<phd unit="keV">
					<lowerLevel>4.0</lowerLevel>
					<upperLevel>11.3</upperLevel>
				</phd>
				<mode>Scanning</mode>
				<activeLength unit="deg">1.021</activeLength>
			</detector>
		</diffractedBeamPath>
		<scan appendNumber="0" mode="Continuous" scanAxis="Gonio" status="Completed">
			<header>
				<startTimeStamp>2024-03-24T15:02:39-07:00</startTimeStamp>
				<endTimeStamp>2024-03-24T15:05:01-07:00</endTimeStamp>
				<author>
					<name>AutomatedUser</name>
				</author>
				<source>
					<applicationSoftware version="1.6 (94)">PANalytical Aeris Instrument Suite</applicationSoftware>
					<instrumentControlSoftware version="3.0.0 20211014">AERIS</instrumentControlSoftware>
					<instrumentID>2879380</instrumentID>
				</source>
			</header>
			<dataPoints>
				<positions axis="2Theta" unit="deg">
					<startPosition>10.02173288</startPosition>
					<endPosition>139.98435528</endPosition>
				</positions>
				<positions axis="Omega" unit="deg">
					<startPosition>5.01086644</startPosition>
					<endPosition>69.99217764</endPosition>
				</positions>
				<commonCountingTime unit="seconds">1.551</commonCountingTime>
				<counts unit="counts">625 590 661 613 613 650 610 590 642 591 606 651 642 631 593 594 661 601 624 586 673 601 599 602 586 600 631 628 623 613 592 590 611 582 586 597 588 589 592 580 560 586 569 579 556 537 563 596 599 555 556 559 533 564 561 580 578 563 544 564 581 591 572 574 537 563 539 561 595 517 537 541 546 590 581 518 562 558 525 546 523 549 570 557 554 573 580 558 565 531 533 510 601 553 517 588 546 535 549 505 567 518 543 532 551 559 519 556 575 595 552 568 555 570 572 547 529 537 545 555 591 548 541 544 501 589 562 568 533 546 571 578 576 522 571 530 558 479 571 562 559 538 598 517 482 530 567 529 596 555 577 522 497 565 488 514 568 539 558 553 578 618 562 526 529 541 581 547 573 562 576 587 562 574 590 588 549 565 568 562 571 571 552 556 546 576 602 620 668 612 681 659 682 792 766 818 896 987 1267 1935 3315 6848 12536 11804 4844 1216 857 724 720 692 680 655 641 588 581 582 571 583 600 605 587 665 589 669 595 665 595 688 678 588 608 611 593 600 608 586 601 600 615 611 603 612 590 620 638 566 611 611 617 610 648 629 621 600 702 709 686 686 646 617 578 580 589 554 612 626 565 611 587 571 613 577 524 583 561 546 579 533 561 597 590 597 608 615 593 518 553 579 559 528 542 557 526 551 564 529 590 485 584 496 545 605 534 544 538 502 560 566 566 564 583 616 640 602 553 554 561 525 537 597 523 528 561 563 599 724 790 942 1000 850 642 588 563 563 547 543 531 578 560 563 531 546 547 501 537 546 584 513 562 523 538 550 547 541 533 525 601 535 559 572 541 578 591 537 534 506 519 534 566 539 546 535 513 531 548 516 528 505 508 504 506 544 512 541 551 508 525 511 500 542 492 527 554 513 527 516 488 480 529 491 516 548 517 519 534 502 506 506 531 517 504 517 500 531 550 527 536 474 509 510 542 454 521 506 465 475 563 523 474 527 483 520 541 467 490 541 469 542 579 523 531 528 549 542 580 593 649 679 574 613 513 533 482 489 520 512 500 526 546 561 515 517 548 506 540 539 573 675 976 1020 944 806 707 688 617 612 541 583 469 518 477 536 477 509 487 515 496 515 468 470 500 501 465 513 479 497 485 449 498 471 491 496 537 499 497 515 538 499 514 486 519 505 522 514 472 467 512 496 470 487 448 527 514 526 515 586 529 525 550 592 661 809 1022 1008 830 701 598 530 503 497 530 512 522 481 446 528 476 542 470 522 510 482 553 455 496 521 522 499 545 475 530 498 532 506 493 498 493 531 534 526 477 499 476 456 484 472 529 654 701 596 634 572 540 562 562 571 603 565 657 687 878 1010 873 766 621 584 496 522 499 485 473 516 508 489 507 499 473 480 508 494 567 621 590 538 576 520 550 614 699 587 592 543 523 512 530 509 531 529 522 516 511 509 463 424 473 476 505 538 516 643 985 1132 797 809 607 508 488 506 492 527 475 488 479 445 529 514 578 524 520 511 449 473 516 474 509 456 502 519 494 532 485 516 517 507 468 448 509 492 439 500 526 495 483 469 496 465 484 489 465 483 484 487 462 501 555 504 530 474 522 468 465 451 511 498 500 478 491 496 622 603 602 600 575 538 516 501 538 484 513 463 476 481 492 412 458 495 471 459 491 451 499 461 471 472 461 464 456 482 444 501 493 480 467 490 476 502 482 494 488 531 620 575 576 610 748 692 589 683 625 578 563 576 566 552 529 517 488 507 499 486 482 489 511 473 490 480 455 462 481 432 464 489 470 516 446 450 450 431 503 486 521 542 581 715 884 730 659 680 588 505 515 465 486 498 484 508 425 470 474 489 434 493 442 463 424 481 497 455 467 472 483 405 507 450 498 473 468 459 496 464 497 465 482 481 457 462 430 461 477 479 456 494 451 453 492 454 470 467 490 440 480 475 471 458 450 478 510 457 482 475 459 460 466 451 455 447 466 480 461 484 515 518 504 522 480 481 462 459 496 468 444 509 463 517 479 457 511 471 528 547 515 496 516 437 432 492 470 471 470 445 444 433 482 482 524 611 647 622 562 581 537 487 468 472 466 443 465 471 472 439 469 473 478 426 482 445 508 469 451 470 481 490 464 466 480 445 465 440 464 487 437 450 421 443 459 491 444 473 458 488 428 504 481 447 411 463 468 460 469 470 473 492 426 435 442 481 457 463 459 454 493 444 465 461 471 450 476 443 486 475 448 490 483 466 398 452 542 447 428 479 465 451 488 498 484 478 447 475 462 462 488 464 441 509 535 507 489 556 624 708 840 775 754 765 725 597 522 569 455 488 474 417 437 435 502 471 462 455 443 466 455 446 444 447 452 455 481 494 469 459 444 412 456 392 496 494 421 459 479 465 438 420 445 441 455 464 463 514 466 474 455 427 444 491 477 422 480 435 463 437 422 453 433 477 480 452 443 453 455 470 451 452 432 486 472 508 435 418 461 469 492 536 446 476 455 428 465 517 472 431 461 435 497 426 440 492 557 654 478 519 552 569 441 496 496 489 509 554 526 539 472 539 493 446 453 442 461 458 418 506 485 435 417 405 463 474 444 466 450 430 414 448 469 461 459 452 416 440 453 440 440 452 457 450 433 444 448 459 462 408 510 458 430 432 449 420 459 442 440 453 410 446 405 456 398 454 478 438 468 460 434 474 443 482 438 433 449 490 475 413 455 454 452 471 486 485 458 429 469 467 480 535 538 582 577 604 537 524 575 509 489 451 480 473 454 478 418 468 491 490 511 455 477 485 469 429 468 432 425 498 438 461 491 424 458 429 490 484 497 559 574 591 597 555 572 564 601 555 589 624 483 500 520 541 443 450 434 459 434 447 432 420 468 418 453 494 428 463 489 512 472 457 478 512 469 433 454 404 451 426 449 465 465 494 438 423 416 448 429 457 466 454 486 442 418 456 459 419 456 463 442 451 415 463 449 426 434 406 452 451 447 468 428 395 447 422 438 449 405 457 429 438 455 450 424 425 491 433 439 428 447 456 413 430 436 437 449 470 443 474 467 460 484 448 492 428 455 434 522 450 452 431 436 438 443 436 447 387 418 436 467 492 438 468 388 443 478 426 445 446 423 478 420 443 457 428 418 427 429 462 413 432 459 448 429 442 456 390 441 446 460 411 472 467 456 384 414 422 429 447 463 445 469 429 419 450 390 428 464 442 446 420 464 425 481 467 505 480 483 472 475 468 458 465 451 488 435 459 446 451 485 463 424 439 454 422 438 448 391 478 449 405 460 444 450 429 425 463 424 426 464 440 454 420 468 476 456 429 400 424 440 437 454 444 473 443 435 429 466 429 484 426 443 453 435 425 498 462 441 471 436 418 426 456 480 424 461 439 457 431 456 401 458 437 436 456 455 440 428 483 441 459 439 415 483 434 454 505 455 505 435 431 456 405 428 432 419 406 427 421 421 443 426 418 422 422 424 406 461 402 442 428 413 432 468 455 457 437 428 422 480 417 454 432 467 471 437 475 467 430 433 444 431 441 476 495 456 446 445 507 470 449 495 410 412 429 474 453 472 450 418 482 430 385 434 448 440 432 452 444 451 483 459 428 459 452 427 416 433 423 464 466 404 442 442 462 398 413 472 407 416 419 377 453 428 403 409 457 428 445 395 437 433 428 452 418 478 415 484 457 401 439 452 480 486 463 512 612 651 528 476 450 527 509 465 455 433 412 473 415 428 396 479 400 463 430 419 439 425 446 437 452 463 442 470 435 420 454 445 478 401 443 429 467 447 406 454 437 505 468 447 474 463 434 429 427 435 447 421 432 457 439 421 437 429 450 423 420 439 430 450 439 395 468 419 405 464 439 419 426 400 450 398 450 473 467 477 482 441 489 465 426 461 474 439 464 455 435 466 424 402 457 455 458 411 431 440 450 467 426 448 458 411 461 468 446 421 475 421 485 428 415 429 401 429 414 460 400 464 441 418 412 410 426 422 447 400 420 415 394 432 450 462 395 383 431 412 457 430 389 407 408 446 443 434 405 424 439 430 402 431 438 407 385 475 424 422 440 452 418 450 409 424 443 435 416 451 421 425 469 471 408 487 420 454 470 477 444 415 452 391 462 450 426 443 416 429 422 430 416 416 427 444 469 429 436 402 436 469 432 421 426 452 419 426 432 440 452 419 418 427 422 419 418 447 460 409 427 454 446 418 423 439 441 427 401 400 415 432 394 436 421 454 413 397 425 410 412 419 457 447 394 411 466 448 427 462 434 410 425 456 452 402 427 407 367 463 417 416 466 428 433 411 444 449 401 466 425 441 389 402 443 397 441 452 440 467 424 408 416 439 481 450 416 438 432 501 436 422 442 447 510 482 445 429 418 437 444 439 465 474 400 480 505 418 443 423 461 468 398 442 417 421 418 419 389 423 426 418 414 426 417 413 399 427 415 450 431 442 439 446 393 402 439 385 442 423 443 422 439 413 426 441 414 439 451 427 449 456 407 428 415 407 407 432 424 456 409 445 396 401 406 449 412 380 436 491 401 427 411 436 414 400 415 410 404 461 414 421 448 395 454 441 421 402 447 446 465 404 415 423 426 419 433 420 427 438 420 437 432 387 408 444 471 420 464 410 455 412 454 388 431 418 419 431 425 421 442 420 380 438 449 437 443 385 443 438 403 406 419 432 422 392 438 402 380 424 407 411 408 417 425 429 397 421 429 420 443 465 487 420 461 393 450 398 414 424 414 447 447 425 435 404 427 457 448 444 425 435 427 406 448 386 413 427 435 418 441 433 419 431 403 426 454 361 412 424 408 411 408 409 415 425 411 446 411 457 447 416 431 414 416 443 434 438 435 382 412 440 414 421 417 407 415 430 426 389 401 407 411 367 450 417 424 440 446 443 447 446 418 404 451 423 427 428 406 431 419 400 424 430 451 439 400 426 419 443 438 428 395 402 413 394 431 377 399 447 402 421 426 443 464 435 429 428 420 402 401 439 435 432 405 431 436 407 426 406 435 394 451 403 410 462 463 440 413 408 438 449 434 454 448 430 435 422 409 427 434 417 449 459 401 398 426 436 434 446 412 459 443 397 414 434 421 428 451 421 376 429 432 378 425 441 401 418 406 440 416 410 410 448 438 417 477 496 521 506 434 427 432 489 412 429 474 454 452 502 441 432 465 395 434 462 367 467 420 389 421 474 397 374 418 452 406 400 439 415 382 424 415 478 442 442 425 411 438 458 459 439 405 467 440 430 433 437 474 407 455 451 421 429 406 436 442 433 450 435 450 369 440 425 426 468 414 435 465 420 400 411 416 440 392 425 463 460 403 453 470 395 390 371 438 409 390 434 456 412 477 436 392 416 409 416 424 436 429 395 439 393 443 424 399 480 415 434 416 421 445 436 430 447 407 450 407 439 401 385 401 427 433 434 456 451 438 445 401 417 428 423 394 420 426 455 435 417 372 429 385 431 411 415 419 421 416 467 384 417 408 451 438 402 453 451 459 481 424 445 476 455 447 392 414 410 474 495 482 437 454 383 446 397 439 384 443 410 427 430 435 399 435 408 435 435 455 414 457 430 460 441 401 398 412 432 455 403 453 425 469 450 413 470 442 423 447 402 416 416 459 409 413 442 456 421 473 435 456 379 399 402 412 439 441 448 458 416 426 474 434 391 430 397 435 495 461 416 399 431 380 441 413 433 469 413 411 376 442 438 420 422 445 409 422 450 441 416 405 420 413 436 414 398 374 403 397 391 434 397 439 456 414 442 414 450 409 420 428 403 398 408 414 438 417 422 415 419 439 433 395 397 456 400 444 431 420 407 401 407 415 427 449 419 416 409 377 410 448 391 465 427 413 427 366 413 441 420 430 465 393 399 447 428 439 433 433 449 426 387 457 455 450 427 450 446 520 445 466 458 406 427 458 449 447 435 462 477 455 447 420 459 430 460 436 447 409 406 412 448 423 426 401 422 463 441 424 423 437 442 438 444 421 454 424 407 415 386 385 387 395 417 424 413 416 437 415 439 418 416 440 417 420 441 415 424 424 414 402 457 399 424 426 412 421 403 424 476 420 435 393 422 425 454 399 393 403 426 414 460 411 395 394 441 429 416 439 391 391 429 442 403 431 417 446 416 418 450 427 414 420 424 422 428 445 443 420 437 435 427 428 479 437 419 440 413 401 437 412 483 447 452 417 435 449 412 424 437 440 434 452 431 465 418 430 417 432 402 425 431 434 401 426 467 432 448 433 435 451 435 448 423 402 431 434 409 454 455 401 461 472 439 428 432 440 401 431 438 421 445 457 392 402 404 421 417 439 417 438 394 417 434 468 418 421 422 443 407 436 443 428 397 441 450 467 453 438 396 457 460 468 450 430 452 445 440 443 464 484 462 439 465 481 420 434 441 459 428 431 426 456 453 440 466 398 428 344 428 428 471 422 409 448 440 427 438 398 446 378 407 420 415 419 405 453 429 430 419 445 430 427 437 438 477 439 420 440 418 442 422 493 428 495 411 454 477 450 435 427 444 401 416 426 464 422 433 479 451 421 443 449 436 444 434 419 428 436 456 421 423 437 403 390 400 442 435 419 418 438 461 425 417 424 443 413 444 443 402 412 412 442 404 440 414 424 442 431 427 433 409 420 399 418 420 427 384 416 411 443 421 389 404 437 428 452 423 428 415 422 461 446 427 443 423 410 423 422 425 416 411 424 400 417 467 464 420 405 424 431 437 451 402 384 427 417 395 421 436 451 439 427 436 414 411 434 402 430 461 433 422 371 440 416 405</counts>
			</dataPoints>
		</scan>
	</xrdMeasurement>
</xrdMeasurements>