File: dataset/precursor_mixture/Fe3O4_CuO_Ga2O3.2-min.xrdml
<?xml version="1.0"?>
<xrdMeasurements xmlns="http://www.xrdml.com/XRDMeasurement/2.2" xmlns:xsi="http://www.w3.org/2001/XMLSchema-instance" xsi:schemaLocation="http://www.xrdml.com/XRDMeasurement/2.2 http://www.xrdml.com/XRDMeasurement/2.2/XRDMeasurement.xsd" status="Completed" recordIdentifier="{82F768D7-510C-4B44-BB9B-5F64F4303073}">
	<comment>
		<entry/>
	</comment>
	<sample type="To be analyzed">
		<id>dara-22-1</id>
		<name></name>
		<preparedBy></preparedBy>
	</sample>
	<xrdMeasurement measurementType="Scan" status="Completed" sampleMode="Reflection">
		<usedWavelength intended="K-Alpha 1">
			<kAlpha1 unit="Angstrom">1.5405980</kAlpha1>
			<kAlpha2 unit="Angstrom">1.5444260</kAlpha2>
			<kBeta unit="Angstrom">1.3922500</kBeta>
			<ratioKAlpha2KAlpha1>0.5000</ratioKAlpha2KAlpha1>
		</usedWavelength>
		<incidentBeamPath>
			<radius unit="mm">145.00</radius>
			<xRayTube id="1010048" name="Empyrean Cu LFF HR (9430 033 7310x) DK430614">
				<tension unit="kV">40.0</tension>
				<current unit="mA">15.0</current>
				<anodeMaterial>Cu</anodeMaterial>
				<focus type="Line">
					<length unit="mm">12.0</length>
					<width unit="mm">0.4</width>
					<takeOffAngle unit="deg">6.0</takeOffAngle>
				</focus>
			</xRayTube>
			<filter id="20010004" name="Beta-filter Nickel">
				<material>Ni</material>
				<thickness unit="mm">0.020</thickness>
			</filter>
			<sollerSlit id="21010002" name="Soller slits 0.04 rad.">
				<opening unit="rad">0.0400</opening>
			</sollerSlit>
			<mask id="22031000" name="Fixed mask 13 mm">
				<width unit="mm">9.00</width>
			</mask>
			<divergenceSlit id="22120001" name="Divergence slit 1°" xsi:type="fixedDivergenceSlitType">
				<distanceToSample unit="mm">50.00</distanceToSample>
				<height unit="mm">1.52</height>
			</divergenceSlit>
		</incidentBeamPath>
		<beamKnife id="29030100" name="Beam knife low"/>
		<sampleMovement xsi:type="spinningSampleMovementType">
			<spinnerRevolutionTime unit="seconds">1.0</spinnerRevolutionTime>
		</sampleMovement>
		<diffractedBeamPath>
			<radius unit="mm">145.00</radius>
			<antiScatterSlit id="22090040" name="AS slit 9 mm" xsi:type="fixedAntiScatterSlitType">
				<height unit="mm">9.00</height>
			</antiScatterSlit>
			<sollerSlit id="21020003" name="Large Soller slits 0.04 rad.">
				<opening unit="rad">0.0400</opening>
			</sollerSlit>
			<filter id="20030001" name="Large beta-filter Nickel">
				<material>Ni</material>
				<thickness unit="mm">0.020</thickness>
			</filter>
			<detector id="7010019" name="PIXcel1D-Medipix3 detector" xsi:type="rtmsDetectorType">
				<phd unit="keV">
					<lowerLevel>4.0</lowerLevel>
					<upperLevel>11.3</upperLevel>
				</phd>
				<mode>Scanning</mode>
				<activeLength unit="deg">1.021</activeLength>
			</detector>
		</diffractedBeamPath>
		<scan appendNumber="0" mode="Continuous" scanAxis="Gonio" status="Completed">
			<header>
				<startTimeStamp>2024-02-18T09:00:59-08:00</startTimeStamp>
				<endTimeStamp>2024-02-18T09:03:21-08:00</endTimeStamp>
				<author>
					<name>AutomatedUser</name>
				</author>
				<source>
					<applicationSoftware version="1.4b (28)">PANalytical Aeris Instrument Suite</applicationSoftware>
					<instrumentControlSoftware version="2.0.0 20210224">AERIS</instrumentControlSoftware>
					<instrumentID>950485</instrumentID>
				</source>
			</header>
			<dataPoints>
				<positions axis="2Theta" unit="deg">
					<startPosition>10.02173288</startPosition>
					<endPosition>139.98435528</endPosition>
				</positions>
				<positions axis="Omega" unit="deg">
					<startPosition>5.01086644</startPosition>
					<endPosition>69.99217764</endPosition>
				</positions>
				<commonCountingTime unit="seconds">1.551</commonCountingTime>
				<counts unit="counts">632 615 639 598 606 579 608 579 578 595 629 571 598 616 555 620 600 638 598 606 574 591 591 621 590 554 607 551 597 560 588 572 571 551 563 600 550 599 556 581 562 575 620 602 596 553 605 533 543 574 599 584 572 570 597 557 552 540 592 567 588 574 600 546 603 564 530 608 552 581 533 572 554 564 588 600 583 570 631 610 579 568 545 569 553 593 569 570 565 566 568 564 590 576 625 558 568 590 585 597 589 563 601 598 569 654 614 543 643 577 580 586 595 547 600 634 603 611 599 559 548 550 629 549 616 599 622 642 578 591 630 578 594 588 563 598 636 591 554 580 622 597 606 574 630 638 624 553 572 608 552 578 614 558 614 615 608 614 583 576 578 552 572 627 615 573 554 617 613 609 592 616 635 573 607 616 593 646 596 605 642 637 596 598 654 651 700 698 675 666 646 586 622 658 645 641 639 686 705 800 862 888 863 802 682 652 664 621 628 610 661 605 623 623 603 610 573 586 634 612 629 567 623 583 599 595 574 644 604 605 623 597 622 612 579 563 610 619 609 603 638 626 593 584 624 629 560 616 632 641 589 608 669 608 577 576 597 577 601 639 577 625 621 567 620 627 633 606 602 599 629 584 511 585 607 581 608 579 575 603 601 574 600 592 570 591 621 586 620 547 603 571 575 622 594 631 594 615 601 592 586 560 604 626 563 629 572 574 618 577 635 628 618 597 598 554 589 595 653 617 579 602 604 575 597 608 648 566 577 568 584 549 582 576 587 614 582 610 587 607 538 580 550 629 552 586 599 569 600 584 579 637 596 572 566 529 604 599 579 631 534 601 574 594 597 572 572 612 611 603 568 564 616 563 618 609 583 607 571 576 592 629 608 630 564 620 618 570 555 579 561 574 561 527 580 615 571 624 598 636 511 572 525 584 550 593 608 566 612 591 566 585 590 587 584 597 580 547 581 550 586 588 630 577 568 556 556 600 609 621 641 608 576 582 593 594 608 631 597 631 623 599 608 663 663 659 697 739 752 851 889 1156 1270 1239 1184 1070 1127 1224 1275 1470 1584 1622 1529 1267 1169 1002 940 866 817 789 735 718 691 706 737 675 710 728 757 701 761 788 846 825 934 1034 1108 1162 1185 1212 1228 1063 983 927 882 753 741 724 691 683 676 636 629 662 587 646 682 703 649 607 582 607 637 614 630 597 606 593 581 560 618 620 584 601 617 612 624 595 607 605 633 618 650 609 604 611 624 599 562 576 574 581 600 605 616 575 572 578 611 582 638 626 599 597 635 613 642 612 658 617 637 620 705 706 725 809 875 919 981 1105 1347 1790 2259 2379 2279 1989 1595 1339 1114 885 788 745 686 657 644 634 614 602 603 576 598 560 599 652 589 616 603 595 565 555 618 546 617 607 638 616 569 618 677 656 664 645 626 672 688 680 662 660 659 615 647 667 627 603 609 594 589 623 626 596 634 647 650 678 677 714 701 775 812 902 821 895 923 924 1023 1115 1178 1140 1100 987 921 829 859 764 707 710 671 633 636 623 604 599 564 593 593 593 517 627 568 564 610 607 577 570 623 557 523 601 557 564 595 588 586 589 575 582 636 554 556 565 602 584 565 583 567 605 561 617 559 595 552 580 598 569 580 539 582 561 558 567 568 502 616 548 557 588 561 578 580 555 572 590 556 559 587 562 543 556 546 540 564 545 573 591 605 505 603 654 599 631 632 654 715 831 818 792 742 737 690 660 609 625 595 537 548 601 589 592 593 563 562 572 566 574 543 577 567 592 606 593 533 587 604 591 568 576 544 568 583 599 614 637 595 630 636 614 564 601 562 528 566 576 582 558 601 579 611 546 593 584 567 553 588 636 650 615 606 643 610 552 636 639 592 605 615 582 589 582 568 540 552 521 555 564 537 581 596 563 583 576 516 553 591 597 564 574 595 595 571 536 532 604 569 559 592 538 584 556 544 580 605 617 616 557 612 614 565 589 587 590 592 580 606 588 616 558 631 656 618 665 730 757 787 736 763 774 704 647 645 628 585 610 612 556 596 573 600 589 580 595 594 608 595 539 569 596 608 561 570 562 577 560 582 557 593 620 596 586 535 572 552 588 530 592 559 552 587 574 653 564 586 559 583 573 576 549 595 562 580 573 610 546 550 604 551 563 547 570 537 544 547 569 552 543 592 519 578 549 546 558 576 571 597 575 595 601 589 548 560 566 549 647 551 596 542 613 553 551 588 575 592 590 594 585 569 678 686 654 631 678 691 654 651 679 621 585 623 598 592 569 568 541 583 540 572 582 594 548 537 579 533 584 542 617 612 538 587 595 529 572 574 581 598 530 534 588 533 577 566 560 567 551 571 585 593 577 567 560 551 565 514 525 541 507 541 585 584 536 573 509 621 570 585 609 604 530 643 605 594 565 605 618 555 667 691 755 831 870 872 765 786 771 722 613 592 625 645 636 580 592 620 687 630 631 628 641 601 618 613 600 579 606 622 623 628 680 618 659 624 666 611 583 628 612 590 591 567 611 602 595 645 583 641 640 669 658 664 665 674 710 592 633 597 584 622 614 605 592 601 562 519 586 543 599 603 626 585 630 551 667 594 582 630 601 608 604 618 639 635 632 588 650 595 566 638 619 607 649 647 609 613 620 644 643 591 653 644 653 622 668 658 632 635 648 630 636 618 564 575 558 563 587 575 555 587 601 573 580 662 691 753 844 853 905 882 891 853 811 725 736 697 724 632 639 614 610 600 586 588 588 575 587 537 584 587 565 542 554 629 589 612 586 597 627 608 556 608 632 653 671 650 610 596 628 656 662 689 713 690 765 738 730 705 749 643 730 653 647 622 612 592 607 599 597 563 567 585 592 557 621 557 621 614 577 592 605 601 618 614 619 644 627 625 609 614 644 656 633 631 627 625 615 628 606 578 625 611 586 584 569 565 555 557 533 542 561 561 562 575 581 626 586 601 596 547 524 609 574 613 560 595 573 564 623 598 631 620 626 645 602 614 644 620 633 590 569 579 571 606 575 565 568 557 601 542 546 571 541 606 568 549 551 530 572 579 522 600 568 633 582 646 583 618 632 601 565 581 590 646 588 617 586 633 555 529 642 601 532 561 580 572 571 584 587 555 559 579 578 589 608 620 525 578 581 595 569 620 581 549 583 555 597 608 510 601 565 530 547 560 575 585 574 551 584 569 562 564 597 568 620 570 580 638 655 580 567 662 612 565 564 562 587 585 586 558 562 575 550 558 518 587 540 580 583 560 601 552 553 566 573 521 555 609 558 603 603 580 638 628 611 609 658 603 625 607 594 582 507 586 594 578 630 557 580 635 567 595 581 546 581 661 597 602 635 614 642 596 629 631 592 599 595 534 621 604 550 602 583 563 542 550 600 560 589 567 595 534 568 574 514 530 575 574 563 578 530 574 517 549 555 560 573 598 532 569 553 522 557 578 520 547 574 550 568 570 532 536 589 529 523 545 545 605 584 552 516 602 543 593 561 546 546 597 558 554 566 605 578 568 531 550 568 544 537 564 529 572 594 619 548 540 556 536 527 541 574 585 561 578 577 581 543 534 546 581 550 535 529 547 572 542 532 542 570 555 558 540 552 549 572 571 629 602 579 573 575 580 587 557 535 531 551 547 569 555 554 555 552 576 538 527 542 528 562 565 559 545 529 542 573 581 604 550 558 575 550 564 560 526 561 559 546 626 551 507 556 616 587 605 552 605 606 549 597 548 595 554 561 590 547 542 579 558 593 583 567 574 553 580 589 547 564 561 571 614 579 511 532 544 591 598 593 540 563 604 566 616 599 545 570 587 605 590 585 587 583 647 586 566 569 540 576 557 546 534 551 513 627 560 553 576 481 552 579 583 592 601 565 544 587 598 548 590 529 585 541 575 569 548 568 578 558 577 551 576 545 530 551 571 556 574 563 566 611 608 553 541 594 582 548 579 597 524 581 602 647 595 536 584 584 552 579 543 564 526 540 583 545 564 538 582 587 560 563 575 592 564 569 574 552 558 540 552 578 567 508 572 543 615 562 545 591 590 535 554 551 553 593 573 570 572 563 573 574 565 605 601 561 628 617 608 650 648 640 664 683 635 599 633 598 586 658 607 614 542 579 608 607 584 594 586 560 554 558 539 573 543 580 573 560 576 591 581 515 554 594 564 578 602 590 556 570 544 536 546 566 586 574 577 531 542 555 511 511 541 595 529 551 534 547 587 572 568 555 614 549 539 547 577 621 582 587 552 606 567 550 557 566 533 559 582 537 541 555 583 621 548 548 565 625 554 563 567 625 573 534 593 587 586 601 542 567 532 563 555 583 569 550 543 569 623 608 573 599 578 572 603 584 571 559 625 568 566 609 515 595 559 611 587 607 540 556 592 596 580 582 609 538 565 580 553 562 551 587 580 592 579 564 567 581 578 573 586 597 543 597 613 605 569 566 603 547 541 561 601 555 560 602 544 608 573 555 616 530 594 526 558 521 546 553 565 610 585 556 557 588 564 599 568 600 532 533 545 561 556 565 561 546 565 598 566 609 577 573 539 557 574 560 573 531 561 547 533 579 574 612 601 596 610 532 568 597 588 543 587 524 584 564 524 572 622 556 571 565 568 519 541 550 532 560 593 561 541 575 585 521 578 582 543 556 515 538 549 575 488 562 578 565 564 586 529 558 525 554 590 535 571 555 655 541 543 588 608 596 579 559 535 593 582 628 608 562 585 593 537 570 567 575 555 596 586 549 573 568 549 570 589 575 582 547 586 563 582 580 552 590 566 553 552 581 566 569 554 607 601 586 604 592 553 587 527 602 537 591 602 546 612 552 573 567 563 570 513 573 575 576 555 582 553 541 565 587 556 579 600 531 593 559 552 564 573 581 550 625 586 627 567 570 579 583 612 632 599 601 564 551 622 610 564 546 578 598 558 546 581 570 562 547 562 557 604 574 586 552 568 592 575 550 556 570 600 632 546 536 575 575 568 595 573 564 557 565 544 552 548 553 583 567 538 562 587 565 519 526 564 615 567 592 549 521 539 542 530 571 596 612 587 561 567 570 533 526 575 506 576 527 572 602 554 556 565 565 599 557 595 596 550 568 534 570 603 608 525 547 561 574 581 552 526 582 571 579 576 576 589 616 615 561 616 573 582 579 606 602 613 593 589 570 628 605 612 556 564 600 605 572 590 537 603 574 574 571 598 540 548 601 560 548 558 595 552 579 559 578 574 554 571 528 567 578 549 560 627 561 517 584 558 563 529 587 594 551 546 521 552 533 570 562 537 553 563 583 613 580 588 596 530 561 534 564 620 576 579 577 559 615 561 563 587 565 544 534 508 610 508 578 590 558 517 540 546 594 582 554 537 593 604 601 531 571 551 548 578 578 569 607 553 569 603 566 547 583 568 606 568 541 590 604 574 580 566 593 568 526 565 579 576 537 593 608 558 588 566 585 549 558 544 588 525 601 541 593 546 575 558 567 557 568 602 586 570 544 578 561 554 581 562 566 560 585 554 528 536 552 576 569 539 581 570 524 551 581 555 553 547 541 556 598 523 537 555 546 603 589 524 585 557 524 591 567 577 601 530 569 572 624 602 554 550 550 573 554 571 592 557 591 566 530 577 525 553 536 541 524 576 615 563 599 636 591 586 590 583 600 549 557 574 558 564 619 589 568 573 578 605 608 574 585 611 549 582 559 576 601 580 578 529 602 582 559 610 587 577 580 550 569 566 614 589 578 599 591 587 596 567 529 587 595 570 569 547 572 583 569 557 567 599 588 561 541 557 559 571 639 615 561 555 545 525 617 563 562 599 575 547 550 576 573 579 562 589 516 554 541 629 563 560 611 572 604 530 587 600 546 591 599 587 549 545 576 602 564 593 596 573 562 567 568 525 559 562 561 577 525 555 538 565 595 564 569 520 538 555 589 575 539 561 578 616 563 528 610 543 535 565 622 590 534 591 613 549 493 555 564 627 608 589 564 589 582 585 588 613 588 523 571 583 600 615 608 574 565 538 544 608 588 601 596 653 580 632 595 573 647 626 594 596 644 650 616 598 589 624 611 583 591 598 589 666 607 652 612 584 610 569 573 565 612 582 599 542 563 565 590 615 537 589 545 581 558 613 558 576 569 590 526 558 580 607 593 564 570 584 547 578 546 593 584 517 535 543 562 590 604 586 617 573 583 627 602 586 598 550 545 553 550 574 559 554 545 573 597 571 517 596 586 548 582 601 549 583 554 563 563 595 605 561 570 560 607 556 539 571 545 525 584 594 607 615 598 631 578 572 605 566 577 621 566 546 637 601 561 596 566 582 533 587 642 620 583 545 563 592 597 597 606 600 594 612 618 586 572 581 584 600 592 632 610 610 607 580 648 575 582 604 592 576 576 584 595 563 572 542 614 584 635 533 570 561 564 596 572 581 612 569 569 600 601 554 565 576 540 587 563 596 571 593 558 556 620 539 587 591 563 593 607 591 587 617 553 527 555 569 580 561 602 565 530 581 598 552 589 553 549 539 572 538 571 595 537 546 577 584 565 607 569 544 604 590 612 510 539 580 568 583 568 547 573 564 593 565 594 562 611 565 584 570 591 541 535 565 603 589 590 565 538 586 536 549 569 572 577 587 563 579 558 619 564 579 568 595 569 574 576 552 597 567 608 591 611 561 592 582 608 571 564 547 575 590 588 598 557 569 547 585 615 578 581 610 545 603 531 608 582 553 600 550 583 576 546 583 571 582 564 592 559 585 603 540 568 511 587 576 634 615 631 536 583 609 585 559 564 570 622 634 546 621 539 571 585 595</counts>
			</dataPoints>
		</scan>
	</xrdMeasurement>
</xrdMeasurements>