File: dataset/precursor_mixture/Fe3O4_Nb2O5_Bi2O3-alpha.12-min.xrdml
<?xml version="1.0"?>
<xrdMeasurements xmlns="http://www.xrdml.com/XRDMeasurement/2.2" xmlns:xsi="http://www.w3.org/2001/XMLSchema-instance" xsi:schemaLocation="http://www.xrdml.com/XRDMeasurement/2.2 http://www.xrdml.com/XRDMeasurement/2.2/XRDMeasurement.xsd" status="Completed" recordIdentifier="{A382BB34-E053-45AA-91DC-E0BFB35BBCF8}">
	<comment>
		<entry/>
	</comment>
	<sample type="To be analyzed">
		<id>dara-27-2</id>
		<name></name>
		<preparedBy></preparedBy>
	</sample>
	<xrdMeasurement measurementType="Scan" status="Completed" sampleMode="Reflection">
		<usedWavelength intended="K-Alpha 1">
			<kAlpha1 unit="Angstrom">1.5405980</kAlpha1>
			<kAlpha2 unit="Angstrom">1.5444260</kAlpha2>
			<kBeta unit="Angstrom">1.3922500</kBeta>
			<ratioKAlpha2KAlpha1>0.5000</ratioKAlpha2KAlpha1>
		</usedWavelength>
		<incidentBeamPath>
			<radius unit="mm">145.00</radius>
			<xRayTube id="1010048" name="Empyrean Cu LFF HR (9430 033 7310x) DK437873">
				<tension unit="kV">40.0</tension>
				<current unit="mA">15.0</current>
				<anodeMaterial>Cu</anodeMaterial>
				<focus type="Line">
					<length unit="mm">12.0</length>
					<width unit="mm">0.4</width>
					<takeOffAngle unit="deg">6.0</takeOffAngle>
				</focus>
			</xRayTube>
			<filter id="20010004" name="Beta-filter Nickel">
				<material>Ni</material>
				<thickness unit="mm">0.020</thickness>
			</filter>
			<sollerSlit id="21010002" name="Soller slits 0.04 rad.">
				<opening unit="rad">0.0400</opening>
			</sollerSlit>
			<mask id="22031000" name="Fixed mask 13 mm">
				<width unit="mm">9.00</width>
			</mask>
			<divergenceSlit id="22120001" name="Divergence slit 1°" xsi:type="fixedDivergenceSlitType">
				<distanceToSample unit="mm">50.00</distanceToSample>
				<height unit="mm">1.52</height>
			</divergenceSlit>
		</incidentBeamPath>
		<beamKnife id="29030100" name="Beam knife low"/>
		<sampleMovement xsi:type="spinningSampleMovementType">
			<spinnerRevolutionTime unit="seconds">1.0</spinnerRevolutionTime>
		</sampleMovement>
		<diffractedBeamPath>
			<radius unit="mm">145.00</radius>
			<antiScatterSlit id="22090040" name="AS slit 9 mm" xsi:type="fixedAntiScatterSlitType">
				<height unit="mm">9.00</height>
			</antiScatterSlit>
			<sollerSlit id="21020003" name="Large Soller slits 0.04 rad.">
				<opening unit="rad">0.0400</opening>
			</sollerSlit>
			<filter id="20030001" name="Large beta-filter Nickel">
				<material>Ni</material>
				<thickness unit="mm">0.020</thickness>
			</filter>
			<detector id="7010019" name="PIXcel1D-Medipix3 detector" xsi:type="rtmsDetectorType">
				<phd unit="keV">
					<lowerLevel>4.0</lowerLevel>
					<upperLevel>11.3</upperLevel>
				</phd>
				<mode>Scanning</mode>
				<activeLength unit="deg">5.020</activeLength>
			</detector>
		</diffractedBeamPath>
		<scan appendNumber="0" mode="Continuous" scanAxis="Gonio" status="Completed">
			<header>
				<startTimeStamp>2024-03-24T16:42:01-07:00</startTimeStamp>
				<endTimeStamp>2024-03-24T16:54:28-07:00</endTimeStamp>
				<author>
					<name>AutomatedUser</name>
				</author>
				<source>
					<applicationSoftware version="1.6 (94)">PANalytical Aeris Instrument Suite</applicationSoftware>
					<instrumentControlSoftware version="3.0.0 20211014">AERIS</instrumentControlSoftware>
					<instrumentID>2879380</instrumentID>
				</source>
			</header>
			<dataPoints>
				<positions axis="2Theta" unit="deg">
					<startPosition>9.99043322</startPosition>
					<endPosition>100.09495370</endPosition>
				</positions>
				<positions axis="Omega" unit="deg">
					<startPosition>4.99521661</startPosition>
					<endPosition>50.04747685</endPosition>
				</positions>
				<commonCountingTime unit="seconds">18.249</commonCountingTime>
				<counts unit="counts">5457 5417 5477 5291 5490 5279 5510 5409 5477 5481 5398 5276 5509 5367 5469 5377 5366 5421 5423 5285 5308 5276 5244 5349 5321 5453 5296 5379 5494 5400 5434 5343 5465 5376 5312 5275 5213 5336 5338 5306 5380 5328 5149 5361 5332 5379 5252 5300 5365 5309 5418 5252 5210 5183 5368 5228 5317 5353 5323 5203 5254 5221 5303 5334 5275 5293 5195 5285 5245 5258 5224 5225 5136 5138 4941 5191 5200 5147 5027 5125 5270 5243 5236 4975 5261 5170 5116 5144 5244 5271 5224 5094 5095 5180 5179 5083 5127 5088 5042 5243 5193 5177 5196 5162 5126 5077 5083 5186 5059 5152 4995 5040 5134 5051 5291 5119 5077 5081 5030 5030 4954 4962 5074 5127 4899 5016 5156 5126 4972 5062 5024 4985 5039 5076 5117 5200 5017 4997 5088 4940 4986 5217 4943 5001 5091 5027 5104 5107 5055 4943 4986 5046 4972 4985 5052 5011 5109 5044 5112 5075 4875 5003 5083 4808 4817 5018 4936 5100 5056 5004 4909 5127 4943 4919 4986 5040 4889 4914 5026 4880 5086 4996 4956 4986 4951 5015 4983 4922 4916 5001 5054 5121 4917 5060 4895 5010 5003 4783 4889 4948 5005 4958 4938 4799 4851 4981 4918 4950 4844 4948 4936 4985 4885 4956 4819 4893 4903 4825 5028 4831 4817 4917 4992 4857 4907 4865 4983 4872 4833 4886 4774 4892 4819 4977 4950 4813 4880 4793 4914 4792 5039 4915 4896 4737 4919 4920 4875 4800 4857 4738 4836 4887 4835 4800 4890 4855 4828 4873 4809 4890 4802 4935 4844 4815 4949 4764 4899 4976 4836 4842 4823 4955 4808 4844 4867 4884 4742 4687 4675 4717 4785 4759 4821 4780 4832 4775 4849 4833 4697 4952 4897 4810 4750 4769 4773 4800 4934 4847 4874 4756 4905 4702 4707 4751 4807 4837 4763 4762 4848 4648 4811 4846 4730 4797 4831 4804 4633 4802 4861 4838 4862 4690 4831 4794 4614 4818 4721 4837 4701 4761 4808 4809 4800 4778 4722 4616 4809 4715 4710 4628 4759 4714 4769 4800 4672 4651 4841 4767 4775 4770 4668 4758 4666 4837 4733 4718 4676 4758 4794 4695 4823 4717 4773 4677 4666 4793 4773 4785 4632 4745 4600 4772 4952 4785 4777 4699 4655 4644 4852 4725 4677 4774 4677 4648 4704 4899 4779 4639 4740 4756 4656 4713 4647 4633 4640 4699 4745 4740 4759 4763 4772 4583 4630 4734 4636 4767 4709 4652 4636 4663 4825 4610 4735 4919 4577 4650 4647 4650 4805 4629 4634 4773 4665 4686 4712 4763 4675 4571 4791 4617 4753 4625 4615 4714 4719 4642 4760 4698 4656 4626 4645 4547 4715 4573 4691 4774 4713 4787 4631 4599 4683 4600 4754 4701 4664 4822 4709 4673 4679 4564 4561 4771 4708 4765 4657 4582 4739 4709 4731 4638 4775 4703 4702 4787 4575 4652 4665 4623 4641 4756 4582 4616 4764 4739 4744 4727 4732 4599 4662 4704 4710 4722 4571 4805 4591 4635 4568 4672 4603 4762 4615 4623 4536 4703 4688 4621 4605 4727 4713 4707 4631 4700 4585 4727 4596 4653 4608 4621 4598 4645 4625 4620 4644 4719 4688 4688 4721 4930 4658 4682 4712 4748 4649 4588 4738 4704 4595 4636 4606 4736 4722 4657 4628 4624 4580 4607 4692 4659 4620 4744 4599 4602 4601 4700 4553 4686 4665 4662 4702 4558 4670 4634 4665 4648 4754 4632 4694 4770 4595 4740 4736 4622 4631 4460 4606 4613 4637 4628 4614 4804 4701 4697 4680 4748 4607 4717 4711 4746 4689 4618 4865 4627 4765 4749 4818 4661 4750 4712 4748 4594 4536 4689 4709 4662 4726 4696 4807 4643 4694 4583 4762 4785 4775 4654 4635 4746 4661 4737 4828 4732 4762 4736 4683 4858 4656 4861 4873 4929 4791 4781 4863 4887 5002 4961 4884 4963 4849 4713 4768 4748 4782 4858 4874 4711 4847 4867 4959 4906 4905 4916 4783 4890 4838 4837 4815 4879 4845 5013 4854 5008 4759 4925 4843 4966 4794 4770 4832 4717 4683 4727 4717 4739 4626 4675 4570 4680 4513 4571 4559 4660 4613 4611 4676 4653 4669 4568 4584 4538 4603 4542 4593 4574 4658 4768 4553 4679 4699 4647 4516 4539 4634 4585 4593 4562 4579 4487 4678 4630 4599 4663 4609 4677 4612 4595 4728 4545 4660 4692 4532 4592 4525 4495 4754 4614 4547 4606 4582 4527 4596 4692 4559 4602 4669 4600 4580 4639 4801 4586 4627 4559 4596 4847 4572 4691 4671 4714 4701 4754 4620 4698 4682 4656 4750 4667 4768 4843 4883 4982 4870 5011 4801 4939 4949 5140 5078 5232 5293 5167 5244 5218 5251 5336 5227 5289 5151 5254 4974 5084 4943 4880 4938 4872 4822 4682 4742 4723 4633 4615 4639 4727 4731 4572 4528 4485 4560 4642 4757 4584 4574 4658 4488 4605 4531 4540 4489 4531 4626 4618 4613 4664 4582 4655 4589 4507 4615 4512 4536 4501 4608 4535 4581 4522 4457 4626 4636 4535 4531 4470 4595 4523 4487 4538 4613 4542 4448 4454 4606 4537 4546 4583 4481 4610 4572 4598 4396 4491 4549 4548 4513 4631 4645 4650 4556 4394 4529 4478 4538 4553 4602 4587 4469 4520 4592 4520 4572 4549 4420 4543 4637 4599 4600 4546 4459 4545 4610 4423 4470 4445 4547 4540 4426 4737 4503 4624 4564 4541 4621 4698 4495 4873 4658 4716 4720 4714 4726 4807 4795 4870 4979 4965 5117 4984 5007 5105 5146 4977 4969 4869 4958 4736 4671 4587 4650 4529 4589 4506 4505 4483 4449 4468 4545 4513 4358 4456 4430 4438 4426 4408 4274 4447 4430 4509 4466 4500 4444 4513 4462 4478 4429 4358 4343 4337 4379 4476 4498 4478 4442 4461 4497 4456 4505 4472 4492 4418 4511 4506 4485 4438 4367 4536 4569 4471 4420 4533 4316 4436 4469 4459 4430 4394 4354 4435 4465 4465 4484 4350 4446 4477 4435 4448 4430 4400 4528 4421 4319 4280 4447 4406 4299 4427 4387 4427 4425 4467 4397 4294 4452 4380 4388 4459 4294 4441 4451 4400 4332 4420 4403 4418 4338 4368 4344 4515 4447 4329 4389 4325 4372 4234 4270 4406 4545 4260 4460 4292 4363 4477 4407 4405 4504 4346 4326 4246 4421 4306 4346 4359 4355 4333 4420 4415 4231 4329 4321 4396 4366 4350 4352 4317 4429 4264 4418 4379 4415 4310 4298 4360 4430 4357 4371 4298 4272 4302 4414 4456 4340 4313 4242 4592 4477 4387 4363 4466 4434 4483 4487 4584 4573 4520 4562 4498 4721 4817 4867 4965 4884 5041 4980 5088 5076 5205 5012 5169 4854 4805 4794 4832 4645 4674 4615 4446 4325 4417 4394 4359 4376 4452 4367 4314 4312 4459 4400 4341 4380 4428 4348 4415 4328 4346 4358 4352 4417 4379 4414 4354 4491 4584 4428 4478 4457 4515 4564 4573 4400 4545 4611 4621 4723 4625 4747 4615 4715 4747 4868 4863 4855 4984 5065 5299 5279 5458 5592 5789 6133 6340 6634 6953 7282 7819 8328 8773 9361 10085 10803 11435 11932 12728 13269 13492 13416 13213 12898 11895 11220 10274 9410 8646 7954 7113 6446 6109 5737 5263 5194 4870 4879 4752 4748 4711 4643 4501 4601 4625 4555 4504 4417 4428 4513 4403 4399 4359 4518 4453 4318 4308 4292 4445 4342 4488 4384 4358 4395 4417 4322 4309 4191 4310 4285 4238 4205 4332 4349 4218 4307 4324 4290 4274 4320 4348 4261 4288 4241 4442 4272 4323 4400 4278 4329 4327 4323 4358 4151 4310 4273 4202 4265 4339 4287 4239 4324 4277 4224 4406 4188 4394 4119 4294 4227 4302 4190 4258 4314 4251 4323 4086 4264 4243 4225 4235 4167 4264 4266 4187 4274 4356 4346 4298 4302 4327 4356 4276 4349 4188 4267 4269 4279 4200 4168 4186 4232 4285 4266 4313 4344 4219 4459 4266 4305 4374 4308 4180 4179 4358 4154 4288 4156 4334 4260 4338 4274 4247 4305 4224 4332 4173 4170 4249 4166 4310 4344 4232 4202 4245 4317 4329 4305 4297 4280 4259 4314 4206 4308 4335 4483 4452 4345 4517 4575 4642 4784 4688 5031 4972 5095 5361 5411 5525 5501 5597 5610 5599 5337 5299 5147 5153 4898 4855 4784 4589 4493 4471 4491 4497 4432 4244 4368 4233 4274 4183 4234 4310 4233 4154 4250 4276 4110 4236 4278 4161 4235 4272 4193 4230 4221 4201 4235 4153 4220 4135 4202 4239 4242 4307 4311 4253 4251 4231 4189 4328 4216 4180 4280 4199 4316 4372 4269 4440 4374 4311 4381 4349 4437 4360 4462 4377 4326 4356 4462 4471 4480 4402 4239 4449 4367 4415 4251 4251 4360 4360 4486 4333 4343 4418 4408 4206 4263 4415 4502 4539 4474 4649 4674 4763 4768 4994 4989 5147 5344 5370 5593 5658 5935 6104 6342 6658 7000 7239 7352 7655 7498 7417 6809 6635 6348 6007 5766 5494 5080 4881 4779 4518 4429 4403 4330 4202 4297 4287 4298 4311 4245 4168 4147 4281 4284 4299 4255 4160 4195 4219 4080 4210 4063 4283 4157 4316 4189 4219 4205 4154 4200 4335 4154 4267 4210 4263 4229 4199 4214 4257 4125 4228 4218 4191 4234 4276 4296 4131 4348 4364 4223 4421 4233 4287 4150 4304 4306 4259 4330 4403 4337 4336 4327 4493 4284 4497 4330 4480 4185 4446 4399 4531 4506 4451 4586 4635 4652 4595 4663 4823 4910 5102 5270 5461 5634 5990 6056 6424 6833 7159 7699 8358 8691 9197 9820 10243 10601 10624 10351 9855 9332 8888 8404 7865 7167 6887 6345 5890 5627 5465 5097 5176 4996 5105 5132 5289 5414 5477 5532 5774 5908 6160 6452 6975 7474 7954 8448 9092 10059 11215 12371 13929 15547 17696 19442 21843 23978 26703 28751 30408 31260 30126 28064 25454 22739 20635 18851 17086 14922 12506 10339 8671 7365 6463 5882 5656 5479 5303 5088 5163 4960 5012 4835 5092 4940 4954 4867 4849 4840 4814 4900 4883 4850 4674 4731 4834 4749 4873 4968 4852 4878 5131 4952 5210 5281 5397 5537 5697 5927 6226 6686 6869 7335 7662 7958 8356 8462 8708 8439 8045 7655 7203 7086 6930 6636 6446 6105 5943 5883 5832 5971 6032 6224 6680 6957 7277 7687 8142 8774 9466 9906 10556 11750 12128 12716 13172 13618 13789 13809 13136 12327 11776 11184 10450 9784 9267 8447 7677 7093 6597 6099 5878 5480 5404 5052 4959 4952 4716 4851 4687 4586 4564 4615 4588 4651 4598 4634 4634 4612 4758 4589 4602 4570 4785 4680 4807 5066 5044 5108 5283 5339 5434 5506 5869 6039 6263 6461 6793 6958 7217 7365 7708 7775 7835 7796 7838 7516 7288 6857 6517 6491 6064 5680 5440 5456 5121 4962 4837 4681 4590 4585 4668 4563 4628 4510 4651 4435 4428 4515 4497 4501 4425 4424 4415 4319 4331 4434 4316 4289 4328 4386 4297 4298 4107 4238 4176 4253 4071 4175 4151 4179 4147 4128 4079 4113 4215 4034 4222 4196 4119 4094 4239 4246 4095 4209 4172 4205 4139 4131 4221 4205 4149 4130 4235 4182 4243 4300 4241 4309 4250 4321 4261 4302 4194 4266 4329 4388 4254 4371 4423 4301 4501 4611 4652 4662 4866 4961 5003 5266 5379 5643 5784 6013 6171 6471 6636 6818 6808 6602 6677 6821 6688 6471 6335 6128 6003 5833 5525 5501 5271 5134 4961 4829 4769 4727 4678 4540 4541 4483 4449 4444 4380 4221 4268 4292 4218 4222 4314 4307 4118 4340 4013 4049 4188 4250 4137 4121 4118 4064 4075 4077 4103 4145 4157 3992 4089 4021 3965 4115 4035 4026 3999 4069 4051 4067 3933 4012 4001 4010 4047 3964 4098 3953 3968 4014 4059 3780 4086 4053 4012 4007 4039 4079 4005 4100 4003 3981 4008 4002 4033 3980 4054 4039 3935 3992 4022 4034 3979 3900 3919 4051 4023 3978 4089 3959 4057 4154 4015 4083 4068 3981 3950 3979 3983 3933 4015 4070 3935 4018 3957 4025 3980 3922 3929 3937 4037 3891 3995 3920 4029 3966 4009 3966 4006 3903 4018 3972 3987 4008 4054 4166 4006 3940 3951 4026 4022 4005 4022 4004 4101 3960 4000 3933 3921 3919 4020 3895 3951 4023 3929 3985 4082 3922 4030 4031 3886 4047 4078 3899 3949 3990 4006 3999 4058 3952 3948 3950 4028 4035 3946 4006 3992 3924 3959 4049 4025 3975 4068 3941 4097 4048 3977 4085 3934 4101 4022 4023 3982 4124 3974 3998 4044 4050 3977 3935 4030 4051 4163 4060 4079 4005 3986 4132 4058 4254 4012 4239 4223 4224 4252 4397 4305 4261 4556 4428 4689 4901 4930 4977 5046 5019 5047 4875 4828 4650 4598 4584 4610 4539 4548 4618 4379 4361 4197 4202 4248 4211 4396 4343 4342 4341 4394 4282 4480 4356 4499 4476 4489 4591 4541 4592 4610 4689 4812 5010 5100 5057 5369 5450 5700 5978 6437 6819 7325 8134 8677 9552 10326 11073 11437 11595 11673 11128 10383 9994 9752 9660 9669 9628 9479 9619 9792 9854 10394 10827 11426 12052 12184 12564 12428 11953 11425 10578 9866 9243 8890 8484 7867 7457 6884 6094 5526 5156 4889 4731 4593 4500 4360 4082 4144 4233 4186 4289 4126 4142 4125 4148 4156 4149 4071 4064 4097 3978 4137 3983 4084 4102 3990 3950 3935 3947 4072 4090 4006 4028 4068 3989 4060 4026 4043 4081 4071 4131 4140 4245 4257 4323 4373 4418 4624 4710 4877 4994 4909 4955 4914 4723 4765 4573 4537 4410 4439 4442 4334 4277 4060 4099 4088 3990 4040 4025 3933 3952 3995 4010 3913 3914 3999 3813 3847 4015 3997 4118 3980 4036 4022 3973 4016 4034 3953 3857 3912 3918 3849 3940 3975 4000 4022 4006 4034 4138 4047 4144 4057 4124 4065 3895 3993 4088 4092 3996 4112 4032 4153 4066 4074 4102 4053 4077 4074 3980 3984 4028 4145 3935 4002 4112 4063 3929 4096 3878 4027 3897 3998 4065 4081 4126 4246 4301 4166 4347 4440 4433 4570 4706 4672 5090 5396 5486 5704 6061 6495 6731 6902 7145 6918 6814 6640 6310 6039 6058 6077 5816 5549 5541 5443 5384 5090 5117 5009 4854 5073 5026 5287 5539 5687 6093 6527 6899 7585 7989 8842 9704 10494 11470 12356 13249 13671 14261 14305 13993 14160 13752 13534 12745 12696 12019 11561 10927 10272 9575 8800 8406 7709 7229 6874 6475 6253 5756 5553 5404 5300 5038 5017 4923 4808 4775 4651 4689 4467 4575 4457 4698 4501 4591 4619 4693 4708 4774 4704 4971 5114 5103 5075 5149 4991 4803 4789 4633 4599 4570 4585 4514 4390 4383 4356 4223 4067 4229 3918 4085 3970 4082 4039 3947 3979 4038 3955 3869 3972 4111 4027 3959 4001 4097 4114 4010 4072 4003 4070 3962 4067 4251 4213 4242 4192 4389 4372 4441 4664 4691 4937 5184 5359 5522 5839 6136 6495 6706 7120 7291 7235 7677 7321 7311 7032 6889 6771 6458 6284 6199 6101 5773 5458 5200 5107 4903 4768 4565 4501 4402 4427 4369 4377 4156 4351 4242 4234 4402 4382 4350 4523 4466 4706 4744 4880 5199 5412 5612 5979 6236 6389 6481 6630 6544 6497 6496 6466 6601 6619 6166 6290 5849 5826 5496 5285 5260 4965 4952 4744 4594 4518 4454 4217 4234 4102 4036 3982 3945 3973 3926 3957 3935 3952 3976 3954 3843 3949 3955 3877 3996 3928 3910 3970 3917 4007 4088 4112 4201 4366 4459 4613 4632 4822 5037 5247 5581 5770 6029 6022 5830 5793 5563 5307 5060 5022 4958 4955 4952 4835 4676 4616 4509 4073 4011 3982 3903 3860 3976 3808 3937 3906 3862 4029 3903 3740 3829 3750 3778 3702 3779 3791 3652 3747 3775 3843 3727 3806 3795 3759 3795 3698 3856 3720 3727 3766 3750 3797 3700 3780 3590 3714 3755 3588 3722 3678 3778 3726 3880 3710 3758 3744 3779 3850 3672 3748 3678 3687 3721 3803 3792 3729 3798 3682 3804 3786 3781 3715 3647 3934 3672 3717 3746 3718 3752 3656 3723 3789 3760 3677 3671 3764 3825 3651 3647 3764 3757 3668 3675 3778 3618 3663 3704 3736 3765 3771 3745 3615 3671 3735 3742 3678 3832 3652 3716 3681 3705 3723 3787 3672 3690 3755 3659 3698 3646 3584 3702 3668 3687 3747 3709 3677 3620 3651 3680 3740 3759 3722 3676 3695 3745 3681 3621 3690 3774 3673 3759 3708 3630 3637 3669 3721 3609 3677 3644 3645 3646 3656 3594 3697 3684 3693 3646 3604 3711 3717 3684 3599 3756 3633 3623 3727 3656 3656 3610 3638 3645 3681 3719 3760 3728 3710 3751 3520 3688 3698 3672 3678 3681 3797 3737 3695 3706 3777 3677 3605 3580 3760 3630 3715 3615 3618 3651 3699 3744 3689 3768 3732 3646 3776 3782 3720 3777 3833 3781 3809 3924 4028 4023 4214 4100 4360 4490 4613 4615 4590 4715 4579 4501 4432 4365 4246 4119 4282 4292 4199 4175 4196 3942 3893 3831 3825 3734 3786 3782 3725 3782 3702 3603 3735 3723 3729 3709 3745 3627 3651 3622 3734 3761 3673 3652 3663 3576 3743 3626 3665 3655 3622 3744 3632 3720 3785 3790 3677 3648 3722 3735 3806 3715 3804 3744 3787 3683 3733 3719 3760 3808 3736 3621 3691 3690 3688 3715 3599 3580 3645 3681 3742 3610 3631 3686 3629 3643 3760 3601 3715 3613 3716 3781 3779 3660 3683 3581 3732 3636 3677 3657 3647 3674 3537 3586 3734 3665 3604 3632 3657 3646 3611 3666 3696 3701 3722 3708 3669 3631 3578 3761 3781 3756 3775 3854 3651 3714 3688 3748 3619 3924 3817 4000 3989 4203 4205 4313 4516 4457 4537 4742 4480 4253 4269 4075 4190 4159 4044 4143 4086 4124 4006 4099 3922 3857 3791 3748 3796 3769 3669 3669 3783 3678 3819 3793 3730 3779 3767 3881 3837 3844 3944 3850 4010 4049 4258 4302 4368 4441 4366 4223 4330 4239 4190 4008 4176 3976 4129 4005 4118 3962 3863 3886 3900 3819 3872 3614 3840 3719 3781 3756 3708 3754 3813 3763 3787 3830 3843 3862 3714 3898 3930 4009 4032 4122 4222 4348 4533 4694 4910 5062 5121 5001 4936 4808 4742 4603 4351 4479 4524 4422 4479 4535 4395 4346 4345 4112 4129 4074 4055 4032 3931 4010 3996 4124 3984 4117 3895 3937 3867 3868 3913 3947 3977 3911 3850 3758 3910 3748 3784 4006 3854 3868 3804 3949 3826 3862 3828 3835 3904 3896 4009 3968 4062 4199 4281 4302 4571 4653 4791 4870 5102 5234 5274 5419 5426 5383 5324 5501 5298 5416 5216 5259 5000 5106 4905 4846 4752 4793 4550 4512 4385 4321 4212 4088 4104 3984 3985 3987 3958 3927 3786 3830 3809 3759 3750 3754 3717 3718 3670 3723 3625 3608 3758 3748 3669 3631 3618 3586 3580 3724 3668 3695 3759 3639 3679 3745 3655 3627 3643 3714 3794 3643 3659 3692 3570 3610 3712 3648 3570 3472 3639 3816 3637 3662 3641 3691 3595 3543 3599 3673 3677 3593 3657 3607 3708 3606 3615 3610 3803 3626 3726 3637 3634 3608 3634 3742 3727 3567 3599 3680 3604 3612 3693 3620 3705 3655 3679 3559 3633 3679 3589 3628 3727 3687 3752 3836 3899 3780 3937 3855 3889 4105 3965 3912 3865 3917 3821 3731 3910 3788 3927 3880 3921 3955 3768 3831 3739 3759 3763 3782 3757 3700 3738 3766 3691 3690 3786 3672 3666 3631 3724 3693 3711 3735 3731 3683 3720 3618 3560 3719 3583 3687 3784 3651 3641 3678 3731 3576 3740 3669 3724 3904 3667 3771 3725 3948 3833 3789 3874 3879 3961 3814 4065 4007 4091 4297 4264 4408 4444 4514 4658 4785 4980 4800 5026 4947 4724 4838 4720 4482 4473 4341 4217 4258 4307 4378 4277 4133 4085 4061 4052 3944 3872 3797 3687 3854 3790 3728 3681 3675 3718 3624 3704 3821 3730 3736 3732 3720 3745 3672 3698 3705 3630 3706 3720 3624 3676 3651 3682 3673 3802 3757 3694 3733 3685 3640 3679 3677 3752 3641 3779 3652 3625 3692 3800 3656 3744 3727 3772 3737 3800 3715 3899 3878 3947 4020 3956 3935 3943 4115 4067 4050 4044 4129 4225 4067 4148 4374 4428 4382 4656 4695 4936 5015 5485 5642 5804 5762 5806 5833 5625 5780 5893 5842 5987 6134 6470 6807 7145 7846 8307 8593 9037 9631 9593 9627 9212 8737 8157 7514 7182 6959 6767 6604 6802 6753 6657 6538 6076 5660 5279 5017 4623 4441 4306 4240 4060 4025 4030 3853 3947 3813 3831 3742 3749 3780 3755 3779 3812 3846 3776 3648 3673 3668 3615 3730 3696 3697 3625 3642 3673 3735 3515 3614 3736 3690 3718 3608 3616 3784 3632 3702 3668 3730 3847 3810 3796 3685 3804 3733 3803 3716 3730 3695 3659 3732 3662 3632 3750 3721 3744 3792 3703 3701 3701 3714 3793 3659 3593 3702 3563 3637 3613 3572 3660 3759 3668 3776 3698 3689 3755 3797 3744 3865 3879 4066 4069 3914 4049 3911 3961 3988 3996 4009 4006 4129 4029 4225 4247 4220 4369 4428 4249 4194 4151 4100 4020 3963 3869 3801 4020 3959 3821 3912 3953 3919 3647 3787 3725 3689 3605 3761 3600 3810 3681 3663 3751 3711 3699 3736 3575 3785 3625 3654 3610 3640 3703 3696 3803 3713 3711 3638 3631 3595 3672 3766 3553 3768 3703 3560 3648 3735 3621 3733 3681 3664 3712 3873 3732 3799 3675 3749 3763 3871 3778 3850 3900 4031 3994 4197 4381 4368 4702 4736 5038 5017 5211 5155 5067 4939 4623 4710 4425 4569 4720 4816 4942 5121 5165 5525 5544 5894 5703 5443 5266 5133 4898 4528 4456 4510 4368 4362 4548 4497 4495 4583 4301 4280 4213 4042 3982 3896 3815 3797 3770 3733 3744 3723 3719 3778 3786 3828 3627 3778 3644 3736 3744 3700 3714 3707 3735 3628 3831 3823 3738 3864 3682 3715 3730 3781 3791 3750 3805 3746 3714 3878 3822 3861 3768 3876 3792 3948 3806 3804 3879 3918 3894 3937 3933 3949 4097 3927 3940 4047 4096 4224 4347 4457 4406 4506 4614 4790 4931 4739 4817 4548 4496 4392 4266 4368 4181 4264 4381 4300 4306 4332 4256 4193 4207 4192 4057 4037 4195 4210 4330 4387 4538 4422 4631 4834 4899 4893 4939 4936 4827 4665 4645 4679 4688 4746 4717 4734 4827 4880 4894 4967 5014 5238 5197 5027 5140 5085 4812 4473 4335 4249 4163 4170 4209 4220 4249 4348 4240 4315 4097 4058 3865 3969 3852 3781 3881 3725 3665 3793 3732 3699 3688 3742 3740 3717 3830 3763 3688 3805 3731 3707 3839 3787 3851 3916 3788 3882 3776 3725 3622 3827 3783 3799 3828 3796 3875 3764 3827 3884 3962 3742 3934 3841 3908 3782 3773 3942 3942 3814 3907 3914 3843 3942 3967 4066 3969 4050 4036 4142 4174 4134 4294 4308 4353 4534 4578 4625 4718 4880 4977 5072 5091 5386 5265 5226 5310 5190 5205 4994 4898 4791 4762 4702 4710 4677 4766 4542 4593 4560 4324 4329 4270 4240 4164 4106 4073 3912 3864 4018 3916 3927 4006 4105 4061 4018 4063 3989 4183 4177 4142 4093 4039 4033 3995 4103 3962 4020 3904 3884 3927 3961 3971 3910 3952 3911 3784 3985 3866 3832 3948 3853 4000 3946 4017 4026 4006 4275 4240 4401 4533 4675 4805 4930 5033 4935 5122 4853 4870 4779 4537 4394 4332 4399 4305 4330 4460 4539 4720 4695 4687 4669 4721 4835 4981 5228 5138 5149 5172 4989 4758 4708 4482 4362 4437 4256 4326 4405 4442 4512 4495 4445 4470 4333 4241 4072 4060 4078 3908 3880 3903 4002 3909 4075 4016 4102 4027 4183 4387 4393 4751 4870 5251 5501 5932 6371 6690 6959 6977 6769 6202 5820 5420 5101 4900 5023 4956 5182 5191 5281 5387 5327 5129 4957 4843 4486 4150 4126 4104 3937 4017 3751 3796 3808 3763 3835 3759 3698 3798 3873 3753 3830 3831 3768 3882 3882 3806 3890 3901 3894 4016 3793 3913 3969 4111 4094 4297 4266 4500 4738 4891 5052 5384 5645 5818 5914 5858 5774 5448 5184 4829 4748 4595 4635 4610 4665 4629 4682 4901 4859 4644 4699 4429 4259 4221 4177 4100 3992 3978 3887 3974 3949 3972 3985 4020 4015 4096 4087 4163 4139 4248 4141 4279 4281 4179 4234 4255 4322 4196 4105 4210 4256 4239 4206 4165 4287 4077 4077 4020 4186 3903 3937 3931 3940 3969 3985 3758 3883 3757 3710 3788 3792 3834 3896 3850 3860 3784 3769 3788 3793 3788 3703 3660 3752 3644 3808 3701 3791 3678 3690 3844 3846 3768 3819 3832 3725 3744 3791 3639 3680 3680 3706 3726 3704 3691 3684 3630 3632 3752 3809 3761 3832 3836 3792 3744 3704 3758 3667 3796 3823 3809 3721 3759 3707 3838 3756 3895 3705 3679 3828 3763 3864 3535 3674 3638 3666 3687 3820 3705 3685 3730 3697 3754 3749 3780 3813 3757 3758 3680 3744 3777 3763 3858 3773 3848 3887 3876 3974 4023 4120 4118 4315 4656 4870 5247 5703 6136 6564 6904 6726 6789 6396 5963 5509 5194 5080 4813 5056 5126 5212 5406 5665 5784 5899 5930 5770 5606 5591 5452 5336 5274 5405 5376 5237 5215 4947 4972 4846 4817 4809 4838 4889 4775 4962 4808 4782 4927 4780 4756 4620 4751 4727 4717 4929 4786 4930 5044 5078 4882 5151 5140 5256 5391 5385 5472 5551 5722 5866 6055 6167 6354 6127 5983 5847 5680 5565 5569 5332 5311 5078 5113 5039 4900 4939 4933 4828 4784 4636 4376 4402 4266 4112 4136 3962 4033 4140 3967 3986 4026 3934 4037 4188 4052 3979 4168 4271 4338 4555 4639 4893 4934 5213 5277 5215 5032 4775 4651 4501 4269 4171 4361 4236 4273 4347 4488 4392 4401 4425 4447 4372 4153 4121 4038 3948 3965 3904 3941 3847 3754 3901 3830 3950 3834 3927 3938 3979 4047 4072 4162 4212 4367 4301 4416 4510 4636 4497 4647 4649 4576 4706 4493 4487 4591 4514 4547 4420 4516 4456 4476 4322 4296 4460 4281 4333 4294 4162 4134 3964 3976 4031 4061 4176 3933 3941 3978 3980 3917 3901 3879 4021 3968 4073 4146 4071 4223 4303 4479 4467 4726 4830 5010 5154 5153 5251 5075 5508 5389 5468 5425 5482 5497 5472 5552 5482 5484 5367 5371 5414 5413 5199 5145 5068 5121 4928 4841 4792 4759 4665 4424 4472 4314 4526 4293 4225 4312 4135 4164 4118 4132 3992 3888 3982 3847 3877 3791 3680 3893 3923 3776 3763 3760 3842 3805 3787 3725 3831 3723 3779 3787 3743 3747 3827 3759 3682 3792 3829 3703 3721 3673 3692 3771 3749 3814 3746 3706 3877 3982 4014 4109 4018 4175 4290 4450 4673 4459 4695 4585 4663 4719 4600 4759 4675 4908 4768 4914 4827 4791 4793 4732 4545 4583 4577 4485 4354 4523 4352 4324 4483 4269 4253 4229 3977 4009 4043 3952 3941 4011 3949 4012 3991 3931 3966 3994 4245 4166 4295 4529 4701 4767 4879 5041 4935 4952 4999 4677 4483 4325 4227 4175 4195 4272 4304 4223 4418 4575 4461 4516 4522 4566 4437 4409 4422 4403 4487 4476 4610 4710 4752 4888 4818 4738 4572 4581 4447 4472 4290 4348 4341 4221 4230 4416 4208 4326 4282 4167 4067 4199 4092 4073 3999 3967 4014 3945 3932 3903 3930 3835 3844 4001 3932 3957 4009 4031 4354 4282 4385 4440 4584 4644 4773 4794 4960 4691 4733 4512 4301 4232 4186 4060 4153 4193 4187 4263 4105 4242 4050 4134 4226 4057 3928 3953 3801 3821 3716 3639 3668 3543 3637 3648 3555 3759 3688 3722 3644 3563 3611 3618 3650 3678 3626 3629 3645 3568 3600 3565 3492 3619 3645 3658 3583 3625 3595 3587 3737 3522 3681 3605 3647 3580 3582 3582 3608 3595 3641 3567 3664 3668 3611 3632 3596 3802 3643 3676 3740 3833 3694 3744 3778 3795 3791 3953 3866 3926 3697 3971 3845 3785 3890 3765 3780 3869 3882 3901 3990 3727 3767 3767 3745 3772 3852 3866 3672 3778 3596 3699 3676 3750 3735 3686 3632 3651 3783 3690 3674 3589 3632 3631 3619 3583 3588 3518 3523 3589 3572 3622 3617 3630 3664 3537 3562 3622 3592 3614 3596 3708 3494 3717 3605 3724 3709 3636 3625 3684 3612 3569 3549 3729 3711 3623 3544 3749 3617 3709 3566 3687 3670 3561 3558 3716 3622 3590 3528 3623 3691 3565 3616 3743 3632 3633 3555 3681 3697 3750 3763 3741 3686 3595 3779 3710 3676 3543 3609 3680 3605 3526 3694 3704 3789 3640 3514 3622 3615 3696 3675 3732 3687 3614 3708 3601 3634 3575 3738 3569 3645 3609 3589 3616 3606 3591 3723 3633 3570 3693 3676 3605 3847 3741 3887 3826 3877 4043 4110 4341 4479 4475 4603 4716 4744 4699 4526 4329 4273 4108 4030 3971 4056 4014 4095 4145 4041 4258 4207 4264 4298 4276 4114 4096 3931 3921 4039 3893 4007 4147 4320 4507 4401 4537 4541 4626 4432 4233 4196 4101 4016 3989 3900 4012 4011 3937 3989 4133 4151 4107 4001 4181 4078 4079 4021 3819 3950 3805 3789 3820 3812 3716 3790 3853 3767 3976 3884 3881 3943 4044 4083 4093 4259 4227 4376 4387 4456 4655 4582 4652 4690 4629 4569 4672 4888 4920 5035 5373 5599 5881 6144 6269 6376 6528 6632 6464 6349 6428 6394 6514 6470 6376 6299 6370 6251 6412 6428 6258 6289 6082 5945 5901 5801 5483 5619 5483 5310 5226 5326 5246 4994 5010 4807 4744 4604 4413 4558 4453 4152 4181 4305 4176 4103 4075 4054 3832 3874 3938 3956 3977 3913 3792 3806 3776 3711 3776 3811 3819 3769 3705 3626 3705 3640 3645 3748 3727 3696 3728 3740 3743 3700 3809 3779 3701 3706 3681 3683 3701 3702 3776 3658 3717 3878 3684 3714 3821 3760 3772 3796 3819 3770 3761 3995 3961 3917 4082 4221 4109 4114 4272 4240 4459 4559 4628 4783 4669 4769 4765 4509 4582 4580 4672 4334 4314 4380 4433 4258 4354 4348 4420 4375 4286 4290 4188 4150 4136 4103 3995 4093 3998 3922 3918 3809 3790 3884 3746 3768 3819 3741 3759 3737 3646 3720 3670 3518 3642 3690 3605 3525 3487 3595 3549 3576 3597 3614 3658 3654 3660 3564 3681 3627 3515 3653 3552 3542 3524 3570 3446 3517 3546 3644 3566 3514 3481 3595 3636 3614 3624 3586 3634 3623 3636 3509 3501 3598 3586 3696 3473 3571 3477 3491 3576 3423 3548 3566 3468 3595 3616 3632 3644 3512 3614 3664 3581 3519 3556 3554 3593 3585 3652 3635 3704 3424 3586 3546 3537 3608 3612 3476 3591 3611 3656 3699 3710 3615 3620 3738 3605 3749 3697 3656 3684 3734 3680 3666 3575 3640 3567 3729 3553 3609 3678 3620 3590 3654 3647 3668 3562 3576 3531 3538 3555 3677 3477 3578 3574 3529 3552 3564 3542 3597 3534 3560 3655 3612 3569 3495 3601 3648 3754 3632 3678 3628 3646 3628 3747 3579 3591 3691 3603 3512 3582 3590 3535 3680 3693 3583 3577 3540 3469 3587 3616 3643 3618 3513 3509 3573 3607 3585 3596 3504 3647 3660 3737 3628 3580 3626 3624 3790 3654 3772 3617 3645 3688 3588 3627 3686 3652 3684 3615 3635 3725 3597 3539 3523 3629 3560 3614 3668 3648 3558 3615 3684 3792 3613 3654 3684 3615 3632 3709 3739 3590 3684 3744 3711 3830 3926 3930 3960 3914 3931 3909 3921 4162 4021 3910 3933 3899 3799 3844 3698 3721 3588 3685 3764 3840 3738 3798 4040 3787 3817 3653 4009 3810 3767 3812 3870 3610 3666 3747 3751 3715 3644 3899 3782 3765 3732 3737 3642 3708 3707 3614 3658 3714 3762 3749 3828 3815 3970 4078 4160 4170 4235 4278 4222 4299 4174 4235 4150 4264 4264 4299 4326 4047 4071 4067 3978 4023 4070 3994 3965 4095 3892 3944 4030 3823 3986 3961 4032 3920 3980 3799 3757 3709 3738 3712 3660 3729 3620 3633 3599 3527 3702 3625 3571 3594 3584 3576 3627 3569 3498 3543 3652 3665 3577 3607 3661 3678 3623 3621 3656 3668 3591 3559 3727 3661 3718 3579 3727 3611 3611 3514 3642 3603 3645 3515 3606 3550 3677 3538 3504 3544 3587 3576 3539 3550 3553 3540 3628 3458 3645 3632 3699 3691 3751 3783 3871 3921 3948 4022 3986 4078 4089 4100 3868 3725 3879 3754 3764 3744 3646 3711 3651 3772 3688 3901 3827 3773 3924 3792 3766 3720 3787 3781 3708 3629 3654 3683 3695 3651 3598 3549 3501 3627 3600 3777 3703 3660 3648 3628 3576 3631 3541 3612 3582 3638 3634 3535 3595 3565 3616 3587 3555 3716 3699 3844 3847 3860 4018 3855 4079 4288 4276 4269 4425 4153 4273 4014 4004 3875 3949 3773 3693 3818 3875 3944 3919 3852 4039 3908 4165 4108 4116 3931 3976 4069 3986 3775 3811 3932 3814 3716 3853 3732 3750 3805 3837 3840 3779 3682 3780 3758 3687 3662 3719 3678 3607 3671 3561 3687 3733 3811 3662 3648 3649 3710 3617 3538 3659 3634 3585 3626 3601 3556 3632 3570 3587 3673 3620 3706 3642 3643 3646 3577 3650 3655 3508 3564 3555 3554 3518 3647 3716 3627 3635 3567 3660 3650 3584 3609 3670 3618 3536 3767 3740 3848 3772 3820 3682 3997 3926 3931 3827 3923 4025 3952 3979 3960 3972 3832 3955 4006 3820 3819 3967 3995 3925 4044 4069 4083 4000 4116 3912 3948 3895 3812 3657 3706 3739 3682 3672 3700 3712 3776 3795 3757 3762 3977 3783 3797 3721 3792 3682 3688 3722 3673 3808 3753 3795 3850 3911 3841 3729 3857 3863 3954 3854 3807 3770 3880 3816 3733 3836 3781 3865 3741 3762 3787 3775 3763 3794 3847 3833 3827 3852 3656 3810 3802 3874 3768 3754 3655 3697 3731 3619 3694 3566 3845 3639 3757 3755 3600 3763 3871 3694 3754 3815 3584 3649 3626 3613 3606 3726 3715 3764 3834 3747 3751 3875 3903 3849 3892 3819 3923 4060 4055 4086 4021 3957 4004 3979 3983 3932 3891 3858 3941 4059 3985 3985 4039 4131 4083 4217 4117 4162 4277 4277 4330 4299 4416 4422 4388 4324 4356 4239 4105 4088 4182 4043 3954 3917 4024 4101 4074 4060 4080 4233 4129 4296 4551 4586 4777 4800 4920 5065 5115 5091 4910 4946 4719 4622 4693 4673 4360 4378 4449 4195 4182 4327 4189 4193 4225 4256 4261 4246 4292 4223 4236 4119 4108 3959 3995 4039 3879 3906 3874 3718 3673 3768 3706 3602 3689 3694 3639 3674 3659 3540 3609 3578 3568 3633 3682 3620 3584 3751 3641 3710 3781 3849 3756 3890 3841 3913 3856 3875 3869 3775 3806 3674 3689 3602 3577 3650 3560 3600 3726 3735 3606 3581 3682 3924 3855 3936 3845 3922 3850 4035 3886 4046 4016 4190 4109 4069 3893 3863 3897 3764 3786 3786 3707 3767 3701 3664 3626 3651 3680 3661 3833 3675 3815 3791 3705 3811 3678 3695 3594 3640 3481 3649 3575 3452 3560 3531 3483 3648 3501 3641 3512 3461 3513 3582 3453 3521 3463 3410 3490 3450 3528 3454 3442 3560 3602 3543 3525 3494 3483 3596 3524 3511 3457 3453 3541 3484 3521 3494 3442 3385 3334 3524 3475 3555 3351 3357 3484 3516 3419 3598 3604 3428 3563 3423 3610 3562 3489 3424 3543 3377 3463 3487 3490 3556 3470 3460 3598 3605 3552 3550 3661 3671 3509 3645 3575 3567 3717 3700 3631 3537 3647 3596 3483 3656 3533 3525 3567 3628 3571 3610 3547 3525 3718 3689 3620 3483 3662 3519 3600 3619 3646 3531 3567 3744 3624 3594 3558 3652 3618 3758 3654 3677 3746 3806 3804 3987 3889 3889 3872 3909 3876 4084 4044 4058 3932 4182 4165 4194 4239 4238 4217 4283 4182 4211 4235 3902 3893 3981 3739 3989 3829 3848 3858 3889 3849 3889 3817 4090 4085 3957 3964 3939 3894 4024 3794 3905 3937 3968 4090 4043 4090 4260 4180 4264 4293 3908 3975 3876 3907 3840 3738 3795 3671 3762 3787 3692 3737 3805 3744 3848 3935 3796 3852 3791 3843 3601 3781 3611 3603 3718 3583 3624 3564 3579 3616 3462 3655 3521 3575 3704 3611 3607 3679 3595 3749 3759 3724 3824 3765 3767 3918 3882 3775 3824 3809 3773 3812 3779 3772 3661 3631 3658 3764 3702 3669 3780 3740 3753 3752 3663 3749 3699 3680 3704 3591 3606 3648 3598 3676 3612 3667 3486 3472 3562 3496 3540 3611 3577 3533 3549 3581 3443 3412 3468 3612 3576 3507 3504 3502 3451 3594 3546 3427 3482 3421 3453 3529 3466 3449 3444 3455 3501 3532 3658 3396 3554 3543 3452 3472 3540 3611 3488 3486 3546 3500 3447 3464 3458 3606 3551 3523 3432 3526 3569 3420 3490 3446 3579 3603 3558 3443 3534 3508 3564 3365 3481 3500 3407 3466 3527 3421 3585 3444 3491 3428 3625 3510 3510 3485 3502 3586 3553 3480 3375 3540 3442 3539 3526 3449 3542 3443 3477 3603 3545 3432 3574 3553 3518 3477 3548 3590 3563 3482 3442 3503 3654 3555 3489 3465 3563 3492 3405 3539 3448 3505 3511 3438 3507 3501 3450 3597 3445 3561 3539 3467 3558 3539 3469 3559 3535 3392 3485 3424 3496 3475 3460 3571 3530 3560 3567 3431 3534 3471 3547 3388 3459 3538 3449 3436 3561 3489 3444 3568 3497 3456 3505 3582 3536 3510 3497 3508 3548 3545 3548 3679 3583 3601 3713 3687 3764 3621 3749 3844 3801 3795 3627 3727 3766 3708 3735 3760 3700 3641 3639 3601 3687 3704 3635 3681 3761 3742 3640 3610 3738 3602 3713 3773 3780 3795 3722 3812 3749 3754 3798 3820 3874 3821 3930 3980 3883 3985 3990 3833 3967 3994 3958 3997 4054 4005 3952 4019 3957 3912 4009 3844 3894 3908 3944 3822 3901 3887 3852 3902 3730 3770 3757 3898 3836 3855 3794 3811 3688 3749 3694 3710 3841 3683 3777 3721 3589 3727 3598 3696 3548 3626 3536 3564 3600 3528 3540 3547 3560 3573 3626 3459 3421 3561 3540 3607 3555 3569 3563 3533 3547 3480 3497 3560 3561 3635 3630 3568 3597 3595 3506 3622 3459 3616 3583 3501 3495 3494 3655 3572 3632 3549 3577 3603 3655 3632 3550 3587 3635 3626 3539 3592 3638 3712 3650 3677 3716 3835 3779 3845 3808 3849 3939 3848 3842 3897 3845 3811 3785 3814 3781 3721 3782 3747 3876 3766 3730 3796 3945 3848 3866 3969 3969 3938 3827 3897 3945 3753 3857 3841 3826 3857 3822 3651 3781 3847 3774 3813 3740 3828 3827 3797 3882 3844 3810 3951 3800 3939 3984 4120 4157 4008 4131 4179 4175 4218 4184 4267 4134 4198 4006 4006 4039 3881 3913 4015 3873 3754 3852 3893 3781 3884 4053 3777 3896 3767 3841 3789 3892 3932 3795 3819 3794 3722 3727 3765 3639 3739 3752 3666 3690 3889 3764 3895 3857 3864 3945 4015 4144 3996 4100 4050 3804 3827 3790 3782 3792 3757 3775 3694 3633 3720 3679 3699 3692 3665 3727 3733 3663 3788 3859 3819 3876 3748 3775 3785 3772 3850 3773 3740 3812 3798 3884 3712 3803 3703 3731 3854 3929 3940 3984 3926 4089 4006 4152 4014 3992 4002 4006 4237 4006 4040 4121 4062 3915 3883 3885 3885 4052 3824 4052 4106 4096 4025 4117 3896 3956 3947 3891 3868 3844 3733 3737 3764 3755 3669 3742 3707 3612 3715 3571 3636 3665 3720 3709 3710 3674 3550 3550 3726 3573 3545 3623 3571 3612 3526 3532 3713 3448 3457 3498 3573 3629 3517 3503 3545 3551 3389 3616 3601 3488 3596 3493 3430 3479 3509 3555 3460 3521 3531 3631 3423 3678 3608 3464 3653 3560 3648 3589 3636 3622 3509 3632 3525 3558 3525 3580 3676 3714 3663 3685 3753 3780 3802 3822 3760 3800 3773 3720 3669 3747 3705 3590 3744 3600 3542 3641 3591 3605 3593 3750 3543 3619 3597 3653 3712 3763 3638 3701 3708 3612 3738 3713 3704 3522 3512 3634 3497 3645 3574 3507 3567 3538 3495 3554 3517 3613 3475 3583 3586 3645 3592 3675 3450 3627 3476 3574 3668 3601 3616 3635 3537 3543 3663 3524 3624 3485 3584 3637 3577 3668 3586 3573 3536 3619 3495 3688 3689 3764 3900 3973 3858 4044 4023 4253 4353 4338 4470 4378 4433 4343 4332 4157 4013 3982 3904 3800 3837 3767 3712 3631 3819 3774 3756 3792 3718 3845 3899 3976 3933 4100 3928 3986 3914 3888 3863 3805 3838 3676 3656 3547 3657 3672 3617 3551 3598 3681 3599 3501 3595 3508 3580 3493 3689 3482 3603 3592 3706 3481 3503 3603 3394 3442 3554 3588 3561 3470 3571 3553 3519 3542 3493 3598 3709 3600 3633 3681 3724 3771 3756 4008 3754 3793 3728 3707 3818 3653 3670 3674 3601 3658 3584 3649 3648 3556 3525 3607 3563 3649 3611 3575 3643 3658 3723 3647 3724 3582 3732 3523 3692 3704 3616 3564 3469 3547 3542 3626 3515 3513 3608 3544 3504 3545 3477 3654 3573 3481 3562 3505 3507 3526 3499 3477 3513 3393 3471 3516 3566 3482 3450 3602 3463 3506 3528 3560 3537 3544 3622 3529 3665 3678 3667 3557 3579 3598 3574 3531 3499 3565 3603 3463 3468 3629 3552 3616 3505 3553 3545 3534 3541 3655 3544 3471 3509 3573 3620 3506 3550 3566 3476 3521 3562 3359 3599 3549 3504 3632 3652 3565 3666 3642 3750 3844 3835 4024 4028 3975 4130 4039 4078 3870 3746 3709 3799 3834 3689 3720 3702 3721 3617 3590 3760 3746 3718 3698 3731 3757 3778 3965 3835 3896 3953 3942 4017 4008 3843 3865 3589 3719 3722 3725 3659 3552 3629 3676 3602 3641 3599 3667 3642 3543 3707 3526 3726 3609 3573 3685 3652 3567 3644 3632 3711 3715 3620 3654 3583 3703 3661 3593 3646 3888 3774 3781 3743 3702 3647 3646 3735 3666 3576 3646 3492 3622 3463 3653 3563 3572 3553 3571 3648 3597 3525 3616 3599 3467 3614 3649 3612 3535 3595 3595 3511 3520 3600 3648 3452 3563 3654 3444 3537 3511 3498 3651 3675 3699 3599 3676 3594 3672 3466 3458 3577 3534 3718 3527 3528 3546 3618 3585 3610 3520 3671 3531 3618 3584 3625 3580 3586 3622 3575 3459 3433 3512 3579 3552 3665 3565 3571 3549 3501 3611 3516 3650 3533 3567 3603 3608 3517 3539 3468 3661 3566 3566 3541 3493 3530 3640 3590 3584 3495 3556 3633 3457 3528 3545 3550 3559 3517 3406 3585 3628 3511 3488 3463 3531 3568 3514 3704 3676 3569 3596 3494 3577 3519 3674 3638 3586 3508 3502 3619 3681 3551 3545 3678 3676 3670 3742 3852 3773 3875 3900 3920 3950 4099 4143 4121 4155 4054 4079 4169 4064 4096 3825 3941 3954 3938 4002 3834 4024 3907 3935 3870 3947 3941 4016 4047 3954 4094 4188 4052 4286 4150 4236 4298 4220 4308 4126 4131 4099 4101 4051 4044 4045 3907 3770 3769 3858 3819 3917 3783 3745 3737 3723 3687 3658 3796 3699 3671 3699 3792 3781 3738 3695 3750 3728 3648 3740 3671 3695 3562 3681 3570 3552 3686 3564 3516 3596 3555 3517 3639 3609 3432 3595 3553 3490 3620 3525 3607 3454 3552 3478 3627 3462 3690 3562 3504 3446 3484 3524 3615 3638 3661 3775 3799 3897 3818 4071 4059 3930 3905 3876 3857 3748 3663 3771 3629 3638 3671 3686 3618 3694 3680 3699 3712 3735 3672 3782 3675 3589 3786 3780 3817 3855 3755 3839 3771 3931 3740 3613 3788 3658 3771 3639 3583 3629 3641 3640 3555 3553 3609 3676 3612 3563 3673 3645 3546 3712 3756 3618 3601 3727 3726 3772 3753 3630 3693 3709 3895 3842 3806 3969 3757 3928 3884 3898 3824 3637 3755 3669 3553 3646 3558 3629 3660 3640 3578 3545 3608 3633 3609 3659 3440 3599 3686 3678 3681 3750 3722 3762 3589 3680 3645 3686 3707 3677 3596 3573 3632 3562 3562 3722 3590 3676 3636 3508 3540 3614 3516 3638 3596 3629 3535 3596 3603 3535 3675 3536 3649 3724 3602 3568 3548 3613 3639 3583 3524 3523 3493 3638 3550 3587 3601 3545 3568 3555 3539 3589 3576 3526 3567 3526 3542 3534 3634 3656 3460 3662 3610 3600 3647 3527 3523 3628 3609 3666 3629 3619 3605 3691 3783 3712 3602 3782 3753 3836 3745 3955 3843 3873 3830 3817 3957 3764 3890 3835 3793 3950 3933 4047 3947 3929 4059 4076 3995 4039 4032 4169 4177 4020 4164 4146 4045 4205 4091 3974 3934 3869 3975 3922 3913 3973 3875 3908 3916 3936 3953 3889 3862 3796 4021 4103 4118 4094 3920 4033 3980 3908 3885 3913 3815 3946 3810 3835 3729 3782 3945 3807 3892 3750 3677 3766 3797 3696 3634 3752 3647 3796 3800 3718 3723 3688 3701 3804 3680 3803 3627 3651 3620 3646 3642 3591 3791 3690 3696 3817 3824 3786 3822 3840 3815 3854 3878 3689 3652 3665 3714 3649 3646 3664 3543 3526 3508 3634 3549 3506 3570 3555 3504 3660 3599 3686 3655 3642 3558 3660 3615 3714 3657 3815 3568 3590 3623 3570 3618 3630 3583 3523 3529 3512 3632 3583 3527 3618 3561 3474 3509 3536 3526 3493 3468 3555 3417 3565 3512 3406 3511 3500 3518 3669 3509 3579 3430 3632 3633 3576 3692 3630 3603 3768 3682 3771 3746 3691 3700 3704 3630 3622 3745 3593 3733 3759 3732 3678 3753 3741 3617 3694 3570 3540 3658 3714 3574 3426 3622 3480 3721 3578 3586 3545 3763 3645 3597 3543 3611 3612 3638 3516 3589 3542 3658 3564 3569 3644 3521 3554 3472 3607 3527 3549 3543 3542 3485 3572 3613 3600 3763 3693 3676 3832 3901 3962 3915 3878 3785 3866 3749 3712 3701 3815 3816 3683 3746 3771 3769 3733 3630 3656 3605 3714 3713 3737 3763 3698 3681 3745 3830 3740 3767 3890 3726 3716 3656 3719 3684 3662 3653 3622 3807 3602 3589 3622 3730 3632 3617 3595 3630 3556 3608 3599 3576 3735 3586 3588 3616 3579 3562 3648 3630 3578 3605 3585 3549 3584 3595 3625 3596 3579 3539 3595 3598 3732 3464 3548 3579 3621 3674 3420 3676 3697 3537 3624 3607 3630 3696 3744 3652 3739 3711 3737 3634 3722 3805 3792 3747 3797 3633 3633 3607 3680 3712 3690 3660 3521 3668 3596 3764 3676 3736 3544 3817 3728 3688 3731 3707 3525 3694 3687 3815 3599 3708 3550 3649 3605 3676 3672 3557 3608 3681 3648 3656 3545 3578 3577 3630 3727 3615 3647 3651 3687 3656 3712 3692 3748 3623 3772 3889 3942 3778 3930 3982 3853 3781 3902 3755 3881 3763 3792 3693 3783 3702 3695 3734 3846 3678 3778 3771 3652 3698 3607 3665 3597 3666 3699 3801 3642 3685 3633 3805 3632 3669 3694 3561 3750 3772 3774 3599 3685 3694 3689 3651 3862 3735 3919 3713 3691 3834 3762 3767 3711 3693 3665 3550 3596 3587 3449 3648 3525 3744 3611 3590 3509 3532 3826 3637 3638 3677 3751 3655 3673 3636 3718 3821 3722 3823 3669 3714 3660 3810 3733 3753 3791 3786 3681 3776 3628 3815 3741 3720 3746 3822 3706 3698 3783 3789 3753 3692 3669 3693 3694 3747 3652 3680 3704 3634 3669 3659 3724 3636 3727 3649 3657 3624 3757 3835 3731 3676 3714 3744 3733 3694 3662 3697 3738 3552 3564 3614 3594 3597 3538 3546 3623 3667 3663 3569 3471 3620 3548 3568 3587 3628 3537 3636 3528 3683 3594 3600 3594 3543 3651 3502 3535 3448 3499 3537 3612 3533 3462 3457 3478 3579 3451 3565 3503 3444 3627 3619 3615 3609 3675 3583 3682 3744 3587 3673 3543 3542 3567 3678 3529 3560 3678 3464 3460 3493 3573 3576 3609 3652 3533 3596 3630 3722 3680 3748 3693 3756 3803 3831 3703 3719 3764 3828 3825 3825 3827 3690 3802 3750 3839 3787 3803 3757 3687 3707 3601 3687 3603 3662 3539 3632 3623 3574 3724 3648 3704 3567 3774 3638 3742 3648 3595 3737 3702 3760 3681 3641 3614 3716 3916 3823 3735 3811 3717 3861 3602 3775 3635 3603 3797 3774 3661 3688 3486 3517 3564 3559 3564 3606 3589 3558 3529 3546 3472 3590 3554 3579 3527 3585 3683 3518 3576 3506 3637 3550 3511 3590 3543 3568 3469 3539 3597 3550 3533 3512 3537 3477 3569 3470 3447 3512 3576 3444 3433 3608 3505 3514 3424 3494 3479 3395 3587 3386 3588 3446 3491 3427 3430 3485 3450 3473 3568 3476 3459 3505 3298 3525 3518 3427 3392 3436 3446 3470 3554 3424 3536 3470 3542 3564 3373 3416 3540 3487 3397 3426 3492 3402 3505 3404 3426 3524 3513 3500 3409 3561 3523 3553 3419 3412 3433 3462 3536 3536 3501 3542 3403 3494 3513 3432 3491 3615 3444 3410 3428 3488 3557 3517 3537 3452 3522 3456 3462 3501 3466 3568 3540 3488 3570 3589 3458 3595 3556 3645 3587 3544 3593 3704 3564 3641 3669 3542 3524 3551 3641 3579 3565 3661 3690 3574 3569 3571 3625 3491 3630 3667 3667 3714 3796 3645 3720 3676 3681 3595 3644 3662 3668 3695 3603 3549 3602 3730 3584 3491 3634 3661 3520 3553 3524 3562 3697 3640 3635 3590 3515 3610 3666 3531 3450 3530 3604 3507 3620 3690 3509 3546 3454 3745 3578 3604 3473 3484 3600 3546 3498 3435 3505 3476 3516 3458 3592 3599 3496 3475 3481 3547 3472 3395 3500 3474 3548 3452 3441 3464 3444 3595 3453 3544 3512 3539 3467 3448 3489 3443 3580 3403 3532 3420 3555 3571 3551 3518 3611 3482 3552 3516 3604 3552 3627 3528 3630 3566 3500 3526 3430 3664 3663 3493 3512 3580 3536 3542 3570 3637 3537 3577 3597 3662 3575 3631 3616 3701 3573 3519 3459 3565 3570 3576 3627 3561 3612 3559 3736 3509 3608 3645 3643 3632 3564 3557 3589 3559 3491 3620 3621 3666 3452 3663 3629 3593 3516 3557 3505 3563 3688 3617 3499 3585 3509 3647 3480 3615 3665 3545 3622 3639 3652 3674 3697 3770 3666 3573 3767 3724 3631 3810 3799 3751 3868 3684 3749 3754 3625 3822 3679 3661 3673 3536 3600 3598 3641 3686 3632 3794 3591 3662 3707 3741 3689 3756 3764 3780 3789</counts>
			</dataPoints>
		</scan>
	</xrdMeasurement>
</xrdMeasurements>