File: dataset/precursor_mixture/Fe3O4_CuO_Ga2O3.12-min.xrdml
<?xml version="1.0"?>
<xrdMeasurements xmlns="http://www.xrdml.com/XRDMeasurement/2.2" xmlns:xsi="http://www.w3.org/2001/XMLSchema-instance" xsi:schemaLocation="http://www.xrdml.com/XRDMeasurement/2.2 http://www.xrdml.com/XRDMeasurement/2.2/XRDMeasurement.xsd" status="Completed" recordIdentifier="{4860FE4F-526D-4CBB-9397-A2B18CCF989E}">
	<comment>
		<entry/>
	</comment>
	<sample type="To be analyzed">
		<id>dara-22-2</id>
		<name></name>
		<preparedBy></preparedBy>
	</sample>
	<xrdMeasurement measurementType="Scan" status="Completed" sampleMode="Reflection">
		<usedWavelength intended="K-Alpha 1">
			<kAlpha1 unit="Angstrom">1.5405980</kAlpha1>
			<kAlpha2 unit="Angstrom">1.5444260</kAlpha2>
			<kBeta unit="Angstrom">1.3922500</kBeta>
			<ratioKAlpha2KAlpha1>0.5000</ratioKAlpha2KAlpha1>
		</usedWavelength>
		<incidentBeamPath>
			<radius unit="mm">145.00</radius>
			<xRayTube id="1010048" name="Empyrean Cu LFF HR (9430 033 7310x) DK430614">
				<tension unit="kV">40.0</tension>
				<current unit="mA">15.0</current>
				<anodeMaterial>Cu</anodeMaterial>
				<focus type="Line">
					<length unit="mm">12.0</length>
					<width unit="mm">0.4</width>
					<takeOffAngle unit="deg">6.0</takeOffAngle>
				</focus>
			</xRayTube>
			<filter id="20010004" name="Beta-filter Nickel">
				<material>Ni</material>
				<thickness unit="mm">0.020</thickness>
			</filter>
			<sollerSlit id="21010002" name="Soller slits 0.04 rad.">
				<opening unit="rad">0.0400</opening>
			</sollerSlit>
			<mask id="22031000" name="Fixed mask 13 mm">
				<width unit="mm">9.00</width>
			</mask>
			<divergenceSlit id="22120001" name="Divergence slit 1°" xsi:type="fixedDivergenceSlitType">
				<distanceToSample unit="mm">50.00</distanceToSample>
				<height unit="mm">1.52</height>
			</divergenceSlit>
		</incidentBeamPath>
		<beamKnife id="29030100" name="Beam knife low"/>
		<sampleMovement xsi:type="spinningSampleMovementType">
			<spinnerRevolutionTime unit="seconds">1.0</spinnerRevolutionTime>
		</sampleMovement>
		<diffractedBeamPath>
			<radius unit="mm">145.00</radius>
			<antiScatterSlit id="22090040" name="AS slit 9 mm" xsi:type="fixedAntiScatterSlitType">
				<height unit="mm">9.00</height>
			</antiScatterSlit>
			<sollerSlit id="21020003" name="Large Soller slits 0.04 rad.">
				<opening unit="rad">0.0400</opening>
			</sollerSlit>
			<filter id="20030001" name="Large beta-filter Nickel">
				<material>Ni</material>
				<thickness unit="mm">0.020</thickness>
			</filter>
			<detector id="7010019" name="PIXcel1D-Medipix3 detector" xsi:type="rtmsDetectorType">
				<phd unit="keV">
					<lowerLevel>4.0</lowerLevel>
					<upperLevel>11.3</upperLevel>
				</phd>
				<mode>Scanning</mode>
				<activeLength unit="deg">5.020</activeLength>
			</detector>
		</diffractedBeamPath>
		<scan appendNumber="0" mode="Continuous" scanAxis="Gonio" status="Completed">
			<header>
				<startTimeStamp>2024-02-18T09:03:52-08:00</startTimeStamp>
				<endTimeStamp>2024-02-18T09:16:20-08:00</endTimeStamp>
				<author>
					<name>AutomatedUser</name>
				</author>
				<source>
					<applicationSoftware version="1.4b (28)">PANalytical Aeris Instrument Suite</applicationSoftware>
					<instrumentControlSoftware version="2.0.0 20210224">AERIS</instrumentControlSoftware>
					<instrumentID>950485</instrumentID>
				</source>
			</header>
			<dataPoints>
				<positions axis="2Theta" unit="deg">
					<startPosition>9.99043322</startPosition>
					<endPosition>100.09495370</endPosition>
				</positions>
				<positions axis="Omega" unit="deg">
					<startPosition>4.99521661</startPosition>
					<endPosition>50.04747685</endPosition>
				</positions>
				<commonCountingTime unit="seconds">18.249</commonCountingTime>
				<counts unit="counts">6361 6401 6442 6407 6378 6350 6263 6428 6396 6246 6407 6245 6304 6310 6520 6466 6402 6308 6367 6332 6340 6402 6436 6330 6356 6430 6414 6302 6293 6262 6321 6284 6390 6404 6353 6344 6438 6288 6371 6310 6475 6367 6268 6320 6303 6379 6394 6359 6355 6169 6263 6247 6318 6477 6358 6435 6140 6264 6407 6354 6415 6317 6425 6272 6219 6251 6125 6203 6219 6429 6184 6248 6327 6225 6316 6272 6250 6327 6378 6370 6252 6224 6434 6329 6325 6336 6304 6174 6514 6210 6299 6288 6065 6231 6322 6057 6175 6186 6281 6219 6299 6441 6177 6196 6282 6201 6119 6235 6153 6328 6369 6281 6135 6345 6363 6184 6139 6226 6228 6276 6242 6298 6226 6177 6449 6206 6251 6330 6364 6298 6171 6248 6256 6257 6204 6300 6186 6371 6304 6221 6164 6283 6317 6278 6333 6119 6247 6165 6271 6213 6291 6290 6157 6418 6313 6210 6096 6400 6378 6235 6162 6258 6310 6251 6270 6274 6184 6144 5974 6220 6283 6275 6289 6311 6268 6204 6095 6414 6192 6174 6219 6180 6232 6238 6215 6317 6293 6175 6332 6288 6230 6208 6130 6276 6230 6211 6191 6265 6089 6176 6273 6224 6205 6187 6192 6012 6252 6297 6158 6114 6273 6236 6257 6213 6209 6123 6226 6152 6232 6178 6130 6093 6134 6076 6118 6228 6076 6245 6339 6085 6219 6174 6253 6141 6339 6213 6260 6192 6305 6247 6210 6206 6330 6176 6251 6233 6218 6276 6246 6082 6234 6170 6224 6237 6245 6177 6251 6230 6272 6266 6061 6223 6258 6267 6155 6116 6122 6167 6327 6165 6130 6230 6268 6198 6134 6079 6300 6357 6367 6234 6242 6273 6317 6311 6337 6228 6159 6138 6243 6414 6197 6266 6262 6212 6169 6202 6281 6262 6327 6283 6127 6291 6329 6201 6310 6407 6072 6328 6274 6290 6334 6503 6271 6159 6223 6178 6342 6355 6222 6348 6130 6307 6356 6213 6295 6256 6219 6423 6375 6250 6370 6330 6290 6326 6482 6295 6302 6272 6240 6289 6433 6247 6357 6385 6330 6310 6238 6377 6474 6168 6478 6237 6288 6419 6363 6413 6204 6304 6295 6320 6430 6258 6263 6272 6477 6426 6255 6289 6439 6504 6245 6313 6332 6407 6435 6200 6365 6081 6369 6374 6228 6404 6444 6360 6388 6413 6441 6516 6320 6280 6432 6325 6520 6504 6386 6314 6470 6379 6321 6321 6252 6333 6313 6160 6426 6473 6423 6465 6451 6350 6474 6355 6511 6596 6422 6227 6503 6455 6318 6285 6421 6366 6374 6381 6418 6398 6417 6381 6438 6473 6369 6456 6452 6514 6572 6496 6277 6561 6400 6448 6528 6591 6261 6429 6469 6330 6436 6390 6528 6419 6365 6519 6503 6421 6477 6404 6412 6562 6560 6682 6490 6430 6377 6490 6519 6421 6537 6364 6370 6512 6452 6555 6358 6439 6489 6753 6448 6608 6484 6536 6573 6519 6538 6495 6468 6405 6631 6529 6568 6412 6408 6475 6639 6405 6610 6600 6490 6554 6521 6427 6492 6716 6492 6630 6670 6602 6475 6701 6649 6649 6559 6648 6695 6446 6614 6711 6546 6637 6558 6702 6666 6766 6742 6625 6728 6644 6667 6594 6514 6659 6902 6743 6583 6750 6595 6638 6668 6595 6753 6510 6702 6624 6643 6702 6710 6762 6667 6699 6693 6678 6577 6750 6703 6511 6684 6478 6704 6694 6609 6601 6687 6572 6805 6656 6695 6710 6696 6667 6595 6502 6766 6565 6672 6558 6592 6890 6598 6656 6654 6576 6656 6492 6852 6697 6744 6601 6691 6685 6716 6789 6596 6698 6722 6711 6754 6702 6812 6687 6664 6835 6735 6838 6824 6747 6930 6711 6710 6612 6778 6538 6825 6637 6636 6783 6658 6863 6681 6721 6627 6793 6685 6664 6751 6711 6611 6748 6629 6726 6683 6860 6895 6703 6779 6793 6727 6795 6734 6862 6743 6761 6808 6795 6940 6699 6841 6763 6702 6546 6738 6720 6713 6732 6822 6793 6678 6707 6618 6765 6783 6643 6734 6927 6779 6797 6714 6734 7030 6813 6774 6700 6779 6664 6644 6822 6857 6874 6794 6877 6733 6686 6762 6741 6783 6785 6634 6754 6801 6728 6891 6775 6930 6799 6853 6930 6844 6756 6760 7011 6769 6658 6952 6802 6668 6733 6883 6786 6789 6950 6899 6855 6772 6906 6817 6819 6652 6850 6955 6949 6745 6813 6780 6748 6749 6795 6793 6691 6700 6859 6798 6694 6862 6701 6758 6906 6897 6777 6879 6736 6759 6863 6993 6808 6920 6879 7016 7148 6878 7147 7007 7077 7024 7041 7082 7046 7176 7271 7317 7374 7389 7457 7664 7621 7586 7804 7841 7901 8033 7824 8077 7942 7950 7945 7558 7840 7649 7408 7372 7283 7294 7271 7129 7164 7098 7159 7050 7131 7040 7100 7119 7083 7010 7126 6968 7109 7259 7022 7337 7325 7288 7282 7359 7373 7216 7412 7577 7450 7647 7705 7744 7758 7670 7895 8170 8187 8349 8369 8725 8868 8836 8930 9238 9462 9466 9339 9582 9667 9741 9581 9724 9476 9646 9250 9049 8841 8569 8509 8346 8110 8008 7759 7598 7681 7627 7578 7459 7357 7387 7277 7269 7205 7124 7177 7208 7150 7230 7074 7106 7015 7110 7096 6924 6958 7090 7142 7146 7204 6938 6874 7139 6973 7019 6947 6974 6858 6900 6953 7116 7014 6943 6831 6912 7028 7059 6903 6902 6988 6921 6895 6993 7010 6898 6862 6798 7009 6913 6895 6828 7101 6986 6827 6972 6941 7007 7011 6845 6847 6972 6865 6771 6806 6902 7102 6835 6844 6958 6777 6902 6843 6853 6803 6926 6900 6839 6896 6729 7002 6990 6846 6868 7066 6875 6862 6906 6886 6844 6885 6772 6866 6918 6896 6935 6796 6902 6899 6931 6778 6989 6829 6694 6811 6816 7015 6806 6982 6904 6948 6843 6945 6975 6846 6801 6950 6907 6970 6836 6904 6980 6897 6802 6804 6848 6967 6884 6950 6885 6939 6884 6870 6926 6937 6807 6994 6786 6806 7058 6912 6802 6909 6937 6785 6922 6960 6970 6920 6858 6801 6954 7027 6936 6949 7083 7137 6866 6854 6943 7011 6958 7050 6725 6945 7007 7004 7030 7027 7020 7099 6834 6898 6901 6959 7000 6985 7027 6864 6697 6884 7037 6873 6807 6912 6842 6906 6730 6831 6769 6900 6768 6887 6833 6761 6825 6950 6954 6933 6931 6843 7031 6998 7175 6942 6888 6892 6905 6856 6980 6892 7024 6953 6972 6975 6926 7010 6841 7034 6941 6886 6875 6827 7047 6851 6790 6969 6865 6943 6979 6824 6834 6820 6916 6991 6803 6967 6788 6876 7053 6877 6735 6999 6988 6997 6741 6976 6884 6851 6959 6895 7024 6762 6969 6947 6828 7045 6856 6871 6846 6940 6799 6773 7038 6902 6945 6917 6853 6741 6846 6934 6916 7057 6989 6971 6971 6963 6896 6900 6936 6959 6907 6907 6849 6714 6954 6888 6835 6688 6829 6979 6919 6897 6766 6786 6914 6837 6902 6897 6965 6921 6898 6788 6776 6832 6927 6828 6896 6911 6859 6721 6855 6959 6879 6884 6957 6905 6926 6896 6687 6853 6795 6905 6795 6802 6902 6760 6815 6772 6667 6882 6779 6754 6934 6861 6952 6814 6902 6947 7042 6822 6906 6869 6737 6861 6800 6805 6821 6954 6764 6894 6808 6718 6869 6910 7001 6852 6752 6784 6939 6891 6903 6886 6889 6906 6746 6929 6894 6908 6697 6780 7041 6800 6755 6868 6853 6894 6716 6826 6820 6798 6761 6891 6844 6793 6788 7103 6748 6796 6876 6889 6942 6862 6878 6854 6783 6879 6808 6796 6802 7012 6881 6878 7005 6896 6755 6962 6810 6724 6797 6885 6885 6856 6802 7003 6757 6778 6976 6753 6907 6817 6825 6884 6781 6936 6849 6956 6929 6857 6899 6864 6885 6952 6911 6859 6719 6826 6639 6814 6833 6847 6912 6816 6867 6808 6821 6844 6786 6908 6775 7034 6888 6965 7047 6804 7071 6842 6985 6912 6949 7073 6956 6923 6865 6930 6897 6960 6965 6934 6883 6880 6888 6967 6974 6919 6829 6855 6759 7021 6882 6799 6842 6846 7042 6832 6866 6776 6846 6732 6819 6968 6773 6819 6835 6866 6677 6888 6854 6863 6793 7040 6860 6963 6726 6816 6797 6884 6938 6807 6760 6797 6798 6756 6905 6746 6770 6767 6859 6790 6821 6779 6884 6814 6701 6845 6948 6789 6782 6854 6793 6716 6776 6922 6816 6770 6743 6802 6717 6749 6980 6762 6700 6650 6810 6628 6816 6725 6819 6878 6928 6910 6845 6805 6867 6791 6684 6781 6839 6751 6802 6735 6882 6759 6615 6603 6740 6912 6723 6852 6688 6594 6800 6821 6867 6954 6776 6692 6654 6828 6950 6797 6768 6947 6741 6709 6844 6796 6689 6897 6740 6624 6675 6732 6915 6675 6848 6886 6595 6822 6898 6855 6690 6720 6919 6741 6734 6691 6680 6844 6736 6825 6834 6858 6727 6901 6857 6741 6742 6934 6937 6814 6863 6764 6855 6668 6605 6799 6784 6771 6849 6909 6864 6924 6558 6780 6782 6849 6841 6973 6913 6693 6787 6789 6852 6723 6821 6829 6786 6801 6685 6746 6741 6711 6921 6789 6775 6819 6698 6831 6860 6695 6858 6769 6708 6976 6815 6623 6709 6698 6816 6748 6729 6788 6767 6777 6707 6757 6645 6709 6721 6694 6820 6770 6687 6827 6625 6716 6819 7038 6772 6761 6714 6755 6765 6804 6801 6780 6726 6694 6692 6784 6681 6748 6831 6852 6704 6953 6661 6677 6632 6738 6678 6654 6886 6773 6830 6676 6587 6675 6743 6700 6845 6859 6650 6743 6744 6862 6600 6804 6763 7028 6695 6795 6606 6641 6727 6892 6755 6736 6944 6604 6871 6760 6906 6716 6822 6754 6745 6715 6669 6873 6647 6866 6825 6752 6824 6850 6797 6706 6814 6705 6880 6596 6744 6685 6673 6753 6805 6835 6851 6913 6791 6700 6819 6815 6780 6721 6735 6794 6692 6844 6807 6748 6878 6823 6557 6723 6827 6934 6832 6633 6803 6583 6894 6665 6609 6864 6700 6727 6703 6767 6704 6754 6741 6589 6850 6732 6873 6696 6743 6773 6732 6807 6858 6761 6742 6776 6871 6720 6909 6709 6798 6696 6706 6719 6851 7009 6750 6807 6616 6759 6933 6811 6786 6676 6832 6778 6699 6692 6633 6726 6846 6752 6699 6676 6670 6678 6788 6834 6748 6770 6817 6627 6677 6750 6735 6752 6681 6827 6729 6692 6699 6856 6669 6844 6797 6754 6855 6701 6616 6758 6798 6711 6798 6901 6831 6889 6819 6978 6762 6806 6938 6819 6848 6737 6671 6965 6886 6733 6757 6823 6673 6928 6790 7004 6632 6767 6914 6821 6858 6883 6778 6762 6810 6732 6988 6821 7002 6894 6687 6839 6812 6842 6739 6986 6890 6926 6850 6836 6776 6886 6947 6888 6930 6987 7084 6907 6890 6890 6958 6874 6993 6967 6914 6847 7071 7002 7053 6918 7123 6916 7133 7032 7252 7164 7236 7265 7351 7127 7127 7172 7255 7147 7097 7184 7299 7243 7275 7215 7091 7194 7285 7128 7441 7243 7368 7400 7420 7510 7565 7501 7305 7470 7729 7657 7586 7779 7824 7775 7844 7760 7936 8011 8003 8013 8157 8366 8581 8429 8752 9069 9105 9202 9321 9680 9680 10186 10534 10672 11273 11509 11903 12427 12860 13441 13832 14262 14298 14353 14380 14203 14392 14344 14115 14027 13697 13354 13110 13204 13174 12885 12723 12930 13063 13078 13242 13753 13784 14039 14415 14822 15116 15625 15807 16518 16720 17257 17336 17662 18004 18437 18396 18540 18535 18099 18060 17865 17630 17096 17033 16395 15792 15060 14714 13938 13921 13162 12697 12331 12006 11457 11450 10964 10771 10416 10034 10038 9950 9700 9687 9501 9212 9183 8972 9092 8709 8897 8665 8805 8680 8521 8476 8492 8316 8314 8415 8164 8279 8139 7914 8113 8201 7999 8181 8182 8254 8163 8066 8047 8106 8004 8138 8079 8288 8037 8292 8242 8085 8206 8286 8282 8313 8148 8293 8158 8356 8413 8427 8399 8537 8613 8895 8654 8886 8934 8939 9087 9218 9348 9355 9330 9537 9844 9939 9948 10392 10464 10724 10860 11002 11215 11337 12176 12065 12339 12665 13057 13456 13575 13818 14250 14379 14543 14674 14722 14891 14988 14851 14902 14710 14306 14424 13985 14229 13812 13413 12805 12734 12207 12046 11611 11472 11190 11007 10587 10351 10518 10117 9786 9633 9444 9581 9248 9068 8891 8788 8609 8546 8512 8367 8330 8338 8325 8170 8123 8033 7858 8044 8010 7710 7792 7701 7784 7589 7550 7649 7621 7459 7432 7648 7481 7263 7500 7478 7375 7371 7311 7384 7552 7405 7498 7455 7465 7485 7637 7616 7642 7772 7845 7695 7591 7570 7704 7555 7634 7517 7633 7544 7365 7505 7460 7252 7447 7298 7185 7155 7103 7123 7059 7147 7151 7101 7044 7143 7035 7002 7018 6929 6953 7066 6974 6946 7005 6884 7077 6871 6987 6879 6820 6955 6926 6909 6966 6903 6965 6968 6760 6952 6996 6973 7040 6995 6995 6930 7068 7050 6726 7021 6924 7013 7116 6957 6923 7059 6932 6963 7003 7109 7068 7098 6908 6938 7058 7209 6999 7164 7006 7103 7192 7174 7254 7291 7116 7207 7201 7171 7282 7457 7282 7244 7260 7327 7267 7276 7231 7312 7240 7282 7067 7305 7308 7127 7337 7363 7080 7141 6986 7094 6879 6907 6997 6779 7045 6945 6864 7023 6932 7020 6975 6902 6864 6862 7005 6802 6874 6911 6868 6835 6786 6969 6811 6860 6901 6851 6755 6848 6806 6868 6731 6823 6877 6945 6840 6692 6776 6833 6934 6820 6788 6919 6877 7010 6823 6890 6814 6988 6902 6819 6906 6834 6880 6837 6948 6977 6968 6972 6940 6849 7056 6935 6976 6758 6959 6874 6785 6838 6789 7042 7007 6906 7023 6931 6898 6943 7012 6920 7011 6951 7055 7152 7092 7037 7018 6929 7064 6897 7083 7161 7188 7046 7165 6987 7064 7213 7183 7258 7195 7147 7537 7413 7277 7467 7312 7141 7324 7456 7505 7501 7480 7367 7519 7660 7668 7746 7740 7851 7897 7953 7890 8222 8136 8264 8424 8538 8799 8798 8895 8969 9215 9459 9496 9848 9751 9944 10184 10507 10662 10838 10821 10998 11138 11456 11592 11929 12275 12805 12988 13705 14359 15332 16107 17256 18517 19818 20988 22097 23690 24988 25696 25971 26720 26980 26874 26528 25989 26018 25683 24905 24078 23343 22230 21727 20363 19481 18087 17415 16445 15800 14974 14215 13379 12793 12308 11721 11237 10590 10331 10082 9686 9479 8981 8826 8608 8532 8379 8418 8389 7813 7994 7818 7960 7806 7749 7570 7647 7446 7320 7453 7480 7415 7378 7253 7275 7316 7162 7204 7196 7169 7199 7131 7145 7018 6932 7180 6949 7034 6906 7041 7053 7076 7205 7192 6828 7000 7006 6997 6977 7049 7063 6924 6952 7011 6797 6825 6938 6811 6854 6842 6777 6989 6762 6926 6869 7080 6878 6930 6859 6861 6787 6811 6950 6891 6866 7133 6959 7024 6817 6837 7035 6839 7015 6844 6874 6915 6761 6939 6770 7076 7013 6842 6961 6977 6916 6891 6881 6929 6839 7090 7022 7116 6978 6909 6895 6950 7037 6894 7016 7092 7048 7033 7351 7199 7435 7321 7488 7512 7514 7778 7678 7699 7736 7804 7700 7730 7789 7724 7744 7653 7697 7593 7483 7810 7573 7826 7588 7586 7598 7554 7556 7762 7637 7632 7510 7649 7686 7740 7685 7599 7653 7708 7705 7850 7649 7654 7701 7552 7601 7469 7617 7543 7515 7401 7358 7235 7582 7346 7492 7165 7266 7154 7181 7197 7217 7367 7202 7112 7199 7105 7243 6931 7095 7144 7183 7110 7149 7139 6999 7219 7111 7010 6977 7165 7097 7050 7146 7222 7135 7096 7168 7169 7211 7074 7218 7140 7221 7431 7045 7423 7304 7352 7220 7453 7370 7492 7440 7457 7637 7584 7685 7653 7816 7844 7868 8071 8169 8113 8203 8387 8300 8248 8700 8672 8850 8893 9066 9122 9342 9262 9510 9510 9440 9883 9826 9774 9996 10010 9900 10122 9937 10021 9840 10156 10264 10276 10254 10412 10854 10723 10913 10906 11249 11453 11735 11805 12153 12562 12584 12815 12981 13250 13295 13261 13554 13427 13493 13282 13116 12756 12646 12369 12327 11880 11794 11299 11310 11077 10964 10781 10385 10222 9996 10032 9800 9692 9513 9427 9251 9129 8901 8909 8676 8603 8576 8405 8276 8128 8018 7895 7743 7690 7622 7640 7440 7369 7427 7272 7236 7192 7150 7133 6921 7098 6991 6998 7007 7007 7073 6951 6873 6833 6816 6965 6962 6870 6830 6817 6884 6807 6782 6809 6823 6825 6856 6614 6705 6806 6687 6695 6616 6696 6670 6752 6694 6616 6584 6730 6635 6697 6602 6740 6596 6897 6723 6648 6580 6630 6623 6698 6693 6696 6621 6584 6545 6501 6786 6629 6690 6599 6663 6706 6772 6769 6692 6675 6551 6636 6542 6566 6551 6594 6675 6530 6556 6563 6594 6644 6713 6623 6616 6678 6510 6605 6435 6514 6710 6554 6633 6577 6482 6534 6420 6497 6635 6660 6455 6552 6522 6527 6682 6621 6738 6622 6544 6753 6671 6514 6675 6696 6556 6649 6656 6509 6626 6490 6716 6497 6577 6651 6599 6519 6577 6533 6623 6688 6552 6484 6536 6670 6638 6577 6622 6625 6499 6470 6596 6553 6493 6827 6733 6522 6678 6716 6628 6381 6541 6424 6538 6491 6553 6627 6747 6551 6619 6607 6553 6509 6585 6480 6523 6575 6483 6526 6622 6654 6516 6580 6523 6611 6733 6617 6462 6512 6379 6616 6752 6605 6490 6416 6574 6547 6420 6566 6635 6598 6608 6577 6636 6666 6643 6573 6541 6660 6711 6510 6528 6502 6667 6462 6621 6485 6582 6585 6623 6549 6657 6477 6499 6513 6531 6592 6491 6655 6705 6612 6479 6445 6605 6619 6549 6633 6404 6668 6447 6699 6581 6497 6460 6631 6660 6567 6611 6603 6638 6468 6663 6617 6549 6435 6498 6528 6537 6663 6771 6517 6691 6561 6768 6588 6631 6574 6498 6581 6606 6531 6518 6618 6526 6560 6446 6603 6547 6531 6622 6688 6639 6567 6486 6603 6597 6762 6586 6620 6597 6586 6559 6570 6485 6434 6471 6490 6548 6561 6746 6589 6725 6647 6608 6511 6679 6586 6687 6690 6621 6494 6615 6632 6472 6570 6566 6592 6638 6617 6523 6674 6801 6592 6643 6526 6629 6591 6718 6654 6691 6686 6760 6734 6659 6704 6810 6698 6714 6713 6792 6711 6778 6775 6929 6968 6849 6856 7043 6958 6909 7057 7087 7293 7198 7121 7318 7432 7629 7823 8140 8192 8541 8888 8891 9169 9330 9490 9539 9495 9507 9733 9556 9424 9498 9324 9466 9021 9091 8858 8801 8498 8345 8251 8075 7949 7745 7729 7486 7335 7406 7299 7219 7074 7174 6975 7072 6885 6985 6877 7108 6794 6650 6737 6726 6810 6705 6742 6641 6789 6586 6599 6782 6635 6752 6533 6563 6702 6680 6608 6620 6638 6617 6495 6527 6628 6475 6684 6555 6611 6676 6520 6567 6519 6684 6443 6684 6705 6564 6546 6568 6576 6494 6553 6600 6655 6540 6683 6501 6526 6520 6680 6551 6667 6564 6511 6499 6624 6511 6539 6516 6431 6661 6550 6646 6571 6533 6691 6730 6671 6480 6409 6557 6534 6634 6739 6724 6658 6667 6643 6570 6571 6545 6639 6618 6681 6446 6614 6345 6711 6492 6699 6715 6674 6613 6686 6732 6665 6798 6794 6657 6567 6600 6710 6705 6678 6753 6675 6706 6705 6915 6883 6846 6870 6761 6696 6830 6823 6760 6782 6794 6763 6784 6914 6738 6862 6966 6898 6705 6869 6796 6846 6811 6733 6572 6750 6628 6839 6704 6686 6756 6745 6634 6675 6753 6786 6575 6620 6498 6641 6535 6649 6626 6723 6456 6803 6394 6447 6687 6671 6602 6469 6475 6723 6627 6662 6577 6584 6642 6547 6628 6509 6685 6634 6661 6549 6646 6659 6686 6601 6736 6665 6717 6615 6660 6751 6563 6659 6623 6760 6670 6714 6742 6844 6584 6646 6927 6672 6743 6753 6843 6880 6870 6787 6769 6765 7011 6853 6822 6985 6907 6988 6964 7038 7050 6974 7063 7234 7193 7025 7038 7065 7256 7167 7224 7139 7189 7067 7060 7009 7084 7215 6937 7085 7037 6867 6879 6997 6912 6898 6844 6765 7049 6777 6833 6814 6631 6791 6895 6674 6687 6677 6908 6554 6786 6788 6838 6543 6727 6668 6768 6709 6821 6600 6743 6795 6743 6650 6677 6678 6622 6612 6564 6706 6551 6617 6704 6617 6642 6589 6523 6680 6608 6645 6505 6552 6487 6463 6580 6526 6502 6533 6557 6471 6692 6607 6537 6571 6459 6546 6522 6555 6523 6585 6550 6537 6423 6706 6574 6471 6492 6495 6525 6463 6402 6633 6451 6671 6459 6474 6692 6427 6404 6605 6563 6532 6504 6594 6513 6539 6431 6431 6503 6732 6540 6479 6637 6693 6506 6466 6592 6625 6782 6474 6765 6547 6688 6648 6569 6517 6433 6453 6578 6559 6423 6655 6501 6637 6374 6384 6640 6626 6515 6655 6545 6589 6518 6580 6486 6541 6423 6609 6500 6412 6592 6613 6575 6411 6557 6473 6530 6411 6465 6578 6319 6545 6421 6421 6477 6562 6543 6492 6736 6769 6269 6634 6553 6431 6387 6505 6517 6547 6466 6545 6481 6521 6515 6549 6491 6571 6573 6572 6536 6521 6503 6555 6552 6688 6416 6555 6505 6632 6583 6571 6566 6394 6658 6587 6484 6635 6651 6622 6560 6652 6497 6733 6590 6634 6720 6694 6724 6708 6600 6606 6712 6690 6824 6755 6739 6618 6777 6726 6850 6847 6778 6881 6832 6838 6897 6979 6875 6940 6988 7094 6928 7132 7191 7294 7313 7251 7304 7589 7402 7659 7724 7775 7823 8030 8263 8185 8289 8369 8312 8511 8636 8525 8473 8777 8647 8853 8810 8896 8801 8847 8835 8839 8855 8786 8671 8557 8634 8737 8257 8291 8221 8283 8098 8051 8010 8030 7839 7696 7538 7534 7374 7417 7313 7156 7256 7256 6956 7116 7143 7059 7012 6927 6973 7016 6904 6807 6866 6859 6898 6864 6776 6847 6871 6673 6897 6802 6631 6763 6822 6784 6683 6893 6828 6715 6725 6667 6834 6744 6592 6713 6947 6911 6825 6905 6899 6786 6929 6905 6829 6883 6912 6921 7000 6923 6838 6908 7001 6858 6740 6884 6913 6541 6787 6839 6944 6653 6816 6719 6713 6704 6746 6654 6786 6740 6581 6623 6583 6411 6703 6636 6679 6715 6538 6485 6454 6514 6435 6593 6580 6578 6476 6462 6599 6558 6663 6493 6432 6478 6583 6471 6541 6513 6539 6470 6508 6389 6489 6446 6622 6517 6533 6587 6523 6624 6411 6552 6586 6495 6399 6386 6573 6498 6424 6473 6575 6629 6687 6509 6647 6521 6596 6627 6587 6589 6590 6584 6493 6596 6547 6517 6579 6666 6537 6648 6532 6587 6596 6600 6469 6626 6622 6490 6634 6647 6662 6759 6708 6820 6684 6863 6860 6828 6857 6835 6947 6739 6777 6829 6890 6977 7027 6949 7065 6828 6941 6889 6869 7013 6968 6990 6887 6838 6924 6881 6954 6762 6974 6956 7002 6929 6972 6859 6765 6551 6699 6787 6886 6752 6778 6619 6711 6814 6664 6624 6637 6743 6672 6630 6718 6633 6562 6634 6550 6611 6550 6711 6473 6586 6753 6556 6598 6623 6620 6608 6480 6449 6499 6629 6565 6624 6509 6527 6602 6605 6444 6458 6540 6455 6452 6595 6517 6441 6471 6484 6492 6476 6590 6547 6446 6449 6502 6503 6361 6356 6422 6509 6342 6407 6427 6518 6568 6425 6439 6394 6543 6556 6524 6532 6392 6342 6633 6351 6515 6472 6484 6358 6534 6378 6428 6488 6446 6538 6398 6556 6530 6527 6507 6512 6516 6470 6409 6363 6506 6388 6523 6530 6491 6503 6351 6463 6511 6548 6425 6524 6426 6601 6446 6349 6521 6428 6572 6595 6478 6372 6467 6236 6492 6548 6492 6416 6587 6282 6477 6458 6470 6623 6340 6499 6501 6532 6454 6648 6496 6441 6651 6556 6359 6581 6458 6552 6445 6427 6476 6400 6553 6613 6418 6545 6572 6501 6437 6591 6565 6429 6578 6419 6551 6516 6565 6515 6451 6500 6481 6498 6365 6571 6527 6625 6593 6542 6597 6577 6576 6509 6564 6560 6751 6649 6694 6610 6591 6554 6689 6741 6604 6913 6672 6583 6662 6796 6655 6823 6820 6878 6966 7009 6941 7148 7134 7324 7227 7443 7481 7500 7740 7865 7650 7877 7718 7907 7865 7960 7852 8004 7848 7939 7713 7982 7873 7783 7649 7590 7744 7476 7649 7591 7382 7447 7389 7254 7246 7249 7217 6912 6789 7091 6992 6895 6979 6761 6923 6807 6763 6746 6805 6740 6805 6621 6523 6910 6661 6713 6666 6539 6619 6540 6594 6708 6548 6545 6586 6549 6590 6607 6435 6750 6594 6670 6491 6465 6399 6480 6548 6562 6493 6528 6485 6578 6439 6552 6528 6554 6552 6595 6702 6425 6630 6470 6476 6617 6508 6577 6654 6531 6485 6431 6620 6570 6606 6514 6661 6587 6518 6660 6404 6652 6613 6583 6735 6784 6550 6411 6610 6566 6498 6607 6541 6595 6586 6696 6694 6468 6524 6470 6476 6515 6627 6544 6545 6715 6725 6497 6518 6592 6418 6379 6563 6575 6544 6448 6516 6528 6609 6508 6458 6485 6470 6552 6560 6436 6548 6419 6521 6531 6431 6542 6428 6404 6423 6555 6539 6578 6531 6427 6622 6508 6459 6515 6423 6499 6409 6548 6475 6521 6453 6450 6493 6330 6431 6516 6465 6475 6349 6503 6488 6396 6406 6394 6366 6533 6456 6448 6379 6467 6336 6523 6489 6520 6481 6395 6465 6476 6543 6471 6616 6452 6512 6560 6430 6438 6463 6373 6435 6379 6323 6329 6443 6538 6414 6408 6503 6392 6430 6460 6490 6583 6464 6469 6495 6517 6390 6475 6474 6564 6460 6493 6442 6509 6453 6622 6470 6527 6596 6577 6658 6445 6368 6557 6441 6464 6594 6550 6448 6448 6465 6575 6389 6492 6440 6542 6517 6447 6367 6440 6430 6550 6490 6573 6381 6656 6494 6589 6406 6512 6574 6689 6545 6432 6559 6452 6535 6609 6540 6621 6805 6704 6581 6640 6629 6677 6622 6661 6551 6698 6779 6582 6573 6652 6560 6756 6559 6769 6638 6779 6774 6794 6757 6695 6809 6880 6939 6867 6804 6913 6955 7114 7234 7187 7316 7497 7563 7641 7894 8124 8246 8363 8543 8794 8869 8968 9168 9303 9462 9373 9575 9545 9272 9479 9638 9283 9291 9510 9223 9192 9057 9124 8896 8762 8780 8459 8475 8390 8354 8089 8127 8019 7904 7601 7721 7520 7652 7443 7374 7336 7334 7104 7300 7238 7076 7111 7180 7252 7152 7163 7241 7146 7044 7248 7225 6944 7299 7148 7220 7497 7155 7484 7262 7267 7188 7281 7242 7318 7393 7287 7299 7502 7368 7348 7314 7373 7286 7391 7406 7173 7428 7307 7277 7372 7278 7135 7270 7121 7110 7105 7103 7094 7121 7220 7143 7036 7156 6919 7052 7022 7098 6977 6946 6856 7004 6862 6945 6984 6960 7005 6903 6950 7109 6982 7106 7137 7068 7315 7139 7191 6980 7179 7224 7203 7141 7117 7278 7281 7268 7311 7335 7200 7263 7278 7273 7301 7356 7161 7192 7299 7202 6974 7113 7172 7130 7104 7151 7119 7063 7059 6857 6864 6905 6856 6823 6974 6940 6779 6781 6869 6724 6953 6788 6861 6719 6962 6779 6701 6711 6942 6816 6690 6783 6681 6869 6837 6651 6854 6861 6627 6798 6936 6971 6788 6839 6926 6937 6952 7013 7159 7179 7243 7102 7330 7272 7247 7239 7421 7628 7390 7373 7465 7542 7811 7557 7726 7600 7493 7634 7622 7629 7621 7658 7706 7734 7573 7639 7518 7517 7504 7555 7465 7414 7359 7281 7196 7219 7251 7087 7229 7148 7047 7166 6843 6898 7030 6885 6810 6879 6912 7011 6957 6849 6979 6813 6854 6789 6706 6811 6818 6750 6874 6763 6838 6707 6668 6677 6832 6721 6783 6700 6812 6751 6987 6769 6845 6870 6918 6780 6864 6873 6937 6848 6790 6812 6976 6805 6844 7003 6970 6891 6963 6896 6979 6917 6949 6942 7102 7003 7002 6864 6888 6924 6967 6916 7005 6959 6869 6829 6944 6912 6810 6768 6830 6868 7010 6937 6992 6925 6834 6853 6838 6733 6951 6964 6878 6949 7004 6860 6972 6971 6952 7046 6902 7037 6979 6954 7044 6771 6976 7047 7037 7036 7129 7112 7165 7003 7027 7068 7079 7120 7018 7105 7129 7150 7219 7021 7205 7127 7001 7141 7071 7008 7268 7015 7142 6950 6892 7035 7135 7057 7152 6857 7322 7024 7210 7046 7055 7315 7268 7272 7233 7507 7361 7473 7411 7365 7435 7292 7245 7329 7256 7180 7340 7453 7099 7266 7275 7337 7245 7269 7300 7430 7131 7259 7194 7163 7075 7102 6975 6960 7079 7022 7089 6970 7002 7095 7014 7040 6999 7083 7142 7026 7111 7095 7007 7208 7116 7119 7176 7211 7278 7233 7452 7430 7512 7602 7584 7585 7604 7678 7700 7889 7705 7737 7675 7652 7539 7536 7464 7491 7610 7652 7520 7505 7491 7277 7455 7273 7307 7266 7060 7330 7161 7332 7181 7101 6989 6969 7105 6767 6945 6976 6845 6838 6828 6971 6919 6942 6666 6723 6720 6702 6687 6725 6678 6703 6777 6831 6791 6714 6716 6646 6791 6819 6854 6737 6855 6884 7031 6951 6705 6773 6856 6792 7036 6965 6835 6928 6957 7149 7041 7105 7177 7355 7228 7340 7669 7662 7722 8285 8550 8553 8728 9224 9348 9753 9805 9822 10122 10231 10247 10547 10524 10454 10666 10500 10657 10890 10881 10730 10573 10666 10612 10373 10217 10169 9909 10201 9733 9692 9470 9408 9591 9205 9141 8857 8955 8576 8497 8457 8317 8163 8028 8032 7896 7794 7666 7536 7439 7430 7389 7243 7215 7191 7062 7123 7105 6997 6967 7040 6998 6800 7011 6965 6730 6781 6844 6857 6710 6635 6685 6971 6772 6738 6787 6817 6635 6741 6827 6351 6640 6810 6729 6767 6771 6543 6635 6524 6731 6678 6641 6624 6649 6744 6655 6692 6675 6627 6642 6761 6652 6536 6612 6627 6559 6563 6629 6549 6823 6702 6644 6664 6561 6754 6814 6781 6857 6556 6678 6579 6806 6640 6667 6682 6755 6689 6785 6818 6881 6749 6752 6719 6887 6706 6846 6864 6958 6895 6859 7053 7177 6997 7009 7080 7281 7254 7095 7220 7278 7238 7399 7467 7419 7457 7290 7484 7541 7303 7383 7562 7536 7457 7470 7508 7514 7361 7442 7487 7463 7373 7528 7427 7588 7462 7534 7429 7560 7446 7484 7433 7555 7585 7618 7636 7634 7677 7687 7670 7783 7621 7839 7859 7713 7773 7824 7803 7950 7999 8101 8291 8419 8504 8141 8378 8404 8218 8458 8441 8450 8274 8328 8354 8311 8347 8388 8347 8133 8207 8170 8163 8110 8133 8012 7943 7786 7776 7578 7738 7765 7595 7611 7514 7547 7286 7451 7442 7326 7293 7298 7299 7172 7082 6998 7101 7044 6988 6953 7047 6923 7005 6904 6839 6853 6914 6719 6835 6859 6838 6869 6916 6821 6848 6799 6912 6963 6734 6679 6748 6710 6766 6794 6532 6702 6827 6766 6820 6794 6847 6760 6827 6802 6717 6699 6679 6763 6774 6947 6944 6790 6857 6920 6902 6895 7037 7107 6930 7084 6958 6989 6973 7071 7051 7040 7109 7203 7203 7226 7188 7140 7105 7324 7215 7279 7391 7308 7200 7235 7212 7163 7203 7154 7241 7150 7245 7265 7084 7143 7171 7372 7206 6956 7035 7133 7117 7163 7093 7078 7172 7219 7094 6932 7140 7156 7205 7230 7149 7313 7230 7169 7331 7355 7475 7456 7522 7542 7404 7522 7486 7459 7300 7507 7490 7331 7404 7302 7375 7515 7196 7282 7302 7209 7308 7195 7224 7170 7043 7030 7146 6986 7059 6876 7019 6750 6873 6819 6880 6835 6821 6663 6789 6696 6761 6773 6684 6785 6831 6637 6750 6625 6539 6501 6784 6690 6554 6613 6612 6614 6423 6588 6617 6432 6581 6615 6545 6557 6618 6576 6675 6518 6478 6595 6612 6595 6476 6485 6637 6604 6638 6472 6573 6501 6585 6431 6441 6546 6565 6467 6481 6522 6658 6513 6558 6797 6592 6534 6581 6529 6329 6512 6581 6596 6535 6503 6575 6637 6517 6687 6573 6555 6569 6726 6737 6518 6659 6542 6478 6499 6623 6570 6681 6591 6722 6809 6778 6782 6642 6645 6660 6612 6767 6664 6729 6805 6785 6762 6660 6767 6806 6714 6757 6868 6747 6888 6970 6892 6964 6969 6869 6992 7133 7022 7068 7117 7181 7115 7215 6986 7078 7229 7116 7169 7327 7205 7469 7210 7372 7617 7446 7441 7429 7430 7616 7358 7446 7590 7486 7363 7251 7419 7284 7484 7240 7180 7146 7262 7262 7009 7147 7222 7046 7265 7069 6969 6994 7106 7094 6934 7074 6655 6768 6822 6909 6862 6742 6766 6565 6585 6643 6581 6557 6734 6716 6509 6586 6657 6586 6538 6475 6515 6592 6559 6739 6560 6671 6455 6525 6596 6436 6666 6631 6608 6615 6615 6621 6567 6473 6510 6702 6508 6536 6702 6573 6586 6590 6547 6503 6517 6585 6713 6754 6684 6495 6569 6567 6683 6649 6584 6663 6634 6529 6679 6486 6747 6705 6605 6720 6615 6607 6722 6621 6661 6774 6707 6562 6695 6583 6687 6619 6528 6810 6621 6680 6756 6670 6866 6802 6954 6702 6830 6883 6843 6757 6867 6916 6729 6903 6856 6875 6868 7053 6928 6830 6790 6840 6857 6972 6848 6872 7043 6854 6769 6841 6802 6900 6714 6914 6961 6855 6702 6893 6880 6605 6813 6918 6846 6638 6842 6737 6740 6737 6577 6638 6712 6674 6727 6647 6587 6628 6873 6606 6756 6684 6557 6646 6753 6687 6736 6599 6660 6538 6615 6532 6599 6519 6534 6709 6582 6646 6653 6544 6690 6757 6568 6681 6659 6752 6679 6702 6487 6675 6612 6613 6760 6783 6686 6802 6671 6800 6738 6839 6738 6669 6664 6743 6802 6648 6713 6740 6761 6793 6750 6786 6809 6586 6566 6539 6734 6604 6706 6748 6756 6663 6730 6678 6619 6688 6624 6761 6692 6840 6651 6788 6681 6683 6750 6714 6839 6608 6747 6693 6803 6680 6656 6738 6890 6810 6727 6862 6942 6890 6771 6677 6895 6918 6822 6756 6868 6835 6951 6871 6815 6787 6851 6795 6857 6866 6804 6737 6822 6800 6752 6831 6800 6794 6609 6606 6729 6731 6740 6687 6565 6735 6660 6585 6729 6483 6644 6588 6657 6615 6653 6598 6465 6619 6658 6611 6632 6494 6471 6550 6481 6512 6562 6525 6681 6446 6493 6447 6432 6413 6511 6412 6476 6466 6506 6453 6430 6480 6619 6495 6440 6463 6518 6510 6519 6414 6570 6439 6676 6489 6543 6503 6437 6509 6480 6426 6535 6580 6484 6411 6602 6647 6683 6410 6572 6496 6396 6525 6578 6553 6681 6613 6654 6575 6573 6624 6625 6447 6631 6559 6516 6609 6522 6630 6711 6716 6616 6879 6831 6752 6694 6577 6674 6842 6791 6877 6910 6749 6717 6966 7083 6882 6915 6970 6913 6945 6882 7107 6994 7091 6890 7184 7257 6955 7014 7000 7005 7132 6865 7008 6970 7005 6917 6911 6979 6947 6919 6862 6834 6912 6951 6881 6744 6871 6693 6779 6761 6790 6591 6766 6779 6684 6726 6518 6690 6721 6613 6745 6657 6674 6485 6756 6647 6684 6505 6465 6556 6596 6726 6607 6692 6590 6664 6657 6518 6539 6618 6404 6408 6548 6472 6472 6671 6405 6405 6575 6437 6406 6468 6601 6430 6570 6418 6486 6533 6478 6560 6504 6438 6527 6475 6519 6511 6393 6464 6519 6405 6457 6566 6548 6515 6507 6360 6486 6503 6493 6473 6500 6506 6441 6647 6466 6536 6642 6499 6531 6515 6477 6637 6641 6517 6741 6486 6535 6622 6797 6490 6635 6681 6641 6617 6798 6599 6646 6727 6691 6774 6784 6795 6742 6826 6834 6897 6924 6909 6981 6937 7103 7100 6952 7172 7134 7153 7189 7251 6958 7200 7041 7225 7219 6994 7118 7123 7005 7227 7118 7131 7047 6976 6940 7027 7092 6948 6953 6905 6818 6774 7016 6806 6767 6809 6819 6931 6862 6816 6839 6650 6890 6757 6641 6781 6580 6745 6706 6731 6626 6626 6579 6595 6759 6665 6669 6760 6532 6650 6495 6581 6693 6551 6456 6558 6601 6613 6594 6635 6648 6503 6626 6595 6637 6531 6413 6552 6579 6555 6780 6549 6796 6578 6718 6633 6792 6737 6702 6898 6905 6848 7038 6938 6952 7010 6930 6888 6938 7172 7023 7285 7167 7274 7011 7128 7352 7064 7151 7167 7104 7082 6957 7017 7123 7194 7018 6902 7152 7045 7086 7098 6951 7122 7221 7073 7164 7097 6814 7037 6944 7038 6874 6851 6802 6954 6765 6891 6766 6777 6844 6740 6638 6805 6761 6968 6647 6494 6717 6636 6808 6596 6755 6556 6529 6558 6770 6585 6621 6506 6626 6516 6459 6521 6619 6412 6381 6682 6489 6650 6627 6339 6339 6523 6335 6457 6505 6337 6568 6404 6436 6533 6504 6438 6457 6463 6364 6407 6598 6610 6442 6347 6491 6593 6397 6360 6542 6454 6485 6359 6496 6449 6393 6400 6373 6452 6420 6426 6565 6388 6365 6371 6390 6338 6492 6449 6424 6502 6443 6267 6420 6420 6429 6465 6365 6484 6545 6460 6402 6396 6442 6375 6440 6402 6566 6338 6363 6543 6322 6245 6431 6536 6373 6404 6492 6405 6618 6447 6468 6308 6473 6495 6452 6443 6527 6439 6391 6268 6420 6432 6462 6350 6346 6493 6511 6517 6420 6361 6277 6498 6448 6467 6471 6464 6397 6433 6483 6219 6491 6329 6420 6478 6535 6378 6310 6410 6446 6267 6297 6501 6397 6369 6480 6303 6290 6299 6444 6485 6385 6574 6532 6330 6494 6323 6502 6301 6446 6257 6531 6415 6465 6420 6372 6324 6453 6473 6398 6352 6437 6353 6312 6409 6468 6270 6466 6468 6432 6508 6373 6642 6489 6331 6369 6404 6400 6309 6391 6350 6452 6474 6362 6393 6471 6380 6428 6371 6535 6367 6452 6421 6368 6339 6405 6652 6376 6528 6455 6456 6348 6393 6504 6424 6391 6532 6512 6384 6421 6569 6389 6418 6513 6446 6434 6391 6466 6496 6499 6434 6420 6372 6566 6405 6418 6491 6464 6292 6313 6387 6439 6367 6352 6419 6374 6473 6526 6537 6503 6398 6391 6524 6561 6415 6336 6354 6382 6489 6474 6396 6565 6515 6373 6499 6402 6389 6371 6474 6342 6457 6352 6494 6401 6504 6392 6452 6382 6451 6507 6575 6462 6503 6491 6320 6478 6563 6429 6328 6435 6519 6392 6465 6455 6410 6561 6399 6457 6605 6450 6474 6560 6618 6520 6483 6633 6320 6566 6626 6574 6636 6575 6437 6534 6538 6589 6589 6628 6614 6592 6679 6774 6763 6685 6692 6753 6687 6610 6636 6619 6718 6630 6589 6520 6594 6628 6546 6673 6574 6656 6653 6616 6450 6560 6563 6719 6529 6605 6729 6569 6518 6446 6522 6540 6464 6534 6574 6621 6562 6393 6460 6505 6404 6417 6570 6461 6492 6412 6491 6453 6486 6469 6337 6571 6471 6406 6495 6454 6365 6424 6511 6410 6487 6460 6509 6425 6425 6273 6443 6345 6402 6427 6491 6456 6505 6483 6473 6286 6394 6465 6498 6376 6450 6474 6330 6512 6486 6372 6459 6548 6420 6497 6514 6457 6560 6364 6457 6440 6279 6410 6433 6391 6334 6476 6518 6585 6520 6518 6594 6489 6436 6428 6546 6506 6443 6515 6546 6459 6559 6563 6417 6521 6533 6449 6453 6530 6477 6609 6408 6522 6527 6503 6539 6369 6346 6407 6418 6570 6597 6523 6479 6537 6392 6570 6548 6507 6544 6388 6453 6420 6573 6392 6449 6380 6588 6410 6547 6397 6385 6279 6451 6496 6358 6379 6360 6500 6432 6468 6183 6338 6525 6399 6539 6303 6519 6519 6527 6406 6240 6312 6375 6360 6371 6420 6295 6429 6422 6368 6443 6388 6334 6446 6394 6403 6414 6362 6357 6226 6383 6377 6486 6420 6251 6434 6371 6332 6379 6340 6434 6391 6410 6419 6396 6242 6334 6471 6317 6479 6511 6515 6255 6379 6378 6444 6354 6173 6325 6409 6528 6444 6469 6540 6269 6412 6407 6495 6455 6435 6352 6428 6362 6483 6359 6435 6422 6514 6483 6457 6427 6347 6510 6404 6541 6364 6515 6357 6392 6481 6545 6321 6344 6508 6314 6493 6566 6338 6457 6528 6541 6395 6501 6481 6451 6322 6469 6378 6405 6473 6441 6514 6557 6524 6503 6419 6360 6418 6580 6394 6523 6420 6535 6444 6487 6483 6555 6583 6620 6478 6556 6589 6510 6509 6458 6610 6575 6626 6638 6717 6576 6643 6644 6590 6594 6727 6761 6675 6647 6582 6504 6660 6710 6636 6713 6752 6536 6704 6758 6823 6531 6637 6713 6635 6685 6676 6750 6521 6627 6790 6660 6647 6709 6684 6708 6532 6795 6530 6502 6659 6525 6699 6604 6496 6519 6682 6531 6568 6689 6653 6646 6572 6656 6633 6683 6566 6682 6702 6595 6730 6650 6571 6586 6643 6534 6545 6796 6603 6694 6592 6653 6666 6626 6587 6621 6601 6773 6636 6511 6613 6676 6469 6556 6459 6751 6432 6508 6555 6644 6542 6663 6609 6465 6502 6609 6661 6633 6643 6603 6482 6568 6512 6468 6549 6618 6564 6513 6609 6745 6659 6638 6620 6611 6774 6710 6555 6656 6633 6632 6566 6590 6573 6464 6463 6572 6692 6560 6566 6625 6692 6529 6445 6569 6544 6676 6495 6785 6619 6597 6577 6581 6586 6607 6632 6448 6515 6706 6764 6634 6684 6657 6673 6693 6539 6592 6597 6530 6684 6567 6493 6478 6530 6682 6568 6657 6603 6743 6502 6586 6635 6572 6656 6679 6495 6601 6647 6553 6432 6539 6699 6548 6534 6494 6577 6643 6577 6605 6738 6557 6763 6583 6609 6453 6747 6638 6526 6590 6510 6630 6720 6665 6568 6711 6537 6539 6522 6595 6505 6636 6543 6631 6473 6591 6579 6572 6648 6571 6469 6656 6444 6471 6506 6603 6624 6448 6494 6562 6401 6548 6566 6466 6589 6496 6500 6625 6634 6434 6512 6498 6467 6498 6427 6468 6494 6524 6506 6353 6478 6535 6539 6428 6425 6492 6614 6530 6527 6499 6501 6627 6336 6544 6598 6559 6420 6357 6394 6519 6610 6622 6602 6511 6464 6578 6567 6489 6604 6521 6534 6549 6513 6594 6552 6639 6660 6586 6559 6621 6512 6593 6629 6592 6568 6596 6552 6737 6566 6579 6595 6613 6564 6507 6577 6613 6530 6751 6379 6513 6604 6632 6689 6712 6642 6500 6607 6641 6637 6449 6698 6551 6622 6621 6555 6606 6598 6672 6520 6647 6585 6585 6534 6569 6586 6458 6434 6628 6488 6512 6530 6528 6561 6561 6504 6477 6426 6530 6581 6654 6568 6541 6430 6424 6486 6617 6523 6629 6639 6397 6547 6497 6535 6397 6459 6432 6493 6363 6464 6448 6545 6576 6472 6546 6523 6538 6486 6583 6478 6515 6506 6443 6475 6516 6501 6608 6489 6525 6313 6469 6593 6627 6653 6532 6526 6606 6618 6477 6710 6679 6791 6701 6610 6721 6549 6725 6680 6635 6630 6689 6644 6694 6648 6496 6692 6814 6590 6515 6677 6682 6749 6694 6577 6752 6743 6642 6596 6778 6700 6799 6591 6665 6622 6619 6787 6554 6550 6573 6557 6697 6530 6700 6721 6586 6599 6680 6551 6544 6653 6728 6533 6458 6564 6450 6548 6646 6595 6495 6541 6443 6431 6424 6388 6549 6571 6295 6523 6392 6512 6525 6352 6416 6418 6533 6382 6511 6263 6558 6443 6465 6482 6530 6507 6509 6472 6400 6511 6432 6429 6390 6479 6262 6390 6530 6393 6402 6424 6329 6317 6292 6415 6439 6320 6428 6474 6372 6351 6458 6390 6337 6458 6322 6420 6384 6411 6397 6457 6465 6504 6467 6420 6461 6460 6364 6522 6304 6502 6441 6388 6471 6392 6407 6455 6422 6459 6465 6539 6502 6434 6502 6432 6410 6440 6327 6405 6492 6345 6537 6492 6487 6464 6538 6375 6349 6399 6272 6390 6406 6528 6487 6464 6384 6428 6467 6454 6478 6397 6491 6421 6441 6595 6431 6423 6462 6413 6451 6611 6633 6473 6388 6518 6617 6564 6335 6654 6421 6494 6611 6560 6541 6487 6572 6598 6484 6616 6562 6492 6564 6545 6531 6664 6559 6747 6447 6515 6613 6563 6539 6589 6620 6685 6640 6734 6536 6565 6615 6730 6760 6791 6629 6663 6676 6733 6757 6756 6741 6667 6713 6700 6687 6739 6727 6729 6682 6832 6821 6635 6772 6783 6894 6823 6760 6797 6729 6721 6819 6882 6712 6827 6677 6657 6822 6869 6857 6813 6856 6964 6891 7017 6963 6871 7117 7186 7210 7040 7304 7218 7279 7100 7288 7297 7360 7315 7372 7371 7213 7421 7523 7328 7438 7494 7367 7241 7449 7486 7346 7534 7369 7353 7441 7283 7324 7488 7440 7626 7280 7354 7377 7297 7333 7358 7147 7328 7193 7282 7132 7157 7268 7140 7051 6902 6943 6952 6890 7085 7068 6912 6830 6914 6971 6851 7019 6945 6986 6906 6880 6882 6750 6723 6641 6706 6703 6728 6668 6859 6548 6580 6675 6801 6706 6704 6755 6666 6648 6511 6553 6694 6650 6557 6511 6411 6562 6663 6518 6629 6506 6607 6430 6535 6540 6590 6676 6491 6582 6628 6648 6641 6548 6538 6498 6585 6488 6549 6532 6456 6519 6464 6516 6500 6699 6565 6685 6595 6443 6385 6507 6507 6546 6451 6524 6752 6461 6403 6549 6475 6526 6506 6544 6494 6518 6597 6671 6564 6464 6558 6611 6655 6472 6610 6405 6738 6637 6576 6559 6604 6481 6781 6555 6687 6683 6657 6555 6461 6455 6560 6671 6594 6693 6595 6589 6528 6591 6678 6716 6582 6606 6716 6680 6587 6465 6626 6610 6664 6814 6549 6704 6741 6568 6666 6673 6610 6713 6659 6387 6548 6428 6438 6631 6588 6615 6671 6664 6646 6622 6638 6712 6558 6643 6589 6716 6659 6741 6820 6562 6624 6388 6504 6644 6542 6547 6585 6526 6612 6397 6656 6409 6520 6446 6461 6568 6477 6581 6337 6562 6423 6478 6564 6592 6568 6452 6573 6477 6551 6613 6471 6499 6540 6611 6512 6509 6551 6473 6485 6389 6611 6468 6412 6468 6442 6553 6530 6429 6552 6558 6496 6496 6436 6553 6459 6398 6456 6345 6569 6479 6596 6385 6458 6466 6380 6381 6574 6580 6556 6468 6461 6323 6441 6509 6388 6617 6589 6386 6493 6357 6462 6450 6470 6484 6609 6449 6443 6409 6413 6480 6526 6467 6620 6551 6364 6392 6383 6476 6355 6442 6533 6383 6423 6487 6455 6445 6235 6573 6506 6480 6486 6462 6514 6502 6523 6464 6468 6506 6493 6435 6343 6435 6514 6394 6574 6473 6535 6497 6549 6551 6567 6485 6652 6376 6439 6414 6516 6614 6579 6500 6581 6525 6380 6419 6581 6284 6249 6466 6524 6557 6479 6461 6532 6418 6529 6480 6434 6489 6266 6501 6495 6518 6452 6405 6616 6518 6412 6526 6404 6658 6506 6374 6499 6507 6387 6359 6520 6510 6206 6381 6416 6559 6734 6433 6495 6439 6493 6435 6525 6481 6512 6446 6461 6619 6491 6577 6603 6701 6426 6572 6471 6389 6670 6651 6539 6514 6492 6583 6551 6462 6546 6510 6510 6626 6398 6638 6471 6567 6558 6544 6450 6548 6699 6489 6584 6671 6694 6640 6631 6730 6788 6589 6592 6632 6655 6719 6539 6921 6764 6893 6814 6647 6680 6564 6859 6859 6748 6805 6879 6837 6695 6733 6919 6884 6857 6818 6801 6750 6789 6810 6895 6854 6970 6833 6721 6842 6786 6714 6881 6824 6844 6754 6762 6872 6675 6703 6774 6711 6755 6885 6749 6638 6601 6780 6690 6738 6677 6737 6840 6678 6593 6672 6662 6608 6797 6642 6628 6634 6484 6658 6674 6595 6699 6500 6576 6510 6602 6568 6456 6653 6580 6658 6575 6588 6616 6486 6579 6657 6548 6489 6569 6541 6724 6531 6584 6560 6637 6560 6614 6576 6588 6551 6686 6643 6561 6597 6665 6549 6656 6521 6773 6705 6551 6669 6713 6566 6806 6554 6694 6493 6477 6590 6555 6598 6593 6355 6574 6625 6623 6767 6510 6681 6708 6697 6622 6665 6583 6521 6718 6678 6661 6558 6607 6571 6611 6632 6575 6751 6714 6602 6696 6726 6768 6745 6464 6621 6854 6682 6765 6690 6586 6556 6756 6494 6607 6857 6686 6664 6796 6565 6586 6674 6686 6660 6574 6538 6727 6644 6496 6649 6570 6678 6686 6655 6694 6697 6598 6423 6612 6601 6765 6706 6652 6705 6711 6769 6683 6620 6737 6612 6621 6601 6507 6680 6674 6560 6479 6650 6646 6677 6668 6728 6641 6670 6748 6536 6666 6561 6691 6571 6569 6595 6685 6556 6614 6570 6605 6554 6558 6693 6560 6561 6515 6464 6635 6537 6467 6536 6660 6585 6439 6631 6606 6652 6435 6484 6357 6490 6420 6651 6560 6590 6441 6492 6539 6518 6425 6537 6606 6461 6470 6614 6441 6382 6367 6384 6513 6492 6633 6492 6543 6348 6474 6471 6660 6595 6403 6437 6510 6473 6454 6532 6355 6607 6513 6505 6389 6603 6403 6667 6356 6518 6365 6495 6490 6416 6297 6328 6593 6506 6489 6516 6457 6360 6328 6334 6426 6352 6455 6574 6482 6363 6422 6392 6481 6439 6334 6503 6380 6580 6471 6517 6561 6573 6527 6529 6559 6622 6456 6431 6531 6486 6508 6493 6700 6488 6556 6397 6445 6572 6340 6660 6495 6528 6487 6471 6659 6457 6360 6506 6383 6513 6570 6399 6547 6575 6616 6569 6457 6525 6619 6612 6497 6549 6434 6646 6508 6556 6572 6610 6551 6557 6602 6517 6395 6594 6553 6627 6692 6643 6550 6516 6698 6741 6566 6556 6605 6596 6427 6500 6641 6488 6617 6613 6691 6569 6558 6462 6658 6588 6619 6408 6600 6588 6713 6678 6487 6660 6559 6633 6515 6664 6772 6515 6723 6472 6524 6545 6661 6618 6593 6610 6562 6588 6661 6576 6483 6507 6457 6558 6575 6685 6492 6617 6524 6594 6497 6611 6690 6707 6663 6604 6614 6659 6609 6590 6460 6653 6629 6571 6578 6560 6707 6411 6731 6610 6535 6587 6685 6645 6519 6473 6595 6466 6637 6626 6653 6627 6523 6564 6690 6466 6637 6639 6433 6644 6690 6543 6690 6590 6697 6530 6692 6613 6556 6577 6552 6724 6502 6442 6758 6629 6480 6699 6590 6745 6670 6607 6600 6557 6531 6596 6632 6532 6474 6558 6486 6655 6562 6626 6543 6666 6430 6608 6508 6496 6603 6582 6626 6537 6503 6524 6532 6564 6413 6612 6306 6383 6638 6553 6537 6532 6533 6592 6485 6534</counts>
			</dataPoints>
		</scan>
	</xrdMeasurement>
</xrdMeasurements>