File: dataset/precursor_mixture/Fe3O4_Nb2O5_Bi2O3-alpha.2-min.xrdml
<?xml version="1.0"?>
<xrdMeasurements xmlns="http://www.xrdml.com/XRDMeasurement/2.2" xmlns:xsi="http://www.w3.org/2001/XMLSchema-instance" xsi:schemaLocation="http://www.xrdml.com/XRDMeasurement/2.2 http://www.xrdml.com/XRDMeasurement/2.2/XRDMeasurement.xsd" status="Completed" recordIdentifier="{432D04EE-E0EB-4283-9A5C-8EA41DBC3B5C}">
	<comment>
		<entry/>
	</comment>
	<sample type="To be analyzed">
		<id>dara-27-1</id>
		<name></name>
		<preparedBy></preparedBy>
	</sample>
	<xrdMeasurement measurementType="Scan" status="Completed" sampleMode="Reflection">
		<usedWavelength intended="K-Alpha 1">
			<kAlpha1 unit="Angstrom">1.5405980</kAlpha1>
			<kAlpha2 unit="Angstrom">1.5444260</kAlpha2>
			<kBeta unit="Angstrom">1.3922500</kBeta>
			<ratioKAlpha2KAlpha1>0.5000</ratioKAlpha2KAlpha1>
		</usedWavelength>
		<incidentBeamPath>
			<radius unit="mm">145.00</radius>
			<xRayTube id="1010048" name="Empyrean Cu LFF HR (9430 033 7310x) DK437873">
				<tension unit="kV">40.0</tension>
				<current unit="mA">15.0</current>
				<anodeMaterial>Cu</anodeMaterial>
				<focus type="Line">
					<length unit="mm">12.0</length>
					<width unit="mm">0.4</width>
					<takeOffAngle unit="deg">6.0</takeOffAngle>
				</focus>
			</xRayTube>
			<filter id="20010004" name="Beta-filter Nickel">
				<material>Ni</material>
				<thickness unit="mm">0.020</thickness>
			</filter>
			<sollerSlit id="21010002" name="Soller slits 0.04 rad.">
				<opening unit="rad">0.0400</opening>
			</sollerSlit>
			<mask id="22031000" name="Fixed mask 13 mm">
				<width unit="mm">9.00</width>
			</mask>
			<divergenceSlit id="22120001" name="Divergence slit 1°" xsi:type="fixedDivergenceSlitType">
				<distanceToSample unit="mm">50.00</distanceToSample>
				<height unit="mm">1.52</height>
			</divergenceSlit>
		</incidentBeamPath>
		<beamKnife id="29030100" name="Beam knife low"/>
		<sampleMovement xsi:type="spinningSampleMovementType">
			<spinnerRevolutionTime unit="seconds">1.0</spinnerRevolutionTime>
		</sampleMovement>
		<diffractedBeamPath>
			<radius unit="mm">145.00</radius>
			<antiScatterSlit id="22090040" name="AS slit 9 mm" xsi:type="fixedAntiScatterSlitType">
				<height unit="mm">9.00</height>
			</antiScatterSlit>
			<sollerSlit id="21020003" name="Large Soller slits 0.04 rad.">
				<opening unit="rad">0.0400</opening>
			</sollerSlit>
			<filter id="20030001" name="Large beta-filter Nickel">
				<material>Ni</material>
				<thickness unit="mm">0.020</thickness>
			</filter>
			<detector id="7010019" name="PIXcel1D-Medipix3 detector" xsi:type="rtmsDetectorType">
				<phd unit="keV">
					<lowerLevel>4.0</lowerLevel>
					<upperLevel>11.3</upperLevel>
				</phd>
				<mode>Scanning</mode>
				<activeLength unit="deg">1.021</activeLength>
			</detector>
		</diffractedBeamPath>
		<scan appendNumber="0" mode="Continuous" scanAxis="Gonio" status="Completed">
			<header>
				<startTimeStamp>2024-03-24T16:39:13-07:00</startTimeStamp>
				<endTimeStamp>2024-03-24T16:41:35-07:00</endTimeStamp>
				<author>
					<name>AutomatedUser</name>
				</author>
				<source>
					<applicationSoftware version="1.6 (94)">PANalytical Aeris Instrument Suite</applicationSoftware>
					<instrumentControlSoftware version="3.0.0 20211014">AERIS</instrumentControlSoftware>
					<instrumentID>2879380</instrumentID>
				</source>
			</header>
			<dataPoints>
				<positions axis="2Theta" unit="deg">
					<startPosition>10.02173288</startPosition>
					<endPosition>139.98435528</endPosition>
				</positions>
				<positions axis="Omega" unit="deg">
					<startPosition>5.01086644</startPosition>
					<endPosition>69.99217764</endPosition>
				</positions>
				<commonCountingTime unit="seconds">1.551</commonCountingTime>
				<counts unit="counts">521 515 482 528 518 513 500 502 529 518 493 521 553 492 501 482 513 483 483 496 512 527 495 478 524 512 459 477 470 434 500 470 487 431 527 478 421 463 483 455 492 503 487 440 462 458 504 486 466 461 443 466 453 453 444 458 487 461 460 454 460 447 460 407 416 425 428 455 459 470 440 396 418 412 456 440 459 388 441 450 420 415 434 414 437 421 492 425 425 425 421 416 421 422 424 443 424 425 393 439 438 453 446 379 403 438 407 435 437 428 463 421 422 424 384 394 438 402 406 429 409 405 391 446 379 401 394 414 472 421 407 410 434 396 422 419 430 383 392 425 379 426 409 392 394 404 420 397 429 409 439 408 390 433 457 419 438 433 395 430 432 416 401 399 374 377 380 368 388 380 421 397 393 392 362 384 377 402 384 386 388 396 407 388 446 420 461 506 488 465 423 456 393 410 371 397 391 378 401 374 408 401 409 372 356 336 394 397 386 364 419 388 409 384 382 350 395 406 437 437 441 422 361 354 361 353 371 381 371 379 386 358 330 411 392 418 365 372 393 378 369 395 377 368 313 406 355 400 366 341 394 370 362 401 353 363 408 386 312 382 350 358 444 374 409 467 457 417 379 373 365 360 369 382 365 340 385 416 394 443 393 483 618 870 1187 1258 903 628 440 391 388 384 382 374 362 374 366 367 380 374 343 350 377 351 372 349 366 350 371 338 365 363 361 340 394 358 363 372 349 374 367 363 356 350 367 403 375 433 463 496 417 390 389 346 368 384 343 381 363 355 382 401 345 375 348 353 419 365 365 357 379 382 415 424 531 685 604 492 376 360 355 341 372 343 376 345 346 353 342 340 338 384 359 352 388 390 389 390 377 469 619 853 971 705 564 461 410 415 593 705 1009 1801 2824 2341 1590 719 455 405 421 424 412 406 395 394 514 598 750 679 577 477 523 662 896 1225 1133 934 673 513 464 366 367 364 435 434 455 466 632 711 686 543 457 411 416 395 383 353 347 360 371 324 382 310 394 386 336 349 354 358 405 402 395 478 545 613 564 483 435 355 351 378 378 377 335 368 390 339 315 353 344 397 360 332 330 320 324 355 355 355 345 337 340 325 348 327 337 364 376 350 315 309 355 318 371 352 326 382 348 347 354 367 387 353 386 329 325 339 386 420 443 386 364 381 394 384 386 382 416 474 691 984 986 772 822 929 1083 855 700 491 397 362 315 355 334 381 360 356 310 364 394 396 422 371 313 360 371 352 378 345 340 353 333 356 350 351 379 329 384 358 329 360 357 352 408 455 563 612 498 456 428 450 540 685 1041 1292 1179 1025 832 601 527 420 375 396 410 410 422 390 357 383 356 333 331 319 363 329 346 373 391 559 705 593 560 483 426 358 296 412 414 507 571 597 567 482 425 390 351 348 365 324 312 370 405 473 521 460 442 377 354 315 333 346 277 317 344 301 320 332 289 307 294 313 331 318 340 303 319 318 318 302 312 300 299 300 293 294 317 336 317 273 334 293 309 323 287 305 344 292 298 336 330 317 311 353 297 304 346 359 416 430 392 336 321 360 347 333 358 322 322 317 289 374 322 308 323 340 307 290 321 343 321 292 338 292 296 284 320 341 308 304 332 420 371 310 320 372 322 323 322 365 362 323 322 348 339 307 335 332 329 362 406 420 423 399 381 329 321 314 308 335 365 342 295 319 328 369 479 479 471 424 390 356 344 344 297 317 335 355 306 301 315 311 334 269 328 331 296 313 338 346 307 312 297 293 324 317 316 320 308 324 352 313 333 335 324 329 321 337 319 324 375 355 397 426 411 328 389 369 341 334 303 302 355 314 317 362 294 339 324 349 314 335 331 326 401 403 499 470 545 677 829 779 593 623 486 343 361 326 308 293 272 286 308 314 285 310 322 257 323 313 368 294 300 286 319 371 301 347 389 371 378 343 331 327 329 318 284 348 290 287 296 313 267 286 333 348 369 436 429 372 461 497 407 393 399 355 309 313 322 361 330 336 298 380 335 332 359 343 343 364 410 393 402 399 391 353 381 444 427 420 390 458 449 434 358 400 378 313 354 324 313 315 281 308 323 333 325 324 315 340 368 359 423 438 422 434 427 382 368 325 345 371 376 336 375 324 354 355 321 340 394 471 412 379 373 390 481 450 369 420 393 348 358 319 398 434 535 567 443 447 467 372 346 328 338 321 326 321 350 376 521 528 392 403 414 388 330 346 309 396 378 334 386 347 355 347 338 334 323 326 328 304 307 309 339 300 301 320 294 321 316 337 319 352 314 330 309 360 375 389 547 625 466 436 455 457 473 442 388 421 437 380 437 456 504 512 498 425 392 438 424 362 345 377 349 401 446 428 350 402 358 319 353 366 334 374 404 406 380 370 393 339 305 324 353 345 367 387 495 455 466 465 453 421 459 369 354 354 313 347 334 312 342 318 327 295 326 377 385 398 410 378 396 369 374 319 315 376 368 435 414 334 403 394 377 412 352 402 424 348 372 362 322 331 350 352 410 409 353 371 422 339 305 330 292 317 323 294 286 300 337 327 310 307 324 323 337 305 317 344 321 328 325 330 304 356 316 295 301 347 308 306 285 338 298 320 336 311 307 320 321 318 294 321 328 312 325 310 299 314 354 427 432 340 336 387 362 372 374 364 355 321 347 369 354 319 321 330 364 390 414 404 462 490 578 541 502 528 509 463 486 405 349 338 338 319 277 343 291 313 324 367 303 311 317 332 336 327 382 446 362 354 382 363 356 374 321 303 301 308 318 304 319 300 327 299 330 296 332 324 305 300 312 307 330 321 317 311 344 319 298 281 303 271 295 300 310 288 316 307 272 290 286 304 281 312 313 293 311 324 305 333 346 315 316 301 324 319 319 386 354 322 324 341 321 347 294 283 323 325 302 328 370 352 338 371 340 316 376 319 308 285 306 308 281 287 283 346 302 272 303 290 321 315 304 328 365 328 343 318 328 314 348 300 340 309 304 330 317 327 350 385 322 316 359 347 360 350 340 352 345 294 316 331 323 313 291 332 311 298 298 330 300 334 365 319 286 325 360 341 307 311 308 297 293 293 315 328 344 326 299 330 366 360 312 308 314 320 344 346 351 310 360 310 345 321 339 356 372 345 321 336 360 397 419 397 380 375 361 335 366 347 322 303 297 308 325 286 334 326 302 290 311 318 314 352 323 340 318 277 305 317 314 304 286 277 267 315 308 291 313 265 308 307 281 270 293 332 329 302 308 306 336 283 289 278 304 320 307 304 297 322 360 342 352 370 294 329 318 341 337 369 372 331 289 315 342 312 354 311 302 324 318 362 312 315 305 320 301 293 300 314 278 305 296 301 310 338 302 324 315 299 279 296 302 299 299 322 285 335 324 306 300 312 284 308 301 295 315 276 299 318 310 307 270 304 319 283 280 288 338 309 303 309 307 303 323 307 326 304 316 318 353 352 324 361 299 292 325 327 336 348 321 304 312 289 293 270 324 289 333 283 307 244 322 311 341 306 310 362 312 317 323 323 307 294 332 316 286 372 345 374 343 325 354 305 328 311 355 332 309 351 377 328 316 323 330 349 345 338 318 326 318 310 359 342 308 373 335 332 335 326 291 292 278 305 289 325 326 297 274 290 319 332 292 300 324 366 324 311 324 310 307 326 309 302 304 312 314 267 269 301 302 306 315 314 323 348 408 332 315 330 303 336 338 330 309 316 317 292 334 302 291 290 283 304 311 328 282 265 295 367 313 292 302 313 288 303 307 314 317 248 322 315 304 292 320 326 327 330 304 333 318 335 390 340 307 330 342 369 333 362 326 309 322 306 291 298 328 324 333 253 294 291 275 323 289 288 298 284 295 325 270 346 316 288 278 291 301 278 313 309 291 301 318 305 266 310 282 287 349 290 293 320 328 361 344 337 353 303 348 389 347 324 353 278 333 330 339 322 303 309 327 273 324 304 316 336 325 323 337 326 324 325 356 308 317 318 362 324 312 308 276 323 324 340 382 318 315 327 325 333 307 324 319 335 307 303 298 293 345 299 313 276 325 296 307 280 310 321 341 312 322 344 316 340 394 320 367 340 328 371 353 336 350 370 352 293 314 330 341 322 335 303 317 334 276 310 306 322 305 340 297 309 298 368 305 310 323 297 323 291 312 307 295 336 301 328 305 294 321 307 299 303 316 372 350 298 314 286 324 337 359 330 286 289 289 336 252 299 295 297 280 288 320 306 303 313 343 323 316 301 316 292 310 315 316 304 329 301 343 333 366 328 332 284 326 295 305 317 322 352 300 314 319 307 321 317 285 332 312 285 307 341 325 336 341 325 322 328 324 310 313 326 311 313 337 326 315 328 323 286 301 278 342 313 329 312 313 348 283 349 363 328 355 323 286 315 281 316 287 303 344 315 299 320 243 305 317 304 289 302 337 330 281 321 296 283 310 300 301 276 305 273 287 275 314 283 296 311 298 352 311 321 315 310 295 270 301 301 318 319 322 335 323 293 309 314 305 307 315 307 288 326 284 298 303 285 300 304 283 319 298 298 304 287 301 330 283 286 290 293 322 267 278 318 291 304 293 300 291 300 309 303 351 308 324 316 325 328 340 337 326 333 328 328 318 338 317 314 334 312 326 351 317 340 295 274 332 304 351 308 283 315 306 335 318 320 327 312 290 321 324 314 316 293 279 322 337 317 291 286 300 304 298 301 317 275 317 332 313 300 293 287 326 325 314 292 281 346 307 340 314 296 259 305 334 332 366 305 339 325 306 330 302 298 322 371 356 329 299 336 321 334 307 311 346 358 323 319 370 310 312 305 317 308 316 340 334 303 274 268 297 281 346 341 328 335 335 319 309 298 338 338 356 311 294 313 328 342 326 339 346 320 351 312 300 318 319 327 360 304 342 312 310 303 304 318 347 312 301 302 314 298 331 320 322 300 300 317 307 339 310 288 343 284 311 339 329 312 337 312 345 286 299 304 340 311 322 314 317 340 301 311 335 299 309 296 312 337 299 301 310 292 306 294 337 321 266 301 322 279 316 308 298 301 300 314 306 317 307 302 322 272 311 279 330 298 279 286 313 306 289 316 312 300 328 321 317 320 296 318 324 265 326 317 299 328 313 320 323 308 294 311 326 324 334 323 328 306 312 316 315 296 295 343 310 290 320 275 330 286 352 287 321 275 286 294 328 285 317 335 299 284 303 318 314 289 345 331 300 305 321 321 317 307 293 299 300 288 324 326 281 327 338 289 288 296 306 305 300 317 279 303 291 320 322 300 289 304 318 297 293 299 326 310 322 317 287 342 320 290 318 325 295 324 299 284 312 296 288 329 314 314 297 337 326 344 373 316 335 320 322 321 338 305 298 324 320 312 311 310 332 300 358 344 309 303 339 326 309 324 306 289 292 313 312 304 306 291 308 325 299 273 305 286 304 297 319 327 306 277 286 322 340 295 321 326 321 342 344 336 318 306 327 308 292 309 305 339 302 341 300 302 316 337 306 299 295 332 325 353 303 306 328 323 314 352 312 324 306 303 302 347 335 314 302 303 344 327 261 300 318 297 296 344 336 303 275 338 287 322 258 338 284 323 325 324 300 315 282 316 307 316 289 298 297 329 287 319 312 335 328 327 292 311 337 325 324 346 315 336 317 289 287 310 312 318 339 333 328 336 321 314 333 338 315 289 342 344 328 336 322 332 330 319 331 359 333 348 322 359 353 393 329 323 331 304 346 341 356 321 319 332 315 331 332 310 336 344 335 324 339 302 292 325 333 298 308 306 293 303 329 335 275 298 310 301 326 293 308 283 321 313 320 313 312 308 317 327 332 323 306 310 309 306 293 324 321 294 297 286 303 318 277 300 319 279 344 294 314 338 352 332 298 295 285 313 329 297 299 291 301 322 320 311 272 275 307 301 290 341 292 280 285 327 304 327 335 365 356 324 305 348 303 289 332 321 353 317 344 320 347 318 338 300 346 343 323 355 346 355 323 315 327 297 331 300 350 322 345 306 340 351 352 315 329 373 354 330 331 351 329 358 348 347 361 328 322 345 341 330 346 318 354 305 297 317 302 312 356 309 356 371 358 326 319 327 360 344 351 321 289 329 314 309 311 282 341 330 323 290 309 329 332 317 328 300 287 300 300 310 297 298 320 315 295 321 283 320 323 312 304 285 289 330 326 297 316 299 307 344 298 308 328 344 305 290 292 299 325 339 303 303 312 318 318 337 339 327 315 331 310 319 320 337 311 340 319 281 276 372 303 326 273 337 333 297 313 359 333 335 354 313 298 333 326 361 348 284 307 279 308 278 325 386 298 308 351 348 336 322 312 329 319 298 308 308 328 310 291 310 314 305 330 303 314 335 326 315 284 309 317 323 345 301 314 326 307 300 308 318 308 312 332 335 316 299 316 343 350 340 339 322 349 351 338 358 343 310 359 338 312 307 357 355 333 306 330 356 320 349 342 321 356 350 315 314 312 356 313 291 312 345 337 319 304 310 316 326 340 334 304 303 347 340 323 333 296 346 316 339 300 339 355 360 338 317 328 308 324 326 320 322 308 312 335 333 285 308 314 338 344 353 357 330 351 280 322 302 319 333 358 357 346 294 296 317 326 326 329 331 328 266 300 329 322 321 290 321 320 339 289 307 319 302 309 337 326 323 279 367 349 340 327 314 318 340 289 311 312 326 335 313 290 295 324 301 330 290 325 318 324 302 335 343 329 316 327 339 316 256 289 298 309 287 296 297 360 305 301 317 290 309 337 321 333 333 287 306 312 324 302</counts>
			</dataPoints>
		</scan>
	</xrdMeasurement>
</xrdMeasurements>