File: dataset/precursor_mixture/GeO2_MnCO3_ZrO2_Bi2O3-alpha.12-min.xrdml
<?xml version="1.0"?>
<xrdMeasurements xmlns="http://www.xrdml.com/XRDMeasurement/2.2" xmlns:xsi="http://www.w3.org/2001/XMLSchema-instance" xsi:schemaLocation="http://www.xrdml.com/XRDMeasurement/2.2 http://www.xrdml.com/XRDMeasurement/2.2/XRDMeasurement.xsd" status="Completed" recordIdentifier="{05CE41ED-55BA-4B09-8E8F-EED9C0F3C601}">
	<comment>
		<entry/>
	</comment>
	<sample type="To be analyzed">
		<id>dara-25-2</id>
		<name></name>
		<preparedBy></preparedBy>
	</sample>
	<xrdMeasurement measurementType="Scan" status="Completed" sampleMode="Reflection">
		<usedWavelength intended="K-Alpha 1">
			<kAlpha1 unit="Angstrom">1.5405980</kAlpha1>
			<kAlpha2 unit="Angstrom">1.5444260</kAlpha2>
			<kBeta unit="Angstrom">1.3922500</kBeta>
			<ratioKAlpha2KAlpha1>0.5000</ratioKAlpha2KAlpha1>
		</usedWavelength>
		<incidentBeamPath>
			<radius unit="mm">145.00</radius>
			<xRayTube id="1010048" name="Empyrean Cu LFF HR (9430 033 7310x) DK437873">
				<tension unit="kV">40.0</tension>
				<current unit="mA">15.0</current>
				<anodeMaterial>Cu</anodeMaterial>
				<focus type="Line">
					<length unit="mm">12.0</length>
					<width unit="mm">0.4</width>
					<takeOffAngle unit="deg">6.0</takeOffAngle>
				</focus>
			</xRayTube>
			<filter id="20010004" name="Beta-filter Nickel">
				<material>Ni</material>
				<thickness unit="mm">0.020</thickness>
			</filter>
			<sollerSlit id="21010002" name="Soller slits 0.04 rad.">
				<opening unit="rad">0.0400</opening>
			</sollerSlit>
			<mask id="22031000" name="Fixed mask 13 mm">
				<width unit="mm">9.00</width>
			</mask>
			<divergenceSlit id="22120001" name="Divergence slit 1°" xsi:type="fixedDivergenceSlitType">
				<distanceToSample unit="mm">50.00</distanceToSample>
				<height unit="mm">1.52</height>
			</divergenceSlit>
		</incidentBeamPath>
		<beamKnife id="29030100" name="Beam knife low"/>
		<sampleMovement xsi:type="spinningSampleMovementType">
			<spinnerRevolutionTime unit="seconds">1.0</spinnerRevolutionTime>
		</sampleMovement>
		<diffractedBeamPath>
			<radius unit="mm">145.00</radius>
			<antiScatterSlit id="22090040" name="AS slit 9 mm" xsi:type="fixedAntiScatterSlitType">
				<height unit="mm">9.00</height>
			</antiScatterSlit>
			<sollerSlit id="21020003" name="Large Soller slits 0.04 rad.">
				<opening unit="rad">0.0400</opening>
			</sollerSlit>
			<filter id="20030001" name="Large beta-filter Nickel">
				<material>Ni</material>
				<thickness unit="mm">0.020</thickness>
			</filter>
			<detector id="7010019" name="PIXcel1D-Medipix3 detector" xsi:type="rtmsDetectorType">
				<phd unit="keV">
					<lowerLevel>4.0</lowerLevel>
					<upperLevel>11.3</upperLevel>
				</phd>
				<mode>Scanning</mode>
				<activeLength unit="deg">5.020</activeLength>
			</detector>
		</diffractedBeamPath>
		<scan appendNumber="0" mode="Continuous" scanAxis="Gonio" status="Completed">
			<header>
				<startTimeStamp>2024-03-25T11:02:18-07:00</startTimeStamp>
				<endTimeStamp>2024-03-25T11:14:46-07:00</endTimeStamp>
				<author>
					<name>AutomatedUser</name>
				</author>
				<source>
					<applicationSoftware version="1.6 (94)">PANalytical Aeris Instrument Suite</applicationSoftware>
					<instrumentControlSoftware version="3.0.0 20211014">AERIS</instrumentControlSoftware>
					<instrumentID>2879380</instrumentID>
				</source>
			</header>
			<dataPoints>
				<positions axis="2Theta" unit="deg">
					<startPosition>9.99043322</startPosition>
					<endPosition>100.09495370</endPosition>
				</positions>
				<positions axis="Omega" unit="deg">
					<startPosition>4.99521661</startPosition>
					<endPosition>50.04747685</endPosition>
				</positions>
				<commonCountingTime unit="seconds">18.249</commonCountingTime>
				<counts unit="counts">4406 4508 4330 4294 4508 4394 4398 4406 4372 4311 4300 4379 4479 4300 4390 4339 4245 4327 4354 4257 4398 4385 4330 4346 4243 4404 4368 4307 4200 4319 4305 4223 4259 4329 4284 4131 4231 4332 4378 4291 4268 4179 4122 4264 4182 4268 4143 4244 4214 4244 4194 4300 4259 4242 4150 4228 4389 4101 4265 4222 4201 4207 4230 4037 4058 4154 4191 4096 4002 4012 4160 4197 4080 4077 4075 4102 4144 4132 4068 4005 3917 4046 4037 4232 4063 4105 4085 4092 3996 4037 4165 3990 4085 3859 3950 4063 4054 4072 4011 4017 3966 3930 3985 4007 3975 3962 3938 4032 3996 4021 4018 4045 3853 3893 3890 3952 3897 3944 3877 3813 3980 3877 3913 3888 3875 3907 3930 3856 3935 4029 3876 3857 3911 3917 3817 3840 3852 3944 3867 3778 3863 3725 3926 3867 3790 3854 3745 3768 3895 3774 3830 3809 3884 3881 3769 3747 3798 3771 3892 3797 3609 3774 3759 3758 3668 3736 3705 3875 3715 3862 3716 3767 3676 3654 3842 3772 3887 3812 3777 3705 3689 3800 3664 3712 3719 3632 3758 3739 3641 3778 3801 3749 3785 3625 3703 3677 3707 3651 3579 3635 3587 3684 3664 3710 3642 3786 3679 3696 3689 3619 3539 3537 3646 3673 3536 3620 3589 3573 3585 3594 3505 3634 3638 3549 3585 3601 3565 3577 3576 3626 3602 3557 3599 3507 3521 3501 3594 3484 3570 3639 3620 3541 3645 3538 3546 3567 3452 3533 3513 3652 3541 3527 3466 3427 3451 3574 3504 3413 3479 3399 3559 3416 3612 3644 3545 3634 3508 3427 3456 3450 3440 3409 3467 3499 3422 3438 3384 3457 3523 3398 3468 3401 3451 3491 3353 3498 3456 3399 3455 3470 3403 3476 3290 3316 3386 3451 3490 3463 3459 3360 3469 3335 3453 3396 3385 3378 3405 3363 3339 3419 3302 3240 3377 3273 3383 3396 3339 3330 3320 3522 3338 3349 3437 3227 3309 3313 3364 3302 3286 3317 3365 3253 3313 3305 3410 3278 3227 3316 3353 3374 3248 3352 3313 3297 3304 3324 3306 3389 3349 3330 3262 3210 3454 3257 3212 3324 3314 3257 3310 3271 3417 3171 3243 3129 3255 3264 3291 3287 3225 3193 3380 3174 3273 3205 3315 3172 3216 3264 3340 3143 3185 3223 3194 3293 3253 3276 3255 3300 3241 3202 3257 3093 3187 3189 3208 3305 3316 3294 3319 3155 3210 3191 3192 3327 3253 3233 3294 3193 3179 3116 3295 3182 3233 3152 3310 3264 3165 3232 3107 3239 3247 3330 3207 3221 3201 3197 3276 3143 3197 3252 3195 3207 3117 3202 3152 3225 3303 3186 3324 3202 3107 3202 3227 3199 3108 3161 3202 3084 3135 3197 3086 3162 3143 3163 3208 3169 3123 2999 3122 3196 3169 3188 3162 3276 3098 3189 3234 3042 3152 3338 3081 3086 3072 3147 3137 3087 3040 3181 3195 3118 3106 3156 3142 3114 3192 3089 3093 3186 3214 3122 3100 3008 3083 3132 3061 3090 3068 3093 3047 3207 3002 2998 3172 3005 3047 3092 3108 3042 3049 3048 3004 3084 3122 3138 3160 3100 2976 3107 3091 3110 3016 3121 3025 3083 3117 3012 2982 3057 3098 3082 3076 3030 3051 3035 3120 3120 3111 3055 3112 3086 3070 3194 3036 3068 3040 2969 3027 3155 3100 3082 3070 3189 3000 3098 3042 3034 2960 3059 3082 3088 3037 3041 3010 2946 2977 3158 3124 2982 3088 3099 3119 3064 3122 3121 3008 3065 3059 3020 3009 2979 3081 2972 3041 3124 2928 2933 3035 3040 3096 3083 3108 3001 3057 2976 2953 3020 2997 3050 3021 3152 2989 3153 3053 3056 3043 3109 3008 2998 2954 3141 3124 3132 3082 3186 3128 3305 3244 3121 3170 3254 3195 3241 3193 3324 3259 3392 3372 3439 3337 3249 3269 3299 3180 3193 3204 3052 3136 3034 3092 3048 2939 3092 2917 2969 2981 2899 3044 2881 3021 2984 3088 3117 3023 2980 3071 2923 2997 2959 2950 3020 2934 3012 3030 3117 3052 3030 3073 2965 3131 3154 3009 3175 3097 3023 3157 3158 3220 3160 3304 3319 3228 3277 3213 3244 3252 3406 3305 3369 3361 3369 3271 3182 3224 3128 3185 3076 3126 3047 3128 3207 3024 2971 3105 2944 3000 3026 2988 2986 2874 2950 2870 2895 3036 2905 2956 2926 2909 2909 2896 2956 2940 2882 2892 2965 2838 3046 2853 3013 2892 2874 2823 2892 2789 3029 2833 2867 2926 2812 2866 2924 2827 2993 2915 2973 2907 2942 2860 2862 2824 2868 2810 2881 2906 2808 2872 2848 2824 2773 2791 2803 2812 2877 2890 2916 2832 2897 2735 2707 2837 2811 2794 2757 2883 2805 2742 2953 2849 2885 2949 2815 2878 2780 2806 2812 2807 2871 2835 2886 2826 2867 2868 2831 2780 2842 2839 2762 2904 2811 2816 2796 2768 2796 2903 2733 2811 2838 2773 2775 2720 2807 2812 2852 2895 2664 2738 2813 2817 2758 2781 2811 2737 2814 2796 2729 2787 2706 2737 2690 2774 2797 2759 2686 2799 2770 2793 2667 2783 2839 2760 2757 2633 2829 2765 2840 2732 2807 2807 2813 2667 2785 2721 2730 2728 2797 2728 2612 2723 2775 2779 2808 2718 2699 2743 2657 2641 2775 2684 2841 2756 2810 2736 2796 2718 2760 2753 2682 2863 2700 2804 2799 2836 2861 2827 2917 2896 2968 2972 3071 3057 3111 3105 3231 3247 3461 3394 3413 3638 3603 3550 3516 3586 3429 3274 3199 3126 3031 2891 2831 2839 2779 2726 2777 2699 2725 2746 2761 2652 2665 2674 2615 2626 2706 2644 2656 2691 2785 2630 2597 2725 2691 2690 2652 2662 2747 2713 2607 2634 2745 2805 2752 2763 2767 2745 2823 2775 2791 2681 2691 2659 2855 2788 2741 2808 2741 2867 2885 2853 2970 3056 2982 3054 3113 3204 3268 3378 3352 3502 3573 3562 3708 3699 3699 3809 3830 3817 3700 3646 3547 3553 3246 3317 3255 3092 2966 2888 2900 2753 2768 2703 2795 2746 2839 2726 2656 2642 2635 2641 2665 2582 2541 2598 2688 2544 2560 2597 2492 2688 2507 2632 2575 2610 2597 2640 2528 2593 2532 2582 2534 2540 2590 2546 2579 2602 2489 2484 2551 2613 2573 2563 2547 2521 2552 2583 2506 2568 2598 2453 2621 2632 2508 2496 2535 2602 2570 2522 2601 2556 2501 2475 2482 2494 2638 2567 2572 2480 2554 2566 2606 2555 2578 2606 2640 2628 2627 2623 2604 2616 2655 2652 2608 2723 2734 2801 2819 2819 2925 2985 2983 3108 3187 3303 3450 3324 3451 3481 3457 3357 3316 3210 3138 3035 2845 2769 2774 2714 2662 2547 2578 2512 2497 2530 2530 2469 2458 2473 2565 2407 2468 2432 2572 2456 2470 2454 2565 2637 2503 2503 2421 2429 2456 2418 2505 2494 2478 2481 2508 2487 2485 2499 2441 2504 2390 2380 2413 2318 2471 2408 2505 2477 2478 2459 2551 2468 2425 2458 2514 2455 2424 2460 2512 2483 2424 2417 2384 2368 2408 2328 2434 2428 2473 2547 2446 2480 2483 2421 2269 2475 2453 2402 2478 2336 2386 2440 2521 2390 2447 2410 2385 2483 2451 2517 2460 2336 2320 2418 2403 2463 2349 2434 2489 2430 2386 2406 2414 2391 2450 2418 2407 2472 2432 2417 2418 2441 2344 2489 2453 2330 2456 2446 2436 2426 2393 2427 2421 2406 2434 2333 2424 2509 2355 2448 2495 2457 2437 2420 2424 2461 2429 2457 2404 2464 2567 2502 2504 2559 2497 2418 2585 2468 2512 2528 2524 2571 2458 2484 2506 2475 2527 2531 2390 2439 2472 2492 2447 2537 2511 2535 2451 2561 2564 2548 2632 2511 2526 2549 2530 2457 2610 2610 2631 2702 2605 2697 2586 2738 2670 2808 2823 2798 2878 2914 2913 2972 3128 3212 3207 3239 3410 3554 3694 3812 3848 3954 4030 4142 4423 4265 4410 4418 4416 4459 4606 4570 4475 4592 4565 4528 4588 4470 4395 4387 4400 4339 4075 4204 3910 3954 3695 3633 3628 3544 3686 3594 3541 3692 3434 3588 3578 3705 3856 3687 3842 3959 4162 4217 4378 4328 4416 4650 4532 4621 4822 4831 4835 4523 4471 4180 3949 3765 3580 3429 3199 3096 2926 2902 2779 2759 2682 2755 2603 2654 2587 2547 2434 2449 2460 2587 2525 2563 2401 2433 2490 2470 2402 2448 2429 2491 2495 2480 2467 2406 2491 2416 2396 2310 2518 2470 2512 2487 2492 2511 2508 2394 2463 2487 2510 2351 2472 2577 2547 2640 2633 2554 2654 2671 2799 2741 2676 2803 2827 2813 2752 2904 2803 2860 2802 2764 2776 2857 2687 2677 2662 2705 2719 2752 2628 2741 2720 2734 2793 2851 2821 2900 2903 3005 3072 3172 3209 3298 3485 3706 3884 3989 4452 4697 5124 5488 5927 6300 6803 7373 8031 8451 8522 8400 8156 7946 7736 7818 8057 7962 8226 8471 8684 9106 9787 9939 10405 11125 11652 11425 11355 10789 10149 9560 8824 8110 7610 6784 6256 5421 4993 4431 4099 3923 3647 3595 3297 3187 3243 3130 2962 2802 2863 2894 2767 2786 2731 2792 2753 2749 2665 2735 2678 2781 2672 2614 2634 2648 2503 2695 2651 2581 2582 2608 2583 2643 2719 2650 2742 2598 2641 2682 2682 2665 2728 2713 2694 2730 2608 2558 2677 2647 2720 2676 2723 2820 2833 2917 2962 3007 3128 3287 3267 3444 3673 4020 4281 4514 4923 5154 5807 6353 6875 7556 8457 9252 9756 10840 10918 10910 10685 10208 9501 8587 7891 7258 6508 5974 5168 4647 4127 3755 3621 3491 3396 3498 3554 3731 3765 3874 4025 4083 4465 4832 5367 5647 6210 6831 7569 8641 9578 11181 12670 14468 16825 19198 21904 24951 28345 31429 34980 37819 38531 37622 34731 30180 26778 23786 21249 19110 16418 13497 10479 8209 6409 5157 4448 4132 3651 3646 3511 3426 3380 3439 3448 3317 3217 3244 3319 3231 3185 3172 3220 3313 3190 3250 3363 3243 3458 3360 3357 3359 3452 3614 3709 3675 4097 4327 4523 4896 5211 5753 6071 6564 7386 7940 8695 9196 9909 10115 10277 9661 9420 9179 9209 9314 9458 9355 9432 9359 9671 9988 10230 10673 10842 11180 10943 10953 10631 10139 9768 9186 8732 8161 7581 7084 6455 6078 5565 5191 4747 4525 4302 3942 3900 3713 3713 3488 3461 3385 3239 3294 3191 3087 3006 2994 2969 2854 2945 2868 2707 2819 2800 2721 2679 2851 2684 2554 2479 2556 2536 2529 2550 2612 2573 2476 2525 2544 2369 2482 2422 2487 2375 2475 2488 2509 2523 2535 2408 2403 2322 2471 2340 2375 2463 2489 2426 2528 2396 2381 2410 2408 2321 2460 2351 2361 2272 2290 2227 2274 2372 2411 2319 2320 2415 2321 2321 2413 2396 2280 2335 2367 2280 2248 2333 2301 2332 2382 2261 2323 2328 2313 2244 2285 2330 2308 2302 2362 2259 2334 2339 2337 2321 2326 2345 2229 2314 2331 2269 2254 2308 2305 2270 2234 2258 2344 2279 2262 2172 2302 2226 2314 2302 2317 2320 2249 2329 2302 2206 2415 2201 2159 2343 2297 2315 2263 2246 2267 2319 2300 2311 2293 2408 2309 2281 2424 2288 2343 2252 2261 2273 2279 2234 2314 2280 2220 2364 2285 2263 2229 2340 2287 2271 2276 2369 2320 2291 2309 2261 2324 2271 2275 2375 2333 2348 2315 2350 2380 2261 2357 2358 2392 2241 2276 2357 2347 2273 2339 2311 2271 2304 2264 2315 2318 2322 2277 2312 2314 2259 2386 2311 2369 2361 2375 2319 2350 2318 2262 2277 2363 2326 2348 2435 2434 2436 2405 2364 2439 2406 2318 2541 2335 2385 2508 2415 2442 2368 2372 2335 2455 2448 2468 2439 2539 2511 2452 2564 2638 2659 2661 2660 2665 2760 2735 2740 2882 2841 2866 2985 2921 2973 3066 2967 3338 3307 3398 3552 3566 3761 3844 4069 4339 4542 4920 5002 5472 5814 6193 6684 6865 7344 7561 8075 8155 8493 8682 8732 9018 8808 9158 8968 9120 9374 9372 9136 9388 9231 8961 9273 9041 8595 8260 8082 7637 7144 6739 6531 6016 5775 5112 4918 4605 4301 4060 3812 3719 3477 3397 3193 3138 3094 3036 2937 2854 2831 2704 2730 2720 2643 2578 2532 2588 2554 2521 2497 2455 2436 2413 2450 2440 2379 2372 2387 2410 2318 2330 2346 2338 2309 2274 2276 2361 2313 2311 2185 2309 2303 2211 2252 2253 2199 2328 2297 2315 2398 2334 2308 2248 2214 2315 2200 2372 2247 2370 2374 2335 2317 2360 2352 2373 2519 2498 2589 2624 2687 2832 2917 3035 3117 3295 3407 3604 3640 3607 3399 3348 3154 2973 2938 2882 2917 2728 2730 2559 2439 2493 2459 2428 2395 2344 2368 2385 2394 2356 2406 2372 2384 2475 2468 2406 2565 2619 2610 2756 2735 2866 3035 3173 3455 3512 3843 4080 4530 5103 5531 6362 7074 8113 8854 10192 10898 11849 11966 11968 11349 10521 9765 9124 8878 9151 9240 9363 9350 9142 9492 10080 10678 11347 12567 13035 13375 13324 12183 11360 10351 9356 8665 8066 7549 7106 6546 5615 4777 4011 3513 3141 2749 2830 2637 2568 2462 2581 2468 2427 2372 2359 2313 2306 2411 2235 2318 2256 2344 2322 2282 2243 2375 2179 2230 2276 2215 2241 2183 2302 2226 2164 2223 2278 2274 2247 2220 2416 2372 2403 2357 2520 2522 2768 2721 2970 3041 3222 3320 3593 3725 3804 3711 3887 3563 3532 3352 3478 3499 3435 3488 3544 3458 3477 3406 3407 3499 3613 3778 3838 3997 3955 4052 3914 3975 3705 3876 3705 3586 3571 3450 3481 3361 3307 3344 3332 3120 3227 3183 3192 3238 3311 3288 3243 3239 3187 3114 3122 3173 2959 2943 2804 2964 2742 2729 2585 2675 2704 2597 2564 2495 2400 2384 2362 2261 2390 2312 2356 2293 2389 2302 2347 2359 2233 2313 2254 2207 2187 2167 2225 2213 2219 2242 2321 2310 2458 2366 2428 2429 2561 2721 2793 2975 3051 3243 3608 3955 4338 4728 5214 5490 5785 6022 5982 5558 5438 4999 4734 4511 4526 4305 4295 4210 3906 3589 3341 3303 3250 3195 3131 3219 3266 3392 3415 3607 3784 3924 3963 4040 4308 4428 4697 4806 4979 5023 5302 5098 4753 4575 4266 4084 3852 3628 3658 3481 3360 3261 2862 2764 2565 2424 2474 2347 2327 2334 2249 2274 2264 2296 2253 2233 2265 2223 2192 2343 2182 2318 2271 2331 2354 2421 2510 2638 2636 2806 2944 3115 3497 3598 3753 3945 4133 4244 4190 4161 4099 3952 3817 3914 3798 3920 3747 3459 3230 3179 2938 2895 2812 2688 2710 2513 2438 2409 2266 2302 2205 2170 2238 2147 2042 2197 2139 2183 2079 2062 2070 2053 1970 2056 1965 2020 2001 2114 2005 1982 2084 1965 1969 2002 1946 1901 2065 2055 1989 2042 1904 1995 1989 1886 1964 1941 1987 1995 2018 1998 2009 1950 1971 1956 2039 2076 1983 1924 2033 1989 2088 2005 1963 1966 2019 1995 2035 2058 1995 2173 2116 2151 2240 2152 2231 2336 2400 2557 2698 2767 3022 3161 3481 3586 3638 3635 3486 3219 3084 2882 2779 2906 2784 2832 2705 2576 2415 2393 2291 2211 2145 2122 2063 2094 2116 2098 2110 2111 2177 2120 2164 2204 2212 2230 2276 2338 2448 2524 2503 2514 2643 2691 2755 2790 2927 2926 2973 2994 2990 3059 3066 3104 3189 3384 3434 3556 3860 3985 4262 4614 4916 5071 5166 5075 4927 4568 4175 3865 3714 3746 3628 3585 3437 3274 2981 2790 2530 2404 2432 2306 2254 2258 2244 2276 2198 2266 2389 2307 2395 2599 2569 2713 2722 2934 3067 3242 3418 3652 3883 4006 4212 4208 4119 4210 4019 3890 3732 3646 3553 3496 3299 3339 3091 2933 2743 2529 2527 2346 2351 2213 2191 2142 2242 2145 2097 2037 2121 2112 2038 2124 2077 2022 2070 2104 2097 2021 2020 2092 2058 2061 2076 2091 2134 2179 2034 2182 2206 2303 2219 2288 2309 2378 2280 2295 2282 2200 2256 2288 2169 2221 2133 2194 2108 2128 1922 2050 2089 2005 2045 1964 1980 1996 1965 1991 1944 1982 1888 1957 1906 1821 1911 1921 1866 1959 1895 1889 1847 1850 1877 1907 1912 1904 1877 1893 1840 1847 1995 1788 1871 1909 1907 1860 1926 1978 1932 1899 1975 1921 1872 1936 1874 1960 1988 1973 1945 2056 2022 2011 2022 2055 2159 2163 2302 2326 2424 2571 2628 2591 2801 2875 3156 3238 3343 3219 3285 3308 3218 3027 2940 2882 2870 2822 2739 2616 2618 2441 2458 2374 2412 2170 2104 2126 2106 2054 1997 2037 2025 1928 1917 1892 1890 1906 1837 1914 1954 1856 1921 1925 1941 1963 1914 2023 1936 1908 1971 1931 2031 2002 2050 2079 2119 2363 2413 2521 2651 2774 2861 3144 3153 3335 3149 2925 2750 2554 2538 2460 2426 2571 2549 2566 2327 2285 2100 2074 1970 2058 1892 1914 1978 1914 1879 1893 1889 1944 1907 1873 1954 1903 1914 1910 1966 1915 1951 1899 2058 2033 1985 1975 1996 2067 2057 2019 2170 2081 2188 2199 2234 2377 2292 2386 2396 2530 2542 2537 2466 2616 2717 2748 2629 2808 2825 2820 2871 2825 2742 2792 2738 2696 2598 2602 2539 2585 2543 2390 2404 2314 2341 2343 2289 2133 2237 2221 2309 2095 2225 2196 2288 2199 2260 2185 2292 2246 2371 2234 2332 2350 2374 2423 2517 2461 2536 2521 2685 2622 2725 2656 2756 2789 2856 2952 3040 3075 3145 3199 3194 3279 3421 3375 3356 3464 3512 3402 3526 3688 3694 3791 3875 3913 3961 3907 3724 3479 3350 3208 3081 3005 2923 2877 3004 2900 2880 2775 2590 2634 2622 2670 2710 2761 2735 2903 3127 3227 3378 3522 3765 3827 3885 3927 3941 3875 3928 3945 3885 3838 3841 3829 3873 4035 3840 3616 3444 3238 3044 2935 2770 2698 2613 2640 2577 2527 2324 2215 2239 2151 2054 2104 1987 2060 1992 1949 2101 2069 2017 1910 1981 1958 2043 2053 2151 2025 2163 2180 2274 2362 2520 2643 2813 2961 3157 3427 3542 3571 3393 3135 2838 2615 2558 2617 2646 2627 2665 2626 2514 2316 2246 2137 1995 1942 1775 1858 1750 1832 1802 1764 1827 1787 1845 1755 1740 1794 1847 1813 1746 1733 1857 1786 1801 1782 1871 1744 1725 1737 1781 1742 1844 1774 1788 1724 1748 1719 1735 1724 1750 1767 1696 1732 1694 1775 1764 1783 1769 1731 1728 1826 1734 1738 1733 1781 1754 1796 1713 1721 1790 1751 1678 1826 1674 1721 1625 1670 1744 1675 1791 1713 1700 1729 1780 1732 1718 1794 1765 1776 1742 1660 1751 1714 1769 1755 1711 1685 1698 1768 1786 1713 1723 1782 1661 1763 1665 1694 1747 1696 1748 1691 1702 1788 1729 1733 1814 1759 1691 1711 1708 1774 1773 1784 1813 1787 1603 1693 1830 1712 1742 1735 1727 1708 1772 1773 1738 1723 1684 1721 1769 1691 1771 1713 1728 1752 1677 1677 1737 1673 1813 1755 1654 1771 1687 1670 1755 1801 1786 1744 1627 1816 1735 1808 1749 1728 1752 1774 1798 1792 1798 1898 1834 1890 1935 1996 2004 2114 2062 2015 2154 2097 1975 1985 1918 1977 1929 2029 1976 1987 2081 2000 1947 1958 1937 1887 1892 1876 1921 1842 1830 1963 1851 1890 1913 1875 1940 1921 1940 1961 1978 1925 2030 2043 1993 2001 2069 2048 2198 2254 2294 2331 2419 2431 2545 2608 2624 2601 2576 2725 2636 2749 2669 2745 2687 2663 2664 2717 2749 2764 2791 2820 2904 2992 3083 3047 3222 3354 3415 3410 3537 3735 3778 3909 3765 3577 3316 3196 2982 2913 2890 2960 2906 2911 2863 2742 2696 2607 2314 2412 2247 2214 2145 2190 2174 2151 2089 2133 2160 2137 2155 2187 2318 2251 2338 2312 2449 2303 2400 2313 2351 2320 2252 2312 2285 2295 2287 2184 2236 2187 2109 2110 2093 2037 2069 2057 2010 1985 1960 1973 1890 1911 1976 1965 1933 1885 1887 1925 1924 1839 1838 1920 1908 1960 1956 1886 1945 1882 1908 1833 1937 1871 1918 1880 1880 1871 1914 1911 1937 1985 1946 2060 1986 2024 2148 2081 2057 2108 2231 2265 2340 2566 2804 3010 3437 3791 4265 4905 5652 6359 7127 7902 8145 8292 7947 7420 6588 5889 5307 5091 5032 5211 5308 5322 5346 4969 4733 4155 3570 3152 2879 2618 2416 2330 2143 2074 2015 2097 1992 2027 1891 1907 1904 1950 1823 1800 1892 1911 1750 1876 1800 1728 1765 1854 1803 1701 1712 1755 1839 1803 1821 1807 1727 1750 1754 1835 1745 1768 1785 1850 1834 1832 1763 1733 1908 1820 1845 1896 1895 1846 1922 1821 1776 1824 1762 1732 1745 1826 1806 1814 1768 1785 1790 1867 1704 1700 1725 1827 1842 1705 1735 1746 1722 1791 1761 1811 1831 1954 1872 1850 1967 1979 2147 2143 2061 2182 2224 2244 2167 2071 2079 2096 2070 2115 2287 2368 2542 2660 2728 2622 2569 2487 2407 2281 2140 2139 2007 2135 2088 2150 2227 2049 2111 2122 1947 1999 1844 1948 1806 1906 1823 1851 1828 1791 1773 1806 1737 1694 1828 1813 1812 1704 1851 1824 1760 1786 1830 1778 1851 1851 1886 1893 1835 1844 1742 1898 1847 1834 1908 1916 1830 1862 2005 2009 2063 2027 2162 2255 2396 2401 2485 2571 2595 2604 2652 2675 2708 2751 2808 3066 3241 3558 3705 3916 4019 3994 3806 3682 3438 3251 3061 3015 3276 3308 3619 3815 4064 4425 4707 5014 4999 5091 5014 4725 4381 4250 4022 3982 3918 4062 4064 4061 4032 3962 3817 3582 3379 3126 3117 3025 2901 2813 2639 2572 2392 2384 2380 2320 2243 2246 2234 2284 2311 2267 2295 2120 2186 2152 2214 2163 2121 2091 2091 2189 2226 2184 2229 2236 2287 2343 2340 2436 2439 2439 2553 2665 2661 2761 2933 3014 2994 3156 3214 3241 3314 3356 3323 3198 3242 3081 3208 3233 3302 3288 3409 3598 3623 3705 3892 4042 4107 3940 3807 3656 3372 3333 3086 2987 3030 2981 3079 3168 3074 3087 3089 2874 2706 2587 2590 2447 2497 2479 2380 2334 2316 2303 2211 2400 2224 2272 2178 2157 2198 2215 2255 2296 2315 2201 2425 2474 2574 2646 2766 3011 3194 3259 3606 3718 3732 3675 3529 3353 3283 3158 3275 3403 3609 3650 3887 4099 4203 4191 4248 4009 4040 3782 3683 3579 3425 3334 3244 3222 3139 3273 3125 3103 3100 3090 2825 2836 2754 2704 2729 2705 2680 2538 2576 2552 2644 2646 2485 2458 2542 2416 2489 2393 2610 2604 2692 2731 2793 2763 2788 2974 2859 2995 2827 2733 2710 2662 2817 2552 2614 2482 2573 2555 2457 2594 2450 2387 2205 2468 2260 2257 2146 2240 2180 2247 2015 2085 2050 1979 2122 2040 2085 2025 1994 2001 2010 2009 2029 2015 2027 1951 2006 2065 2068 2111 2010 2169 2051 2139 2138 2082 2198 2246 2240 2262 2290 2348 2327 2385 2431 2373 2503 2429 2438 2629 2530 2591 2723 2668 2796 2789 2816 2845 2795 2710 2679 2664 2748 2871 2885 2896 3016 3066 3164 3013 3101 3010 2908 2958 2976 3143 3198 3213 3313 3555 3587 3809 3963 4083 4106 4298 4374 4401 4366 4665 4574 4531 4306 3957 3691 3518 3463 3373 3379 3376 3374 3463 3483 3519 3418 3541 3407 3438 3617 3758 3934 3910 3794 3578 3423 3070 2933 2763 2653 2723 2759 2809 2849 2950 2919 2863 2819 2659 2556 2480 2349 2281 2141 2131 2156 2125 2145 2155 2167 2244 2350 2336 2508 2661 2842 3054 3361 3914 4314 5009 5435 5658 5923 5612 5053 4482 3931 3477 3161 3232 3133 3266 3551 3686 3841 3889 3662 3451 3045 2700 2403 2329 2158 2114 1996 2113 1906 1887 1905 1999 1920 1904 1883 1928 1928 2039 1933 1883 1872 1940 1921 1832 1890 2028 2004 2073 2136 2142 2240 2228 2430 2578 2819 3057 3262 3606 3975 4415 4543 4756 4725 4447 4335 3820 3481 3106 3056 2954 3090 3161 3249 3280 3255 3275 3270 3119 2855 2566 2437 2299 2316 2173 2193 2243 2281 2332 2345 2424 2521 2532 2572 2442 2501 2406 2428 2387 2248 2294 2279 2202 2234 2169 2268 2246 2249 2162 2158 2145 2094 2027 2071 1966 1897 1966 1892 1941 1971 1866 1908 1932 1928 1846 1861 1796 1884 1906 1831 1904 1876 1933 1995 1948 1946 1849 1970 2000 1886 2026 1979 1955 1999 1931 2023 2029 2084 2181 2097 2166 2130 2173 2201 2187 2360 2212 2292 2380 2408 2456 2551 2645 2624 2645 2668 2593 2578 2584 2561 2622 2478 2616 2482 2391 2479 2301 2369 2419 2288 2374 2234 2244 2224 2251 2098 2051 2018 2081 2032 2068 1947 1926 1957 1989 1948 1860 1880 1859 1971 1936 1869 1985 1931 1993 1985 1877 1945 2024 1942 1931 2008 2011 2124 2124 2149 2246 2344 2585 2762 3091 3406 4037 4440 4971 5543 5853 5708 5373 4802 4118 3557 3215 3130 3013 3023 3327 3414 3740 3798 3879 3686 3504 3236 2792 2657 2311 2303 2206 2093 2103 2106 2070 2020 2107 2001 2043 2073 2034 2158 2080 2133 2221 2114 2212 2378 2265 2263 2309 2502 2505 2487 2476 2524 2571 2588 2610 2842 2873 2978 3138 3309 3485 3650 3934 4311 4429 4555 4472 4385 4354 3963 3822 3742 3649 3611 3373 3399 3465 3655 3662 3691 3550 3561 3225 3219 3095 2942 2858 2748 2590 2558 2569 2447 2552 2568 2417 2545 2542 2562 2701 2736 2913 3032 3169 3319 3593 3889 4065 4124 4093 3994 3724 3416 3224 2912 2758 2688 2848 2823 2931 2931 3018 3066 3020 2976 2802 2626 2430 2286 2156 2166 2144 2136 2163 2095 2136 2130 2065 2192 2075 2056 2100 2067 2085 2077 2012 2144 2027 2000 2055 2028 2016 1967 1863 1902 2018 2002 2023 1970 2090 2040 2114 2150 2097 2146 2072 1981 1989 1838 1849 1862 1941 1890 1924 1946 1958 1887 1960 1951 1978 1946 1868 1886 1870 1755 1840 1845 1785 1810 1774 1874 1734 1785 1845 1875 1796 1769 1872 1765 1873 1865 1874 1885 1899 1844 1876 1873 2027 1883 1906 1957 2009 1894 1990 1989 2067 1998 2038 2043 2136 2165 2006 2207 2193 2271 2250 2241 2261 2320 2275 2226 2173 2151 2135 2107 2149 2176 2148 2073 2147 2086 2058 2047 2049 1963 1936 1983 2077 1976 2006 1854 1812 1933 1845 1903 1896 1942 1965 1908 1906 1869 1911 1966 1837 1940 1961 1945 1910 1901 2031 2002 1985 2053 2165 2289 2388 2480 2641 2878 3010 3097 3311 3102 3100 3016 3134 3122 3361 3461 3638 3663 3559 3597 3498 3356 3240 3170 3101 3027 2965 2922 2956 2888 2892 2939 2812 2802 2624 2557 2416 2421 2366 2320 2376 2304 2228 2308 2368 2419 2446 2590 2802 2750 3138 3379 3473 3750 3777 3618 3511 3141 3032 2765 2729 2539 2629 2571 2648 2676 2780 2861 2929 2927 2794 2687 2648 2528 2406 2385 2375 2382 2515 2645 2615 2528 2547 2431 2365 2359 2238 2268 2308 2276 2417 2465 2592 2581 2662 2847 3057 3274 3211 3372 3376 3551 3589 3555 3551 3333 3434 3270 3146 3191 3036 3146 3167 3133 3372 3344 3509 3547 3643 3745 3810 3881 3949 4004 3928 3778 3533 3226 2936 2696 2780 2673 2573 2580 2563 2624 2669 2678 2614 2693 2624 2623 2403 2349 2310 2039 2076 1975 1958 1981 1973 1946 1904 1933 1940 1943 1921 1844 1929 1847 1937 1849 1868 1819 1872 1860 1989 1926 1951 1955 1948 1864 1876 2012 1859 1969 1924 1960 2069 1992 2054 2095 2156 2118 2165 2209 2273 2280 2282 2374 2353 2507 2616 2556 2597 2485 2498 2608 2565 2639 2689 2641 2835 2847 2857 2910 2845 2871 2974 2811 2750 2881 2814 2802 2768 2794 2831 2732 2773 2694 2697 2504 2552 2570 2451 2489 2422 2428 2343 2302 2256 2218 2267 2199 2233 2241 2080 2064 2083 2122 2041 1946 1880 1958 1862 1900 1913 1949 1976 1761 1856 1865 1810 1842 1825 1896 1803 1907 1852 1875 1913 1839 1932 1816 1766 1846 1688 1813 1823 1812 1723 1777 1791 1736 1787 1828 1710 1809 1751 1676 1715 1742 1712 1732 1788 1736 1773 1757 1761 1688 1717 1672 1848 1738 1824 1632 1689 1666 1779 1745 1755 1813 1722 1707 1719 1725 1778 1778 1711 1751 1823 1740 1901 1756 1740 1764 1759 1811 1839 1790 1838 1818 1864 1935 1875 1968 1977 1972 1920 1997 1939 2006 2037 2099 2138 2086 2275 2184 2251 2336 2342 2349 2508 2573 2709 2802 2952 2998 3338 3473 3382 3366 3262 3082 2845 2707 2595 2515 2648 2653 2789 2684 2986 2978 3188 3127 3130 2986 2786 2791 2630 2578 2480 2579 2699 2761 2835 3038 3187 3218 3415 3214 3204 2939 2868 2629 2654 2515 2459 2488 2415 2584 2600 2781 2742 2661 2830 2667 2666 2548 2387 2309 2226 2214 2159 2199 2126 2197 2128 2214 2126 2132 2115 2108 2182 2055 2093 2264 2219 2286 2279 2409 2565 2652 2592 2650 2506 2485 2368 2135 2270 2327 2286 2438 2462 2698 2706 2890 3023 2931 2874 2874 2609 2593 2432 2412 2478 2370 2309 2312 2298 2314 2318 2409 2369 2334 2376 2345 2294 2197 2230 2252 2259 2249 2080 2217 2185 2253 2094 2237 2188 2299 2397 2412 2350 2375 2332 2462 2284 2319 2276 2225 2118 2138 2090 2115 2171 2061 2071 2146 2131 2099 2105 2061 1986 1994 2002 1967 1981 1857 1856 1896 1832 1864 1785 1844 1842 1752 1889 1801 1808 1807 1804 1849 1884 1892 1801 1792 1852 1767 1854 1888 1792 1802 1802 1866 1995 1885 1871 1927 2050 1964 1956 2115 2121 2159 2331 2323 2443 2415 2471 2464 2639 2367 2473 2320 2180 2244 2179 2171 2181 2188 2269 2260 2339 2342 2392 2388 2301 2360 2246 2103 2168 2024 2070 1886 1993 2050 2015 1991 2055 1888 1976 1847 1894 1912 1879 1870 1764 1848 1805 1866 1825 1886 1838 1911 1857 1814 1899 1883 1884 1888 1840 1891 1836 1813 1784 1875 1767 1913 1894 1828 1886 1769 1817 1887 1907 1867 1963 1945 1869 1835 1801 1811 1818 1818 1814 1802 1795 1755 1820 1758 1797 1751 1714 1811 1767 1812 1810 1728 1794 1744 1756 1798 1681 1828 1667 1705 1752 1732 1767 1756 1764 1855 1694 1793 1787 1765 1728 1818 1736 1692 1768 1720 1802 1689 1724 1745 1742 1744 1672 1779 1745 1745 1748 1751 1815 1675 1742 1679 1786 1691 1728 1743 1715 1787 1789 1756 1803 1793 1711 1728 1734 1810 1857 1764 1726 1837 1828 1842 1801 1890 1883 1828 1837 1864 1825 1889 1853 1821 1859 1986 2045 2120 2032 2082 2126 2229 2189 2251 2111 2089 2036 2033 2112 2104 2079 2078 2107 2118 2190 2192 2164 2305 2319 2328 2306 2417 2462 2551 2636 2713 2755 2984 3042 3154 3258 3330 3455 3400 3227 3112 3126 2959 2799 2924 2816 2704 2633 2876 2815 2959 2876 2928 2959 3100 3073 3050 2986 3133 3131 3120 3152 3173 3370 3263 3274 3284 3086 3076 3006 2898 2814 2771 2648 2554 2617 2647 2652 2682 2758 2872 2913 2785 2870 2933 2807 2846 2865 2773 2741 2740 2618 2428 2365 2271 2153 2170 2128 2099 2124 2102 2019 2109 2145 2171 2174 2095 2234 2084 2058 2036 2036 1973 1985 1997 2033 2014 1978 2135 2113 2012 1953 2032 1857 1873 1935 1860 1908 1863 1908 1938 1964 2079 2146 2187 2300 2425 2561 2552 2629 2628 2647 2589 2602 2574 2656 2707 2853 2856 2844 2908 2882 2883 3059 2908 2967 2963 2886 2832 2842 2741 2706 2548 2542 2579 2573 2400 2448 2456 2363 2337 2300 2291 2263 2266 2193 2119 2110 2017 2023 2003 1986 2045 1971 1858 1893 1737 1851 1842 1999 2019 1961 2000 1946 1962 2094 2075 2021 2003 2030 2016 2065 2039 1929 1892 1873 1854 1996 1884 1931 1924 1915 1929 2080 1998 1927 1935 1832 1950 1811 1957 1915 1890 1835 1996 1868 1894 1900 1871 1930 1950 1992 2101 2167 2283 2322 2377 2292 2230 2129 2068 1947 1858 1815 1765 1910 1855 1825 1883 1920 1989 1934 1931 2032 1973 2013 1874 1909 1906 1858 1806 1731 1796 1689 1782 1733 1737 1683 1681 1669 1626 1704 1711 1688 1633 1666 1737 1631 1644 1649 1664 1669 1733 1694 1664 1711 1702 1750 1806 1844 1868 1901 1950 1952 2183 2200 2421 2455 2512 2601 2529 2488 2379 2168 2091 1987 1936 1987 1960 1904 1922 1964 1994 2087 2172 2247 2302 2411 2279 2372 2220 2133 2113 2040 2011 1893 1897 1927 1930 2020 1966 2148 2106 2034 1984 2025 1943 1898 1855 1945 1905 1887 1855 1761 1887 1767 1790 1722 1775 1767 1896 1870 1856 1753 1824 1896 1760 1733 1723 1695 1755 1797 1786 1871 1915 1859 1875 1873 1829 1804 1792 1828 1823 1672 1764 1675 1761 1790 1783 1755 1752 1700 1881 1782 1849 1905 1774 1861 1814 1964 1965 1935 2000 2000 2104 2019 2066 2112 2221 2234 2218 2176 2076 2138 2045 2079 2098 2107 2113 2157 2173 2275 2351 2426 2443 2351 2237 2187 2205 2169 2078 2167 2074 2130 2107 2179 2268 2286 2338 2414 2535 2624 2647 2659 2504 2474 2440 2154 2255 2123 2040 1919 1954 2019 1911 2053 2080 2086 2021 2049 2149 2011 1985 1985 1957 1922 1947 1823 1815 1820 1814 1709 1788 1702 1766 1775 1695 1781 1743 1782 1859 1783 1786 1664 1730 1790 1698 1756 1755 1718 1708 1698 1765 1706 1812 1805 1868 1803 1825 1846 1821 1721 1783 1720 1782 1692 1725 1710 1672 1749 1655 1775 1866 1801 1831 1849 1935 1958 2027 2050 1983 2020 1964 1915 2111 1992 1900 1860 1863 1934 1894 1872 1895 1932 2016 1957 1964 1960 1938 1953 1967 2021 2010 1958 1996 1944 1992 1891 1892 1927 1914 2006 1844 1958 1952 1970 2047 2062 2130 2164 2178 2146 2227 2382 2474 2557 2683 2835 2907 3125 3451 3492 3267 3258 3230 2971 2902 2800 2837 2578 2540 2490 2479 2430 2345 2461 2488 2505 2513 2468 2597 2552 2507 2372 2410 2346 2292 2160 2098 2124 2067 1995 1933 1920 1831 1919 1754 1760 1774 1839 1744 1782 1737 1752 1789 1813 1693 1871 1762 1906 1862 1858 1904 1945 1959 2011 2080 2097 2214 2151 2160 2130 2046 1907 1947 1833 1898 1925 1870 1850 1877 1914 1862 1958 2018 2020 2125 2123 2122 2111 2121 2181 2390 2290 2484 2329 2336 2321 2322 2252 2124 2022 2006 1927 1910 1977 1876 1932 1912 1905 1976 2057 2026 2009 2037 1924 2027 1933 2027 1951 1911 1831 1794 1822 1865 1772 1828 1693 1740 1721 1799 1772 1781 1664 1670 1658 1655 1670 1662 1648 1658 1697 1636 1734 1667 1669 1619 1618 1682 1641 1652 1629 1605 1582 1638 1536 1620 1659 1691 1549 1669 1632 1638 1596 1655 1624 1679 1575 1629 1676 1633 1560 1617 1600 1599 1577 1574 1650 1649 1662 1512 1580 1621 1624 1601 1584 1539 1597 1686 1579 1687 1676 1717 1694 1692 1724 1775 1877 1861 1863 1764 1775 1728 1788 1762 1725 1737 1737 1719 1739 1668 1705 1736 1764 1796 1728 1827 1849 1889 1892 1919 1959 1866 1949 2017 1981 2074 2070 2124 2091 2138 2045 2000 2032 2076 1976 1981 1950 1935 1929 1960 1856 1992 1951 2008 2091 2086 2149 2218 2307 2308 2339 2365 2316 2229 2109 2064 1994 1970 1818 1856 1825 1766 1862 1774 1779 1780 1896 1880 1955 1926 1995 2046 1927 2008 1957 1898 1902 1944 2045 2007 2175 2197 2249 2391 2385 2409 2243 2246 2067 2024 1939 1875 1958 1774 1839 1855 1790 1832 1891 1929 1929 1889 2010 2058 2130 2027 2024 1930 1974 1933 1942 1849 1755 1790 1811 1885 1769 1712 1775 1777 1688 1757 1739 1782 1695 1756 1834 1882 1858 1978 1914 1983 1926 1938 1976 1982 1901 1928 1929 1838 1813 1851 1844 1919 1878 1890 1909 1955 1867 1916 1913 1935 1886 1945 1933 1834 1797 1885 1825 1743 1741 1722 1791 1781 1785 1852 1743 1780 1793 1787 1706 1720 1821 1757 1784 1750 1748 1751 1643 1800 1702 1747 1700 1666 1750 1715 1658 1718 1704 1733 1605 1646 1647 1622 1688 1631 1735 1675 1668 1738 1707 1660 1691 1682 1669 1580 1655 1620 1701 1701 1673 1625 1685 1682 1670 1737 1702 1774 1638 1655 1680 1644 1570 1662 1689 1705 1652 1622 1623 1704 1691 1673 1651 1725 1697 1632 1727 1692 1798 1765 1754 1662 1787 1790 1733 1726 1742 1628 1698 1720 1753 1670 1692 1765 1818 1780 1689 1724 1859 1760 1829 1795 1714 1829 1787 1757 1740 1782 1782 1758 1762 1849 1841 1822 1759 1803 1755 1801 1842 1833 1774 1731 1753 1730 1660 1719 1755 1777 1670 1722 1703 1757 1649 1708 1679 1745 1648 1690 1659 1602 1663 1640 1704 1600 1702 1651 1661 1723 1653 1717 1645 1620 1651 1724 1712 1654 1696 1644 1738 1759 1727 1667 1667 1733 1784 1761 1736 1799 1912 1775 1880 1986 2009 2104 2096 2108 2094 2045 1980 1937 2045 1939 2058 2020 2120 2133 2176 2251 2175 2199 2184 2204 2087 2123 2081 2101 2121 2055 2072 1999 2051 2060 2153 2122 2138 2183 2177 2242 2377 2300 2290 2271 2333 2230 2370 2357 2375 2416 2399 2377 2255 2346 2241 2211 2208 2105 2167 2100 2091 2021 2063 2118 2038 2049 2049 1976 2108 2092 2070 2072 2069 2036 1976 2037 2007 1911 1914 1965 1982 1940 1842 1885 1794 1859 1741 1834 1791 1778 1850 1787 1884 1800 1767 1778 1832 1820 1821 1788 1703 1759 1741 1856 1730 1757 1744 1755 1711 1814 1774 1746 1781 1731 1763 1764 1816 1749 1781 1771 1731 1821 1746 1808 1844 1842 1895 1919 1826 1845 1853 1929 1911 1955 1877 1935 1824 1870 1928 1932 1923 1860 1943 2019 2058 2073 1995 2133 2109 2225 2186 2202 2167 2058 2031 2000 1913 1937 1905 1941 1935 1951 1851 1915 1914 2068 1901 2030 2044 2009 1964 2087 2052 2017 1957 1928 1878 1841 1770 1790 1824 1736 1664 1727 1780 1891 1718 1799 1836 1806 1795 1860 1870 1933 2032 2103 2107 2107 2179 2216 2337 2293 2282 2327 2223 2186 2180 2029 2019 1935 1977 1923 1910 1784 1854 1812 1871 1826 1841 1865 1970 1895 2004 2033 2018 1930 1869 1855 1882 1841 1873 1757 1852 1869 1707 1920 1791 1889 1895 1909 1979 2061 2060 2166 2326 2285 2271 2253 2271 2151 2176 2112 1951 1939 1880 1900 1816 1930 1842 1972 1900 1939 2042 2060 2128 2229 2315 2299 2265 2369 2350 2306 2368 2200 2292 2151 2062 2167 2094 2046 2000 2027 2010 2003 2109 2198 2247 2307 2364 2507 2557 2450 2530 2399 2377 2433 2342 2397 2204 2296 2270 2189 2147 2075 1995 2090 2073 2160 2274 2226 2305 2298 2254 2201 2160 2091 2043 2040 2022 1975 1833 1923 1868 1844 1823 1815 1869 1839 1815 1799 1794 1865 1852 1843 1894 1713 1810 1761 1706 1686 1592 1642 1634 1675 1577 1700 1648 1687 1728 1654 1592 1644 1679 1677 1614 1666 1609 1659 1686 1677 1626 1586 1652 1750 1635 1684 1619 1654 1619 1675 1613 1684 1661 1636 1646 1635 1640 1718 1715 1640 1701 1696 1750 1725 1702 1765 1867 1899 1846 1905 2055 2029 1936 1950 1965 1855 1747 1826 1765 1740 1803 1747 1674 1703 1708 1713 1760 1773 1827 1741 1765 1844 1862 1964 1843 1908 1866 1812 1801 1791 1874 1741 1782 1749 1651 1706 1756 1710 1756 1688 1693 1715 1720 1702 1748 1718 1730 1635 1740 1704 1747 1696 1710 1718 1660 1656 1637 1708 1695 1675 1757 1689 1665 1691 1814 1695 1819 1804 1744 1748 1744 1763 1787 1866 1914 1988 1983 2116 2234 2253 2414 2450 2567 2563 2766 2697 2794 2739 2566 2434 2228 2114 2048 2101 1943 1847 1944 1885 1862 1912 2003 2020 2101 2058 2061 2162 2251 2237 2262 2195 2153 2173 2178 2077 1957 1934 1848 1835 1806 1797 1790 1791 1788 1801 1808 1822 1721 1837 1753 1755 1769 1713 1733 1647 1714 1705 1762 1717 1687 1729 1686 1710 1661 1714 1696 1731 1757 1732 1692 1856 1835 1895 1822 1877 1945 2018 2056 2058 2147 2021 2070 2030 1955 1916 1853 1940 1937 1874 1942 1779 1817 1907 1829 1897 1835 1928 1835 1965 1854 1858 1942 1841 1883 1888 1945 1889 1831 1855 1850 1852 1852 1784 1835 1774 1801 1771 1701 1749 1726 1704 1734 1785 1700 1737 1705 1721 1785 1731 1768 1639 1687 1678 1692 1761 1726 1707 1682 1707 1734 1729 1720 1719 1735 1745 1758 1880 1847 1867 1932 1824 1885 1879 1901 1803 1822 1757 1761 1805 1777 1860 1796 1731 1767 1767 1808 1820 1708 1824 1840 1795 1847 1904 1784 1860 1836 1786 1857 1839 1867 1895 1823 1821 1841 1906 1959 1964 1949 2054 2086 2119 2204 2416 2336 2468 2379 2374 2286 2255 2185 2102 2088 1979 1943 1893 1857 1808 1821 1839 1843 1885 1792 1901 1932 1973 1952 1996 2049 2039 2113 2045 1983 1998 1945 1856 1826 1779 1819 1818 1690 1737 1676 1666 1714 1691 1716 1663 1661 1700 1693 1725 1719 1627 1718 1797 1767 1755 1726 1737 1844 1855 1906 1941 1967 1979 1946 1914 1962 1981 2087 1932 2003 1937 1886 1913 1905 1876 1745 1788 1788 1790 1744 1757 1750 1738 1757 1868 1792 1759 1866 1842 1756 1825 1796 1766 1856 1792 1807 1774 1748 1781 1710 1740 1638 1749 1724 1719 1701 1677 1662 1790 1749 1625 1713 1662 1729 1692 1652 1720 1663 1782 1721 1714 1774 1725 1765 1813 1730 1706 1642 1678 1663 1615 1619 1659 1635 1648 1638 1641 1662 1645 1562 1676 1622 1678 1711 1646 1689 1596 1677 1651 1602 1588 1704 1633 1652 1563 1649 1703 1606 1610 1622 1641 1637 1696 1566 1663 1623 1617 1568 1662 1634 1637 1647 1673 1670 1636 1698 1642 1766 1692 1734 1656 1696 1662 1676 1778 1683 1752 1616 1697 1657 1719 1666 1829 1723 1675 1650 1721 1651 1722 1754 1798 1768 1879 1918 2032 2082 2191 2143 2237 2371 2322 2362 2341 2289 2153 2147 2132 2087 2005 2004 1874 1978 1983 1917 1864 1862 1889 1860 1998 1864 2021 1901 2042 2078 2196 2215 2267 2286 2325 2356 2177 2159 2241 2179 2177 2181 2063 2032 1901 1855 1822 1722 1840 1683 1803 1749 1740 1770 1776 1766 1872 1794 1794 1853 1859 1896 1943 1831 1829 1815 1913 1804 1801 1809 1785 1898 1785 1729 1669 1777 1709 1723 1688 1721 1627 1703 1769 1773 1707 1711 1749 1783 1815 1730 1779 1777 1795 1686 1845 1722 1686 1726 1684 1762 1865 1880 1886 1891 1991 1940 2129 2164 2308 2204 2335 2148 2161 2170 2039 2024 1952 1916 1930 1936 1911 1961 2015 1911 1937 1985 2019 2000 2122 2065 2054 2026 2024 2029 2154 2053 2168 2109 2030 1938 2049 1999 1993 1971 1912 1927 1990 1914 1951 1853 2031 1990 1995 1989 1954 1988 2052 2104 2014 2074 2061 2034 2166 2148 2044 2102 2190 2193 2265 2309 2334 2410 2419 2480 2473 2381 2364 2232 2255 2130 2232 2094 2134 2045 2079 2173 2161 2113 2166 2136 2177 2283 2190 2206 2292 2373 2353 2322 2307 2253 2222 2198 2167 2115 2050 2077 1927 2040 2073 1979 2004 2053 1917 1958 2039 2012 2036 2002 2027 2001 1950 1940 1890 2006 1948 1934 1996 1900 1966 1922 1899 1897 1844 1877 1936 1876 1871 1799 1811 1809 1757 1890 1780 1779 1812 1634 1719 1792 1777 1694 1707 1756 1731 1757 1807 1819 1753 1756 1769 1768 1802 1774 1734 1782 1708 1797 1784 1773 1760 1763 1743 1742 1783 1853 1766 1772 1721 1848 1776 1803 1829 1899 1942 1849 1931 1971 1825 1928 1929 2045 1976 1942 1947 2047 2003 2076 1983 2032 2121 2081 2036 1900 1994 2025 2020 1925 1923 1974 1915 1957 1968 1972 1926 1992 1950 2063 2117 2036 2017 2022 2022 2079 2148 2167 2115 2194 2208 2172 2005 2058 1983 1888 1915 1865 1810 1823 1892 1926 1881 1918 1867 1886 1881 1769 1784 1789 1759 1866 1869 1866 1784 1803 1864 1857 1832 1855 1675 1791 1801 1747 1737 1732 1822 1782 1834 1845 1812 1878 2013 1896 1938 1830 1946 1871 1860 1844 1808 1865 1772 1722 1794 1649 1742 1700 1670 1715 1722 1680 1712 1780 1599 1748 1663 1778 1769 1837 1858 1710 1847 1743 1802 1713 1683 1744 1696 1690 1675 1638 1736 1666 1628 1630 1735 1644 1636 1671 1657 1631 1654 1754 1665 1705 1604 1689 1602 1699 1659 1731 1619 1685 1654 1652 1678 1715 1742 1800 1807 1768 1772 1800 1858 1902 1993 1991 1944 1865 1918 1946 1897 1853 1875 1875 1857 1976 1883 1843 1815 1861 1856 1809 1728 1749 1743 1782 1743 1712 1879 1760 1789 1811 1788 1814 1740 1831 1765 1751 1783 1736 1714 1755 1880 1743 1791 1739 1794 1778 1772 1780 1704 1687 1721 1725 1762 1711 1812 1765 1749 1890 1922 1910 1956 2054 2042 2004 2036 2005 1873 2006 1916 2030 1944 1903 1984 1920 1934 1879 1855 1843 1802 1762 1898 1838 1960 1919 1978 1930 2023 1971 2005 2059 2041 2028 2108 2158 2129 2148 1951 2029 2020 1961 1943 1945 1915 1885 1904 1868 1787 1800 1845 1853 1786 1796 1827 1862 1861 1797 1747 1768 1754 1788 1761 1812 1759 1781 1806 1778 1798 1769 1727 1790 1792 1761 1706 1689 1650 1638 1682 1676 1745 1742 1780 1749 1744 1734 1845 1869 1870 1773 1805 1817 1870 1877 1869 1886 1857 1809 1899 1834 1762 1744 1762 1748 1770 1802 1816 1749 1865 1863 1848 1853 1961 1731 1898 1809 1908 1884 1809 1869 1827 1785 1835 1888 1851 1877 1831 1797 1702 1810 1840 1775 1698 1717 1693 1711 1723 1754 1770 1809 1690 1722 1736 1746 1791 1800 1780 1792 1872 1905 1985 2054 2138 2097 1999 2067 2066 2081 1983 1980 1907 1967 1892 1882 1857 1867 1901 1920 1892 1860 1894 1884 1776 1945 1869 1810 1952 1836 1888 1882 1918 1956 1963 1879 1869 1882 1863 1796 1778 1865 1824 2012 1884 1945 1867 1933 1932 2006 1988 1971 1918 1854 1841 1830 1895 1782 1775 1783 1801 1689 1759 1777 1641 1689 1680 1730 1703 1658 1675 1642 1660 1635 1652 1737 1714 1677 1664 1661 1762 1741 1774 1679 1655 1688 1653 1604 1676 1701 1663 1531 1561 1665 1595 1614 1680 1576 1624 1646 1596 1512 1614 1634 1610 1640 1629 1685 1661 1631 1694 1706 1703 1741 1684 1752 1748 1588 1742 1676 1778 1707 1759 1714 1745 1747 1707 1731 1709 1710 1670 1695 1665 1722 1617 1742 1639 1677 1638 1634 1689 1743 1724 1710 1702 1814 1628 1733 1731 1773 1821 1825 1745 1750 1670 1709 1706 1770 1666 1784 1732 1740 1761 1765 1761 1770 1738 1767 1766 1721 1709 1586 1699 1770 1783 1724 1807 1755 1796 1761 1823 1829 1820 1811 1711 1757 1826 1766 1829 1843 1829 1815 1831 1895 1786 1928 1892 1935 1969 2006 2038 1934 1992 2075 2040 1987 2041 2006 2078 2108 2085 2101 2038 2062 1988 2005 2023 2021 1921 1941 1929 1891 1933 1926 1852 1859 1908 1950 1920 2017 1938 1891 1937 1790 1897 1941 1903 1941 1923 1999 1980 1898 1911 1909 1960 2036 1936 1916 2010 1976 1902 1963 2010 2042 1883 1920 1864 1917 1877 1860 1907 1769 1829 1753 1777 1779 1803 1756 1823 1815 1789 1770 1846 1862 1878 1957 1871 1829 2055 1889 1889 1835 1952 1975 1859 1823 1799 1859 1912 1766 1812 1779 1793 1845 1815 1770 1785 1802 1840 1837 1780 1825 1873 1870 1849 1869 1903 1945 1865 1864 1875 1910 2050 1869 1982 2000 1936 1859 1918 1938 1936 1941 1961 1851 1839 1850 1905 1857 1874 1763 1798 1818 1841 1855 1762 1811 1810 1851 1863 1805 1861 1736 1781 1773 1726 1856 1756 1762 1780 1708 1687 1725 1701 1733 1691 1761 1679 1762 1713 1816 1740 1703 1714 1703 1675 1671 1661 1712 1630 1729 1697 1673 1678 1605 1673 1631 1678 1605 1662 1684 1607 1757 1627 1588 1716 1686 1650 1650 1744 1662 1679 1728 1647 1695 1691 1687 1714 1664 1704 1713 1625 1699 1663 1689 1745 1752 1767 1773 1908 1861 1833 1881 1893 1870 1922 1916 1878 1921 1800 1868 1798 1739 1850 1778 1794 1797 1723 1658 1737 1760 1787 1688 1690 1741 1758 1750 1777 1646 1771 1752 1790 1782 1798 1862 1795 1842 1781 1731 1738 1692 1667 1708 1763 1642 1713 1722 1694 1726 1728 1748 1673 1742 1643 1692 1656 1685 1707 1681 1624 1598 1664 1644 1689 1671 1640 1699 1654 1728 1795 1652 1826 1723 1791 1639 1655 1719 1722 1765 1651 1715 1746 1769 1731 1774 1710 1716 1735 1677 1705 1800 1764 1750 1720 1743 1713 1728 1732 1759 1828 1732 1773 1749 1897 1790 1767 1828 1837 1900 1861 1886 1903 1948 1896 1958 1919 1957 2045 2015 2079 2100 1980 2124 2126 2064 2118 2163 2112 2008 2035 2093 2184 2069 2159 2145 2102 2144 2069 2159 2140 2050 2158 2103 2066 2080 2178 2109 2170 2103 2140 2130 2050 2177 2179 2145 2184 2125 2169 2146 2143 2138 2059 2023 2152 2131 2101 2120 2136 2171 2223 2225 2154 2149 2142 2135 2041 1985 2085 2087 2051 2149 1936 2032 1873 1985 2032 1893 2050 1894 1944 1955 1962 1924 2040 1978 2083 2071 2099 2046 2031 2170 2331</counts>
			</dataPoints>
		</scan>
	</xrdMeasurement>
</xrdMeasurements>