File: dataset/precursor_mixture/GeO2_Nb2O5_In2O3_K2SO4.2-min.xrdml
<?xml version="1.0"?>
<xrdMeasurements xmlns="http://www.xrdml.com/XRDMeasurement/2.2" xmlns:xsi="http://www.w3.org/2001/XMLSchema-instance" xsi:schemaLocation="http://www.xrdml.com/XRDMeasurement/2.2 http://www.xrdml.com/XRDMeasurement/2.2/XRDMeasurement.xsd" status="Completed" recordIdentifier="{63A19ECF-B17B-4779-918C-E9336444F46F}">
	<comment>
		<entry/>
	</comment>
	<sample type="To be analyzed">
		<id>dara-37-1</id>
		<name></name>
		<preparedBy></preparedBy>
	</sample>
	<xrdMeasurement measurementType="Scan" status="Completed" sampleMode="Reflection">
		<usedWavelength intended="K-Alpha 1">
			<kAlpha1 unit="Angstrom">1.5405980</kAlpha1>
			<kAlpha2 unit="Angstrom">1.5444260</kAlpha2>
			<kBeta unit="Angstrom">1.3922500</kBeta>
			<ratioKAlpha2KAlpha1>0.5000</ratioKAlpha2KAlpha1>
		</usedWavelength>
		<incidentBeamPath>
			<radius unit="mm">145.00</radius>
			<xRayTube id="1010048" name="Empyrean Cu LFF HR (9430 033 7310x) DK430614">
				<tension unit="kV">40.0</tension>
				<current unit="mA">15.0</current>
				<anodeMaterial>Cu</anodeMaterial>
				<focus type="Line">
					<length unit="mm">12.0</length>
					<width unit="mm">0.4</width>
					<takeOffAngle unit="deg">6.0</takeOffAngle>
				</focus>
			</xRayTube>
			<filter id="20010004" name="Beta-filter Nickel">
				<material>Ni</material>
				<thickness unit="mm">0.020</thickness>
			</filter>
			<sollerSlit id="21010002" name="Soller slits 0.04 rad.">
				<opening unit="rad">0.0400</opening>
			</sollerSlit>
			<mask id="22031000" name="Fixed mask 13 mm">
				<width unit="mm">9.00</width>
			</mask>
			<divergenceSlit id="22120001" name="Divergence slit 1°" xsi:type="fixedDivergenceSlitType">
				<distanceToSample unit="mm">50.00</distanceToSample>
				<height unit="mm">1.52</height>
			</divergenceSlit>
		</incidentBeamPath>
		<beamKnife id="29030100" name="Beam knife low"/>
		<sampleMovement xsi:type="spinningSampleMovementType">
			<spinnerRevolutionTime unit="seconds">1.0</spinnerRevolutionTime>
		</sampleMovement>
		<diffractedBeamPath>
			<radius unit="mm">145.00</radius>
			<antiScatterSlit id="22090040" name="AS slit 9 mm" xsi:type="fixedAntiScatterSlitType">
				<height unit="mm">9.00</height>
			</antiScatterSlit>
			<sollerSlit id="21020003" name="Large Soller slits 0.04 rad.">
				<opening unit="rad">0.0400</opening>
			</sollerSlit>
			<filter id="20030001" name="Large beta-filter Nickel">
				<material>Ni</material>
				<thickness unit="mm">0.020</thickness>
			</filter>
			<detector id="7010019" name="PIXcel1D-Medipix3 detector" xsi:type="rtmsDetectorType">
				<phd unit="keV">
					<lowerLevel>4.0</lowerLevel>
					<upperLevel>11.3</upperLevel>
				</phd>
				<mode>Scanning</mode>
				<activeLength unit="deg">1.021</activeLength>
			</detector>
		</diffractedBeamPath>
		<scan appendNumber="0" mode="Continuous" scanAxis="Gonio" status="Completed">
			<header>
				<startTimeStamp>2024-02-18T12:13:18-08:00</startTimeStamp>
				<endTimeStamp>2024-02-18T12:15:40-08:00</endTimeStamp>
				<author>
					<name>AutomatedUser</name>
				</author>
				<source>
					<applicationSoftware version="1.4b (28)">PANalytical Aeris Instrument Suite</applicationSoftware>
					<instrumentControlSoftware version="2.0.0 20210224">AERIS</instrumentControlSoftware>
					<instrumentID>950485</instrumentID>
				</source>
			</header>
			<dataPoints>
				<positions axis="2Theta" unit="deg">
					<startPosition>10.02173288</startPosition>
					<endPosition>139.98435528</endPosition>
				</positions>
				<positions axis="Omega" unit="deg">
					<startPosition>5.01086644</startPosition>
					<endPosition>69.99217764</endPosition>
				</positions>
				<commonCountingTime unit="seconds">1.551</commonCountingTime>
				<counts unit="counts">346 346 373 403 366 360 373 381 372 358 359 341 372 351 357 314 348 352 320 336 325 363 305 347 360 314 330 326 300 303 308 335 325 318 310 314 301 313 337 298 280 307 287 302 288 317 286 281 267 297 283 278 251 277 299 272 288 295 277 269 278 267 288 260 297 317 263 265 279 303 266 270 286 271 293 237 265 240 244 253 227 232 259 236 303 268 267 281 260 270 266 228 277 248 240 253 232 254 217 232 242 254 252 264 245 236 283 251 222 226 261 265 231 231 222 216 230 256 237 256 219 215 203 245 236 234 259 208 201 217 208 197 222 216 210 199 219 207 222 232 218 220 200 221 223 190 227 202 220 172 214 210 213 219 207 224 208 219 257 229 214 219 194 201 177 200 175 211 223 207 261 250 233 251 215 203 187 220 224 192 215 208 173 167 195 163 206 168 197 192 182 159 204 204 176 204 190 202 203 167 184 193 166 216 178 204 189 189 190 219 186 196 180 186 169 197 180 174 189 201 161 200 175 185 171 222 163 211 203 185 231 209 225 286 308 367 533 617 454 321 250 228 199 181 181 180 163 178 198 200 185 215 283 303 301 340 360 395 530 418 304 200 158 181 211 172 170 178 183 170 198 207 180 183 217 207 169 224 229 262 358 537 902 1246 1050 657 352 271 224 189 186 169 181 189 161 160 202 182 182 171 163 172 205 177 160 189 150 192 221 258 316 249 180 177 148 177 177 159 153 142 131 194 176 173 133 140 151 163 169 172 167 170 157 178 157 168 173 146 119 170 192 159 168 207 189 177 214 208 231 270 271 256 277 337 426 618 883 1563 2450 2336 1576 836 460 339 255 297 258 236 238 201 191 179 158 186 176 161 146 126 170 165 180 167 171 181 151 163 168 180 185 156 152 141 147 168 175 172 154 172 144 163 147 172 184 162 182 161 221 221 284 347 524 830 1100 1014 750 441 270 252 208 188 192 185 217 262 315 446 556 482 330 224 236 221 221 179 176 153 116 155 156 156 175 215 212 285 351 395 311 256 192 166 195 173 194 179 201 223 190 253 292 387 665 1167 2322 3273 2241 1744 854 895 797 631 424 387 379 283 210 214 169 160 147 150 139 159 140 112 149 144 137 139 121 141 145 141 152 152 145 141 125 114 143 149 147 152 116 121 115 111 133 104 129 128 132 127 177 130 110 148 140 137 161 170 173 151 139 130 127 110 122 135 118 131 115 137 116 136 132 128 99 106 110 110 132 138 130 97 128 133 137 138 128 127 119 136 142 142 144 116 133 109 121 106 138 139 122 128 130 123 135 146 155 203 270 483 830 953 666 571 424 286 239 248 208 243 243 340 365 355 321 221 156 152 162 141 147 187 216 289 370 472 410 336 273 217 187 130 161 171 199 231 323 330 354 268 207 185 142 133 141 132 151 132 137 166 252 290 248 235 221 219 251 394 560 460 397 319 215 171 162 147 135 112 124 121 135 103 129 115 121 133 117 108 113 93 115 96 113 120 138 131 138 135 191 214 358 371 288 232 202 152 157 134 127 144 119 153 140 123 112 99 110 108 110 95 134 128 148 134 121 132 119 96 127 119 120 117 122 128 122 126 99 101 85 86 100 103 129 109 99 125 113 106 128 153 190 270 384 498 513 421 343 246 178 150 111 129 122 104 109 128 147 121 113 126 137 143 141 143 117 120 87 97 107 99 152 151 119 111 121 123 159 201 145 165 148 198 141 169 110 119 100 111 104 106 122 118 118 106 89 92 102 105 100 118 108 105 90 93 99 122 117 105 90 122 112 121 152 149 162 154 152 174 139 145 169 115 132 116 109 126 92 107 120 198 314 325 237 208 216 120 147 131 140 177 275 298 219 225 184 170 145 99 102 91 115 110 119 105 119 108 100 101 103 109 98 105 104 118 82 104 102 92 83 100 89 104 104 99 94 88 103 122 120 116 91 112 115 116 115 136 128 124 195 213 174 159 149 141 154 181 235 286 315 264 265 256 174 121 120 116 119 132 157 127 156 167 170 168 153 148 150 119 113 122 133 134 196 203 186 178 160 143 117 119 99 93 89 111 119 125 114 118 107 135 125 137 135 135 173 167 213 250 358 535 1007 1187 715 667 635 337 202 162 113 147 145 143 116 125 116 107 115 93 107 82 93 105 118 103 90 97 112 95 84 104 110 91 92 94 102 93 113 114 152 178 113 147 137 135 138 152 132 161 130 137 124 142 183 195 152 188 164 134 151 107 107 114 101 83 102 116 116 116 109 109 125 91 112 97 123 110 121 105 105 84 139 119 157 115 125 115 115 122 159 228 261 266 251 207 232 202 191 215 206 231 201 210 160 166 122 92 113 115 146 128 125 157 220 217 155 156 221 152 141 203 198 177 234 209 152 171 137 132 97 118 128 98 94 108 84 116 91 107 82 108 95 97 129 107 96 111 131 123 129 108 92 101 111 111 97 95 86 86 101 88 100 96 104 99 96 104 121 109 119 164 149 190 199 223 234 315 369 343 249 246 239 251 203 246 198 153 170 169 131 123 117 102 119 90 103 101 96 106 108 113 103 113 121 127 115 106 105 115 109 109 107 120 141 139 167 179 321 634 770 484 321 400 375 215 184 144 113 101 96 116 99 98 112 97 120 108 127 98 113 148 173 133 143 118 158 112 134 114 116 138 159 208 215 174 147 170 145 121 112 88 107 106 95 117 108 87 93 92 102 91 89 92 94 111 98 93 113 102 103 106 136 99 148 137 191 265 245 169 176 172 143 129 106 99 123 158 150 141 99 111 123 97 115 100 134 107 92 114 101 83 108 122 120 111 142 131 130 158 161 160 141 127 146 115 114 135 110 122 128 144 179 249 241 193 171 211 213 253 286 269 258 232 241 187 148 163 123 133 115 114 119 116 134 117 110 129 126 133 162 211 229 225 195 144 146 161 123 129 125 115 137 119 105 89 86 87 108 102 105 81 94 106 112 162 152 129 111 133 129 112 111 107 95 79 76 87 93 83 86 93 95 110 93 99 96 81 90 88 92 96 89 103 85 94 127 129 126 112 114 109 98 97 83 111 125 116 137 148 211 189 154 139 193 179 152 126 117 110 105 95 86 76 88 81 94 87 95 71 92 91 103 120 128 171 141 124 132 103 137 102 100 109 95 77 82 99 95 99 82 72 76 111 103 100 100 69 97 81 99 97 92 104 101 90 97 94 98 87 82 86 91 84 94 91 69 98 88 110 86 91 72 68 105 114 81 107 87 80 112 127 166 133 158 180 149 149 149 101 136 125 107 89 103 82 89 95 79 91 109 95 84 83 90 94 77 81 77 94 105 115 136 154 160 124 119 113 96 128 99 111 117 102 84 104 79 110 93 65 106 96 107 110 105 69 72 91 113 105 116 134 152 155 167 159 115 112 112 130 134 91 92 104 99 93 84 108 106 89 96 107 123 120 124 116 115 137 137 142 127 168 144 146 151 167 142 150 139 125 127 101 89 106 74 82 95 79 87 93 123 121 87 98 126 85 101 121 111 105 116 119 85 104 138 151 126 97 96 119 106 99 123 110 83 109 99 88 87 90 116 94 88 92 116 134 141 139 114 113 126 115 128 135 123 113 112 107 88 91 85 118 116 84 115 92 95 86 81 99 90 71 71 84 90 80 104 107 116 95 92 90 106 111 144 161 141 102 98 99 125 131 148 112 116 95 96 87 115 81 76 91 97 78 68 88 67 54 92 98 78 96 109 105 122 196 219 202 144 114 120 157 156 113 115 101 93 92 81 105 86 82 113 99 74 92 82 106 89 90 107 77 82 86 96 85 100 96 109 122 109 109 115 94 96 106 90 108 103 79 79 94 86 105 110 77 91 89 74 73 80 78 88 85 126 158 160 144 102 118 119 134 119 136 116 88 82 77 102 81 98 87 93 101 86 75 90 73 92 80 100 92 69 95 92 112 88 99 108 81 76 101 90 100 82 69 72 75 71 72 72 79 85 73 109 93 84 70 88 85 79 100 75 99 71 90 110 119 118 113 80 94 98 106 104 94 97 93 94 81 78 81 73 73 77 83 92 77 105 96 84 98 112 114 103 121 110 131 125 94 69 99 116 88 95 85 82 109 87 70 79 91 64 69 76 95 97 98 99 81 93 91 68 83 87 82 90 84 91 83 72 85 96 81 81 73 83 53 62 76 77 66 94 85 83 92 80 91 87 98 125 119 110 123 122 137 138 119 119 108 120 110 122 120 109 111 94 72 99 119 106 93 95 83 82 93 95 90 82 84 89 83 85 79 73 64 75 102 75 67 105 84 70 106 79 84 79 85 80 68 69 85 94 86 94 69 66 109 78 91 105 105 89 104 104 120 108 121 92 99 98 109 130 111 112 84 119 92 114 92 95 85 92 107 103 78 77 75 79 98 112 81 101 105 136 140 148 136 114 107 99 95 167 126 109 106 110 103 100 105 73 97 103 90 77 114 78 95 77 86 96 76 81 91 113 127 146 107 93 95 99 103 121 109 113 98 95 75 86 72 80 125 101 107 78 103 77 86 92 71 91 95 100 91 135 126 164 140 130 133 118 118 117 128 116 140 159 120 111 114 110 101 81 101 101 85 96 79 99 83 83 91 103 80 103 100 99 96 79 101 90 78 62 76 90 71 61 74 84 85 89 84 81 79 92 82 109 73 87 89 100 67 91 89 105 152 157 160 115 94 107 93 111 121 120 122 94 79 72 70 76 69 84 74 68 76 71 78 74 80 51 75 77 84 75 102 90 85 103 108 91 86 68 93 103 100 91 85 87 117 100 90 78 71 80 90 86 97 87 93 102 89 94 91 116 118 119 156 175 155 121 107 108 112 114 104 118 130 113 98 94 83 69 82 88 78 86 96 94 68 88 66 74 72 79 102 90 97 120 141 108 106 94 78 78 90 86 102 106 108 88 94 78 94 79 69 105 93 95 76 83 79 96 70 59 72 99 74 72 79 77 67 91 91 72 71 87 71 87 68 72 61 82 69 78 99 93 94 97 94 93 77 75 67 73 78 82 83 93 79 107 115 149 119 107 102 107 80 99 82 107 114 68 102 96 113 87 104 77 102 83 76 84 87 111 104 108 86 83 105 98 116 117 161 117 108 119 113 105 107 108 100 132 131 127 129 106 126 112 115 113 118 102 103 102 128 91 106 101 112 113 106 121 107 128 140 122 128 94 104 111 92 102 143 138 117 112 115 94 120 93 109 97 92 112 102 107 109 94 91 96 84 90 112 83 84 113 133 109 106 104 104 87 100 113 99 100 106 97 109 112 111 77 92 71 87 85 85 84 85 86 82 108 93 112 93 94 100 85 135 131 121 124 115 87 88 88 85 107 114 131 103 101 102 81 77 79 67 80 71 83 113 104 105 82 73 81 76 97 75 71 71 77 82 87 81 99 93 69 86 92 67 93 82 90 79 94 89 84 93 109 67 98 80 105 82 80 96 55 78 82 78 107 112 95 115 107 121 138 101 98 97 100 108 110 99 116 96 84 87 86 85 97 79 77 90 77 81 88 89 84 69 88 79 100 89 93 106 105 113 95 110 118 95 97 105 88 81 82 97 107 115 97 80 107 87 100 100 101 88 73 122 86 113 87 90 75 99 91 116 85 77 87 122 74 80 93 100 97 78 75 106 80 83 89 77 102 80 85 65 74 80 101 92 82 93 105 102 93 88 112 91 88 96 93 83 101 116 102 110 106 75 104 95 110 90 93 86 81 90 112 115 115 97 98 97 82 59 83 99 92 82 103 112 91 98 100 85 109 100 110 84 103 97 101 125 131 126 105 87 84 88 80 111 95 100 72 113 100 100 81 75 86 86 90 93 74 80 78 102 99 110 102 88 82 72 86 91 91 80 95 97 100 103 109 100 89 77 89 105 72 78 101 84 78 112 89 108 82 92 78 90 91 91 96 106 106 91 129 125 97 105 88 101 101 111 109 98 121 93 114 118 108 93 87 105 121 108 100 99 105 86 119 128 85 100 95 97 95 99 109 79 114 87 88 78 107 113 105 101 122 110 124 111 116 133 167 141 135 103 111 113 113 97 97 94 129 121 89 128 121 95 94 91 76 97 101 95 89 76 75 91 114 77 101 91 77 75 97 88 93 95 93 101 94 99 114 98 99 91 86 102 97 98 81 80 91 105 74 103 98 92 104 92 86 106 83 77 92 104 95 91 90 84 102 88 104 98 109 87 76 130 115 112 126 121 119 112 102 102 112 87 97 85 96 101 108 107 98 117 93 108 108 76 101 89 91 88 101 89 107 79 77 90 100 82 93 104 89 79 91 100 98 106 125 114 120 119 111 95 87 93 101 82 97 80 97 103 114 126 104 121 106 96 78 107 82 100 89 66 80 91 100 98 97 114 92 73 102 116 97 106 93 106 110 116 136 152 133 118 105 106 121 91 112 108 108 86 107 111 114 127 111 113 132 103 110 100 93 92 93 107 108 109 102 95 84 93 94 110 91 114 74 98 112 97 119 115 108 132 116 118 109 118 115 101 92 105 78 80 95 79 91 110 111 82 89 119 115 80 112 111 79 121 87 111 107 102 98 102 100 102 77 106 107 111 117 115 94 78 101 116 120 136 132 123 138 121 141 119 141 122 92 95 89 98 109 112 102 124 102 120 101 109 101 122 115 112 104 94 127 92 105 137 72 111 78 124 98 102 102 83 78 87 110 105 90 88 124 114 109 93 108 99 97 118 84 97 121 103 110 95 115 89 113 123 117 116 90 113 111 115 126 96 113 99 111 103 123 91 113</counts>
			</dataPoints>
		</scan>
	</xrdMeasurement>
</xrdMeasurements>