File: dataset/precursor_mixture/GeO2_MnCO3_ZrO2_Bi2O3-alpha.2-min.xrdml
<?xml version="1.0"?>
<xrdMeasurements xmlns="http://www.xrdml.com/XRDMeasurement/2.2" xmlns:xsi="http://www.w3.org/2001/XMLSchema-instance" xsi:schemaLocation="http://www.xrdml.com/XRDMeasurement/2.2 http://www.xrdml.com/XRDMeasurement/2.2/XRDMeasurement.xsd" status="Completed" recordIdentifier="{D323CBBB-101E-4AD7-B09E-0547C8486C1B}">
	<comment>
		<entry/>
	</comment>
	<sample type="To be analyzed">
		<id>dara-25-1</id>
		<name></name>
		<preparedBy></preparedBy>
	</sample>
	<xrdMeasurement measurementType="Scan" status="Completed" sampleMode="Reflection">
		<usedWavelength intended="K-Alpha 1">
			<kAlpha1 unit="Angstrom">1.5405980</kAlpha1>
			<kAlpha2 unit="Angstrom">1.5444260</kAlpha2>
			<kBeta unit="Angstrom">1.3922500</kBeta>
			<ratioKAlpha2KAlpha1>0.5000</ratioKAlpha2KAlpha1>
		</usedWavelength>
		<incidentBeamPath>
			<radius unit="mm">145.00</radius>
			<xRayTube id="1010048" name="Empyrean Cu LFF HR (9430 033 7310x) DK437873">
				<tension unit="kV">40.0</tension>
				<current unit="mA">15.0</current>
				<anodeMaterial>Cu</anodeMaterial>
				<focus type="Line">
					<length unit="mm">12.0</length>
					<width unit="mm">0.4</width>
					<takeOffAngle unit="deg">6.0</takeOffAngle>
				</focus>
			</xRayTube>
			<filter id="20010004" name="Beta-filter Nickel">
				<material>Ni</material>
				<thickness unit="mm">0.020</thickness>
			</filter>
			<sollerSlit id="21010002" name="Soller slits 0.04 rad.">
				<opening unit="rad">0.0400</opening>
			</sollerSlit>
			<mask id="22031000" name="Fixed mask 13 mm">
				<width unit="mm">9.00</width>
			</mask>
			<divergenceSlit id="22120001" name="Divergence slit 1°" xsi:type="fixedDivergenceSlitType">
				<distanceToSample unit="mm">50.00</distanceToSample>
				<height unit="mm">1.52</height>
			</divergenceSlit>
		</incidentBeamPath>
		<beamKnife id="29030100" name="Beam knife low"/>
		<sampleMovement xsi:type="spinningSampleMovementType">
			<spinnerRevolutionTime unit="seconds">1.0</spinnerRevolutionTime>
		</sampleMovement>
		<diffractedBeamPath>
			<radius unit="mm">145.00</radius>
			<antiScatterSlit id="22090040" name="AS slit 9 mm" xsi:type="fixedAntiScatterSlitType">
				<height unit="mm">9.00</height>
			</antiScatterSlit>
			<sollerSlit id="21020003" name="Large Soller slits 0.04 rad.">
				<opening unit="rad">0.0400</opening>
			</sollerSlit>
			<filter id="20030001" name="Large beta-filter Nickel">
				<material>Ni</material>
				<thickness unit="mm">0.020</thickness>
			</filter>
			<detector id="7010019" name="PIXcel1D-Medipix3 detector" xsi:type="rtmsDetectorType">
				<phd unit="keV">
					<lowerLevel>4.0</lowerLevel>
					<upperLevel>11.3</upperLevel>
				</phd>
				<mode>Scanning</mode>
				<activeLength unit="deg">1.021</activeLength>
			</detector>
		</diffractedBeamPath>
		<scan appendNumber="0" mode="Continuous" scanAxis="Gonio" status="Completed">
			<header>
				<startTimeStamp>2024-03-25T10:59:30-07:00</startTimeStamp>
				<endTimeStamp>2024-03-25T11:01:52-07:00</endTimeStamp>
				<author>
					<name>AutomatedUser</name>
				</author>
				<source>
					<applicationSoftware version="1.6 (94)">PANalytical Aeris Instrument Suite</applicationSoftware>
					<instrumentControlSoftware version="3.0.0 20211014">AERIS</instrumentControlSoftware>
					<instrumentID>2879380</instrumentID>
				</source>
			</header>
			<dataPoints>
				<positions axis="2Theta" unit="deg">
					<startPosition>10.02173288</startPosition>
					<endPosition>139.98435528</endPosition>
				</positions>
				<positions axis="Omega" unit="deg">
					<startPosition>5.01086644</startPosition>
					<endPosition>69.99217764</endPosition>
				</positions>
				<commonCountingTime unit="seconds">1.551</commonCountingTime>
				<counts unit="counts">446 426 444 425 427 461 393 408 425 433 448 415 388 426 400 382 380 396 371 402 363 390 388 376 355 393 394 427 374 420 415 382 391 362 371 368 330 345 337 330 347 340 321 362 359 332 381 380 359 324 325 374 329 359 319 314 336 351 328 333 286 283 337 346 326 275 304 336 331 322 332 336 304 324 304 308 352 302 291 303 297 315 310 286 271 291 304 302 274 297 290 314 258 281 307 274 298 310 275 318 268 276 260 290 320 302 292 279 266 289 280 306 249 266 290 279 281 303 287 288 281 260 277 293 247 257 263 268 249 274 268 238 274 255 229 267 266 226 262 257 245 266 274 238 280 264 253 260 263 286 256 268 288 308 248 242 271 252 272 268 218 280 288 259 252 262 313 300 280 254 266 259 225 255 244 259 248 275 247 246 235 214 250 234 209 238 240 260 228 194 269 254 269 224 275 222 258 265 228 218 264 226 262 238 229 199 249 222 234 244 217 217 199 238 223 212 278 289 342 298 264 232 242 233 230 194 237 224 223 215 251 263 226 269 224 310 312 308 340 225 274 218 228 228 214 244 206 218 214 197 221 213 216 224 252 169 213 212 219 212 226 204 250 287 304 308 259 203 216 192 210 219 230 217 202 184 204 186 205 221 179 219 222 217 221 201 217 192 229 212 212 205 200 191 238 207 216 233 188 211 215 221 196 213 223 217 226 177 228 210 222 261 229 289 291 323 386 412 374 392 378 324 299 320 349 342 376 425 367 303 273 231 210 245 225 201 213 226 203 207 195 188 234 231 221 234 241 226 237 219 225 294 353 465 735 587 663 761 1043 966 722 423 313 257 269 223 231 215 236 233 247 229 223 217 223 216 249 313 375 631 974 934 662 343 256 330 330 480 675 1181 2456 3670 2371 1464 483 338 301 268 281 282 269 281 356 427 657 871 776 794 894 1006 900 750 503 387 341 272 256 258 266 207 219 216 213 192 202 196 204 217 200 167 223 181 220 191 212 214 175 207 191 169 195 207 187 189 196 177 188 151 210 188 206 186 202 186 196 186 197 194 169 175 223 201 187 206 206 216 220 194 223 208 211 235 234 211 250 298 311 409 529 670 795 745 818 785 680 547 437 291 287 226 236 236 201 213 202 190 197 196 210 206 166 209 175 221 236 290 315 236 255 221 224 206 190 212 248 263 372 633 1099 895 791 737 1024 1113 794 653 284 224 188 216 214 202 189 184 185 168 214 220 307 310 326 289 301 339 335 337 318 274 279 259 231 191 213 215 214 196 198 209 201 190 191 265 347 539 441 377 325 217 294 311 382 451 393 332 290 207 203 201 221 177 216 229 336 374 338 345 248 246 218 202 175 172 171 180 166 169 168 153 146 163 139 171 167 186 208 223 353 262 287 226 199 168 187 180 189 211 258 250 259 281 428 450 337 327 221 188 183 202 240 299 392 328 325 291 207 178 150 161 171 157 187 191 194 226 217 155 176 156 149 172 144 156 151 141 158 158 178 155 164 167 185 227 286 284 234 228 171 203 179 161 143 172 175 173 172 225 261 234 220 194 187 168 172 161 142 169 163 179 200 213 215 242 218 230 224 229 177 193 215 208 234 227 233 259 275 286 298 338 298 295 282 254 228 258 291 333 353 347 320 279 197 215 179 178 162 176 196 256 291 237 223 232 159 142 175 150 129 156 147 166 143 162 140 148 147 161 157 152 164 143 152 146 160 120 162 166 164 159 174 163 140 135 163 134 179 148 128 139 151 174 144 178 185 186 163 169 167 159 174 196 160 171 177 211 219 235 249 243 292 287 317 314 223 259 214 182 191 193 191 218 213 211 173 163 174 145 158 168 168 177 173 173 176 167 196 257 466 694 514 416 467 281 170 168 179 156 157 146 154 141 156 151 177 131 151 150 137 150 135 149 132 143 197 175 164 212 218 177 191 174 159 189 169 158 165 162 145 140 160 192 209 241 207 285 328 268 291 369 442 340 361 341 276 218 219 179 172 208 173 168 212 208 235 268 267 268 277 344 306 284 272 278 216 210 206 187 191 239 265 351 299 304 396 364 266 306 257 247 210 236 195 251 232 239 225 247 240 190 185 190 163 171 162 139 159 178 172 231 224 243 245 251 259 213 293 291 368 373 388 361 279 271 286 350 334 222 232 239 192 182 178 225 286 464 436 275 298 269 196 174 172 180 188 181 190 178 292 362 357 272 250 289 233 235 192 212 197 176 192 178 168 180 140 161 158 179 162 178 194 167 193 214 214 229 252 229 209 179 156 198 172 159 150 157 170 178 231 421 446 257 291 325 232 214 174 185 184 175 212 246 256 291 360 372 294 304 319 287 218 196 189 244 309 341 271 250 257 251 187 160 154 189 164 176 146 176 170 161 179 153 148 161 152 140 132 183 152 160 160 163 154 200 194 166 181 184 168 180 133 170 141 158 156 182 234 285 264 289 293 283 257 222 205 186 197 242 343 270 241 216 251 252 202 243 181 215 226 315 311 277 238 314 327 363 284 232 237 237 199 174 169 170 182 160 163 161 160 171 196 190 181 228 232 244 252 245 265 235 224 211 196 189 175 146 154 179 158 168 143 138 152 130 141 152 147 125 159 138 165 140 141 155 157 176 160 194 237 248 311 255 228 218 281 266 231 220 294 212 232 222 254 237 197 181 171 176 205 217 196 213 247 229 193 210 206 182 181 208 190 209 211 167 171 170 196 143 165 134 151 156 156 168 186 160 192 217 215 197 169 205 175 185 180 165 150 139 151 145 145 157 140 160 155 138 161 154 125 134 142 163 140 146 151 145 138 167 170 153 118 153 119 151 125 152 152 173 202 216 187 145 214 232 224 244 266 248 226 230 252 250 266 271 218 234 247 238 253 205 196 208 197 199 177 166 146 168 165 176 220 214 232 227 231 241 251 206 147 204 143 174 174 194 151 179 175 169 152 151 177 158 168 154 202 170 148 134 141 137 147 146 154 139 131 137 142 148 194 201 213 182 166 159 206 214 168 166 159 170 158 125 174 140 146 161 165 151 152 148 150 150 179 171 183 185 184 185 232 189 196 194 215 209 155 185 176 176 160 142 154 171 175 119 127 146 128 165 158 145 154 171 171 162 170 159 182 188 166 164 165 176 196 276 303 234 207 215 241 188 207 161 149 177 141 145 138 187 179 149 153 163 188 203 197 209 159 163 174 170 148 159 167 146 127 130 131 135 141 149 129 137 152 131 141 135 137 153 157 144 138 141 167 157 165 183 182 155 154 160 160 170 218 219 174 148 161 168 207 155 180 189 186 169 182 170 176 147 150 158 146 171 184 143 159 174 180 139 184 161 151 167 144 142 147 154 160 139 179 131 156 139 138 142 152 160 121 126 154 162 119 156 154 163 175 149 137 167 161 156 139 145 135 131 149 131 148 123 137 156 127 177 176 183 167 163 168 174 171 189 207 192 163 211 178 186 178 193 174 177 183 153 144 142 156 139 148 145 153 146 145 153 166 151 168 156 164 213 167 147 134 193 162 169 160 134 170 156 175 204 186 185 182 157 165 150 161 162 180 187 160 195 170 192 188 193 189 174 199 179 208 242 222 209 158 180 194 195 151 158 152 159 144 133 146 123 120 130 152 119 121 141 158 123 158 156 180 169 154 166 146 180 141 182 144 149 159 125 137 143 138 135 135 166 150 184 218 254 177 165 182 169 188 197 182 121 140 126 159 141 133 116 137 169 165 161 171 158 136 156 179 151 139 144 153 142 129 135 131 144 140 162 164 157 167 161 159 130 146 167 163 169 191 206 164 165 164 160 162 155 143 166 165 153 161 140 179 168 178 135 142 144 147 158 183 154 156 159 115 174 151 122 135 161 149 132 122 153 158 133 137 125 151 146 158 129 125 155 132 136 142 153 180 177 185 180 194 157 130 169 208 208 167 180 172 143 163 155 151 151 145 137 166 163 155 144 154 147 170 162 185 139 153 153 185 202 192 176 181 142 166 156 192 177 205 173 190 169 184 189 218 185 174 152 161 167 161 169 172 166 125 154 144 145 146 165 168 168 135 154 142 172 150 189 193 200 168 187 147 184 163 200 171 167 138 163 171 157 155 125 131 132 168 176 173 149 153 151 140 158 157 160 165 136 142 177 129 138 152 164 187 165 152 174 171 146 147 155 175 147 155 135 135 135 166 170 191 155 159 155 152 182 193 200 184 191 162 157 141 167 144 124 127 149 157 171 163 132 146 145 171 171 165 166 143 141 138 178 154 164 163 175 169 161 179 181 149 174 155 159 182 159 168 147 156 132 120 139 147 125 169 116 144 145 161 131 152 141 142 149 162 128 150 132 146 149 149 143 137 143 135 148 137 134 152 155 189 173 165 164 161 181 174 175 171 157 145 160 149 152 185 189 149 167 169 147 146 155 166 159 137 131 154 157 146 146 148 190 163 167 174 149 124 144 149 143 130 157 130 154 130 147 141 125 165 129 142 153 148 161 153 177 141 157 137 156 152 137 138 144 154 146 158 137 131 146 124 148 159 140 148 139 172 148 162 135 176 134 170 159 178 203 191 195 199 163 159 202 159 209 192 169 188 163 157 200 161 172 151 172 209 190 198 195 215 184 146 184 188 164 170 151 156 176 174 160 140 221 205 218 156 166 171 174 159 201 170 171 162 140 195 149 161 128 176 163 152 159 161 155 166 165 155 131 144 139 163 135 149 152 158 168 136 138 146 149 157 161 144 141 154 132 149 151 122 153 160 146 139 157 162 182 156 135 175 174 201 173 198 146 166 167 144 172 164 162 167 163 190 162 132 206 181 152 177 181 165 150 148 138 131 150 148 150 145 135 127 142 136 148 153 151 181 155 142 150 151 149 122 166 163 122 131 130 133 142 180 170 167 151 156 166 152 130 152 156 129 166 163 138 138 138 162 143 136 146 138 176 141 144 130 145 146 146 142 148 133 150 155 158 155 128 127 145 160 171 155 165 157 161 135 157 174 196 186 164 183 169 149 152 147 135 151 168 151 146 148 146 186 159 143 181 174 154 155 154 162 145 176 154 151 160 162 142 156 148 174 149 146 146 147 131 161 183 141 177 148 141 159 141 156 133 155 161 162 166 182 157 189 166 146 168 161 159 144 168 156 177 176 180 153 165 183 168 181 151 178 189 163 181 132 191 174 160 168 186 185 149 172 148 191 169 167 188 205 182 163 186 194 162 180 184 198 152 168 186 185 154 177 149 180 163 149 156 142 154 126 139 141 138 131 141 147 130 154 121 134 146 154 138 134 155 159 163 181 141 156 160 156 168 145 153 130 142 146 140 148 146 135 135 129 134 146 166 165 138 155 176 193 159 177 141 144 124 158 162 166 184 157 149 130 152 167 170 161 157 171 132 140 173 157 154 136 129 153 145 141 143 136 138 137 158 122 163 129 143 155 152 154 162 137 149 148 164 150 149 154 148 136 151 146 125 161 158 159 159 152 150 142 145 153 164 148 130 154 145 159 144 167 136 189 172 151 131 160 147 155 165 143 168 190 165 141 168 164 163 162 134 149 169 134 156 173 160 177 147 150 138 154 128 140 134 140 155 158 149 155 154 149 145 150 150 153 166 155 118 158 157 141 160 138 130 140 176 131 167 174 176 172 182 166 170 162 167 191 165 177 183 200 184 177 166 169 165 157 185 158 158 140 172 165 148 168 146 170 140 163 158 171 187 153 174 157 172 165 153 169 177 170 183 166 164 166 139 155 145 180 188 143 186 166 153 169 154 146 154 139 166 146 143 182 151 148 135 149 127 150 143 149 144 139 143 159 137 159 157 134 158 138 117 150 156 144 133 152 146 125 137 138 149 148 156 154 135 147 140 163 158 155 157 126 136 154 158 132 160 182 167 142 139 142 153 133 137 141 152 162 147 131 148 151 143 144 158 160 143 149 178 182 155 144 161 152 170 155 157 143 161 153 152 160 156 152 161 141 163 163 144 163 173 163 160 142 154 158 159 158 180 148 165 167 168 152 156 155 160 167 160 165 175 158 150 181 177 150 159 162 157 169 153 192 150 142 155 143 162 160 163 158 141 172 188 166 150 171 179 150 184 185 161 165 186 180 190 170 166 151 189 162 169 139 162 180 152 145 129 158 168 156 177 154 128 146 162 152 166 153 157 169 168 160 184 149 163 146 182 154 148 154 182 176 153 171 168 199 158 146 165 188 167 181 187 198 176 177 178 160 150 161 156 181 160 167 176 170 143 139 185 166 174 166 175 166 150 157 161 155 139 144 177 169 162 158 162 161 159 180 158 156 178 197 152 151 163 194 182 186 181 166 149 179 159 149 151 173 144 182 164 171 152 158 160 160 162 147 146 171 179 174 179 146 154 142 140 137 149 169 162 133 155 157 139 159 155 153 195 185 157 184 161 159 169 177 185 181 194 170 170 154 176 166 181 196 187 198 154 173 201 187 195 192 194 160 148 189 155 144 172 168 150 140 159 176 173 140 159 135 161 134 152 152 136 176 163 163 148 172 163 154 150 168 140 161 158 179 185 155 163 172 204 126 173 157 175 169 150 140 164 179 158 171 178 178 190 146 169 165 154 157 181 179 170 157 161 163 149 190 174 151 160 184 150 150 184 188 195 158 173 169 189 161 153 158 158 156 149 143 156 152 162 166 190 150 175 144 167 161 156 149 148 149 159 146 173 161 183 164 164 164 153 161 143 185 173 156 175 154 153 147 171 164 171 163 160 157 174 168 153 156 130 153 188 163 193 150 149 161 170 173 191 149 185 183</counts>
			</dataPoints>
		</scan>
	</xrdMeasurement>
</xrdMeasurements>