File: dataset/precursor_mixture/GeO2_Li2TiO3_In2O3.2-min.xrdml
<?xml version="1.0"?>
<xrdMeasurements xmlns="http://www.xrdml.com/XRDMeasurement/2.2" xmlns:xsi="http://www.w3.org/2001/XMLSchema-instance" xsi:schemaLocation="http://www.xrdml.com/XRDMeasurement/2.2 http://www.xrdml.com/XRDMeasurement/2.2/XRDMeasurement.xsd" status="Completed" recordIdentifier="{2A695596-5428-4FA1-BE27-EC489DCDD7A2}">
	<comment>
		<entry/>
	</comment>
	<sample type="To be analyzed">
		<id></id>
		<name></name>
		<preparedBy></preparedBy>
	</sample>
	<xrdMeasurement measurementType="Scan" status="Completed" sampleMode="Reflection">
		<usedWavelength intended="K-Alpha 1">
			<kAlpha1 unit="Angstrom">1.5405980</kAlpha1>
			<kAlpha2 unit="Angstrom">1.5444260</kAlpha2>
			<kBeta unit="Angstrom">1.3922500</kBeta>
			<ratioKAlpha2KAlpha1>0.5000</ratioKAlpha2KAlpha1>
		</usedWavelength>
		<incidentBeamPath>
			<radius unit="mm">145.00</radius>
			<xRayTube id="1010048" name="Empyrean Cu LFF HR (9430 033 7310x) DK437873">
				<tension unit="kV">40.0</tension>
				<current unit="mA">15.0</current>
				<anodeMaterial>Cu</anodeMaterial>
				<focus type="Line">
					<length unit="mm">12.0</length>
					<width unit="mm">0.4</width>
					<takeOffAngle unit="deg">6.0</takeOffAngle>
				</focus>
			</xRayTube>
			<filter id="20010004" name="Beta-filter Nickel">
				<material>Ni</material>
				<thickness unit="mm">0.020</thickness>
			</filter>
			<sollerSlit id="21010002" name="Soller slits 0.04 rad.">
				<opening unit="rad">0.0400</opening>
			</sollerSlit>
			<mask id="22031000" name="Fixed mask 13 mm">
				<width unit="mm">9.00</width>
			</mask>
			<divergenceSlit id="22120001" name="Divergence slit 1°" xsi:type="fixedDivergenceSlitType">
				<distanceToSample unit="mm">50.00</distanceToSample>
				<height unit="mm">1.52</height>
			</divergenceSlit>
		</incidentBeamPath>
		<beamKnife id="29030100" name="Beam knife low"/>
		<sampleMovement xsi:type="spinningSampleMovementType">
			<spinnerRevolutionTime unit="seconds">1.0</spinnerRevolutionTime>
		</sampleMovement>
		<diffractedBeamPath>
			<radius unit="mm">145.00</radius>
			<antiScatterSlit id="22090040" name="AS slit 9 mm" xsi:type="fixedAntiScatterSlitType">
				<height unit="mm">9.00</height>
			</antiScatterSlit>
			<sollerSlit id="21020003" name="Large Soller slits 0.04 rad.">
				<opening unit="rad">0.0400</opening>
			</sollerSlit>
			<filter id="20030001" name="Large beta-filter Nickel">
				<material>Ni</material>
				<thickness unit="mm">0.020</thickness>
			</filter>
			<detector id="7010019" name="PIXcel1D-Medipix3 detector" xsi:type="rtmsDetectorType">
				<phd unit="keV">
					<lowerLevel>4.0</lowerLevel>
					<upperLevel>11.3</upperLevel>
				</phd>
				<mode>Scanning</mode>
				<activeLength unit="deg">1.021</activeLength>
			</detector>
		</diffractedBeamPath>
		<scan appendNumber="0" mode="Continuous" scanAxis="Gonio" status="Completed">
			<header>
				<startTimeStamp>2024-03-22T20:48:41-07:00</startTimeStamp>
				<endTimeStamp>2024-03-22T20:51:03-07:00</endTimeStamp>
				<author>
					<name>Instrument</name>
				</author>
				<source>
					<applicationSoftware version="1.6 (94)">PANalytical Aeris Instrument Suite</applicationSoftware>
					<instrumentControlSoftware version="3.0.0 20211014">AERIS</instrumentControlSoftware>
					<instrumentID>2879380</instrumentID>
				</source>
			</header>
			<dataPoints>
				<positions axis="2Theta" unit="deg">
					<startPosition>10.02173288</startPosition>
					<endPosition>139.98435528</endPosition>
				</positions>
				<positions axis="Omega" unit="deg">
					<startPosition>5.01086644</startPosition>
					<endPosition>69.99217764</endPosition>
				</positions>
				<commonCountingTime unit="seconds">1.551</commonCountingTime>
				<counts unit="counts">380 411 415 398 358 348 381 382 380 352 360 374 393 402 359 332 354 355 334 353 350 303 323 344 342 366 343 347 351 312 321 357 300 334 341 342 317 374 336 330 306 347 309 313 314 310 289 297 306 284 268 312 297 289 264 275 286 272 298 269 330 279 313 281 241 272 242 217 256 234 284 245 293 244 271 281 279 269 258 205 274 230 258 238 238 237 234 257 245 250 232 220 262 240 238 231 249 256 243 225 228 221 242 237 247 259 250 267 226 221 244 226 230 195 268 219 211 189 197 211 239 216 196 199 224 210 200 203 181 210 219 172 197 192 208 206 195 209 218 205 221 201 188 179 229 215 229 179 199 186 181 223 187 198 189 208 190 200 174 185 192 178 205 153 192 204 215 200 221 216 182 169 181 184 200 180 195 202 175 195 176 196 196 199 197 207 221 209 243 252 237 236 233 210 190 220 207 197 171 177 215 179 188 194 163 199 161 171 187 201 206 182 154 183 192 171 156 186 179 176 197 177 169 161 192 205 210 173 206 214 247 250 259 290 420 529 720 896 791 506 323 264 243 206 200 208 193 190 233 205 195 204 177 195 215 223 274 433 622 584 384 234 182 152 176 158 153 159 148 163 159 174 151 174 145 185 161 147 159 152 135 168 160 162 144 160 170 166 134 156 150 132 145 135 160 120 143 146 145 147 157 155 167 157 158 141 135 125 140 142 129 130 139 131 142 149 143 152 149 124 173 142 154 137 159 128 131 153 137 137 139 136 155 148 156 171 137 130 174 166 168 181 191 204 218 225 206 254 210 238 278 277 340 436 560 810 1388 2400 3824 4091 2933 1596 730 502 376 327 298 227 222 227 195 187 192 173 170 157 171 161 144 152 159 158 141 153 134 152 144 122 142 132 160 129 128 127 121 162 143 131 124 116 129 138 117 132 120 110 112 113 128 141 124 125 131 128 131 139 109 128 127 124 126 124 131 102 136 123 100 107 96 110 108 129 111 127 125 124 105 130 120 119 122 112 124 125 158 152 129 125 111 137 158 149 175 196 192 153 184 221 316 424 743 1225 2587 4089 3044 1945 793 361 254 200 212 181 175 172 172 125 123 106 123 116 133 120 125 112 109 119 108 96 106 122 114 88 137 123 101 103 103 110 118 118 104 106 111 107 102 106 112 111 90 111 103 79 106 90 84 107 101 101 101 138 150 135 121 95 104 99 119 105 116 95 116 101 114 127 85 95 113 92 98 94 85 93 84 86 92 94 117 85 101 94 102 99 116 91 100 90 99 90 111 103 108 97 114 98 111 115 131 140 204 217 276 496 932 1216 804 688 364 203 174 152 159 165 257 309 459 452 368 272 224 152 154 163 109 103 89 94 107 127 107 106 78 122 92 97 86 107 99 87 79 103 102 89 74 103 85 98 96 120 106 110 121 157 236 332 279 206 203 235 280 484 712 688 577 487 272 192 160 140 129 100 109 102 91 99 111 99 110 93 119 97 86 87 91 93 103 97 94 87 104 141 185 247 418 427 381 335 255 161 129 110 141 135 121 130 76 102 82 81 75 79 95 75 70 76 59 100 68 86 86 74 92 79 88 97 90 83 63 92 72 85 92 98 87 91 84 73 106 90 98 99 127 136 186 288 496 638 675 588 477 291 180 135 111 129 85 109 92 92 77 81 83 97 88 80 110 87 89 93 75 81 89 86 81 105 83 81 105 98 93 113 101 144 137 150 196 262 240 283 306 258 284 246 173 172 162 144 119 117 110 80 87 96 80 81 75 78 86 70 68 89 84 68 92 106 102 119 117 98 81 88 98 94 70 79 81 69 81 79 67 91 107 163 290 373 230 202 204 126 93 86 73 71 81 55 63 64 58 51 64 71 61 91 64 67 69 68 77 55 67 71 73 66 75 78 81 74 73 70 70 81 81 67 82 73 59 73 52 69 73 72 61 89 69 75 74 83 90 93 97 92 148 230 208 166 181 134 129 143 193 344 391 293 271 243 167 128 85 90 82 90 70 85 75 151 193 135 119 106 79 69 89 83 91 68 73 84 77 86 73 69 65 67 84 68 70 65 68 69 86 70 62 72 74 91 80 84 90 106 112 147 225 412 950 1287 741 607 743 374 204 118 119 81 102 78 70 71 76 61 73 75 63 70 69 59 70 66 75 65 64 76 64 79 60 68 68 79 79 76 93 79 131 133 96 87 113 129 121 151 130 100 119 102 85 126 175 243 186 156 162 139 118 100 85 74 82 64 69 76 52 70 60 64 67 65 74 65 73 83 71 62 79 83 74 68 51 57 68 60 48 57 59 60 76 62 52 70 64 58 74 61 61 71 70 72 82 62 75 75 77 77 68 61 78 139 221 194 142 139 156 114 114 107 102 103 85 75 89 87 74 75 68 43 48 68 68 63 64 71 49 65 69 54 74 71 64 63 69 69 75 96 124 101 73 115 102 77 77 69 52 74 57 65 55 66 79 62 65 75 77 75 80 81 81 75 96 146 183 289 416 418 292 296 271 245 229 250 213 148 127 161 138 90 82 71 79 59 71 68 72 64 72 81 77 84 64 72 68 62 93 74 50 67 77 108 88 100 133 181 357 721 874 533 345 488 469 234 143 100 97 91 71 55 65 78 68 74 73 78 88 95 90 136 164 152 130 108 141 109 109 107 98 93 103 179 237 135 136 143 145 106 102 64 66 51 79 78 68 70 63 65 60 86 79 78 78 84 105 112 114 133 137 143 176 157 156 156 208 273 279 170 147 152 144 99 89 80 65 73 64 61 74 78 55 76 68 71 70 69 80 73 74 64 68 67 73 82 73 56 77 86 118 138 100 80 93 118 93 75 91 110 111 126 187 278 264 221 197 247 252 268 341 311 257 216 200 203 176 128 110 95 74 112 104 107 114 111 100 114 82 109 131 171 221 227 184 161 164 158 128 119 99 80 70 77 61 71 82 77 80 70 70 65 58 89 100 121 126 97 74 69 139 92 65 56 58 58 65 64 75 51 58 58 64 59 40 55 61 64 52 58 61 66 72 56 55 79 66 94 99 79 82 98 70 99 72 87 82 74 106 111 176 153 131 98 115 105 111 95 89 74 67 62 59 64 53 74 46 58 61 51 54 56 69 42 59 60 56 54 48 50 66 44 46 44 48 51 41 59 70 46 67 53 46 46 63 56 54 58 46 46 52 49 55 43 63 54 38 44 63 52 57 51 34 44 48 60 58 54 57 59 66 58 54 67 61 58 63 63 75 57 97 86 132 129 136 173 160 145 125 97 132 92 84 73 65 57 58 73 64 52 48 58 51 61 55 62 44 57 50 55 71 86 115 163 135 102 69 80 122 97 81 59 48 51 47 51 49 56 62 53 68 51 50 64 63 51 65 58 71 48 74 74 107 167 151 126 103 83 84 109 98 60 75 55 55 60 49 47 70 62 68 94 87 116 107 74 92 82 75 104 94 111 119 121 143 136 109 99 95 96 76 72 79 60 56 71 54 74 65 72 87 92 73 84 76 94 76 76 71 62 66 75 63 76 90 116 103 91 60 64 71 77 77 51 61 66 79 56 62 55 57 76 67 86 137 130 133 107 99 133 112 113 94 115 107 134 111 87 91 65 74 79 73 59 47 42 60 48 47 51 51 47 60 65 48 58 51 49 49 60 74 52 73 77 79 112 121 118 87 67 83 80 89 77 64 75 59 64 71 47 69 64 67 43 73 56 81 61 77 52 60 67 60 84 109 158 241 173 117 102 97 117 140 91 90 71 58 45 59 62 50 41 43 34 42 48 51 58 46 40 59 64 43 36 55 40 55 45 43 49 62 47 43 66 57 66 85 52 60 47 71 59 58 46 57 68 66 63 52 52 49 39 58 65 86 119 197 150 95 75 77 94 119 89 72 79 54 40 51 55 47 63 48 44 57 45 49 39 70 45 45 62 68 58 73 59 78 56 75 44 53 52 59 45 48 59 49 52 40 67 60 51 45 61 50 42 42 64 41 60 49 55 64 50 73 81 92 107 91 70 84 69 82 81 63 72 72 48 49 51 47 67 41 59 60 40 50 65 72 77 80 81 83 58 99 103 113 82 76 66 69 77 81 73 65 64 54 51 47 70 43 52 42 47 76 61 43 53 44 50 43 48 55 55 50 54 62 45 57 58 47 72 70 45 40 49 52 58 48 50 52 46 54 58 49 50 57 64 65 77 85 105 99 100 110 125 128 122 107 90 73 88 64 80 66 54 73 59 64 58 81 65 63 50 63 56 65 58 53 53 47 38 37 41 48 42 45 44 50 49 51 43 45 60 43 59 42 55 43 58 45 44 50 51 49 63 46 45 52 61 69 54 60 62 71 107 123 91 71 58 55 73 85 90 80 78 61 67 67 59 73 73 61 47 80 86 59 65 60 70 48 65 89 96 114 137 172 118 97 71 91 91 98 115 95 81 81 83 65 66 59 69 72 59 82 52 45 57 57 55 49 67 55 78 77 102 114 66 69 43 83 84 77 90 79 63 50 57 50 53 53 43 67 64 55 54 49 45 55 63 42 69 62 74 81 117 138 131 110 114 84 102 77 133 120 145 101 98 102 95 78 77 72 71 68 49 61 45 72 62 56 36 46 44 65 90 70 76 50 62 56 46 50 55 51 72 57 70 60 45 51 47 36 52 39 61 57 47 45 50 50 56 78 59 75 96 108 135 107 66 76 79 73 90 101 84 71 57 62 62 39 51 42 46 51 49 62 45 48 42 51 50 46 36 38 62 68 61 63 58 53 48 55 70 66 55 52 48 71 41 62 53 56 44 53 61 68 80 87 93 90 91 83 90 69 87 97 139 163 137 115 106 93 66 79 85 97 72 77 66 67 52 61 43 53 48 48 52 54 51 57 61 52 56 62 64 64 79 95 120 99 110 71 68 68 65 75 74 91 62 45 53 69 41 32 54 51 48 55 49 45 32 66 60 52 51 43 48 44 41 54 45 49 41 54 50 56 67 58 47 48 59 57 54 52 48 57 58 52 49 43 59 51 59 39 53 66 48 55 67 85 91 107 103 72 69 68 61 59 77 93 72 78 65 67 45 57 60 61 68 72 72 52 64 61 80 70 75 65 76 72 90 92 103 94 98 89 64 85 62 54 99 112 87 80 98 75 77 76 89 89 100 81 72 82 103 93 86 76 74 72 70 73 96 88 140 124 80 97 79 86 103 102 121 115 116 109 78 99 89 83 93 85 73 74 76 80 83 71 78 76 83 87 65 76 81 104 118 115 87 92 70 66 83 66 67 81 81 85 83 89 73 60 54 51 66 68 64 65 63 58 55 56 66 48 51 68 77 66 93 109 74 75 67 54 64 69 65 83 76 92 72 72 49 68 60 51 51 63 60 72 62 47 65 49 55 55 50 50 45 49 54 45 47 46 59 59 61 63 52 54 49 46 44 47 43 50 41 36 54 52 41 51 54 55 57 50 63 48 49 57 50 74 56 54 59 83 67 64 72 73 67 58 53 69 58 62 67 69 77 61 65 51 66 55 41 61 58 38 49 50 57 65 44 49 54 64 59 64 92 114 89 71 59 63 78 58 50 59 80 66 67 74 62 76 45 71 58 47 46 54 51 63 53 63 62 63 43 60 68 56 65 49 56 59 54 36 74 73 62 57 49 51 42 44 49 40 57 47 54 42 62 47 40 56 52 57 42 40 51 67 68 56 47 52 59 64 59 72 80 62 76 52 66 61 56 44 55 64 73 67 73 74 76 56 56 57 49 58 42 57 67 65 56 65 57 46 52 48 52 54 66 65 70 77 80 63 81 67 57 49 56 50 45 66 75 69 68 76 68 71 47 52 70 57 56 52 56 72 56 54 46 45 46 71 35 71 48 61 50 53 74 56 71 82 58 69 72 53 61 65 72 64 67 58 67 66 65 71 51 60 64 69 73 49 54 65 89 82 61 54 78 57 72 66 70 69 77 95 94 92 93 94 69 64 49 68 59 52 87 71 77 64 69 67 57 57 63 70 62 57 55 52 62 55 56 71 70 52 61 61 61 74 89 101 103 137 100 108 88 65 77 65 59 78 82 75 77 84 98 100 97 77 62 63 67 75 60 75 62 63 59 54 80 54 47 61 64 53 61 74 53 71 63 73 59 83 56 51 65 57 57 59 49 59 71 55 68 54 64 88 68 76 57 76 64 58 81 56 69 97 51 71 83 74 80 72 71 77 83 80 84 103 103 110 107 120 96 97 86 99 68 65 91 61 77 70 79 90 91 85 77 57 62 66 78 52 59 56 67 47 73 54 74 76 65 54 73 68 58 68 85 92 87 114 134 101 105 86 84 73 65 60 57 77 69 69 70 70 96 79 101 77 68 65 70 64 71 74 48 53 69 55 60 46 61 61 49 60 57 67 60 63 66 67 103 100 109 108 110 97 96 79 75 74 55 70 59 62 67 68 78 75 92 80 83 78 64 62 61 53 42 61 54 68 65 54 77 61 52 65 52 68 68 78 94 79 82 86 88 98 100 99 91 88 81 64 76 78 53 84 67 70 79 72 70 78 85 81 86 83 65 72 50 56 71 57 55 68 69 75 60 67 71 68 78 83 72 75 70 79 77 104 112 80 125 114 119 100 99 77 64 83 80 94 55 75 75 65 78 74 79 87 87 83 60 76 64 95 85 61 79 67 63 68 82 74 68 74 82 83 60 59 70 75 77 65 72 77 62 69 81 64 79 62 96 73 68 57 88 78 72 64 81 61 64 87 59 65 67 81 72 59 68 74 63 70 63 63 58 74</counts>
			</dataPoints>
		</scan>
	</xrdMeasurement>
</xrdMeasurements>