File: dataset/precursor_mixture/GeO2_ZrO2_Bi2O3-alpha.2-min.xrdml
<?xml version="1.0"?>
<xrdMeasurements xmlns="http://www.xrdml.com/XRDMeasurement/2.2" xmlns:xsi="http://www.w3.org/2001/XMLSchema-instance" xsi:schemaLocation="http://www.xrdml.com/XRDMeasurement/2.2 http://www.xrdml.com/XRDMeasurement/2.2/XRDMeasurement.xsd" status="Completed" recordIdentifier="{F7061495-C5DA-4370-B72E-812AEFFF6042}">
	<comment>
		<entry/>
	</comment>
	<sample type="To be analyzed">
		<id>dara-16-1</id>
		<name></name>
		<preparedBy></preparedBy>
	</sample>
	<xrdMeasurement measurementType="Scan" status="Completed" sampleMode="Reflection">
		<usedWavelength intended="K-Alpha 1">
			<kAlpha1 unit="Angstrom">1.5405980</kAlpha1>
			<kAlpha2 unit="Angstrom">1.5444260</kAlpha2>
			<kBeta unit="Angstrom">1.3922500</kBeta>
			<ratioKAlpha2KAlpha1>0.5000</ratioKAlpha2KAlpha1>
		</usedWavelength>
		<incidentBeamPath>
			<radius unit="mm">145.00</radius>
			<xRayTube id="1010048" name="Empyrean Cu LFF HR (9430 033 7310x) DK430614">
				<tension unit="kV">40.0</tension>
				<current unit="mA">15.0</current>
				<anodeMaterial>Cu</anodeMaterial>
				<focus type="Line">
					<length unit="mm">12.0</length>
					<width unit="mm">0.4</width>
					<takeOffAngle unit="deg">6.0</takeOffAngle>
				</focus>
			</xRayTube>
			<filter id="20010004" name="Beta-filter Nickel">
				<material>Ni</material>
				<thickness unit="mm">0.020</thickness>
			</filter>
			<sollerSlit id="21010002" name="Soller slits 0.04 rad.">
				<opening unit="rad">0.0400</opening>
			</sollerSlit>
			<mask id="22031000" name="Fixed mask 13 mm">
				<width unit="mm">9.00</width>
			</mask>
			<divergenceSlit id="22120001" name="Divergence slit 1°" xsi:type="fixedDivergenceSlitType">
				<distanceToSample unit="mm">50.00</distanceToSample>
				<height unit="mm">1.52</height>
			</divergenceSlit>
		</incidentBeamPath>
		<beamKnife id="29030100" name="Beam knife low"/>
		<sampleMovement xsi:type="spinningSampleMovementType">
			<spinnerRevolutionTime unit="seconds">1.0</spinnerRevolutionTime>
		</sampleMovement>
		<diffractedBeamPath>
			<radius unit="mm">145.00</radius>
			<antiScatterSlit id="22090040" name="AS slit 9 mm" xsi:type="fixedAntiScatterSlitType">
				<height unit="mm">9.00</height>
			</antiScatterSlit>
			<sollerSlit id="21020003" name="Large Soller slits 0.04 rad.">
				<opening unit="rad">0.0400</opening>
			</sollerSlit>
			<filter id="20030001" name="Large beta-filter Nickel">
				<material>Ni</material>
				<thickness unit="mm">0.020</thickness>
			</filter>
			<detector id="7010019" name="PIXcel1D-Medipix3 detector" xsi:type="rtmsDetectorType">
				<phd unit="keV">
					<lowerLevel>4.0</lowerLevel>
					<upperLevel>11.3</upperLevel>
				</phd>
				<mode>Scanning</mode>
				<activeLength unit="deg">1.021</activeLength>
			</detector>
		</diffractedBeamPath>
		<scan appendNumber="0" mode="Continuous" scanAxis="Gonio" status="Completed">
			<header>
				<startTimeStamp>2024-02-18T15:05:17-08:00</startTimeStamp>
				<endTimeStamp>2024-02-18T15:07:39-08:00</endTimeStamp>
				<author>
					<name>AutomatedUser</name>
				</author>
				<source>
					<applicationSoftware version="1.4b (28)">PANalytical Aeris Instrument Suite</applicationSoftware>
					<instrumentControlSoftware version="2.0.0 20210224">AERIS</instrumentControlSoftware>
					<instrumentID>950485</instrumentID>
				</source>
			</header>
			<dataPoints>
				<positions axis="2Theta" unit="deg">
					<startPosition>10.02173288</startPosition>
					<endPosition>139.98435528</endPosition>
				</positions>
				<positions axis="Omega" unit="deg">
					<startPosition>5.01086644</startPosition>
					<endPosition>69.99217764</endPosition>
				</positions>
				<commonCountingTime unit="seconds">1.551</commonCountingTime>
				<counts unit="counts">366 361 353 322 381 318 366 388 324 378 346 318 313 364 351 315 363 364 330 339 314 327 304 325 317 331 302 318 287 340 325 287 321 318 309 306 292 304 283 317 273 283 308 303 301 288 312 293 277 300 250 279 307 310 310 262 258 283 287 276 289 275 278 258 282 292 283 294 277 295 285 289 292 267 259 274 288 257 260 273 265 266 234 225 242 260 230 226 264 249 241 252 276 246 248 267 272 230 221 245 244 246 241 242 229 248 249 223 246 204 230 218 206 227 225 217 223 230 239 192 243 226 242 231 198 216 213 206 223 212 261 203 221 221 250 200 197 211 202 209 210 200 229 212 220 199 202 228 202 210 228 216 228 243 230 209 204 209 222 181 185 196 213 228 199 233 233 218 250 240 242 219 212 224 190 195 175 204 175 192 197 213 183 183 175 217 179 186 186 163 193 169 199 202 162 174 177 202 206 189 162 164 168 169 160 214 166 164 182 189 164 193 182 211 159 181 161 185 230 278 263 220 217 179 163 186 175 195 206 214 181 231 157 189 206 247 280 363 415 391 266 197 209 197 191 191 178 182 166 162 173 175 152 164 188 158 159 170 170 152 172 172 183 213 238 297 260 226 157 180 166 161 174 157 171 154 147 176 157 160 175 176 152 145 171 150 152 167 154 142 146 150 139 187 154 169 149 161 139 155 170 171 164 157 173 141 155 179 169 155 194 172 153 210 210 266 278 324 276 276 247 207 215 213 272 258 312 366 469 393 305 198 220 181 155 174 176 156 167 152 176 147 178 161 185 223 215 218 184 192 238 203 287 366 544 919 818 813 1122 1549 1580 1168 688 368 297 249 221 203 214 188 186 219 205 201 205 217 208 225 288 387 654 1055 1101 715 425 254 297 330 434 706 1223 2503 3924 2765 1672 507 289 268 269 267 255 223 260 362 444 757 1064 1009 944 1067 1234 1121 820 569 426 332 263 267 233 248 207 184 197 177 170 163 160 147 163 159 161 166 165 161 148 157 166 160 169 148 168 125 167 137 136 154 153 143 138 153 156 154 180 155 146 153 166 157 189 158 135 158 167 168 148 160 152 137 149 155 130 159 174 152 162 187 205 214 217 264 318 371 526 705 778 742 622 435 291 237 240 172 202 150 138 171 139 145 154 153 131 162 130 168 157 135 225 301 210 228 182 161 143 165 168 186 234 327 622 1110 958 853 809 1160 1313 881 722 327 204 183 172 161 180 162 156 167 139 173 236 278 314 317 298 312 347 374 323 280 253 289 242 246 245 199 193 174 144 132 150 152 150 180 253 369 521 505 385 351 271 320 314 367 493 382 333 273 172 132 153 130 143 179 197 321 380 353 326 232 220 180 147 137 138 110 127 142 139 121 115 109 132 115 95 129 121 139 173 290 256 202 191 150 113 127 114 107 140 106 146 161 211 338 461 354 294 221 163 149 159 228 317 422 413 334 281 183 168 136 136 138 149 131 152 155 163 148 125 148 135 154 120 110 108 93 108 128 111 117 99 135 128 147 211 261 318 271 213 182 138 135 114 135 110 117 102 130 206 264 220 202 138 128 136 136 152 116 122 151 153 157 180 215 225 244 212 168 169 140 132 153 142 142 159 156 162 182 166 201 222 257 222 235 190 181 218 360 385 416 361 297 210 200 162 158 132 146 131 164 230 304 195 194 185 123 105 108 112 107 98 94 90 118 116 108 91 102 94 113 110 118 105 120 97 94 76 110 108 89 101 113 84 92 101 97 110 112 99 96 109 90 91 119 125 152 128 130 96 114 95 100 96 115 117 166 206 196 180 166 198 157 158 241 195 191 201 154 128 134 135 163 174 158 150 134 143 132 120 138 113 121 112 109 121 118 134 164 279 481 783 574 440 446 253 172 137 118 123 114 95 126 98 91 82 104 120 107 110 104 95 99 115 114 100 135 145 121 179 179 118 145 132 96 110 111 119 103 117 101 112 137 149 167 190 205 291 357 274 277 380 486 371 389 354 248 206 202 157 156 150 158 156 163 214 228 272 273 276 299 332 322 215 218 211 163 164 144 124 152 180 232 312 294 278 435 349 275 268 255 199 216 201 176 171 244 211 219 173 161 172 136 159 121 130 129 142 113 164 155 157 156 170 164 134 150 149 124 150 166 237 300 231 191 229 255 299 269 179 207 225 143 156 138 160 266 448 469 228 292 303 175 120 117 128 128 122 141 160 230 356 381 223 249 290 177 166 170 202 181 190 179 132 152 103 120 106 109 122 107 114 135 183 124 177 224 182 215 172 186 160 160 122 106 101 124 116 153 161 254 413 420 253 291 274 179 143 149 135 128 133 159 182 250 316 414 403 351 320 314 277 242 188 189 219 290 383 273 219 249 242 168 136 149 131 157 149 129 137 148 117 96 123 103 108 117 116 114 113 109 135 119 150 135 147 186 133 157 173 123 121 114 105 116 119 122 159 200 292 247 343 288 264 212 203 160 177 175 216 291 229 193 223 230 136 158 178 170 170 215 246 329 323 276 272 309 356 273 233 205 221 180 147 122 116 105 120 109 109 115 117 160 166 180 205 181 197 188 191 187 183 130 150 148 144 97 110 86 119 118 114 111 114 97 95 105 109 84 78 69 89 103 127 112 96 110 114 125 150 168 235 242 247 219 193 250 216 194 227 245 225 174 198 209 170 161 134 137 159 186 153 157 171 218 216 174 164 167 153 171 140 140 151 179 166 146 156 125 143 120 121 111 112 81 104 136 141 135 177 155 137 124 148 132 112 106 97 77 116 110 90 108 133 103 132 126 117 103 87 106 110 103 93 86 118 86 91 84 109 105 97 81 109 101 99 107 97 112 120 140 120 141 146 146 178 216 296 283 232 213 272 255 273 290 262 250 197 187 223 218 173 165 148 135 122 140 132 139 123 107 135 190 166 203 171 238 250 232 187 167 144 136 130 115 96 96 132 112 87 83 92 110 109 100 129 150 143 116 106 136 139 100 88 109 104 95 94 86 123 140 145 161 137 123 122 149 159 128 154 145 110 110 107 100 100 110 110 114 80 112 109 121 116 102 135 149 134 152 148 188 131 126 147 224 158 124 129 144 147 118 97 93 105 115 101 80 130 98 100 115 104 95 121 136 104 103 119 153 125 125 134 133 137 152 236 278 251 156 189 186 175 178 133 101 71 113 101 100 160 123 114 93 101 151 148 174 175 124 137 122 145 112 115 109 99 95 120 113 94 90 88 101 87 76 83 87 75 104 70 84 71 94 92 120 109 87 105 134 152 133 135 122 129 155 161 110 122 125 123 120 131 176 161 146 117 128 119 136 110 91 132 108 104 117 106 123 133 103 121 122 118 104 119 104 93 83 105 74 89 115 86 101 104 96 96 92 99 91 91 87 98 122 101 111 99 119 124 107 105 105 126 114 107 100 100 112 95 101 75 82 100 113 134 140 153 134 169 129 141 133 147 187 181 185 173 145 108 129 126 122 138 118 110 122 88 111 118 101 109 105 120 108 114 131 129 113 120 145 143 117 94 110 156 110 124 115 98 111 104 126 145 165 138 136 123 146 109 116 147 113 141 157 138 117 126 129 139 163 159 119 149 143 158 185 172 194 133 170 148 134 106 101 129 107 99 87 80 87 79 93 110 90 105 114 72 94 114 130 153 95 108 111 110 107 106 107 109 116 110 100 115 86 90 109 91 176 168 185 196 171 121 117 145 171 141 108 89 75 93 100 102 103 80 110 123 145 127 109 115 133 128 117 100 104 118 103 82 138 95 107 126 102 110 134 105 126 130 106 98 118 121 126 138 158 190 149 121 114 119 154 150 126 103 112 100 101 89 103 89 133 114 117 86 114 112 130 105 93 89 107 95 96 106 124 93 102 103 108 111 99 83 73 76 69 86 91 91 88 99 80 101 99 91 125 152 171 139 128 123 112 140 149 154 145 128 108 100 110 116 118 94 95 118 74 112 111 120 92 114 149 142 140 115 91 120 174 136 133 120 135 111 109 116 143 148 168 150 145 147 148 151 157 144 158 153 119 145 111 102 119 119 124 101 99 114 105 121 108 106 111 92 98 94 141 136 125 119 142 159 122 124 127 121 142 101 119 119 101 116 107 127 87 84 101 94 107 124 81 108 89 109 84 93 85 114 116 98 112 93 118 109 120 121 116 122 100 76 106 105 121 97 102 73 112 96 117 141 118 109 146 127 146 124 162 159 140 111 135 131 131 109 97 113 86 96 103 113 104 130 100 108 117 110 103 135 118 98 110 104 122 120 128 139 108 94 99 135 97 116 116 125 117 114 145 121 113 124 95 68 104 97 86 102 83 92 101 114 88 98 100 87 83 83 93 98 101 107 107 97 99 121 115 100 115 108 108 113 94 135 138 172 144 141 151 148 143 113 128 126 110 132 116 110 131 123 113 104 116 113 117 124 92 107 116 120 101 121 115 139 147 126 106 102 87 103 119 109 106 95 116 91 82 88 103 92 112 88 86 109 100 119 110 121 114 124 81 84 95 108 91 92 97 83 91 102 112 100 91 84 107 98 115 100 100 111 139 96 114 140 123 132 131 166 158 120 152 147 122 153 136 164 150 166 159 158 107 102 136 132 127 149 146 154 130 141 134 130 128 147 137 142 135 119 126 128 129 117 137 158 172 172 146 139 127 127 139 157 148 141 150 127 117 113 124 125 99 121 106 101 86 101 93 97 96 102 87 102 101 106 95 96 105 96 81 96 95 84 87 93 94 108 115 100 107 121 94 101 108 105 118 107 105 102 104 135 108 128 154 153 167 119 120 128 93 119 138 117 93 151 125 133 121 144 114 110 123 95 111 94 116 127 106 106 94 90 96 108 110 133 81 75 106 120 129 104 103 94 100 122 130 116 113 125 105 101 103 97 103 105 121 119 127 118 108 99 117 96 78 91 98 93 101 102 87 79 96 88 103 89 77 97 82 89 101 115 95 84 90 97 79 104 90 85 84 97 115 82 126 127 141 114 100 119 147 118 108 97 101 109 115 115 101 116 119 93 101 100 102 117 102 121 114 91 112 100 102 107 126 113 109 93 120 95 111 117 92 89 78 98 90 112 93 82 117 121 115 128 103 127 141 143 134 114 103 112 119 122 139 141 128 130 122 121 122 118 108 117 114 106 123 111 109 114 132 161 121 152 144 109 138 119 120 157 123 129 130 132 146 121 121 129 140 119 135 139 156 171 130 137 162 133 133 137 157 120 117 150 109 106 112 132 105 93 109 108 116 86 113 116 95 87 101 95 70 100 78 101 87 109 102 115 102 98 109 114 123 113 94 90 102 97 103 81 104 84 85 103 105 70 99 102 83 90 93 111 97 112 111 134 108 113 109 110 97 99 119 125 100 102 92 107 99 88 104 88 102 98 119 117 104 104 119 110 107 95 112 93 97 99 104 104 111 105 98 91 113 133 112 100 90 116 119 93 97 110 97 115 114 97 107 103 119 127 107 131 117 110 110 88 104 127 115 103 93 102 90 117 106 82 109 122 93 97 98 110 90 116 119 107 108 107 142 134 139 162 82 148 114 123 144 113 88 108 130 117 131 95 101 114 90 98 105 78 109 85 113 101 97 92 147 92 91 97 100 112 112 108 110 118 116 123 100 104 119 103 113 104 120 125 133 109 126 130 120 129 101 119 161 144 134 133 133 145 141 115 137 134 107 127 149 138 118 112 119 132 128 130 137 129 140 133 138 136 133 119 130 103 127 136 157 130 104 128 139 119 119 90 116 111 109 116 107 124 141 96 118 108 114 117 95 112 127 107 97 110 122 111 99 91 93 106 90 95 97 90 94 99 87 86 90 119 114 100 125 84 110 86 105 100 99 102 96 93 115 77 101 97 117 104 109 101 90 93 75 85 92 94 107 99 87 107 107 98 97 95 94 104 80 85 105 125 106 85 98 105 141 128 148 143 118 146 116 120 116 108 137 113 121 113 118 121 101 134 122 106 105 112 133 105 138 148 124 111 114 100 122 95 104 119 148 133 123 132 146 109 99 111 121 114 110 126 133 119 106 97 110 128 111 102 107 117 102 142 126 108 150 91 76 108 106 155 134 150 133 137 130 145 145 114 122 134 136 133 109 124 108 128 118 118 112 109 122 138 129 113 95 135 104 102 97 106 97 105 99 110 105 113 124 120 132 145 114 114 143 128 115 124 117 129 113 115 104 125 113 103 121 114 134 132 137 164 129 113 101 115 133 106 123 123 121 133 128 117 123 133 131 143 104 102 125 160 137 118 141 122 117 115 114 107 114 116 118 115 114 109 99 111 131 111 96 116 118 107 122 109 112 119 113 127 133 106 146 148 135 142 125 139 108 110 91 105 146 117 104 140 124 134 117 128 134 119 85 132 116 97 106 98 97 97 103 124 95 106 101 111 118 125 109 117 126 132 143 112 134 134 149 170 135 142 135 103 126 131 118 111 133 126 137 103 135 136 147 141 157 139 115 109 123 128 141 130 117 120 116 118 115 123 101 101 121 122 133 125 113 108 107 96 136 114 100 122 123 126 125 129 115 164 157 145 120 136 125 126 128 145 100 126 115 115 125 138 121 136 132 141 152 126 176 184 147 143 124 142 123 116 147 126 89 102 109 118 128 126 113 118 123 139 101 149 108 134 127 103 120 120 124 130 107 111 133 106 129 107 115 116 103 119 107 122 106 115 108 118 120 111 102 113 111 132 115 101 112 143 116 113 122 115 127 120 116 135 116 108 142 121 126 134 115 113 144 130 114 128 99 119 122 137 110 127 128 137 97 132</counts>
			</dataPoints>
		</scan>
	</xrdMeasurement>
</xrdMeasurements>