File: dataset/precursor_mixture/GeO2_La(OH)3_ZrO2_SnO2.2-min.xrdml
<?xml version="1.0"?>
<xrdMeasurements xmlns="http://www.xrdml.com/XRDMeasurement/2.2" xmlns:xsi="http://www.w3.org/2001/XMLSchema-instance" xsi:schemaLocation="http://www.xrdml.com/XRDMeasurement/2.2 http://www.xrdml.com/XRDMeasurement/2.2/XRDMeasurement.xsd" status="Completed" recordIdentifier="{50E1991B-D809-4974-9DD6-06299E0D862C}">
	<comment>
		<entry/>
	</comment>
	<sample type="To be analyzed">
		<id>dara-24-1</id>
		<name></name>
		<preparedBy></preparedBy>
	</sample>
	<xrdMeasurement measurementType="Scan" status="Completed" sampleMode="Reflection">
		<usedWavelength intended="K-Alpha 1">
			<kAlpha1 unit="Angstrom">1.5405980</kAlpha1>
			<kAlpha2 unit="Angstrom">1.5444260</kAlpha2>
			<kBeta unit="Angstrom">1.3922500</kBeta>
			<ratioKAlpha2KAlpha1>0.5000</ratioKAlpha2KAlpha1>
		</usedWavelength>
		<incidentBeamPath>
			<radius unit="mm">145.00</radius>
			<xRayTube id="1010048" name="Empyrean Cu LFF HR (9430 033 7310x) DK430614">
				<tension unit="kV">40.0</tension>
				<current unit="mA">15.0</current>
				<anodeMaterial>Cu</anodeMaterial>
				<focus type="Line">
					<length unit="mm">12.0</length>
					<width unit="mm">0.4</width>
					<takeOffAngle unit="deg">6.0</takeOffAngle>
				</focus>
			</xRayTube>
			<filter id="20010004" name="Beta-filter Nickel">
				<material>Ni</material>
				<thickness unit="mm">0.020</thickness>
			</filter>
			<sollerSlit id="21010002" name="Soller slits 0.04 rad.">
				<opening unit="rad">0.0400</opening>
			</sollerSlit>
			<mask id="22031000" name="Fixed mask 13 mm">
				<width unit="mm">9.00</width>
			</mask>
			<divergenceSlit id="22120001" name="Divergence slit 1°" xsi:type="fixedDivergenceSlitType">
				<distanceToSample unit="mm">50.00</distanceToSample>
				<height unit="mm">1.52</height>
			</divergenceSlit>
		</incidentBeamPath>
		<beamKnife id="29030100" name="Beam knife low"/>
		<sampleMovement xsi:type="spinningSampleMovementType">
			<spinnerRevolutionTime unit="seconds">1.0</spinnerRevolutionTime>
		</sampleMovement>
		<diffractedBeamPath>
			<radius unit="mm">145.00</radius>
			<antiScatterSlit id="22090040" name="AS slit 9 mm" xsi:type="fixedAntiScatterSlitType">
				<height unit="mm">9.00</height>
			</antiScatterSlit>
			<sollerSlit id="21020003" name="Large Soller slits 0.04 rad.">
				<opening unit="rad">0.0400</opening>
			</sollerSlit>
			<filter id="20030001" name="Large beta-filter Nickel">
				<material>Ni</material>
				<thickness unit="mm">0.020</thickness>
			</filter>
			<detector id="7010019" name="PIXcel1D-Medipix3 detector" xsi:type="rtmsDetectorType">
				<phd unit="keV">
					<lowerLevel>4.0</lowerLevel>
					<upperLevel>11.3</upperLevel>
				</phd>
				<mode>Scanning</mode>
				<activeLength unit="deg">1.021</activeLength>
			</detector>
		</diffractedBeamPath>
		<scan appendNumber="0" mode="Continuous" scanAxis="Gonio" status="Completed">
			<header>
				<startTimeStamp>2024-02-18T09:16:49-08:00</startTimeStamp>
				<endTimeStamp>2024-02-18T09:19:11-08:00</endTimeStamp>
				<author>
					<name>AutomatedUser</name>
				</author>
				<source>
					<applicationSoftware version="1.4b (28)">PANalytical Aeris Instrument Suite</applicationSoftware>
					<instrumentControlSoftware version="2.0.0 20210224">AERIS</instrumentControlSoftware>
					<instrumentID>950485</instrumentID>
				</source>
			</header>
			<dataPoints>
				<positions axis="2Theta" unit="deg">
					<startPosition>10.02173288</startPosition>
					<endPosition>139.98435528</endPosition>
				</positions>
				<positions axis="Omega" unit="deg">
					<startPosition>5.01086644</startPosition>
					<endPosition>69.99217764</endPosition>
				</positions>
				<commonCountingTime unit="seconds">1.551</commonCountingTime>
				<counts unit="counts">383 343 407 355 365 352 354 359 322 328 359 344 322 351 395 341 350 348 319 300 360 304 331 305 315 285 304 346 320 321 318 287 314 338 322 314 303 307 268 285 318 326 273 287 317 290 304 251 304 300 306 273 249 280 278 302 296 291 325 265 277 280 250 218 281 305 249 256 291 246 278 261 261 267 256 283 241 266 239 235 263 247 234 267 277 245 249 241 242 228 249 246 275 223 251 279 253 237 268 248 250 243 238 254 229 233 217 265 241 254 217 238 210 243 254 207 253 274 322 256 317 351 392 463 521 663 757 802 752 571 459 360 338 280 228 208 232 236 245 203 227 222 213 211 221 225 182 207 197 196 198 217 214 185 189 187 183 208 203 191 219 203 208 216 239 214 197 232 208 207 203 197 208 215 202 189 169 219 181 169 193 201 179 181 184 198 171 168 157 186 203 173 166 209 156 185 189 211 152 157 174 133 146 174 176 157 152 166 180 175 175 155 149 149 215 151 159 165 159 163 164 197 194 180 179 172 155 171 172 173 177 170 184 196 198 220 297 324 283 230 222 205 157 155 164 158 168 152 171 162 156 175 122 171 162 153 168 160 158 163 146 195 159 148 144 169 142 158 157 148 146 149 194 167 161 148 151 155 137 143 154 136 137 157 122 155 136 123 129 155 140 167 143 128 149 150 141 175 136 166 142 151 162 150 162 152 166 152 164 149 141 152 182 211 202 206 245 247 221 204 141 151 174 146 161 197 170 178 170 153 158 154 156 150 169 154 166 163 167 138 134 142 170 156 173 161 162 165 176 162 164 180 178 204 222 344 430 569 977 1116 947 560 361 269 264 257 255 253 293 373 503 718 954 1375 1319 993 658 447 316 275 247 248 241 237 303 363 379 458 581 586 592 473 361 300 291 231 210 247 241 286 347 406 494 706 810 808 863 796 816 848 806 526 421 325 305 233 211 209 181 179 179 160 185 118 154 135 119 139 156 119 130 123 132 118 104 112 128 144 139 147 111 113 126 136 108 109 115 134 121 134 121 134 142 137 127 123 134 144 133 112 137 146 153 112 149 141 85 152 120 125 144 119 139 139 161 147 132 190 209 228 284 332 430 573 506 493 411 345 269 189 225 165 150 135 138 132 120 132 99 118 113 122 107 115 104 118 115 99 96 118 121 130 108 114 116 104 127 122 144 127 101 123 128 123 136 163 134 154 137 147 185 197 219 263 343 479 730 1062 1023 820 631 398 344 315 292 261 247 203 183 211 184 177 195 140 145 127 103 127 125 132 104 119 133 136 98 139 125 139 148 155 174 167 157 158 142 94 107 134 118 109 143 153 162 184 226 222 197 173 175 127 127 125 116 115 118 121 99 111 102 106 96 106 98 118 94 81 106 112 102 81 109 91 137 99 126 105 97 89 108 120 121 113 126 132 164 157 184 221 355 419 526 474 400 308 229 142 133 124 116 107 112 137 133 141 139 116 124 112 112 117 166 161 185 189 172 170 185 194 201 254 316 353 508 624 572 438 403 297 230 190 174 142 125 117 107 116 113 107 84 118 110 118 105 108 94 93 121 99 103 114 124 154 150 118 129 149 109 100 99 122 121 122 116 126 127 128 123 130 139 130 118 93 146 156 190 247 259 212 201 150 134 143 134 135 154 149 147 176 141 113 110 112 85 110 88 105 87 96 110 89 100 105 93 101 75 82 82 111 91 82 77 101 96 79 86 86 80 106 95 76 101 88 75 64 83 83 81 84 73 64 69 73 92 97 77 102 88 72 101 71 101 99 108 116 127 135 122 120 106 106 98 89 80 92 91 95 119 106 114 102 115 89 104 103 93 105 105 97 59 75 88 83 82 77 93 107 78 77 71 97 78 106 76 84 82 92 73 78 91 110 99 132 127 134 138 142 126 137 125 115 110 96 125 110 81 80 102 99 83 88 96 88 90 128 136 148 158 164 213 227 280 282 311 248 272 270 280 313 406 444 488 410 388 369 277 244 198 206 163 144 154 164 166 245 218 201 212 148 152 134 111 90 115 123 119 129 125 136 154 160 154 205 212 262 217 202 192 150 155 112 138 134 145 162 141 122 115 155 102 103 83 99 103 113 93 126 108 163 115 132 111 125 120 145 129 174 190 241 400 587 798 672 572 541 448 265 205 158 129 115 108 107 84 113 101 90 89 82 101 92 85 103 81 97 102 96 102 106 121 94 94 90 77 111 105 107 124 116 112 113 110 77 113 85 102 95 96 98 105 119 111 110 135 136 141 120 136 114 91 103 119 113 113 103 125 163 183 256 231 203 214 160 168 125 164 140 157 186 203 220 214 222 226 184 176 151 170 129 140 133 148 131 132 131 117 136 117 132 139 144 156 133 121 134 120 129 125 109 111 100 85 83 93 76 94 105 91 83 94 95 88 110 116 92 80 92 111 102 109 102 110 122 106 108 121 161 172 185 174 148 156 141 131 107 119 96 108 104 101 103 86 107 105 99 108 132 127 190 190 245 194 200 183 197 135 121 94 98 94 91 73 72 93 81 76 91 96 94 80 117 118 125 114 109 137 105 97 119 106 106 121 86 80 85 111 79 87 57 96 74 66 87 77 57 70 81 84 76 76 62 83 104 93 81 82 108 125 106 86 120 111 143 126 128 160 165 181 250 260 235 202 193 189 124 105 95 123 105 67 80 90 89 109 78 105 101 84 123 104 115 112 128 97 95 95 94 87 76 82 66 74 85 70 96 75 82 80 89 93 123 104 104 129 111 164 117 160 140 143 158 117 143 113 114 123 135 112 88 130 134 173 194 230 164 219 179 165 144 141 136 117 114 110 127 108 133 120 94 109 119 132 147 184 204 204 184 195 246 269 325 359 300 315 248 244 197 155 147 124 89 103 94 100 96 83 79 83 91 91 87 101 123 105 150 130 128 114 129 118 109 93 80 68 89 76 76 98 94 74 83 78 70 74 84 80 69 81 71 69 75 83 75 83 93 74 69 74 70 77 71 70 69 62 71 69 67 96 77 87 79 85 87 86 84 81 97 95 94 88 110 107 99 117 111 122 128 142 120 105 125 168 139 125 125 123 110 122 97 87 80 87 98 69 68 79 71 72 100 89 88 95 99 98 120 117 108 116 126 174 167 163 136 142 121 107 111 124 94 71 78 68 74 84 63 82 68 55 78 86 81 73 85 90 71 71 74 81 62 67 83 67 78 78 79 71 90 73 60 70 79 83 86 67 61 73 90 82 69 65 86 63 73 74 91 68 109 85 106 92 104 71 77 96 68 77 75 98 86 81 65 69 59 84 76 76 75 114 87 81 63 84 75 83 79 93 87 100 91 82 72 84 91 69 77 72 86 99 90 116 93 81 100 104 109 105 111 109 98 82 105 89 119 112 110 126 114 119 118 107 102 102 87 108 102 97 79 102 97 100 118 116 135 162 119 127 146 137 162 117 128 147 163 119 128 134 122 130 114 105 109 96 102 88 108 103 80 95 93 95 104 104 90 116 138 151 177 197 219 164 153 122 153 131 122 87 96 92 95 78 65 68 79 86 89 84 84 63 84 87 97 72 72 80 84 92 119 101 97 79 87 90 82 91 80 70 70 60 86 72 97 77 77 76 64 74 73 76 78 81 98 98 103 106 92 87 76 75 77 100 67 76 95 80 72 86 74 65 55 80 100 76 72 79 93 97 103 93 99 74 91 112 106 100 110 102 67 77 89 58 82 69 115 102 69 80 79 82 85 91 86 69 88 78 95 89 96 105 98 132 146 125 106 94 130 107 115 104 104 117 80 92 72 81 89 76 70 67 77 92 84 81 66 78 76 79 100 85 73 80 89 84 88 78 76 64 83 102 81 79 66 57 86 83 68 87 64 71 79 74 53 69 67 72 81 90 77 80 65 57 78 73 61 54 64 57 69 96 86 87 68 68 75 71 62 78 76 87 112 111 112 92 77 79 98 100 81 69 106 74 97 67 71 89 87 77 73 76 86 67 84 92 86 67 98 106 104 107 111 117 119 110 118 111 93 107 93 113 109 87 82 92 99 92 66 95 70 74 80 77 94 104 111 103 125 151 154 172 133 147 119 129 134 151 127 99 91 99 110 80 96 95 85 102 99 110 102 85 120 105 130 161 172 150 128 106 127 137 137 136 123 122 111 85 68 83 78 72 78 75 90 96 53 70 65 68 70 78 82 86 74 101 97 88 94 99 68 65 77 76 76 95 69 78 94 72 72 74 75 79 104 94 74 81 80 96 116 108 93 73 65 67 86 97 80 98 72 72 98 72 66 69 57 73 79 52 66 85 72 72 72 70 83 81 80 55 62 73 72 81 87 68 88 89 79 93 66 79 83 75 85 110 96 82 105 86 103 113 78 106 95 109 106 136 124 108 116 118 107 122 125 119 103 93 113 100 124 95 103 97 112 112 85 104 119 107 112 106 89 104 114 107 91 74 109 117 73 99 73 91 82 74 76 69 81 88 84 84 87 76 72 79 82 70 78 77 74 82 84 74 54 67 69 72 71 67 80 93 92 81 63 77 67 87 96 90 103 90 106 109 99 97 87 93 103 99 99 105 106 95 97 101 87 75 78 65 80 75 77 79 67 94 61 90 75 75 74 73 80 74 87 64 87 89 78 76 101 104 85 72 83 68 80 94 87 79 77 84 85 78 81 94 105 95 70 77 72 86 96 82 90 62 75 93 67 85 70 68 75 74 46 80 81 62 69 73 49 67 75 57 74 77 91 52 77 70 90 87 92 81 89 78 76 80 83 81 74 84 73 69 75 84 75 101 81 84 50 93 83 61 90 66 95 64 84 79 76 77 103 91 75 75 67 76 80 63 63 56 77 65 83 76 82 65 86 80 63 76 62 82 71 82 70 80 68 74 60 79 74 84 66 69 66 63 81 63 73 79 81 58 70 70 83 67 55 63 62 58 66 78 55 58 64 65 66 71 78 77 74 73 90 74 84 80 64 58 81 82 79 58 78 74 86 78 64 85 87 97 104 87 109 119 145 148 155 128 182 156 118 125 123 121 136 128 160 142 135 103 105 92 92 90 96 83 84 85 85 94 94 78 92 101 101 65 79 89 77 100 81 96 83 84 65 67 90 99 71 98 113 63 76 98 61 72 76 89 94 85 95 93 104 86 96 94 94 80 92 72 82 101 69 88 96 84 98 102 80 69 81 83 86 97 97 93 112 105 125 136 127 117 87 99 99 91 118 120 101 129 110 83 86 65 85 79 60 75 81 91 85 99 74 75 93 84 84 71 65 81 82 74 83 66 76 61 67 65 74 66 70 80 61 76 77 71 80 64 76 67 77 89 95 93 90 90 77 98 96 99 135 122 114 106 92 119 103 108 85 102 88 95 108 97 99 115 96 76 108 92 98 113 108 100 108 101 132 152 135 152 143 124 102 124 129 119 106 126 123 130 144 134 99 124 92 116 120 98 110 106 86 104 67 70 85 75 69 96 82 64 70 80 71 83 85 78 79 86 76 66 80 82 80 79 107 82 81 93 70 73 79 76 82 75 84 74 90 84 82 84 92 99 87 93 90 71 98 87 62 60 78 79 79 76 75 75 87 67 72 82 81 89 83 57 75 61 76 55 76 90 88 72 81 73 83 69 86 94 80 87 71 74 86 101 66 71 85 82 96 83 76 86 88 83 80 72 72 67 75 91 99 76 105 100 126 139 161 151 151 140 162 134 129 109 111 120 105 117 98 110 108 127 123 113 85 103 71 95 85 106 94 85 91 94 76 91 94 91 74 73 81 72 95 82 93 50 74 76 83 78 64 75 101 87 84 57 72 61 71 70 61 75 66 72 58 62 69 79 84 63 86 61 59 77 59 86 86 90 62 58 80 55 70 69 68 96 69 81 80 82 74 103 66 72 61 85 62 100 81 69 74 64 73 62 94 77 96 96 65 95 94 78 103 95 95 78 95 73 101 77 65 92 58 91 70 80 101 88 82 71 91 76 106 75 79 88 98 80 94 77 81 95 86 86 77 115 62 76 75 70 72 73 105 98 99 78 82 93 83 75 60 86 82 68 95 85 77 96 81 96 91 60 52 67 78 80 73 63 79 67 100 73 68 77 83 102 84 90 111 88 75 75 92 108 88 97 110 98 98 89 94 118 82 116 147 132 164 158 142 125 124 104 121 118 101 117 112 136 146 120 127 126 123 125 105 75 77 87 105 92 115 96 97 97 97 103 90 111 118 88 103 80 107 93 91 93 101 94 117 91 98 85 102 90 95 87 72 101 98 90 80 92 100 108 69 73 97 91 92 90 100 99 103 97 103 98 127 100 112 107 98 106 98 91 86 93 87 78 103 81 109 82 65 86 82 92 96 83 83 68 84 82 81 67 74 77 76 93 68 70 79 79 102 71 81 87 76 110 89 85 76 92 73 86 95 73 109 95 55 92 92 89 91 77 72 68 97 88 95 69 76 78 85 75 106 99 87 98 89 79 98 107 85 88 77 75 84 82 80 101 110 106 90 123 114 142 162 141 115 111 91 97 101 108 98 107 102 105 96 95 118 120 102 115 116 146 117 105 113 110 94 118 129 116 91 98 99 111 125 124 120 110 105 114 99 92 86 114 116 87 127 107 98 118 104 119 132 99 140 123 107 100 107 114 106 112 92 97 96 131 95 121 88 121 98 87 102 106 104 100 101 97 80 103 91 118 98 117 94 80 94 97 97 96 105 113 97 99 101 106 97 119 94 92 110 105 72 102 103 93 88 93 90 89 89 87 98 92 92 102 82 114 95 127</counts>
			</dataPoints>
		</scan>
	</xrdMeasurement>
</xrdMeasurements>