File: dataset/precursor_mixture/GeO2_La(OH)3_ZrO2_SnO2.12-min.xrdml
<?xml version="1.0"?>
<xrdMeasurements xmlns="http://www.xrdml.com/XRDMeasurement/2.2" xmlns:xsi="http://www.w3.org/2001/XMLSchema-instance" xsi:schemaLocation="http://www.xrdml.com/XRDMeasurement/2.2 http://www.xrdml.com/XRDMeasurement/2.2/XRDMeasurement.xsd" status="Completed" recordIdentifier="{F45C3ADF-CDB2-4EF0-8DE2-0D78DDEE6EF4}">
	<comment>
		<entry/>
	</comment>
	<sample type="To be analyzed">
		<id>dara-24-2</id>
		<name></name>
		<preparedBy></preparedBy>
	</sample>
	<xrdMeasurement measurementType="Scan" status="Completed" sampleMode="Reflection">
		<usedWavelength intended="K-Alpha 1">
			<kAlpha1 unit="Angstrom">1.5405980</kAlpha1>
			<kAlpha2 unit="Angstrom">1.5444260</kAlpha2>
			<kBeta unit="Angstrom">1.3922500</kBeta>
			<ratioKAlpha2KAlpha1>0.5000</ratioKAlpha2KAlpha1>
		</usedWavelength>
		<incidentBeamPath>
			<radius unit="mm">145.00</radius>
			<xRayTube id="1010048" name="Empyrean Cu LFF HR (9430 033 7310x) DK430614">
				<tension unit="kV">40.0</tension>
				<current unit="mA">15.0</current>
				<anodeMaterial>Cu</anodeMaterial>
				<focus type="Line">
					<length unit="mm">12.0</length>
					<width unit="mm">0.4</width>
					<takeOffAngle unit="deg">6.0</takeOffAngle>
				</focus>
			</xRayTube>
			<filter id="20010004" name="Beta-filter Nickel">
				<material>Ni</material>
				<thickness unit="mm">0.020</thickness>
			</filter>
			<sollerSlit id="21010002" name="Soller slits 0.04 rad.">
				<opening unit="rad">0.0400</opening>
			</sollerSlit>
			<mask id="22031000" name="Fixed mask 13 mm">
				<width unit="mm">9.00</width>
			</mask>
			<divergenceSlit id="22120001" name="Divergence slit 1°" xsi:type="fixedDivergenceSlitType">
				<distanceToSample unit="mm">50.00</distanceToSample>
				<height unit="mm">1.52</height>
			</divergenceSlit>
		</incidentBeamPath>
		<beamKnife id="29030100" name="Beam knife low"/>
		<sampleMovement xsi:type="spinningSampleMovementType">
			<spinnerRevolutionTime unit="seconds">1.0</spinnerRevolutionTime>
		</sampleMovement>
		<diffractedBeamPath>
			<radius unit="mm">145.00</radius>
			<antiScatterSlit id="22090040" name="AS slit 9 mm" xsi:type="fixedAntiScatterSlitType">
				<height unit="mm">9.00</height>
			</antiScatterSlit>
			<sollerSlit id="21020003" name="Large Soller slits 0.04 rad.">
				<opening unit="rad">0.0400</opening>
			</sollerSlit>
			<filter id="20030001" name="Large beta-filter Nickel">
				<material>Ni</material>
				<thickness unit="mm">0.020</thickness>
			</filter>
			<detector id="7010019" name="PIXcel1D-Medipix3 detector" xsi:type="rtmsDetectorType">
				<phd unit="keV">
					<lowerLevel>4.0</lowerLevel>
					<upperLevel>11.3</upperLevel>
				</phd>
				<mode>Scanning</mode>
				<activeLength unit="deg">5.020</activeLength>
			</detector>
		</diffractedBeamPath>
		<scan appendNumber="0" mode="Continuous" scanAxis="Gonio" status="Completed">
			<header>
				<startTimeStamp>2024-02-18T09:19:41-08:00</startTimeStamp>
				<endTimeStamp>2024-02-18T09:32:09-08:00</endTimeStamp>
				<author>
					<name>AutomatedUser</name>
				</author>
				<source>
					<applicationSoftware version="1.4b (28)">PANalytical Aeris Instrument Suite</applicationSoftware>
					<instrumentControlSoftware version="2.0.0 20210224">AERIS</instrumentControlSoftware>
					<instrumentID>950485</instrumentID>
				</source>
			</header>
			<dataPoints>
				<positions axis="2Theta" unit="deg">
					<startPosition>9.99043322</startPosition>
					<endPosition>100.09495370</endPosition>
				</positions>
				<positions axis="Omega" unit="deg">
					<startPosition>4.99521661</startPosition>
					<endPosition>50.04747685</endPosition>
				</positions>
				<commonCountingTime unit="seconds">18.249</commonCountingTime>
				<counts unit="counts">3841 3826 3777 3677 3824 3742 3871 3760 3736 3692 3818 3695 3718 3653 3686 3714 3645 3727 3646 3708 3634 3598 3680 3554 3686 3660 3561 3652 3492 3583 3622 3669 3594 3637 3498 3665 3618 3613 3548 3630 3514 3591 3618 3643 3610 3522 3463 3528 3640 3598 3509 3543 3546 3489 3526 3539 3493 3665 3551 3570 3498 3470 3543 3559 3430 3435 3555 3593 3388 3562 3380 3573 3516 3524 3452 3497 3428 3471 3557 3438 3353 3389 3362 3424 3500 3385 3471 3483 3410 3358 3390 3401 3400 3242 3403 3373 3461 3289 3282 3287 3308 3326 3248 3332 3294 3215 3298 3238 3242 3322 3340 3289 3253 3286 3232 3240 3242 3261 3203 3289 3290 3175 3298 3278 3178 3339 3411 3210 3254 3230 3210 3252 3278 3180 3176 3229 3257 3208 3190 3120 3265 3154 3223 3191 3232 3158 3205 3152 3174 3162 3109 3019 3162 3114 3126 3145 3259 3087 3200 3102 3159 3078 3052 3147 3079 3042 3057 3199 3076 3161 3046 3091 3051 3136 3027 3115 3013 3097 2991 3054 3087 2982 2961 3139 2991 3032 3017 3068 3039 3048 3038 3016 3018 3051 3019 3037 3127 3006 2919 3043 2967 3081 2974 3069 2867 3002 2994 2967 3026 3038 2875 2938 2907 3030 2959 3009 2936 3001 2860 2929 2946 3009 3029 3013 2913 2911 2885 2935 2873 2933 2884 2817 2944 2910 2947 2913 2865 2812 2822 2802 2855 2879 2884 2900 2968 2850 2965 2898 2796 2912 2921 2908 2915 2800 2935 2824 2817 2783 2868 2843 2832 2873 2865 2754 2841 2736 2725 2775 2817 2801 2902 2762 2786 2809 2844 2671 2819 2730 2799 2824 2749 2774 2722 2754 2762 2835 2808 2750 2712 2745 2788 2797 2715 2763 2663 2792 2824 2699 2799 2680 2732 2690 2809 2772 2682 2784 2656 2795 2718 2753 2690 2798 2702 2717 2707 2658 2793 2669 2740 2683 2784 2688 2763 2681 2718 2680 2600 2780 2645 2712 2792 2744 2677 2708 2670 2677 2595 2700 2568 2765 2576 2637 2673 2702 2643 2693 2667 2579 2577 2569 2533 2565 2697 2701 2658 2551 2637 2544 2699 2647 2671 2623 2567 2563 2642 2664 2582 2653 2699 2604 2663 2729 2606 2670 2577 2627 2656 2558 2562 2711 2581 2606 2497 2525 2677 2672 2587 2633 2683 2606 2680 2619 2592 2577 2477 2592 2540 2520 2463 2458 2586 2600 2465 2608 2521 2547 2545 2545 2509 2535 2553 2610 2569 2625 2607 2568 2547 2547 2555 2487 2594 2533 2528 2506 2476 2548 2542 2574 2607 2584 2510 2587 2615 2519 2559 2431 2509 2560 2578 2543 2585 2552 2534 2621 2560 2598 2573 2611 2463 2586 2548 2614 2524 2530 2592 2496 2572 2616 2596 2532 2587 2666 2566 2606 2641 2726 2671 2666 2707 2807 2716 2772 2754 2747 2742 2721 2712 2725 2783 2829 2982 2905 2999 2885 3070 2985 3005 2990 3044 3084 3278 3209 3339 3405 3485 3483 3575 3705 3810 3809 3931 4066 4331 4381 4520 4666 4911 5099 5479 5714 5796 6000 6381 6731 6858 7317 7408 7726 8123 8328 8461 8614 8731 8953 8686 8717 8519 8255 8089 7562 7191 6799 6427 6047 5592 5133 4971 4669 4418 4204 4106 3913 3573 3599 3403 3365 3187 3089 3125 3088 3118 3020 2869 2856 2862 2756 2773 2799 2763 2653 2827 2692 2727 2728 2636 2700 2729 2609 2546 2568 2505 2591 2598 2479 2570 2543 2565 2512 2483 2466 2492 2413 2422 2491 2404 2590 2390 2408 2340 2440 2446 2419 2506 2481 2403 2404 2536 2507 2417 2455 2495 2515 2381 2418 2447 2438 2440 2398 2371 2440 2373 2419 2466 2409 2510 2365 2361 2372 2353 2447 2420 2334 2333 2289 2347 2298 2242 2318 2290 2416 2340 2365 2320 2414 2355 2318 2219 2287 2341 2262 2300 2354 2354 2310 2327 2355 2418 2344 2436 2325 2320 2338 2284 2339 2415 2302 2363 2396 2330 2314 2448 2326 2402 2348 2372 2348 2467 2384 2349 2320 2282 2415 2437 2340 2426 2491 2424 2464 2313 2407 2350 2457 2426 2601 2503 2409 2554 2496 2443 2495 2457 2431 2465 2478 2481 2493 2557 2462 2390 2402 2306 2408 2355 2353 2290 2289 2289 2256 2296 2293 2178 2257 2202 2188 2231 2275 2261 2235 2256 2295 2314 2168 2183 2271 2229 2244 2283 2188 2172 2135 2210 2154 2278 2139 2228 2314 2115 2186 2262 2213 2198 2217 2228 2212 2182 2130 2146 2162 2138 2198 2145 2146 2128 2183 2170 2142 2193 2242 2077 2155 2073 2057 2237 2191 2162 2253 2129 2251 2115 2229 2126 2151 2114 2123 2117 2160 2047 2177 2187 2184 2181 2146 2166 2271 2165 2124 2131 2217 2130 2067 2121 2109 2092 2049 2169 2112 2133 2165 2013 2094 2111 2183 2115 2078 2047 2051 2262 2164 2180 2139 2206 2054 2126 2145 2180 2076 2143 2139 2065 2013 2094 2160 2107 2115 2102 2074 2110 2076 2099 2081 2069 2092 2043 2052 2103 2045 2163 2072 2085 2093 2119 2108 2174 2024 2124 2067 2160 1959 2089 2128 2048 2043 2048 2128 2112 2088 2050 1998 2036 1970 2020 2067 2041 2100 2037 2021 2020 2081 1953 2024 2005 2005 2044 2056 2054 1990 1983 1990 1984 2047 1987 2037 2087 2016 2105 2001 2031 1922 2058 2039 2071 2071 2070 2046 1935 1979 2083 2029 2030 2045 2016 2034 2002 2048 2065 1989 1952 1939 2005 1975 2041 2105 1980 2137 1960 1979 2063 1964 2038 2031 2058 1992 2010 2015 1978 1974 2012 1956 1986 1954 1990 1960 2006 1992 2065 2039 2107 2115 2140 2013 2013 1974 1976 2060 1922 2069 2085 2019 2122 2129 2131 2146 2218 2174 2200 2263 2261 2306 2370 2467 2499 2502 2473 2710 2798 2832 2885 3055 3140 3247 3340 3483 3577 3609 3692 3610 3589 3502 3550 3378 3158 2885 2809 2710 2641 2494 2299 2368 2241 2153 2064 2141 2155 2024 2044 2041 2097 2032 1973 1989 1993 2045 1903 2019 2072 2036 1979 1955 1966 1975 2020 1979 2048 1999 1947 1901 1945 1969 2008 1935 1882 1978 1925 1885 1942 1928 1942 1997 1965 1882 1864 1892 1812 1886 1868 1891 2008 1876 2000 1945 1925 1787 1959 1887 1828 1902 1818 1950 1909 1925 1919 1962 1730 1947 1852 1920 1887 1849 1866 1810 1887 1901 1878 1879 1826 1896 1915 1887 1824 1936 1893 1852 1846 1874 1886 1903 1910 1848 1932 1871 1919 1885 1906 1887 1778 1890 1861 1905 1866 1906 1885 1825 1904 1822 1821 1803 1907 1759 1870 1818 1839 1882 1778 1876 1895 1828 1856 1841 1815 1772 1871 1864 1863 1793 1828 1778 1742 1844 1801 1840 1778 1824 1816 1850 1845 1847 1864 1840 1819 1800 1842 1876 1792 1841 1828 1796 1806 1767 1828 1779 1705 1822 1708 1860 1782 1776 1759 1780 1793 1818 1799 1771 1776 1821 1771 1861 1787 1928 1782 1722 1740 1741 1808 1817 1757 1742 1834 1806 1791 1774 1803 1812 1854 1814 1793 1798 1818 1742 1828 1757 1902 1844 1819 1654 1719 1746 1752 1769 1759 1803 1803 1775 1776 1766 1724 1686 1748 1745 1835 1781 1765 1693 1780 1787 1828 1862 1791 1760 1769 1752 1730 1731 1774 1840 1816 1769 1670 1727 1817 1726 1708 1875 1763 1762 1779 1740 1749 1822 1812 1741 1817 1797 1823 1782 1788 1777 1760 1745 1872 1707 1833 1849 1837 1834 1772 1758 1877 1768 1786 1875 1794 1820 1803 1729 1799 1828 1810 1764 1780 1823 1822 1756 1795 1813 1781 1807 1714 1814 1829 1837 1779 1815 1879 1816 1868 1880 1910 1943 1940 1971 2122 2044 2085 2111 2147 2090 2221 2214 2282 2384 2404 2371 2407 2495 2592 2663 2723 2795 2705 2789 2646 2716 2670 2559 2493 2362 2316 2217 2194 2264 2150 2060 2090 2039 2073 2133 2168 2065 2020 2071 2059 2089 2176 2116 2167 2229 2146 2217 2286 2258 2255 2344 2337 2431 2390 2372 2327 2291 2297 2387 2154 2206 2157 2102 2073 1990 1995 1923 1917 1883 1951 1840 1814 1854 1786 1805 1828 1766 1780 1777 1843 1709 1769 1789 1753 1725 1747 1735 1698 1780 1734 1717 1723 1743 1753 1804 1742 1781 1709 1752 1702 1790 1786 1717 1732 1754 1719 1760 1719 1719 1756 1786 1738 1779 1857 1769 1775 1758 1867 1811 1778 1776 1871 1873 1814 1809 1784 1791 1833 1907 1790 1868 1855 1831 1944 1951 1834 1950 1912 1876 1809 1819 1846 1930 1924 1976 1949 1940 1993 1981 2017 2046 1987 1977 2036 2092 2102 2112 2150 2212 2178 2219 2290 2342 2320 2325 2436 2511 2615 2729 2837 2914 3049 3309 3412 3662 4036 4237 4478 5007 5382 5931 6393 7281 7829 8815 9614 10461 11066 11948 12301 12546 12559 12109 11689 11049 10108 9242 8722 7697 6848 6200 5374 4974 4394 4085 3804 3507 3335 3327 3088 3025 3044 3018 3027 3003 2881 2890 3017 2948 2970 3053 3149 3153 3206 3276 3357 3514 3574 3698 3943 4078 4349 4651 4851 5268 5581 6078 6503 7127 7843 8410 9141 9999 10659 11647 12707 13239 13941 15013 15231 15154 15140 14859 14100 13293 12373 11730 10492 9920 8733 7953 7219 6462 5748 5195 4861 4498 4306 3927 3776 3646 3420 3361 3389 3188 3152 2976 3043 3020 2952 2973 2956 2845 2911 2969 2939 2895 3047 3009 3086 3055 3312 3188 3368 3506 3462 3842 3952 4250 4276 4645 4724 4920 5262 5523 5712 5928 6159 6380 6645 6771 6851 6754 6781 6745 6778 6523 6306 6125 5949 5683 5452 5101 5010 4647 4519 4219 4089 3769 3755 3577 3365 3393 3170 3081 3032 3074 3007 2930 2914 2830 2872 2844 2857 2817 2793 2823 2815 2920 2969 3026 3168 3196 3278 3469 3478 3581 3720 3937 4177 4307 4496 4751 5016 5428 5667 5912 6159 6795 7205 7550 8059 8270 8713 8791 9184 9382 9417 9705 9822 9708 9377 9396 9200 9329 8820 9016 8926 8947 8950 8713 9106 9349 8997 9127 9175 9149 9147 8937 8609 8339 7860 7706 7169 6619 6356 5752 5428 5157 4572 4298 3983 3743 3554 3372 3119 3007 2877 2773 2694 2710 2599 2512 2577 2472 2347 2322 2284 2258 2172 2236 2125 2080 2094 2060 2006 2009 1910 1964 1935 1922 1921 1896 1869 1862 1842 1897 1804 1764 1774 1725 1728 1878 1718 1731 1719 1710 1734 1706 1673 1756 1747 1734 1757 1717 1724 1673 1701 1612 1739 1690 1624 1659 1663 1496 1591 1597 1594 1597 1608 1672 1630 1641 1650 1585 1662 1622 1603 1642 1638 1573 1639 1558 1550 1559 1743 1566 1668 1591 1545 1557 1571 1594 1596 1558 1569 1564 1559 1573 1538 1543 1630 1563 1579 1520 1601 1534 1508 1466 1606 1554 1517 1596 1584 1466 1527 1540 1492 1553 1468 1531 1533 1536 1533 1588 1529 1490 1538 1550 1559 1477 1511 1614 1554 1535 1396 1457 1487 1523 1536 1474 1575 1586 1472 1452 1521 1505 1458 1465 1487 1620 1470 1539 1564 1509 1535 1486 1489 1438 1483 1436 1476 1496 1512 1558 1456 1560 1543 1510 1434 1445 1500 1498 1431 1579 1529 1526 1519 1539 1507 1438 1477 1490 1441 1534 1481 1547 1506 1499 1483 1537 1493 1505 1430 1622 1500 1559 1446 1517 1534 1466 1555 1576 1558 1635 1563 1621 1560 1534 1535 1567 1574 1543 1450 1527 1527 1491 1464 1573 1519 1549 1521 1515 1497 1666 1533 1573 1540 1554 1626 1519 1617 1490 1530 1474 1552 1564 1656 1619 1519 1633 1583 1601 1648 1699 1592 1660 1626 1709 1680 1590 1730 1774 1818 1766 1796 1839 1791 1893 1935 1951 1939 1936 2055 2092 2106 2234 2229 2345 2369 2393 2603 2620 2810 2973 3032 3167 3374 3497 3776 3931 4262 4542 4807 4925 5458 5518 5853 5885 5998 6034 6081 6236 5946 5943 5656 5523 5247 5127 4910 4692 4391 4291 3932 3944 3580 3397 3261 3006 3016 2906 2787 2596 2446 2351 2364 2152 2180 2047 2064 1959 2005 1887 1933 1830 1825 1719 1709 1678 1667 1680 1678 1594 1529 1568 1567 1604 1480 1683 1559 1562 1489 1478 1502 1455 1491 1483 1475 1490 1393 1477 1372 1414 1373 1481 1448 1466 1458 1387 1395 1403 1324 1441 1296 1372 1351 1357 1403 1277 1422 1336 1410 1448 1360 1401 1409 1402 1365 1329 1421 1361 1397 1462 1399 1378 1372 1375 1338 1359 1296 1307 1384 1317 1401 1434 1361 1355 1460 1347 1324 1396 1421 1381 1387 1444 1317 1445 1355 1384 1419 1386 1459 1428 1388 1386 1367 1340 1415 1388 1348 1488 1445 1423 1408 1410 1391 1414 1458 1368 1321 1419 1426 1437 1495 1418 1375 1435 1416 1387 1468 1408 1507 1441 1497 1484 1441 1440 1486 1508 1486 1544 1548 1440 1468 1519 1589 1500 1478 1583 1513 1585 1675 1621 1644 1616 1718 1675 1691 1648 1768 1728 1820 1750 1826 1766 1872 1853 1965 1917 2035 1928 2045 1995 2108 2133 2281 2320 2553 2442 2604 2749 2912 3137 3298 3621 3775 4133 4459 4931 5259 5882 6355 6902 7713 8643 9208 10027 10787 11439 11724 12245 12275 11934 11622 10893 10442 10007 9604 8967 8343 7778 7035 6444 6008 5440 4893 4630 4302 4143 3963 3942 3821 3634 3845 3596 3534 3538 3525 3325 3317 3291 3112 3073 2902 2999 2931 2736 2754 2654 2515 2416 2474 2400 2414 2421 2430 2467 2453 2344 2326 2369 2250 2246 2129 2122 2120 2024 2032 2009 1930 1963 1823 1773 1724 1701 1734 1611 1679 1588 1578 1497 1563 1531 1498 1568 1444 1513 1455 1541 1527 1522 1516 1436 1416 1423 1416 1415 1390 1374 1421 1435 1361 1467 1424 1396 1454 1477 1383 1279 1441 1403 1412 1441 1406 1447 1410 1361 1486 1488 1474 1480 1498 1571 1520 1590 1565 1483 1594 1638 1652 1701 1680 1782 1865 1852 1966 1941 2019 2056 2147 2098 2218 2150 2150 2119 2172 2153 2036 1927 1917 1865 1842 1871 1783 1692 1608 1538 1575 1506 1552 1583 1490 1420 1439 1433 1422 1378 1395 1427 1379 1467 1347 1354 1392 1331 1427 1481 1441 1414 1461 1376 1501 1475 1553 1538 1432 1573 1710 1644 1728 1761 1760 1909 1967 2090 2073 2276 2319 2430 2595 2648 2692 2896 2747 2961 2822 2736 2682 2702 2674 2507 2355 2308 2230 2132 2118 1954 1941 1747 1754 1637 1641 1607 1533 1558 1470 1456 1445 1435 1296 1333 1325 1367 1351 1282 1276 1366 1307 1331 1311 1254 1250 1273 1307 1272 1190 1254 1206 1255 1263 1257 1334 1264 1278 1306 1260 1289 1249 1190 1225 1260 1211 1243 1251 1197 1226 1244 1194 1266 1199 1271 1231 1246 1211 1257 1272 1235 1174 1189 1131 1208 1272 1211 1193 1203 1199 1199 1213 1225 1243 1308 1226 1238 1199 1215 1218 1213 1256 1242 1194 1201 1192 1139 1251 1222 1260 1214 1235 1252 1218 1295 1219 1203 1210 1192 1219 1160 1152 1221 1227 1167 1208 1248 1216 1239 1251 1224 1232 1262 1251 1228 1242 1205 1251 1276 1268 1271 1294 1241 1262 1287 1307 1368 1375 1365 1313 1290 1382 1369 1380 1371 1418 1401 1405 1409 1431 1509 1483 1421 1532 1501 1512 1447 1557 1564 1682 1613 1766 1782 1859 1932 2010 2206 2181 2383 2539 2733 2897 3204 3419 3874 4166 4359 4729 5124 5232 5641 5692 5922 5798 5864 5723 5712 5663 5250 5059 4734 4498 4174 3810 3712 3473 3099 2914 2738 2446 2275 2153 1945 2056 1788 1741 1705 1666 1521 1552 1583 1594 1490 1496 1449 1443 1446 1490 1467 1454 1301 1446 1471 1476 1545 1508 1586 1522 1550 1487 1494 1537 1566 1599 1638 1648 1609 1654 1638 1603 1512 1508 1525 1521 1582 1472 1557 1497 1464 1519 1556 1504 1436 1485 1431 1530 1490 1459 1564 1490 1453 1499 1630 1616 1574 1646 1593 1761 1770 1786 1932 1942 2033 2002 2035 2053 2024 2060 2038 2182 2006 1992 2073 2056 1980 2148 1967 1959 2036 2071 2029 2048 2072 2215 2156 2304 2202 2430 2455 2617 2701 2874 3009 3116 3430 3616 3699 4145 4222 4589 4981 5195 5591 5891 6058 6365 6413 6571 6603 6730 6699 6641 6508 6168 6052 6058 5641 5632 5092 4912 4750 4528 4241 3936 3739 3484 3229 3068 2870 2815 2649 2591 2450 2307 2258 2093 2108 2008 2026 1848 1919 1778 1658 1714 1658 1635 1660 1488 1538 1532 1488 1543 1600 1447 1487 1337 1463 1465 1406 1343 1465 1330 1421 1354 1314 1251 1383 1258 1230 1314 1256 1365 1252 1246 1314 1218 1231 1196 1284 1227 1229 1250 1269 1249 1237 1217 1249 1259 1285 1216 1245 1193 1231 1243 1287 1269 1190 1235 1276 1275 1252 1280 1397 1396 1295 1288 1346 1359 1438 1380 1343 1489 1458 1489 1544 1424 1528 1558 1660 1675 1653 1739 1694 1733 1816 1829 1904 1823 1737 1839 1699 1773 1756 1625 1699 1670 1614 1614 1551 1533 1525 1424 1419 1518 1369 1383 1420 1381 1401 1369 1438 1407 1370 1401 1354 1363 1326 1460 1351 1465 1471 1502 1515 1513 1516 1503 1585 1436 1566 1480 1475 1542 1488 1504 1467 1525 1407 1501 1479 1444 1515 1515 1542 1441 1395 1462 1470 1494 1506 1454 1415 1481 1446 1461 1405 1388 1405 1386 1361 1423 1420 1466 1433 1436 1481 1454 1486 1476 1565 1551 1660 1729 1889 1931 2024 2224 2397 2534 2587 2803 2821 3043 3013 2941 2850 2741 2641 2602 2612 2451 2370 2379 2303 2225 2039 2038 1858 1857 1754 1673 1695 1612 1597 1527 1613 1530 1573 1576 1690 1633 1667 1731 1689 1680 1861 1785 1836 1905 1769 1845 1876 1995 1885 1938 1886 1832 1889 1906 1851 1754 1780 1679 1646 1725 1613 1590 1532 1496 1546 1509 1455 1518 1354 1381 1374 1354 1407 1334 1316 1314 1344 1283 1288 1315 1325 1341 1352 1363 1401 1303 1359 1298 1356 1279 1261 1315 1245 1323 1214 1260 1208 1173 1208 1119 1181 1171 1138 1136 1070 1166 1131 1125 1096 1178 1094 1119 1103 1130 1116 1078 1035 1133 1064 1095 1072 1048 1060 1052 1040 1055 1022 1103 1050 1032 1015 1041 1029 1051 1001 1028 1027 1028 1053 1026 1031 1064 1006 1042 1028 1073 1087 1066 1031 1029 1015 1041 1109 1045 1050 1049 984 1019 1029 1010 1053 1029 1075 1089 996 1021 1020 1060 1069 1030 1032 1058 1059 1058 1091 1028 1028 1031 1025 1070 1071 987 1077 1063 1105 1090 1090 1013 1029 1016 1113 1074 1015 1123 1051 1034 1089 961 1012 1057 1035 1030 1068 1123 1042 1060 985 1014 994 954 1023 960 1119 976 935 1058 979 1012 1040 950 976 1038 1035 1066 1120 1052 1028 1030 1041 1015 1129 1058 1080 1028 1043 1037 984 1017 1071 1058 993 994 1037 1045 1012 1037 1101 1033 1058 1022 1090 961 997 1037 1020 1059 1033 1023 1033 1047 1080 1050 1061 1068 1060 1052 1035 1070 1112 1151 1143 1192 1071 1196 1158 1180 1140 1175 1170 1275 1283 1289 1262 1405 1406 1494 1491 1532 1467 1545 1523 1506 1593 1468 1559 1540 1492 1445 1441 1413 1424 1452 1339 1317 1338 1248 1346 1249 1263 1169 1275 1150 1138 1126 1106 1132 1103 1189 1087 1139 1103 1095 1082 1094 1141 1067 1130 1140 1073 1165 1176 1150 1123 1177 1099 1142 1071 1198 1179 1160 1236 1201 1233 1216 1199 1237 1262 1327 1332 1326 1335 1383 1363 1347 1323 1374 1347 1313 1282 1267 1343 1334 1318 1200 1291 1264 1219 1212 1186 1171 1151 1102 1064 1058 1045 1108 1047 1069 1166 1092 1090 1075 1038 1043 1038 1097 991 1049 1090 1054 1013 1036 1032 1060 1091 1026 1051 980 1075 1014 1042 1022 1033 1029 982 1069 990 1006 1036 987 1055 1043 1022 1036 1022 1000 1014 1006 1013 960 1016 1071 1003 1029 998 947 976 997 1046 1003 1047 952 1016 1042 1003 1024 1056 1041 1046 1105 1034 1031 1025 1011 1036 1059 1075 1105 988 1058 1028 1028 1090 1045 1091 1035 1030 1032 1047 1065 1059 1077 1087 1137 1137 1132 1079 1042 1051 1122 1086 1139 1081 1151 1215 1209 1194 1214 1299 1256 1248 1245 1394 1352 1399 1435 1455 1467 1545 1577 1556 1593 1695 1717 1624 1739 1744 1771 1674 1666 1659 1634 1699 1696 1593 1659 1576 1584 1396 1503 1464 1437 1361 1373 1279 1308 1398 1245 1194 1286 1201 1192 1203 1225 1236 1206 1243 1139 1232 1119 1200 1133 1207 1115 1179 1158 1125 1108 1212 1103 1168 1195 1141 1149 1157 1231 1121 1260 1191 1212 1095 1179 1165 1188 1173 1226 1280 1275 1230 1219 1205 1263 1264 1368 1267 1348 1399 1400 1393 1449 1398 1473 1421 1449 1466 1636 1615 1590 1640 1672 1741 1767 1876 1837 1982 2069 1989 2198 2242 2365 2371 2519 2521 2539 2594 2771 2768 2857 2947 3020 3111 3255 3250 3257 3288 3384 3314 3248 3209 3151 3117 3125 3209 3088 3030 3186 3054 3222 3185 3262 3241 3233 3281 3424 3388 3512 3715 3666 3769 4051 4167 4364 4598 4709 5090 5101 5336 5501 5533 5721 5619 5589 5540 5472 5248 4927 4893 4714 4759 4556 4477 4350 4255 3944 3860 3637 3446 3311 2981 2925 2853 2614 2685 2496 2527 2370 2249 2249 2159 2049 2092 2031 1943 1921 1913 1924 1881 1841 1881 1823 1831 1843 1867 1741 1740 1878 1866 1923 1891 2004 1937 2006 2073 2151 2233 2269 2268 2317 2357 2179 2103 2213 2151 2099 2056 1982 1943 1971 1867 1768 1837 1716 1824 1652 1661 1622 1586 1542 1504 1480 1391 1462 1388 1431 1371 1340 1291 1380 1381 1359 1377 1341 1331 1387 1328 1362 1404 1338 1356 1397 1372 1420 1495 1415 1510 1508 1569 1530 1551 1576 1742 1690 1768 1755 1792 1760 1805 1875 1855 1918 1951 2001 2001 2017 2039 2182 2216 2303 2388 2336 2547 2450 2497 2499 2656 2626 2597 2502 2521 2424 2360 2320 2359 2312 2267 2193 2113 2183 2094 2036 1914 1870 1843 1716 1733 1613 1562 1584 1534 1602 1483 1531 1512 1578 1582 1627 1493 1595 1652 1607 1714 1641 1727 1805 1786 1796 1735 1784 1786 1744 1718 1698 1688 1704 1614 1664 1710 1689 1586 1579 1546 1563 1530 1415 1390 1405 1301 1392 1315 1315 1305 1247 1294 1280 1251 1253 1175 1174 1265 1219 1177 1233 1234 1202 1235 1218 1241 1266 1214 1318 1283 1224 1285 1303 1326 1328 1362 1377 1311 1416 1452 1493 1455 1494 1385 1534 1363 1470 1456 1442 1453 1456 1391 1445 1486 1534 1504 1500 1570 1552 1470 1496 1528 1525 1590 1549 1627 1621 1572 1665 1598 1655 1693 1846 1770 1924 1818 1922 2120 2191 2184 2391 2637 2882 3075 3354 3570 3952 4394 4987 5470 6071 6747 7443 8085 8922 9221 9298 9242 8982 8532 8077 7358 7033 6596 6503 6387 6354 6332 6362 6020 5768 5297 4907 4429 4006 3565 3253 3021 2730 2519 2356 2252 2201 2048 1935 1882 1766 1734 1615 1577 1532 1430 1502 1470 1406 1375 1336 1322 1337 1304 1260 1290 1265 1282 1146 1325 1157 1141 1193 1190 1136 1194 1148 1189 1117 1183 1108 1073 1034 1079 1051 1068 1121 1060 1054 1153 1081 1050 1054 1063 1112 1176 1065 1076 1079 1076 1068 1074 1072 1029 1044 1021 1042 1051 1054 1017 1046 1057 1038 1059 1100 1061 1047 1054 1079 1087 1115 1110 1130 1147 1105 1165 1125 1215 1281 1295 1251 1350 1276 1252 1353 1199 1252 1157 1244 1181 1189 1206 1181 1254 1217 1207 1243 1157 1181 1194 1183 1265 1264 1220 1241 1320 1281 1346 1438 1421 1447 1512 1558 1623 1593 1562 1631 1510 1511 1473 1515 1446 1416 1385 1447 1417 1450 1417 1350 1326 1371 1331 1235 1191 1245 1109 1209 1095 1163 1085 1116 1131 1070 1101 1109 1087 1035 1132 1161 1105 1104 1105 1164 1111 1163 1084 1157 1096 1128 1154 1226 1139 1176 1163 1251 1188 1150 1221 1250 1251 1338 1279 1280 1293 1319 1421 1359 1445 1422 1494 1557 1610 1615 1626 1647 1655 1670 1645 1588 1581 1596 1550 1494 1471 1463 1492 1442 1442 1376 1431 1366 1394 1426 1438 1262 1306 1275 1235 1269 1243 1285 1251 1246 1307 1162 1202 1258 1236 1216 1301 1305 1276 1251 1305 1311 1306 1326 1393 1414 1421 1464 1605 1620 1624 1676 1798 1841 2076 2140 2305 2460 2627 2856 2886 3052 3020 2949 2889 2779 2609 2620 2341 2368 2372 2290 2303 2299 2233 2402 2269 2240 2149 2038 1994 1895 1809 1766 1718 1696 1637 1623 1662 1659 1634 1666 1725 1762 1730 1755 1801 1861 1813 1966 2054 2076 2140 2126 2167 2189 2318 2358 2424 2427 2559 2382 2399 2483 2419 2360 2433 2501 2453 2391 2449 2433 2421 2386 2243 2178 2210 2174 2102 2121 2031 1935 2045 1870 1983 1887 1885 1869 1849 1917 1823 1779 1712 1748 1667 1613 1607 1603 1659 1537 1542 1551 1561 1542 1500 1586 1573 1592 1521 1589 1559 1571 1585 1545 1627 1530 1600 1556 1520 1596 1496 1583 1501 1505 1566 1453 1428 1537 1487 1518 1560 1488 1596 1527 1540 1496 1490 1543 1505 1513 1487 1540 1575 1536 1701 1607 1684 1662 1715 1666 1687 1723 1697 1753 1713 1727 1676 1668 1678 1598 1590 1489 1582 1500 1414 1426 1438 1455 1460 1366 1460 1315 1319 1287 1314 1239 1202 1291 1225 1214 1146 1118 1225 1209 1142 1090 1048 1164 1073 1151 1074 1077 1095 1076 1069 1102 1056 1116 1123 1069 1049 1112 1068 1085 1056 1072 1116 1134 1083 1086 1082 1121 1127 1148 1108 1152 1134 1075 1098 1169 1128 1216 1160 1210 1205 1230 1276 1274 1283 1323 1423 1344 1351 1338 1441 1381 1403 1440 1315 1356 1367 1336 1322 1301 1299 1298 1307 1307 1285 1334 1229 1233 1172 1227 1291 1232 1243 1197 1196 1178 1193 1173 1165 1179 1189 1202 1128 1198 1237 1214 1250 1202 1296 1285 1288 1219 1254 1363 1371 1418 1452 1436 1413 1560 1599 1749 1740 1878 1884 1967 1997 2175 2197 2294 2219 2227 2262 2120 2204 2058 1999 2066 2036 2017 1957 1932 1944 1859 1860 1878 1895 1776 1685 1652 1659 1650 1518 1559 1415 1516 1451 1365 1383 1337 1284 1263 1317 1282 1284 1291 1341 1295 1240 1322 1344 1324 1320 1346 1221 1328 1338 1292 1211 1239 1201 1261 1225 1197 1225 1163 1233 1271 1211 1262 1192 1168 1240 1186 1209 1260 1294 1339 1288 1248 1315 1321 1288 1275 1385 1373 1424 1463 1494 1554 1695 1766 1909 1869 2028 2179 2362 2436 2504 2610 2643 2606 2617 2439 2382 2377 2285 2132 2058 2107 2052 2046 2045 2107 2083 2106 2013 1956 1846 1722 1682 1573 1477 1480 1426 1354 1285 1300 1259 1293 1202 1270 1240 1153 1158 1177 1193 1205 1164 1110 1094 1078 1092 1107 1108 1085 1047 1096 1135 1056 1035 987 1085 1114 1063 1057 1080 985 1058 1065 1059 1040 1060 1040 1045 1037 1055 1060 1066 1077 1144 1088 1065 1138 1062 1095 1123 1156 1113 1129 1228 1210 1255 1324 1258 1284 1440 1435 1442 1463 1444 1500 1444 1461 1415 1384 1322 1443 1430 1378 1429 1428 1431 1426 1409 1464 1442 1512 1347 1489 1409 1366 1403 1431 1379 1416 1318 1414 1353 1304 1305 1274 1275 1237 1223 1237 1227 1273 1270 1203 1158 1204 1169 1170 1049 1137 1106 1122 1106 1110 1065 1115 1060 1046 997 1025 980 1010 961 984 984 980 1028 985 1031 1020 998 1038 992 969 981 1024 993 942 978 924 980 1052 952 993 975 976 982 956 937 962 957 975 954 963 943 989 958 989 1011 933 1005 971 937 906 920 1003 998 955 953 928 944 972 1009 914 1008 958 968 1040 966 984 986 1045 960 1027 982 1024 1064 1016 993 1046 1052 1095 1068 1027 1096 1067 991 1066 1116 1099 1056 1128 1164 1183 1190 1238 1280 1274 1239 1323 1241 1285 1340 1340 1297 1270 1243 1273 1281 1231 1302 1330 1273 1371 1320 1487 1394 1451 1405 1435 1498 1513 1598 1590 1646 1655 1647 1655 1629 1728 1658 1705 1623 1676 1641 1778 1741 1866 1916 2042 2210 2398 2517 2676 2726 2796 2855 3020 2896 2808 2657 2566 2500 2337 2290 2264 2267 2317 2269 2280 2283 2296 2242 2188 2168 1998 1930 1939 1763 1720 1692 1576 1556 1528 1475 1436 1382 1299 1285 1233 1323 1171 1251 1167 1187 1156 1150 1186 1132 1125 1110 1095 1127 1069 1101 1083 1120 1058 1125 1115 1038 1089 1133 1059 1042 1111 1040 1113 1055 1076 1060 1173 1117 1123 1148 1143 1106 1119 1112 1184 1163 1173 1162 1175 1113 1232 1232 1314 1267 1300 1311 1310 1359 1382 1503 1439 1479 1398 1426 1370 1358 1291 1376 1282 1331 1242 1333 1203 1195 1299 1220 1235 1218 1252 1205 1192 1160 1168 1109 1079 1082 1102 1077 1094 1069 1012 1099 1042 1076 968 993 1030 1014 1085 1081 981 1053 989 1030 1005 964 952 1012 966 1011 1007 1008 964 1031 978 1008 947 1025 987 1028 999 1062 1083 1102 1067 1050 1101 1067 1063 1116 1067 1087 1088 1064 1121 1117 1169 1121 1171 1211 1120 1289 1190 1248 1194 1307 1233 1361 1344 1357 1378 1309 1447 1388 1498 1557 1492 1539 1559 1646 1679 1654 1681 1691 1672 1663 1793 1663 1691 1704 1721 1671 1775 1715 1725 1727 1829 1736 1750 1681 1629 1679 1668 1618 1598 1577 1557 1533 1577 1520 1557 1550 1634 1481 1497 1563 1450 1477 1475 1395 1413 1369 1338 1336 1369 1330 1327 1352 1332 1394 1316 1389 1444 1444 1413 1351 1404 1435 1403 1466 1508 1533 1557 1565 1715 1731 1902 1887 2111 2175 2207 2322 2508 2602 2568 2637 2596 2474 2398 2232 2216 2126 2020 2134 1970 1997 2055 2017 2103 2194 2125 2156 2129 2022 1990 1872 1941 1767 1823 1748 1687 1591 1638 1568 1528 1517 1507 1578 1447 1436 1517 1400 1396 1360 1425 1388 1428 1409 1405 1430 1362 1378 1309 1351 1360 1357 1310 1323 1338 1353 1316 1319 1400 1363 1324 1289 1335 1328 1301 1268 1327 1388 1423 1363 1386 1474 1415 1503 1469 1500 1407 1537 1582 1632 1721 1788 1773 1866 2038 2089 2170 2398 2405 2498 2547 2547 2569 2478 2432 2407 2332 2407 2336 2281 2328 2492 2490 2563 2765 2878 3109 3404 3390 3750 3819 3838 4046 4188 4257 4131 4050 4031 3853 3771 3578 3413 3230 3206 3119 3041 2986 2890 2907 2910 2823 2837 2795 2717 2683 2570 2411 2374 2144 2059 2011 1919 1793 1658 1601 1563 1492 1425 1329 1317 1304 1298 1277 1224 1190 1121 1181 1127 1111 1132 1139 1081 1093 1118 1116 1089 1092 1070 1035 1038 1043 1032 1028 1002 1060 985 998 1020 1039 1010 1034 995 981 1035 1015 973 1042 1011 1046 984 987 1007 983 1086 1119 1082 1061 1087 1203 1163 1223 1296 1363 1387 1405 1480 1576 1563 1638 1595 1573 1467 1440 1505 1410 1347 1336 1306 1413 1275 1301 1332 1260 1279 1335 1283 1351 1253 1337 1236 1224 1195 1121 1134 1110 1128 1180 1092 1083 940 1014 976 1016 971 1063 949 990 984 966 956 982 906 971 857 900 874 957 957 901 911 952 866 931 909 900 998 923 905 872 824 955 974 903 956 917 995 942 932 848 900 882 923 893 900 881 909 932 911 914 888 882 910 870 912 841 922 873 901 885 852 908 871 896 874 941 882 932 887 922 829 957 820 903 916 875 912 915 846 867 873 919 844 954 906 969 903 886 869 881 882 896 937 875 827 861 832 885 912 902 911 924 976 850 872 891 917 868 927 891 884 842 908 898 879 936 850 874 919 835 892 928 968 860 874 900 949 929 942 931 915 934 953 987 913 932 929 921 961 965 938 961 961 993 1055 976 1022 1021 959 963 993 959 972 1069 994 1023 987 1008 971 987 988 1014 990 1026 1058 1007 965 1025 996 982 940 1007 1041 1042 1004 1049 1012 1016 1058 1024 1031 1051 1025 1052 1065 1065 1048 1089 1077 1055 1106 1112 1138 1088 1132 1176 1166 1146 1241 1192 1206 1301 1215 1343 1343 1362 1372 1442 1369 1421 1480 1453 1473 1501 1439 1550 1499 1557 1464 1495 1417 1517 1453 1439 1401 1467 1419 1447 1392 1401 1463 1302 1394 1364 1472 1422 1419 1441 1467 1441 1431 1600 1640 1627 1708 1655 1680 1746 1580 1551 1550 1496 1467 1365 1370 1307 1347 1298 1340 1347 1327 1372 1282 1401 1303 1291 1291 1326 1238 1278 1186 1229 1208 1094 1079 1078 1077 1067 1023 1036 980 974 1065 969 1034 1020 994 989 978 943 954 1015 976 1020 983 970 1010 963 1008 1030 1055 997 940 995 1013 1001 961 1049 1018 1005 986 1050 978 1109 1087 1071 1165 1033 1107 1087 1078 1156 1111 1173 1179 1173 1151 1184 1203 1189 1196 1162 1187 1242 1204 1276 1230 1241 1303 1307 1256 1295 1307 1300 1335 1316 1283 1372 1407 1380 1381 1396 1324 1399 1506 1544 1638 1615 1786 1839 1867 1920 2085 1899 2009 1963 1979 1838 1717 1639 1609 1625 1525 1522 1465 1482 1458 1436 1589 1476 1545 1533 1559 1466 1480 1380 1336 1311 1316 1244 1197 1189 1153 1158 1073 1062 1122 1026 1034 1084 1039 1062 979 950 1005 1015 931 958 1062 927 986 973 950 883 953 918 932 965 971 960 942 973 951 939 892 858 955 981 1012 953 961 925 1037 907 955 912 974 986 977 973 964 998 952 947 934 915 972 995 949 979 947 969 949 932 972 965 871 1016 888 951 951 999 955 903 910 1014 853 900 928 953 895 990 942 909 962 1034 1033 1002 1025 960 927 984 938 990 931 1041 1049 961 1012 1020 962 977 1021 1072 992 1021 975 953 986 938 1029 1025 1009 1003 997 1060 996 1003 949 959 1017 966 961 975 970 1010 913 954 941 918 966 932 934 927 920 895 924 944 911 888 958 836 912 912 895 835 913 895 904 870 876 948 944 881 934 859 892 869 939 827 819 855 883 875 900 869 943 906 871 888 864 951 883 949 878 880 905 824 867 917 934 840 915 911 880 936 908 911 937 940 962 968 990 1027 1046 1056 1067 1074 1077 1185 1182 1249 1215 1219 1248 1265 1229 1207 1107 1012 1075 1116 1126 1122 1073 1110 1070 1108 1096 1055 1127 1082 1088 1156 1012 1047 1023 1055 1094 1050 1036 1000 1009 960 928 950 942 902 967 914 894 932 853 1017 933 1007 875 859 830 912 859 852 883 877 907 926 884 920 894 862 872 894 894 931 931 948 884 887 952 940 914 915 848 861 845 928 906 939 977 961 926 969 971 948 973 939 1016 944 966 877 957 1009 965 999 963 988 945 920 946 949 925 983 949 967 934 981 963 946 949 1001 1006 975 1013 993 990 999 1058 991 1093 1106 1057 1047 1077 1043 1034 1012 1019 1005 1099 995 1075 1053 1051 995 1064 1043 1045 977 1042 1014 1056 1053 987 1035 986 989 1025 1030 988 998 969 990 954 1016 959 971 1009 956 963 1008 990 1005 979 1001 956 967 961 1038 1054 1016 994 987 1045 991 1018 1097 1063 1069 1030 1061 1019 1054 1061 1128 1075 1100 1067 1123 1094 1152 1150 1099 1126 1164 1138 1142 1140 1165 1106 1150 1123 1155 1166 1100 1112 1144 1157 1147 1159 1133 1196 1107 1226 1092 1205 1146 1114 1123 1182 1147 1177 1114 1139 1159 1242 1247 1265 1215 1256 1253 1265 1267 1326 1253 1294 1330 1348 1378 1403 1360 1371 1357 1291 1273 1339 1343 1407 1309 1367 1326 1326 1306 1278 1268 1286 1311 1259 1315 1307 1260 1226 1275 1272 1209 1234 1283 1126 1125 1249 1163 1182 1055 1161 1145 1159 1124 1123 1147 1104 1169 1142 1118 1092 1156 1152 1101 1156 1124 1174 1193 1192 1149 1152 1213 1097 1196 1159 1258 1228 1296 1266 1234 1329 1270 1340 1333 1396 1315 1360 1394 1426 1367 1478 1481 1560 1518 1580 1575 1599 1647 1674 1777 1733 1774 1673 1717 1705 1718 1738 1755 1706 1673 1723 1739 1741 1757 1781 1735 1775 1747 1796 1885 1809 1933 1860 1867 1868 1870 1908 1817 1869 1903 1824 1937 1763 1826 1860 1783 1760 1752 1678 1681 1662 1594 1644 1530 1426 1477 1546 1474 1482 1418 1480 1465 1416 1417 1358 1393 1370 1377 1331 1338 1290 1268 1289 1234 1314 1306 1228 1152 1154 1147 1190 1224 1177 1148 1131 1076 1226 1115 1136 1167 1127 1185 1149 1179 1091 1124 1075 1126 1094 1094 1151 1175 1103 1064 1180 1155 1138 1188 1189 1125 1125 1165 1128 1160 1175 1216 1255 1331 1322 1269 1288 1312 1352 1304 1446 1441 1424 1329 1448 1483 1375 1471 1463 1510 1535 1681 1568 1725 1863 1952 2009 2149 2163 2403 2394 2396 2470 2321 2240 2086 2070 1925 1813 1746 1673 1754 1719 1665 1620 1618 1679 1725 1669 1665 1745 1774 1780 1708 1632 1634 1607 1591 1469 1400 1330 1351 1263 1230 1258 1161 1211 1174 1172 1082 1018 1118 1106 1105 1016 1035 1075 1055 977 943 998 965 948 963 939 922 900 936 953 954 991 994 966 968 931 895 887 858 934 895 921 861 946 946 886 798 918 897 902 911 958 889 979 937 892 882 892 872 889 857 887 885 799 914 858 954 946 875 885 948 917 995 879 903 923 967 935 959 989 969 1017 1016 1040 1131 986 1133 1154 1161 1196 1159 1157 1153 1154 1135 1113 1185 1087 1118 1025 1039 1071 1094 1011 1024 1104 1029 1082 1064 1022 1099 1084 1092 1014 1070 1063 1108 1080 1016 965 992 959 1040 959 896 1026 1003 960 922 935 949 929 911 902 973 923 984 940 896 910 934 895 880 842 843 867 887 874 880 988 840 877 814 857 916 918 915 837 861 926 865 859 866 934 874 928 909 852 887 890 921 874 867 887 885 923 920 920 912 931 948 913 980 966 947 1009 999 1003 1040 1048 1045 1128 1144 1206 1233 1299 1338 1206 1228 1192 1175 1157 1122 1068 1058 1105 1133 1086 1114 1024 1081 1121 1120 1076 1081 1096 1103 1125 1138 1103 1122 1069 1063 1059 1050 1038 1002 1024 988 1020 1046 1019 1011 996 1030 998 967 993 1057 993 997 959 919 952 970 945 956 946 954 974 968 991 877 972 1015 932 968 957 958 1015 979 979 917 950 921 964 925 905 917 934 940 949 969 942 949 984 960 1020 999 1031 988 1013 968 1008 1043 1005 1070 1049 1081 1102 1099 1050 1102 1080 1109 1039 1120 1083 1172 1157 1221 1117 1111 1069 1161 1131 1164 1130 1129 1179 1191 1124 1153 1091 1182 1096 1137 1091 1107 1129 1137 1088 1156 1118 1099 1129 1115 1196 1112 1125 1137 1117 1020 1052 1078 1081 1067 1087 1045 977 1022 1040 1018 967 1001 1019 975 987 942 967 944 1002 959 961 929 1005 1025 936 976 994 959 977 1031 981 935 1004 926 984 912 1007 1010 917 972 997 1049 1015 973 1024 1062 1016 958 1005 998 981 993 1008 1002 938 959 983 975 956 974 999 976 953 1001 965 1035 947 991 1003 1031 972 985 1024 1003 1104 1027 1027 1090 960 1044 1030 1030 1053 1085 1020 1113 1103 1144 1139 1235 1283 1244 1330 1436 1482 1560 1601 1636 1750 1756 1820 1730 1832 1591 1540 1510 1466 1485 1397 1387 1296 1333 1269 1268 1332 1309 1287 1317 1415 1325 1416 1401 1434 1400 1415 1464 1435 1394 1212 1261 1267 1174 1217 1190 1119 1155 1082 1079 1094 1079 1047 1061 1059 1090 1088 1034 1016 1020 994 1018 1055 1001 968 994 913 932 937 953 950 930 917 970 983 947 900 926 952 942 963 914 942 898 914 902 924 921 921 855 889 979 873 842 867 925 959 893 912 929 966 964 907 908 902 921 937 972 932 921 941 938 959 996 949 978 1040 1070 1053 1036 1018 1092 1057 987 1017 1031 1021 974 978 1030 1045 928 977 963 990 939 1003 956 912 999 960 984 1041 966 987 959 988 978 938 928 929 900 896 884 910 954 887 970 888 874 935 901 948 868 878 860 874 840 876 859 858 847 813 836 783 848 818 816 858 832 898 862 851 934 869 853 835 848 857 890 857 879 854 834 894 865 859 892 837 874 883 861 860 929 894 855 834 857 847 864 934 853 855 924 839 899 854 855 861 891 836 854 871 888 888 898 830 875 870 854 840 836 890 825 890 869 912 957 876 868 894 884 865 837 871 883 877 941 919 924 847 874 884 919 818 864 899 889 866 869 886 860 902 864 833 837 875 892 861 862 908 834 936 887 864 934 848 891 855 838 877 885 864 838 809 871 838 811 841 867 881 920 887 881 859 873 862 899 856 929 916 835 869 837 911 873 866 875 896 836 900 892 908 864 909 903 884 909 932 919 873 967 946 982 953 989 1022 1016 1090 1120 1151 1151 1204 1190 1180 1260 1257 1278 1270 1264 1132 1128 1109 1150 1092 1107 1064 1088 1107 1111 1053 1097 1082 1081 1158 1170 1166 1152 1160 1119 1192 1094 1094 1127 1109 1073 1051 1056 973 1031 999 987 987 1046 938 954 1000 952 939 962 982 918 923 957 1006 984 981 950 844 873 866 884 985 912 936 891 938 932 923 875 899 927 882 917 963 987 947 1010 942 917 969 956 1002 992 978 967 955 1004 988 1016 1020 1018 1064 1026 1022 1006 1089 1043 1042 1002 1105 1016 1059 1002 1080 1076 1077 1036 1095 1076 1042 1097 1100 1075 1183 1197 1179 1225 1243 1260 1240 1264 1317 1365 1363 1371 1377 1413 1358 1377 1432 1354 1383 1272 1326 1363 1261 1410 1296 1382 1324 1351 1262 1329 1378 1343 1366 1285 1260 1329 1256 1413 1317 1273 1313 1293 1218 1231 1242 1176 1199 1238 1205 1260 1170 1132 1214 1121 1149 1182 1157 1155 1066 1101 1054 1078 1084 1118 1109 1091 1089 1052 1074 1054 1115 1051 1036 1063 976 1102 1057 1065 1120 1097 1086 1102 1147 1106 1033 1023 1074 1039 1030 1083 1061 1090 1034 1119 1026 1096 1144 1077 1140 1133 1164 1207 1213 1243 1261 1308 1306 1304 1331 1327 1358 1396 1459 1301 1447 1486 1558 1512 1657 1660 1732 1819 1918 1982 1861 1943 2017 2013 1948 1947 1907 1879 1879 1790 1670 1682 1650 1535 1592 1585 1514 1477 1584 1439 1518 1585 1615 1594 1609 1716 1672 1639 1574 1569 1611 1610 1519 1472 1461 1425 1433 1454 1424 1298 1281 1294 1202 1289 1232 1243 1244 1240 1242 1190 1215 1286 1188 1188 1209 1155 1173 1196 1156 1192 1147 1120 1130 1160 1120 1136 1184 1163 1114 1150 1080 1131 1109 1090 1213 1167 1232 1197 1172 1214 1113 1104 1177 1168 1173 1121 1185 1183 1176 1236 1227 1284 1301 1382 1415 1390 1455 1478 1610 1697 1722 1727 1817 1935 1889 2028 1936 1901 1833 1728 1722 1719 1553 1533 1524 1505 1402 1401 1444 1400 1386 1386 1357 1368 1376 1392 1435 1437 1457 1483 1546 1493 1460 1527 1501 1400 1395 1422 1351 1289 1299 1188 1187 1181 1139 1120 1139 1124 1073 1155 1027 1118 1079 1053 1051 1028 1019 1024 977 984 1031 1064 1013 979 1075 968 1028 948 893 1016 992 902 975 972 890 926 959 923 914 889 954 940 989 894 960 881 927 896 967 896 893 862 909 890 970 898 905 917 923 889 904 886 933 907 931 900 910 899 920 935 909 972 969 865 933 960 965 902 947 964 921 1025 1020 1006 1039 1013 1045 1103 1038 1049 1092 1093 1056 1025 1090 1005 1007 967 992 1024 975 999 960 982 948 948 984 942 953 927 909 968 1016 950 992 962 1034 1030 1024 1017 961 957 995 964 925 956 920 927 949 868 912 843 948 918 934 898 894 873 877 861 882 842 968 882 912 851 974 973 898 957 939 885 900 942 931 1028 948 916 965 905 1003 978 972 1032 1027 1002 1079 1048 1089 1090 1104 1016 1069 1094 1135 1087 1131 1133 1160 1273 1213 1299 1338 1419 1400 1332 1374 1298 1318 1253 1303 1244 1179 1188 1172 1153 1095 1249 1075 1097 1030 1055 1074 1031 1069 1104 1105 1057 1109 1046 1097 1085 1142 1075 1157 1057 1158 1067 1138 1029 1063 1135 981 963 1001 975 1025 958 994 960 989 993 955 970 936 904 923 918 972 879 956 895 972 865 897 872 905 892 885 894 898 909 841 944 896 887 859 890 842 876 903 890 917 913 922 892 908 844 932 880 916 889 881 887 905 834 859 891 873 907 918 865 816 912 814 852 845 905 896 918 866 884 807 893 840 849 893 963 890 814 900 839 852 867 904 800 911 821 942 833 878 898 960 869 906 892 823 878 901 919 917 923 941 942 908 936 991 945 948 868 977 998 946 930 915 932 986 958 939 915 951 1000 987 968 930 1044 962 992 999 994 976 1071 1029 1057 1083 999 962 1043 1041 1035 964 993 1058 1099 1119 1093 1060 1109 1068 1068 1054 1069 1054 1089 1118 1100 1102 1183 1155 1182 1131 1153 1166 1213 1327 1239 1258 1355 1245 1224 1169 1292 1302 1318 1314 1274 1348 1239 1268 1263 1314 1266 1330 1279 1240 1310 1265 1218 1193 1232 1223 1311 1286 1266 1238 1254 1261 1280 1235 1316 1258 1274 1355 1347 1366 1345 1371 1417 1379 1440 1441 1486 1444 1499 1504 1499 1492 1445 1350 1450 1297 1340 1367 1274 1337 1358 1286 1377 1275 1257 1276 1236 1251 1291 1242 1291 1213 1259 1305 1241 1312 1260 1330 1325 1335 1282 1317 1320 1266 1328 1199 1189 1294 1248 1256 1271 1249 1230 1259 1230 1171 1216 1215 1211 1216 1237 1287 1202 1278 1282 1288 1272 1245 1255 1213 1287 1197 1214 1204 1298 1217 1195 1314 1218 1220 1279 1249 1364 1227 1306 1264 1278 1338 1294 1353 1352 1272 1313 1280 1282 1266 1197 1234 1198 1187 1164 1208 1221 1236 1144 1212 1193 1180 1217 1125 1159 1113 1121 1122 1168 1177 1081 1183 1114 1142 1119 1114 1178 1132 1060 1021 1033 1085 1075 1008 948 999 992 993 1009 1042 967 1012 926 1017 1009 946 926 932 1005 1000 940 929 936 937 867 971 864 883 908 960 935 946 899 911 918 963 848 929 909 942 897 897 903 897 869 918 909 877 846 855 934 904 980 910 854 911 864 992 958 913 925 953 946 917 973 904 932 883 909 895 899 896 913 916 883 865 932 900 946 899 907 927 848 897 936 923 913 933 907 998 910 1043 953 970 919 912 934 900 894 909 885 942 912 968 933 861 894 899 852 923 917 875 958 887 873 946 940 983 969 878 956 891 955 922 943 904 931 981 885 894 954 886 1009 927 977 976 855 955 957 920 960 950 983 925 894 986 928 988 963 989 953 1001 946 978 998 984 949 860 978 960 940 994 980 1019 991 900 1007 1029 1057 1069 1092 1054 1083 1124 1117 1169 1104 1110 1203 1137 1272 1253 1214 1193 1197 1175 1203 1225 1209 1205 1190 1158 1197 1180 1151 1151 1132 1193 1253 1151 1190 1234 1232 1173 1195 1253 1196 1229 1226 1238 1183 1230 1145 1235 1212 1181 1257 1190 1128 1168 1198 1162 1162 1109 1106 1118 1104 1051 1101 1018 1127 1035 1087 1038 1006 1075 1042 1046 1000 1075 1047 1079 1000 953 964 991 1002 1001 946 996 997 942 923 958 982 945 990 948 1002</counts>
			</dataPoints>
		</scan>
	</xrdMeasurement>
</xrdMeasurements>