File: dataset/precursor_mixture/GeO2_ZrO2_Bi2O3-alpha.12-min.xrdml
<?xml version="1.0"?>
<xrdMeasurements xmlns="http://www.xrdml.com/XRDMeasurement/2.2" xmlns:xsi="http://www.w3.org/2001/XMLSchema-instance" xsi:schemaLocation="http://www.xrdml.com/XRDMeasurement/2.2 http://www.xrdml.com/XRDMeasurement/2.2/XRDMeasurement.xsd" status="Completed" recordIdentifier="{B6A7133A-0E02-43C0-B80A-148EF3A47BE1}">
	<comment>
		<entry/>
	</comment>
	<sample type="To be analyzed">
		<id>dara-16-2</id>
		<name></name>
		<preparedBy></preparedBy>
	</sample>
	<xrdMeasurement measurementType="Scan" status="Completed" sampleMode="Reflection">
		<usedWavelength intended="K-Alpha 1">
			<kAlpha1 unit="Angstrom">1.5405980</kAlpha1>
			<kAlpha2 unit="Angstrom">1.5444260</kAlpha2>
			<kBeta unit="Angstrom">1.3922500</kBeta>
			<ratioKAlpha2KAlpha1>0.5000</ratioKAlpha2KAlpha1>
		</usedWavelength>
		<incidentBeamPath>
			<radius unit="mm">145.00</radius>
			<xRayTube id="1010048" name="Empyrean Cu LFF HR (9430 033 7310x) DK430614">
				<tension unit="kV">40.0</tension>
				<current unit="mA">15.0</current>
				<anodeMaterial>Cu</anodeMaterial>
				<focus type="Line">
					<length unit="mm">12.0</length>
					<width unit="mm">0.4</width>
					<takeOffAngle unit="deg">6.0</takeOffAngle>
				</focus>
			</xRayTube>
			<filter id="20010004" name="Beta-filter Nickel">
				<material>Ni</material>
				<thickness unit="mm">0.020</thickness>
			</filter>
			<sollerSlit id="21010002" name="Soller slits 0.04 rad.">
				<opening unit="rad">0.0400</opening>
			</sollerSlit>
			<mask id="22031000" name="Fixed mask 13 mm">
				<width unit="mm">9.00</width>
			</mask>
			<divergenceSlit id="22120001" name="Divergence slit 1°" xsi:type="fixedDivergenceSlitType">
				<distanceToSample unit="mm">50.00</distanceToSample>
				<height unit="mm">1.52</height>
			</divergenceSlit>
		</incidentBeamPath>
		<beamKnife id="29030100" name="Beam knife low"/>
		<sampleMovement xsi:type="spinningSampleMovementType">
			<spinnerRevolutionTime unit="seconds">1.0</spinnerRevolutionTime>
		</sampleMovement>
		<diffractedBeamPath>
			<radius unit="mm">145.00</radius>
			<antiScatterSlit id="22090040" name="AS slit 9 mm" xsi:type="fixedAntiScatterSlitType">
				<height unit="mm">9.00</height>
			</antiScatterSlit>
			<sollerSlit id="21020003" name="Large Soller slits 0.04 rad.">
				<opening unit="rad">0.0400</opening>
			</sollerSlit>
			<filter id="20030001" name="Large beta-filter Nickel">
				<material>Ni</material>
				<thickness unit="mm">0.020</thickness>
			</filter>
			<detector id="7010019" name="PIXcel1D-Medipix3 detector" xsi:type="rtmsDetectorType">
				<phd unit="keV">
					<lowerLevel>4.0</lowerLevel>
					<upperLevel>11.3</upperLevel>
				</phd>
				<mode>Scanning</mode>
				<activeLength unit="deg">5.020</activeLength>
			</detector>
		</diffractedBeamPath>
		<scan appendNumber="0" mode="Continuous" scanAxis="Gonio" status="Completed">
			<header>
				<startTimeStamp>2024-02-18T15:08:10-08:00</startTimeStamp>
				<endTimeStamp>2024-02-18T15:20:38-08:00</endTimeStamp>
				<author>
					<name>AutomatedUser</name>
				</author>
				<source>
					<applicationSoftware version="1.4b (28)">PANalytical Aeris Instrument Suite</applicationSoftware>
					<instrumentControlSoftware version="2.0.0 20210224">AERIS</instrumentControlSoftware>
					<instrumentID>950485</instrumentID>
				</source>
			</header>
			<dataPoints>
				<positions axis="2Theta" unit="deg">
					<startPosition>9.99043322</startPosition>
					<endPosition>100.09495370</endPosition>
				</positions>
				<positions axis="Omega" unit="deg">
					<startPosition>4.99521661</startPosition>
					<endPosition>50.04747685</endPosition>
				</positions>
				<commonCountingTime unit="seconds">18.249</commonCountingTime>
				<counts unit="counts">3718 3861 3772 3803 3774 3849 3873 3752 3676 3777 3834 3654 3797 3740 3677 3717 3696 3776 3687 3696 3680 3747 3660 3733 3611 3622 3537 3648 3745 3655 3597 3670 3732 3613 3680 3617 3672 3604 3667 3662 3628 3550 3637 3573 3636 3645 3655 3648 3674 3683 3680 3586 3675 3722 3625 3532 3608 3526 3597 3633 3633 3591 3475 3488 3675 3509 3454 3526 3463 3492 3496 3474 3476 3381 3480 3432 3458 3481 3434 3475 3489 3411 3422 3440 3414 3348 3569 3415 3371 3428 3391 3452 3484 3406 3311 3407 3396 3338 3458 3277 3454 3379 3389 3284 3362 3327 3252 3264 3389 3243 3313 3265 3410 3341 3278 3335 3425 3254 3319 3323 3321 3312 3276 3366 3253 3265 3309 3225 3243 3240 3341 3283 3180 3320 3372 3290 3204 3257 3297 3227 3256 3291 3157 3259 3135 3203 3112 3230 3148 3159 3172 3160 3178 3168 3248 3240 3240 3134 3200 3087 3122 3123 3311 3199 3253 3160 3022 3165 3166 3129 3039 3163 3106 3131 3089 3139 3090 3240 3144 3148 3100 3129 3097 3085 3038 3088 3011 3159 3093 3024 3043 3158 3124 3183 3106 3029 3119 3023 3065 3046 2943 3040 3054 3055 3004 3108 3118 2916 3113 3034 3017 3051 2946 2972 3051 3048 3041 3073 3077 3048 3000 2898 2964 2956 2924 3021 2985 3043 2992 3000 2982 2971 2934 3006 2966 2991 2885 2857 2930 2879 2887 2928 2924 2928 2855 2873 2937 2925 2910 2941 2869 2888 2835 2878 2914 2945 2846 2923 2899 2805 2814 2914 2830 2927 2984 2843 2975 2941 2819 2906 2963 2891 2873 2815 2862 2865 2890 2904 2863 2868 2940 2866 2942 2890 2783 2880 2766 2873 2835 2740 2816 2816 2767 2844 2755 2776 2778 2825 2745 2756 2686 2759 2820 2776 2723 2802 2789 2716 2810 2742 2791 2831 2753 2792 2788 2747 2724 2719 2782 2681 2790 2702 2688 2679 2741 2659 2684 2699 2755 2809 2728 2695 2773 2603 2624 2680 2659 2830 2675 2631 2597 2686 2742 2651 2769 2784 2653 2664 2641 2652 2702 2622 2655 2673 2706 2640 2589 2690 2677 2641 2652 2635 2604 2684 2532 2575 2658 2645 2653 2631 2725 2661 2607 2693 2676 2537 2643 2626 2638 2644 2582 2662 2648 2566 2589 2547 2678 2670 2604 2693 2662 2673 2613 2672 2738 2628 2510 2681 2637 2651 2634 2776 2506 2633 2655 2634 2611 2596 2632 2536 2653 2531 2557 2573 2579 2508 2685 2561 2559 2566 2566 2489 2575 2613 2567 2630 2647 2495 2578 2461 2428 2495 2589 2461 2651 2536 2544 2560 2650 2501 2556 2570 2637 2553 2538 2528 2543 2648 2598 2552 2635 2436 2469 2533 2563 2600 2705 2492 2521 2551 2554 2518 2457 2538 2518 2571 2535 2569 2547 2470 2574 2562 2488 2510 2465 2461 2542 2487 2518 2494 2488 2431 2521 2609 2480 2518 2578 2433 2514 2463 2535 2456 2495 2488 2502 2487 2474 2512 2550 2541 2441 2474 2423 2446 2508 2392 2499 2521 2551 2457 2450 2445 2528 2493 2528 2414 2512 2420 2482 2470 2565 2504 2534 2517 2492 2510 2454 2577 2421 2406 2470 2359 2525 2376 2493 2357 2518 2364 2480 2425 2410 2522 2378 2481 2525 2385 2462 2459 2374 2390 2329 2477 2552 2383 2509 2453 2499 2361 2501 2405 2467 2457 2390 2407 2406 2461 2330 2408 2439 2391 2463 2408 2422 2360 2386 2480 2514 2495 2469 2437 2535 2438 2470 2398 2420 2381 2399 2331 2401 2367 2418 2308 2461 2546 2359 2433 2405 2439 2395 2416 2479 2427 2415 2409 2365 2533 2385 2536 2438 2435 2398 2359 2425 2476 2512 2446 2509 2470 2574 2616 2464 2533 2670 2553 2624 2648 2697 2706 2748 2725 2674 2854 2769 2780 2746 2816 2538 2670 2575 2559 2486 2368 2492 2429 2353 2424 2414 2375 2483 2355 2389 2434 2446 2397 2405 2490 2433 2379 2354 2424 2422 2450 2565 2370 2432 2322 2412 2372 2491 2342 2417 2503 2537 2583 2549 2465 2548 2538 2570 2633 2653 2722 2630 2746 2800 2706 2764 2839 2811 2771 2946 2878 2849 2918 2910 2844 2801 2710 2718 2634 2636 2540 2515 2502 2533 2474 2451 2357 2488 2420 2390 2390 2342 2256 2443 2363 2405 2314 2235 2357 2277 2328 2317 2336 2198 2308 2343 2362 2252 2276 2294 2395 2178 2182 2262 2245 2255 2215 2285 2298 2315 2225 2339 2096 2323 2245 2218 2250 2224 2324 2392 2259 2295 2181 2201 2299 2242 2286 2295 2247 2198 2210 2205 2157 2228 2254 2206 2207 2166 2219 2172 2268 2207 2185 2272 2113 2206 2186 2237 2192 2273 2151 2247 2217 2123 2172 2139 2257 2180 2152 2254 2186 2276 2252 2168 2169 2145 2218 2148 2180 2034 2150 2185 2197 2200 2122 2179 2119 2175 2151 2172 2112 2205 2129 2227 2166 2212 2068 2137 2103 2161 2079 2197 2102 2124 2127 2161 2237 2155 2161 2121 2124 2217 2172 2277 2149 2174 2128 2134 2166 2128 2123 2136 2151 2181 2150 2147 2022 2085 2134 2148 2120 2119 2042 2134 2024 2144 2098 2159 2108 2168 2134 2150 2056 2131 2202 2118 2147 2195 2120 2090 2145 2106 2107 2163 2152 2246 2105 2189 2195 2161 2195 2216 2222 2286 2328 2366 2407 2307 2419 2418 2449 2419 2471 2649 2579 2665 2909 2829 3009 3039 3038 2980 3013 3072 2968 2853 2817 2760 2607 2456 2389 2226 2237 2243 2201 2086 2112 2167 2113 2089 2051 2188 2221 2197 2104 2075 2106 2013 2209 2130 2097 2126 2102 2148 2072 2095 2103 2154 2080 2272 2139 2132 2232 2193 2201 2129 2219 2130 2208 2197 2352 2192 2327 2276 2352 2318 2490 2411 2534 2668 2676 2698 2775 2945 3042 3165 3181 3313 3541 3703 3804 4002 4036 4212 4335 4299 4481 4410 4271 4256 4012 3967 3555 3427 3156 3185 2883 2813 2608 2502 2470 2295 2420 2223 2258 2208 2252 2144 2244 2075 2127 2191 2021 2104 2087 2071 2052 2083 2091 2072 2052 2105 2116 2051 2101 2066 2049 1996 2084 2063 2041 2016 2016 1969 2068 1982 1954 1977 2018 2026 1992 2044 1941 1997 2050 2023 1970 2065 1940 1961 1951 1994 1946 1956 1967 2059 1944 1963 1962 1982 1937 1995 1901 2015 1998 1973 1966 1944 1898 2001 1985 1970 1983 2038 1987 2068 2092 2094 2087 2044 2064 2224 2230 2217 2274 2272 2339 2300 2544 2508 2646 2647 2793 2815 2872 3065 3012 3151 3160 3113 2897 2868 2716 2664 2515 2428 2233 2170 2093 2131 2005 1967 1973 1990 1966 1946 1958 2013 1949 2042 1979 1917 1948 1983 1886 1933 1964 1868 1970 1932 1946 1826 1912 1954 1826 1786 2020 1896 1889 1932 1855 1904 1867 1909 1937 1926 1777 1811 1858 1888 1825 1909 1889 1953 1921 1817 1968 1949 1865 1997 1836 1879 1850 1814 1874 1815 1833 1870 1896 1819 1880 1895 1917 1819 1820 1815 1929 1831 1864 1963 1841 1863 1808 1902 1792 1822 1895 1939 1823 1924 1882 1939 1909 1833 1826 1833 1863 1890 1868 1916 1850 1875 1856 1816 1872 1940 1820 1844 1827 1867 1850 1842 1888 1904 1904 1891 1846 1825 1827 1853 1808 1871 1880 1917 1904 1862 1889 1917 1906 1820 1776 1837 1887 1878 1887 1935 1809 1849 1924 1900 1949 1888 1896 1856 1943 1907 1942 1902 1953 1933 1884 1986 1914 1887 1857 1911 1816 1945 1894 1830 1869 2011 1902 1907 1911 1943 1944 1906 1876 1977 1979 2017 1901 1926 1896 1932 1999 1963 2098 1995 1948 2017 1990 1961 1959 2080 2141 2266 2303 2200 2231 2294 2396 2356 2499 2497 2460 2715 2784 2877 2988 3063 3218 3219 3246 3518 3573 3612 3728 3833 3877 3876 3726 3757 3628 3539 3380 3237 3017 3074 2855 2837 2743 2738 2580 2662 2500 2532 2576 2600 2453 2609 2540 2691 2779 2765 2810 2917 3041 3049 3262 3320 3439 3538 3738 3708 3881 4057 4121 4231 4400 4416 4600 4698 4695 4822 4954 4804 4446 4175 3912 3611 3416 3226 2933 2818 2540 2439 2380 2256 2233 2245 2133 2061 2104 2085 2129 2025 2038 1912 2050 1977 1934 1917 2055 1927 1914 2056 1957 1988 1868 1913 1876 1900 1854 1934 1945 1979 2018 1906 1997 2004 1899 2065 2012 2076 2030 1969 2124 2042 2055 2091 2067 1998 2092 2169 2155 2201 2237 2251 2191 2370 2308 2377 2415 2465 2518 2349 2438 2416 2326 2341 2360 2377 2290 2287 2388 2371 2313 2421 2397 2498 2445 2498 2557 2629 2725 2847 2980 3001 3216 3292 3453 3791 4008 4294 4731 4914 5448 6019 6661 7141 7902 8586 9116 9883 10256 10206 10181 10003 10093 10282 10701 10603 11455 12023 12643 13318 14336 15369 16238 16985 17720 18107 17678 17277 16321 15172 14139 12824 11598 10225 9189 7932 6786 6000 5328 4824 4079 3990 3650 3515 3343 3103 3051 2938 2786 2860 2738 2617 2681 2609 2537 2529 2479 2488 2460 2513 2318 2418 2296 2327 2273 2263 2347 2389 2282 2215 2201 2336 2188 2301 2183 2305 2308 2288 2361 2296 2327 2334 2287 2252 2271 2305 2347 2322 2439 2373 2341 2429 2493 2530 2511 2743 2852 3025 3167 3217 3548 3603 4046 4400 4899 5270 5927 6390 7203 8009 8973 9674 10771 11399 11781 12250 12138 11325 10471 9463 8906 8028 7032 6296 5867 4807 4246 3829 3461 3336 3388 3299 3270 3353 3311 3500 3755 3892 4338 4547 5010 5420 5899 6504 7440 8396 9478 10982 12686 14685 16816 19703 22186 25654 29026 32691 35660 38983 40655 40403 37809 33746 29834 27121 23842 21311 18642 15127 12243 9303 7178 5804 4943 4204 3861 3518 3318 3222 3185 3191 3152 3044 3009 3104 2871 3018 3079 3024 2924 3048 2993 3010 2991 3041 3033 3118 3129 3258 3380 3437 3619 3788 4043 4322 4595 5055 5438 5950 6384 7200 7843 8722 9642 10265 10983 11570 11786 11496 11156 10832 10946 11018 11069 11353 11527 11334 11802 12188 12583 13065 13911 13877 13997 13683 13548 12876 12228 11405 11001 10093 9505 8596 7768 7053 6418 5997 5485 5135 4668 4435 4091 4024 3709 3635 3470 3303 3226 3145 2962 2932 2890 2885 2701 2649 2618 2649 2451 2405 2477 2378 2413 2378 2300 2231 2236 2261 2237 2234 2105 2172 2154 2129 2113 2124 1995 2041 2038 2038 1980 1999 1955 1955 1982 1922 1953 1997 1984 1958 1939 1861 1873 1962 1921 1932 1876 1917 1860 1917 1848 1844 1932 1847 1910 1834 1903 1857 1919 1970 1824 1828 1847 1873 1895 1816 1798 1756 1804 1854 1782 1809 1816 1799 1813 1864 1823 1744 1873 1811 1786 1782 1725 1740 1776 1865 1831 1855 1821 1800 1791 1829 1756 1691 1809 1769 1782 1835 1737 1833 1857 1778 1721 1880 1764 1836 1800 1826 1777 1713 1828 1725 1860 1780 1681 1792 1795 1751 1831 1727 1760 1688 1726 1725 1780 1855 1815 1754 1800 1887 1722 1800 1698 1749 1795 1743 1683 1830 1765 1785 1766 1760 1747 1808 1807 1830 1791 1802 1742 1792 1813 1696 1715 1731 1680 1793 1706 1759 1830 1828 1764 1760 1791 1776 1777 1878 1743 1728 1743 1730 1723 1839 1759 1776 1801 1814 1792 1835 1812 1818 1789 1770 1730 1806 1808 1796 1852 1787 1798 1799 1794 1862 1848 1829 1777 1758 1831 1750 1807 1713 1752 1813 1910 1862 1789 1792 1800 1771 1795 1847 1911 1803 1804 1851 1798 1872 1904 1798 1888 1879 1862 1943 1940 1914 1877 1898 1979 1937 1916 1930 1957 1976 2043 2037 2016 2082 1964 2071 2020 2055 2165 2220 2140 2172 2206 2316 2418 2445 2513 2430 2555 2530 2677 2796 2890 2880 3093 3218 3498 3542 3807 4021 4312 4471 4867 5081 5513 6136 6189 6843 7190 7658 8197 8568 8939 9246 9488 9522 9492 9031 8737 8484 7861 7364 6933 6414 6110 5409 5129 4652 4278 4045 3722 3485 3148 3017 2918 2837 2684 2572 2491 2444 2346 2269 2185 2267 2110 2149 2153 2183 1975 2068 2023 1932 1956 1908 1928 1865 1886 1798 1793 1817 1850 1805 1728 1755 1725 1746 1832 1790 1752 1697 1802 1709 1747 1739 1686 1738 1669 1702 1679 1705 1731 1729 1745 1653 1686 1658 1662 1719 1792 1824 1789 1843 1771 1789 1883 1819 1848 1917 1973 2048 2133 2287 2477 2605 2650 2885 2903 3090 3241 3216 3097 2851 2726 2607 2626 2522 2457 2493 2235 2184 2001 2014 1944 1948 1908 1823 1910 1881 1868 1886 1888 1974 1966 1889 1979 1989 2039 2039 2166 2271 2315 2444 2538 2680 2931 3214 3409 3714 4154 4672 5382 6049 7162 8225 9350 10309 11481 12648 13034 12915 12441 11542 10928 10015 10016 9935 9825 9751 10003 10168 10304 10741 11562 12519 13197 14044 14780 14501 14066 13298 12062 10985 9746 9271 8463 7973 6948 6246 5261 4387 3520 3155 2682 2386 2337 2225 2086 2047 2075 1906 1947 1931 1834 1881 1755 1947 1882 1803 1814 1793 1775 1779 1720 1757 1805 1743 1781 1760 1644 1751 1687 1811 1709 1873 1770 1794 1856 1885 1882 2005 2057 2120 2153 2316 2422 2582 2714 2813 3062 3296 3481 3621 3813 3665 3648 3448 3389 3395 3353 3382 3468 3484 3488 3354 3459 3470 3526 3715 3758 3987 3998 4129 4065 4172 4071 3934 3943 3848 3632 3673 3647 3509 3474 3273 3254 3239 3085 3108 3136 3109 3319 3252 3145 3151 3104 3247 3050 3105 2899 2804 2819 2749 2703 2496 2451 2372 2414 2277 2236 2134 2071 2005 2082 2063 1920 1958 1889 1901 1903 1902 1789 1751 1788 1798 1788 1742 1759 1788 1738 1797 1898 1788 1860 1832 1780 1844 1904 1984 2137 2116 2273 2429 2614 2782 3097 3414 3657 4200 4466 5090 5366 5987 6188 6219 5964 5620 5213 4986 4655 4440 4509 4307 4147 3882 3510 3293 3198 2968 3001 2924 3049 3150 3223 3424 3618 3620 3772 3954 4096 4163 4366 4536 4742 4959 5041 5215 5247 5008 4686 4309 3868 3784 3655 3421 3367 3069 2914 2633 2468 2280 2107 2062 2018 1835 1798 1767 1858 1734 1820 1769 1804 1839 1841 1770 1800 1881 1870 1867 1891 1963 1957 2199 2207 2385 2533 2718 2857 3227 3520 3820 4092 4218 4421 4542 4397 4302 4220 4273 4266 4248 4093 3881 3714 3470 3263 2978 2871 2679 2494 2329 2226 2170 2022 1978 1929 1872 1764 1676 1662 1645 1620 1624 1481 1621 1611 1591 1525 1520 1569 1587 1519 1520 1557 1535 1527 1476 1507 1453 1461 1425 1441 1443 1439 1413 1444 1516 1450 1370 1467 1474 1448 1401 1385 1437 1428 1411 1416 1419 1468 1399 1446 1411 1452 1459 1439 1370 1378 1366 1459 1368 1444 1348 1485 1492 1523 1450 1581 1605 1720 1697 1819 1994 2019 2110 2314 2589 2730 2891 3168 3179 3222 3047 2837 2617 2535 2403 2400 2392 2347 2316 2103 1942 1863 1782 1642 1560 1578 1504 1469 1436 1511 1449 1408 1414 1468 1473 1503 1448 1451 1465 1493 1440 1405 1462 1405 1505 1442 1603 1502 1547 1533 1567 1699 1724 1794 1818 1976 2081 2267 2545 2693 3163 3394 3783 4157 4551 5000 5139 5072 4932 4679 4260 3818 3674 3501 3398 3373 3337 3066 2914 2504 2326 2108 1925 1889 1834 1891 1767 1807 1840 1836 1924 1947 2031 2180 2287 2483 2657 2787 2990 3355 3497 4034 4211 4549 4702 4965 4934 4830 4665 4429 4067 3973 3875 3675 3597 3343 3182 2958 2760 2618 2354 2136 2003 1921 1900 1850 1738 1647 1631 1706 1639 1574 1631 1627 1514 1632 1511 1543 1603 1564 1610 1597 1659 1687 1642 1636 1654 1763 1764 1788 1865 1913 1955 1939 1966 1955 1945 1870 1870 1938 1864 1807 1830 1774 1714 1737 1780 1737 1673 1604 1641 1604 1525 1538 1473 1570 1528 1491 1477 1462 1485 1453 1463 1400 1400 1431 1392 1413 1417 1430 1440 1409 1368 1384 1366 1356 1333 1439 1450 1382 1407 1360 1351 1402 1368 1325 1420 1373 1388 1410 1354 1320 1402 1358 1442 1380 1369 1511 1477 1466 1582 1577 1560 1725 1757 1801 1902 1890 2053 2228 2397 2551 2673 2966 3111 3192 3336 3477 3389 3366 3409 3143 3189 3046 2913 2807 2731 2668 2446 2357 2200 2099 1885 1938 1781 1690 1621 1556 1614 1592 1541 1532 1509 1485 1485 1509 1485 1440 1469 1372 1472 1390 1328 1440 1412 1431 1473 1469 1503 1459 1578 1554 1564 1605 1738 1792 1931 2050 2291 2398 2671 2755 2912 2827 2853 2678 2569 2204 2207 2088 1990 2235 2122 2159 2032 1945 1731 1653 1517 1423 1474 1471 1412 1369 1396 1426 1419 1359 1429 1405 1451 1378 1503 1380 1468 1432 1418 1443 1470 1455 1574 1476 1497 1555 1632 1593 1737 1657 1778 1779 1830 1899 1898 1989 2091 2234 2173 2313 2321 2419 2439 2527 2514 2634 2739 2645 2760 2661 2620 2630 2411 2476 2457 2378 2269 2265 2181 2148 2108 1948 1890 1934 1790 1883 1784 1774 1793 1678 1716 1762 1640 1757 1810 1780 1716 1820 1830 1756 1800 1817 1805 1941 1903 1963 1999 1931 2012 1956 1977 2007 2034 1944 1974 1967 2002 2003 2011 2041 2069 2068 2168 2051 2200 2188 2471 2442 2522 2675 2721 2897 2976 3041 3079 3149 3088 2918 2775 2674 2536 2519 2336 2484 2387 2452 2331 2300 2216 2271 2196 2235 2226 2350 2511 2719 2930 3239 3381 3629 3882 4038 4289 4450 4482 4431 4490 4256 4176 4303 4252 4229 4288 4126 4145 3869 3752 3216 3095 2909 2702 2521 2504 2275 2296 2240 2061 1957 1784 1802 1730 1594 1575 1496 1556 1443 1499 1447 1521 1499 1425 1534 1537 1557 1577 1565 1551 1718 1842 1918 2000 2151 2527 2677 2963 3119 3325 3365 3259 3056 2688 2495 2306 2215 2311 2264 2296 2246 2237 2069 1834 1708 1555 1463 1430 1341 1385 1284 1300 1279 1251 1257 1271 1288 1322 1247 1235 1274 1207 1245 1234 1242 1235 1238 1205 1184 1280 1191 1165 1271 1113 1198 1225 1212 1246 1242 1180 1157 1103 1187 1307 1188 1197 1205 1138 1252 1174 1235 1186 1209 1193 1208 1193 1171 1105 1143 1125 1225 1151 1160 1227 1111 1276 1212 1155 1179 1136 1156 1162 1172 1125 1136 1170 1135 1186 1208 1107 1145 1167 1164 1192 1242 1162 1165 1126 1110 1155 1124 1164 1157 1222 1146 1225 1195 1193 1122 1228 1139 1141 1176 1138 1189 1144 1204 1165 1117 1253 1175 1107 1167 1133 1166 1109 1123 1147 1095 1187 1201 1212 1114 1193 1160 1223 1187 1154 1144 1186 1208 1151 1180 1216 1161 1195 1153 1147 1185 1137 1242 1169 1199 1180 1172 1219 1104 1228 1283 1118 1278 1221 1225 1257 1183 1205 1284 1255 1234 1314 1273 1250 1222 1310 1326 1462 1398 1487 1489 1638 1646 1611 1529 1593 1545 1467 1485 1402 1401 1480 1435 1438 1450 1429 1344 1361 1371 1327 1255 1245 1329 1324 1403 1326 1323 1352 1337 1324 1440 1488 1517 1381 1460 1549 1481 1579 1622 1560 1637 1727 1841 1744 1919 1973 2052 1990 2140 2218 2283 2244 2188 2236 2227 2138 2121 2184 2031 1923 1997 1901 1932 1851 1878 1864 1890 1901 1982 1983 2023 2099 2290 2542 2591 2779 2874 2737 2717 2451 2347 2234 2020 2045 2044 2097 2100 2204 2221 1945 1995 1869 1670 1631 1616 1473 1511 1557 1568 1565 1539 1597 1606 1688 1717 1753 1798 1780 1920 1802 1943 2011 1954 1927 1898 1882 1890 1899 1790 1912 1747 1797 1746 1787 1677 1611 1634 1545 1528 1588 1463 1519 1469 1482 1340 1432 1462 1413 1384 1429 1404 1362 1365 1382 1322 1324 1369 1329 1339 1356 1362 1316 1288 1320 1370 1346 1398 1353 1370 1372 1347 1412 1420 1487 1448 1529 1507 1514 1603 1627 1662 1717 1777 1911 2111 2465 2685 3059 3370 4029 4732 5592 6409 7093 7953 8387 8759 8337 7851 7167 6389 5733 5354 5226 5038 5200 5152 5230 5069 4604 4042 3458 3067 2631 2248 2012 1825 1705 1622 1553 1552 1490 1411 1452 1434 1426 1369 1346 1337 1350 1304 1310 1309 1269 1328 1250 1221 1200 1267 1326 1274 1277 1203 1250 1202 1266 1191 1293 1280 1238 1186 1229 1262 1194 1382 1206 1328 1255 1347 1259 1350 1271 1275 1361 1278 1233 1295 1247 1297 1263 1287 1237 1302 1234 1247 1226 1289 1290 1257 1251 1243 1239 1178 1209 1231 1252 1199 1305 1306 1282 1248 1375 1434 1413 1450 1537 1627 1670 1711 1795 1712 1670 1595 1687 1639 1640 1664 1851 1965 2043 2060 2156 2219 2159 2010 1952 1800 1711 1661 1666 1606 1587 1667 1649 1649 1630 1586 1498 1491 1420 1383 1222 1355 1236 1317 1306 1316 1286 1239 1215 1225 1272 1253 1298 1315 1280 1319 1255 1273 1300 1305 1220 1312 1282 1365 1265 1305 1384 1369 1411 1369 1340 1443 1490 1446 1484 1450 1622 1673 1692 1872 1817 1992 2177 2314 2379 2393 2537 2527 2588 2620 2687 2901 3106 3354 3496 3771 3973 3878 3952 3597 3450 3056 2950 2890 3032 3317 3512 3781 4258 4498 4922 5323 5353 5684 5592 5402 4948 4748 4534 4487 4521 4523 4395 4519 4436 4245 4006 3850 3466 3323 3050 3071 2836 2741 2560 2397 2366 2141 2048 1964 2062 1922 1938 1853 1857 1813 1799 1859 1743 1741 1878 1825 1761 1808 1786 1809 1893 1872 1794 1965 1900 1915 1972 2038 2090 2125 2211 2299 2457 2594 2667 2655 2947 2969 3102 3250 3143 3239 3266 3143 3134 3070 3027 3128 2990 3185 3386 3357 3497 3740 3778 3832 3836 3854 3586 3434 3040 2832 2657 2520 2484 2558 2416 2461 2461 2453 2443 2242 2140 2011 1857 1820 1768 1742 1652 1665 1610 1587 1564 1577 1553 1699 1585 1580 1609 1725 1670 1679 1733 1830 1950 2049 2153 2269 2513 2606 2887 3195 3406 3627 3719 3791 3593 3447 3210 3193 3284 3313 3608 3759 4053 4166 4486 4529 4489 4292 4223 4032 3844 3671 3389 3322 3333 3109 3102 3065 3163 2961 3054 2837 2781 2617 2549 2555 2457 2422 2298 2217 2319 2316 2251 2169 2200 2167 2292 2119 2071 2262 2316 2474 2399 2488 2709 2691 2703 2692 2775 2717 2645 2622 2472 2448 2336 2414 2268 2295 2193 2277 2199 2249 2050 2112 1994 1994 1907 1796 1814 1791 1703 1631 1666 1593 1603 1565 1482 1540 1473 1537 1518 1494 1533 1525 1493 1505 1480 1470 1462 1552 1493 1591 1472 1552 1521 1490 1607 1583 1646 1643 1699 1727 1836 1727 1784 1821 1817 1865 1903 1837 1891 1921 1940 1930 2054 2131 2161 2174 2040 2004 1995 1738 1755 1608 1532 1691 1721 1696 1723 1722 1675 1639 1642 1530 1585 1508 1565 1556 1615 1676 1780 1779 1913 2059 2218 2434 2555 2841 2993 3183 3209 3477 3523 3439 3252 3011 2686 2508 2399 2365 2404 2472 2499 2533 2751 2767 2959 2845 2988 2992 3111 3368 3434 3594 3507 3378 3179 2957 2588 2385 2346 2247 2283 2348 2473 2566 2520 2527 2425 2345 2185 1971 1925 1795 1795 1679 1606 1607 1631 1586 1663 1757 1779 1959 2029 2211 2479 2715 3213 3687 4168 4745 5367 5645 5763 5728 5392 4534 3969 3435 3078 2992 2999 3100 3215 3489 3627 3727 3492 3312 2872 2609 2294 1902 1772 1595 1657 1517 1521 1395 1461 1431 1462 1453 1462 1414 1387 1369 1447 1353 1364 1476 1325 1510 1399 1506 1479 1529 1527 1638 1768 1889 1945 2281 2414 2793 3023 3492 3866 4293 4651 4669 4861 4599 4352 3918 3427 3081 2938 2786 2857 2944 3020 3149 3155 3131 3109 2802 2573 2337 2190 2033 1981 1886 1829 1850 1938 2060 1977 2166 2227 2276 2274 2372 2235 2221 2226 2094 2009 1984 1932 1962 1936 1927 1877 1871 1833 1769 1822 1779 1713 1655 1598 1511 1563 1471 1461 1454 1442 1396 1349 1381 1377 1368 1467 1414 1447 1399 1416 1412 1404 1470 1451 1469 1512 1573 1561 1487 1562 1449 1551 1530 1556 1498 1581 1655 1556 1681 1673 1757 1645 1794 1798 1909 1979 1974 2037 2068 2189 2196 2349 2301 2443 2435 2490 2391 2504 2351 2402 2394 2271 2214 2221 2146 2070 2144 2080 1995 2018 1999 1950 1882 1844 1862 1827 1736 1719 1568 1624 1558 1625 1573 1512 1576 1458 1418 1499 1440 1535 1448 1451 1477 1374 1479 1390 1442 1415 1417 1511 1522 1529 1622 1598 1674 1697 1789 1945 2160 2402 2649 3067 3628 4154 4861 5435 5636 5680 5242 4731 4046 3553 3051 2882 2759 2763 2925 3102 3280 3500 3629 3621 3370 3020 2628 2350 2193 1956 1746 1813 1667 1634 1693 1629 1698 1600 1642 1596 1735 1652 1696 1661 1730 1715 1737 1927 1910 1981 1971 2014 2080 2152 2267 2258 2281 2496 2468 2622 2786 2870 3170 3336 3583 3790 4192 4408 4552 4886 4767 4695 4530 4291 4014 3932 3687 3658 3721 3546 3559 3525 3717 3680 3715 3591 3447 3245 3033 2883 2757 2724 2495 2483 2331 2368 2308 2353 2261 2251 2232 2332 2478 2479 2668 2918 3026 3334 3612 3822 3893 4170 4251 4171 3968 3564 3160 2796 2715 2635 2626 2624 2666 2708 2740 2943 2833 2710 2647 2386 2127 2002 1875 1787 1776 1722 1648 1618 1687 1644 1682 1676 1662 1647 1691 1720 1618 1714 1616 1589 1691 1598 1611 1593 1438 1613 1543 1523 1548 1595 1547 1642 1588 1615 1674 1700 1611 1747 1625 1579 1645 1502 1429 1502 1401 1428 1421 1393 1449 1411 1451 1478 1423 1509 1454 1357 1364 1319 1393 1253 1318 1346 1348 1321 1296 1305 1283 1252 1351 1252 1426 1337 1349 1368 1394 1420 1379 1411 1408 1431 1400 1472 1452 1514 1487 1481 1525 1558 1592 1545 1725 1646 1746 1705 1807 1794 1896 1954 1979 1844 1919 1901 1876 1859 1868 1822 1797 1861 1681 1743 1770 1715 1767 1742 1698 1665 1645 1689 1534 1547 1545 1501 1470 1531 1444 1489 1379 1500 1369 1442 1407 1452 1516 1370 1461 1469 1436 1448 1462 1456 1561 1577 1531 1577 1590 1673 1775 1868 2069 2108 2421 2660 2813 3057 3183 3015 3142 3017 3054 3181 3393 3494 3625 3873 3662 3665 3561 3293 3340 3074 3010 2902 2768 2759 2729 2699 2807 2720 2626 2515 2407 2331 2180 2105 2003 2039 1909 1974 1991 1948 1923 1972 2134 2293 2426 2638 2919 3042 3310 3477 3618 3513 3309 3082 2833 2556 2441 2359 2230 2228 2230 2395 2504 2528 2631 2635 2564 2390 2247 2245 2147 2080 2061 2112 2105 2238 2163 2263 2119 2056 2047 1873 1847 1890 1869 1833 1941 2000 2185 2259 2486 2571 2850 3026 3139 3372 3363 3592 3666 3594 3729 3578 3472 3366 3077 3087 2982 2995 3078 3116 3051 3422 3480 3562 3628 3717 3824 3776 3894 3756 3858 3643 3419 3134 2855 2561 2336 2321 2236 2137 2303 2195 2216 2306 2407 2312 2228 2146 1976 1827 1761 1595 1605 1457 1559 1365 1448 1420 1401 1526 1364 1336 1424 1396 1363 1412 1370 1382 1326 1403 1390 1329 1393 1345 1409 1409 1462 1402 1373 1518 1459 1437 1466 1479 1496 1475 1602 1599 1652 1654 1739 1670 1777 1862 1882 1923 1969 2035 2120 2134 2241 2141 2064 2042 2100 2169 2218 2155 2211 2187 2191 2260 2253 2185 2258 2152 2140 2190 2117 2118 2078 2005 2158 2069 2085 1989 2062 2116 1950 1958 1871 1778 1775 1749 1741 1642 1656 1632 1676 1631 1649 1626 1540 1534 1510 1539 1470 1412 1398 1393 1295 1389 1333 1291 1311 1268 1322 1315 1322 1279 1318 1332 1261 1390 1325 1283 1384 1332 1326 1292 1309 1280 1290 1268 1239 1262 1281 1256 1200 1259 1182 1268 1270 1263 1277 1223 1256 1254 1142 1209 1176 1161 1198 1169 1244 1213 1171 1254 1233 1272 1110 1204 1183 1226 1284 1219 1218 1257 1254 1259 1220 1226 1195 1325 1222 1268 1283 1300 1330 1264 1255 1349 1345 1343 1394 1343 1358 1368 1337 1369 1445 1441 1506 1494 1489 1492 1543 1598 1672 1683 1724 1817 1759 1883 1865 1976 1932 2046 2120 2153 2346 2538 2629 2921 3034 3280 3208 3264 3101 2902 2642 2591 2371 2371 2489 2480 2516 2527 2719 2757 2904 2940 2962 2810 2676 2568 2313 2310 2181 2291 2277 2430 2589 2809 2943 3204 3178 3149 3026 2919 2551 2530 2345 2079 2144 2128 2142 2235 2361 2354 2399 2511 2475 2532 2437 2297 2188 2037 2074 1814 1849 1827 1690 1714 1698 1720 1691 1714 1683 1754 1697 1689 1824 1699 1776 1848 1922 2029 2071 2203 2217 2299 2155 2052 2005 1907 1981 1929 2052 2084 2217 2315 2507 2787 2826 2780 2662 2519 2385 2193 2166 2129 2101 2026 1994 1991 1963 1973 2013 2046 2059 1993 1914 1935 1882 1930 1866 1830 1874 1791 1857 1803 1820 1808 1873 1867 1911 2031 2009 2079 2150 2110 2073 2056 1921 1976 1888 1846 1801 1889 1865 1814 1728 1692 1693 1782 1679 1716 1799 1669 1587 1564 1510 1480 1503 1392 1397 1347 1337 1391 1370 1300 1257 1319 1329 1308 1263 1299 1291 1291 1209 1270 1280 1307 1259 1248 1213 1216 1217 1288 1246 1298 1287 1337 1307 1378 1420 1499 1447 1520 1599 1665 1728 1701 1876 1972 1974 2065 2092 2006 1872 1759 1639 1570 1449 1449 1481 1512 1553 1576 1616 1549 1683 1600 1596 1590 1469 1374 1437 1352 1317 1280 1210 1229 1163 1221 1218 1161 1221 1191 1215 1214 1156 1196 1104 1141 1215 1280 1287 1210 1218 1266 1200 1270 1339 1328 1268 1311 1304 1353 1310 1248 1283 1249 1272 1288 1280 1382 1340 1288 1340 1379 1374 1372 1381 1423 1348 1329 1311 1322 1309 1287 1241 1272 1327 1319 1198 1214 1331 1241 1309 1204 1276 1268 1229 1307 1272 1237 1195 1188 1190 1177 1213 1214 1197 1191 1285 1221 1314 1352 1290 1288 1270 1240 1245 1170 1226 1236 1133 1205 1227 1154 1201 1224 1206 1179 1292 1257 1177 1248 1218 1198 1185 1316 1245 1258 1224 1246 1287 1183 1234 1274 1169 1242 1258 1217 1256 1134 1172 1213 1231 1199 1222 1260 1277 1256 1317 1305 1247 1332 1291 1270 1359 1278 1389 1416 1398 1465 1425 1499 1543 1628 1596 1617 1674 1587 1557 1660 1611 1581 1553 1587 1596 1619 1709 1656 1770 1640 1796 1755 1933 1936 1912 2111 2114 2173 2275 2472 2585 2770 2906 3200 3175 3380 3458 3382 3417 3129 3005 2893 2812 2724 2598 2516 2542 2509 2626 2675 2842 2846 2862 2972 3062 2965 2995 3020 3101 3133 3070 3238 3335 3309 3105 3333 3138 3027 2834 2826 2673 2560 2524 2403 2418 2243 2328 2428 2407 2505 2559 2556 2562 2663 2572 2720 2678 2578 2537 2468 2202 2069 2014 1850 1761 1665 1671 1582 1655 1608 1694 1596 1668 1610 1659 1675 1631 1718 1555 1597 1542 1494 1404 1422 1385 1513 1506 1514 1485 1521 1451 1429 1413 1403 1348 1405 1388 1426 1473 1473 1556 1523 1710 1768 1975 2162 2165 2279 2381 2372 2335 2315 2319 2407 2463 2472 2540 2631 2644 2614 2720 2716 2776 2823 2889 2823 2802 2729 2574 2551 2447 2377 2320 2204 2194 2162 2204 2063 2021 1946 2002 1979 1999 1886 1773 1672 1690 1541 1542 1536 1376 1454 1344 1338 1340 1350 1368 1381 1299 1234 1311 1308 1252 1261 1313 1289 1232 1283 1272 1363 1242 1288 1207 1231 1182 1151 1171 1105 1189 1080 1157 1153 1200 1163 1180 1121 1275 1219 1118 1203 1110 1188 1157 1251 1214 1149 1231 1279 1230 1351 1499 1508 1668 1803 1774 1919 1884 1784 1663 1599 1480 1454 1354 1290 1341 1336 1320 1339 1375 1485 1394 1513 1516 1467 1477 1457 1454 1346 1336 1235 1220 1263 1211 1228 1175 1206 1156 1216 1142 1161 1147 1120 1130 1111 1118 1129 1181 1128 1229 1161 1076 1109 1161 1179 1263 1197 1244 1274 1267 1333 1311 1435 1611 1586 1834 1973 2108 2089 2224 2119 2006 1901 1773 1695 1605 1460 1457 1426 1420 1448 1509 1457 1613 1630 1763 1837 1991 1949 1963 1967 1801 1760 1572 1578 1537 1497 1485 1534 1494 1576 1644 1621 1615 1566 1504 1556 1491 1505 1422 1414 1363 1420 1366 1266 1295 1406 1357 1353 1369 1328 1347 1293 1344 1284 1286 1194 1204 1226 1229 1223 1313 1312 1272 1376 1370 1276 1376 1373 1293 1252 1187 1226 1249 1179 1222 1171 1218 1228 1242 1242 1282 1296 1308 1299 1292 1465 1361 1391 1422 1494 1531 1435 1529 1585 1622 1618 1701 1769 1775 1729 1709 1731 1658 1689 1682 1703 1658 1686 1753 1763 1939 2032 1955 2103 2073 1942 1914 1920 1767 1749 1727 1610 1697 1852 1766 1837 1990 2071 2295 2251 2355 2395 2321 2284 2096 2035 1906 1750 1781 1692 1644 1570 1543 1512 1562 1626 1622 1614 1696 1682 1589 1624 1639 1534 1531 1445 1423 1295 1348 1257 1234 1334 1264 1187 1268 1266 1287 1209 1305 1355 1309 1306 1279 1243 1192 1189 1240 1205 1227 1249 1245 1286 1267 1293 1322 1370 1342 1349 1298 1288 1266 1258 1310 1257 1302 1210 1204 1234 1215 1243 1293 1363 1411 1454 1452 1465 1507 1544 1623 1547 1533 1541 1619 1552 1554 1453 1479 1394 1428 1396 1369 1387 1450 1485 1523 1523 1426 1594 1523 1608 1544 1560 1574 1602 1575 1494 1464 1474 1475 1467 1547 1521 1527 1582 1528 1577 1617 1695 1667 1774 1752 1865 1954 2032 2170 2266 2534 2703 2946 3127 3022 3109 2913 2826 2809 2642 2496 2477 2385 2245 2216 2167 2034 2024 2017 2149 2158 2205 2274 2201 2127 2121 1944 1936 1868 1780 1797 1794 1594 1537 1534 1406 1408 1312 1263 1297 1389 1248 1245 1186 1253 1213 1297 1262 1236 1228 1253 1319 1305 1344 1333 1320 1388 1514 1561 1679 1684 1699 1733 1647 1610 1557 1427 1410 1340 1286 1442 1346 1418 1424 1402 1443 1470 1451 1452 1522 1581 1647 1702 1647 1769 1827 1897 1906 2026 1994 2043 1910 1855 1752 1617 1589 1585 1525 1521 1513 1438 1442 1392 1472 1570 1592 1599 1576 1582 1543 1550 1510 1447 1423 1370 1352 1318 1337 1245 1225 1242 1292 1183 1248 1210 1179 1185 1130 1250 1138 1209 1089 1111 1119 1086 1104 1148 1144 1101 1105 1109 1148 1039 1115 1110 1094 1074 1081 1074 1108 1046 1104 1112 1039 1073 1029 1042 1095 1097 1074 1037 982 1040 1065 1175 1102 1113 1097 989 1075 1110 998 1127 1098 1094 1079 1059 1138 1092 1066 1121 1046 1079 1123 1094 1155 1205 1197 1246 1329 1315 1232 1300 1224 1146 1186 1260 1160 1163 1195 1190 1152 1157 1210 1119 1219 1246 1324 1284 1341 1343 1351 1453 1486 1461 1527 1500 1615 1450 1663 1706 1716 1745 1692 1701 1749 1626 1550 1604 1561 1566 1464 1486 1500 1535 1475 1566 1537 1627 1710 1774 1897 1956 1899 2005 1956 1958 1890 1804 1567 1543 1458 1413 1410 1394 1326 1299 1313 1389 1371 1291 1386 1447 1445 1580 1534 1518 1436 1366 1425 1409 1466 1593 1609 1739 1720 1832 1855 1881 1848 1824 1745 1633 1555 1535 1488 1364 1370 1450 1324 1385 1419 1414 1481 1465 1465 1563 1557 1542 1631 1540 1424 1443 1421 1410 1341 1375 1298 1356 1243 1210 1248 1266 1201 1276 1218 1225 1227 1255 1340 1319 1388 1312 1461 1459 1519 1463 1476 1528 1497 1492 1386 1454 1380 1400 1395 1438 1361 1410 1450 1391 1461 1550 1476 1529 1497 1375 1490 1446 1384 1391 1450 1277 1388 1318 1403 1362 1315 1320 1323 1406 1312 1290 1349 1222 1309 1260 1242 1215 1181 1172 1235 1221 1202 1188 1144 1182 1168 1220 1145 1140 1144 1158 1143 1220 1096 1183 1114 1218 1101 1163 1094 1196 1094 1125 1158 1109 1132 1050 1124 1087 1104 1005 1085 1117 1087 1076 1137 1189 1148 1093 1019 1051 1027 1115 1083 1005 1070 1065 1096 1151 1028 1077 992 1090 1027 1046 1021 1092 1094 1142 1114 1167 1131 1181 1134 1208 1114 1115 1130 1146 1162 1219 1177 1223 1215 1226 1309 1275 1354 1266 1296 1301 1315 1288 1323 1380 1239 1284 1313 1262 1246 1301 1315 1350 1330 1314 1343 1285 1382 1362 1320 1357 1322 1263 1248 1231 1320 1231 1163 1166 1235 1245 1157 1126 1176 1263 1167 1123 1164 1166 1164 1108 1179 1125 1154 1185 1083 1115 1091 1099 1162 1141 1128 1092 1121 1141 1145 1102 1094 1178 1148 1148 1152 1164 1189 1232 1223 1189 1221 1247 1255 1314 1414 1445 1472 1501 1537 1622 1598 1566 1598 1542 1543 1642 1663 1616 1622 1641 1790 1673 1791 1797 1827 1759 1776 1816 1799 1701 1758 1673 1684 1695 1653 1572 1619 1623 1642 1767 1736 1868 1965 1923 1953 2003 2007 2057 1941 2067 2007 2081 2142 2117 2001 2001 1870 1795 1734 1791 1719 1612 1601 1588 1604 1494 1592 1590 1608 1585 1561 1448 1590 1568 1669 1578 1487 1411 1483 1407 1417 1293 1352 1292 1264 1227 1170 1178 1220 1182 1196 1172 1120 1152 1203 1171 1158 1225 1280 1191 1176 1200 1214 1246 1179 1181 1278 1240 1250 1318 1253 1268 1159 1260 1242 1363 1279 1282 1303 1271 1170 1250 1276 1241 1265 1253 1317 1359 1375 1398 1389 1366 1353 1330 1447 1429 1442 1358 1393 1377 1382 1333 1422 1442 1522 1505 1604 1632 1714 1760 1741 1766 1819 1772 1766 1793 1626 1651 1614 1497 1496 1499 1469 1480 1482 1468 1402 1459 1457 1564 1553 1590 1555 1560 1628 1589 1607 1475 1496 1444 1386 1406 1472 1326 1303 1249 1251 1323 1287 1331 1336 1324 1414 1374 1444 1443 1551 1535 1546 1663 1636 1768 1875 1908 1914 1860 1899 1882 1777 1802 1654 1579 1556 1493 1416 1367 1307 1410 1363 1407 1390 1383 1480 1529 1638 1506 1530 1487 1593 1554 1536 1398 1447 1409 1360 1360 1395 1235 1391 1354 1294 1419 1358 1499 1612 1746 1830 1851 1950 1895 1870 1834 1769 1558 1615 1412 1437 1349 1448 1336 1410 1412 1406 1442 1502 1574 1630 1693 1735 1854 1941 2009 2023 1857 1952 1899 1819 1811 1816 1746 1713 1643 1670 1573 1651 1671 1723 1786 1806 1915 2040 2136 2098 2253 2151 2141 2120 1958 2154 2143 2048 2037 1941 1829 1770 1743 1736 1624 1730 1756 1843 1771 1932 1954 1946 2025 1779 1830 1729 1663 1582 1561 1559 1434 1490 1414 1392 1375 1327 1311 1354 1303 1361 1327 1355 1338 1382 1287 1284 1295 1266 1220 1161 1198 1135 1112 1139 1113 1145 1090 1152 1086 1151 1052 1192 1177 1157 1134 1116 1079 1146 1168 1164 1098 1090 1173 1197 1121 1075 1014 1093 1099 1118 1088 1084 1069 1098 1198 1123 1122 1200 1137 1187 1155 1203 1280 1253 1262 1288 1346 1390 1496 1540 1521 1622 1584 1483 1538 1437 1408 1318 1318 1238 1222 1198 1274 1238 1279 1146 1228 1224 1259 1297 1259 1348 1408 1382 1459 1435 1413 1375 1337 1249 1277 1340 1290 1221 1232 1214 1240 1211 1232 1249 1186 1154 1216 1228 1198 1304 1280 1255 1220 1159 1234 1189 1178 1122 1157 1185 1163 1196 1152 1186 1145 1166 1159 1190 1158 1241 1228 1292 1165 1268 1314 1314 1371 1400 1421 1559 1708 1759 1847 1995 2007 2128 2254 2313 2433 2406 2495 2429 2259 2028 1850 1795 1712 1587 1493 1521 1525 1479 1415 1458 1514 1515 1631 1677 1691 1771 1765 1902 1947 1879 1878 1814 1704 1664 1559 1470 1388 1452 1296 1308 1363 1338 1348 1346 1235 1352 1262 1269 1196 1223 1239 1200 1206 1241 1186 1188 1261 1157 1276 1236 1232 1266 1201 1275 1221 1300 1278 1279 1327 1250 1317 1371 1354 1468 1531 1604 1580 1686 1624 1639 1591 1615 1560 1524 1482 1470 1495 1450 1357 1440 1381 1366 1345 1359 1289 1369 1424 1380 1407 1489 1510 1466 1503 1475 1463 1437 1369 1369 1357 1353 1357 1229 1298 1223 1308 1278 1232 1243 1231 1233 1268 1227 1204 1349 1262 1221 1195 1245 1257 1191 1189 1228 1248 1176 1184 1151 1288 1196 1200 1170 1248 1230 1252 1262 1330 1245 1320 1324 1351 1386 1394 1288 1368 1284 1326 1295 1318 1320 1298 1358 1323 1277 1305 1264 1303 1342 1247 1310 1323 1273 1275 1337 1341 1374 1327 1368 1377 1378 1348 1394 1352 1310 1310 1363 1388 1508 1536 1624 1656 1735 1802 1970 1960 2030 2029 1964 1999 1915 1748 1559 1589 1558 1490 1368 1319 1347 1356 1335 1354 1309 1350 1409 1401 1514 1441 1551 1555 1581 1610 1580 1598 1427 1460 1292 1299 1263 1322 1202 1217 1229 1192 1214 1218 1221 1262 1142 1199 1167 1254 1212 1174 1186 1180 1293 1226 1230 1303 1283 1334 1349 1408 1402 1425 1407 1501 1490 1479 1492 1625 1627 1593 1534 1413 1407 1386 1404 1220 1258 1260 1213 1216 1258 1243 1225 1308 1320 1343 1310 1246 1315 1220 1302 1292 1262 1338 1262 1188 1212 1218 1268 1213 1224 1177 1121 1177 1156 1131 1244 1247 1215 1166 1206 1205 1133 1161 1198 1185 1186 1190 1224 1273 1292 1273 1271 1260 1251 1243 1212 1222 1164 1134 1148 1117 1129 1143 1117 1167 1073 1051 1106 1145 1165 1134 1162 1176 1192 1181 1100 1245 1121 1183 1156 1165 1101 1052 1096 1104 1086 1148 1044 1082 1059 1093 1049 1108 1050 1095 1166 1113 1120 1160 1042 1130 1079 1138 1092 1156 1174 1178 1127 1142 1201 1182 1220 1169 1156 1184 1177 1107 1213 1096 1179 1087 1113 1207 1249 1121 1261 1277 1274 1267 1317 1276 1367 1356 1459 1556 1577 1732 1788 1870 1984 1956 1912 1894 1815 1748 1734 1668 1565 1539 1568 1489 1458 1435 1476 1356 1473 1398 1381 1501 1550 1625 1597 1689 1746 1693 1760 1874 1872 1822 1804 1827 1776 1843 1647 1648 1686 1592 1481 1462 1391 1338 1349 1272 1242 1225 1259 1173 1259 1304 1212 1300 1309 1317 1368 1345 1332 1312 1397 1301 1302 1322 1325 1322 1233 1190 1213 1230 1172 1225 1185 1125 1177 1178 1271 1199 1174 1169 1170 1234 1234 1236 1296 1330 1266 1296 1260 1249 1201 1323 1183 1261 1222 1263 1332 1333 1330 1377 1492 1502 1665 1687 1750 1787 1860 1676 1722 1648 1534 1549 1493 1361 1412 1378 1381 1420 1356 1391 1432 1510 1413 1459 1554 1400 1462 1521 1533 1565 1568 1572 1574 1549 1511 1539 1450 1463 1395 1428 1359 1338 1311 1419 1361 1437 1400 1389 1377 1416 1472 1393 1397 1432 1461 1422 1527 1503 1542 1567 1535 1529 1617 1637 1688 1688 1749 1814 1937 1899 1847 1885 1809 1686 1701 1593 1645 1604 1591 1624 1672 1562 1611 1658 1596 1725 1736 1763 1779 1787 1906 1826 1885 1854 1898 1909 1754 1799 1693 1679 1544 1555 1556 1570 1483 1506 1509 1505 1428 1516 1625 1495 1508 1523 1467 1483 1523 1461 1413 1527 1498 1476 1542 1414 1417 1482 1482 1454 1439 1421 1379 1383 1389 1318 1397 1303 1293 1236 1300 1273 1286 1242 1219 1235 1174 1254 1187 1212 1157 1360 1200 1242 1324 1216 1265 1244 1310 1269 1221 1260 1240 1215 1280 1203 1296 1296 1249 1254 1161 1237 1205 1204 1299 1232 1286 1250 1299 1326 1355 1417 1462 1465 1534 1477 1597 1565 1633 1480 1434 1484 1564 1562 1482 1543 1548 1500 1469 1528 1531 1452 1384 1516 1405 1461 1417 1412 1421 1527 1541 1538 1468 1418 1525 1544 1498 1576 1545 1599 1603 1638 1679 1662 1585 1594 1551 1496 1529 1467 1368 1417 1361 1357 1373 1310 1368 1350 1262 1329 1216 1285 1300 1273 1287 1333 1235 1299 1280 1261 1352 1241 1201 1205 1290 1220 1233 1228 1315 1257 1249 1239 1321 1291 1325 1341 1427 1328 1379 1407 1429 1374 1369 1327 1359 1229 1216 1226 1200 1197 1146 1129 1162 1217 1180 1114 1193 1151 1171 1166 1246 1160 1295 1260 1297 1279 1187 1238 1240 1247 1147 1182 1153 1190 1107 1187 1157 1179 1119 1174 1177 1172 1112 1180 1102 1116 1171 1079 1148 1145 1097 1099 1134 1131 1168 1196 1133 1191 1284 1208 1219 1171 1244 1248 1264 1273 1354 1409 1415 1488 1508 1544 1539 1578 1528 1478 1513 1488 1416 1429 1424 1394 1389 1463 1422 1389 1358 1284 1239 1253 1219 1295 1239 1286 1260 1272 1354 1271 1341 1314 1285 1302 1223 1292 1232 1322 1232 1289 1273 1304 1314 1224 1272 1232 1232 1154 1173 1241 1253 1244 1233 1267 1315 1384 1337 1377 1426 1458 1540 1568 1642 1605 1573 1618 1542 1598 1546 1518 1545 1497 1423 1408 1425 1448 1360 1373 1361 1423 1313 1414 1391 1410 1416 1511 1511 1630 1651 1595 1700 1654 1668 1638 1686 1607 1654 1565 1632 1593 1558 1517 1460 1436 1443 1484 1368 1438 1307 1380 1267 1381 1288 1355 1308 1318 1316 1306 1274 1324 1319 1337 1336 1373 1276 1309 1296 1317 1247 1240 1230 1211 1238 1217 1135 1206 1220 1256 1256 1264 1206 1321 1313 1396 1312 1317 1285 1364 1382 1366 1375 1415 1414 1403 1481 1566 1425 1380 1399 1357 1343 1252 1323 1307 1400 1313 1353 1487 1449 1373 1503 1454 1439 1403 1452 1444 1408 1404 1453 1344 1433 1357 1394 1302 1321 1294 1257 1262 1311 1244 1250 1250 1272 1194 1295 1247 1277 1287 1336 1262 1315 1291 1346 1325 1303 1325 1355 1455 1556 1586 1619 1680 1700 1576 1586 1546 1494 1532 1430 1425 1494 1447 1412 1422 1457 1472 1501 1308 1406 1365 1367 1349 1426 1344 1429 1403 1435 1465 1493 1393 1444 1469 1382 1388 1352 1281 1334 1325 1414 1356 1444 1325 1384 1462 1450 1488 1560 1475 1460 1443 1450 1389 1386 1313 1246 1197 1219 1144 1241 1183 1193 1194 1159 1186 1231 1137 1135 1129 1202 1136 1196 1123 1182 1214 1190 1174 1180 1148 1149 1157 1149 1167 1160 1118 1103 1060 1098 1070 1082 1037 1065 1164 1132 1055 1088 1090 1069 1161 1098 1095 1050 1071 1104 1057 1133 1174 1113 1191 1132 1116 1135 1156 1200 1207 1208 1212 1242 1254 1222 1308 1236 1222 1221 1241 1254 1230 1186 1176 1129 1187 1129 1156 1181 1197 1123 1220 1052 1250 1226 1160 1246 1188 1163 1161 1231 1253 1234 1321 1283 1247 1260 1213 1314 1232 1282 1269 1260 1287 1268 1267 1244 1272 1245 1200 1260 1216 1256 1275 1270 1281 1293 1258 1329 1334 1286 1248 1330 1298 1229 1279 1304 1312 1318 1287 1372 1354 1408 1446 1402 1498 1424 1446 1489 1522 1511 1570 1518 1534 1583 1622 1619 1583 1643 1646 1633 1638 1689 1654 1594 1627 1637 1661 1646 1538 1554 1507 1566 1516 1484 1413 1469 1489 1487 1459 1477 1479 1499 1470 1478 1445 1427 1486 1466 1503 1525 1503 1513 1488 1626 1524 1491 1576 1578 1544 1631 1598 1550 1555 1568 1468 1503 1532 1423 1484 1392 1477 1361 1392 1440 1384 1344 1378 1300 1307 1262 1382 1285 1287 1338 1395 1350 1404 1478 1421 1458 1382 1486 1464 1445 1395 1476 1431 1512 1371 1414 1370 1508 1342 1466 1393 1336 1414 1415 1345 1365 1337 1385 1316 1384 1385 1339 1405 1388 1429 1424 1434 1469 1513 1460 1544 1455 1493 1434 1466 1418 1436 1422 1473 1456 1319 1420 1421 1416 1393 1440 1333 1377 1360 1274 1365 1369 1410 1280 1329 1346 1295 1398 1339 1270 1316 1280 1266 1322 1317 1301 1359 1261 1249 1229 1242 1183 1234 1198 1197 1251 1218 1180 1258 1200 1173 1233 1207 1131 1192 1128 1191 1192 1165 1101 1077 1132 1096 1162 1085 1112 1154 1157 1128 1158 1112 1189 1154 1186 1143 1206 1150 1039 1147 1163 1162 1184 1253 1242 1232 1278 1221 1210 1196 1231 1264 1313 1260 1327 1289 1286 1243 1448 1417 1458 1362 1383 1354 1383 1337 1311 1297 1288 1277 1215 1235 1227 1188 1254 1224 1206 1180 1241 1231 1221 1230 1245 1275 1240 1242 1308 1288 1227 1238 1271 1248 1278 1288 1247 1254 1255 1284 1224 1208 1240 1173 1181 1160 1207 1126 1178 1189 1179 1165 1191 1145 1168 1174 1150 1098 1200 1178 1179 1146 1141 1199 1179 1264 1209 1196 1227 1241 1166 1194 1274 1206 1157 1245 1244 1124 1207 1256 1220 1248 1266 1309 1187 1271 1171 1247 1218 1272 1248 1257 1313 1256 1336 1276 1244 1279 1297 1303 1306 1310 1216 1327 1400 1359 1400 1459 1488 1390 1424 1537 1472 1453 1517 1523 1578 1696 1701 1710 1759 1702 1762 1690 1701 1682 1668 1713 1699 1738 1765 1680 1737 1678 1767 1762 1769 1777 1686 1711 1685 1720 1715 1714 1748 1781 1758 1733 1855 1776 1828 1763 1817 1775 1707 1762 1785 1757 1763 1803 1691 1745 1717 1714 1690 1746 1696 1829 1686 1768 1799 1760 1695 1679 1620 1627 1527 1638 1583 1584 1537 1477 1503 1442 1536 1430 1460 1455 1497 1449 1482 1447 1554 1542 1554 1498 1531</counts>
			</dataPoints>
		</scan>
	</xrdMeasurement>
</xrdMeasurements>