File: dataset/precursor_mixture/GeO2_Nb2O5_In2O3_K2SO4.12-min.xrdml
<?xml version="1.0"?>
<xrdMeasurements xmlns="http://www.xrdml.com/XRDMeasurement/2.2" xmlns:xsi="http://www.w3.org/2001/XMLSchema-instance" xsi:schemaLocation="http://www.xrdml.com/XRDMeasurement/2.2 http://www.xrdml.com/XRDMeasurement/2.2/XRDMeasurement.xsd" status="Completed" recordIdentifier="{90C2E98F-642D-4279-B8CA-F1061061B388}">
	<comment>
		<entry/>
	</comment>
	<sample type="To be analyzed">
		<id>dara-37-2</id>
		<name></name>
		<preparedBy></preparedBy>
	</sample>
	<xrdMeasurement measurementType="Scan" status="Completed" sampleMode="Reflection">
		<usedWavelength intended="K-Alpha 1">
			<kAlpha1 unit="Angstrom">1.5405980</kAlpha1>
			<kAlpha2 unit="Angstrom">1.5444260</kAlpha2>
			<kBeta unit="Angstrom">1.3922500</kBeta>
			<ratioKAlpha2KAlpha1>0.5000</ratioKAlpha2KAlpha1>
		</usedWavelength>
		<incidentBeamPath>
			<radius unit="mm">145.00</radius>
			<xRayTube id="1010048" name="Empyrean Cu LFF HR (9430 033 7310x) DK430614">
				<tension unit="kV">40.0</tension>
				<current unit="mA">15.0</current>
				<anodeMaterial>Cu</anodeMaterial>
				<focus type="Line">
					<length unit="mm">12.0</length>
					<width unit="mm">0.4</width>
					<takeOffAngle unit="deg">6.0</takeOffAngle>
				</focus>
			</xRayTube>
			<filter id="20010004" name="Beta-filter Nickel">
				<material>Ni</material>
				<thickness unit="mm">0.020</thickness>
			</filter>
			<sollerSlit id="21010002" name="Soller slits 0.04 rad.">
				<opening unit="rad">0.0400</opening>
			</sollerSlit>
			<mask id="22031000" name="Fixed mask 13 mm">
				<width unit="mm">9.00</width>
			</mask>
			<divergenceSlit id="22120001" name="Divergence slit 1°" xsi:type="fixedDivergenceSlitType">
				<distanceToSample unit="mm">50.00</distanceToSample>
				<height unit="mm">1.52</height>
			</divergenceSlit>
		</incidentBeamPath>
		<beamKnife id="29030100" name="Beam knife low"/>
		<sampleMovement xsi:type="spinningSampleMovementType">
			<spinnerRevolutionTime unit="seconds">1.0</spinnerRevolutionTime>
		</sampleMovement>
		<diffractedBeamPath>
			<radius unit="mm">145.00</radius>
			<antiScatterSlit id="22090040" name="AS slit 9 mm" xsi:type="fixedAntiScatterSlitType">
				<height unit="mm">9.00</height>
			</antiScatterSlit>
			<sollerSlit id="21020003" name="Large Soller slits 0.04 rad.">
				<opening unit="rad">0.0400</opening>
			</sollerSlit>
			<filter id="20030001" name="Large beta-filter Nickel">
				<material>Ni</material>
				<thickness unit="mm">0.020</thickness>
			</filter>
			<detector id="7010019" name="PIXcel1D-Medipix3 detector" xsi:type="rtmsDetectorType">
				<phd unit="keV">
					<lowerLevel>4.0</lowerLevel>
					<upperLevel>11.3</upperLevel>
				</phd>
				<mode>Scanning</mode>
				<activeLength unit="deg">5.020</activeLength>
			</detector>
		</diffractedBeamPath>
		<scan appendNumber="0" mode="Continuous" scanAxis="Gonio" status="Completed">
			<header>
				<startTimeStamp>2024-02-18T12:16:09-08:00</startTimeStamp>
				<endTimeStamp>2024-02-18T12:28:37-08:00</endTimeStamp>
				<author>
					<name>AutomatedUser</name>
				</author>
				<source>
					<applicationSoftware version="1.4b (28)">PANalytical Aeris Instrument Suite</applicationSoftware>
					<instrumentControlSoftware version="2.0.0 20210224">AERIS</instrumentControlSoftware>
					<instrumentID>950485</instrumentID>
				</source>
			</header>
			<dataPoints>
				<positions axis="2Theta" unit="deg">
					<startPosition>9.99043322</startPosition>
					<endPosition>100.09495370</endPosition>
				</positions>
				<positions axis="Omega" unit="deg">
					<startPosition>4.99521661</startPosition>
					<endPosition>50.04747685</endPosition>
				</positions>
				<commonCountingTime unit="seconds">18.249</commonCountingTime>
				<counts unit="counts">3874 3763 3914 3828 3724 3775 3806 3732 3763 3829 3794 3804 3681 3666 3766 3767 3790 3695 3745 3705 3695 3777 3792 3832 3742 3667 3573 3764 3774 3694 3631 3627 3803 3578 3658 3679 3775 3604 3748 3691 3580 3610 3576 3699 3641 3586 3696 3630 3653 3572 3559 3640 3598 3721 3525 3570 3584 3529 3594 3522 3494 3584 3585 3603 3480 3636 3451 3430 3499 3471 3569 3508 3565 3506 3449 3521 3554 3539 3427 3547 3487 3415 3521 3373 3504 3512 3468 3540 3404 3542 3478 3492 3430 3472 3323 3533 3466 3448 3478 3496 3401 3477 3374 3494 3424 3328 3305 3341 3482 3398 3425 3317 3343 3358 3511 3293 3336 3299 3383 3358 3478 3255 3283 3246 3325 3326 3247 3369 3300 3214 3322 3265 3288 3261 3194 3345 3342 3332 3300 3338 3201 3119 3269 3185 3231 3316 3224 3225 3282 3247 3160 3141 3346 3172 3226 3218 3182 3261 3194 3184 3260 3182 3157 3143 3175 3119 3168 3171 3290 3028 3171 3163 3235 3077 3127 3112 3145 3109 3087 3158 2972 3079 3082 3107 3163 3158 3025 3053 3124 3130 3089 3137 3005 3054 3109 3136 3105 3062 3089 3035 3081 3098 3028 3018 3080 3030 3084 2936 3052 3034 3075 3058 3069 2963 3030 2997 3104 2941 2939 3020 3002 2956 3025 2955 3064 2933 2962 3093 3032 2933 2940 2925 3081 2879 3089 2934 2903 2997 2922 2882 2915 3003 2960 2944 2912 2948 2899 2906 2911 3001 2887 2913 2976 2901 2997 2939 2876 2933 2873 2851 2913 2996 2909 2900 2915 2834 2829 2980 2952 2880 2945 2840 2923 2906 2838 2913 3004 2898 2804 2908 2863 2883 2839 2853 2892 2903 2899 2861 2898 2818 2795 2847 2826 2897 2841 2835 2836 2854 2794 2865 2785 2891 2829 2861 2881 2789 2800 2824 2811 2916 2900 2742 2794 2880 2824 2755 2761 2768 2819 2792 2779 2842 2921 2752 2744 2742 2785 2847 2886 2767 2768 2628 2738 2753 2756 2784 2763 2735 2852 2761 2823 2780 2694 2790 2685 2662 2739 2654 2764 2821 2728 2724 2726 2719 2720 2707 2791 2760 2713 2665 2663 2679 2732 2699 2654 2805 2640 2757 2730 2683 2711 2750 2739 2806 2718 2724 2679 2661 2689 2715 2716 2597 2582 2679 2691 2594 2679 2670 2604 2711 2638 2656 2662 2625 2606 2652 2685 2594 2642 2607 2665 2687 2662 2648 2676 2600 2695 2598 2706 2634 2655 2618 2595 2649 2781 2632 2595 2502 2701 2601 2691 2603 2566 2700 2666 2670 2743 2638 2631 2697 2624 2591 2562 2722 2602 2673 2613 2693 2563 2594 2605 2557 2626 2668 2650 2585 2623 2532 2553 2594 2671 2566 2611 2638 2552 2663 2631 2568 2590 2603 2532 2542 2518 2546 2521 2502 2679 2402 2651 2497 2502 2504 2620 2597 2646 2667 2541 2627 2660 2544 2465 2672 2453 2604 2618 2548 2564 2483 2529 2540 2535 2531 2477 2671 2610 2588 2502 2501 2551 2567 2574 2514 2539 2599 2638 2557 2636 2543 2523 2709 2517 2537 2561 2471 2482 2554 2607 2483 2454 2539 2652 2510 2657 2456 2519 2550 2524 2498 2511 2502 2613 2492 2573 2481 2632 2474 2560 2555 2546 2525 2542 2493 2505 2461 2545 2527 2590 2586 2561 2599 2442 2437 2540 2462 2515 2521 2471 2527 2469 2535 2443 2463 2361 2470 2495 2455 2496 2501 2522 2547 2509 2463 2529 2446 2485 2422 2550 2480 2405 2527 2544 2456 2427 2477 2402 2432 2423 2461 2418 2564 2453 2460 2514 2498 2452 2476 2386 2433 2488 2503 2433 2466 2427 2527 2426 2437 2524 2430 2426 2559 2486 2499 2429 2353 2421 2344 2418 2464 2397 2409 2446 2496 2396 2397 2455 2450 2407 2381 2381 2415 2488 2404 2498 2538 2561 2484 2560 2589 2557 2535 2505 2604 2514 2549 2579 2624 2621 2615 2747 2742 2706 2697 2876 2650 2729 2569 2660 2648 2677 2546 2530 2512 2532 2531 2487 2561 2324 2484 2385 2485 2344 2381 2404 2369 2376 2433 2372 2494 2424 2408 2497 2383 2460 2448 2505 2570 2500 2499 2452 2555 2568 2609 2633 2681 2564 2771 2839 2809 2809 2876 2911 2969 2974 2932 3028 2883 2855 2855 2700 2746 2733 2689 2631 2531 2534 2508 2509 2464 2269 2315 2330 2331 2331 2262 2365 2236 2320 2385 2285 2295 2305 2251 2273 2280 2304 2274 2304 2245 2265 2297 2288 2314 2325 2320 2281 2345 2377 2258 2288 2230 2248 2328 2333 2285 2167 2294 2242 2302 2304 2231 2310 2326 2361 2292 2286 2271 2296 2360 2326 2370 2268 2369 2340 2411 2374 2367 2395 2370 2334 2283 2296 2274 2268 2329 2276 2326 2246 2254 2239 2221 2288 2276 2288 2304 2186 2157 2190 2238 2208 2300 2312 2250 2205 2258 2256 2132 2156 2284 2163 2220 2160 2168 2201 2178 2227 2192 2187 2200 2181 2163 2217 2314 2205 2199 2203 2191 2152 2158 2280 2201 2237 2281 2169 2144 2227 2212 2259 2174 2258 2147 2144 2155 2118 2161 2201 2218 2209 2195 2160 2123 2164 2152 2253 2205 2175 2194 2186 2124 2130 2190 2218 2130 2126 2202 2157 2211 2117 2199 2224 2140 2147 2169 2201 2201 2139 2231 2171 2197 2169 2109 2201 2203 2141 2185 2100 2088 2133 2109 2215 2122 2166 2191 2076 2084 2157 2252 2189 2186 2177 2084 2106 2156 2142 2104 2178 2175 2164 2134 2212 2150 2158 2217 2068 2127 2201 2160 2165 2223 2197 2179 2126 2205 2195 2143 2195 2275 2232 2155 2250 2173 2264 2283 2277 2279 2248 2130 2304 2278 2345 2341 2316 2404 2430 2444 2340 2486 2416 2538 2520 2641 2559 2721 2731 2786 2799 3031 3020 3186 3189 3396 3700 3759 3840 4330 4484 4695 5013 5255 5495 5672 5810 6031 6179 6188 6249 6152 5756 5518 5093 4614 4405 4034 3672 3413 3171 2993 2856 2713 2631 2512 2503 2410 2409 2459 2444 2387 2394 2297 2372 2300 2318 2291 2247 2281 2283 2160 2228 2162 2194 2222 2239 2267 2198 2270 2225 2250 2210 2304 2229 2274 2281 2238 2305 2331 2433 2309 2410 2427 2416 2536 2639 2704 2693 2861 2869 3098 3211 3385 3418 3486 3444 3582 3514 3645 3673 3768 3635 3827 3778 3771 3857 3842 4008 4300 4362 4452 4779 4805 5177 5344 5323 5621 5442 5244 4960 4546 4188 4027 3484 3260 2890 2790 2589 2484 2269 2260 2225 2199 2214 2202 2103 2122 2194 2230 2275 2128 2104 2166 2104 2169 2162 2215 2170 2159 2100 2096 2166 2124 2156 2050 2088 2106 2112 2114 2102 2096 1995 2044 2087 2105 2118 2123 2128 2127 2169 2216 2104 2153 2217 2228 2195 2224 2245 2277 2298 2266 2247 2238 2346 2256 2261 2289 2382 2416 2379 2387 2486 2540 2565 2752 2759 2936 2987 3234 3346 3483 3729 4161 4421 4628 5038 5654 6097 6802 7308 8026 8747 9487 10460 11195 11887 12637 13139 12878 12706 11940 11195 10270 9127 8210 7194 6204 5307 4547 3950 3545 3179 2991 2835 2623 2526 2421 2359 2329 2307 2312 2274 2267 2238 2238 2238 2203 2176 2225 2137 2122 2128 2142 2087 2099 2073 2124 1975 2144 1986 2023 1943 2024 1938 1964 1958 2034 1954 2059 1909 1953 2054 2051 2011 1967 1983 2007 1960 2002 2060 1981 2007 2017 1935 1951 2034 2038 2008 2089 2055 2017 2052 2022 1996 2051 1958 2053 1967 1984 1928 2003 2001 2063 2097 2099 2083 2074 2046 2139 2067 2161 2185 2191 2185 2260 2342 2454 2408 2502 2667 2797 2954 3041 3059 3259 3508 3508 3506 3296 3147 2996 2909 2803 2566 2372 2250 2161 2100 2014 1899 1859 1947 1897 1952 2027 1928 1883 1930 1931 1881 1948 1890 1933 1810 1945 1943 1955 1888 1884 1972 1925 1936 1879 1853 1879 1895 1955 1840 1923 1902 1868 1880 1964 1923 1908 1832 1841 1976 1936 1892 1992 1898 1861 1777 1986 1860 1960 1928 1949 1852 2017 1999 1866 1835 1904 1914 1966 1877 1920 1950 1977 1981 1883 1861 1928 1972 1962 1943 1969 1929 1903 1989 1875 2009 1932 1975 1979 1826 1966 1871 1936 1916 1967 2028 1954 2003 1936 1972 1915 1980 1930 1992 1963 2015 2056 2041 2021 1981 2031 2106 2035 2017 2059 2073 2012 2093 2075 2042 2073 2110 2077 2088 2116 2017 2113 2147 2191 2206 2098 2248 2294 2245 2292 2232 2259 2395 2371 2404 2442 2438 2494 2426 2624 2659 2632 2701 2656 2651 2710 2582 2716 2668 2695 2733 2801 2781 2790 2838 2828 2879 3002 3040 3169 3130 3213 3137 3409 3423 3427 3655 3879 4007 4210 4179 4659 4891 5350 5682 6117 6941 7370 8229 9250 10432 11545 12879 14219 16189 17852 19737 21267 23233 25115 26160 27040 27386 26250 25244 23668 22061 20040 17928 16147 14048 12312 10393 8956 7745 6911 6104 5365 4824 4549 4176 4056 3826 3604 3545 3362 3388 3260 3252 3272 3100 3161 3158 3141 3114 3027 2966 2976 2828 2861 2667 2759 2549 2519 2472 2434 2398 2337 2232 2247 2237 2281 2170 2206 2160 2119 2209 2067 2135 2067 2084 2175 2130 2110 2084 2065 2102 2053 2018 2036 2115 2017 1980 2026 1954 1972 1926 1985 2005 2025 2011 2127 2034 2020 1993 2041 1990 1887 1959 1863 1895 1912 1921 1896 1930 1995 1908 1853 1773 1903 1830 1837 1940 1905 1807 1868 1941 1832 1870 1811 1815 1869 1879 1878 1885 1857 1866 1802 1833 1814 1809 1846 1910 1853 1817 1833 1934 1944 1880 1902 1882 1890 1981 1859 1935 1931 1952 1924 1916 1961 1989 1896 1955 1943 1950 1925 1919 1919 1928 1925 1977 1985 2058 1941 2043 1833 1906 1913 1922 1892 1879 2032 1921 1911 1905 1901 1862 1918 1996 2008 2011 2030 1943 2029 2008 1987 2057 2016 2049 1999 1977 2175 2095 2043 2069 2163 2190 2102 2083 2117 2099 2191 2230 2164 2214 2294 2309 2345 2480 2547 2530 2699 2796 2920 3010 3247 3591 3815 4256 4562 4945 5439 6170 6774 7344 8110 9105 9797 10440 11171 11956 12120 12466 12412 11929 11297 10519 9482 9090 8272 7391 6618 5926 5181 4476 3985 3655 3365 3228 2876 2704 2496 2440 2476 2450 2355 2263 2286 2259 2243 2152 2213 2209 2259 2301 2247 2318 2374 2368 2496 2455 2539 2618 2807 2840 3004 3123 3471 3505 3725 4159 4244 4556 4871 5040 5359 5743 5855 5857 5960 5736 5436 5330 4890 4538 4354 4030 3786 3513 3247 2998 2852 2649 2573 2525 2424 2407 2390 2345 2324 2368 2253 2263 2280 2262 2112 2110 2096 1910 2075 2013 1974 1962 1914 1932 1888 1905 1883 1802 1824 1817 1803 1745 1836 1808 1864 1837 1886 1899 1901 1908 1912 2010 1926 2014 2051 2034 2130 2214 2068 2298 2386 2469 2562 2749 2947 3193 3268 3473 3735 3867 4264 4270 4229 4238 4342 4369 4429 4210 3868 3566 3327 3176 3058 2932 2795 2521 2387 2278 2177 2113 2156 2060 2040 2125 1873 2099 2076 2094 2104 2130 2104 2114 2227 2049 2172 2228 2207 2195 2257 2203 2258 2245 2338 2286 2311 2510 2376 2400 2454 2529 2463 2662 2797 2818 3019 2975 3343 3385 3775 4041 4247 4696 5178 5784 6736 7333 8371 9677 11119 12897 15002 17320 19997 22854 25912 28523 31521 33906 34847 33835 32063 28970 25765 23708 21882 20663 18903 16900 14849 12939 11356 10224 9754 9431 9983 9940 10235 10198 9357 8134 7482 6757 6669 6457 6310 5933 5207 4918 4530 4385 4388 4342 4281 4243 4125 3708 3521 3409 3046 3056 2966 2719 2662 2447 2278 2250 2067 2132 2102 2043 1985 1970 1892 1922 1874 1832 1787 1861 1776 1807 1826 1752 1874 1789 1758 1771 1732 1814 1725 1789 1728 1701 1748 1647 1730 1640 1664 1642 1777 1654 1764 1727 1744 1718 1632 1654 1635 1658 1661 1588 1648 1582 1572 1684 1644 1608 1604 1638 1661 1576 1631 1643 1615 1635 1610 1628 1672 1587 1557 1560 1556 1687 1612 1632 1641 1628 1537 1641 1651 1618 1668 1685 1719 1522 1633 1631 1639 1503 1616 1510 1597 1571 1522 1494 1520 1566 1534 1616 1589 1542 1496 1577 1551 1567 1519 1567 1507 1524 1548 1578 1563 1516 1558 1614 1502 1615 1525 1609 1503 1524 1455 1539 1589 1563 1532 1495 1509 1498 1544 1484 1617 1499 1490 1479 1543 1488 1529 1469 1447 1520 1556 1501 1553 1599 1556 1567 1620 1574 1515 1579 1638 1589 1695 1660 1631 1674 1734 1750 1797 1830 1676 1724 1778 1809 1731 1749 1765 1689 1710 1630 1602 1594 1537 1655 1565 1591 1620 1589 1619 1653 1620 1646 1668 1736 1732 1840 1812 1896 1886 1917 1876 1853 1860 1761 1816 1725 1755 1739 1590 1583 1603 1641 1528 1512 1527 1544 1574 1521 1503 1501 1520 1536 1459 1500 1430 1515 1487 1507 1519 1501 1630 1547 1448 1552 1492 1537 1445 1428 1536 1492 1591 1489 1643 1630 1531 1531 1572 1603 1565 1565 1593 1532 1487 1455 1476 1543 1488 1485 1377 1471 1452 1473 1479 1476 1462 1461 1408 1468 1402 1444 1424 1439 1443 1449 1447 1460 1444 1406 1447 1387 1508 1340 1586 1425 1365 1483 1456 1492 1358 1380 1419 1424 1376 1379 1410 1397 1469 1457 1470 1470 1418 1492 1465 1504 1423 1498 1492 1470 1436 1460 1480 1472 1443 1491 1432 1508 1534 1461 1650 1544 1512 1648 1688 1672 1658 1589 1584 1578 1643 1626 1670 1670 1588 1624 1571 1601 1577 1562 1567 1568 1499 1597 1500 1532 1477 1435 1560 1527 1500 1470 1483 1502 1571 1436 1553 1415 1459 1387 1413 1543 1584 1461 1467 1485 1526 1499 1504 1459 1518 1520 1505 1527 1582 1585 1561 1625 1542 1555 1531 1599 1628 1657 1646 1563 1698 1577 1646 1693 1685 1658 1714 1782 1715 1811 1815 1822 1884 1928 2077 2148 2162 2357 2568 2744 2994 3283 3667 4076 4525 5315 5991 6955 7892 8781 9655 10498 10823 10994 10491 9795 8849 8196 7558 7370 7223 7002 6861 6255 5641 5164 4808 4523 4114 3869 3573 3220 2962 2894 2742 2889 2794 2933 2663 2493 2375 2352 2433 2407 2611 2534 2790 2784 2880 3004 3064 3325 3462 3734 3903 3877 4032 4124 4182 4220 4189 4140 4104 3819 3735 3591 3368 3239 3245 3076 2844 2747 2543 2322 2202 2146 2112 1942 1943 1845 1908 1823 1836 1790 1767 1804 1728 1699 1756 1767 1784 1841 1869 1877 1957 1998 2055 2001 2224 2341 2461 2582 2847 3085 3335 3678 4005 4434 4776 5124 5373 5535 5789 5459 5353 5118 4863 4635 4424 4280 4092 3849 3641 3453 3110 2902 2613 2485 2326 2165 2011 2044 1909 1819 1862 1833 1892 1751 1813 1768 1869 1960 1874 1959 1922 2122 2162 2202 2251 2397 2401 2646 2825 3059 3220 3392 3473 3672 3703 3876 4012 4075 4033 4082 3965 3855 3776 3759 3402 3113 2915 2683 2593 2492 2444 2321 2223 2024 1843 1806 1734 1653 1588 1614 1601 1576 1603 1573 1497 1623 1548 1573 1578 1576 1523 1498 1597 1541 1601 1600 1596 1611 1663 1681 1783 1778 1764 1899 2052 2145 2312 2528 2628 2803 2954 3301 3369 3457 3422 3265 3235 2956 2903 2784 2848 2837 2752 2700 2680 2680 2652 2574 2577 2634 2618 2621 2717 2897 3100 3287 3580 3882 4313 4634 5000 5524 5774 6196 6230 6261 5930 5906 5463 5107 4853 4663 4503 4197 4053 3873 3534 3082 2916 2547 2445 2245 2021 1956 1875 1888 1801 1836 1741 1745 1727 1739 1634 1581 1568 1565 1571 1578 1518 1513 1439 1487 1536 1508 1531 1503 1493 1521 1456 1447 1440 1433 1485 1378 1464 1410 1268 1381 1301 1364 1392 1373 1459 1388 1331 1315 1372 1402 1430 1334 1375 1407 1401 1358 1387 1265 1378 1353 1420 1316 1356 1350 1442 1346 1432 1345 1405 1415 1433 1348 1462 1359 1343 1376 1399 1371 1416 1410 1352 1430 1460 1349 1390 1426 1375 1422 1408 1433 1406 1416 1436 1415 1480 1481 1527 1510 1565 1510 1529 1651 1593 1707 1838 1831 1999 2006 2138 2294 2448 2732 2843 3022 3302 3538 3756 4008 3911 3898 3948 3810 3619 3438 3335 3266 3087 3161 2791 2818 2560 2491 2227 2167 2026 1870 1818 1783 1810 1778 1664 1676 1696 1570 1673 1642 1623 1738 1728 1753 1830 1774 1798 1791 1673 1687 1611 1619 1526 1567 1530 1607 1536 1420 1420 1400 1473 1454 1423 1327 1372 1327 1393 1337 1387 1425 1292 1312 1310 1305 1306 1287 1283 1282 1351 1375 1351 1296 1261 1257 1345 1316 1400 1352 1380 1341 1415 1495 1546 1476 1602 1558 1649 1724 1720 1694 1808 1763 1733 1754 1737 1747 1649 1619 1619 1672 1535 1514 1465 1555 1489 1472 1368 1390 1347 1347 1406 1298 1286 1313 1308 1362 1386 1426 1297 1376 1316 1341 1380 1449 1366 1465 1506 1592 1591 1669 1796 1819 1761 1834 1770 1631 1724 1609 1548 1570 1591 1472 1528 1546 1480 1512 1444 1333 1336 1371 1258 1251 1329 1279 1420 1391 1304 1328 1390 1307 1351 1241 1326 1266 1228 1248 1287 1345 1248 1343 1343 1294 1300 1262 1330 1370 1396 1271 1380 1370 1402 1377 1464 1344 1350 1400 1450 1414 1392 1485 1457 1451 1471 1481 1475 1572 1595 1672 1630 1707 1794 1866 1991 2076 2178 2371 2606 2786 3080 3444 3646 4034 4561 4789 5256 5421 5581 5877 5869 5769 5677 5557 5417 5343 5012 4647 4399 4305 3922 3647 3466 3290 3164 2904 2702 2433 2131 2084 1903 1784 1756 1696 1566 1605 1569 1576 1486 1547 1492 1582 1487 1501 1458 1429 1427 1398 1420 1344 1359 1406 1430 1337 1387 1379 1439 1395 1455 1441 1423 1390 1412 1438 1381 1400 1393 1444 1354 1485 1381 1423 1482 1437 1472 1491 1459 1456 1493 1535 1560 1597 1582 1551 1531 1592 1601 1576 1602 1556 1587 1474 1481 1533 1403 1472 1371 1405 1419 1368 1428 1291 1319 1331 1302 1340 1364 1320 1319 1264 1281 1246 1314 1346 1396 1346 1364 1441 1390 1589 1477 1590 1658 1565 1549 1497 1434 1432 1350 1390 1480 1487 1492 1503 1400 1521 1465 1449 1448 1443 1600 1675 1697 1705 1941 1888 1906 1852 1800 1752 1712 1700 1757 1804 1772 1940 1952 1994 2049 2076 2132 2213 2124 2158 1989 1906 1783 1615 1644 1651 1619 1611 1677 1600 1613 1479 1497 1342 1388 1319 1266 1308 1288 1291 1257 1400 1338 1378 1348 1451 1377 1477 1514 1429 1502 1422 1403 1477 1339 1272 1373 1323 1477 1333 1396 1322 1336 1348 1286 1307 1216 1242 1239 1164 1278 1178 1226 1195 1217 1163 1186 1197 1205 1219 1188 1198 1153 1241 1189 1208 1202 1161 1172 1238 1212 1276 1178 1208 1272 1188 1157 1174 1228 1229 1203 1235 1254 1205 1269 1241 1298 1367 1303 1301 1306 1352 1254 1281 1300 1320 1308 1283 1335 1300 1276 1253 1230 1325 1304 1235 1292 1260 1301 1252 1182 1200 1273 1256 1301 1308 1294 1344 1291 1349 1396 1322 1356 1433 1454 1503 1563 1604 1639 1663 1731 1627 1709 1660 1656 1686 1739 1648 1838 1721 1771 1766 1804 1822 1897 2029 1911 1978 1877 1938 1795 1808 1822 1672 1643 1708 1630 1616 1673 1564 1632 1651 1654 1605 1595 1566 1492 1460 1418 1478 1350 1429 1349 1475 1435 1386 1405 1476 1359 1336 1329 1316 1266 1353 1356 1377 1357 1488 1422 1445 1430 1575 1645 1719 1812 2062 2164 2434 2696 3007 3330 3732 3812 3883 3909 3641 3334 3032 2802 2628 2586 2618 2643 2728 2787 2698 2494 2292 2115 1903 1842 1644 1714 1646 1639 1578 1659 1590 1678 1638 1611 1625 1614 1692 1757 1916 2080 2166 2391 2506 2642 2903 3087 3272 3238 3545 3322 3262 3091 2943 2854 2666 2703 2622 2629 2684 2477 2549 2398 2197 2051 1949 1815 1602 1649 1525 1486 1398 1450 1383 1386 1281 1321 1270 1275 1267 1247 1258 1182 1293 1259 1345 1238 1204 1267 1276 1265 1326 1402 1376 1361 1473 1384 1416 1346 1359 1282 1287 1237 1235 1270 1292 1222 1217 1279 1239 1254 1188 1169 1120 1233 1123 1149 1128 1215 1167 1155 1144 1231 1181 1151 1173 1174 1161 1192 1146 1206 1180 1164 1183 1175 1193 1139 1181 1150 1168 1133 1135 1171 1167 1125 1150 1193 1156 1162 1163 1189 1181 1167 1120 1170 1173 1128 1171 1162 1181 1180 1113 1196 1142 1199 1102 1184 1127 1153 1157 1188 1099 1163 1167 1165 1228 1176 1149 1213 1132 1198 1183 1182 1206 1220 1193 1136 1136 1155 1152 1211 1228 1207 1166 1178 1281 1275 1190 1226 1244 1215 1273 1208 1184 1151 1189 1274 1193 1238 1275 1308 1201 1232 1264 1293 1191 1232 1248 1366 1365 1345 1396 1339 1353 1353 1410 1504 1549 1596 1574 1585 1601 1745 1695 1729 1646 1715 1756 1838 1942 1943 2139 2189 2283 2519 2389 2485 2346 2318 2218 2083 2050 1956 1965 1951 2032 2028 2129 2017 2041 1956 1876 1833 1848 1754 1823 1846 1918 1896 2009 2166 2234 2386 2542 2795 3124 3435 3620 4067 4387 4501 4373 4361 3958 3641 3552 3241 3219 3127 3133 3089 3081 3178 3048 2925 2745 2546 2222 2141 1979 1911 1731 1707 1680 1634 1615 1526 1580 1502 1499 1449 1492 1497 1571 1554 1521 1578 1558 1482 1516 1609 1555 1519 1592 1510 1507 1481 1637 1617 1648 1710 1826 1819 1850 1954 2054 2121 2250 2358 2281 2338 2173 2054 1998 1868 1761 1811 1783 1850 1849 1749 1813 1750 1697 1565 1592 1518 1448 1439 1486 1392 1380 1386 1383 1356 1485 1350 1373 1434 1404 1463 1492 1516 1628 1809 1806 1836 2073 2072 2185 2357 2449 2565 2648 2587 2451 2353 2247 2204 2133 2116 2070 2036 2057 2075 2054 2051 1926 1968 1813 1672 1641 1613 1539 1491 1528 1408 1360 1396 1332 1308 1287 1292 1275 1269 1260 1325 1331 1304 1257 1223 1255 1238 1265 1292 1243 1243 1317 1204 1210 1213 1118 1284 1244 1312 1250 1245 1250 1275 1239 1317 1352 1312 1289 1319 1323 1298 1367 1342 1362 1356 1449 1367 1458 1411 1454 1509 1536 1510 1578 1679 1552 1548 1624 1558 1724 1633 1773 1764 1883 1859 1968 1942 1973 2054 2027 2233 2367 2372 2558 2640 2905 3008 3232 3517 3788 4088 4506 4988 5634 6290 7062 7989 9081 10335 11589 12721 13514 13913 13242 11872 10364 9046 7867 7057 7006 6788 7087 7400 7713 7876 7423 6870 5882 5026 4295 3531 3109 2737 2409 2422 2077 2066 1927 1958 1842 1862 1724 1694 1658 1683 1567 1659 1570 1585 1557 1547 1539 1574 1591 1570 1535 1549 1485 1396 1359 1365 1420 1405 1373 1335 1322 1371 1318 1306 1255 1285 1259 1254 1289 1297 1246 1263 1191 1281 1243 1192 1220 1217 1211 1162 1195 1199 1249 1216 1178 1181 1174 1188 1220 1149 1270 1127 1187 1124 1180 1208 1186 1264 1174 1214 1246 1182 1133 1135 1172 1195 1194 1280 1143 1247 1265 1197 1278 1278 1334 1245 1227 1198 1214 1219 1285 1199 1228 1290 1284 1207 1296 1241 1236 1219 1186 1255 1225 1167 1171 1244 1202 1265 1263 1208 1226 1234 1231 1267 1275 1213 1273 1232 1275 1215 1310 1323 1404 1298 1376 1461 1447 1534 1672 1794 1821 1880 1865 1889 1796 1801 1685 1602 1562 1550 1562 1628 1649 1578 1667 1725 1657 1676 1635 1658 1634 1608 1629 1602 1629 1656 1724 1758 1706 1765 1782 1687 1606 1598 1560 1577 1395 1469 1543 1573 1595 1553 1648 1497 1580 1577 1472 1533 1538 1527 1557 1667 1648 1727 1843 1912 1934 2153 2267 2334 2302 2378 2293 2254 2160 2116 2051 1999 1914 1958 2007 1929 1907 1894 1898 1888 1785 1767 1617 1586 1524 1537 1453 1412 1418 1405 1361 1370 1339 1328 1288 1307 1397 1286 1296 1217 1264 1267 1322 1192 1261 1298 1264 1222 1276 1167 1214 1269 1298 1246 1296 1296 1236 1284 1241 1273 1255 1306 1267 1244 1299 1245 1348 1291 1308 1276 1303 1409 1445 1479 1397 1435 1394 1406 1370 1350 1341 1320 1306 1306 1309 1300 1339 1324 1348 1354 1341 1361 1421 1437 1407 1489 1433 1534 1453 1382 1408 1314 1361 1287 1312 1350 1399 1288 1294 1360 1334 1315 1337 1378 1414 1417 1511 1454 1456 1616 1659 1652 1653 1737 1596 1524 1435 1397 1426 1381 1390 1423 1449 1537 1497 1537 1548 1498 1464 1461 1456 1403 1478 1474 1614 1601 1656 1750 1940 2065 2369 2508 2633 2784 2856 2919 2931 3017 3140 3049 3054 3167 2944 2993 2788 2846 2799 2760 2742 2657 2547 2618 2440 2431 2473 2420 2410 2417 2379 2349 2354 2346 2342 2550 2544 2679 2668 2526 2604 2595 2602 2585 2545 2586 2585 2594 2557 2332 2354 2266 2179 2277 2150 2117 1972 1967 1916 1881 1896 1846 1775 1700 1685 1613 1536 1547 1457 1420 1506 1427 1455 1389 1339 1380 1373 1359 1355 1401 1375 1249 1399 1318 1401 1357 1399 1451 1499 1570 1566 1694 1747 1888 2040 2221 2470 2491 2740 2706 2704 2483 2363 2140 1972 1903 1870 1925 1806 1961 1942 1995 2109 2073 2073 1994 2020 1853 1853 1828 1760 1855 1887 1956 1934 2067 2106 2134 2199 2217 2175 2220 2327 2360 2406 2470 2404 2669 2655 2561 2560 2444 2387 2216 2094 1969 2020 2000 1934 1871 1898 1826 1863 1702 1811 1622 1622 1556 1509 1442 1334 1280 1376 1231 1307 1241 1258 1207 1227 1136 1296 1177 1198 1182 1118 1251 1106 1180 1160 1134 1151 1178 1186 1183 1205 1163 1161 1247 1245 1153 1214 1171 1281 1300 1323 1273 1283 1268 1332 1272 1214 1206 1188 1237 1210 1119 1283 1277 1256 1240 1308 1274 1204 1231 1160 1161 1178 1090 1160 1143 1218 1231 1194 1214 1145 1121 1212 1209 1137 1147 1206 1189 1204 1175 1162 1178 1233 1151 1248 1323 1354 1347 1393 1532 1468 1481 1525 1561 1423 1387 1298 1248 1223 1285 1272 1349 1316 1245 1367 1307 1305 1282 1329 1213 1259 1179 1157 1179 1185 1129 1262 1084 1152 1183 1220 1135 1151 1146 1141 1170 1170 1183 1141 1213 1109 1175 1127 1088 1138 1158 1123 1127 1080 1133 1164 1192 1184 1156 1101 1219 1158 1169 1293 1213 1244 1132 1239 1206 1143 1192 1234 1216 1217 1314 1244 1256 1255 1319 1290 1271 1322 1382 1367 1331 1475 1441 1433 1491 1585 1635 1688 1826 1784 1853 1897 1980 2001 1957 2052 2126 2230 2225 2236 2336 2292 2380 2366 2453 2435 2667 2629 2971 2913 3123 3322 3519 3759 3885 4060 4160 4187 3995 4036 3784 3664 3434 3223 3218 3141 3129 3015 2846 2989 2990 2974 2872 2854 2687 2715 2507 2526 2451 2446 2489 2459 2601 2702 2812 2724 2734 2658 2555 2351 2063 1955 1856 1773 1800 1754 1792 1867 1878 1973 1957 1918 1956 1792 1630 1635 1474 1486 1431 1483 1328 1336 1306 1327 1258 1243 1288 1208 1218 1308 1236 1247 1341 1222 1295 1206 1316 1241 1208 1223 1309 1193 1210 1290 1220 1239 1219 1192 1215 1255 1247 1285 1282 1282 1266 1326 1227 1330 1255 1257 1292 1314 1292 1313 1353 1271 1342 1322 1379 1242 1353 1332 1400 1419 1382 1407 1398 1487 1422 1411 1331 1349 1374 1387 1381 1333 1376 1372 1343 1357 1363 1299 1299 1292 1309 1360 1319 1389 1300 1331 1302 1388 1387 1359 1421 1355 1438 1450 1398 1534 1489 1467 1461 1485 1467 1541 1500 1625 1534 1568 1615 1735 1704 1862 1990 2124 2317 2539 2938 3446 3838 4534 5327 6078 7164 8052 8728 8876 8603 7676 6795 5730 4766 4331 4041 3738 3882 3817 4158 4567 4864 5017 5171 5082 4883 4405 3711 3328 2803 2506 2275 2054 1935 1804 1768 1654 1607 1585 1482 1537 1456 1442 1306 1307 1400 1376 1253 1329 1342 1292 1352 1295 1279 1215 1287 1215 1320 1241 1258 1194 1225 1243 1249 1238 1215 1274 1284 1271 1267 1304 1181 1183 1177 1241 1262 1160 1183 1161 1192 1255 1238 1313 1304 1283 1274 1321 1366 1419 1465 1412 1392 1489 1588 1599 1707 1841 1883 1951 1903 1901 1898 1828 1871 1660 1702 1617 1611 1513 1606 1595 1654 1585 1605 1602 1724 1615 1657 1525 1516 1486 1495 1426 1449 1406 1403 1353 1320 1337 1337 1396 1301 1332 1353 1436 1462 1466 1517 1533 1707 1771 1871 2101 2173 2407 2664 2791 2817 2747 2636 2466 2221 2081 1828 1790 1766 1797 1794 1743 1767 1912 1977 1964 2012 1931 1899 1788 1675 1555 1530 1346 1407 1295 1258 1283 1262 1199 1272 1224 1140 1187 1157 1120 1182 1159 1145 1134 1154 1223 1143 1168 1254 1187 1285 1315 1254 1255 1159 1185 1224 1207 1180 1146 1101 1118 1152 1110 1170 1124 1139 1195 1112 1114 1132 1232 1142 1155 1142 1102 1062 1109 1155 1103 1164 1130 1102 1146 1045 1133 1130 1121 1105 1131 1101 1113 1209 1152 1132 1119 1250 1175 1139 1178 1221 1287 1153 1182 1227 1266 1270 1190 1277 1246 1253 1300 1230 1256 1241 1311 1298 1263 1282 1352 1399 1423 1382 1378 1466 1350 1482 1548 1591 1639 1743 1766 1904 2089 2084 2256 2441 2591 2844 2931 3162 3111 3118 2919 2806 2487 2296 2244 2116 1974 2032 2003 2003 2097 2129 2277 2315 2275 2168 2039 1994 1859 1713 1593 1628 1490 1429 1363 1326 1422 1283 1329 1291 1371 1317 1353 1293 1353 1481 1491 1517 1636 1696 1704 1587 1494 1378 1395 1350 1305 1300 1268 1284 1294 1307 1313 1385 1394 1420 1372 1387 1386 1292 1279 1228 1176 1184 1182 1245 1177 1190 1225 1292 1204 1236 1317 1282 1249 1341 1334 1368 1320 1268 1315 1223 1325 1163 1243 1206 1274 1163 1264 1204 1217 1231 1229 1272 1273 1237 1216 1212 1183 1271 1181 1209 1253 1194 1200 1134 1214 1227 1293 1260 1245 1257 1259 1378 1355 1335 1474 1481 1521 1565 1616 1698 1684 1629 1691 1568 1552 1590 1534 1645 1685 1759 1780 1882 1845 2004 1831 1799 1760 1682 1565 1527 1517 1520 1471 1416 1427 1511 1481 1489 1520 1528 1500 1455 1485 1421 1378 1351 1375 1358 1365 1313 1331 1347 1358 1245 1392 1358 1442 1463 1475 1391 1419 1540 1573 1726 1733 1857 1929 2069 2112 2247 2433 2444 2642 2777 2871 2872 2810 2803 2740 2510 2576 2468 2436 2371 2245 2282 2280 2393 2385 2474 2514 2500 2718 2691 2726 2862 2829 2915 2995 3099 3188 3236 3155 3292 3241 3148 3113 3039 2864 2696 2635 2452 2342 2379 2363 2325 2294 2337 2439 2417 2278 2263 2299 2226 2083 1952 1946 1777 1825 1659 1695 1593 1532 1608 1460 1485 1391 1328 1409 1408 1372 1358 1359 1339 1372 1378 1418 1418 1417 1489 1414 1512 1504 1574 1563 1638 1648 1625 1609 1461 1461 1477 1383 1456 1444 1402 1322 1422 1378 1322 1498 1506 1514 1602 1605 1535 1609 1510 1540 1603 1586 1594 1685 1711 1877 1975 2012 2238 2473 2366 2521 2450 2549 2424 2399 2375 2316 2337 2209 2100 2146 2103 2069 2012 2005 1981 2004 2076 2100 2135 2090 2033 2014 1894 1881 1763 1793 1656 1620 1671 1507 1397 1452 1390 1395 1359 1352 1413 1290 1393 1346 1330 1283 1270 1230 1259 1329 1238 1222 1198 1179 1233 1205 1191 1270 1206 1231 1254 1118 1216 1167 1188 1187 1159 1107 1113 1204 1096 1172 1163 1156 1159 1129 1153 1194 1224 1173 1155 1166 1162 1086 1131 1147 1213 1178 1152 1261 1188 1297 1322 1341 1379 1401 1525 1662 1698 1769 1823 1896 1891 1805 1822 1689 1544 1345 1388 1338 1349 1336 1326 1326 1366 1396 1424 1502 1496 1556 1476 1451 1338 1278 1353 1278 1247 1258 1184 1217 1171 1212 1192 1136 1135 1129 1130 1148 1146 1109 1178 1178 1075 1118 1114 1141 1090 1078 1132 1077 1041 1133 1155 1083 1145 1098 1196 1113 1105 1110 1113 1134 1062 1140 1076 1069 1128 1133 1111 1077 1080 1142 1114 1018 1102 1040 1091 1087 1144 1106 1087 1069 1082 1100 1105 1035 1107 1070 1050 1077 1018 1125 1020 1048 1131 1053 1073 1116 1042 1054 1084 1108 1045 1103 1072 1077 1035 1145 1087 1121 1112 1070 1113 1151 1087 1178 1182 1094 1145 1243 1188 1262 1333 1396 1386 1371 1472 1462 1575 1506 1453 1550 1538 1588 1465 1412 1428 1390 1295 1312 1242 1310 1269 1332 1278 1360 1333 1275 1316 1300 1374 1418 1357 1298 1332 1300 1237 1200 1124 1215 1224 1176 1233 1161 1205 1179 1266 1190 1185 1251 1207 1295 1306 1393 1419 1496 1504 1641 1736 1768 1959 2034 2063 2099 2167 2152 1998 1934 1917 1773 1776 1743 1686 1779 1764 1917 1812 1965 2056 1956 2062 2019 2048 1916 1845 1832 1739 1646 1521 1620 1506 1569 1471 1427 1475 1493 1358 1440 1442 1353 1380 1353 1284 1270 1345 1253 1266 1175 1198 1150 1186 1204 1169 1232 1181 1150 1102 1118 1147 1114 1105 1076 1054 1113 1051 1130 1034 1099 1120 1074 1043 1087 1109 1083 1113 1087 1132 1035 1093 1098 1133 1076 1095 1134 1124 1179 1103 1146 1095 1222 1182 1108 1083 1236 1176 1302 1248 1324 1349 1386 1493 1437 1510 1636 1626 1610 1725 1608 1658 1598 1547 1587 1527 1489 1469 1481 1416 1355 1414 1367 1418 1412 1383 1406 1374 1430 1415 1361 1387 1335 1302 1270 1350 1245 1232 1157 1208 1157 1122 1132 1040 1072 1003 1091 1081 1050 1039 1070 1077 982 1122 1067 1065 1057 1016 986 1058 1020 978 956 1035 1056 1041 1094 1023 1031 1029 1002 975 993 1074 980 1064 996 994 1019 1013 1070 1084 1034 1034 1036 1103 1083 1083 1131 1181 1092 1122 1112 1080 1124 1103 1122 1095 1032 1083 1037 1082 1125 1082 1085 1069 1008 1031 1105 1096 1052 1040 1031 983 1024 1002 1016 1079 1042 1063 1013 1044 1111 1088 1058 1081 1055 1119 1133 1091 1073 1103 1076 1038 1124 1063 1001 1047 1070 1117 1087 1042 1088 1066 1125 1110 1137 1091 1193 1137 1139 1073 1048 1009 1016 1034 1009 998 1055 1021 1078 1075 1061 1054 1092 986 1056 1051 1024 1026 1061 1028 1073 1009 1044 1001 1028 987 1037 963 1023 1020 1022 1005 1027 1013 1030 1007 1035 1023 1009 1049 1084 995 1076 1037 1073 1017 1035 1058 1034 1019 1115 998 993 1065 1019 1050 1037 1016 1059 1033 1052 1047 1037 1083 1007 1034 1021 1055 1104 1104 1099 1119 1097 1096 1060 1088 1053 1085 1214 1109 1288 1279 1302 1410 1437 1483 1599 1715 1742 1853 1922 1872 1833 1931 1907 1868 1803 1882 1905 1831 1923 1888 1821 1916 1831 1828 1770 1784 1803 1821 1697 1666 1673 1619 1650 1630 1597 1553 1519 1515 1460 1413 1475 1381 1432 1404 1357 1311 1267 1209 1254 1185 1187 1121 1152 1107 1183 1181 1142 1084 1132 1053 1096 1118 1082 1088 1109 1102 1043 1017 1041 1050 1069 1075 1017 1004 1045 1053 1068 975 1019 1063 1057 1014 1024 1038 963 1056 1038 1030 1051 970 1086 1108 1044 1042 1092 1023 1033 1048 1071 1051 1108 1045 1076 1075 1087 1108 1062 1071 1056 1069 1077 1048 1080 1120 1116 1020 1036 1017 1096 1124 1065 1131 1203 1147 1166 1259 1222 1309 1450 1540 1577 1788 1802 1920 1982 1952 1883 1776 1734 1570 1533 1422 1392 1284 1300 1187 1320 1282 1328 1340 1294 1354 1398 1482 1487 1457 1487 1385 1415 1328 1256 1198 1228 1231 1156 1206 1181 1171 1202 1232 1270 1162 1209 1145 1094 1055 1101 1093 1072 1062 1034 1064 1052 1108 1153 1137 1088 1100 1077 1018 1074 1068 1208 1106 1092 1061 1132 1087 1164 1060 1098 1064 1043 1040 1013 1030 1051 1046 1058 1058 1012 1030 1038 1126 1120 1044 1178 1116 1157 1087 1138 1075 1084 1046 1107 1035 1050 1072 1094 1092 1135 1121 1109 1145 1199 1197 1201 1134 1146 1131 1151 1147 1202 1203 1326 1321 1280 1380 1361 1437 1440 1468 1568 1519 1713 1735 1878 1877 1964 2105 2078 2052 2021 1920 1858 1759 1724 1597 1515 1431 1500 1500 1472 1421 1421 1411 1508 1402 1559 1525 1565 1578 1520 1544 1443 1335 1290 1247 1282 1190 1222 1164 1212 1197 1163 1148 1042 1120 1126 1161 1164 1125 1080 1085 1056 1117 1095 1074 1043 1116 1089 1099 1105 1070 1096 1124 1134 1107 1114 1172 1089 1111 1167 1094 1183 1285 1152 1167 1201 1296 1293 1330 1357 1455 1392 1429 1438 1502 1469 1509 1532 1433 1484 1430 1437 1387 1344 1379 1432 1383 1383 1377 1341 1379 1361 1373 1483 1418 1524 1404 1553 1497 1610 1564 1591 1637 1613 1754 1752 1825 1834 1962 1867 1933 1783 1870 1747 1805 1781 1720 1759 1684 1805 1807 1869 1921 1837 1919 1888 1930 1881 1749 1765 1656 1730 1535 1566 1578 1474 1453 1486 1441 1436 1484 1424 1525 1543 1479 1438 1351 1358 1333 1250 1250 1202 1197 1187 1231 1189 1287 1134 1165 1171 1226 1137 1134 1112 1113 1073 1132 1146 1150 1135 1102 1156 1090 1104 1143 1150 1155 1175 1163 1194 1292 1261 1374 1314 1293 1301 1328 1276 1315 1347 1334 1296 1315 1326 1217 1268 1207 1206 1237 1202 1202 1255 1243 1242 1194 1267 1203 1260 1208 1283 1254 1292 1224 1190 1299 1185 1247 1187 1188 1196 1266 1240 1215 1195 1187 1236 1213 1217 1248 1193 1254 1230 1195 1228 1292 1262 1274 1269 1365 1312 1461 1393 1476 1514 1672 1597 1764 1779 1730 1699 1641 1588 1428 1389 1396 1369 1320 1273 1222 1265 1214 1263 1322 1225 1362 1289 1351 1317 1387 1447 1383 1365 1280 1311 1237 1227 1259 1227 1123 1168 1120 1073 1156 1069 1098 1102 1071 1095 1101 1148 1123 1061 1222 1111 1110 1081 1006 1130 1070 1025 1023 1063 1149 1033 1055 1084 1048 1086 1117 1059 1125 1173 1145 1193 1215 1213 1225 1185 1223 1277 1274 1398 1404 1413 1549 1567 1618 1606 1674 1658 1730 1673 1684 1740 1694 1567 1651 1591 1528 1506 1523 1529 1478 1503 1470 1504 1423 1454 1512 1426 1468 1503 1342 1445 1404 1439 1462 1421 1464 1298 1487 1335 1364 1308 1271 1386 1335 1345 1415 1407 1392 1443 1495 1385 1417 1390 1398 1336 1282 1222 1195 1138 1238 1168 1140 1114 1147 1130 1103 1168 1194 1196 1204 1284 1198 1260 1270 1182 1204 1131 1089 1104 1135 1111 1055 1030 1152 1090 1062 1080 1048 1134 1011 1022 1058 1044 1106 1046 1074 1032 1053 1016 1030 1057 1018 1074 1063 992 1066 1031 981 1083 1045 1069 1117 1077 1049 1107 1066 1085 1082 1056 1078 1060 1078 1132 1074 1118 1143 1095 1099 1101 1112 1131 1101 1148 1100 1103 1106 1107 1123 1103 1191 1131 1113 1061 1128 1083 1161 1134 1101 1138 1103 1088 1192 1130 1169 1107 1157 1123 1144 1147 1201 1164 1159 1264 1255 1340 1266 1393 1431 1404 1650 1665 1866 1921 1920 1845 1759 1715 1553 1542 1467 1389 1404 1396 1282 1266 1238 1261 1270 1312 1351 1320 1393 1346 1505 1590 1498 1585 1521 1574 1576 1424 1434 1369 1252 1319 1311 1288 1166 1251 1178 1162 1186 1206 1163 1106 1151 1172 1102 1197 1141 1163 1153 1157 1249 1107 1117 1133 1183 1114 1117 1071 1193 1137 1084 1162 1165 1134 1075 1124 1063 1066 1079 1124 1159 1032 1080 1076 1041 1125 1102 1120 1054 1113 1096 1016 1084 1084 1064 1085 1099 1090 1039 1025 1075 1118 1039 1090 1110 1116 1070 1100 1156 1074 1105 1111 1165 1051 1067 1126 1105 1162 1235 1205 1193 1275 1309 1331 1407 1475 1610 1707 1922 2091 2334 2579 2647 2638 2620 2548 2388 2149 1967 1890 1656 1537 1505 1373 1400 1388 1378 1450 1373 1448 1541 1565 1646 1691 1733 1815 1796 1741 1866 1664 1627 1548 1450 1361 1272 1274 1136 1124 1196 1140 1149 1125 1099 1064 1122 1076 1059 1077 1070 1006 1062 1154 1152 1049 1107 1101 1072 1115 1067 1073 1094 1057 1041 1068 1082 1022 1110 1101 1132 1151 1167 1111 1088 1084 1058 1052 1069 1065 1032 1102 1057 1072 1017 980 1003 1018 1021 1011 999 1023 1050 1071 1091 1103 1055 1077 954 995 939 1024 1028 1027 1042 1053 984 948 1020 948 1016 968 1059 978 1097 1027 1069 992 1061 1079 1086 1112 1080 1096 1202 1167 1162 1158 1217 1217 1270 1249 1285 1236 1253 1159 1183 1268 1319 1191 1202 1254 1184 1144 1159 1162 1132 1153 1163 1193 1170 1219 1264 1198 1192 1284 1278 1221 1215 1238 1244 1227 1260 1194 1175 1121 1192 1161 1120 1196 1075 1164 1168 1132 1216 1106 1103 1098 1081 1125 1067 1082 1017 1145 1000 1164 1109 1080 1118 1078 1107 1043 1002 1052 1040 1073 1050 1078 1044 1038 1088 1082 1056 1092 1097 1039 1071 1065 1028 991 1057 1017 969 1035 1031 987 1030 1011 979 1007 1024 934 1075 1058 1085 1119 1018 1049 1062 1068 1092 1081 1125 1059 1101 1121 1055 1238 1226 1235 1300 1253 1261 1364 1485 1584 1699 1785 1930 2121 2093 2161 2069 1964 1918 1747 1573 1535 1453 1401 1322 1366 1330 1245 1250 1323 1246 1347 1302 1403 1413 1516 1512 1469 1624 1665 1661 1622 1557 1525 1388 1360 1228 1237 1203 1174 1070 1132 1061 1099 1113 1081 1094 1059 1093 1068 1042 1072 1095 994 1093 1059 970 993 992 976 1036 1023 981 1046 990 1001 1021 1034 1034 1034 1024 1055 988 1008 974 992 1007 997 1025 1001 943 1019 937 976 934 1002 960 981 959 1028 984 950 949 1056 930 1028 1046 1032 989 981 961 1006 980 1024 1008 1053 1062 1050 1019 1005 1088 982 976 1037 1071 1066 991 1073 1011 1103 1051 1114 1107 1103 1153 1191 1203 1236 1212 1173 1173 1140 1156 1137 1109 1062 1047 1002 1052 1113 1016 1065 1037 1005 1065 1088 1002 1057 1081 1042 1006 1077 1040 1090 1092 1133 1068 1081 973 1033 978 1018 975 1007 1000 1084 1022 1028 948 957 941 1011 947 1010 995 989 960 991 969 966 1033 930 910 955 934 945 952 969 984 967 1009 983 961 945 949 972 963 944 978 1009 961 1062 1034 995 1045 1009 988 1024 972 1013 977 1007 951 966 1031 993 953 1024 1026 994 1003 990 1021 1025 971 1064 985 1000 1014 1019 1063 1022 1062 1091 1053 1114 1019 1045 1071 1067 1140 1120 1128 1134 1184 1266 1233 1278 1399 1300 1464 1395 1485 1342 1351 1377 1287 1364 1282 1342 1230 1218 1220 1310 1186 1192 1201 1243 1179 1224 1200 1254 1251 1210 1273 1224 1239 1262 1220 1172 1170 1099 1190 1177 1144 1145 1151 1183 1138 1169 1098 1149 1071 1115 1074 1074 1092 1028 1058 1138 1057 1015 986 1015 1038 982 1018 1051 1050 1039 994 1046 1012 1064 1033 1043 1057 1089 1048 1110 1051 1060 1026 1064 1046 1031 1004 1058 1065 1009 1108 1035 985 1095 1058 1096 1149 1131 1132 1139 1151 1198 1135 1175 1274 1260 1266 1266 1278 1280 1362 1303 1355 1315 1319 1176 1219 1163 1216 1213 1242 1249 1257 1263 1333 1365 1484 1458 1538 1604 1542 1710 1693 1635 1644 1538 1484 1467 1398 1307 1343 1218 1246 1215 1211 1131 1236 1124 1151 1158 1140 1242 1197 1183 1279 1270 1260 1375 1324 1310 1254 1180 1237 1219 1199 1162 1098 1133 1031 1056 1010 1068 1000 1055 1057 1052 1103 1035 1050 1040 1055 1042 1013 1011 1036 969 1042 1044 1018 1004 1008 1037 968 956 1092 1046 1048 979 968 1015 1050 970 1022 992 1028 973 991 1001 1014 1024 1028 1044 988 1040 1003 995 1070 1002 1052 1025 997 989 1075 1076 1032 1099 1090 1094 1028 1006 1028 1026 1018 1045 1018 1076 1045 1074 1107 968 1046 1030 1034 1008 1045 1056 980 985 992 1028 1009 1031 1061 1057 1058 1008 1084 1035 1036 1035 1021 1068 1014 996 990 1043 1017 1022 997 983 941 994 982 938 979 971 1009 1017 1031 951 1023 947 960 984 1018 970 941 963 996 975 918 984 916 938 984 933 931 963 942 1004 944 1000 979 961 983 947 1017 921 993 962 938 954 886 1029 972 1052 973 1019 980 969 1034 954 1069 939 980 937 1006 963 964 1000 945 979 987 1060 975 1018 989 1054 1001 1042 1057 1004 993 1112 1048 1110 1173 1120 1221 1149 1162 1224 1236 1236 1252 1356 1336 1341 1355 1381 1324 1385 1261 1284 1344 1353 1349 1233 1290 1396 1393 1480 1487 1600 1603 1695 1654 1680 1631 1625 1657 1483 1450 1426 1354 1394 1335 1312 1369 1303 1272 1230 1260 1266 1218 1197 1198 1235 1239 1306 1300 1277 1298 1344 1279 1297 1306 1221 1194 1237 1109 1162 1134 1123 1106 1112 1074 1122 1056 1129 1176 1067 1111 1122 1093 1128 1149 1149 1211 1148 1183 1095 1187 1207 1229 1185 1177 1241 1102 1269 1095 1230 1093 1100 1101 1109 1122 1084 1111 1128 1088 1088 1101 1081 1048 1070 1058 1110 1126 1082 1073 1124 1133 1113 1150 1164 1141 1105 1123 1162 1150 1125 1124 1110 1129 1107 1112 1051 1077 1032 1047 963 1051 947 978 1010 1030 1061 966 1055 997 1002 1059 1047 1031 1022 1077 1052 1049 1059 1085 1100 1144 1159 1143 1125 1115 1093 1068 1057 1054 1049 1031 972 1081 1013 1006 968 1008 995 1035 1012 1000 963 1047 1011 1087 1019 1112 1000 1128 1069 1072 1062 1002 1036 1025 1076 1071 1060 1002 1048 1015 1078 988 1012 1087 1020 1098 1049 1073 1051 1090 1003 1030 1095 1069 1112 1103 1106 1059 1130 1117 1057 1044 1059 1076 1079 1046 992 1093 1097 1074 1043 1061 1095 1024 1121 1073 1053 996 981 1032 1072 1061 1057 1065 1117 1087 1004 1077 1087 1120 1084 1073 1030 1063 1132 1065 1099 1066 1119 1115 1123 1078 1112 1094 1163 1149 1212 1161 1209 1159 1254 1334 1319 1398 1432 1435 1521 1499 1583 1544 1548 1447 1349 1446 1263 1226 1311 1199 1148 1139 1170 1231 1057 1197 1169 1191 1152 1192 1202 1164 1198 1209 1257 1349 1334 1342 1353 1350 1362 1300 1392 1337 1355 1318 1280 1325 1227 1199 1274 1271 1223 1224 1296 1212 1185 1256 1142 1183 1142 1189 1198 1123 1157 1100 1093 1067 1083 1016 1056 1082 1136 1082 1131 1142 1192 1125 1081 1157 1154 1159 1197 1058 1151 1121 1107 1107 1109 1097 1129 1089 1100 1013 1039 1138 1027 1118 1030 1096 1017 1092 1079 1080 1083 1132 1057 1028 1102 1101 1065 1131 1050 1152 1138 1095 1181 1138 1153 1177 1134 1215 1239 1385 1327 1366 1426 1532 1605 1743 1896 1888 1945 1932 1929 1798 1807 1703 1616 1556 1443 1362 1368 1281 1256 1293 1191 1262 1150 1186 1161 1175 1184 1196 1219 1347 1273 1262 1449 1393 1470 1502 1584 1612 1554 1462 1589 1458 1469 1441 1420 1408 1386 1336 1318 1292 1330 1194 1221 1265 1175 1175 1112 1148 1179 1167 1092 1117 1085 1080 1091 1130 1141 1166 1115 1084 1144 1177 1113 1067 1122 1170 1193 1129 1140 1109 1116 1077 1137 1109 1101 1131 1036 1100 1056 1065 1057 1003 1079 1072 1012 1032 1005 1054 1025 1074 1107 1089 1116 980 1103 1061 1022 1006 1041 1062 1106 1158 1074 1151 1071 1195 1113 1183 1167 1278 1283 1249 1318 1368 1351 1462 1510 1480 1493 1590 1601 1521 1616 1521 1409 1409 1361 1352 1278 1296 1260 1178 1232 1188 1106 1163 1106 1156 1221 1141 1098 1221 1175 1229 1232 1285 1254 1278 1352 1273 1360 1306 1371 1340 1264 1260 1233 1203 1156 1194 1209 1148 1139 1145 1065 1022 1124 1050 1114 1094 1049 1034 957 1082 973 1022 1043 1073 1079 1070 1029 1041 1034 977 1017 1046 998 1037 1075 1114 1113 1044 1029 1050 1073 987 979 1071 963 1059 1029 1037 1036 1078 1054 1057 1085 982 1077 1089 1157 1109 1048 1210 1097 1125 1122 1066 1105 1093 1103 1150 1192 1129 1140 1154 1159 1192 1177 1095 1223 1176 1186 1227 1339 1319 1326 1314 1410 1366 1529 1491 1555 1580 1598 1612 1665 1642 1724 1662 1730 1533 1607 1594 1594 1588 1655 1469 1544 1571 1482 1519 1507 1419 1491 1407 1463 1444 1482 1493 1493 1489 1541 1498 1587 1640 1585 1558 1614 1572 1580 1580 1564 1577 1555 1622 1529 1542 1561 1474 1424 1328 1432 1403 1393 1306 1336 1267 1356 1342 1324 1286 1288 1378 1321 1314 1258 1207 1316 1282 1302 1315 1228 1251 1174 1251 1176 1265 1236 1249 1256 1163 1205 1277 1166 1228 1300 1207 1210 1165 1154</counts>
			</dataPoints>
		</scan>
	</xrdMeasurement>
</xrdMeasurements>