File: dataset/precursor_mixture/GeO2_Li2TiO3_In2O3.12-min.xrdml
<?xml version="1.0"?>
<xrdMeasurements xmlns="http://www.xrdml.com/XRDMeasurement/2.2" xmlns:xsi="http://www.w3.org/2001/XMLSchema-instance" xsi:schemaLocation="http://www.xrdml.com/XRDMeasurement/2.2 http://www.xrdml.com/XRDMeasurement/2.2/XRDMeasurement.xsd" status="Completed" recordIdentifier="{FD038CB3-485F-4850-BE62-D8804934B261}">
	<comment>
		<entry/>
	</comment>
	<sample type="To be analyzed">
		<id></id>
		<name></name>
		<preparedBy></preparedBy>
	</sample>
	<xrdMeasurement measurementType="Scan" status="Completed" sampleMode="Reflection">
		<usedWavelength intended="K-Alpha 1">
			<kAlpha1 unit="Angstrom">1.5405980</kAlpha1>
			<kAlpha2 unit="Angstrom">1.5444260</kAlpha2>
			<kBeta unit="Angstrom">1.3922500</kBeta>
			<ratioKAlpha2KAlpha1>0.5000</ratioKAlpha2KAlpha1>
		</usedWavelength>
		<incidentBeamPath>
			<radius unit="mm">145.00</radius>
			<xRayTube id="1010048" name="Empyrean Cu LFF HR (9430 033 7310x) DK437873">
				<tension unit="kV">40.0</tension>
				<current unit="mA">15.0</current>
				<anodeMaterial>Cu</anodeMaterial>
				<focus type="Line">
					<length unit="mm">12.0</length>
					<width unit="mm">0.4</width>
					<takeOffAngle unit="deg">6.0</takeOffAngle>
				</focus>
			</xRayTube>
			<filter id="20010004" name="Beta-filter Nickel">
				<material>Ni</material>
				<thickness unit="mm">0.020</thickness>
			</filter>
			<sollerSlit id="21010002" name="Soller slits 0.04 rad.">
				<opening unit="rad">0.0400</opening>
			</sollerSlit>
			<mask id="22031000" name="Fixed mask 13 mm">
				<width unit="mm">9.00</width>
			</mask>
			<divergenceSlit id="22120001" name="Divergence slit 1°" xsi:type="fixedDivergenceSlitType">
				<distanceToSample unit="mm">50.00</distanceToSample>
				<height unit="mm">1.52</height>
			</divergenceSlit>
		</incidentBeamPath>
		<beamKnife id="29030100" name="Beam knife low"/>
		<sampleMovement xsi:type="spinningSampleMovementType">
			<spinnerRevolutionTime unit="seconds">1.0</spinnerRevolutionTime>
		</sampleMovement>
		<diffractedBeamPath>
			<radius unit="mm">145.00</radius>
			<antiScatterSlit id="22090040" name="AS slit 9 mm" xsi:type="fixedAntiScatterSlitType">
				<height unit="mm">9.00</height>
			</antiScatterSlit>
			<sollerSlit id="21020003" name="Large Soller slits 0.04 rad.">
				<opening unit="rad">0.0400</opening>
			</sollerSlit>
			<filter id="20030001" name="Large beta-filter Nickel">
				<material>Ni</material>
				<thickness unit="mm">0.020</thickness>
			</filter>
			<detector id="7010019" name="PIXcel1D-Medipix3 detector" xsi:type="rtmsDetectorType">
				<phd unit="keV">
					<lowerLevel>4.0</lowerLevel>
					<upperLevel>11.3</upperLevel>
				</phd>
				<mode>Scanning</mode>
				<activeLength unit="deg">5.020</activeLength>
			</detector>
		</diffractedBeamPath>
		<scan appendNumber="0" mode="Continuous" scanAxis="Gonio" status="Completed">
			<header>
				<startTimeStamp>2024-03-22T21:17:22-07:00</startTimeStamp>
				<endTimeStamp>2024-03-22T21:29:50-07:00</endTimeStamp>
				<author>
					<name>Instrument</name>
				</author>
				<source>
					<applicationSoftware version="1.6 (94)">PANalytical Aeris Instrument Suite</applicationSoftware>
					<instrumentControlSoftware version="3.0.0 20211014">AERIS</instrumentControlSoftware>
					<instrumentID>2879380</instrumentID>
				</source>
			</header>
			<dataPoints>
				<positions axis="2Theta" unit="deg">
					<startPosition>9.99043322</startPosition>
					<endPosition>100.09495370</endPosition>
				</positions>
				<positions axis="Omega" unit="deg">
					<startPosition>4.99521661</startPosition>
					<endPosition>50.04747685</endPosition>
				</positions>
				<commonCountingTime unit="seconds">18.249</commonCountingTime>
				<counts unit="counts">3947 4024 4128 3876 3856 3930 3993 4050 3963 3924 3967 4080 3833 3967 3915 3976 4013 4017 3872 3972 3900 3764 3869 3881 3882 3979 3854 3884 3874 3811 3822 3806 3946 3911 3837 3849 3906 3910 3862 3791 3860 3846 3869 3827 3803 3878 3882 3742 3781 3765 3806 3781 3768 3686 3742 3655 3633 3577 3748 3784 3775 3681 3873 3638 3700 3709 3762 3729 3764 3590 3749 3481 3693 3612 3605 3731 3723 3642 3503 3597 3698 3634 3686 3713 3641 3626 3667 3690 3584 3588 3432 3634 3518 3480 3526 3602 3558 3628 3529 3577 3653 3601 3509 3577 3595 3572 3474 3511 3486 3486 3503 3532 3516 3592 3511 3465 3477 3416 3409 3406 3470 3356 3430 3458 3451 3338 3422 3379 3346 3314 3377 3381 3345 3321 3435 3366 3352 3323 3380 3381 3294 3366 3401 3338 3326 3307 3344 3295 3307 3273 3321 3332 3310 3296 3282 3322 3292 3361 3367 3324 3355 3289 3319 3330 3206 3317 3222 3276 3268 3339 3215 3210 3191 3323 3233 3342 3065 3291 3184 3308 3169 3298 3248 3238 3084 3163 3128 3228 3277 3111 3267 3015 3237 3090 3164 3161 3181 3122 3193 3140 3042 3259 3166 3046 3162 3093 3000 3035 3164 2983 3150 3149 3051 3114 3040 3117 3073 2986 3138 3126 3096 3022 3012 2995 3013 3085 2952 3047 3011 2875 3016 3055 2947 3066 2912 2990 3067 3039 3000 3031 2992 2983 3040 2851 2972 2995 2915 2930 2890 2908 2993 2987 3002 2966 2831 2931 2971 2945 2900 2896 2917 2964 2985 2985 2917 2915 2918 2845 2954 2899 2932 2863 2874 2856 2965 2811 2931 2972 2820 2837 2880 2940 2924 2882 2813 2844 2940 2880 2831 2844 2827 2780 2781 2762 2825 2867 2798 2805 2821 2837 2807 2822 2843 2759 2803 2701 2899 2742 2839 2747 2762 2797 2759 2720 2770 2727 2744 2735 2722 2678 2698 2779 2659 2706 2730 2815 2747 2806 2721 2725 2621 2713 2838 2788 2701 2693 2711 2714 2765 2775 2696 2695 2588 2710 2733 2587 2605 2695 2756 2751 2600 2735 2705 2650 2685 2598 2637 2590 2603 2646 2605 2647 2581 2626 2605 2656 2631 2613 2626 2733 2679 2652 2571 2574 2562 2629 2600 2599 2650 2542 2666 2497 2664 2585 2557 2550 2569 2567 2553 2585 2617 2671 2597 2620 2524 2590 2546 2614 2736 2554 2543 2518 2616 2569 2607 2524 2600 2561 2621 2504 2510 2562 2633 2629 2527 2532 2579 2527 2538 2517 2499 2588 2650 2595 2580 2550 2509 2544 2678 2588 2491 2480 2483 2470 2579 2471 2525 2515 2574 2488 2557 2446 2523 2476 2571 2544 2543 2483 2527 2486 2497 2516 2468 2446 2557 2489 2542 2427 2492 2483 2349 2441 2548 2457 2522 2527 2460 2449 2427 2566 2485 2467 2433 2563 2506 2482 2490 2518 2472 2509 2400 2467 2437 2303 2480 2446 2431 2386 2517 2431 2458 2398 2405 2476 2417 2427 2490 2370 2431 2524 2451 2434 2425 2391 2444 2443 2420 2383 2521 2408 2515 2466 2444 2401 2360 2388 2451 2452 2428 2419 2509 2337 2425 2397 2368 2374 2370 2389 2392 2425 2341 2473 2317 2454 2422 2443 2381 2399 2379 2364 2332 2404 2424 2429 2418 2348 2398 2365 2427 2322 2383 2507 2443 2413 2412 2446 2360 2342 2418 2326 2324 2446 2428 2341 2388 2281 2317 2385 2315 2392 2348 2392 2343 2349 2341 2316 2376 2393 2404 2346 2355 2348 2338 2330 2330 2363 2350 2299 2278 2287 2436 2342 2332 2375 2396 2407 2283 2304 2423 2248 2411 2252 2344 2375 2325 2407 2337 2352 2370 2306 2277 2312 2402 2219 2334 2203 2347 2295 2320 2342 2295 2278 2316 2327 2294 2357 2239 2283 2340 2407 2367 2331 2255 2282 2300 2277 2302 2347 2284 2303 2297 2253 2269 2265 2204 2293 2342 2233 2311 2196 2332 2291 2249 2290 2368 2239 2301 2258 2296 2321 2264 2290 2350 2288 2337 2272 2299 2341 2277 2319 2245 2366 2282 2331 2220 2258 2227 2315 2329 2328 2319 2289 2336 2320 2269 2359 2288 2266 2312 2305 2372 2330 2368 2394 2430 2341 2360 2319 2416 2347 2345 2305 2242 2355 2289 2269 2316 2271 2253 2271 2231 2286 2332 2220 2309 2266 2343 2360 2308 2332 2329 2325 2372 2199 2393 2331 2286 2383 2251 2248 2361 2299 2359 2258 2368 2340 2271 2332 2385 2416 2443 2304 2415 2394 2330 2360 2381 2430 2441 2425 2525 2508 2484 2404 2597 2474 2425 2547 2559 2488 2619 2587 2565 2548 2570 2689 2618 2710 2730 2844 2742 2888 2889 2818 2906 2810 2894 2874 2991 2989 2924 2930 2989 3002 2976 2869 2860 2899 2818 2880 2748 2682 2628 2681 2595 2626 2613 2489 2569 2590 2532 2518 2465 2488 2376 2403 2309 2429 2299 2330 2333 2300 2345 2402 2232 2411 2232 2232 2286 2246 2218 2337 2338 2310 2201 2199 2202 2296 2253 2282 2281 2257 2125 2271 2136 2143 2198 2178 2144 2148 2251 2162 2190 2104 2195 2227 2151 2241 2165 2116 2194 2135 2202 2240 2162 2204 2117 2149 2132 2029 2140 2203 2183 2238 2131 2191 2267 2246 2145 2214 2152 2152 2191 2133 2158 2128 2102 2139 2264 2135 2134 2149 2117 2104 2104 2129 2185 2101 2116 2180 2115 2135 2088 2182 2184 2108 2137 2151 2125 2071 2084 2069 2136 2174 2182 2245 2069 2153 2162 2260 2155 2132 2197 2224 2184 2218 2223 2182 2156 2229 2289 2263 2254 2226 2243 2246 2290 2313 2331 2371 2333 2274 2435 2371 2426 2371 2514 2416 2416 2567 2658 2586 2592 2651 2642 2663 2890 2780 2869 2867 3045 3142 3274 3303 3572 3689 3757 4079 4232 4428 4814 5064 5229 5895 6195 6439 7067 7527 7792 8292 8733 9063 9485 9537 9597 9386 9028 8727 7919 7385 6748 5950 5447 4937 4368 3758 3650 3356 3178 3061 2978 2861 2737 2702 2669 2510 2520 2516 2646 2430 2441 2467 2460 2434 2409 2367 2340 2262 2322 2268 2260 2338 2362 2278 2251 2305 2203 2341 2181 2252 2235 2177 2188 2211 2284 2250 2201 2255 2280 2294 2262 2324 2352 2329 2322 2289 2327 2437 2401 2465 2413 2626 2648 2652 2723 2812 3006 3075 3228 3389 3535 3756 4039 4290 4642 4853 5171 5529 5685 6009 6304 6649 6333 6459 5938 5644 5275 4583 4221 3796 3351 2914 2811 2578 2390 2259 2228 2195 2014 2230 2074 2033 2043 2055 2003 2015 2140 2080 1998 2031 1968 1918 1993 1935 1950 1854 1931 1969 1996 1946 1908 1960 1827 1941 1946 1903 1827 1958 1964 2002 1866 1865 1851 1823 1909 1896 1937 1898 2016 1850 1830 1845 1905 1906 1837 1914 1883 1908 1836 1798 1827 1865 1861 1836 1860 1838 1814 1837 1868 1823 1847 1911 1920 1873 1722 1839 1849 1882 1813 1703 1847 1840 1886 1829 1910 1771 1872 1823 1911 1795 1880 1821 1841 1758 1847 1876 1878 1832 1882 1912 1818 1822 1758 1812 1742 1819 1804 1794 1833 1779 1758 1807 1739 1812 1768 1756 1670 1832 1784 1838 1708 1714 1850 1797 1736 1843 1838 1732 1730 1686 1758 1771 1837 1746 1827 1744 1741 1704 1799 1667 1748 1793 1750 1750 1798 1818 1778 1779 1841 1761 1785 1717 1813 1728 1766 1685 1874 1741 1757 1714 1829 1820 1822 1829 1836 1921 1874 1781 1825 1821 1778 1791 1875 1835 1823 1793 1791 1838 1789 1721 1742 1787 1803 1761 1721 1736 1735 1706 1759 1731 1757 1704 1736 1746 1662 1690 1709 1656 1717 1728 1709 1729 1714 1718 1662 1634 1648 1710 1759 1713 1602 1726 1738 1716 1744 1679 1637 1623 1766 1695 1604 1729 1643 1748 1702 1730 1644 1649 1673 1694 1666 1765 1653 1629 1637 1716 1697 1619 1647 1664 1676 1735 1655 1621 1704 1637 1640 1672 1642 1662 1628 1634 1627 1692 1659 1666 1731 1687 1707 1702 1647 1619 1637 1651 1655 1639 1702 1690 1727 1671 1662 1639 1708 1617 1660 1677 1690 1680 1724 1749 1722 1604 1717 1720 1711 1619 1683 1645 1687 1717 1691 1740 1693 1668 1758 1753 1709 1743 1725 1739 1725 1762 1675 1781 1684 1851 1680 1872 1734 1815 1771 1859 1874 1827 1910 1828 1929 1957 1930 2050 2042 1965 2031 2059 2118 2099 2022 2076 2153 2136 2173 2194 2218 2279 2319 2254 2411 2344 2393 2358 2519 2592 2569 2607 2547 2668 2670 2672 2731 2698 2721 2775 2789 2858 2678 2736 2870 2686 2771 2903 2968 2969 2991 3113 3168 3105 3254 3249 3308 3453 3599 3838 3962 4007 4266 4508 4816 5107 5540 5892 6463 6939 7679 8567 9315 10396 11796 13296 14906 16620 18475 20981 24040 26279 29702 32719 36287 39232 41986 43835 45331 45075 43647 41105 38768 35557 31881 28412 25170 21334 18345 15244 13031 11097 9389 8327 7261 6458 6043 5465 5076 4849 4535 4333 4139 4090 3856 3782 3685 3462 3455 3364 3284 3191 3064 3047 3075 2861 2807 2805 2594 2609 2555 2485 2461 2395 2385 2329 2245 2332 2256 2217 2247 2121 2096 2151 2096 2058 2080 2043 1986 2068 2036 1962 2035 1907 1992 1911 1877 1962 1873 1903 1866 1859 1884 1846 1843 1787 1774 1722 1772 1822 1767 1691 1808 1751 1842 1784 1739 1779 1727 1739 1693 1753 1763 1614 1707 1675 1694 1701 1689 1650 1673 1631 1691 1670 1704 1655 1592 1701 1620 1674 1603 1659 1656 1621 1566 1598 1603 1610 1594 1561 1499 1630 1657 1565 1527 1619 1587 1616 1552 1613 1536 1451 1608 1593 1617 1599 1621 1632 1681 1592 1582 1596 1679 1578 1619 1609 1629 1674 1715 1675 1749 1636 1615 1560 1534 1580 1545 1508 1494 1530 1538 1532 1487 1423 1575 1537 1521 1534 1557 1498 1462 1532 1497 1481 1560 1534 1512 1475 1532 1438 1486 1498 1462 1427 1439 1453 1577 1540 1499 1475 1424 1413 1430 1432 1496 1475 1427 1448 1514 1449 1470 1356 1474 1424 1514 1459 1456 1406 1441 1432 1470 1387 1511 1411 1429 1468 1400 1521 1377 1454 1443 1441 1523 1432 1523 1424 1444 1433 1420 1465 1448 1327 1393 1398 1390 1432 1450 1443 1409 1380 1382 1376 1467 1406 1458 1366 1424 1426 1342 1331 1362 1389 1414 1388 1332 1361 1372 1450 1417 1437 1453 1362 1403 1351 1394 1364 1305 1415 1429 1344 1395 1385 1388 1395 1442 1456 1311 1364 1428 1389 1302 1344 1342 1373 1350 1298 1407 1400 1347 1423 1385 1403 1316 1345 1405 1312 1377 1352 1423 1356 1388 1412 1389 1402 1427 1377 1297 1376 1388 1429 1341 1359 1364 1384 1388 1358 1405 1491 1371 1363 1386 1411 1365 1399 1419 1410 1387 1477 1460 1520 1501 1530 1535 1434 1499 1582 1587 1518 1550 1521 1557 1486 1517 1489 1472 1505 1528 1467 1533 1503 1549 1495 1468 1567 1449 1568 1546 1501 1472 1523 1530 1539 1570 1557 1697 1635 1555 1582 1652 1583 1626 1707 1693 1660 1673 1668 1731 1762 1832 1865 1799 1805 1897 1929 1929 1985 1924 1979 2063 2056 1974 2046 2171 2076 2289 2285 2418 2405 2463 2600 2732 2779 2993 3168 3438 3554 4086 4396 4896 5380 6064 6832 7830 8956 10574 12344 14363 16949 19404 22650 26445 29865 34183 37765 41306 42977 43502 41722 38509 34013 30251 27285 25113 22732 20385 16777 13644 10550 8204 6322 5268 4407 3843 3439 3227 3052 2830 2710 2695 2491 2451 2398 2377 2259 2266 2171 2128 2033 1983 1927 1906 2022 1892 1808 1791 1760 1719 1689 1713 1603 1603 1522 1591 1572 1522 1518 1490 1486 1543 1507 1489 1475 1535 1413 1455 1504 1399 1434 1401 1346 1478 1361 1320 1410 1340 1443 1438 1383 1458 1359 1420 1386 1428 1372 1354 1354 1344 1342 1438 1372 1362 1332 1376 1421 1324 1351 1372 1392 1363 1345 1339 1309 1328 1395 1346 1379 1353 1396 1323 1377 1300 1380 1341 1364 1297 1306 1286 1341 1368 1322 1297 1325 1294 1314 1320 1394 1316 1364 1282 1358 1363 1355 1290 1313 1292 1302 1298 1306 1279 1299 1287 1325 1289 1297 1267 1204 1282 1347 1291 1299 1265 1284 1305 1258 1221 1274 1258 1230 1223 1205 1228 1185 1205 1300 1249 1330 1262 1253 1235 1231 1287 1251 1251 1233 1233 1253 1196 1183 1184 1221 1309 1293 1260 1193 1237 1242 1220 1263 1176 1244 1277 1230 1194 1257 1197 1211 1255 1212 1274 1263 1217 1160 1194 1209 1171 1241 1228 1225 1175 1273 1205 1186 1165 1187 1201 1251 1135 1122 1055 1240 1268 1227 1224 1233 1273 1259 1296 1245 1313 1288 1400 1333 1466 1529 1549 1720 1690 1638 1670 1674 1616 1620 1497 1512 1527 1485 1370 1381 1327 1303 1259 1191 1207 1236 1220 1234 1197 1196 1201 1220 1204 1139 1226 1168 1149 1195 1190 1152 1232 1167 1115 1187 1228 1193 1166 1176 1222 1222 1179 1176 1228 1191 1235 1190 1171 1149 1199 1135 1144 1141 1159 1182 1128 1147 1164 1131 1156 1068 1139 1134 1132 1137 1142 1134 1136 1160 1153 1136 1116 1135 1124 1110 1156 1089 1204 1092 1170 1123 1195 1157 1119 1110 1212 1111 1119 1174 1090 1129 1205 1092 1102 1098 1112 1111 1128 1141 1197 1135 1227 1200 1216 1163 1228 1172 1182 1222 1123 1191 1262 1206 1125 1182 1199 1158 1183 1122 1155 1133 1182 1106 1151 1129 1153 1149 1146 1167 1196 1129 1155 1097 1201 1188 1123 1157 1171 1142 1190 1063 1151 1205 1107 1142 1102 1149 1169 1135 1133 1120 1147 1230 1191 1138 1179 1191 1239 1169 1225 1208 1201 1232 1221 1186 1180 1263 1191 1218 1229 1231 1231 1251 1331 1327 1308 1207 1295 1310 1329 1322 1423 1334 1304 1457 1398 1429 1427 1451 1430 1458 1469 1526 1572 1581 1643 1685 1782 1935 1908 2101 2292 2458 2564 2921 3466 3721 4256 4879 5617 6594 7349 8741 9712 11164 12266 13368 13313 13441 12617 11314 10011 9130 8593 8014 7962 7389 6537 5699 4623 3858 3234 2753 2438 2187 2165 2019 1957 1913 1884 1894 1818 1717 1873 1870 1855 2008 2062 2004 2096 2218 2332 2375 2564 2694 2952 3105 3434 3803 3977 4219 4580 4800 4940 5166 5069 5155 4862 4653 4411 4205 4150 3911 3725 3466 3264 2981 2721 2620 2349 2125 2036 1935 1853 1697 1712 1609 1681 1539 1557 1461 1472 1528 1382 1414 1351 1392 1361 1337 1244 1238 1309 1295 1325 1313 1275 1246 1218 1251 1205 1274 1216 1205 1155 1192 1171 1184 1149 1197 1221 1164 1268 1146 1161 1167 1055 1162 1202 1136 1223 1122 1137 1117 1154 1104 1226 1160 1165 1168 1164 1114 1171 1134 1199 1134 1166 1186 1120 1184 1173 1138 1199 1192 1202 1107 1095 1147 1131 1143 1156 1212 1202 1088 1116 1110 1164 1079 1080 1096 1120 1094 1145 1133 1076 1105 1156 1089 1120 1164 1176 1159 1149 1193 1199 1230 1168 1186 1211 1179 1211 1135 1190 1194 1169 1172 1248 1258 1224 1213 1290 1237 1270 1262 1322 1380 1429 1443 1473 1537 1573 1616 1755 1840 1929 2120 2216 2472 2680 2813 3045 3358 3476 3688 3516 3504 3283 3009 2876 2743 2640 2709 2725 2688 2632 2532 2467 2390 2444 2479 2559 2822 2966 3152 3631 3937 4446 5117 5789 6362 7209 7811 8427 8800 9095 8724 8536 7952 7635 6956 6558 6208 6068 5629 5373 4903 4222 3813 3431 2956 2664 2400 2160 2061 1917 1757 1670 1729 1645 1618 1566 1498 1542 1433 1431 1412 1374 1352 1396 1238 1306 1319 1366 1302 1258 1244 1332 1157 1235 1221 1290 1195 1220 1137 1202 1156 1249 1164 1192 1146 1142 1157 1164 1138 1120 1129 1147 1099 1132 1172 1176 1115 1110 1165 1087 1095 1079 1146 1087 1142 1136 1073 1132 1127 1149 1088 1052 1162 1139 1164 1096 1190 1135 1180 1062 1148 1122 1149 1159 1102 1176 1184 1170 1156 1182 1213 1270 1246 1202 1232 1216 1334 1233 1350 1336 1364 1420 1443 1409 1536 1641 1720 1843 1981 2083 2235 2518 2749 3059 3299 3759 4010 4482 4797 5184 5197 5320 5251 5124 4999 4830 4273 4172 4069 4002 3574 3524 3285 3066 2608 2475 2367 2081 2058 1802 1691 1655 1630 1584 1510 1606 1519 1569 1540 1592 1670 1712 1714 1710 1764 1629 1575 1525 1471 1439 1380 1385 1319 1391 1317 1319 1291 1304 1160 1157 1193 1082 1153 1079 1080 1047 1014 1095 1046 1064 987 1050 1047 1011 1036 1041 1053 1010 998 1035 999 1029 965 971 994 989 983 972 1051 963 1009 1070 989 1016 1046 940 963 962 993 1012 916 987 1030 1019 1007 986 1092 987 985 1025 986 948 991 998 965 1001 977 959 1000 982 955 955 1015 944 946 975 971 978 959 974 961 979 972 980 1004 1043 971 928 930 974 991 998 965 957 1021 1006 970 1016 921 1035 958 960 983 964 1021 1003 983 1044 996 1017 1001 1006 972 1024 992 1019 1020 1018 1016 1096 1084 1031 1067 1040 1043 1052 1087 1075 1033 1057 1059 1068 1117 1147 1126 1173 1122 1097 1213 1167 1101 1150 1196 1195 1151 1276 1203 1267 1269 1316 1335 1375 1367 1493 1454 1552 1603 1659 1622 1913 1911 2285 2298 2653 2969 3217 3429 3954 4456 4970 5730 6342 6730 7432 7511 8013 7986 7964 7692 7577 7344 7212 6790 6612 6076 5520 5420 4840 4481 4124 3835 3617 3081 2926 2502 2189 2107 1900 1770 1653 1662 1501 1458 1510 1450 1419 1336 1366 1230 1344 1309 1204 1276 1171 1240 1198 1171 1195 1125 1099 1179 1090 1166 1159 1133 1068 1086 1095 1071 1048 1043 1061 1051 1027 1034 1024 1029 992 1029 1063 1045 1051 996 983 1047 1042 1016 976 942 1013 989 980 1014 1012 1032 991 1002 964 1000 938 946 989 967 1039 972 1028 997 995 1002 921 983 910 1037 1005 1003 1062 943 989 1032 1049 990 989 960 1025 1034 1012 1044 1048 1066 1058 997 1062 1098 1091 1075 1141 1136 1078 1076 1160 1084 1171 1160 1147 1116 1165 1156 1188 1178 1182 1246 1295 1311 1355 1320 1376 1443 1409 1498 1504 1528 1549 1648 1547 1645 1728 1778 1893 1938 1961 2049 2074 2250 2355 2391 2508 2556 2699 2862 2896 2962 3117 3174 3206 3342 3451 3447 3560 3672 3550 3459 3557 3579 3561 3477 3528 3444 3463 3233 3191 3150 3126 2945 2875 2730 2507 2460 2266 2166 2181 2097 2074 1973 1849 1856 1679 1596 1595 1500 1533 1386 1390 1360 1368 1341 1250 1292 1232 1165 1203 1120 1145 1134 1173 1124 1101 1144 1106 1085 1107 1020 1055 970 1081 1038 1079 1041 999 1027 978 1012 995 1039 893 991 938 922 932 981 993 946 956 982 944 974 929 914 1016 967 940 914 1017 924 950 956 929 897 927 929 912 929 971 945 959 885 927 958 1003 1061 1054 1086 1069 1135 1205 1207 1332 1285 1368 1398 1475 1490 1484 1447 1410 1353 1353 1263 1249 1264 1207 1290 1187 1253 1179 1171 1118 1053 979 1022 1069 996 977 940 956 895 945 905 956 918 953 976 943 954 933 919 905 882 971 975 916 963 914 930 907 893 841 959 990 1000 990 957 1008 997 1008 1001 1053 1061 1049 1108 1148 1198 1291 1334 1473 1582 1723 2021 2226 2577 2957 3364 3801 4027 4261 4141 4076 3587 3347 2997 2642 2531 2617 2567 2675 2700 2685 2450 2249 1984 1709 1500 1346 1198 1125 1046 1033 991 937 900 990 921 947 935 944 905 856 920 901 877 883 875 837 844 826 853 883 849 839 855 834 886 859 821 839 858 851 820 854 828 818 840 760 836 826 792 824 834 861 829 847 835 806 780 856 842 791 798 851 889 784 822 785 839 814 800 775 842 796 794 862 852 798 800 832 840 789 824 778 840 848 808 762 803 835 812 803 843 818 761 805 824 827 764 831 809 855 814 812 850 764 829 830 820 850 879 865 782 830 854 811 813 772 843 799 814 836 810 809 848 851 806 790 833 797 811 873 839 868 854 817 832 771 861 771 824 832 865 837 843 828 889 856 839 824 849 849 851 905 860 847 866 876 828 884 830 848 859 889 891 857 882 909 870 846 920 867 894 898 954 923 946 930 911 936 891 938 936 889 902 954 931 971 947 994 909 977 983 988 948 1006 930 943 956 1030 990 1003 1017 1011 1071 1066 1052 1043 1055 1063 1143 1081 1205 1181 1182 1221 1264 1329 1358 1439 1548 1646 1781 1988 2109 2368 2488 2589 2532 2625 2444 2388 2315 2052 2048 1979 1997 2039 2098 2069 2024 1895 2003 1844 1612 1713 1614 1654 1603 1701 1717 1915 1926 2102 2265 2521 2843 3161 3474 3857 4180 4437 4588 4487 4474 4272 4107 3812 3565 3519 3328 3353 3185 3188 3185 3159 2885 2678 2373 2274 2107 1895 1729 1646 1502 1458 1424 1340 1281 1252 1171 1200 1126 1119 1172 1037 1100 1065 1078 1011 1053 1023 956 994 1027 983 1038 1110 994 1134 1183 1085 1131 1173 1243 1310 1494 1670 1630 1742 1810 1851 1978 1718 1685 1466 1455 1306 1366 1371 1318 1392 1364 1412 1299 1297 1159 1188 1081 1097 1035 933 978 910 922 884 867 921 855 918 832 812 851 893 883 875 839 875 848 853 823 885 837 838 788 831 875 865 842 817 838 791 818 838 882 835 851 831 800 796 820 862 817 793 843 800 797 794 831 776 841 798 885 827 856 824 826 870 867 883 802 833 856 865 821 887 821 820 830 800 870 868 849 877 812 854 823 841 802 846 842 839 829 878 855 861 896 872 956 894 939 951 922 945 962 909 992 972 998 956 1065 961 1071 992 1043 1097 1080 1094 1064 1146 1128 1165 1181 1210 1232 1307 1375 1333 1339 1371 1489 1567 1592 1755 1708 1910 2087 2306 2452 2872 3179 3969 4758 5794 6763 8054 9631 11594 12968 14534 15158 15013 13626 11930 10058 8408 7473 7029 7087 7245 7735 8231 8377 8134 7737 6834 5829 4708 3863 2994 2538 2212 1939 1781 1738 1555 1524 1378 1378 1354 1304 1284 1216 1122 1190 1124 1094 1104 1041 1054 1022 907 1037 972 999 912 942 949 951 962 912 897 870 854 889 872 862 872 892 849 904 851 847 797 820 863 867 832 803 825 822 857 775 828 809 855 722 818 817 827 785 832 863 853 788 841 828 790 826 803 854 831 801 821 860 813 795 808 814 799 824 805 808 842 808 795 815 824 810 818 798 745 818 837 821 834 811 800 829 862 870 841 824 877 832 816 843 770 830 851 857 817 872 858 878 819 840 874 896 870 865 902 867 954 1003 1002 935 1093 1077 1203 1221 1314 1476 1526 1646 1676 1765 1657 1587 1414 1352 1279 1229 1264 1286 1328 1301 1322 1380 1351 1397 1342 1296 1265 1219 1389 1300 1434 1443 1537 1593 1689 1766 1647 1577 1529 1478 1382 1379 1350 1365 1404 1419 1442 1334 1429 1425 1341 1349 1267 1416 1316 1354 1398 1453 1512 1658 1731 1865 2010 2201 2334 2543 2609 2586 2557 2435 2383 2336 2158 2095 1993 1937 1875 1888 1934 1956 1899 1794 1791 1674 1562 1477 1353 1354 1234 1153 1087 1074 1016 1005 1009 1014 941 956 938 924 891 845 917 852 844 904 871 847 832 883 857 822 870 811 868 876 891 860 840 843 844 857 882 812 842 849 836 852 887 864 862 809 844 846 816 844 809 791 849 811 822 849 809 823 829 819 834 845 789 876 838 848 890 916 846 883 919 899 961 937 1010 979 1018 927 898 839 817 899 862 862 842 875 881 903 858 850 870 808 843 848 807 763 783 784 744 802 754 765 758 775 801 779 793 773 814 786 768 806 744 733 727 773 736 761 774 740 730 793 723 782 762 781 794 772 761 772 687 772 787 827 812 754 842 812 765 824 758 810 819 761 797 819 775 834 812 748 811 788 822 785 842 823 863 781 803 753 845 763 803 810 736 777 834 728 779 770 752 784 771 835 832 791 793 783 745 812 802 781 825 839 806 820 819 790 790 843 802 822 816 791 871 833 821 863 797 860 857 880 834 889 813 866 851 918 938 911 974 992 1064 1121 1206 1294 1417 1593 1724 1948 2177 2326 2679 2667 2600 2503 2294 2084 1777 1638 1522 1601 1522 1558 1672 1754 1803 1878 1900 1822 1632 1571 1358 1374 1327 1285 1242 1284 1320 1342 1320 1323 1380 1290 1250 1252 1232 1203 1181 1168 1130 1164 1088 1127 1153 1132 1058 1120 1051 1138 1037 1011 1003 914 846 941 957 868 886 857 821 820 833 804 838 832 812 836 842 771 753 810 788 821 797 773 829 843 841 788 793 825 834 812 795 831 774 821 825 772 800 795 777 799 808 800 803 776 746 761 783 852 756 812 794 822 783 822 772 812 844 803 790 795 840 799 846 810 871 825 856 853 823 829 850 796 835 831 830 781 829 880 820 816 874 844 887 868 926 917 886 921 1038 995 1072 1096 1157 1207 1221 1287 1258 1233 1303 1158 1124 1042 1076 997 1020 1151 1052 1126 1116 1109 1097 1111 1074 954 1001 915 969 950 950 855 880 914 916 868 841 866 818 884 861 909 881 874 886 865 879 862 829 853 865 810 822 808 900 828 864 881 807 875 854 851 869 859 848 847 883 822 884 834 857 814 869 833 881 845 899 880 885 874 916 867 905 1033 931 1015 985 962 940 1002 990 1013 1028 1011 982 1040 1036 1123 1062 1145 1112 1181 1137 1211 1306 1302 1361 1440 1507 1614 1799 1911 2030 2323 2555 2902 3259 3530 3829 4064 4422 4678 4725 4712 4733 4491 4257 3965 3812 3527 3483 3438 3326 3440 3409 3311 3379 3512 3213 3252 3043 2923 2821 2726 2605 2501 2565 2671 2707 2880 3000 2896 2923 2573 2397 2061 1876 1806 1669 1601 1680 1661 1712 1721 1688 1785 1844 1710 1650 1626 1448 1301 1297 1196 1095 1055 997 1020 1005 989 935 960 893 912 912 979 929 927 967 899 872 938 864 834 888 865 894 882 857 888 889 862 877 803 882 826 878 827 850 814 819 847 825 764 821 791 864 835 853 855 831 890 833 825 837 829 836 896 787 803 801 888 836 820 792 805 829 810 906 794 870 844 884 888 866 858 898 920 896 920 985 878 946 944 968 926 931 963 951 1021 1007 1102 1067 1079 1163 1058 1156 1084 1182 1249 1193 1202 1212 1309 1288 1432 1512 1587 1688 1831 2007 2318 2476 2962 3471 4178 4923 5944 6968 8148 9329 10177 10628 10495 9663 8396 7118 5906 5033 4512 4319 4057 4196 4351 4922 5294 5674 5839 5696 5416 4787 4224 3471 2984 2499 2061 1928 1695 1624 1472 1446 1297 1252 1211 1194 1167 1055 1040 1113 1030 1056 1039 945 1016 927 957 930 934 946 903 837 897 935 912 854 849 891 825 916 907 868 951 832 897 877 905 850 859 883 849 861 868 877 902 890 910 973 943 989 992 1034 1073 1024 1141 1157 1217 1342 1449 1449 1574 1734 1889 1886 1933 1956 1851 1883 1783 1693 1629 1547 1474 1460 1426 1399 1526 1484 1499 1530 1515 1503 1497 1361 1377 1363 1256 1181 1186 1121 1109 1064 1046 1026 1079 1043 1099 1060 1025 1094 1065 1172 1199 1292 1359 1528 1678 1810 2128 2269 2539 2727 2903 2817 2653 2433 2175 1913 1714 1615 1481 1483 1485 1606 1540 1732 1754 1786 1861 1806 1719 1551 1466 1331 1157 1117 1120 992 1007 933 937 917 880 893 889 873 846 909 922 856 822 858 857 851 868 849 846 839 823 867 819 827 909 870 904 820 859 856 835 906 866 830 875 906 845 827 855 917 843 915 855 897 938 892 867 907 937 896 912 952 981 984 969 942 969 972 959 998 1043 1018 1041 1075 1125 1180 1047 1122 1182 1153 1247 1285 1256 1252 1244 1363 1385 1480 1512 1481 1459 1536 1560 1674 1668 1625 1805 1651 1804 1815 1843 1801 1849 1890 1881 2069 1932 1958 2021 1987 2046 2115 2149 2299 2219 2397 2574 2681 2926 3099 3263 3476 3354 3160 2967 2581 2381 2213 2034 1892 1873 1866 1881 1805 1923 2019 1979 2046 1965 1933 1829 1711 1520 1438 1353 1131 1187 1148 1014 1098 1003 1019 979 969 982 932 930 874 867 871 891 943 918 896 861 793 802 808 863 847 872 765 795 820 849 826 820 802 823 826 844 834 769 792 763 764 816 851 719 818 752 765 742 784 745 755 811 771 753 814 793 738 751 751 700 782 746 787 740 731 755 806 821 834 757 789 766 747 788 785 773 780 784 839 814 797 785 799 802 799 783 773 783 834 850 834 834 758 818 817 833 842 795 845 908 865 838 894 973 1021 1081 1136 1204 1325 1333 1446 1466 1500 1581 1518 1371 1334 1208 1092 1097 1068 1035 1055 1082 1093 1134 1187 1248 1325 1248 1269 1219 1223 1074 1034 1065 1022 1015 1004 995 1026 976 942 996 1110 1127 1031 1081 1106 1155 1129 1214 1285 1413 1433 1570 1720 1824 1934 2222 2378 2648 2920 3129 3352 3399 3340 3255 3105 2995 2778 2517 2478 2389 2348 2363 2342 2300 2400 2552 2668 2763 2879 3001 3083 3156 3154 3205 3368 3490 3525 3623 3878 3780 3798 3712 3434 3358 3112 2978 2877 2714 2521 2536 2529 2459 2540 2453 2491 2484 2529 2496 2412 2333 2209 2110 2066 1927 1711 1676 1584 1495 1392 1365 1360 1260 1215 1200 1155 1202 1111 1173 1102 1157 1097 1150 1096 1197 1139 1148 1236 1181 1319 1380 1388 1409 1442 1348 1354 1305 1276 1225 1225 1090 1159 1117 1171 1172 1190 1221 1241 1286 1290 1380 1310 1361 1334 1305 1314 1292 1370 1270 1457 1511 1612 1723 1803 1901 2166 2241 2489 2426 2497 2604 2646 2616 2476 2415 2280 2174 2173 2028 2019 1962 1908 1842 1850 1937 1913 1897 1896 1878 1778 1761 1756 1687 1544 1463 1395 1323 1229 1287 1175 1172 1089 1057 1028 966 947 938 980 940 898 998 933 906 891 897 940 865 941 845 853 836 842 787 892 772 881 774 845 758 800 813 782 805 796 828 803 799 813 842 842 822 787 781 758 799 795 785 814 806 872 830 904 832 885 981 890 1010 1024 1039 1204 1272 1386 1489 1646 1689 1792 1764 1699 1556 1430 1359 1194 1085 987 1025 979 1055 1133 1121 1098 1196 1182 1173 1301 1210 1151 1121 1060 982 960 848 862 853 862 798 787 830 768 754 722 688 726 774 725 724 747 673 740 668 754 733 737 704 712 676 710 702 704 718 780 678 759 702 762 705 688 696 743 719 712 690 731 711 761 716 745 688 717 675 722 666 701 698 722 683 727 708 697 729 696 712 630 719 704 711 731 705 700 677 693 708 718 738 738 715 734 723 747 708 776 650 753 712 676 708 726 731 706 797 766 723 719 740 754 712 733 739 786 841 911 970 972 1050 1082 1137 1177 1274 1194 1212 1140 1137 1067 996 895 894 897 852 893 863 859 970 928 1013 1004 991 1075 1039 953 930 945 913 901 817 817 879 826 792 877 812 880 854 918 925 939 971 959 1023 1092 1169 1270 1388 1453 1644 1712 1805 2045 2116 2184 2284 2162 2008 1965 1713 1717 1570 1537 1395 1405 1401 1342 1402 1414 1471 1426 1524 1590 1534 1500 1458 1453 1302 1190 1174 1136 1005 1017 935 946 837 850 907 842 771 793 767 803 777 829 829 749 720 806 718 714 773 683 760 721 684 676 670 741 777 696 742 627 737 677 727 688 683 695 654 698 680 699 703 653 698 668 723 666 688 663 664 654 711 699 713 656 666 666 680 679 692 666 624 653 655 582 703 687 632 677 641 673 613 659 615 623 685 671 698 643 621 634 682 689 615 598 690 631 672 644 644 627 617 619 691 606 619 679 628 614 611 630 629 644 611 646 607 678 662 616 628 648 615 686 647 704 656 668 627 630 637 595 634 666 641 629 629 649 585 623 626 642 641 626 645 686 607 627 675 662 661 644 625 643 607 634 676 659 659 633 638 629 644 629 654 667 619 671 655 636 664 675 596 627 643 665 654 621 681 632 636 676 631 689 642 632 666 619 631 632 615 662 626 605 679 677 575 585 607 626 608 619 646 637 626 644 656 631 592 687 604 658 661 633 625 632 610 646 636 677 590 621 617 648 667 624 635 634 623 692 642 626 616 668 663 623 572 625 639 694 660 674 640 640 625 642 645 673 609 661 654 668 651 678 647 623 644 666 642 640 659 668 649 670 663 699 679 645 646 619 643 678 683 637 663 638 687 677 699 654 663 654 712 666 652 659 677 675 714 733 674 687 709 699 713 683 704 745 759 752 762 818 711 790 810 830 831 849 847 890 861 932 1037 1196 1211 1279 1407 1543 1496 1656 1672 1666 1682 1678 1648 1653 1611 1741 1780 1867 1849 1852 1861 1841 1746 1798 1709 1651 1666 1558 1569 1481 1459 1386 1296 1385 1323 1302 1314 1284 1328 1341 1322 1246 1211 1145 1068 1086 1004 948 919 898 889 839 843 806 816 767 747 798 791 769 719 765 743 713 725 721 713 689 735 680 693 716 734 704 689 714 699 718 686 689 654 676 713 683 655 663 677 680 665 658 635 660 658 759 675 675 658 725 675 670 670 682 700 659 714 659 736 721 657 730 710 688 718 723 714 734 727 763 741 793 779 834 895 876 917 1006 1091 1149 1251 1309 1490 1649 1752 1829 1833 1804 1635 1565 1437 1342 1141 1095 994 1023 1022 967 999 1058 1123 1045 1166 1245 1278 1276 1257 1292 1282 1137 1132 997 958 856 829 810 835 738 726 713 713 736 745 754 671 716 700 688 717 663 661 670 718 740 678 688 627 697 613 686 674 663 705 687 704 682 682 662 692 685 692 725 705 684 633 694 607 712 654 703 676 697 678 682 675 716 698 732 690 739 700 729 677 746 719 762 691 724 761 744 763 764 720 753 811 797 800 773 754 845 818 838 872 872 937 989 1010 1009 1057 1059 1102 1193 1136 1171 1339 1354 1352 1577 1675 1718 1854 1994 1934 1946 1767 1704 1538 1440 1334 1159 1096 1145 1145 1060 1104 1072 1070 1145 1093 1230 1266 1300 1334 1293 1276 1243 1132 1053 1049 940 868 856 882 814 855 765 759 756 683 756 714 727 702 710 683 750 706 727 687 711 706 694 693 691 714 748 730 715 723 768 795 737 826 781 833 780 824 808 826 877 912 962 968 1010 1063 1159 1135 1262 1262 1260 1325 1340 1274 1341 1258 1218 1148 1109 1083 1103 1027 1064 966 992 1036 1023 1079 1105 1155 1205 1176 1214 1264 1233 1263 1324 1326 1293 1385 1434 1424 1473 1452 1451 1472 1427 1332 1352 1341 1238 1231 1298 1294 1352 1408 1482 1522 1604 1573 1541 1542 1475 1339 1286 1311 1212 1133 1162 1061 1067 1072 1014 979 990 1017 1010 1105 1027 1146 1051 1010 1022 987 885 922 802 820 804 791 757 811 796 752 772 750 735 705 730 726 728 739 706 774 737 783 724 762 759 754 814 736 801 861 892 915 922 958 947 984 974 947 973 996 998 992 1019 946 923 896 902 890 888 883 939 879 860 807 863 852 882 899 848 922 908 871 880 850 848 798 821 849 822 773 779 762 761 732 703 781 700 774 752 701 726 740 795 724 759 779 725 742 808 857 804 874 918 984 1112 1104 1189 1256 1360 1321 1336 1294 1206 1126 1045 985 912 866 859 865 848 733 794 892 869 893 886 971 984 1022 1029 1003 1004 981 930 891 840 807 805 801 777 755 741 705 724 751 728 762 718 717 679 747 750 720 695 765 731 727 726 680 766 726 733 776 768 753 759 804 804 812 919 809 872 878 946 930 961 1014 1019 1000 1077 1139 1185 1293 1408 1322 1455 1493 1577 1599 1556 1538 1566 1545 1534 1449 1512 1416 1387 1351 1251 1290 1309 1263 1363 1352 1305 1351 1427 1398 1384 1362 1281 1415 1343 1355 1360 1312 1296 1215 1217 1155 1177 1191 1122 1243 1174 1106 1188 1202 1332 1309 1309 1285 1293 1256 1186 1234 1079 1058 1017 935 974 893 919 831 904 879 817 883 852 905 894 885 891 921 916 924 898 878 824 761 783 756 804 750 714 740 688 719 720 705 657 699 682 696 661 678 678 653 688 662 645 683 689 682 652 638 705 614 673 640 649 628 680 631 692 666 666 692 688 684 684 679 632 703 710 733 695 680 713 714 804 705 722 729 757 681 650 673 665 713 684 694 705 656 702 721 699 682 734 685 690 753 719 721 719 742 690 703 721 734 701 778 776 822 835 811 922 980 1066 1121 1233 1338 1452 1551 1693 1627 1644 1512 1349 1290 1200 1073 960 983 944 932 918 882 884 950 931 990 1018 1069 1098 1115 1201 1338 1244 1191 1152 1189 1107 1077 1063 1020 996 917 893 872 857 794 801 780 827 825 762 730 711 778 721 720 750 755 769 735 754 726 767 764 735 781 691 782 756 743 705 701 691 717 739 709 636 704 698 708 668 683 666 720 729 661 701 663 704 712 675 697 684 662 655 694 731 688 695 764 718 699 766 736 743 768 780 810 720 778 736 804 778 827 817 817 866 855 948 1015 967 1053 1099 1236 1347 1501 1648 1891 2096 2303 2444 2701 2716 2650 2581 2259 2094 1831 1567 1449 1366 1306 1202 1156 1120 1138 1182 1138 1193 1268 1366 1402 1448 1593 1664 1637 1636 1572 1501 1374 1272 1195 1101 1019 942 902 878 866 824 771 739 707 732 690 727 718 663 651 683 638 628 641 661 685 686 667 661 632 658 641 612 653 652 634 604 635 611 588 615 637 610 634 599 626 645 632 610 600 585 597 593 599 640 644 623 590 633 643 596 570 583 633 638 617 586 629 617 586 613 590 572 584 615 588 599 640 616 640 587 601 629 609 633 600 591 599 644 647 629 626 620 596 636 655 659 657 675 651 671 624 697 639 619 630 638 625 645 657 626 621 636 621 582 633 624 652 607 641 612 666 610 700 629 628 730 681 746 661 651 704 665 722 757 787 756 773 713 795 725 725 733 755 655 780 692 668 702 677 679 671 649 711 718 730 697 638 748 731 729 667 672 700 741 702 703 689 680 696 656 629 683 615 670 677 648 706 663 652 626 645 625 654 624 647 630 634 649 637 675 620 669 716 710 705 705 714 704 711 697 752 731 770 772 789 831 795 935 930 1011 1061 1134 1330 1413 1558 1633 1861 1999 2142 2072 1996 1815 1715 1534 1382 1282 1170 1088 1081 1044 965 1000 871 902 930 940 1036 995 1200 1188 1303 1327 1289 1353 1319 1326 1140 1084 1068 979 909 856 848 724 784 623 694 693 678 668 637 647 678 673 648 616 652 566 677 609 673 608 627 617 619 647 666 626 630 600 634 583 621 619 565 597 584 594 630 587 581 595 603 658 577 586 597 584 641 595 684 589 601 577 582 540 570 553 590 599 600 624 613 597 631 561 584 594 597 651 610 607 604 658 596 544 678 638 646 651 632 655 624 658 709 760 710 786 785 871 861 857 851 880 755 738 712 692 675 677 645 617 653 637 637 624 665 637 706 651 663 739 639 650 693 771 718 725 772 685 651 644 636 637 640 624 635 612 619 570 624 592 598 581 592 609 581 570 544 604 634 618 575 570 567 590 524 582 612 577 578 597 609 613 604 539 567 529 591 627 588 606 655 583 581 594 629 606 609 601 583 579 599 569 620 590 633 630 623 596 609 609 654 613 599 641 624 660 680 611 621 574 687 628 662 677 664 623 676 627 681 659 652 791 745 770 804 836 882 954 1014 1088 1141 1175 1198 1193 1195 1207 1129 1104 1190 1080 1080 1032 1097 1053 1016 917 961 927 901 908 937 922 998 888 961 983 1033 976 959 968 982 924 938 890 847 863 887 818 820 841 810 781 785 761 714 713 769 782 712 740 689 728 647 687 657 692 613 687 686 688 630 685 670 641 624 644 661 646 647 673 629 598 723 652 689 655 633 669 710 682 686 662 672 664 709 702 721 746 697 771 778 754 792 872 823 848 882 955 980 964 1034 1046 1001 973 910 976 1021 948 945 922 913 883 888 896 925 924 988 1063 1164 1228 1300 1349 1440 1477 1449 1414 1350 1273 1261 1172 1053 1021 990 934 917 838 817 863 800 775 795 850 811 820 837 873 947 943 978 965 964 948 941 891 835 805 850 761 726 728 720 679 686 588 659 656 605 650 641 657 626 618 613 651 594 589 581 613 590 618 624 644 644 626 582 596 546 606 597 616 586 604 650 617 578 624 600 608 581 625 653 606 627 628 622 614 623 612 572 609 619 613 608 617 591 613 575 603 636 599 678 609 608 650 669 654 640 655 655 640 667 668 701 647 637 665 655 709 649 693 717 710 709 703 701 694 693 675 662 676 635 687 670 651 679 676 628 684 681 637 633 659 670 661 660 640 595 636 659 639 651 723 626 629 632 637 638 585 627 621 599 664 625 636 622 597 625 663 625 671 625 635 610 574 620 606 612 590 617 616 590 607 603 630 596 654 579 629 609 587 622 607 633 597 608 643 628 620 640 634 592 645 646 640 656 603 654 679 632 626 671 708 702 694 665 735 788 821 822 789 855 925 975 990 986 1014 1158 1063 1114 1146 1149 1117 1162 1060 1080 1119 1094 1061 1101 1118 1114 1128 1175 1250 1257 1321 1411 1469 1430 1476 1460 1394 1317 1321 1138 1178 1161 1102 1087 1051 1015 959 919 902 941 916 887 888 921 929 977 940 1056 960 1010 1028 1021 1037 1028 931 835 876 781 771 787 785 737 753 729 742 762 718 762 779 783 761 683 734 761 724 770 798 823 785 816 827 780 816 802 841 805 824 753 786 791 773 764 768 728 703 727 739 694 686 684 694 692 732 713 732 720 716 713 765 747 730 699 706 693 682 683 645 706 679 646 658 658 647 623 663 646 670 628 593 645 630 705 622 609 630 601 642 610 599 580 646 618 586 584 551 624 600 604 595 595 584 595 606 571 583 599 597 637 590 600 612 585 640 586 625 594 637 578 591 617 573 577 609 583 559 588 560 592 561 604 586 578 602 571 615 577 600 587 626 563 615 626 557 617 590 597 565 562 643 568 620 578 579 619 605 575 593 528 600 619 589 580 634 588 611 600 638 571 630 584 590 619 557 564 568 626 597 642 603 604 603 605 598 601 607 658 633 619 607 610 605 640 625 633 633 600 616 611 640 625 662 694 688 695 702 654 761 752 813 855 877 923 1015 1100 1086 1103 1251 1241 1233 1234 1129 1154 1027 1038 926 883 863 796 803 804 712 810 709 756 777 776 733 771 784 861 815 899 924 931 951 1015 973 1069 999 994 1011 1019 975 956 945 943 1002 952 911 909 913 928 905 910 854 907 889 845 847 840 798 807 774 784 807 735 771 754 784 807 801 770 805 767 811 843 790 846 809 822 827 847 764 853 817 814 757 785 737 777 781 755 769 753 717 720 731 725 741 749 805 750 744 800 769 797 829 788 775 808 765 823 761 812 805 919 839 918 861 990 1012 1130 1063 1227 1274 1437 1493 1626 1735 1830 1858 1892 1930 1661 1585 1455 1400 1331 1236 1134 1098 1084 944 997 938 955 868 901 910 959 960 991 998 1028 1085 1096 1231 1211 1365 1396 1390 1399 1391 1363 1380 1324 1270 1231 1195 1194 1112 1079 1046 948 918 950 862 824 843 824 802 787 790 757 772 771 802 776 723 764 729 798 777 816 750 789 791 761 791 835 762 780 766 782 736 761 712 699 719 671 698 697 622 701 628 693 736 635 706 620 638 679 659 647 672 673 686 629 671 604 665 667 686 623 689 693 631 683 707 788 718 707 736 782 776 839 893 926 981 1020 1031 1221 1280 1231 1294 1238 1191 1127 1058 943 985 927 836 854 840 799 739 734 729 748 711 731 732 716 764 736 771 796 829 879 866 889 869 938 919 950 925 883 861 839 812 750 741 694 671 738 664 658 691 647 662 587 689 644 639 690 676 612 655 659 631 595 607 638 600 610 668 645 608 592 619 637 595 634 619 641 631 630 587 651 618 656 611 625 634 647 618 632 637 651 633 629 657 682 658 651 635 676 636 679 661 684 668 693 681 740 716 680 726 739 774 752 753 739 801 848 843 888 908 970 969 1009 1116 1166 1175 1301 1391 1326 1413 1432 1404 1379 1441 1375 1366 1420 1425 1451 1418 1353 1338 1405 1224 1227 1203 1221 1184 1146 1187 1127 1128 1132 1227 1186 1250 1275 1297 1292 1349 1344 1359 1342 1390 1387 1410 1433 1379 1410 1393 1377 1349 1303 1304 1209 1180 1160 1132 1054 1064 1058 999 987 962 967 931 907 954 918 918 878 863 917 904 913 824 874 933 864 881 789 879 820 837 822 766 763 819 738 792 753 691 744 667 708 744</counts>
			</dataPoints>
		</scan>
	</xrdMeasurement>
</xrdMeasurements>