File: dataset/precursor_mixture/HfO2_La(OH)3_Y2O3.2-min.xrdml
<?xml version="1.0"?>
<xrdMeasurements xmlns="http://www.xrdml.com/XRDMeasurement/2.2" xmlns:xsi="http://www.w3.org/2001/XMLSchema-instance" xsi:schemaLocation="http://www.xrdml.com/XRDMeasurement/2.2 http://www.xrdml.com/XRDMeasurement/2.2/XRDMeasurement.xsd" status="Completed" recordIdentifier="{F545E91E-E42F-43BE-9A38-E358E326F52A}">
	<comment>
		<entry/>
	</comment>
	<sample type="To be analyzed">
		<id></id>
		<name></name>
		<preparedBy></preparedBy>
	</sample>
	<xrdMeasurement measurementType="Scan" status="Completed" sampleMode="Reflection">
		<usedWavelength intended="K-Alpha 1">
			<kAlpha1 unit="Angstrom">1.5405980</kAlpha1>
			<kAlpha2 unit="Angstrom">1.5444260</kAlpha2>
			<kBeta unit="Angstrom">1.3922500</kBeta>
			<ratioKAlpha2KAlpha1>0.5000</ratioKAlpha2KAlpha1>
		</usedWavelength>
		<incidentBeamPath>
			<radius unit="mm">145.00</radius>
			<xRayTube id="1010048" name="Empyrean Cu LFF HR (9430 033 7310x) DK437873">
				<tension unit="kV">40.0</tension>
				<current unit="mA">15.0</current>
				<anodeMaterial>Cu</anodeMaterial>
				<focus type="Line">
					<length unit="mm">12.0</length>
					<width unit="mm">0.4</width>
					<takeOffAngle unit="deg">6.0</takeOffAngle>
				</focus>
			</xRayTube>
			<filter id="20010004" name="Beta-filter Nickel">
				<material>Ni</material>
				<thickness unit="mm">0.020</thickness>
			</filter>
			<sollerSlit id="21010002" name="Soller slits 0.04 rad.">
				<opening unit="rad">0.0400</opening>
			</sollerSlit>
			<mask id="22031000" name="Fixed mask 13 mm">
				<width unit="mm">9.00</width>
			</mask>
			<divergenceSlit id="22120001" name="Divergence slit 1°" xsi:type="fixedDivergenceSlitType">
				<distanceToSample unit="mm">50.00</distanceToSample>
				<height unit="mm">1.52</height>
			</divergenceSlit>
		</incidentBeamPath>
		<beamKnife id="29030100" name="Beam knife low"/>
		<sampleMovement xsi:type="spinningSampleMovementType">
			<spinnerRevolutionTime unit="seconds">1.0</spinnerRevolutionTime>
		</sampleMovement>
		<diffractedBeamPath>
			<radius unit="mm">145.00</radius>
			<antiScatterSlit id="22090040" name="AS slit 9 mm" xsi:type="fixedAntiScatterSlitType">
				<height unit="mm">9.00</height>
			</antiScatterSlit>
			<sollerSlit id="21020003" name="Large Soller slits 0.04 rad.">
				<opening unit="rad">0.0400</opening>
			</sollerSlit>
			<filter id="20030001" name="Large beta-filter Nickel">
				<material>Ni</material>
				<thickness unit="mm">0.020</thickness>
			</filter>
			<detector id="7010019" name="PIXcel1D-Medipix3 detector" xsi:type="rtmsDetectorType">
				<phd unit="keV">
					<lowerLevel>4.0</lowerLevel>
					<upperLevel>11.3</upperLevel>
				</phd>
				<mode>Scanning</mode>
				<activeLength unit="deg">1.021</activeLength>
			</detector>
		</diffractedBeamPath>
		<scan appendNumber="0" mode="Continuous" scanAxis="Gonio" status="Completed">
			<header>
				<startTimeStamp>2024-03-22T20:45:56-07:00</startTimeStamp>
				<endTimeStamp>2024-03-22T20:48:18-07:00</endTimeStamp>
				<author>
					<name>Instrument</name>
				</author>
				<source>
					<applicationSoftware version="1.6 (94)">PANalytical Aeris Instrument Suite</applicationSoftware>
					<instrumentControlSoftware version="3.0.0 20211014">AERIS</instrumentControlSoftware>
					<instrumentID>2879380</instrumentID>
				</source>
			</header>
			<dataPoints>
				<positions axis="2Theta" unit="deg">
					<startPosition>10.02173288</startPosition>
					<endPosition>139.98435528</endPosition>
				</positions>
				<positions axis="Omega" unit="deg">
					<startPosition>5.01086644</startPosition>
					<endPosition>69.99217764</endPosition>
				</positions>
				<commonCountingTime unit="seconds">1.551</commonCountingTime>
				<counts unit="counts">404 363 385 377 388 425 419 427 404 377 380 347 370 378 370 357 354 423 360 343 355 340 351 354 360 372 360 327 343 351 306 356 337 303 363 340 315 345 335 378 306 327 349 308 316 330 283 318 317 275 331 289 277 290 277 306 281 295 310 277 309 276 269 283 294 306 261 275 267 303 270 284 250 286 276 272 280 301 271 309 254 255 262 262 272 251 252 256 276 275 264 252 276 273 248 260 265 243 250 237 262 245 269 249 246 260 285 257 242 257 256 247 264 226 268 278 275 282 316 317 315 390 423 521 558 745 936 925 830 606 494 384 341 287 255 237 236 234 207 259 225 238 204 209 222 217 215 215 259 210 208 227 243 219 232 224 208 227 243 201 188 204 239 206 212 218 213 253 246 252 281 256 213 198 183 166 217 192 192 195 202 191 191 202 227 195 207 215 202 203 194 222 178 174 189 181 211 194 212 199 195 190 159 175 197 190 186 216 187 203 193 176 173 162 176 194 178 153 160 182 198 199 184 180 162 182 183 190 177 178 187 155 217 215 276 342 402 368 301 246 190 217 187 185 153 158 200 185 185 199 201 170 160 176 161 152 180 180 153 161 160 172 153 142 197 198 156 182 146 134 156 173 134 154 160 196 152 139 166 188 137 151 136 159 152 169 146 163 172 159 152 158 165 179 161 177 141 176 151 159 185 156 154 164 148 160 168 149 155 149 158 185 195 175 196 213 221 232 310 367 402 324 230 206 183 214 217 280 309 353 287 207 177 160 159 166 162 152 152 158 177 165 148 162 164 155 124 148 182 133 154 162 146 156 130 138 170 142 150 141 167 142 138 123 179 154 156 161 164 154 168 153 158 164 137 153 153 183 197 179 175 191 221 258 320 374 473 580 640 729 560 543 400 368 278 292 285 261 293 305 423 517 632 837 921 937 896 689 655 675 771 964 1304 1482 1288 974 632 478 329 316 288 253 286 274 312 327 345 501 723 1176 1850 2316 1975 1290 763 430 293 259 251 208 235 191 175 219 174 174 170 176 162 147 157 163 145 141 161 161 123 168 139 150 145 150 122 153 148 146 147 166 132 143 148 147 148 160 190 200 166 202 191 190 259 280 320 360 524 693 923 1149 1110 956 706 466 351 264 222 222 232 165 144 153 158 161 134 172 186 129 135 157 140 134 158 144 149 151 120 109 125 110 131 138 138 156 148 116 129 136 127 145 144 148 151 180 220 295 430 564 536 460 366 241 198 173 201 195 236 255 327 379 420 398 347 290 298 364 415 404 315 275 224 166 173 153 138 152 136 131 165 130 170 155 158 169 256 353 451 442 353 304 224 195 160 188 234 279 262 266 267 254 231 216 163 137 121 136 123 113 115 117 115 120 108 123 123 126 108 96 126 92 106 115 121 125 113 121 112 112 113 104 129 108 97 112 128 116 106 107 116 132 130 118 131 108 124 116 88 110 124 125 119 115 113 138 114 126 140 155 162 206 229 212 186 198 163 151 162 177 165 208 251 250 357 450 542 543 542 525 455 363 309 306 264 274 282 252 202 162 165 134 111 137 139 134 123 134 108 97 127 133 119 128 133 146 141 142 146 183 199 250 255 255 179 167 143 151 145 144 162 155 154 162 165 172 179 175 183 176 141 151 145 115 126 148 148 168 204 204 163 152 175 165 138 134 141 132 98 95 140 112 126 103 116 92 104 112 79 131 130 121 133 114 128 131 206 232 230 208 206 157 155 130 118 108 120 88 128 80 77 111 84 100 98 104 93 90 103 108 115 77 112 115 88 103 104 88 103 91 103 103 147 145 155 126 133 137 123 128 99 124 128 125 118 123 158 152 167 172 191 164 147 137 117 100 100 105 126 137 83 107 134 108 109 102 84 112 113 125 154 119 113 159 191 158 193 187 165 210 186 197 185 147 163 131 122 122 123 104 130 118 119 134 126 115 137 140 177 180 198 263 287 324 316 342 358 366 488 677 904 1155 1025 874 883 681 567 406 317 309 243 192 222 155 152 179 135 156 159 159 159 192 217 270 361 288 301 294 204 199 166 193 192 198 149 204 154 163 152 184 204 184 243 329 392 340 315 277 238 196 184 182 197 229 253 180 206 178 130 130 130 118 126 103 114 140 134 131 160 132 155 162 148 122 91 111 121 97 109 129 89 119 130 86 65 88 116 84 88 94 98 79 99 94 96 80 90 103 106 113 91 96 120 107 121 147 183 144 133 133 162 108 96 97 96 78 82 87 67 97 104 92 107 94 104 99 128 112 100 88 132 154 186 177 249 219 209 205 195 169 160 141 138 130 134 125 142 150 165 163 168 152 214 222 239 219 226 184 204 217 203 234 315 256 234 247 265 236 207 220 229 244 260 261 289 266 266 279 225 215 186 173 119 147 122 110 129 117 88 105 102 120 94 117 115 126 125 139 132 151 153 174 231 356 440 593 569 471 403 380 320 239 163 181 157 141 123 135 153 167 206 182 168 200 159 146 146 159 169 155 159 138 159 157 151 160 185 219 181 139 151 153 135 120 131 116 101 92 92 82 86 119 97 104 105 104 85 119 108 114 117 144 176 188 205 174 188 217 244 232 207 186 187 153 136 110 108 108 101 79 114 101 85 100 115 81 82 104 95 98 82 95 129 102 113 110 135 136 154 184 196 179 158 151 168 129 124 127 137 137 149 168 209 154 131 130 142 123 130 119 90 97 118 105 108 124 103 131 102 137 147 187 196 233 222 161 145 179 151 128 116 134 137 115 126 149 186 153 150 183 189 166 154 144 156 163 136 142 134 143 163 148 170 146 144 165 148 136 131 131 111 124 137 143 129 124 130 132 120 127 113 125 99 87 108 104 82 147 125 129 152 159 155 152 155 177 158 191 184 169 156 150 152 149 114 113 116 106 103 86 105 82 100 76 76 78 84 83 83 78 74 77 100 103 72 91 76 94 70 83 86 84 90 71 77 73 101 80 93 94 89 62 88 84 105 90 68 88 81 81 79 76 94 92 90 70 97 81 76 97 83 95 81 77 101 106 88 133 121 116 124 129 122 157 147 151 157 177 170 187 188 151 156 136 139 152 117 107 96 110 88 82 105 93 89 121 84 114 84 89 114 104 122 115 109 116 153 144 177 153 142 134 153 131 117 142 132 113 127 128 176 142 145 139 136 142 103 143 108 109 112 120 105 121 93 139 155 136 144 111 111 136 118 128 128 99 108 122 111 106 100 83 116 128 106 107 124 115 91 102 103 76 82 112 104 123 106 103 76 90 110 123 86 103 95 85 85 90 114 85 98 61 81 97 89 84 104 98 88 97 86 107 98 118 87 126 116 108 109 123 114 109 118 96 111 119 103 113 126 124 150 116 146 154 158 130 125 146 122 137 134 152 136 119 115 139 114 103 147 123 122 107 131 107 126 133 120 135 113 125 132 169 143 194 133 143 170 185 200 205 177 179 205 209 179 158 182 174 179 156 160 167 126 124 117 115 137 120 116 125 111 109 131 125 135 179 194 221 188 180 152 158 178 140 120 120 109 107 107 106 89 92 94 78 90 102 127 127 122 118 106 92 108 89 109 90 94 86 105 73 83 103 100 83 96 72 86 84 80 99 75 96 88 100 109 83 124 115 100 82 113 125 141 155 116 113 124 126 111 128 89 91 86 97 94 83 101 77 78 95 115 117 91 110 112 114 128 151 113 108 152 110 115 113 127 122 134 113 100 101 88 115 103 82 99 105 96 109 122 116 116 116 97 94 109 112 122 114 146 105 133 129 128 126 108 100 118 91 93 98 100 113 83 97 116 87 93 101 92 117 106 136 108 135 156 138 138 133 114 106 117 141 105 116 89 78 100 83 122 107 97 100 83 108 100 96 101 93 113 126 113 103 94 112 61 86 93 82 115 106 98 79 111 77 78 104 84 108 108 90 101 91 83 79 80 99 94 113 98 116 97 104 103 91 109 100 107 96 101 94 107 94 77 82 71 86 88 93 104 110 104 104 105 107 118 102 114 124 124 117 103 101 127 113 134 140 124 140 139 121 138 131 154 151 152 139 131 143 117 128 109 93 139 129 139 131 116 120 100 113 147 101 134 97 119 115 109 104 116 143 116 132 116 106 137 118 128 143 154 123 157 181 162 115 128 124 110 124 125 122 89 95 127 88 97 129 86 106 106 106 96 97 81 93 94 109 113 119 109 128 130 127 118 103 115 101 93 82 87 89 97 85 80 94 87 73 89 96 80 88 101 112 91 66 105 89 105 97 92 89 80 113 114 90 77 97 95 75 124 73 79 85 94 65 89 96 74 98 75 89 107 96 88 93 109 115 113 109 116 102 116 85 111 88 79 91 84 112 73 96 83 108 102 83 116 128 131 157 152 174 170 189 148 152 135 170 147 170 153 124 129 131 112 114 103 117 126 110 108 122 101 121 110 139 137 133 130 136 140 118 148 110 129 123 119 122 162 96 129 125 125 118 128 130 137 127 143 152 122 118 107 111 131 115 145 161 145 131 125 115 120 130 142 129 106 90 96 107 104 91 100 109 101 100 123 115 110 119 114 131 134 148 118 140 108 135 112 114 114 124 134 123 107 117 115 117 117 95 127 115 106 121 135 104 102 114 107 99 123 96 120 114 126 110 92 82 107 91 106 96 101 89 104 101 90 105 102 120 127 113 142 120 131 125 147 137 160 142 126 137 107 104 132 117 141 122 115 116 112 78 131 140 107 109 122 98 125 97 104 135 109 103 102 118 140 127 149 130 93 104 124 111 105 142 111 99 100 123 102 94 84 114 104 99 104 76 93 120 104 91 86 109 114 110 106 104 115 94 95 91 91 113 106 99 99 107 85 101 99 74 83 72 96 85 92 85 77 76 96 93 112 116 110 109 98 91 104 85 99 88 105 110 86 123 113 76 79 99 79 85 107 100 93 95 97 88 106 88 95 101 109 106 91 114 96 111 98 90 80 115 98 97 110 121 105 104 120 85 74 108 106 104 89 95 95 89 101 88 108 109 74 114 97 101 105 92 107 114 104 104 117 104 92 118 119 113 128 92 133 116 117 108 127 110 111 122 137 125 126 111 118 95 103 84 110 81 138 118 122 113 115 124 104 126 108 90 100 91 89 88 95 116 120 118 122 115 136 133 98 87 98 104 103 89 119 109 118 120 118 105 112 122 108 109 115 81 93 106 99 108 117 107 113 112 126 127 109 108 137 101 127 115 99 96 104 93 115 98 101 100 111 101 90 84 102 90 118 119 101 101 134 120 110 104 121 135 116 127 107 116 128 93 84 94 109 99 110 115 88 143 93 114 106 90 108 88 126 81 111 99 110 109 132 123 131 134 140 111 102 98 107 120 120 83 136 126 102 122 109 100 106 95 115 87 88 100 115 80 98 82 95 88 80 118 103 127 123 107 121 119 106 101 137 130 112 121 106 106 105 129 107 108 94 105 114 124 109 120 111 91 114 109 111 115 112 114 119 121 126 113 121 121 107 126 110 106 106 121 100 109 106 119 112 97 96 91 116 113 87 116 111 87 104 106 129 131 139 105 101 113 123 105 95 104 114 117 115 132 127 116 105 101 103 98 112 75 97 113 103 78 98 109 85 86 126 100 92 98 97 118 86 84 110 64 91 85 88 91 79 93 78 110 111 103 94 89 72 96 85 86 107 89 91 109 78 114 88 114 113 127 103 107 140 109 99 93 134 125 129 148 113 112 129 147 150 139 91 120 100 117 91 111 114 126 124 108 135 112 127 119 123 108 131 118 89 104 111 99 110 105 94 125 109 123 118 113 87 108 88 79 103 106 87 107 92 101 99 95 108 104 124 109 92 101 107 95 94 105 111 96 103 124 85 96 85 100 106 117 97 106 83 103 86 102 122 102 101 82 100 103 108 97 95 118 110 115 126 106 102 92 88 94 97 121 107 109 98 112 97 98 100 95 101 113 112 110 121 92 99 99 100 78 110 107 103 87 110 97 114 132 128 105 128 117 107 122 105 104 133 98 124 119 130 127 136 119 111 114 103 108 90 113 116 101 111 105 116 104 103 106 120 90 104 122 98 109 119 123 93 79 107 114 90 91 94 93 89 93 112 107 123 107 116 117 99 112 117 119 101 112 127 111 94 108 122 121 107 134 103 120 116 113 91 103 105 95 104 108 119 109 113 104 107 120 116 98 110 110 95 101 111 110 104 115 114 80 99 113 106 101 114 116 111 135 130 140 120 137 127 125 138 125 122 109 137 111 146 150 153 126 136 119 146 125 149 105 147 129 128 130 131 126 134 124 143 152 112 123 142 137 129 140 139 135 139 122 132 146 116 128 115 110 116 103 134 109 121 121 118 121 125 109 96 129 115 112 92 109 105 104 120 121 133 121 122 90 128 137 128 113 111 118 109 116 97 123 107 110 81 106 110 103 114 117 107 108 119 119 128 121 115 95 107 93 132 113 82 92 106 127 113 100 111 122 129 131 114 123 119 146 145 120 144 127 126 138 104 125 88 110 125 123 114 124 112 131 144 112 107 126 111 134 102 97 123 124 101 117 117 111 114 133 132 125 126 127 137 123 133 160 104 132 128 138 125 127 142 141 126 124 118 140 145 133 136 156 146 142 141 131 125 111 135 139 126 122 129 133 133 130 146 129 143 121 146 162 157 132 152 148 144 149 157 137 162 145 151 152 150 147 152 138 123 138 169 121 127 154 128 142 134 153 153 146 143 148 135 137 123 141 155 124 146 155 136 141 129 145 139 155 142 144 149 143 149 152 140 144 142 145 137 150 146 126 140</counts>
			</dataPoints>
		</scan>
	</xrdMeasurement>
</xrdMeasurements>