File: dataset/precursor_mixture/HfO2_K2SO4_Bi2O3-beta.2-min.xrdml
<?xml version="1.0"?>
<xrdMeasurements xmlns="http://www.xrdml.com/XRDMeasurement/2.2" xmlns:xsi="http://www.w3.org/2001/XMLSchema-instance" xsi:schemaLocation="http://www.xrdml.com/XRDMeasurement/2.2 http://www.xrdml.com/XRDMeasurement/2.2/XRDMeasurement.xsd" status="Completed" recordIdentifier="{D02D8121-24D2-4DBB-A38F-8AE3E7A42654}">
	<comment>
		<entry/>
	</comment>
	<sample type="To be analyzed">
		<id>dara-40-1</id>
		<name></name>
		<preparedBy></preparedBy>
	</sample>
	<xrdMeasurement measurementType="Scan" status="Completed" sampleMode="Reflection">
		<usedWavelength intended="K-Alpha 1">
			<kAlpha1 unit="Angstrom">1.5405980</kAlpha1>
			<kAlpha2 unit="Angstrom">1.5444260</kAlpha2>
			<kBeta unit="Angstrom">1.3922500</kBeta>
			<ratioKAlpha2KAlpha1>0.5000</ratioKAlpha2KAlpha1>
		</usedWavelength>
		<incidentBeamPath>
			<radius unit="mm">145.00</radius>
			<xRayTube id="1010048" name="Empyrean Cu LFF HR (9430 033 7310x) DK437873">
				<tension unit="kV">40.0</tension>
				<current unit="mA">15.0</current>
				<anodeMaterial>Cu</anodeMaterial>
				<focus type="Line">
					<length unit="mm">12.0</length>
					<width unit="mm">0.4</width>
					<takeOffAngle unit="deg">6.0</takeOffAngle>
				</focus>
			</xRayTube>
			<filter id="20010004" name="Beta-filter Nickel">
				<material>Ni</material>
				<thickness unit="mm">0.020</thickness>
			</filter>
			<sollerSlit id="21010002" name="Soller slits 0.04 rad.">
				<opening unit="rad">0.0400</opening>
			</sollerSlit>
			<mask id="22031000" name="Fixed mask 13 mm">
				<width unit="mm">9.00</width>
			</mask>
			<divergenceSlit id="22120001" name="Divergence slit 1°" xsi:type="fixedDivergenceSlitType">
				<distanceToSample unit="mm">50.00</distanceToSample>
				<height unit="mm">1.52</height>
			</divergenceSlit>
		</incidentBeamPath>
		<beamKnife id="29030100" name="Beam knife low"/>
		<sampleMovement xsi:type="spinningSampleMovementType">
			<spinnerRevolutionTime unit="seconds">1.0</spinnerRevolutionTime>
		</sampleMovement>
		<diffractedBeamPath>
			<radius unit="mm">145.00</radius>
			<antiScatterSlit id="22090040" name="AS slit 9 mm" xsi:type="fixedAntiScatterSlitType">
				<height unit="mm">9.00</height>
			</antiScatterSlit>
			<sollerSlit id="21020003" name="Large Soller slits 0.04 rad.">
				<opening unit="rad">0.0400</opening>
			</sollerSlit>
			<filter id="20030001" name="Large beta-filter Nickel">
				<material>Ni</material>
				<thickness unit="mm">0.020</thickness>
			</filter>
			<detector id="7010019" name="PIXcel1D-Medipix3 detector" xsi:type="rtmsDetectorType">
				<phd unit="keV">
					<lowerLevel>4.0</lowerLevel>
					<upperLevel>11.3</upperLevel>
				</phd>
				<mode>Scanning</mode>
				<activeLength unit="deg">1.021</activeLength>
			</detector>
		</diffractedBeamPath>
		<scan appendNumber="0" mode="Continuous" scanAxis="Gonio" status="Completed">
			<header>
				<startTimeStamp>2024-03-24T18:52:24-07:00</startTimeStamp>
				<endTimeStamp>2024-03-24T18:54:46-07:00</endTimeStamp>
				<author>
					<name>AutomatedUser</name>
				</author>
				<source>
					<applicationSoftware version="1.6 (94)">PANalytical Aeris Instrument Suite</applicationSoftware>
					<instrumentControlSoftware version="3.0.0 20211014">AERIS</instrumentControlSoftware>
					<instrumentID>2879380</instrumentID>
				</source>
			</header>
			<dataPoints>
				<positions axis="2Theta" unit="deg">
					<startPosition>10.02173288</startPosition>
					<endPosition>139.98435528</endPosition>
				</positions>
				<positions axis="Omega" unit="deg">
					<startPosition>5.01086644</startPosition>
					<endPosition>69.99217764</endPosition>
				</positions>
				<commonCountingTime unit="seconds">1.551</commonCountingTime>
				<counts unit="counts">405 416 407 379 336 380 413 382 402 379 344 399 393 343 374 333 361 355 336 341 342 331 331 382 342 347 351 343 349 410 367 332 333 358 352 329 330 328 341 371 293 358 318 326 320 310 329 300 297 304 281 308 275 310 294 296 297 300 289 302 295 297 272 263 287 289 299 303 284 300 260 286 332 308 283 286 239 254 263 270 238 259 262 287 271 286 241 241 239 257 266 268 191 248 242 272 248 255 232 227 263 208 246 248 228 227 232 242 234 219 229 213 231 231 247 230 219 215 228 227 232 208 210 220 225 217 231 214 207 211 213 205 228 238 210 235 227 249 223 235 261 228 215 185 220 226 217 189 198 199 189 190 220 176 192 196 209 186 205 205 236 184 198 198 162 199 203 200 219 247 272 328 356 293 272 249 199 220 195 184 182 169 169 195 160 200 190 187 203 155 191 216 180 183 169 153 188 190 164 168 159 179 193 161 191 183 187 167 181 186 155 177 172 175 161 181 154 178 169 160 180 156 160 156 179 158 156 156 162 167 151 170 156 146 180 143 149 167 165 145 154 157 164 175 147 153 165 173 175 161 155 165 172 217 242 271 261 220 189 163 156 163 149 134 148 154 174 164 124 159 136 140 134 138 133 136 121 186 158 125 143 124 134 152 156 135 152 144 149 149 161 156 146 142 183 152 162 134 158 143 143 140 132 135 166 134 179 164 157 186 229 299 278 249 199 176 216 190 243 333 375 416 342 298 223 190 209 218 259 285 341 333 243 198 218 156 160 160 176 149 149 179 114 155 172 171 134 159 187 158 168 190 170 194 256 274 235 205 169 144 153 150 172 162 143 150 143 144 174 173 183 148 136 154 154 128 194 145 148 126 141 160 173 154 165 174 196 151 182 201 184 215 199 212 244 244 254 298 302 412 497 704 1114 1982 3405 5428 5079 3538 1769 1008 797 860 1138 1382 1760 1634 1215 860 605 435 334 326 265 240 210 222 203 201 211 184 190 215 211 200 161 157 153 180 150 171 189 202 190 174 255 311 395 379 294 288 202 183 188 176 191 221 221 263 303 274 192 204 183 181 168 230 260 317 602 784 585 534 352 383 290 255 212 205 184 208 228 221 267 280 390 462 630 936 1215 1495 1566 1647 1235 895 579 360 254 232 212 207 185 178 175 172 189 197 203 238 312 423 695 1161 1509 1220 869 514 301 196 217 201 157 139 163 125 131 136 108 133 141 134 123 148 128 141 139 136 125 135 133 121 156 125 122 148 180 211 246 361 432 483 462 438 369 318 392 463 457 399 307 197 207 161 132 132 134 115 149 141 149 146 172 185 181 233 342 457 523 567 498 376 261 211 199 196 185 223 176 209 225 224 197 196 143 137 135 122 105 136 118 118 111 114 110 112 105 94 102 104 88 126 138 201 304 203 168 144 112 102 96 98 97 101 126 109 114 98 130 116 131 111 131 113 105 112 111 106 102 120 133 110 123 115 124 101 114 123 142 156 197 208 222 241 197 162 120 132 89 117 122 102 107 108 114 97 101 118 89 99 86 115 98 91 110 115 82 109 89 86 138 109 89 111 116 125 135 141 145 118 149 143 103 119 98 138 145 150 219 253 291 296 258 247 205 152 207 194 236 254 221 189 173 166 169 154 164 135 144 104 113 102 108 118 130 131 110 120 114 107 123 92 93 88 84 97 107 104 82 103 86 84 104 83 109 110 95 105 87 142 125 147 157 168 147 195 231 177 144 135 111 106 78 94 69 107 101 99 105 85 88 82 65 112 95 107 107 84 62 84 86 107 110 95 81 105 113 104 94 121 118 137 153 164 235 212 148 199 164 134 147 128 121 126 129 144 152 165 172 212 203 204 197 157 229 262 350 673 1187 1209 826 834 624 345 221 204 163 176 167 158 172 205 300 532 641 498 400 404 237 183 111 120 102 118 97 87 109 89 120 83 97 91 97 88 84 88 108 82 114 96 128 108 108 115 108 107 102 108 161 137 118 130 158 151 136 127 132 126 103 109 103 113 119 107 111 134 125 151 137 151 185 218 226 330 336 265 272 272 186 142 147 124 141 144 145 111 145 117 119 161 150 241 323 390 408 357 305 277 233 141 188 163 246 247 235 237 228 178 142 148 160 209 202 165 187 151 165 185 146 166 180 124 125 95 95 82 88 98 121 87 76 87 100 88 98 102 95 82 92 77 81 103 81 81 107 99 93 85 98 114 87 87 100 86 95 83 89 91 88 103 96 95 101 103 96 119 129 104 131 129 130 121 116 122 143 132 186 226 382 620 801 578 528 586 448 344 309 279 205 217 162 161 174 155 168 192 200 145 191 192 173 178 185 227 321 505 892 1220 878 756 891 817 542 425 388 340 293 272 240 214 189 193 191 196 219 229 165 197 199 168 129 134 118 108 122 116 112 105 87 126 116 128 118 131 115 111 106 108 106 131 143 133 185 232 243 244 323 450 566 395 315 315 330 195 168 139 141 157 162 170 162 159 157 141 137 160 133 150 167 173 155 163 133 109 112 115 101 129 146 137 111 117 122 96 75 102 100 88 88 94 117 145 95 110 109 107 99 93 99 98 142 166 192 218 175 186 212 232 182 169 152 147 161 124 121 90 102 107 73 81 82 97 78 75 83 79 94 103 91 60 82 92 91 93 108 119 133 166 157 163 167 119 146 148 151 155 155 186 148 131 181 181 176 159 129 118 140 117 111 116 117 83 117 107 100 90 120 121 140 144 140 164 163 163 179 155 149 135 116 101 91 101 90 90 86 85 109 88 91 89 121 122 118 99 103 91 94 111 114 113 129 125 135 134 153 137 100 111 98 101 111 128 118 117 83 97 109 71 90 87 76 84 99 78 97 111 111 107 107 111 137 130 159 140 161 220 205 185 188 198 184 220 234 150 120 132 151 112 103 85 70 76 99 96 111 112 77 70 91 85 94 77 69 83 52 86 90 85 71 69 78 88 74 73 70 82 63 81 70 86 72 74 82 73 98 75 79 96 118 182 157 106 119 119 141 118 107 80 70 76 97 77 74 87 124 111 121 94 108 135 150 119 123 107 129 118 88 84 88 75 103 73 80 80 88 83 72 68 72 74 81 73 72 70 84 75 74 71 73 77 103 89 113 82 108 88 91 101 94 97 71 90 73 80 89 101 108 100 146 135 122 131 141 155 126 97 107 90 80 103 95 70 75 87 74 79 84 120 107 104 104 112 125 119 121 109 103 99 94 67 104 84 85 103 98 110 93 101 107 105 100 78 88 85 88 75 77 85 74 91 103 94 83 112 82 95 98 66 102 105 109 104 140 209 337 437 284 184 237 280 262 191 144 119 110 117 100 99 107 122 125 109 113 126 105 123 181 242 236 206 173 194 202 231 195 183 209 229 271 171 149 137 175 173 128 115 118 90 92 94 107 107 94 91 126 125 97 100 103 131 116 118 88 125 117 99 109 118 109 139 131 196 238 176 136 157 198 144 152 126 116 128 194 234 179 200 128 156 147 145 114 111 122 98 88 117 83 88 96 73 92 108 69 70 81 92 70 105 98 86 76 80 86 92 105 102 115 113 89 94 99 88 99 107 72 71 85 71 102 73 73 68 74 84 82 81 105 98 70 66 85 105 96 88 88 82 65 77 72 85 90 84 71 63 73 84 95 83 86 79 81 103 76 89 88 71 101 88 84 108 114 103 93 85 98 111 104 94 106 100 71 77 83 74 79 89 88 88 54 83 75 89 79 75 83 87 99 102 88 99 109 132 139 127 95 101 143 110 123 100 94 113 133 122 130 100 145 121 110 101 108 91 92 97 86 95 84 112 114 121 100 106 101 118 128 121 81 101 122 106 111 132 117 143 166 176 143 142 120 145 144 138 134 124 104 107 89 97 109 109 104 113 90 97 74 86 71 98 107 106 94 86 92 84 114 118 171 200 268 236 150 120 171 151 163 152 106 124 64 101 94 81 81 71 76 74 91 86 82 77 91 83 68 103 73 105 74 65 101 108 103 104 114 114 97 105 91 83 75 93 99 69 92 91 89 83 96 93 107 112 113 101 96 93 105 100 112 121 86 110 98 93 95 114 92 79 73 83 94 79 82 83 85 86 94 78 93 97 95 104 100 93 108 96 128 140 123 117 106 107 121 117 151 170 146 127 108 117 113 110 120 117 93 94 82 76 82 77 80 75 79 75 70 77 82 84 105 92 96 109 92 85 84 90 105 106 98 82 97 83 83 104 82 84 96 108 113 142 130 106 82 94 100 107 124 116 96 83 68 76 85 84 75 69 74 105 98 99 145 196 226 171 138 121 92 141 135 139 149 127 92 101 80 94 93 97 97 82 81 103 78 87 101 78 82 79 110 89 100 94 95 74 66 99 94 74 91 110 104 98 80 109 114 98 98 105 98 106 94 75 91 101 87 75 67 76 80 69 76 85 77 105 105 82 96 108 97 110 87 98 89 110 96 111 113 114 95 108 122 98 96 106 98 93 107 104 121 111 110 99 87 80 100 92 106 108 77 78 68 70 82 86 104 88 79 91 123 87 94 108 89 94 91 98 77 86 109 91 85 106 90 116 84 97 93 86 105 99 90 94 100 90 114 78 106 91 90 109 98 121 123 111 108 115 99 83 114 108 91 102 99 92 87 89 93 77 81 81 100 85 84 76 95 108 93 76 82 66 103 89 104 77 93 96 78 75 80 93 75 83 90 89 78 136 93 92 99 86 110 91 110 94 82 91 85 86 79 78 92 84 77 97 82 69 80 71 79 82 83 103 84 82 88 85 124 124 143 129 111 114 71 92 89 92 113 99 63 78 77 79 84 79 82 90 98 71 77 56 93 69 67 85 81 98 90 54 83 74 60 73 68 79 85 80 67 61 78 65 71 78 85 97 89 89 74 70 75 79 87 86 92 80 73 89 78 78 75 79 85 77 95 80 79 83 90 75 95 113 93 91 90 74 81 86 77 74 85 82 96 94 80 73 97 90 85 77 80 104 79 90 75 73 95 93 102 81 75 83 84 64 96 94 107 86 74 86 83 79 87 106 99 89 82 86 80 111 113 103 130 138 103 98 101 91 113 105 118 151 192 202 211 165 122 127 109 114 130 137 175 145 145 116 113 91 110 92 100 92 94 104 126 92 134 107 90 89 93 95 95 99 115 104 109 128 122 120 117 102 105 120 129 113 114 140 139 175 161 192 178 129 122 124 128 138 142 155 122 132 119 110 101 103 100 128 117 115 131 112 103 155 176 152 150 141 128 101 142 125 147 178 217 214 172 169 135 155 148 120 149 117 133 150 117 125 115 104 88 96 84 105 113 113 85 95 95 82 90 92 86 81 80 101 100 101 94 89 101 128 123 113 119 77 110 100 79 108 101 102 97 105 107 95 82 90 97 92 101 100 103 93 74 99 74 108 99 101 100 114 83 96 83 100 85 85 93 106 96 123 91 109 99 91 86 74 80 69 112 91 107 79 70 84 80 77 79 88 74 79 93 82 78 76 92 92 87 93 91 84 114 91 103 91 77 93 90 86 87 79 84 85 85 81 85 82 82 81 72 75 65 95 94 73 99 96 112 92 87 92 83 103 98 107 101 107 86 111 115 87 97 92 86 89 92 95 87 81 88 70 99 85 91 117 85 105 92 97 97 128 116 115 112 103 80 102 96 88 92 85 97 90 94 115 89 99 101 84 88 100 93 85 93 99 89 110 81 116 121 104 99 126 118 107 113 123 91 98 103 115 98 104 101 107 94 88 64 123 87 93 79 84 79 62 81 81 86 80 99 100 94 73 69 69 99 86 89 81 71 92 89 88 77 91 99 87 91 91 99 98 100 75 94 93 94 102 76 100 72 72 85 78 75 73 54 91 61 106 96 89 75 85 122 105 107 113 130 101 101 80 93 96 86 102 93 97 108 113 123 86 127 107 119 107 94 93 83 110 112 110 111 124 100 95 96 115 129 103 121 108 83 101 102 90 95 86 96 93 85 115 95 97 108 107 109 82 119 86 85 90 115 83 94 93 88 105 97 97 92 93 98 89 84 84 95 82 107 90 126 125 98 85 79 91 103 98 95 87 86 74 92 83 91 86 103 77 92 93 93 100 119 101 87 103 84 90 82 98 112 88 91 88 117 112 97 101 102 107 97 87 99 90 111 140 131 128 135 88 101 96 95 99 94 99 91 91 84 118 113 121 113 110 85 94 105 92 78 104 90 93 107 115 137 135 99 121 124 116 125 125 116 119 104 112 117 130 132 119 128 76 131 109 130 117 119 108 116 121 122 111 108 120 169 154 159 161 141 151 114 145 122 117 108 98 107 95 89 109 115 125 113 143 124 97 106 90 116 108 94 90 101 94 88 84 79 114 104 102 78 99 104 118 113 103 120 122 101 105 94 110 107 82 84 109 94 99 121 108 95 96 112 108 86 97 89 85 110 120 105 95 98 112 115 117 98 80 124 115 97 96 102 103 99 101 84 103 86 103 111 92 110 99 104 128 142 133 135 155 144 138 130 111 119 102 81 105 110 97 114 97 112 115 119 127 108 109 113 96 105 109 93 110 116 109 117 77 110 85 108 80 111 92 117 94 94 91 106 106 80 97 101 100 79 89 88 86 101 82 100 88 106 103 92 72 88 71 107 85 95 105 90 80 99 82 112 131 104 98 114 107 109 115 114 92 113 127 91 104 84 89 102 109 111 98 102 99 87 91 100 120 132 109 105 111 119 107 131 99 93 114 105 83 104 107 88 112 95 107 104 93 134 95 94 115 90 105 112 114 126 108 124 109 97 107 75</counts>
			</dataPoints>
		</scan>
	</xrdMeasurement>
</xrdMeasurements>