File: dataset/precursor_mixture/HfO2_La(OH)3_Y2O3.12-min.xrdml
<?xml version="1.0"?>
<xrdMeasurements xmlns="http://www.xrdml.com/XRDMeasurement/2.2" xmlns:xsi="http://www.w3.org/2001/XMLSchema-instance" xsi:schemaLocation="http://www.xrdml.com/XRDMeasurement/2.2 http://www.xrdml.com/XRDMeasurement/2.2/XRDMeasurement.xsd" status="Completed" recordIdentifier="{30BBB814-93DC-4405-84E0-E7C9A40ABAC6}">
	<comment>
		<entry/>
	</comment>
	<sample type="To be analyzed">
		<id></id>
		<name></name>
		<preparedBy></preparedBy>
	</sample>
	<xrdMeasurement measurementType="Scan" status="Completed" sampleMode="Reflection">
		<usedWavelength intended="K-Alpha 1">
			<kAlpha1 unit="Angstrom">1.5405980</kAlpha1>
			<kAlpha2 unit="Angstrom">1.5444260</kAlpha2>
			<kBeta unit="Angstrom">1.3922500</kBeta>
			<ratioKAlpha2KAlpha1>0.5000</ratioKAlpha2KAlpha1>
		</usedWavelength>
		<incidentBeamPath>
			<radius unit="mm">145.00</radius>
			<xRayTube id="1010048" name="Empyrean Cu LFF HR (9430 033 7310x) DK437873">
				<tension unit="kV">40.0</tension>
				<current unit="mA">15.0</current>
				<anodeMaterial>Cu</anodeMaterial>
				<focus type="Line">
					<length unit="mm">12.0</length>
					<width unit="mm">0.4</width>
					<takeOffAngle unit="deg">6.0</takeOffAngle>
				</focus>
			</xRayTube>
			<filter id="20010004" name="Beta-filter Nickel">
				<material>Ni</material>
				<thickness unit="mm">0.020</thickness>
			</filter>
			<sollerSlit id="21010002" name="Soller slits 0.04 rad.">
				<opening unit="rad">0.0400</opening>
			</sollerSlit>
			<mask id="22031000" name="Fixed mask 13 mm">
				<width unit="mm">9.00</width>
			</mask>
			<divergenceSlit id="22120001" name="Divergence slit 1°" xsi:type="fixedDivergenceSlitType">
				<distanceToSample unit="mm">50.00</distanceToSample>
				<height unit="mm">1.52</height>
			</divergenceSlit>
		</incidentBeamPath>
		<beamKnife id="29030100" name="Beam knife low"/>
		<sampleMovement xsi:type="spinningSampleMovementType">
			<spinnerRevolutionTime unit="seconds">1.0</spinnerRevolutionTime>
		</sampleMovement>
		<diffractedBeamPath>
			<radius unit="mm">145.00</radius>
			<antiScatterSlit id="22090040" name="AS slit 9 mm" xsi:type="fixedAntiScatterSlitType">
				<height unit="mm">9.00</height>
			</antiScatterSlit>
			<sollerSlit id="21020003" name="Large Soller slits 0.04 rad.">
				<opening unit="rad">0.0400</opening>
			</sollerSlit>
			<filter id="20030001" name="Large beta-filter Nickel">
				<material>Ni</material>
				<thickness unit="mm">0.020</thickness>
			</filter>
			<detector id="7010019" name="PIXcel1D-Medipix3 detector" xsi:type="rtmsDetectorType">
				<phd unit="keV">
					<lowerLevel>4.0</lowerLevel>
					<upperLevel>11.3</upperLevel>
				</phd>
				<mode>Scanning</mode>
				<activeLength unit="deg">5.020</activeLength>
			</detector>
		</diffractedBeamPath>
		<scan appendNumber="0" mode="Continuous" scanAxis="Gonio" status="Completed">
			<header>
				<startTimeStamp>2024-03-22T21:04:32-07:00</startTimeStamp>
				<endTimeStamp>2024-03-22T21:17:00-07:00</endTimeStamp>
				<author>
					<name>Instrument</name>
				</author>
				<source>
					<applicationSoftware version="1.6 (94)">PANalytical Aeris Instrument Suite</applicationSoftware>
					<instrumentControlSoftware version="3.0.0 20211014">AERIS</instrumentControlSoftware>
					<instrumentID>2879380</instrumentID>
				</source>
			</header>
			<dataPoints>
				<positions axis="2Theta" unit="deg">
					<startPosition>9.99043322</startPosition>
					<endPosition>100.09495370</endPosition>
				</positions>
				<positions axis="Omega" unit="deg">
					<startPosition>4.99521661</startPosition>
					<endPosition>50.04747685</endPosition>
				</positions>
				<commonCountingTime unit="seconds">18.249</commonCountingTime>
				<counts unit="counts">4092 3989 4053 4097 4013 4029 4090 3940 3932 3878 3968 4022 4083 3990 4011 3953 4014 3981 3911 3924 3870 3956 3826 3875 3864 3937 3897 3926 3812 3853 4008 3891 3861 3833 3826 3942 3867 3818 3981 3906 3818 3824 3870 3796 3862 3849 3681 3907 3805 3877 3860 3780 3887 3815 3678 3804 3777 3843 3733 3799 3600 3770 3698 3661 3743 3767 3821 3688 3637 3735 3706 3734 3655 3599 3632 3674 3670 3648 3604 3650 3640 3704 3726 3658 3712 3722 3473 3626 3636 3565 3588 3635 3542 3577 3612 3529 3583 3701 3678 3586 3508 3564 3473 3624 3559 3592 3479 3671 3539 3498 3482 3521 3477 3455 3490 3520 3484 3526 3562 3453 3496 3544 3470 3468 3390 3428 3482 3535 3418 3439 3469 3397 3441 3340 3567 3474 3452 3424 3332 3460 3430 3372 3430 3358 3470 3434 3303 3369 3297 3432 3431 3337 3360 3430 3367 3422 3332 3402 3366 3274 3357 3264 3441 3361 3317 3362 3301 3270 3328 3404 3336 3309 3331 3219 3424 3383 3257 3318 3285 3289 3212 3173 3242 3211 3300 3333 3213 3249 3304 3268 3180 3238 3280 3231 3291 3216 3268 3146 3313 3191 3239 3186 3202 3252 3179 3071 3145 3128 3152 3260 3185 3082 2984 3268 3185 3192 3207 3230 3087 3137 3164 3160 3207 3150 3162 3246 3176 3156 3104 3153 3149 3184 3066 3138 3106 3035 3051 3119 3117 3059 3122 3090 3107 3160 3133 3143 3132 3050 3151 3018 2972 2994 3097 3162 3048 3073 3003 3094 3068 3044 2998 3067 3011 3009 2943 3043 3015 2966 3027 3089 2989 3079 2986 3004 3031 3008 3037 2986 2988 2923 3069 2959 3044 2993 3034 2886 2975 3009 2940 2959 2946 2926 2975 2882 2978 2879 2967 2926 2952 2973 2844 2962 2972 3065 2863 2901 2829 2849 3047 2962 2949 2969 2944 2886 2932 2904 2956 2936 2868 2933 2892 2952 2836 3109 2884 2872 2980 2867 2937 2962 2830 2796 2808 2897 2890 2900 2886 2855 3006 2788 2947 2956 2857 2841 2861 2836 2909 2839 2917 2794 2906 2905 2807 2765 2862 2823 2910 2830 2864 2877 2844 2809 2938 2848 2809 2808 2742 2892 2796 2910 2852 2842 2835 2782 2887 2808 2876 2850 2751 2763 2806 2960 2767 2759 2780 2820 2799 2784 2854 2774 2723 2834 2734 2826 2712 2755 2710 2801 2659 2786 2788 2876 2742 2795 2711 2765 2684 2733 2757 2683 2793 2716 2746 2814 2778 2837 2772 2623 2780 2698 2715 2746 2779 2690 2768 2861 2734 2808 2708 2755 2744 2740 2708 2739 2837 2729 2811 2684 2685 2702 2713 2751 2795 2790 2763 2822 2841 2813 2747 2672 2771 2691 2715 2870 2783 2779 2846 2799 2832 2794 2783 2880 2800 2891 2864 2845 2886 2936 2941 2913 2923 2913 2901 2859 2987 3022 2971 3033 3107 3096 3138 3203 3147 3305 3340 3302 3401 3388 3467 3518 3549 3622 3789 3809 3936 4026 4031 4334 4401 4479 4464 4769 4766 5169 5190 5567 5838 6097 6298 6624 6808 7079 7301 7723 8130 8461 8809 8847 9238 9527 9773 9916 9573 10024 9774 9580 9410 9189 8703 8463 7847 7535 7016 6364 6002 5588 5418 5014 4784 4463 4373 4126 4025 3830 3686 3574 3711 3466 3578 3263 3226 3334 3187 3161 3066 3072 3068 2989 2934 2991 2985 2934 2923 2874 2835 2810 2852 2873 2807 2869 2830 2739 2690 2783 2669 2732 2770 2709 2708 2713 2785 2749 2628 2733 2651 2751 2771 2626 2634 2694 2607 2631 2654 2728 2650 2713 2687 2670 2600 2454 2587 2645 2727 2625 2569 2599 2602 2583 2691 2576 2618 2545 2560 2645 2597 2616 2626 2507 2602 2619 2601 2704 2571 2502 2557 2618 2599 2588 2614 2579 2620 2490 2423 2551 2560 2570 2507 2537 2551 2463 2470 2518 2493 2573 2545 2486 2578 2478 2491 2485 2466 2558 2502 2492 2614 2582 2609 2469 2706 2499 2425 2533 2542 2496 2550 2551 2514 2505 2477 2533 2661 2542 2589 2473 2530 2579 2586 2573 2657 2669 2517 2571 2602 2767 2820 2756 2778 2778 2931 2828 2878 3126 2948 2981 3011 3049 3068 3148 3249 3207 3154 3107 3079 3034 2971 2903 2746 2789 2635 2665 2569 2657 2565 2461 2558 2516 2596 2498 2514 2457 2413 2426 2464 2490 2488 2426 2423 2459 2335 2348 2466 2417 2420 2311 2380 2483 2446 2427 2401 2317 2389 2407 2359 2410 2416 2284 2443 2378 2288 2429 2396 2260 2395 2451 2336 2339 2341 2294 2328 2336 2370 2290 2347 2320 2318 2265 2375 2409 2360 2336 2243 2283 2297 2297 2322 2283 2376 2386 2368 2375 2408 2364 2254 2368 2352 2350 2362 2360 2402 2371 2314 2319 2280 2265 2301 2372 2286 2298 2237 2398 2264 2317 2306 2250 2325 2311 2335 2360 2280 2274 2304 2218 2353 2236 2332 2290 2230 2228 2270 2218 2194 2227 2237 2227 2236 2244 2217 2220 2247 2314 2237 2281 2292 2288 2375 2291 2250 2216 2315 2244 2286 2266 2149 2255 2275 2216 2280 2301 2320 2308 2291 2281 2221 2262 2253 2208 2183 2224 2345 2308 2209 2225 2195 2231 2223 2174 2148 2170 2228 2201 2208 2134 2230 2165 2199 2166 2183 2204 2120 2233 2177 2195 2236 2164 2140 2240 2163 2210 2206 2175 2216 2150 2173 2248 2194 2097 2140 2154 2098 2176 2180 2291 2098 2298 2248 2238 2219 2189 2149 2165 2207 2136 2244 2188 2128 2181 2161 2217 2238 2221 2256 2217 2087 2222 2192 2228 2205 2277 2189 2104 2279 2239 2196 2243 2268 2172 2254 2258 2259 2357 2267 2230 2297 2323 2441 2355 2490 2352 2409 2580 2536 2495 2647 2697 2757 2802 2927 2959 3179 3230 3351 3475 3511 3646 3904 3907 4157 4324 4444 4547 4412 4526 4355 4379 4124 3877 3773 3550 3321 3038 3032 2845 2658 2648 2530 2420 2382 2364 2327 2348 2185 2315 2157 2212 2147 2229 2179 2136 2104 2153 2029 2114 2099 2125 2008 2058 2103 2226 2102 2113 2094 2098 2123 2103 2105 2023 2089 2048 2098 2027 2070 2055 1980 2001 2097 2047 2121 1988 1970 2123 2032 2082 2069 2055 1993 2083 2127 1950 2004 2000 2000 2001 2029 1958 2047 1982 2080 2110 1966 2125 2009 2048 1958 1935 1979 2025 1968 2046 2026 2025 2033 2053 1999 2083 2086 2055 2013 1967 2021 1940 1941 2051 1994 2120 2008 1976 1953 1878 2054 1908 1997 1961 1975 2087 1989 2021 1979 1933 2015 1995 2012 1987 1972 1995 1952 2022 1988 1999 1974 1882 1964 1911 1988 1846 2039 2039 2003 1921 2014 1941 1959 1956 1959 1913 1947 1952 1972 1937 1959 1954 1907 1901 1924 2007 1908 1966 1855 1960 1875 1928 1935 1943 1957 1877 2002 1961 1983 1970 1949 1952 1918 1998 1884 1969 1982 1953 1923 1946 1996 1899 1952 1876 1900 1998 2034 1985 1955 1865 1924 1931 1982 1925 1933 1847 1970 1836 1953 1925 1949 1954 1902 1856 1889 1910 1954 1792 1944 1891 1835 1875 1922 1969 1951 1867 1891 1843 1914 1943 1944 1918 2008 1937 1915 1837 1963 1927 1836 1960 1950 1888 1960 1873 1846 1857 2007 1879 1914 1976 1874 1900 1847 1854 1809 1932 1926 1922 1827 1902 1822 1800 1948 1942 1878 1869 1894 1841 1889 1926 1797 1919 1921 2002 1954 1881 1958 1900 1925 1971 1835 1928 1945 1968 1847 1911 1916 1867 1879 1880 1951 1921 1877 1927 1883 1916 1836 1880 1862 1883 1889 2018 1864 1863 1880 1882 1856 1911 1919 1836 1909 1923 2054 1983 1901 1968 2006 1971 1964 2007 1985 1998 2051 1960 2059 2056 2095 2072 2065 1990 2109 2111 2235 2273 2330 2359 2441 2516 2642 2726 2749 2804 2923 3009 3213 3334 3514 3694 3780 4061 4121 4123 4157 4098 4033 3994 3915 3766 3625 3454 3259 3065 2963 2889 2792 2692 2512 2406 2362 2498 2366 2424 2373 2457 2453 2505 2553 2605 2617 2724 2782 3007 2949 3070 3217 3327 3433 3627 3731 3746 3676 3681 3733 3564 3486 3280 3120 3003 2819 2692 2560 2513 2311 2278 2117 2097 2147 2045 1984 2094 2006 1987 1920 2086 1908 1816 1968 1946 1924 2009 1905 1913 1808 1835 1926 1842 1832 1888 1899 1871 1901 1839 1843 1806 1785 1838 1893 1889 1854 1872 1793 1845 1905 1805 1834 1835 1853 1878 1839 1837 1867 1840 1819 1843 1847 1756 1857 1849 1741 1838 1745 1799 1833 1681 1842 1791 1921 1872 1813 1864 1775 1859 1822 1829 1845 1785 1864 1808 1838 1890 1845 1876 1783 1848 1798 1811 1841 1787 1826 1807 1814 1817 1827 1842 1889 1795 1747 1745 1866 1721 1813 1798 1781 1725 1863 1794 1811 1877 1779 1734 1796 1895 1800 1790 1743 1814 1744 1766 1794 1758 1845 1798 1746 1748 1865 1856 1862 1856 1788 1820 1788 1883 1804 1751 1875 1807 1817 1840 1813 1847 1901 1909 1843 1871 1861 1946 1790 1896 1856 1856 1849 1834 1867 1901 1941 1822 1960 1873 1865 1849 1855 1880 1884 1941 1853 1812 1828 1925 1936 1854 1867 1889 1806 1998 1894 1915 1878 1937 1919 1885 1932 1966 2038 1959 1963 1974 2047 1992 2045 2001 1982 2061 2181 2081 2224 2121 2228 2147 2208 2279 2327 2397 2442 2482 2504 2515 2553 2639 2720 2817 2907 2850 3106 3161 3387 3452 3675 3737 3833 4175 4332 4597 4800 5032 5500 5636 5939 6213 6524 6857 7097 7389 7680 7788 7767 7992 8143 7887 7780 7427 7491 7078 6867 6635 6223 5944 5687 5404 5060 4823 4474 4341 4180 4029 3877 3764 3610 3474 3575 3445 3297 3317 3225 3320 3267 3343 3266 3288 3382 3171 3395 3300 3486 3540 3611 3547 3810 3948 4154 4394 4452 4673 5059 4996 5424 5839 6185 6414 6787 7177 7541 8000 8543 8962 9524 9758 10116 10618 10924 10925 11039 11254 10797 10729 10621 10272 9906 9578 9225 8792 8693 8444 8038 7943 7769 7680 7537 7663 7687 7924 8202 8700 9056 9485 10026 10742 11185 12044 13054 13388 14089 15028 15448 15991 16010 16107 15613 15420 15080 13958 13188 12363 11573 10637 9706 8969 8014 7380 6818 6229 5799 5272 5053 4711 4595 4281 4244 4083 3850 3658 3725 3479 3431 3478 3363 3268 3382 3303 3265 3329 3221 3228 3202 3130 3236 3190 3174 3206 3219 3339 3401 3473 3558 3686 3734 3839 4103 4341 4565 4872 5239 5591 6239 6708 7302 8159 8961 10058 11053 12224 13864 15426 17169 18832 20336 21947 23366 24788 24926 25066 24585 23378 22007 20435 18964 16955 15598 13820 12188 10791 9137 7835 6950 5994 5345 4829 4462 4072 3847 3661 3552 3425 3355 3154 2906 3007 2850 2836 2854 2725 2635 2524 2490 2418 2445 2386 2386 2264 2256 2248 2220 2060 2148 2083 2164 2093 2143 2001 2004 1939 2046 1989 1978 1969 2031 1950 2045 1933 1901 2002 1932 1871 1845 1871 1935 1925 1916 1893 1926 1840 1866 1880 1829 1928 1954 1867 1864 1823 1852 1834 1932 1820 1862 1827 1789 1842 1757 1791 1830 1793 1816 1879 1784 1798 1840 1765 1803 1839 1774 1802 1786 1739 1767 1846 1749 1756 1794 1749 1726 1766 1833 1854 1694 1807 1810 1841 1827 1833 1773 1830 1763 1830 1813 1850 1822 1791 1849 1793 1809 1863 1827 1870 1803 1795 1794 1768 1867 1839 1879 1861 1802 1800 1831 1868 1838 1792 1828 1839 1870 1821 1856 1855 1959 1877 1898 1956 1799 1964 1913 1864 1921 1883 1863 1898 1819 1842 1964 1950 2057 1966 1970 2012 1955 1984 2080 2006 2166 2055 2079 2101 2189 2203 2094 2203 2157 2233 2244 2291 2299 2297 2390 2354 2358 2488 2541 2660 2628 2777 2692 2752 2916 2952 3059 3317 3331 3342 3619 3780 4004 4173 4505 4663 5176 5409 5876 6149 6795 6957 7695 8084 8833 9465 10142 10650 11469 11835 12252 12712 12998 13236 12979 12632 12309 11815 11451 10825 10070 9537 8519 7912 7378 6820 6154 5757 5216 4796 4441 4157 3821 3554 3456 3402 3212 2981 2854 2761 2767 2711 2596 2505 2489 2401 2376 2371 2251 2317 2137 2041 2143 2126 2082 2085 2090 2008 1916 1972 1926 1877 1845 1879 1929 1768 1750 1862 1779 1831 1822 1864 1773 1795 1702 1703 1747 1786 1706 1743 1798 1635 1698 1585 1713 1644 1684 1623 1752 1624 1586 1561 1609 1645 1687 1596 1659 1592 1631 1693 1616 1600 1705 1606 1639 1594 1680 1601 1580 1546 1552 1623 1585 1626 1642 1630 1663 1609 1649 1609 1587 1581 1530 1572 1587 1588 1581 1574 1574 1503 1527 1665 1497 1592 1537 1635 1623 1590 1595 1583 1597 1607 1636 1624 1548 1643 1616 1590 1542 1570 1596 1565 1523 1594 1595 1569 1552 1666 1573 1532 1589 1612 1617 1575 1666 1600 1708 1672 1647 1716 1673 1785 1675 1679 1692 1721 1755 1747 1750 1838 1759 1754 1873 1810 1864 1899 1990 1986 2031 2092 2116 2275 2334 2340 2486 2739 2805 3026 3205 3513 3748 4243 4564 5093 5483 5874 6131 6574 6510 6790 6486 6556 6081 5680 5324 5196 4820 4813 4440 4117 3697 3421 3046 2844 2706 2549 2398 2360 2226 2209 2141 2190 2119 2144 2067 2187 2181 2136 2234 2261 2288 2379 2432 2531 2671 2688 2792 2965 3098 3324 3605 3752 3901 4161 4380 4610 4760 4846 5026 5138 5169 5207 5060 5059 4880 4804 4684 4362 4300 4116 4002 3869 3828 3802 3759 3561 3607 3747 3793 3967 4133 4299 4408 4550 4696 4649 4712 4539 4620 4359 4370 4178 4002 3841 3684 3366 3274 3071 2885 2713 2536 2435 2362 2179 2193 2142 1936 1974 1982 1834 1836 1801 1803 1806 1717 1743 1684 1765 1629 1696 1787 1708 1620 1658 1591 1751 1707 1624 1685 1611 1667 1603 1709 1675 1710 1687 1766 1692 1656 1659 1752 1665 1767 1776 1850 1770 1882 1854 1894 2004 1998 2076 2119 2212 2342 2393 2556 2749 2756 3097 3258 3432 3860 4062 4249 4456 4757 4829 5038 4949 4932 4980 4828 4594 4475 4106 3884 3756 3580 3249 3078 2988 2854 2607 2535 2367 2311 2257 2293 2151 2182 2246 2282 2344 2277 2437 2511 2522 2670 2711 2840 3183 3152 3239 3367 3268 3231 3218 3086 3189 3213 3245 3204 3222 3190 3114 3120 3060 3127 3013 3088 2950 2858 2833 2665 2752 2558 2562 2345 2317 2236 2153 2126 2009 1985 1900 1907 1763 1744 1680 1637 1656 1646 1581 1556 1490 1540 1543 1498 1555 1481 1512 1487 1558 1438 1401 1460 1550 1409 1423 1429 1460 1458 1454 1408 1409 1389 1357 1351 1349 1399 1409 1415 1424 1377 1384 1377 1313 1397 1302 1405 1360 1402 1376 1418 1356 1335 1315 1358 1331 1320 1343 1393 1346 1384 1358 1407 1391 1392 1372 1375 1311 1354 1335 1316 1319 1379 1345 1357 1411 1320 1336 1373 1360 1373 1359 1390 1327 1314 1386 1365 1412 1439 1349 1410 1328 1379 1283 1361 1294 1303 1383 1381 1341 1255 1319 1376 1353 1316 1285 1381 1347 1349 1364 1318 1336 1333 1320 1356 1402 1339 1334 1343 1357 1384 1358 1335 1387 1329 1391 1310 1346 1342 1409 1258 1399 1327 1367 1274 1416 1323 1345 1313 1349 1418 1337 1396 1402 1343 1461 1431 1498 1475 1507 1481 1521 1585 1536 1615 1575 1556 1552 1579 1552 1548 1462 1547 1491 1486 1549 1450 1436 1404 1428 1481 1374 1418 1392 1371 1395 1375 1400 1347 1356 1363 1388 1352 1373 1384 1411 1306 1432 1317 1362 1386 1323 1455 1362 1426 1424 1387 1426 1421 1440 1353 1394 1381 1510 1420 1496 1520 1435 1467 1464 1503 1407 1434 1476 1569 1563 1527 1609 1563 1694 1669 1770 1735 1754 1814 1941 1980 2052 2165 2188 2277 2355 2470 2492 2559 2648 2734 2712 2728 2658 2596 2541 2546 2377 2416 2395 2269 2245 2193 2118 2105 1992 2012 1995 2003 1894 1910 1946 1855 2078 2080 2111 1992 1999 2050 2108 2096 2197 2240 2251 2246 2330 2349 2514 2649 2663 2822 2843 3050 3097 3177 3562 3582 3815 4140 4143 4424 4725 5058 5345 5477 5676 5950 6092 6375 6556 6607 6621 6700 6813 6772 6703 6522 6281 6026 5910 5699 5609 5308 5048 4842 4758 4520 4353 4090 3900 3701 3636 3490 3387 3269 3235 3142 3135 3150 3160 3121 3211 3224 3228 3318 3327 3251 3295 3246 3094 2999 2766 2759 2624 2539 2555 2451 2239 2243 2208 2035 2065 1919 1832 1807 1811 1771 1673 1644 1704 1638 1668 1665 1697 1620 1662 1567 1646 1557 1677 1622 1596 1548 1567 1552 1576 1436 1475 1576 1570 1506 1501 1464 1431 1498 1413 1462 1443 1491 1462 1502 1430 1391 1415 1408 1472 1415 1503 1474 1438 1457 1482 1443 1492 1420 1429 1413 1463 1467 1457 1441 1514 1564 1520 1521 1518 1558 1466 1618 1556 1680 1690 1755 1777 1825 1780 1907 1892 1946 2144 2091 2215 2316 2391 2467 2651 2612 2807 2890 2956 2948 3037 2982 2834 2834 2829 2746 2701 2625 2662 2608 2460 2481 2212 2218 2182 2141 1987 1931 1950 1923 1901 1838 1869 1814 1768 1827 1825 1770 1793 1762 1861 1828 1896 1960 1961 1945 1942 1985 2007 2012 1923 1933 1972 1943 1886 1948 1868 1859 1884 1870 1855 1888 1870 1852 1923 1848 1984 1961 1977 2035 2002 2052 2038 2042 2039 2034 1995 2088 1915 1938 1938 1866 1822 1800 1754 1694 1739 1734 1677 1565 1544 1536 1620 1563 1517 1568 1624 1633 1570 1617 1622 1650 1582 1600 1585 1688 1657 1713 1759 1766 1823 1815 1836 1913 1930 1985 2083 2006 2152 2220 2204 2209 2202 2201 2156 2266 2301 2200 2112 2098 2109 2077 2107 2073 2011 1987 1976 1890 1909 1759 1733 1749 1687 1685 1566 1597 1514 1616 1571 1448 1470 1432 1420 1490 1432 1540 1351 1355 1423 1367 1426 1363 1320 1353 1377 1355 1384 1359 1336 1272 1295 1304 1344 1270 1286 1287 1327 1359 1255 1276 1266 1294 1251 1274 1314 1268 1233 1219 1279 1257 1261 1320 1364 1315 1254 1225 1241 1268 1280 1245 1203 1294 1240 1387 1320 1307 1265 1290 1273 1336 1287 1260 1359 1352 1315 1351 1280 1282 1336 1378 1375 1423 1457 1417 1490 1504 1506 1609 1670 1638 1881 1830 2015 2141 2273 2466 2643 2827 2822 2835 2975 2955 2861 2835 2739 2512 2466 2375 2445 2381 2270 2209 2136 1953 1847 1753 1690 1554 1711 1634 1439 1476 1366 1420 1395 1289 1344 1344 1346 1315 1331 1298 1348 1260 1303 1275 1300 1231 1235 1221 1254 1279 1247 1196 1257 1232 1211 1206 1209 1258 1248 1305 1254 1142 1233 1219 1120 1226 1211 1274 1167 1235 1233 1197 1222 1162 1191 1194 1194 1160 1262 1200 1191 1210 1204 1206 1135 1241 1198 1223 1233 1249 1198 1207 1186 1199 1185 1206 1207 1193 1183 1169 1231 1157 1257 1224 1264 1238 1245 1211 1274 1228 1211 1240 1141 1199 1130 1219 1248 1265 1228 1234 1217 1226 1290 1244 1211 1262 1251 1235 1299 1282 1260 1275 1270 1360 1338 1209 1308 1321 1348 1327 1367 1421 1392 1512 1489 1517 1538 1527 1552 1655 1640 1667 1717 1702 1712 1792 1796 1774 1855 1815 1689 1717 1716 1676 1679 1604 1623 1588 1546 1570 1547 1513 1514 1439 1411 1406 1369 1349 1413 1348 1321 1353 1276 1272 1323 1378 1354 1374 1265 1327 1301 1335 1355 1311 1324 1337 1389 1314 1338 1363 1325 1471 1363 1497 1462 1580 1619 1611 1596 1708 1748 1692 1747 1812 1810 1852 1908 2025 1968 2052 1973 2106 2028 2009 1988 1877 1902 1849 1770 1741 1728 1702 1651 1724 1592 1567 1556 1516 1509 1460 1488 1392 1452 1419 1323 1423 1298 1308 1344 1301 1220 1303 1249 1226 1226 1223 1308 1247 1210 1243 1245 1243 1247 1230 1246 1217 1213 1276 1225 1278 1304 1164 1248 1242 1276 1191 1259 1188 1281 1158 1215 1241 1226 1271 1229 1304 1308 1275 1217 1299 1263 1244 1312 1174 1330 1367 1232 1281 1379 1274 1243 1338 1300 1345 1351 1391 1335 1367 1423 1456 1500 1514 1499 1661 1545 1751 1694 1845 1886 1887 1957 1991 2015 2023 2030 2096 2037 2073 2041 2046 2150 2155 2171 2210 2295 2276 2327 2388 2248 2274 2326 2271 2258 2185 2188 2082 2061 2132 2106 2059 1983 2003 1941 1898 1835 1870 1760 1850 1752 1708 1626 1577 1662 1526 1625 1501 1536 1487 1554 1435 1533 1428 1459 1467 1424 1387 1417 1385 1413 1472 1421 1362 1423 1461 1418 1435 1472 1396 1531 1430 1454 1480 1453 1497 1512 1470 1519 1543 1421 1522 1546 1552 1611 1535 1550 1556 1636 1709 1571 1596 1607 1675 1685 1826 1822 1891 1849 1916 1913 1931 2042 2091 2182 2195 2301 2289 2394 2417 2468 2655 2677 2746 2919 2965 3067 3166 3226 3448 3363 3536 3670 3705 3703 3840 3825 4061 3989 3838 3999 4105 4031 4157 4339 4262 4399 4450 4646 4680 4989 5278 5490 5980 6313 6845 7643 8151 9001 9860 10641 11757 12406 12891 13087 12948 12740 12179 11794 11380 11026 10857 10807 10925 11064 10884 10477 10007 9540 9046 8344 7785 7103 6787 6515 5928 5668 5315 5106 4766 4672 4428 4153 4044 3741 3698 3549 3410 3212 3121 3002 2865 2789 2703 2691 2613 2444 2396 2424 2270 2232 2216 2187 2146 2163 2076 2047 2076 1911 1944 1874 1941 1859 1923 1925 1955 1830 1821 1802 1882 1901 1918 1869 1920 1883 1811 1915 1835 1847 1828 1900 1950 2038 2017 2157 2104 2143 2312 2362 2503 2568 2711 2798 3151 3328 3515 3785 3792 3948 4048 3851 3911 3710 3553 3540 3431 3271 3330 3100 3239 3160 3120 3029 2952 2744 2664 2568 2394 2345 2266 2290 2140 2157 2220 2081 2092 2134 2069 2101 2067 2147 2159 2068 2172 2066 2165 2062 2171 2071 2107 2018 2090 2054 2174 2092 2186 2078 2127 2140 2205 2267 2350 2161 2148 2088 2048 2023 1966 2051 1964 2154 2067 2068 1957 2032 2132 2251 2241 2353 2279 2648 2757 2902 3097 3297 3703 3987 4041 4217 4400 4494 4524 4397 4292 4123 3927 3833 3689 3582 3454 3545 3399 3382 3238 3156 3105 2910 2728 2549 2445 2289 2238 2154 2107 2044 2050 2091 2032 2047 2052 2143 2229 2272 2414 2449 2596 2714 2660 2708 2802 2773 2762 2562 2596 2593 2469 2475 2386 2294 2339 2286 2195 2263 2109 2091 1885 1985 1823 1793 1725 1659 1613 1576 1519 1530 1517 1470 1429 1423 1422 1383 1379 1316 1437 1315 1369 1362 1393 1359 1400 1328 1351 1284 1359 1406 1489 1465 1503 1405 1467 1471 1563 1547 1573 1694 1732 1726 1745 1818 1737 1730 1750 1824 1774 1732 1709 1749 1786 1709 1713 1652 1640 1721 1651 1582 1661 1595 1510 1490 1435 1450 1337 1325 1356 1317 1298 1318 1266 1328 1282 1307 1325 1228 1199 1244 1186 1236 1193 1241 1196 1193 1211 1200 1169 1175 1160 1161 1163 1126 1179 1253 1192 1186 1183 1101 1205 1156 1190 1210 1166 1214 1237 1148 1131 1150 1183 1102 1166 1166 1223 1123 1181 1268 1129 1157 1162 1175 1188 1136 1123 1175 1145 1127 1148 1158 1191 1105 1126 1130 1168 1170 1142 1132 1172 1189 1179 1234 1139 1220 1213 1150 1242 1044 1093 1115 1178 1147 1218 1141 1132 1178 1176 1211 1187 1183 1203 1202 1211 1154 1133 1205 1127 1127 1181 1174 1225 1157 1218 1171 1149 1133 1267 1210 1230 1220 1161 1315 1272 1234 1296 1331 1289 1333 1327 1469 1466 1585 1632 1753 1774 1876 2015 1934 2174 2077 2087 2037 1976 1925 1827 1738 1727 1695 1625 1670 1776 1687 1780 1623 1675 1559 1535 1501 1396 1372 1344 1366 1277 1328 1263 1187 1217 1255 1244 1253 1202 1169 1232 1138 1146 1165 1140 1201 1186 1145 1178 1178 1201 1194 1136 1174 1134 1170 1192 1202 1174 1141 1198 1265 1139 1167 1167 1230 1213 1265 1194 1151 1155 1173 1229 1158 1258 1212 1130 1179 1246 1188 1280 1235 1243 1227 1159 1266 1210 1218 1257 1258 1254 1283 1337 1445 1354 1319 1419 1367 1423 1429 1482 1531 1517 1528 1578 1620 1664 1777 1784 1857 1910 1887 2057 2090 2096 2226 2370 2387 2448 2505 2500 2522 2662 2558 2659 2426 2421 2442 2393 2361 2306 2232 2153 2255 2159 2081 2137 2039 2039 1998 1916 1991 1917 1845 1850 1939 1814 1700 1636 1704 1655 1690 1550 1560 1574 1585 1603 1589 1541 1550 1540 1556 1551 1600 1528 1574 1554 1586 1573 1596 1578 1676 1659 1677 1716 1788 1723 1775 1781 1873 1787 1821 1877 1946 2031 2011 2078 2066 2208 2169 2201 2353 2333 2448 2504 2393 2542 2539 2535 2519 2496 2475 2327 2461 2455 2428 2407 2349 2284 2346 2254 2298 2319 2231 2207 2287 2224 2256 2276 2208 2334 2371 2370 2403 2418 2512 2487 2614 2687 2770 2807 2961 3054 3084 3052 3209 3145 3160 3249 3202 3195 3051 3063 3190 3017 2997 2913 2938 2913 3066 2911 2899 3009 2946 2989 2780 2837 2928 2786 2755 2683 2552 2478 2484 2408 2420 2355 2412 2453 2494 2543 2509 2564 2567 2674 2817 2889 2885 3033 3151 3180 3167 3185 3194 3382 3263 3292 3271 3386 3334 3451 3434 3324 3275 3208 3174 3019 3035 2997 2932 2923 2788 2645 2605 2511 2437 2337 2271 2215 2093 2073 1971 1948 1867 1763 1765 1713 1683 1597 1662 1619 1467 1564 1484 1561 1427 1480 1367 1387 1397 1366 1392 1328 1388 1379 1381 1313 1365 1231 1294 1347 1290 1334 1333 1318 1378 1312 1342 1234 1326 1271 1317 1342 1351 1298 1322 1261 1322 1344 1278 1304 1283 1372 1332 1316 1377 1311 1321 1363 1413 1386 1412 1453 1456 1432 1439 1430 1512 1532 1465 1519 1595 1517 1525 1615 1682 1649 1769 1808 1816 1866 1920 1959 2055 2152 2303 2430 2608 2673 2904 3030 3262 3559 3861 4091 4503 5033 5341 5801 6386 6709 7164 7291 7381 7137 6815 6436 5862 5582 5327 5001 5019 4847 4844 5030 5007 4981 5023 4821 4391 4211 3843 3618 3327 2961 2781 2677 2520 2350 2331 2164 2102 2009 1940 1937 1905 1890 1827 1847 1794 1730 1665 1676 1681 1610 1696 1647 1668 1659 1645 1632 1726 1716 1816 1811 1907 1990 1915 1970 2062 1984 2101 2094 1999 2170 2093 1963 1969 1945 1965 1875 1931 1875 2004 1830 1899 1901 1871 1839 1780 1847 1811 1836 1747 1725 1738 1763 1755 1791 1718 1837 1838 1948 1824 1937 1961 2036 2023 1988 2015 1934 1964 1900 1877 1972 1890 1944 1943 1831 1904 1879 1962 1887 1916 1827 1851 1847 1892 1817 1872 1827 1761 1866 1916 1911 1958 2008 2052 2221 2211 2421 2395 2434 2492 2437 2343 2337 2228 2118 2013 1883 1913 1942 1833 1843 1782 1912 1863 1831 1829 1721 1623 1605 1596 1558 1504 1481 1420 1308 1328 1261 1337 1256 1309 1226 1188 1251 1212 1208 1223 1212 1213 1261 1217 1233 1195 1129 1194 1188 1201 1203 1208 1221 1186 1213 1213 1145 1272 1190 1091 1160 1195 1144 1199 1182 1199 1259 1202 1133 1210 1214 1231 1198 1228 1242 1243 1127 1262 1247 1257 1248 1224 1241 1266 1226 1287 1339 1334 1245 1393 1402 1419 1397 1482 1477 1470 1547 1499 1617 1618 1692 1711 1853 1883 1984 2072 2120 2226 2275 2300 2329 2417 2271 2441 2268 2271 2324 2354 2305 2405 2537 2446 2492 2632 2652 2684 2806 2753 3000 2963 2938 3082 2976 2924 2915 2734 2669 2578 2388 2259 2290 2166 2164 2207 2328 2203 2100 2128 2076 2014 1962 1913 1830 1660 1716 1615 1601 1507 1472 1462 1329 1361 1367 1350 1320 1280 1291 1261 1275 1257 1222 1185 1213 1197 1197 1158 1189 1207 1185 1265 1184 1185 1156 1126 1138 1169 1189 1169 1141 1087 1152 1119 1193 1119 1158 1159 1183 1207 1127 1152 1156 1162 1191 1123 1132 1124 1132 1126 1164 1110 1196 1096 1135 1122 1138 1182 1093 1177 1138 1174 1234 1254 1208 1248 1207 1184 1212 1273 1273 1207 1271 1321 1283 1239 1358 1384 1452 1418 1474 1391 1522 1500 1577 1646 1596 1651 1674 1788 1806 1907 1905 2038 2080 2117 2185 2161 2147 2212 2248 2169 2192 2073 2073 2003 1934 1861 1862 1826 1847 1816 1732 1852 1758 1758 1739 1715 1729 1723 1649 1697 1634 1479 1577 1581 1615 1546 1554 1565 1434 1505 1532 1524 1630 1515 1648 1637 1653 1689 1747 1758 1754 1869 1889 2004 1954 1953 2018 1986 2047 2143 1967 1897 1962 1895 1837 1793 1805 1723 1714 1667 1694 1675 1739 1655 1648 1598 1583 1646 1568 1466 1486 1442 1338 1432 1350 1375 1286 1309 1268 1325 1279 1238 1258 1285 1272 1233 1285 1182 1258 1269 1263 1260 1227 1294 1209 1213 1176 1317 1253 1225 1290 1302 1275 1346 1325 1294 1279 1390 1324 1359 1353 1414 1444 1467 1547 1576 1599 1580 1636 1689 1730 1850 1862 2004 2093 2071 2214 2213 2300 2267 2276 2292 2482 2354 2349 2286 2338 2310 2168 2240 2216 2168 2101 2087 2054 2004 1987 1968 1927 1908 1899 1853 1899 1690 1725 1694 1668 1587 1568 1569 1571 1519 1512 1428 1466 1453 1399 1503 1504 1523 1420 1442 1559 1489 1464 1587 1476 1514 1550 1583 1583 1650 1670 1639 1735 1633 1712 1752 1776 1869 1896 1953 1820 2014 1933 2029 2067 2067 2038 2151 2099 2087 2043 2026 2039 2012 1999 2061 2102 1942 1999 1977 1942 1985 2018 1950 1854 1872 1820 1881 1828 1755 1730 1751 1685 1665 1628 1612 1698 1647 1654 1601 1573 1625 1555 1642 1575 1662 1708 1743 1673 1734 1778 1855 1835 1933 1983 1995 2027 2088 2040 1984 1979 1869 1918 1808 1841 1810 1805 1883 1934 1864 2015 1985 1956 1973 1963 1885 1770 1741 1764 1675 1597 1669 1505 1631 1526 1605 1608 1520 1526 1478 1522 1501 1486 1409 1532 1484 1464 1489 1561 1454 1465 1499 1436 1481 1497 1530 1370 1567 1520 1491 1434 1403 1435 1520 1409 1400 1398 1413 1477 1417 1439 1388 1374 1436 1421 1397 1384 1323 1289 1358 1363 1356 1406 1348 1302 1418 1320 1329 1304 1359 1376 1405 1389 1300 1313 1298 1309 1242 1272 1229 1296 1286 1304 1187 1295 1281 1365 1338 1308 1357 1359 1377 1361 1352 1406 1510 1436 1534 1483 1574 1630 1689 1623 1745 1742 1808 1771 1841 1819 1811 1854 1791 1761 1692 1836 1765 1780 1841 1829 1798 1867 1933 1890 1916 1903 1983 2071 2112 2028 2095 2177 2180 2196 2233 2142 2283 2322 2274 2183 2085 2189 2086 2046 2057 1980 1873 1927 1920 1893 1864 1919 1955 1912 1869 1872 1790 1781 1720 1652 1604 1622 1553 1523 1468 1454 1435 1389 1420 1346 1351 1300 1338 1315 1297 1339 1165 1172 1193 1218 1174 1182 1132 1229 1156 1131 1092 1167 1028 1149 1175 1135 1109 1063 1082 1118 1099 1077 1095 1143 1086 1092 1035 1069 1046 1080 1095 1087 1108 1080 1101 1047 1080 1092 1031 1084 1029 1090 1128 1048 1095 1041 1141 1057 995 1058 997 1059 1111 1043 1058 1123 1050 1020 1089 1015 1019 1095 1010 1035 1015 983 1068 1011 1030 1000 1075 1007 1010 1019 1036 1070 1016 979 1032 1071 1060 1068 1073 1040 1042 1046 1031 1034 990 985 1019 1028 1063 1073 985 1031 946 1046 1075 1050 1032 1070 1041 999 1093 1045 1024 1071 1033 1016 1065 1035 1028 1066 1034 1023 1006 1091 1031 1035 1062 1065 1007 1016 997 1035 1096 983 960 978 1039 1040 1029 980 983 1035 1035 1034 985 985 997 1034 1013 1030 1007 1006 1085 984 1092 1047 1085 1021 1057 1036 1000 1032 939 991 1009 985 1105 1046 1057 1076 960 1032 1010 1009 1003 1054 1064 1086 1027 1021 1018 1023 1003 1033 1085 1065 1032 1052 1045 1079 1110 980 1002 1032 1024 1082 1020 1082 1037 980 1026 1031 994 1049 990 1088 998 1051 1047 1091 1029 1054 1082 1082 1063 1100 1127 1072 1086 1040 1039 1096 1002 1162 1110 1143 1092 1101 1079 1063 1062 1121 1158 1154 1041 1105 1056 1135 1101 1103 1105 1152 1157 1207 1177 1166 1195 1199 1164 1255 1219 1252 1288 1249 1324 1260 1324 1346 1404 1408 1425 1531 1528 1591 1630 1527 1615 1611 1569 1570 1627 1617 1653 1616 1668 1719 1723 1720 1701 1824 1832 1732 1796 1866 1831 1853 1961 1916 1987 2021 1982 2026 1990 2035 2055 2119 2055 2180 2098 2164 2071 2097 2025 1962 1990 1939 1946 1925 1875 1809 1816 1703 1691 1689 1619 1672 1660 1628 1723 1633 1701 1620 1598 1524 1575 1522 1484 1502 1424 1363 1423 1306 1311 1383 1328 1382 1291 1260 1288 1269 1264 1199 1249 1254 1266 1253 1221 1232 1190 1239 1178 1169 1132 1172 1159 1189 1224 1194 1192 1154 1194 1166 1195 1149 1177 1110 1166 1155 1235 1226 1168 1258 1151 1194 1193 1222 1238 1247 1265 1233 1187 1189 1166 1263 1238 1254 1237 1261 1273 1203 1215 1327 1360 1306 1283 1393 1417 1390 1379 1390 1354 1468 1475 1474 1403 1506 1535 1538 1481 1590 1572 1604 1693 1762 1779 1851 1937 1956 1919 2022 1871 1944 1851 1830 1673 1679 1607 1706 1574 1570 1531 1536 1544 1573 1614 1596 1618 1629 1635 1591 1552 1539 1551 1422 1364 1381 1416 1424 1368 1379 1330 1421 1439 1347 1469 1413 1441 1437 1549 1533 1571 1623 1511 1573 1636 1650 1673 1653 1643 1674 1596 1597 1675 1701 1612 1674 1676 1686 1731 1756 1711 1655 1672 1604 1618 1549 1613 1454 1539 1384 1525 1453 1397 1472 1468 1283 1447 1314 1420 1341 1327 1235 1317 1308 1274 1313 1311 1279 1245 1170 1209 1271 1223 1196 1118 1225 1172 1210 1246 1154 1158 1190 1299 1304 1176 1323 1258 1376 1383 1491 1543 1510 1653 1572 1738 1813 1765 1767 1707 1744 1637 1646 1548 1497 1505 1500 1471 1510 1459 1527 1512 1493 1571 1609 1619 1572 1608 1567 1605 1546 1564 1542 1454 1480 1373 1378 1399 1403 1420 1422 1370 1335 1339 1379 1304 1360 1272 1339 1258 1368 1266 1397 1390 1299 1297 1307 1271 1301 1267 1292 1287 1299 1296 1344 1361 1317 1306 1354 1337 1306 1298 1254 1290 1345 1254 1280 1340 1237 1299 1288 1300 1302 1339 1310 1315 1261 1306 1245 1247 1235 1246 1293 1149 1229 1127 1228 1202 1203 1183 1156 1184 1114 1198 1178 1138 1238 1182 1167 1117 1162 1161 1201 1128 1214 1192 1263 1219 1292 1251 1361 1264 1346 1349 1340 1297 1296 1254 1275 1205 1245 1211 1209 1153 1116 1189 1153 1120 1192 1180 1226 1209 1163 1196 1197 1235 1192 1222 1114 1174 1091 1149 1166 1133 1058 1138 1084 1125 1086 1110 1101 1094 1080 1069 1084 1045 1068 1142 1082 1062 1053 1073 1152 1090 1048 1087 1051 1089 1030 1120 1021 1068 1028 1072 1010 1033 1046 1075 1032 944 1038 1073 1083 1101 1043 1085 1016 1022 1038 1015 1045 1063 997 1074 1053 1000 1001 1036 987 1004 1099 1032 1076 1073 1050 1043 1041 1093 1094 1073 1105 1066 1045 1063 1112 1140 1093 1159 1132 1132 1172 1158 1249 1216 1310 1330 1330 1394 1402 1386 1334 1411 1363 1303 1274 1287 1339 1290 1283 1229 1256 1219 1277 1300 1329 1313 1300 1312 1375 1461 1351 1399 1350 1359 1439 1401 1387 1422 1411 1331 1414 1344 1418 1444 1383 1303 1288 1399 1295 1323 1270 1281 1241 1297 1298 1247 1309 1267 1356 1261 1325 1365 1271 1337 1432 1390 1409 1453 1509 1507 1520 1523 1587 1587 1576 1598 1659 1743 1634 1669 1685 1635 1714 1744 1636 1699 1686 1653 1682 1613 1684 1718 1665 1811 1729 1779 1737 1630 1717 1822 1750 1769 1689 1741 1689 1623 1780 1565 1650 1611 1597 1589 1588 1674 1566 1653 1602 1599 1687 1614 1611 1666 1664 1711 1614 1692 1709 1659 1601 1538 1517 1578 1519 1569 1536 1506 1594 1547 1501 1599 1544 1597 1631 1594 1599 1562 1605 1598 1714 1507 1563 1527 1526 1568 1526 1431 1472 1494 1504 1475 1460 1426 1393 1450 1419 1470 1377 1473 1367 1410 1433 1361 1487 1363 1474 1360 1382 1368 1398 1402 1380 1401 1365 1393 1422 1472 1445 1413 1359 1379 1476 1526 1482 1583 1503 1497 1599 1592 1620 1568 1637 1659 1671 1666 1718 1719 1800 1696 1773 1716 1742 1821 1797 1764 1864 1852 1780 1840 1902 1885 1932 1941 1957 1988 1918 1971 2051 2061 2137 2131 2005 2172 2203 2261 2425 2430 2370 2423 2442 2525 2481 2440 2426 2356 2288 2206 2293 2229 2353 2324 2248 2285 2267 2308 2324 2291 2327 2331 2256 2279 2348 2268 2130 2162 2071 2042 2004 1990 1960 1960 2066 1910 1934 1940 1888 1891 1847 1901 1880 1817 1788 1753 1733 1735 1697 1720 1728 1690 1695 1645 1550 1601 1542 1635 1590 1548 1640 1525 1540 1505 1504 1544 1531 1583 1538 1531 1517 1517 1463 1519 1458 1495 1443 1414 1442 1430 1459 1426 1376 1436 1416 1421 1469 1483 1400 1513 1387 1449 1452 1457 1393 1511 1570 1448 1526 1495 1583 1559 1612 1696 1628 1735 1814 1923 1969 1993 2117 2280 2248 2475 2554 2649 2610 2529 2541 2324 2282 2229 2138 2074 1947 1886 1849 1817 1805 1789 1845 1762 1867 1866 1840 1864 1959 1927 1922 1925 1893 1834 1664 1656 1600 1530 1479 1494 1437 1358 1388 1316 1321 1241 1357 1273 1311 1292 1258 1228 1209 1210 1226 1156 1141 1227 1228 1209 1141 1241 1150 1169 1131 1189 1109 1166 1125 1150 1179 1210 1196 1220 1182 1242 1224 1175 1188 1279 1273 1333 1320 1337 1379 1386 1419 1343 1388 1470 1399 1387 1324 1316 1258 1283 1269 1323 1195 1282 1296 1244 1199 1207 1227 1273 1256 1187 1263 1287 1225 1241 1244 1227 1232 1242 1258 1164 1162 1136 1104 1144 1085 1134 1151 1181 1133 1102 1061 1066 1085 1016 1043 1079 996 1065 1099 1090 1108 1056 1035 1097 1009 1104 992 1052 1050 1042 1042 1088 1027 1024 1025 1086 1033 1074 1006 1066 1001 1006 996 973 1027 1036 983 1041 1032 1047 987 984 1020 973 1019 1027 1059 1051 984 1001 1087 1044 1087 1062 1063 1049 1045 1056 1030 1032 978 1049 1012 1001 1038 1006 1084 1052 1124 1025 1088 1072 1042 1007 1042 1110 1095 1073 1025 1086 1064 1116 1160 1101 1088 1046 1158 1236 1201 1195 1197 1221 1210 1221 1286 1311 1339 1357 1444 1527 1530 1558 1643 1782 1824 1738 1785 1835 1826 1682 1619 1593 1454 1530 1467 1449 1328 1402 1383 1378 1319 1394 1374 1401 1417 1490 1422 1452 1448 1439 1451 1476 1460 1388 1290 1334 1183 1211 1224 1149 1157 1057 1122 1111 1154 1101 1129 1121 1113 1093 1071 1123 1080 1101 1049 1097 1089 1180 1125 1075 1113 1144 1115 1167 1121 1119 1111 1132 1078 1127 1073 1116 1144 1186 1094 1215 1131 1144 1173 1184 1167 1149 1236 1174 1208 1232 1201 1258 1208 1281 1298 1228 1253 1256 1277 1344 1379 1334 1437 1415 1381 1403 1437 1491 1510 1469 1516 1543 1549 1562 1528 1536 1543 1528 1572 1555 1576 1488 1601 1576 1491 1649 1486 1570 1466 1520 1502 1524 1505 1475 1538 1543 1498 1467 1433 1510 1424 1423 1413 1357 1414 1341 1447 1360 1321 1364 1306 1320 1306 1318 1306 1246 1298 1174 1240 1248 1238 1231 1262 1244 1229 1224 1166 1191 1291 1124 1269 1146 1180 1197 1257 1168 1263 1183 1091 1164 1124 1206 1179 1172 1236 1190 1170 1210 1188 1216 1126 1263 1220 1156 1176 1248 1246 1245 1202 1300 1269 1296 1281 1251 1329 1315 1355 1331 1347 1282 1297 1276 1268 1238 1253 1292 1243 1217 1323 1305 1301 1290 1278 1297 1340 1343 1307 1277 1323 1349 1391 1394 1393 1404 1367 1389 1441 1299 1399 1430 1402 1294 1353 1350 1400 1369 1372 1454 1397 1422 1298 1373 1485 1416 1463 1471 1466 1433 1363 1419 1314 1330 1298 1326 1371 1332 1327 1333 1305 1330 1381 1268 1335 1334 1376 1417 1369 1276 1311 1245 1251 1297 1272 1300 1259 1225 1190 1175 1160 1207 1247 1220 1211 1245 1221 1184 1203 1153 1129 1186 1137 1235 1126 1229 1217 1239 1207 1166 1145 1248 1194 1220 1190 1253 1202 1197 1183 1273 1254 1247 1307 1369 1292 1362 1321 1330 1364 1384 1419 1285 1365 1375 1468 1434 1381 1433 1510 1487 1440 1496 1550 1563 1522 1667 1698 1757 1722 1824 1649 1685 1652 1660 1712 1563 1570 1594 1517 1556 1597 1493 1491 1434 1442 1452 1455 1412 1521 1473 1416 1413 1475 1442 1443 1423 1425 1424 1301 1335 1397 1372 1334 1254 1211 1188 1217 1215 1194 1240 1243 1245 1236 1173 1196 1197 1189 1129 1175 1143 1141 1172 1163 1215 1231 1188 1070 1252 1192 1202 1158 1284 1200 1208 1284 1173 1325 1237 1272 1273 1333 1263 1353 1316 1287 1250 1334 1324 1272 1224 1320 1241 1228 1146 1149 1198 1226 1214 1178 1165 1153 1200 1212 1158 1155 1151 1195 1194 1182 1216 1113 1210 1164 1123 1084 1178 1163 1106 1081 1112 1061 1125 1101 1075 1085 1049 1088 1064 1053 1068 1091 1046 1037 1085 995 1054 1027 1089 1052 984 1109 1044 1092 1049 1077 1090 1059 1016 1064 1033 1071 1076 989 1035 984 1005 1004 1053 1033 1038 1003 1078 1027 1059 1067 1088 1084 1097 1070 1067 1087 1047 1100 1044 1106 1077 1033 1117 1151 1095 1135 1114 1164 1156 1118 1149 1145 1242 1180 1181 1140 1235 1167 1243 1167 1179 1236 1132 1183 1172 1196 1155 1200 1145 1167 1156 1192 1137 1215 1142 1163 1177 1208 1194 1152 1194 1204 1163 1167 1208 1200 1211 1200 1264 1269 1311 1350 1323 1419 1329 1397 1361 1400 1341 1431 1330 1358 1298 1255 1198 1200 1140 1165 1189 1169 1138 1135 1080 1131 1224 1216 1186 1193 1169 1166 1220 1205 1316 1153 1134 1195 1156 1145 1115 1100 1163 1087 1117 1107 1146 1150 1107 1123 1190 1100 1097 1101 1069 1092 1054 1108 1077 1095 1126 1081 1112 1099 995 1066 1074 1093 1136 1022 1123 1033 1100 1067 1132 1067 1043 1136 1050 1125 1138 1138 1078 1103 1166 1178 1182 1194 1231 1218 1263 1302 1265 1278 1373 1328 1304 1389 1253 1262 1318 1294 1308 1364 1305 1227 1326 1317 1268 1234 1279 1247 1273 1204 1262 1235 1293 1236 1334 1289 1287 1358 1302 1308 1324 1332 1342 1364 1273 1391 1369 1402 1361 1352 1374 1366 1403 1396 1336 1417 1451 1379 1470 1430 1474 1498 1461 1537 1551 1521 1527 1630 1560 1611 1636 1622 1704 1606 1698 1686 1651 1637 1640 1678 1650 1625 1652 1595 1633 1609 1545 1612 1633 1613 1597 1544 1599 1603 1611 1532 1616 1551 1599 1552 1560 1627 1556 1606 1543 1557 1625 1590 1616 1517 1645 1597 1675 1605 1565 1592 1497 1547 1508 1563 1458 1519 1467 1513 1453 1368 1471 1420 1341 1404 1330 1411 1356 1439 1390 1390 1425 1507 1429 1417 1479 1607 1590 1601 1599 1571 1628 1590 1602 1617 1578 1482 1492 1488 1452 1460 1445 1415 1520 1394 1371 1423 1331 1321 1333 1308 1399 1401 1377 1392 1468 1430 1472 1448 1447 1425 1506 1424 1394 1387 1437 1386 1366 1417 1463 1440 1434 1354 1410 1378 1412 1393 1372 1416 1373 1370 1356 1356 1380 1332 1297 1480 1388 1413 1436 1458 1502 1443 1467 1373 1498 1429 1492 1462 1522 1434 1565 1493 1537 1550 1579 1582 1615 1587 1572 1581 1646 1630 1640 1649 1625 1645 1571 1648 1520 1652 1590 1603 1591 1643 1602 1584 1613 1612 1647 1714 1661 1695 1655 1795 1813 1864 1855 1942 1993 2000 2045 2075 2039 2050 2048 2062 1908 1936 1746 1749 1653 1694 1617 1532 1552 1539 1490 1528 1500 1524 1494 1397 1534 1484 1532 1584 1569 1592 1508 1652 1634 1499 1493 1521 1419 1472 1382 1451 1377 1351 1285 1271 1251 1247 1330 1288 1272 1271 1278 1231 1267 1289 1259 1275 1250 1285 1275 1161 1196 1254 1237 1234 1249 1200 1246 1171 1289 1181 1240 1136 1246 1164 1161 1253 1146 1183 1203 1223 1244 1235 1200 1171 1174 1199 1185 1230 1164 1234 1194 1229 1225 1205 1218 1226 1151 1211 1198 1244 1177 1239 1260 1260 1251 1299 1275 1346 1372 1427 1456 1434 1446 1474 1543 1540 1517 1549 1500 1406 1441 1468 1350 1361 1354 1348 1247 1283 1301 1234 1253 1245 1315 1170 1272 1311 1281 1230 1214 1302 1344 1379 1341 1337 1279 1310 1238 1281 1207 1309 1216 1197 1241 1172 1155 1151 1134 1135 1192 1185 1066 1107 1078 1097 1073 1078 1108 1079 1088 1146 1069 1110 1092 1120 1041 1030 1050 1070 1043 1120 1108 1112 1025 1041 997 1042 1046 978 993 988 984 1072 1053 974 1120 961 1057 1012 1035 1055 1016 1063 1049 985 1041 1006 983 1064 1032 1069 1060 1021 1121 1093 1071 1084 1073 1093 1095 1092 1135 1185 1259 1193 1195 1158 1208 1150 1205 1158 1203 1154 1151 1058 1153 1079 1096 1116 1078 1065 1135 1103 1129 1102 1085 1070 1033 1101 1079 1186 1098 1129 1106 1167 1117 1141 1091 1086 1117 1073 1096 1087 1114 1042 1054 1069 1052 1169 1083 1112 1004 1082 1065 1077 1020 1146 1008 1022 1026 1087 1017 1044 1085 1043 1017 1035 1073 1104 1058 1038 1059 1084 1037 1024 1078 1046 1057 975 1066 1009 1079 1026 1049 1046 1011 1056 1060 1033 1036 1090 1013 1006 1039 961 1095 961 1065 1046 1069 1041 1094 1104 1057 1091 1110 1076 1052 1117 1090 1185 1121 1181 1199 1163 1115 1208 1216 1234 1200 1226 1232 1208 1304 1246 1275 1225 1270 1252 1200 1222 1223 1256 1275 1212 1264 1222 1181 1155 1223 1212 1249 1191 1236 1185 1250 1236 1232 1135 1203 1223 1183 1240 1187 1147 1219 1177 1236 1207 1246 1234 1147 1270 1224 1183 1187 1181 1227 1139 1223 1180 1154 1088 1127 1259 1112 1157 1136 1136 1198 1158 1180 1170 1208 1161 1194 1195 1185 1197 1168 1276 1225 1134 1255 1181 1278 1215 1227 1254 1198 1248 1236 1326 1287 1346 1322 1351 1439 1421 1506 1479 1420 1431 1463 1490 1485 1581 1599 1594 1630 1735 1816 1775 1832 1863 1788 1856 1966 1979 1901 2059 1989 2031 1967 2010 1846 1902 1805 1815 1834 1759 1886 1771 1726 1779 1722 1818 1764 1612 1689 1764 1851 1832 1769 1801 1723 1833 1908 1860 1893 1801 1833 1881 1849 1713 1638 1630 1643 1600 1633 1602 1556 1566 1461 1510 1555 1508 1549 1472 1449 1412 1462 1369 1398 1355 1422 1367 1394 1366 1407 1304 1325 1373 1334 1396 1376 1274 1291 1286 1306 1375 1248 1316 1265 1295 1355 1297 1255 1287 1330 1352 1310 1272 1350 1293 1347 1315 1378 1346 1442 1364 1425 1435 1438 1355 1456 1409 1422 1410 1538 1398 1535 1446 1432 1517 1522 1557 1619 1608 1633 1667 1681 1757 1617 1584 1712 1670 1680 1725 1609 1636 1574 1619 1558 1507 1516 1567 1506 1483 1565 1497 1554 1528 1459 1498 1452 1463 1501 1524 1603 1532 1581 1559 1547 1508 1568 1623 1533 1563 1652 1626 1518 1625 1526 1618 1559 1605 1551 1599 1517 1557 1519 1573 1529 1485 1457 1534 1498 1490 1437 1518 1480 1504 1391 1528 1481 1472 1423 1497 1494 1502 1454 1545 1511 1473 1502 1422 1515 1480 1535 1514 1471 1494 1531 1495 1538 1524 1580 1442 1449 1511 1430 1475 1500 1428 1448 1384 1408 1404 1464 1400 1565 1483 1502 1535 1535 1513 1646 1585 1709 1685 1759 1874 1825 1799 1836 1772 1889 1711 1662 1707 1666 1628 1534 1555 1466 1413 1416 1375 1404 1361 1371 1382 1420 1391 1339 1352 1477 1311 1453 1424 1453 1408 1449 1432 1425 1446 1411 1408 1422 1329 1372 1354 1291 1354 1217 1363 1329 1278 1244 1256 1246 1191 1206 1244 1129 1276 1233 1275 1267 1304 1225 1235 1241 1162 1337 1282 1315 1284 1297 1287 1334 1320 1334 1215 1331 1305 1307 1359 1248 1289 1290 1265 1310 1222 1280 1292 1288 1270 1362 1275 1280 1252 1254 1244 1233 1272 1285 1316 1323 1374 1364 1334 1421 1326 1382 1346 1354 1388 1453 1396 1418 1469 1477 1580 1554 1615 1637 1593 1610 1556 1564 1508 1525 1461 1464 1467 1472 1357 1336 1406 1342 1474 1455 1386 1467 1338 1374 1347 1477 1375 1373 1404 1427 1488 1531 1483 1451 1523 1396 1438 1452 1396 1425 1376 1400 1417 1353 1291 1275 1262 1254 1262 1257 1302 1282 1318 1229 1287 1281 1266 1262 1284 1297 1308 1324 1360 1323 1242 1233 1376 1289 1323 1302 1308 1306 1362 1392 1324 1404 1387 1382 1309 1349 1355</counts>
			</dataPoints>
		</scan>
	</xrdMeasurement>
</xrdMeasurements>