File: dataset/precursor_mixture/HfO2_Li3PO4_Bi2O3-beta.12-min.xrdml
<?xml version="1.0"?>
<xrdMeasurements xmlns="http://www.xrdml.com/XRDMeasurement/2.2" xmlns:xsi="http://www.w3.org/2001/XMLSchema-instance" xsi:schemaLocation="http://www.xrdml.com/XRDMeasurement/2.2 http://www.xrdml.com/XRDMeasurement/2.2/XRDMeasurement.xsd" status="Completed" recordIdentifier="{75DC20AD-F720-49DE-89BC-C13BBE52553D}">
	<comment>
		<entry/>
	</comment>
	<sample type="To be analyzed">
		<id>dara-42-2</id>
		<name></name>
		<preparedBy></preparedBy>
	</sample>
	<xrdMeasurement measurementType="Scan" status="Completed" sampleMode="Reflection">
		<usedWavelength intended="K-Alpha 1">
			<kAlpha1 unit="Angstrom">1.5405980</kAlpha1>
			<kAlpha2 unit="Angstrom">1.5444260</kAlpha2>
			<kBeta unit="Angstrom">1.3922500</kBeta>
			<ratioKAlpha2KAlpha1>0.5000</ratioKAlpha2KAlpha1>
		</usedWavelength>
		<incidentBeamPath>
			<radius unit="mm">145.00</radius>
			<xRayTube id="1010048" name="Empyrean Cu LFF HR (9430 033 7310x) DK437873">
				<tension unit="kV">40.0</tension>
				<current unit="mA">15.0</current>
				<anodeMaterial>Cu</anodeMaterial>
				<focus type="Line">
					<length unit="mm">12.0</length>
					<width unit="mm">0.4</width>
					<takeOffAngle unit="deg">6.0</takeOffAngle>
				</focus>
			</xRayTube>
			<filter id="20010004" name="Beta-filter Nickel">
				<material>Ni</material>
				<thickness unit="mm">0.020</thickness>
			</filter>
			<sollerSlit id="21010002" name="Soller slits 0.04 rad.">
				<opening unit="rad">0.0400</opening>
			</sollerSlit>
			<mask id="22031000" name="Fixed mask 13 mm">
				<width unit="mm">9.00</width>
			</mask>
			<divergenceSlit id="22120001" name="Divergence slit 1°" xsi:type="fixedDivergenceSlitType">
				<distanceToSample unit="mm">50.00</distanceToSample>
				<height unit="mm">1.52</height>
			</divergenceSlit>
		</incidentBeamPath>
		<beamKnife id="29030100" name="Beam knife low"/>
		<sampleMovement xsi:type="spinningSampleMovementType">
			<spinnerRevolutionTime unit="seconds">1.0</spinnerRevolutionTime>
		</sampleMovement>
		<diffractedBeamPath>
			<radius unit="mm">145.00</radius>
			<antiScatterSlit id="22090040" name="AS slit 9 mm" xsi:type="fixedAntiScatterSlitType">
				<height unit="mm">9.00</height>
			</antiScatterSlit>
			<sollerSlit id="21020003" name="Large Soller slits 0.04 rad.">
				<opening unit="rad">0.0400</opening>
			</sollerSlit>
			<filter id="20030001" name="Large beta-filter Nickel">
				<material>Ni</material>
				<thickness unit="mm">0.020</thickness>
			</filter>
			<detector id="7010019" name="PIXcel1D-Medipix3 detector" xsi:type="rtmsDetectorType">
				<phd unit="keV">
					<lowerLevel>4.0</lowerLevel>
					<upperLevel>11.3</upperLevel>
				</phd>
				<mode>Scanning</mode>
				<activeLength unit="deg">5.020</activeLength>
			</detector>
		</diffractedBeamPath>
		<scan appendNumber="0" mode="Continuous" scanAxis="Gonio" status="Completed">
			<header>
				<startTimeStamp>2024-03-25T11:49:15-07:00</startTimeStamp>
				<endTimeStamp>2024-03-25T12:01:42-07:00</endTimeStamp>
				<author>
					<name>AutomatedUser</name>
				</author>
				<source>
					<applicationSoftware version="1.6 (94)">PANalytical Aeris Instrument Suite</applicationSoftware>
					<instrumentControlSoftware version="3.0.0 20211014">AERIS</instrumentControlSoftware>
					<instrumentID>2879380</instrumentID>
				</source>
			</header>
			<dataPoints>
				<positions axis="2Theta" unit="deg">
					<startPosition>9.99043322</startPosition>
					<endPosition>100.09495370</endPosition>
				</positions>
				<positions axis="Omega" unit="deg">
					<startPosition>4.99521661</startPosition>
					<endPosition>50.04747685</endPosition>
				</positions>
				<commonCountingTime unit="seconds">18.249</commonCountingTime>
				<counts unit="counts">4015 4028 3937 3891 4034 3974 4042 4022 3921 4024 3833 3844 3928 3943 3936 3816 3872 3936 3966 3871 3836 4007 3906 4051 3878 3977 3892 3876 4039 3861 3869 3818 3916 3813 3885 3799 3809 3840 3776 3845 3873 3793 3830 3817 3770 3782 3880 3707 3878 3867 3768 3828 3855 3849 3741 3845 3781 3861 3779 3775 3730 3725 3715 3680 3699 3671 3725 3761 3756 3760 3669 3609 3746 3825 3717 3672 3552 3753 3560 3603 3778 3632 3639 3673 3648 3638 3676 3559 3523 3490 3727 3480 3664 3683 3650 3650 3729 3688 3528 3545 3643 3537 3584 3582 3633 3498 3565 3424 3584 3545 3514 3470 3539 3433 3452 3399 3501 3489 3516 3462 3585 3617 3400 3460 3530 3410 3535 3629 3517 3458 3403 3495 3473 3442 3407 3521 3440 3384 3375 3375 3327 3460 3440 3482 3369 3432 3388 3357 3332 3366 3380 3442 3380 3384 3396 3348 3339 3273 3303 3318 3380 3444 3287 3248 3284 3360 3325 3334 3398 3364 3261 3267 3260 3320 3300 3293 3300 3295 3259 3236 3307 3186 3236 3286 3278 3262 3288 3260 3355 3277 3264 3163 3249 3096 3286 3237 3336 3169 3100 3120 3169 3178 3284 3203 3170 3156 3192 3184 3185 3119 3128 3287 3222 3036 3134 3132 3111 3268 3080 3037 3078 3170 3153 3220 3184 3150 3082 3134 3141 3188 3121 3103 3112 3185 3107 3124 3092 3147 3185 3078 3088 3155 3258 3068 3205 3034 3033 3159 3246 3111 3159 3100 3173 3178 3080 3054 3083 3183 3113 3165 3181 3052 3138 3120 3145 3083 3152 2993 3125 3099 3160 3117 3145 3072 3118 3141 3066 2987 3097 3107 3183 3128 3039 2936 3014 2994 3006 2982 2991 3020 3066 2854 2915 2977 3012 2878 2963 2951 2816 2988 2887 2775 2857 2858 2868 2897 2775 2925 2834 2873 2925 2948 2890 2829 2816 2898 2857 2768 2881 2908 2765 2794 2818 2786 2785 2775 2841 2818 2801 2912 2874 2805 2805 2757 2842 2862 2807 2733 2843 2916 2767 2747 2855 2709 2812 2850 2843 2830 2809 2804 2710 2671 2754 2800 2752 2887 2862 2715 2835 2766 2644 2849 2738 2818 2781 2817 2653 2809 2772 2700 2724 2647 2655 2752 2772 2809 2745 2670 2720 2809 2691 2694 2636 2669 2713 2707 2720 2709 2663 2720 2670 2685 2729 2684 2784 2701 2662 2749 2744 2767 2677 2713 2688 2746 2746 2693 2720 2648 2664 2660 2664 2687 2672 2725 2638 2662 2681 2673 2742 2650 2717 2683 2574 2648 2671 2690 2683 2587 2655 2605 2629 2623 2583 2595 2614 2669 2662 2657 2572 2733 2666 2577 2652 2665 2632 2622 2634 2608 2658 2587 2504 2576 2624 2645 2643 2618 2532 2647 2521 2574 2653 2481 2605 2668 2606 2579 2568 2629 2522 2669 2675 2586 2625 2649 2528 2595 2556 2513 2651 2634 2591 2497 2521 2584 2674 2598 2491 2544 2585 2509 2477 2573 2603 2484 2587 2554 2521 2474 2430 2550 2496 2523 2529 2659 2437 2580 2530 2518 2520 2567 2510 2609 2533 2592 2503 2572 2614 2433 2515 2357 2472 2490 2560 2525 2541 2509 2585 2484 2518 2527 2490 2483 2510 2466 2561 2455 2432 2519 2447 2486 2577 2508 2634 2462 2550 2447 2554 2443 2560 2438 2559 2653 2627 2518 2637 2610 2597 2615 2613 2728 2665 2661 2750 2684 2759 2786 2769 2903 2830 2997 2979 2968 3036 3010 3019 2985 3066 3025 2934 2855 2864 2815 2705 2652 2561 2536 2495 2530 2487 2535 2456 2460 2454 2544 2468 2484 2454 2479 2394 2458 2515 2491 2516 2426 2435 2505 2458 2456 2460 2537 2450 2495 2446 2613 2506 2612 2521 2510 2565 2517 2638 2636 2511 2553 2690 2554 2664 2717 2784 2648 2654 2728 2641 2789 2746 2805 2828 2827 2838 2780 2890 2832 2975 2993 2791 2802 2779 2731 2758 2703 2683 2714 2582 2607 2597 2479 2465 2563 2554 2459 2530 2435 2472 2388 2497 2451 2462 2466 2475 2481 2475 2530 2459 2502 2572 2545 2533 2516 2432 2552 2576 2631 2656 2673 2649 2684 2756 2812 2860 2922 2972 3003 2995 3080 2985 3161 3278 3344 3335 3336 3335 3284 3332 3359 3310 3221 3034 2989 2973 2735 2786 2653 2532 2495 2498 2415 2371 2385 2378 2423 2406 2395 2511 2383 2438 2341 2371 2398 2330 2375 2369 2334 2332 2241 2267 2189 2289 2232 2256 2295 2386 2238 2300 2322 2230 2351 2279 2271 2254 2289 2214 2200 2254 2345 2298 2322 2311 2288 2335 2211 2271 2281 2301 2293 2235 2340 2200 2247 2256 2224 2187 2190 2275 2211 2191 2256 2132 2285 2138 2224 2239 2278 2262 2167 2222 2154 2209 2158 2186 2263 2174 2173 2153 2112 2158 2251 2201 2151 2178 2167 2201 2151 2110 2164 2214 2237 2246 2195 2237 2128 2172 2170 2133 2107 2156 2131 2227 2178 2257 2212 2133 2247 2261 2119 2189 2194 2211 2169 2141 2112 2259 2143 2222 2142 2211 2170 2287 2191 2218 2105 2200 2085 2187 2172 2155 2144 2052 2135 2150 2207 2168 2129 2123 2210 2151 2180 2159 2107 2126 2074 2082 2187 2101 2097 2072 2101 2120 2207 2074 2047 2132 2153 2143 2091 2089 2101 2221 2173 2049 2100 2076 2165 2051 2129 2118 2090 2076 2061 2016 2052 2121 2088 2169 2102 2117 2104 2072 2046 2204 2176 2075 2060 2017 2138 2035 2086 2003 2074 2059 2100 2017 2113 2116 2088 2039 1986 1957 2049 2104 2004 2110 2104 2099 2033 2019 2006 1998 2099 2073 2059 2009 2056 2095 2140 2039 1981 2070 2083 2012 2065 2066 2098 2023 2049 1997 2064 2036 2043 2003 2039 2076 1995 2052 2067 1904 2040 2058 2089 2094 1967 1964 2010 1999 1957 2002 2047 1995 2004 1851 1953 1972 2028 1977 2016 1968 2038 2010 1925 2094 1988 2020 1947 2073 1996 1919 2026 1973 2025 1860 1947 1984 2000 1927 2049 1917 2042 2022 1937 1959 2007 1911 2065 2018 1988 1901 1883 2080 1928 1959 1991 1909 1928 1931 1969 1961 1925 1906 2021 1980 2026 2044 1964 1966 1910 1974 1893 1949 1955 1994 1946 1983 2020 1943 1941 1990 1970 1895 2026 1922 1957 1957 1921 2021 1905 1948 1944 1955 1917 2033 1960 1921 2035 1924 1937 1893 1876 1891 1943 1984 1924 1975 1934 1873 1923 2019 2007 1962 1953 1880 1910 1902 1952 2048 1997 1984 1876 1950 1934 1984 1985 1957 2028 2019 1937 1990 1936 1968 1916 2010 1951 1984 1951 2062 1988 1989 2013 1898 2051 2110 2007 2033 2018 1974 2015 2094 1974 2133 2059 2117 2124 2091 2259 2221 2180 2185 2232 2317 2312 2357 2299 2361 2386 2423 2598 2566 2561 2591 2718 2759 2860 2912 3069 3219 3141 3280 3472 3435 3458 3625 3611 3778 3746 3618 3698 3480 3651 3431 3280 3158 3069 2919 2767 2685 2505 2479 2453 2418 2358 2312 2213 2237 2232 2182 2174 2073 2156 2037 2093 2138 2028 2013 2044 2009 2037 1989 1970 1998 2020 2031 2039 2040 2032 2011 2030 2086 2055 2051 1965 1999 2049 2074 2042 2167 2222 2171 2158 2206 2186 2247 2231 2293 2312 2338 2312 2396 2286 2372 2348 2493 2501 2452 2577 2649 2697 2794 2787 2831 2922 3032 3055 2994 3009 3183 3197 3115 3138 3029 3198 3045 2946 2979 2871 2992 2996 3052 3004 2972 2950 3061 2875 2842 2821 2757 2692 2677 2620 2494 2471 2394 2286 2207 2198 2189 2153 2102 2159 2050 2095 2096 2111 2104 2077 2014 1992 2071 2061 2103 2079 2073 2023 2057 1972 2100 2105 2072 2243 2139 2164 2283 2215 2238 2294 2337 2332 2306 2277 2365 2396 2362 2392 2437 2388 2443 2536 2617 2671 2747 2860 2937 2970 3110 3204 3397 3505 3728 3961 4091 4484 4578 4540 4972 4920 5017 5080 5005 4920 4891 4536 4298 4149 3868 3678 3482 3250 3080 2890 2807 2766 2726 2680 2660 2705 2743 2679 2624 2868 2945 2875 3065 3122 3234 3487 3577 3697 3752 3935 4219 4306 4269 4443 4545 4535 4497 4439 4394 4125 4036 3848 3608 3417 3347 3116 3123 3035 2924 2857 2798 2810 2718 2748 2710 2773 2734 2826 2725 2595 2673 2563 2661 2486 2526 2634 2550 2577 2536 2524 2487 2442 2503 2508 2516 2331 2330 2245 2260 2134 2185 2260 2268 2258 2084 2157 2116 2123 2258 2134 2150 2113 2125 2016 2008 2069 2022 1890 1922 1912 2000 1898 1859 1908 1882 1947 1883 1900 1942 1950 1879 1948 1903 1931 1954 1906 2058 2017 2021 2024 2096 2133 2179 2283 2281 2300 2355 2516 2648 2700 2833 2910 3004 3198 3275 3344 3474 3481 3391 3160 3091 2968 2931 2717 2488 2427 2273 2316 2098 2016 2040 1988 1935 1958 1895 1905 1949 1767 1794 1747 1904 1812 1857 1827 1794 1879 1759 1756 1851 1806 1814 1831 1826 1741 1800 1816 1755 1687 1849 1731 1802 1785 1774 1707 1775 1729 1734 1782 1774 1768 1794 1765 1811 1678 1788 1768 1733 1721 1749 1634 1742 1769 1745 1753 1697 1694 1781 1745 1827 1780 1695 1649 1698 1791 1696 1716 1770 1664 1738 1763 1763 1688 1708 1757 1766 1769 1674 1737 1800 1742 1799 1678 1794 1714 1814 1709 1816 1736 1771 1786 1783 1703 1911 1837 1797 1827 1779 1868 1898 1860 1901 1947 2007 2017 1968 2045 2089 2002 2039 2003 2141 2103 2019 2114 2076 2181 2206 2113 2164 2072 2162 2062 2178 2121 2197 2168 2232 2212 2303 2333 2199 2364 2311 2247 2307 2332 2452 2414 2468 2480 2462 2484 2587 2646 2670 2753 2849 2891 2861 2935 3017 3078 3056 3241 3264 3224 3265 3414 3548 3521 3610 3807 3972 4234 4285 4499 4688 4955 5352 5712 6236 6719 7312 8225 9015 10036 11488 12996 14705 16817 19537 22539 26005 30081 34203 39439 44906 50681 56237 62962 68357 73130 75697 76010 73015 67641 61854 55783 49666 44637 39723 34138 28730 23358 18972 15758 13430 11652 10868 10101 9861 9592 9751 9879 10404 10812 11552 12033 12729 13538 14440 15502 16553 17671 18748 19486 20199 20910 20808 20848 20686 20234 19621 18613 17623 16183 15005 13773 12640 11660 10377 9356 8564 7722 7096 6527 5939 5615 5288 4970 4626 4508 4324 4212 3959 3778 3781 3746 3600 3595 3385 3392 3267 3199 3138 2982 3055 2979 2943 2939 2893 2883 2853 2826 2844 2815 2665 2773 2706 2720 2599 2604 2620 2677 2593 2534 2533 2636 2492 2502 2457 2481 2507 2546 2333 2488 2441 2433 2381 2461 2524 2379 2454 2416 2437 2380 2436 2389 2398 2432 2302 2325 2258 2262 2265 2236 2148 2171 2135 2139 2252 2056 2080 2015 2088 2157 2087 2175 2053 2064 2077 2096 1992 2103 2043 1959 1942 2004 2035 1904 2012 1934 1960 1945 1876 1895 1885 1898 1879 1885 1977 1939 1965 1893 1894 1903 1952 2001 1822 1852 1907 1972 1889 1911 1959 1966 1905 1963 1943 1887 1917 1973 1952 1955 2031 2043 2000 2048 2045 1925 2018 1912 2047 2050 2062 2109 2124 2207 2219 2296 2261 2306 2430 2428 2483 2579 2695 2649 2851 2905 2990 3231 3315 3523 3592 3587 3650 3711 3551 3522 3361 3260 3167 3091 2859 2889 2716 2541 2492 2415 2284 2163 2063 2073 2034 2075 1976 2022 1982 2021 2036 1999 1947 2017 1986 2045 1916 1950 2005 1981 1905 2020 1961 1995 1933 1951 1984 1888 1940 1958 2084 1964 2010 1931 1975 1962 1995 1962 1951 2048 1924 1974 1926 2013 2031 1884 2048 2066 2091 2057 2103 2039 2029 2085 2098 2108 2223 2135 2142 2136 2159 2191 2202 2226 2233 2314 2297 2336 2333 2350 2448 2512 2484 2483 2461 2514 2608 2634 2763 2736 2829 2889 3008 3010 3141 3301 3318 3497 3611 3722 3882 4015 4269 4518 4801 5016 5476 5703 6202 6755 7254 7721 8529 9242 10113 10955 12218 13082 13988 14727 15782 16715 17719 18728 19129 19705 20113 20124 20688 20931 21162 21137 20909 20429 19452 18471 16528 15103 13636 12183 11696 10383 9546 8504 7422 6283 5582 4941 4432 4117 3872 3671 3439 3335 3193 3205 2987 2902 2751 2736 2667 2609 2610 2613 2496 2459 2432 2364 2340 2309 2321 2334 2269 2299 2336 2262 2300 2165 2199 2317 2196 2273 2226 2151 2231 2277 2261 2174 2258 2344 2287 2319 2319 2473 2449 2504 2665 2777 2894 3107 3226 3511 3765 3988 4538 4851 5559 6222 7037 7969 9103 10372 12168 13591 15392 17054 18632 20039 20751 20716 20184 18685 17195 15532 14406 13327 12544 11560 10105 8740 7488 6094 5241 4368 3825 3469 3121 3033 2813 2622 2560 2368 2441 2397 2252 2202 2256 2116 2092 2082 2058 1989 2043 1917 1922 1907 1905 1863 1777 1848 1796 1883 1704 1843 1748 1701 1693 1728 1643 1680 1685 1724 1761 1765 1648 1676 1636 1714 1667 1749 1686 1645 1734 1688 1705 1696 1669 1700 1816 1656 1716 1753 1698 1716 1789 1702 1766 1588 1743 1749 1794 1787 1757 1838 1768 1777 1787 1815 1857 1877 1891 1883 1965 1914 2048 2042 2124 2124 2258 2315 2283 2457 2406 2592 2634 2729 2785 2845 2966 3083 3127 3079 3097 3229 3081 3171 2964 3117 2929 3014 3022 2924 2913 2860 2802 2826 2896 2861 2924 2985 3062 3212 3191 3421 3532 3850 3823 4101 4354 4570 4685 5177 5338 5660 5917 6163 6478 6547 6633 6737 6867 6628 6626 6490 6329 6004 5924 5568 5554 5192 5087 4891 4459 4635 4516 4511 4532 4580 4781 4888 5072 5347 5618 5621 5851 5833 5905 5954 5871 5395 5302 5097 4936 4633 4608 4347 3957 3745 3445 3259 2971 2922 2812 2508 2421 2328 2379 2216 2135 2092 2095 1974 1902 1936 2015 1820 1905 1874 1932 1898 1847 1814 1831 1807 1846 1804 1749 1845 1771 1764 1770 1876 1746 1807 1849 1843 1778 1827 1924 1763 1827 1873 1906 1925 1917 1878 2042 2002 2151 2126 2268 2317 2475 2596 2684 2699 3052 3079 3238 3619 3876 4040 4530 4960 5098 5488 5654 5930 6250 6203 6243 5943 5966 5588 5177 5027 4589 4521 4184 3947 3576 3425 3072 2939 2586 2567 2338 2239 2212 2120 2047 1962 1975 1990 1964 1888 1864 1939 1869 1973 1826 1968 1957 1949 1965 1974 1966 1983 2091 2153 2112 2154 2171 2309 2364 2419 2484 2464 2736 2610 2659 2660 2656 2663 2517 2563 2439 2432 2236 2226 2201 2178 2020 1979 1987 1806 1820 1752 1762 1750 1687 1702 1673 1625 1620 1576 1593 1635 1582 1656 1594 1725 1711 1722 1682 1825 1845 1903 1795 1914 2033 1969 2024 1937 1953 1930 2014 2006 1918 1939 1892 1886 1822 1794 1768 1749 1810 1722 1771 1624 1645 1708 1594 1595 1673 1627 1537 1567 1584 1643 1619 1515 1568 1637 1618 1627 1580 1602 1647 1644 1671 1656 1633 1628 1632 1680 1781 1735 1679 1781 1785 1708 1668 1632 1639 1709 1598 1585 1496 1486 1442 1531 1491 1511 1348 1428 1352 1398 1331 1356 1293 1401 1307 1327 1326 1326 1385 1320 1304 1361 1269 1381 1320 1299 1265 1321 1255 1313 1230 1322 1231 1313 1285 1307 1258 1280 1329 1265 1202 1236 1266 1293 1281 1275 1320 1230 1281 1266 1239 1275 1297 1241 1267 1249 1328 1298 1304 1282 1277 1249 1281 1230 1190 1311 1216 1240 1251 1214 1220 1284 1266 1244 1298 1229 1253 1293 1265 1281 1253 1248 1242 1299 1222 1276 1238 1317 1253 1259 1322 1245 1266 1293 1266 1306 1281 1261 1336 1322 1370 1384 1438 1424 1505 1503 1461 1530 1655 1560 1567 1723 1637 1565 1561 1562 1531 1534 1510 1512 1556 1471 1475 1414 1423 1439 1421 1404 1506 1556 1464 1507 1539 1629 1531 1615 1612 1733 1797 1807 1804 1942 2003 2145 2242 2366 2468 2548 2605 2776 2926 3093 3045 3066 2934 2926 2806 2807 2758 2576 2511 2534 2442 2330 2134 2051 2053 1842 1882 1713 1833 1704 1636 1662 1625 1569 1632 1603 1570 1545 1549 1521 1516 1461 1482 1477 1415 1442 1365 1414 1373 1327 1336 1326 1348 1294 1275 1312 1303 1294 1314 1295 1286 1233 1284 1364 1227 1253 1310 1213 1303 1244 1276 1307 1331 1298 1294 1315 1320 1284 1232 1268 1309 1353 1329 1270 1353 1258 1276 1245 1318 1276 1278 1285 1302 1164 1256 1235 1267 1230 1246 1322 1190 1252 1270 1234 1322 1213 1223 1236 1238 1356 1261 1273 1197 1251 1262 1215 1259 1231 1324 1287 1221 1274 1243 1379 1329 1346 1371 1417 1476 1460 1418 1565 1566 1595 1498 1523 1572 1481 1517 1532 1530 1398 1445 1487 1475 1456 1423 1371 1372 1379 1380 1302 1366 1285 1291 1275 1369 1237 1335 1288 1350 1313 1357 1289 1254 1266 1323 1259 1309 1337 1314 1363 1375 1366 1369 1346 1363 1328 1423 1389 1410 1434 1462 1441 1479 1487 1525 1514 1524 1545 1700 1640 1712 1714 1820 1803 1982 2045 2045 2164 2280 2445 2538 2611 2789 2890 3170 3200 3303 3342 3476 3465 3539 3350 3297 3191 3288 3161 3021 3066 2839 2752 2707 2608 2502 2449 2388 2354 2307 2339 2300 2285 2294 2281 2373 2455 2617 2796 2913 3040 3203 3212 3077 3110 2956 2816 2709 2770 2707 2785 2841 2768 2668 2489 2432 2269 2170 2153 2116 2139 2095 2004 2070 2060 1949 2077 2101 2176 2063 1981 2027 2122 1986 1999 1885 1982 1960 1939 1972 1792 1816 1797 1730 1683 1666 1618 1506 1521 1563 1518 1517 1412 1434 1359 1392 1355 1394 1332 1382 1390 1383 1391 1435 1456 1442 1561 1498 1578 1645 1550 1597 1565 1546 1515 1489 1460 1442 1490 1491 1469 1498 1447 1554 1406 1385 1398 1374 1294 1329 1303 1228 1269 1306 1263 1311 1251 1283 1268 1203 1178 1283 1149 1205 1184 1176 1177 1213 1207 1158 1146 1079 1197 1224 1212 1186 1113 1154 1146 1179 1177 1139 1088 1148 1107 1147 1155 1117 1139 1075 1100 1128 1037 1179 1107 1178 1055 1123 1156 1138 1143 1134 1129 1148 1142 1175 1126 1145 1079 1098 1032 1163 1114 1140 1107 1084 1128 1086 1079 1124 1128 1091 1164 1124 1165 1153 1142 1153 1163 1175 1121 1122 1150 1120 1133 1207 1192 1123 1159 1150 1090 1090 1188 1135 1196 1175 1177 1163 1138 1184 1146 1110 1150 1185 1171 1167 1137 1145 1097 1107 1141 1185 1183 1134 1137 1120 1117 1151 1178 1136 1160 1151 1122 1147 1126 1190 1135 1204 1092 1195 1243 1130 1159 1158 1204 1116 1187 1084 1137 1097 1200 1136 1136 1154 1090 1064 1177 1113 1140 1138 1105 1140 1088 1061 1105 1102 1115 1136 1116 1097 1103 1112 1084 1074 1057 1074 1107 1081 1131 1076 1126 1120 1113 1090 1173 1087 1118 1100 1113 1131 1096 1073 1091 1080 1112 1092 1129 1106 1084 1110 1069 1096 1061 1118 1092 1040 1106 1125 1152 1129 1103 1119 1109 1220 1067 1145 1104 1153 1145 1146 1135 1193 1141 1188 1191 1213 1133 1183 1227 1238 1208 1195 1224 1183 1149 1204 1173 1221 1215 1188 1219 1177 1292 1254 1211 1252 1316 1306 1297 1226 1310 1352 1427 1363 1347 1439 1452 1472 1534 1653 1643 1635 1754 1762 1929 1978 1975 2071 2134 2267 2297 2445 2478 2543 2575 2713 2605 2802 2525 2362 2389 2201 2101 2042 2049 1972 2107 1961 1956 1826 1789 1632 1591 1587 1457 1504 1437 1455 1469 1415 1326 1402 1447 1493 1434 1427 1421 1391 1470 1417 1477 1417 1530 1470 1546 1557 1599 1683 1662 1713 1770 1744 1833 1911 1946 2128 2091 2232 2231 2354 2422 2426 2566 2478 2560 2481 2503 2491 2497 2465 2524 2399 2428 2410 2391 2279 2372 2374 2229 2258 2273 2323 2275 2405 2411 2499 2593 2747 2909 3005 3280 3651 3997 4386 5191 5942 6850 8090 9340 11191 12992 15115 16792 17985 19101 19033 17820 15702 13775 12109 11200 10835 10722 10969 11039 10963 10812 9917 8496 7149 5935 4923 4160 3619 3196 2883 2661 2453 2350 2169 2153 2026 2010 1885 1942 1874 1801 1844 1827 1730 1788 1762 1724 1808 1817 1814 1852 1848 1856 1850 1985 2106 2046 2272 2362 2532 2840 3208 3538 3927 4577 5399 6165 7075 8160 8752 9401 9538 9286 8530 7759 6693 6059 5777 5653 5619 5852 5832 5876 5538 5247 4571 3935 3418 2954 2624 2314 2144 2042 1881 1755 1761 1658 1670 1585 1527 1479 1522 1343 1435 1467 1400 1384 1341 1375 1282 1280 1321 1229 1267 1287 1280 1269 1251 1206 1295 1276 1230 1198 1200 1219 1180 1203 1200 1292 1191 1207 1132 1148 1136 1186 1211 1177 1176 1178 1207 1208 1215 1204 1159 1178 1217 1180 1168 1206 1180 1222 1220 1212 1201 1205 1194 1104 1125 1228 1197 1138 1189 1122 1142 1154 1171 1206 1150 1173 1202 1173 1201 1168 1187 1161 1182 1134 1186 1212 1167 1163 1086 1196 1127 1205 1127 1145 1138 1178 1165 1143 1205 1163 1152 1201 1181 1179 1216 1230 1241 1260 1284 1282 1321 1362 1523 1522 1583 1712 1736 1785 1779 1844 1819 1753 1745 1662 1628 1545 1472 1503 1532 1521 1517 1490 1500 1525 1470 1418 1359 1364 1358 1283 1260 1349 1219 1213 1178 1212 1193 1192 1186 1219 1271 1239 1284 1272 1294 1273 1213 1267 1310 1329 1194 1259 1301 1256 1289 1328 1258 1356 1229 1314 1258 1323 1344 1289 1314 1348 1350 1275 1338 1415 1423 1429 1345 1502 1419 1486 1509 1556 1583 1594 1599 1711 1625 1742 1778 1681 1687 1752 1783 1719 1755 1816 1860 1804 1950 1917 2102 2230 2208 2242 2369 2555 2712 2918 3060 3294 3490 3777 4022 4235 4313 4474 4513 4480 4406 4381 4066 4044 3986 3772 3687 3715 3368 3424 3229 3215 3104 2930 2814 2506 2469 2333 2236 2153 2036 1944 1878 1769 1761 1703 1690 1717 1640 1646 1677 1672 1748 1731 1780 1709 1624 1642 1652 1555 1633 1579 1520 1613 1537 1559 1581 1560 1597 1498 1571 1600 1582 1503 1545 1571 1572 1687 1648 1706 1706 1776 1908 1870 1998 2171 2158 2466 2566 2779 2926 3204 3571 3912 4371 4653 4978 5169 5320 5490 5340 5355 5232 5022 4810 4609 4484 4351 4374 4185 4204 4024 3894 3818 3626 3492 3212 2997 2924 2616 2634 2572 2427 2409 2348 2499 2454 2476 2511 2667 2776 2795 2894 3049 3166 3213 3408 3390 3498 3432 3469 3307 3275 3104 3065 3032 2994 2790 2850 2744 2820 2704 2647 2519 2433 2362 2282 2336 2139 2173 2019 2050 2061 2129 2060 2105 2185 2263 2393 2627 2706 2882 3044 3026 3004 2893 2676 2384 2353 2321 2212 2289 2214 2341 2348 2389 2382 2381 2359 2224 2159 2204 2144 2172 2187 2130 2192 2132 2054 2136 2129 2121 2071 2031 2003 2015 1991 2009 1842 1931 1908 1855 1821 1754 1757 1583 1644 1606 1596 1505 1501 1501 1510 1487 1384 1377 1455 1396 1287 1323 1260 1312 1306 1278 1289 1275 1215 1267 1223 1317 1229 1294 1302 1237 1272 1268 1241 1226 1241 1234 1227 1221 1239 1266 1216 1268 1202 1196 1218 1262 1212 1308 1253 1230 1181 1311 1221 1261 1180 1233 1202 1186 1164 1231 1229 1246 1225 1214 1243 1222 1168 1184 1173 1203 1151 1216 1200 1097 1161 1175 1145 1212 1192 1158 1212 1133 1139 1172 1155 1087 1221 1144 1145 1109 1209 1155 1201 1106 1106 1153 1196 1202 1137 1124 1177 1236 1190 1148 1263 1176 1189 1156 1197 1188 1124 1266 1142 1170 1154 1124 1174 1139 1149 1156 1154 1113 1215 1186 1153 1147 1199 1140 1200 1125 1154 1159 1167 1135 1166 1191 1174 1188 1146 1080 1098 1121 1149 1149 1146 1204 1176 1106 1166 1173 1267 1189 1319 1217 1203 1188 1216 1176 1198 1221 1209 1225 1245 1239 1276 1299 1283 1279 1247 1312 1384 1353 1360 1466 1477 1507 1547 1535 1582 1631 1672 1712 1564 1544 1524 1594 1554 1442 1495 1420 1538 1517 1549 1494 1533 1534 1503 1436 1453 1451 1418 1482 1460 1485 1511 1453 1484 1534 1554 1590 1602 1553 1655 1741 1713 1771 1782 1818 1782 1978 2014 2116 2171 2293 2383 2751 2783 3164 3386 3955 4439 5174 5923 6890 7886 8970 9978 10794 11393 11244 10575 9783 8666 7531 6981 6565 6718 6774 7050 7536 7810 7891 8012 7599 7271 6595 5820 5247 4549 4232 3815 3694 3467 3260 3179 2997 2937 2881 2730 2720 2532 2491 2363 2287 2247 2050 2018 1970 1925 1809 1815 1823 1705 1740 1610 1647 1610 1599 1615 1623 1572 1553 1504 1597 1563 1546 1642 1643 1610 1591 1582 1617 1668 1697 1654 1627 1610 1724 1686 1748 1761 1784 1789 1758 1806 1855 1837 1794 1840 1826 1970 2066 2018 2016 2054 2082 2168 2232 2254 2281 2344 2480 2662 2765 2881 3152 3342 3761 4120 4563 5284 6262 7079 8386 10053 11734 13230 15407 16828 17903 17665 16765 15019 13059 11424 10214 9794 9410 9744 10211 10928 11611 12214 12584 12158 11456 10542 9459 8459 7357 6853 6189 5762 5490 5073 4961 4687 4678 4436 4418 4308 4347 4275 4092 4104 3917 3770 3692 3618 3582 3296 3235 3067 2948 2956 2799 2772 2662 2607 2522 2471 2501 2385 2404 2259 2251 2268 2244 2206 2218 2280 2223 2273 2285 2349 2498 2550 2568 2759 2709 2851 2763 2754 2800 2790 2642 2625 2580 2536 2452 2463 2428 2340 2518 2336 2220 2270 2237 2027 2066 1991 1907 1819 1811 1684 1727 1640 1616 1517 1486 1489 1487 1459 1475 1352 1428 1426 1319 1336 1388 1358 1340 1376 1372 1351 1343 1335 1334 1329 1328 1317 1364 1365 1405 1374 1365 1351 1356 1381 1366 1431 1427 1371 1315 1414 1400 1375 1397 1324 1378 1363 1375 1439 1376 1436 1389 1356 1398 1331 1430 1401 1410 1405 1457 1448 1483 1481 1527 1438 1504 1433 1493 1493 1527 1514 1667 1576 1561 1600 1632 1633 1706 1699 1694 1873 1861 1899 1987 2119 2180 2238 2365 2453 2465 2519 2592 2671 2715 2861 2860 2894 2858 2783 2857 2927 3034 3075 3195 3397 3634 3927 4366 4955 5409 5900 6829 7379 8199 8406 8329 7920 7181 6191 5567 4793 4337 4119 4144 4303 4373 4591 4957 4994 5188 4965 4493 3910 3448 2980 2698 2489 2334 2075 1974 1937 1781 1851 1864 1778 1780 1843 1781 1829 1855 1856 1962 1914 1969 2138 2140 2145 2155 2268 2262 2266 2296 2270 2148 2210 2211 2175 2264 2117 2041 2062 2075 2039 1986 2029 1934 1954 1967 1895 1839 1771 1858 1766 1769 1769 1818 1779 1738 1707 1844 1839 1863 1922 1978 1881 1967 1930 1940 1866 1797 1777 1853 1682 1696 1658 1752 1654 1691 1723 1709 1589 1635 1538 1577 1462 1543 1497 1473 1463 1392 1429 1416 1393 1399 1389 1491 1420 1382 1463 1549 1492 1662 1707 1768 1910 2002 1934 1985 1961 1887 1822 1652 1549 1576 1540 1454 1492 1513 1549 1534 1594 1642 1638 1635 1458 1460 1424 1384 1333 1376 1275 1249 1230 1287 1181 1178 1256 1254 1270 1212 1234 1242 1198 1184 1180 1262 1240 1186 1237 1318 1239 1257 1310 1369 1354 1419 1502 1497 1585 1621 1610 1579 1450 1581 1492 1432 1371 1403 1309 1365 1370 1440 1484 1447 1473 1475 1475 1456 1422 1413 1411 1388 1379 1320 1402 1390 1414 1460 1454 1456 1461 1525 1573 1546 1639 1759 1686 1774 1980 2017 2083 2181 2238 2373 2527 2502 2546 2633 2745 2630 2657 2657 2600 2549 2596 2495 2604 2630 2639 2691 2637 2692 2740 2733 2772 2712 2647 2696 2710 2717 2583 2623 2489 2452 2371 2389 2319 2254 2171 2176 2108 2074 2142 2080 2055 1949 1929 1836 1766 1837 1704 1672 1647 1671 1629 1466 1514 1469 1520 1503 1453 1452 1424 1379 1371 1369 1352 1393 1338 1266 1338 1319 1398 1325 1429 1454 1430 1456 1429 1454 1484 1569 1494 1518 1515 1527 1553 1481 1509 1485 1525 1506 1568 1572 1487 1434 1527 1471 1462 1467 1402 1456 1413 1375 1427 1360 1404 1386 1384 1333 1375 1348 1291 1218 1313 1299 1216 1235 1276 1284 1238 1255 1240 1242 1272 1293 1249 1304 1285 1424 1320 1414 1347 1421 1491 1391 1517 1538 1660 1678 1755 1725 1726 1792 1838 1927 2000 2084 1977 2154 2022 2081 2105 2099 2034 2132 2004 1900 1922 1894 1818 1861 1977 1864 1869 1937 1829 1888 1773 1878 1713 1833 1828 1722 1694 1697 1704 1754 1721 1727 1831 1890 1876 2003 2019 2177 2061 2122 2105 2027 1975 1961 1959 2030 2109 2112 2162 2244 2278 2331 2476 2536 2696 2597 2525 2569 2555 2496 2315 2368 2201 2221 2104 2082 2069 1962 1998 1931 1988 1885 1809 1829 1800 1684 1659 1657 1663 1580 1580 1462 1432 1412 1370 1386 1306 1293 1310 1263 1245 1263 1312 1285 1218 1313 1250 1214 1274 1220 1231 1273 1173 1278 1273 1282 1284 1205 1241 1216 1252 1271 1338 1336 1341 1348 1372 1429 1389 1397 1463 1390 1541 1450 1483 1584 1549 1657 1691 1763 1750 1771 1848 2068 2081 2185 2254 2291 2465 2319 2431 2488 2442 2593 2504 2568 2423 2530 2338 2334 2233 2200 2196 2165 2047 2093 2092 2055 2009 1944 1922 1821 1833 1846 1707 1679 1615 1479 1541 1544 1442 1452 1407 1347 1329 1280 1332 1244 1285 1205 1260 1087 1190 1092 1136 1098 1140 1137 1180 1099 1187 1105 1099 1064 1043 1057 1066 1082 1020 1089 1143 1131 1161 1005 1053 1052 1056 1038 1013 1097 1039 1046 1022 1082 1082 1052 1075 1051 1010 1012 1048 1028 1079 1050 1083 1072 1021 1046 1073 1062 1098 1077 1091 1036 1123 1071 1076 1084 1120 1113 1147 1134 1121 1142 1143 1187 1145 1225 1230 1219 1207 1281 1304 1307 1309 1237 1451 1403 1360 1448 1404 1399 1343 1481 1504 1469 1470 1555 1578 1615 1648 1702 1667 1738 1648 1676 1577 1612 1656 1522 1528 1541 1589 1503 1508 1526 1533 1424 1425 1463 1367 1389 1301 1302 1296 1298 1268 1257 1237 1204 1248 1174 1147 1204 1083 1184 1117 1212 1066 1150 1091 1045 1109 1078 1123 1087 1044 1075 1125 1084 1087 1093 1063 1064 1099 1094 1117 1045 1107 1116 1102 1082 1102 1135 1109 1134 1141 1177 1141 1173 1160 1202 1233 1166 1211 1204 1152 1185 1176 1167 1158 1200 1144 1161 1208 1119 1269 1176 1204 1252 1286 1294 1224 1303 1264 1259 1354 1334 1425 1423 1512 1459 1551 1564 1580 1523 1592 1646 1556 1620 1570 1558 1605 1569 1486 1705 1582 1569 1614 1679 1679 1816 1837 1871 1923 2062 1985 2154 2152 2307 2322 2445 2404 2451 2526 2468 2445 2481 2540 2484 2512 2437 2361 2381 2343 2473 2294 2382 2424 2397 2506 2477 2634 2790 2872 2940 2944 3006 2951 2949 2710 2582 2424 2246 2033 1952 1851 1730 1719 1812 1746 1799 1844 1863 1821 1862 1778 1713 1676 1578 1501 1453 1349 1390 1298 1266 1231 1197 1213 1205 1075 1128 1166 1097 1099 1048 1108 1056 1050 1045 1048 1069 1065 1080 1044 1031 988 1007 1006 990 999 1069 1084 976 1078 1039 1016 958 993 1045 1031 1048 1092 1024 1061 1019 1055 1105 1152 1138 1086 1062 996 1053 1031 1052 976 997 1040 1034 1077 998 1009 1077 1042 1012 1026 1028 1079 1017 965 1034 997 973 961 1000 1036 979 1052 1055 969 1024 979 969 1050 1017 1053 1036 1075 1117 1124 1164 1132 1104 1044 1130 1058 1013 1044 955 1038 1016 990 1033 1030 1087 1048 1055 1062 1042 985 1059 1016 1011 1044 1044 1029 1061 966 1034 1047 1054 1057 1074 986 1076 1046 1056 1061 1050 1032 1032 1102 957 1036 1058 1032 1040 1053 1078 1092 1042 1047 1101 1063 1046 1149 1071 1081 1049 1083 1096 1120 1109 1123 1163 1156 1115 1123 1114 1193 1165 1209 1319 1358 1310 1486 1560 1717 1879 2005 2187 2343 2552 2741 2734 2625 2578 2191 2071 1918 1686 1648 1637 1592 1548 1613 1588 1693 1818 1824 1797 1910 1954 1850 1747 1624 1576 1455 1338 1226 1331 1195 1226 1162 1124 1102 1124 1069 1152 1086 1132 1087 1094 1055 1162 1031 1109 1078 1058 1116 1047 1101 1088 1077 1078 1139 1130 1134 1168 1260 1276 1353 1380 1387 1540 1583 1588 1696 1594 1456 1537 1533 1404 1374 1312 1420 1437 1429 1445 1490 1496 1537 1579 1685 1628 1635 1682 1658 1561 1501 1543 1461 1330 1341 1304 1336 1231 1322 1249 1250 1218 1281 1296 1247 1270 1302 1226 1235 1128 1214 1198 1157 1105 1127 1042 1030 1076 1005 1122 1070 1069 1035 1064 1035 1074 1028 1033 1052 1069 1077 1059 1103 1052 1099 1085 1088 1057 1066 1014 1110 1078 1097 1096 1097 1132 1155 1109 1079 1009 1078 1115 1068 1124 1116 1156 1049 1054 1094 1095 1087 1132 1087 1076 1056 1100 1118 1083 1091 1034 1055 1109 1134 1138 1084 1111 1118 1101 1124 1119 1126 1078 1126 1002 1097 1052 1034 1014 1069 1105 1045 1046 1145 1094 1131 1103 1135 1130 1068 1135 1119 1086 1062 1047 1068 1072 1030 1086 1073 1062 1068 1080 1074 1025 1073 1076 1035 1081 1080 1148 1159 1194 1264 1245 1258 1277 1363 1417 1321 1486 1424 1312 1318 1341 1320 1193 1217 1170 1168 1121 1171 1164 1157 1183 1197 1190 1279 1311 1263 1239 1263 1261 1241 1171 1234 1139 1191 1125 1191 1094 1181 1172 1241 1186 1154 1242 1222 1276 1235 1295 1251 1310 1364 1313 1400 1443 1431 1519 1633 1612 1578 1583 1613 1651 1625 1670 1658 1733 1756 1765 1637 1787 1788 1802 1881 1804 1881 1792 1870 1859 1789 1798 1839 1726 1706 1686 1658 1611 1547 1491 1489 1475 1378 1430 1410 1380 1384 1373 1340 1417 1322 1345 1324 1282 1217 1160 1194 1156 1161 1176 1131 1143 1152 1091 1098 1090 1123 1153 1110 1136 1118 1114 1107 1139 1137 1082 1081 1126 1099 1121 1101 1068 1144 1057 1120 1171 1113 1206 1192 1277 1270 1324 1272 1371 1256 1357 1398 1380 1336 1325 1291 1340 1349 1287 1322 1261 1374 1324 1358 1370 1402 1445 1380 1360 1379 1436 1296 1335 1263 1335 1350 1300 1265 1304 1190 1321 1258 1152 1299 1276 1301 1245 1336 1260 1300 1346 1233 1219 1212 1246 1259 1281 1247 1288 1292 1308 1388 1412 1440 1338 1329 1372 1402 1399 1452 1330 1343 1400 1423 1435 1455 1454 1430 1462 1463 1468 1440 1415 1420 1410 1341 1378 1389 1406 1392 1347 1472 1351 1269 1378 1302 1336 1305 1200 1264 1218 1243 1282 1265 1256 1235 1162 1237 1110 1168 1149 1144 1091 1195 1118 1127 1136 1160 1075 1201 1124 1162 1073 1190 1177 1189 1124 1138 1144 1126 1109 1183 1133 1119 1128 1132 1107 1171 1093 1088 1159 1188 1176 1162 1247 1150 1241 1217 1262 1282 1305 1345 1292 1272 1341 1386 1346 1326 1266 1368 1232 1316 1366 1282 1322 1308 1337 1373 1359 1416 1346 1436 1347 1369 1399 1426 1432 1402 1329 1422 1391 1458 1482 1460 1472 1574 1640 1742 1716 1873 1957 2166 2229 2468 2706 3134 3676 4188 4787 5384 5895 6291 6364 6307 5841 5331 4610 3964 3557 3148 2940 2676 2521 2589 2612 2675 2791 2877 3275 3423 3806 3986 3917 3906 3572 3319 2893 2663 2315 2095 1971 1903 1762 1620 1519 1546 1424 1406 1403 1330 1425 1351 1395 1343 1333 1271 1272 1398 1293 1288 1271 1337 1359 1395 1380 1389 1408 1406 1441 1448 1415 1500 1470 1532 1487 1519 1551 1535 1484 1483 1440 1502 1461 1409 1419 1508 1456 1444 1411 1523 1538 1630 1622 1670 1710 1828 1877 1942 2123 2210 2405 2653 2881 3172 3518 3825 3803 3797 3778 3539 3349 2998 2816 2755 2584 2541 2501 2410 2382 2423 2319 2477 2599 2651 2756 2859 2889 2891 2960 2803 2667 2601 2474 2468 2344 2438 2358 2366 2498 2566 2817 3027 3371 3510 3680 3947 3909 3784 3477 3191 2833 2529 2356 2133 1953 1890 1824 1781 1740 1887 1891 1962 2130 2180 2317 2421 2391 2443 2212 2241 1969 1828 1672 1574 1475 1426 1387 1378 1266 1246 1243 1198 1221 1254 1175 1143 1191 1129 1173 1162 1162 1251 1091 1158 1117 1099 1196 1048 1168 1180 1123 1203 1247 1217 1219 1236 1223 1328 1413 1368 1522 1599 1582 1660 1683 1590 1534 1552 1454 1434 1361 1443 1452 1326 1430 1446 1511 1469 1397 1477 1503 1550 1636 1616 1627 1689 1644 1524 1627 1612 1537 1596 1475 1453 1464 1515 1471 1425 1329 1447 1416 1374 1381 1391 1381 1378 1383 1409 1338 1340 1374 1345 1358 1344 1365 1340 1359 1359 1331 1336 1360 1420 1501 1441 1558 1625 1650 1747 1862 1943 2090 2353 2534 2754 3066 3173 3123 3106 2853 2742 2448 2113 2082 1919 1752 1782 1705 1690 1850 1646 1764 1790 1985 1956 2133 2168 2280 2319 2335 2186 2087 1970 1955 1850 1805 1673 1753 1668 1686 1688 1670 1716 1821 1861 1981 2033 2225 2404 2500 2765 2831 3137 3194 3211 2914 2811 2524 2412 2203 2091 1985 1874 1862 1791 1825 1730 1762 1806 1884 1975 2018 2089 2206 2188 2270 2099 2077 1916 1703 1697 1625 1557 1520 1521 1430 1342 1313 1355 1337 1200 1224 1259 1222 1235 1220 1267 1265 1231 1136 1225 1204 1258 1201 1258 1292 1254 1290 1210 1200 1225 1165 1253 1189 1284 1186 1171 1104 1128 1186 1161 1131 1192 1113 1171 1102 1168 1140 1215 1082 1117 1105 1125 1092 1060 1075 1103 1133 1166 1031 1088 1025 1061 1150 1094 1106 1087 1045 1069 1061 1029 1038 1063 1128 1094 1114 1111 1220 1130 1168 1152 1173 1174 1105 1129 1077 1120 1115 1147 1068 1175 1190 1138 1175 1146 1137 1228 1211 1250 1276 1276 1307 1330 1428 1462 1430 1478 1467 1430 1372 1497 1438 1410 1397 1366 1303 1380 1175 1201 1241 1245 1253 1186 1227 1354 1292 1224 1283 1236 1245 1253 1269 1232 1229 1267 1214 1225 1158 1103 1119 1125 1109 1102 1118 1050 1068 1045 1088 1055 1047 1054 1037 1061 1074 1053 1042 1010 1006 1009 996 1039 1023 1013 1015 1065 1002 1043 979 998 1053 1043 1118 1087 1075 1136 1095 1147 1069 1122 1105 1124 1123 1099 1164 1156 1185 1176 1210 1224 1209 1253 1240 1197 1167 1175 1086 1075 1086 1044 1052 1023 1094 1082 1037 1115 1101 1104 1152 1125 1177 1177 1175 1107 1083 1108 1118 1097 1097 1083 1038 1039 1026 1065 1030 1048 1127 1060 1070 1034 1026 989 1032 1035 1059 1046 1019 1067 1074 1052 1149 1113 1105 1147 1099 1144 1090 985 1109 1129 1045 1077 1075 1070 1053 1152 1122 1076 1091 1104 1100 1063 1071 1100 1114 1196 1134 1113 1126 1089 1157 1122 1206 1222 1191 1193 1228 1197 1293 1355 1341 1289 1342 1336 1211 1269 1189 1190 1262 1086 1115 1051 1190 1161 1045 1086 1096 1191 1112 1212 1124 1127 1251 1225 1133 1230 1138 1159 1177 1089 1103 1188 1153 1168 1181 1251 1193 1196 1221 1167 1228 1292 1223 1252 1132 1221 1169 1137 1165 1235 1193 1151 1209 1199 1190 1222 1270 1237 1263 1219 1259 1294 1316 1291 1336 1342 1413 1360 1467 1413 1475 1467 1448 1522 1456 1513 1558 1437 1427 1385 1414 1339 1329 1343 1184 1324 1235 1210 1252 1197 1276 1248 1278 1278 1284 1211 1298 1290 1226 1270 1128 1234 1230 1286 1137 1131 1130 1169 1128 1082 1088 1163 1088 1051 1088 1051 1101 1124 1069 1106 1062 1132 1064 1110 1147 1101 1054 1134 1129 1179 1148 1139 1127 1180 1119 1201 1138 1171 1125 1081 1064 1199 1187 1157 1126 1228 1160 1143 1134 1178 1167 1168 1180 1209 1237 1200 1137 1244 1266 1281 1252 1313 1358 1326 1318 1467 1498 1432 1509 1520 1544 1582 1567 1715 1671 1787 1754 1882 1774 1780 1750 1535 1564 1481 1525 1497 1430 1446 1447 1404 1423 1380 1438 1449 1349 1451 1444 1457 1550 1552 1630 1634 1600 1503 1524 1509 1380 1467 1466 1497 1453 1501 1481 1481 1459 1542 1517 1554 1568 1513 1520 1611 1548 1553 1571 1551 1540 1488 1400 1447 1338 1391 1349 1418 1359 1429 1413 1446 1427 1447 1387 1411 1448 1428 1441 1405 1434 1429 1361 1333 1351 1330 1251 1246 1271 1253 1219 1314 1198 1255 1176 1234 1248 1238 1199 1186 1208 1182 1287 1207 1234 1250 1253 1221 1216 1235 1273 1225 1220 1216 1255 1183 1336 1232 1280 1247 1350 1399 1315 1409 1443 1334 1412 1383 1389 1421 1427 1354 1394 1384 1394 1383 1341 1371 1420 1413 1320 1415 1477 1457 1408 1526 1456 1458 1519 1430 1509 1459 1487 1487 1507 1483 1453 1445 1504 1449 1458 1537 1491 1522 1495 1501 1443 1400 1404 1416 1393 1432 1493 1492 1480 1422 1499 1495 1535 1602 1732 1762 1909 2036 2193 2317 2580 2746 2697 2798 2717 2606 2285 2228 2067 1866 1799 1616 1596 1545 1525 1511 1424 1461 1522 1577 1578 1601 1801 1818 1989 2028 2037 2083 2064 1946 1952 1921 1791 1714 1618 1511 1462 1453 1401 1406 1376 1300 1350 1243 1270 1195 1256 1228 1297 1241 1265 1263 1171 1231 1281 1285 1256 1260 1265 1292 1311 1290 1318 1347 1366 1479 1465 1584 1525 1544 1529 1554 1405 1412 1269 1285 1240 1286 1153 1191 1138 1215 1135 1187 1104 1096 1128 1179 1194 1178 1270 1296 1353 1305 1335 1316 1336 1269 1283 1359 1272 1295 1296 1270 1325 1354 1393 1346 1313 1437 1253 1378 1330 1287 1274 1275 1286 1276 1249 1223 1363 1362 1347 1399 1463 1530 1512 1615 1739 1903 1936 2106 2209 2330 2676 2867 3226 3450 3647 3820 3900 3657 3507 3260 2749 2609 2259 2215 2178 1986 1983 1798 1772 1840 1804 1831 1844 1916 1891 2019 2092 2292 2320 2426 2486 2527 2313 2282 2044 1944 1814 1649 1614 1528 1512 1470 1394 1338 1303 1240 1294 1152 1203 1166 1146 1187 1224 1095 1136 1042 1071 1054 1149 1096 1108 1105 1024 1078 1069 1036 1038 1070 1062 1070 1046 1064 986 1078 1045 1102 1105 1135 1126 1131 1099 1128 1071 1098 1069 1020 1049 1032 1064 1037 1052 1079 1071 1067 1050 1108 1036 1119 1044 1127 1116 1211 1036 1130 1145 1134 1189 1136 1211 1165 1207 1169 1285 1182 1201 1203 1148 1156 1171 1080 1060 1075 1159 1126 1098 1191 1218 1188 1217 1261 1326 1302 1355 1347 1348 1351 1405 1396 1324 1304 1332 1236 1254 1269 1291 1246 1299 1283 1210 1200 1249 1228 1163 1167 1233 1203 1219 1216 1148 1192 1176 1188 1267 1225 1180 1169 1172 1185 1229 1141 1181 1162 1121 1191 1140 1206 1158 1156 1204 1159 1145 1200 1253 1225 1153 1202 1217 1183 1226 1232 1232 1247 1262 1279 1286 1310 1284 1327 1371 1396 1389 1359 1348 1398 1387 1326 1377 1296 1362 1349 1406 1377 1308 1310 1302 1248 1277 1319 1239 1427 1331 1360 1368 1422 1384 1333 1389 1375 1417 1410 1496 1449 1432 1420 1412 1389 1367 1508 1416 1434 1401 1362 1390 1347 1351 1368 1272 1292 1296 1319 1336 1229 1218 1321 1312 1294 1267 1254 1250 1243 1264 1260 1231 1185 1244 1258 1221 1224 1244 1214 1125 1155 1189 1157 1135 1128 1091 1117 1081 1106 1112 1123 1034 1117 1075 1088 1111 1111 1110 1071 1091 1072 1059 1137 1083 1104 1050 1071 1142 1066 1094 1078 1119 1161 1147 1120 1184 1213 1189 1209 1147 1178 1195 1202 1087 1115 1188 1177 1095 1150 1177 1141 1135 1112 1181 1179 1251 1191 1210 1166 1271 1186 1205 1206 1253 1209 1245 1255 1239 1295 1251 1284 1288 1370 1321 1431 1410 1301 1411 1403 1474 1308 1371 1446 1428 1458 1451 1499 1478 1407 1426 1373 1411 1512 1458 1501 1384 1434 1423 1436 1441 1410 1385 1454 1405 1417 1430 1501 1369 1441 1446 1561 1548 1558 1702 1720 1768 1931 1982 2250 2355 2447 2509 2468 2527 2417 2228 2067 1847 1868 1677 1565 1515 1376 1374 1386 1464 1331 1337 1333 1381 1472 1430 1470 1423 1600 1612 1743 1719 1700 1757 1774 1700 1606 1542 1451 1409 1365 1263 1189 1238 1217 1232 1251 1144 1161 1196 1151 1189 1153 1092 1173 1104 1136 1092 1101 1088 1093 1142 1093 1130 1154 1130 1116 1050 1104 1063 1099 1134 1122 1085 1092 1140 1090 1145 1109 1126 1082 1015 1068 1153 1078 992 1042 1040 1048 1045 1079 1047 1062 1116 1066 1105 1102 1119 1127 1100 1122 1139 1170 1135 1186 1177 1241 1152 1215 1261 1229 1218 1238 1159 1190 1230 1210 1211 1160 1152 1115 1136 1077 1147 1143 1122 1146 1197 1109 1163 1158 1216 1186 1240 1202 1219 1300 1353 1337 1345 1418 1391 1352 1306 1275 1245 1184 1151 1217 1178 1133 1079 1086 1018 1105 1089 1108 1119 1036 1161 1112 1169 1117 1147 1185 1164 1126 1186 1206 1196 1179 1215 1189 1214 1178 1167 1216 1255 1335 1340 1386 1521 1555 1717 1837 1973 2074 2099 2103 2115 1972 1928 1773 1623 1617 1439 1384 1353 1348 1306 1264 1241 1190 1211 1226 1190 1167 1189 1243 1266 1308 1435 1421 1563 1519 1623 1497 1506 1521 1457 1338 1310 1271 1265 1124 1131 1101 1124 1079 1115 1047 1089 1059 1062 1047 1072 1120 983 1092 1039 1008 1080 1024 1027 1048 1013 1059 1052 1130 1009 1195 1091 1124 1096 1083 1159 1144 1193 1262 1187 1196 1207 1228 1313 1239 1251 1331 1503 1441 1540 1664 1650 1901 1975 2169 2373 2475 2727 2894 2936 2886 2645 2610 2320 2194 2169 2000 1852 1866 1833 1830 1849 1726 1678 1729 1665 1684 1626 1613 1691 1636 1692 1694 1777 1871 1997 2024 1992 2005 1892 1818 1763 1660 1670 1552 1540 1546 1495 1435 1418 1379 1373 1420 1350 1366 1300 1346 1254 1252 1205 1260 1258 1203 1281 1287 1185 1307 1250 1290 1209 1219 1187 1206 1218 1175 1235 1220 1219 1212 1168 1189 1136 1214 1170 1113 1154 1111 1175 1160 1051 1182 1137 1114 1141 1160 1145 1121 1163 1172 1154 1113 1126 1145 1105 1119 1122 1134 1116 1127 1119 1124 1099 1062 1088 1120 1064 1101 1094 1043 1027 1112 1134 1082 1073 1034 1071 1095 1064 1063 1036 1070 1062 1051 1061 1091 1099 1117 1066 1091 1127 1086 1113 1137 1222 1172 1200 1234 1225 1342 1306 1357 1297 1346 1389 1255 1353 1367 1302 1220 1240 1222 1240 1311 1176 1260 1220 1168 1154 1213 1297 1223 1190 1085 1226 1224 1279 1291 1253 1243 1374 1248 1326 1367 1354 1308 1338 1330 1377 1316 1353 1285 1394 1287 1296 1329 1312 1306 1278 1384 1259 1289 1247 1254 1217 1247 1267 1262 1251 1281 1216 1200 1254 1172 1185 1127 1156 1200 1147 1138 1205 1210 1134 1206 1100 1108 1132 1198 1145 1154 1112 1127 1062 1110 1068 1157 1100 1129 1083 1066 1055 1066 1072 1128 1063 1018 1072 1097 1087 1085 1070 1107 1099 1066 1136 1119 1152 1090 1181 1106 1177 1143 1170 1172 1132 1086 1162 1138 1140 1174 1116 1174 1176 1158 1218 1228 1284 1253 1231 1219 1261 1234 1297 1234 1363 1291 1377 1337 1410 1279 1307 1417 1351 1236 1291 1345 1318 1306 1331 1276 1247 1282 1281 1230 1237 1220 1273 1277 1288 1282 1325 1346 1340 1343 1357 1416 1400 1453 1453 1415 1436 1456 1493 1428 1499 1472 1462 1545 1506 1483 1472 1443 1464 1426 1465 1482 1486 1502 1443 1465 1502 1498 1487 1499 1405 1416 1374 1440 1506 1457 1506 1456 1421 1436 1495 1464 1535 1464 1509 1562 1544 1508 1565 1535 1511 1518 1556 1549 1557 1438 1435 1420 1424 1377 1390 1405 1316 1322 1329 1273 1303 1337 1266 1245 1244 1217 1285 1309 1256 1289 1229 1283 1289 1328 1277 1346 1282 1306 1275 1270 1205 1228 1233 1221 1148 1165 1162 1243 1146 1199 1156 1108 1154 1145 1113 1143 1127 1065 1058 1119 1059 1064 1107 1108 1113 1065 1105 1121 1078 1079 1117 1056 1162 1081 1165 1115 1120 1138 1173 1202 1202 1301 1313 1252 1298 1276 1262 1218 1199 1251 1184 1182 1223 1201 1223 1160 1251 1237 1286 1228 1261 1247 1382 1283 1290 1322 1239 1333 1279 1216 1273 1263 1330 1333 1248 1262 1264 1201 1180 1200 1237 1266 1102 1206 1203 1161 1215 1162 1268 1117 1227 1175 1223 1160 1167 1174 1209 1135 1205 1185 1172 1182 1183 1128 1137 1154 1131 1184 1108 1152 1101 1198 1169 1238 1155 1201 1169 1288 1150 1298 1279 1230 1246 1220 1256 1184 1258 1293 1301 1222 1265 1237 1226 1208 1257 1254 1189 1231 1259 1243 1223 1230 1196 1236 1155 1238 1136 1200 1218 1246 1243 1178 1217 1238 1252 1195 1248 1273 1257 1313 1251 1271 1280 1245 1320 1300 1241 1327 1329 1385 1232 1434 1325 1438 1389 1391 1338 1432 1375 1418 1373 1409 1412 1357</counts>
			</dataPoints>
		</scan>
	</xrdMeasurement>
</xrdMeasurements>