File: dataset/precursor_mixture/HfO2_K2SO4_Bi2O3-beta.12-min.xrdml
<?xml version="1.0"?>
<xrdMeasurements xmlns="http://www.xrdml.com/XRDMeasurement/2.2" xmlns:xsi="http://www.w3.org/2001/XMLSchema-instance" xsi:schemaLocation="http://www.xrdml.com/XRDMeasurement/2.2 http://www.xrdml.com/XRDMeasurement/2.2/XRDMeasurement.xsd" status="Completed" recordIdentifier="{CB779C8B-865C-4533-8C36-E851FDB223EE}">
	<comment>
		<entry/>
	</comment>
	<sample type="To be analyzed">
		<id>dara-40-2</id>
		<name></name>
		<preparedBy></preparedBy>
	</sample>
	<xrdMeasurement measurementType="Scan" status="Completed" sampleMode="Reflection">
		<usedWavelength intended="K-Alpha 1">
			<kAlpha1 unit="Angstrom">1.5405980</kAlpha1>
			<kAlpha2 unit="Angstrom">1.5444260</kAlpha2>
			<kBeta unit="Angstrom">1.3922500</kBeta>
			<ratioKAlpha2KAlpha1>0.5000</ratioKAlpha2KAlpha1>
		</usedWavelength>
		<incidentBeamPath>
			<radius unit="mm">145.00</radius>
			<xRayTube id="1010048" name="Empyrean Cu LFF HR (9430 033 7310x) DK437873">
				<tension unit="kV">40.0</tension>
				<current unit="mA">15.0</current>
				<anodeMaterial>Cu</anodeMaterial>
				<focus type="Line">
					<length unit="mm">12.0</length>
					<width unit="mm">0.4</width>
					<takeOffAngle unit="deg">6.0</takeOffAngle>
				</focus>
			</xRayTube>
			<filter id="20010004" name="Beta-filter Nickel">
				<material>Ni</material>
				<thickness unit="mm">0.020</thickness>
			</filter>
			<sollerSlit id="21010002" name="Soller slits 0.04 rad.">
				<opening unit="rad">0.0400</opening>
			</sollerSlit>
			<mask id="22031000" name="Fixed mask 13 mm">
				<width unit="mm">9.00</width>
			</mask>
			<divergenceSlit id="22120001" name="Divergence slit 1°" xsi:type="fixedDivergenceSlitType">
				<distanceToSample unit="mm">50.00</distanceToSample>
				<height unit="mm">1.52</height>
			</divergenceSlit>
		</incidentBeamPath>
		<beamKnife id="29030100" name="Beam knife low"/>
		<sampleMovement xsi:type="spinningSampleMovementType">
			<spinnerRevolutionTime unit="seconds">1.0</spinnerRevolutionTime>
		</sampleMovement>
		<diffractedBeamPath>
			<radius unit="mm">145.00</radius>
			<antiScatterSlit id="22090040" name="AS slit 9 mm" xsi:type="fixedAntiScatterSlitType">
				<height unit="mm">9.00</height>
			</antiScatterSlit>
			<sollerSlit id="21020003" name="Large Soller slits 0.04 rad.">
				<opening unit="rad">0.0400</opening>
			</sollerSlit>
			<filter id="20030001" name="Large beta-filter Nickel">
				<material>Ni</material>
				<thickness unit="mm">0.020</thickness>
			</filter>
			<detector id="7010019" name="PIXcel1D-Medipix3 detector" xsi:type="rtmsDetectorType">
				<phd unit="keV">
					<lowerLevel>4.0</lowerLevel>
					<upperLevel>11.3</upperLevel>
				</phd>
				<mode>Scanning</mode>
				<activeLength unit="deg">5.020</activeLength>
			</detector>
		</diffractedBeamPath>
		<scan appendNumber="0" mode="Continuous" scanAxis="Gonio" status="Completed">
			<header>
				<startTimeStamp>2024-03-24T18:55:12-07:00</startTimeStamp>
				<endTimeStamp>2024-03-24T19:07:39-07:00</endTimeStamp>
				<author>
					<name>AutomatedUser</name>
				</author>
				<source>
					<applicationSoftware version="1.6 (94)">PANalytical Aeris Instrument Suite</applicationSoftware>
					<instrumentControlSoftware version="3.0.0 20211014">AERIS</instrumentControlSoftware>
					<instrumentID>2879380</instrumentID>
				</source>
			</header>
			<dataPoints>
				<positions axis="2Theta" unit="deg">
					<startPosition>9.99043322</startPosition>
					<endPosition>100.09495370</endPosition>
				</positions>
				<positions axis="Omega" unit="deg">
					<startPosition>4.99521661</startPosition>
					<endPosition>50.04747685</endPosition>
				</positions>
				<commonCountingTime unit="seconds">18.249</commonCountingTime>
				<counts unit="counts">3965 4098 3950 4068 4069 4051 3934 3989 4053 3959 3916 4042 4069 3998 4008 3941 4008 3923 3957 3939 3989 3875 3900 4000 3939 3979 3839 3915 3879 3821 3767 3904 3835 3926 3752 3962 3818 3778 3820 3848 3869 3804 3965 3891 3942 3894 3783 3864 3807 3679 3865 3854 3687 3855 3847 3645 3862 3652 3885 3811 3773 3775 3763 3721 3735 3685 3740 3704 3727 3865 3626 3819 3691 3747 3669 3741 3695 3837 3697 3624 3625 3669 3707 3746 3712 3641 3611 3657 3686 3661 3645 3589 3654 3709 3687 3727 3639 3587 3607 3718 3564 3620 3650 3634 3606 3583 3707 3643 3450 3562 3653 3474 3503 3465 3584 3510 3456 3614 3556 3624 3542 3456 3563 3469 3483 3442 3475 3425 3568 3407 3507 3445 3425 3476 3425 3437 3459 3450 3420 3509 3390 3446 3485 3498 3412 3330 3501 3371 3402 3306 3353 3398 3398 3419 3279 3330 3427 3343 3469 3367 3382 3403 3328 3400 3349 3251 3269 3311 3346 3253 3354 3295 3234 3385 3266 3288 3397 3171 3214 3269 3224 3169 3212 3251 3295 3257 3316 3231 3334 3336 3359 3277 3275 3257 3275 3271 3196 3185 3244 3327 3205 3189 3285 3211 3214 3119 3217 3231 3282 3261 3224 3177 3277 3083 3121 3071 3181 3052 3176 3112 3146 3102 3103 3130 3107 3191 3178 3098 3071 3037 3117 3103 3058 3127 3118 3146 3034 3048 3130 3166 3084 3015 3075 3107 3022 3130 3151 3092 3047 2945 3083 3069 3144 3045 3082 3021 3039 3039 3126 3023 3039 3054 2995 3086 3040 3078 3028 3130 3172 3153 3083 3179 3043 3065 3051 2977 2896 2964 2992 2990 3101 3056 2890 3040 2989 2967 3020 2958 2965 2882 3007 2954 2812 2931 2870 3037 2948 2953 2836 2861 2930 2928 2982 2868 2924 2946 2891 2756 2922 2839 2778 2880 2827 2840 2818 2926 2903 2849 2806 2794 2950 2792 2928 2858 2767 2742 2833 2748 2802 2771 2843 2937 2810 2717 2761 2693 2776 2836 2810 2758 2796 2769 2795 2745 2687 2812 2820 2730 2693 2832 2766 2781 2804 2773 2747 2719 2712 2729 2835 2760 2742 2706 2876 2736 2789 2681 2718 2724 2648 2658 2648 2783 2813 2770 2766 2748 2698 2678 2620 2688 2654 2653 2700 2682 2719 2668 2673 2670 2621 2726 2652 2700 2692 2694 2612 2607 2719 2653 2664 2648 2736 2638 2684 2636 2626 2642 2601 2656 2660 2642 2584 2678 2560 2653 2579 2695 2756 2568 2663 2571 2618 2632 2664 2669 2598 2629 2709 2629 2694 2628 2659 2629 2669 2561 2756 2608 2610 2688 2569 2734 2564 2611 2614 2750 2643 2629 2558 2542 2618 2538 2643 2652 2635 2559 2616 2554 2586 2641 2514 2533 2544 2551 2638 2603 2577 2655 2555 2588 2543 2725 2441 2556 2595 2536 2618 2553 2502 2508 2510 2571 2510 2510 2538 2543 2500 2588 2503 2538 2509 2466 2520 2448 2411 2436 2487 2512 2528 2508 2434 2522 2498 2416 2492 2513 2506 2509 2467 2602 2535 2453 2533 2504 2523 2475 2499 2567 2432 2519 2535 2588 2485 2543 2611 2486 2507 2464 2515 2400 2478 2471 2517 2505 2474 2453 2525 2524 2494 2439 2455 2494 2414 2502 2461 2471 2491 2407 2599 2480 2474 2449 2533 2519 2557 2458 2486 2481 2458 2509 2576 2492 2565 2519 2632 2699 2680 2685 2624 2695 2623 2637 2681 2738 2838 2846 2867 2870 2810 2874 2958 2843 2858 2821 2815 2765 2746 2636 2745 2562 2559 2508 2517 2434 2471 2428 2298 2407 2445 2408 2466 2340 2364 2405 2310 2356 2321 2465 2408 2436 2351 2353 2378 2320 2362 2463 2295 2378 2286 2356 2309 2343 2405 2408 2417 2353 2273 2348 2293 2390 2303 2358 2300 2390 2290 2319 2376 2465 2416 2269 2360 2426 2345 2335 2463 2350 2372 2361 2325 2417 2388 2254 2361 2325 2323 2282 2378 2382 2416 2367 2310 2299 2337 2410 2344 2438 2371 2301 2297 2396 2406 2448 2408 2362 2472 2391 2455 2382 2497 2423 2420 2471 2398 2570 2504 2561 2547 2568 2650 2646 2704 2747 2698 2789 2831 2939 2977 2991 3001 3132 3093 3308 3360 3458 3478 3553 3583 3758 3769 3622 3718 3639 3636 3483 3238 3253 3190 2946 2838 2744 2677 2533 2646 2484 2547 2525 2538 2389 2387 2270 2275 2340 2389 2267 2202 2249 2307 2219 2216 2339 2252 2218 2198 2156 2254 2342 2298 2161 2233 2227 2245 2291 2189 2237 2175 2197 2202 2235 2179 2174 2179 2258 2286 2244 2166 2224 2318 2224 2198 2211 2188 2260 2150 2306 2212 2076 2210 2189 2131 2192 2148 2180 2261 2146 2180 2127 2185 2226 2187 2225 2140 2210 2169 2123 2114 2089 2139 2195 2156 2142 2128 2103 2128 2044 2190 2122 2165 2137 2160 2144 2191 2135 2110 2079 2121 2180 2135 2133 2171 2065 2135 2051 2097 2110 2155 2041 2097 2091 2097 2123 2085 2095 2139 2071 2066 2100 2087 2199 2132 2041 2093 2076 2015 2042 2096 2043 2116 2158 2120 2101 2174 2071 2056 2082 2039 2091 2068 2088 2135 2160 2120 2009 2001 2076 2182 2030 2066 2051 2024 1986 2045 2066 2048 2120 2059 2015 2068 2076 2014 2124 2071 2048 2081 1970 2043 2041 1989 2028 2042 1987 2014 2067 2051 2017 1999 1969 2030 2064 1968 2023 2036 2015 2066 1916 1951 2037 2035 2006 2037 1980 1963 2017 1930 1986 2052 2043 1942 2034 1946 1917 1996 1922 1954 1922 2038 1972 1966 1967 1944 2010 1947 2029 2037 1954 2074 1982 1986 1885 2021 1900 1930 1985 1918 2022 1979 2028 1969 1941 1975 1857 1929 1897 2011 1831 1979 1839 1979 1980 1902 1920 2028 1933 1913 1978 1910 1929 1911 1958 1940 1947 1972 1931 1962 1906 1960 1982 1962 1954 1919 1999 1911 1951 1911 1850 1956 1960 1941 1931 1815 1916 1908 1947 1943 2002 1862 1926 1939 1884 1936 2000 1944 1920 1927 1843 1994 1982 1901 1879 1893 1868 1872 1990 1937 1882 1967 1889 1959 1936 1937 1841 1956 1865 1943 1959 1988 1967 1985 1931 1939 2042 2026 1990 1995 2044 2101 2138 2096 2267 2409 2384 2514 2545 2674 2795 2913 3015 3101 3164 3216 3149 3043 3142 3069 2928 2994 3021 2888 2709 2658 2466 2363 2269 2161 2224 2136 2106 1991 1987 1868 1891 1937 1870 1904 1804 1838 1862 1828 1858 1865 1866 1789 1792 1842 1887 1862 1867 1876 1897 1798 1854 1868 1860 1826 1814 1845 1782 1866 1900 1751 1894 1834 1783 1846 1850 1865 1773 1815 1812 1772 1874 1827 1767 1854 1806 1808 1815 1827 1811 1830 1818 1820 1833 1809 1822 1799 1812 1848 1791 1839 1769 1840 1785 1794 1914 1813 1835 1892 1798 1863 1768 1828 1827 1799 1796 1847 1813 1777 1819 1921 1764 1808 1837 1791 1775 1813 1754 1767 1764 1785 1844 1766 1803 1752 1781 1753 1735 1775 1751 1810 1735 1725 1830 1762 1811 1762 1718 1780 1709 1754 1736 1806 1794 1753 1785 1734 1813 1774 1773 1707 1772 1688 1837 1811 1805 1806 1812 1882 1832 1863 1862 1787 1912 1898 1759 1937 1857 1847 1851 1833 1809 1845 1710 1778 1776 1745 1765 1747 1815 1722 1706 1812 1816 1764 1816 1854 1718 1759 1820 1796 1781 1765 1686 1741 1753 1763 1764 1799 1779 1759 1866 1832 1757 1774 1823 1734 1795 1817 1862 1792 1830 1888 1802 1750 1830 1826 1824 1827 1917 1793 1874 1886 1895 1928 1989 2012 2038 2111 2118 2208 2248 2249 2446 2490 2714 2773 2994 3086 3151 3299 3484 3564 3521 3358 3229 3027 2958 2865 2699 2585 2445 2392 2247 2279 2188 2229 2220 2235 2319 2388 2406 2270 2490 2590 2676 2890 2836 3059 3153 3220 3328 3663 3691 4078 4219 4318 4279 4417 4513 4541 4709 4466 4338 4258 4124 3871 3642 3405 3247 3036 2899 2717 2770 2631 2532 2440 2355 2477 2467 2443 2496 2507 2546 2741 2744 2774 2989 3037 3109 3178 3402 3682 3712 3815 3901 4047 4013 4098 3960 4016 3824 3612 3451 3303 3183 2964 2730 2626 2482 2307 2203 2255 2181 2033 2018 1982 1972 1944 1891 1908 1939 1952 1922 1810 1758 1824 1876 1782 1841 1810 1844 1853 1818 1806 1822 1714 1845 1854 1845 1766 1838 1818 1767 1823 1857 1877 1901 2005 1921 2022 1995 1914 1938 1923 1911 1902 1952 1820 1879 1851 1929 1915 1954 1825 1973 2020 1941 1955 2001 1930 2051 2015 2108 1920 2000 1914 1993 1933 1884 1975 1968 1930 2006 2050 2066 2118 2172 2235 2243 2414 2486 2574 2569 2659 2800 2836 2962 2895 3066 3129 3100 3077 2818 2834 2621 2654 2397 2353 2279 2188 1991 2049 1961 1880 1832 1843 1880 1872 1858 1860 1767 1798 1767 1813 1822 1873 1777 1762 1753 1758 1795 1897 1775 1764 1736 1876 1746 1797 1787 1791 1762 1791 1817 1808 1827 1796 1834 1905 1863 1885 1875 2036 1841 1980 1883 1945 1974 1850 1876 1953 1829 1855 1738 1833 1819 1823 1804 1734 1813 1709 1690 1785 1817 1791 1781 1725 1811 1719 1705 1778 1839 1856 1741 1674 1740 1757 1854 1724 1803 1668 1743 1668 1759 1788 1770 1831 1802 1772 1711 1773 1747 1820 1760 1885 1864 1835 1788 1828 1853 1865 1958 1929 1871 1936 1942 1992 1957 2059 2043 2012 2075 2059 2018 2076 2130 2150 2091 2184 2127 2158 2098 2200 2094 2140 2096 2200 2164 2171 2223 2245 2343 2312 2280 2269 2361 2353 2291 2419 2459 2399 2474 2527 2515 2642 2614 2624 2726 2746 2778 2864 2820 2988 3012 3004 3052 3130 3257 3264 3316 3518 3581 3711 3748 3885 3940 4147 4455 4526 4682 5025 5323 5825 6202 6643 7460 8087 8819 9927 10930 12238 13547 15286 17579 19543 22831 25740 28783 33125 36577 41264 45490 50383 54564 58280 60655 61394 60890 56255 52456 47780 43624 39432 35440 31127 26905 22690 19107 16342 14019 12387 11186 10630 10125 9685 9654 9681 10063 10500 10836 11417 11899 12689 13458 14410 15127 16188 17089 17868 18932 19257 19387 19533 19622 19086 18552 17467 16769 15850 14876 13517 12549 11144 10233 9322 8491 7808 6866 6570 6016 5354 5268 4824 4618 4304 4222 4125 4014 3717 3690 3550 3507 3422 3328 3280 3122 3044 2864 3089 2901 2780 2723 2788 2641 2648 2579 2558 2557 2467 2440 2484 2488 2389 2381 2378 2419 2365 2260 2294 2307 2413 2359 2261 2253 2269 2229 2387 2364 2265 2338 2303 2385 2387 2285 2402 2462 2308 2204 2319 2180 2187 2135 2265 2179 2097 2179 2084 2060 2088 2081 2074 2050 2111 2097 2080 2068 2028 2118 2017 2097 2019 2104 2047 2083 2095 2102 2012 2109 2072 2115 2169 2110 2151 2082 2158 2117 2247 2334 2221 2440 2623 2668 2785 2916 3037 3246 3552 3699 4107 4378 4424 4593 4584 4531 4469 4409 4394 4159 4042 3747 3480 3218 3001 2943 2673 2664 2519 2298 2195 2189 2122 2092 2183 2079 2095 2085 2154 2166 2224 2141 2136 2127 2222 2232 2220 2260 2392 2392 2394 2445 2566 2607 2671 2751 2758 2926 2941 2996 3202 3174 3306 3257 3092 3028 3088 2896 2866 2893 2658 2627 2526 2432 2372 2388 2193 2317 2173 2182 2188 2133 2245 2149 2188 2197 2227 2262 2353 2531 2445 2464 2693 2749 2877 3053 3279 3554 3746 4085 4461 4925 5327 5966 6647 7443 8299 8491 8681 8170 7382 6784 6459 6283 6213 5926 5603 4955 4791 4280 4289 4187 4375 4175 4189 4037 3943 3627 3513 3433 3338 3152 3020 2954 2856 2654 2651 2659 2524 2466 2426 2528 2428 2530 2444 2445 2639 2600 2640 2584 2665 2629 2708 2669 2808 2846 2939 2971 2991 3014 3136 3206 3270 3348 3596 3709 3933 3960 4234 4459 4700 4904 5448 5685 6075 6700 7066 7939 8500 9161 10163 10812 11927 12625 13663 14423 15521 16199 16842 17418 17931 18052 18347 18380 18402 18318 18634 18302 17486 17112 16096 14994 13772 12409 11297 10247 9711 8978 7802 6976 6263 5618 4848 4613 4140 3880 3674 3414 3442 3274 3124 2915 2910 2837 2718 2832 2620 2479 2548 2528 2422 2478 2362 2376 2345 2318 2267 2255 2231 2288 2222 2273 2228 2224 2112 2181 2220 2257 2247 2246 2251 2218 2141 2232 2372 2428 2295 2387 2494 2457 2597 2646 2788 2901 3150 3243 3540 3539 4023 4394 4596 5131 5762 6402 7064 7980 8822 10044 11416 12585 13728 14921 15775 16623 16822 16438 15376 14336 13305 12246 11462 10835 10050 9003 7798 6770 5841 5029 4394 3784 3588 3259 3073 2882 2678 2586 2519 2385 2279 2264 2219 2244 2157 2063 2032 2017 1956 1987 1921 2004 1856 1876 1886 1897 1860 1794 1802 1751 1751 1711 1647 1720 1675 1660 1706 1650 1633 1671 1555 1659 1649 1700 1669 1622 1591 1559 1568 1574 1595 1668 1596 1637 1637 1519 1546 1559 1622 1651 1638 1650 1613 1606 1587 1621 1615 1606 1682 1758 1678 1681 1781 1683 1767 1632 1617 1698 1635 1693 1622 1579 1613 1544 1601 1591 1571 1532 1586 1608 1600 1630 1634 1605 1664 1610 1662 1653 1665 1624 1714 1664 1755 1704 1793 1746 1733 1722 1782 1882 1881 1798 1915 1880 2040 2060 2034 2201 2207 2382 2445 2668 2717 2820 3003 3317 3472 3690 3772 4205 4392 4757 5019 5252 5443 5573 5677 5968 5843 5871 5650 5569 5567 5266 5118 4954 4779 4784 4564 4538 4201 4219 4052 4100 4204 4386 4461 4591 4847 4896 4968 5257 5300 5427 5154 5184 5023 4955 4741 4462 4353 4140 3877 3703 3486 3210 2936 2825 2665 2567 2373 2344 2150 2063 1980 1953 1874 1870 1742 1820 1734 1783 1744 1715 1692 1681 1708 1757 1689 1578 1679 1631 1661 1665 1687 1630 1651 1664 1677 1654 1622 1704 1679 1683 1647 1615 1748 1764 1806 1740 1713 1799 1838 1918 1838 1912 2008 2027 2133 2260 2245 2462 2538 2702 2917 3065 3230 3628 3800 4062 4488 4709 5198 5540 5781 5848 6102 6427 6434 6556 6551 6362 6413 6209 6280 5737 5607 5224 4758 4301 3959 3690 3471 3134 3061 2931 2708 2555 2332 2316 2251 2206 2318 2247 2439 2385 2498 2470 2366 2361 2446 2356 2439 2373 2378 2324 2276 2290 2325 2230 2278 2418 2370 2369 2411 2366 2478 2443 2473 2609 2476 2304 2355 2372 2244 2195 2123 2029 1968 1982 1842 1795 1737 1599 1588 1567 1639 1485 1506 1473 1473 1421 1440 1356 1359 1369 1413 1342 1398 1357 1265 1367 1311 1308 1261 1314 1345 1310 1314 1272 1314 1348 1350 1318 1328 1268 1322 1250 1364 1286 1336 1226 1289 1362 1320 1325 1326 1354 1270 1287 1275 1299 1372 1317 1277 1300 1249 1364 1373 1342 1248 1290 1285 1275 1301 1304 1386 1349 1369 1399 1410 1518 1642 1587 1670 1725 1879 2054 2206 2372 2639 2856 3055 3340 3088 2961 2730 2551 2280 2230 2136 2364 2162 2159 1982 1874 1629 1612 1429 1373 1318 1314 1243 1357 1291 1228 1296 1260 1311 1232 1229 1223 1215 1294 1225 1228 1211 1211 1237 1280 1229 1251 1219 1281 1327 1321 1326 1383 1366 1427 1455 1438 1462 1443 1443 1479 1351 1384 1359 1313 1386 1344 1400 1455 1401 1429 1427 1473 1450 1555 1549 1730 1569 1605 1544 1422 1391 1343 1392 1360 1391 1379 1300 1320 1288 1229 1249 1240 1218 1252 1225 1188 1183 1203 1183 1207 1200 1211 1244 1268 1248 1227 1203 1176 1324 1237 1241 1305 1312 1283 1330 1422 1413 1396 1406 1467 1479 1429 1480 1426 1400 1407 1394 1384 1393 1356 1381 1361 1374 1342 1357 1285 1387 1321 1394 1330 1366 1358 1392 1433 1377 1486 1461 1460 1579 1642 1742 1821 1918 2052 2024 2145 2280 2330 2552 2585 2662 2641 2585 2694 2451 2559 2496 2322 2418 2214 2150 2129 1986 1917 1842 1773 1679 1773 1642 1579 1578 1471 1467 1457 1370 1430 1284 1373 1365 1324 1286 1281 1343 1259 1299 1268 1218 1282 1252 1273 1296 1243 1211 1170 1213 1243 1204 1174 1164 1174 1220 1198 1197 1202 1201 1230 1215 1226 1152 1154 1161 1151 1211 1206 1176 1208 1209 1259 1198 1196 1238 1214 1171 1183 1176 1172 1174 1140 1168 1172 1230 1213 1217 1216 1173 1145 1208 1193 1188 1226 1107 1207 1138 1214 1116 1209 1194 1237 1160 1214 1139 1198 1132 1158 1133 1198 1249 1178 1231 1240 1148 1235 1196 1253 1288 1295 1318 1339 1322 1308 1357 1382 1368 1489 1429 1479 1513 1399 1447 1400 1445 1453 1497 1500 1407 1418 1489 1404 1425 1484 1503 1595 1559 1554 1554 1566 1656 1655 1731 1661 1762 1704 1648 1659 1609 1601 1659 1622 1584 1528 1508 1441 1451 1494 1400 1494 1360 1363 1361 1412 1416 1393 1387 1413 1427 1426 1469 1419 1431 1505 1589 1624 1646 1785 1787 1946 1908 2044 2179 2289 2450 2677 2756 2776 2887 2898 3034 3134 3118 3263 3451 3333 3400 3513 3455 3378 3299 3240 2954 2829 2881 2746 2633 2580 2503 2574 2425 2243 2230 2130 2037 2139 2094 2120 2132 2257 2235 2408 2385 2590 2486 2644 2837 2694 2732 2730 2640 2576 2602 2546 2512 2551 2557 2479 2336 2295 2136 2198 2040 2096 1982 1900 1987 1923 1886 1877 1898 1994 1923 1917 1954 1888 1916 1959 1918 1844 1754 1823 1708 1797 1724 1716 1629 1616 1539 1529 1483 1437 1498 1380 1356 1281 1371 1302 1326 1294 1241 1318 1372 1296 1248 1289 1315 1344 1373 1344 1419 1419 1385 1449 1443 1459 1423 1462 1305 1354 1334 1375 1320 1392 1303 1327 1262 1292 1269 1282 1251 1181 1178 1195 1186 1174 1183 1150 1160 1182 1181 1220 1104 1179 1186 1135 1126 1101 1117 1120 1116 1168 1120 1084 1115 1117 1085 1091 1109 1131 1088 1110 1094 1150 1083 1088 1092 1083 1082 1105 1058 1116 1128 1104 1107 1118 1095 1092 1100 1107 1130 1122 1121 1147 1121 1128 1117 1171 1103 1134 1089 1158 1113 1153 1168 1165 1110 1199 1232 1176 1238 1309 1282 1345 1418 1410 1374 1338 1322 1312 1199 1295 1276 1336 1339 1340 1400 1299 1470 1444 1601 1628 2034 1988 2363 2299 2489 2277 2231 2123 1963 1836 1873 1847 1938 1935 2133 2044 2301 2142 2280 2230 2474 2387 2567 2362 2269 2128 1768 1693 1656 1669 1779 1740 1756 1712 1660 1439 1409 1327 1240 1193 1152 1144 1177 1128 1131 1114 1059 1054 1114 1079 1133 1149 1127 1090 1056 1043 1057 1088 1098 1097 1080 1105 1051 1117 1043 1044 1053 1011 1078 1044 1046 1071 1070 1033 1072 1076 1097 1010 1025 1114 1007 1069 1109 1063 1045 1027 1065 1050 1079 1096 998 1085 1078 1079 1089 1059 1127 1018 1072 1052 1031 1023 1055 1065 1065 1052 1069 1022 1061 1075 1097 1058 1083 1110 1076 1078 1104 1045 1061 1066 1090 1114 1085 1108 1146 1071 1112 1104 1151 1112 1157 1196 1125 1095 1146 1173 1174 1183 1146 1164 1190 1155 1175 1192 1190 1201 1187 1183 1227 1264 1271 1320 1289 1332 1280 1324 1278 1374 1361 1489 1503 1457 1535 1572 1660 1670 1758 1855 1897 1905 1908 2140 2245 2177 2244 2387 2340 2428 2449 2399 2368 2209 2342 2164 2171 2132 2228 2231 2204 2197 2012 1948 1837 1765 1726 1644 1543 1627 1582 1624 1458 1507 1418 1452 1423 1406 1401 1448 1375 1446 1447 1423 1412 1431 1411 1546 1549 1542 1479 1545 1576 1637 1587 1708 1724 1783 1889 1978 2055 1985 2111 2168 2317 2252 2310 2447 2490 2408 2460 2430 2449 2334 2486 2305 2383 2323 2429 2220 2330 2228 2380 2287 2336 2293 2345 2426 2374 2465 2607 2713 2781 2935 3136 3406 3754 4075 4548 5161 5970 6925 7763 8785 10398 11454 12916 13867 14672 14799 14345 13089 11880 10509 9694 9128 8997 8953 9090 9054 8796 8252 7457 6539 5535 4992 4179 3522 3271 2925 2759 2496 2388 2358 2335 2197 2153 2079 2028 1905 1926 1931 1881 1904 1975 1977 2039 2060 2003 2081 1965 2036 2050 1955 2126 2063 2136 2329 2401 2578 2703 2965 3279 3692 4022 4474 5178 5795 6321 7063 7439 7446 7294 7012 6392 5795 5314 5032 4946 4754 4895 5036 4826 4682 4368 4068 3510 3173 2741 2524 2203 2057 2012 1794 1753 1636 1652 1617 1585 1514 1483 1440 1363 1431 1373 1327 1300 1366 1347 1333 1243 1269 1253 1235 1233 1218 1207 1204 1243 1215 1154 1206 1128 1186 1142 1194 1190 1153 1176 1118 1115 1103 1107 1159 1162 1144 1114 1179 1160 1149 1108 1167 1115 1092 1121 1094 1144 1113 1116 1127 1149 1147 1179 1188 1218 1090 1071 1119 1091 1166 1140 1159 1129 1180 1095 1109 1137 1115 1201 1165 1139 1181 1143 1167 1253 1192 1293 1246 1306 1363 1344 1454 1420 1507 1464 1366 1412 1372 1302 1341 1283 1312 1220 1319 1354 1304 1363 1257 1322 1237 1247 1301 1323 1296 1317 1343 1367 1441 1522 1516 1466 1613 1662 1692 1578 1516 1473 1434 1430 1439 1465 1435 1575 1491 1544 1604 1616 1679 1737 1758 1744 1790 1824 1894 1761 1696 1519 1431 1520 1412 1447 1490 1491 1542 1542 1399 1491 1386 1351 1336 1287 1276 1246 1171 1275 1178 1213 1191 1297 1220 1193 1270 1273 1172 1310 1285 1264 1329 1373 1414 1453 1399 1453 1390 1412 1393 1405 1466 1531 1487 1542 1508 1608 1627 1582 1601 1575 1630 1597 1629 1620 1629 1629 1662 1699 1722 1817 1742 1803 1915 1909 1918 2024 2193 2271 2408 2699 2716 2967 3174 3453 3587 3812 4005 4008 4102 4069 4036 3870 3853 3816 3606 3488 3335 3340 3299 3123 3068 2959 2778 2808 2635 2490 2221 2221 2026 2016 1858 1708 1801 1740 1679 1622 1604 1599 1581 1583 1563 1553 1573 1620 1538 1570 1576 1520 1526 1438 1485 1469 1398 1422 1490 1471 1496 1451 1426 1463 1449 1447 1495 1513 1514 1510 1494 1494 1533 1491 1591 1684 1679 1770 1876 1909 2059 2125 2382 2401 2775 2971 3221 3519 3924 4244 4436 4759 4811 4954 4903 4933 4732 4569 4398 4221 4082 3907 3864 3935 3852 3827 3533 3453 3286 3108 2917 2706 2536 2446 2242 2290 2142 2138 2088 2101 2100 2192 2178 2189 2290 2598 2538 2647 2753 2845 2903 3004 3039 3007 3014 2966 2907 2806 2712 2748 2624 2571 2514 2431 2385 2364 2286 2236 2184 2110 2028 2046 1894 1885 1799 1699 1847 1730 1736 1833 1849 1932 2071 2082 2259 2364 2483 2570 2462 2392 2214 2145 2098 1978 2015 1997 2079 2000 2134 2143 2147 2166 2096 1991 2095 2021 2065 2071 2110 2082 2072 2008 2087 1942 2017 1911 1866 1827 1882 1890 1902 1876 1772 1843 1721 1719 1622 1628 1514 1517 1480 1484 1439 1387 1451 1336 1358 1326 1339 1304 1253 1198 1234 1167 1156 1210 1182 1177 1201 1141 1152 1170 1176 1180 1145 1182 1098 1145 1206 1136 1067 1183 1112 1161 1192 1173 1151 1170 1197 1230 1255 1225 1303 1207 1257 1197 1167 1238 1140 1125 1204 1204 1196 1156 1223 1233 1199 1164 1185 1238 1147 1087 1140 1130 1102 1165 1169 1056 1129 1096 1151 1078 1148 1086 1088 1062 1055 1085 1051 1103 1104 1136 1072 1023 1049 1090 1080 1056 1086 1073 1095 1136 1096 1073 1057 1143 1097 1048 1111 1077 1086 1149 1122 1173 1075 1090 1116 1148 1100 1122 1095 1118 1109 1053 1103 1158 1069 1079 1149 1066 1104 1083 1103 1098 1063 1121 1123 1064 1091 1085 1058 1117 1028 1081 1075 1091 1137 1148 1061 1066 1134 1076 1103 1092 1094 1146 1086 1140 1151 1129 1110 1081 1099 1116 1195 1155 1214 1169 1173 1180 1214 1210 1206 1230 1221 1280 1220 1267 1276 1293 1308 1385 1296 1417 1444 1405 1541 1479 1465 1518 1427 1499 1392 1397 1402 1387 1442 1432 1392 1425 1508 1463 1488 1448 1402 1411 1379 1431 1488 1411 1414 1469 1491 1493 1533 1487 1487 1559 1581 1590 1676 1631 1746 1779 1902 1856 1965 2095 2227 2211 2318 2461 2523 2634 2788 2901 3197 3426 3892 4332 4897 5489 6377 7169 7843 8433 8972 9153 8825 8220 7406 6696 6337 6068 5869 6031 6017 6240 6676 6637 6776 6634 6251 5867 5312 4982 4538 4068 3895 3671 3495 3371 3452 3177 3298 3230 3195 3025 2915 2866 2579 2446 2312 2124 2165 2159 2093 2042 2037 2003 2004 1970 1855 1808 1804 1766 1699 1680 1675 1701 1748 1768 1869 1971 1991 2014 2228 2297 2513 2423 2398 2326 2204 2116 2042 1949 1935 1932 2007 2040 2191 2139 2188 2187 2230 2210 2106 2099 2009 2005 2080 2120 2095 2159 2196 2239 2378 2257 2373 2386 2682 2615 2788 2994 3248 3486 3800 4251 4742 5418 6210 7095 8340 9537 10845 12119 13046 13517 13823 13120 12126 10821 9738 8913 8305 8288 8257 8569 9039 9484 9857 10098 9841 9590 8873 8103 7333 6742 6244 5732 5301 5049 4770 4730 4606 4409 4343 4052 3988 3983 4003 3974 3775 3665 3687 3555 3406 3337 3199 3157 2964 2877 2778 2689 2582 2561 2467 2432 2360 2333 2291 2291 2252 2241 2146 2106 2066 2009 2099 2144 2123 2203 2255 2304 2456 2496 2595 2749 2740 2803 2612 2686 2604 2569 2472 2323 2451 2438 2357 2322 2291 2305 2284 2372 2282 2227 2124 2017 1928 1802 1806 1763 1693 1593 1599 1573 1462 1479 1452 1473 1386 1390 1250 1343 1336 1332 1257 1304 1253 1251 1263 1257 1295 1287 1341 1216 1287 1220 1197 1245 1225 1318 1239 1289 1259 1222 1262 1278 1319 1214 1309 1291 1322 1259 1326 1342 1349 1333 1318 1339 1399 1353 1329 1297 1356 1300 1364 1286 1352 1259 1324 1337 1283 1377 1385 1399 1356 1405 1355 1389 1373 1417 1390 1444 1506 1497 1507 1472 1595 1502 1653 1586 1729 1714 1791 1850 1948 1990 2008 2134 2192 2289 2407 2385 2510 2623 2570 2623 2631 2669 2618 2681 2777 2814 2825 2993 3182 3249 3446 3836 4095 4550 4954 5437 5928 6463 6610 6451 6418 5852 5119 4619 4197 3888 3713 3567 3633 3769 3810 4003 4210 4026 4011 3773 3384 3007 2742 2382 2213 2034 1928 1873 1761 1741 1726 1601 1663 1709 1573 1633 1650 1705 1716 1700 1783 1845 1856 1900 1982 2049 2051 2028 2081 2104 2011 1986 1958 2008 1948 1958 1902 1933 1808 1874 1917 1844 1875 1854 1796 1725 1815 1779 1711 1699 1720 1674 1769 1697 1780 1703 1760 1806 1676 1771 1821 1801 1824 1907 1892 1860 1969 1870 1853 1897 1740 1731 1681 1703 1663 1680 1697 1670 1698 1739 1576 1569 1555 1501 1500 1433 1424 1384 1323 1288 1361 1356 1296 1339 1315 1370 1244 1334 1415 1297 1429 1455 1521 1611 1651 1764 1662 1620 1549 1499 1371 1343 1363 1350 1301 1312 1327 1360 1414 1332 1383 1416 1328 1298 1233 1234 1159 1152 1097 1104 1125 1122 1089 1071 1190 1146 1102 1155 1070 1070 1141 1135 1150 1090 1150 1150 1133 1200 1172 1247 1252 1260 1238 1334 1258 1418 1399 1421 1457 1435 1442 1429 1315 1299 1278 1244 1235 1217 1295 1252 1279 1352 1276 1335 1267 1311 1316 1213 1276 1240 1266 1255 1322 1242 1206 1255 1340 1309 1311 1346 1394 1393 1439 1433 1600 1630 1738 1721 1845 1969 2043 2147 2187 2283 2387 2448 2321 2381 2366 2349 2459 2276 2238 2409 2325 2382 2258 2331 2337 2452 2532 2572 2540 2513 2534 2483 2428 2438 2242 2226 2199 2083 2041 1960 2054 1943 1906 1779 1766 1851 1791 1798 1630 1581 1561 1505 1480 1499 1395 1381 1300 1322 1338 1224 1313 1240 1213 1153 1172 1180 1093 1145 1102 1102 1120 1128 1101 1079 1043 1064 1101 1108 1131 1111 1065 1120 1121 1133 1026 1110 1118 1143 1127 1043 1144 1020 1117 1035 1034 1076 1062 1066 1078 1086 1117 1058 1046 1029 1102 1056 1040 1062 1079 1086 1079 1138 987 1121 1090 1095 1090 1018 1125 1095 1067 1107 1112 1072 1043 1101 1182 1158 1074 1147 1180 1222 1169 1193 1209 1313 1319 1313 1289 1270 1317 1370 1445 1447 1471 1502 1579 1712 1717 1681 1821 1779 1866 1904 1905 1973 1964 1942 1993 1945 1921 1856 1840 1879 1858 1874 1825 1876 1813 1838 1767 1698 1667 1714 1703 1638 1638 1613 1570 1456 1536 1530 1559 1679 1710 1675 1724 1790 1730 1905 1907 1943 1778 1845 1840 1820 1865 1739 1879 1782 1863 2029 2131 2156 2182 2289 2329 2320 2288 2354 2218 2254 2097 2126 2117 2014 1963 1946 1843 1853 1818 1753 1688 1676 1700 1707 1640 1627 1628 1568 1611 1509 1440 1426 1337 1292 1286 1294 1311 1294 1302 1273 1270 1180 1290 1208 1173 1201 1164 1154 1184 1139 1081 1198 1121 1244 1252 1187 1140 1141 1223 1254 1272 1197 1169 1222 1213 1205 1237 1224 1206 1345 1335 1373 1365 1346 1399 1400 1405 1562 1431 1557 1597 1596 1720 1749 1854 1991 1970 2033 2063 2195 2148 2241 2311 2225 2194 2212 2286 2123 2144 2053 1999 2003 1934 2029 1916 1938 1819 1833 1803 1910 1809 1791 1724 1637 1577 1545 1472 1421 1378 1339 1360 1270 1347 1256 1164 1184 1148 1096 1136 1121 1151 1028 1066 1119 1079 1107 1074 1053 1036 1071 1089 1068 1120 1046 1058 968 1043 1029 1034 987 1011 1027 1003 1025 994 1069 1018 983 1030 1109 1094 1078 1090 1193 1210 1260 1455 1498 1771 1732 1682 1591 1537 1426 1256 1178 1213 1157 1105 1126 1120 1166 1265 1364 1327 1372 1411 1316 1257 1207 1217 1146 1116 1180 1144 1219 1146 1156 1164 1205 1202 1262 1260 1378 1320 1381 1470 1435 1370 1497 1481 1472 1362 1404 1371 1356 1471 1467 1564 1560 1535 1568 1598 1549 1596 1618 1590 1539 1426 1506 1372 1397 1350 1401 1391 1334 1298 1350 1342 1346 1236 1215 1250 1288 1352 1273 1326 1304 1372 1335 1463 1405 1533 1442 1506 1346 1279 1223 1150 1106 1096 1101 1138 1088 1128 1155 1135 1209 1160 1148 1193 1131 1244 1080 1068 1087 1046 1088 1075 1013 980 976 1049 1094 1020 997 1070 1083 1070 1068 1107 1110 1057 1091 1126 1100 1112 1070 1117 1057 1021 1160 1119 1212 1173 1230 1156 1177 1238 1238 1248 1236 1216 1255 1248 1250 1241 1232 1312 1317 1414 1436 1393 1508 1482 1487 1541 1599 1544 1458 1473 1456 1452 1495 1493 1542 1544 1560 1598 1663 1668 1682 1719 1797 1817 1849 1882 1934 2066 2176 2232 2169 2265 2244 2324 2328 2309 2283 2278 2362 2284 2257 2282 2234 2113 2232 2162 2125 2259 2219 2255 2408 2332 2427 2421 2566 2549 2622 2566 2504 2374 2211 2061 1905 1799 1769 1625 1631 1593 1498 1575 1598 1516 1641 1624 1584 1564 1600 1450 1436 1338 1334 1313 1224 1202 1151 1106 1159 1072 1079 1161 1055 1066 1036 1023 1013 965 1011 1051 1001 1020 1016 981 1010 1052 985 1041 1061 1108 1111 1200 1153 1212 1115 1195 1088 1052 1064 970 979 1051 1052 1022 1075 1101 1018 1057 1059 1138 1163 1158 1133 1125 1132 1144 1091 1134 1069 1058 1020 1034 980 990 950 993 971 948 948 960 962 1006 981 972 963 988 996 969 918 914 904 870 903 903 995 969 916 918 942 966 959 1015 939 946 998 981 945 963 984 906 918 921 935 900 933 932 940 965 957 936 900 910 965 950 936 908 894 910 885 869 919 905 881 904 903 944 895 855 918 918 917 925 931 885 897 930 912 914 915 911 929 939 889 966 963 941 1025 926 978 955 967 969 981 1046 944 1012 992 1013 1030 1027 1027 1100 1091 1190 1210 1270 1283 1345 1454 1536 1714 1718 1845 1953 2162 2221 2158 2158 2020 1974 1780 1644 1589 1444 1451 1362 1359 1351 1493 1490 1600 1601 1713 1693 1653 1505 1514 1427 1316 1234 1158 1212 1104 1044 1061 1076 1034 1004 1086 981 996 995 1023 1036 969 983 1012 995 959 975 981 1010 1044 1064 1011 1022 1018 1037 999 1062 1118 1104 1108 1218 1300 1309 1344 1297 1376 1424 1461 1389 1333 1269 1296 1289 1290 1265 1430 1386 1411 1477 1556 1631 1769 1717 1797 1693 1685 1612 1578 1529 1456 1414 1379 1282 1302 1347 1270 1285 1350 1313 1329 1307 1333 1282 1228 1255 1235 1186 1165 1133 1126 1119 1128 1045 1007 1045 962 967 961 1060 963 960 989 1006 957 936 937 929 945 921 962 943 971 963 900 990 1050 980 933 956 995 910 993 968 977 990 1037 1021 985 1013 1035 1021 1068 990 1063 1018 975 1030 968 938 973 1024 980 990 973 1005 982 982 992 1041 992 1064 975 1002 1009 986 958 978 1010 991 960 998 967 978 941 994 981 930 975 1002 940 1009 985 1004 930 1011 1052 1005 1025 1038 1007 1007 1003 982 979 961 991 964 969 929 998 894 971 1006 1046 1019 989 1051 1060 1074 1039 1068 1052 1101 1113 1183 1180 1243 1207 1219 1199 1196 1132 1106 1143 1079 1013 1001 1049 1008 1039 1029 1003 1098 1101 1105 1112 1039 1165 1090 1092 1092 1096 1004 1096 973 1050 1047 1059 995 1064 1021 1088 1101 1100 1114 1062 1153 1162 1127 1079 1191 1183 1246 1239 1318 1278 1378 1349 1373 1397 1418 1486 1476 1514 1430 1584 1482 1559 1567 1517 1586 1574 1650 1619 1645 1600 1744 1676 1651 1648 1573 1613 1590 1498 1487 1514 1423 1450 1404 1377 1337 1220 1373 1344 1291 1264 1256 1267 1195 1114 1147 1170 1182 1114 1105 1075 1091 1023 1040 1017 1055 1028 977 978 999 1006 967 1068 1001 986 1018 990 1041 1058 996 1009 977 1089 1064 1058 1047 1061 1031 1055 1124 1096 1097 1111 1116 1186 1208 1308 1213 1278 1335 1292 1284 1263 1247 1275 1211 1230 1295 1279 1277 1294 1265 1349 1365 1318 1378 1343 1388 1422 1361 1303 1234 1261 1174 1196 1209 1178 1174 1149 1158 1141 1145 1202 1213 1139 1200 1208 1207 1100 1148 1103 1070 1166 1088 1179 1091 1160 1128 1091 1150 1143 1211 1228 1226 1132 1240 1216 1180 1187 1176 1222 1225 1212 1169 1190 1202 1238 1266 1209 1189 1155 1187 1190 1133 1136 1095 1069 1131 1171 1102 1117 1060 1067 1093 1067 1052 1085 1079 974 1086 1104 1034 1010 953 992 958 948 994 911 985 1027 1041 972 985 1010 953 957 987 953 971 959 988 1080 1021 1032 1033 1106 1028 1114 1062 1053 1023 1002 1032 971 1062 988 1022 924 1034 1052 1108 1050 1022 1095 1094 1068 1121 1137 1199 1132 1177 1169 1116 1146 1180 1117 1139 1101 1105 1112 1106 1158 1092 1150 1175 1151 1232 1214 1159 1270 1178 1267 1231 1265 1232 1312 1275 1256 1302 1288 1349 1418 1474 1505 1534 1577 1644 1802 1845 1951 2171 2310 2651 2846 3357 3747 4255 4660 4943 5068 4928 4537 4068 3762 3276 3034 2742 2484 2366 2283 2290 2218 2301 2427 2501 2735 2825 3139 3135 3149 3091 2952 2691 2473 2259 1961 1843 1735 1691 1544 1464 1467 1320 1320 1314 1291 1260 1240 1252 1169 1246 1173 1235 1207 1190 1151 1291 1220 1219 1186 1237 1293 1292 1205 1322 1335 1310 1313 1389 1383 1423 1343 1375 1426 1405 1434 1460 1334 1351 1354 1456 1356 1312 1386 1404 1408 1415 1536 1522 1483 1613 1670 1715 1766 1952 1990 1984 2243 2400 2564 2767 2970 3121 3169 3095 3029 2962 2816 2646 2508 2454 2408 2292 2282 2233 2174 2191 2300 2266 2296 2388 2422 2574 2473 2452 2452 2418 2299 2223 2246 2203 2081 2088 2124 2104 2201 2289 2361 2567 2700 2919 3030 3184 3204 3047 2885 2661 2450 2288 2047 2002 1842 1792 1769 1708 1704 1721 1757 1814 1823 1969 1986 1986 2106 2134 2016 1813 1795 1783 1633 1515 1449 1434 1422 1329 1419 1313 1284 1225 1337 1231 1186 1149 1245 1161 1101 1121 1150 1136 1140 1172 1196 1154 1113 1106 1151 1179 1159 1154 1129 1108 1204 1230 1176 1264 1243 1344 1367 1469 1427 1454 1505 1452 1386 1337 1327 1300 1254 1352 1196 1345 1270 1366 1295 1329 1291 1354 1345 1405 1450 1388 1470 1436 1468 1458 1401 1457 1416 1427 1436 1367 1440 1313 1378 1320 1340 1269 1371 1403 1328 1258 1319 1260 1303 1359 1348 1294 1258 1280 1311 1169 1236 1287 1331 1290 1272 1262 1336 1314 1317 1389 1393 1454 1476 1621 1640 1720 1913 1987 2259 2376 2483 2585 2526 2547 2356 2229 2044 1969 1689 1703 1579 1663 1606 1557 1452 1645 1622 1713 1734 1724 1840 1889 1973 1980 1934 1819 1843 1706 1675 1656 1649 1483 1571 1541 1631 1512 1583 1620 1698 1650 1765 1880 1910 2037 2235 2241 2524 2571 2546 2599 2517 2289 2167 1984 1907 1789 1764 1668 1654 1594 1638 1619 1596 1618 1722 1720 1838 1820 1860 1833 1855 1819 1729 1646 1572 1531 1492 1409 1350 1313 1260 1262 1232 1241 1173 1095 1178 1217 1158 1135 1155 1144 1129 1175 1111 1098 1176 1155 1160 1126 1124 1151 1162 1067 1152 1157 1232 1214 1114 1091 1101 1098 1064 1075 1062 1092 1137 1087 1073 1074 1034 1104 1077 1083 1019 1057 1058 1024 1010 1021 1051 989 1019 1034 1033 1004 1017 1038 1003 1016 1089 1017 992 1019 1044 1071 1028 1071 1093 1050 1125 1091 1133 1066 1069 1033 1059 1069 1052 1029 1074 972 993 981 981 1077 1056 1022 1090 1127 1122 1228 1105 1170 1176 1185 1167 1267 1295 1278 1285 1302 1288 1287 1284 1289 1338 1309 1221 1206 1199 1184 1167 1175 1150 1153 1134 1093 1180 1156 1072 1121 1147 1122 1155 1161 1106 1125 1106 1054 1135 1081 1013 1118 1047 1051 1066 1018 981 962 1018 968 932 1013 932 979 962 920 874 941 978 934 971 948 944 914 924 920 959 939 904 966 958 955 884 976 996 989 973 965 1052 993 961 977 1022 946 1002 980 998 1007 1029 1055 1031 999 1041 1009 1097 1030 1058 1028 1033 985 995 961 972 920 960 902 944 958 929 913 947 928 1004 949 1023 963 912 988 947 918 895 967 881 825 920 929 928 876 928 884 957 923 905 871 975 1005 949 994 982 949 909 986 1109 1057 1007 992 983 982 976 1025 950 979 944 930 943 881 960 896 952 969 977 1007 1004 1009 1045 976 1063 1035 1097 1071 1005 1081 1071 1039 1021 1084 1080 1066 1083 1133 1121 1192 1167 1154 1208 1083 1142 1070 1086 1104 1027 1057 968 1057 993 1063 1058 1002 1061 1038 969 1011 1049 1056 1029 1044 1043 1054 1086 1087 1073 1037 965 1065 952 1095 1016 1046 1075 1107 1074 1079 1154 1135 1228 1157 1119 1126 1190 1180 1148 1179 1166 1134 1136 1178 1142 1149 1127 1160 1212 1152 1200 1241 1234 1180 1257 1292 1238 1336 1371 1349 1383 1384 1397 1432 1427 1317 1347 1336 1276 1340 1263 1170 1184 1205 1191 1148 1181 1122 1169 1121 1165 1089 1139 1186 1144 1179 1085 1150 1101 1121 1170 1057 1054 1022 1049 1124 1005 990 1099 955 998 910 954 977 989 928 959 973 1017 969 972 960 931 977 1009 957 949 1008 969 991 994 996 993 1053 968 1053 983 999 994 1011 983 987 999 993 1007 1002 963 1032 935 1043 1030 1043 1084 1028 1067 1054 1128 1133 1131 1114 1246 1281 1252 1215 1240 1309 1285 1297 1283 1345 1390 1419 1378 1437 1429 1497 1548 1572 1585 1494 1508 1481 1404 1358 1402 1399 1370 1279 1316 1306 1270 1278 1329 1304 1342 1332 1384 1375 1380 1430 1376 1367 1395 1352 1372 1438 1356 1364 1360 1373 1342 1392 1339 1404 1407 1388 1427 1482 1522 1495 1510 1509 1528 1553 1477 1449 1395 1351 1349 1365 1307 1416 1330 1433 1322 1363 1389 1451 1352 1381 1332 1392 1357 1293 1324 1326 1296 1229 1258 1271 1233 1249 1159 1236 1121 1211 1163 1193 1185 1146 1143 1173 1195 1150 1136 1163 1041 1086 1107 1137 1167 1135 1100 1104 1078 1061 1138 1165 1191 1170 1117 1113 1228 1163 1159 1245 1179 1251 1232 1278 1233 1269 1345 1340 1281 1412 1288 1344 1372 1389 1279 1383 1354 1433 1402 1404 1407 1284 1360 1404 1373 1371 1438 1367 1351 1368 1405 1464 1461 1394 1453 1373 1452 1377 1438 1338 1420 1424 1365 1372 1354 1364 1369 1372 1371 1313 1327 1377 1348 1291 1374 1308 1384 1408 1368 1414 1485 1536 1676 1729 1903 2000 2035 2110 2249 2240 2234 2176 1995 1759 1682 1645 1566 1477 1444 1440 1472 1425 1476 1351 1381 1430 1487 1581 1450 1565 1666 1747 1783 1766 1724 1788 1704 1650 1572 1534 1510 1394 1396 1375 1335 1232 1235 1245 1215 1204 1215 1154 1162 1069 1128 1180 1192 1165 1192 1145 1185 1163 1113 1193 1197 1212 1184 1196 1222 1249 1304 1278 1262 1380 1354 1294 1271 1308 1272 1242 1133 1127 1083 1052 1048 1109 1030 1089 1067 1099 1062 1096 1135 1110 1127 1164 1186 1165 1162 1221 1193 1177 1201 1160 1158 1113 1159 1101 1177 1211 1195 1203 1222 1261 1203 1212 1203 1180 1195 1234 1169 1173 1192 1194 1160 1191 1209 1297 1203 1371 1338 1344 1461 1455 1507 1698 1763 1852 1947 2112 2313 2485 2627 2942 2995 3079 2919 2829 2714 2518 2282 2114 1971 1845 1765 1751 1626 1611 1702 1546 1486 1582 1615 1709 1693 1735 1773 1989 2059 2076 2053 2029 1996 1975 1733 1686 1567 1453 1510 1451 1346 1218 1244 1200 1173 1165 1163 1107 1135 1054 1001 1104 1094 1038 1092 1068 1008 928 1000 1002 958 945 1005 1007 994 972 995 982 968 977 968 971 989 947 998 978 1007 970 1027 955 1008 956 943 966 998 940 985 953 970 995 951 1001 922 1013 926 1004 938 997 948 980 981 1028 1031 1027 1025 1066 1034 1080 1042 1077 1082 1088 1032 1032 1035 1007 1053 1003 1020 1061 1092 1021 1060 1090 1070 1118 1092 1092 1108 1130 1157 1160 1238 1217 1252 1284 1284 1222 1220 1173 1189 1276 1140 1129 1183 1124 1135 1140 1042 1125 1101 1116 1131 1115 1112 1102 1082 1136 1087 1070 1089 1051 1096 1083 1065 1010 1105 1074 1127 1055 1012 1069 1103 1111 1015 1034 1033 1086 996 965 1035 1066 1005 1026 1041 1079 1088 1132 1097 1127 1084 1148 1124 1174 1106 1139 1170 1155 1177 1216 1186 1200 1195 1214 1256 1197 1221 1229 1231 1278 1143 1198 1184 1202 1218 1170 1206 1218 1221 1236 1266 1235 1238 1197 1221 1293 1271 1249 1335 1291 1371 1325 1315 1408 1335 1252 1342 1296 1375 1362 1335 1362 1278 1326 1280 1299 1265 1245 1236 1268 1184 1195 1151 1222 1153 1185 1178 1126 1179 1178 1176 1268 1184 1258 1243 1229 1157 1201 1146 1146 1185 1150 1081 1133 1025 1077 1059 1034 1074 1070 1060 1038 1068 1098 1060 1108 1092 1154 1138 1156 1142 1162 1079 1114 1044 1026 1087 1065 1073 1068 1059 1072 1052 986 1046 1036 1035 1110 1053 1071 1076 1103 1101 1115 1057 1123 1185 1126 1135 1089 1166 1039 1067 1072 1001 1052 1096 1078 1136 1114 1082 1155 1193 1114 1167 1171 1169 1167 1193 1105 1245 1195 1238 1242 1210 1234 1230 1216 1277 1255 1284 1334 1267 1336 1273 1312 1238 1306 1287 1302 1243 1240 1368 1287 1289 1298 1314 1358 1309 1351 1294 1261 1263 1263 1345 1289 1269 1301 1325 1382 1369 1332 1343 1368 1496 1453 1582 1656 1750 1800 1887 1972 2029 2039 2000 1992 1838 1807 1722 1487 1501 1468 1379 1328 1255 1285 1222 1221 1209 1219 1181 1210 1170 1258 1264 1352 1430 1425 1418 1585 1423 1426 1406 1369 1414 1277 1263 1234 1159 1186 1145 1072 1020 1103 1034 1057 1032 1061 1033 1041 1057 995 1015 968 1024 940 1036 942 997 968 994 942 990 1015 970 1038 1036 971 986 994 975 986 1071 915 966 949 998 929 902 942 991 925 955 970 1034 1007 1015 989 965 1010 1027 989 1015 1019 1017 1064 1044 1041 1085 1065 1019 1037 1098 1107 1109 1119 1162 1146 1105 1071 1114 1069 1032 1074 1062 1060 1043 1029 1020 1010 1028 1007 1095 1011 1057 1070 1035 1085 1103 1040 1075 1085 1105 1178 1244 1206 1175 1158 1212 1113 1193 1190 1082 1123 1015 1048 1010 991 1026 1052 1015 1111 969 1017 1010 1006 1061 977 1010 1047 1054 1054 1004 1053 1080 1107 1118 1075 1112 1090 1120 1117 1097 1087 1100 1213 1228 1306 1360 1482 1489 1580 1706 1770 1788 1722 1626 1612 1468 1412 1340 1314 1291 1195 1158 1141 1124 1095 1124 1104 1070 1068 1147 1129 1103 1191 1184 1263 1325 1312 1384 1358 1404 1342 1282 1284 1282 1201 1158 1116 1057 1108 1064 1053 1065 979 1020 942 936 939 971 962 950 975 1005 1042 941 959 952 1040 1014 986 967 1006 934 1041 1033 991 996 981 1068 1036 1144 1078 1122 1073 1170 1104 1117 1196 1178 1197 1273 1312 1326 1343 1424 1477 1634 1772 1849 1990 2135 2297 2325 2487 2497 2341 2220 2127 1957 1822 1700 1690 1621 1671 1585 1490 1559 1541 1499 1523 1420 1440 1433 1446 1455 1513 1478 1619 1640 1742 1744 1808 1751 1795 1599 1615 1563 1471 1416 1347 1369 1338 1327 1316 1309 1253 1241 1211 1259 1169 1190 1217 1243 1137 1216 1172 1160 1152 1148 1068 1150 1114 1140 1212 1087 1085 1069 1101 1117 1121 1145 1133 1092 1095 1012 1107 1067 1055 1015 1015 1034 1050 1083 1056 1056 1075 1098 1105 1051 1032 1112 1066 1056 1083 1062 1060 1016 1113 1036 1013 1038 1027 1065 1113 1098 1034 1125 1079 1102 1092 1091 1138 1050 1069 1013 1040 1009 1007 1031 1029 1038 977 1047 1010 1067 1021 1004 1047 942 946 963 1077 1039 1044 1067 1036 1093 1146 1087 1085 1107 1142 1184 1160 1129 1151 1223 1140 1247 1269 1206 1196 1216 1139 1199 1183 1137 1121 1110 1042 1150 1128 1141 1138 1077 1136 1098 1094 1127 1119 1116 1183 1204 1214 1227 1179 1167 1237 1145 1224 1261 1164 1194 1181 1218 1205 1222 1186 1222 1261 1213 1192 1240 1174 1153 1211 1188 1137 1155 1117 1126 1122 1118 1233 1111 1154 1072 1086 1102 1067 1086 1000 1061 1013 1008 1058 1021 1078 1022 1047 1018 968 1060 997 1033 1074 992 978 984 958 985 944 998 932 1026 978 981 966 927 957 961 985 952 958 955 958 986 974 967 1019 1059 949 1002 982 1011 981 1051 1029 1022 1053 1003 1003 1018 1011 1027 1082 1042 1073 1078 1117 1044 1074 1058 1076 1156 1111 1126 1145 1140 1108 1195 1192 1144 1157 1230 1204 1174 1264 1171 1222 1185 1139 1178 1202 1228 1176 1171 1113 1137 1149 1082 1067 1176 1183 1180 1188 1177 1179 1206 1251 1263 1267 1252 1291 1346 1336 1239 1389 1405 1361 1378 1323 1412 1352 1430 1308 1353 1336 1308 1376 1325 1260 1323 1311 1312 1253 1371 1249 1264 1315 1229 1324 1273 1288 1324 1328 1301 1315 1349 1317 1238 1352 1333 1392 1364 1303 1393 1390 1337 1273 1345 1393 1315 1311 1385 1284 1337 1248 1183 1204 1186 1190 1127 1187 1148 1183 1154 1104 1152 1182 1163 1123 1117 1135 1133 1167 1117 1138 1128 1125 1106 1148 1075 1105 1086 1089 1086 1083 1026 1034 1074 1035 1026 1078 1105 1074 1087 1083 1022 984 1030 1026 987 1080 1006 1047 1017 1050 1005 1025 1018 1016 1036 1041 996 1048 1054 964 1019 1043 1042 1087 1034 1100 1122 1176 1162 1248 1118 1189 1081 1118 1097 1148 1054 1032 1103 1068 1073 1163 1206 1135 1166 1097 1159 1131 1081 1131 1188 1149 1094 1189 1132 1175 1161 1156 1142 1107 1116 1172 1120 1092 1070 1066 1034 1091 1013 1082 1080 1069 1213 1073 1087 1115 1110 1037 1081 1095 1043 1036 1054 1092 1086 1023 1064 1105 1045 1100 1069 985 1057 1043 1042 1018 1043 1018 1025 1053 1041 1071 1063 1105 1053 1132 1127 1140 1130 1131 1182 1157 1170 1189 1122 1156 1105 1083 1155 1158 1150 1151 1124 1121 1154 1203 1116 1114 1078 1049 1080 1042 1187 1160 1119 1104 1068 1112 1163 1114 1145 1135 1101 1109 1141 1057 1166 1090 1094 1160 1184 1173 1159 1171 1098 1181 1212 1245 1197 1164 1223 1305 1220 1205 1302 1268 1288</counts>
			</dataPoints>
		</scan>
	</xrdMeasurement>
</xrdMeasurements>