File: dataset/precursor_mixture/HfO2_La(OH)3_Li3PO4_Bi2O3-beta.2-min.xrdml
<?xml version="1.0"?>
<xrdMeasurements xmlns="http://www.xrdml.com/XRDMeasurement/2.2" xmlns:xsi="http://www.w3.org/2001/XMLSchema-instance" xsi:schemaLocation="http://www.xrdml.com/XRDMeasurement/2.2 http://www.xrdml.com/XRDMeasurement/2.2/XRDMeasurement.xsd" status="Completed" recordIdentifier="{6E138368-D565-47FE-AC80-DF6E6F8DC8D7}">
	<comment>
		<entry/>
	</comment>
	<sample type="To be analyzed">
		<id>dara-49-1</id>
		<name></name>
		<preparedBy></preparedBy>
	</sample>
	<xrdMeasurement measurementType="Scan" status="Completed" sampleMode="Reflection">
		<usedWavelength intended="K-Alpha 1">
			<kAlpha1 unit="Angstrom">1.5405980</kAlpha1>
			<kAlpha2 unit="Angstrom">1.5444260</kAlpha2>
			<kBeta unit="Angstrom">1.3922500</kBeta>
			<ratioKAlpha2KAlpha1>0.5000</ratioKAlpha2KAlpha1>
		</usedWavelength>
		<incidentBeamPath>
			<radius unit="mm">145.00</radius>
			<xRayTube id="1010048" name="Empyrean Cu LFF HR (9430 033 7310x) DK437873">
				<tension unit="kV">40.0</tension>
				<current unit="mA">15.0</current>
				<anodeMaterial>Cu</anodeMaterial>
				<focus type="Line">
					<length unit="mm">12.0</length>
					<width unit="mm">0.4</width>
					<takeOffAngle unit="deg">6.0</takeOffAngle>
				</focus>
			</xRayTube>
			<filter id="20010004" name="Beta-filter Nickel">
				<material>Ni</material>
				<thickness unit="mm">0.020</thickness>
			</filter>
			<sollerSlit id="21010002" name="Soller slits 0.04 rad.">
				<opening unit="rad">0.0400</opening>
			</sollerSlit>
			<mask id="22031000" name="Fixed mask 13 mm">
				<width unit="mm">9.00</width>
			</mask>
			<divergenceSlit id="22120001" name="Divergence slit 1°" xsi:type="fixedDivergenceSlitType">
				<distanceToSample unit="mm">50.00</distanceToSample>
				<height unit="mm">1.52</height>
			</divergenceSlit>
		</incidentBeamPath>
		<beamKnife id="29030100" name="Beam knife low"/>
		<sampleMovement xsi:type="spinningSampleMovementType">
			<spinnerRevolutionTime unit="seconds">1.0</spinnerRevolutionTime>
		</sampleMovement>
		<diffractedBeamPath>
			<radius unit="mm">145.00</radius>
			<antiScatterSlit id="22090040" name="AS slit 9 mm" xsi:type="fixedAntiScatterSlitType">
				<height unit="mm">9.00</height>
			</antiScatterSlit>
			<sollerSlit id="21020003" name="Large Soller slits 0.04 rad.">
				<opening unit="rad">0.0400</opening>
			</sollerSlit>
			<filter id="20030001" name="Large beta-filter Nickel">
				<material>Ni</material>
				<thickness unit="mm">0.020</thickness>
			</filter>
			<detector id="7010019" name="PIXcel1D-Medipix3 detector" xsi:type="rtmsDetectorType">
				<phd unit="keV">
					<lowerLevel>4.0</lowerLevel>
					<upperLevel>11.3</upperLevel>
				</phd>
				<mode>Scanning</mode>
				<activeLength unit="deg">1.021</activeLength>
			</detector>
		</diffractedBeamPath>
		<scan appendNumber="0" mode="Continuous" scanAxis="Gonio" status="Completed">
			<header>
				<startTimeStamp>2024-03-24T18:21:08-07:00</startTimeStamp>
				<endTimeStamp>2024-03-24T18:23:30-07:00</endTimeStamp>
				<author>
					<name>AutomatedUser</name>
				</author>
				<source>
					<applicationSoftware version="1.6 (94)">PANalytical Aeris Instrument Suite</applicationSoftware>
					<instrumentControlSoftware version="3.0.0 20211014">AERIS</instrumentControlSoftware>
					<instrumentID>2879380</instrumentID>
				</source>
			</header>
			<dataPoints>
				<positions axis="2Theta" unit="deg">
					<startPosition>10.02173288</startPosition>
					<endPosition>139.98435528</endPosition>
				</positions>
				<positions axis="Omega" unit="deg">
					<startPosition>5.01086644</startPosition>
					<endPosition>69.99217764</endPosition>
				</positions>
				<commonCountingTime unit="seconds">1.551</commonCountingTime>
				<counts unit="counts">380 388 385 417 371 391 375 382 352 342 382 386 394 387 352 349 392 350 372 359 359 362 337 384 352 343 328 341 329 363 333 365 364 391 333 345 346 287 302 322 291 315 355 309 337 304 290 329 315 305 296 321 310 271 276 318 310 299 279 321 295 272 288 258 273 288 291 282 288 281 256 291 235 290 229 296 250 251 263 265 268 271 279 256 284 269 254 243 240 253 243 261 221 282 275 240 251 207 226 249 220 234 240 255 229 226 243 262 226 227 254 216 214 220 246 240 212 240 255 277 316 319 356 351 485 612 697 890 994 808 643 488 382 327 305 260 251 254 256 241 248 291 215 193 221 189 221 196 198 212 216 189 225 198 240 228 212 220 223 192 205 200 203 205 200 210 198 214 206 229 249 298 220 242 192 163 180 159 204 184 205 195 190 184 182 190 195 205 171 158 188 152 185 160 167 171 183 176 198 164 175 163 178 150 141 164 166 180 154 143 153 155 162 149 172 178 185 169 152 152 147 163 156 167 155 161 155 166 170 149 162 163 144 175 144 155 161 152 163 145 150 149 159 153 164 154 163 161 134 143 146 147 160 146 156 173 141 142 140 149 163 158 169 135 135 160 143 159 162 149 156 153 174 158 174 195 168 237 243 252 212 211 139 182 163 171 159 145 138 149 151 166 153 147 190 192 194 187 188 200 195 174 197 184 179 166 144 154 156 147 155 150 152 121 157 157 195 184 240 209 312 338 275 234 188 183 192 205 239 287 271 258 246 152 208 191 166 183 205 174 162 160 178 175 163 141 124 154 136 158 128 157 161 192 176 206 203 160 144 134 124 139 123 135 142 128 155 136 127 119 160 150 117 137 148 160 138 152 147 146 136 173 217 227 265 277 317 421 506 608 651 591 528 444 339 332 282 303 348 385 504 697 1099 1879 3101 4605 3769 2529 1443 838 710 731 885 1069 1179 1050 760 575 379 333 296 216 233 197 182 201 182 165 156 168 129 147 190 155 179 181 157 148 148 131 148 148 136 141 139 146 98 143 132 117 126 127 120 144 129 188 182 214 219 201 157 146 146 125 151 136 146 137 142 126 131 147 110 143 137 154 155 154 141 174 179 208 238 252 319 435 555 828 1013 1053 1141 1126 844 574 368 279 198 171 149 163 148 139 144 135 152 133 137 204 246 328 582 845 1030 780 522 319 185 190 129 148 136 116 123 110 119 119 121 119 109 114 102 116 101 127 101 150 140 155 169 193 212 208 168 171 177 208 259 301 364 335 335 305 266 288 288 360 299 272 230 143 120 126 146 149 119 112 116 104 136 124 143 153 148 178 271 390 366 332 242 185 143 130 114 165 151 197 177 183 186 175 143 148 130 117 113 115 107 147 114 120 130 93 135 118 98 118 119 107 122 109 112 104 109 126 114 98 117 109 98 115 92 94 101 81 91 102 93 92 110 103 98 93 66 85 84 83 112 88 114 115 87 91 96 116 107 111 115 139 163 188 189 166 174 131 137 184 123 140 169 190 235 280 387 410 498 470 427 349 298 220 205 173 140 134 127 112 121 132 128 102 115 97 119 89 108 88 107 85 103 81 101 88 114 116 119 128 142 188 239 213 179 201 140 128 148 180 156 183 135 161 139 133 125 136 124 132 101 93 85 114 93 109 162 150 137 168 139 167 145 133 114 87 105 103 88 91 84 96 75 97 85 76 91 84 98 104 85 73 88 74 77 78 80 77 65 83 104 90 78 79 97 82 85 74 77 83 81 76 86 77 73 71 65 92 72 84 81 72 100 92 81 84 82 84 68 84 100 118 106 113 111 154 155 138 124 120 119 96 91 109 80 78 82 115 99 123 145 152 141 123 149 138 125 186 296 586 935 832 549 574 388 188 152 145 124 125 132 99 127 170 299 456 494 365 392 315 213 156 143 148 132 112 99 114 96 110 92 75 109 97 96 89 101 86 136 129 135 143 191 201 233 272 261 216 260 291 278 260 333 335 390 348 373 370 282 278 204 193 153 151 144 130 119 135 119 114 96 127 153 183 250 238 268 210 197 162 153 145 148 152 154 142 144 132 126 133 113 124 123 202 244 271 286 274 229 200 157 144 149 166 205 191 182 135 143 145 105 116 161 140 163 153 161 124 124 132 150 140 121 106 86 106 79 88 84 78 75 87 78 88 78 75 75 68 97 87 73 55 62 72 83 79 75 77 82 95 68 83 77 96 63 85 83 86 81 60 90 68 63 94 91 79 86 114 93 106 91 89 105 85 111 103 106 114 123 179 274 482 525 434 362 453 303 211 164 155 125 109 102 99 101 95 105 112 136 151 144 138 179 216 237 230 291 481 795 864 595 521 656 548 350 272 257 265 203 192 168 159 141 140 162 196 181 213 196 203 148 164 112 112 104 98 99 83 82 94 80 89 82 108 89 102 102 105 90 88 118 113 119 133 154 166 152 213 252 386 461 327 249 282 244 179 133 116 128 116 146 142 139 116 149 108 128 125 107 131 134 109 126 131 105 99 104 119 111 106 123 96 91 65 77 72 75 62 71 78 77 94 95 115 100 113 87 83 115 89 95 102 116 144 120 163 114 138 147 170 149 127 120 120 101 102 80 96 100 80 91 102 109 95 94 100 68 80 86 69 58 77 69 72 93 82 101 107 111 95 120 120 124 88 110 119 73 101 109 120 114 137 123 126 117 109 103 91 78 84 53 74 73 59 93 70 87 64 92 84 93 112 122 124 156 139 122 115 127 122 94 98 75 69 72 91 111 113 125 104 115 110 134 122 125 108 118 113 111 88 101 106 92 97 115 122 133 81 99 84 97 95 102 98 102 113 79 88 82 88 88 69 90 70 81 71 87 75 121 109 116 95 83 107 118 122 115 156 134 153 139 139 147 149 166 107 110 116 114 93 83 64 79 65 64 67 77 72 61 74 81 97 69 69 79 74 50 63 55 65 86 67 74 74 85 75 57 63 70 66 57 81 77 62 71 85 77 60 93 80 143 148 122 116 76 104 113 85 86 80 76 78 69 80 72 80 89 99 93 102 87 114 113 97 125 89 130 138 107 126 137 100 102 100 102 92 79 80 68 84 75 92 72 91 92 73 90 75 69 82 83 74 84 96 83 74 96 105 99 71 81 82 75 94 77 83 85 76 93 104 113 112 116 99 117 110 76 95 96 72 66 60 74 70 75 72 83 59 74 95 68 84 85 67 91 109 84 91 70 107 108 95 109 98 96 80 86 85 111 83 76 77 78 57 80 89 74 65 69 82 76 85 60 76 65 80 77 79 68 95 78 79 95 77 121 203 305 306 191 158 151 186 194 158 119 101 72 93 81 82 82 92 93 115 103 99 106 104 147 179 225 166 164 168 158 198 149 150 191 186 222 164 135 129 157 132 154 132 106 114 96 85 98 114 100 111 109 122 113 91 105 126 110 111 123 118 129 139 158 133 147 149 189 219 209 147 162 170 165 157 152 124 108 158 169 183 177 127 114 124 121 102 108 94 103 102 104 85 94 85 100 81 71 84 74 72 80 82 85 76 80 98 73 57 85 78 70 90 89 80 77 62 80 73 94 59 80 51 76 80 77 68 73 77 72 76 65 59 72 62 60 65 76 61 81 71 71 66 67 89 79 65 70 57 83 64 54 62 60 67 91 81 70 71 73 62 74 51 65 83 78 79 64 83 91 88 70 102 90 74 87 96 100 96 77 94 77 63 86 75 86 71 86 67 78 70 75 62 80 78 99 89 89 91 99 75 86 85 101 93 83 78 97 103 94 81 94 91 86 90 79 86 71 73 81 66 67 92 94 84 79 88 100 87 77 87 95 74 108 109 76 99 97 108 96 122 166 138 100 103 95 97 108 113 100 84 85 85 90 85 110 82 104 89 70 66 74 75 77 70 67 95 81 77 75 69 90 104 113 187 199 175 138 120 138 135 127 125 102 78 67 80 80 67 57 79 76 54 58 51 61 67 57 62 61 81 73 80 70 80 99 73 77 80 78 74 78 79 80 77 84 87 86 76 107 103 89 108 112 91 95 103 100 78 101 78 102 86 98 99 72 80 81 80 75 92 85 63 69 80 74 72 79 72 69 97 91 92 78 77 110 78 102 106 92 115 77 95 93 104 101 112 116 109 145 146 137 112 81 87 99 104 117 85 88 66 71 73 71 78 79 63 56 72 81 74 73 60 47 70 68 77 81 83 73 56 86 85 81 61 69 57 61 72 72 71 72 89 109 112 108 68 82 58 93 73 81 74 61 73 64 60 78 66 54 65 76 64 72 100 120 142 152 128 116 111 95 107 127 108 99 72 77 83 90 79 71 72 67 78 73 62 57 69 78 77 70 71 90 77 66 51 89 87 94 103 97 102 95 119 89 95 79 97 121 121 117 91 96 114 76 101 86 69 97 84 94 89 73 66 88 90 71 90 74 104 72 80 103 96 84 111 88 85 90 113 106 96 91 112 86 95 108 91 108 82 99 117 76 86 84 73 80 77 66 75 81 77 62 83 68 79 69 53 71 69 66 87 83 80 64 85 73 71 78 79 74 72 87 69 67 69 55 98 73 67 69 79 89 73 74 83 67 79 71 71 78 74 64 85 66 110 81 81 92 110 96 87 67 95 64 51 79 72 83 82 77 74 65 58 69 57 84 74 67 95 97 88 79 83 96 86 87 100 94 108 88 101 81 89 100 84 74 106 93 77 100 70 65 79 82 82 62 74 84 79 95 70 77 71 81 72 79 73 78 70 86 72 76 63 72 97 102 82 85 102 114 107 115 113 105 103 77 88 87 100 91 85 77 88 92 69 85 79 84 76 61 54 72 68 76 67 59 78 65 74 74 73 64 67 68 59 78 60 60 52 66 50 71 49 79 72 86 66 66 55 55 72 59 70 69 74 79 92 75 89 80 80 64 71 68 70 64 64 67 56 76 86 66 81 69 73 80 68 74 62 81 70 53 90 74 73 81 60 68 82 91 80 72 71 65 77 69 82 74 75 75 70 82 75 62 58 91 71 80 66 80 91 70 86 78 74 74 107 103 86 101 83 98 82 116 110 86 97 93 90 76 99 140 121 124 176 144 144 89 106 109 112 105 125 121 109 130 118 75 91 81 80 82 81 84 94 92 85 86 70 93 64 94 78 84 90 90 83 105 83 92 93 86 103 99 88 89 109 100 104 107 140 138 168 134 125 126 101 78 94 101 120 98 130 127 85 84 85 105 85 79 97 99 100 118 130 117 166 123 106 108 118 106 91 134 145 173 158 151 113 121 117 122 98 77 99 102 108 101 99 87 88 75 96 73 79 76 77 82 79 68 71 78 89 76 80 93 75 84 82 85 90 81 110 95 95 99 98 99 101 111 107 107 106 94 108 101 78 95 82 85 84 91 107 102 85 90 85 74 90 92 99 103 78 69 78 100 102 81 96 98 89 81 82 79 118 106 94 105 83 82 92 87 91 92 80 86 81 73 91 88 82 82 85 76 83 75 83 75 86 79 75 80 83 97 91 101 65 76 80 69 57 65 77 78 82 70 61 60 81 68 67 65 81 71 61 77 74 75 81 74 80 76 72 79 72 89 78 81 84 74 71 84 66 85 66 66 79 71 65 72 67 56 61 76 70 47 73 79 68 80 78 109 98 103 97 83 71 77 101 76 88 75 84 91 110 87 81 76 73 66 72 67 71 93 77 82 82 89 92 99 96 75 71 89 88 80 77 88 72 62 89 108 99 84 67 97 77 86 79 82 73 68 85 92 73 70 90 95 74 73 65 72 81 67 69 63 71 73 70 66 80 76 85 84 54 92 74 82 76 79 79 87 92 56 74 75 81 70 70 75 78 55 71 86 79 58 60 73 72 64 83 70 92 82 71 88 93 93 95 94 91 72 74 93 62 81 68 81 87 86 95 94 97 117 100 70 80 88 86 77 91 101 80 85 80 83 86 98 77 108 112 77 96 81 67 77 73 70 66 77 76 105 92 102 97 100 90 95 68 68 73 85 74 113 82 77 70 91 81 79 81 86 85 75 78 88 84 91 67 80 89 77 82 89 78 82 102 86 78 82 76 63 67 56 67 81 83 86 75 87 98 64 67 88 89 72 83 99 75 82 80 89 103 89 78 76 106 95 82 89 83 92 84 73 100 99 83 118 109 84 118 97 97 100 88 107 79 83 80 71 96 103 84 102 92 89 75 104 103 82 88 92 105 85 121 130 101 115 102 76 116 99 104 87 111 99 107 101 110 116 135 111 125 101 116 116 118 123 87 106 106 114 113 110 126 131 135 130 140 129 122 106 107 131 105 80 97 85 102 80 104 113 113 96 102 103 99 100 98 98 84 109 89 93 86 91 69 77 88 82 91 86 94 83 102 90 97 98 84 91 76 89 87 88 87 70 73 81 91 69 78 74 102 79 86 72 90 63 104 86 77 79 88 86 95 103 97 112 93 109 97 93 84 84 79 100 84 102 90 107 82 86 83 75 112 97 98 113 113 109 128 108 85 108 66 84 99 86 92 71 80 100 87 98 100 102 103 91 75 85 87 98 64 100 106 109 87 106 99 100 91 93 60 94 90 104 114 84 91 95 103 96 83 108 104 98 111 82 113 117 116 83 83 86 115 90 87 89 95 94 97 93 91 113 78 93 108 101 113 89 116 107 89 117 115 120 115 106 124 104 96 123 90 94 118 105 99 111 109 117 109 105 97 114 117 103 95 102 92 98 125 98 100 104 88 103 82 94 107 125 107 114 98 101 114 118 129 98 83 114 88 115 111 102 119 113 97 76</counts>
			</dataPoints>
		</scan>
	</xrdMeasurement>
</xrdMeasurements>