File: dataset/precursor_mixture/HfO2_La(OH)3_Li3PO4_Bi2O3-beta.12-min.xrdml
<?xml version="1.0"?>
<xrdMeasurements xmlns="http://www.xrdml.com/XRDMeasurement/2.2" xmlns:xsi="http://www.w3.org/2001/XMLSchema-instance" xsi:schemaLocation="http://www.xrdml.com/XRDMeasurement/2.2 http://www.xrdml.com/XRDMeasurement/2.2/XRDMeasurement.xsd" status="Completed" recordIdentifier="{57E74BA4-982B-43B3-B907-2D3753B26A1A}">
	<comment>
		<entry/>
	</comment>
	<sample type="To be analyzed">
		<id>dara-49-2</id>
		<name></name>
		<preparedBy></preparedBy>
	</sample>
	<xrdMeasurement measurementType="Scan" status="Completed" sampleMode="Reflection">
		<usedWavelength intended="K-Alpha 1">
			<kAlpha1 unit="Angstrom">1.5405980</kAlpha1>
			<kAlpha2 unit="Angstrom">1.5444260</kAlpha2>
			<kBeta unit="Angstrom">1.3922500</kBeta>
			<ratioKAlpha2KAlpha1>0.5000</ratioKAlpha2KAlpha1>
		</usedWavelength>
		<incidentBeamPath>
			<radius unit="mm">145.00</radius>
			<xRayTube id="1010048" name="Empyrean Cu LFF HR (9430 033 7310x) DK437873">
				<tension unit="kV">40.0</tension>
				<current unit="mA">15.0</current>
				<anodeMaterial>Cu</anodeMaterial>
				<focus type="Line">
					<length unit="mm">12.0</length>
					<width unit="mm">0.4</width>
					<takeOffAngle unit="deg">6.0</takeOffAngle>
				</focus>
			</xRayTube>
			<filter id="20010004" name="Beta-filter Nickel">
				<material>Ni</material>
				<thickness unit="mm">0.020</thickness>
			</filter>
			<sollerSlit id="21010002" name="Soller slits 0.04 rad.">
				<opening unit="rad">0.0400</opening>
			</sollerSlit>
			<mask id="22031000" name="Fixed mask 13 mm">
				<width unit="mm">9.00</width>
			</mask>
			<divergenceSlit id="22120001" name="Divergence slit 1°" xsi:type="fixedDivergenceSlitType">
				<distanceToSample unit="mm">50.00</distanceToSample>
				<height unit="mm">1.52</height>
			</divergenceSlit>
		</incidentBeamPath>
		<beamKnife id="29030100" name="Beam knife low"/>
		<sampleMovement xsi:type="spinningSampleMovementType">
			<spinnerRevolutionTime unit="seconds">1.0</spinnerRevolutionTime>
		</sampleMovement>
		<diffractedBeamPath>
			<radius unit="mm">145.00</radius>
			<antiScatterSlit id="22090040" name="AS slit 9 mm" xsi:type="fixedAntiScatterSlitType">
				<height unit="mm">9.00</height>
			</antiScatterSlit>
			<sollerSlit id="21020003" name="Large Soller slits 0.04 rad.">
				<opening unit="rad">0.0400</opening>
			</sollerSlit>
			<filter id="20030001" name="Large beta-filter Nickel">
				<material>Ni</material>
				<thickness unit="mm">0.020</thickness>
			</filter>
			<detector id="7010019" name="PIXcel1D-Medipix3 detector" xsi:type="rtmsDetectorType">
				<phd unit="keV">
					<lowerLevel>4.0</lowerLevel>
					<upperLevel>11.3</upperLevel>
				</phd>
				<mode>Scanning</mode>
				<activeLength unit="deg">5.020</activeLength>
			</detector>
		</diffractedBeamPath>
		<scan appendNumber="0" mode="Continuous" scanAxis="Gonio" status="Completed">
			<header>
				<startTimeStamp>2024-03-24T18:23:54-07:00</startTimeStamp>
				<endTimeStamp>2024-03-24T18:36:22-07:00</endTimeStamp>
				<author>
					<name>AutomatedUser</name>
				</author>
				<source>
					<applicationSoftware version="1.6 (94)">PANalytical Aeris Instrument Suite</applicationSoftware>
					<instrumentControlSoftware version="3.0.0 20211014">AERIS</instrumentControlSoftware>
					<instrumentID>2879380</instrumentID>
				</source>
			</header>
			<dataPoints>
				<positions axis="2Theta" unit="deg">
					<startPosition>9.99043322</startPosition>
					<endPosition>100.09495370</endPosition>
				</positions>
				<positions axis="Omega" unit="deg">
					<startPosition>4.99521661</startPosition>
					<endPosition>50.04747685</endPosition>
				</positions>
				<commonCountingTime unit="seconds">18.249</commonCountingTime>
				<counts unit="counts">3933 3891 3807 3977 3900 3915 3919 3875 3891 3730 3929 3910 3958 3947 3912 3961 3724 3780 3797 3873 3867 3813 3862 3755 3891 3788 3789 3770 3658 3834 3856 3755 3788 3788 3763 3687 3737 3812 3717 3739 3842 3866 3733 3779 3801 3757 3842 3725 3784 3855 3725 3611 3631 3723 3667 3725 3702 3710 3619 3712 3632 3601 3615 3595 3572 3701 3725 3659 3605 3527 3582 3586 3580 3664 3690 3633 3651 3647 3628 3570 3577 3509 3561 3528 3577 3543 3603 3466 3534 3449 3610 3455 3531 3577 3517 3482 3615 3635 3523 3487 3478 3496 3374 3453 3470 3438 3438 3416 3459 3519 3482 3413 3416 3508 3402 3434 3477 3411 3406 3394 3427 3298 3488 3364 3471 3454 3278 3505 3383 3361 3465 3362 3364 3321 3421 3294 3354 3343 3369 3352 3319 3322 3333 3295 3287 3352 3243 3356 3314 3154 3254 3220 3279 3269 3308 3231 3265 3290 3286 3244 3228 3202 3189 3181 3233 3227 3255 3123 3243 3146 3311 3200 3018 3217 3109 3274 3188 3133 3197 3291 3155 3196 3159 3188 3271 3254 3184 3250 3229 3260 3131 3203 3205 3155 3119 3137 3262 3041 3248 3028 3102 3107 3112 3093 3157 3100 3120 3140 3136 3092 3084 3056 3010 3107 3165 3132 3083 3078 3152 2990 3102 3057 3124 3025 3042 3091 3044 3153 3073 3098 2908 3058 3022 2938 3017 3069 2994 2997 2961 3018 3030 3066 2951 2901 2961 3013 2999 3006 2900 2938 3003 2994 3037 2970 2930 3021 2965 2971 2938 2938 2895 2891 2955 2941 2911 2913 2839 2928 2836 2928 2797 2968 2909 2942 3018 2868 2933 2903 2919 2869 2984 2910 2915 2850 2804 2850 2848 2867 2776 2773 2882 2751 2864 2867 2877 2875 2898 2750 2843 2791 2746 2885 2791 2744 2828 2846 2841 2907 2856 2684 2843 2829 2813 2792 2874 2804 2759 2737 2678 2761 2805 2793 2703 2819 2679 2742 2678 2781 2728 2776 2636 2807 2855 2738 2697 2754 2797 2790 2722 2692 2653 2756 2716 2747 2723 2770 2670 2731 2797 2666 2669 2761 2607 2688 2737 2653 2771 2687 2686 2661 2786 2727 2684 2632 2717 2685 2636 2772 2653 2617 2502 2688 2677 2712 2684 2690 2634 2663 2669 2658 2615 2732 2665 2676 2610 2641 2539 2553 2631 2654 2645 2634 2691 2712 2678 2584 2604 2729 2639 2598 2580 2597 2699 2591 2592 2638 2588 2536 2724 2649 2681 2552 2586 2580 2598 2545 2630 2650 2565 2592 2630 2648 2573 2579 2616 2545 2528 2681 2572 2592 2571 2592 2581 2600 2534 2599 2554 2539 2506 2645 2616 2552 2551 2658 2539 2617 2490 2737 2597 2569 2652 2582 2590 2634 2609 2668 2550 2568 2560 2602 2589 2669 2602 2647 2681 2723 2624 2659 2726 2653 2586 2739 2791 2690 2786 2716 2718 2896 2782 2927 2915 2896 2948 2907 2919 3079 3053 3066 3086 3248 3087 3160 3288 3386 3389 3485 3475 3697 3691 3802 3889 3893 4204 4318 4332 4532 4653 4861 5173 5191 5619 5726 6022 6398 6613 6832 7103 7390 7760 8284 8560 8931 9250 9388 9556 9854 9811 9886 9804 9741 9715 9463 8949 8544 8215 7669 7266 6723 6122 5771 5434 5202 4786 4517 4346 4030 3975 3888 3634 3470 3434 3292 3198 3193 3170 3207 3121 3054 3069 3082 2937 2980 2892 2873 2892 2989 2866 2851 2830 2890 2940 2885 2762 2902 2734 2710 2949 2798 2851 2813 2892 2795 2748 2690 2669 2689 2571 2632 2602 2595 2623 2537 2494 2567 2472 2492 2453 2546 2368 2362 2383 2524 2448 2398 2398 2444 2473 2390 2401 2466 2533 2401 2430 2482 2449 2435 2406 2389 2389 2383 2459 2409 2433 2394 2325 2403 2463 2398 2485 2516 2504 2499 2531 2557 2417 2571 2484 2527 2658 2572 2482 2669 2544 2560 2568 2566 2668 2630 2561 2567 2547 2508 2522 2459 2457 2477 2501 2378 2430 2406 2322 2361 2475 2318 2339 2364 2355 2393 2271 2329 2298 2335 2293 2338 2286 2417 2341 2413 2337 2282 2369 2409 2397 2503 2394 2505 2478 2454 2471 2559 2541 2536 2630 2509 2504 2672 2687 2758 2700 2843 2833 2798 2838 2835 2723 2745 2849 2776 2677 2661 2588 2558 2439 2428 2516 2378 2364 2290 2274 2267 2369 2340 2261 2271 2203 2195 2228 2153 2208 2169 2183 2241 2195 2218 2205 2252 2114 2147 2171 2142 2232 2183 2256 2156 2194 2186 2182 2159 2171 2165 2167 2150 2143 2095 2180 2125 2182 2205 2219 2128 2083 2205 2157 2203 2150 2101 2233 2122 2140 2158 2249 2061 2078 2183 2126 2095 2116 2085 2220 2128 2115 2134 2114 2189 2087 2125 2130 2105 2097 2047 2173 2048 2134 2040 2164 2022 2036 2028 2095 2111 2080 2198 2026 2114 2076 2074 2065 2043 2089 2058 1994 2039 2086 2089 2034 2061 2038 2111 2058 2025 2051 2053 2084 2101 2023 2015 2076 2085 1962 2033 1945 2049 2030 2030 1972 2089 2023 2023 2006 1994 1954 2060 1975 2041 2033 2070 2052 2032 2065 1963 2013 1999 2022 1984 1923 2107 1961 1982 2086 2019 2081 2089 2089 2009 1986 1985 1976 2020 1961 1933 1993 2000 1901 2062 1935 2025 1977 1994 1945 1915 2099 1903 1923 1883 1950 1966 1906 1952 1987 1964 2006 1956 2000 1922 1889 1945 1971 1868 2018 2018 1964 1959 1992 1942 2007 1999 1915 2051 1872 2029 1933 1857 1973 1954 1976 1939 1938 1894 1922 1920 1844 2005 1909 1994 1917 1896 1926 1894 1991 1891 2020 1983 1878 1991 1964 1967 1913 1954 1940 1895 1971 1877 1906 1935 1922 1879 1883 1868 1941 1873 1914 1878 1918 1925 1877 1863 1846 1953 1827 1842 1973 1795 1894 1927 1886 1909 1869 1821 1836 1782 1775 1876 1833 1800 1940 1839 1987 1884 1832 1827 1928 1839 1844 1833 1778 1868 1890 1897 1814 1824 1868 1840 1849 1850 1880 1874 1863 1862 1814 1877 1858 1814 1852 1918 1749 1830 1905 1816 1907 1849 1809 1826 1774 1790 1740 1817 1806 1831 1891 1767 1873 1802 1770 1805 1821 1864 1786 1802 1764 1789 1897 1772 1844 1869 1826 1898 1751 1800 1846 1844 1776 1797 1815 1779 1871 1780 1820 1831 1828 1859 1832 1838 1817 1777 1760 1730 1752 1828 1777 1840 1783 1743 1829 1763 1758 1759 1784 1762 1830 1696 1785 1743 1832 1719 1787 1747 1702 1794 1742 1692 1828 1730 1833 1762 1823 1807 1759 1887 1938 1800 1751 1763 1780 1802 1855 1841 1822 1897 1818 1878 1838 1835 1834 1812 1848 1842 1843 1810 1807 1918 1731 1870 1804 1930 1886 1883 1877 1920 1908 1911 1937 1967 1986 2033 2056 2113 2158 2132 2136 2168 2230 2304 2261 2433 2355 2465 2537 2620 2636 2671 2664 2652 2840 2694 2814 2734 2706 2714 2681 2567 2437 2411 2344 2331 2187 2159 2089 2084 2035 1995 1896 2009 1956 1995 1902 1854 1879 1858 1841 1871 1863 1813 1860 1775 1822 1797 1778 1839 1803 1869 1824 1735 1704 1757 1827 1667 1683 1769 1791 1890 1832 1818 1819 1820 1843 1810 1925 1849 1921 1911 1946 1953 1959 1907 1994 1965 1980 2000 2069 1924 2082 2000 2024 2134 2085 2229 2229 2188 2248 2315 2221 2303 2422 2441 2439 2429 2360 2396 2395 2368 2423 2420 2425 2391 2359 2445 2330 2337 2327 2382 2343 2322 2295 2259 2206 2286 2118 2093 2005 2029 2033 1807 1858 1911 1903 1865 1886 1831 1802 1778 1723 1872 1815 1778 1773 1687 1745 1752 1762 1811 1720 1728 1762 1735 1781 1869 1826 1771 1845 1779 1839 1814 1945 1847 1867 1916 1891 1823 1867 1880 1981 1962 1994 2008 1973 1929 2061 2141 2136 2153 2164 2354 2354 2433 2518 2633 2743 2920 2969 3038 3199 3324 3436 3466 3473 3379 3481 3381 3389 3212 2991 3055 2773 2721 2680 2510 2366 2393 2249 2228 2125 2189 2162 2093 2123 2143 2146 2129 2170 2274 2374 2398 2534 2604 2640 2736 2741 3001 3049 3118 2971 3202 3272 3131 3261 3079 3096 2890 2848 2794 2740 2630 2631 2441 2368 2292 2319 2211 2188 2231 2049 2149 2114 2075 2212 2215 2127 2149 2119 2117 2013 2072 2091 2057 2139 2026 2062 2077 1964 1995 1971 1989 1995 1925 1996 1835 1911 1943 1938 1820 1787 1867 1810 1851 1848 1786 1813 1864 1749 1816 1797 1749 1752 1720 1725 1810 1701 1790 1742 1697 1647 1665 1637 1597 1654 1635 1612 1607 1656 1628 1648 1642 1672 1687 1769 1704 1759 1792 1786 1784 1829 1850 1829 1882 1980 1971 2161 2121 2171 2199 2262 2320 2391 2416 2462 2414 2485 2467 2323 2252 2205 2064 2072 1912 1908 1804 1824 1703 1737 1614 1630 1654 1572 1652 1579 1613 1534 1622 1620 1716 1619 1583 1554 1611 1550 1571 1609 1632 1642 1572 1624 1570 1603 1519 1609 1567 1611 1575 1630 1556 1547 1583 1558 1552 1567 1577 1612 1579 1615 1630 1595 1595 1518 1594 1525 1598 1624 1622 1619 1606 1587 1617 1628 1650 1612 1587 1633 1708 1663 1668 1579 1618 1672 1650 1682 1697 1761 1635 1706 1672 1699 1627 1764 1772 1729 1787 1799 1734 1782 1742 1861 1749 1770 1795 1845 1883 1875 1846 1873 1974 1989 2024 1954 2083 2143 2192 2279 2264 2328 2419 2373 2472 2727 2641 2756 2802 3054 3161 3241 3414 3520 3748 3845 4157 4281 4631 4892 5017 5308 5628 5886 6123 6410 6847 6747 6922 7236 7207 7240 7260 7084 7050 6883 6771 6483 6175 6083 5716 5536 5298 4995 4797 4528 4289 4299 4109 3974 3926 3760 3724 3698 3636 3604 3704 3634 3635 3501 3613 3758 3697 3811 3943 4035 4158 4417 4480 4794 5071 5636 5934 6384 6832 7545 8441 9172 10316 11388 12875 14461 16431 18702 21117 23777 26893 30156 33244 37101 40674 43974 47090 48529 48594 47844 45495 42052 38783 35631 32313 29385 25990 22418 18999 16395 14078 12355 10933 10001 9328 8866 8424 8027 8140 8003 8090 8422 8620 9050 9463 9815 10528 10815 11712 11881 12655 12883 13280 13428 13223 13085 12901 12397 11816 11144 10610 9723 9076 8344 7593 6850 6391 5726 5541 4846 4619 4325 4086 3851 3595 3417 3347 3196 3169 3070 2878 2876 2754 2617 2670 2687 2634 2515 2489 2342 2367 2319 2288 2314 2211 2167 2240 2276 2254 2209 2224 2127 2134 2140 2096 2147 2050 2074 2162 2101 2079 2157 2093 1997 2008 2079 1993 1950 1981 1985 1966 2052 1945 1952 1905 1984 1987 1944 1883 1907 1932 1871 1987 1834 1882 1886 1886 1887 1885 1764 1812 1795 1742 1745 1723 1656 1795 1651 1779 1658 1795 1720 1674 1725 1675 1703 1680 1653 1636 1654 1660 1633 1637 1635 1694 1657 1596 1579 1583 1574 1596 1615 1663 1625 1627 1596 1555 1526 1541 1607 1595 1624 1711 1596 1580 1607 1586 1592 1570 1629 1542 1589 1638 1616 1619 1585 1627 1609 1550 1670 1577 1643 1625 1624 1620 1595 1586 1620 1680 1714 1601 1631 1652 1682 1678 1681 1731 1796 1753 1779 1872 1871 1967 2079 2101 2120 2166 2187 2284 2318 2503 2592 2394 2359 2387 2403 2257 2254 2113 2103 2048 1963 1834 1749 1825 1750 1674 1703 1691 1665 1579 1629 1638 1615 1617 1623 1632 1589 1616 1580 1549 1606 1564 1658 1640 1674 1617 1542 1640 1583 1688 1638 1571 1656 1564 1648 1523 1650 1564 1638 1577 1703 1619 1577 1586 1615 1652 1640 1619 1634 1580 1671 1707 1651 1601 1603 1578 1716 1659 1720 1751 1726 1714 1727 1688 1816 1809 1787 1825 1857 1853 1878 1886 1852 1882 1818 2006 1974 2005 1970 2139 2147 2093 2252 2147 2214 2236 2411 2351 2542 2590 2718 2819 2770 3056 3167 3358 3382 3650 3951 4113 4229 4619 4791 5101 5481 6154 6647 7078 7475 8079 8849 9089 9892 10244 11030 11565 11788 12523 12617 12832 13090 12834 13099 13160 13010 12969 12984 12614 12182 11315 10616 9838 8781 8179 7508 6948 6274 5651 5075 4469 4080 3628 3176 3040 2897 2727 2647 2656 2441 2357 2278 2181 2187 2110 2089 2042 2063 1924 1962 1955 1969 1841 1766 1831 1807 1834 1762 1795 1751 1766 1791 1732 1684 1745 1757 1646 1747 1720 1714 1685 1701 1695 1752 1748 1806 1708 1769 1816 1908 1874 1919 1983 2206 2235 2333 2434 2587 2814 2941 3094 3487 4010 4358 4829 5563 6191 7113 7852 8795 9795 10769 11447 12025 11740 11488 10776 9902 9122 8499 8038 7439 6746 6029 5242 4544 3992 3323 2977 2527 2442 2248 2058 1980 1833 1866 1718 1699 1723 1698 1713 1690 1666 1650 1581 1491 1573 1460 1522 1497 1486 1471 1441 1515 1408 1448 1423 1485 1431 1435 1412 1389 1400 1453 1412 1322 1398 1363 1390 1423 1353 1396 1320 1352 1382 1411 1474 1352 1398 1348 1354 1402 1361 1377 1310 1396 1385 1382 1413 1354 1339 1486 1368 1363 1414 1394 1438 1463 1466 1439 1423 1393 1359 1398 1469 1436 1525 1463 1500 1626 1633 1583 1647 1668 1686 1759 1704 1819 1788 1869 1930 2023 2071 2135 2155 2224 2218 2183 2201 2247 2231 2276 2164 2204 2105 2083 2192 2101 2033 2049 2010 2092 2097 2042 2117 2094 2266 2266 2458 2561 2575 2687 2765 2907 3110 3261 3384 3431 3650 3841 4005 4164 4269 4269 4457 4472 4410 4356 4194 4189 3952 3834 3647 3520 3472 3288 3242 3093 3057 3044 2999 3032 3088 3156 3306 3382 3417 3503 3634 3652 3858 3805 3909 3750 3690 3596 3398 3383 3191 3084 2884 2765 2596 2428 2354 2255 2086 2046 1900 1807 1697 1694 1658 1642 1564 1504 1613 1562 1577 1474 1515 1422 1483 1479 1430 1401 1326 1416 1435 1395 1456 1373 1396 1374 1368 1464 1432 1390 1412 1373 1478 1460 1442 1471 1374 1458 1478 1511 1528 1478 1499 1569 1607 1636 1572 1664 1695 1732 1887 1922 1904 2039 2169 2265 2452 2653 2766 2917 3193 3371 3613 3817 3987 4040 4049 3908 3868 3855 3787 3582 3388 3240 3076 2991 2690 2623 2456 2302 2213 2029 1845 1840 1813 1706 1793 1607 1576 1619 1599 1643 1590 1626 1650 1714 1670 1800 1767 1756 1757 1827 1899 1818 1885 1989 2004 2066 2061 2177 2147 2191 2224 2221 2237 2243 2276 2322 2187 2273 2188 2063 2032 2022 1919 1870 1815 1802 1800 1695 1685 1559 1535 1459 1430 1433 1340 1428 1426 1337 1330 1321 1384 1288 1369 1328 1367 1280 1369 1328 1373 1358 1393 1461 1482 1420 1418 1488 1421 1488 1530 1465 1506 1487 1496 1434 1442 1499 1487 1451 1383 1411 1387 1428 1314 1357 1348 1275 1348 1305 1298 1338 1289 1287 1368 1299 1323 1271 1339 1247 1335 1263 1334 1309 1384 1305 1338 1310 1328 1328 1299 1412 1333 1329 1325 1408 1361 1298 1318 1438 1365 1287 1298 1222 1318 1263 1214 1252 1208 1260 1227 1220 1117 1180 1150 1098 1096 1064 1157 1119 1117 1081 1103 1146 1109 1106 1068 1078 1076 1137 1141 1144 1109 1089 1078 1056 1086 1093 1064 1138 1156 1083 1081 1062 1100 1082 1132 1082 1147 1021 1072 1066 1138 1064 1107 1010 1066 1085 1072 1040 1046 1091 1055 1062 1048 1066 1118 1041 1059 1077 1098 993 1063 1131 1102 1093 1136 1078 1087 1082 1073 1087 1097 1108 1097 1019 1168 1095 1142 1109 1071 1072 1063 1096 1096 1117 1127 1118 1183 1089 1156 1123 1094 1127 1110 1200 1152 1179 1194 1266 1134 1234 1290 1308 1280 1338 1254 1313 1217 1336 1297 1277 1275 1281 1188 1282 1292 1257 1275 1179 1250 1172 1223 1231 1276 1252 1267 1296 1286 1308 1324 1440 1409 1478 1533 1490 1591 1613 1779 1778 1870 1876 1942 1997 2202 2151 2189 2158 2248 2222 2227 2209 2178 2101 2077 2036 1976 1889 1865 1813 1738 1766 1681 1693 1606 1581 1661 1634 1588 1614 1577 1649 1612 1643 1627 1661 1726 1746 1762 1769 1854 1808 1843 1994 2122 2143 2122 2287 2328 2398 2569 2748 2818 2928 3075 3130 3404 3713 3853 4006 4185 4377 4672 4858 5023 5112 5359 5435 5650 5522 5470 5465 5417 5230 5140 5143 4940 4743 4527 4395 4324 4073 3907 3602 3427 3295 3108 2890 2811 2693 2498 2346 2361 2218 2084 2055 1859 1932 1824 1754 1733 1619 1661 1553 1601 1564 1519 1438 1435 1441 1424 1401 1390 1274 1352 1246 1323 1309 1283 1345 1305 1306 1287 1297 1275 1313 1322 1324 1359 1387 1346 1296 1285 1277 1336 1277 1280 1267 1265 1294 1293 1309 1212 1285 1191 1242 1217 1257 1194 1156 1144 1164 1117 1187 1172 1208 1045 1135 1098 1148 1158 1104 1138 1115 1135 1200 1161 1186 1144 1210 1131 1118 1190 1196 1178 1214 1123 1205 1161 1256 1238 1263 1218 1264 1249 1250 1256 1258 1269 1312 1398 1395 1416 1471 1564 1527 1530 1656 1778 1839 1904 1990 2057 2094 2216 2281 2344 2355 2323 2388 2361 2308 2271 2258 2179 2136 2139 2093 2059 1918 1884 1784 1797 1773 1685 1667 1681 1570 1630 1753 1676 1762 1742 1886 2004 2008 2052 2106 2181 2157 2080 2055 2056 1964 1999 2033 1893 1987 1861 1899 1855 1799 1658 1634 1623 1578 1616 1588 1589 1553 1592 1641 1547 1550 1545 1581 1548 1565 1626 1542 1527 1513 1509 1542 1462 1444 1440 1377 1325 1366 1403 1331 1328 1319 1319 1254 1320 1222 1380 1220 1306 1295 1290 1282 1265 1230 1258 1357 1285 1315 1352 1441 1441 1509 1509 1525 1575 1590 1596 1586 1639 1739 1745 1759 1762 1824 1891 1888 1879 1961 1858 1904 1866 1930 1891 1843 1778 1831 1805 1764 1751 1691 1724 1593 1609 1553 1528 1507 1528 1438 1442 1325 1317 1277 1264 1222 1293 1237 1120 1220 1176 1069 1141 1173 1147 1137 1068 1070 1042 1106 1055 1041 1026 1071 1101 986 1056 1027 983 1099 1027 1015 994 997 1048 1024 970 1047 995 977 962 989 950 946 982 979 959 1020 1011 1024 1030 998 931 977 960 952 1040 1014 961 1017 957 990 996 928 1026 981 944 979 941 1042 1022 992 1033 968 950 994 1039 982 1028 917 999 969 986 993 978 981 938 967 991 956 984 923 944 978 940 999 927 990 946 992 956 999 994 1006 996 978 1020 944 1017 983 950 960 987 915 943 996 1005 975 1014 969 986 981 982 958 958 959 949 956 917 947 988 925 960 973 939 915 976 978 984 918 1005 922 954 934 960 958 927 930 921 920 963 892 915 963 939 932 913 917 953 904 901 974 959 934 943 908 953 918 907 929 951 931 936 950 953 877 921 921 887 964 971 939 933 902 976 953 995 948 903 980 974 960 996 937 957 940 960 981 970 957 991 962 975 1021 1014 1021 975 910 957 966 974 1042 1045 1056 1040 1012 962 990 1029 1004 1057 995 987 1183 1041 1081 1091 1042 1095 1091 1053 1175 1163 1162 1153 1183 1208 1338 1284 1287 1449 1450 1485 1576 1524 1656 1660 1678 1777 1834 1819 1788 1752 1858 1744 1781 1629 1611 1553 1538 1501 1480 1428 1381 1432 1436 1389 1269 1246 1197 1175 1260 1223 1145 1205 1136 1071 1092 1083 1130 1103 1067 1058 1187 1133 1110 1150 1153 1174 1150 1141 1232 1130 1238 1238 1264 1273 1335 1392 1338 1485 1461 1425 1585 1665 1617 1655 1737 1725 1766 1788 1848 1753 1788 1747 1691 1715 1738 1761 1649 1731 1740 1655 1628 1694 1636 1609 1658 1665 1670 1729 1772 1822 1898 1906 2073 2090 2342 2557 2814 3127 3578 4203 4767 5642 6612 7532 8671 9330 10312 10781 10836 10077 9362 8502 7459 6936 6487 6495 6329 6603 6446 6199 5790 5239 4528 3771 3280 2729 2437 2273 1966 1883 1771 1730 1585 1515 1568 1577 1435 1426 1463 1436 1337 1436 1432 1403 1323 1433 1395 1311 1403 1377 1434 1453 1471 1509 1535 1583 1666 1730 1901 2060 2321 2517 2787 3181 3558 4112 4520 4961 5489 5670 5804 5808 5257 4921 4567 4142 4056 4046 4022 4174 4145 4103 3986 3762 3516 3324 3147 2774 2529 2427 2267 2225 2090 2023 2002 1867 1892 1813 1724 1705 1705 1700 1534 1530 1500 1414 1377 1490 1370 1308 1360 1293 1265 1276 1256 1214 1234 1171 1187 1159 1166 1186 1111 1131 1122 1170 1171 1143 1139 1101 1127 1142 1234 1155 1039 1132 1100 1133 1212 1222 1108 1148 1166 1225 1092 1179 1155 1169 1192 1170 1192 1199 1276 1295 1194 1263 1302 1384 1293 1354 1360 1414 1421 1372 1471 1496 1537 1526 1583 1691 1612 1647 1656 1735 1792 1913 1937 1996 2078 2101 2242 2309 2356 2499 2639 2577 2660 2694 2827 2816 2815 2739 2854 2786 2846 2845 2828 2880 2820 2876 2904 2908 2913 2861 2937 2950 2962 3137 3148 3223 3309 3289 3331 3343 3421 3337 3515 3582 3761 3938 3889 4127 4121 4333 4419 4419 4480 4590 4664 4581 4608 4742 4563 4525 4366 4359 4209 4229 4077 3930 3793 3650 3627 3506 3355 3180 3073 3043 2866 2707 2583 2625 2535 2345 2266 2178 2096 1998 1973 1903 1867 1846 1792 1736 1743 1589 1602 1648 1567 1526 1576 1503 1504 1522 1495 1549 1465 1462 1423 1514 1432 1472 1505 1494 1505 1554 1491 1519 1567 1513 1580 1492 1537 1547 1456 1601 1559 1598 1675 1765 1724 1695 1885 1844 1934 2171 2311 2322 2639 2580 2689 2978 2947 3112 3098 2984 3017 2991 2850 2865 2657 2660 2643 2534 2653 2613 2410 2348 2272 2325 2105 2092 2002 1989 1845 1839 1784 1818 1801 1660 1741 1730 1706 1667 1760 1734 1722 1756 1808 1793 1685 1810 1736 1711 1724 1653 1576 1667 1627 1613 1522 1569 1570 1521 1576 1406 1452 1416 1388 1430 1393 1409 1320 1423 1452 1382 1385 1420 1489 1498 1553 1561 1636 1812 1804 1957 2123 2387 2451 2654 2804 3042 3144 3390 3397 3668 3580 3588 3409 3331 3314 3167 3029 2986 2813 2801 2805 2836 2682 2449 2513 2396 2313 2144 2070 1908 1852 1803 1759 1756 1717 1847 1674 1831 1839 1744 1846 1880 2061 2016 2150 2136 2211 2300 2299 2300 2342 2294 2198 2134 2089 2114 2048 1968 2021 1882 1989 1851 1890 1831 1679 1726 1662 1591 1509 1512 1481 1507 1433 1336 1483 1499 1502 1619 1699 1753 1852 1856 1994 2046 2015 1912 1742 1742 1664 1623 1602 1495 1556 1583 1604 1604 1646 1684 1574 1585 1568 1631 1508 1496 1538 1480 1488 1543 1509 1500 1568 1555 1592 1493 1438 1392 1409 1421 1359 1443 1327 1299 1339 1277 1246 1198 1255 1206 1245 1145 1103 1120 1127 1091 1107 1107 1047 1045 1027 1081 1013 1029 990 960 1034 972 940 928 1034 953 1008 934 994 1003 978 953 962 1019 921 947 951 898 921 978 965 952 922 971 978 958 926 896 963 959 936 956 989 926 959 941 896 1011 1028 917 971 950 913 955 941 1001 1019 980 869 978 966 925 922 989 963 961 1011 884 927 939 984 920 878 913 900 893 925 933 933 893 953 889 925 924 908 868 945 889 903 927 983 912 934 985 910 949 920 957 904 869 950 923 935 924 919 937 885 953 978 912 968 929 924 897 905 900 931 935 925 914 916 879 995 895 930 918 894 940 892 975 883 906 855 959 949 939 899 964 883 957 944 899 973 976 965 944 962 1027 996 926 936 958 962 990 954 982 975 1022 940 993 1021 1040 1022 1036 1093 1072 1110 1157 1229 1258 1134 1220 1208 1148 1176 1146 1110 1073 1170 1086 1094 1024 1184 1172 1210 1089 1115 1161 1139 1085 1064 1152 1063 1129 1134 1112 1136 1104 1112 1186 1172 1230 1238 1165 1259 1287 1243 1315 1267 1313 1414 1498 1557 1584 1628 1736 1792 2044 2178 2473 2739 3166 3464 4074 4516 5040 5868 6100 6575 6640 6373 5794 5529 4930 4522 4216 4302 4117 4350 4530 4564 4979 5137 4772 4559 4228 3619 3467 2982 2773 2682 2499 2393 2175 2210 2093 2108 1912 1976 1812 1883 1787 1736 1610 1596 1546 1560 1410 1433 1329 1377 1340 1273 1256 1288 1260 1352 1320 1283 1248 1313 1221 1256 1258 1276 1242 1351 1355 1319 1321 1370 1434 1360 1482 1406 1483 1478 1456 1562 1465 1630 1650 1653 1641 1731 1710 1858 1892 1955 2063 2034 2099 2130 2289 2230 2369 2363 2360 2425 2524 2571 2703 2689 2701 2957 2905 2960 3191 3467 3808 4139 4674 5142 5941 6652 7696 8613 9622 10289 10840 10634 10203 9078 8027 7261 6595 6219 6162 6232 6442 6825 7165 7491 7444 7248 6957 6537 5872 5397 4871 4488 4072 3809 3521 3467 3339 3242 3102 3065 3005 3079 2933 2910 2850 2730 2725 2711 2483 2563 2451 2346 2327 2336 2171 2171 2008 2019 1976 1987 1900 1985 1968 1848 1928 1843 1813 1848 1855 1825 1881 1891 1899 1960 1966 2040 2193 2269 2286 2307 2305 2452 2364 2398 2370 2438 2344 2313 2226 2227 2202 2205 2038 2166 1982 2084 2059 1964 1957 1799 1731 1723 1609 1670 1505 1446 1428 1478 1340 1304 1350 1258 1275 1217 1238 1218 1209 1247 1196 1102 1145 1129 1179 1178 1101 1064 1109 1043 1121 1100 1076 1137 1041 1025 1062 1037 1090 1111 1053 1076 1045 1021 1008 1010 990 1017 983 1107 1008 1008 1048 1009 984 1067 1024 1058 1098 1091 1111 1044 1118 1067 1062 1077 1100 1066 1129 1112 1101 1118 1112 1141 1131 1228 1167 1177 1189 1103 1214 1233 1193 1337 1268 1261 1285 1270 1357 1391 1437 1479 1577 1594 1693 1700 1692 1818 1844 1893 1876 1912 1978 1958 2044 1973 2166 2037 2189 2068 2265 2293 2575 2720 2739 3225 3542 3919 4355 4678 4980 5100 5205 4999 4555 4032 3604 3340 2983 2920 2968 2841 3023 3199 3292 3369 3299 3135 2941 2680 2521 2250 2001 1813 1753 1582 1603 1522 1515 1483 1397 1356 1345 1438 1382 1384 1434 1503 1410 1457 1475 1525 1527 1546 1562 1650 1600 1640 1593 1556 1632 1572 1503 1508 1490 1553 1530 1505 1496 1454 1435 1434 1423 1449 1470 1460 1451 1408 1375 1434 1406 1369 1352 1412 1436 1381 1429 1484 1555 1483 1549 1575 1482 1536 1532 1467 1538 1520 1470 1484 1504 1487 1469 1487 1507 1580 1486 1468 1449 1429 1399 1396 1341 1377 1370 1275 1285 1293 1289 1236 1255 1335 1262 1272 1263 1273 1260 1266 1279 1353 1379 1428 1434 1511 1493 1359 1404 1393 1251 1281 1144 1148 1174 1145 1131 1155 1142 1214 1261 1161 1229 1104 1168 1140 1076 1067 1012 1032 1029 983 933 986 914 966 967 919 972 915 967 962 957 949 971 913 970 935 980 946 986 957 959 1038 1040 1094 1218 1178 1190 1137 1173 1128 1119 1059 1028 1058 1021 1027 996 996 1070 1030 1070 1061 1092 1084 1080 1030 1066 1052 975 1098 1004 1012 1035 1052 1056 1056 1106 1069 1105 1134 1220 1129 1207 1266 1307 1391 1338 1461 1513 1563 1634 1668 1704 1733 1818 1776 1793 1754 1765 1695 1699 1730 1709 1876 1870 1871 1770 1845 1788 1822 1834 1876 1834 1842 1915 1778 1777 1695 1786 1698 1631 1661 1615 1543 1626 1549 1474 1423 1416 1446 1425 1339 1396 1305 1334 1287 1229 1261 1205 1201 1170 1147 1151 1082 1097 1083 1052 1054 1013 999 1044 1008 987 1008 1049 1000 1000 1001 989 1036 995 1054 1017 1029 1024 1144 1059 1126 1055 1048 1093 1034 1112 1107 1150 1119 1137 1105 1106 1118 1081 1138 1160 1089 1110 1063 1078 1035 1013 978 997 1066 1029 998 996 1027 994 925 960 972 937 931 966 963 1010 977 959 983 956 919 951 932 970 994 965 977 1019 973 1045 996 1032 1077 1072 1098 1115 1091 1162 1184 1260 1254 1296 1374 1307 1397 1420 1487 1493 1513 1507 1413 1521 1431 1464 1490 1483 1425 1311 1372 1381 1377 1255 1367 1374 1270 1287 1283 1231 1297 1253 1208 1196 1225 1223 1144 1216 1225 1263 1214 1359 1290 1363 1446 1453 1483 1468 1422 1347 1390 1361 1438 1450 1394 1456 1546 1551 1644 1602 1730 1843 1726 1701 1701 1797 1694 1714 1555 1521 1562 1527 1436 1509 1436 1413 1374 1342 1325 1440 1323 1356 1328 1231 1225 1199 1161 1198 1149 1066 1139 1044 1062 1020 1005 1003 954 1000 995 983 1040 985 973 849 977 957 895 927 959 976 947 1004 939 936 965 939 951 960 928 976 988 1001 994 991 961 1022 1043 992 1077 1055 1108 1071 1114 1172 1187 1136 1196 1181 1296 1355 1371 1473 1430 1516 1537 1489 1568 1632 1729 1696 1737 1739 1841 1733 1721 1690 1635 1646 1603 1604 1548 1543 1514 1495 1485 1516 1435 1490 1373 1410 1397 1391 1346 1367 1284 1240 1271 1243 1137 1162 1135 1162 1147 1171 1169 1095 1099 1156 1097 1061 1117 1154 1237 1109 1140 1187 1278 1216 1213 1247 1272 1283 1322 1333 1275 1431 1340 1403 1408 1390 1493 1500 1510 1578 1534 1544 1588 1609 1648 1624 1545 1604 1578 1624 1543 1523 1520 1532 1466 1515 1518 1557 1518 1445 1455 1344 1381 1351 1392 1278 1322 1205 1248 1214 1247 1221 1189 1230 1150 1177 1198 1211 1153 1199 1186 1140 1170 1151 1125 1176 1198 1168 1213 1235 1176 1168 1155 1178 1210 1152 1252 1181 1219 1254 1245 1214 1267 1312 1246 1310 1265 1300 1311 1301 1260 1312 1307 1271 1311 1239 1261 1104 1185 1177 1207 1199 1233 1240 1159 1219 1218 1132 1126 1188 1134 1098 1191 1146 1193 1210 1217 1145 1134 1214 1146 1258 1092 1151 1098 1149 1140 1185 1100 1067 1119 1112 1067 1092 1041 1126 1058 1098 1014 1106 1076 1044 1035 1018 1013 1048 1011 1017 1000 947 1019 943 956 972 1025 1026 1022 984 978 1022 1001 1023 969 960 1037 1024 996 976 930 965 977 933 1002 1105 1032 1053 1025 1008 984 1095 1040 1060 1079 1128 1124 1170 1179 1150 1218 1244 1242 1222 1259 1204 1302 1340 1150 1224 1279 1271 1309 1344 1293 1291 1340 1326 1363 1396 1362 1426 1544 1471 1598 1613 1654 1744 1626 1740 1817 1776 1779 1851 1756 1821 1735 1804 1684 1633 1644 1696 1648 1714 1633 1721 1717 1842 1857 1828 1850 1997 2002 2048 2063 2039 1909 1798 1593 1542 1458 1393 1380 1418 1243 1313 1322 1285 1330 1260 1333 1318 1255 1286 1231 1102 1102 1039 1036 960 962 952 913 962 926 900 930 879 870 868 858 876 840 853 846 846 851 822 832 855 868 868 806 843 797 808 777 822 816 787 809 806 781 843 786 738 796 811 806 766 814 797 840 817 862 872 823 933 815 830 845 837 854 862 868 811 809 787 785 806 772 824 803 775 809 821 781 805 775 831 823 808 757 787 796 783 813 771 800 791 783 863 809 860 860 860 878 827 813 813 792 790 847 793 821 777 826 813 840 858 851 807 828 826 815 867 816 869 762 829 836 811 847 799 852 742 816 812 834 806 799 852 849 880 820 854 817 864 867 796 861 848 838 802 802 811 854 854 880 839 843 842 878 892 832 850 846 863 855 839 914 824 882 896 859 947 897 905 935 988 988 1021 1075 1087 1255 1333 1414 1602 1616 1717 1804 1748 1639 1644 1533 1317 1280 1235 1210 1182 1150 1118 1106 1225 1185 1213 1279 1325 1333 1288 1243 1238 1170 1113 1066 961 953 918 911 929 923 930 885 885 912 814 895 882 853 878 840 875 852 815 859 816 794 839 944 842 897 893 918 851 977 949 972 1028 969 1051 1102 1155 1163 1262 1208 1277 1222 1162 1198 1122 1146 1103 1152 1101 1136 1129 1200 1264 1246 1327 1391 1398 1357 1365 1318 1372 1383 1371 1288 1228 1276 1326 1345 1327 1367 1335 1417 1338 1377 1416 1369 1492 1434 1433 1472 1458 1473 1408 1472 1453 1439 1411 1393 1364 1363 1354 1374 1355 1378 1272 1341 1310 1301 1325 1281 1367 1263 1241 1243 1191 1184 1232 1181 1146 1083 1217 1079 1130 1138 1067 1054 1049 1038 1089 1066 994 1029 1037 990 1036 921 1000 989 987 928 947 937 893 986 915 962 966 959 965 941 890 894 920 894 926 937 944 967 898 961 930 941 988 902 959 947 876 895 931 861 870 859 915 906 963 951 959 974 934 993 932 972 888 944 951 940 951 956 953 939 964 961 977 900 1002 1002 1019 983 1030 991 1092 1022 1020 1034 1169 1163 1180 1143 1221 1227 1229 1234 1231 1187 1120 1141 1051 1099 1032 1039 1084 1075 1021 1076 1048 1069 1046 1056 988 1098 1051 1073 1024 1029 1025 998 1045 1012 1040 968 942 1029 941 945 982 949 997 1028 1020 932 1000 951 959 1066 1065 1103 1141 1051 1103 1108 1144 1166 1124 1224 1246 1227 1206 1240 1197 1285 1290 1246 1248 1347 1342 1250 1266 1282 1319 1260 1265 1299 1272 1232 1172 1232 1226 1136 1162 1097 1142 1139 1129 1130 1098 1078 1049 1048 1009 980 1020 1061 981 996 999 934 891 901 861 889 934 911 932 880 852 836 898 842 886 848 887 862 818 812 804 874 833 873 827 845 855 876 890 931 828 897 895 876 910 939 968 977 1002 963 1019 1033 1090 988 1076 971 1059 1048 1023 1013 1016 996 1004 945 1038 1032 1098 1047 1023 1041 1040 1060 1105 1090 1053 1150 1035 1051 1033 1056 1000 1048 1076 1035 1022 1037 997 1072 1043 1018 1025 1067 978 1012 1056 1032 1048 1054 1057 1095 1104 1053 1102 1069 1046 1155 1112 1095 1091 1127 1075 1044 1117 1074 1094 1137 1132 1134 1139 1110 1098 1078 1128 1111 1075 1060 1038 1019 1011 1026 958 1078 989 1030 1034 1034 1034 1062 928 941 929 945 969 931 918 930 966 875 924 878 873 921 883 891 919 846 884 940 865 814 812 891 868 889 869 916 930 841 857 782 869 884 877 863 849 846 815 895 844 927 848 912 892 903 908 889 885 934 964 882 974 961 1020 1027 1030 1007 999 988 1006 986 971 924 1033 943 986 1039 984 953 1029 967 955 988 1038 1037 993 1010 1037 1034 1037 1063 1072 1015 1100 1034 1108 1012 1087 1192 1157 1211 1240 1315 1366 1431 1627 1774 1826 2130 2265 2622 2884 3187 3607 3733 3852 3819 3626 3138 2851 2500 2299 2016 1861 1848 1768 1690 1713 1788 1846 1884 2058 2220 2365 2486 2512 2446 2253 2101 1971 1762 1561 1465 1361 1235 1276 1215 1070 1065 1070 1063 1030 1015 1024 996 1010 1003 1013 992 1085 941 1010 1013 1026 1021 1008 1038 999 1049 1036 1044 1064 1063 1092 1027 1087 1135 1148 1125 1116 1066 1088 1083 1122 1111 1141 1160 1072 1121 1102 1146 1072 1110 1162 1184 1209 1271 1308 1352 1388 1405 1498 1559 1752 1867 2033 2171 2366 2485 2418 2405 2419 2294 2164 2005 1973 1879 1794 1831 1771 1799 1721 1809 1808 1882 1965 2001 2100 2111 2157 2175 1985 2089 2004 1924 1908 1895 1858 1910 1863 1904 1935 1973 2145 2267 2352 2446 2470 2707 2637 2539 2537 2376 2207 2022 1894 1765 1647 1651 1576 1592 1618 1542 1617 1716 1710 1794 1867 1880 1880 1869 1888 1813 1738 1549 1530 1422 1474 1354 1362 1319 1274 1318 1246 1297 1212 1195 1239 1147 1243 1247 1239 1185 1233 1218 1155 1226 1145 1111 1154 1163 1209 1235 1207 1212 1191 1181 1211 1164 1204 1263 1205 1312 1319 1396 1384 1399 1352 1389 1332 1293 1300 1139 1295 1230 1200 1269 1181 1243 1286 1288 1195 1284 1381 1404 1382 1427 1425 1410 1450 1466 1541 1386 1453 1512 1438 1490 1477 1440 1492 1463 1451 1543 1475 1429 1479 1528 1558 1454 1618 1563 1512 1577 1525 1588 1601 1577 1563 1534 1585 1658 1580 1672 1705 1704 1754 1791 1775 1758 1908 1916 2085 2121 2319 2312 2444 2610 2706 2828 2766 2638 2675 2502 2329 2260 2101 1977 1981 2027 1957 1864 1876 1863 1897 1841 1985 2046 2129 1973 2059 2004 2116 1986 1968 1868 1797 1756 1667 1667 1552 1614 1523 1708 1595 1661 1634 1664 1708 1736 1884 1834 2050 2049 2180 2244 2231 2264 1993 1979 1881 1747 1735 1562 1543 1507 1421 1372 1329 1360 1463 1389 1453 1489 1539 1567 1626 1622 1633 1511 1613 1454 1329 1377 1287 1306 1247 1164 1199 1154 1184 1173 1073 1091 1144 1134 1164 1091 1083 1079 1100 1093 1153 1081 1096 1119 1064 1122 1098 1118 1067 1142 1112 1112 1128 1021 1136 999 1031 1042 986 1042 1014 1011 1056 1023 985 997 961 1005 986 973 1027 941 997 949 953 944 896 967 941 914 906 907 846 901 901 868 899 886 942 926 899 913 883 901 903 882 930 911 911 947 925 958 903 940 929 864 901 916 880 916 836 853 891 969 915 886 929 989 905 946 1018 998 1061 1081 1059 1033 1074 1090 1090 1069 1053 1104 1054 1027 950 991 983 1023 981 970 1009 931 980 913 997 948 932 957 966 925 932 967 909 927 919 940 931 853 894 883 853 846 890 884 895 839 869 797 811 819 839 855 771 754 796 835 777 810 817 806 809 778 821 798 782 803 822 788 786 805 859 915 821 883 836 932 880 822 884 881 845 898 798 884 914 858 849 899 918 941 953 916 891 929 831 842 877 920 855 833 828 788 834 811 841 874 740 835 866 867 890 841 876 849 919 820 865 799 800 772 795 819 861 813 897 789 822 801 808 802 819 845 866 835 799 833 871 792 812 835 863 810 829 807 800 808 832 850 798 849 815 838 813 835 867 884 888 810 787 856 861 849 838 824 809 836 849 833 871 867 849 865 885 892 887 938 983 887 987 1035 1098 925 932 937 991 951 858 878 870 839 880 834 850 865 833 904 832 852 881 905 874 916 932 841 867 887 868 899 812 845 877 879 871 840 873 914 890 910 952 958 982 946 936 939 962 903 919 965 905 962 903 915 872 958 963 962 1028 943 1008 1065 950 980 1067 1097 1108 1073 1087 1065 1122 1122 1204 1095 1192 1184 1171 1172 1140 1164 1156 1169 1157 1181 1177 1138 1085 1140 1144 1103 1172 1148 1153 1148 1145 1113 1145 1073 1165 1199 1161 1149 1045 1065 1088 1049 1118 1076 1119 1040 993 1052 1034 1005 987 968 1003 967 968 1011 957 943 971 1005 991 914 950 964 971 946 925 998 914 949 896 901 896 951 943 888 965 926 918 912 904 923 892 932 864 915 912 928 902 892 899 902 949 916 971 984 974 958 1061 995 977 1049 1005 1034 1040 1121 1062 1100 1131 1156 1144 1201 1170 1246 1286 1308 1304 1214 1145 1237 1110 1127 1106 1010 1050 1021 988 1029 1018 1036 1017 1049 1009 1111 1046 1135 1063 1170 1143 1082 1093 1107 1121 1046 1117 1038 1045 1061 1091 1044 1112 1050 1142 1107 1088 1100 1092 1078 1087 1195 1049 1130 1080 1054 1087 1032 1071 1047 999 1051 1020 1065 1046 1036 1027 1027 1095 1110 1054 1084 1024 1047 1021 1033 949 1044 1010 1002 955 902 1018 993 951 917 880 852 983 920 937 908 965 898 939 920 910 926 898 873 861 953 857 885 952 913 953 892 906 933 916 926 959 984 968 933 968 1009 963 995 996 1007 1045 1044 1056 1029 1027 1045 997 1000 992 1038 1053 1033 1011 1003 1049 1055 1103 1077 1106 1086 1107 1092 1114 1126 1083 1043 1041 1163 1151 1073 1086 1120 1059 1053 1073 1086 1153 1154 1068 1174 1033 1137 1008 1119 1162 1130 1112 1105 1110 1179 1111 1160 1202 1249 1227 1223 1327 1437 1526 1726 1713 1788 1798 1746 1795 1676 1594 1454 1302 1320 1207 1236 1206 1180 1229 1096 1036 1147 1077 1115 1200 1188 1287 1272 1355 1356 1406 1411 1446 1412 1410 1330 1307 1205 1226 1141 1108 1150 1066 1041 1021 1042 987 983 958 976 950 988 951 953 1022 935 1024 965 962 969 1041 960 980 963 1001 1056 988 996 1099 1091 1085 1113 1110 1131 1106 1074 1033 1090 1026 996 911 884 958 883 886 878 869 912 941 911 887 854 912 898 922 943 996 960 1035 928 950 966 936 944 903 982 918 955 1001 987 985 1018 957 1027 1022 993 932 917 940 946 919 921 952 970 1027 962 1037 1051 1059 1090 1116 1163 1201 1292 1405 1488 1565 1648 1863 1952 2109 2221 2419 2387 2369 2189 2080 1974 1882 1706 1508 1427 1359 1351 1274 1357 1258 1229 1182 1240 1273 1308 1382 1462 1382 1490 1537 1598 1581 1602 1510 1444 1398 1289 1294 1184 1134 1124 1052 972 966 951 939 889 879 869 855 893 904 894 868 808 774 833 789 813 881 805 837 831 805 818 808 820 832 814 799 826 821 783 855 806 920 848 849 830 881 836 842 790 808 828 775 826 863 783 768 805 866 769 841 804 807 801 771 838 813 823 923 833 879 884 872 858 868 932 942 953 916 915 884 900 850 870 941 960 822 852 852 938 933 865 838 853 943 975 917 1046 1019 1006 1030 985 994 1024 1072 1006 987 1039 971 987 981 1049 972 970 1017 989 1036 1007 1024 958 1005 945 965 1015 1043 1033 992 971 1001 939 968 1002 990 996 994 993 1087 1018 1121 1031 1094 1042 1009 1058 1063 1046 1028 1057 994 1128 1110 1016 1108 1166 1170 1148 1212 1190 1238 1231 1207 1258 1261 1225 1213 1358 1264 1263 1263 1265 1214 1226 1208 1217 1225 1196 1192 1263 1157 1232 1176 1199 1200 1191 1192 1272 1195 1199 1199 1221 1187 1242 1219 1167 1235 1172 1248 1245 1208 1153 1195 1143 1142 1196 1169 1136 1185 1130 1112 1115 1101 1115 1143 1008 1105 1048 1088 1080 994 1046 1025 1038 969 1016 993 1029 1015 977 971 998 959 976 966 971 1027 916 1013 939 921 952 913 924 929 926 899 978 944 910 924 924 953 905 937 998 970 904 901 917 971 924 873 936 949 973 939 946 909 974 992 973 973 1031 954 1000 944 1032 1031 1012 997 1003 1002 1005 1030 1029 1022 1071 1061 1008 1014 1014 992 1045 1079 974 1061 1035 1095 1068 1095 1029 1029 1082 1081 1118 1093 1139 1180 1163 1178 1103 1300 1221 1224 1193 1213 1201 1201 1227 1218 1245 1182 1211 1212 1244 1195 1258 1211 1222 1181 1185 1252 1172 1196 1216 1141 1183 1159 1203 1139 1221 1177 1220 1225 1200 1153 1166 1181 1160 1185 1274 1168 1205 1239 1220 1398 1356 1429 1480 1569 1760 1666 1728 1677 1642 1599 1536 1416 1279 1208 1188 1199 1086 1141 1086 1142 1133 1057 1101 1051 1077 1062 1234 1143 1263 1158 1254 1219 1280 1279 1325 1278 1160 1192 1109 1109 1040 1021 1029 1072 1001 1044 1032 1044 953 1008 968 984 968 887 951 958 964 950 930 886 870 895 915 935 884 922 930 882 886 914 907 948 945 874 947 915 874 848 928 886 900 880 840 840 885 857 878 859 920 874 927 866 877 901 901 820 910 927 869 900 896 897 916 889 905 939 936 946 932 937 986 992 949 1008 980 992 932 911 884 960 912 923 870 928 900 904 909 935 871 884 889 952 916 909 982 966 1000 1017 985 1004 1022 1045 935 1013 966 893 968 891 921 933 842 838 896 870 847 816 878 858 919 839 832 855 847 868 878 941 847 925 939 960 921 882 897 905 828 959 922 934 968 987 1071 1081 1132 1209 1292 1327 1337 1347 1435 1389 1264 1335 1147 1091 1086 1065 1048 1019 935 975 902 881 871 896 901 876 934 1013 964 925 981 1029 1046 1122 1106 1093 1111 1074 1090 1018 1029 1031 940 879 883 901 863 813 827 853 897 794 829 787 781 765 780 786 823 800 805 809 814 801 837 794 830 845 798 868 813 877 846 835 848 856 913 854 926 876 894 879 914 932 976 947 969 1045 1052 1138 1141 1172 1283 1426 1459 1674 1696 1859 1768 1820 1792 1668 1611 1491 1364 1372 1332 1255 1289 1204 1169 1236 1246 1253 1156 1213 1178 1189 1132 1201 1158 1212 1261 1299 1307 1327 1439 1383 1363 1265 1226 1252 1178 1094 1053 1044 1072 1000 1017 1018 1035 1001 977 1035 971 914 950 996 927 915 942 932 912 956 1002 935 934 889 928 892 972 923 968 903 916 901 883 873 942 894 872 898 922 925 904 920 839 968 857 814 849 862 904 844 897 806 916 861 890 912 887 936 891 875 848 903 906 941 909 845 871 888 940 861 906 949 926 864 910 864 895 860 878 908 888 897 936 872 876 889 1034 888 900 928 937 926 925 962 990 984 1018 1047 985 1055 1070 1056 1039 1095 1185 1098 1141 1196 1202 1229 1165 1195 1176 1192 1225 1228 1232 1160 1173 1184 1227 1180 1189 1184 1194 1148 1172 1221 1238 1204 1227 1173 1254 1153 1262 1256 1255 1316 1278 1282 1228 1327 1199 1258 1253 1276 1199 1210 1211 1239 1279 1196 1171 1235 1220 1137 1110 1168 1107 1183 1207 1187 1129 1121 1096 1086 1156 1142 1043 1032 1104 962 1084 1100 1030 1028 1029 1036 980 988 938 1011 992 1026 950 999 1026 974 959 994 930 965 1001 1012 956 985 950 997 959 958 972 924 955 987 986 964 952 953 1068 1062 1027 1021 1067 998 1059 1032 1053 1105 1033 1089 1074 1064 1092 1088 1008 1083 1065 1148 1100 1104 1129 1114 1045 1158 1127 1156 1212 1163 1187 1171 1179 1137 1190 1154 1255 1158 1156 1193 1236 1138 1103 1101 1114 1110 1111 1145 1057 1134 1143 1079 1153 1116 1137 1128 1121 1095 1185 1102 1124 1182 1104 1173 1120 1124 1164 1176 1140 1238 1223 1168 1188 1163 1170 1182 1163 1211 1170 1156 1125 1174 1096 1173 1100 1155 1157 1192 1148 1045 1080 1078 1102 1028 1111 1095 1074 1095 1070 1111 1098 1110 1126 1116 1097 1036 1149 1106 1110 1167 1165 1160 1206 1138 1131 1062 1087 1045 1080 999 1034 1022 1046 1011 994 1056 1015 939 957 960 951 942 972 895 971 999 955 931 950 1030 930 985 951 972 967 928 845 955 923 874 879 885 909 829 912 897 851 883 846 883 874 807 861 838 854 810 884 857 852 863 809 907 830 887 831 867 875 838 875 871 882 852 897 908 900 906 950 990 949 979 956 981 956 960 924 889 946 935 910 881 917 888 938 929 960 992 984 1018 957 988 949 956 965 1036 985 926 990 983 957 1009 993 968 955 970 884 983 909 968 927 881 864 964 856 895 903 898 913 902 926 885 857 890 853 892 916 933 910 884 930 950 916 879 964 936 852 858 897 848 954 918 917 905 851 945 912 930 860 947 975 914 995 918 961 925 893 936 958 952 951 927 942 956 867 967 980 961 934 922 909 904 870 907 924 865 897 876 926 964 950 894 916 864 968 908 921 928 899 924 960 978 970 961 930 989 964 999 959 1038 1034 979 1000 1108 992 1070 993 1015 1044 1112 1031</counts>
			</dataPoints>
		</scan>
	</xrdMeasurement>
</xrdMeasurements>