File: dataset/precursor_mixture/HfO2_Li3PO4_Bi2O3-beta.2-min.xrdml
<?xml version="1.0"?>
<xrdMeasurements xmlns="http://www.xrdml.com/XRDMeasurement/2.2" xmlns:xsi="http://www.w3.org/2001/XMLSchema-instance" xsi:schemaLocation="http://www.xrdml.com/XRDMeasurement/2.2 http://www.xrdml.com/XRDMeasurement/2.2/XRDMeasurement.xsd" status="Completed" recordIdentifier="{017ABA38-6D64-40B5-97FA-412802453878}">
	<comment>
		<entry/>
	</comment>
	<sample type="To be analyzed">
		<id>dara-42-1</id>
		<name></name>
		<preparedBy></preparedBy>
	</sample>
	<xrdMeasurement measurementType="Scan" status="Completed" sampleMode="Reflection">
		<usedWavelength intended="K-Alpha 1">
			<kAlpha1 unit="Angstrom">1.5405980</kAlpha1>
			<kAlpha2 unit="Angstrom">1.5444260</kAlpha2>
			<kBeta unit="Angstrom">1.3922500</kBeta>
			<ratioKAlpha2KAlpha1>0.5000</ratioKAlpha2KAlpha1>
		</usedWavelength>
		<incidentBeamPath>
			<radius unit="mm">145.00</radius>
			<xRayTube id="1010048" name="Empyrean Cu LFF HR (9430 033 7310x) DK437873">
				<tension unit="kV">40.0</tension>
				<current unit="mA">15.0</current>
				<anodeMaterial>Cu</anodeMaterial>
				<focus type="Line">
					<length unit="mm">12.0</length>
					<width unit="mm">0.4</width>
					<takeOffAngle unit="deg">6.0</takeOffAngle>
				</focus>
			</xRayTube>
			<filter id="20010004" name="Beta-filter Nickel">
				<material>Ni</material>
				<thickness unit="mm">0.020</thickness>
			</filter>
			<sollerSlit id="21010002" name="Soller slits 0.04 rad.">
				<opening unit="rad">0.0400</opening>
			</sollerSlit>
			<mask id="22031000" name="Fixed mask 13 mm">
				<width unit="mm">9.00</width>
			</mask>
			<divergenceSlit id="22120001" name="Divergence slit 1°" xsi:type="fixedDivergenceSlitType">
				<distanceToSample unit="mm">50.00</distanceToSample>
				<height unit="mm">1.52</height>
			</divergenceSlit>
		</incidentBeamPath>
		<beamKnife id="29030100" name="Beam knife low"/>
		<sampleMovement xsi:type="spinningSampleMovementType">
			<spinnerRevolutionTime unit="seconds">1.0</spinnerRevolutionTime>
		</sampleMovement>
		<diffractedBeamPath>
			<radius unit="mm">145.00</radius>
			<antiScatterSlit id="22090040" name="AS slit 9 mm" xsi:type="fixedAntiScatterSlitType">
				<height unit="mm">9.00</height>
			</antiScatterSlit>
			<sollerSlit id="21020003" name="Large Soller slits 0.04 rad.">
				<opening unit="rad">0.0400</opening>
			</sollerSlit>
			<filter id="20030001" name="Large beta-filter Nickel">
				<material>Ni</material>
				<thickness unit="mm">0.020</thickness>
			</filter>
			<detector id="7010019" name="PIXcel1D-Medipix3 detector" xsi:type="rtmsDetectorType">
				<phd unit="keV">
					<lowerLevel>4.0</lowerLevel>
					<upperLevel>11.3</upperLevel>
				</phd>
				<mode>Scanning</mode>
				<activeLength unit="deg">1.021</activeLength>
			</detector>
		</diffractedBeamPath>
		<scan appendNumber="0" mode="Continuous" scanAxis="Gonio" status="Completed">
			<header>
				<startTimeStamp>2024-03-25T11:46:27-07:00</startTimeStamp>
				<endTimeStamp>2024-03-25T11:48:49-07:00</endTimeStamp>
				<author>
					<name>AutomatedUser</name>
				</author>
				<source>
					<applicationSoftware version="1.6 (94)">PANalytical Aeris Instrument Suite</applicationSoftware>
					<instrumentControlSoftware version="3.0.0 20211014">AERIS</instrumentControlSoftware>
					<instrumentID>2879380</instrumentID>
				</source>
			</header>
			<dataPoints>
				<positions axis="2Theta" unit="deg">
					<startPosition>10.02173288</startPosition>
					<endPosition>139.98435528</endPosition>
				</positions>
				<positions axis="Omega" unit="deg">
					<startPosition>5.01086644</startPosition>
					<endPosition>69.99217764</endPosition>
				</positions>
				<commonCountingTime unit="seconds">1.551</commonCountingTime>
				<counts unit="counts">401 399 395 354 375 400 360 365 385 408 360 370 353 383 374 363 370 335 362 387 346 387 364 347 400 324 363 365 350 356 352 352 351 329 330 342 304 313 336 333 301 334 329 283 271 320 328 319 300 313 352 289 311 289 313 267 308 320 350 288 321 271 314 274 298 301 284 287 279 291 242 274 280 287 290 282 251 235 252 290 263 257 246 283 250 264 264 275 251 262 241 225 250 288 232 250 263 266 251 245 229 209 248 252 248 248 217 251 235 195 237 242 243 212 239 237 221 248 216 189 240 210 227 228 222 239 228 219 223 233 238 205 172 235 225 225 225 255 226 254 265 233 236 199 211 228 199 198 227 204 218 225 194 211 234 216 280 226 249 232 213 217 210 227 213 227 204 210 247 292 315 302 247 207 194 202 210 194 162 184 207 190 170 196 213 167 201 207 170 203 192 181 173 186 184 196 183 174 199 158 165 190 166 187 196 171 175 179 176 173 163 187 176 160 150 179 173 164 171 204 181 174 154 168 185 191 173 167 157 162 188 168 170 157 158 181 136 138 165 205 185 190 154 157 183 171 192 175 167 183 133 136 162 156 147 157 186 172 167 149 162 151 146 169 177 151 172 155 160 168 189 163 212 195 212 251 282 328 344 296 256 191 189 193 184 170 178 147 184 183 194 196 183 171 218 217 220 256 281 271 248 227 237 218 202 184 179 174 155 185 160 168 208 203 189 189 215 221 311 415 445 409 310 258 220 227 250 289 372 402 390 315 254 235 246 232 232 232 211 216 218 171 177 202 188 183 169 150 175 179 166 183 244 268 340 264 218 183 166 151 161 121 159 134 169 138 172 146 159 152 158 142 149 125 145 160 160 158 149 175 178 166 156 173 159 175 168 209 183 181 197 209 227 238 259 262 270 356 362 494 693 1101 1969 3625 6327 6595 4398 2175 1031 845 879 1106 1485 1868 1754 1422 967 686 451 410 343 288 272 268 242 220 202 235 227 201 212 213 220 194 212 194 167 166 173 179 164 177 168 174 154 178 184 175 152 143 138 158 178 186 197 237 275 319 278 239 206 199 168 161 166 161 174 161 163 172 169 180 165 188 185 179 183 202 231 233 241 256 304 397 503 654 944 1309 1658 1725 1859 1561 1032 625 363 326 226 235 192 187 176 189 172 187 190 213 234 330 434 663 1217 1838 1617 1206 631 341 229 166 181 162 159 159 152 145 132 169 136 136 159 134 127 149 149 162 148 175 195 260 223 252 284 241 247 266 291 340 428 532 628 586 491 398 361 430 487 539 381 325 257 205 160 165 177 180 164 165 142 159 147 172 176 225 246 353 428 538 453 391 313 214 179 149 141 152 172 197 209 230 266 203 196 148 128 143 140 150 171 188 158 175 197 151 131 131 145 148 149 168 151 170 136 134 120 134 96 114 116 100 109 115 96 115 111 97 114 115 101 99 110 130 124 119 118 99 78 96 115 116 151 109 132 122 118 107 98 114 182 197 270 244 234 217 199 165 125 150 139 101 131 101 115 103 102 119 122 120 77 110 109 101 136 93 90 98 83 112 116 110 131 125 141 133 119 111 108 101 116 99 108 100 128 143 127 173 148 226 190 251 303 260 263 208 200 187 266 276 273 221 190 186 166 149 170 172 162 162 130 130 115 118 113 120 138 104 120 101 117 104 110 91 98 125 87 110 114 98 84 101 108 90 97 103 99 81 88 80 92 118 97 102 119 105 110 92 113 106 86 82 91 99 91 90 111 96 84 85 95 81 86 112 94 67 87 109 85 98 83 80 99 101 93 118 91 111 94 93 118 139 160 159 174 216 212 190 194 148 125 116 107 100 95 122 149 151 174 193 205 233 179 178 188 213 216 346 689 1337 1645 1023 954 773 366 212 187 151 155 138 137 151 197 331 588 874 601 451 515 294 185 166 124 127 113 105 94 93 99 118 99 92 79 89 79 82 96 95 114 90 95 77 117 84 96 103 119 116 126 140 133 117 144 123 125 91 127 115 117 117 104 109 108 93 124 126 152 128 155 168 135 143 204 271 380 403 347 313 267 215 169 160 145 147 145 150 120 124 144 115 142 151 231 326 434 457 389 342 318 243 210 218 197 250 297 266 282 259 196 163 181 166 232 259 194 183 189 195 161 188 173 177 166 156 166 112 115 89 93 92 90 111 109 104 107 91 110 113 94 94 95 94 120 96 107 111 84 99 103 98 97 105 89 87 115 90 76 96 97 90 108 90 126 113 108 126 129 129 131 114 137 130 133 140 139 133 146 195 263 328 656 951 703 575 707 576 427 287 227 207 161 167 143 138 129 135 143 135 138 134 168 150 182 189 232 305 486 958 1543 1131 816 964 971 672 481 410 344 329 286 233 208 218 158 181 224 234 208 199 177 195 176 144 133 121 107 120 114 109 100 131 107 108 122 112 104 110 155 113 97 162 160 171 176 232 237 254 234 331 501 717 615 420 412 414 253 173 160 162 142 174 205 198 206 165 162 148 144 146 144 177 146 110 126 117 137 136 115 131 140 167 164 130 118 142 99 109 97 95 95 106 110 123 140 127 95 127 134 121 116 98 128 138 157 226 240 237 249 251 241 229 201 213 203 170 157 147 129 115 101 112 116 104 129 142 119 125 130 129 116 123 112 78 115 111 121 117 141 149 150 193 166 183 183 166 166 158 170 166 167 182 178 219 212 181 189 182 156 158 140 120 112 102 118 112 89 98 96 122 121 114 125 170 194 223 185 177 191 162 125 134 109 117 104 86 90 117 78 73 79 84 86 75 83 96 96 96 77 101 93 86 106 122 101 111 129 158 137 154 134 114 101 118 131 88 81 114 93 89 89 73 99 129 110 98 98 86 110 114 116 143 134 109 149 106 149 164 187 237 212 233 208 195 262 264 175 153 156 136 109 131 99 100 86 93 78 80 101 84 86 74 91 94 88 80 108 93 87 82 73 84 94 94 117 96 76 85 69 88 85 85 83 88 97 116 83 99 91 99 109 128 204 222 185 134 144 168 161 103 104 86 97 87 89 86 93 119 105 128 111 124 135 130 135 90 103 95 129 85 89 100 75 78 70 62 87 98 73 95 92 78 93 87 108 113 92 87 79 112 80 69 88 74 118 83 90 95 117 102 92 88 98 106 110 110 96 96 114 114 95 108 167 169 139 120 163 157 109 106 107 104 103 88 97 88 75 95 97 124 116 102 101 87 111 115 145 122 128 96 109 115 62 110 103 135 119 121 126 110 117 102 119 108 83 107 96 83 81 104 96 114 87 108 112 111 122 103 102 108 115 124 119 123 147 173 252 388 543 438 220 244 290 333 288 166 139 114 130 109 106 121 123 139 126 102 123 124 142 166 267 310 311 231 208 213 242 189 187 209 283 341 211 181 152 190 196 137 115 108 101 78 101 105 93 95 130 134 116 123 119 136 137 133 101 128 106 122 101 114 87 127 136 168 233 273 223 158 172 152 190 173 127 144 154 207 265 236 211 181 155 178 182 117 109 97 108 116 102 90 93 93 104 72 112 102 93 71 74 92 80 85 106 84 89 95 111 97 100 123 128 104 121 115 99 121 82 91 87 122 79 93 86 65 79 91 110 71 87 109 91 72 76 89 88 78 104 98 98 100 89 82 95 79 80 99 87 77 93 89 101 116 100 103 95 88 95 86 90 84 112 106 110 109 91 111 110 100 97 140 99 111 107 115 88 121 126 101 103 95 85 90 106 101 119 76 105 102 84 106 81 112 123 117 139 148 135 133 119 128 143 127 134 120 133 136 127 112 121 116 128 121 121 107 99 83 105 92 107 121 105 87 118 110 124 126 102 148 144 117 106 98 117 126 117 116 118 222 243 158 145 122 128 132 140 158 131 102 104 106 114 136 98 122 115 119 105 95 103 86 120 122 92 123 95 105 93 116 147 143 229 330 302 211 161 152 157 228 192 153 131 111 111 77 77 86 84 87 81 96 83 63 67 74 77 111 108 112 108 69 82 70 122 104 119 108 97 100 74 102 110 77 112 98 101 107 85 105 110 121 108 128 133 96 109 106 118 105 106 94 125 111 103 93 98 84 98 100 106 96 105 110 93 91 110 70 87 120 106 100 98 86 90 110 123 125 97 137 115 120 119 129 138 115 127 167 201 171 166 119 113 129 128 128 134 124 109 98 95 87 98 104 100 102 67 94 76 95 88 93 73 117 114 94 97 107 107 104 115 106 116 106 94 97 102 96 104 101 118 127 174 178 155 104 97 93 124 140 115 103 89 106 91 78 107 93 101 92 118 94 107 161 241 237 228 170 154 110 139 185 141 135 133 127 110 117 107 97 83 76 92 103 98 96 100 101 105 97 92 107 98 52 84 71 85 116 111 104 128 98 106 104 111 112 90 110 115 111 110 108 109 103 90 83 95 90 99 78 86 87 77 81 73 83 82 101 96 98 121 112 116 107 129 115 121 100 122 125 133 115 135 105 109 119 125 131 133 109 113 130 122 129 110 111 100 85 97 104 101 104 108 111 108 61 81 112 103 83 124 125 102 99 92 101 86 108 112 95 126 93 87 84 113 95 83 95 96 84 106 97 89 109 121 106 91 111 100 116 105 102 100 104 105 120 119 114 130 123 122 114 112 100 113 127 119 115 90 80 75 89 85 87 87 80 94 106 92 107 127 114 84 93 100 104 113 133 125 116 121 115 118 111 94 111 110 107 120 122 105 102 124 120 113 119 96 118 109 90 105 106 82 99 98 101 96 77 98 88 80 95 88 91 119 114 75 104 118 127 122 159 146 114 90 95 95 113 93 123 125 113 120 73 61 95 97 86 92 115 68 78 78 72 83 107 78 92 86 90 89 82 86 72 89 83 73 95 75 87 86 96 95 94 77 94 108 121 96 90 81 94 86 88 114 106 104 82 90 78 87 93 80 96 106 89 95 84 94 92 99 91 113 98 99 101 91 116 61 105 82 85 92 91 78 84 82 93 101 93 103 93 88 120 105 99 91 90 94 79 88 97 112 89 95 96 78 97 102 97 86 100 86 77 85 109 92 79 75 100 113 102 90 142 144 135 124 110 105 112 122 159 129 218 231 217 212 143 142 106 147 157 145 176 158 156 148 129 123 121 105 117 118 110 134 109 115 128 120 140 112 104 95 123 116 122 143 129 143 143 120 148 108 137 108 126 141 111 135 147 157 178 236 194 204 139 148 147 129 153 149 165 168 139 122 132 141 110 142 112 114 97 115 146 148 161 200 188 158 150 155 142 116 160 180 274 266 238 186 175 150 137 143 150 136 147 153 137 119 115 107 120 111 121 112 93 77 100 109 95 95 102 102 110 118 102 101 109 83 128 124 105 132 147 122 114 116 101 100 109 95 103 118 104 123 123 137 103 77 91 99 89 93 93 109 109 105 107 94 113 121 134 112 115 101 100 103 103 106 114 89 113 117 142 118 97 103 129 87 97 112 90 97 92 95 89 100 93 100 82 85 88 87 73 90 96 96 110 105 104 81 97 100 114 105 107 110 102 108 86 87 87 86 92 85 92 102 75 73 78 87 87 83 89 96 104 109 84 116 124 106 113 114 98 97 112 111 106 131 121 122 101 89 111 98 119 87 106 106 92 106 79 120 91 72 103 126 108 110 100 107 139 127 135 141 114 119 123 107 112 95 88 108 102 117 141 119 112 111 100 93 109 87 98 92 79 107 103 108 121 119 112 130 121 94 135 114 120 119 131 114 116 106 118 116 113 110 117 108 131 109 87 92 89 96 109 93 91 115 91 91 109 106 117 101 75 87 92 93 94 109 106 85 114 103 100 88 92 93 120 103 110 124 89 110 84 102 83 98 82 98 100 114 96 105 90 81 92 104 100 115 101 89 104 99 86 105 128 154 125 121 96 118 106 105 109 112 109 117 131 143 133 161 146 123 115 116 113 92 123 107 118 108 158 137 124 116 97 154 153 135 136 106 154 114 113 108 116 122 111 87 119 115 96 108 116 106 118 130 107 103 126 103 99 118 116 105 84 109 87 94 121 108 102 95 113 93 88 96 98 94 109 111 98 118 111 128 133 109 101 102 116 97 89 108 114 110 97 106 101 98 109 116 113 81 86 107 120 119 106 111 99 113 114 102 102 108 77 93 79 112 121 107 118 126 111 130 142 148 145 137 104 103 109 113 116 104 106 107 85 111 99 142 106 95 117 114 112 94 108 118 123 119 127 134 161 187 137 107 133 133 116 112 133 125 142 109 140 125 147 155 120 157 124 151 119 129 143 143 144 124 116 136 137 118 154 165 168 185 183 203 157 160 137 134 127 119 115 105 113 114 136 125 138 146 154 128 95 127 98 115 94 102 114 100 117 111 123 99 93 108 113 103 91 100 110 127 129 113 115 113 132 126 99 131 95 102 107 112 96 103 118 104 111 111 109 101 119 103 87 110 96 118 132 128 112 121 111 101 113 100 119 105 121 109 116 105 103 116 91 112 114 125 113 113 133 141 142 158 165 166 142 160 134 133 124 130 107 109 124 113 78 93 101 121 133 135 122 131 125 118 112 116 130 124 131 135 121 123 127 120 111 114 137 113 100 115 95 102 101 130 124 94 100 134 127 102 104 103 110 109 111 88 100 103 117 107 101 117 109 99 94 108 99 94 114 105 102 113 90 106 108 110 118 128 120 122 111 122 113 113 121 101 115 114 111 126 111 99 131 112 105 108 99 115 105 108 109 110 86 96 92 110 122 136 102 115 118 97 123 122 116 106 120 115 116 124 98 109 95 89 121 129 99 103 122 121 115 117</counts>
			</dataPoints>
		</scan>
	</xrdMeasurement>
</xrdMeasurements>