File: dataset/precursor_mixture/HfO2_La(OH)3_Nb2O5_CaCO3.12-min.xrdml
<?xml version="1.0"?>
<xrdMeasurements xmlns="http://www.xrdml.com/XRDMeasurement/2.2" xmlns:xsi="http://www.w3.org/2001/XMLSchema-instance" xsi:schemaLocation="http://www.xrdml.com/XRDMeasurement/2.2 http://www.xrdml.com/XRDMeasurement/2.2/XRDMeasurement.xsd" status="Completed" recordIdentifier="{61EA45A1-376E-4EE3-BCE6-549EA1904689}">
	<comment>
		<entry/>
	</comment>
	<sample type="To be analyzed">
		<id>dara-39-2</id>
		<name></name>
		<preparedBy></preparedBy>
	</sample>
	<xrdMeasurement measurementType="Scan" status="Completed" sampleMode="Reflection">
		<usedWavelength intended="K-Alpha 1">
			<kAlpha1 unit="Angstrom">1.5405980</kAlpha1>
			<kAlpha2 unit="Angstrom">1.5444260</kAlpha2>
			<kBeta unit="Angstrom">1.3922500</kBeta>
			<ratioKAlpha2KAlpha1>0.5000</ratioKAlpha2KAlpha1>
		</usedWavelength>
		<incidentBeamPath>
			<radius unit="mm">145.00</radius>
			<xRayTube id="1010048" name="Empyrean Cu LFF HR (9430 033 7310x) DK430614">
				<tension unit="kV">40.0</tension>
				<current unit="mA">15.0</current>
				<anodeMaterial>Cu</anodeMaterial>
				<focus type="Line">
					<length unit="mm">12.0</length>
					<width unit="mm">0.4</width>
					<takeOffAngle unit="deg">6.0</takeOffAngle>
				</focus>
			</xRayTube>
			<filter id="20010004" name="Beta-filter Nickel">
				<material>Ni</material>
				<thickness unit="mm">0.020</thickness>
			</filter>
			<sollerSlit id="21010002" name="Soller slits 0.04 rad.">
				<opening unit="rad">0.0400</opening>
			</sollerSlit>
			<mask id="22031000" name="Fixed mask 13 mm">
				<width unit="mm">9.00</width>
			</mask>
			<divergenceSlit id="22120001" name="Divergence slit 1°" xsi:type="fixedDivergenceSlitType">
				<distanceToSample unit="mm">50.00</distanceToSample>
				<height unit="mm">1.52</height>
			</divergenceSlit>
		</incidentBeamPath>
		<beamKnife id="29030100" name="Beam knife low"/>
		<sampleMovement xsi:type="spinningSampleMovementType">
			<spinnerRevolutionTime unit="seconds">1.0</spinnerRevolutionTime>
		</sampleMovement>
		<diffractedBeamPath>
			<radius unit="mm">145.00</radius>
			<antiScatterSlit id="22090040" name="AS slit 9 mm" xsi:type="fixedAntiScatterSlitType">
				<height unit="mm">9.00</height>
			</antiScatterSlit>
			<sollerSlit id="21020003" name="Large Soller slits 0.04 rad.">
				<opening unit="rad">0.0400</opening>
			</sollerSlit>
			<filter id="20030001" name="Large beta-filter Nickel">
				<material>Ni</material>
				<thickness unit="mm">0.020</thickness>
			</filter>
			<detector id="7010019" name="PIXcel1D-Medipix3 detector" xsi:type="rtmsDetectorType">
				<phd unit="keV">
					<lowerLevel>4.0</lowerLevel>
					<upperLevel>11.3</upperLevel>
				</phd>
				<mode>Scanning</mode>
				<activeLength unit="deg">5.020</activeLength>
			</detector>
		</diffractedBeamPath>
		<scan appendNumber="0" mode="Continuous" scanAxis="Gonio" status="Completed">
			<header>
				<startTimeStamp>2024-02-18T09:51:19-08:00</startTimeStamp>
				<endTimeStamp>2024-02-18T10:03:47-08:00</endTimeStamp>
				<author>
					<name>AutomatedUser</name>
				</author>
				<source>
					<applicationSoftware version="1.4b (28)">PANalytical Aeris Instrument Suite</applicationSoftware>
					<instrumentControlSoftware version="2.0.0 20210224">AERIS</instrumentControlSoftware>
					<instrumentID>950485</instrumentID>
				</source>
			</header>
			<dataPoints>
				<positions axis="2Theta" unit="deg">
					<startPosition>9.99043322</startPosition>
					<endPosition>100.09495370</endPosition>
				</positions>
				<positions axis="Omega" unit="deg">
					<startPosition>4.99521661</startPosition>
					<endPosition>50.04747685</endPosition>
				</positions>
				<commonCountingTime unit="seconds">18.249</commonCountingTime>
				<counts unit="counts">3790 4039 3882 3902 3892 3925 3913 3919 4020 3833 3874 3920 3840 3850 3913 3742 3818 3857 3891 3873 3744 3806 3811 3872 3917 3764 3837 3658 3855 3711 3767 3792 3737 3781 3674 3852 3703 3846 3755 3698 3769 3732 3710 3746 3564 3640 3766 3737 3781 3756 3688 3819 3669 3673 3621 3697 3586 3528 3683 3659 3663 3777 3642 3609 3711 3617 3611 3527 3519 3628 3657 3516 3607 3649 3590 3646 3637 3623 3486 3561 3523 3517 3620 3580 3662 3605 3504 3548 3552 3497 3597 3449 3576 3527 3455 3487 3395 3557 3491 3569 3424 3433 3581 3463 3615 3384 3542 3427 3379 3420 3423 3462 3467 3530 3446 3420 3483 3264 3323 3384 3496 3458 3410 3353 3392 3356 3482 3234 3339 3504 3389 3277 3404 3385 3390 3366 3435 3292 3306 3308 3408 3285 3339 3262 3267 3246 3444 3403 3360 3221 3354 3459 3258 3362 3298 3410 3285 3232 3377 3274 3387 3392 3241 3295 3272 3409 3412 3328 3185 3300 3138 3317 3311 3328 3282 3207 3238 3249 3259 3162 3165 3266 3267 3250 3214 3106 3197 3205 3271 3289 3311 3257 3191 3179 3185 3106 3242 3286 3262 3166 3113 3269 3180 3231 3131 3113 3253 3140 3180 3124 3137 3119 3221 3238 3150 3086 3213 3101 3161 3154 3140 3112 3163 3081 3155 3087 3259 3177 3280 3200 3058 3099 3095 3135 3132 3069 3157 3079 3184 3166 3028 3089 3087 3142 3003 3160 3077 3078 3030 3111 3006 3074 3040 3080 3040 3053 3088 3111 3064 3053 3107 3067 3114 3106 3064 2989 2978 2978 3118 3007 3017 2987 3112 3062 3157 3051 3028 2956 3002 2953 3080 2963 2924 2951 3078 3043 3098 2996 2960 2977 2902 2979 2897 2881 3036 3007 2919 2910 2937 2991 2997 2897 2872 3006 2935 2999 2895 2842 2837 2900 2917 2921 2925 2980 2916 2935 2920 2865 2963 2915 2995 2789 3011 2892 2928 2862 2867 2855 2912 2955 2889 2899 2810 2825 2880 2795 2838 2905 2849 2906 2902 2907 2942 2859 2934 2948 2844 2844 2884 2938 2780 2906 2875 2829 2866 2826 2873 2938 2746 2848 2949 2776 2893 2870 2889 2757 2831 2872 2912 2818 2854 2915 2926 2798 2806 2773 2871 2767 2906 2808 2827 2783 2834 2849 2859 2734 2795 2814 2745 2772 2782 2932 2837 2897 2781 2873 2847 2763 2791 2765 2707 2909 2717 2824 2788 2815 2804 2806 2821 2851 2718 2805 2757 2693 2771 2611 2704 2730 2807 2765 2842 2855 2809 2817 2754 2869 2718 2809 2778 2794 2731 2738 2783 2838 2816 2776 2800 2842 2683 2744 2756 2836 2710 2719 2780 2768 2733 2693 2855 2754 2733 2800 2872 2875 2842 2809 2800 2794 2779 2734 2826 2851 2911 2809 2922 2756 2792 2846 2901 2979 2915 2976 2863 2959 3025 2953 3052 3065 3144 3030 3042 3163 3163 3147 3188 3177 3202 3171 3297 3373 3358 3442 3485 3583 3527 3772 3683 3813 4083 4001 4168 4123 4221 4465 4644 4755 4770 4947 5158 5476 5517 5872 6086 6346 6573 6933 7323 7436 7806 8154 8389 8745 8973 9387 9521 9683 9880 9920 9977 9969 9824 9702 9421 9145 8548 7916 7686 7179 6700 6457 5934 5536 5181 4863 4655 4380 4254 4118 3970 3847 3695 3590 3488 3369 3405 3295 3330 3250 3227 3200 3130 2991 3044 3035 2937 2972 2986 2924 2930 2852 2870 2716 2887 2891 2780 2831 2862 2708 2842 2731 2730 2819 2757 2788 2792 2695 2725 2687 2666 2668 2730 2703 2692 2782 2683 2692 2663 2711 2589 2713 2700 2675 2570 2668 2608 2562 2616 2558 2657 2607 2598 2683 2654 2556 2451 2608 2619 2661 2587 2633 2549 2633 2706 2573 2537 2742 2612 2584 2528 2512 2608 2586 2545 2531 2535 2613 2566 2585 2594 2627 2692 2547 2554 2638 2630 2736 2575 2713 2677 2661 2651 2666 2749 2761 2744 2741 2821 2744 2760 2774 2785 2749 2749 2751 2693 2694 2640 2610 2601 2497 2568 2488 2563 2537 2587 2489 2599 2588 2613 2631 2510 2530 2564 2542 2584 2634 2602 2713 2636 2687 2718 2708 2824 2925 2949 2844 2889 2909 2850 2996 2981 2997 3026 3016 2984 3080 3113 3032 2928 2880 2780 2826 2738 2675 2600 2579 2577 2516 2601 2426 2460 2457 2471 2394 2489 2396 2494 2398 2406 2412 2398 2361 2341 2354 2375 2439 2339 2397 2450 2349 2305 2407 2403 2257 2379 2391 2352 2326 2338 2327 2322 2314 2192 2372 2377 2383 2407 2314 2332 2326 2304 2318 2223 2364 2271 2353 2378 2309 2272 2415 2290 2341 2361 2273 2353 2270 2305 2305 2356 2293 2436 2259 2380 2231 2351 2245 2323 2298 2245 2393 2284 2281 2384 2301 2207 2249 2276 2181 2297 2277 2223 2292 2282 2247 2178 2244 2098 2315 2286 2280 2323 2290 2173 2170 2261 2201 2210 2272 2225 2123 2169 2249 2179 2244 2165 2280 2168 2244 2236 2158 2144 2225 2236 2288 2216 2245 2227 2256 2222 2118 2328 2230 2122 2250 2119 2101 2137 2242 2145 2231 2144 2207 2240 2186 2194 2193 2204 2203 2158 2139 2158 2226 2175 2110 2085 2123 2147 2102 2124 2104 2127 2136 2227 2206 2190 2193 2260 2138 2133 2125 2182 2181 2142 2176 2105 2220 2130 2099 2147 2102 2135 2098 2067 2122 2102 2099 2099 2157 2106 2136 2198 2133 2097 2133 2220 2091 2079 2061 2079 2149 2110 2131 2041 2208 2109 2133 2115 2171 2149 2019 1999 2098 2163 2053 2056 2030 2074 2145 2031 2136 2095 2109 2061 2135 2091 2112 2134 2115 2088 2112 2105 2043 2085 2076 2056 2008 2070 2165 1984 2036 2049 1939 2202 2036 2156 2063 2059 2032 2083 2066 2132 2046 2082 2017 2115 1996 2076 2103 2084 2040 2067 2003 1929 2079 2046 2054 1986 2021 2041 1958 1899 1980 1983 2024 2029 2066 2041 2047 2055 2093 2014 2010 2111 1982 2062 2014 1958 2044 1992 1979 2086 2017 2034 2065 2057 2034 1959 2126 1973 2045 2031 2018 2006 1995 2053 2080 2012 1974 1964 2005 2052 2065 1923 2051 2008 2079 2085 1942 2032 1957 2008 1950 1982 2003 2025 2043 2020 1990 1983 1986 1950 2039 1966 1966 1973 2057 2063 1985 1981 2036 2014 1964 1967 1925 2030 2004 1908 1994 1872 2076 2003 2050 1958 1999 1951 1971 1998 1974 1964 1977 2025 2041 1913 1956 1974 1967 1989 2024 1944 1979 1979 1980 1980 1928 1950 1982 2039 1965 1945 1978 1941 2006 2081 1939 1946 1926 2034 2050 1984 2004 2099 2066 2085 1997 2026 2066 1973 2037 2049 2063 2076 1988 1978 1960 2031 2002 1969 2073 2018 2030 1958 2051 2017 2017 2085 2096 1989 2009 2045 2105 2104 2088 2064 2114 2115 2183 2106 2194 2190 2069 2281 2262 2267 2410 2361 2367 2385 2513 2573 2728 2793 2875 3118 3292 3450 3837 3869 4230 4586 5152 5493 5988 6437 6968 7569 8232 8823 9232 9724 9903 9661 9510 8967 8427 7685 7051 6420 5606 4892 4412 3811 3385 3021 2823 2752 2426 2364 2231 2357 2300 2169 2194 2154 2208 2187 2166 2146 2120 2115 2206 2104 2105 2177 2159 2121 2100 2023 2117 2147 2238 2194 2155 2139 2067 2084 2065 2129 2108 2031 1972 2000 1990 1987 2014 1927 1982 1907 1976 1887 1994 1842 1877 1966 1902 1945 1894 1929 1945 1880 1958 1873 1945 1928 1905 1916 1947 1914 1954 1996 2024 1868 2016 1840 1914 1974 1946 1866 1907 1973 1891 1920 1889 1912 1961 1928 2005 1957 1998 1861 1901 1937 1847 1981 1997 1925 1949 1906 1955 1887 1987 1878 1972 1849 1963 1970 1975 1944 2001 2021 1961 2017 2121 2097 2171 2201 2120 2231 2267 2282 2325 2333 2424 2566 2531 2714 2774 2878 2899 3117 3252 3393 3573 3639 3895 3886 3851 3893 3836 3886 3724 3533 3536 3248 3139 3052 2792 2658 2689 2514 2428 2474 2353 2426 2398 2332 2343 2232 2370 2509 2482 2443 2668 2619 2646 2698 2921 3022 3010 3190 3255 3369 3440 3494 3355 3483 3540 3279 3314 3206 3009 2894 2871 2703 2462 2402 2276 2341 2160 2163 2017 2046 2111 1973 1940 1918 1880 1933 2044 1890 1892 1980 1875 1924 1880 1933 1891 1863 1892 1854 1847 1887 1986 1904 1786 1910 1831 1744 1788 1824 1834 1811 1908 1827 1818 1795 1858 1843 1825 1750 1768 1821 1785 1890 1874 1768 1910 1852 1797 1831 1819 1842 1866 1783 1786 1875 1782 1922 1800 1896 1798 1839 1912 1852 1848 1911 1854 1878 1829 1942 1964 1882 1981 1934 2025 1993 1984 1944 1940 1994 1977 1948 1876 1822 1807 1898 1808 1828 1828 1786 1817 1773 1811 1772 1878 1835 1794 1780 1721 1836 1735 1669 1776 1771 1780 1805 1690 1706 1710 1770 1812 1759 1807 1744 1847 1728 1806 1756 1840 1859 1718 1800 1781 1787 1757 1723 1768 1762 1781 1837 1778 1797 1834 1752 1810 1784 1863 1838 1806 1824 1829 1749 1851 1828 1855 1775 1840 1898 1808 1843 1739 1866 1922 1929 1903 1909 1980 1935 2051 1966 2032 2018 1951 1981 1967 1950 1943 1918 1949 1932 1801 1928 1928 1925 1957 1987 2043 1961 1997 1956 1945 2054 1952 1943 1916 2022 2084 2066 2085 2172 2169 2174 2203 2172 2274 2296 2359 2333 2416 2458 2501 2503 2619 2591 2790 2734 2807 2909 3058 3324 3362 3457 3680 3918 3922 4121 4460 4522 4956 5153 5402 5768 6033 6406 6490 6823 6899 7244 7218 7256 7252 7151 7240 6912 6969 6876 6481 6340 5935 5798 5545 4980 4950 4594 4486 4160 4033 3998 3823 3571 3557 3511 3342 3414 3305 3205 3079 3133 3137 3152 3192 3153 3141 3220 3302 3224 3463 3334 3501 3561 3741 3939 3945 4091 4322 4366 4653 4916 5209 5372 5723 6054 6327 6590 7337 7714 8069 8298 8647 9275 9475 9914 10144 10368 10588 10443 10513 10294 9969 9957 9588 9363 8985 8613 8549 8230 8066 7916 7824 7941 7968 8155 8367 8711 8910 9812 10268 11012 11909 12995 14252 15331 16618 18017 19322 20598 21124 21617 21940 21951 21456 20307 19376 18378 16930 15386 14445 12931 11677 10435 9169 8448 7500 6860 6345 5719 5437 4921 4701 4497 4321 4091 3914 3815 3524 3491 3455 3382 3304 3329 3223 3153 3153 3202 3131 3246 3183 3187 3271 3364 3428 3509 3722 3827 3861 4179 4243 4501 4738 4933 5105 5331 5528 5717 5554 5503 5569 5273 4990 4856 4622 4394 4302 3966 3828 3642 3475 3352 3373 3331 3292 3309 3402 3452 3598 3876 4043 4207 4622 5016 5577 6113 6600 7665 8987 10582 12173 14227 16702 19857 23402 27314 31587 36772 41691 45333 48121 46908 43541 38076 33749 30079 27991 25573 22931 19032 15308 11547 8739 6873 5493 4473 4026 3544 3411 3090 3093 2980 2914 2810 2789 2813 2607 2569 2567 2541 2563 2454 2385 2339 2359 2198 2351 2167 2106 2196 2063 2111 2061 1982 1990 2053 2006 2033 1997 1921 1941 1863 1867 1908 1911 1924 1875 1849 1926 1863 1903 1909 1875 1891 1880 1773 1807 1884 1801 1882 1873 1832 1860 1862 1774 1878 1805 1812 1791 1844 1816 1800 1922 1787 1867 1834 1850 1852 1791 1865 1837 1865 1826 1802 1818 1836 1872 1801 1798 1762 1806 1777 1805 1818 1808 1782 1874 1858 1801 1848 1811 1761 1867 1828 1898 1833 1772 1780 1792 1762 1866 1865 1794 1870 1794 1809 1836 1875 1860 1887 1888 1841 1797 1869 1803 1879 1991 1908 1941 1856 1963 1826 1955 1912 1900 1953 1959 1991 2017 2014 1916 1974 1965 2036 2066 1986 2140 2038 2080 2058 2116 2017 2140 2130 2140 2123 2226 2294 2236 2326 2390 2441 2391 2417 2575 2589 2697 2735 2785 2888 2919 3222 3321 3307 3469 3576 3824 4041 4225 4368 4608 5014 5247 5511 5870 6322 6872 7199 7700 8343 8716 9117 9962 10178 10768 11134 11227 11394 11651 11504 11055 10621 10182 9678 9104 8444 8045 7431 6896 6305 5793 5257 4780 4581 4202 3885 3648 3398 3299 3181 2938 2916 2824 2626 2659 2545 2509 2453 2400 2315 2246 2186 2170 2162 2026 2131 1971 2038 1928 1953 1967 1969 2002 1876 1953 1821 1868 1772 1923 1912 1846 1711 1786 1710 1697 1820 1700 1715 1681 1769 1698 1681 1596 1648 1622 1580 1640 1696 1669 1665 1619 1663 1666 1702 1523 1597 1631 1594 1620 1580 1583 1614 1653 1685 1622 1675 1683 1632 1675 1603 1722 1689 1595 1650 1696 1728 1663 1667 1743 1675 1822 1733 1736 1740 1719 1690 1698 1612 1670 1559 1661 1626 1597 1610 1640 1468 1574 1603 1543 1616 1517 1521 1540 1583 1488 1574 1461 1501 1485 1493 1540 1545 1478 1614 1467 1440 1510 1517 1516 1433 1491 1584 1494 1496 1492 1463 1574 1586 1511 1492 1527 1546 1543 1491 1468 1472 1513 1489 1522 1431 1519 1453 1546 1476 1466 1492 1466 1516 1494 1492 1458 1459 1473 1413 1507 1441 1557 1479 1497 1547 1503 1519 1419 1534 1466 1467 1516 1534 1499 1512 1570 1554 1529 1549 1516 1483 1512 1528 1595 1593 1548 1519 1554 1553 1541 1569 1612 1507 1659 1586 1599 1645 1591 1735 1719 1602 1683 1685 1699 1692 1841 1827 1898 1935 1997 2050 2111 2162 2343 2468 2557 2489 2731 2988 3039 3155 3494 3531 3759 3923 4193 4286 4335 4645 4554 4623 4578 4503 4462 4248 4194 4030 3876 3827 3711 3521 3481 3459 3470 3386 3363 3456 3535 3635 3790 3870 4006 4037 4147 4242 4150 4135 4047 4022 3891 3657 3669 3413 3323 3053 2992 2785 2644 2450 2267 2225 2131 2082 2013 1905 1956 1792 1800 1695 1668 1710 1741 1677 1616 1650 1624 1657 1573 1603 1544 1553 1661 1620 1587 1562 1476 1598 1602 1611 1622 1606 1558 1536 1509 1543 1632 1643 1654 1608 1627 1673 1609 1680 1662 1716 1720 1814 1738 1800 1852 1898 1981 1978 2101 2142 2272 2470 2536 2649 2972 3012 3278 3436 3824 3981 4040 4291 4484 4353 4540 4401 4305 4155 3933 3935 3647 3441 3237 3134 2944 2780 2521 2504 2304 2132 2095 1973 1977 1917 1927 1886 1906 1820 1855 1881 1873 1862 1924 1988 2057 2056 2081 2171 2202 2275 2407 2579 2586 2615 2698 2745 2728 2699 2783 2779 2784 2718 2793 2739 2799 2799 2665 2657 2554 2586 2420 2353 2308 2243 2161 2010 2026 1986 1904 1875 1785 1809 1715 1795 1662 1787 1692 1748 1755 1733 1865 1905 1923 2004 1998 2208 2320 2509 2762 2954 3226 3425 3592 3883 4150 4332 4382 4415 4417 4178 3984 3950 3585 3528 3403 3283 3258 2910 2716 2524 2295 2118 2003 2039 1855 1805 1739 1708 1663 1660 1579 1600 1683 1543 1602 1561 1664 1647 1672 1639 1818 1729 1849 1945 1984 2052 2149 2223 2398 2554 2606 2677 2587 2556 2514 2405 2343 2292 2139 2094 2070 1922 1865 1830 1735 1641 1631 1537 1531 1419 1401 1366 1413 1390 1412 1332 1301 1352 1333 1343 1306 1291 1309 1297 1341 1341 1317 1273 1382 1250 1270 1315 1251 1307 1315 1315 1246 1322 1253 1263 1320 1317 1297 1351 1260 1298 1264 1269 1289 1300 1246 1287 1286 1276 1199 1236 1285 1260 1277 1303 1294 1344 1287 1302 1269 1288 1328 1235 1261 1255 1339 1273 1261 1304 1302 1256 1328 1281 1355 1287 1300 1189 1273 1288 1267 1300 1347 1338 1268 1355 1346 1290 1261 1285 1360 1330 1368 1280 1329 1395 1283 1297 1324 1271 1319 1296 1252 1316 1264 1338 1338 1332 1364 1336 1370 1375 1280 1300 1322 1361 1321 1441 1316 1467 1357 1369 1459 1449 1416 1453 1383 1448 1523 1459 1567 1433 1538 1564 1500 1577 1600 1662 1638 1851 1849 1885 1916 2088 2117 2157 2287 2322 2364 2368 2440 2506 2454 2407 2351 2339 2374 2270 2208 2122 2101 2078 2057 1975 1946 1979 1921 1830 1823 1897 1895 1888 1847 1891 1845 1844 1875 1869 1855 1869 1962 2066 2110 2140 2205 2192 2339 2369 2403 2522 2457 2743 2791 2899 3026 3199 3405 3617 3860 4059 4193 4548 4772 5240 5267 5855 5737 6049 6431 6374 6397 6537 6418 6428 6297 6305 6092 5966 5854 5591 5264 5127 4834 4752 4416 4287 3922 3800 3567 3475 3298 3169 3009 2846 2702 2678 2510 2374 2298 2274 2201 2115 2022 1991 1997 1944 1846 1790 1836 1826 1699 1692 1670 1642 1674 1617 1606 1566 1571 1525 1471 1495 1523 1544 1490 1493 1555 1469 1493 1524 1482 1495 1463 1422 1522 1493 1503 1548 1529 1439 1509 1464 1473 1509 1433 1478 1480 1395 1456 1441 1385 1483 1311 1368 1314 1263 1306 1290 1311 1351 1365 1286 1384 1395 1345 1338 1396 1430 1361 1390 1397 1365 1420 1357 1407 1423 1385 1442 1333 1369 1443 1381 1460 1391 1457 1540 1475 1457 1451 1573 1486 1571 1565 1630 1625 1705 1660 1755 1796 1793 1926 1960 2066 2187 2286 2321 2471 2446 2547 2564 2643 2727 2669 2588 2627 2566 2587 2559 2391 2453 2268 2258 2218 2123 2048 1968 1941 1843 1781 1811 1808 1760 1700 1739 1722 1651 1561 1702 1764 1609 1721 1655 1781 1650 1733 1830 1812 1747 1835 1758 1754 1792 1804 1736 1800 1755 1755 1822 1748 1750 1652 1732 1666 1713 1675 1821 1725 1777 1761 1763 1764 1767 1702 1729 1712 1703 1765 1653 1712 1615 1546 1626 1582 1604 1520 1535 1490 1502 1439 1402 1465 1353 1407 1431 1454 1472 1434 1408 1416 1404 1398 1390 1423 1453 1445 1473 1446 1595 1632 1595 1630 1558 1754 1748 1702 1770 1809 1914 1930 2014 2010 1923 1910 2012 2034 2001 2059 2047 2051 1922 1920 2015 1824 1944 1856 1781 1837 1799 1798 1784 1726 1727 1686 1711 1663 1613 1574 1668 1625 1502 1607 1510 1585 1522 1574 1546 1510 1565 1570 1478 1602 1515 1537 1569 1540 1510 1502 1469 1400 1394 1371 1409 1402 1278 1354 1315 1349 1306 1291 1239 1239 1246 1275 1275 1250 1254 1255 1229 1197 1259 1275 1272 1234 1234 1285 1240 1220 1329 1249 1332 1280 1277 1377 1407 1485 1560 1549 1641 1814 1831 1946 1944 1948 1889 1851 1752 1617 1586 1597 1539 1523 1667 1600 1625 1542 1498 1416 1244 1251 1302 1237 1172 1226 1223 1170 1167 1234 1220 1184 1114 1153 1204 1222 1198 1197 1123 1190 1209 1186 1166 1160 1124 1221 1182 1150 1202 1150 1116 1167 1156 1185 1152 1166 1140 1141 1158 1171 1093 1139 1091 1162 1200 1104 1158 1151 1177 1097 1150 1157 1191 1109 1157 1210 1153 1120 1076 1113 1105 1141 1156 1209 1170 1172 1184 1135 1140 1161 1114 1238 1152 1195 1165 1203 1177 1116 1114 1141 1189 1205 1105 1189 1103 1177 1195 1153 1162 1134 1230 1182 1159 1182 1226 1212 1169 1218 1187 1209 1206 1296 1191 1179 1270 1246 1233 1215 1183 1282 1251 1293 1177 1213 1301 1182 1266 1217 1201 1191 1207 1151 1255 1195 1175 1177 1189 1199 1235 1254 1206 1201 1236 1191 1217 1213 1290 1246 1219 1300 1302 1285 1341 1347 1388 1412 1417 1441 1471 1581 1608 1684 1592 1714 1777 1842 1896 1940 1887 1941 2101 2054 2139 2087 2005 2056 1913 1844 1872 1863 1822 1801 1825 1737 1705 1655 1630 1577 1519 1376 1465 1414 1350 1372 1312 1322 1289 1243 1361 1260 1334 1284 1276 1197 1257 1289 1274 1254 1337 1266 1328 1306 1344 1294 1266 1423 1359 1295 1409 1406 1477 1381 1515 1547 1586 1607 1584 1628 1670 1669 1716 1863 1762 1958 1962 2003 1903 1886 1914 1897 1911 1930 1926 1901 1905 1767 1800 1760 1739 1758 1739 1816 1655 1716 1623 1682 1680 1741 1838 1882 1936 1925 2143 2229 2373 2591 2602 2790 2866 2821 2740 2565 2537 2362 2322 2404 2339 2334 2286 2341 2128 2153 1931 1900 1759 1704 1666 1541 1434 1433 1430 1319 1368 1327 1270 1245 1275 1239 1242 1233 1271 1270 1199 1277 1164 1231 1219 1202 1182 1260 1174 1158 1249 1175 1228 1272 1219 1233 1194 1255 1270 1215 1215 1196 1244 1308 1319 1225 1280 1318 1262 1349 1340 1333 1342 1428 1377 1398 1466 1452 1501 1522 1522 1652 1630 1673 1672 1778 1797 1811 1927 1989 2003 2081 2076 2168 2084 2094 2099 2146 2109 2150 2034 2061 1830 1962 1991 1894 1888 1832 1787 1775 1724 1821 1713 1764 1692 1622 1621 1714 1707 1677 1698 1705 1751 1843 1971 2074 2263 2483 2644 2928 3103 3200 3144 3028 2763 2556 2382 2254 2175 2206 2237 2328 2340 2302 2187 2141 2001 1892 1707 1646 1606 1536 1486 1580 1390 1553 1488 1508 1490 1538 1519 1525 1576 1574 1509 1645 1558 1556 1647 1672 1739 1726 1806 1798 1869 1874 1933 1971 1942 1975 2096 2145 2109 2336 2240 2407 2484 2454 2687 2650 2700 2882 2969 2910 2994 3115 3134 3083 3223 3174 3076 3150 3228 3131 3137 3157 3164 3177 3212 3223 3307 3215 3180 3408 3344 3489 3564 3687 3921 4077 4389 4471 4679 4858 5124 4946 5057 5110 4914 5046 5193 5185 5123 5411 5527 5494 5541 5297 5548 5223 5212 4978 4987 4872 4512 4576 4369 4100 4260 4057 3948 3797 3548 3522 3207 3128 3017 2983 2792 2631 2705 2520 2486 2433 2327 2240 2265 2221 2165 2139 2068 2006 2011 1979 1983 1937 1994 1881 1919 1898 1890 1823 1850 1930 1910 1813 1929 1777 1819 1817 1845 1837 1869 1810 1862 1847 1826 1955 1836 1883 1835 1826 1891 1867 1968 1954 1998 2045 2086 2169 2197 2241 2481 2613 2783 2841 3094 3236 3191 3388 3452 3555 3562 3350 3350 3252 3299 3304 3112 3187 3063 3150 3075 3047 3078 3198 3125 3149 3256 3302 2987 3056 3015 3027 2844 2765 2694 2644 2613 2674 2573 2670 2560 2556 2522 2428 2334 2285 2339 2131 2147 2121 1975 2076 1901 1926 1973 1865 1873 1699 1806 1758 1738 1714 1624 1585 1769 1620 1638 1597 1643 1653 1625 1622 1716 1713 1799 1832 1838 1973 1952 2139 2261 2434 2585 2732 2945 3157 3578 3624 3825 3894 4047 4019 3811 3772 3629 3617 3577 3404 3307 3200 3159 3159 3076 3032 2880 2827 2740 2616 2502 2349 2389 2237 2135 2120 2059 2168 2149 2176 2276 2186 2339 2559 2554 2619 2765 3025 3039 3181 3318 3483 3428 3508 3606 3604 3583 3623 3685 3419 3325 3253 3194 3037 2874 2911 2670 2620 2737 2461 2407 2425 2186 2067 2006 1939 1800 1637 1723 1633 1545 1543 1532 1511 1489 1487 1419 1451 1391 1507 1428 1347 1458 1407 1354 1411 1386 1494 1435 1449 1442 1503 1507 1607 1533 1582 1547 1575 1685 1610 1601 1672 1643 1565 1658 1597 1686 1542 1587 1531 1583 1531 1439 1564 1504 1425 1518 1420 1382 1471 1331 1334 1343 1273 1281 1301 1276 1234 1249 1199 1236 1239 1178 1217 1183 1207 1215 1174 1116 1132 1139 1162 1129 1118 1092 1128 1140 1189 1207 1122 1146 1122 1182 1077 1166 1127 1080 1121 1084 1157 1087 1138 1064 1125 1098 1114 1105 1095 1105 1147 1126 1176 1129 1076 1104 1090 1130 1143 1119 1132 1065 1114 1071 1152 1016 1089 1075 1110 1133 1131 1196 1092 1100 1095 1141 1099 1110 1092 1099 1125 1079 1090 1065 1130 1098 1070 1073 1153 1114 1096 1092 1155 1173 1131 1140 1174 1111 1160 1145 1135 1123 1094 1100 1098 1189 1175 1139 1244 1091 1147 1133 1167 1084 1089 1100 1158 1114 1115 1113 1182 1110 1148 1138 1131 1123 1088 1074 1092 1062 1102 1083 1075 1138 1054 1033 1109 1090 1053 1069 1103 1074 1067 1139 1058 1160 1082 1119 1077 1054 1151 1097 1080 1091 1128 1122 1108 1105 1057 1135 1175 1106 1139 1055 1163 1137 1075 1126 1109 1087 1071 1142 1112 1087 1160 1150 1151 1185 1109 1115 1132 1081 1089 1121 1112 1127 1139 1119 1128 1088 1095 1180 1175 1171 1129 1212 1170 1162 1246 1201 1244 1200 1223 1169 1184 1192 1280 1220 1175 1268 1190 1162 1264 1192 1271 1208 1307 1261 1205 1177 1250 1276 1307 1193 1307 1335 1325 1335 1372 1451 1323 1361 1490 1426 1511 1584 1547 1523 1643 1616 1722 1840 1889 1881 1994 2017 2059 2037 2187 2241 2266 2230 2374 2288 2332 2320 2202 2232 2169 2110 1990 2076 1954 1932 1959 1834 1811 1877 1835 1735 1695 1753 1677 1500 1553 1580 1541 1509 1475 1543 1548 1411 1486 1385 1449 1552 1437 1452 1476 1511 1590 1494 1597 1642 1711 1797 1787 1934 2071 2209 2290 2498 2645 2728 2677 2852 2765 2736 2684 2689 2688 2583 2591 2690 2674 2791 2798 2844 2893 2952 3007 3081 2947 3066 3114 3162 3071 3203 3113 3375 3300 3197 3324 3382 3291 3230 3303 3251 3199 3255 3158 3181 2980 2954 3018 2911 2777 2825 2766 2721 2682 2703 2768 2675 2731 2566 2753 2817 2724 2762 2683 2831 2859 2836 2907 2972 2998 2908 3018 2934 2972 2826 2761 2733 2796 2819 2841 2643 2669 2747 2674 2640 2658 2752 2643 2591 2598 2504 2482 2357 2323 2329 2184 2140 2160 2154 2143 2009 2098 2120 2151 2087 2071 2172 2079 2087 2176 2121 2188 2251 2330 2334 2433 2472 2491 2629 2656 2876 2904 2839 3065 3075 2974 3080 2903 3087 3078 3051 3073 3131 3048 3011 2994 2909 2873 2728 2511 2548 2451 2401 2354 2193 2167 2218 2222 2157 2126 2011 1994 1804 1741 1630 1564 1504 1541 1530 1518 1457 1405 1421 1428 1349 1358 1327 1354 1308 1264 1224 1242 1247 1213 1269 1228 1261 1213 1228 1218 1169 1206 1268 1185 1160 1176 1194 1120 1196 1235 1159 1262 1226 1184 1159 1090 1220 1214 1196 1211 1128 1263 1239 1291 1258 1238 1256 1244 1277 1185 1226 1255 1228 1326 1318 1370 1400 1432 1446 1484 1447 1566 1551 1642 1663 1637 1711 1803 1759 1743 1711 1796 1795 1931 1886 2033 1962 2035 2039 2182 2073 2013 2086 2064 2020 1884 1955 1943 1865 1946 1838 1902 1883 1948 1869 1836 1826 1772 1755 1764 1744 1751 1676 1640 1615 1551 1528 1584 1618 1659 1574 1577 1461 1502 1552 1437 1510 1453 1484 1508 1515 1442 1498 1475 1431 1468 1530 1612 1603 1522 1450 1530 1520 1548 1468 1555 1567 1624 1623 1752 1766 1755 1775 1868 1917 1901 1872 1821 1884 1854 1837 1798 1779 1763 1793 1809 1818 1822 1779 1746 1857 1808 1758 1803 1824 1778 1874 1785 1828 1888 1888 1980 1952 1991 2109 2118 2206 2225 2274 2175 2258 2189 2103 2235 2097 2139 2074 2048 2137 2091 1992 2055 2024 2022 1913 1878 1780 1817 1736 1646 1735 1671 1591 1495 1521 1466 1479 1506 1445 1370 1351 1407 1330 1341 1375 1301 1291 1295 1276 1268 1260 1255 1174 1168 1231 1220 1231 1217 1132 1145 1171 1132 1174 1121 1073 1173 1122 1214 1154 1143 1144 1054 1125 1172 1093 1105 1158 1146 1101 1156 1117 1136 1107 1089 1142 1123 1084 1124 1105 1079 1201 1041 1115 1071 1128 1109 1179 1185 1124 1106 1140 1087 1099 1069 1165 1107 1154 1116 1156 1112 1169 1156 1242 1162 1175 1218 1213 1233 1260 1240 1317 1211 1224 1299 1189 1297 1351 1260 1353 1386 1327 1442 1418 1437 1411 1515 1454 1467 1498 1587 1500 1594 1599 1643 1674 1797 1848 1947 1989 2060 2011 2192 2173 2103 2089 2125 2135 2023 1970 1935 2056 2010 2067 2047 2033 2092 2091 2054 2155 1983 2064 2006 1904 1906 1952 1862 1951 1850 1825 1759 1747 1718 1682 1684 1710 1689 1586 1633 1576 1634 1591 1605 1579 1597 1653 1650 1584 1567 1579 1482 1392 1392 1375 1308 1262 1306 1304 1302 1291 1324 1356 1445 1368 1495 1354 1374 1356 1451 1366 1475 1576 1578 1661 1822 2082 2090 2365 2340 2452 2214 1937 1776 1664 1483 1428 1369 1400 1508 1486 1594 1648 1750 1711 1772 1656 1564 1471 1404 1371 1252 1219 1248 1222 1167 1244 1281 1275 1311 1372 1382 1494 1342 1392 1405 1398 1328 1334 1311 1281 1277 1371 1336 1243 1330 1356 1332 1399 1431 1469 1367 1377 1436 1444 1465 1509 1474 1505 1524 1512 1604 1598 1655 1730 1672 1771 1718 1682 1641 1751 1674 1634 1749 1645 1657 1586 1586 1628 1577 1569 1559 1526 1555 1583 1525 1458 1489 1511 1497 1492 1475 1452 1421 1412 1330 1441 1358 1411 1398 1519 1383 1397 1446 1409 1489 1505 1554 1507 1574 1544 1643 1629 1651 1586 1739 1790 1784 1852 1879 1851 1867 1913 1873 1895 1941 1874 1845 1831 1759 1708 1656 1627 1667 1634 1610 1605 1557 1556 1535 1530 1443 1512 1346 1413 1423 1316 1295 1275 1262 1249 1231 1247 1240 1167 1192 1120 1201 1160 1197 1158 1221 1160 1194 1079 1155 1131 1134 1195 1160 1114 1163 1137 1187 1191 1147 1194 1207 1152 1282 1213 1196 1259 1244 1359 1315 1407 1393 1427 1412 1465 1461 1489 1462 1612 1531 1599 1681 1660 1764 1805 1895 1869 1995 1962 2033 2025 2165 2034 2115 2111 2134 2093 2032 1940 2018 1965 1933 1860 1971 1894 1823 1869 1801 1799 1839 1839 1833 1812 1774 1667 1773 1738 1654 1758 1776 1771 1823 1827 1867 1897 1872 1830 1873 1822 1905 1686 1756 1724 1702 1726 1674 1787 1734 1813 1766 1769 1828 1791 1765 1848 1769 1856 1763 1796 1852 1888 1888 2008 1894 1875 1812 1939 1972 1866 1947 1952 1936 1915 1944 1901 1898 1893 1738 1828 1824 1798 1831 1717 1806 1712 1722 1706 1693 1612 1739 1560 1549 1609 1564 1508 1518 1428 1534 1433 1384 1359 1409 1417 1454 1409 1370 1402 1428 1428 1376 1399 1408 1445 1432 1458 1418 1377 1451 1483 1411 1492 1460 1430 1478 1521 1560 1579 1678 1729 1691 1759 1779 1679 1632 1630 1569 1630 1559 1524 1558 1474 1523 1556 1528 1508 1590 1518 1598 1539 1554 1558 1535 1482 1581 1548 1577 1452 1529 1441 1538 1512 1482 1457 1423 1421 1390 1393 1412 1372 1411 1401 1513 1426 1441 1404 1389 1388 1348 1358 1360 1288 1386 1257 1329 1395 1334 1333 1271 1283 1329 1233 1257 1261 1292 1195 1349 1293 1244 1249 1284 1271 1296 1311 1288 1261 1301 1346 1317 1342 1341 1368 1503 1409 1500 1529 1555 1620 1583 1512 1522 1439 1400 1400 1389 1390 1366 1433 1479 1489 1567 1569 1535 1620 1665 1686 1691 1621 1633 1583 1545 1530 1574 1588 1559 1558 1604 1565 1552 1600 1565 1614 1696 1695 1801 1706 1809 1697 1799 1803 1832 1847 1875 2043 2012 2024 2050 1969 1977 1972 2042 1971 1913 1907 1912 1919 1762 1744 1859 1714 1781 1706 1691 1677 1712 1739 1680 1655 1636 1560 1531 1486 1493 1486 1471 1387 1290 1380 1302 1314 1311 1212 1296 1264 1242 1245 1158 1180 1164 1227 1194 1170 1210 1164 1219 1182 1071 1086 1152 1144 1164 1089 1069 1097 1116 1125 1112 1103 1104 1062 1067 1062 1085 1084 1156 1064 1014 1052 1061 1049 1139 1041 1067 1030 1140 1050 1062 1082 1041 1076 1131 1088 1117 1028 1104 1028 1001 1099 1002 1040 1028 1021 1058 1038 1013 990 1055 1016 1052 977 1003 999 1087 992 1049 1002 1110 1016 1064 989 1041 998 972 1014 1028 1077 1090 993 1036 986 1020 1053 1023 1000 1002 1012 1031 1018 1059 965 1097 980 1000 1010 1007 993 1018 999 992 1130 996 969 992 998 999 952 1010 996 1025 985 994 978 1033 1044 966 1048 961 1011 1013 1046 1019 1080 979 994 985 972 1028 985 992 1025 1013 976 953 985 1010 984 1012 992 1034 1065 929 999 991 1028 1001 1057 1003 1019 990 980 961 976 1036 957 997 1002 992 1003 988 988 1012 1055 990 1068 1016 969 903 990 1047 1009 990 1046 985 944 992 960 1020 960 1100 983 1018 1096 1034 1017 1034 1002 1034 965 991 1021 996 1041 1034 1038 988 1043 1000 1030 1041 988 1023 980 1057 995 1033 1031 1064 1021 1031 1049 1040 995 1047 1041 1096 1059 1089 1023 1169 1108 1132 1060 1052 1074 1045 1075 1006 1084 1079 1107 1108 1132 1180 1156 1200 1206 1161 1229 1176 1196 1246 1178 1224 1240 1203 1239 1285 1308 1277 1354 1397 1357 1386 1410 1454 1559 1413 1503 1456 1507 1482 1606 1475 1481 1513 1543 1492 1530 1541 1626 1562 1627 1669 1629 1691 1688 1702 1651 1690 1639 1729 1636 1771 1692 1703 1633 1701 1591 1646 1633 1663 1529 1545 1629 1572 1520 1647 1578 1521 1445 1483 1509 1484 1474 1439 1429 1390 1408 1412 1345 1406 1358 1364 1322 1407 1349 1301 1343 1362 1340 1337 1354 1410 1436 1392 1391 1464 1505 1517 1522 1438 1559 1512 1561 1459 1456 1440 1433 1394 1458 1341 1393 1346 1337 1345 1280 1338 1384 1311 1296 1267 1316 1275 1239 1283 1232 1268 1164 1154 1187 1214 1139 1191 1139 1126 1119 1201 1104 1225 1169 1219 1162 1163 1188 1177 1193 1240 1151 1202 1214 1170 1246 1174 1221 1177 1213 1291 1220 1216 1213 1251 1238 1252 1267 1267 1262 1271 1345 1280 1343 1290 1439 1289 1367 1391 1403 1420 1340 1374 1475 1486 1545 1559 1641 1565 1612 1586 1648 1653 1568 1617 1591 1539 1522 1473 1451 1406 1410 1447 1356 1429 1435 1397 1413 1526 1414 1418 1344 1423 1400 1413 1408 1418 1343 1419 1474 1411 1376 1381 1450 1462 1472 1449 1452 1430 1509 1459 1534 1484 1478 1495 1544 1521 1530 1489 1543 1466 1580 1521 1602 1581 1509 1538 1435 1409 1424 1363 1404 1371 1375 1369 1401 1381 1359 1313 1301 1240 1240 1257 1293 1259 1247 1216 1199 1229 1211 1236 1169 1252 1173 1099 1101 1157 1076 1101 1149 1103 1090 1052 1067 1102 1096 1111 1083 999 963 1049 1013 1108 1099 1145 1077 1034 1055 1106 1114 1114 1038 1075 1091 1067 1122 1076 1077 1123 1126 1168 1146 1113 1185 1138 1108 1127 1171 1162 1168 1147 1202 1218 1225 1203 1202 1209 1222 1227 1212 1200 1285 1224 1164 1249 1182 1234 1210 1217 1284 1237 1177 1228 1191 1197 1233 1271 1318 1261 1245 1252 1283 1293 1311 1296 1267 1239 1261 1209 1258 1304 1252 1232 1268 1307 1328 1283 1261 1259 1279 1230 1276 1226 1277 1202 1299 1246 1281 1242 1192 1143 1175 1199 1126 1118 1218 1082 1096 1078 1140 1124 1040 1088 1096 1055 1041 1082 1059 1094 978 1112 1013 1094 976 1093 929 1055 990 1050 947 972 1057 980 935 1005 941 1022 968 992 1016 988 1020 1060 1022 1005 976 996 985 1006 1002 1004 988 1007 994 1008 1017 953 1001 952 974 987 995 991 1001 987 975 1042 990 1013 1030 1026 987 1010 1000 1000 1001 1027 1001 1000 986 989 953 953 978 1021 986 1011 1004 997 991 963 1007 963 1037 1015 959 1030 1000 1006 1061 979 957 999 1045 1003 961 939 969 965 1022 956 917 993 909 971 939 902 980 985 985 956 984 955 1048 1006 938 1051 927 977 886 1081 943 927 987 937 928 980 1000 971 1034 942 966 1011 975 992 977 1073 1033 986 983 1032 999 959 1007 1032 1010 994 1003 1058 1000 1002 971 1076 1017 989 1051 1019 1001 1065 1047 1068 1092 1070 1022 1047 1093 1132 1180 1109 1214 1217 1172 1207 1214 1185 1165 1266 1237 1238 1235 1265 1168 1217 1124 1206 1174 1198 1178 1129 1101 1186 1191 1161 1222 1193 1243 1230 1176 1236 1304 1383 1261 1296 1336 1385 1336 1372 1437 1452 1466 1497 1459 1511 1493 1513 1576 1535 1486 1420 1496 1493 1554 1561 1525 1526 1460 1608 1523 1653 1531 1568 1566 1549 1503 1571 1460 1459 1523 1523 1458 1443 1451 1394 1459 1381 1385 1371 1345 1405 1390 1405 1294 1387 1323 1328 1339 1331 1336 1296 1382 1274 1337 1328 1295 1334 1236 1333 1318 1444 1330 1376 1303 1391 1367 1398 1369 1374 1341 1299 1383 1384 1371 1330 1358 1288 1343 1324 1392 1408 1325 1331 1321 1311 1339 1285 1271 1324 1280 1292 1244 1286 1258 1321 1288 1294 1341 1347 1274 1371 1332 1258 1318 1247 1291 1263 1343 1267 1371 1298 1330 1329 1310 1262 1388 1365 1469 1282 1393 1332 1400 1428 1463 1473 1494 1488 1539 1507 1547 1573 1598 1470 1586 1505 1656 1596 1575 1668 1647 1670 1705 1841 1758 1823 1822 1908 1799 1885 1818 1836 1854 1806 1755 1708 1726 1774 1774 1777 1861 1772 1830 1718 1919 1863 1884 1901 1952 1885 1839 1894 1886 1890 1881 1993 1945 1868 1905 2013 1898 1989 1964 1925 1918 1920 1880 1962 1873 1949 1951 1943 1923 1932 1942 1858 1831 1862 1865 1743 1888 1823 1745 1779 1803 1785 1668 1729 1712 1658 1691 1651 1716 1689 1649 1644 1572 1603 1541 1475 1454 1484 1527 1402 1468 1461 1432 1473 1381 1428 1437 1346 1444 1443 1338 1387 1384 1267 1390 1315 1413 1253 1288 1273 1228 1203 1268 1224 1280 1252 1258 1275 1235 1278 1243 1249 1213 1267 1318 1213 1248 1226 1275 1283 1325 1316 1279 1239 1274 1333 1246 1258 1336 1349 1287 1328 1296 1248 1265 1298 1304 1284 1266 1330 1285 1325 1234 1287 1240 1233 1258 1312 1282 1265 1233 1298 1232 1265 1233 1193 1237 1258 1217 1260 1239 1173 1167 1253 1274 1187 1198 1202 1216 1192 1209 1163 1201 1124 1135 1124 1192 1229 1204 1220 1246 1231 1235 1258 1153 1144 1146 1185 1210 1179 1176 1207 1128 1110 1090 1163 1169 1121 1194 1116 1161 1184 1125 1195 1270 1169 1277 1175 1228 1298 1331 1283 1313 1215 1413 1306 1337 1293 1327 1301 1290 1242 1219 1237 1210 1223 1180 1166 1191 1173 1200 1151 1169 1193 1158 1198 1116 1188 1179 1177 1133 1088 1132 1119 1113 1128 1028 1105 995 1070 1076 1038 1010 1054 983 1053 999 968 1001 1052 1010 977 1041 987 1040 1002 1034 1020 1027 1080 1121 1083 1111 1128 1201 1052 1106 1108 1106 1046 1077 1037 1161 1019 1071 1034 1009 1054 1050 1053 1076 1059 1095 1056 1100 1055 1100 1010 1094 958 991 1022 960 1033 1021 1030 1024 1070 994 1010 1018 961 1041 982 1029 974 955 951 938 968 1038 961 958 936 974 994 1040 939 1030 952 1032 1048 1019 973 978 1007 977 1085 972 1057 965 978 986 1015 1050 998 997 988 1058 1011 1036 1017 1083 1053 1013 1000 988 1008 1070 1073 1029 1092 1033 1025 984 1015 1059 1045 1049 1075 1067 1047 1093 1016 1163 1031 1043 1058 1050 1073 1061 1094 1007 1027 1005 1095 957 1047 1022 988 994 1079 1130 1043 1098 1100 1092 1126 1103 1197 1185 1188 1250 1340 1392 1355 1345 1325 1252 1175 1132 1190 1101 1175 1115 1161 1051 1147 1055 1091 1084 1129 1146 1209 1269 1265 1221 1262 1257 1279 1202 1167 1194 1146 1184 1110 1212 1151 1191 1197 1162 1231 1170 1208 1102 1264 1215 1164 1235 1284 1255 1255 1278 1279 1392 1393 1335 1395 1333 1353 1329 1392 1344 1370 1370 1354 1413 1408 1384 1343 1362 1362 1368 1282 1390 1371 1342 1376 1382 1342 1369 1355 1399 1420 1310 1380 1370 1340 1343 1272 1314 1284 1279 1242 1261 1256 1274 1209 1275 1327 1202 1239 1245 1170 1224 1245 1191 1203 1228 1163 1231 1183 1181 1134 1082 1083 1180 1147 1194 1110 1095 1094 1071 1162 1079 1058 1168 1081 1067 1124 1112 1078 1044 1086 1045 1098 1074 1128 1077 1052 1075 1119 1131 1119 1117 1196 1204 1171 1133 1156 1112 1213 1209 1192 1274 1110 1187 1171 1188 1200 1201 1115 1103 1219 1174 1110 1138 1186 1176 1106 1157 1165 1125 1185 1101 1205 1175 1093 1169 1184 1152 1134 1133 1083 1155 1153 1146 1171 1216 1102 1129 1186 1197 1240 1235 1166 1248 1228 1203 1258 1245 1308 1259 1262 1293 1250 1298 1311 1300 1240 1326 1359 1311 1295 1290 1305 1199 1265 1230 1207 1277 1250 1213 1217 1233 1261 1193 1236 1234 1190 1218 1239 1163 1211 1197 1154 1107 1190 1172 1140 1078 1094 1109 1150 1072 1180 1122 1141 1192 1117 1123 1145 1130 1169 1173 1086 1154 1139 1195 1160 1118 1120 1190 1156 1154 1077 1137 1232 1171 1198 1214 1218 1239 1246 1273 1326 1308 1341 1318 1327 1391 1345 1372 1341 1403 1353 1237 1330 1346 1313 1289 1287 1254 1432 1288 1389 1231 1359 1347 1371 1390 1437 1465 1437 1418 1493 1436 1423 1436 1348 1392 1324 1316 1334 1364 1301 1265 1195 1263 1290 1190 1236 1211 1251 1211 1228 1225 1195 1215 1194 1153 1209 1218 1177 1134 1149 1153 1192 1195 1086 1024 1107 1080 1083 1042 1115 1057 1109 1075 1087 1089 1076 1022 1151 1059 1053 1117 1098 991 1090 1092 1169 1203 1168 1145 1165 1167 1205 1246 1162 1160 1182 1210 1177 1165 1107 1066 1124 1142 1132 1038 1100 1119 1019 1056 1094 1135 1092 1066 1073 1080 1070 1062 1140 1068 1080 1051 1096 1114 1104 1077 1080 1039 1128 985 1008 1070 1037 1064 996 991 997 1009 1074 1004 991 1015 1036 1040 1048 1003 1099 1029 1036 1122 1031 1045 1048 1063 1012 1039 1085 1028 1045 922 942 1002 1034 980 1036 1044 1046 978 973 949 960 965 1019 1004 1084 968 1032 1028 981 1091 1019 1052 970 1077 1017 1068 1024 1019 1009 1004 991 947 1058 1066 1050 1066 984 1002 1000 1033 1032 1040 1055 1034 1067 1099 1066 1139 1088 1076 1187 1075 1106 1111 1150 1075 1116 1062 1126 1086 1031 1029 1072 1107 1037 1079 1099 1094 1062 1064 1038 1047 1100 1017 1014 1013 1052 988 1104 987 1013 991 1029 990 987 994 1008 1011 1005 992 978 1026 982 908 969 971 956 948 1014 1010 942 1004 966 968 969 920 926 963 938 962 961 895 895 884 973 983 963 989 997 1015 1005 949 996 901 906 948 967 983 1026 943 969 994 985 957 945 967 981 1011 966 964 1002 1023 977 988 906 984 977 1024 969 1015 972 1037 993 1060 980 1022 1085 1025 1008 1059 1096 1067 1055 1138 1059 1105 1135 1157 1118 1152 1206 1119 1206 1185 1244 1220 1157 1201 1165 1200 1120 1200 1168 1127 1132 1165 1209 1188 1167 1184 1153 1237 1220 1162 1158 1212 1151 1232 1177 1154 1240 1192 1209 1256 1201 1184 1264 1186 1246 1231 1290 1221 1315 1290 1320 1207 1269 1270 1390 1383 1328 1327 1233 1330 1365 1353 1395 1353 1477 1427 1495 1557 1460 1435 1504 1434 1408 1437 1515 1534 1444 1517 1440 1483 1414 1421 1400 1443 1473 1404 1435 1431 1363 1426 1376 1276 1446 1394 1432 1461 1351 1428 1393 1354 1405 1360 1407 1408 1384 1417 1462 1443 1374 1451 1380 1352 1388 1302 1252 1388 1314 1235 1300 1260 1278 1231 1220 1209 1209 1232 1188 1147 1183 1170 1186 1190 1197 1217 1145 1137 1126 1229 1115 1202 1134 1182 1072 1162 1150 1078 1113 1071 1169 1142 1127 1140 1135 1108 1155 1168 1139 1098 1158 1078 1169 1150 1140 1110 1147 1123 1067 1144 1088 1154 1144 1213 1130 1148 1090 1114 1197 1148 1200 1232 1189 1238 1153 1234 1222 1257 1192 1233 1275 1261 1234 1302 1207 1299 1189 1243 1216 1221 1239 1189 1268 1290 1287 1259 1258 1274 1314 1286 1345 1260 1389 1297 1327 1336 1392 1385 1429 1349 1374 1437 1475 1476 1461 1382 1386 1407 1429 1360 1427 1398 1362 1425 1334 1411 1356 1333 1397 1368 1275 1401 1294 1360 1323 1225 1262 1293 1281 1280 1271 1287 1309 1330 1269 1252 1207 1235 1276 1209 1240 1166 1204 1162 1068 1100 1152 1111 1137 1124 1142 1119 1153 1055 1122 1154 1091 1103 1132 1082 1138 1076 1116 1127 1039 1054 996 1084 1089 1096 1083 1116 1086 994 1082 1041 1053 1084 1098 1055 1102 1107 1072 1108 1089 1126 1136 1137 1165 1099 1094 1087 1043 1050 1086 1110 1085 1038 1096 1071 1062 1111 1048 1141 1055 1088 1040 981 1076 1084 1042 1076 991 1040 1100 1104 1072 1039 1090 1038 1054 1049 1028 1011 1065 1067 1036 1074 1062 1017 1020 1094 987 1045 1007 1040 1052 1044 1039 1092 1070 1060 1038 1040 1074 1146 1037 1148 1100 1123 1059 1116 1074 1123 1128 1033 1094 1026 1101 1089 1079 1028 1082 1049 1028 1074 1048 1004 1025 1050 1033 1029 1033 1075 1056 1021 988 1034 1025 1062 1039 985 1027 1026 1034 1067 1009 979 1001 1064 1021 1040 1056 1003 985 1004 1024 1042 971 997 987 1052 978 1028 1018 985 984 961 998 991 1010 969 1035 984 933 973 951 972 1049 961 968 934 966 1007 1002 945 977 1030 946 959 1006 1029 979 976 958 950 997 977 965 969 972 991 1022 1036 1132 1068 1108 1127 1096 1121 1109 1048 1051 1003 1019 1009 991 963 1045 1013 990 982 992 982 985 984 984 1004 1041 924 1019 1073 1045 1024 1012 1031 1052 972 1074 1022 1005 1060 1012 1019 1084 1016 1000 1026 1090 1088 1024 996 951 1002 1019 977 994 965 1012 1065 1000 998 1002 1031 980 1010 941 1011 1021 969 957 963 1023 959 963 1039 984 957 997 954 1003 938 980 987 914 1041 1065 970 984 968 982 1031 1007 998 1019 984 993 953 1015 986 939 1019 1019 1041 1003 977 1005 981 1032 1004 1008 990 1020 1005 1041 994 1051 1009 999 1086 995 1035 978 1006 1036 1097 1044 1032 1135 1085 1111 1100 1094 1150 1103 1164 1182 1194 1172 1222 1125 1134 1180 1172 1204 1182 1206 1138 1161 1200 1149 1133 1107 1154 1170 1118 1205 1194 1215 1210 1270 1185 1200 1291 1204 1186 1239 1159 1220 1199 1102 1218 1103 1141 1125 1113 1135 1170 1109 1221 1172 1241 1198 1304 1291 1337 1285 1313 1304 1359 1211 1296 1224 1230 1206 1146 1137 1114 1168 1181 1220 1135 1194 1191 1161 1137 1167 1181 1135 1249 1298 1252 1245 1222 1268 1315 1240 1341 1338 1301 1361 1290 1333 1417 1275 1253 1376 1376 1425 1365 1351 1407 1368 1450 1430 1410 1371 1470 1364 1454 1425 1389 1391 1389 1463 1465 1418 1473 1549 1484 1427 1425 1460 1446 1440 1457 1480 1451 1450 1441 1506 1514 1382 1444 1454 1506 1434 1403 1444 1432 1432 1503 1396 1462 1411 1398 1412 1416 1426 1324 1432 1410 1293 1370 1301 1427 1382 1347 1394 1339 1455 1474 1391 1473 1474 1445 1381 1424 1313 1329 1429 1340 1314 1239 1248 1286 1222 1195 1195 1235 1217 1249 1141 1228 1244 1255 1247 1250 1259 1276 1295 1320 1351 1294 1254 1263 1219 1256 1238 1353 1221 1323 1218 1243 1302 1226 1309 1301 1256 1325 1231 1343 1355 1284 1340 1321 1319 1326 1320 1325 1352 1413 1400 1337 1409 1311 1388 1387 1432 1313 1332 1372 1399 1423 1316 1387 1260 1393 1293 1306 1351 1250 1319 1316 1334 1346 1353 1406 1380 1326 1331 1347 1371 1301 1300 1384 1342 1381 1303 1386 1430 1402 1383 1378 1474 1394 1405 1370 1448 1404 1373 1411 1406 1388 1350 1274 1415 1293 1379 1279 1291 1287 1374 1356 1365 1402 1312 1345 1366 1331 1350 1345 1394 1310 1378 1391 1451 1358 1317 1376 1419 1394 1486 1392 1417 1491 1476 1422 1401 1437 1400 1355 1468 1336 1361 1304 1298 1242 1247 1255 1235 1232 1209 1244 1176 1195 1184 1184 1232 1229 1132 1236 1226 1167 1208 1138 1222 1219 1278 1233 1142 1163 1222 1211 1196 1208 1164 1210 1180 1159 1172 1096 1078 1149 1090 1135 1098 1069 1043 1043 1108 1107 1155 1079 1093 990 1070 1012 1076 999 1057 1009 1051 1076 1088 1031 1083 1055 1017 1028 1059 1020 1148 1066 1092 1105 1107 1160 1109 1072 1200 1074 1129 1164 1167 1138 1167 1163 1191 1168 1178 1194 1169 1223 1226 1221 1249 1203 1184 1175 1181 1263 1176 1215 1168 1177 1197 1246 1224 1289 1203 1257 1206 1204 1201 1243 1283 1231 1236 1209 1307 1284 1431 1478 1579 1545 1711 1689 1791 1824 1781 1724 1654 1557 1435 1460 1352 1357 1323 1299 1294 1288 1237 1256 1254 1235 1216 1310 1233 1276 1259 1321 1274 1295 1396 1331 1383 1441 1558 1484 1506 1494 1419 1329 1405 1331 1341 1310 1314 1278 1288 1216 1241 1250 1208 1208 1198 1223 1204 1169 1201 1169 1225 1301 1148 1262 1180 1214 1202 1201 1207 1181 1159 1298 1247 1226 1245 1242 1186 1261 1223 1292 1229 1241 1219 1245 1234 1257 1261 1213 1344 1247</counts>
			</dataPoints>
		</scan>
	</xrdMeasurement>
</xrdMeasurements>