File: dataset/precursor_mixture/HfO2_La(OH)3_Nb2O5_CaCO3.2-min.xrdml
<?xml version="1.0"?>
<xrdMeasurements xmlns="http://www.xrdml.com/XRDMeasurement/2.2" xmlns:xsi="http://www.w3.org/2001/XMLSchema-instance" xsi:schemaLocation="http://www.xrdml.com/XRDMeasurement/2.2 http://www.xrdml.com/XRDMeasurement/2.2/XRDMeasurement.xsd" status="Completed" recordIdentifier="{BB410499-E7E0-412A-98B2-A782B8EB3502}">
	<comment>
		<entry/>
	</comment>
	<sample type="To be analyzed">
		<id>dara-39-1</id>
		<name></name>
		<preparedBy></preparedBy>
	</sample>
	<xrdMeasurement measurementType="Scan" status="Completed" sampleMode="Reflection">
		<usedWavelength intended="K-Alpha 1">
			<kAlpha1 unit="Angstrom">1.5405980</kAlpha1>
			<kAlpha2 unit="Angstrom">1.5444260</kAlpha2>
			<kBeta unit="Angstrom">1.3922500</kBeta>
			<ratioKAlpha2KAlpha1>0.5000</ratioKAlpha2KAlpha1>
		</usedWavelength>
		<incidentBeamPath>
			<radius unit="mm">145.00</radius>
			<xRayTube id="1010048" name="Empyrean Cu LFF HR (9430 033 7310x) DK430614">
				<tension unit="kV">40.0</tension>
				<current unit="mA">15.0</current>
				<anodeMaterial>Cu</anodeMaterial>
				<focus type="Line">
					<length unit="mm">12.0</length>
					<width unit="mm">0.4</width>
					<takeOffAngle unit="deg">6.0</takeOffAngle>
				</focus>
			</xRayTube>
			<filter id="20010004" name="Beta-filter Nickel">
				<material>Ni</material>
				<thickness unit="mm">0.020</thickness>
			</filter>
			<sollerSlit id="21010002" name="Soller slits 0.04 rad.">
				<opening unit="rad">0.0400</opening>
			</sollerSlit>
			<mask id="22031000" name="Fixed mask 13 mm">
				<width unit="mm">9.00</width>
			</mask>
			<divergenceSlit id="22120001" name="Divergence slit 1°" xsi:type="fixedDivergenceSlitType">
				<distanceToSample unit="mm">50.00</distanceToSample>
				<height unit="mm">1.52</height>
			</divergenceSlit>
		</incidentBeamPath>
		<beamKnife id="29030100" name="Beam knife low"/>
		<sampleMovement xsi:type="spinningSampleMovementType">
			<spinnerRevolutionTime unit="seconds">1.0</spinnerRevolutionTime>
		</sampleMovement>
		<diffractedBeamPath>
			<radius unit="mm">145.00</radius>
			<antiScatterSlit id="22090040" name="AS slit 9 mm" xsi:type="fixedAntiScatterSlitType">
				<height unit="mm">9.00</height>
			</antiScatterSlit>
			<sollerSlit id="21020003" name="Large Soller slits 0.04 rad.">
				<opening unit="rad">0.0400</opening>
			</sollerSlit>
			<filter id="20030001" name="Large beta-filter Nickel">
				<material>Ni</material>
				<thickness unit="mm">0.020</thickness>
			</filter>
			<detector id="7010019" name="PIXcel1D-Medipix3 detector" xsi:type="rtmsDetectorType">
				<phd unit="keV">
					<lowerLevel>4.0</lowerLevel>
					<upperLevel>11.3</upperLevel>
				</phd>
				<mode>Scanning</mode>
				<activeLength unit="deg">1.021</activeLength>
			</detector>
		</diffractedBeamPath>
		<scan appendNumber="0" mode="Continuous" scanAxis="Gonio" status="Completed">
			<header>
				<startTimeStamp>2024-02-18T09:48:26-08:00</startTimeStamp>
				<endTimeStamp>2024-02-18T09:50:48-08:00</endTimeStamp>
				<author>
					<name>AutomatedUser</name>
				</author>
				<source>
					<applicationSoftware version="1.4b (28)">PANalytical Aeris Instrument Suite</applicationSoftware>
					<instrumentControlSoftware version="2.0.0 20210224">AERIS</instrumentControlSoftware>
					<instrumentID>950485</instrumentID>
				</source>
			</header>
			<dataPoints>
				<positions axis="2Theta" unit="deg">
					<startPosition>10.02173288</startPosition>
					<endPosition>139.98435528</endPosition>
				</positions>
				<positions axis="Omega" unit="deg">
					<startPosition>5.01086644</startPosition>
					<endPosition>69.99217764</endPosition>
				</positions>
				<commonCountingTime unit="seconds">1.551</commonCountingTime>
				<counts unit="counts">355 372 356 369 374 370 369 349 345 374 373 343 337 342 364 369 354 344 338 379 372 336 349 330 314 333 314 336 344 350 334 325 312 321 353 327 329 325 308 339 306 300 303 279 293 300 328 304 304 282 304 282 313 275 291 307 332 331 278 280 272 274 312 283 294 250 289 288 255 305 293 280 266 263 295 283 302 264 269 271 258 251 277 259 252 253 280 266 261 250 263 302 263 276 271 267 272 271 261 253 275 236 239 261 262 231 268 247 273 236 269 245 281 260 257 271 299 301 284 279 309 378 365 452 551 592 762 953 988 902 703 526 422 338 331 255 286 217 232 257 229 254 257 222 247 218 212 225 222 265 257 193 238 186 227 234 209 237 220 263 259 231 211 208 205 251 224 215 229 245 248 250 273 216 240 245 180 241 209 217 182 198 217 210 189 192 207 174 220 197 184 198 176 167 192 205 208 172 177 194 187 172 190 192 184 166 182 205 179 215 191 198 193 174 211 178 181 178 187 186 189 183 154 150 190 182 180 197 176 182 157 169 172 173 153 190 157 168 156 213 169 162 158 162 137 147 193 180 186 155 158 162 153 169 148 175 201 166 182 187 169 148 190 153 150 183 176 159 171 183 176 171 164 188 184 168 167 173 195 205 229 257 359 517 827 911 691 441 239 210 179 176 193 203 220 152 184 187 166 148 172 164 171 163 181 177 160 145 176 161 175 169 144 179 164 165 172 224 227 266 341 364 287 235 223 183 243 207 221 299 335 324 226 202 162 155 124 154 151 141 185 146 170 143 152 145 166 156 155 142 154 162 157 161 160 126 154 161 154 143 149 146 147 143 146 164 160 156 117 135 130 148 151 149 165 163 145 166 172 189 177 231 211 221 241 291 331 383 486 593 648 581 568 434 310 288 299 265 267 250 325 387 524 573 752 891 927 855 727 699 718 873 1217 1735 1970 1655 1250 840 520 394 324 281 289 265 298 317 453 461 489 439 352 242 276 331 417 653 1307 2958 4631 3147 2124 632 335 249 254 235 205 174 178 158 131 167 151 157 157 160 156 157 173 172 188 163 145 140 166 147 132 169 145 146 151 149 157 148 165 171 161 154 193 180 234 221 275 280 372 485 537 775 1095 1036 865 702 448 367 282 222 229 183 155 170 168 136 163 139 148 129 151 137 146 146 159 149 126 140 168 139 140 151 102 137 132 146 111 115 128 127 111 126 112 109 140 156 122 136 124 151 150 146 133 152 140 158 141 156 141 177 218 268 346 386 377 340 360 292 335 370 335 289 248 183 157 151 131 149 115 132 149 135 153 135 138 152 178 221 287 375 406 366 254 187 177 146 184 154 149 214 233 232 225 219 199 186 170 142 120 161 192 253 400 355 311 237 193 157 113 114 146 143 184 255 243 198 193 125 119 118 129 125 110 101 117 113 109 106 102 97 116 105 130 109 97 105 107 107 109 106 96 92 109 129 110 145 151 110 133 145 108 150 172 198 210 168 191 176 154 155 142 167 191 211 248 316 399 511 537 548 532 409 334 275 214 204 166 150 153 147 136 116 129 118 121 121 109 110 112 125 102 100 119 137 132 138 134 123 133 148 158 218 225 224 203 213 176 127 128 157 134 154 170 146 149 140 141 129 152 124 135 127 93 121 104 111 148 134 155 157 180 182 162 185 122 147 157 119 127 138 148 113 90 122 101 103 85 98 114 118 118 157 167 143 124 94 99 99 88 114 103 126 94 110 99 80 85 104 91 77 94 87 98 113 82 116 98 98 91 97 110 97 99 102 124 107 105 108 110 78 103 110 156 165 153 186 163 144 150 112 103 124 120 114 115 115 103 117 140 163 158 151 125 136 149 123 121 188 211 216 193 191 165 129 116 118 117 112 101 87 107 84 85 120 86 124 109 146 167 171 172 187 155 154 175 117 170 131 218 264 207 183 190 161 153 116 100 142 157 181 173 181 214 199 265 264 269 275 271 268 342 378 406 458 457 486 424 396 368 316 261 212 187 191 168 156 144 147 161 170 198 171 174 194 249 300 286 273 285 304 245 239 228 211 200 152 169 179 147 132 156 140 140 197 295 350 315 295 258 244 185 190 192 206 280 282 335 267 283 238 168 153 121 107 133 128 128 129 115 139 130 112 144 117 120 108 107 103 101 89 88 103 83 91 89 82 110 82 90 93 84 108 111 104 91 91 78 90 80 104 101 95 81 89 82 90 91 82 102 85 85 112 111 84 62 65 76 87 107 98 92 87 96 96 94 115 99 116 95 100 136 109 160 146 200 202 225 199 161 145 165 132 140 133 136 126 164 197 226 250 248 233 253 243 260 276 260 237 245 239 232 221 254 229 224 257 236 245 180 217 192 195 173 161 214 221 239 262 239 270 254 217 188 182 135 143 151 102 115 80 92 111 96 90 98 95 97 93 114 106 124 108 154 145 150 180 170 159 161 177 132 149 146 124 115 147 117 114 128 141 171 147 164 144 140 145 139 141 169 207 194 175 157 148 153 108 107 127 118 102 116 115 95 106 103 81 93 117 91 85 102 99 87 107 95 111 90 106 115 118 131 118 155 147 153 191 149 166 174 160 200 142 134 125 144 151 124 114 99 127 91 120 157 189 160 95 157 153 99 97 106 122 110 86 109 119 127 134 150 154 135 148 150 105 117 120 95 121 122 120 114 147 161 171 154 151 137 122 115 119 100 79 106 144 120 97 125 104 89 104 120 104 133 147 189 190 186 147 153 146 168 180 156 161 171 141 155 164 176 169 171 161 159 134 131 130 152 125 107 118 128 121 118 101 143 143 138 149 135 137 129 135 104 116 91 125 111 124 118 114 109 111 101 79 100 108 139 134 121 137 143 144 124 150 148 133 140 162 168 163 168 143 131 146 138 120 119 106 104 87 95 93 83 83 89 85 76 92 99 88 80 75 93 89 96 86 92 107 84 72 87 79 98 95 87 94 97 89 83 82 74 85 66 95 116 77 98 77 77 71 68 80 81 73 81 74 81 80 99 77 105 102 82 88 97 97 97 88 95 107 114 116 90 122 119 150 124 145 147 160 134 123 123 125 132 133 107 122 122 144 133 110 126 108 87 113 94 101 116 105 120 92 77 75 120 106 129 99 132 122 148 122 109 115 126 104 116 120 142 152 104 123 119 142 141 111 107 110 119 120 117 110 105 95 84 88 93 83 77 98 81 93 105 115 115 141 103 80 121 129 118 104 106 90 103 101 121 108 87 86 86 82 82 67 92 83 88 82 82 69 77 77 91 82 84 81 72 86 88 109 57 75 104 82 89 76 73 76 92 91 89 68 87 72 87 72 64 76 82 78 93 101 105 102 90 82 94 99 110 113 130 154 105 139 132 124 140 115 110 111 113 113 125 87 114 127 136 106 122 127 116 101 108 120 121 91 102 91 99 105 129 149 150 137 159 150 152 169 147 152 164 117 155 172 184 162 167 159 167 157 149 172 176 142 136 173 143 122 110 121 110 120 106 104 108 113 102 101 117 108 143 123 126 123 112 102 109 123 94 109 76 95 112 102 111 80 100 112 97 106 126 98 111 92 76 124 79 71 93 92 86 87 68 73 80 102 79 91 87 82 81 62 91 92 82 79 79 82 83 86 75 86 86 86 90 85 86 84 89 86 93 94 101 91 115 121 105 79 96 99 109 90 91 89 96 93 94 108 132 85 109 102 104 121 120 108 104 104 93 88 96 104 99 105 74 94 87 91 84 98 84 104 98 82 104 100 118 73 103 96 108 81 132 105 101 107 106 89 99 109 114 101 114 74 107 90 109 112 92 100 104 118 113 106 92 107 108 125 112 102 89 84 115 110 108 79 85 105 81 89 93 82 94 88 88 98 102 89 96 93 115 71 70 68 69 81 86 76 88 67 91 80 81 90 68 94 86 78 60 91 111 84 99 73 97 98 104 94 83 85 48 97 81 78 70 70 79 87 69 71 89 69 76 75 94 64 92 81 112 82 95 111 103 82 112 110 85 97 103 121 109 103 114 89 122 124 114 133 117 119 139 124 119 118 121 137 125 122 105 104 108 114 100 78 93 99 99 85 86 88 86 98 88 91 111 101 96 101 135 110 109 104 98 115 116 137 120 94 96 128 109 114 79 79 112 92 87 80 85 97 77 74 87 112 82 78 83 104 82 75 73 96 95 66 81 79 74 86 91 84 105 83 114 106 94 89 89 95 70 81 70 87 81 92 90 77 76 64 60 80 74 86 80 91 89 98 93 98 85 93 100 79 78 95 80 83 88 72 94 101 61 92 84 91 81 78 83 69 76 79 110 109 97 77 79 102 89 75 90 108 94 101 102 90 113 83 104 103 105 95 99 86 83 93 119 110 106 98 134 112 109 111 127 113 113 129 127 125 128 123 120 127 136 126 123 107 103 109 112 94 92 135 104 100 122 138 129 123 115 114 134 96 119 110 138 109 99 122 140 111 132 111 122 120 122 128 121 125 130 122 102 113 98 124 79 95 82 84 88 90 102 101 101 89 102 100 86 72 109 96 106 92 123 102 103 95 106 91 106 101 148 132 125 92 101 102 120 128 136 110 112 87 114 95 98 115 105 126 132 94 110 96 97 112 129 120 116 118 120 111 94 99 111 100 82 89 94 71 101 91 92 85 94 70 105 92 119 92 88 92 98 98 121 105 107 105 106 114 107 97 96 111 107 98 110 109 98 106 90 111 113 84 126 91 76 98 96 93 106 85 97 106 97 100 92 108 106 81 74 115 95 102 90 103 83 104 96 99 77 81 112 106 102 97 79 84 92 90 75 105 100 97 88 89 101 81 76 79 99 84 79 73 83 82 101 91 73 105 94 82 101 76 68 88 80 79 81 82 92 88 85 104 71 97 78 45 96 74 83 91 82 87 75 76 73 96 84 76 92 82 93 90 90 93 89 75 93 78 71 89 99 92 65 81 72 102 74 91 81 84 94 88 89 99 117 103 114 115 89 83 88 80 78 111 84 76 91 91 91 88 100 86 109 98 97 87 99 92 89 93 87 96 107 90 113 90 83 85 88 103 97 92 109 103 99 101 98 114 97 108 74 92 92 108 105 117 86 84 85 86 80 96 101 105 95 111 85 93 90 89 114 78 106 109 76 90 101 106 96 72 88 97 109 111 107 107 109 93 105 128 96 109 100 107 106 87 88 91 107 96 99 84 98 106 106 98 115 118 112 108 121 93 93 98 108 83 95 100 110 94 118 90 79 103 108 100 107 110 112 82 116 122 107 99 116 102 111 95 103 99 95 95 115 89 97 109 108 89 94 77 93 72 102 88 87 88 99 85 87 93 93 83 82 94 102 83 98 102 97 83 87 105 100 87 103 98 98 91 106 102 108 94 92 115 100 96 94 93 114 98 98 103 86 88 114 85 80 78 101 107 92 90 75 113 112 87 81 98 114 125 103 77 112 105 101 124 96 88 114 106 107 96 119 129 82 85 88 80 94 116 83 115 85 99 122 118 95 108 98 116 121 112 83 91 89 85 84 90 94 69 81 107 88 95 86 105 90 92 76 93 102 71 88 78 103 86 93 103 71 81 93 78 113 102 96 92 107 94 89 81 94 103 118 94 127 83 85 93 91 73 89 97 107 99 79 102 89 105 81 69 83 85 97 88 98 91 87 135 103 95 97 85 102 76 86 60 116 110 103 87 105 104 103 90 106 122 108 77 79 108 120 117 106 112 107 127 122 121 120 99 98 92 95 95 94 101 103 91 117 102 79 102 84 74 76 96 94 101 97 95 87 82 91 78 94 88 97 93 99 75 65 95 83 119 92 101 75 87 94 112 76 91 77 84 101 107 102 108 90 103 86 83 76 71 82 84 99 103 93 105 84 75 82 83 118 72 100 116 85 90 91 111 83 97 98 85 86 93 92 78 98 81 90 79 80 105 105 81 126 94 98 128 114 100 95 87 90 83 91 84 93 68 107 75 108 97 83 98 100 106 83 90 75 103 111 86 99 84 106 118 106 128 125 118 108 110 108 119 87 114 98 112 106 115 102 103 98 104 102 99 84 94 100 83 101 96 99 87 74 91 102 71 86 92 106 106 86 106 104 101 93 99 115 87 95 109 81 103 137 98 86 98 114 105 114 98 106 124 99 94 100 93 90 100 92 100 87 103 111 100 100 78 88 111 83 118 96 98 108 84 97 91 104 115 92 112 102 103 100 93 71 114 103 107 90 92 92 120 110 118 98 102 93 116 105 93 108 127 109 125 110 121 124 112 112 121 131 115 110 77 115 114 140 103 109 86 96 114 108 116 91 108 91 111 75 91 94 101 94 89 113 117 86 91 102 93 125 93 100 75 104 105 96 101 118 106 109 88 106 94 107 114 92 116 113 109 96 101 100 124 107 109 110 127 89 100 106 123 98 94 107 100 68 99 102 105 87 95 89 84 93 83 91 109 91 105 101 108 98 99 102 111 88 102 104 106 79 100 110 106 79 88 112 111 88 96 96 101 95 77 82 78 82 107 84 88 82 117 90 104 83 91 100 111 94 82 99 110 106 112 111 91 108 90 104 94 88 87 129 94 106 125 115 113 94 117 111 107 115 110 116 114 119 133 130 117 113 114 92 125 122 132 111 130 119 122 102 113 109 114 114 122 123 119 122 136 101 102 148 120 121 150 116 121 104 133 120 112 127 117 89 110 116 118 124 115 123 136 129 106 115 112 115 105 106 133 124 126 101 108 128 125 137 104 114 140 96 120 131 118 120 115 123 108 92 117 137 95 110 142 123 104 116 111 123</counts>
			</dataPoints>
		</scan>
	</xrdMeasurement>
</xrdMeasurements>