File: dataset/precursor_mixture/In2O3_0p3022-La(OH)3_0p5014-TiO2_0p2004--8min.xrdml
<?xml version="1.0"?>
<xrdMeasurements xmlns="http://www.xrdml.com/XRDMeasurement/2.3" xmlns:xsi="http://www.w3.org/2001/XMLSchema-instance" xsi:schemaLocation="http://www.xrdml.com/XRDMeasurement/2.3 http://www.xrdml.com/XRDMeasurement/2.3/XRDMeasurement.xsd" status="Completed" recordIdentifier="{358FF16F-CBCF-448C-B82B-81EA9367A165}">
	<comment>
		<entry/>
	</comment>
	<sample type="To be analyzed">
		<id>In2O3_0p3022-La(OH)3_0p5014-TiO2_0p2004--8min</id>
		<name></name>
		<preparedBy></preparedBy>
	</sample>
	<xrdMeasurement measurementType="Scan" status="Completed" sampleMode="Reflection">
		<usedWavelength intended="K-Alpha 1">
			<kAlpha1 unit="Angstrom">1.5405980</kAlpha1>
			<kAlpha2 unit="Angstrom">1.5444260</kAlpha2>
			<kBeta unit="Angstrom">1.3922500</kBeta>
			<ratioKAlpha2KAlpha1>0.5000</ratioKAlpha2KAlpha1>
		</usedWavelength>
		<incidentBeamPath>
			<radius unit="mm">145.00</radius>
			<xRayTube id="1010048" name="Empyrean Cu LFF HR (9430 033 7310x)">
				<tension unit="kV">40.0</tension>
				<current unit="mA">15.0</current>
				<anodeMaterial>Cu</anodeMaterial>
				<focus type="Line">
					<length unit="mm">12.0</length>
					<width unit="mm">0.4</width>
					<takeOffAngle unit="deg">6.0</takeOffAngle>
				</focus>
			</xRayTube>
			<sollerSlit id="21010002" name="Soller slits 0.04 rad.">
				<opening unit="rad">0.0400</opening>
			</sollerSlit>
			<mask id="22031000" name="Fixed mask 13 mm">
				<width unit="mm">9.00</width>
			</mask>
			<divergenceSlit id="22120001" name="Divergence slit 1°" xsi:type="fixedDivergenceSlitType">
				<distanceToSample unit="mm">50.00</distanceToSample>
				<height unit="mm">1.52</height>
			</divergenceSlit>
		</incidentBeamPath>
		<sampleMovement xsi:type="spinningSampleMovementType">
			<spinnerRevolutionTime unit="seconds">1.0</spinnerRevolutionTime>
		</sampleMovement>
		<diffractedBeamPath>
			<radius unit="mm">145.00</radius>
			<antiScatterSlit id="22090040" name="AS slit 9 mm (PIXcel)" xsi:type="fixedAntiScatterSlitType">
				<height unit="mm">9.00</height>
			</antiScatterSlit>
			<sollerSlit id="21020003" name="Large Soller slits 0.04 rad.">
				<opening unit="rad">0.0400</opening>
			</sollerSlit>
			<filter id="20030001" name="Large beta-filter Nickel">
				<material>Ni</material>
				<thickness unit="mm">0.020</thickness>
			</filter>
			<detector id="7010019" name="PIXcel1D-Medipix3 detector" xsi:type="rtmsDetectorType">
				<phd unit="keV">
					<lowerLevel>4.02</lowerLevel>
					<upperLevel>11.27</upperLevel>
				</phd>
				<mode>Scanning</mode>
				<activeLength unit="deg">5.542</activeLength>
			</detector>
		</diffractedBeamPath>
		<scan appendNumber="0" mode="Continuous" scanAxis="Gonio" status="Completed">
			<header>
				<startTimeStamp>2024-11-14T14:46:15-08:00</startTimeStamp>
				<endTimeStamp>2024-11-14T14:54:22-08:00</endTimeStamp>
				<author>
					<name>AutomatedUser</name>
				</author>
				<source>
					<applicationSoftware version="1.7b (136)">PANalytical Aeris Instrument Suite</applicationSoftware>
					<instrumentControlSoftware version="3.2.00000000 20240306">AERIS</instrumentControlSoftware>
					<instrumentID>950485</instrumentID>
				</source>
			</header>
			<dataPoints>
				<positions axis="2Theta" unit="deg">
					<startPosition>10.00943322</startPosition>
					<endPosition>99.99442286</endPosition>
				</positions>
				<positions axis="Omega" unit="deg">
					<startPosition>5.00471661</startPosition>
					<endPosition>49.99721143</endPosition>
				</positions>
				<commonCountingTime unit="seconds">12.495</commonCountingTime>
				<counts unit="counts">2349 2267 2294 2368 2315 2234 2324 2301 2210 2314 2244 2272 2353 2296 2272 2279 2207 2296 2309 2221 2270 2161 2248 2282 2295 2167 2260 2283 2161 2246 2182 2147 2269 2217 2057 2181 2298 2245 2230 2229 2153 2189 2177 2244 2166 2161 2201 2143 2233 2147 2173 2120 2198 2147 2169 2081 2162 2138 2107 2115 2172 2190 2105 2153 2084 2081 2049 2156 2038 2076 2093 2124 2093 2071 2101 2096 2074 2172 2032 2134 2105 2074 2003 2055 2066 1991 1994 2005 2096 2049 2125 1939 2003 2108 2061 2025 2054 2030 1948 2041 2080 2041 2022 1937 1919 2021 2053 2010 2035 2007 2003 1978 2009 1985 1927 1928 2053 2008 2019 2006 1972 1928 1959 1914 1961 1981 2035 1894 1937 1941 1911 1935 1955 1892 1986 1967 1934 1962 1864 1917 1888 1903 1943 1834 1876 1867 1909 1865 1855 1944 1909 1929 1853 1804 1913 1866 1940 1959 1829 1822 1830 1858 1878 1793 1831 1791 1910 1903 1792 1845 1826 1804 1853 1866 1823 1892 1802 1819 1739 1793 1824 1860 1819 1863 1814 1867 1890 1870 1718 1885 1788 1765 1833 1865 1684 1794 1861 1761 1746 1836 1755 1782 1819 1798 1723 1816 1780 1851 1738 1736 1792 1735 1814 1858 1772 1734 1801 1789 1803 1760 1771 1713 1662 1740 1676 1722 1682 1725 1753 1740 1710 1743 1794 1720 1693 1753 1708 1633 1703 1648 1680 1689 1706 1650 1682 1661 1671 1693 1706 1658 1713 1696 1643 1682 1711 1747 1673 1620 1607 1644 1655 1657 1670 1629 1718 1656 1645 1657 1672 1692 1585 1621 1653 1621 1596 1603 1616 1584 1577 1647 1598 1687 1676 1602 1684 1611 1573 1636 1585 1634 1600 1530 1540 1583 1558 1625 1604 1621 1665 1557 1594 1540 1638 1566 1536 1560 1480 1557 1580 1640 1552 1598 1557 1563 1523 1690 1615 1601 1540 1578 1650 1662 1601 1532 1518 1568 1502 1545 1583 1568 1516 1505 1549 1531 1530 1618 1531 1656 1572 1517 1558 1550 1532 1490 1530 1640 1474 1560 1493 1501 1635 1556 1595 1581 1535 1528 1597 1542 1501 1569 1524 1498 1423 1513 1482 1515 1525 1546 1542 1497 1534 1570 1452 1522 1506 1523 1519 1496 1462 1482 1537 1552 1527 1548 1468 1545 1553 1545 1513 1495 1573 1523 1518 1449 1508 1487 1513 1543 1460 1485 1482 1476 1483 1468 1489 1518 1547 1574 1503 1469 1469 1502 1496 1469 1522 1520 1477 1499 1532 1453 1496 1513 1487 1483 1501 1483 1430 1499 1430 1464 1457 1468 1418 1533 1509 1522 1478 1500 1478 1418 1493 1404 1387 1511 1533 1479 1463 1445 1459 1483 1513 1531 1459 1421 1490 1447 1541 1478 1466 1489 1496 1512 1452 1483 1545 1520 1518 1464 1570 1470 1562 1538 1515 1534 1588 1575 1520 1552 1585 1622 1609 1589 1630 1601 1622 1585 1705 1665 1714 1662 1708 1744 1714 1803 1764 1758 1946 1854 1875 1826 1931 2004 2058 2025 2196 2211 2283 2312 2428 2440 2491 2529 2696 2716 2805 2971 3004 3069 3252 3307 3434 3651 3800 3935 4043 4112 4329 4434 4567 4658 4788 5028 5103 4998 5131 5123 5164 5312 5097 5182 5031 4867 4907 4461 4430 4096 4057 3611 3591 3240 3248 2855 2788 2621 2416 2399 2207 2224 2136 2095 1866 1960 1991 1844 1838 1727 1759 1740 1693 1661 1596 1693 1677 1604 1561 1623 1566 1599 1559 1556 1554 1530 1574 1540 1552 1551 1447 1477 1523 1476 1495 1516 1478 1400 1466 1454 1465 1422 1387 1485 1462 1364 1457 1404 1492 1473 1400 1417 1439 1344 1460 1441 1384 1359 1467 1448 1390 1300 1385 1359 1356 1406 1408 1357 1424 1351 1311 1347 1373 1378 1342 1413 1400 1362 1369 1339 1359 1321 1357 1441 1329 1310 1349 1380 1366 1316 1404 1360 1324 1377 1331 1332 1305 1375 1325 1301 1247 1326 1332 1402 1346 1386 1299 1276 1313 1320 1346 1337 1324 1280 1379 1294 1350 1287 1255 1314 1346 1261 1364 1387 1328 1290 1323 1276 1398 1351 1345 1345 1344 1366 1309 1362 1342 1284 1393 1349 1273 1373 1338 1274 1328 1332 1265 1337 1290 1350 1352 1384 1340 1285 1276 1296 1370 1268 1336 1327 1286 1274 1344 1338 1309 1276 1281 1244 1314 1331 1296 1311 1295 1256 1249 1275 1261 1226 1259 1246 1209 1241 1252 1332 1279 1219 1290 1270 1243 1262 1355 1300 1209 1261 1210 1172 1248 1198 1230 1212 1303 1290 1292 1271 1258 1262 1275 1267 1243 1181 1256 1251 1311 1290 1235 1266 1290 1264 1243 1279 1235 1279 1244 1226 1271 1191 1266 1115 1195 1184 1244 1252 1174 1213 1239 1234 1200 1236 1254 1214 1199 1164 1231 1154 1208 1179 1270 1174 1193 1157 1242 1256 1229 1133 1224 1204 1233 1197 1256 1227 1181 1201 1168 1224 1208 1211 1129 1224 1199 1158 1157 1144 1154 1182 1218 1209 1216 1250 1176 1138 1232 1169 1138 1146 1190 1189 1115 1248 1217 1143 1120 1164 1150 1202 1121 1145 1183 1161 1208 1116 1180 1156 1193 1160 1136 1155 1161 1163 1168 1161 1178 1227 1163 1091 1112 1203 1206 1119 1168 1261 1167 1168 1109 1175 1144 1193 1190 1152 1197 1221 1128 1150 1147 1203 1177 1086 1127 1152 1131 1131 1139 1134 1096 1123 1152 1163 1096 1176 1106 1104 1131 1164 1137 1182 1087 1136 1135 1163 1060 1151 1125 1147 1115 1160 1076 1152 1190 1107 1087 1141 1110 1091 1145 1090 1157 1155 1055 1135 1172 1122 1110 1030 1024 1090 1087 1116 1110 1072 1079 1080 1117 1064 1114 1098 1123 1061 1082 1044 1061 1103 1086 1137 1117 1097 1089 1104 1053 1075 1103 1132 1148 1151 1099 1003 1120 941 1038 1071 1056 1094 1068 1055 1136 1094 1056 1119 1070 1054 1062 1054 1124 996 1103 1048 1039 1083 1057 1094 1080 1122 1081 1147 1061 1086 1105 1056 1039 1112 1107 1061 1111 1142 1112 1038 1062 1071 1087 1053 1054 1064 1072 1066 1077 1043 1098 1070 1094 1119 1028 1124 1057 1038 1085 1124 1033 1093 1056 1124 1087 995 1140 1081 1105 1098 1113 1051 1098 1121 1121 1068 1132 1169 1212 1111 1200 1186 1287 1216 1252 1258 1286 1320 1287 1370 1455 1423 1464 1535 1555 1614 1634 1690 1679 1773 1751 1799 1870 1794 1820 1953 1861 1778 1971 1849 1833 1808 1738 1656 1534 1414 1392 1292 1242 1301 1161 1187 1131 1147 1065 1122 1069 1122 1021 1076 1076 1042 1100 1083 1018 1089 1005 1080 1109 1020 990 995 999 1037 988 1065 1024 1055 1009 1040 973 1000 1089 1012 1013 1056 1007 1010 988 996 1042 1025 1034 940 1046 958 992 1019 981 990 1007 980 940 999 943 983 976 995 998 985 998 1020 960 920 1011 990 1012 964 962 1103 1007 1006 1005 972 1047 1014 973 1049 949 1034 1012 946 1005 1013 1025 1019 958 972 957 989 990 994 964 926 949 1008 968 1013 921 973 960 1007 998 984 965 929 974 1022 981 967 967 957 946 941 962 978 981 1043 938 932 990 986 913 956 975 1006 950 937 988 933 993 1015 937 938 965 932 953 961 983 998 971 989 968 960 979 909 914 982 977 964 991 996 965 923 962 924 945 921 939 972 937 956 927 974 890 959 921 901 952 933 965 927 946 972 970 940 947 901 988 919 937 942 930 970 960 923 923 958 901 874 915 921 957 926 934 929 961 881 857 1000 968 940 931 960 953 967 925 930 891 921 916 963 922 937 877 934 1009 951 949 925 909 924 911 917 899 913 911 926 944 867 944 931 947 940 899 967 941 971 897 902 991 958 922 943 839 863 916 917 824 895 894 855 961 870 907 975 966 918 998 911 890 898 915 880 916 905 945 959 907 868 926 951 913 929 928 895 918 921 908 935 958 943 902 964 958 1011 969 965 865 909 932 907 929 957 981 994 960 932 942 1022 1049 1003 985 1062 993 1001 1057 1068 1105 1109 1145 1150 1171 1210 1211 1305 1371 1418 1512 1570 1667 1717 1892 1962 2088 2093 2275 2448 2534 2719 2811 2888 2877 3078 3136 3220 3163 3227 3240 3188 3074 3025 2816 2741 2472 2230 2144 1874 1735 1625 1459 1359 1300 1229 1130 1130 1061 1028 1065 1001 999 989 974 987 929 1012 946 942 949 989 878 921 903 938 914 893 936 926 866 907 860 894 861 895 872 884 870 938 894 906 909 874 907 834 856 863 864 897 886 878 880 867 823 823 897 886 857 873 869 889 888 860 867 921 852 919 954 909 852 911 898 938 907 895 957 929 924 881 908 970 944 886 946 905 981 926 865 931 918 979 891 988 957 961 955 945 951 970 908 948 953 865 989 966 964 947 1043 968 960 952 981 1020 977 981 1040 1039 1046 1062 1099 1102 1067 1075 1073 1094 1121 1123 1191 1201 1242 1265 1297 1293 1292 1311 1437 1397 1464 1516 1543 1628 1690 1788 1846 1903 1954 2158 2295 2321 2384 2598 2784 2813 3041 3168 3316 3384 3637 3766 3872 4052 4235 4273 4483 4652 4645 4685 4811 4775 4809 4734 4600 4685 4386 4517 4209 4134 4013 3771 3524 3462 3275 3118 3019 2760 2613 2524 2411 2443 2138 2236 2085 2001 2058 1945 1989 2056 1939 1911 1863 1899 1928 1928 2027 2087 2118 2206 2214 2363 2416 2559 2614 2789 2910 3135 3321 3479 3575 3811 3955 4192 4525 4556 4964 5050 5347 5576 5648 5925 5811 6184 6078 6197 6222 6280 6031 6015 5838 5644 5522 5029 4917 4732 4425 4097 3913 3692 3368 3133 2922 2661 2508 2457 2304 2163 2000 1850 1860 1768 1658 1592 1484 1439 1469 1385 1247 1325 1245 1303 1164 1196 1155 1122 1128 1163 1073 1037 1057 1054 1048 1070 1020 986 973 952 946 979 913 1002 931 922 981 912 930 918 914 850 886 887 901 819 891 806 926 899 835 857 890 862 823 858 906 834 877 863 834 850 893 853 869 808 796 859 829 802 849 829 848 793 862 837 840 827 798 833 838 778 832 819 868 816 809 802 808 852 803 811 818 815 800 785 753 800 806 826 811 801 807 782 818 862 813 868 794 859 812 862 853 819 848 913 848 839 815 823 862 850 863 876 838 809 871 864 859 875 799 813 852 839 839 920 924 839 888 892 829 852 879 822 845 830 908 778 820 863 843 933 869 832 841 792 896 874 876 881 900 918 907 930 897 934 918 908 921 915 917 950 950 1005 990 1025 1045 983 1043 1044 1005 1139 1114 1172 1183 1154 1221 1232 1348 1388 1443 1405 1481 1635 1729 1818 1885 2068 2254 2478 2768 3055 3296 3674 4053 4294 4789 5420 6002 6474 7027 7612 8222 8620 9200 9513 9797 10200 10371 10437 10470 10348 10020 9545 8643 8001 7286 6616 5875 5096 4633 4040 3485 2950 2478 2301 2021 1766 1634 1569 1426 1348 1317 1343 1264 1184 1189 1163 1182 1122 1139 1056 1119 1054 983 1028 1088 1038 1008 993 926 963 938 901 904 904 877 957 873 891 938 991 866 907 905 954 923 980 967 1005 949 948 934 1024 926 937 969 1014 1087 1110 1099 1153 1154 1136 1184 1236 1252 1321 1347 1419 1453 1495 1508 1553 1583 1647 1573 1773 1643 1669 1770 1777 1707 1678 1696 1610 1629 1568 1559 1542 1453 1411 1468 1355 1302 1316 1134 1101 1161 1088 1086 1008 1059 959 944 934 932 888 915 893 840 917 820 794 787 796 791 828 783 762 767 805 762 789 726 750 766 704 708 741 750 662 768 745 709 727 693 696 738 710 762 777 684 719 680 698 707 721 686 732 702 713 703 728 698 724 725 726 714 656 707 709 685 697 705 731 720 743 675 655 676 684 716 670 685 691 708 664 669 713 665 703 656 707 672 651 654 666 721 736 685 718 707 686 699 688 649 672 635 687 679 708 734 664 673 706 717 731 747 674 740 692 713 744 753 754 768 745 770 776 775 771 755 737 813 763 750 708 709 731 723 754 686 677 658 654 650 713 637 675 666 687 632 630 659 620 665 648 627 645 632 650 628 641 611 623 616 662 647 632 647 629 665 640 648 652 605 637 591 651 680 679 628 693 629 648 629 640 633 620 584 628 648 604 602 619 621 638 651 611 627 579 655 593 624 602 635 635 634 622 657 619 656 614 626 589 599 640 660 618 620 609 618 606 703 617 687 645 610 621 602 630 656 617 595 629 676 658 615 631 639 659 625 605 676 644 614 600 613 599 643 691 570 619 631 638 629 629 624 604 617 613 589 603 610 613 635 657 642 542 657 615 655 619 598 633 611 615 628 648 670 653 656 700 618 635 575 651 654 668 636 615 645 697 668 663 658 705 672 661 639 673 687 678 692 718 633 677 703 691 753 668 705 752 702 725 774 695 779 737 779 829 801 856 911 919 898 1023 1077 1085 1174 1248 1311 1469 1598 1733 1948 2125 2229 2359 2614 2821 2859 2947 3207 3388 3435 3546 3517 3524 3563 3460 3283 2991 2764 2566 2463 2194 2033 2000 1751 1538 1475 1290 1194 1083 1023 961 925 901 833 801 889 856 868 846 827 800 859 857 874 870 892 886 864 914 909 964 948 971 987 986 1014 967 986 981 1036 1035 1019 957 999 993 966 929 936 961 879 883 866 830 832 861 832 835 744 821 729 704 646 745 664 650 628 654 678 646 623 599 651 626 640 619 645 581 579 634 627 612 616 611 624 596 605 584 587 590 579 581 624 611 568 616 584 609 605 630 565 568 640 575 538 583 608 597 607 609 586 595 632 611 622 637 646 634 661 684 663 657 689 717 689 676 739 676 701 738 713 680 737 703 731 670 687 608 630 686 600 686 650 697 661 603 589 616 569 578 567 573 596 591 565 586 585 568 585 587 578 558 558 534 534 559 618 605 624 630 590 616 640 613 638 659 629 663 660 716 672 703 721 741 826 847 850 929 955 1075 996 1119 1128 1178 1207 1260 1324 1339 1399 1440 1553 1485 1399 1401 1382 1364 1421 1401 1313 1414 1280 1247 1143 1099 987 1040 901 906 858 837 819 732 698 732 769 648 645 636 652 636 615 611 632 596 618 601 570 603 600 594 598 593 656 596 622 587 598 603 567 592 614 582 610 627 582 637 598 634 597 614 624 613 618 681 634 648 706 683 679 696 713 644 734 744 773 788 789 754 802 743 820 786 816 780 724 697 766 751 754 731 733 706 717 661 676 713 640 719 685 696 705 681 739 698 698 712 740 718 725 720 786 789 774 829 799 834 821 867 853 862 857 878 938 915 962 978 1000 1089 1036 1139 1189 1284 1300 1372 1407 1533 1576 1674 1716 1793 1883 2067 2160 2153 2256 2602 2649 2785 2922 3091 3231 3416 3399 3807 3875 3832 4182 3951 4204 4119 4178 4268 4182 4142 4211 3999 3949 3859 3760 3609 3369 3160 3076 2897 2749 2649 2445 2297 2194 2128 1882 1896 1825 1753 1682 1633 1559 1492 1479 1355 1302 1227 1256 1254 1177 1121 1055 1048 1053 1017 936 927 904 881 874 830 826 772 744 747 757 702 751 695 712 694 650 624 646 598 698 631 624 690 654 634 607 619 647 584 610 608 597 601 627 592 569 565 545 593 599 536 557 614 564 574 554 545 554 535 578 581 538 559 637 567 556 523 576 542 529 535 545 494 556 559 585 529 574 543 571 524 531 512 494 553 562 539 543 523 525 575 524 507 554 556 526 507 515 509 532 509 556 549 517 525 555 526 539 528 509 529 540 513 506 511 544 515 515 547 532 520 491 530 528 525 496 555 563 540 582 511 544 581 547 566 500 531 546 562 547 564 506 563 522 556 525 545 512 513 554 525 514 564 488 574 564 496 534 525 580 563 597 571 556 596 575 549 605 581 621 610 609 608 668 695 696 736 723 814 812 879 897 911 955 977 961 1046 1027 1149 1087 1125 1110 992 1047 1023 957 934 981 959 967 927 908 951 899 923 921 958 893 916 950 977 1008 1016 1064 1084 1110 1052 1108 1112 1144 1263 1210 1160 1211 1194 1155 1244 1101 1165 1113 1112 1076 1042 951 988 989 971 858 863 841 806 845 791 783 779 693 659 659 662 703 647 630 664 630 577 553 597 598 592 554 578 566 562 564 592 597 556 512 556 577 547 533 540 579 481 473 486 509 549 524 527 506 541 516 499 499 506 538 503 499 521 486 510 468 529 515 486 516 503 514 524 520 516 518 548 516 467 504 496 471 513 507 492 474 521 513 487 502 474 468 535 469 479 486 486 489 465 474 492 492 528 465 500 446 521 478 480 514 453 507 564 454 505 472 483 466 484 503 484 523 472 521 518 466 494 494 485 492 544 529 571 512 566 563 567 550 573 537 637 559 606 585 532 553 630 515 537 522 538 509 512 513 505 525 523 497 521 468 462 494 472 452 440 468 478 454 529 482 470 472 458 489 531 475 479 491 449 520 466 522 457 505 475 484 514 444 473 463 455 442 465 500 454 472 464 490 464 490 438 434 493 449 436 492 448 471 481 506 446 473 474 446 462 488 422 471 438 459 437 422 507 419 472 510 486 467 454 455 466 431 488 475 479 457 495 428 470 466 457 442 503 409 468 430 475 453 441 451 440 486 452 453 492 458 470 507 447 482 489 444 445 501 422 464 458 438 439 486 442 466 465 459 489 506 459 508 506 510 486 498 503 499 531 494 543 491 555 525 538 527 521 555 556 569 586 655 716 720 711 796 852 862 963 927 1022 1059 1141 1147 1200 1248 1316 1347 1368 1358 1258 1304 1215 1133 1074 1006 1021 989 968 902 945 901 875 813 718 643 622 581 592 514 546 521 515 515 531 511 492 536 530 518 495 497 517 487 505 473 478 435 477 471 506 480 541 484 472 500 497 439 499 471 483 470 448 488 469 490 477 492 456 481 480 481 477 455 494 493 506 490 490 485 482 511 548 525 512 496 470 519 474 501 495 527 486 537 469 510 530 565 499 556 552 551 541 558 575 550 560 567 643 590 535 601 604 620 632 705 685 708 724 741 846 753 798 870 820 882 936 968 963 1024 1020 1063 1059 1122 1104 1062 1108 1122 1139 1094 1092 1138 1042 1056 1076 1093 1034 952 897 923 910 860 927 854 762 736 805 780 713 689 744 721 673 714 636 661 646 650 658 594 606 588 617 580 654 651 551 616 606 593 643 626 600 622 608 615 650 614 659 647 677 657 675 666 660 694 681 684 723 705 750 737 755 806 843 828 835 891 957 944 1020 1040 1140 1213 1302 1405 1381 1576 1663 1683 1797 1902 1990 2011 2153 2202 2276 2215 2265 2330 2253 2269 2344 2369 2220 2390 2342 2476 2375 2438 2422 2318 2272 2319 2232 2205 2230 2243 2172 2219 2204 2202 2206 2189 2176 2148 2245 2247 2235 2340 2336 2315 2479 2508 2743 2652 2646 2836 2912 3006 3021 3228 3237 3329 3385 3422 3365 3503 3550 3617 3551 3485 3457 3389 3320 3311 3238 3143 3046 2978 2816 2739 2648 2487 2339 2325 2156 2095 2090 1849 1797 1797 1673 1583 1525 1454 1391 1355 1289 1315 1240 1147 1103 1084 1051 980 1035 931 912 919 979 863 867 836 880 856 788 806 768 869 830 832 813 861 862 891 880 912 907 903 903 907 834 829 833 797 758 795 708 743 771 724 793 658 690 666 655 656 640 622 649 595 601 607 635 590 613 611 609 615 619 626 654 621 632 687 611 675 648 693 715 724 735 744 751 778 803 749 826 765 813 889 850 905 858 921 898 877 885 935 918 880 879 861 867 845 859 811 757 791 774 788 726 731 735 754 704 715 703 640 645 624 572 625 601 586 593 566 554 550 560 528 543 598 553 533 541 531 540 541 521 553 532 540 508 546 544 539 521 581 550 551 577 573 536 500 550 525 566 584 594 551 613 598 603 614 627 647 656 650 691 694 687 750 707 786 848 835 897 945 993 1090 1133 1225 1445 1558 1712 1927 2065 2278 2606 2743 3150 3272 3390 3710 3766 4020 4112 4199 4065 3876 3600 3363 3125 2873 2693 2592 2587 2481 2427 2325 2218 2115 1899 1695 1557 1349 1192 1012 989 927 846 740 754 763 677 650 628 687 628 606 588 597 566 581 580 543 533 527 527 539 547 517 495 501 467 462 489 429 482 488 480 500 453 461 460 439 474 475 511 499 476 470 471 456 458 460 414 466 441 452 425 451 470 484 433 446 490 458 425 393 421 455 391 459 419 487 431 465 460 458 433 461 456 470 406 442 452 373 456 432 429 424 418 459 416 416 427 422 455 465 426 428 447 414 404 446 387 448 414 441 380 439 446 437 418 420 419 444 435 458 426 425 447 424 418 469 426 499 503 477 493 516 501 549 523 566 577 609 615 651 652 656 690 584 667 612 610 608 525 525 530 597 561 523 553 532 532 501 506 513 463 496 455 428 440 440 444 429 417 442 442 375 425 408 461 447 440 412 412 436 403 429 419 433 446 443 441 403 426 422 425 429 436 391 437 422 397 411 441 404 411 383 427 431 415 443 391 410 456 413 450 439 426 420 425 407 442 447 406 437 405 433 458 430 459 422 410 409 482 423 471 488 465 438 497 476 522 509 560 593 623 610 704 650 712 781 784 774 839 885 857 833 803 833 799 809 801 721 683 703 727 693 676 637 641 649 632 656 560 552 551 535 500 460 492 434 454 506 469 514 452 477 478 473 466 485 498 478 501 461 499 527 478 510 492 508 489 484 475 468 462 499 482 446 426 489 469 439 507 463 492 497 426 447 431 436 468 462 432 482 439 454 458 516 446 485 485 504 512 501 482 530 485 519 520 498 542 538 582 550 577 644 644 602 691 657 725 731 751 800 905 917 997 1044 1083 1108 1180 1146 1167 1237 1284 1195 1279 1317 1267 1335 1256 1305 1276 1309 1405 1442 1378 1446 1411 1464 1345 1413 1314 1386 1400 1304 1295 1260 1216 1248 1175 1202 1155 1176 1079 1067 1048 1025 974 930 972 879 836 888 838 827 786 751 722 765 673 701 682 648 660 682 669 611 605 644 594 582 603 569 607 564 630 584 636 606 599 612 682 662 676 643 704 753 782 860 883 900 999 975 1008 1056 998 1037 1026 1007 1039 989 954 938 915 951 928 990 920 928 1003 977 967 977 988 878 946 929 922 917 872 883 864 872 885 811 952 850 886 815 787 829 768 812 739 768 729 786 699 705 711 705 696 672 601 617 624 597 559 629 547 570 562 578 546 515 493 528 498 509 469 506 460 517 437 447 466 470 476 451 466 422 488 399 431 447 431 388 468 423 398 426 425 449 450 406 440 433 436 422 396 459 417 427 405 447 453 420 436 422 403 434 379 401 399 400 371 409 385 409 408 393 404 423 420 466 417 431 441 418 432 460 434 477 451 425 441 451 425 495 481 477 446 510 465 535 536 580 523 524 611 589 612 546 583 541 598 530 569 547 523 607 558 583 627 611 615 645 599 671 620 677 615 632 619 610 685 573 614 583 574 581 533 589 619 596 571 564 635 535 598 538 566 520 502 499 542 545 495 505 498 469 474 457 509 430 438 456 467 468 414 430 485 408 460 454 479 442 449 411 459 420 430 425 412 449 444 441 462 418 497 456 516 480 476 478 501 479 503 443 464 471 498 493 531 509 482 508 515 560 592 568 597 565 556 590 600 618 620 592 653 592 655 637 640 633 609 629 650 613 626 628 611 638 631 588 622 551 606 615 642 666 620 608 639 666 665 746 683 755 799 803 787 819 823 870 856 836 801 782 803 726 671 680 636 610 614 619 643 639 651 653 641 594 574 578 502 490 492 462 410 463 427 457 429 428 440 424 436 451 460 416 447 378 400 386 459 431 368 439 385 411 438 427 442 406 392 427 360 448 412 384 382 378 391 390 428 407 401 389 408 398 391 417 406 406 403 410 424 404 392 398 429 400 400 401 406 388 428 422 418 391 439 371 424 426 401 453 440 429 428 441 468 433 440 497 458 470 490 469 484 501 485 521 561 513 515 551 558 518 585 560 567 585 617 590 634 635 705 753 829 858 963 999 1099 1251 1412 1503 1648 1956 2036 2179 2404 2435 2667 2811 2760 2943 2717 2684 2445 2249 2068 1923 1895 1782 1740 1696 1652 1782 1773 1753 1743 1660 1696 1424 1327 1190 1106 960 846 759 727 641 675 643 603 597 536 527 523 567 506 523 469 477 498 454 459 419 438 441 445 421 412 469 393 441 435 437 409 403 439 380 386 422 402 408 389 439 390 431 415 413 415 421 364 402 409 395 370 397 405 406 449 408 401 383 375 398 374 412 383 359 389 384 397 356 384 389 417 391 387 386 379 437 375 384 406 405 390 400 400 407 411 386 387 403 398 428 405 446 421 446 460 461 463 443 473 500 502 541 538 579 618 678 665 690 749 775 780 894 886 920 937 951 1037 939 977 878 848 783 712 745 722 723 678 632 686 734 679 667 691 639 678 586 632 556 564 518 477 519 471 438 482 521 492 432 491 448 476 523 500 561 561 573 604 654 648 679 734 687 683 724 669 710 730 694 652 593 627 517 557 596 567 592 566 611 579 542 568 538 541 546 519 456 431 443 467 453 417 434 459 407 376 428 377 425 404 384 428 394 362 388 393 343 419 387 393 445 403 408 444 412 400 407 407 379 429 435 435 438 445 428 471 422 457 428 466 461 469 449 523 478 479 532 567 521 546 553 569 644 648 725 694 759 841 856 895 862 953 1039 1082 1015 1038 1000 1013 1068 925 998 887 876 917 1028 928 994 1077 1089 1057 1015 1053 1037 1056 1090 1099 1140 1121 1072 1096 1050 1140 1118 1047 1180 1054 1121 1006 1098 1089 1000 1089 1064 1013 1085 1008 992 921 885 929 850 884 883 885 829 756 790 774 737 739 705 742 661 734 601 626 583 615 596 564 553 606 528 573 549 531 507 524 504 503 511 519 530 519 519 476 537 504 448 474 475 510 450 450 475 434 404 500 462 451 516 477 486 485 487 485 487 469 486 505 455 512 481 536 460 567 561 540 544 560 608 573 592 567 591 629 656 597 638 663 725 700 736 778 749 802 760 753 775 810 786 765 775 747 742 648 634 632 647 635 669 665 608 613 593 578 569 555 563 583 574 562 492 498 485 455 498 447 490 454 462 470 461 415 432 451 428 421 441 409 454 460 435 417 428 380 374 387 365 435 408 394 420 423 477 420 424 396 410 408 399 396 421 392 430 458 432 436 454 439 459 443 453 409 437 463 449 487 458 484 431 419 477 441 457 422 401 451 465 452 438 443 459 436 420 447 391 396 399 395 432 409 396 379 418 382 387 433 403 376 388 410 373 392 393 399 388 401 403 408 401 371 401 402 419 455 422 448 453 418 434 450 447 460 491 446 452 429 386 436 387 419 409 435 435 420 422 404 378 393 387 432 429 387 357 366 349 362 327 353 347 370 343 358 353 377 383 345 337 361 331 339 325 332 321 390 379 359 340 360 332 360 344 374 346 384 341 337 329 340 307 376 345 294 335 347 341 346 347 347 337 353 373 349 355 371 349 366 363 328 394 331 377 337 368 335 322 333 345 377 354 331 351 335 350 354 377 383 366 352 326 349 387 342 355 383 332 342 370 366 351 382 394 376 378 366 354 367 372 398 420 394 405 424 435 418 458 492 495 484 573 596 604 573 635 574 596 638 552 573 524 485 491 454 457 458 441 457 534 442 517 470 494 484 514 456 437 450 473 429 379 425 408 382 386 377 338 341 371 362 352 366 402 409 356 344 364 350 377 393 387 332 371 334 384 387 425 376 396 384 375 420 406 427 414 445 477 476 486 513 507 470 492 523 532 504 500 470 500 482 440 473 445 436 443 463 490 417 459 450 456 471 440 428 432 443 456 456 442 434 426 455 409 425 389 404 418 449 421 420 428 422 429 451 487 464 460 469 425 453 464 526 502 470 527 572 540 566 581 661 621 654 691 679 758 738 728 748 797 765 832 791 775 830 813 809 797 827 860 857 889 920 882 891 952 902 955 913 929 880 863 859 836 865 802 871 748 831 826 800 815 745 749 782 766 726 736 776 651 649 637 660 618 677 639 547 581 620 559 571 544 532 505 538 537 498 491 508 485 500 479 496 532 549 536 534 555 533 521 569 599 558 602 590 603 579 523 504 498 536 477 469 480 493 495 508 483 496 523 485 561 487 519 489 484 430 494 443 476 463 452 474 444 415 415 439 444 417 452 483 430 439 451 464 434 453 485 512 467 499 492 488 491 507 517 505 536 502 513 469 515 544 496 509 503 472 494 528 477 490 497 518 518 437 472 472 480 440 496 483 460 458 425 429 426 435 419 440 411 402 398 397 408 398 355 400 364 423 392 409 373 370 399 354 369 365 362 364 359 377 363 366 369 364 343 338 358 372 360 364 315 341 335 304 324 316 381 385 346 334 358 341 326 334 354 339 333 378 321 361 305 332 304 368 298 361 297 291 302 362 320 296 345 353 359 326 346 322 305 325 325 323 326 345 320 313 369 345 346 334 338 306 307 330 350 340 343 326 329 345 315 316 342 322 363 332 346 342 359 366 366 335 314 369 341 360 331 349 345 391 323 345 346 321 353 340 386 362 376 354 349 351 356 328 384 358 411 371 375 380 436 423 403 415 359 423 423 403 407 429 405 432 388 402 404 399 402 405 369 404 415 385 399 394 404 388 383 396 382 424 408 385 376 382 392 419 391 405 370 388 377 377 372 378 365 373 379 365 402 387 379 356 357 368 357 350 348 348 327 358 341 345 348 308 332 358 347 368 332 360 374 345 388 387 370 351 404 358 372 365 410 391 443 396 404 462 522 512 530 548 487 524 495 516 579 537 479 466 520 454 431 374 465 412 433 407 436 370 428 445 434 440 426 453 439 420 408 366 380 369 395 365 372 354 342 379 381 383 355 371 363 379 361 334 359 353 326 327 355 322 324 326 342 345 337 339 346 370 351 319 363 350 321 381 350 353 343 335 349 316 326 345 346 372 359 334 367 361 358 331 333 331 385 316 367 334 360 393 376 350 343 368 372 365 374 367 399 357 357 363 358 373 388 370 386 383 390 383 388 431 423 453 386 400 462 456 523 510 560 549 641 645 656 723 738 771 788 850 847 911 898 907 845 784 772 646 638 633 662 590 613 642 586 639 591 604 605 628 663 581 601 655 619 600 552 543 546 491 465 482 505 415 462 456 418 474 427 455 438 445 439 479 435 463 445 439 434 442 472 486 463 434 489 488 458 503 480 503 517 500 545 561 527 579 573 569 606 585 629 567 597 606 578 591 638 615 635 606 592 623 640 635 604 662 695 628 695 689 623 664 714 665 704 666 635 676 722 655 694 638 637 680 644 619 705 687 655 699 706 710 730 760 764 769 774 804 820 906 830 838 885 881 921 929 941 933 927 956 885 877 847 766 793 762 738 718 770 647 704 753 739 776 740 717 763 700 797 693 742 670 732 696 632 642 634 628 673 593 639 614 612 610 614 587 548 571 609 587 585 581 604 601 621 686 619 627 623 626 624 622 706 652 672 625 716 700 738 786 737 787 758 808 771 761 786 819 850 866 899 877 875 827 895 884 876 860 949 870 894 913 997 974 947 986 1005 939 1034 954 972 994 1016 1052 1029 1048 1010 971 981 987 1030 1017 1021 987 953 996 1024 941 1006 968 960 946 928 964 912 928 929 925 977 930 1011 951 957 916 889 910 892 837 831 781 720 694 669 716 683 703 657 686 603 643 615 620 639 672 643 614 631 566 523 574 534 578 509 539 511 520 497 485 512 458 462 493 533 503 456 520 484 499 503 473 488 474 439 473 484 528 476 486 472 443 513 504 510 490 524 464 508 477 490 479 494 498 482 521 514 480 527 458 453 489 446 466 492 503 493 446 461 461 473 488 491 496 496 428 422 441 445 459 438 433 457 421 387 401 420 430 416 390 361 416 413 414 410 439 468 439 428 435 457 492 512 442 494 519 507 507 523 528 560 547 505 478 489 430 448 408 434 417 414 410 428 407 409 416 434 496 415 398 466 424 416 417 439 403 405 382 374 376 411 387 361 339 351 373 365 347 358 371 378 379 371 355 358 348 306 367 342 354 325 319 361 327 352 340 375 337 304 310 326 349 335 313 332 327 321 306 362 314 347 329 308 316 312 338 325 298 318 325 361 316 365 328 348 370 333 331 315 329 324 369 373 335 348 371 349 349 318 357 312 335 334 357 311 370 372 309 376 341 369 379 331 342 398 396 376 422 408 432 399 459 475 424 445 416 450 419 380 377 378 364 357 361 359 354 379 366 347 353 370 396 384 362 350 387 385 371 387 367 378 348 337 349 315 358 345 355 353 337 354 318 377 343 327 338 364 294 322 364 353 331 319 304 343 337 317 310 328 312 299 303 348 321 305 345 318 331 351 320 308 346 313 315 318 326 346 321 355 350 333 320 348 326 327 330 299 359 316 360 352 355 327 326 338 356 369 362 337 320 334 386 365 371 369 337 357 359 357 363 364 367 426 394 422 448 465 418 491 447 500 597 574 620 633 581 648 649 602 576 565 544 519 493 459 490 459 485 462 510 452 462 483 498 489 532 526 559 529 549 551 605 542 523 546 546 547 509 536 549 558 514 523 519 528 573 559 570 574 500 541 570 550 569 540 598 537 533 559 555 538 498 531 517 505 505 572 536 534 493 504 512 545 580 569 542 497 545 556 567 559 523 614 557 550 519 517 539 564 497 525 505 464 467 483 451 445 497 450 450 422 452 438 495 398 481 480 472 470 502 454 502 497 489 485 491 526 588 561 602 590 649 706 780 771 891 882 837 937 1021 939 893 879 870 737 731 673 658 613 544 550 512 542 507 550 560 582 572 632 587 620 634 686 606 575 648 593 576 509 502 459 469 414 407 376 377 389 362 352 390 360 374 352 358 340 345 334 323 340 341 365 348 323 365 322 348 356 320 287 317 334 320 342 332 338 299 314 311 313 286 318 347 326 339 330 338 330 306 324 308 277 325 349 315 300 314 305 321 324 298 331 314 309 317 311 333 307 324 312 317 335 316 322 324 305 320 301 328 324 283 330 288 323 351 355 345 334 337 342 340 309 392 342 344 332 320 341 324 316 348 333 329 335 327 349 336 334 349 335 352 347 356 384 345 364 334 337 382 355 374 411 360 399 396 348 363 383 362 395 342 362 347 374 371 368 391 366 365 366 368 351 374 358 352 389 365 374 369 378 344 361 343 398 362 347 367 362 336 399 330 375 387 389 362 389 347 384 361 369 373 359 370 380 362 359 376 362 377 350 366 354 343 329 374 351 322 352 389 383 383 394 400 367 402 406 379 370 406 403 397 404 424 445 471 491 529 576 568 584 646 641 702 712 711 781 763 750 707 678 683 623 594 543 479 499 487 435 474 486 463 541 456 532 515 494 561 536 548 549 506 552 549 539 496 462 463 427 421 424 446 371 431 339 374 367 357 368 297 343 338 310 341 310 371 361 335 336 340 359 322 336 307 337 350 335 329 295 326 339 330 318 305 344 329 333 329 355 337 354 333 314 345 323 319 322 327 310 299 322 273 331 304 314 303 321 338 324 331 335 339 347 293 326 305 317 305 297 358 338 311 350 314 331 385 337 332 326 328 342 349 355 381 343 370 366 376 382 396 359 380 395 394 383 366 359 307 343 352 375 325 338 307 324 335 325 381 316 351 341 348 324 391 332 335 319 311 374 355 319 343 316 315 329 326 331 318 354 319 329 313 316 327 346 319 317 311 306 296 300 324 273 325 320 314 322 340 324 330 334 328 351 333 319 354 300 315 321 314 341 352 374 307 346 323 344 315 357 348 344 355 336 390 360 344 368 355 339 339 363 385 375 368 384 369 370 370 380 378 388 396 383 409 410 407 426 431 444 433 440 387 485 441 479 423 458 486 530 553 551 594 563 565 577 537 552 535 559 574 615 534 572 559 562 634 576 594 620 579 682 596 593 624 589 629 614 632 615 607 568 561 581 547 584 560 591 568 544 580 576 506 536 509 531 521 513 539 478 568 478 483 489 485 524 503 487 440 478 451 446 432 430 442 447 447 379 415 387 429 414 393 427 398 403 377 386 370 408 379 382 398 360 434 374 379 388 414 407 358 371 368 412 399 363 395 386 395 356 409 395 402 395 390 398 360 347 421 440 417 404 397 484 485 448 511 447 512 520 549 584 588 568 553 605 586 532 561 511 511 485 481 518 487 468 515 482 516 482 509 480 475 508 561 542 530 520 582 555 561 563 539 576 566 517 516 535 493 495 510 467 506 481 515 460 513 503 499 517 467 498 473 496 507 509 500 479 528 488 506 457 506 463 464 478 460 472 421 444 523 450 451 443 468 456 440 453 403 454 449 403 407 402 400 426 440 425 412 397 402 425 406 373 419 398 356 421 406 391 412 373 366 385 393 384 374 376 375 387 391 404 353 362 402 397 388 431 373 391 369 390 393 411 377 359 389 427 422 408 417 403 440 383 420 406 453 420 408 396 413 435 378 411 414 398 354 393 424 385 390 409 417 397 401 406 432 386 384 381 368 371 380 347 397 367 400 383 358 371 390 410 375 367 369 371 385 345 340 356 413 378 357 358 407 291 344 360 353 355 362 397 322 344 347 375 373 357 338 374 330 335 325 342 280 318 327 364 370 327 371 351 381 355 357 354 362 348 347 389 380 354 376 372 384 330 359 400 331 353 327 324 379 352 368 387 361 399 423 425 434 451 401 478 504 462 505 482 476 456 502 497 470 473 446 401 426 413 411 377 400 416 344 375 383 393 393 348 368 387 346 388 383 411 410 424 408 421 410 390 417 353 425 407 349 310 371 310 356 298 289 340 351 325 321 343 338 344 341 330 308 315 341 329 289 332 295 345 346 344 308 301 326 321 342 306 309 346 293 327 360 356 299 317 288 339 330 300 320 297 297 317 364 320 300 346 315 316 288 295 314 318 347 319 324 322 306 298 347 305 326 291 299 299 343 311 319 333 320 316 301 302 330 308 302 332 291 326 309 314 315 321 306 324 312 312 326 249 316 329 312 281 301 331 294 297 331 289 321 334 307 284 288 344 339 323 335 311 322 308 367 341 394 333 375 361 370 346 390 371 360 396 380 390 385 333 350 336 344 335 355 332 367 309 324 346 358 300 347 320 360 326 354 329 352 381 376 360 331 370 363 343 331 348 329 355 345 335 344 335 339 343 377 356 364 346 331 331 367 348 325 360 336 357 347 385 372 355 337 402 375 388 383 387 419 391 394 399 405 400 435 451 484 472 519 483 537 547 570 587 574 629 617 653 638 614 650 603 621 595 584 563 581 572 518 526 501 516 521 562 540 574 571 633 557 607 577 627 601 603 673 691 616 690 685 685 632 599 615 651 585 656 637 624 642 632 611 577 611 608 567 570 612 569 567 559 621 582 585 595 564 584 560 574 583 571 581 575 563 579 555 532 565 540 541 548 558 511 562 559 509 497 535 534 475 517 500 482 517 489 480 479 506 482 476 501 467 494 449 498 460 484 499 485 528 477 472 502 471 547 499 543 493 606 578 546 594 630 654 658 708 715 800 705 772 772 777 810 758 709 737 640 683 680 664 687 637 562 595 594 519 642 552 623 579 639 614 627 666 680 667 701 682 671 692 691 707 662 698 647 611 582 626 570 600 552 548 548 534 558 504 509 522 469 474 504 474 509 480 490 474 472 459 478 470 501 455 459 441 455 453 425 411 381 459 403 418 429 459 433 444 412 407 415 391 432 415 402 402 428 404 372 368 349 377 391 379 336 385 363 355 386 395 332 370 389 391 366 406 365 370 386 383 378 373 410 445 421 461 429 426 473 438 459 495 475 490 529 506 497 502 520 477 446 448 460 423 406 442 387 433 412 396 385 385 360 395 408 402 387 434 386 399 418 428 438 434 419 399 395 443 430 408 421 408 391 413 404 382 394 409 398 412 355 388 358 372 366 373 369 385 412 381 402 389 346 380 371 370 367 362 396 330 374 327 385 335 341 366 353 347 370 308 345 355 387 363 354 367 326 343 339 304 357 339 377 360 347 335 316 328 329 351 332 388 340 354 353 330 329 314 369 359 356 328 368 364 354 382 349 350 351 412 385 434 384 377 443 408 418 424 471 422 418 428 397 435 394 391 386 361 335 345 333 387 370 342 364 337 335 298 330 334 343 347 353 365 379 397 354 389 387 364 339 385 357 375 391 341 331 351 350 340 322 344 321 355 324 349 291 305 341 356 323 338 310 280 312 346 345 332 309 356 321 346 339 336</counts>
			</dataPoints>
		</scan>
	</xrdMeasurement>
</xrdMeasurements>