File: dataset/precursor_mixture/In2O3_0p5002-MnCO3_0p5000--2min.xrdml
<?xml version="1.0"?>
<xrdMeasurements xmlns="http://www.xrdml.com/XRDMeasurement/2.3" xmlns:xsi="http://www.w3.org/2001/XMLSchema-instance" xsi:schemaLocation="http://www.xrdml.com/XRDMeasurement/2.3 http://www.xrdml.com/XRDMeasurement/2.3/XRDMeasurement.xsd" status="Completed" recordIdentifier="{C7C0D6B3-CF1B-4AD4-9394-007B1FEC52E7}">
	<comment>
		<entry/>
	</comment>
	<sample type="To be analyzed">
		<id>Dara_redo_3-2min_manual</id>
		<name></name>
		<preparedBy></preparedBy>
	</sample>
	<xrdMeasurement measurementType="Scan" status="Completed" sampleMode="Reflection">
		<usedWavelength intended="K-Alpha 1">
			<kAlpha1 unit="Angstrom">1.5405980</kAlpha1>
			<kAlpha2 unit="Angstrom">1.5444260</kAlpha2>
			<kBeta unit="Angstrom">1.3922500</kBeta>
			<ratioKAlpha2KAlpha1>0.5000</ratioKAlpha2KAlpha1>
		</usedWavelength>
		<incidentBeamPath>
			<radius unit="mm">145.00</radius>
			<xRayTube id="1010048" name="Empyrean Cu LFF HR (9430 033 7310x)">
				<tension unit="kV">40.0</tension>
				<current unit="mA">15.0</current>
				<anodeMaterial>Cu</anodeMaterial>
				<focus type="Line">
					<length unit="mm">12.0</length>
					<width unit="mm">0.4</width>
					<takeOffAngle unit="deg">6.0</takeOffAngle>
				</focus>
			</xRayTube>
			<sollerSlit id="21010002" name="Soller slits 0.04 rad.">
				<opening unit="rad">0.0400</opening>
			</sollerSlit>
			<mask id="22031000" name="Fixed mask 13 mm">
				<width unit="mm">9.00</width>
			</mask>
			<divergenceSlit id="22120001" name="Divergence slit 1°" xsi:type="fixedDivergenceSlitType">
				<distanceToSample unit="mm">50.00</distanceToSample>
				<height unit="mm">1.52</height>
			</divergenceSlit>
		</incidentBeamPath>
		<sampleMovement xsi:type="spinningSampleMovementType">
			<spinnerRevolutionTime unit="seconds">1.0</spinnerRevolutionTime>
		</sampleMovement>
		<diffractedBeamPath>
			<radius unit="mm">145.00</radius>
			<antiScatterSlit id="22090040" name="AS slit 9 mm (PIXcel)" xsi:type="fixedAntiScatterSlitType">
				<height unit="mm">9.00</height>
			</antiScatterSlit>
			<sollerSlit id="21020003" name="Large Soller slits 0.04 rad.">
				<opening unit="rad">0.0400</opening>
			</sollerSlit>
			<filter id="20030001" name="Large beta-filter Nickel">
				<material>Ni</material>
				<thickness unit="mm">0.020</thickness>
			</filter>
			<detector id="7010019" name="PIXcel1D-Medipix3 detector" xsi:type="rtmsDetectorType">
				<phd unit="keV">
					<lowerLevel>4.02</lowerLevel>
					<upperLevel>11.27</upperLevel>
				</phd>
				<mode>Scanning</mode>
				<activeLength unit="deg">5.542</activeLength>
			</detector>
		</diffractedBeamPath>
		<scan appendNumber="0" mode="Continuous" scanAxis="Gonio" status="Completed">
			<header>
				<startTimeStamp>2024-11-21T08:15:24-08:00</startTimeStamp>
				<endTimeStamp>2024-11-21T08:17:28-08:00</endTimeStamp>
				<author>
					<name>AutomatedUser</name>
				</author>
				<source>
					<applicationSoftware version="1.7b (136)">PANalytical Aeris Instrument Suite</applicationSoftware>
					<instrumentControlSoftware version="3.2.00000000 20240306">AERIS</instrumentControlSoftware>
					<instrumentID>950485</instrumentID>
				</source>
			</header>
			<dataPoints>
				<positions axis="2Theta" unit="deg">
					<startPosition>10.02173288</startPosition>
					<endPosition>99.99585608</endPosition>
				</positions>
				<positions axis="Omega" unit="deg">
					<startPosition>5.01086644</startPosition>
					<endPosition>49.99792804</endPosition>
				</positions>
				<commonCountingTime unit="seconds">10.965</commonCountingTime>
				<counts unit="counts">2220 2204 2244 2313 2142 2296 2192 2211 2171 2151 2108 2221 2106 2108 2076 2090 2049 2099 2100 2112 2015 2079 2013 1998 1946 1995 1961 1952 1983 1932 1970 2039 1953 1915 1913 1878 1893 1887 1921 1865 1831 1898 1909 1878 1875 1848 1849 1865 1767 1825 1817 1838 1847 1797 1737 1798 1846 1790 1782 1734 1813 1760 1844 1765 1697 1686 1765 1705 1737 1736 1749 1712 1660 1824 1667 1744 1615 1697 1702 1640 1627 1682 1704 1665 1671 1672 1700 1706 1661 1626 1654 1581 1692 1600 1671 1654 1726 1696 1561 1654 1608 1656 1609 1598 1519 1649 1651 1647 1595 1613 1568 1686 1659 1637 1670 1594 1628 1573 1647 1493 1650 1591 1611 1566 1639 1675 1544 1551 1590 1677 1511 1524 1561 1521 1617 1591 1618 1595 1537 1576 1591 1627 1558 1628 1648 1574 1586 1626 1565 1593 1600 1564 1518 1528 1573 1547 1554 1591 1629 1549 1551 1666 1566 1550 1549 1586 1616 1578 1583 1564 1525 1538 1517 1503 1556 1544 1553 1528 1606 1602 1504 1596 1484 1592 1487 1487 1531 1564 1504 1537 1567 1539 1505 1583 1474 1473 1527 1436 1486 1539 1450 1510 1467 1505 1478 1505 1506 1568 1499 1492 1543 1487 1541 1511 1435 1594 1478 1512 1515 1452 1424 1472 1374 1487 1506 1469 1486 1426 1487 1571 1501 1411 1521 1431 1458 1503 1369 1427 1397 1463 1443 1498 1513 1532 1423 1469 1405 1456 1450 1498 1397 1438 1463 1532 1469 1376 1529 1604 1577 1715 1753 1826 2122 2315 2484 2599 2711 2410 2152 1895 1635 1511 1472 1431 1496 1395 1398 1475 1430 1448 1431 1392 1408 1437 1396 1395 1411 1431 1410 1409 1405 1433 1357 1401 1442 1383 1413 1380 1432 1420 1446 1418 1422 1435 1517 1408 1438 1487 1456 1448 1481 1435 1399 1363 1415 1430 1462 1434 1521 1577 1571 1553 1713 1815 1922 2108 2198 2177 2303 2086 2058 1858 1720 1613 1450 1480 1350 1381 1395 1477 1450 1409 1360 1373 1397 1403 1367 1324 1424 1366 1339 1409 1344 1478 1346 1319 1398 1296 1362 1366 1351 1309 1352 1373 1375 1368 1334 1339 1353 1356 1382 1318 1326 1352 1282 1381 1365 1369 1370 1358 1345 1368 1311 1291 1286 1319 1400 1299 1374 1313 1317 1255 1329 1375 1339 1301 1358 1246 1321 1314 1274 1347 1310 1340 1361 1361 1318 1380 1365 1322 1300 1269 1374 1269 1353 1322 1326 1350 1364 1295 1351 1361 1295 1303 1241 1373 1306 1380 1241 1353 1384 1290 1306 1335 1326 1348 1389 1353 1375 1309 1402 1369 1432 1385 1327 1339 1361 1376 1451 1317 1401 1430 1419 1453 1443 1444 1355 1433 1463 1447 1416 1495 1533 1654 1575 1794 1944 2224 2681 3483 5096 7110 9896 12582 14959 15919 15203 11675 7376 4424 2642 2192 1993 2043 2109 2068 2286 2549 3171 3505 4207 4539 4643 4324 3861 3107 2519 2077 1770 1657 1599 1566 1432 1511 1492 1448 1418 1496 1397 1417 1363 1384 1382 1425 1331 1278 1369 1332 1381 1271 1347 1325 1292 1291 1408 1340 1293 1356 1355 1436 1404 1428 1507 1510 1396 1391 1409 1383 1257 1312 1274 1328 1223 1282 1296 1201 1281 1202 1303 1219 1255 1277 1272 1254 1280 1227 1289 1248 1255 1268 1315 1330 1331 1203 1261 1227 1296 1236 1255 1233 1264 1227 1265 1225 1269 1244 1331 1332 1316 1354 1549 1679 1984 2658 3393 4122 5194 5934 5973 4870 3502 2538 1888 1473 1407 1334 1306 1298 1203 1300 1280 1353 1316 1217 1296 1240 1275 1213 1250 1190 1169 1218 1213 1210 1222 1174 1196 1209 1208 1160 1192 1164 1274 1187 1289 1315 1342 1316 1478 1570 1657 1775 1876 1907 1842 1892 1926 2013 2160 2139 1941 1674 1590 1358 1142 1235 1212 1207 1199 1179 1214 1176 1157 1207 1225 1162 1191 1162 1099 1118 1169 1174 1106 1091 1188 1146 1179 1200 1110 1209 1157 1138 1092 1168 1108 1091 1196 1125 1091 1204 1167 1130 1169 1200 1232 1230 1310 1278 1372 1302 1177 1208 1186 1185 1107 1149 1169 1172 1070 1134 1102 1139 1107 1122 1188 1093 1192 1130 1157 1165 1180 1139 1222 1173 1152 1163 1242 1275 1311 1471 1517 1696 1774 1885 1722 1683 1566 1396 1362 1382 1351 1444 1616 1874 1892 1966 1733 1591 1426 1234 1191 1162 1126 1110 1123 1149 1124 1085 1053 1112 1064 1132 1091 1147 979 1082 1076 1112 1133 1130 1098 1075 1132 1076 1081 1057 1068 1141 1111 1058 1107 1088 1094 1112 1130 1140 1148 1268 1299 1267 1265 1187 1124 1166 1103 1065 1112 1079 1127 1088 1126 1142 1092 1169 1067 1118 1153 1089 1050 1077 1121 1214 1144 1230 1357 1360 1567 1688 1729 1742 1682 1529 1480 1325 1264 1282 1239 1286 1426 1572 1684 2206 2468 2562 2309 1999 1782 1462 1195 1146 1128 1061 1158 1072 997 1077 1074 1092 1059 1026 1108 1125 1080 1035 1098 1099 1079 1031 1034 1083 1062 996 1082 1104 1031 1024 1041 1042 1041 1036 1056 1077 1026 1066 988 1063 1090 1044 985 1006 1044 1064 1126 1105 1026 1066 1046 1094 1037 1082 1070 1069 1096 1060 1093 992 1067 1014 1083 1030 1078 1074 1017 1053 1098 1097 1142 1049 1135 1070 1126 1126 1203 1293 1407 1451 1644 1523 1418 1445 1395 1401 1377 1422 1363 1340 1262 1198 1195 1108 1195 1100 1086 1154 1112 1142 1098 1157 1153 1131 1155 1159 1100 1162 1220 1207 1267 1312 1420 1503 1631 2240 2994 4265 5963 7107 7207 6223 4884 4217 3145 2139 1885 1816 1816 1994 2115 2231 2172 2247 2211 2056 1836 1688 1463 1430 1381 1304 1230 1172 1185 1107 1065 1068 1048 1086 1117 1069 1181 1102 1123 1144 1347 1344 1428 1430 1330 1244 1252 1242 1096 1079 1033 1005 1070 1038 1054 1004 1004 1079 1062 1011 1047 1061 1039 1061 1045 1057 1046 1038 1032 1015 967 1052 1075 1055 988 1038 1086 1083 1065 1150 1109 1083 1054 1070 1064 1030 1053 1043 996 1012 1052 1001 1040 1025 982 957 1028 995 1059 1026 1032 1006 1076 1090 1029 985 1037 1019 1068 1056 1002 1105 1122 1144 1191 1430 1681 1802 1807 1684 1514 1489 1404 1200 1107 1112 1049 1024 1053 1007 979 987 989 980 1027 1004 1005 980 1000 992 1029 1019 996 995 1054 989 1049 945 987 996 1040 991 1089 1251 1197 1169 1180 1142 1184 1059 1034 1055 1013 998 993 950 1024 1043 1028 948 1022 1003 1039 980 992 1028 1035 1058 1059 1068 1023 1062 1040 1099 1049 1183 1206 1417 1515 1696 1757 1719 1441 1435 1395 1271 1143 1029 1104 1086 1086 1076 1086 1120 1117 1179 1237 1296 1330 1390 1433 1384 1312 1355 1256 1304 1242 1348 1251 1331 1479 1808 2532 3327 4481 5543 5134 4106 3399 3275 2874 1928 1485 1275 1153 1158 1076 1127 1094 1067 990 1011 1076 1034 1079 1001 1026 1030 942 976 1024 1063 1075 1103 1098 1194 1195 1410 1533 1826 1975 1879 1547 1477 1452 1372 1157 1053 1011 1026 1015 1030 1041 960 1014 983 1018 924 1076 1063 996 993 1071 1078 1146 1114 1075 1070 1150 1181 1227 1371 1545 1745 2012 2090 1749 1600 1637 1543 1339 1171 1128 1084 1117 1079 1069 1036 1020 1078 959 1023 976 1015 1071 1005 985 1007 998 1023 978 990 1051 1009 1010 1150 1184 1217 1385 1335 1233 1282 1292 1229 1089 1022 1093 1050 1032 1001 979 946 1010 987 1059 1009 982 999 1024 1005 1026 995 1045 1113 1011 1066 1065 1048 1156 1076 1237 1257 1190 1241 1132 1140 1114 1070 1055 1006 990 1002 1060 969 1053 1024 954 1031 1086 1173 1190 1162 1174 1170 1213 1152 1190 1130 1136 1097 1165 1130 1200 1299 1391 1506 1304 1248 1192 1259 1128 1049 1026 990 957 971 940 934 948 991 939 943 945 1015 929 943 919 960 997 1026 1025 1031 980 1028 1044 1030 1223 1195 1168 1155 1152 996 1116 1058 1006 995 948 1065 982 927 915 944 1031 959 978 958 955 882 876 960 955 949 950 930 955 950 982 962 980 908 917 910 965 974 883 948 950 949 912 954 881 962 943 926 961 970 973 888 972 972 930 927 985 913 991 1030 1028 1014 999 1027 1111 1064 1033 1043 949 959 969 991 954 1008 909 964 1008 958 947 964 955 943 959 950 986 960 965 980 1007 1038 949 970 947 986 997 1103 1168 1234 1316 1283 1177 1091 1103 1072 1125 1050 1040 995 973 953 965 923 982 1046 1019 983 940 989 933 916 934 908 915 951 1005 991 1117 1190 1236 1451 1511 1400 1253 1229 1189 1239 1153 1057 951 923 935 1014 982 950 971 961 943 964 970 997 1072 1087 1032 1033 1004 1040 959 1081 1082 1169 1363 1523 1456 1339 1245 1232 1279 1197 1172 988 1002 978 967 972 984 961 936 905 984 975 887 905 949 963 964 1000 1049 970 1054 1055 1176 1219 1337 1305 1261 1203 1173 1205 1235 1116 1067 1057 984 1017 969 966 963 978 907 944 976 937 911 941 957 979 983 948 1012 996 1024 1050 1166 1242 1213 1152 1127 1042 1057 1105 1106 1039 1000 971 941 947 963 987 942 986 1042 987 1025 965 950 972 925 979 928 953 969 963 1051 1037 1088 1144 1106 1065 981 1017 1006 1005 1021 975 951 933 937 936 983 956 1006 971 915 948 941 910 904 937 899 960 982 986 1101 1158 1239 1383 1436 1294 1159 1101 1148 1271 1193 1146 1049 973 959 932 931 956 959 936 959 1044 985 962 936 933 951 1011 918 1023 1060 1179 1322 1682 1924 1898 1638 1352 1290 1351 1469 1389 1217 1083 1033 959 964 993 982 947 933 895 946 937 975 958 935 955 951 1020 993 1036 1042 947 994 1038 935 1013 1002 929 971 920 938 1007 869 929 961 1023 942 1023 1042 979 931 935 992 939 991 972 918 1005 1018 1038 1059 1205 1358 1646 1678 1505 1299 1207 1244 1269 1404 1240 1114 1080 1006 949 974 987 986 974 938 952 947 927 952 971 916 915 936 979 955 987 1005 1053 1054 1074 1055 969 996 958 1001 1046 1075 982 943 989 1015 1013 977 955 972 1020 980 1050 1014 1102 1031 1029 1080 1118 1097 1099 1118 1169 1226 1150 1100 1090 1015 1006 1084 1049 1052 1020 950 875 980 1015 899 918 922 953 992 904 899 963 931 967 884 991 902 1104 1065 1114 1273 1299 1351 1224 1073 1044 1044 1102 1130 1098 994 1038 973 992 957 958 992 872 919 942 973 960 966 947 900 948 902 975 953 974 999 944 983 959 1023 881 968 909 918 969 969 968 924 885 894 888 946 955 975 861 978 934 985 959 920 941 996 954 963 1031 1084 1111 1262 1254 1186 1095 994 1055 1056 1130 1117 1039 960 893 916 974 922 914 924 900 921 864 944 866 991 938 943 969 961 904 890 953 860 914 921 903 912 933 920 856 961 901 974 946 955 941 907 900 965 944 935 940 921 935 962 1034 919 963 948 990 961 1030 1135 1221 1297 1164 1016 1033 1023 1037 1085 1066 1117 1020 941 984 931 954 924 933 932 953 948 1022 963 899 896 969 931 997 1004 1106 1188 1416 1571 1532 1355 1144 1079 1126 1166 1299 1326 1195 1079 1084 1027 936 967 952 909 942 947 901 950 948 925 870 900 897 942 1001 1115 1095 1191 1337 1227 1127 1069 989 1021 1079 1021 1082 1055 1012 986 1013 953 945 958 955 914 933 915 953 943 932 969 1003 1045 997 974 1118 1074 1102 1192 1131 1002 1056 979 1001 1033 1016 999 1000 971 960 986 912 946 948 1067 1031 1011</counts>
			</dataPoints>
		</scan>
	</xrdMeasurement>
</xrdMeasurements>