File: dataset/precursor_mixture/In2O3_0p5002-MnCO3_0p5000--8min.xrdml
<?xml version="1.0"?>
<xrdMeasurements xmlns="http://www.xrdml.com/XRDMeasurement/2.3" xmlns:xsi="http://www.w3.org/2001/XMLSchema-instance" xsi:schemaLocation="http://www.xrdml.com/XRDMeasurement/2.3 http://www.xrdml.com/XRDMeasurement/2.3/XRDMeasurement.xsd" status="Completed" recordIdentifier="{030BFD61-7765-42F2-9BE6-A5AD5280C2BB}">
	<comment>
		<entry/>
	</comment>
	<sample type="To be analyzed">
		<id>Dara_redo_3_manual</id>
		<name></name>
		<preparedBy></preparedBy>
	</sample>
	<xrdMeasurement measurementType="Scan" status="Completed" sampleMode="Reflection">
		<usedWavelength intended="K-Alpha 1">
			<kAlpha1 unit="Angstrom">1.5405980</kAlpha1>
			<kAlpha2 unit="Angstrom">1.5444260</kAlpha2>
			<kBeta unit="Angstrom">1.3922500</kBeta>
			<ratioKAlpha2KAlpha1>0.5000</ratioKAlpha2KAlpha1>
		</usedWavelength>
		<incidentBeamPath>
			<radius unit="mm">145.00</radius>
			<xRayTube id="1010048" name="Empyrean Cu LFF HR (9430 033 7310x)">
				<tension unit="kV">40.0</tension>
				<current unit="mA">15.0</current>
				<anodeMaterial>Cu</anodeMaterial>
				<focus type="Line">
					<length unit="mm">12.0</length>
					<width unit="mm">0.4</width>
					<takeOffAngle unit="deg">6.0</takeOffAngle>
				</focus>
			</xRayTube>
			<sollerSlit id="21010002" name="Soller slits 0.04 rad.">
				<opening unit="rad">0.0400</opening>
			</sollerSlit>
			<mask id="22031000" name="Fixed mask 13 mm">
				<width unit="mm">9.00</width>
			</mask>
			<divergenceSlit id="22120001" name="Divergence slit 1°" xsi:type="fixedDivergenceSlitType">
				<distanceToSample unit="mm">50.00</distanceToSample>
				<height unit="mm">1.52</height>
			</divergenceSlit>
		</incidentBeamPath>
		<sampleMovement xsi:type="spinningSampleMovementType">
			<spinnerRevolutionTime unit="seconds">1.0</spinnerRevolutionTime>
		</sampleMovement>
		<diffractedBeamPath>
			<radius unit="mm">145.00</radius>
			<antiScatterSlit id="22090040" name="AS slit 9 mm (PIXcel)" xsi:type="fixedAntiScatterSlitType">
				<height unit="mm">9.00</height>
			</antiScatterSlit>
			<sollerSlit id="21020003" name="Large Soller slits 0.04 rad.">
				<opening unit="rad">0.0400</opening>
			</sollerSlit>
			<filter id="20030001" name="Large beta-filter Nickel">
				<material>Ni</material>
				<thickness unit="mm">0.020</thickness>
			</filter>
			<detector id="7010019" name="PIXcel1D-Medipix3 detector" xsi:type="rtmsDetectorType">
				<phd unit="keV">
					<lowerLevel>4.02</lowerLevel>
					<upperLevel>11.27</upperLevel>
				</phd>
				<mode>Scanning</mode>
				<activeLength unit="deg">5.542</activeLength>
			</detector>
		</diffractedBeamPath>
		<scan appendNumber="0" mode="Continuous" scanAxis="Gonio" status="Completed">
			<header>
				<startTimeStamp>2024-11-21T08:00:38-08:00</startTimeStamp>
				<endTimeStamp>2024-11-21T08:08:45-08:00</endTimeStamp>
				<author>
					<name>AutomatedUser</name>
				</author>
				<source>
					<applicationSoftware version="1.7b (136)">PANalytical Aeris Instrument Suite</applicationSoftware>
					<instrumentControlSoftware version="3.2.00000000 20240306">AERIS</instrumentControlSoftware>
					<instrumentID>950485</instrumentID>
				</source>
			</header>
			<dataPoints>
				<positions axis="2Theta" unit="deg">
					<startPosition>10.00943322</startPosition>
					<endPosition>99.99442286</endPosition>
				</positions>
				<positions axis="Omega" unit="deg">
					<startPosition>5.00471661</startPosition>
					<endPosition>49.99721143</endPosition>
				</positions>
				<commonCountingTime unit="seconds">12.495</commonCountingTime>
				<counts unit="counts">2552 2493 2661 2540 2494 2539 2417 2504 2532 2432 2521 2572 2413 2518 2532 2473 2477 2580 2509 2492 2462 2435 2490 2445 2507 2510 2459 2423 2423 2495 2427 2454 2442 2469 2531 2412 2438 2472 2459 2479 2487 2437 2349 2406 2469 2398 2425 2423 2348 2452 2419 2415 2335 2477 2368 2424 2430 2464 2349 2364 2340 2333 2475 2402 2321 2389 2309 2367 2388 2439 2411 2391 2370 2312 2388 2268 2380 2307 2367 2324 2396 2336 2272 2361 2375 2386 2349 2344 2265 2416 2242 2299 2290 2304 2345 2224 2326 2373 2280 2255 2424 2218 2195 2260 2298 2307 2355 2320 2266 2267 2268 2232 2278 2294 2265 2205 2174 2287 2214 2239 2277 2208 2250 2225 2218 2206 2098 2213 2212 2255 2279 2258 2225 2231 2152 2192 2133 2260 2226 2252 2190 2178 2186 2230 2206 2195 2231 2215 2195 2117 2237 2260 2213 2273 2177 2147 2196 2313 2142 2214 2193 2158 2207 2150 2241 2089 2255 2169 2239 2131 2174 2205 2135 2103 2182 2126 2125 2180 2179 2100 2235 2111 2094 2133 2197 2133 2064 2181 2119 2052 2088 2132 2091 2116 2064 2105 2167 2083 1999 2111 2058 2085 2008 2018 2128 2160 2055 2036 2102 2038 1999 2036 2059 2003 2090 2074 2024 2082 1997 2045 2053 2025 2094 1973 2109 1946 2113 2025 2006 2013 2040 2060 1970 2028 2080 1951 2019 2047 2092 2038 2034 2001 2011 2047 2038 2038 1967 1998 2113 1988 2057 1997 2036 2033 2030 1930 2080 2076 1941 1996 1929 1969 1965 2026 1987 1962 1990 1933 1901 2055 2006 1993 1992 1908 2005 1951 2010 1990 1976 1906 2026 1922 1953 1971 1998 1925 1960 1962 2045 2011 1969 1983 1931 1930 1917 1999 1924 1972 1942 1898 1927 1883 1942 1905 1889 2070 1970 1916 1908 2000 1926 1997 1870 2031 1991 1900 1945 1917 1955 1939 1801 1867 1977 1944 1959 1830 1878 1912 1952 1897 1910 1968 1911 1904 1930 1917 1910 2036 1906 1838 1834 1946 1915 1829 1881 1890 1904 1898 1914 1967 1933 1867 1852 1920 1909 1882 1864 1941 1880 1894 1840 1773 1926 1939 1796 1840 1944 1949 1824 1829 1809 1845 1905 1878 1848 1846 1846 1922 1909 1812 1793 1821 1882 1922 1918 1895 1771 1837 1840 1912 1913 1924 1935 1774 1835 1789 1852 1780 1857 1942 1979 1931 1963 1930 1897 1817 1898 1825 1812 1779 1805 1873 1840 1824 1739 1885 1890 1817 1894 1844 1894 1920 1847 1888 1905 1865 1802 1763 1910 1919 1808 1812 1891 1800 1854 1964 1748 1913 1735 1885 1840 1849 1868 1785 1880 1852 1816 1834 1832 1816 1826 1808 1825 1803 1937 1887 1900 1864 1867 1856 1848 1795 1866 1883 1834 1800 1839 1805 1782 1797 1854 1850 1836 1857 1839 1795 1798 1875 1779 1896 1808 1858 1846 1800 1816 1873 1821 1838 1784 1811 1849 1854 1865 1755 1840 1781 1810 1781 1862 1895 1815 1832 1837 1829 1867 1844 1841 1812 1784 1929 1882 1819 1834 1778 1882 1838 1849 1766 1850 1854 1831 1918 1802 1815 1825 1910 1875 1823 1795 1895 1830 1769 1756 1845 1775 1819 1802 1857 1793 1801 1849 1754 1824 1772 1787 1846 1809 1700 1774 1901 1859 1818 1819 1805 1857 1817 1807 1769 1834 1821 1792 1847 1806 1865 1791 1772 1778 1800 1832 1834 1769 1799 1849 1778 1764 1791 1788 1818 1777 1870 1871 1826 1769 1845 1848 1803 1821 1785 1929 1782 1762 1804 1860 1844 1776 1813 1743 1723 1838 1794 1849 1769 1750 1756 1769 1853 1776 1741 1754 1790 1772 1757 1796 1803 1795 1798 1730 1754 1812 1767 1841 1817 1791 1787 1774 1782 1801 1707 1821 1808 1839 1760 1786 1767 1770 1801 1837 1759 1733 1767 1769 1811 1677 1821 1775 1786 1820 1717 1778 1840 1847 1765 1802 1830 1788 1787 1867 1865 1802 1850 1798 1797 1742 1798 1708 1775 1727 1829 1764 1795 1731 1774 1715 1853 1836 1854 1765 1697 1843 1794 1881 1878 1833 1815 1732 1758 1798 1790 1746 1801 1819 1797 1818 1769 1819 1789 1735 1768 1751 1725 1758 1788 1787 1777 1795 1807 1822 1797 1744 1827 1716 1694 1784 1788 1779 1718 1790 1791 1798 1793 1824 1732 1703 1731 1729 1768 1789 1760 1764 1785 1767 1796 1739 1719 1750 1796 1741 1778 1799 1811 1756 1787 1738 1743 1670 1798 1693 1717 1791 1745 1727 1782 1812 1716 1741 1851 1764 1648 1773 1717 1720 1793 1659 1751 1745 1708 1694 1769 1775 1724 1823 1710 1775 1737 1682 1693 1711 1732 1760 1736 1694 1716 1739 1723 1752 1702 1747 1756 1695 1679 1720 1674 1729 1732 1728 1632 1782 1735 1813 1712 1709 1684 1785 1718 1682 1701 1710 1756 1692 1732 1712 1692 1664 1824 1686 1749 1693 1711 1705 1738 1714 1797 1629 1768 1650 1748 1756 1656 1691 1665 1776 1681 1665 1769 1729 1730 1705 1702 1726 1648 1687 1715 1715 1632 1670 1690 1743 1707 1793 1657 1669 1808 1732 1672 1705 1729 1733 1752 1754 1662 1773 1745 1721 1712 1714 1711 1747 1656 1691 1740 1674 1704 1666 1721 1692 1655 1696 1664 1732 1625 1690 1694 1671 1604 1676 1671 1772 1642 1732 1651 1644 1753 1667 1734 1755 1622 1637 1640 1727 1608 1700 1746 1695 1746 1687 1748 1661 1707 1731 1656 1646 1620 1648 1603 1610 1769 1739 1687 1699 1676 1662 1659 1674 1683 1668 1746 1731 1689 1676 1678 1674 1673 1679 1691 1744 1715 1769 1690 1678 1693 1583 1701 1712 1662 1639 1590 1674 1615 1627 1732 1615 1585 1654 1633 1618 1665 1680 1642 1645 1705 1677 1694 1669 1697 1597 1711 1643 1622 1705 1656 1621 1767 1720 1655 1720 1648 1685 1631 1671 1681 1630 1620 1634 1729 1702 1717 1633 1653 1628 1729 1681 1683 1587 1710 1740 1657 1653 1684 1722 1678 1679 1603 1688 1661 1653 1630 1682 1622 1730 1726 1661 1743 1707 1731 1694 1679 1718 1700 1757 1680 1660 1721 1744 1629 1667 1739 1734 1739 1728 1745 1714 1739 1794 1780 1823 1877 1828 1868 1849 1915 2002 2023 2049 2171 2169 2191 2278 2342 2325 2441 2504 2583 2535 2645 2622 2787 2753 2853 2754 2917 2942 3004 3022 2864 2999 3072 2931 2880 2882 2835 2760 2744 2551 2521 2342 2220 2116 2033 1952 1915 1838 1863 1717 1747 1657 1685 1611 1665 1759 1718 1686 1661 1633 1634 1718 1633 1617 1729 1620 1684 1694 1683 1649 1680 1685 1678 1579 1634 1580 1648 1640 1687 1703 1649 1629 1636 1618 1658 1686 1663 1665 1750 1662 1678 1590 1670 1596 1675 1692 1727 1657 1539 1602 1643 1629 1691 1680 1713 1613 1708 1638 1592 1598 1627 1653 1622 1640 1624 1722 1631 1636 1696 1658 1581 1622 1649 1635 1623 1641 1604 1684 1568 1657 1617 1734 1589 1665 1556 1634 1603 1687 1582 1609 1605 1560 1673 1678 1664 1633 1659 1570 1660 1568 1570 1709 1598 1569 1658 1600 1606 1655 1695 1656 1622 1586 1619 1532 1688 1631 1606 1597 1574 1592 1658 1610 1584 1542 1652 1638 1693 1582 1600 1627 1650 1646 1681 1613 1616 1581 1666 1724 1675 1624 1625 1648 1664 1592 1672 1568 1586 1621 1700 1560 1645 1682 1679 1603 1595 1682 1612 1629 1599 1597 1651 1561 1629 1605 1627 1727 1661 1606 1572 1684 1599 1711 1657 1680 1681 1638 1613 1721 1685 1661 1650 1617 1664 1651 1699 1722 1745 1683 1761 1605 1655 1660 1660 1735 1710 1708 1681 1704 1804 1715 1847 1815 1780 1806 1833 1942 1999 1971 1931 2036 2034 2044 2183 2135 2259 2281 2270 2339 2316 2435 2385 2454 2418 2444 2520 2560 2520 2513 2581 2517 2536 2509 2490 2489 2507 2258 2414 2365 2259 2237 2275 2213 2080 1984 2024 1963 1949 1881 1875 1744 1725 1712 1764 1698 1807 1706 1689 1657 1651 1694 1660 1682 1658 1649 1575 1677 1621 1636 1640 1603 1647 1550 1657 1594 1667 1584 1632 1612 1642 1653 1597 1617 1540 1558 1624 1644 1596 1621 1621 1602 1552 1503 1596 1610 1625 1609 1525 1583 1629 1547 1608 1533 1594 1582 1579 1532 1584 1619 1551 1618 1536 1588 1588 1625 1612 1577 1539 1606 1615 1603 1621 1623 1613 1645 1527 1596 1559 1598 1619 1509 1637 1480 1596 1535 1529 1569 1574 1471 1584 1625 1614 1470 1609 1535 1583 1511 1621 1548 1580 1510 1593 1538 1504 1604 1609 1516 1504 1530 1537 1509 1606 1515 1585 1563 1475 1546 1609 1532 1537 1551 1437 1468 1561 1556 1496 1565 1541 1502 1509 1541 1542 1555 1541 1585 1555 1573 1525 1507 1525 1580 1496 1548 1496 1604 1590 1584 1606 1529 1485 1510 1508 1495 1587 1500 1502 1511 1535 1533 1558 1524 1493 1569 1596 1560 1564 1517 1546 1580 1514 1468 1526 1522 1568 1500 1507 1536 1489 1508 1527 1552 1539 1497 1528 1479 1562 1521 1588 1530 1497 1505 1498 1567 1464 1479 1525 1541 1522 1498 1498 1474 1559 1562 1551 1569 1507 1511 1493 1480 1527 1487 1518 1544 1493 1550 1530 1547 1488 1523 1487 1526 1535 1422 1583 1548 1517 1499 1587 1508 1495 1536 1610 1477 1549 1451 1411 1459 1571 1484 1498 1539 1477 1530 1498 1532 1462 1500 1492 1531 1589 1552 1500 1463 1441 1466 1535 1470 1454 1530 1558 1526 1513 1512 1505 1545 1535 1514 1580 1536 1450 1462 1574 1519 1586 1528 1564 1484 1580 1571 1494 1525 1473 1567 1517 1502 1444 1507 1562 1580 1487 1576 1474 1582 1557 1547 1517 1567 1545 1538 1567 1490 1516 1464 1480 1558 1519 1510 1475 1463 1537 1443 1511 1456 1486 1507 1505 1467 1487 1473 1524 1476 1535 1489 1534 1529 1413 1490 1479 1525 1508 1538 1532 1539 1468 1505 1489 1435 1454 1489 1496 1531 1446 1529 1498 1546 1573 1532 1503 1470 1495 1522 1488 1535 1484 1438 1481 1487 1375 1491 1397 1519 1439 1478 1465 1538 1465 1524 1431 1511 1478 1494 1460 1453 1479 1463 1517 1482 1453 1455 1525 1533 1442 1494 1499 1532 1535 1529 1530 1562 1459 1452 1516 1529 1550 1494 1428 1435 1427 1516 1514 1480 1537 1448 1440 1551 1472 1390 1554 1481 1538 1518 1424 1462 1479 1485 1513 1469 1451 1495 1515 1502 1481 1487 1514 1542 1469 1434 1490 1507 1508 1482 1476 1460 1538 1561 1454 1500 1539 1488 1501 1513 1511 1525 1479 1500 1472 1518 1454 1503 1478 1528 1513 1503 1539 1462 1489 1480 1527 1564 1534 1608 1490 1511 1500 1549 1540 1622 1548 1539 1593 1575 1547 1654 1600 1595 1542 1583 1619 1568 1541 1643 1611 1590 1645 1639 1663 1632 1563 1633 1636 1593 1583 1563 1637 1655 1661 1581 1707 1646 1684 1559 1647 1710 1688 1655 1691 1659 1703 1726 1635 1760 1661 1725 1768 1697 1694 1704 1781 1760 1773 1843 1857 1800 1812 1833 1926 1873 1931 1964 2022 2000 2035 2084 2232 2242 2273 2434 2512 2669 2650 2987 2975 3397 3409 3688 4027 4510 4878 5182 5688 6284 6605 7416 8074 8858 9536 10358 11134 11886 12550 13377 14319 14938 15357 15969 16572 17123 17954 18019 18184 18230 18311 17954 17172 16820 15735 14910 13573 12233 10981 9476 8553 7375 6420 5849 4995 4449 3772 3214 2981 2801 2535 2512 2411 2296 2392 2313 2301 2144 2225 2256 2308 2219 2205 2261 2332 2356 2299 2248 2280 2491 2427 2579 2612 2684 2777 2898 2947 3120 2997 3368 3386 3561 3630 3837 3989 4004 4386 4483 4666 4609 4791 5000 5026 4976 5141 5102 5147 5023 5034 5188 4879 4870 4677 4482 4258 4107 3916 3716 3564 3347 3147 2936 2909 2642 2568 2465 2351 2233 2186 2139 1991 2072 1976 1978 1912 1893 1753 1844 1761 1762 1764 1745 1689 1762 1683 1640 1642 1721 1666 1628 1699 1757 1636 1517 1635 1563 1603 1659 1591 1544 1729 1548 1645 1632 1641 1655 1568 1560 1612 1531 1572 1537 1631 1541 1524 1523 1524 1600 1506 1500 1489 1579 1539 1618 1543 1503 1515 1537 1468 1527 1516 1525 1538 1530 1514 1590 1522 1512 1453 1544 1527 1572 1454 1509 1511 1519 1512 1448 1490 1504 1441 1635 1436 1508 1503 1530 1556 1517 1538 1465 1460 1452 1475 1529 1493 1457 1518 1527 1473 1453 1492 1493 1484 1464 1492 1465 1463 1490 1458 1441 1464 1507 1444 1545 1532 1469 1494 1521 1503 1568 1468 1505 1525 1492 1506 1573 1549 1553 1634 1664 1583 1596 1639 1654 1579 1673 1632 1651 1621 1744 1639 1673 1671 1695 1640 1615 1638 1597 1645 1615 1525 1581 1577 1530 1447 1465 1546 1466 1530 1470 1498 1467 1470 1480 1493 1475 1434 1456 1402 1454 1443 1461 1413 1443 1436 1428 1411 1407 1450 1423 1413 1439 1483 1449 1459 1448 1450 1385 1406 1431 1444 1448 1445 1456 1445 1404 1478 1451 1373 1430 1423 1425 1403 1446 1408 1416 1419 1386 1493 1428 1430 1403 1368 1405 1447 1455 1375 1438 1286 1401 1391 1379 1471 1446 1407 1456 1360 1401 1407 1448 1453 1437 1419 1510 1445 1428 1448 1487 1474 1454 1398 1436 1361 1485 1376 1407 1438 1472 1440 1440 1430 1409 1514 1472 1429 1484 1455 1441 1495 1411 1364 1383 1474 1419 1424 1475 1418 1457 1448 1377 1501 1456 1412 1362 1364 1398 1457 1342 1415 1399 1417 1419 1445 1476 1430 1421 1516 1475 1401 1443 1486 1450 1500 1362 1497 1397 1376 1477 1482 1404 1436 1419 1447 1548 1455 1443 1465 1507 1524 1507 1456 1503 1492 1487 1566 1565 1528 1412 1497 1537 1532 1506 1615 1493 1534 1531 1567 1634 1736 1678 1748 1833 1958 1954 2053 2232 2291 2349 2498 2772 2856 3093 3333 3529 3738 4012 4201 4539 4765 4981 5272 5498 5902 6084 6210 6571 6645 6566 6826 6597 6668 6454 6261 6008 5663 5364 4873 4346 4051 3619 3518 3180 2992 2757 2374 2177 1991 1812 1716 1725 1650 1597 1673 1626 1542 1633 1608 1541 1528 1522 1535 1490 1491 1451 1466 1478 1467 1445 1474 1446 1456 1512 1423 1476 1458 1501 1457 1451 1498 1421 1471 1419 1477 1423 1388 1398 1454 1435 1402 1372 1365 1432 1398 1384 1404 1398 1368 1489 1401 1426 1359 1375 1372 1411 1382 1437 1443 1326 1421 1389 1387 1402 1419 1397 1397 1406 1395 1416 1309 1451 1364 1368 1377 1298 1358 1328 1332 1361 1347 1377 1380 1260 1324 1407 1370 1392 1316 1355 1430 1392 1368 1303 1402 1381 1365 1326 1380 1365 1348 1396 1266 1428 1362 1375 1417 1376 1337 1347 1408 1410 1359 1390 1402 1394 1369 1391 1425 1503 1375 1389 1416 1418 1422 1372 1413 1408 1501 1416 1460 1385 1430 1473 1462 1465 1548 1535 1544 1605 1596 1524 1603 1644 1702 1657 1714 1741 1783 1797 1882 1894 1877 2044 1971 1957 2022 2041 2029 2068 2197 2157 2214 2143 2174 2152 2148 2067 2119 2227 2184 2111 2185 2206 2227 2342 2188 2278 2272 2305 2362 2426 2402 2459 2435 2464 2510 2449 2439 2306 2209 2192 2151 2124 1996 1851 1919 1814 1740 1717 1637 1595 1549 1519 1459 1463 1409 1345 1396 1354 1383 1388 1400 1416 1447 1363 1409 1372 1419 1362 1351 1318 1300 1254 1350 1279 1270 1389 1344 1311 1334 1331 1375 1311 1406 1304 1405 1313 1293 1373 1283 1336 1320 1307 1262 1365 1327 1326 1325 1320 1297 1340 1340 1325 1315 1253 1307 1317 1287 1415 1300 1282 1331 1314 1298 1319 1352 1366 1348 1357 1335 1286 1252 1246 1285 1346 1275 1323 1260 1292 1263 1273 1254 1382 1276 1323 1343 1312 1300 1231 1319 1266 1277 1372 1228 1338 1283 1288 1302 1262 1322 1384 1362 1283 1288 1304 1287 1315 1334 1333 1289 1316 1302 1362 1269 1287 1344 1264 1297 1344 1296 1274 1318 1270 1224 1273 1294 1281 1242 1312 1295 1297 1247 1287 1298 1272 1279 1361 1263 1270 1270 1240 1317 1289 1295 1317 1273 1365 1251 1267 1244 1295 1274 1306 1297 1367 1333 1292 1306 1300 1301 1324 1412 1289 1360 1327 1305 1410 1346 1381 1377 1440 1388 1419 1497 1442 1447 1462 1475 1501 1533 1520 1441 1471 1555 1507 1440 1418 1434 1424 1411 1442 1399 1372 1424 1302 1374 1351 1332 1248 1245 1327 1231 1360 1275 1251 1245 1238 1248 1330 1261 1324 1277 1297 1336 1266 1236 1275 1303 1295 1298 1214 1259 1242 1305 1301 1330 1227 1234 1259 1266 1238 1295 1296 1337 1274 1246 1270 1281 1275 1280 1297 1294 1250 1302 1332 1270 1271 1269 1216 1236 1234 1305 1287 1287 1262 1183 1225 1338 1271 1270 1200 1306 1324 1251 1336 1336 1295 1255 1357 1309 1344 1316 1340 1346 1287 1312 1311 1372 1317 1340 1292 1342 1304 1409 1340 1308 1294 1330 1356 1303 1434 1377 1385 1341 1438 1461 1535 1472 1546 1528 1526 1593 1499 1594 1710 1671 1768 1796 1740 1796 1807 1866 1919 1935 1948 1954 2021 2057 2175 2167 2095 2063 1978 1915 2062 2071 2000 1895 1842 1884 1857 1757 1848 1773 1683 1635 1642 1544 1604 1591 1630 1567 1531 1574 1570 1546 1538 1550 1600 1588 1655 1638 1576 1650 1702 1776 1741 1825 1895 2026 1998 2061 2075 2140 2062 2185 2104 2198 2245 2173 2142 2058 2077 2080 1928 1842 1773 1672 1763 1645 1606 1590 1503 1534 1430 1382 1406 1346 1397 1353 1290 1281 1305 1279 1248 1258 1315 1281 1312 1313 1290 1274 1265 1371 1265 1275 1244 1216 1249 1273 1315 1255 1236 1232 1223 1205 1227 1261 1225 1242 1161 1207 1210 1248 1261 1248 1241 1237 1212 1246 1223 1256 1246 1227 1242 1180 1169 1217 1233 1306 1235 1243 1250 1184 1220 1320 1219 1206 1218 1132 1256 1280 1257 1218 1222 1250 1182 1197 1251 1196 1275 1268 1233 1177 1217 1279 1177 1208 1186 1203 1197 1188 1210 1191 1223 1245 1198 1278 1168 1259 1144 1217 1190 1232 1205 1224 1261 1298 1208 1265 1257 1234 1176 1221 1251 1158 1211 1210 1258 1230 1223 1223 1225 1267 1279 1248 1208 1194 1238 1170 1238 1182 1177 1260 1199 1274 1247 1294 1137 1222 1248 1225 1206 1320 1310 1353 1250 1273 1267 1217 1259 1266 1269 1298 1321 1333 1341 1335 1384 1343 1410 1340 1411 1428 1420 1431 1416 1419 1386 1336 1483 1389 1382 1371 1305 1323 1355 1318 1352 1313 1318 1293 1295 1298 1305 1232 1274 1263 1250 1255 1308 1183 1244 1288 1225 1231 1223 1209 1280 1264 1226 1187 1243 1247 1233 1233 1208 1313 1255 1301 1276 1265 1282 1247 1262 1268 1190 1248 1277 1226 1292 1250 1254 1267 1256 1276 1270 1196 1327 1298 1192 1235 1289 1216 1257 1246 1280 1279 1281 1256 1313 1238 1333 1302 1323 1297 1269 1309 1338 1256 1313 1279 1350 1341 1381 1354 1305 1371 1363 1337 1375 1366 1400 1424 1490 1458 1553 1581 1494 1613 1625 1772 1736 1713 1768 1769 1806 1880 1919 1872 1941 1964 1999 1966 2036 2008 1918 1996 1965 2000 1898 1899 1918 1833 1773 1682 1723 1720 1659 1602 1588 1553 1539 1583 1496 1501 1522 1485 1440 1486 1465 1428 1415 1381 1394 1470 1442 1475 1478 1431 1524 1612 1562 1658 1780 1722 1857 1852 1993 2053 2133 2198 2290 2363 2438 2670 2802 2787 2878 2973 2954 2886 2969 2872 2855 2803 2632 2465 2352 2325 2158 2113 2036 2035 1896 1833 1830 1612 1633 1596 1513 1467 1331 1330 1295 1321 1350 1290 1299 1262 1257 1258 1272 1287 1229 1301 1269 1279 1259 1190 1178 1250 1245 1238 1246 1266 1152 1218 1216 1262 1210 1261 1309 1245 1254 1264 1198 1324 1239 1149 1227 1233 1193 1156 1215 1201 1207 1257 1196 1215 1183 1241 1203 1217 1111 1175 1228 1200 1223 1205 1274 1235 1219 1220 1259 1238 1164 1160 1222 1215 1262 1153 1212 1242 1222 1247 1192 1170 1180 1206 1206 1196 1190 1124 1241 1207 1223 1199 1243 1195 1228 1231 1182 1178 1197 1249 1185 1165 1101 1212 1154 1162 1203 1154 1194 1251 1235 1217 1251 1226 1152 1189 1224 1171 1238 1196 1223 1217 1208 1217 1186 1272 1166 1170 1256 1232 1223 1187 1140 1269 1229 1206 1145 1179 1152 1201 1252 1157 1184 1146 1226 1225 1205 1224 1185 1202 1209 1184 1182 1197 1180 1187 1141 1172 1230 1238 1207 1132 1167 1190 1256 1178 1155 1244 1225 1152 1157 1175 1225 1205 1151 1251 1186 1206 1206 1183 1204 1173 1188 1211 1198 1209 1192 1182 1213 1222 1231 1177 1269 1258 1215 1104 1180 1158 1236 1190 1236 1160 1178 1153 1232 1218 1145 1136 1190 1201 1166 1164 1152 1178 1142 1200 1184 1206 1134 1149 1191 1214 1171 1159 1237 1261 1141 1179 1200 1196 1199 1196 1214 1239 1229 1205 1233 1192 1221 1186 1259 1084 1177 1209 1227 1143 1202 1181 1249 1181 1191 1201 1267 1203 1147 1216 1295 1217 1217 1227 1174 1134 1249 1178 1220 1170 1175 1163 1187 1143 1224 1236 1179 1194 1170 1252 1250 1205 1225 1195 1209 1194 1205 1277 1293 1236 1272 1294 1272 1221 1224 1303 1314 1232 1273 1256 1335 1277 1326 1292 1364 1359 1349 1416 1458 1376 1434 1552 1536 1621 1587 1647 1705 1782 1661 1803 1846 1725 1766 1810 1722 1731 1695 1672 1746 1678 1631 1621 1713 1603 1719 1582 1658 1652 1633 1600 1566 1577 1589 1586 1578 1582 1585 1601 1558 1492 1510 1581 1556 1488 1495 1520 1505 1447 1429 1481 1486 1498 1407 1401 1439 1366 1423 1417 1357 1333 1249 1324 1277 1270 1274 1306 1271 1337 1235 1308 1245 1244 1269 1287 1298 1287 1301 1326 1288 1287 1322 1228 1229 1237 1263 1183 1316 1263 1246 1260 1276 1192 1268 1262 1280 1248 1272 1309 1223 1253 1246 1309 1244 1320 1292 1301 1332 1324 1259 1319 1295 1243 1267 1321 1286 1350 1301 1369 1348 1352 1332 1363 1364 1349 1361 1384 1333 1389 1430 1424 1371 1411 1442 1450 1468 1448 1484 1418 1555 1554 1687 1591 1721 1690 1730 1833 1938 2022 2174 2138 2399 2469 2876 2914 3102 3415 3734 4054 4293 4782 5150 5511 6028 6410 6739 7313 7782 8222 8332 8625 8570 8577 8328 7907 7567 6965 6582 6056 5636 5422 5164 5034 5023 4917 4503 4315 4029 3666 3301 3027 2651 2490 2308 2150 2019 1980 1985 2004 2128 1989 2047 1997 2125 2104 2050 2211 2190 2250 2284 2389 2323 2363 2375 2480 2472 2434 2526 2526 2526 2598 2515 2549 2523 2581 2607 2392 2571 2549 2502 2383 2375 2328 2277 2282 2202 2141 2126 2074 2024 2021 1975 1910 1774 1823 1759 1657 1726 1603 1589 1523 1550 1494 1461 1401 1474 1389 1436 1389 1322 1383 1339 1382 1330 1296 1380 1260 1313 1286 1326 1337 1340 1323 1304 1272 1228 1300 1296 1273 1229 1333 1311 1207 1291 1240 1217 1299 1229 1283 1302 1291 1253 1190 1230 1213 1207 1250 1265 1212 1215 1254 1269 1285 1239 1294 1240 1281 1257 1317 1311 1315 1329 1383 1375 1377 1377 1368 1413 1551 1476 1521 1551 1640 1593 1681 1620 1637 1650 1603 1573 1612 1515 1485 1439 1550 1430 1454 1387 1414 1395 1487 1398 1342 1324 1339 1329 1258 1194 1272 1302 1252 1185 1280 1267 1218 1182 1191 1178 1206 1216 1277 1181 1193 1214 1189 1265 1127 1147 1225 1156 1154 1190 1155 1234 1216 1170 1146 1186 1220 1152 1203 1169 1163 1173 1210 1121 1148 1188 1204 1177 1219 1161 1133 1207 1150 1144 1214 1168 1140 1146 1169 1115 1120 1172 1172 1177 1113 1172 1142 1224 1140 1204 1205 1188 1194 1151 1191 1173 1141 1159 1189 1193 1211 1098 1173 1151 1167 1166 1155 1160 1179 1113 1228 1142 1201 1177 1136 1162 1201 1194 1168 1211 1198 1188 1215 1211 1157 1172 1208 1065 1110 1154 1224 1261 1224 1252 1176 1246 1158 1183 1200 1177 1187 1190 1162 1147 1142 1218 1202 1233 1220 1258 1286 1294 1275 1230 1265 1279 1232 1298 1265 1219 1290 1220 1247 1240 1277 1197 1218 1253 1201 1200 1221 1200 1181 1180 1144 1187 1203 1211 1166 1173 1129 1112 1142 1114 1130 1148 1217 1184 1157 1192 1130 1193 1138 1140 1170 1131 1206 1171 1117 1169 1180 1203 1216 1187 1195 1124 1139 1158 1155 1119 1164 1108 1194 1264 1173 1184 1139 1177 1138 1189 1152 1217 1226 1165 1200 1169 1137 1188 1110 1185 1074 1201 1209 1139 1146 1145 1163 1128 1133 1139 1171 1176 1195 1192 1159 1230 1194 1216 1137 1185 1128 1149 1179 1159 1227 1188 1144 1175 1179 1189 1148 1152 1212 1133 1223 1160 1223 1199 1175 1146 1189 1235 1182 1205 1187 1170 1202 1228 1214 1234 1242 1296 1294 1314 1336 1267 1263 1319 1314 1389 1465 1460 1516 1537 1626 1623 1758 1757 1819 1850 2033 2138 2063 2093 2082 2166 2112 1999 2071 2078 1972 1827 1737 1735 1665 1675 1636 1595 1589 1677 1636 1603 1592 1458 1467 1317 1308 1340 1269 1235 1283 1219 1270 1189 1205 1167 1163 1188 1204 1132 1131 1237 1150 1108 1137 1129 1156 1127 1151 1189 1240 1183 1193 1175 1197 1196 1137 1142 1105 1167 1114 1155 1115 1197 1171 1178 1123 1118 1201 1122 1155 1126 1131 1099 1145 1123 1204 1152 1173 1147 1107 1122 1043 1139 1124 1152 1199 1113 1119 1143 1136 1200 1159 1145 1151 1112 1156 1186 1189 1211 1193 1157 1173 1151 1138 1189 1234 1163 1168 1162 1062 1107 1141 1163 1139 1145 1156 1113 1143 1130 1085 1131 1180 1158 1135 1123 1150 1246 1179 1173 1216 1151 1151 1159 1231 1144 1182 1215 1211 1224 1240 1247 1210 1268 1265 1347 1312 1361 1358 1385 1414 1409 1344 1328 1370 1329 1363 1281 1299 1302 1236 1295 1357 1268 1203 1223 1240 1226 1203 1198 1226 1211 1185 1185 1161 1177 1182 1192 1165 1177 1168 1102 1180 1166 1192 1088 1147 1138 1146 1224 1126 1190 1155 1212 1148 1179 1146 1170 1088 1097 1149 1143 1130 1165 1056 1115 1093 1165 1136 1188 1112 1116 1073 1180 1125 1163 1089 1162 1158 1136 1107 1154 1183 1212 1165 1093 1134 1182 1165 1140 1139 1128 1135 1209 1202 1190 1148 1146 1166 1196 1190 1155 1157 1227 1161 1184 1156 1166 1196 1201 1193 1210 1222 1188 1187 1219 1239 1182 1163 1190 1194 1264 1331 1246 1248 1258 1260 1299 1268 1250 1276 1218 1243 1286 1296 1339 1408 1337 1465 1463 1446 1509 1512 1518 1569 1600 1713 1719 1838 1863 1937 1943 2016 2063 2099 1988 2080 2048 1917 1837 1794 1664 1668 1677 1591 1682 1641 1557 1585 1587 1510 1532 1458 1469 1419 1332 1363 1349 1347 1233 1309 1267 1264 1293 1303 1264 1271 1177 1261 1219 1252 1233 1247 1187 1283 1214 1285 1230 1263 1171 1256 1209 1239 1230 1270 1271 1228 1250 1276 1309 1267 1330 1382 1322 1337 1393 1395 1368 1457 1422 1434 1531 1519 1474 1473 1477 1547 1553 1554 1592 1560 1589 1645 1658 1536 1599 1538 1576 1636 1473 1569 1530 1453 1525 1549 1481 1511 1521 1466 1466 1365 1427 1492 1504 1451 1412 1396 1411 1412 1492 1382 1430 1423 1490 1487 1461 1449 1419 1446 1524 1528 1672 1638 1715 1775 1775 1900 2029 2103 2252 2409 2637 2700 2971 3096 3526 3620 3965 4385 4544 5070 5308 5726 5766 6212 6259 6265 6219 5878 5713 5212 4859 4424 4299 3993 3842 3981 3825 3811 3793 3781 3745 3577 3425 3321 3072 2790 2502 2215 1999 1946 1782 1660 1556 1525 1402 1431 1424 1349 1311 1296 1381 1302 1333 1260 1227 1293 1294 1286 1285 1190 1264 1231 1181 1234 1231 1153 1246 1263 1177 1186 1149 1252 1187 1182 1187 1139 1229 1142 1232 1150 1163 1145 1106 1193 1190 1196 1145 1225 1216 1127 1175 1162 1152 1112 1186 1155 1184 1196 1207 1171 1157 1197 1238 1090 1177 1112 1162 1220 1170 1177 1182 1231 1164 1142 1165 1177 1149 1171 1178 1112 1219 1231 1132 1236 1165 1148 1215 1228 1210 1221 1286 1249 1230 1220 1281 1332 1326 1352 1347 1411 1507 1455 1601 1654 1676 1695 1799 1809 1960 1955 2098 2142 2140 2221 2230 2170 2161 2027 2088 1912 1818 1776 1720 1702 1711 1671 1574 1708 1709 1665 1611 1699 1616 1527 1540 1441 1428 1364 1213 1304 1267 1258 1262 1264 1207 1145 1190 1178 1186 1206 1164 1154 1195 1098 1162 1144 1140 1139 1165 1213 1193 1138 1191 1122 1165 1168 1112 1190 1144 1175 1150 1181 1174 1206 1139 1195 1171 1162 1128 1135 1103 1108 1141 1137 1156 1229 1214 1176 1173 1086 1211 1106 1123 1183 1184 1168 1137 1093 1119 1154 1248 1152 1085 1209 1174 1148 1160 1184 1242 1195 1216 1202 1255 1259 1247 1248 1182 1212 1325 1302 1297 1246 1300 1286 1265 1229 1242 1358 1240 1260 1304 1394 1409 1361 1422 1489 1518 1561 1560 1666 1767 1782 1772 1864 1979 2063 2098 2197 2214 2318 2363 2341 2314 2396 2315 2165 2128 2085 1933 1855 1894 1922 1874 1845 1788 1880 1956 1840 1871 1831 1704 1702 1574 1569 1461 1461 1460 1357 1305 1306 1378 1296 1271 1207 1261 1258 1264 1285 1238 1236 1205 1177 1149 1222 1236 1157 1221 1200 1071 1169 1146 1190 1172 1157 1188 1142 1155 1148 1175 1124 1191 1162 1113 1120 1138 1192 1139 1122 1176 1120 1197 1144 1119 1134 1145 1141 1142 1103 1156 1066 1154 1173 1133 1152 1139 1170 1080 1110 1154 1165 1154 1159 1123 1192 1142 1168 1105 1131 1183 1168 1148 1185 1193 1195 1182 1171 1112 1150 1157 1161 1157 1126 1141 1199 1210 1226 1181 1175 1200 1263 1218 1304 1201 1242 1225 1273 1402 1282 1419 1386 1417 1437 1461 1522 1539 1546 1542 1567 1503 1524 1532 1488 1472 1404 1374 1355 1422 1346 1495 1373 1359 1379 1375 1433 1367 1407 1413 1345 1337 1355 1360 1260 1241 1270 1279 1204 1242 1226 1187 1219 1194 1262 1184 1213 1174 1223 1176 1156 1156 1220 1200 1188 1165 1138 1151 1193 1107 1115 1137 1110 1117 1169 1135 1146 1104 1133 1204 1092 1107 1175 1117 1140 1158 1201 1081 1194 1153 1179 1112 1179 1119 1111 1196 1132 1125 1177 1164 1126 1125 1197 1161 1167 1184 1173 1125 1200 1204 1191 1183 1176 1220 1191 1218 1250 1217 1223 1169 1193 1248 1184 1224 1126 1228 1211 1165 1246 1158 1145 1224 1250 1265 1200 1213 1295 1232 1279 1201 1292 1274 1236 1381 1310 1330 1358 1279 1339 1335 1376 1387 1451 1465 1417 1387 1387 1306 1347 1291 1279 1292 1211 1254 1235 1298 1262 1264 1245 1239 1263 1244 1253 1245 1277 1277 1155 1192 1117 1135 1140 1139 1066 1194 1128 1119 1088 1174 1114 1140 1148 1207 1152 1178 1164 1120 1150 1128 1149 1115 1135 1154 1186 1166 1114 1181 1233 1189 1188 1149 1156 1176 1162 1155 1174 1151 1142 1233 1162 1263 1274 1250 1240 1264 1297 1313 1202 1392 1347 1327 1293 1401 1312 1403 1397 1385 1440 1389 1388 1376 1333 1396 1357 1356 1474 1456 1357 1360 1391 1312 1297 1365 1310 1334 1321 1361 1238 1285 1310 1227 1263 1242 1253 1295 1298 1244 1279 1276 1413 1229 1344 1258 1289 1289 1426 1372 1412 1417 1485 1532 1535 1588 1708 1677 1699 1625 1678 1611 1622 1663 1549 1522 1496 1422 1493 1405 1417 1397 1398 1390 1435 1448 1425 1344 1415 1399 1419 1254 1339 1265 1240 1187 1201 1180 1101 1103 1157 1086 1138 1123 1075 1132 1089 1161 1101 1114 1124 1094 1124 1082 1167 1028 1147 1103 1096 1137 1088 1120 1099 1177 1147 1092 1145 1123 1098 1071 1114 1157 1096 1059 1102 1135 1089 1071 1105 1096 1043 1047 1083 1100 1087 1103 1068 1040 1155 1116 1123 1052 1082 1111 1081 1130 1147 1045 1079 1137 1176 1057 1131 1107 1098 1164 1126 1070 1088 1126 1103 1084 1202 1123 1129 1124 1093 1120 1141 1131 1192 1122 1062 1128 1150 1167 1129 1216 1181 1252 1208 1211 1299 1240 1307 1357 1311 1316 1390 1374 1396 1435 1402 1389 1362 1410 1294 1245 1328 1264 1283 1263 1183 1201 1302 1220 1218 1222 1288 1194 1218 1232 1215 1218 1143 1125 1154 1112 1101 1028 1080 1186 1063 1118 1098 1081 1134 1186 1120 1064 1029 1120 1126 1122 1086 1091 1133 1074 1033 1112 1064 1127 1088 1107 1037 1089 1101 1123 1099 1090 1119 1085 1103 1128 1036 1106 1109 1098 1088 1101 1051 1118 1125 1053 1109 1099 1077 1060 1152 1068 1093 1088 1046 1046 1060 1075 1095 1047 1136 1014 1060 1167 1085 1134 1086 1009 1093 1120 1068 1022 1049 1173 1078 1094 1041 1058 1069 1028 1066 1115 996 1046 1066 1035 1039 1060 1110 1059 1067 1117 1123 1088 1104 1076 1079 1070 1108 1097 1117 1084 1064 1061 1100 1147 1101 1047 1083 1090 1026 1056 1010 1089 1066 1066 1051 1110 1096 1107 1057 1064 1073 1078 1080 1118 1073 1074 1075 1056 1096 1097 1095 1078 1090 1058 1130 1055 1076 1105 1103 1148 1118 1047 1121 1049 1097 1090 1071 1076 1099 1134 1154 1081 1023 1069 1091 1054 1080 1075 1111 1082 1030 1056 1054 1076 1128 1156 1082 1111 1055 1100 1070 1054 1117 1117 1101 1032 1077 1112 1069 1094 1052 1031 1083 1060 1066 1056 1067 1064 1118 1095 1054 1054 1094 1060 1093 1110 1115 1049 1128 1091 1145 1042 1095 1065 1167 1105 1101 1144 1096 1103 1133 1102 1152 1169 1210 1138 1161 1161 1215 1138 1210 1190 1186 1174 1175 1224 1132 1139 1166 1125 1140 1161 1138 1093 1152 1196 1107 1174 1119 1184 1112 1154 1135 1161 1158 1084 1075 1154 1096 1131 1090 1032 1064 1106 1048 1118 1101 1070 1033 1078 1140 1067 1107 1086 1125 1092 1109 1066 1068 1040 1120 1042 1093 1120 1059 1065 1038 1062 1068 1084 1039 1037 1083 1068 1069 1113 1076 1169 1091 1099 1076 1045 1068 1070 1128 1076 1055 1078 1076 1101 1118 1100 1095 1046 1090 1138 1066 1113 1110 1104 1088 1073 1118 1104 1066 1098 1116 1055 1054 1112 1064 1075 1086 1064 1063 1132 1112 1074 1105 1050 1070 1154 1120 1092 1155 1111 1137 1163 1161 1190 1115 1220 1223 1288 1241 1234 1206 1254 1308 1365 1249 1383 1422 1368 1466 1505 1526 1575 1440 1554 1408 1475 1342 1361 1326 1280 1279 1233 1287 1258 1287 1259 1274 1321 1283 1295 1299 1343 1310 1319 1295 1222 1249 1145 1126 1182 1148 1181 1132 1173 1137 1072 1090 1062 1088 1187 1047 1106 1115 1073 1061 1132 1151 1204 1132 1037 1119 1100 1106 1062 1105 1143 1114 1176 1020 1096 1134 1092 1093 1055 1046 1102 1093 1109 1072 1109 1085 1112 1091 1081 1081 1151 1091 1027 1136 1110 1098 1056 1091 1081 1121 1180 1103 1093 1116 1076 1163 1142 1111 1143 1098 1053 1090 1104 1079 1112 1108 1183 1122 1138 1118 1128 1121 1199 1163 1145 1158 1194 1201 1183 1318 1339 1292 1402 1373 1435 1475 1505 1545 1572 1683 1688 1682 1740 1660 1691 1715 1557 1681 1510 1561 1421 1395 1419 1358 1355 1330 1395 1428 1383 1413 1428 1378 1344 1403 1410 1370 1405 1341 1273 1273 1216 1210 1258 1159 1175 1123 1148 1143 1172 1169 1088 1160 1108 1121 1143 1038 1168 1039 1113 1061 1097 1086 1153 1183 1115 1081 1119 1100 1060 1069 1099 1043 1144 1078 1089 1076 1113 1160 1128 1116 1153 1097 1261 1135 1135 1161 1116 1175 1176 1152 1132 1094 1156 1115 1139 1175 1140 1162 1192 1172 1141 1105 1159 1113 1170 1170 1183 1155 1166 1160 1158 1178 1183 1106 1115 1147 1201 1186 1204 1210 1165 1209 1198 1194 1235 1308 1274 1284 1350 1417 1469 1405 1455 1559 1637 1648 1702 1711 1730 1744 1575 1637 1667 1640 1533 1554 1442 1384 1387 1339 1328 1344 1411 1313 1318 1361 1347 1421 1420 1451 1417 1395 1404 1369 1292 1355 1266 1228 1202 1214 1109 1237 1159 1097 1141 1150 1082 1096 1051 1130 1094 1097 1127 1056 1090 1075 1072 1099 1080 1084 1033 1094 1043 1091 1074 1112 1071 1076 1084 1075 1102 1148 1102 1080 1081 1129 1092 1055 1152 1125 1163 1138 1059 1128 1102 1051 1079 1077 1071 1118 1064 1064 1138 1126 1127 1064 1144 1131 1152 1090 1174 1101 1141 1126 1148 1074 1082 1196 1131 1122 1125 1199 1077 1156 1176 1165 1152 1195 1172 1262 1244 1311 1314 1324 1305 1288 1404 1371 1369 1559 1566 1572 1430 1593 1551 1596 1535 1578 1508 1434 1406 1496 1364 1332 1298 1341 1354 1302 1344 1362 1390 1343 1394 1334 1357 1403 1329 1425 1345 1282 1262 1284 1259 1256 1191 1227 1189 1194 1168 1193 1170 1107 1167 1120 1116 1135 1111 1118 1172 1117 1088 1063 1118 1104 1097 1099 1048 1080 1079 1107 1104 1110 1113 1047 1099 1066 1069 1114 1069 1098 1094 1082 1058 1026 1082 1137 1042 1108 1001 1115 1174 1090 1154 1088 1107 1090 1067 1099 1083 1113 1078 1093 1099 1127 1118 1109 1075 1109 1079 1113 1150 1117 1129 1098 1088 1058 1099 1069 1167 1091 1053 1092 1132 1129 1184 1101 1186 1220 1252 1286 1212 1266 1346 1383 1354 1374 1410 1477 1517 1386 1390 1416 1392 1348 1288 1284 1270 1262 1268 1163 1193 1263 1218 1249 1228 1208 1255 1234 1263 1252 1236 1256 1253 1208 1225 1171 1164 1190 1200 1140 1167 1171 1127 1100 1110 1099 1092 1095 1105 1058 1154 1112 1128 1127 1150 1106 1134 1124 1056 1104 1155 1122 1116 1132 1131 1174 1090 1059 1078 1156 1093 1077 1147 1088 1091 1154 1138 1091 1049 1031 1054 1037 1123 1140 1077 1124 1099 1096 1167 1079 1021 1138 1128 1085 1031 1072 1159 1134 1046 1099 1148 1129 1105 1068 1140 1132 1054 1084 1123 1086 1060 1040 1114 1100 1132 1146 1127 1193 1138 1131 1141 1154 1229 1155 1203 1243 1256 1225 1236 1288 1318 1328 1312 1265 1330 1358 1216 1263 1237 1265 1140 1188 1178 1133 1199 1146 1185 1141 1154 1134 1137 1188 1186 1153 1204 1189 1198 1159 1174 1158 1170 1193 1160 1171 1103 1067 1108 1080 1045 1107 1093 1029 1048 1098 1036 1107 1080 1047 1112 1089 1048 1103 1088 1082 1065 1097 1053 1107 1104 1088 1088 1049 1108 1047 1017 1092 1108 1073 1051 1072 1110 1064 1054 1076 1051 1117 1023 1052 1099 1039 1091 1086 1140 1054 1088 1045 1065 1034 1133 1083 1046 1067 1123 1166 1128 1101 1093 1125 1118 1092 1146 1058 1066 1063 1107 1090 1135 1168 1178 1231 1198 1160 1202 1252 1226 1273 1316 1411 1390 1403 1483 1504 1497 1594 1665 1685 1632 1641 1570 1641 1508 1494 1494 1383 1360 1351 1296 1313 1353 1208 1328 1241 1273 1260 1276 1347 1309 1353 1358 1387 1277 1319 1283 1287 1328 1285 1256 1220 1201 1158 1169 1156 1148 1148 1105 1094 1075 1071 1107 1126 1038 1146 1122 1100 1048 1021 1144 1067 1077 1058 1123 1105 1098 1057 1033 998 1086 1119 1111 1077 1071 1122 1107 1076 1041 1091 1038 1108 1111 1100 1090 1069 1088 1055 1060 1085 1061 1146 1068 1072 1171 1135 1100 1110 1107 1140 1123 1158 1138 1039 1142 1109 1172 1098 1139 1164 1143 1207 1251 1247 1185 1221 1179 1259 1298 1339 1411 1452 1537 1527 1651 1770 1746 1764 1950 1994 2196 2193 2230 2235 2326 2211 2216 2163 1958 1856 1762 1681 1601 1611 1562 1539 1474 1517 1483 1527 1525 1538 1600 1565 1675 1657 1698 1697 1694 1676 1554 1509 1494 1426 1441 1389 1258 1243 1307 1200 1181 1196 1133 1159 1084 1141 1098 1126 1082 1139 1095 1085 1081 1104 1102 1124 1056 1094 1066 1123 1073 1132 1007 1093 1079 1082 1163 1023 1031 1091 1102 1084 1112 1106 1099 1046 1070 1119 1098 1094 1083 1080 1061 1102 1115 1108 1127 1032 1131 1107 1072 1131 1099 1127 1138 1124 1125 1120 1098 1099 1066 1169 1178 1071 1118 1087 1139 1139 1121 1147 1119 1048 1163 1076 1198 1080 1191 1202 1148 1098 1134 1151 1142 1168 1107 1142 1123 1161 1217 1132 1137 1091 1173 1092 1035 1051 1098 1082 1053 1090 1121 1101 1109 1069 1108 1098 1135 1075 1116 1075 1093 1101 1082 1204 1100 1108 1109 1129 1106 1145 1142 1110 1092 1136 1133 1082 1046 1100 1124 1132 1137 1061 1058 1106 1117 1062 1077 1066 1098 1157 1084 1101 1008 1099 1079 1143 1065 1119 1114 1118 1127 1089 1082 1087 1100 1048 1042 1043 1121 1119 1114 1058 1035 1059 1095 1065 1136 1165 1078 1101 1140 1084 1099 1103 1079 1105 1101 1114 1132 1098 1119 1092 1097 1126 1160 1157 1099 1127 1179 1185 1270 1297 1274 1282 1262 1290 1284 1350 1443 1528 1475 1550 1630 1737 1706 1838 1815 1891 1927 1908 1937 1918 1865 1769 1748 1661 1602 1485 1454 1349 1398 1321 1436 1360 1334 1365 1379 1361 1441 1490 1472 1466 1557 1530 1508 1549 1526 1455 1349 1341 1312 1329 1187 1182 1203 1166 1150 1121 1137 1133 1153 1119 1083 1162 1098 1073 1100 1105 1043 1064 1069 1125 1108 1110 1113 1139 1126 1108 1107 1072 1077 1017 1068 1077 1057 1147 1096 1131 1066 1039 1101 1078 992 1088 1117 1018 1091 1008 1104 1034 1066 1110 1056 1088 1147 1083 1091 1101 1057 1064 1100 1112 1090 1041 1074 1066 1067 1068 1063 1032 1055 1197 1061 1052 1086 1118 1123 1086 1117 1149 1100 1096 1141 1200 1117 1238 1153 1216 1316 1203 1185 1315 1275 1189 1240 1163 1192 1151 1104 1111 1127 1124 1103 1133 1107 1073 1086 1152 1140 1124 1135 1137 1102 1116 1154 1150 1143 1202 1143 1119 1175 1168 1124 1142 1078 1093 1103 1099 1106 1101 1110 1135 1103 1070 1117 1056 1125 1087 1127 1132 1138 1131 1131 1118 1167 1184 1104 1107 1125 1132 1201 1099 1181 1096 1144 1159 1164 1130 1162 1189 1187 1231 1141 1150 1174 1196 1142 1178 1188 1151 1228 1211 1237 1119 1204 1234 1174 1260 1195 1225 1254 1187 1253 1261 1296 1303 1276 1191 1212 1279 1240 1256 1182 1260 1241 1198 1259 1235 1233 1300 1276 1280 1247 1286 1271 1249 1274 1270 1278 1313 1285 1422 1320 1347 1363 1354 1295 1375 1279 1254 1330 1281 1235 1186 1187 1168 1207 1258 1134 1221 1187 1191 1165 1230 1174 1218 1181 1206 1205 1169 1236 1193 1116 1230 1164 1144 1144 1045 1102 1122 1069 1152 1122 1094 1115 1072 1069 1103 1044 1074 1163 1105 1098 1127 1122 1130 1080 1098 1094 1132 1092 1119 1039 1082 1121 1141 1140 1103 1057 1077 1023 1099 1042 1106 1079 1063 1129 1114 1086 1043 1124 1027 1089 1115 1056 1097 1050 1057 1093 1088 1107 1026 1071 1125 1137 1093 1107 1093 1144 1055 1047 1129 1127 1175 1162 1158 1152 1182 1152 1191 1139 1222 1230 1246 1238 1282 1322 1356 1373 1405 1375 1516 1492 1483 1532 1494 1529 1465 1512 1488 1463 1455 1352 1327 1319 1292 1308 1263 1209 1275 1242 1175 1257 1222 1268 1298 1220 1288 1329 1304 1315 1318 1293 1334 1292 1302 1225 1217 1193 1215 1212 1196 1046 1192 1112 1102 1101 1029 1131 1088 1051 1155 1139 1131 1094 1041 1091 1102 1077 1102 1085 1077 1085 1065 1057 1087 1072 1089 1057 1082 1097 1045 1118 1066 1125 1031 1088 1059 1079 1036 1092 1080 1095 1049 1054 1062 1104 1087 1055 1097 1077 1118 1075 1061 1085 1081 1063 1057 1082 1066 1055 1064 1036 1064 1085 1095 1066 1095 1074 1128 1039 1093 1069 1025 1073 1021 1143 1104 1081 1081 1039 1079 1070 1094 1066 1049 1113 1128 1144 1092 1066 1080 1066 1134 1068 1090 1058 1138 1080 1054 1050 1086 1075 1015 1050 1021 1101 1055 1099 1030 1072 1082 1059 1075 1055 1014 1078 1034 1110 1086 1091 1113 1101 1042 1063 1059 1081 1069 980 1075 1074 1070 1018 1037 1014 1061 1012 999 1110 1036 1089 1058 1039 1036 1023 1085 1028 1018 1123 1139 1040 1055 1020 1043 1070 1077 1028 1027 1103 1023 1055 1070 993 1086 1062 1075 1049 1081 1031 1087 1084 1021 1037 1059 1080 1108 1057 1043 1039 1060 1114 1101 1060 1099 1092 1124 1037 1168 1107 1088 1110 1087 1118 1129 1078 1204 1186 1189 1200 1200 1239 1316 1307 1299 1324 1371 1414 1398 1449 1467 1462 1471 1520 1446 1401 1375 1309 1272 1241 1270 1145 1232 1166 1227 1165 1197 1188 1138 1218 1152 1179 1175 1213 1295 1276 1246 1231 1241 1292 1278 1283 1224 1250 1200 1163 1216 1154 1141 1099 1155 1077 1053 1029 1096 1093 1079 1081 1045 1075 1122 1042 1027 1038 1054 1056 1066 1080 1069 1054 1094 1078 1058 1028 1038 1066 1046 1140 992 1094 1035 1105 1020 1079 1021 1061 1082 1032 1067 1079 1049 1020 1034 1023 1085 1130 1069 1035 1077 979 1027 1065 999 1115 1050 1068 1051 957 1040 1034 1065 1078 1009 1054 1104 1084 1064 1107 1056 1017 1095 974 1076 1048 1051 1051 1049 996 1051 1059 1036 1028 1069 1087 1031 1107 1014 1072 1065 1069 1030 1033 1033 1052 1059 1078 1094 1059 1009 987 1090 1030 1044 1006 1047 961 1008 1081 1087 1072 1059 1058 1069 1044 1077 1097 1056 1087 1122 1020 1055 1016 1036 1054 1055 1065 1059 1040 1043 1079 1048 1082 1038 1017 1083 1042 1025 1084 1066 1108 1096 1042 1049 1058 1015 1116 1063 1058 1065 1097 1068 1017 1050 1028 1115 1045 1066 1044 1041 1070 1092 1049 1056 1057 1036 1081 1085 1084 982 1022 1104 1028 1104 1119 1088 1076 1106 1076 1101 1111 1115 1047 1082 1059 1126 1082 1075 1097 1151 1114 1146 1151 1172 1186 1224 1234 1269 1255 1277 1348 1328 1370 1418 1403 1407 1426 1475 1381 1347 1350 1381 1368 1330 1311 1204 1166 1232 1161 1194 1224 1218 1149 1221 1125 1237 1157 1137 1177 1177 1225 1229 1206 1236 1264 1260 1326 1183 1187 1196 1181 1229 1173 1150 1119 1167 1122 1157 1086 1077 1070 1057 1099 1107 1109 1011 1026 980 1115 1068 1033 1078 1009 1079 1063 1094 1067 1031 1024 1058 1097 1069 1080 1051 1039 1050 1092 1030 1098 1060 1143 1080 1073 1055 1110 1045 1103 1091 1060 1027 1117 1044 1065 1083 1091 1048 1096 1153 1149 1122 1025 1122 1095 1149 1085 1129 1101 1098 1129 1154 1162 1163 1184 1244 1243 1258 1298 1339 1345 1386 1406 1503 1509 1531 1601 1730 1737 1753 1759 1843 1789 1849 1820 1673 1677 1509 1508 1422 1370 1340 1380 1312 1263 1291 1266 1196 1325 1262 1266 1303 1302 1329 1322 1456 1351 1399 1448 1459 1410 1565 1486 1464 1431 1365 1353 1248 1299 1251 1152 1216 1188 1153 1170 1162 1147 1090 1073 1067 1119 1121 1073 1105 1119 1015 1073 1065 1078 1065 1106 1089 1063 1070 1021 1090 1024 1032 1069 1073 1092 1043 1084 1056 1018 1060 1075 1033 1072 1108 1106 1080 1092 1122 1088 1092 1090 1086 1065 1076 1120 1118 1086 1111 1090 1063 1061 1079 1040 1091 1017 1089 1036 1126 1119 1167 1147 1133 1184 1132 1180 1185 1172 1239 1206 1257 1295 1316 1301 1375 1390 1423 1461 1458 1446 1504 1504 1433 1385 1400 1358 1247 1244 1266 1277 1165 1182 1181 1137 1183 1149 1204 1160 1183 1173 1190 1193 1181 1255 1255 1246 1239 1279 1271 1284 1299 1298 1271 1181 1231 1266 1130 1138 1119 1188 1143 1149 1118 1082 1117 1097 1055 1069 1023 1078 1089 1081 1090 1070 1096 1021 1018 1009 1073 1065 1094 1019 1009 1046 1051 1012 1123 1065 1076 1086 1116 1109 1058 1082 1039 1123 1058 1078 1072 1056 1076 1070 1118 995 1073 1062 1122 1105 1102 1098 1102 1042 1041 1102 1108 1085 1048 1057 1096 1057 1078 1044 1129 1087 1039 1104 1051 1169 1147 1147 1155 1203 1132 1178 1187 1186 1194 1229 1258 1334 1311 1312 1327 1307 1382 1364 1308 1350 1185 1222 1213 1196 1164 1125 1142 1146 1202 1102 1160 1085 1111 1111 1171 1148 1119 1189 1158 1168 1156 1188 1184 1217 1238 1206 1237 1209 1120 1154 1177 1128 1119 1166 1114 1127 1146 1050 1071 1086 1122 1082 1090 1033 1104 1116 1078 1130 1091 1167 1004 1088 1075 1080 1065 1112 1064 1081 1087 1115 1092 1143 1117 1105 1060 1083 1090</counts>
			</dataPoints>
		</scan>
	</xrdMeasurement>
</xrdMeasurements>