File: dataset/precursor_mixture/In2O3_0p3022-La(OH)3_0p5014-TiO2_0p2004--2min.xrdml
<?xml version="1.0"?>
<xrdMeasurements xmlns="http://www.xrdml.com/XRDMeasurement/2.3" xmlns:xsi="http://www.w3.org/2001/XMLSchema-instance" xsi:schemaLocation="http://www.xrdml.com/XRDMeasurement/2.3 http://www.xrdml.com/XRDMeasurement/2.3/XRDMeasurement.xsd" status="Completed" recordIdentifier="{C762148C-4523-4314-818F-8CC6A504A518}">
	<comment>
		<entry/>
	</comment>
	<sample type="To be analyzed">
		<id>In2O3_0p3022-La(OH)3_0p5014-TiO2_0p2004--2min</id>
		<name></name>
		<preparedBy></preparedBy>
	</sample>
	<xrdMeasurement measurementType="Scan" status="Completed" sampleMode="Reflection">
		<usedWavelength intended="K-Alpha 1">
			<kAlpha1 unit="Angstrom">1.5405980</kAlpha1>
			<kAlpha2 unit="Angstrom">1.5444260</kAlpha2>
			<kBeta unit="Angstrom">1.3922500</kBeta>
			<ratioKAlpha2KAlpha1>0.5000</ratioKAlpha2KAlpha1>
		</usedWavelength>
		<incidentBeamPath>
			<radius unit="mm">145.00</radius>
			<xRayTube id="1010048" name="Empyrean Cu LFF HR (9430 033 7310x)">
				<tension unit="kV">40.0</tension>
				<current unit="mA">15.0</current>
				<anodeMaterial>Cu</anodeMaterial>
				<focus type="Line">
					<length unit="mm">12.0</length>
					<width unit="mm">0.4</width>
					<takeOffAngle unit="deg">6.0</takeOffAngle>
				</focus>
			</xRayTube>
			<sollerSlit id="21010002" name="Soller slits 0.04 rad.">
				<opening unit="rad">0.0400</opening>
			</sollerSlit>
			<mask id="22031000" name="Fixed mask 13 mm">
				<width unit="mm">9.00</width>
			</mask>
			<divergenceSlit id="22120001" name="Divergence slit 1°" xsi:type="fixedDivergenceSlitType">
				<distanceToSample unit="mm">50.00</distanceToSample>
				<height unit="mm">1.52</height>
			</divergenceSlit>
		</incidentBeamPath>
		<sampleMovement xsi:type="spinningSampleMovementType">
			<spinnerRevolutionTime unit="seconds">1.0</spinnerRevolutionTime>
		</sampleMovement>
		<diffractedBeamPath>
			<radius unit="mm">145.00</radius>
			<antiScatterSlit id="22090040" name="AS slit 9 mm (PIXcel)" xsi:type="fixedAntiScatterSlitType">
				<height unit="mm">9.00</height>
			</antiScatterSlit>
			<sollerSlit id="21020003" name="Large Soller slits 0.04 rad.">
				<opening unit="rad">0.0400</opening>
			</sollerSlit>
			<filter id="20030001" name="Large beta-filter Nickel">
				<material>Ni</material>
				<thickness unit="mm">0.020</thickness>
			</filter>
			<detector id="7010019" name="PIXcel1D-Medipix3 detector" xsi:type="rtmsDetectorType">
				<phd unit="keV">
					<lowerLevel>4.02</lowerLevel>
					<upperLevel>11.27</upperLevel>
				</phd>
				<mode>Scanning</mode>
				<activeLength unit="deg">5.542</activeLength>
			</detector>
		</diffractedBeamPath>
		<scan appendNumber="0" mode="Continuous" scanAxis="Gonio" status="Completed">
			<header>
				<startTimeStamp>2024-11-14T14:54:56-08:00</startTimeStamp>
				<endTimeStamp>2024-11-14T14:57:00-08:00</endTimeStamp>
				<author>
					<name>AutomatedUser</name>
				</author>
				<source>
					<applicationSoftware version="1.7b (136)">PANalytical Aeris Instrument Suite</applicationSoftware>
					<instrumentControlSoftware version="3.2.00000000 20240306">AERIS</instrumentControlSoftware>
					<instrumentID>950485</instrumentID>
				</source>
			</header>
			<dataPoints>
				<positions axis="2Theta" unit="deg">
					<startPosition>10.02173288</startPosition>
					<endPosition>99.99585608</endPosition>
				</positions>
				<positions axis="Omega" unit="deg">
					<startPosition>5.01086644</startPosition>
					<endPosition>49.99792804</endPosition>
				</positions>
				<commonCountingTime unit="seconds">10.965</commonCountingTime>
				<counts unit="counts">1991 2061 1996 1995 1977 1904 1941 1986 1972 1917 1978 1909 1858 1847 1838 1900 1783 1804 1728 1813 1816 1763 1818 1764 1724 1807 1793 1727 1795 1832 1733 1710 1706 1719 1688 1630 1683 1645 1659 1610 1653 1669 1615 1580 1661 1555 1617 1530 1487 1563 1508 1568 1566 1560 1583 1539 1463 1498 1480 1506 1474 1488 1464 1458 1461 1393 1429 1436 1481 1370 1419 1434 1384 1391 1440 1425 1455 1413 1362 1394 1347 1316 1351 1369 1412 1400 1362 1339 1338 1332 1334 1326 1315 1387 1240 1380 1315 1306 1392 1377 1340 1393 1330 1366 1304 1248 1330 1310 1303 1320 1257 1331 1295 1303 1275 1305 1288 1362 1318 1340 1440 1386 1447 1576 1670 1736 1959 2181 2404 2799 3238 3568 4144 4379 4499 4300 3631 2938 2299 1992 1696 1514 1516 1446 1357 1290 1241 1280 1323 1262 1238 1256 1257 1191 1198 1238 1219 1230 1164 1182 1192 1165 1188 1227 1166 1146 1150 1147 1149 1083 1164 1100 1188 1130 1139 1118 1157 1100 1090 1109 1092 1143 1071 1054 1079 1124 1053 1082 1078 1049 1114 1088 1028 1101 1036 1059 1051 1092 1059 1094 1045 1030 1039 1121 1089 1062 1074 1019 1062 1040 1015 1055 1003 1032 1012 976 1056 1097 1076 996 979 1002 973 1026 981 998 1058 1018 965 1015 1034 977 991 979 1001 1011 998 948 936 996 916 918 907 974 969 963 1011 918 905 933 915 918 938 960 916 987 1016 895 918 962 937 909 980 1113 1162 1274 1374 1531 1648 1614 1532 1343 1087 1009 951 919 954 918 899 913 876 886 930 921 884 894 900 837 903 854 807 801 871 842 872 869 791 887 883 835 821 820 874 828 840 870 822 773 838 808 853 842 839 852 850 820 771 789 848 836 811 801 815 779 841 805 818 829 781 760 806 832 819 856 802 833 827 850 813 837 781 848 858 811 822 838 851 874 884 980 1103 1225 1378 1750 2169 2384 2742 2695 2396 1728 1151 972 862 839 851 874 854 831 736 751 775 780 743 736 742 771 760 821 794 764 795 792 825 877 786 860 814 895 924 926 957 1028 1035 1144 1432 1544 1735 2181 2686 3323 3741 4040 4134 3846 3274 2614 2243 1870 1712 1696 1678 1963 2312 2629 3390 4087 4658 5226 5234 4804 4160 3157 2389 1853 1545 1319 1153 1028 960 953 889 850 804 815 778 792 759 764 794 745 725 759 743 675 665 710 686 677 726 689 738 680 740 702 693 728 745 788 759 705 735 792 761 779 773 833 846 924 921 1012 1111 1409 1724 2183 3265 4682 6320 7925 9113 8221 5753 3658 2112 1292 1068 1040 919 904 868 856 769 775 816 805 852 905 1022 1099 1169 1345 1476 1518 1516 1270 1149 1010 864 797 828 698 646 691 632 693 637 629 678 582 628 624 574 570 616 577 602 591 590 566 607 612 594 522 581 611 631 654 680 670 645 599 627 584 559 590 578 556 560 517 505 564 540 577 513 547 533 561 557 516 541 553 506 508 559 567 513 548 554 565 503 530 568 561 572 517 544 542 530 559 616 612 597 595 656 684 761 933 1118 1547 1950 2574 3017 3033 2293 1691 1138 845 723 756 729 750 779 840 854 866 800 774 693 657 572 564 538 561 512 472 523 480 531 445 504 533 481 547 534 570 657 614 554 574 523 531 535 477 452 535 473 527 547 608 642 782 952 1095 1301 1252 1211 1060 883 726 620 591 561 567 543 535 505 534 523 553 552 642 602 658 687 675 677 643 608 567 644 634 650 703 757 878 937 1067 1307 1546 1913 2426 2958 3454 3640 3581 3345 2778 2342 1806 1512 1272 1202 940 870 796 727 600 652 568 526 531 492 524 495 480 497 501 492 479 478 460 415 427 489 421 434 445 466 469 417 473 433 446 461 440 463 455 416 472 474 456 533 459 519 565 601 728 899 937 904 870 863 824 802 851 978 989 1078 972 922 758 760 669 578 533 512 479 475 472 423 454 406 435 409 439 424 392 403 440 452 452 442 441 468 413 427 414 395 445 441 397 461 462 484 511 502 430 405 401 378 406 398 387 431 385 390 398 442 385 394 361 411 366 426 413 357 410 378 406 400 401 393 347 407 394 397 391 418 456 432 444 480 563 590 805 954 1203 1133 944 794 777 576 530 482 457 424 428 408 408 381 396 422 407 433 414 412 416 411 445 426 448 517 499 610 623 703 763 901 916 1003 924 846 784 725 681 641 545 587 597 530 561 538 557 636 670 691 800 923 1053 1396 1721 1902 2015 2018 2174 1979 1928 1854 1783 1885 2129 2292 2663 2792 3062 2995 2818 2489 2195 1817 1522 1279 1016 915 766 737 695 754 790 785 784 662 645 616 552 486 517 558 570 590 627 640 792 793 756 794 725 670 636 568 466 493 517 459 469 550 492 471 486 486 510 536 572 642 803 1011 1463 2140 2988 3603 3169 2479 2166 1713 1039 723 611 562 469 488 432 442 381 375 376 381 370 313 361 384 374 352 371 385 339 394 356 332 322 372 394 386 398 410 395 432 470 523 537 511 459 481 430 416 340 364 376 367 355 356 340 343 352 360 358 401 345 367 398 390 421 405 473 583 701 803 700 700 589 517 488 395 372 394 399 390 425 427 408 417 403 383 369 416 399 452 408 489 544 598 697 883 1042 1109 1113 1121 1256 1178 1189 1037 923 868 762 648 578 604 520 558 519 549 598 717 768 913 890 804 840 827 820 764 766 720 711 659 586 596 443 454 472 427 395 384 359 351 339 333 385 363 357 344 316 349 357 356 360 344 371 450 462 482 513 515 531 542 572 536 575 550 510 522 449 394 437 398 373 367 333 384 439 440 437 438 409 400 442 498 527 496 554 576 529 519 593 556 621 731 716 618 563 566 517 425 376 339 358 337 350 309 324 375 337 353 377 361 330 350 366 329 345 415 412 405 424 447 486 546 606 820 1172 1727 2281 2522 1956 1501 1507 1335 1000 644 501 477 418 409 382 365 401 359 317 395 380 330 364 330 372 361 333 312 337 328 379 353 375 382 453 579 745 819 828 663 602 634 544 457 397 424 451 479 521 631 620 552 487 464 494 434 388 356 385 351 335 377 354 352 349 381 391 396 492 545 643 818 888 814 793 884 975 982 980 978 939 958 827 780 746 651 590 571 517 490 416 413 450 382 423 373 396 429 377 455 466 462 535 583 634 641 644 610 602 496 538 448 446 375 379 331 388 356 339 384 335 337 374 384 395 369 365 407 386 381 320 390 324 337 329 309 375 361 427 407 389 336 328 353 363 317 328 307 284 292 327 294 321 259 282 332 281 279 291 311 312 278 305 265 300 332 307 302 339 357 414 519 485 442 470 402 406 400 352 316 356 318 318 315 317 321 381 372 387 451 433 410 364 357 398 347 347 406 310 361 361 396 462 543 574 610 706 734 820 752 814 783 689 647 655 632 611 554 484 457 420 464 473 460 477 411 421 400 436 362 373 407 380 401 396 401 433 467 418 410 426 396 406 356 400 367 322 351 352 308 294 330 313 284 332 318 294 262 281 277 254 285 272 290 259 286 318 264 319 279 251 329 276 296 299 289 347 318 300 326 323 359 325 366 357 350 308 315 319 307 323 293 328 325 324 307 270 283 318 345 345 464 459 380 361 344 363 401 346 377 315 290 281 280 284 265 308 294 275 301 274 309 301 311 303 279 318 368 340 344 396 508 667 770 678 586 555 537 557 540 419 407 365 319 351 347 409 428 478 453 490 529 562 527 581 619 551 592 639 556 624 675 733 730 816 816 712 668 639 604 658 624 550 484 438 503 510 560 651 575 594 654 706 706 834 828 763 865 904 918 904 869 799 803 892 839 840 737 675 593 619 529 520 412 432 453 408 428 420 398 438 439 400 452 400 448 403 438 380 399 341 372 362 328 355 418 412 438 408 360 337 346 352 368 330 299 337 302 300 277 286 308 273 272 278 272 288 282 290 286 267 286 290 289 309 297 312 335 399 333 304 276 338 363 332 311 300 286 264 260 262 248 255 264 281 276 271 281 276 299 295 273 302 323 309 324 356 405 541 535 478 412 423 439 451 451 473 489 511 456 492 467 467 433 471 489 440 483 492 467 432 392 406 381 402 445 426 500 587 798 805 688 540 523 498 574 573 466 411 310 320 316 312 296 338 260 267 278 280 279 291 278 259 241 310 272 244 303 306 271 310 339 251 265 277 275 318 337 326 326 304 306 341 325 283 321 319 278 301 336 312 256 286 310 297 338 348 389 415 453 625 643 561 447 417 373 437 435 430 384 325 284 278 273 285 305 284 316 269 296 267 274 271 254 286 238 284 310 280 271 296 290 327 340 302 293 300 280 296 292 259 297 306 270 279 277 296 258 279 275 294 266 337 289 322 299 313 344 326 384 374 456 474 468 473 524 524 539 551 548 465 460 483 427 446 385 383 378 322 356 359 307 334 304 313 316 316 338 364 334 403 412 454 516 482 438 403 424 438 483 492 453 431 452 376 390 417 396 404 405 401 366 317 376 367 367 341 320 319 319 277 347 333 353 335 310 353 357 299 323 351 349 325 334 310 317 314 303 281 340 270 277 294 300 324 296 278 334 329 293 353 339 411 438 433 391 326 341 310 318 344 333 291 312 286 276 273 297 262 242 248 256 276 291 264 284 285 279 269 283 276 269 227 282 276 258 270 264 250 271 247 285 325 309 317 304 301 277 271 274 284 276 304 270 296 305 308 333 314 339 344 357 398 429 488 561 479 479 470 479 496 527 586 577 563 555 573 579 527 464 495 451 529 465 446 451 416 450 424 434 376 438 460 514 628 680 704 636 586 510 527 551 583 546 531 499 462 452 400 388 430 352 407 370 352 325 328 350 307 318 324 347 341 351 345 397 452 398 360 342 334 337 351 370 368 350 354 343 359 331 318 272 292 288 312 306 299 307 309 258 295 286 312 311 346 335 355 342 336 322 309 310 295 272 318 276 294 286 286 278 276 271 283 271</counts>
			</dataPoints>
		</scan>
	</xrdMeasurement>
</xrdMeasurements>