File: dataset/precursor_mixture/La(OH)3_Ga2O3_Bi2O3-alpha.12-min.xrdml
<?xml version="1.0"?>
<xrdMeasurements xmlns="http://www.xrdml.com/XRDMeasurement/2.2" xmlns:xsi="http://www.w3.org/2001/XMLSchema-instance" xsi:schemaLocation="http://www.xrdml.com/XRDMeasurement/2.2 http://www.xrdml.com/XRDMeasurement/2.2/XRDMeasurement.xsd" status="Completed" recordIdentifier="{352753DE-7A84-4686-8BCF-A41F358E406E}">
	<comment>
		<entry/>
	</comment>
	<sample type="To be analyzed">
		<id>dara-36-2</id>
		<name></name>
		<preparedBy></preparedBy>
	</sample>
	<xrdMeasurement measurementType="Scan" status="Completed" sampleMode="Reflection">
		<usedWavelength intended="K-Alpha 1">
			<kAlpha1 unit="Angstrom">1.5405980</kAlpha1>
			<kAlpha2 unit="Angstrom">1.5444260</kAlpha2>
			<kBeta unit="Angstrom">1.3922500</kBeta>
			<ratioKAlpha2KAlpha1>0.5000</ratioKAlpha2KAlpha1>
		</usedWavelength>
		<incidentBeamPath>
			<radius unit="mm">145.00</radius>
			<xRayTube id="1010048" name="Empyrean Cu LFF HR (9430 033 7310x) DK437873">
				<tension unit="kV">40.0</tension>
				<current unit="mA">15.0</current>
				<anodeMaterial>Cu</anodeMaterial>
				<focus type="Line">
					<length unit="mm">12.0</length>
					<width unit="mm">0.4</width>
					<takeOffAngle unit="deg">6.0</takeOffAngle>
				</focus>
			</xRayTube>
			<filter id="20010004" name="Beta-filter Nickel">
				<material>Ni</material>
				<thickness unit="mm">0.020</thickness>
			</filter>
			<sollerSlit id="21010002" name="Soller slits 0.04 rad.">
				<opening unit="rad">0.0400</opening>
			</sollerSlit>
			<mask id="22031000" name="Fixed mask 13 mm">
				<width unit="mm">9.00</width>
			</mask>
			<divergenceSlit id="22120001" name="Divergence slit 1°" xsi:type="fixedDivergenceSlitType">
				<distanceToSample unit="mm">50.00</distanceToSample>
				<height unit="mm">1.52</height>
			</divergenceSlit>
		</incidentBeamPath>
		<beamKnife id="29030100" name="Beam knife low"/>
		<sampleMovement xsi:type="spinningSampleMovementType">
			<spinnerRevolutionTime unit="seconds">1.0</spinnerRevolutionTime>
		</sampleMovement>
		<diffractedBeamPath>
			<radius unit="mm">145.00</radius>
			<antiScatterSlit id="22090040" name="AS slit 9 mm" xsi:type="fixedAntiScatterSlitType">
				<height unit="mm">9.00</height>
			</antiScatterSlit>
			<sollerSlit id="21020003" name="Large Soller slits 0.04 rad.">
				<opening unit="rad">0.0400</opening>
			</sollerSlit>
			<filter id="20030001" name="Large beta-filter Nickel">
				<material>Ni</material>
				<thickness unit="mm">0.020</thickness>
			</filter>
			<detector id="7010019" name="PIXcel1D-Medipix3 detector" xsi:type="rtmsDetectorType">
				<phd unit="keV">
					<lowerLevel>4.0</lowerLevel>
					<upperLevel>11.3</upperLevel>
				</phd>
				<mode>Scanning</mode>
				<activeLength unit="deg">5.020</activeLength>
			</detector>
		</diffractedBeamPath>
		<scan appendNumber="0" mode="Continuous" scanAxis="Gonio" status="Completed">
			<header>
				<startTimeStamp>2024-03-25T10:36:14-07:00</startTimeStamp>
				<endTimeStamp>2024-03-25T10:48:42-07:00</endTimeStamp>
				<author>
					<name>AutomatedUser</name>
				</author>
				<source>
					<applicationSoftware version="1.6 (94)">PANalytical Aeris Instrument Suite</applicationSoftware>
					<instrumentControlSoftware version="3.0.0 20211014">AERIS</instrumentControlSoftware>
					<instrumentID>2879380</instrumentID>
				</source>
			</header>
			<dataPoints>
				<positions axis="2Theta" unit="deg">
					<startPosition>9.99043322</startPosition>
					<endPosition>100.09495370</endPosition>
				</positions>
				<positions axis="Omega" unit="deg">
					<startPosition>4.99521661</startPosition>
					<endPosition>50.04747685</endPosition>
				</positions>
				<commonCountingTime unit="seconds">18.249</commonCountingTime>
				<counts unit="counts">3980 3935 3953 3919 3898 3987 3842 3896 3882 3934 3801 3864 3783 3892 3852 3849 3951 3973 3757 3946 3864 3831 3757 3829 3725 3785 3657 3747 3817 3704 3816 3754 3731 3758 3821 3787 3746 3755 3730 3775 3655 3589 3791 3660 3683 3715 3721 3719 3740 3663 3794 3709 3842 3603 3670 3674 3668 3714 3553 3577 3610 3602 3531 3585 3553 3799 3535 3649 3485 3422 3746 3684 3531 3649 3597 3542 3541 3594 3645 3498 3531 3473 3698 3629 3569 3492 3535 3513 3581 3466 3441 3509 3447 3381 3605 3474 3536 3401 3371 3565 3480 3340 3406 3488 3550 3507 3460 3421 3393 3502 3346 3358 3496 3373 3399 3383 3324 3558 3468 3365 3405 3352 3256 3324 3281 3338 3341 3355 3272 3262 3410 3300 3347 3322 3323 3267 3230 3243 3235 3329 3316 3335 3277 3340 3304 3355 3355 3230 3228 3309 3148 3216 3190 3213 3124 3195 3136 3208 3193 3188 3108 3108 3188 3079 3235 3241 3184 3167 3127 3120 3132 3074 3169 3162 3238 3056 3214 3137 3251 3021 3076 3228 3159 3051 3094 3100 3004 3085 3097 3106 3138 3032 3090 3047 3015 3055 3001 2985 3106 3204 3087 2959 3004 3187 2959 2893 2984 3075 3095 2954 3011 3046 3027 3114 3018 3014 2968 2954 2970 2917 2970 2988 2841 2878 2981 3017 2978 2933 3029 2969 2948 2823 2927 3041 2918 3051 2983 2824 2938 2874 2917 2961 2877 2876 2896 2856 2948 2895 2881 2938 2840 2884 2826 2870 2796 2776 2795 2801 2895 2872 2769 2878 2942 2765 2788 2807 2867 2869 2810 2797 2844 2839 2877 2824 2746 2835 2803 2712 2856 2836 2830 2696 2824 2740 2802 2717 2805 2728 2756 2763 2775 2651 2825 2653 2682 2769 2691 2823 2716 2725 2772 2740 2744 2660 2688 2738 2753 2698 2604 2652 2779 2724 2756 2607 2745 2614 2655 2670 2708 2718 2739 2629 2650 2670 2589 2594 2648 2607 2686 2747 2689 2687 2703 2565 2613 2579 2663 2691 2631 2549 2718 2541 2623 2647 2588 2688 2572 2566 2653 2580 2713 2690 2610 2629 2598 2586 2514 2651 2645 2627 2677 2615 2609 2613 2680 2470 2579 2578 2617 2573 2608 2516 2539 2623 2613 2514 2736 2535 2508 2626 2585 2590 2477 2504 2512 2589 2584 2510 2550 2504 2581 2498 2627 2429 2614 2541 2568 2515 2502 2490 2432 2514 2524 2567 2553 2542 2551 2507 2635 2574 2502 2575 2547 2536 2544 2498 2491 2527 2506 2521 2470 2481 2578 2444 2503 2513 2459 2429 2580 2516 2473 2499 2442 2524 2537 2496 2503 2586 2518 2492 2498 2468 2482 2467 2547 2490 2512 2468 2484 2517 2504 2557 2615 2435 2564 2583 2612 2568 2552 2556 2584 2636 2628 2623 2635 2647 2669 2725 2750 2698 2778 2599 2765 2792 2801 2780 2752 2879 2800 2871 2906 2911 2914 3108 2922 3096 3153 3215 3322 3354 3341 3436 3656 3634 3711 3743 3777 3886 4079 4198 4153 4475 4661 4789 4907 5184 5426 5496 5768 5995 6294 6619 6986 7087 7355 7702 7943 8266 8528 8696 9126 9165 9408 9393 9192 9094 8953 8502 8312 7936 7446 7031 6552 6317 5830 5442 5096 4846 4469 4292 4093 3872 3704 3601 3470 3339 3369 3192 3215 3087 3035 2930 3001 2875 2883 2774 2840 2831 2782 2758 2754 2724 2568 2642 2477 2526 2587 2496 2485 2518 2544 2459 2580 2401 2428 2505 2480 2556 2435 2511 2430 2437 2364 2384 2455 2349 2575 2346 2418 2414 2353 2397 2383 2357 2331 2226 2340 2296 2342 2334 2350 2417 2248 2343 2361 2330 2375 2313 2382 2367 2363 2328 2416 2442 2336 2303 2396 2326 2355 2356 2449 2410 2431 2398 2510 2502 2563 2616 2555 2637 2559 2563 2578 2464 2308 2416 2347 2283 2330 2282 2222 2249 2135 2250 2183 2233 2262 2126 2222 2312 2218 2291 2185 2204 2234 2116 2200 2197 2207 2264 2129 2105 2133 2076 2133 2206 2216 2264 2263 2089 2244 2156 2099 2078 2095 2201 2054 2195 2061 2129 2195 2179 2134 2170 2139 2129 2118 2079 2121 2108 2112 2146 2116 2070 2150 2140 2160 2182 2181 2061 2141 2102 2133 2153 2134 2137 2047 2081 2040 2067 2083 2118 2078 2063 2086 2096 2123 2100 2124 2094 2039 2085 2029 2130 2038 2032 2041 2019 2030 2068 2095 2071 1992 2141 2039 2077 1931 1980 2000 2112 2108 2065 1974 2043 1942 1983 1991 2038 2097 1957 2081 2027 2052 2082 2064 2005 2054 2005 2013 2022 2053 2019 2073 2048 2041 2115 2070 2029 2074 2096 2151 1952 2124 1995 2109 2066 2111 2082 2124 2138 2044 2149 2124 2066 2182 2117 2143 2093 2158 2115 2038 2157 2211 2192 2140 2294 2185 2269 2248 2281 2296 2404 2356 2398 2479 2486 2398 2580 2612 2638 2787 2737 2898 3004 2975 3131 3215 3340 3410 3419 3506 3620 3724 3820 3753 3859 3840 3819 3803 3718 3627 3376 3373 3185 3083 2930 2794 2764 2619 2675 2437 2338 2356 2380 2329 2238 2197 2169 2117 2195 2108 2106 2024 2098 2013 2126 2106 2075 2007 1997 1991 2016 2161 2049 1968 1955 1962 1909 1969 2026 1898 1933 1858 1922 2015 2001 1981 2009 1930 1967 1927 2055 2017 2027 2034 1987 2022 2116 2059 2111 2212 2317 2268 2334 2446 2360 2399 2494 2530 2522 2678 2612 2515 2486 2300 2289 2171 2209 2085 2064 1974 1899 1873 1885 1881 1860 1883 1820 1822 1836 1838 1816 1885 1832 1827 1742 1817 1824 1860 1769 1747 1731 1763 1828 1816 1829 1740 1818 1781 1872 1705 1851 1773 1804 1746 1776 1730 1749 1768 1817 1761 1797 1769 1806 1834 1713 1767 1746 1695 1705 1708 1755 1740 1725 1707 1737 1703 1790 1737 1790 1742 1718 1779 1608 1662 1732 1677 1711 1814 1679 1670 1645 1653 1698 1790 1693 1635 1660 1760 1685 1685 1687 1692 1696 1711 1628 1667 1723 1631 1744 1804 1688 1665 1691 1783 1685 1667 1701 1644 1628 1697 1719 1643 1663 1672 1654 1657 1699 1641 1623 1598 1604 1650 1666 1636 1663 1675 1661 1665 1667 1661 1728 1623 1617 1614 1649 1688 1639 1696 1737 1660 1664 1645 1675 1693 1713 1582 1616 1699 1597 1632 1668 1634 1626 1637 1681 1607 1634 1682 1653 1674 1665 1691 1626 1736 1684 1729 1633 1752 1705 1720 1707 1826 1933 1844 1866 1920 1936 2047 2106 2150 2253 2261 2312 2362 2383 2334 2406 2303 2226 2166 2000 1994 1954 1811 1816 1640 1680 1685 1684 1590 1641 1576 1552 1564 1552 1623 1576 1604 1609 1636 1569 1656 1613 1604 1569 1608 1508 1610 1561 1608 1582 1591 1599 1566 1635 1591 1560 1574 1640 1512 1523 1587 1558 1524 1564 1548 1576 1586 1541 1590 1533 1526 1451 1565 1561 1520 1612 1586 1643 1542 1642 1579 1539 1572 1520 1495 1563 1521 1537 1565 1541 1556 1601 1538 1586 1492 1481 1578 1551 1571 1489 1531 1508 1506 1542 1501 1552 1507 1518 1523 1553 1419 1467 1509 1527 1478 1493 1549 1554 1539 1546 1454 1539 1481 1483 1416 1493 1495 1492 1505 1470 1531 1442 1501 1489 1479 1457 1444 1455 1447 1402 1463 1470 1449 1490 1466 1500 1528 1493 1510 1449 1518 1498 1514 1387 1465 1537 1437 1492 1396 1426 1424 1502 1464 1552 1417 1508 1457 1525 1502 1513 1450 1462 1541 1500 1430 1413 1525 1399 1461 1481 1485 1494 1488 1483 1478 1441 1537 1498 1530 1451 1484 1452 1462 1477 1461 1465 1414 1485 1565 1572 1500 1467 1494 1533 1517 1448 1486 1492 1418 1554 1458 1391 1487 1493 1438 1519 1450 1450 1494 1493 1531 1466 1493 1522 1470 1449 1508 1517 1421 1482 1475 1548 1489 1546 1479 1552 1510 1523 1470 1438 1470 1494 1497 1576 1484 1519 1491 1531 1564 1534 1559 1511 1626 1585 1594 1614 1602 1679 1675 1714 1870 1982 1928 2027 2164 2286 2357 2555 2627 2917 2931 3135 3091 3211 2989 2843 2626 2583 2360 2216 2079 1942 1858 1777 1628 1630 1717 1571 1564 1509 1445 1419 1473 1489 1400 1406 1492 1402 1457 1457 1371 1466 1447 1448 1491 1379 1454 1412 1472 1458 1434 1392 1460 1409 1509 1379 1429 1422 1449 1534 1498 1487 1475 1481 1427 1506 1382 1565 1479 1488 1478 1496 1599 1591 1498 1683 1592 1588 1670 1701 1750 1664 1695 1675 1676 1714 1646 1647 1557 1525 1564 1507 1504 1471 1472 1518 1508 1452 1505 1531 1538 1640 1594 1679 1541 1678 1761 1871 1991 2170 2302 2453 2621 2874 3092 3348 3585 4097 4315 4727 5187 5419 5594 5445 4944 4720 4085 3838 3607 3273 2905 2358 2174 1959 1709 1637 1581 1535 1433 1497 1566 1489 1581 1465 1481 1435 1414 1493 1535 1437 1508 1458 1517 1459 1438 1418 1400 1519 1408 1425 1401 1546 1477 1403 1472 1458 1483 1389 1443 1462 1492 1414 1556 1510 1477 1463 1484 1489 1543 1534 1538 1582 1609 1571 1623 1609 1684 1621 1597 1682 1655 1647 1677 1706 1675 1752 1712 1696 1740 1740 1760 1783 1823 1777 1871 1821 1947 2020 2064 2128 2253 2283 2315 2549 2688 2970 3202 3259 3698 4102 4417 4886 5489 6035 6650 7342 7955 8794 9353 9726 9682 9341 8977 8287 7497 6853 6512 5706 5385 4998 4408 4328 4058 4043 4282 4413 4486 4898 5053 5262 5676 6015 6711 7100 7572 8049 8843 9449 10391 11022 12201 13226 14399 15623 17479 19033 20905 23047 25098 27894 30688 32833 34491 34871 33235 30077 26536 23101 20609 18559 16712 14233 11695 8928 6923 5692 4794 4162 3988 3671 3682 3464 3442 3347 3355 3367 3348 3318 3393 3409 3351 3469 3534 3512 3727 3838 3990 4158 4319 4572 4770 5140 5394 5724 6031 6530 7075 7435 8185 8719 9331 9979 10698 11179 12061 12633 13294 13686 13726 14347 13757 13358 12315 11245 10290 9594 8869 8210 7267 6421 5804 5033 4618 4185 3867 3653 3384 3220 3112 3036 2954 2710 2603 2518 2464 2341 2343 2226 2156 2135 2208 2049 2096 2005 1982 2008 1906 1899 1843 1890 1740 1762 1762 1753 1756 1691 1685 1700 1685 1734 1691 1643 1599 1582 1605 1608 1504 1546 1514 1538 1553 1501 1516 1544 1566 1497 1474 1518 1481 1453 1441 1546 1488 1491 1528 1464 1547 1468 1406 1386 1434 1551 1480 1482 1467 1492 1446 1469 1530 1470 1442 1373 1375 1376 1381 1390 1510 1481 1422 1495 1414 1461 1381 1405 1459 1453 1443 1392 1428 1412 1519 1500 1540 1426 1455 1505 1464 1507 1483 1472 1407 1454 1452 1560 1427 1530 1533 1513 1545 1548 1468 1505 1537 1600 1549 1530 1630 1529 1545 1549 1554 1593 1593 1696 1687 1668 1638 1664 1669 1760 1749 1732 1693 1755 1753 1837 1782 1725 1854 1810 1923 1944 1983 2011 2056 2056 2070 2029 1995 2144 2196 2323 2325 2447 2456 2485 2511 2634 2667 2739 2785 2844 3029 3103 3247 3198 3309 3291 3457 3654 3662 3589 3707 3799 3742 3838 3886 3868 3931 4016 3958 4071 4114 4274 4476 4586 4728 4859 4909 5137 5394 5625 5893 6081 6339 6574 6949 7195 7322 7481 7623 7836 7999 8132 8195 8284 8132 8256 7976 7899 7648 7357 7066 6851 6577 6405 6120 5707 5285 4987 4983 4656 4442 4119 4008 3795 3710 3501 3288 3219 3258 3013 2947 2841 2844 2774 2693 2582 2658 2577 2464 2367 2404 2331 2368 2313 2131 2233 2153 2234 2186 2220 2160 2160 2145 2191 2101 2175 2093 2132 2103 2119 2110 2097 2183 2086 2203 2130 2187 2200 2236 2200 2240 2162 2316 2285 2218 2317 2397 2424 2444 2484 2547 2583 2682 2705 2790 2860 2836 2836 3204 3302 3246 3473 3674 3633 3786 4007 4018 4394 4535 4704 5072 5160 5277 5432 5564 5981 6179 6208 6546 6608 6816 6997 7041 7220 7149 7030 7245 7058 7125 7018 6670 6490 6361 6303 6068 5826 5555 5324 5182 4822 4617 4531 4383 4033 3999 3797 3696 3422 3442 3255 3069 3117 2897 2739 2737 2665 2637 2529 2356 2301 2355 2256 2171 2155 2082 2016 1981 2007 1919 1901 1918 1919 1769 1856 1790 1832 1700 1752 1658 1702 1647 1580 1633 1678 1628 1596 1616 1675 1685 1646 1757 1864 1820 1928 1989 2116 2334 2268 2371 2551 2560 2613 2454 2317 2232 2169 2112 2011 2034 2004 1856 1763 1562 1654 1599 1580 1526 1495 1519 1581 1498 1476 1451 1588 1497 1591 1513 1645 1641 1720 1740 1706 1766 1848 1969 1976 2190 2416 2468 2791 3070 3392 3853 4372 5138 5666 6665 7574 8449 9456 9791 9933 9742 9071 8520 7630 7364 7293 7486 7397 7640 7443 7378 7689 7992 9013 9436 10456 10884 10989 10588 9999 9074 8186 7335 6779 6437 6122 5524 4942 4172 3559 2977 2541 2212 2163 1945 1926 1918 1911 1785 1892 1775 1819 1693 1668 1792 1652 1667 1648 1554 1521 1550 1455 1462 1450 1435 1346 1445 1398 1391 1334 1404 1362 1352 1412 1338 1403 1320 1414 1355 1396 1399 1425 1443 1537 1666 1719 1791 1898 2069 2135 2326 2435 2516 2428 2352 2202 1963 1925 1782 1899 1733 1737 1689 1593 1451 1393 1311 1227 1215 1193 1193 1186 1129 1155 1127 1142 1149 1130 1245 1188 1135 1189 1129 1200 1134 1151 1208 1188 1163 1208 1165 1176 1138 1105 1165 1104 1156 1153 1182 1158 1096 1203 1086 1202 1200 1173 1161 1144 1169 1215 1157 1128 1232 1139 1214 1186 1240 1226 1208 1222 1226 1212 1267 1233 1294 1226 1294 1304 1285 1334 1275 1358 1359 1416 1496 1520 1557 1575 1606 1694 1860 1851 2118 2209 2430 2607 2828 3175 3591 4006 4343 4850 5123 5484 5286 4918 4759 4330 4127 4222 4221 4285 4209 3903 3685 3521 3385 3203 3135 3059 2944 2893 2873 2930 2787 2806 2826 2813 2996 2925 3064 3214 3312 3496 3735 3918 3897 3906 3592 3331 3000 2798 2723 2667 2561 2489 2410 2170 1930 1751 1601 1587 1467 1401 1466 1388 1362 1269 1316 1405 1288 1326 1320 1300 1277 1365 1375 1373 1400 1447 1427 1515 1623 1538 1638 1711 1871 1885 2175 2405 2425 2611 2807 2522 2524 2447 2260 2215 2132 2216 2174 2168 2177 1976 1907 1758 1650 1590 1551 1477 1566 1489 1449 1384 1360 1338 1318 1304 1294 1209 1248 1219 1179 1163 1244 1168 1157 1101 1090 1122 1097 1159 1142 1129 1048 1159 1049 1073 1078 1056 1020 1072 1061 1085 1064 1076 1059 1092 1060 1108 1099 1143 1054 1057 1064 1059 1057 1023 1078 1097 1105 1006 1077 1017 1048 1097 1129 1060 1068 1071 1153 1111 1172 1127 1113 1192 1193 1185 1279 1295 1289 1375 1532 1628 1826 1909 2042 2197 2354 2529 2556 2515 2350 2164 1972 1852 1919 1868 1968 1929 1793 1718 1594 1487 1371 1361 1325 1314 1277 1420 1339 1365 1411 1363 1377 1408 1451 1442 1469 1474 1529 1395 1485 1618 1587 1580 1574 1657 1651 1547 1677 1704 1709 1716 1743 1826 1758 1817 1874 2062 2282 2482 2686 2964 3209 3448 3716 3923 4000 3974 3752 3369 2925 2707 2644 2587 2612 2511 2425 2271 2000 1769 1575 1486 1315 1400 1330 1306 1279 1227 1335 1226 1205 1226 1240 1217 1268 1228 1257 1253 1213 1245 1219 1285 1252 1283 1257 1330 1271 1388 1245 1327 1367 1324 1424 1327 1476 1405 1501 1480 1547 1565 1637 1628 1647 1733 1798 1721 1786 1993 1995 2082 2121 2080 2198 2307 2341 2422 2357 2352 2392 2353 2385 2407 2353 2275 2328 2334 2268 2131 2185 2115 1977 1981 1841 1826 1745 1783 1666 1602 1593 1547 1570 1498 1458 1433 1436 1412 1393 1342 1318 1329 1303 1306 1302 1251 1282 1254 1324 1256 1224 1286 1245 1273 1214 1259 1245 1211 1286 1356 1245 1280 1326 1292 1350 1338 1339 1295 1356 1445 1366 1483 1415 1454 1504 1479 1538 1574 1556 1577 1744 1724 1796 1877 1862 1948 1997 2078 2199 2322 2457 2545 2789 2829 2936 3344 3441 3476 3704 4025 4255 4367 4755 4966 5183 5309 5650 5988 5958 5973 6102 5998 6004 5910 5770 5640 5562 5297 5186 5045 4695 4405 4338 4126 3914 3657 3478 3263 3040 2912 2819 2605 2508 2303 2321 2135 1996 1999 1917 1853 1822 1699 1713 1664 1522 1561 1513 1491 1456 1425 1383 1461 1430 1385 1482 1433 1440 1563 1587 1772 1862 1990 2207 2226 2271 2264 2163 1997 1755 1602 1614 1606 1656 1637 1637 1532 1484 1329 1225 1178 978 1048 999 1050 992 956 1037 968 989 964 1007 1009 939 977 967 944 921 892 929 965 873 985 914 962 919 971 927 928 965 919 900 929 971 962 985 989 1004 1069 1040 995 995 964 986 1021 970 899 913 977 958 939 965 896 911 871 934 895 887 894 881 885 872 883 875 924 830 941 899 931 858 831 833 879 849 843 896 889 897 909 875 835 836 855 913 905 926 881 804 922 868 877 894 864 894 887 937 887 895 994 918 960 930 957 977 986 1017 1047 1110 1171 1285 1378 1516 1706 1873 1925 1847 1983 1756 1646 1544 1448 1334 1492 1400 1322 1392 1346 1288 1248 1148 1145 967 979 1023 994 1017 884 976 970 976 939 986 1028 1083 1137 1117 1189 1260 1240 1317 1526 1596 1731 1746 1807 1765 1652 1603 1549 1572 1515 1494 1610 1604 1574 1537 1537 1531 1568 1515 1462 1470 1465 1514 1528 1626 1641 1604 1654 1716 1693 1787 1887 1868 1978 1905 1915 2042 2030 2029 2070 2260 2355 2506 2540 2918 2871 3031 2939 2725 2568 2244 2084 1995 1962 1961 1957 1958 1857 1811 1612 1453 1360 1277 1201 1199 1104 994 996 1067 1061 1012 1039 1017 1012 973 1062 994 1078 983 971 1034 950 1018 954 1070 959 1007 1032 971 1030 971 1012 966 1048 1052 1033 1056 996 1012 1009 1045 1013 1005 993 1032 995 990 1042 1012 1019 1101 1026 1061 1010 1011 1007 975 979 996 1019 1040 988 941 931 963 912 963 860 879 886 893 970 888 920 931 958 896 872 878 911 872 884 870 900 920 858 824 854 898 834 873 877 871 904 798 844 816 839 813 869 842 834 858 879 821 806 853 813 859 850 905 856 812 791 829 913 830 864 878 864 854 807 820 893 841 810 836 851 870 788 783 798 856 813 791 840 811 847 785 771 862 816 854 873 837 820 836 794 837 837 808 857 822 863 826 878 860 900 922 912 856 941 958 1069 1069 1121 1143 1147 1182 1175 1102 986 1013 1055 1001 1056 1095 1074 1101 1083 1018 992 934 958 990 935 920 986 968 985 1039 1005 1008 1090 1000 1046 998 1060 1060 1076 1034 1032 989 1010 1126 1027 1011 1039 1046 1016 994 1084 1045 1037 1024 971 986 1002 989 1027 1065 1004 950 970 972 941 961 1068 992 1076 1009 1041 1028 1126 1203 1209 1373 1493 1683 1759 1817 1856 1860 1828 1534 1379 1375 1260 1316 1287 1382 1422 1411 1414 1244 1221 1098 1042 983 1027 891 962 980 918 936 933 979 983 947 1024 994 937 1021 1042 1078 1030 984 1008 985 1018 992 1008 1024 1047 1075 1026 1045 1049 1069 1011 1072 1068 1092 1197 1196 1220 1197 1176 1189 1199 1172 1225 1283 1259 1209 1266 1258 1289 1223 1252 1302 1261 1273 1245 1257 1277 1211 1204 1298 1151 1108 1150 1189 1133 1198 1221 1172 1179 1156 1183 1190 1179 1220 1225 1261 1300 1298 1378 1491 1705 1792 1962 2410 2768 3299 3749 4367 5190 5748 6474 6797 6616 6295 5426 4850 4180 3847 3690 3788 3770 4056 3991 3913 3743 3308 2736 2301 1934 1764 1471 1386 1331 1217 1177 1098 1112 1150 1051 1018 1049 1002 1048 957 1003 983 1000 958 1050 1076 1038 1003 1037 973 1035 1070 1106 1028 1040 1063 1087 1077 1116 1100 1130 1222 1145 1299 1248 1311 1358 1432 1461 1534 1615 1614 1636 1692 1742 1785 1739 1872 1832 1788 1735 1740 1688 1719 1673 1668 1676 1684 1574 1539 1542 1552 1423 1452 1344 1335 1323 1348 1208 1263 1213 1242 1169 1226 1269 1284 1349 1308 1423 1391 1369 1467 1381 1444 1316 1326 1275 1285 1443 1509 1577 1625 1768 1794 1875 1728 1662 1526 1430 1350 1346 1358 1308 1387 1328 1392 1472 1430 1344 1238 1191 1269 1200 1242 1325 1226 1180 1242 1211 1242 1295 1301 1338 1356 1385 1325 1433 1456 1464 1513 1577 1630 1640 1723 1864 1852 1956 2028 2040 2122 2303 2404 2458 2575 2619 2760 2664 2815 2895 3021 3030 3116 3100 3169 3095 3164 3371 3191 3346 3343 3404 3491 3478 3831 3903 4126 4405 4472 4746 4762 4855 4670 4562 4463 4383 4375 4611 4824 5107 5437 5931 6331 6591 7149 7364 7540 7590 7373 7076 6824 6440 6318 6404 6408 6330 6381 6551 6309 6249 5836 5421 5063 4825 4698 4459 4283 4005 3806 3544 3371 3268 3090 2917 2743 2635 2514 2401 2365 2244 2186 2000 1916 1825 1859 1776 1812 1680 1632 1673 1513 1522 1458 1425 1462 1402 1317 1331 1307 1341 1258 1246 1229 1252 1295 1254 1176 1266 1283 1199 1156 1237 1210 1231 1315 1274 1364 1351 1388 1457 1646 1768 1879 2100 2306 2319 2426 2403 2326 2146 1891 1874 1742 1744 1735 1705 1795 1906 1862 1889 1724 1676 1610 1437 1353 1298 1321 1319 1267 1353 1245 1189 1262 1283 1243 1258 1334 1322 1389 1309 1378 1360 1510 1568 1578 1598 1726 1907 2016 2195 2280 2417 2585 2822 2663 2669 2316 2035 1902 1721 1723 1796 1799 1844 1811 1877 1901 1740 1594 1482 1303 1233 1163 1172 1067 1055 1025 988 1054 1040 1063 959 1016 975 997 974 975 984 1006 1040 1095 1081 1144 1104 1102 1093 1017 1017 933 979 933 959 984 947 917 953 1026 998 931 941 957 957 925 931 924 934 937 980 957 1025 991 1034 970 1001 1022 1046 1015 1074 1050 1089 1124 1052 1233 1167 1171 1103 1178 1132 1148 1039 1135 1150 1173 1141 1086 1096 1095 1102 1106 1023 1058 1094 996 1042 1009 1067 1016 994 1006 974 930 938 929 926 962 962 914 989 917 944 926 974 975 1006 1038 1125 1158 1256 1213 1243 1152 1104 1054 1014 979 1003 975 955 1043 1035 1012 1045 1025 979 1030 974 943 876 1009 953 970 1039 1047 1123 1289 1321 1520 1647 1815 1899 2032 2136 2280 2368 2418 2367 2110 1848 1662 1523 1540 1524 1557 1576 1763 1838 1906 1896 1839 1894 1938 2023 2244 2401 2519 2557 2406 2209 2062 1821 1560 1527 1435 1498 1568 1690 1623 1798 1785 1782 1653 1531 1412 1293 1178 1123 1083 1022 1077 1032 1029 1114 1090 1169 1130 1341 1340 1514 1654 1946 2228 2642 3262 3748 4148 4407 4373 4029 3430 2849 2386 2003 1958 1899 2077 2157 2357 2573 2686 2617 2282 2058 1742 1510 1158 1119 1036 1021 969 941 935 913 928 878 954 890 909 888 832 910 877 911 869 880 863 901 897 896 942 952 968 1003 1051 1196 1228 1353 1523 1792 2037 2319 2594 2916 3038 3158 3135 2996 2685 2250 1916 1710 1663 1621 1746 1783 1885 1960 2020 1950 1731 1652 1475 1224 1095 976 975 899 877 833 823 811 824 780 824 799 815 830 784 818 786 802 795 791 835 756 765 772 707 765 764 721 695 747 785 729 796 782 727 813 741 745 711 743 741 752 748 707 740 699 751 713 763 731 744 768 810 781 759 759 785 769 764 789 759 754 752 724 798 790 814 703 774 736 752 789 733 778 794 777 766 769 792 779 754 741 837 820 833 856 901 880 918 933 904 971 866 782 808 805 820 810 831 891 879 948 909 956 886 955 839 893 861 907 817 829 860 870 916 952 910 892 864 951 938 926 924 931 972 983 972 1004 1015 1024 988 1092 1108 1088 1229 1290 1438 1591 1734 2065 2404 2780 3333 3822 4347 4580 4444 3821 3167 2625 2237 1989 1939 1939 1960 2181 2367 2666 2887 2887 2622 2306 2058 1751 1618 1371 1418 1314 1271 1320 1297 1225 1336 1331 1335 1434 1392 1468 1531 1546 1575 1651 1711 1688 1875 1858 1883 1963 1962 2004 2070 1969 1938 2050 2021 1962 2012 2129 2178 2233 2321 2391 2501 2902 3085 3191 3353 3194 3079 2880 2628 2446 2247 2250 2031 1999 2047 1929 2010 2101 2025 1975 1906 1708 1616 1526 1414 1431 1270 1169 1150 1065 1078 1044 1025 1087 1087 1152 1188 1221 1273 1390 1553 1705 1891 2116 2239 2510 2502 2505 2402 2079 1779 1554 1467 1418 1385 1437 1562 1716 1718 1786 1835 1782 1732 1668 1426 1354 1299 1309 1284 1194 1263 1307 1301 1341 1286 1377 1362 1383 1354 1415 1358 1417 1307 1329 1312 1355 1338 1329 1269 1319 1241 1246 1261 1284 1214 1313 1276 1298 1337 1329 1313 1424 1307 1249 1285 1110 1067 1041 1094 1050 1062 998 1024 1038 1005 1051 992 978 915 938 874 842 907 873 855 857 886 799 842 873 881 821 867 767 810 808 805 780 851 791 797 865 825 790 813 796 864 818 783 845 802 854 830 797 812 780 792 811 861 863 841 916 844 839 893 909 900 886 874 888 868 959 903 917 947 962 959 950 927 992 1027 1037 1089 1070 1065 1079 1141 1094 1143 1168 1179 1196 1194 1235 1297 1278 1339 1329 1401 1392 1348 1351 1406 1443 1415 1501 1510 1495 1496 1522 1594 1732 1798 1980 2009 2289 2248 2443 2446 2587 2529 2409 2406 2391 2474 2615 2813 2749 2757 2674 2461 2495 2442 2374 2180 2254 2068 1941 1891 1940 1779 1873 1823 1791 1654 1524 1490 1416 1339 1405 1323 1307 1263 1280 1243 1242 1316 1369 1403 1573 1768 1873 2016 2280 2443 2502 2335 2130 1890 1630 1498 1385 1399 1346 1397 1499 1539 1645 1669 1726 1647 1687 1537 1432 1427 1342 1286 1369 1396 1497 1498 1518 1371 1398 1410 1253 1191 1190 1181 1192 1213 1204 1308 1337 1319 1430 1422 1408 1416 1401 1388 1345 1355 1317 1344 1326 1412 1360 1342 1439 1482 1464 1573 1570 1748 1817 1914 2058 2158 2201 2389 2538 2672 2852 2806 2827 2765 2659 2415 2210 2221 2092 1990 2036 2057 2058 2120 2126 2221 2204 2128 2009 1915 1804 1591 1559 1459 1394 1395 1357 1355 1259 1189 1256 1120 1157 1093 1081 1070 1040 1102 985 1006 938 994 996 930 925 950 920 902 886 912 894 945 900 924 890 868 942 912 890 896 871 925 844 877 884 923 888 898 946 913 937 957 996 900 954 1019 1036 1063 1109 1080 1116 1129 1107 1100 1108 1037 1065 1067 1016 1068 1002 1061 1070 1053 1044 1079 1006 1091 1025 1068 996 1020 979 1026 1033 988 1002 965 979 999 998 1014 992 988 1017 969 1016 985 977 1022 1052 1125 1025 1034 1037 1037 1005 1054 1090 1112 1136 1039 1065 1100 1120 1119 1133 1113 1192 1129 1160 1119 1167 1107 1177 1097 1114 1070 1119 1133 1133 1086 1062 1158 1088 1108 1018 1093 1088 1086 1084 1156 1128 1105 1149 1135 1137 1161 1208 1229 1276 1251 1281 1341 1256 1267 1282 1289 1276 1260 1213 1218 1195 1191 1129 1145 1124 1191 1113 1143 1123 1101 1085 1036 1083 1063 1009 1032 1019 971 906 1006 946 1026 924 878 924 900 918 885 892 915 897 868 961 952 875 969 996 1054 1130 1205 1309 1440 1616 1728 1967 1979 2104 1950 1742 1568 1333 1143 1178 1116 1097 1107 1166 1182 1270 1325 1440 1438 1445 1361 1232 1171 1151 1092 1101 1082 1175 1284 1406 1570 1623 1752 1708 1693 1569 1424 1253 1161 1110 1094 1006 991 927 1056 1100 1140 1274 1254 1256 1267 1198 1104 1004 946 895 859 824 876 804 821 815 808 792 807 859 875 835 879 945 973 999 1101 1211 1296 1389 1474 1569 1510 1436 1341 1255 1249 1256 1211 1339 1308 1458 1568 1695 1903 1959 1878 1893 1782 1565 1504 1439 1432 1384 1429 1408 1280 1372 1377 1413 1442 1419 1341 1405 1268 1245 1242 1203 1269 1203 1204 1176 1154 1090 1088 1000 1016 1026 1057 1015 1014 1060 1059 989 988 972 945 971 922 924 861 892 864 900 829 831 858 864 858 918 855 804 817 863 903 800 809 811 772 779 793 765 786 823 827 777 759 847 870 814 765 801 788 827 805 776 810 824 870 883 820 888 919 916 987 947 979 1065 1021 1133 1102 1207 1302 1315 1415 1493 1500 1626 1598 1635 1508 1396 1323 1356 1217 1258 1255 1380 1345 1434 1417 1565 1538 1585 1595 1659 1653 1537 1494 1469 1535 1512 1654 1544 1730 1706 1768 1782 1912 1949 1965 1843 2042 2065 2083 2122 2079 2158 2120 2174 2177 2242 2109 2241 2220 2207 2167 2228 2152 2147 2174 2217 2058 2022 2091 2048 1965 2049 1917 1889 1950 1841 1826 1842 1772 1717 1803 1711 1822 1646 1641 1680 1676 1665 1688 1677 1714 1704 1725 1737 1825 1851 1821 1731 1759 1796 1781 1868 1911 1950 1999 2036 1946 2087 2054 2122 2045 2131 2089 2071 2079 2141 2112 2087 2048 2039 1996 1984 1887 2010 1980 1909 1858 1788 1819 1753 1795 1686 1711 1645 1652 1583 1617 1632 1573 1512 1452 1427 1436 1499 1449 1452 1388 1369 1321 1333 1371 1255 1330 1284 1232 1198 1222 1122 1178 1122 1188 1161 1131 1075 1043 1064 1017 1055 1011 1017 1023 962 1011 1033 993 1038 971 974 1007 981 920 889 890 849 852 838 867 837 836 893 816 864 829 804 852 825 779 750 798 749 795 783 723 742 734 760 809 724 752 717 708 757 834 740 760 693 755 772 800 748 774 814 812 815 798 834 796 807 793 804 781 807 811 889 844 802 768 846 795 725 802 864 824 818 816 774 818 757 864 809 859 944 972 992 1074 1053 1146 1173 1212 1324 1273 1270 1130 1114 1013 987 938 899 833 914 822 916 844 889 926 1015 985 968 995 950 913 919 854 855 796 783 786 858 902 920 912 869 887 845 843 788 778 801 773 742 768 798 834 853 933 923 1080 1204 1347 1391 1377 1356 1369 1382 1364 1310 1290 1274 1292 1274 1231 1221 1153 1096 1067 1104 1064 1089 1133 1014 1042 1003 983 940 967 931 979 991 911 883 857 831 725 748 738 722 702 672 717 706 685 696 687 715 666 677 664 700 658 660 649 664 683 709 710 712 690 714 765 742 767 760 736 683 710 686 725 680 698 707 692 674 663 659 653 689 706 692 723 756 683 674 701 731 676 720 710 705 728 704 777 765 875 929 998 1059 1183 1208 1294 1209 1137 1121 935 918 829 798 797 771 805 848 803 836 890 989 976 965 971 980 908 879 812 806 777 780 768 734 750 743 761 688 690 732 681 708 697 672 740 704 699 762 674 706 700 689 694 722 736 709 758 771 778 807 822 884 952 1073 1154 1249 1354 1494 1556 1575 1428 1346 1272 1082 1057 982 974 868 894 966 959 1001 996 1084 1148 1271 1323 1335 1347 1378 1175 1158 1016 1021 920 881 985 928 935 956 999 1041 1026 980 1006 922 989 975 920 948 933 908 859 863 909 894 913 970 900 924 988 905 914 968 871 878 896 932 993 966 962 1087 1094 1088 1108 1081 1135 1180 1135 1161 1161 1166 1157 1200 1213 1247 1190 1244 1238 1342 1372 1350 1382 1416 1461 1440 1512 1540 1597 1653 1660 1698 1749 1815 1792 1916 1951 1871 1928 2058 2009 2034 1930 1943 1851 1853 1921 1938 1891 1946 2011 1988 1929 2142 1994 1992 1815 1786 1669 1690 1555 1518 1464 1414 1400 1271 1361 1381 1346 1287 1343 1272 1301 1242 1155 1228 1081 1057 1065 1059 1018 992 958 979 997 949 932 975 930 963 933 931 872 985 958 942 946 970 961 948 972 960 986 939 965 930 972 893 992 994 1048 1019 960 918 934 940 980 954 971 927 980 975 999 987 1014 1070 1080 1115 1094 1040 1044 1041 980 1001 1009 1024 1048 991 1016 1026 1073 1112 1136 1212 1215 1239 1222 1329 1305 1347 1284 1323 1332 1353 1281 1180 1221 1121 1147 1104 1120 1144 1101 1081 1054 1037 1093 1089 1026 1082 1078 1048 1063 1086 1012 976 948 977 937 890 936 861 864 902 877 908 924 906 906 972 977 984 1117 1102 1259 1340 1458 1714 1865 2137 2138 2215 2023 1900 1852 1805 1688 1619 1531 1424 1396 1329 1298 1210 1299 1251 1434 1454 1465 1504 1467 1435 1357 1361 1235 1242 1204 1120 1074 1004 951 929 875 840 860 816 825 775 796 732 815 748 770 722 704 746 729 831 755 789 759 851 799 867 896 889 1046 1074 1080 1121 960 981 910 879 877 836 766 805 845 857 818 860 836 897 959 1051 1109 1001 1127 1142 1147 1184 1269 1285 1400 1448 1471 1342 1283 1270 1165 1236 1080 1120 991 958 1047 1078 988 994 1008 1080 1096 1175 1231 1174 1139 1058 1078 1022 1020 1044 937 970 955 907 912 930 843 901 890 860 805 824 899 916 822 870 833 788 833 802 799 835 785 784 852 812 857 789 779 825 768 784 802 731 732 696 730 733 751 702 721 710 741 680 743 748 727 723 710 705 677 699 688 678 702 664 658 640 654 680 682 705 729 647 662 676 655 679 727 687 723 758 749 784 841 829 859 770 803 761 740 719 705 742 726 694 687 702 738 700 716 739 762 792 776 827 809 815 777 784 802 737 775 719 767 710 737 763 748 692 718 696 697 710 736 742 744 807 771 824 788 866 831 857 895 971 1041 1099 1160 1247 1142 1097 1008 881 857 856 788 762 769 767 732 730 810 802 830 861 868 995 977 968 913 926 915 950 896 941 953 1003 1043 1131 1322 1298 1428 1324 1259 1219 1064 1020 953 956 825 890 749 803 817 853 809 890 869 843 907 1013 1034 988 944 963 915 814 802 752 782 732 713 735 687 673 683 686 681 670 692 619 724 709 803 750 725 745 842 789 838 868 841 815 758 725 731 708 731 671 721 650 652 672 660 727 772 705 680 749 739 762 754 706 792 706 674 690 698 647 662 652 685 652 622 678 689 666 653 680 684 608 657 679 607 633 732 647 709 676 742 712 706 673 720 693 758 714 747 761 741 810 772 796 731 836 827 876 807 834 785 816 842 871 856 809 896 930 923 923 942 910 925 968 962 989 907 977 941 977 1030 1012 891 946 930 1010 955 979 981 944 946 939 971 999 889 1023 967 987 1052 1000 983 974 1009 1067 960 1008 981 993 982 984 971 1000 1010 976 1067 973 1063 1115 1106 1085 1095 1084 1024 1082 1042 1070 997 1064 990 1045 1049 1052 1042 971 1020 961 973 1047 991 1071 1022 953 979 961 1040 896 967 954 951 911 965 978 933 869 912 901 897 967 913 916 935 928 849 941 906 888 975 902 876 968 939 955 953 986 951 968 939 978 1014 968 1006 1054 1066 1094 1115 1131 1177 1230 1280 1301 1377 1501 1461 1494 1572 1498 1447 1448 1511 1462 1458 1456 1449 1470 1395 1438 1489 1562 1515 1486 1592 1564 1531 1650 1576 1593 1671 1609 1620 1618 1644 1669 1752 1692 1735 1864 1840 1822 1940 1865 1863 1819 1895 1877 1775 1831 1747 1741 1729 1635 1628 1539 1590 1478 1480 1442 1533 1615 1481 1470 1496 1499 1391 1418 1373 1409 1296 1342 1357 1256 1306 1217 1129 1135 1143 1080 1041 1045 987 1004 993 933 966 959 922 935 930 866 918 910 892 918 863 933 889 863 797 881 854 863 876 902 872 889 855 863 890 858 901 919 995 919 930 875 854 903 786 869 901 870 896 891 813 894 875 866 922 905 887 893 892 969 928 994 988 938 946 1001 957 1104 1090 1191 1216 1183 1130 1193 1178 1226 1147 1217 1127 1063 954 1027 951 904 887 884 908 919 876 991 906 940 1001 1006 960 1004 963 1039 958 912 943 856 865 820 821 804 802 782 737 774 760 860 772 823 787 839 861 898 991 996 1025 1081 1190 1227 1283 1248 1198 1182 1226 1240 1138 1099 1012 945 974 887 886 889 830 865 833 886 928 958 935 943 932 987 953 989 954 947 969 922 875 865 804 769 822 821 794 809 872 864 932 983 1080 1084 1179 1264 1231 1261 1232 1089 1049 989 909 863 775 808 779 767 783 739 732 828 785 804 827 881 972 993 1025 973 902 928 950 830 787 753 743 749 714 697 744 761 778 771 802 909 978 978 1123 1256 1200 1209 1201 1215 1112 1076 1150 1176 1073 1094 1007 1006 894 933 906 919 959 948 1054 1109 1156 1147 1173 1149 1067 1003 1004 927 912 895 890 858 825 788 790 759 769 743 763 769 746 778 811 800 710 746 710 679 720 684 643 644 669 663 674 651 626 625 618 633 627 666 678 705 685 644 698 643 646 636 642 595 664 699 639 623 680 620 606 632 648 608 592 630 616 672 618 696 637 691 631 604 629 673 696 705 750 757 785 895 874 941 927 960 867 878 722 736 747 719 682 654 722 684 673 640 639 646 700 678 720 757 763 760 811 824 698 729 675 701 663 607 684 589 667 642 692 627 688 692 627 692 680 678 678 688 696 718 688 716 707 692 716 689 692 658 681 673 706 724 739 723 797 715 735 730 761 757 835 796 822 841 864 897 924 953 989 1124 1190 1246 1417 1565 1668 1725 1769 1851 1805 1812 1749 1606 1486 1239 1296 1201 1254 1122 1075 1101 1083 1141 1135 1126 1132 1263 1256 1290 1259 1369 1315 1291 1363 1286 1178 1092 1080 1051 961 998 959 873 865 937 795 825 762 842 821 795 787 782 749 759 799 772 744 710 736 705 712 733 705 711 761 714 738 706 686 691 717 697 697 713 760 804 835 906 889 1009 976 978 984 913 921 837 854 769 775 754 728 709 653 713 722 704 731 727 751 788 723 799 806 772 855 796 697 764 764 706 704 694 669 645 701 642 646 663 715 698 671 744 675 670 668 680 705 686 695 707 639 629 653 665 657 650 677 607 683 632 685 670 668 677 680 732 755 731 771 825 812 763 784 767 718 734 705 702 695 712 712 644 696 725 676 665 710 722 704 730 703 720 736 751 744 761 763 721 718 748 702 769 753 767 774 766 795 864 804 905 959 1024 1126 1194 1260 1368 1400 1444 1348 1322 1167 1117 995 945 939 941 933 845 856 874 845 896 829 897 889 930 910 1037 1093 1118 1120 1085 1026 983 979 960 948 845 862 829 876 824 801 830 795 740 742 729 799 812 787 761 803 818 790 713 760 784 784 755 804 851 832 836 913 916 883 889 944 949 967 1006 958 962 997 928 904 901 800 901 791 749 799 763 791 820 778 789 813 807 834 841 820 845 908 895 889 905 879 864 817 812 854 857 844 833 840 810 849 829 926 865 803 808 798 821 856 819 833 869 835 868 876 856 951 986 934 897 948 879 897 894 877 836 887 854 826 812 802 829 840 781 828 793 843 836 880 795 861 772 760 856 845 801 762 816 754 762 753 726 709 761 712 723 733 705 713 722 688 737 680 696 683 721 677 697 675 708 684 664 693 608 661 640 670 666 711 617 703 640 667 669 677 727 719 654 723 704 737 725 694 732 767 782 818 820 919 870 991 987 1108 1185 1203 1329 1314 1256 1235 1179 1137 1054 1020 1048 973 950 973 950 889 843 894 875 872 842 879 888 937 1003 1076 1069 1093 1194 1141 1274 1268 1226 1134 1106 1074 1090 1128 1023 928 942 860 816 787 757 738 758 708 677 693 698 727 768 798 804 820 789 772 731 830 788 747 737 716 734 717 706 657 697 659 661 660 644 593 664 658 614 625 602 682 614 591 656 634 624 612 634 615 554 630 644 639 636 664 666 702 683 686 761 724 811 900 899 1004 1112 1186 1192 1161 1123 1002 945 928 856 820 822 788 801 763 832 816 833 844 910 845 853 855 865 847 900 969 992 962 946 998 977 982 940 848 830 779 838 749 781 765 728 789 787 771 752 726 790 760 798 798 867 815 809 823 807 831 910 943 925 985 960 1030 1099 1169 1156 1340 1308 1222 1159 1012 1035 1026 915 948 878 906 931 953 924 956 977 916 991 1021 1029 1019 1088 1103 1144 1132 1235 1219 1282 1297 1185 1199 1186 1111 1195 1118 1128 1117 1134 1132 1164 1171 1156 1207 1178 1203 1165 1174 1161 1131 1118 1122 1098 1152 1186 1146 1078 1122 1156 1122 1156 1186 1146 1163 1160 1135 1171 1137 1096 1008 1086 1032 1063 1020 1026 984 1060 993 1001 926 886 915 947 883 942 990 952 914 876 843 912 926 853 870 823 861 788 868 804 788 854 775 771 764 829 773 816 761 781 787 795 769 791 761 800 793 799 795 877 847 810 858 829 879 852 906 947 941 917 851 887 847 826 845 820 806 794 830 775 805 841 861 879 847 844 881 862 918 951 968 995 1039 1128 1102 1162 1105 1120 1038 987 997 945 978 931 947 994 980 952 980 970 958 964 993 987 996 1003 965 913 941 1034 1046 1008 1059 971 1029 1010 942 1002 957 1000 991 1033 1000 1078 1046 1076 1108 1057 1163 1169 1120 1135 1066 1088 1039 961 943 965 930 889 948 849 914 884 778 882 889 823 892 839 896 874 889 883 913 913 915 957 964 873 900 854 857 881 771 835 801 797 762 727 741 753 770 787 794 754 766 739 803 745 776 824 761 736 807 859 871 780 738 823 780 797 834 808 922 929 909 908 991 991 1045 1148 1187 1118 1111 1076 1061 1044 987 1029 1075 999 1064 1083 1057 1008 1039 990 1009 966 973 927 918 945 911 974 947 912 963 974 975 982 958 943 921 886 949 960 932 848 898 873 885 911 869 851 788 876 860 816 849 844 879 806 870 895 1020 947 1022 1027 1131 1162 1168 1117 1067 1055 1034 1012 1060 1047 996 1019 1011 953 903 896 875 864 859 919 878 870 927 921 938 970 943 950 964 920 910 966 876 906 906 855 911 870 798 944 792 812 791 788 839 735 748 747 753 771 795 789 780 770 799 714 745 754 666 724 666 654 714 688 728 711 671 750 634 673 631 733 681 681 694 657 658 681 696 775 734 764 775 791 829 798 836 789 750 763 884 827 905 857 878 896 814 815 752 772 711 727 790 753 783 770 783 771 826 774 751 779 791 805 747 775 795 737 749 783 767 825 816 711 775 757 644 728 727 680 695 689 701 727 731 663 789 706 726 722 751 800 753 766 771 799 866 959 975 1100 1077 1086 1064 1007 979 896 903 846 873 813 850 885 835 879 881 859 896 839 830 795 789 810 787 828 823 764 864 841 900 855 889 809 840 850 781 722 797 796 775 770 801 848 847 883 886 887 907 897 912 891 878 828 797 745 769 764 708 741 708 729 725 692 712 682 735 728 703 750 767 750 770 789 799 764 796 789 808 777 773 744 713 737 739 679 729 734 722 738 709 720 685 715 692 701 692 694 728 709 750 666 736 734 696 691 750 739 701 752 763 780 713 813 804 693 797 778 796 786 745 774 767 802 753 775 780 754 714 760 743 755 763 717 746 761 782 767 789 809 755 752 779 779 819 786 836 838 774 833 803 839 827 786 843 841 803 828 821 843 896 853 869 870 880 905 926 939 916 937 909 894 1034 942 1040 1015 1065 1031 1083 1057 1055 1056 1086 1072 1082 1084 1081 1143 1091 1119 1131 1149 1246 1140 1251 1226 1285 1252 1228 1302 1351 1368 1327 1329 1380 1392 1361 1471 1440 1386 1437 1417 1370 1341 1316 1330 1313 1287 1222 1219 1154 1114 1186 1164 1172 1200 1243 1255 1131 1200 1153 1106 1206 1075 1182 1125 1191 1200 1170 1158 1169 1182 1159 1168 1152 1208 1205 1132 1141 1177 1126 1119 1089 1066 1037 1073 1018 982 993 1010 959 973 974 968 945 957 933 949 986 950 968 988 1025 972 960 974 962 997 1066 991 1027 1035 1015 961 1072 977 1021 938 989 979 949 965 1016 1047 958 964 1007 960 1029 952 990 956 1004 1018 971 957 899 954 1001 866 919 950 898 867 964 945 858 904 917 887 879 882 874 859 875 829 865 810 812 832 877 843 849 838 819 804 789 840 744 800 726 763 800 751 732 748 742 783 743 724 764 721 672 728 770 732 764 747 732 732 726 679 687 682 731 689 715 705 666 661 641 718 658 657 654 743 669 717 658 688 644 666 684 680 663 630 671 685 704 691 711 666 707 725 682 644 676 681 648 658 701 760 749 806 765 819 820 753 862 905 892 858 797 800 754 763 756 741 720 718 760 700 671 712 702 687 690 698 665 723 727 716 704 724 682 704 726 770 772 746 774 717 725 754 754 667 687 715 705 714 731 735 700 658 658 687 675 634 718 686 721 705 710 651 711 687 706 686 665 685 717 690 767 736 638 740 689 643 721 665 666 682 669 655 688 651 686 712 700 703 720 623 687 668 710 696 671 698 686 738 691 714 686 670 649 647 743 679 752 780 736 807 746 768 782 755 745 697 741 697 702 683 689 655 711 731 668 711 657 715 694 706 765 698 718 701 670 740 708 706 731 752 722 726 745 773 770 766 703 710 749 730 675 709 683 721 639 647 667 702 717 663 690 694 755 713 713 718 673 720 738 767 766 785 877 859 903 851 938 870 871 790 832 808 688 715 716 731 678 708 650 749 677 703 659 777 713 725 679 769 789 788 847 872 910 896 943</counts>
			</dataPoints>
		</scan>
	</xrdMeasurement>
</xrdMeasurements>