File: dataset/precursor_mixture/La(OH)3_Ga2O3_Bi2O3-alpha.2-min.xrdml
<?xml version="1.0"?>
<xrdMeasurements xmlns="http://www.xrdml.com/XRDMeasurement/2.2" xmlns:xsi="http://www.w3.org/2001/XMLSchema-instance" xsi:schemaLocation="http://www.xrdml.com/XRDMeasurement/2.2 http://www.xrdml.com/XRDMeasurement/2.2/XRDMeasurement.xsd" status="Completed" recordIdentifier="{FF9DAA82-F4A1-4BF9-BD7B-2DBC3F9B05D2}">
	<comment>
		<entry/>
	</comment>
	<sample type="To be analyzed">
		<id>dara-36-1</id>
		<name></name>
		<preparedBy></preparedBy>
	</sample>
	<xrdMeasurement measurementType="Scan" status="Completed" sampleMode="Reflection">
		<usedWavelength intended="K-Alpha 1">
			<kAlpha1 unit="Angstrom">1.5405980</kAlpha1>
			<kAlpha2 unit="Angstrom">1.5444260</kAlpha2>
			<kBeta unit="Angstrom">1.3922500</kBeta>
			<ratioKAlpha2KAlpha1>0.5000</ratioKAlpha2KAlpha1>
		</usedWavelength>
		<incidentBeamPath>
			<radius unit="mm">145.00</radius>
			<xRayTube id="1010048" name="Empyrean Cu LFF HR (9430 033 7310x) DK437873">
				<tension unit="kV">40.0</tension>
				<current unit="mA">15.0</current>
				<anodeMaterial>Cu</anodeMaterial>
				<focus type="Line">
					<length unit="mm">12.0</length>
					<width unit="mm">0.4</width>
					<takeOffAngle unit="deg">6.0</takeOffAngle>
				</focus>
			</xRayTube>
			<filter id="20010004" name="Beta-filter Nickel">
				<material>Ni</material>
				<thickness unit="mm">0.020</thickness>
			</filter>
			<sollerSlit id="21010002" name="Soller slits 0.04 rad.">
				<opening unit="rad">0.0400</opening>
			</sollerSlit>
			<mask id="22031000" name="Fixed mask 13 mm">
				<width unit="mm">9.00</width>
			</mask>
			<divergenceSlit id="22120001" name="Divergence slit 1°" xsi:type="fixedDivergenceSlitType">
				<distanceToSample unit="mm">50.00</distanceToSample>
				<height unit="mm">1.52</height>
			</divergenceSlit>
		</incidentBeamPath>
		<beamKnife id="29030100" name="Beam knife low"/>
		<sampleMovement xsi:type="spinningSampleMovementType">
			<spinnerRevolutionTime unit="seconds">1.0</spinnerRevolutionTime>
		</sampleMovement>
		<diffractedBeamPath>
			<radius unit="mm">145.00</radius>
			<antiScatterSlit id="22090040" name="AS slit 9 mm" xsi:type="fixedAntiScatterSlitType">
				<height unit="mm">9.00</height>
			</antiScatterSlit>
			<sollerSlit id="21020003" name="Large Soller slits 0.04 rad.">
				<opening unit="rad">0.0400</opening>
			</sollerSlit>
			<filter id="20030001" name="Large beta-filter Nickel">
				<material>Ni</material>
				<thickness unit="mm">0.020</thickness>
			</filter>
			<detector id="7010019" name="PIXcel1D-Medipix3 detector" xsi:type="rtmsDetectorType">
				<phd unit="keV">
					<lowerLevel>4.0</lowerLevel>
					<upperLevel>11.3</upperLevel>
				</phd>
				<mode>Scanning</mode>
				<activeLength unit="deg">1.021</activeLength>
			</detector>
		</diffractedBeamPath>
		<scan appendNumber="0" mode="Continuous" scanAxis="Gonio" status="Completed">
			<header>
				<startTimeStamp>2024-03-25T10:33:26-07:00</startTimeStamp>
				<endTimeStamp>2024-03-25T10:35:48-07:00</endTimeStamp>
				<author>
					<name>AutomatedUser</name>
				</author>
				<source>
					<applicationSoftware version="1.6 (94)">PANalytical Aeris Instrument Suite</applicationSoftware>
					<instrumentControlSoftware version="3.0.0 20211014">AERIS</instrumentControlSoftware>
					<instrumentID>2879380</instrumentID>
				</source>
			</header>
			<dataPoints>
				<positions axis="2Theta" unit="deg">
					<startPosition>10.02173288</startPosition>
					<endPosition>139.98435528</endPosition>
				</positions>
				<positions axis="Omega" unit="deg">
					<startPosition>5.01086644</startPosition>
					<endPosition>69.99217764</endPosition>
				</positions>
				<commonCountingTime unit="seconds">1.551</commonCountingTime>
				<counts unit="counts">389 380 417 385 377 371 364 388 373 382 346 382 377 372 329 349 323 380 351 353 352 354 325 382 363 334 310 341 385 340 320 310 312 320 307 321 327 299 354 304 269 312 307 328 313 321 270 327 279 305 295 281 290 306 309 311 278 267 255 268 302 299 259 253 277 305 266 240 289 212 270 296 253 242 238 258 256 256 250 277 275 231 242 236 231 232 260 256 257 229 215 214 276 228 259 227 225 247 238 239 259 244 209 232 240 212 220 235 239 219 242 189 242 264 239 269 251 254 287 278 284 322 395 450 561 691 876 938 769 592 394 362 291 265 239 228 244 241 231 196 202 211 152 197 213 183 202 186 199 210 218 200 200 211 223 166 198 197 177 185 199 165 179 195 163 197 231 167 155 163 143 171 216 179 175 189 159 182 158 145 190 130 168 172 167 163 179 173 183 159 148 200 189 145 164 187 228 220 241 321 309 333 278 231 216 209 200 166 172 172 143 162 137 168 156 151 179 206 193 253 203 171 149 155 133 144 156 153 151 139 146 133 180 161 169 139 136 140 149 129 146 148 128 146 142 129 144 155 128 156 152 139 133 106 152 119 141 144 133 152 144 154 173 184 203 207 164 136 121 130 123 141 144 127 135 107 137 125 136 106 122 130 149 141 137 121 131 133 131 142 119 116 128 127 129 119 131 130 139 130 101 131 104 122 121 127 130 116 122 112 104 115 114 125 142 119 113 124 141 116 126 124 137 155 139 152 173 271 267 234 138 142 120 122 116 130 111 123 116 105 130 143 139 149 123 144 121 140 133 123 125 160 195 264 469 509 326 188 165 116 103 134 130 117 114 141 119 124 103 121 116 140 153 131 154 160 195 215 284 415 746 926 648 440 347 362 548 653 871 1169 1792 3120 2712 1801 734 379 284 270 306 330 341 435 558 825 1013 1332 1065 782 443 361 261 226 190 169 184 161 151 151 160 125 133 123 115 152 143 128 133 110 131 131 136 128 146 109 139 113 130 148 121 100 131 124 179 150 169 172 191 209 198 237 276 295 298 319 344 394 415 489 564 650 713 720 624 563 446 344 299 252 228 205 173 180 207 179 163 213 203 203 190 232 235 225 260 355 393 464 529 591 609 601 533 469 376 315 268 270 206 178 166 137 155 132 127 156 143 157 201 177 183 179 128 134 135 127 145 172 220 388 779 883 693 589 744 974 769 571 325 212 175 157 135 133 140 95 110 109 130 139 158 241 180 160 109 99 106 109 80 102 90 85 124 102 123 82 113 95 98 109 119 135 121 182 228 418 431 363 348 292 239 248 237 292 328 216 230 173 130 103 118 135 112 109 158 257 204 200 154 148 116 109 100 73 100 109 105 94 109 116 105 80 106 85 99 113 101 109 170 213 137 145 134 122 110 131 119 139 127 136 162 154 256 339 288 230 189 118 119 109 99 124 121 125 95 147 129 153 146 174 184 191 225 167 162 133 110 124 122 115 113 91 93 116 98 121 115 107 150 142 161 235 310 402 448 455 506 441 394 319 268 232 156 140 134 123 121 134 179 180 115 165 97 101 78 75 79 67 78 79 75 108 89 71 67 70 76 77 75 77 74 89 72 64 80 75 58 88 111 104 157 147 121 121 95 83 72 82 85 132 173 121 121 131 127 124 149 164 157 190 263 229 202 172 111 85 88 71 82 72 78 90 78 96 90 88 97 110 91 69 73 82 60 57 61 58 66 57 82 74 67 73 81 58 65 61 69 64 67 71 63 78 66 91 84 93 80 97 82 80 74 86 83 81 88 82 66 77 73 61 81 87 134 145 113 91 99 73 85 73 89 88 82 90 94 92 95 112 122 102 115 98 107 118 105 99 108 163 265 558 535 323 349 252 154 94 83 83 96 91 76 83 81 101 98 149 161 167 145 116 119 117 111 108 110 109 95 153 148 112 90 100 82 103 109 99 142 141 154 165 192 263 263 280 275 294 356 367 400 486 606 633 584 582 475 363 307 278 221 167 151 120 125 126 107 114 106 113 101 155 206 170 171 163 136 110 107 115 102 123 158 214 212 148 166 143 113 73 84 72 83 94 101 103 68 81 88 78 76 67 93 95 92 84 105 98 89 64 81 76 81 89 92 79 80 106 80 84 98 154 187 176 129 136 144 179 216 146 141 141 125 114 107 94 186 290 349 178 225 242 125 90 76 86 64 91 79 72 128 225 286 167 140 164 100 79 68 56 48 66 62 69 62 67 50 66 60 51 49 56 46 59 64 66 72 77 79 67 72 66 69 83 61 72 94 98 86 81 138 264 428 207 180 262 182 119 109 119 119 157 174 156 167 187 240 307 199 188 181 160 118 102 95 100 126 217 179 125 150 148 131 113 118 117 121 104 107 112 113 118 113 88 68 81 78 59 71 76 70 70 82 69 83 65 83 69 69 90 76 86 83 117 106 118 148 131 150 205 191 220 211 204 177 146 127 108 113 113 169 172 132 143 126 131 114 130 101 94 123 111 111 129 122 119 158 230 234 199 162 166 150 149 123 81 92 80 81 68 72 74 74 62 72 79 83 78 85 100 88 100 90 89 85 84 80 83 97 94 100 95 106 91 79 81 88 97 77 106 110 105 107 96 86 94 79 87 76 63 94 76 144 163 117 100 90 120 91 123 146 119 95 88 91 92 89 67 65 95 96 108 115 91 143 163 117 118 121 118 105 105 85 79 73 76 58 72 67 77 66 91 91 74 72 85 66 80 109 117 124 110 106 125 138 125 139 151 165 149 207 198 185 178 169 163 151 141 151 163 135 168 164 206 167 172 198 153 126 161 147 113 133 100 132 91 87 94 88 94 91 82 53 73 69 75 52 60 55 63 45 66 77 72 57 83 71 64 72 66 123 100 85 63 92 96 82 70 72 62 46 59 117 114 112 131 87 90 92 93 65 63 65 52 58 49 47 67 64 37 50 39 53 52 59 73 95 103 82 72 56 91 72 69 54 56 52 50 60 48 77 118 133 107 103 96 139 102 86 84 75 72 71 61 71 64 66 74 91 117 88 86 88 130 166 139 148 172 165 145 183 173 120 118 102 119 84 72 68 67 65 84 78 93 80 73 69 80 89 87 68 85 84 104 113 93 75 77 73 78 81 68 67 90 81 118 190 127 135 127 111 120 113 88 55 51 73 53 77 62 92 86 57 63 71 89 91 101 105 87 66 87 101 90 79 72 61 65 56 57 70 69 63 76 54 65 45 58 44 63 66 61 65 61 49 52 60 71 63 65 71 67 62 53 85 86 73 51 62 59 74 98 88 114 88 76 69 81 114 62 62 71 64 58 68 70 52 48 50 50 65 52 49 58 53 50 39 42 64 72 62 65 91 82 69 91 80 97 81 79 76 89 94 81 75 99 90 83 86 80 91 84 94 82 52 60 93 74 72 86 85 71 87 120 122 124 121 124 123 137 134 147 161 171 176 151 143 121 115 117 114 96 86 80 79 51 85 61 71 77 77 75 64 68 59 78 90 91 81 92 111 96 70 74 110 90 84 55 68 68 75 77 109 90 77 55 90 80 80 67 50 75 94 102 100 65 53 70 73 76 56 70 75 130 110 87 71 63 86 121 110 71 68 60 83 72 47 61 52 45 47 68 61 36 38 42 56 58 74 76 65 54 58 53 71 45 55 51 64 44 53 78 59 53 65 50 71 86 137 183 141 88 83 122 114 114 88 70 61 78 58 70 45 59 67 56 61 99 74 52 47 57 71 67 68 72 59 55 52 53 50 63 75 60 52 75 79 59 67 62 64 61 74 79 107 104 96 85 91 74 80 99 86 66 64 73 70 66 63 71 72 97 80 64 63 83 64 66 82 68 75 76 76 80 96 78 75 81 68 76 86 66 50 67 56 54 47 59 52 57 45 50 46 60 70 110 101 113 94 80 65 61 92 92 86 72 56 43 60 64 55 62 55 49 60 45 69 57 53 78 79 82 78 61 66 88 86 74 83 73 60 73 50 76 76 72 87 80 87 78 66 78 99 77 86 82 100 91 90 107 86 77 108 73 77 78 72 75 94 85 79 65 70 49 72 57 68 71 83 55 61 70 70 99 103 89 91 96 81 82 75 72 89 85 116 98 88 67 83 93 62 58 85 73 76 67 64 61 77 67 71 79 77 93 104 84 81 69 82 99 71 91 73 57 58 71 71 75 84 76 84 69 72 68 77 75 74 69 56 53 44 50 61 63 64 61 62 52 47 72 77 56 76 73 70 64 73 66 57 54 77 73 69 84 72 66 75 70 70 64 49 69 68 57 69 67 61 68 46 65 67 58 76 71 53 57 58 62 54 60 71 67 69 64 70 53 66 47 72 73 75 68 78 71 89 83 82 81 102 94 108 98 128 113 135 102 112 108 92 94 101 87 100 101 89 91 66 58 80 87 105 89 90 86 105 80 83 84 66 74 76 81 74 68 71 71 62 66 50 52 46 49 52 62 53 59 47 47 43 59 52 51 62 71 65 62 66 42 63 58 60 68 71 50 58 48 63 75 68 51 54 63 70 56 71 64 49 65 77 62 60 45 40 52 61 50 72 47 61 59 49 72 62 54 59 60 59 53 44 66 67 83 80 97 82 67 73 63 73 74 77 81 88 78 52 50 66 61 51 67 90 83 75 75 54 66 72 87 70 71 79 77 69 64 74 72 67 83 69 92 78 69 66 76 41 74 71 95 65 63 72 53 68 77 76 59 67 65 73 79 69 59 77 67 85 69 90 67 76 81 95 96 114 93 92 63 94 115 100 109 113 91 83 81 81 77 82 100 86 69 75 71 74 76 76 66 60 53 65 59 62 48 67 58 70 71 55 46 64 49 33 55 68 74 74 61 52 48 70 46 66 66 62 60 77 53 61 69 54 75 69 67 80 63 55 68 62 60 64 43 58 48 54 58 61 59 68 50 52 55 58 53 59 53 52 59 61 59 55 46 67 65 64 71 66 59 57 65 76 83 73 74 88 62 75 89 92 70 58 77 87 73 58 76 80 83 55 75 69 70 100 70 80 72 66 71 75 77 68 73 65 67 53 78 66 77 68 80 85 53 62 75 51 68 80 71 66 83 70 82 71 73 55 92 61 57 73 87 82 90 81 89 63 67 86 59 58 72 94 71 87 65 74 62 60 72 73 68 56 70 65 68 63 52 82 58 66 66 71 84 63 80 72 71 79 68 64 71 82 60 69 95 81 74 72 62 61 78 72 64 80 66 77 73 70 61 60 67 59 54 63 57 56 60 57 59 64 67 69 51 45 71 44 81 69 51 51 53 44 57 51 68 46 67 72 68 57 48 55 74 59 57 58 53 64 64 75 77 76 94 84 81 97 72 66 80 76 82 69 82 98 84 78 81 80 70 82 72 71 86 75 90 68 87 72 76 77 69 87 65 73 86 82 72 81 87 75 77 67 78 75 63 75 70 68 95 81 73 81 73 75 73 90 78 57 88 88 66 69 71 74 71 87 68 77 58 55 67 71 67 73 87 78 79 50 54 81 76 56 68 80 65 81 73 85 86 71 61 71 68 68 69 71 60 75 46 56 86 47 51 64 60 51 68 65 49 79 68 76 58 74 51 45 76 69 53 69 62 61 44 62 63 78 57 44 59 48 73 68 67 68 76 74 96 57 74 56 61 47 84 69 70 77 75 62 64 57 52 63 57 83 76 82 72 59 74 58 62 83 97 69 60 69 92 71 67 83 89 75 71 87 75 68 68 66 64 68 75 68 57 75 67 78 98 65 67 65 71 54 50 72 55 52 73 52 72 49 58 59 60 60 47 50 61 57 46 81 41 58 73 47 57 68 70 44 59 49 65 55 52 61 71 52 49 63 51 46 62 51 62 57 61 63 70 62 60 57 75 58 51 58 63 56 54 62 43 51 42 63 66 50 44 51 42 65 56 61 67 77 73 74 74 71 65 72 57 62 68 64 58 71 83 100 69 90 69 65 81 67 76 86 90 87 77 79 69 75 86 80 85 72 82 90 82 74 81 81 74 85 76 77 81 104 80 81 81 59 72 64 71 74 54 50 61 71 69 69 67 71 70 68 90 71 81 97 83 95 71 79 85 90 69 94 70 95 66 92 70 63 74 70 77 88 79 92 73 72 90 82 67 76 73 82 72 68 73 76 90 91 76 84 96 69 75 75 73 108 101 88 79 95 100 75 93 88 76 68 93 80 83 101 73 96 86 70 87 70 73 82 79 92 75 90 88 92 81 68 93 98 97 98 88 56 74 93 74 85 82 93 76 82 75 80 73 84 71 76 82 100 89 93 85 92 80 75 97 74 80 86 83 120 92 102 85 103 80 67 72 69 86 65 75 87 102 87 83 86 108 93 85 73 104 69 96 77 69 81 59 66 70 86 67 69 77 75 60 71 65 84 82 82 80 74 91 85 96 111 97 114 85 76 96 77 91 92 105 89 89 87 77 94 71 80 118 106 102 68 84 84 78 80 78 80 89 80 72 75 64 75 53 57 71 77 84 91 75 84 79 67 66 51 79 71 67 78 82 87 70 102 100 75 77 83 75 82 70 86 97 75 69 94 92 114 85 82 111 70 97 123 96 95 89 101 82 95 83 105 95 110 108 98 100 98 79 101 106 105 86 83 90 84 100 89 95 103 104 87 82 88 93 93 113 92 98 85 97 80 98 86 88 81 83 96 101 124 105 73 84 95 83 105 90 92 101 92 92 100 92 100 97 94 91 101 97 80 88 118 106 94 90 109 100 100 91 93 101 100 88 96 95 110 75 94 121 101</counts>
			</dataPoints>
		</scan>
	</xrdMeasurement>
</xrdMeasurements>