File: dataset/precursor_mixture/Li2CO3_Li2TiO3_Y2O3_In2O3.2-min.xrdml
<?xml version="1.0"?>
<xrdMeasurements xmlns="http://www.xrdml.com/XRDMeasurement/2.2" xmlns:xsi="http://www.w3.org/2001/XMLSchema-instance" xsi:schemaLocation="http://www.xrdml.com/XRDMeasurement/2.2 http://www.xrdml.com/XRDMeasurement/2.2/XRDMeasurement.xsd" status="Completed" recordIdentifier="{9F14A6E9-ADED-4356-B419-04407F83C10E}">
	<comment>
		<entry/>
	</comment>
	<sample type="To be analyzed">
		<id></id>
		<name></name>
		<preparedBy></preparedBy>
	</sample>
	<xrdMeasurement measurementType="Scan" status="Completed" sampleMode="Reflection">
		<usedWavelength intended="K-Alpha 1">
			<kAlpha1 unit="Angstrom">1.5405980</kAlpha1>
			<kAlpha2 unit="Angstrom">1.5444260</kAlpha2>
			<kBeta unit="Angstrom">1.3922500</kBeta>
			<ratioKAlpha2KAlpha1>0.5000</ratioKAlpha2KAlpha1>
		</usedWavelength>
		<incidentBeamPath>
			<radius unit="mm">145.00</radius>
			<xRayTube id="1010048" name="Empyrean Cu LFF HR (9430 033 7310x) DK437873">
				<tension unit="kV">40.0</tension>
				<current unit="mA">15.0</current>
				<anodeMaterial>Cu</anodeMaterial>
				<focus type="Line">
					<length unit="mm">12.0</length>
					<width unit="mm">0.4</width>
					<takeOffAngle unit="deg">6.0</takeOffAngle>
				</focus>
			</xRayTube>
			<filter id="20010004" name="Beta-filter Nickel">
				<material>Ni</material>
				<thickness unit="mm">0.020</thickness>
			</filter>
			<sollerSlit id="21010002" name="Soller slits 0.04 rad.">
				<opening unit="rad">0.0400</opening>
			</sollerSlit>
			<mask id="22031000" name="Fixed mask 13 mm">
				<width unit="mm">9.00</width>
			</mask>
			<divergenceSlit id="22120001" name="Divergence slit 1°" xsi:type="fixedDivergenceSlitType">
				<distanceToSample unit="mm">50.00</distanceToSample>
				<height unit="mm">1.52</height>
			</divergenceSlit>
		</incidentBeamPath>
		<beamKnife id="29030100" name="Beam knife low"/>
		<sampleMovement xsi:type="spinningSampleMovementType">
			<spinnerRevolutionTime unit="seconds">1.0</spinnerRevolutionTime>
		</sampleMovement>
		<diffractedBeamPath>
			<radius unit="mm">145.00</radius>
			<antiScatterSlit id="22090040" name="AS slit 9 mm" xsi:type="fixedAntiScatterSlitType">
				<height unit="mm">9.00</height>
			</antiScatterSlit>
			<sollerSlit id="21020003" name="Large Soller slits 0.04 rad.">
				<opening unit="rad">0.0400</opening>
			</sollerSlit>
			<filter id="20030001" name="Large beta-filter Nickel">
				<material>Ni</material>
				<thickness unit="mm">0.020</thickness>
			</filter>
			<detector id="7010019" name="PIXcel1D-Medipix3 detector" xsi:type="rtmsDetectorType">
				<phd unit="keV">
					<lowerLevel>4.0</lowerLevel>
					<upperLevel>11.3</upperLevel>
				</phd>
				<mode>Scanning</mode>
				<activeLength unit="deg">1.021</activeLength>
			</detector>
		</diffractedBeamPath>
		<scan appendNumber="0" mode="Continuous" scanAxis="Gonio" status="Completed">
			<header>
				<startTimeStamp>2024-03-28T12:11:27-07:00</startTimeStamp>
				<endTimeStamp>2024-03-28T12:13:50-07:00</endTimeStamp>
				<author>
					<name>Instrument</name>
				</author>
				<source>
					<applicationSoftware version="1.6 (94)">PANalytical Aeris Instrument Suite</applicationSoftware>
					<instrumentControlSoftware version="3.0.0 20211014">AERIS</instrumentControlSoftware>
					<instrumentID>2879380</instrumentID>
				</source>
			</header>
			<dataPoints>
				<positions axis="2Theta" unit="deg">
					<startPosition>10.02173288</startPosition>
					<endPosition>139.98435528</endPosition>
				</positions>
				<positions axis="Omega" unit="deg">
					<startPosition>5.01086644</startPosition>
					<endPosition>69.99217764</endPosition>
				</positions>
				<commonCountingTime unit="seconds">1.551</commonCountingTime>
				<counts unit="counts">378 418 396 421 419 417 387 370 391 413 377 387 345 383 417 375 397 409 403 380 376 315 343 366 351 360 379 348 354 339 339 342 362 355 373 406 330 338 370 353 348 346 318 302 333 331 342 313 330 341 304 317 336 300 342 288 329 339 290 281 304 306 309 282 310 306 288 252 305 323 292 306 309 335 275 270 267 298 294 312 289 262 279 243 295 274 296 289 279 309 246 256 296 273 267 247 245 278 269 240 246 246 301 265 292 284 256 235 249 264 287 260 273 240 256 277 256 255 236 258 258 245 232 229 248 235 244 244 227 242 223 267 259 219 227 235 225 281 241 240 225 234 226 242 249 245 227 229 230 248 274 231 213 232 215 226 205 254 235 256 254 212 217 242 227 234 222 232 225 253 228 244 215 214 214 256 230 229 193 241 256 238 221 239 249 227 265 251 252 245 258 249 284 255 226 228 244 203 226 239 230 222 210 218 203 227 194 213 238 194 228 234 203 176 200 205 183 204 205 202 213 213 214 218 234 197 198 184 191 227 238 252 254 289 382 413 520 472 395 306 273 212 195 197 208 216 245 223 237 209 258 223 279 260 368 513 436 479 601 584 494 326 224 188 197 211 188 196 146 193 203 162 187 201 166 188 189 207 205 177 206 182 162 162 170 165 203 167 163 162 196 181 161 178 179 172 162 153 183 180 174 223 202 196 198 189 178 176 210 141 178 178 167 164 174 180 155 176 193 154 186 152 201 198 201 178 171 168 173 156 184 167 171 161 177 195 196 165 168 198 149 133 162 149 154 193 192 197 186 170 161 182 183 177 161 166 150 145 137 148 150 164 185 146 183 158 182 175 180 171 153 180 152 130 145 167 174 157 169 160 156 179 161 176 148 157 127 142 148 149 131 167 191 178 161 187 179 130 164 175 140 167 156 180 153 170 156 164 152 175 174 161 160 156 172 183 168 227 179 194 185 188 250 244 260 330 406 547 906 1474 2193 2758 2398 1575 999 558 334 360 316 292 216 240 214 176 171 199 195 186 207 196 202 205 219 225 243 236 242 285 315 459 720 1184 2349 3832 3431 2255 1130 433 322 297 218 216 221 218 165 186 163 177 178 182 171 163 174 162 160 187 224 255 295 362 347 333 291 259 204 195 184 158 163 139 145 182 160 150 146 162 135 148 135 165 155 142 149 157 150 141 125 131 140 187 201 183 176 158 182 150 143 146 149 180 202 227 259 344 506 691 727 536 426 276 218 229 228 257 196 189 172 152 140 150 148 144 139 137 173 165 171 148 135 162 155 146 172 161 140 168 181 162 182 206 274 437 865 1193 904 756 432 252 198 198 200 246 261 271 254 231 211 249 195 204 198 150 121 141 147 144 137 125 124 110 150 133 159 152 184 177 181 193 185 172 146 133 118 116 128 131 145 144 107 124 135 152 271 311 296 244 185 180 170 156 149 123 115 130 115 120 144 123 119 112 119 121 102 132 128 132 98 140 119 125 131 132 112 110 135 128 100 98 129 119 121 110 123 131 156 166 174 189 177 178 230 302 317 292 218 202 166 139 142 113 138 130 110 118 137 129 125 125 120 115 91 121 109 117 129 105 112 113 97 127 117 119 107 135 114 121 103 96 110 128 145 120 126 148 172 173 245 245 206 203 160 136 120 127 127 136 121 114 106 112 119 97 107 118 107 129 132 129 103 113 123 145 150 111 156 132 144 164 134 163 195 228 302 395 416 391 365 360 307 305 262 252 272 194 154 158 176 139 160 114 144 132 146 118 109 123 100 119 121 116 139 122 130 123 118 123 111 103 114 108 114 116 138 107 114 139 91 128 123 153 134 184 262 388 324 251 250 191 133 110 106 140 118 107 103 109 89 99 119 105 106 110 127 135 121 115 98 119 147 134 173 148 134 151 128 112 87 113 100 106 106 117 124 106 121 92 114 114 108 114 108 115 112 143 131 124 146 187 142 108 155 179 185 237 324 571 801 1006 926 699 656 521 338 249 190 169 147 143 153 125 135 103 156 172 203 154 159 181 135 131 94 111 128 134 131 95 129 97 89 133 135 124 141 157 178 157 152 134 140 135 134 106 129 136 127 112 155 131 156 183 249 386 820 1211 918 652 751 521 260 183 148 180 142 103 120 119 115 90 132 116 106 110 127 118 97 124 115 100 143 123 89 114 118 78 107 102 115 102 111 90 140 181 167 140 154 133 130 120 116 162 141 170 201 204 182 169 156 124 122 76 99 96 89 119 109 102 125 111 125 58 82 114 117 108 87 120 107 107 110 139 94 116 124 120 111 113 133 109 121 116 117 106 118 99 101 127 100 110 110 105 114 129 118 122 106 96 133 124 129 101 111 107 121 184 207 240 211 165 243 212 196 202 157 142 119 116 128 147 113 95 113 121 118 105 105 141 130 110 104 117 112 133 126 114 142 138 166 186 207 284 526 739 723 512 496 470 344 237 198 162 137 137 136 121 115 134 118 133 120 102 120 139 118 125 127 138 113 133 112 113 135 196 210 262 293 306 294 215 249 199 161 124 123 105 80 131 118 105 117 125 124 146 120 102 125 124 107 102 127 128 113 145 130 169 235 212 246 275 381 670 875 651 411 483 502 345 216 176 152 130 142 116 131 113 120 141 143 96 122 126 98 100 89 102 128 129 151 152 151 130 143 142 123 217 294 249 173 185 186 140 134 150 90 107 108 106 102 116 118 116 117 99 95 119 119 134 155 141 159 115 155 149 166 193 178 200 220 293 297 192 181 203 219 143 121 118 96 94 94 115 121 108 87 95 116 112 131 171 157 130 127 122 116 101 96 105 111 89 118 107 157 156 170 101 111 130 142 113 112 117 95 109 121 101 99 107 109 121 110 120 78 106 96 85 85 107 103 128 87 107 83 108 105 135 91 107 113 102 146 127 92 130 104 95 98 87 105 93 92 88 96 114 83 88 82 112 99 98 86 93 69 92 89 102 102 157 166 155 125 129 143 152 95 122 97 94 91 105 123 82 89 97 76 73 100 92 75 108 92 104 91 92 72 67 77 87 82 139 125 123 136 105 123 124 134 154 129 109 97 126 125 106 105 83 82 86 86 110 90 85 83 111 104 106 101 89 80 98 103 125 98 114 137 144 149 157 139 129 151 119 134 78 106 107 101 92 104 117 82 88 87 88 95 85 88 100 85 113 111 72 135 140 149 174 143 142 117 106 102 121 105 113 93 101 98 83 104 83 88 92 77 86 105 97 95 89 109 92 89 142 122 124 172 170 148 160 134 131 119 116 123 99 108 88 86 104 89 113 90 108 101 105 80 67 96 72 110 102 115 133 146 152 164 181 199 161 123 111 160 160 120 110 100 93 70 100 77 107 100 91 68 109 90 112 115 82 111 91 116 106 99 127 133 137 165 178 116 116 128 143 162 106 81 94 99 95 117 73 95 108 102 94 94 124 138 139 149 136 132 118 114 109 104 124 128 142 112 95 117 124 128 91 91 77 89 93 95 86 86 114 109 134 164 194 184 145 173 142 174 159 85 121 114 113 115 165 144 113 101 99 96 118 103 113 83 82 82 79 80 93 88 82 101 80 91 106 76 90 94 120 98 106 107 116 126 112 127 127 113 99 100 78 111 98 111 91 132 142 158 178 126 164 126 116 115 133 126 107 97 88 108 118 90 88 112 132 153 154 135 101 131 133 117 124 145 104 114 124 82 92 89 110 114 108 74 96 79 88 95 80 118 105 144 100 125 203 275 228 144 128 145 163 145 177 123 120 95 97 88 94 78 80 104 100 81 98 104 74 65 100 81 72 82 92 79 106 86 82 89 99 100 130 117 102 89 93 110 102 98 83 82 100 94 86 93 82 91 79 82 90 101 99 112 97 121 143 189 174 137 130 120 126 172 121 127 112 99 87 95 100 114 91 99 76 94 75 83 101 84 99 81 95 68 103 106 129 124 135 97 96 114 118 93 130 103 91 96 87 86 91 100 83 83 78 97 98 82 82 80 79 105 105 79 82 97 92 117 100 96 104 84 101 93 97 90 58 93 109 89 82 83 108 87 80 102 74 89 128 125 119 128 110 106 110 120 151 137 134 141 133 118 141 110 94 91 76 87 63 100 85 98 92 97 98 99 137 154 170 170 119 117 116 115 140 119 103 97 108 92 94 82 86 87 90 105 76 96 87 87 69 105 102 136 102 125 113 101 114 108 107 124 127 110 99 109 141 146 116 104 91 91 109 100 100 78 104 108 79 113 96 131 100 108 111 105 103 89 81 93 106 125 93 86 91 84 76 93 82 113 89 69 109 65 72 78 92 93 103 119 108 106 93 86 95 87 105 115 64 77 84 93 94 115 87 106 114 123 110 102 95 115 96 118 135 122 123 130 120 122 100 111 112 107 109 115 109 101 93 98 108 102 99 105 125 122 144 182 155 104 135 125 157 125 167 172 116 93 100 106 97 81 78 75 86 81 119 76 83 102 82 89 97 106 118 131 131 136 148 109 143 155 173 158 135 113 95 123 132 117 108 100 108 97 94 101 102 117 67 72 91 97 99 100 96 92 118 162 152 145 160 119 111 119 125 113 124 106 113 93 101 78 81 96 56 83 84 84 89 78 75 55 73 69 99 109 97 109 92 76 73 69 91 94 79 105 92 69 82 92 88 72 81 82 89 84 78 95 115 116 96 100 91 142 120 146 142 163 175 135 151 119 123 137 143 119 151 103 97 85 82 96 84 120 88 65 76 77 78 101 93 116 91 142 121 99 99 116 112 131 136 124 96 86 90 79 107 69 88 74 103 70 82 103 89 88 93 91 100 97 113 108 98 108 96 106 106 105 149 175 167 143 135 97 115 96 112 134 128 116 102 90 92 79 90 81 88 146 117 132 114 104 95 88 84 114 121 126 150 157 150 130 107 100 93 75 93 102 113 110 92 104 98 97 98 95 121 113 87 108 94 99 112 93 99 79 84 111 88 70 92 79 70 99 116 82 92 89 73 76 96 72 88 85 81 85 80 108 86 74 68 96 98 109 112 94 78 65 65 97 107 91 123 150 146 89 99 105 83 87 90 141 134 132 139 144 128 89 77 86 105 105 86 88 90 101 95 112 115 100 97 121 130 122 140 162 122 114 90 101 118 105 114 140 129 113 117 98 92 101 91 73 83 94 86 83 86 77 110 85 87 82 98 89 99 87 153 121 92 103 84 79 103 103 98 118 117 102 108 83 65 103 66 76 87 115 115 83 94 98 88 84 106 110 76 95 130 125 176 138 144 117 106 115 114 116 105 111 109 128 89 92 98 110 107 104 69 79 74 84 102 78 94 112 98 91 83 76 88 122 121 120 136 128 112 105 70 88 111 102 106 106 109 96 83 84 100 90 92 94 77 62 71 93 96 88 76 102 69 77 102 111 95 110 111 109 95 106 107 76 84 94 91 106 84 95 96 104 72 88 76 70 85 85 70 79 90 82 73 91 110 112 98 90 118 110 89 125 110 128 109 99 77 106 97 107 107 87 105 84 90 82 117 92 76 107 73 88 92 127 136 119 114 132 117 106 94 113 105 120 116 108 129 122 137 122 119 101 78 111 74 92 81 103 89 90 112 99 85 104 113 98 82 81 106 97 94 93 97 76 83 93 92 87 94 74 92 94 113 81 82 91 66 83 88 104 101 81 77 68 106 98 99 98 115 98 115 108 114 83 81 64 76 101 97 116 106 83 99 106 126 115 113 89 111 99 102 140 93 97 103 98 87 106 118 106 115 144 150 93 115 99 91 95 98 93 86 97 104 111 111 119 95 94 116 109 145 131 110 109 112 94 88 94 101 80 98 114 116 114 117 121 111 90 79 93 94 97 97 97 74 87 105 96 106 92 110 98 116 76 88 95 104 96 111 99 98 100 120 88 110 120 102 92 119 126 110 95 101 115 102 79 72 100 101 92 94 106 101 75 100 79 104 102 85 116 101 89 114 121 130 128 123 118 110 124 122 153 118 130 108 102 111 114 134 107 97 95 102 83 80 99 97 113 83 86 97 104 104 102 85 104 93 85 122 136 124 154 129 160 142 119 115 94 114 93 96 107 104 103 114 121 92 129 115 99 112 95 81 84 86 82 100 90 83 95 90 94 96 92 97 94 104 93 81 84 86 105 117 106 85 103 93 78 77 91 92 102 107 103 108 98 89 98 112 95 83 96 86 93 101 103 97 88 110 99 123 96 86 97 121 137 117 146 135 156 121 127 94 115 93 112 106 87 80 105 97 102 102 114 112 110 93 106 86 103 90 97 99 89 105 80 87 113 99 80 80 112 141 129 135 118 107 112 110 136 142 114 143 129 136 131 111 97 131 101 108 117 116 119 103 121 118 122 101 101 94 113 116 107 97 89 91 87 83 98 123 109 92 96 125 118 102 108 111 81 116 121 155 114 140 107 106 94 96 92 104 111 118 97 97 101 119 111 107 116 118 108 102 97 108 111 113 123 108 137 129 141 133 114 126 133 120 112 125 103 104 105 115 98 142 136 154 117 130 115 109 100 116 128 119 123 97 114 76 110 95 111 105 107 112 111 112 93 98 134 111 117 108 99 102 109 98 86 74 82 83 112 110 139 84 88 114 122 122 128 139 139 126 95 111 94 99 102 115 103 102 118 96 95 119 109 113 117 120 105 117 138 125 137 145 131 142 134 139 140 109 124 102 111 94 114 140 114 114 125 119 110 116 113 142 112 118 110 105 117 120 120 134 143 118 111 121 107 112 122 122 108 105 124 124 92 90 123 108 121 127 123 132 128 121 101</counts>
			</dataPoints>
		</scan>
	</xrdMeasurement>
</xrdMeasurements>