File: dataset/precursor_mixture/Li2CO3_NaHCO3_CuO.2-min.xrdml
<?xml version="1.0"?>
<xrdMeasurements xmlns="http://www.xrdml.com/XRDMeasurement/2.2" xmlns:xsi="http://www.w3.org/2001/XMLSchema-instance" xsi:schemaLocation="http://www.xrdml.com/XRDMeasurement/2.2 http://www.xrdml.com/XRDMeasurement/2.2/XRDMeasurement.xsd" status="Completed" recordIdentifier="{ECAEE3B8-558E-4518-A0C4-DFCCD67E61FF}">
	<comment>
		<entry/>
	</comment>
	<sample type="To be analyzed">
		<id>dara-4-1</id>
		<name></name>
		<preparedBy></preparedBy>
	</sample>
	<xrdMeasurement measurementType="Scan" status="Completed" sampleMode="Reflection">
		<usedWavelength intended="K-Alpha 1">
			<kAlpha1 unit="Angstrom">1.5405980</kAlpha1>
			<kAlpha2 unit="Angstrom">1.5444260</kAlpha2>
			<kBeta unit="Angstrom">1.3922500</kBeta>
			<ratioKAlpha2KAlpha1>0.5000</ratioKAlpha2KAlpha1>
		</usedWavelength>
		<incidentBeamPath>
			<radius unit="mm">145.00</radius>
			<xRayTube id="1010048" name="Empyrean Cu LFF HR (9430 033 7310x) DK437873">
				<tension unit="kV">40.0</tension>
				<current unit="mA">15.0</current>
				<anodeMaterial>Cu</anodeMaterial>
				<focus type="Line">
					<length unit="mm">12.0</length>
					<width unit="mm">0.4</width>
					<takeOffAngle unit="deg">6.0</takeOffAngle>
				</focus>
			</xRayTube>
			<filter id="20010004" name="Beta-filter Nickel">
				<material>Ni</material>
				<thickness unit="mm">0.020</thickness>
			</filter>
			<sollerSlit id="21010002" name="Soller slits 0.04 rad.">
				<opening unit="rad">0.0400</opening>
			</sollerSlit>
			<mask id="22031000" name="Fixed mask 13 mm">
				<width unit="mm">9.00</width>
			</mask>
			<divergenceSlit id="22120001" name="Divergence slit 1°" xsi:type="fixedDivergenceSlitType">
				<distanceToSample unit="mm">50.00</distanceToSample>
				<height unit="mm">1.52</height>
			</divergenceSlit>
		</incidentBeamPath>
		<beamKnife id="29030100" name="Beam knife low"/>
		<sampleMovement xsi:type="spinningSampleMovementType">
			<spinnerRevolutionTime unit="seconds">1.0</spinnerRevolutionTime>
		</sampleMovement>
		<diffractedBeamPath>
			<radius unit="mm">145.00</radius>
			<antiScatterSlit id="22090040" name="AS slit 9 mm" xsi:type="fixedAntiScatterSlitType">
				<height unit="mm">9.00</height>
			</antiScatterSlit>
			<sollerSlit id="21020003" name="Large Soller slits 0.04 rad.">
				<opening unit="rad">0.0400</opening>
			</sollerSlit>
			<filter id="20030001" name="Large beta-filter Nickel">
				<material>Ni</material>
				<thickness unit="mm">0.020</thickness>
			</filter>
			<detector id="7010019" name="PIXcel1D-Medipix3 detector" xsi:type="rtmsDetectorType">
				<phd unit="keV">
					<lowerLevel>4.0</lowerLevel>
					<upperLevel>11.3</upperLevel>
				</phd>
				<mode>Scanning</mode>
				<activeLength unit="deg">1.021</activeLength>
			</detector>
		</diffractedBeamPath>
		<scan appendNumber="0" mode="Continuous" scanAxis="Gonio" status="Completed">
			<header>
				<startTimeStamp>2024-03-24T15:52:15-07:00</startTimeStamp>
				<endTimeStamp>2024-03-24T15:54:37-07:00</endTimeStamp>
				<author>
					<name>AutomatedUser</name>
				</author>
				<source>
					<applicationSoftware version="1.6 (94)">PANalytical Aeris Instrument Suite</applicationSoftware>
					<instrumentControlSoftware version="3.0.0 20211014">AERIS</instrumentControlSoftware>
					<instrumentID>2879380</instrumentID>
				</source>
			</header>
			<dataPoints>
				<positions axis="2Theta" unit="deg">
					<startPosition>10.02173288</startPosition>
					<endPosition>139.98435528</endPosition>
				</positions>
				<positions axis="Omega" unit="deg">
					<startPosition>5.01086644</startPosition>
					<endPosition>69.99217764</endPosition>
				</positions>
				<commonCountingTime unit="seconds">1.551</commonCountingTime>
				<counts unit="counts">517 493 497 472 515 497 491 506 502 536 501 497 507 486 479 465 499 487 445 500 522 490 501 490 517 462 494 516 482 485 498 504 457 472 454 475 448 492 497 416 447 428 456 459 505 447 473 464 446 443 437 485 459 438 466 451 465 440 439 465 431 466 439 443 429 440 477 440 446 412 403 458 405 437 424 440 449 440 453 433 462 375 436 436 407 459 444 417 419 406 442 471 388 433 460 485 461 407 410 414 445 423 425 406 441 407 396 412 480 458 501 560 598 435 419 392 426 379 403 413 379 382 444 405 382 407 407 431 448 370 408 353 410 387 400 434 389 377 370 379 427 421 404 411 392 374 418 417 411 385 404 443 447 367 400 404 410 355 405 444 390 394 429 355 399 391 429 389 398 435 387 438 414 419 406 421 436 397 433 421 405 460 496 495 637 892 1547 1427 733 504 414 406 427 407 408 426 412 420 397 392 375 386 391 411 389 444 420 414 461 409 406 410 431 403 427 391 467 447 406 421 422 426 414 382 432 394 425 422 362 402 382 421 372 406 429 398 378 424 392 401 389 407 408 444 426 438 403 426 460 490 568 658 865 1166 1639 1386 927 488 436 427 401 415 417 403 457 403 469 459 463 376 415 361 375 407 394 380 391 379 402 374 360 391 372 388 402 394 361 420 389 419 396 379 381 425 443 408 421 401 482 523 580 591 563 523 433 373 415 433 422 465 553 611 612 450 420 379 399 394 437 395 399 405 371 391 396 379 434 369 364 379 375 396 417 365 378 386 372 378 418 406 388 402 369 428 375 447 499 611 773 1060 1524 1090 684 518 460 403 419 406 475 438 445 402 391 406 364 383 371 390 400 337 361 359 386 375 353 376 380 363 364 368 378 370 385 339 364 343 438 400 462 431 419 416 371 373 400 412 400 397 391 420 404 397 378 353 351 370 392 373 375 377 347 355 392 411 363 358 402 386 421 367 367 345 418 402 515 605 726 631 621 563 557 586 502 537 516 578 663 722 604 563 484 439 413 407 398 416 415 441 476 536 658 791 1218 1561 1715 1558 1376 1270 1654 2216 2011 1809 1554 1391 1213 892 706 574 466 511 416 433 446 406 407 432 396 432 427 440 428 419 469 530 572 714 863 1141 1408 1620 1521 1238 976 744 615 462 485 419 482 431 485 489 496 534 581 674 632 598 551 497 433 422 392 418 397 393 413 379 357 358 401 404 427 458 539 521 541 455 411 408 394 384 387 418 420 454 437 466 491 583 654 802 757 650 593 592 533 656 771 1090 1458 1274 1030 758 550 446 483 452 477 448 475 503 514 544 586 624 705 910 1149 1470 2044 2638 3177 3340 3521 3065 2566 1891 1463 973 791 725 668 613 642 717 753 670 653 555 445 413 462 446 436 384 394 427 390 428 419 451 485 565 722 833 900 807 673 531 460 490 486 517 474 492 432 460 452 436 401 417 434 423 450 454 424 439 451 482 510 502 566 568 597 658 708 759 946 1004 1264 1636 1923 2504 2890 3132 3150 2800 2562 2232 1814 1717 1438 1298 1068 905 777 637 560 555 492 511 518 584 615 606 621 546 488 457 412 465 543 552 501 443 447 419 399 427 396 384 375 378 421 402 446 470 538 679 860 1120 1010 876 701 543 412 414 386 371 415 335 388 324 307 343 367 333 345 367 334 353 353 371 348 320 341 336 348 350 342 358 368 351 367 360 339 362 312 374 362 354 395 352 349 414 387 373 376 360 397 376 324 331 332 374 361 340 378 367 392 432 418 386 406 405 353 369 345 356 361 357 330 331 342 348 316 351 360 368 353 357 371 459 528 571 607 665 629 544 492 438 388 366 357 369 349 385 337 364 319 333 329 364 362 365 342 380 376 371 340 414 359 376 382 373 388 407 418 484 510 601 580 502 474 455 421 425 369 354 347 360 349 317 369 317 346 358 412 439 423 447 361 351 323 304 311 350 334 347 366 380 370 359 389 387 434 459 520 513 481 464 418 418 408 375 382 354 371 392 356 403 388 449 479 609 651 715 814 993 1006 1179 1236 1168 1045 987 795 691 618 579 474 468 395 400 414 377 400 428 311 378 342 359 362 363 364 368 360 380 359 398 365 392 358 334 365 369 368 379 346 398 367 333 334 341 330 335 299 352 324 321 347 331 353 358 350 338 330 339 389 404 422 395 339 357 326 346 323 331 296 337 301 330 320 322 331 345 318 308 356 350 334 335 340 340 374 374 418 441 403 422 437 457 454 389 375 359 322 375 378 371 387 366 414 406 480 493 497 452 511 477 441 483 432 413 413 387 382 366 371 343 354 382 374 340 355 401 388 375 369 360 366 369 365 310 359 345 346 314 335 305 284 319 360 327 336 329 396 386 403 383 371 373 345 309 316 351 346 286 339 330 308 366 331 336 347 342 392 348 362 324 342 326 293 327 311 304 307 363 389 381 359 385 402 450 434 555 671 874 789 627 527 566 404 380 374 371 347 329 363 330 417 386 386 435 396 426 429 427 415 464 442 543 603 626 668 682 615 672 650 602 550 522 503 442 468 386 432 380 428 407 455 414 377 383 377 393 409 386 412 361 343 302 376 338 359 370 438 416 398 410 405 424 408 362 353 349 326 331 333 302 326 312 354 352 343 355 371 347 358 378 384 422 365 436 489 437 417 433 473 422 463 423 451 501 547 536 590 727 704 750 740 663 692 630 585 531 474 401 395 383 360 332 322 375 386 358 355 339 323 344 342 332 350 368 389 389 318 345 393 343 319 333 318 335 358 337 360 385 350 390 387 356 341 375 384 363 346 344 351 334 347 313 348 315 330 330 303 315 335 349 334 368 306 295 292 328 334 343 300 326 360 318 376 363 321 319 331 315 334 331 386 359 355 394 404 449 463 466 439 467 535 511 521 560 528 593 596 578 534 560 547 552 575 638 610 655 700 671 640 575 603 535 550 495 418 389 377 381 321 353 325 339 352 364 378 363 346 352 364 379 394 393 386 379 407 379 400 458 493 493 511 563 557 596 631 696 700 645 598 551 505 506 436 445 422 361 371 371 377 367 320 330 337 337 328 319 342 345 322 286 294 365 367 385 383 362 316 384 358 358 351 300 327 310 290 301 341 324 333 335 316 309 310 303 300 310 328 323 317 302 314 317 340 350 336 323 294 335 282 289 307 294 301 306 346 285 340 257 276 278 302 315 303 308 267 297 287 302 363 339 354 290 326 312 333 309 342 375 328 414 379 425 420 416 436 411 398 412 382 369 399 354 374 364 351 364 326 321 333 361 321 264 287 270 328 327 319 286 291 315 325 323 323 303 310 327 306 306 323 355 319 358 338 305 299 301 292 301 314 314 334 344 348 353 348 342 368 417 384 409 445 506 480 503 437 472 431 428 462 430 431 469 368 361 378 350 331 348 318 327 316 317 306 284 301 305 300 271 308 318 307 297 315 270 299 298 280 301 302 327 347 298 326 281 264 281 286 290 285 297 263 315 312 298 285 293 293 303 282 300 288 271 263 270 278 307 270 298 291 291 291 264 272 308 292 267 308 280 263 323 302 318 293 303 286 290 276 303 270 299 297 290 318 339 303 292 326 297 292 306 303 276 285 253 305 292 270 303 301 267 276 305 316 321 326 279 320 308 321 336 334 301 324 324 305 284 311 281 283 307 307 297 312 315 299 278 260 284 272 311 286 311 280 299 296 318 315 285 299 315 307 282 322 314 294 304 293 316 293 309 343 300 322 287 336 314 324 373 356 381 373 362 365 364 379 340 373 363 365 343 335 362 358 385 347 357 383 371 324 360 327 339 335 332 376 339 374 323 352 335 331 330 324 313 328 334 322 279 308 281 290 304 293 297 311 254 282 298 298 284 294 306 293 275 305 294 322 310 271 277 276 289 295 318 275 284 290 299 269 279 305 288 291 255 304 292 245 251 280 270 309 296 295 293 331 347 286 310 320 279 318 321 280 304 331 336 325 312 316 274 302 305 301 268 272 299 327 288 288 289 285 282 283 290 307 272 270 303 329 298 294 308 294 269 275 306 275 268 287 290 306 283 279 272 286 278 291 289 276 256 272 302 280 260 295 318 307 268 301 289 312 272 283 306 287 294 304 292 306 326 326 308 329 359 320 312 321 383 340 313 322 327 343 316 331 326 297 315 312 282 301 317 288 302 289 281 248 296 286 271 258 277 274 283 275 277 276 305 275 295 312 335 306 291 305 294 287 294 281 305 303 296 283 306 300 283 314 267 302 311 310 296 297 287 317 297 296 316 321 275 279 280 286 269 279 299 262 266 277 300 279 287 314 283 296 265 298 300 283 319 267 300 239 270 252 276 294 261 296 253 304 276 278 269 286 270 279 275 260 299 280 291 298 299 280 302 308 303 288 287 302 273 282 284 281 293 266 294 283 289 283 314 291 296 276 279 278 285 315 312 285 288 287 281 285 256 279 306 295 299 262 300 272 285 249 276 297 298 291 293 307 300 270 325 300 288 286 297 283 299 294 267 266 274 252 262 291 269 275 319 253 252 298 290 286 312 284 268 274 293 282 275 341 295 295 290 308 324 274 300 272 309 317 310 326 309 298 356 298 308 344 294 318 305 304 310 292 319 312 321 292 293 320 325 314 312 305 287 347 293 286 297 327 306 305 277 304 295 281 292 276 283 274 278 277 290 275 277 247 292 272 280 238 278 276 297 292 257 271 262 321 275 278 296 274 275 278 282 294 264 301 298 271 277 261 288 278 289 298 288 291 285 284 287 301 294 294 278 268 284 279 281 307 313 303 281 268 265 273 319 309 311 323 269 271 290 323 296 317 350 359 374 351 357 351 311 377 308 293 332 337 308 317 275 306 304 331 288 257 282 265 296 270 283 268 336 274 255 284 265 247 275 265 273 272 268 266 238 240 272 260 274 309 269 274 262 248 301 267 240 285 271 268 269 278 282 259 287 284 248 271 294 274 285 276 263 264 253 294 253 293 253 263 250 246 304 290 285 309 270 282 290 318 315 284 275 337 295 341 302 283 290 314 275 308 256 295 285 291 276 242 275 281 251 297 264 273 289 218 258 286 290 287 271 274 279 297 290 257 293 260 302 295 267 279 307 315 267 286 264 282 297 309 294 283 316 280 286 307 282 277 292 273 277 278 300 278 306 285 299 273 312 339 330 326 303 301 311 324 295 320 315 343 293 305 289 297 303 296 269 347 280 314 339 298 324 299 315 308 324 317 329 301 269 334 294 289 282 304 281 303 285 276 270 296 296 295 294 287 267 288 271 317 284 287 280 272 271 297 301 286 295 272 259 314 301 266 317 316 307 275 315 270 293 277 293 312 316 265 317 288 313 309 323 310 295 310 297 321 279 325 294 303 301 296 328 296 299 323 321 280 292 297 302 289 283 291 300 283 275 289 307 286 297 293 329 312 282 267 298 266 295 271 297 292 293 305 256 281 305 287 274 263 296 300 286 328 263 300 270 297 255 308 284 281 282 250 285 249 277 274 291 278 254 292 283 274 281 292 274 292 293 279 296 272 295 288 294 289 265 279 320 306 304 261 274 299 292 255 294 282 280 251 287 257 262 261 259 292 285 256 265 234 269 276 278 309 271 280 303 280 278 287 280 268 317 256 272 251 298 265 269 267 328 306 296 278 300 327 282 302 329 315 294 306 273 299 325 344 331 315 315 324 320 357 311 320 344 328 308 314 345 294 326 326 356 317 304 304 327 312 303 332 310 339 292 303 303 302 301 297 285 283 317 271 282 301 263 299 277 289 252 214 283 293 275 270 272 277 301 281 280 259 292 265 267 302 288 241 289 279 282 287 258 240 275 244 277 265 283 255 270 295 269 275 275 275 279 274 260 276 278 268 301 238 267 266 258 300 265 268 275 293 296 252 237 272 273 265 287 274 284 263 268 250 270 281 285 262 277 297 250 263 277 257 255 279 273 252 290 262 256 296 270 275 283 278 290 277 257 288 280 271 288 287 266 279 286 245 278 252 323 259 259 258 254 263 309 264 263 283 272 302 263 295 276 259 278 300 308 291 291 301 288 261 317 298 296 313 277 284 308 287 271 336 301 290 335 298 282 298 325 287 321 310 305 289 303 307 291 315 318 314 337 279 285 319 278 256 307 309 306 283 291 295 289 298 290 295 297 282 268 304 239 220 273 293 261 253 303 300 284 247 294 284 263 305 259 272 255 248 293 296 305 280 267 280 306 285 279 306 280 288 279 272 260 297 281 272 278 290 276 273 298 288 301 289 319 297 293 293 288 295 291 282 287 310 305 298 279 292 335 307 291 301 324 282 320 305 301 278 329 268 299 287 302 309 309 282 296 275 343 307 303 292 331 283 294 326 305 287 288 269 293 283 287 291 298 300 305 304 276 303 296 278 268 294 287 306 283 288 242 265 263 291 299 286 267 244 269 293 292 267 297 281 276 277 282 285 274 269 269 250 260 269 302 246 269 245 258 266 260 268 303 273 248 273 276 283 281 245 262 249 287 264 252 272 274 282 258 233 279 277 281 228 252 277 260 301 255 264 287 277 263 274 256 243 274 295 286 277 252 277 258 282 291 271 237 243 282 263 260 253 245 278 246 283 294 259 256 273 260 277 248 278 242 244 258 275 275 275 262 317 285 251 282 256 268 260 309 268 297 252 254 289 276 285 278 263 276 313 280 278 294 302 280 263 304 283 282 276 285 265 321 269 276 278 264 290 294 306 278 282 279 276 265 272 295 281 272 321 307 303 302 257 268 270 265 249 254 268 275 280 267 292 265 265 271 293 285 262 277 254 304 316 320 267 302 273 295 271 305 274 251 272 302 283 279 304 283 272</counts>
			</dataPoints>
		</scan>
	</xrdMeasurement>
</xrdMeasurements>