File: dataset/precursor_mixture/Li2CO3_Li2TiO3_Bi2O3-beta.2-min.xrdml
<?xml version="1.0"?>
<xrdMeasurements xmlns="http://www.xrdml.com/XRDMeasurement/2.2" xmlns:xsi="http://www.w3.org/2001/XMLSchema-instance" xsi:schemaLocation="http://www.xrdml.com/XRDMeasurement/2.2 http://www.xrdml.com/XRDMeasurement/2.2/XRDMeasurement.xsd" status="Completed" recordIdentifier="{2AE5B694-86C5-4BA5-B02B-79976FD1A320}">
	<comment>
		<entry/>
	</comment>
	<sample type="To be analyzed">
		<id>dara-15-1</id>
		<name></name>
		<preparedBy></preparedBy>
	</sample>
	<xrdMeasurement measurementType="Scan" status="Completed" sampleMode="Reflection">
		<usedWavelength intended="K-Alpha 1">
			<kAlpha1 unit="Angstrom">1.5405980</kAlpha1>
			<kAlpha2 unit="Angstrom">1.5444260</kAlpha2>
			<kBeta unit="Angstrom">1.3922500</kBeta>
			<ratioKAlpha2KAlpha1>0.5000</ratioKAlpha2KAlpha1>
		</usedWavelength>
		<incidentBeamPath>
			<radius unit="mm">145.00</radius>
			<xRayTube id="1010048" name="Empyrean Cu LFF HR (9430 033 7310x) DK437873">
				<tension unit="kV">40.0</tension>
				<current unit="mA">15.0</current>
				<anodeMaterial>Cu</anodeMaterial>
				<focus type="Line">
					<length unit="mm">12.0</length>
					<width unit="mm">0.4</width>
					<takeOffAngle unit="deg">6.0</takeOffAngle>
				</focus>
			</xRayTube>
			<filter id="20010004" name="Beta-filter Nickel">
				<material>Ni</material>
				<thickness unit="mm">0.020</thickness>
			</filter>
			<sollerSlit id="21010002" name="Soller slits 0.04 rad.">
				<opening unit="rad">0.0400</opening>
			</sollerSlit>
			<mask id="22031000" name="Fixed mask 13 mm">
				<width unit="mm">9.00</width>
			</mask>
			<divergenceSlit id="22120001" name="Divergence slit 1°" xsi:type="fixedDivergenceSlitType">
				<distanceToSample unit="mm">50.00</distanceToSample>
				<height unit="mm">1.52</height>
			</divergenceSlit>
		</incidentBeamPath>
		<beamKnife id="29030100" name="Beam knife low"/>
		<sampleMovement xsi:type="spinningSampleMovementType">
			<spinnerRevolutionTime unit="seconds">1.0</spinnerRevolutionTime>
		</sampleMovement>
		<diffractedBeamPath>
			<radius unit="mm">145.00</radius>
			<antiScatterSlit id="22090040" name="AS slit 9 mm" xsi:type="fixedAntiScatterSlitType">
				<height unit="mm">9.00</height>
			</antiScatterSlit>
			<sollerSlit id="21020003" name="Large Soller slits 0.04 rad.">
				<opening unit="rad">0.0400</opening>
			</sollerSlit>
			<filter id="20030001" name="Large beta-filter Nickel">
				<material>Ni</material>
				<thickness unit="mm">0.020</thickness>
			</filter>
			<detector id="7010019" name="PIXcel1D-Medipix3 detector" xsi:type="rtmsDetectorType">
				<phd unit="keV">
					<lowerLevel>4.0</lowerLevel>
					<upperLevel>11.3</upperLevel>
				</phd>
				<mode>Scanning</mode>
				<activeLength unit="deg">1.021</activeLength>
			</detector>
		</diffractedBeamPath>
		<scan appendNumber="0" mode="Continuous" scanAxis="Gonio" status="Completed">
			<header>
				<startTimeStamp>2024-03-24T19:08:06-07:00</startTimeStamp>
				<endTimeStamp>2024-03-24T19:10:28-07:00</endTimeStamp>
				<author>
					<name>AutomatedUser</name>
				</author>
				<source>
					<applicationSoftware version="1.6 (94)">PANalytical Aeris Instrument Suite</applicationSoftware>
					<instrumentControlSoftware version="3.0.0 20211014">AERIS</instrumentControlSoftware>
					<instrumentID>2879380</instrumentID>
				</source>
			</header>
			<dataPoints>
				<positions axis="2Theta" unit="deg">
					<startPosition>10.02173288</startPosition>
					<endPosition>139.98435528</endPosition>
				</positions>
				<positions axis="Omega" unit="deg">
					<startPosition>5.01086644</startPosition>
					<endPosition>69.99217764</endPosition>
				</positions>
				<commonCountingTime unit="seconds">1.551</commonCountingTime>
				<counts unit="counts">404 375 375 386 364 350 401 361 341 391 366 363 382 376 372 376 352 342 387 343 331 333 388 355 302 366 360 340 333 316 332 371 332 363 331 314 317 304 342 317 289 306 303 311 296 301 306 293 285 300 296 266 283 288 276 271 290 295 276 253 273 286 296 293 300 283 298 318 285 245 229 292 253 244 277 272 268 300 259 274 243 282 220 269 242 273 249 253 269 236 242 252 250 214 251 255 228 238 240 239 213 266 223 246 234 253 196 225 229 247 249 236 211 229 235 227 208 182 194 217 212 215 225 223 207 231 221 228 221 228 225 205 214 211 224 234 239 268 231 237 261 246 212 184 206 201 182 206 180 210 199 162 224 194 238 220 192 203 215 200 231 202 207 188 170 186 176 169 179 203 185 158 192 197 205 185 218 198 176 207 188 211 185 200 175 217 193 191 227 227 239 247 231 224 210 230 195 194 186 189 162 192 185 162 182 178 197 155 170 179 161 163 165 166 195 186 171 157 174 200 181 150 191 154 170 179 163 175 201 169 195 174 152 151 142 181 179 169 182 158 176 160 167 161 202 177 173 158 180 169 186 186 201 218 288 445 493 345 231 192 172 159 155 169 166 158 164 152 171 140 156 154 148 163 110 133 158 156 159 157 135 161 142 144 146 148 153 143 137 129 146 140 160 155 133 139 143 147 141 154 148 142 169 156 169 156 126 127 171 146 159 137 145 133 117 163 132 154 125 127 140 160 164 126 143 130 127 136 153 164 135 127 136 127 130 152 115 141 144 152 157 132 176 144 173 177 169 181 170 147 161 157 237 285 350 310 254 176 141 141 137 132 156 139 143 147 142 140 137 127 106 127 162 136 136 121 115 117 128 136 145 140 167 193 164 175 225 189 180 207 201 230 226 248 281 288 305 355 412 539 842 1342 2355 4272 7605 8735 5924 3281 1322 701 550 394 380 283 262 220 221 171 169 142 176 164 156 168 153 155 132 149 154 169 128 128 140 151 146 164 173 176 169 174 175 145 126 119 142 152 154 161 127 129 119 115 143 180 194 200 283 320 287 247 226 204 229 294 352 311 291 224 176 186 135 169 145 139 149 131 136 144 127 148 171 148 189 186 195 199 323 419 678 1177 1809 1948 1515 1071 533 354 283 193 225 182 175 184 190 173 145 225 224 305 467 763 1313 2271 1993 1512 873 445 274 231 181 192 182 169 146 150 135 149 162 138 142 135 135 139 119 140 115 118 124 120 83 116 134 144 166 203 182 170 133 136 123 118 110 114 109 118 94 119 129 107 120 94 135 102 83 97 99 87 105 87 109 116 114 104 94 110 96 102 102 94 104 84 127 128 155 129 130 149 182 292 302 193 212 136 108 97 86 84 101 93 85 111 109 112 101 114 99 128 161 208 176 143 161 126 99 97 90 91 87 98 103 97 104 101 86 82 96 105 108 86 93 88 85 104 90 76 97 97 109 122 121 113 134 103 107 94 64 92 80 82 79 87 91 92 78 71 80 75 75 80 76 95 106 105 94 83 95 107 117 147 103 119 105 76 87 114 99 120 107 110 110 102 82 114 96 77 90 67 88 76 88 76 66 81 80 84 84 76 102 74 98 94 87 94 71 127 165 214 201 155 170 97 98 88 112 79 77 74 87 72 91 80 103 111 111 115 101 94 114 80 95 87 79 80 110 93 80 80 77 84 76 76 86 74 80 107 101 92 106 110 99 101 104 121 147 147 198 198 240 293 235 282 256 221 191 196 164 176 130 89 93 91 88 85 102 68 92 89 52 96 94 74 88 79 76 108 69 79 91 114 89 114 115 159 190 143 124 129 97 96 90 77 108 93 100 96 108 128 118 125 159 143 166 223 287 443 785 1518 1990 1288 1191 1060 573 351 249 186 177 180 200 195 254 373 622 940 786 585 546 357 225 162 134 121 135 105 110 97 84 93 92 83 75 94 82 89 100 99 125 75 96 88 98 90 94 96 74 105 148 173 155 127 111 142 126 119 121 114 116 105 116 82 91 101 95 78 88 87 74 83 97 67 89 82 93 85 76 84 106 83 100 99 87 93 125 94 103 81 71 103 75 78 100 81 84 80 89 79 84 72 69 97 65 72 90 95 77 78 73 115 90 150 165 211 198 169 161 129 119 93 75 77 101 94 70 85 78 89 74 77 78 108 80 76 88 62 75 85 85 77 77 78 63 77 69 76 81 71 91 78 91 91 83 98 86 77 75 84 84 94 88 89 98 81 95 83 118 142 137 98 100 128 102 112 119 134 167 185 265 353 625 1043 855 566 679 551 320 207 163 121 116 112 124 112 123 98 101 142 138 138 155 163 159 191 225 335 582 986 1621 1356 941 999 993 569 307 269 204 211 161 118 128 118 106 109 98 89 83 115 92 92 58 94 67 74 81 79 81 118 126 105 97 104 100 100 91 86 80 94 81 87 106 110 105 118 111 131 169 272 473 819 687 491 399 506 316 204 162 139 107 121 96 110 94 124 114 79 93 88 103 84 71 70 85 96 79 92 89 109 137 134 160 123 117 125 100 94 115 77 82 89 89 106 117 125 119 112 119 89 83 83 78 101 81 76 71 70 70 63 66 76 62 65 76 79 73 59 62 67 74 79 81 76 93 79 89 81 73 84 98 87 80 92 73 84 86 63 84 79 63 82 62 77 90 74 82 67 119 139 148 113 110 97 96 93 82 96 85 82 79 80 88 82 72 96 64 72 70 78 87 111 77 87 126 132 124 149 145 155 201 148 143 160 136 128 99 115 88 87 97 92 80 78 64 74 70 57 68 53 63 77 65 48 56 64 61 68 86 74 96 74 91 60 63 70 71 60 80 66 60 80 64 90 58 78 59 72 81 84 60 66 65 77 72 71 72 81 101 78 87 94 107 108 145 178 165 110 126 124 123 90 64 81 67 66 101 65 85 81 65 79 74 87 60 73 81 88 91 75 70 59 62 82 80 63 73 64 60 71 84 74 73 59 69 58 59 67 80 97 111 110 193 227 223 154 149 166 157 106 95 81 70 70 75 81 90 75 120 139 85 77 106 128 93 86 52 67 61 64 67 66 74 76 82 60 77 49 79 66 66 65 72 63 65 60 74 64 73 62 84 79 62 63 74 75 93 103 101 93 72 81 75 96 78 70 72 64 61 57 73 64 70 65 64 66 57 73 65 55 71 82 77 66 67 57 85 65 68 76 85 91 90 80 78 72 80 67 75 86 63 58 76 59 64 75 74 58 60 87 75 83 69 79 70 74 79 80 64 34 64 65 63 79 77 96 110 80 96 111 110 127 100 122 138 189 244 385 566 487 316 260 281 336 293 168 115 133 107 100 71 99 106 88 92 106 126 114 124 129 230 295 247 189 176 219 224 186 186 194 257 297 271 174 157 196 214 175 112 111 91 92 79 82 83 99 86 135 117 89 82 85 100 96 87 79 101 82 68 107 81 95 118 159 195 246 216 149 134 153 208 180 134 123 149 161 248 209 173 133 133 166 145 135 95 77 67 84 79 73 82 46 79 65 72 74 59 68 45 68 61 62 84 67 82 66 58 74 74 59 72 46 61 66 57 71 85 52 77 86 70 57 70 72 87 83 94 101 81 121 80 87 74 82 77 77 80 62 88 69 56 53 76 53 71 75 59 61 45 71 79 80 69 78 69 71 55 69 86 59 82 76 59 62 60 72 61 71 79 84 67 62 81 59 86 88 84 62 60 67 60 64 47 45 71 71 59 76 72 71 79 81 95 97 109 93 96 83 74 82 87 61 79 66 77 76 72 61 67 63 58 62 87 47 54 74 73 68 60 63 60 58 57 69 74 59 78 55 71 78 75 88 83 99 85 97 147 156 235 199 127 110 115 127 174 117 95 89 65 68 89 74 84 106 115 112 87 86 78 109 93 99 103 127 123 96 104 97 111 140 204 290 254 224 170 159 145 203 172 139 120 85 80 93 100 75 77 80 84 64 69 74 69 57 89 61 70 58 75 67 57 60 72 73 72 64 63 53 55 44 57 40 77 58 63 51 62 55 50 59 57 55 51 59 58 63 59 64 67 65 48 45 83 58 53 65 53 55 67 67 54 50 60 65 80 48 67 75 65 67 64 55 74 59 58 60 55 43 74 75 67 79 95 92 102 136 189 169 152 115 118 114 113 119 121 89 64 59 64 80 61 76 69 53 62 58 53 71 67 75 64 62 91 67 67 93 66 69 78 111 94 91 76 63 82 80 92 104 93 137 158 190 137 101 88 109 87 124 139 92 96 83 85 60 74 65 73 113 96 97 109 153 200 245 171 143 146 127 130 165 152 122 108 116 109 87 80 64 72 62 87 56 70 66 71 51 58 71 75 55 78 66 63 59 73 75 77 79 77 82 70 74 77 78 82 72 71 62 75 71 57 69 65 85 57 71 66 51 48 63 53 42 52 99 75 68 65 72 76 70 47 68 62 66 77 60 54 68 56 80 75 71 46 72 69 48 50 63 53 57 67 78 71 73 68 56 61 65 59 65 57 70 59 66 63 71 60 69 79 100 71 55 68 64 58 54 92 83 67 48 58 64 59 55 61 53 65 55 52 59 66 65 63 53 56 44 44 63 70 70 78 65 74 69 51 51 64 70 61 51 52 51 79 66 60 73 50 64 61 72 52 46 42 70 67 76 48 64 58 71 49 77 75 70 67 76 69 79 76 67 71 68 60 78 51 66 83 75 61 72 57 60 59 59 79 94 70 51 75 74 83 73 56 46 71 75 74 69 68 72 74 88 78 121 85 86 79 114 131 156 130 108 134 94 101 102 87 95 111 94 90 95 66 58 59 71 73 90 93 59 80 63 63 67 71 92 48 71 72 57 62 69 48 57 65 61 52 50 73 53 80 76 79 82 102 79 67 74 81 78 86 89 85 101 67 65 61 59 73 56 55 77 76 66 56 72 62 94 58 81 61 78 87 69 83 65 73 99 70 85 45 62 70 61 80 82 60 59 63 70 69 57 76 70 74 68 86 64 77 54 65 67 74 97 99 78 86 80 72 66 75 81 66 81 78 78 88 67 73 74 102 104 131 132 103 92 90 109 105 104 130 173 237 223 209 143 141 92 128 131 131 144 178 142 138 122 97 86 77 93 96 81 95 107 93 90 80 97 70 73 90 93 74 89 107 87 96 97 116 98 87 89 79 94 113 106 94 120 152 188 191 179 152 124 122 106 104 135 137 162 148 157 111 138 98 106 88 109 87 111 113 124 142 167 184 180 159 149 142 114 120 131 181 219 291 255 228 156 162 133 119 101 129 125 136 131 126 102 85 106 80 63 83 89 71 73 66 73 69 74 113 79 89 77 74 72 71 71 94 124 144 123 131 89 93 82 92 105 103 75 97 111 95 101 105 94 73 88 89 98 113 94 97 102 101 89 102 94 112 123 107 92 85 84 73 70 64 68 97 96 78 90 98 84 68 78 78 77 60 83 82 75 85 83 97 65 74 80 73 79 73 65 62 69 80 56 52 56 63 75 80 72 62 57 63 46 61 72 66 93 55 51 68 64 45 54 67 63 67 57 75 62 84 83 69 101 75 108 70 99 86 62 62 78 84 73 87 91 111 91 95 75 79 86 83 87 84 93 104 86 97 77 76 110 68 101 87 67 100 118 125 133 124 118 97 108 74 81 92 91 95 88 91 84 94 80 69 68 84 79 73 74 88 69 66 66 54 66 85 78 71 74 73 54 56 93 58 64 65 55 67 78 91 69 59 76 71 76 77 72 63 61 61 69 68 78 69 69 94 84 79 73 56 72 60 72 65 65 61 65 78 84 72 85 67 58 61 76 72 81 90 51 73 70 72 65 70 72 72 71 73 83 86 78 74 76 76 66 66 70 74 87 105 86 98 105 81 99 103 97 64 87 99 101 87 111 103 88 135 128 117 135 94 96 104 94 101 90 88 89 103 94 115 97 105 105 86 111 97 103 86 103 89 73 88 95 68 75 83 79 90 92 86 90 73 81 83 73 84 87 68 99 71 90 78 75 81 73 73 91 81 96 83 94 78 79 74 83 77 93 94 84 71 109 106 96 105 116 93 73 54 61 95 83 91 96 82 80 75 80 101 85 81 49 78 71 72 98 86 64 90 66 74 77 107 97 83 73 73 70 93 100 74 109 94 119 139 122 103 110 81 89 79 105 86 89 102 85 119 104 112 124 128 114 98 99 113 86 108 119 100 115 115 129 120 145 134 140 120 90 123 76 91 100 105 111 113 116 109 117 91 101 83 108 99 96 93 109 102 105 82 100 121 120 160 149 195 162 148 158 115 113 101 92 107 105 125 104 96 114 104 138 130 128 108 91 82 98 109 81 106 95 76 76 89 81 79 73 68 95 76 76 60 79 86 72 71 70 75 76 89 81 89 96 78 78 82 69 70 88 82 71 80 86 88 83 94 72 80 81 102 96 108 118 109 98 93 75 90 89 70 134 88 101 94 107 96 105 99 99 103 110 96 124 117 118 114 138 127 145 149 119 98 112 91 123 72 102 105 95 107 96 120 102 111 120 123 100 88 98 85 116 103 89 93 100 97 70 89 74 92 72 93 72 84 71 53 101 86 90 78 97 89 107 83 83 82 80 79 70 88 89 73 90 75 87 93 100 80 84 61 85 50 102 83 80 72 62 82 77 76 97 65 90 109 85 73 82 67 67 74 91 79 94 77 74 72 79 72 69 74 73 60 101 87 80 74 61 71 74 80 71 73 75 84 77 52 65 83 80 69 96 75 72 89 63 77 89 85 74 81 93 68 89 81 89 79</counts>
			</dataPoints>
		</scan>
	</xrdMeasurement>
</xrdMeasurements>