File: dataset/precursor_mixture/Li2CO3_CuO_SnO2_Bi2O3-beta.12-min.xrdml
<?xml version="1.0"?>
<xrdMeasurements xmlns="http://www.xrdml.com/XRDMeasurement/2.2" xmlns:xsi="http://www.w3.org/2001/XMLSchema-instance" xsi:schemaLocation="http://www.xrdml.com/XRDMeasurement/2.2 http://www.xrdml.com/XRDMeasurement/2.2/XRDMeasurement.xsd" status="Completed" recordIdentifier="{65916AA6-EBD0-4170-8E33-E4B5F2417855}">
	<comment>
		<entry/>
	</comment>
	<sample type="To be analyzed">
		<id>dara-46-2</id>
		<name></name>
		<preparedBy></preparedBy>
	</sample>
	<xrdMeasurement measurementType="Scan" status="Completed" sampleMode="Reflection">
		<usedWavelength intended="K-Alpha 1">
			<kAlpha1 unit="Angstrom">1.5405980</kAlpha1>
			<kAlpha2 unit="Angstrom">1.5444260</kAlpha2>
			<kBeta unit="Angstrom">1.3922500</kBeta>
			<ratioKAlpha2KAlpha1>0.5000</ratioKAlpha2KAlpha1>
		</usedWavelength>
		<incidentBeamPath>
			<radius unit="mm">145.00</radius>
			<xRayTube id="1010048" name="Empyrean Cu LFF HR (9430 033 7310x) DK437873">
				<tension unit="kV">40.0</tension>
				<current unit="mA">15.0</current>
				<anodeMaterial>Cu</anodeMaterial>
				<focus type="Line">
					<length unit="mm">12.0</length>
					<width unit="mm">0.4</width>
					<takeOffAngle unit="deg">6.0</takeOffAngle>
				</focus>
			</xRayTube>
			<filter id="20010004" name="Beta-filter Nickel">
				<material>Ni</material>
				<thickness unit="mm">0.020</thickness>
			</filter>
			<sollerSlit id="21010002" name="Soller slits 0.04 rad.">
				<opening unit="rad">0.0400</opening>
			</sollerSlit>
			<mask id="22031000" name="Fixed mask 13 mm">
				<width unit="mm">9.00</width>
			</mask>
			<divergenceSlit id="22120001" name="Divergence slit 1°" xsi:type="fixedDivergenceSlitType">
				<distanceToSample unit="mm">50.00</distanceToSample>
				<height unit="mm">1.52</height>
			</divergenceSlit>
		</incidentBeamPath>
		<beamKnife id="29030100" name="Beam knife low"/>
		<sampleMovement xsi:type="spinningSampleMovementType">
			<spinnerRevolutionTime unit="seconds">1.0</spinnerRevolutionTime>
		</sampleMovement>
		<diffractedBeamPath>
			<radius unit="mm">145.00</radius>
			<antiScatterSlit id="22090040" name="AS slit 9 mm" xsi:type="fixedAntiScatterSlitType">
				<height unit="mm">9.00</height>
			</antiScatterSlit>
			<sollerSlit id="21020003" name="Large Soller slits 0.04 rad.">
				<opening unit="rad">0.0400</opening>
			</sollerSlit>
			<filter id="20030001" name="Large beta-filter Nickel">
				<material>Ni</material>
				<thickness unit="mm">0.020</thickness>
			</filter>
			<detector id="7010019" name="PIXcel1D-Medipix3 detector" xsi:type="rtmsDetectorType">
				<phd unit="keV">
					<lowerLevel>4.0</lowerLevel>
					<upperLevel>11.3</upperLevel>
				</phd>
				<mode>Scanning</mode>
				<activeLength unit="deg">5.020</activeLength>
			</detector>
		</diffractedBeamPath>
		<scan appendNumber="0" mode="Continuous" scanAxis="Gonio" status="Completed">
			<header>
				<startTimeStamp>2024-03-25T11:17:56-07:00</startTimeStamp>
				<endTimeStamp>2024-03-25T11:30:24-07:00</endTimeStamp>
				<author>
					<name>AutomatedUser</name>
				</author>
				<source>
					<applicationSoftware version="1.6 (94)">PANalytical Aeris Instrument Suite</applicationSoftware>
					<instrumentControlSoftware version="3.0.0 20211014">AERIS</instrumentControlSoftware>
					<instrumentID>2879380</instrumentID>
				</source>
			</header>
			<dataPoints>
				<positions axis="2Theta" unit="deg">
					<startPosition>9.99043322</startPosition>
					<endPosition>100.09495370</endPosition>
				</positions>
				<positions axis="Omega" unit="deg">
					<startPosition>4.99521661</startPosition>
					<endPosition>50.04747685</endPosition>
				</positions>
				<commonCountingTime unit="seconds">18.249</commonCountingTime>
				<counts unit="counts">4281 4141 4153 4148 4279 4108 4281 4149 4085 4167 4169 4154 4219 4264 4156 4100 4028 4185 4177 4105 4251 4150 4062 4035 4130 4163 4168 4087 4040 4152 4159 4213 4036 4029 4133 4078 4121 4034 4023 3978 4036 4024 4056 3982 4064 4060 4038 4022 4005 4165 3924 4024 3975 3973 3991 3981 3915 4043 3957 3993 4074 3956 3980 3914 3912 3877 3838 3973 3951 3873 3952 3854 3931 3842 3918 3923 3935 3816 3989 3850 3708 3859 3892 3674 3849 3834 3872 3884 3864 3775 3927 3722 3814 3845 3962 3759 3921 3890 3831 3787 3886 3772 3814 3743 3729 3897 3752 3791 3659 3686 3719 3800 3689 3742 3732 3718 3864 3790 3733 3768 3772 3787 3764 3659 3753 3712 3723 3681 3640 3754 3761 3799 3663 3641 3558 3547 3728 3748 3670 3659 3703 3624 3705 3591 3579 3605 3572 3721 3643 3642 3683 3679 3545 3643 3569 3626 3662 3718 3608 3644 3599 3548 3468 3518 3600 3640 3541 3586 3552 3501 3617 3576 3530 3600 3423 3577 3550 3449 3456 3468 3536 3522 3501 3473 3364 3453 3460 3562 3465 3434 3493 3450 3432 3389 3467 3438 3473 3496 3457 3571 3509 3440 3447 3404 3316 3420 3508 3245 3497 3404 3413 3438 3460 3392 3361 3337 3420 3363 3371 3472 3352 3317 3250 3511 3415 3354 3465 3429 3357 3415 3368 3381 3370 3406 3284 3349 3295 3314 3379 3350 3400 3327 3442 3416 3498 3466 3438 3411 3417 3338 3357 3271 3429 3458 3279 3322 3314 3446 3333 3358 3276 3333 3291 3293 3288 3384 3418 3285 3356 3314 3328 3272 3393 3377 3319 3287 3297 3342 3192 3326 3191 3272 3304 3253 3369 3367 3203 3308 3282 3207 3275 3239 3302 3228 3254 3215 3113 3143 3238 3149 3167 3287 3237 3192 3194 3258 3263 3170 3070 3250 3213 3128 3329 3117 3183 3079 3152 3138 3104 3155 3139 3130 3166 3134 3136 3122 3082 3211 3187 3144 3171 3086 3266 3034 3194 3179 3170 3120 3078 3092 3122 3143 3159 3080 3034 3102 3028 3180 3122 3051 3118 3090 3022 3149 3056 3010 3065 3062 3043 3034 3018 3132 3034 3056 3152 3030 3131 2916 3104 2927 3071 3055 3107 3005 3074 2982 3016 2920 3052 3069 3067 2925 3023 3130 3028 2958 3015 2965 3007 2975 3116 3074 2973 2959 2862 2942 2952 2946 3039 2879 2998 3000 3067 2985 2969 2883 2937 2975 2975 3065 2959 3072 2843 3026 2963 2988 2858 3066 2938 3043 2975 2950 2897 2938 3002 2994 2997 2910 2943 2973 2945 2996 3007 2994 2919 2944 2964 2863 2920 2908 2932 2974 2973 2935 2891 2918 2968 2882 2923 2847 3022 2812 2996 2988 2906 3004 2931 2949 3013 2891 2908 2944 2907 2980 2827 2897 2811 2907 2891 2903 2961 2881 2907 3028 2958 2905 2919 2829 2767 2891 2838 2841 2930 2887 2964 2910 2926 2908 2885 2714 2841 2884 2944 2902 2824 2829 2873 2898 2876 2860 2748 2868 2742 2970 2804 2911 2909 2834 2798 2869 2823 2889 2800 2898 2862 2863 2933 2911 2840 2835 2909 2883 2813 2963 2941 2830 2889 2814 2899 2872 2852 2820 2771 2766 2858 2844 2851 2833 2813 2851 2893 2840 2882 2711 2878 2819 2916 2958 2851 2948 2889 2887 2886 2889 2868 2817 2861 2912 2945 3084 3062 3018 3047 2966 3080 3122 3173 3099 2990 3105 3117 3232 3150 3236 3183 3140 3223 3234 3034 3169 3022 2922 2927 2934 2979 2927 2898 2928 2800 2806 2733 2803 2802 2856 2776 2842 2786 2860 2708 2778 2811 2738 2773 2839 2746 2691 2773 2719 2755 2747 2700 2746 2771 2776 2796 2726 2733 2682 2902 2702 2717 2738 2749 2703 2710 2672 2758 2665 2682 2697 2838 2746 2766 2735 2683 2701 2668 2683 2688 2740 2746 2640 2637 2787 2748 2732 2740 2690 2789 2736 2723 2658 2744 2690 2698 2577 2767 2771 2659 2773 2699 2731 2745 2694 2564 2730 2559 2711 2695 2662 2673 2743 2819 2656 2693 2639 2664 2678 2725 2725 2726 2703 2655 2827 2551 2649 2698 2513 2762 2698 2620 2655 2559 2698 2594 2666 2665 2628 2615 2601 2656 2586 2639 2630 2639 2662 2559 2654 2681 2610 2570 2540 2668 2650 2658 2630 2682 2665 2661 2566 2642 2619 2541 2646 2565 2741 2538 2623 2567 2625 2567 2647 2750 2649 2616 2621 2542 2597 2654 2752 2706 2585 2694 2564 2529 2562 2548 2477 2587 2655 2643 2521 2676 2614 2650 2576 2675 2664 2649 2627 2575 2568 2618 2664 2592 2631 2553 2570 2592 2549 2574 2644 2640 2604 2607 2577 2601 2568 2640 2584 2593 2526 2515 2593 2482 2576 2524 2575 2566 2585 2491 2615 2591 2552 2494 2516 2469 2552 2513 2503 2570 2603 2422 2557 2483 2479 2564 2559 2498 2486 2551 2509 2530 2529 2557 2534 2521 2547 2483 2426 2531 2519 2555 2618 2508 2478 2487 2541 2520 2451 2501 2416 2538 2491 2522 2425 2441 2484 2493 2507 2361 2509 2611 2464 2532 2451 2525 2418 2469 2458 2482 2551 2457 2534 2428 2430 2460 2517 2518 2497 2461 2450 2426 2487 2421 2442 2446 2483 2524 2465 2358 2489 2419 2413 2513 2441 2463 2457 2433 2560 2472 2476 2415 2468 2349 2423 2466 2461 2464 2484 2376 2537 2387 2360 2471 2456 2402 2418 2403 2499 2495 2381 2484 2449 2447 2346 2382 2420 2418 2386 2380 2349 2399 2453 2384 2469 2413 2384 2390 2446 2400 2409 2340 2270 2421 2354 2366 2403 2328 2357 2317 2364 2426 2449 2325 2392 2350 2429 2417 2438 2438 2313 2439 2369 2371 2419 2315 2365 2309 2351 2399 2272 2482 2233 2439 2317 2341 2422 2422 2403 2363 2463 2249 2337 2272 2361 2432 2354 2327 2294 2366 2298 2376 2323 2374 2345 2423 2341 2297 2340 2349 2323 2317 2272 2383 2337 2304 2403 2322 2373 2341 2303 2452 2404 2451 2328 2305 2317 2215 2373 2399 2259 2267 2390 2382 2372 2305 2370 2347 2341 2403 2250 2373 2301 2458 2339 2377 2358 2412 2473 2347 2293 2394 2491 2329 2532 2475 2518 2443 2467 2513 2450 2591 2692 2609 2759 2760 3012 3112 3212 3369 3454 3627 3768 3979 4099 4267 4467 4548 4847 4863 4780 4620 4414 4058 3929 3696 3401 3135 2933 2644 2648 2511 2521 2451 2393 2349 2427 2332 2256 2319 2367 2269 2270 2341 2236 2314 2296 2285 2176 2205 2315 2239 2274 2277 2361 2316 2275 2210 2235 2288 2310 2113 2216 2216 2223 2283 2234 2305 2282 2223 2246 2234 2229 2293 2157 2283 2270 2260 2197 2228 2189 2219 2244 2131 2175 2151 2210 2181 2210 2268 2176 2205 2223 2243 2192 2175 2280 2175 2232 2169 2266 2134 2278 2152 2227 2316 2229 2177 2117 2133 2242 2138 2249 2188 2189 2157 2234 2150 2170 2209 2154 2241 2158 2280 2242 2199 2163 2189 2158 2231 2242 2174 2176 2252 2223 2132 2167 2198 2171 2073 2095 2122 2202 2225 2226 2235 2149 2253 2154 2229 2231 2247 2257 2167 2146 2177 2195 2117 2204 2162 2189 2277 2278 2240 2172 2239 2203 2186 2222 2298 2120 2254 2213 2221 2195 2210 2123 2161 2272 2194 2140 2198 2190 2194 2097 2183 2209 2228 2275 2159 2193 2181 2218 2241 2215 2197 2176 2263 2137 2186 2211 2151 2281 2279 2288 2271 2211 2312 2311 2278 2296 2226 2246 2275 2287 2305 2302 2264 2282 2249 2268 2169 2250 2268 2207 2185 2176 2270 2198 2177 2145 2154 2102 2211 2176 2106 2113 2205 2147 2205 2251 2108 2154 2266 2255 2245 2290 2236 2338 2228 2294 2240 2350 2319 2385 2385 2309 2298 2353 2327 2282 2352 2310 2370 2213 2336 2330 2240 2170 2183 2188 2205 2079 2160 2100 2113 2279 2242 2119 2168 2085 2023 2145 2208 2157 2185 2182 2206 2091 2171 2064 2233 2126 2169 2084 2120 2148 2026 2100 2138 2163 2133 2074 2128 2125 2164 2142 2107 2069 1980 2201 2098 2086 2089 2110 2128 2095 2117 2003 2113 2068 2094 2054 2068 2123 2042 2117 2144 2180 2131 2163 2162 2072 2099 2118 2175 2099 2110 2055 2132 2076 2103 2075 2069 2049 2164 2069 2154 2090 2197 2176 2058 2119 2206 2107 2128 2253 2160 2129 2142 2090 2194 2139 2226 2202 2250 2112 2148 2148 2311 2298 2206 2315 2320 2365 2283 2238 2352 2299 2228 2264 2139 2199 2065 2183 2238 2163 2211 2223 2172 2285 2161 2179 2191 2176 2304 2188 2230 2215 2268 2222 2322 2251 2375 2270 2342 2446 2498 2527 2550 2626 2802 2706 2795 2810 2963 2970 3216 3279 3323 3414 3461 3387 3367 3339 3211 3318 3107 3021 2862 2847 2717 2723 2497 2548 2491 2459 2512 2577 2516 2486 2443 2484 2528 2385 2464 2478 2596 2557 2493 2716 2539 2591 2634 2645 2683 2654 2678 2759 2789 2887 2778 2958 2979 2898 2967 3001 3126 3247 3187 3349 3353 3629 3727 3783 3868 4128 4154 4402 4587 4817 5115 5399 5661 6270 6679 7204 7718 8556 9213 10076 11059 12111 12882 14284 15412 16515 18020 19007 20278 21362 21827 22077 22109 21221 20237 18989 17680 16449 15101 13802 12109 11224 9846 8788 7885 7100 6470 5963 5450 5231 4788 4614 4470 4133 4061 3883 3962 3541 3605 3539 3447 3351 3223 3300 3314 3129 3141 3176 3064 3057 2954 3040 3048 3051 2933 2949 2875 2867 2848 2893 2849 2813 2846 2714 2833 2766 2629 2658 2778 2824 2689 2813 2761 2780 2737 2768 2672 2833 2818 2917 2755 2772 2931 2920 2957 2961 2882 2995 3004 3035 3112 3095 3161 3236 3225 3211 3352 3379 3409 3379 3452 3482 3655 3736 3753 3875 3990 4096 4252 4334 4530 4865 5068 5589 6035 6453 6858 7492 8358 9093 10241 11456 12889 14610 16365 18460 21364 24498 27490 31196 34977 38962 42962 46780 50543 53032 54446 53535 51440 47711 43585 39274 35579 31899 28084 24134 20240 16715 13899 11492 9640 8313 7267 6521 6054 5603 5185 5046 4708 4503 4279 4199 4034 3905 3783 3611 3615 3451 3471 3443 3379 3248 3182 3095 3056 2987 2858 2856 2811 2809 2769 2604 2485 2636 2633 2623 2551 2585 2470 2601 2456 2386 2540 2464 2476 2514 2512 2428 2499 2510 2394 2344 2328 2462 2444 2412 2290 2365 2432 2367 2421 2369 2352 2296 2242 2318 2416 2342 2335 2394 2276 2345 2288 2299 2208 2237 2240 2280 2261 2240 2308 2237 2273 2198 2250 2242 2165 2261 2311 2264 2216 2177 2200 2138 2310 2146 2194 2211 2207 2184 2246 2120 2248 2145 2235 2330 2234 2303 2284 2337 2275 2380 2309 2344 2349 2387 2374 2419 2408 2584 2432 2482 2447 2473 2476 2529 2465 2469 2475 2367 2459 2390 2377 2380 2259 2311 2234 2213 2187 2200 2261 2261 2242 2191 2158 2226 2139 2215 2251 2202 2134 2114 2107 2262 2174 2256 2299 2324 2266 2189 2206 2193 2213 2113 2230 2251 2248 2234 2288 2191 2199 2272 2229 2337 2368 2217 2338 2277 2312 2315 2298 2425 2369 2393 2442 2474 2514 2632 2580 2615 2721 2760 2800 2902 2975 3001 3082 3244 3285 3263 3362 3333 3474 3334 3165 3117 3069 3079 2912 2890 2796 2693 2769 2717 2788 2613 2735 2686 2790 2830 2891 2883 2994 3151 3249 3291 3407 3446 3434 3535 3472 3447 3506 3376 3276 3311 3103 3011 2847 2838 2805 2635 2566 2503 2483 2416 2377 2426 2271 2379 2269 2245 2257 2156 2136 2267 2155 2116 2179 2122 2194 2084 2247 2154 2244 2194 2125 2123 2039 2165 2117 2142 2125 2117 2070 2113 2089 2118 2190 2098 2187 2173 2105 2161 2144 2153 2160 2160 2117 2125 2213 2225 2324 2144 2274 2320 2246 2296 2301 2365 2442 2419 2342 2407 2547 2429 2424 2675 2606 2670 2713 2832 2889 3009 2965 3185 3346 3431 3626 3820 4048 4388 4748 4987 5550 6046 6688 7303 8275 9033 10169 10903 11796 13020 13930 14685 15339 15757 15325 14907 14126 13272 12191 11673 10986 9937 9290 8082 7362 6504 5829 5023 4758 4163 4008 3647 3452 3287 3222 3107 3042 2843 2841 2764 2874 2685 2716 2640 2758 2641 2483 2478 2467 2354 2439 2482 2478 2534 2441 2408 2438 2440 2364 2472 2525 2425 2462 2530 2572 2616 2533 2594 2636 2796 2719 2976 2907 2958 3043 3118 3285 3400 3456 3772 3851 4069 4237 4496 4952 5191 5705 6237 6734 7408 8452 9246 10156 11198 12245 13458 14605 15053 15732 15625 14856 14027 12974 12139 11306 10666 9738 9069 8135 7308 6261 5425 4930 4340 4094 3711 3513 3264 3171 3132 2977 2880 2789 2727 2586 2672 2538 2530 2505 2458 2624 2482 2413 2478 2273 2336 2354 2316 2316 2338 2362 2339 2281 2280 2297 2310 2290 2251 2241 2216 2153 2280 2306 2268 2238 2183 2241 2260 2322 2389 2367 2384 2419 2372 2372 2499 2457 2442 2491 2545 2509 2584 2619 2721 2795 2795 2886 2904 2951 3090 3045 3205 3333 3343 3464 3682 3746 4092 4193 4647 4875 5118 5534 5955 6545 7081 7819 8451 9141 10163 11236 12268 13319 14466 15604 16384 17338 17669 17663 17274 16551 15780 14891 14162 13421 12581 11969 10887 9897 9014 8218 7219 6671 6259 5731 5305 5064 4645 4550 4193 4005 3810 3769 3564 3425 3333 3203 3036 3048 2942 2820 2668 2758 2579 2495 2545 2477 2464 2455 2338 2404 2254 2179 2277 2168 2186 2227 2181 2105 2060 2197 2142 2119 2087 2066 2106 2021 2053 2051 2128 2046 2055 1998 2049 2030 2046 1963 2041 2053 1957 1947 1989 2029 1999 2068 1943 2005 1925 2016 1987 1907 1948 1985 1980 2014 2014 1998 2038 2093 1941 1998 2114 1980 2013 2025 2033 1966 2022 1967 2016 2005 2075 2018 1994 2026 2057 2064 2044 2094 2157 2058 2162 2179 2162 2281 2215 2258 2305 2364 2285 2536 2456 2516 2735 2666 2783 2867 3081 3200 3324 3596 3740 3996 4134 4439 4709 4972 5210 5715 5826 5996 6342 6560 6669 6765 6856 7011 7148 7059 7195 7125 6982 6836 6892 6575 6345 6170 5707 5424 5189 5109 4879 4584 4226 4084 3789 3663 3492 3251 3272 2976 2878 2849 2653 2596 2563 2475 2548 2442 2410 2332 2305 2323 2369 2337 2336 2339 2425 2481 2443 2477 2748 2922 2977 3378 3522 3881 4184 4609 4786 4901 4738 4359 4017 3774 3622 3496 3477 3319 3295 3104 2836 2667 2431 2148 2059 1931 2004 1960 1870 1859 1910 1858 1924 1844 1790 1851 1847 1771 1781 1824 1859 1811 1769 1798 1777 1759 1732 1795 1827 1747 1779 1792 1801 1816 1750 1847 1795 1839 1761 1799 1827 1770 1887 1813 1777 1826 1817 1750 1813 1751 1819 1818 1772 1841 1772 1845 1778 1841 1882 2013 1930 1920 2005 1917 2092 2045 2132 2079 2160 2259 2160 2157 2129 2055 2162 2176 2080 2022 2048 1992 1994 1988 1986 1922 1844 1916 1885 1866 1832 1814 1844 1921 1884 1777 1734 1770 1767 1744 1790 1799 1789 1856 1893 1831 1801 1785 1849 1782 1769 1860 1815 1850 1814 1868 1827 1872 1808 1921 1939 1881 1897 1879 1966 1913 2002 1878 1894 1956 1952 1951 1981 1971 2003 2121 2045 2069 2083 2139 2111 2308 2215 2234 2396 2325 2507 2614 2534 2789 2882 3075 3146 3415 3563 3751 4242 4399 4822 5118 5296 5622 5937 6143 5889 6091 5746 5636 5486 5275 5162 4856 4662 4524 4206 4052 3729 3552 3221 3048 2961 2858 2868 2662 2676 2524 2608 2470 2530 2403 2426 2484 2464 2547 2468 2561 2600 2700 2591 2713 2734 2787 2719 2686 2691 2794 2835 2872 2934 2927 3049 3057 3195 3319 3370 3588 3676 3800 3870 4063 4194 4460 4737 4913 5028 5369 5341 5688 5798 6100 6196 6325 6507 6397 6513 6331 6409 6159 6288 6132 6068 5768 5696 5522 5520 5373 5278 5006 4995 4878 4840 4790 4515 4576 4500 4563 4482 4374 4534 4161 4124 3943 4040 3786 3639 3521 3314 3256 3228 3031 2924 2753 2666 2543 2572 2536 2352 2236 2202 2102 2208 2104 2054 2073 2048 1974 2017 2054 1951 1893 1914 1921 1900 1841 1870 1900 1738 1900 1892 1832 1834 1894 1807 1883 1904 1940 1877 1950 2010 2160 2095 2086 2049 2163 2053 1992 2018 2056 1993 1935 1891 1881 1921 1866 1820 1841 1763 1710 1763 1642 1760 1735 1733 1748 1706 1690 1721 1749 1772 1788 1808 1810 1818 1813 1776 1810 1803 1781 1783 1714 1856 1719 1742 1785 1713 1751 1779 1743 1766 1781 1669 1732 1785 1839 1827 1760 1695 1704 1694 1655 1690 1671 1655 1630 1668 1609 1568 1591 1615 1637 1634 1608 1571 1585 1661 1626 1691 1658 1611 1605 1587 1555 1569 1575 1574 1596 1568 1614 1566 1487 1602 1559 1536 1449 1514 1571 1600 1581 1568 1530 1545 1608 1579 1543 1606 1510 1613 1504 1632 1558 1541 1573 1549 1515 1617 1590 1611 1559 1543 1557 1556 1522 1487 1623 1613 1578 1598 1622 1540 1598 1607 1571 1557 1579 1534 1635 1567 1556 1626 1595 1599 1646 1608 1629 1582 1702 1661 1699 1620 1776 1677 1748 1811 1822 1904 2083 2029 2162 2299 2364 2371 2289 2402 2343 2318 2175 2218 2057 2087 2010 2028 2024 2060 1983 1950 1870 1802 1778 1632 1691 1670 1628 1631 1626 1613 1653 1664 1626 1548 1534 1659 1528 1677 1507 1611 1628 1568 1591 1559 1627 1493 1597 1588 1554 1517 1540 1625 1610 1616 1627 1627 1605 1561 1646 1548 1565 1591 1563 1519 1582 1620 1655 1599 1583 1706 1748 1720 1757 1739 1739 1756 1761 1782 1693 1781 1710 1741 1798 1789 1783 1762 1686 1683 1610 1777 1623 1725 1687 1713 1684 1652 1591 1639 1588 1620 1617 1548 1610 1630 1644 1568 1534 1570 1575 1617 1580 1659 1545 1636 1612 1640 1597 1632 1576 1695 1608 1721 1616 1691 1738 1744 1772 1751 1761 1831 1866 1824 1825 1817 1797 1753 1789 1759 1706 1766 1770 1684 1683 1668 1594 1626 1587 1627 1605 1597 1506 1590 1587 1516 1510 1504 1515 1588 1477 1576 1476 1480 1544 1526 1558 1566 1607 1601 1523 1494 1504 1517 1551 1528 1544 1486 1504 1405 1509 1536 1509 1476 1518 1517 1529 1451 1518 1451 1504 1519 1555 1534 1627 1525 1484 1585 1549 1552 1594 1586 1574 1637 1753 1751 1757 1699 1655 1794 1639 1660 1685 1629 1631 1641 1694 1607 1655 1595 1592 1476 1547 1582 1543 1497 1557 1492 1516 1498 1508 1602 1468 1546 1522 1527 1504 1545 1556 1493 1501 1479 1420 1542 1468 1405 1564 1435 1452 1460 1444 1466 1548 1416 1544 1490 1494 1510 1497 1483 1408 1426 1483 1531 1534 1514 1444 1501 1486 1493 1460 1475 1491 1514 1542 1479 1429 1515 1506 1424 1506 1497 1424 1456 1553 1520 1532 1412 1526 1506 1522 1560 1382 1476 1523 1433 1494 1473 1451 1506 1428 1522 1470 1542 1477 1475 1513 1516 1584 1555 1469 1508 1553 1565 1585 1592 1488 1586 1544 1502 1527 1556 1553 1565 1529 1633 1475 1492 1547 1519 1534 1509 1557 1517 1564 1543 1559 1539 1619 1635 1541 1609 1577 1602 1563 1656 1619 1681 1618 1660 1672 1712 1664 1781 1773 1749 1850 1946 1885 2020 2004 2037 2140 2089 2101 2010 1967 1938 1936 1870 1839 1975 1787 1915 1917 1908 1802 1706 1780 1666 1668 1629 1707 1643 1659 1582 1660 1615 1658 1573 1604 1650 1594 1609 1668 1625 1617 1650 1650 1623 1610 1616 1704 1602 1606 1661 1625 1701 1653 1724 1708 1682 1650 1705 1652 1743 1733 1753 1759 1764 1833 1734 1778 1823 1787 1861 1823 1849 1869 1897 1939 2056 2010 2082 2081 2240 2178 2235 2180 2383 2437 2482 2623 2641 2828 2919 3121 3386 3577 3969 4131 4675 5461 6142 6959 8007 9288 10582 11934 12643 13447 13930 13728 13133 11917 10673 9678 8896 8882 8618 8937 8680 8483 8263 7588 6931 5951 5161 4449 4102 3544 3240 2951 2844 2664 2700 2622 2561 2411 2412 2288 2219 2326 2262 2212 2150 2173 2173 2142 2172 2079 2070 2132 2236 2170 2211 2274 2231 2309 2462 2517 2608 2876 2975 3269 3499 3857 4166 4761 5422 5985 6481 7071 7242 7305 6993 6531 5947 5678 5131 5050 4961 4982 4981 4943 4911 4719 4465 3961 3535 3208 2916 2669 2522 2327 2291 2169 2121 2042 2046 1928 1984 1886 1870 1832 1759 1732 1812 1818 1783 1707 1619 1755 1716 1714 1721 1688 1582 1696 1624 1625 1598 1623 1594 1573 1713 1564 1608 1595 1662 1605 1653 1624 1523 1616 1670 1607 1625 1567 1596 1657 1557 1555 1579 1554 1585 1572 1527 1590 1565 1637 1684 1576 1574 1591 1542 1557 1539 1649 1524 1484 1579 1519 1521 1579 1503 1555 1602 1540 1628 1560 1565 1551 1558 1543 1609 1507 1593 1582 1625 1676 1680 1499 1621 1517 1678 1679 1597 1579 1642 1518 1586 1665 1598 1624 1659 1556 1616 1687 1631 1539 1738 1696 1673 1731 1771 1688 1768 1906 1947 1913 1955 2035 2103 2198 2130 2166 2198 2103 2056 2035 2114 1975 2099 2157 2156 2152 2173 2255 2195 2211 2292 2331 2388 2406 2379 2477 2546 2668 2682 2632 2859 2729 2820 2851 3002 2891 2910 2827 2848 2819 2808 2768 2694 2752 2664 2645 2597 2531 2412 2452 2480 2389 2246 2301 2245 2145 2223 2120 2054 1945 1991 1978 1881 1888 1787 1825 1794 1825 1824 1718 1768 1697 1705 1675 1663 1657 1696 1698 1730 1694 1689 1743 1666 1746 1656 1640 1568 1608 1624 1611 1617 1660 1638 1584 1599 1614 1634 1578 1575 1592 1572 1534 1560 1491 1506 1601 1490 1534 1616 1569 1580 1565 1599 1550 1586 1561 1633 1571 1595 1595 1533 1547 1603 1589 1562 1561 1563 1585 1629 1667 1577 1507 1611 1627 1613 1618 1592 1678 1691 1756 1662 1734 1763 1697 1723 1730 1660 1650 1619 1578 1619 1583 1633 1658 1644 1685 1607 1687 1575 1654 1531 1608 1613 1621 1640 1627 1614 1651 1597 1636 1614 1580 1618 1685 1619 1622 1579 1660 1575 1587 1644 1658 1615 1591 1611 1632 1600 1680 1624 1618 1606 1702 1551 1599 1566 1440 1595 1607 1568 1612 1563 1604 1582 1558 1631 1597 1563 1574 1620 1537 1611 1632 1632 1544 1541 1564 1610 1558 1649 1668 1594 1640 1600 1621 1591 1541 1642 1654 1702 1566 1666 1608 1697 1604 1674 1613 1701 1669 1645 1722 1654 1719 1684 1822 1853 1785 1834 1768 1854 1882 1879 1896 2033 1977 2092 2231 2320 2384 2539 2655 2770 2732 2769 2807 2703 2719 2682 2543 2549 2615 2538 2585 2629 2642 2722 2701 2582 2600 2546 2427 2576 2514 2549 2584 2584 2609 2703 2644 2807 2987 3035 2978 3120 3290 3433 3644 3965 4168 4531 4858 5284 5821 6345 7259 7964 8756 9793 10741 11804 12628 13166 13279 13185 12587 11931 10973 10443 9778 9512 9356 9115 9130 9049 8910 8710 8346 7463 6916 6260 5678 5170 4775 4250 3934 3699 3463 3442 3252 2941 2889 2826 2760 2570 2579 2448 2446 2282 2283 2295 2165 2156 2262 2008 2025 2008 1969 1973 1925 1917 1876 1873 1979 1788 1859 1849 1771 1806 1806 1847 1781 1852 1806 1718 1759 1793 1748 1753 1765 1710 1715 1695 1797 1633 1675 1708 1674 1682 1628 1707 1671 1728 1644 1709 1654 1663 1668 1671 1609 1614 1569 1630 1680 1659 1650 1639 1661 1646 1694 1647 1679 1602 1601 1571 1667 1661 1694 1706 1751 1656 1615 1613 1620 1693 1649 1641 1660 1674 1728 1625 1663 1695 1745 1632 1723 1749 1696 1689 1721 1675 1688 1733 1677 1737 1756 1711 1805 1677 1840 1823 1770 1911 1727 1840 1815 1933 1849 1962 1931 2026 1909 1917 1967 1891 1993 1910 2037 2006 2026 2048 2051 1979 1986 1994 2007 2084 2052 2040 2111 2099 2175 2138 2179 2145 2132 1996 2060 2108 2025 2020 1973 1889 2060 1862 1949 2002 2010 2008 1884 1965 1910 1919 1813 1842 1921 1876 1810 1887 1836 1923 1886 1851 1887 1970 1847 1932 1945 2017 1916 1968 2005 2074 2108 2154 2248 2308 2389 2451 2533 2647 2896 2948 3309 3588 4019 4350 4956 5549 6239 6893 7550 7914 8164 7963 7577 6737 6073 5543 5207 4979 4878 4851 5028 5155 5307 5481 5142 4991 4497 4232 3663 3382 3108 2944 2809 2561 2614 2491 2491 2451 2556 2494 2581 2635 2642 2743 2771 2913 3058 3184 3283 3585 3751 3968 4162 4350 4440 4507 4321 4181 3891 3700 3579 3494 3494 3322 3402 3395 3364 3326 3298 3234 3172 2999 2830 2654 2597 2590 2334 2277 2328 2209 2202 2128 2113 2152 2204 2109 2086 2077 2141 2170 2121 2106 2201 2206 2232 2209 2332 2295 2338 2294 2389 2538 2456 2637 2642 2846 2884 3021 3251 3513 3915 4251 4786 5399 6118 6912 8076 9060 10292 11177 12276 12262 12276 11692 10513 9405 8388 7616 7231 6928 7159 7333 7663 7796 8039 7968 7993 7151 6616 5698 4974 4478 3963 3653 3227 3095 2956 2856 2813 2723 2520 2561 2355 2332 2261 2136 2033 2069 2017 2041 1945 1875 1891 1837 1856 1865 1758 1817 1738 1732 1636 1784 1664 1660 1717 1606 1701 1643 1664 1586 1601 1638 1593 1690 1550 1593 1600 1593 1640 1629 1579 1572 1557 1617 1617 1578 1561 1643 1558 1551 1506 1601 1581 1530 1657 1549 1602 1584 1618 1646 1606 1594 1633 1608 1669 1594 1619 1686 1577 1576 1614 1652 1588 1626 1699 1606 1511 1581 1658 1691 1664 1656 1686 1753 1783 1703 1831 1800 1864 1793 1849 1843 1748 1695 1681 1765 1689 1668 1758 1737 1783 1688 1809 1789 1766 1758 1803 1689 1675 1595 1586 1682 1617 1668 1553 1644 1636 1674 1606 1634 1632 1618 1669 1647 1594 1566 1584 1578 1576 1610 1612 1608 1641 1682 1632 1669 1663 1691 1670 1621 1663 1665 1676 1711 1628 1724 1704 1707 1681 1756 1748 1731 1712 1833 1788 1936 1841 1913 1843 1986 2002 1920 2088 2131 2159 2202 2279 2476 2528 2672 2894 3071 3462 3738 4186 4720 5183 5874 6365 6937 6958 7127 6816 6399 6041 5595 5253 5041 4825 4818 4883 4908 4908 4960 5073 5059 4868 4706 4435 3942 3676 3457 3225 3068 2851 2780 2704 2596 2510 2508 2404 2413 2419 2335 2308 2278 2245 2263 2281 2204 2158 2190 2332 2170 2205 2273 2206 2255 2213 2233 2145 2105 2167 2167 2201 2050 2045 2165 1997 2000 2097 2021 2000 1984 1955 1913 1830 1869 1816 1822 1819 1835 1791 1726 1769 1754 1704 1743 1785 1699 1695 1704 1681 1598 1653 1688 1666 1648 1682 1596 1651 1682 1660 1613 1585 1576 1607 1679 1659 1655 1637 1635 1699 1657 1621 1562 1694 1643 1767 1695 1702 1714 1745 1684 1718 1847 1827 1823 1955 1986 2043 2007 2173 2037 2082 2063 1955 1778 1810 1778 1715 1790 1735 1736 1745 1772 1747 1743 1744 1735 1803 1727 1671 1639 1534 1624 1575 1552 1570 1488 1613 1596 1562 1480 1533 1572 1508 1525 1529 1539 1535 1513 1549 1558 1630 1575 1607 1559 1638 1761 1713 1683 1789 1772 1759 1789 1871 1888 1900 1811 1768 1777 1759 1775 1744 1819 1730 1767 1750 1771 1750 1730 1657 1678 1649 1681 1595 1653 1625 1535 1549 1470 1527 1472 1494 1552 1521 1513 1480 1440 1521 1448 1524 1509 1389 1477 1505 1479 1436 1523 1458 1443 1481 1529 1445 1538 1465 1502 1465 1498 1433 1415 1427 1514 1460 1447 1492 1395 1455 1449 1426 1483 1389 1436 1419 1480 1392 1449 1463 1509 1432 1416 1523 1547 1503 1437 1468 1435 1423 1456 1440 1503 1439 1405 1425 1437 1466 1396 1516 1480 1505 1504 1419 1443 1420 1421 1407 1482 1517 1471 1457 1501 1481 1482 1451 1450 1465 1452 1498 1461 1509 1491 1529 1483 1489 1523 1532 1622 1588 1645 1568 1597 1579 1618 1629 1606 1676 1556 1629 1640 1622 1650 1586 1604 1650 1676 1663 1642 1616 1661 1718 1645 1687 1689 1673 1688 1665 1745 1849 1745 1887 1801 1964 1919 1950 2013 1889 1988 2128 2074 2189 2160 2278 2329 2286 2211 2392 2359 2406 2462 2419 2448 2437 2413 2460 2427 2441 2442 2415 2344 2501 2466 2472 2420 2469 2566 2501 2501 2631 2598 2630 2860 2977 3038 3274 3242 3471 3710 3763 3903 3962 3760 3716 3609 3384 3296 3011 2921 2904 2925 2892 2941 3070 3008 3033 3085 3025 3105 3049 2840 2774 2734 2542 2579 2443 2308 2216 2154 2072 2068 1886 1943 1970 1958 1863 1954 1930 1916 1934 1911 1769 1712 1730 1652 1619 1661 1629 1678 1611 1672 1504 1502 1566 1564 1578 1567 1569 1558 1522 1459 1543 1505 1474 1515 1452 1488 1562 1401 1431 1497 1494 1386 1459 1466 1494 1452 1444 1463 1456 1419 1482 1400 1446 1413 1456 1451 1471 1521 1419 1504 1467 1451 1415 1409 1523 1490 1494 1476 1502 1501 1541 1432 1539 1446 1531 1479 1433 1422 1493 1551 1474 1453 1473 1444 1402 1419 1409 1447 1544 1487 1456 1422 1462 1474 1414 1515 1436 1373 1420 1436 1498 1516 1379 1496 1532 1454 1511 1469 1478 1514 1553 1488 1529 1528 1527 1444 1474 1509 1446 1469 1491 1498 1501 1471 1474 1470 1529 1474 1470 1548 1476 1431 1491 1436 1534 1500 1429 1419 1442 1380 1435 1462 1508 1468 1375 1470 1469 1472 1431 1454 1445 1453 1403 1487 1483 1423 1384 1455 1417 1469 1519 1420 1435 1498 1472 1380 1527 1471 1426 1506 1428 1515 1432 1517 1402 1427 1477 1489 1482 1583 1523 1446 1507 1548 1444 1518 1544 1548 1523 1508 1563 1443 1521 1579 1592 1518 1585 1618 1556 1581 1522 1637 1630 1669 1569 1587 1641 1633 1711 1738 1737 1742 1795 1881 1828 1881 1954 1990 2030 2109 2181 2197 2306 2466 2577 2695 2906 3012 3218 3305 3480 3605 3693 3582 3630 3454 3348 3213 3089 2848 2846 2848 2871 2760 2782 2722 2760 2826 2842 2859 2718 2733 2513 2418 2344 2332 2182 2144 2064 2059 1869 1948 1867 1790 1780 1819 1744 1706 1722 1678 1794 1702 1665 1650 1629 1646 1665 1666 1646 1666 1578 1608 1658 1596 1739 1610 1783 1677 1615 1636 1689 1698 1742 1722 1780 1702 1876 1848 1785 1841 1839 1897 1816 1839 1770 1918 1871 1821 1968 1816 1947 2000 2028 2081 2116 2138 2046 2178 2082 2061 2159 2178 2147 2253 2217 2323 2366 2416 2486 2507 2628 2539 2767 2838 2827 2969 3154 3225 3589 3662 3858 4094 4229 4493 4700 4776 4565 4715 4406 4176 4099 4048 3970 3770 3664 3659 3534 3513 3606 3700 3787 3711 3593 3741 3670 3650 3417 3422 3310 3167 3062 3062 3101 2995 2967 2896 2963 3019 3097 3166 3204 3157 3071 2952 2950 2739 2665 2445 2430 2349 2353 2320 2287 2408 2313 2235 2337 2271 2308 2199 2200 2165 2013 1961 1969 1836 1833 1835 1724 1658 1666 1653 1578 1614 1659 1588 1577 1619 1567 1635 1537 1512 1500 1515 1513 1532 1489 1505 1530 1583 1535 1538 1417 1505 1465 1544 1488 1569 1472 1473 1532 1449 1446 1490 1486 1452 1482 1476 1641 1515 1517 1503 1520 1596 1499 1514 1561 1456 1491 1466 1516 1544 1443 1561 1480 1467 1464 1523 1521 1475 1510 1443 1576 1534 1519 1502 1452 1550 1490 1603 1482 1553 1525 1536 1495 1527 1573 1553 1574 1632 1580 1556 1544 1586 1662 1678 1631 1603 1637 1653 1595 1667 1613 1676 1635 1687 1699 1658 1832 1663 1700 1735 1718 1839 1811 1830 1745 1797 1814 1845 1954 1951 1928 1895 1891 1915 1920 1968 1980 1951 2027 1955 2048 2071 2063 2076 2223 2176 2102 2150 2110 2178 2116 2132 2163 2090 2096 2045 2047 2071 2023 1927 1965 2008 1962 1920 2011 1878 1917 1886 1857 1922 1826 1899 1884 1921 1931 1919 1913 1940 2007 2142 2134 2221 2303 2491 2592 2548 2638 2674 2568 2573 2348 2287 2098 2010 1970 1944 2008 1930 1874 1942 2021 2032 2057 2071 2084 1951 2058 1869 1898 1827 1783 1706 1719 1598 1682 1543 1578 1452 1584 1574 1529 1540 1565 1501 1508 1528 1516 1566 1435 1497 1471 1527 1432 1508 1386 1451 1458 1472 1519 1455 1533 1552 1540 1576 1532 1626 1712 1799 1790 1759 1826 1747 1782 1665 1710 1691 1611 1535 1593 1545 1582 1640 1565 1549 1568 1604 1562 1582 1584 1610 1585 1660 1560 1566 1512 1472 1400 1460 1476 1470 1426 1423 1442 1459 1461 1372 1444 1358 1430 1392 1390 1418 1403 1441 1459 1420 1406 1364 1345 1397 1422 1387 1369 1397 1342 1331 1417 1450 1441 1374 1388 1361 1390 1419 1386 1426 1384 1369 1378 1337 1463 1321 1321 1307 1386 1308 1368 1333 1298 1325 1355 1385 1409 1413 1424 1318 1337 1374 1385 1322 1386 1359 1344 1376 1358 1367 1378 1405 1405 1396 1390 1375 1339 1412 1444 1442 1452 1373 1479 1410 1413 1441 1463 1414 1362 1450 1418 1417 1403 1448 1376 1324 1363 1434 1389 1406 1418 1429 1421 1413 1458 1342 1432 1434 1410 1393 1404 1428 1533 1357 1419 1495 1388 1432 1524 1538 1431 1324 1401 1444 1455 1513 1487 1430 1578 1465 1569 1657 1699 1660 1712 1744 1690 1645 1804 1660 1644 1547 1560 1681 1567 1646 1595 1702 1657 1714 1780 1693 1731 1852 1891 1913 1873 1956 2041 2166 2082 2288 2325 2432 2522 2498 2573 2537 2464 2315 2276 2155 2049 2038 2042 1956 1876 1956 1942 1962 1925 2038 1899 1966 2135 2048 2043 1934 1854 1861 1839 1740 1701 1698 1629 1681 1609 1620 1579 1573 1530 1494 1531 1523 1480 1529 1507 1503 1491 1505 1497 1461 1463 1424 1518 1463 1431 1463 1370 1504 1453 1450 1487 1495 1428 1402 1505 1443 1450 1440 1447 1469 1570 1458 1514 1470 1474 1433 1436 1490 1519 1500 1465 1479 1481 1477 1521 1478 1393 1521 1530 1427 1512 1415 1630 1461 1542 1566 1473 1580 1594 1593 1588 1656 1660 1681 1632 1706 1692 1728 1733 1811 1691 1758 1735 1635 1665 1588 1608 1616 1624 1651 1636 1546 1578 1542 1626 1600 1568 1702 1616 1579 1619 1554 1542 1592 1547 1516 1447 1554 1446 1516 1413 1487 1443 1498 1446 1500 1400 1448 1421 1406 1438 1436 1434 1392 1408 1462 1335 1486 1462 1407 1443 1435 1430 1371 1413 1434 1410 1443 1452 1399 1379 1411 1421 1415 1474 1450 1419 1511 1405 1468 1484 1390 1415 1417 1458 1371 1353 1379 1418 1402 1401 1359 1423 1406 1381 1461 1441 1429 1425 1448 1448 1486 1412 1375 1451 1416 1416 1413 1303 1347 1370 1430 1339 1414 1410 1461 1411 1443 1442 1389 1450 1418 1455 1390 1386 1406 1397 1382 1440 1525 1505 1428 1445 1491 1335 1424 1417 1441 1530 1461 1391 1471 1477 1485 1495 1555 1457 1570 1599 1597 1615 1619 1614 1543 1591 1595 1595 1630 1566 1602 1577 1542 1481 1623 1594 1593 1652 1655 1614 1650 1553 1695 1650 1610 1635 1703 1711 1776 1736 1721 1791 1710 1827 1816 1815 1924 1906 2069 2044 2147 2317 2468 2579 2783 3165 3330 3728 4160 4506 4925 5145 5190 5050 4747 4384 3934 3547 3269 3026 2893 2745 2833 2575 2722 2762 2887 2902 3198 3183 3463 3425 3553 3309 3274 3072 2837 2645 2446 2218 2225 2131 2180 2054 2016 1961 2006 1931 1980 1999 1999 1928 1943 1999 1960 2012 2011 1857 1972 1865 1897 1846 1834 1937 1815 1879 1875 1935 1825 1874 1857 1868 1890 1900 1951 2003 1890 1881 1881 1860 1868 1853 1825 1815 1887 1873 1905 1811 1797 1833 1828 1886 1850 1842 1953 1945 1970 2018 2272 2246 2281 2464 2663 2859 2966 3100 3145 3055 3011 2790 2642 2497 2372 2258 2189 2153 2005 2116 2018 2095 2058 2083 2176 2205 2396 2462 2507 2365 2461 2337 2356 2252 2118 2124 2005 2133 2167 2202 2316 2458 2488 2681 2900 3074 3128 3288 3247 3136 2930 2736 2566 2381 2266 2044 2129 2021 1987 2047 1987 2042 2107 2085 2139 2214 2367 2399 2316 2282 2205 2092 2014 1891 1846 1787 1664 1683 1680 1640 1583 1502 1577 1497 1449 1536 1522 1570 1573 1516 1510 1526 1472 1445 1474 1544 1571 1403 1461 1431 1433 1464 1489 1537 1400 1509 1492 1587 1578 1623 1660 1773 1721 1757 1739 1809 1733 1793 1735 1728 1648 1609 1550 1606 1560 1513 1531 1542 1614 1474 1593 1567 1509 1693 1568 1597 1626 1628 1568 1613 1572 1469 1423 1540 1626 1513 1584 1534 1519 1490 1503 1492 1440 1548 1452 1505 1475 1467 1503 1469 1543 1492 1550 1544 1546 1537 1532 1504 1522 1463 1590 1613 1653 1590 1687 1600 1686 1719 1780 1917 1952 2028 2117 2290 2565 2651 2670 2822 2822 2784 2666 2598 2387 2310 1982 1984 1924 1910 1923 1910 1883 1914 1863 1896 2031 2131 2180 2168 2219 2112 2153 2115 2034 1962 1873 1862 1828 1881 1738 1805 1724 1760 1782 1805 1817 1894 1905 1962 2180 2244 2330 2559 2634 2612 2728 2675 2675 2517 2300 2177 2078 2076 1995 1968 1915 1781 1889 1813 1909 1914 1966 1987 2126 2084 2099 2107 2132 2054 2069 1986 1928 1866 1847 1779 1793 1692 1771 1711 1716 1794 1641 1605 1660 1645 1590 1663 1654 1660 1657 1688 1666 1695 1715 1788 1707 1730 1848 1877 1913 1964 2129 2138 2280 2338 2418 2529 2727 2838 2899 3183 3003 3075 2984 2923 2892 2755 2558 2435 2495 2308 2307 2108 2203 2188 2219 2131 2212 2229 2298 2321 2320 2413 2385 2362 2311 2238 2104 2050 2049 1907 1847 1801 1813 1704 1704 1724 1612 1599 1602 1612 1594 1592 1553 1612 1549 1557 1511 1473 1503 1527 1511 1428 1415 1464 1440 1458 1437 1434 1428 1468 1433 1409 1448 1434 1431 1391 1447 1451 1413 1375 1468 1385 1393 1442 1335 1376 1354 1429 1501 1432 1356 1405 1472 1394 1359 1339 1367 1362 1449 1396 1404 1408 1371 1371 1398 1331 1403 1386 1413 1388 1375 1379 1427 1450 1372 1405 1317 1394 1393 1307 1364 1390 1400 1432 1411 1387 1363 1353 1394 1386 1442 1396 1335 1382 1483 1446 1417 1477 1428 1465 1492 1425 1533 1522 1562 1549 1574 1544 1522 1551 1586 1513 1507 1548 1597 1526 1560 1501 1601 1584 1643 1539 1566 1547 1521 1496 1619 1457 1472 1447 1505 1564 1612 1472 1446 1390 1514 1381 1458 1415 1499 1485 1526 1441 1483 1478 1439 1419 1433 1407 1380 1379 1405 1430 1434 1421 1416 1428 1402 1414 1368 1411 1453 1398 1446 1442 1446 1395 1435 1412 1434 1466 1450 1414 1467 1466 1453 1535 1527 1489 1488 1551 1522 1523 1505 1633 1590 1729 1718 1795 1722 1797 1783 1929 1880 1821 1845 1755 1884 1781 1820 1787 1770 1735 1669 1688 1759 1759 1725 1776 1862 1900 1912 1822 1813 1833 1762 1698 1774 1738 1678 1606 1621 1588 1636 1629 1538 1527 1556 1516 1566 1603 1566 1649 1575 1497 1528 1571 1511 1491 1513 1449 1453 1514 1522 1495 1450 1500 1494 1499 1521 1491 1511 1483 1446 1521 1428 1359 1416 1365 1459 1505 1422 1397 1369 1406 1443 1457 1408 1465 1454 1477 1435 1447 1461 1496 1460 1486 1490 1404 1479 1436 1485 1394 1390 1534 1385 1385 1431 1527 1451 1461 1364 1385 1409 1402 1432 1493 1455 1517 1453 1507 1485 1444 1495 1478 1538 1547 1564 1452 1564 1548 1544 1577 1446 1500 1499 1484 1605 1618 1550 1507 1544 1486 1484 1555 1533 1522 1588 1527 1487 1514 1595 1492 1561 1536 1518 1476 1537 1509 1567 1498 1534 1528 1477 1476 1448 1467 1521 1454 1574 1544 1500 1566 1545 1540 1489 1520 1541 1500 1604 1532 1585 1478 1537 1539 1509 1539 1547 1556 1550 1613 1562 1600 1589 1558 1533 1608 1671 1646 1724 1819 1767 1797 1826 1913 1890 1953 1973 1912 1825 1847 1683 1734 1751 1680 1736 1624 1634 1634 1722 1706 1667 1689 1735 1794 1723 1829 1846 1775 1835 1812 1828 1820 1818 1855 1838 1880 1869 1915 2034 2091 2070 2118 2201 2312 2424 2453 2672 2687 2714 2915 2793 2722 2642 2409 2391 2247 2185 2061 2107 2015 2049 2059 1979 1882 2009 2060 2040 2040 2063 2148 2086 2218 2195 2198 2033 2050 2016 1992 1970 1789 1752 1699 1695 1682 1665 1659 1536 1638 1510 1547 1551 1536 1498 1549 1533 1494 1464 1479 1456 1428 1399 1482 1571 1524 1459 1410 1460 1390 1446 1470 1375 1436 1466 1495 1430 1496 1399 1479 1422 1409 1392 1382 1369 1375 1419 1381 1442 1390 1371 1384 1350 1395 1457 1382 1441 1346 1409 1395 1374 1445 1469 1446 1446 1424 1404 1370 1438 1397 1469 1438 1475 1419 1526 1511 1425 1517 1564 1476 1515 1630 1524 1469 1584 1471 1527 1521 1438 1564 1619 1670 1582 1703 1683 1802 1732 1805 1981 1940 2194 2290 2362 2446 2517 2560 2554 2310 2204 2151 2038 1809 1839 1735 1774 1663 1793 1596 1659 1702 1739 1724 1730 1765 1782 1879 1909 1938 1986 1940 1924 1952 1823 1723 1766 1690 1676 1605 1583 1573 1489 1509 1468 1420 1468 1494 1460 1458 1476 1420 1447 1519 1505 1482 1393 1483 1457 1388 1465 1450 1427 1423 1537 1455 1613 1642 1561 1592 1688 1752 1754 1719 1719 1658 1625 1538 1633 1530 1564 1543 1598 1535 1519 1540 1468 1504 1492 1553 1651 1519 1584 1534 1633 1661 1679 1670 1660 1644 1674 1608 1630 1630 1585 1615 1617 1652 1624 1714 1610 1653 1726 1620 1659 1583 1562 1661 1571 1605 1609 1665 1658 1631 1665 1693 1676 1766 1773 1780 1831 1883 1925 1901 2108 2208 2272 2397 2494 2728 2805 3164 3263 3134 3248 3109 2940 2749 2558 2396 2277 2075 2041 2050 2022 1950 2070 1862 1957 1939 2059 2068 1939 2056 2193 2243 2360 2415 2410 2420 2337 2218 2206 2085 1921 1900 1898 1851 1782 1759 1758 1705 1705 1709 1705 1584 1696 1729 1768 1827 1795 1734 1848 1887 2025 1969 2059 1928 1949 1952 1875 1797 1834 1772 1712 1682 1709 1631 1685 1637 1582 1698 1640 1733 1678 1605 1696 1716 1722 1822 1713 1774 1673 1675 1727 1690 1638 1549 1518 1599 1544 1473 1565 1459 1540 1490 1430 1486 1459 1568 1517 1460 1511 1500 1517 1554 1550 1518 1512 1450 1494 1477 1422 1500 1493 1465 1374 1489 1415 1419 1436 1433 1314 1355 1372 1414 1387 1428 1444 1376 1405 1373 1452 1427 1395 1399 1464 1409 1366 1392 1392 1386 1450 1376 1386 1309 1412 1341 1359 1309 1327 1369 1348 1436 1406 1328 1224 1303 1334 1363 1441 1271 1360 1323 1385 1389 1325 1347 1311 1368 1450 1428 1369 1403 1384 1318 1438 1390 1345 1406 1456 1368 1330 1319 1387 1368 1401 1361 1358 1340 1351 1346 1371 1343 1448 1382 1355 1433 1359 1381 1358 1346 1407 1321 1369 1386 1357 1389 1297 1332 1381 1339 1329 1360 1392 1376 1392 1396 1389 1421 1378 1398 1393 1322 1422 1406 1356 1418 1393 1351 1338 1406 1353 1378 1441 1296 1434 1414 1411 1431 1450 1396 1515 1428 1451 1457 1448 1515 1415 1497 1505 1438 1517 1562 1549 1549 1528 1473 1517 1504 1558 1511 1588 1592 1528 1591 1590 1659 1680 1554 1663 1636 1730 1767 1776 1783 1776 1889 1938 1990 2050 2047 2033 2164 2333 2325 2473 2484 2625 2617 2767 2855 2680 2722 2657 2566 2473 2332 2403 2205 2064 2095 2105 2114 2047 2038 2145 2144 2033 2009 2030 2047 2098 2046 2101 2166 2228 2138 2171 2117 1987 2027 2014 1945 1945 1886 1776 1790 1722 1636 1726 1630 1651 1581 1714 1584 1586 1626 1627 1664 1627 1611 1615 1628 1571 1555 1616 1557 1615 1596 1591 1580 1609 1655 1523 1675 1650 1597 1598 1607 1634 1574 1737 1703 1656 1738 1631 1709 1765 1792 1697 1747 1755 1771 1747 1792 1853 1941 1996 1997 2057 2231 2215 2357 2495 2599 2853 2946 3018 3343 3474 3592 3580 3531 3435 3423 3247 3155 2849 2776 2629 2447 2376 2445 2217 2185 2191 2231 2226 2242 2196 2252 2290 2332 2351 2527 2535 2590 2604 2673 2632 2551 2469 2416 2265 2160 2155 2042 1972 1913 1910 1900 1798 1731 1736 1628 1734 1699 1672 1670 1590 1631 1642 1607 1593 1514 1463 1580 1519 1518 1525 1577 1541 1563 1477 1537 1515 1500 1499 1494 1537 1493 1456 1460 1450 1429 1395 1442 1469 1478 1494 1460 1434 1501 1456 1435 1494 1442 1506 1507 1454 1474 1496 1464 1434 1426 1448 1512 1529 1475 1487 1449 1513 1495 1485 1502 1536 1539 1506 1526 1529 1415 1432 1414 1449 1400 1397 1404 1468 1545 1491 1448 1484 1486 1506 1494 1471 1490 1543 1582 1534 1613 1690 1702 1678 1617 1680 1589 1613 1577 1586 1565 1509 1556 1602 1470 1504 1435 1426 1517 1476 1496 1445 1534 1485 1538 1519 1538 1579 1607 1614 1590 1612 1606 1593 1569 1571 1545 1580 1646 1654 1645 1657 1683 1755 1816 1669 1842 1955 2113 2126 2108 2262 2177 2210 2048 2045 1932 1875 1809 1826 1738 1623 1619 1722 1637 1697 1688 1669 1615 1656 1710 1739 1695 1755 1779 1872 1929 1975 1960 1980 1999 1970 1957 1994 1908 1996 2005 1968 2144 2080 2101 2127 2107 2084 2157 2073 1994 1905 1922 1915 1802 1750 1842 1831 1755 1645 1801 1697 1671 1706 1778 1750 1656 1719 1716 1847 1782 1752 1784 1817 1805 1887 1863 1877 1898 1914 1817 1781 1841 1827 1804 1820 1853 1999 2016 1947 2008 2224 2270 2458 2519 2641 2679 2704 2624 2601 2548 2419 2214 2152 2104 2040 2082 2027 1965 1874 1913 1844 1911 1969 1844 1885 1870 1824 1841 1897 1993 1933 2141 2164 2128 2049 2063 2037 1931 1953 1860 1753 1748 1716 1759 1722 1681 1637 1562 1637 1607 1541 1533 1582 1491 1550 1431 1478 1380 1538 1446 1404 1460 1425 1440 1441 1376 1362 1358 1387 1380 1380 1376 1401 1391 1397 1395 1418 1354 1373 1353 1384 1312 1345 1398 1330 1348 1377 1371 1452 1382 1396 1352 1412 1313 1388 1392 1323 1313 1375 1381 1384 1400 1371 1415 1359 1380 1399 1503 1403 1400 1397 1351 1375 1307 1379 1386 1385 1379 1425 1384 1351 1362 1323 1399 1373 1426 1358 1443 1365 1467 1396 1381 1454 1427 1386 1408 1381 1405 1400 1355 1466 1448 1449 1502 1513 1536 1501 1504 1568 1598 1546 1558 1503 1566 1526 1525 1489 1506 1405 1517 1385 1420 1477 1500 1389 1480 1501 1392 1448 1514 1516 1498 1441 1460 1496 1455 1495 1531 1391 1569 1529 1509 1481 1418 1500 1556 1492 1487 1518 1516 1547 1578 1598 1565 1621 1603 1580 1632 1583 1682 1755 1833 1706 1786 1723 1838 1805 1779 1732 1788 1680 1738 1728 1669 1663 1735 1626 1637 1590 1509 1562 1565 1578 1530 1586 1605 1553 1547 1499 1577 1538 1573 1612 1566 1635 1623 1731 1630 1485 1592 1587 1546 1535 1573 1591 1423 1524 1458 1514 1460 1412 1426 1501 1428 1448 1413 1374 1509 1471 1446 1444 1458 1390 1453 1428 1381 1401 1404 1403 1446 1339 1402 1409 1392 1356 1390 1413 1400 1414 1355 1355 1337 1407 1360 1397 1354 1367 1399 1372 1373 1359 1331 1341 1418 1376 1413 1336 1370 1351 1378 1339 1340 1322 1313 1378 1337 1348 1385 1298 1364 1321 1282 1337 1352 1303 1343 1298 1303 1337 1362 1327 1352 1349 1417 1333 1319 1324 1353 1360 1310 1406 1348 1439 1332 1345 1308 1291 1351 1338 1329 1357 1379 1336 1362 1367 1297 1378 1336 1341 1366 1402 1369 1335 1287 1368 1377 1359 1458 1303 1416 1291 1347 1370 1373 1326 1369 1416 1281 1364 1364 1323 1321 1337 1421 1373 1354 1336 1428 1298 1447 1340 1347 1393 1357 1404 1285 1362 1387 1386 1411 1392 1409 1391 1425 1468 1399 1427 1348 1374 1410 1384 1418 1363 1379 1349 1370 1421 1346 1421 1388 1357 1415 1422 1438 1394 1357 1429 1432 1420 1431 1442 1406 1384 1407 1446 1421 1419 1424 1497 1451 1431 1416 1456 1453 1420 1504 1611 1557 1508 1550 1533 1506 1504 1487 1493 1494 1485 1491 1429 1443 1390 1469 1475 1428 1404 1425 1426 1516 1512 1454 1402 1327 1461 1395 1463 1426 1501 1504 1500 1485 1544 1459 1440 1433 1445 1470 1369 1501 1430 1385 1442 1379 1404 1410 1371 1439 1429 1454 1420 1406 1375 1365 1389 1450 1375 1392 1316 1379 1356 1427 1384 1376 1420 1356 1468 1364 1443 1420 1422 1299 1430 1393 1397 1373 1394 1376 1362 1402 1390 1419 1382 1399 1435 1398 1396 1428 1389 1452 1436 1430 1416 1406 1411 1442 1402 1454 1374 1418 1481 1392 1452 1331 1436 1357 1485 1419 1382 1414 1366 1409 1425 1413 1379 1420 1463 1435 1443 1473 1361 1472 1496 1460 1426 1434 1472 1481 1489 1385 1462 1505 1365 1430 1450 1471 1400 1478 1457 1473 1443 1426</counts>
			</dataPoints>
		</scan>
	</xrdMeasurement>
</xrdMeasurements>