File: dataset/precursor_mixture/Li2CO3_0p9001-ZrO2_0p1000--8min.xrdml
<?xml version="1.0"?>
<xrdMeasurements xmlns="http://www.xrdml.com/XRDMeasurement/2.3" xmlns:xsi="http://www.w3.org/2001/XMLSchema-instance" xsi:schemaLocation="http://www.xrdml.com/XRDMeasurement/2.3 http://www.xrdml.com/XRDMeasurement/2.3/XRDMeasurement.xsd" status="Completed" recordIdentifier="{FCC385A4-DC80-4C36-BECB-3746C1EB06B9}">
	<comment>
		<entry/>
	</comment>
	<sample type="To be analyzed">
		<id>Li2CO3_0p9001-ZrO2_0p1000--8min</id>
		<name></name>
		<preparedBy></preparedBy>
	</sample>
	<xrdMeasurement measurementType="Scan" status="Completed" sampleMode="Reflection">
		<usedWavelength intended="K-Alpha 1">
			<kAlpha1 unit="Angstrom">1.5405980</kAlpha1>
			<kAlpha2 unit="Angstrom">1.5444260</kAlpha2>
			<kBeta unit="Angstrom">1.3922500</kBeta>
			<ratioKAlpha2KAlpha1>0.5000</ratioKAlpha2KAlpha1>
		</usedWavelength>
		<incidentBeamPath>
			<radius unit="mm">145.00</radius>
			<xRayTube id="1010048" name="Empyrean Cu LFF HR (9430 033 7310x)">
				<tension unit="kV">40.0</tension>
				<current unit="mA">15.0</current>
				<anodeMaterial>Cu</anodeMaterial>
				<focus type="Line">
					<length unit="mm">12.0</length>
					<width unit="mm">0.4</width>
					<takeOffAngle unit="deg">6.0</takeOffAngle>
				</focus>
			</xRayTube>
			<sollerSlit id="21010002" name="Soller slits 0.04 rad.">
				<opening unit="rad">0.0400</opening>
			</sollerSlit>
			<mask id="22031000" name="Fixed mask 13 mm">
				<width unit="mm">9.00</width>
			</mask>
			<divergenceSlit id="22120001" name="Divergence slit 1°" xsi:type="fixedDivergenceSlitType">
				<distanceToSample unit="mm">50.00</distanceToSample>
				<height unit="mm">1.52</height>
			</divergenceSlit>
		</incidentBeamPath>
		<sampleMovement xsi:type="spinningSampleMovementType">
			<spinnerRevolutionTime unit="seconds">1.0</spinnerRevolutionTime>
		</sampleMovement>
		<diffractedBeamPath>
			<radius unit="mm">145.00</radius>
			<antiScatterSlit id="22090040" name="AS slit 9 mm (PIXcel)" xsi:type="fixedAntiScatterSlitType">
				<height unit="mm">9.00</height>
			</antiScatterSlit>
			<sollerSlit id="21020003" name="Large Soller slits 0.04 rad.">
				<opening unit="rad">0.0400</opening>
			</sollerSlit>
			<filter id="20030001" name="Large beta-filter Nickel">
				<material>Ni</material>
				<thickness unit="mm">0.020</thickness>
			</filter>
			<detector id="7010019" name="PIXcel1D-Medipix3 detector" xsi:type="rtmsDetectorType">
				<phd unit="keV">
					<lowerLevel>4.02</lowerLevel>
					<upperLevel>11.27</upperLevel>
				</phd>
				<mode>Scanning</mode>
				<activeLength unit="deg">5.542</activeLength>
			</detector>
		</diffractedBeamPath>
		<scan appendNumber="0" mode="Continuous" scanAxis="Gonio" status="Completed">
			<header>
				<startTimeStamp>2024-11-14T14:21:09-08:00</startTimeStamp>
				<endTimeStamp>2024-11-14T14:29:16-08:00</endTimeStamp>
				<author>
					<name>AutomatedUser</name>
				</author>
				<source>
					<applicationSoftware version="1.7b (136)">PANalytical Aeris Instrument Suite</applicationSoftware>
					<instrumentControlSoftware version="3.2.00000000 20240306">AERIS</instrumentControlSoftware>
					<instrumentID>950485</instrumentID>
				</source>
			</header>
			<dataPoints>
				<positions axis="2Theta" unit="deg">
					<startPosition>10.00943322</startPosition>
					<endPosition>99.99442286</endPosition>
				</positions>
				<positions axis="Omega" unit="deg">
					<startPosition>5.00471661</startPosition>
					<endPosition>49.99721143</endPosition>
				</positions>
				<commonCountingTime unit="seconds">12.495</commonCountingTime>
				<counts unit="counts">2700 2686 2752 2792 2736 2793 2784 2644 2674 2653 2754 2596 2730 2673 2717 2732 2678 2618 2683 2732 2686 2703 2652 2646 2623 2578 2670 2623 2650 2698 2610 2605 2561 2600 2551 2624 2607 2624 2583 2538 2628 2516 2649 2682 2590 2727 2647 2699 2619 2606 2546 2625 2610 2461 2538 2651 2586 2484 2651 2592 2462 2641 2585 2474 2498 2480 2577 2581 2529 2602 2454 2468 2452 2472 2447 2461 2474 2513 2491 2510 2503 2502 2483 2604 2567 2547 2425 2561 2409 2441 2469 2428 2508 2509 2526 2411 2374 2469 2470 2467 2404 2500 2328 2486 2444 2393 2441 2381 2403 2414 2397 2419 2366 2421 2482 2399 2411 2427 2388 2317 2406 2341 2442 2427 2441 2280 2421 2374 2396 2436 2442 2332 2369 2465 2279 2361 2358 2372 2431 2354 2332 2369 2350 2313 2271 2290 2377 2376 2294 2384 2355 2322 2277 2318 2379 2277 2338 2319 2299 2300 2433 2371 2387 2264 2387 2284 2323 2265 2383 2347 2291 2247 2253 2277 2339 2305 2298 2331 2223 2295 2311 2266 2199 2163 2221 2327 2168 2193 2249 2299 2167 2245 2172 2199 2204 2206 2203 2229 2207 2233 2243 2313 2220 2235 2165 2246 2180 2244 2243 2237 2188 2224 2231 2253 2147 2193 2216 2302 2175 2227 2174 2246 2203 2190 2235 2232 2158 2156 2259 2173 2290 2128 2201 2068 2119 2181 2169 2170 2101 2175 2136 2138 2149 2185 2161 2194 2225 2198 2186 2097 2211 2101 2217 2170 2114 2149 2153 2177 2143 2172 2129 2179 2164 2184 2141 2113 2003 2083 2190 2032 2190 2147 2190 2187 2204 2138 2241 2244 2179 2178 2145 2147 2163 2086 2147 2106 2162 2122 2130 2149 2041 2052 2204 2203 2291 2100 2181 2102 2137 2178 2197 2124 2050 2040 2095 2084 2057 2089 2147 2059 2056 2095 2117 2122 2101 2145 2055 2105 2120 2080 2207 2147 2158 2148 2015 2050 2067 2109 2140 2192 2074 2095 2067 2119 2121 2124 2157 2264 2075 2090 2127 2087 2095 2129 2056 2024 2127 2143 2079 2061 2179 2113 2122 2109 2134 2141 2123 2098 2148 2071 2160 2052 2157 2079 2149 2059 2240 2082 2188 2164 2143 2139 2200 2230 2141 2146 2111 2134 2158 2198 2213 2199 2224 2166 2194 2078 2200 2204 2185 2104 2076 2206 2107 2225 2184 2240 2199 2130 2187 2098 2186 2118 2096 2104 2042 2088 2160 2089 2117 2097 2089 2076 2206 2151 2135 2118 2071 2089 2138 2133 2160 2139 2055 2081 2102 2113 2197 2128 2136 2199 2170 2101 2249 2197 2185 2109 2229 2096 2089 2130 2047 2092 2208 2222 2048 2083 2134 2101 2138 2143 2072 2128 2091 2095 2102 2056 2181 2031 2161 2129 2225 2103 2077 2091 2124 2135 2174 2104 2139 2170 2155 2187 2099 2073 2103 2089 2052 2168 2239 2147 2099 2087 2113 2151 2108 2085 2088 2128 2132 2121 2091 2086 2116 2107 2060 2103 2098 2133 2110 2082 2116 2159 2032 2120 2114 2214 2015 2111 2068 2129 2066 2190 2081 2023 2084 2009 2073 2129 2165 2103 2115 2154 2117 2056 2178 2109 2123 2115 1990 2158 2133 2210 2072 2168 2192 2066 2060 2122 1972 2065 2009 2012 2126 2075 2101 2123 2220 2232 2140 2170 2127 2090 2063 2112 2156 2056 2029 2090 1991 2047 2082 2093 2136 2131 2148 1990 2053 2022 2068 2143 2085 2087 2045 2077 2099 2007 2086 2023 2053 2020 2101 2087 1992 2055 2039 2148 2056 2055 2023 2105 2030 2071 2049 2028 2129 2221 2054 2134 2100 2011 2065 2126 2066 2089 2012 2057 2012 2012 2042 2022 1925 2041 2035 2037 2134 2070 2092 1994 2030 2100 2051 2032 2128 2020 2055 2065 2023 2015 2056 2065 2083 1994 2054 1995 2044 1991 2078 1977 2127 2021 2022 1992 2084 2034 2035 2007 2057 1959 2051 2033 2089 1998 2060 1996 2081 2035 1990 2086 2121 2047 2156 2066 2168 2124 2057 2088 2206 2057 2024 2058 2123 2117 2124 2150 2023 2189 2178 2176 2154 2237 2141 2185 2211 2165 2271 2167 2232 2243 2298 2271 2291 2346 2236 2334 2345 2300 2311 2290 2287 2348 2355 2313 2393 2283 2255 2294 2245 2213 2320 2198 2193 2251 2177 2195 2224 2170 2165 2149 2177 2048 2064 2028 2131 2050 2051 2012 2097 2080 2060 2000 2088 1996 1973 2036 1983 1935 1982 1973 1931 2005 1976 2032 1952 1939 1969 1966 2051 1905 1932 2042 1883 1950 1943 1909 1947 1968 1881 1913 2025 1889 1952 1926 1903 1876 1921 1935 2017 1916 2036 1940 2001 1861 1980 1924 1921 1955 1873 1962 1888 1942 1883 2006 1873 1945 1918 1912 2000 1875 1841 1860 1917 1844 1836 1892 1895 1898 1981 1929 1942 1960 1919 1941 1871 1849 1838 1862 1883 1938 1837 1891 1890 1883 1964 1962 1848 1901 2046 1846 1927 1965 1949 1903 1834 1893 1840 1902 1856 1854 1940 1941 1963 1898 1945 1896 1930 1842 1977 1919 1873 1889 1913 1826 1921 1865 1994 1960 1888 1880 1951 1958 1896 1851 1787 1867 1850 1917 1814 1818 1867 1808 1844 1885 1796 1948 1851 1933 1831 1847 1938 1836 1864 1880 1921 1921 1841 1758 1832 1924 1791 1842 1834 1861 1836 1848 1811 1784 1755 1754 1804 1837 1843 1843 1817 1831 1839 1777 1842 1750 1841 1745 1813 1771 1836 1773 1839 1793 1785 1881 1823 1770 1741 1805 1790 1810 1790 1861 1853 1755 1816 1779 1890 1768 1830 1817 1843 1808 1870 1825 1763 1863 1811 1810 1822 1831 1738 1859 1788 1820 1747 1820 1835 1735 1848 1780 1828 1705 1765 1840 1735 1769 1743 1771 1803 1804 1733 1810 1731 1775 1817 1757 1766 1721 1746 1778 1772 1734 1893 1765 1779 1733 1811 1745 1821 1801 1788 1872 1840 1893 1815 1839 1853 1866 1874 1834 1910 1856 1833 1895 1822 1882 1918 1902 1777 1841 1846 1898 1903 1989 1994 1869 2017 2031 1986 2055 2109 2087 2033 2100 2091 2079 2113 2140 2195 2203 2205 2262 2307 2413 2401 2460 2587 2721 2671 2785 2912 2971 3189 3416 3524 3851 4064 4255 4455 4669 4918 5295 5693 5913 6393 6577 7231 7360 7730 8153 8278 8846 9129 9534 9715 9991 10186 10253 10726 11044 10895 11258 11332 11360 11412 11557 11577 11297 11128 11077 10501 10369 9778 9380 8919 8470 7780 7272 6763 6247 5939 5432 5000 4806 4382 4240 3936 3767 3649 3397 3241 3212 2866 2956 2778 2745 2638 2582 2487 2412 2470 2314 2212 2114 2258 2214 2047 2119 1991 2068 1999 2032 2018 1919 1987 1993 1883 1901 1906 1890 1948 1794 1978 1890 1880 1865 1801 1840 1688 1794 1836 1778 1840 1806 1798 1842 1796 1755 1798 1858 1802 1840 1722 1785 1762 1705 1723 1789 1714 1743 1755 1838 1759 1805 1753 1782 1829 1817 1765 1783 1869 1816 1784 1770 1782 1798 1820 1724 1788 1711 1738 1730 1714 1718 1602 1783 1770 1705 1816 1769 1688 1778 1814 1792 1701 1702 1741 1731 1712 1779 1675 1810 1747 1687 1833 1800 1859 1684 1714 1757 1793 1763 1740 1741 1837 1715 1786 1739 1817 1776 1786 1824 1827 1847 1779 1790 1856 1841 1803 1845 1918 1977 1926 1992 2017 1968 1978 2025 2061 2130 2198 2239 2351 2352 2469 2407 2446 2414 2595 2747 2723 2728 2845 2890 2907 3096 3018 3169 3248 3203 3240 3361 3332 3346 3359 3393 3594 3365 3463 3334 3456 3357 3304 3251 3094 3211 3085 3111 3006 2907 2939 2737 2735 2644 2601 2571 2446 2492 2379 2307 2314 2331 2285 2251 2240 2314 2312 2263 2200 2331 2296 2295 2395 2375 2364 2349 2339 2442 2586 2625 2677 2652 2717 2681 2752 2723 2833 2915 2911 2886 3029 2956 2981 3032 2839 2994 2976 2971 3031 3063 2963 2972 2860 2957 2839 2886 2788 2816 2752 2639 2667 2668 2630 2558 2660 2545 2784 2588 2625 2701 2630 2575 2634 2672 2603 2660 2650 2654 2679 2568 2511 2618 2550 2644 2421 2584 2385 2283 2456 2381 2345 2326 2358 2204 2308 2184 2145 2066 2010 2032 2040 1923 1896 1974 1877 1970 1884 1889 1814 1827 1928 1820 1734 1654 1721 1702 1743 1761 1724 1785 1702 1761 1683 1671 1693 1683 1716 1659 1690 1704 1714 1632 1615 1651 1569 1689 1725 1627 1653 1660 1669 1646 1698 1618 1623 1549 1667 1639 1560 1634 1655 1547 1586 1625 1528 1678 1623 1591 1581 1587 1599 1695 1586 1592 1701 1623 1640 1625 1595 1597 1514 1587 1658 1638 1550 1599 1581 1548 1552 1593 1588 1602 1598 1599 1578 1543 1545 1528 1624 1540 1603 1654 1615 1586 1591 1615 1534 1584 1511 1551 1650 1581 1629 1579 1524 1608 1508 1598 1451 1465 1645 1620 1573 1555 1633 1574 1541 1552 1562 1605 1537 1604 1558 1550 1568 1560 1568 1566 1496 1685 1514 1654 1553 1611 1571 1510 1599 1552 1619 1594 1588 1539 1555 1523 1597 1520 1477 1577 1555 1562 1567 1494 1558 1577 1610 1622 1642 1515 1548 1549 1582 1481 1620 1539 1544 1608 1589 1475 1592 1475 1515 1540 1593 1548 1608 1534 1512 1550 1547 1582 1552 1566 1558 1546 1531 1497 1559 1548 1613 1539 1471 1485 1513 1565 1585 1619 1566 1575 1545 1582 1649 1618 1606 1520 1563 1619 1586 1595 1647 1617 1502 1525 1594 1489 1566 1494 1574 1590 1535 1656 1558 1587 1637 1646 1575 1558 1668 1667 1633 1569 1573 1588 1609 1636 1684 1630 1581 1715 1668 1664 1609 1651 1664 1681 1701 1665 1658 1707 1744 1764 1702 1679 1652 1704 1769 1763 1678 1800 1831 1792 1869 1774 1863 1891 1899 1859 1904 1926 1877 1866 1929 1890 2018 2021 2104 2017 2061 2200 2138 2219 2353 2311 2319 2422 2467 2492 2517 2667 2680 2763 2850 3008 3278 3282 3368 3570 3673 3937 4063 4220 4513 4795 5018 5314 5535 5732 5905 6277 6566 6934 7191 7343 7730 7814 7984 8371 8511 8775 8803 9163 9080 9265 9381 9510 9644 9522 9390 9336 9364 9082 8906 8832 8348 8209 7840 7592 7103 6918 6496 6155 5947 5595 5238 4910 4778 4544 4339 4054 3952 3863 3612 3522 3325 3214 3129 2972 2879 2830 2769 2765 2687 2532 2520 2479 2535 2335 2320 2294 2300 2319 2179 2165 2166 2119 2079 2093 2083 2092 2059 2056 2015 2012 2045 1996 2052 1953 1948 2031 2019 2005 1993 2009 1963 2017 2079 1971 2061 1989 1979 1996 2109 2104 2190 2145 2187 2228 2330 2325 2300 2422 2417 2494 2651 2682 2776 2796 2884 3037 3043 3166 3318 3364 3471 3554 3712 3718 3837 3835 4050 4223 4391 4419 4451 4630 4649 4709 4819 4758 4801 4821 4820 4819 4854 4778 4706 4699 4603 4487 4508 4412 4190 4030 3951 3944 3751 3689 3546 3512 3293 3144 3138 3025 2951 2763 2827 2736 2618 2689 2494 2371 2534 2454 2373 2420 2363 2376 2314 2242 2264 2272 2310 2159 2200 2257 2180 2302 2107 2293 2313 2312 2134 2249 2199 2397 2299 2357 2394 2401 2367 2479 2469 2540 2634 2695 2707 2836 2834 2970 2983 3103 3074 3439 3385 3601 3907 3977 4132 4385 4566 4720 4991 5352 5511 5739 6029 6118 6842 7015 7207 7647 7922 8242 8586 9012 9181 9475 9689 10106 10395 10567 10829 11038 11174 11386 11462 11391 11590 11424 11498 11418 11465 11396 11169 10892 10678 10281 10055 9616 9223 8889 8296 7957 7669 7192 6886 6632 6249 6006 5676 5427 5160 5179 4908 4657 4633 4390 4268 4115 4106 4002 3880 4017 3814 3715 3845 3796 3686 3722 3800 3830 3839 3863 4027 4145 4148 4206 4400 4387 4559 4741 4942 5067 5355 5474 5508 5812 6089 6331 6732 6806 6983 7439 7616 8073 8212 8563 8941 9427 9488 10011 10204 10667 10787 11253 11490 11849 12369 12982 13129 13724 13961 14186 14452 14839 15297 15432 15715 16141 16680 16919 17251 17304 17443 17649 18167 18240 18360 18304 18936 18657 19101 19257 18922 18902 18896 18816 18653 18192 17912 17667 17410 16576 16014 15527 14823 14495 13458 13030 12327 11575 11017 10520 9832 9457 8951 8302 7903 7393 7022 6531 6374 5853 5543 5337 5216 4831 4592 4430 4354 3922 3884 3723 3532 3464 3278 3271 3182 3154 3000 2831 2862 2840 2739 2668 2544 2445 2444 2515 2462 2394 2303 2201 2287 2189 2315 2244 2138 2203 2174 2215 2054 2108 2089 2046 2006 1934 1898 2082 1913 1917 1875 1914 1935 1981 1952 1991 1965 1857 1773 1867 1920 1819 1829 1862 1837 1779 1830 1741 1851 1849 1853 1774 1779 1811 1718 1741 1760 1691 1791 1807 1792 1763 1725 1768 1720 1794 1736 1729 1745 1727 1785 1728 1713 1750 1746 1719 1794 1725 1651 1729 1650 1673 1757 1715 1690 1711 1715 1743 1713 1739 1688 1865 1744 1757 1699 1783 1698 1721 1758 1646 1781 1743 1708 1760 1811 1735 1786 1887 1766 1794 1822 1885 1835 1814 1923 1922 1916 1878 1975 1904 2016 1945 1995 2093 2075 2098 2160 2182 2222 2342 2478 2427 2390 2526 2570 2574 2649 2782 2960 3116 3096 3438 3566 3633 3801 3946 4201 4371 4533 4735 4939 5289 5262 5560 5690 5965 6260 6331 6453 6816 6968 7118 7297 7362 7555 7696 7921 7865 7883 7972 8035 7899 7967 7951 7815 7600 7660 7382 7300 7349 7071 6769 6613 6380 6134 5895 5703 5492 5108 4981 4867 4815 4685 4354 4180 4091 3994 3953 3776 3708 3601 3473 3411 3334 3113 3105 3045 2944 2775 2844 2525 2486 2428 2468 2326 2488 2353 2305 2319 2206 2136 2100 2063 2096 1969 1975 2005 1978 1930 1950 1889 1874 1821 1872 1881 1885 1792 1786 1827 1892 1856 1917 1811 1860 1895 1898 1923 1963 1823 2013 1980 1919 2056 2054 2115 2124 2115 2186 2283 2198 2251 2349 2447 2365 2386 2451 2457 2508 2604 2626 2622 2596 2756 2643 2680 2752 2695 2763 2768 2752 2679 2689 2785 2711 2671 2611 2613 2554 2446 2471 2467 2395 2323 2264 2217 2325 2229 2131 2053 2113 2045 2026 2034 2046 1996 1994 1828 1925 1933 1940 1939 1916 2069 1956 1984 2128 2012 2125 2209 2204 2364 2351 2389 2456 2524 2600 2695 2838 2907 3105 3102 3302 3361 3449 3621 3668 3792 4051 4122 4081 4293 4350 4550 4541 4682 4667 4714 4754 4902 4856 4917 4861 4796 4914 4678 4798 4565 4431 4142 4094 3993 4037 3665 3530 3388 3188 3161 3041 2848 2758 2723 2510 2546 2394 2377 2248 2193 2142 2161 2210 2014 2059 2012 2038 1989 1935 2004 1985 2048 2036 2020 2077 2048 2105 2039 2215 2121 2222 2391 2260 2529 2447 2629 2795 2876 2990 3008 3177 3299 3296 3586 3706 3930 3966 4079 4285 4428 4465 4697 4877 5033 5047 5237 5241 5227 5420 5587 5522 5674 5607 5762 5767 5751 5733 5661 5588 5644 5524 5335 5261 5203 5008 4687 4442 4497 4143 4000 3876 3667 3435 3276 3156 3101 2883 2870 2645 2535 2495 2391 2325 2231 2133 2067 1944 1923 1894 1847 1863 1744 1748 1780 1679 1712 1579 1668 1564 1625 1618 1518 1550 1516 1503 1481 1576 1391 1471 1459 1506 1508 1396 1352 1526 1388 1426 1432 1411 1393 1381 1393 1401 1359 1408 1404 1443 1342 1344 1404 1399 1398 1405 1385 1389 1394 1407 1407 1361 1385 1375 1348 1349 1423 1329 1360 1371 1378 1409 1353 1347 1381 1323 1343 1369 1323 1330 1385 1440 1353 1377 1347 1386 1379 1346 1333 1435 1376 1447 1461 1345 1473 1391 1433 1438 1501 1506 1473 1518 1541 1535 1654 1481 1537 1574 1585 1675 1604 1604 1620 1724 1664 1652 1721 1665 1664 1756 1706 1817 1773 1732 1823 1707 1817 1806 1808 1817 1819 1680 1760 1677 1789 1642 1684 1598 1652 1569 1642 1540 1531 1564 1538 1510 1456 1516 1463 1475 1550 1511 1488 1489 1490 1497 1446 1446 1479 1478 1472 1438 1491 1448 1468 1438 1445 1541 1466 1488 1377 1507 1489 1437 1537 1508 1521 1557 1561 1624 1706 1608 1707 1697 1807 1739 1876 1886 1997 2046 2076 2252 2282 2299 2339 2558 2434 2680 2721 2838 2979 3063 3210 3251 3342 3417 3541 3744 3841 3762 3851 3884 4079 4094 4238 4051 4163 4222 4239 4260 4407 4400 4342 4278 4240 4100 4143 4118 3857 3809 3854 3607 3730 3740 3582 3593 3541 3376 3461 3276 3370 3331 3298 3275 3209 3281 3188 3174 3117 3085 3094 3071 2963 2997 2985 2946 2944 2652 2779 2697 2698 2561 2563 2324 2404 2268 2241 2093 2112 2032 2055 1955 1892 1833 1870 1748 1714 1650 1625 1583 1593 1653 1611 1621 1564 1563 1643 1619 1556 1569 1574 1593 1610 1639 1595 1662 1725 1637 1684 1642 1710 1766 1780 1781 1911 1968 1975 1917 2016 1984 2004 2026 2205 2065 2133 2221 2294 2242 2281 2332 2297 2253 2298 2262 2357 2375 2479 2390 2244 2349 2259 2247 2322 2197 2252 2368 2155 2189 2168 2103 2085 2051 2027 1961 1973 2005 1996 1973 1886 1881 1821 1902 1907 1871 1850 1795 1815 1916 1951 1913 2015 1898 1919 1889 1895 1857 1942 1948 1945 1872 1950 1915 1887 1777 1971 1856 1912 1917 1861 1853 1853 1782 1783 1841 1774 1848 1736 1754 1706 1729 1728 1734 1692 1639 1665 1631 1583 1431 1562 1510 1508 1447 1494 1385 1434 1347 1452 1398 1333 1317 1262 1329 1308 1332 1256 1345 1284 1290 1298 1281 1270 1274 1285 1245 1321 1228 1255 1245 1234 1196 1244 1174 1308 1199 1187 1208 1247 1165 1231 1243 1258 1242 1234 1293 1185 1278 1184 1202 1220 1184 1137 1246 1238 1252 1193 1214 1208 1212 1239 1258 1230 1214 1234 1320 1196 1208 1215 1280 1192 1185 1283 1254 1236 1236 1331 1279 1284 1328 1344 1272 1345 1410 1488 1444 1367 1389 1415 1454 1468 1501 1529 1524 1649 1534 1506 1623 1633 1605 1650 1640 1612 1639 1613 1620 1695 1684 1569 1659 1710 1658 1660 1638 1607 1627 1541 1585 1601 1486 1459 1512 1408 1446 1403 1406 1398 1388 1331 1300 1340 1391 1250 1295 1311 1275 1316 1283 1291 1334 1322 1231 1282 1341 1268 1395 1299 1376 1319 1411 1500 1377 1587 1501 1540 1625 1588 1649 1645 1745 1790 1780 1830 1853 1925 1910 2071 1954 2086 2054 2072 2144 2155 2135 2201 2304 2206 2140 2190 2192 2204 2151 2134 2066 1998 2015 1966 1871 1911 1843 1805 1748 1701 1657 1578 1563 1534 1503 1436 1416 1377 1393 1332 1331 1288 1250 1231 1319 1266 1292 1231 1259 1194 1265 1239 1215 1252 1195 1109 1217 1192 1132 1233 1156 1175 1209 1155 1217 1207 1150 1114 1165 1208 1144 1172 1155 1174 1171 1102 1154 1089 1170 1111 1152 1106 1151 1160 1183 1216 1179 1174 1164 1182 1149 1218 1139 1155 1220 1105 1169 1158 1167 1198 1244 1275 1203 1254 1300 1228 1279 1307 1272 1254 1286 1289 1221 1319 1338 1263 1362 1413 1435 1536 1503 1440 1450 1544 1548 1486 1542 1627 1595 1624 1635 1664 1695 1623 1779 1748 1792 1808 1825 1792 1752 1846 1813 1818 1828 1807 1849 1834 1758 1769 1784 1753 1771 1779 1743 1778 1691 1664 1718 1586 1620 1570 1565 1584 1587 1481 1453 1526 1427 1518 1443 1515 1502 1434 1503 1455 1444 1438 1448 1465 1488 1528 1480 1491 1559 1610 1443 1572 1577 1571 1581 1538 1553 1656 1621 1585 1595 1597 1562 1682 1681 1695 1645 1715 1634 1655 1687 1668 1683 1491 1630 1634 1515 1526 1534 1571 1432 1444 1448 1462 1406 1335 1427 1257 1356 1339 1291 1271 1278 1248 1231 1209 1238 1202 1158 1174 1150 1081 1221 1158 1194 1116 1162 1075 1188 1136 1144 1183 1138 1066 1091 1155 1098 1125 1137 1098 1139 1106 1140 1108 1065 1160 1060 1121 1108 1130 1086 1121 1078 1130 1117 1126 1100 1136 1012 1167 990 1103 1053 1072 1064 1112 1083 1131 1116 1094 1118 1067 1092 1058 1064 1002 1066 1052 1039 1045 1072 1065 1050 1053 1103 1049 1065 1090 1049 1061 1027 1080 1049 1086 1090 1043 1120 1160 1066 1030 1083 1088 1097 1070 1137 1051 1119 1069 1033 1014 1115 1097 1031 1097 1069 1072 1047 1042 1059 1053 1115 1088 1118 1048 1142 1016 1137 1088 1105 1068 1135 1067 1149 1126 1071 1138 1035 1072 1085 1108 1166 1104 1179 1197 1094 1151 1084 1217 1149 1182 1142 1164 1164 1195 1141 1167 1174 1136 1189 1197 1244 1198 1174 1185 1237 1176 1212 1191 1206 1219 1228 1225 1235 1197 1239 1308 1247 1267 1282 1196 1220 1192 1198 1262 1274 1207 1240 1219 1295 1206 1276 1261 1282 1235 1228 1202 1240 1292 1254 1341 1329 1312 1354 1303 1371 1331 1341 1343 1330 1354 1378 1294 1400 1354 1417 1364 1453 1365 1367 1415 1523 1439 1414 1385 1372 1311 1385 1391 1464 1341 1416 1346 1377 1397 1362 1413 1437 1377 1438 1475 1514 1527 1556 1543 1643 1657 1611 1655 1620 1680 1737 1743 1855 1854 1834 1954 1994 2045 2147 2122 2266 2349 2466 2338 2431 2577 2699 2721 2752 2713 2957 2959 2977 3042 3127 3258 3229 3278 3465 3363 3552 3507 3501 3519 3563 3478 3525 3632 3459 3463 3406 3396 3551 3346 3324 3180 3189 3118 3233 3161 3058 3033 3031 3046 2918 2992 2854 2969 2761 2802 2753 2903 2830 2713 2812 2768 2759 2795 2908 2917 2790 2894 2851 2835 2941 2851 3098 2969 3018 3050 2974 2958 2970 2890 2899 2909 2945 2822 2696 2731 2701 2643 2533 2557 2414 2468 2326 2320 2296 2238 2156 2142 2061 1992 1991 1934 1874 1884 1845 1834 1691 1673 1683 1626 1748 1729 1596 1637 1634 1609 1613 1653 1611 1624 1663 1651 1680 1826 1739 1803 1827 1873 1932 1844 1978 2040 2146 2142 2256 2232 2416 2429 2449 2480 2630 2673 2802 2825 2917 3046 3110 3182 3350 3337 3270 3363 3413 3455 3461 3486 3568 3358 3584 3679 3670 3648 3543 3623 3492 3407 3521 3329 3276 3347 3459 3254 3152 3147 3155 3209 2995 3007 2926 2918 2905 2836 2850 2763 2792 2733 2681 2741 2698 2710 2631 2638 2568 2570 2601 2592 2576 2555 2508 2351 2341 2458 2274 2346 2341 2301 2196 2220 2067 2194 2075 2008 1965 1976 1903 1908 1749 1761 1732 1649 1639 1640 1646 1608 1595 1564 1521 1597 1527 1473 1547 1522 1425 1478 1590 1510 1493 1501 1535 1484 1492 1511 1474 1553 1560 1523 1567 1633 1563 1559 1635 1588 1570 1541 1601 1581 1592 1593 1543 1577 1500 1532 1518 1453 1464 1513 1478 1429 1499 1413 1418 1358 1357 1261 1379 1292 1278 1244 1278 1190 1285 1254 1155 1137 1241 1175 1202 1115 1103 1202 1115 1121 1058 1181 1095 1148 1124 1138 1047 1131 1076 1018 1025 1084 1054 1022 1121 1146 1057 1072 950 1116 1022 1092 1054 1085 1135 1069 1060 1033 1038 1031 1109 1068 985 1060 1031 1021 1062 1049 1064 1039 1062 1078 977 1041 1055 1026 1038 1033 1042 1035 965 1090 1012 1015 1020 993 1029 1002 994 983 1048 1020 1057 990 1043 959 1021 1059 963 1003 1019 1019 1029 1048 1001 1045 949 1002 969 988 986 1005 987 1058 1001 1086 988 969 1012 998 1072 988 951 1015 1003 1024 980 1017 994 978 1035 993 1017 1034 1001 1080 1063 1047 1045 1027 1036 997 1029 1061 984 1036 1028 992 1055 1010 1078 1003 1035 1034 1001 1009 999 993 1043 1000 1046 1034 1050 1049 1041 1004 1006 1034 1069 1057 996 998 1011 980 1079 1045 1051 1085 1022 1048 987 1038 1038 1066 1044 1107 1001 1061 1055 1052 1019 1122 1086 1061 1090 1064 1053 1054 1062 1055 1027 1085 1052 1084 1086 1053 1139 1022 1143 1128 1165 1129 1160 1109 1094 1150 1187 1149 1184 1193 1186 1242 1259 1280 1232 1154 1219 1274 1271 1305 1349 1388 1380 1434 1412 1405 1473 1546 1570 1545 1582 1630 1603 1704 1567 1710 1673 1773 1830 1888 1818 1912 1876 1893 1909 1914 1981 2028 2018 1950 2035 2024 2039 1940 2046 1880 1963 1964 1936 1772 1962 1757 1746 1710 1550 1692 1637 1624 1549 1527 1574 1539 1511 1473 1482 1375 1472 1352 1382 1397 1330 1332 1196 1285 1263 1250 1294 1145 1153 1250 1228 1256 1178 1198 1121 1139 1220 1130 1180 1165 1150 1119 1182 1208 1175 1166 1214 1173 1192 1236 1127 1221 1210 1252 1214 1199 1181 1192 1157 1139 1234 1202 1173 1259 1222 1257 1242 1260 1322 1314 1259 1323 1316 1280 1371 1293 1371 1408 1406 1470 1454 1587 1510 1550 1622 1580 1734 1732 1705 1795 1854 1754 1870 1935 1932 2001 1935 2176 2116 2180 2238 2123 2217 2340 2205 2251 2318 2279 2366 2365 2325 2384 2371 2390 2335 2330 2361 2341 2355 2278 2202 2318 2293 2199 2228 2328 2218 2198 2236 2182 2082 2119 2107 2081 2081 2155 2069 2122 2092 2029 2035 1990 2012 2019 2014 2014 2043 1986 2040 2043 1998 1978 1931 1961 1928 1962 1922 1834 1869 1811 1876 1784 1734 1752 1793 1771 1746 1736 1595 1642 1597 1478 1538 1521 1514 1446 1395 1502 1384 1460 1335 1372 1385 1322 1365 1297 1277 1326 1234 1240 1282 1238 1255 1197 1209 1252 1250 1231 1222 1202 1229 1233 1330 1256 1301 1265 1220 1294 1363 1287 1354 1396 1381 1431 1379 1468 1412 1494 1467 1583 1571 1607 1587 1680 1745 1733 1817 1819 1727 1844 1854 1924 1971 1809 1950 1884 1936 1960 1943 1977 1961 1924 1940 2048 1938 1933 2008 1900 1935 1913 1827 1892 1931 1816 1842 1905 1915 1740 1869 1893 1797 1836 1869 1763 1857 1833 1805 1789 1816 1868 1791 1828 1777 1894 1910 1789 1806 1868 1836 1733 1756 1802 1840 1723 1756 1771 1690 1667 1624 1658 1600 1670 1737 1618 1718 1720 1706 1762 1697 1813 1801 1813 1769 1821 1868 1860 1880 2075 1972 2061 2085 2100 2106 2251 2316 2211 2302 2243 2389 2458 2446 2481 2470 2633 2620 2539 2569 2614 2585 2579 2666 2597 2589 2543 2449 2585 2458 2595 2534 2602 2459 2457 2428 2333 2411 2302 2357 2246 2336 2318 2279 2316 2291 2198 2307 2164 2272 2289 2217 2284 2236 2265 2186 2243 2233 2362 2298 2281 2242 2255 2280 2105 2239 2180 2247 2163 2235 2253 2217 2168 2185 2237 2237 2194 2225 2224 2079 2143 2244 2138 2216 2147 2119 2067 2070 2155 2108 2070 2016 2026 2068 2027 2040 1932 2046 2034 2074 2057 2063 2063 2080 1973 2086 2112 2083 2097 2054 2106 2175 2209 2148 2269 2148 2135 2187 2182 2276 2296 2199 2213 2266 2233 2294 2238 2245 2298 2299 2259 2306 2260 2324 2261 2189 2341 2200 2316 2184 2136 2167 1980 2030 2077 1995 1993 2013 2064 1987 1885 1851 1914 1848 1818 1789 1850 1807 1851 1824 1765 1813 1791 1768 1809 1762 1831 1849 1888 1791 1908 1916 1969 2005 2026 2089 2132 2241 2159 2197 2372 2420 2427 2529 2679 2678 2780 2788 2999 2963 3015 3123 3179 3258 3239 3342 3321 3423 3431 3506 3574 3494 3563 3635 3564 3520 3451 3542 3381 3497 3483 3326 3366 3270 3176 3092 3086 3185 3123 2973 2878 2861 2923 2725 2696 2614 2696 2479 2477 2433 2375 2291 2323 2149 2182 2080 2108 2053 2058 1953 1886 1835 1869 1677 1826 1699 1655 1732 1634 1601 1610 1591 1568 1512 1601 1473 1467 1452 1422 1411 1351 1315 1342 1369 1315 1314 1298 1260 1373 1317 1305 1267 1280 1297 1319 1245 1247 1183 1183 1188 1249 1239 1249 1318 1263 1233 1254 1267 1248 1322 1269 1303 1261 1314 1348 1403 1288 1319 1319 1375 1379 1386 1382 1459 1506 1451 1551 1520 1621 1578 1675 1637 1643 1641 1656 1691 1740 1760 1815 1882 1858 1881 1919 1945 1949 2076 1995 2142 2023 2106 2099 1995 2071 2093 2116 2266 2185 2240 2226 2152 2278 2279 2257 2361 2319 2349 2306 2356 2448 2427 2339 2381 2310 2336 2219 2353 2341 2285 2296 2096 2158 2166 2113 2122 2123 2000 2074 1890 2048 1997 1862 1979 1851 1782 1765 1784 1691 1812 1772 1681 1691 1638 1682 1624 1692 1592 1690 1674 1562 1711 1678 1717 1630 1738 1675 1721 1713 1649 1704 1665 1749 1714 1788 1711 1757 1731 1721 1677 1734 1711 1721 1725 1684 1595 1659 1593 1622 1602 1602 1507 1553 1456 1471 1430 1442 1416 1366 1493 1378 1434 1400 1491 1362 1328 1316 1312 1274 1292 1306 1194 1322 1320 1303 1299 1283 1297 1211 1320 1232 1309 1238 1302 1299 1241 1317 1308 1304 1312 1379 1355 1384 1418 1417 1456 1437 1423 1623 1509 1495 1579 1568 1550 1576 1589 1706 1672 1685 1665 1792 1810 1816 1831 1784 1784 1770 1878 1785 1796 1736 1858 1824 1804 1930 1820 1844 1743 1759 1781 1677 1734 1763 1705 1663 1653 1684 1611 1662 1577 1585 1661 1564 1594 1532 1526 1468 1536 1529 1562 1513 1476 1475 1513 1519 1480 1482 1591 1458 1603 1534 1544 1618 1613 1648 1669 1584 1586 1554 1628 1635 1597 1673 1632 1651 1582 1654 1698 1665 1730 1640 1678 1587 1650 1631 1682 1644 1623 1575 1646 1624 1595 1551 1542 1558 1570 1525 1484 1534 1435 1507 1510 1447 1407 1370 1398 1370 1407 1349 1345 1335 1361 1349 1354 1384 1287 1320 1252 1255 1283 1214 1293 1326 1230 1312 1216 1242 1237 1271 1298 1348 1389 1238 1271 1293 1312 1307 1259 1315 1303 1340 1345 1309 1304 1342 1290 1286 1283 1278 1268 1315 1339 1211 1304 1224 1299 1319 1223 1177 1246 1158 1275 1181 1255 1098 1151 1211 1189 1248 1172 1205 1129 1121 1186 1171 1153 1182 1147 1217 1154 1214 1159 1124 1172 1105 1141 1114 1092 1131 1262 1134 1183 1159 1141 1163 1192 1257 1212 1222 1266 1272 1252 1247 1239 1273 1193 1255 1272 1195 1216 1168 1262 1270 1305 1269 1267 1257 1300 1292 1292 1304 1329 1316 1323 1301 1359 1335 1365 1390 1371 1399 1391 1412 1495 1463 1435 1529 1486 1534 1559 1681 1619 1727 1689 1664 1751 1770 1828 1769 1821 1974 1903 1963 1999 1920 2024 2063 2112 2020 2072 2120 2101 2070 2063 2029 1935 2071 2034 2024 2044 2065 2092 2072 2027 2043 1983 1952 1939 1941 1831 1847 1922 1881 1838 1854 1748 1839 1714 1742 1649 1719 1681 1682 1619 1581 1555 1526 1506 1364 1427 1438 1392 1374 1421 1423 1410 1415 1265 1254 1288 1179 1198 1201 1197 1234 1179 1141 1098 1133 1108 1040 1107 1105 1102 1095 1013 1089 1032 1099 1057 1009 1082 1023 1085 1041 1046 1041 990 967 1029 1006 1012 944 988 947 1019 1017 980 998 982 1001 978 990 964 918 1039 921 985 983 911 973 949 963 932 932 974 955 987 931 984 937 962 892 1025 907 911 897 964 978 909 927 966 965 986 933 954 916 946 955 941 972 961 1015 954 946 951 1040 930 1067 954 971 1053 1005 1051 1057 1025 1038 1019 1064 1058 1110 1095 1096 1118 1087 1053 1037 1122 1080 1070 1061 1098 1119 1102 1097 1114 1059 1113 1041 1079 1036 1101 1020 1055 1043 1054 1087 1081 1032 1094 1046 1055 1016 1011 1078 1016 963 998 1009 1014 947 1005 1002 981 1002 923 946 967 960 922 912 986 928 885 947 986 1032 906 921 975 898 962 916 981 891 902 896 985 961 927 987 952 949 966 944 954 957 955 952 994 1025 943 956 915 1029 979 956 976 976 984 996 976 1001 984 1024 953 983 978 984 977 1023 970 1064 944 1001 1001 977 969 937 914 969 891 908 956 990 921 965 905 958 934 925 906 975 926 920 944 906 880 923 845 939 854 881 842 943 908 921 965 964 881 853 935 943 931 918 955 973 954 885 915 918 937 925 993 990 985 926 1040 997 967 1065 1036 1091 1040 966 1022 1038 1040 1119 1032 1027 1058 1052 1070 1047 1057 1041 1058 1017 1005 949 1070 1021 1022 1053 1030 1039 1048 1022 1013 1085 1132 1005 1066 1036 1052 1000 1047 978 1068 1070 1099 1099 1044 1113 1033 1135 1104 1078 1091 1023 1084 1134 1161 1162 1049 1065 1058 1127 1069 1088 1108 1049 1089 1124 1055 1085 1079 1051 1056 1071 1020 1047 1012 995 1033 1021 1033 1058 1013 1093 1039 959 1039 989 1010 959 970 1014 983 997 1003 938 963 970 921 939 949 960 982 975 977 891 933 910 954 928 944 948 923 942 983 939 984 962 897 888 932 958 922 936 947 977 974 944 861 993 877 907 956 903 948 957 923 931 962 1037 989 949 1003 985 973 958 982 983 966 924 974 978 969 946 960 975 919 1014 981 984 1014 915 979 997 915 953 962 969 936 904 925 987 970 994 989 961 994 927 1014 1008 988 971 919 1020 974 985 1002 979 1013 1033 1069 1015 1059 1040 1016 1112 1031 1094 1055 1089 1113 1054 1160 1115 1165 1182 1132 1150 1209 1183 1192 1160 1220 1204 1244 1235 1242 1276 1263 1234 1213 1221 1269 1307 1277 1307 1246 1275 1180 1287 1187 1276 1231 1289 1212 1211 1220 1193 1257 1170 1186 1201 1170 1120 1200 1164 1168 1217 1218 1181 1197 1123 1135 1121 1154 1146 1165 1094 1099 1102 1118 1166 1072 1218 1162 1187 1173 1164 1181 1162 1168 1181 1176 1250 1164 1228 1134 1187 1180 1229 1159 1192 1215 1214 1156 1242 1173 1206 1266 1161 1179 1098 1185 1077 1152 1130 1120 1139 1141 1118 1192 1082 1161 1129 1092 1148 1127 1104 1115 1128 1088 1030 1098 1055 1038 1047 1074 1111 1114 1152 1094 1045 1070 1072 1096 1081 1042 1054 995 1100 1053 1138 1058 1044 1063 1021 1054 996 1042 1070 1050 1106 1026 1134 1027 1034 1094 1081 1010 1022 1029 1001 1073 914 997 1037 1031 1020 993 999 986 981 1076 975 999 943 977 979 948 945 922 901 921 898 917 948 900 928 938 947 955 922 902 943 896 851 923 850 901 898 906 895 886 948 856 891 901 888 935 912 915 918 980 895 873 825 905 898 883 878 907 887 964 911 937 924 897 987 969 946 998 978 973 963 996 1049 1076 981 1080 1040 1044 1086 1146 1102 1127 1070 1152 1039 1128 1136 1112 1225 1176 1212 1177 1268 1273 1256 1227 1195 1255 1267 1353 1298 1337 1315 1343 1382 1348 1355 1299 1366 1397 1349 1373 1339 1461 1357 1456 1410 1455 1392 1450 1333 1476 1307 1387 1398 1422 1364 1299 1385 1280 1299 1323 1314 1281 1185 1235 1202 1249 1215 1096 1174 1171 1198 1201 1097 1185 1096 1063 1105 1066 1052 1090 1037 1109 1088 1017 1001 1043 1030 1043 1019 1049 1004 1069 1045 1027 963 1027 1028 1065 1025 1019 1045 1067 1150 1083 1058 1091 1019 1075 1109 1078 1093 1096 1086 1090 1140 1155 1161 1136 1142 1204 1190 1200 1283 1296 1270 1288 1275 1291 1295 1362 1314 1386 1335 1412 1400 1399 1384 1439 1486 1396 1496 1403 1514 1499 1533 1487 1440 1476 1583 1451 1575 1480 1430 1454 1473 1488 1470 1487 1357 1400 1403 1402 1497 1399 1392 1411 1319 1394 1271 1322 1354 1347 1268 1261 1280 1258 1184 1190 1248 1224 1244 1191 1220 1169 1092 1164 1108 1145 1094 1091 1067 1072 1122 1064 1067 1097 1095 1086 1006 1021 1032 1046 1027 981 1035 1049 888 978 958 972 1011 938 945 925 917 943 929 946 947 877 913 898 838 945 964 864 912 887 908 943 872 871 859 914 841 904 803 935 876 866 933 949 889 900 861 879 805 843 893 917 896 921 963 920 918 871 893 1029 944 958 891 940 950 939 907 913 985 985 977 921 907 982 969 968 950 994 979 983 1002 1007 1006 1058 935 972 987 962 1024 979 949 936 911 887 904 887 940 839 952 944 943 939 941 924 892 827 870 932 901 888 882 897 864 838 908 825 901 917 897 888 928 855 827 904 920 904 916 935 901 862 890 942 857 934 939 862 956 886 965 919 935 962 979 974 977 982 1008 940 958 962 988 975 965 1028 1027 1035 947 960 999 1000 990 960 975 984 983 959 966 927 949 1001 931 948 935 932 960 929 926 953 1011 929 912 943 927 937 1007 898 883 883 967 957 848 938 857 893 840 943 918 897 895 886 884 859 835 903 881 882 868 866 889 920 877 870 912 901 860 826 882 890 919 862 855 860 918 889 882 889 892 866 878 867 883 848 776 873 834 851 929 885 881 881 899 899 825 817 809 885 837 844 844 865 869 868 856 894 902 871 827 888 792 849 830 804 822 903 858 867 889 879 886 868 841 877 838 937 855 874 860 880 866 914 900 933 844 932 940 981 945 890 966 910 989 942 928 1022 970 983 1009 1002 1047 977 1008 1026 971 1002 976 968 996 929 980 959 918 957 867 929 949 943 971 882 949 952 918 934 912 920 933 893 897 864 908 857 867 816 890 872 813 847 798 853 796 835 806 803 793 779 800 902 781 751 826 811 818 802 757 765 793 828 806 797 783 777 781 768 785 759 779 800 774 769 703 741 861 803 829 749 765 737 735 782 783 809 777 755 767 828 771 746 776 784 789 811 740 775 762 775 766 721 751 770 752 748 812 747 773 758 752 700 738 780 769 825 701 780 803 766 798 810 770 805 786 804 849 784 828 736 780 762 749 744 751 778 782 776 762 779 727 799 842 740 804 802 810 779 826 760 791 801 830 819 837 752 808 816 780 846 860 800 770 845 773 815 820 781 799 836 829 850 857 874 823 907 849 826 830 861 869 869 835 823 866 829 874 881 832 858 905 861 822 821 792 803 839 879 816 876 851 828 855 858 804 829 850 832 818 873 845 892 876 887 876 886 853 917 784 873 889 861 865 870 866 848 903 869 876 938 836 920 863 909 909 938 966 887 922 926 951 957 1013 953 993 984 957 966 974 944 1011 1027 1063 1044 936 982 1016 941 1042 961 1022 971 967 1048 1056 997 930 1046 1061 1033 1010 991 946 977 1004 1050 1018 995 1083 1036 1017 1004 1005 1026 1002 1030 990 982 1038 1002 947 1021 1004 978 996 992 1006 972 983 936 959 1001 1002 957 911 975 975 886 991 938 1019 987 917 982 949 955 951 911 950 921 997 928 999 966 937 1031 965 986 932 949 1032 1043 964 992 1002 995 968 1050 986 1000 974 1019 990 1014 1051 931 1065 1051 987 994 969 1065 1000 1008 942 1006 934 982 970 978 1018 975 945 946 1013 1003 1007 1092 955 949 988 1012 952 964 1026 938 964 976 1012 1005 1012 1008 1066 1007 985 1117 1087 1018 1089 1039 1020 1042 1028 1056 1031 1051 1060 1142 1101 1081 1104 1098 1037 1100 1074 1113 1093 1071 1072 1052 1066 1096 1040 1064 1057 1066 1064 1026 1016 980 1024 1010 1090 1017 979 990 999 1001 975 988 953 971 990 976 964 930 954 986 1021 968 911 921 930 974 954 940 967 966 998 891 936 921 922 913 939 902 935 951 1021 924 973 999 991 1002 1030 985 999 995 948 998 1021 1004 955 1069 1062 1032 1049 1026 1009 1031 1014 1014 1051 1026 997 980 1003 998 1021 1059 1000 934 977 998 1045 956 942 996 964 997 909 1019 1025 958 955 930 939 951 890 955 926 919 951 888 958 922 912 917 891 886 875 906 880 891 890 936 895 832 931 890 878 934 857 833 848 934 847 814 887 911 887 907 893 883 874 889 884 896 899 895 916 948 901 908 874 930 914 874 904 904 909 965 963 959 916 871 962 949 863 933 913 894 892 856 872 873 874 899 827 915 890 874 888 989 859 916 910 870 883 875 922 907 837 848 817 925 884 886 898 834 874 921 973 844 905 901 849 847 890 923 895 841 820 866 849 848 843 850 883 831 864 870 818 836 894 908 859 876 849 856 858 867 891 845 871 840 884 877 905 815 880 852 815 924 906 859 918 901 916 942 932 924 953 939 903 934 964 977 1004 1003 1015 1029 1013 1006 1090 1006 1143 1113 1057 1131 1152 1168 1181 1173 1168 1095 1194 1174 1158 1263 1169 1236 1252 1220 1222 1240 1262 1158 1153 1120 1170 1126 1212 1152 1157 1145 1186 1227 1125 1076 1143 1080 1135 1088 1147 1070 1115 1065 1016 1080 1010 1028 1119 991 952 975 972 938 1000 914 979 1009 939 825 949 901 973 904 932 895 899 965 908 910 852 886 905 892 895 874 877 902 886 879 929 877 969 840 875 869 934 892 876 862 821 857 891 833 828 899 860 903 855 804 872 858 880 878 878 924 875 917 841 879 878 893 918 864 901 859 871 940 933 919 969 955 914 891 948 965 997 978 886 985 996 970 948 940 958 976 911 896 958 945 963 1003 954 899 930 995 978 986 1003 911 934 956 929 982 898 931 888 942 873 909 959 898 900 936 909 883 888 904 890 972 876 923 929 905 867 888 880 902 935 904 949 940 931 994 910 1005 909 949 894 970 956 947 952 970 929 977 951 988 969 1054 1081 1035 1032 1044 1031 977 1054 992 1030 1004 1019 1015 1071 1043 1055 1069 1052 1064 997 1067 1038 1055 1075 1116 1031 1072 988 1059 1042 1107 1052 1084 1042 1030 986 1029 984 1016 1025 1039 1073 940 1024 970 960 1023 1023 1009 961 926 956 911 906 916 912 958 933 874 891 913 963 893 926 962 898 889 919 907 891 871 889 808 840 831 831 808 917 807 858 834 825 899 820 822 848 841 826 828 817 853 847 851 889 854 783 874 861 830 880 826 874 872 874 826 887 895 829 853 893 856 974 894 888 896 854 847 925 879 875 885 844 905 907 832 890 941 918 908 925 936 909 886 898 891 971 922 930 946 883 928 934 928 948 960 928 975 1019 985 1006 964 1017 1007 943 1018 929 989 986 960 966 962 975 954 953 970 941 921 897 888 918 898 902 938 906 830 888 919 923 917 836 906 845 888 874 866 883 864 878 830 861 833 837 810 827 846 785 844 735 848 817 801 812 792 833 809 788 830 807 714 784 696 821 787 796 791 764 812 769 841 742 800 842 775 848 786 805 812 827 795 802 758 800 809 824 801 794 776 759 777 818 802 795 786 810 774 831 783 703 770 775 776 762 777 786 771 773 780 784 764 759 774 813 777 770 767 789 770 763 792 818 804 786 827 797 786 870 776 769 755 827 796 801 749 756 794 798 774 800 746 847 819 780 803 818 757 789 768 801 809 798 811 776 793 827 797 835 781 796 780 772 784 770 802 765 732 784 776 811 803 808 762 693 774 782 738 836 798 817 753 778 840 741 822 748 726 768 777 736 820 767 817 735 772 782 778 763 775 766 765 804 765 807 749 790 836 832 837 832 864 884 861 853 863 878 862 868 942 941 916 999 977 866 982 987 993 1053 973 1014 979 1001 1034 1061 1059 1030 1053 1002 996 994 1089 1021 1048 997 1001 1047 959 950 973 976 921 952 951 928 934 936 971 1042 919 952 841 873 886 892 875 900 865 824 901 887 908 904 905 867 906 894 851 841 832 891 769 828 824 852 850 884 845 866 844 836 862 845 816 861 850 852 871 862 908 934 950 896 904 884 838 949 871 895 884 917 900 936 900 891 915 931 925 971 927 979 891 932 909 924 892 945 884 925 860 955 889 896 937 967 906 878 861 915 852 855 863 957 858 862 954 923 877 870 873 888 929 946 948 938 917 916 917 919 906 936 974 957 874 939 914 903 942 915 900 890 876 920 913 860 858 876 853 827 911 875 832 846 819 882 848 915 835 807 805 882 850 860 874 766 859 875 866 795 844 903 778 847 773 776 847 820 850 795 789 821 752 749 772 812 801 782 824 769 772 782 759 787 804 779 793 739 849 788 819 808 808 793 797 804 750 836 770 803 815 789 834 774 795 827 757 864 821 860 805 813 850 822 867 854 875 831 859 809 880 850 852 865 886 914 930 855 908 883 834 912 862 892 896 898 883 890 912 958 973 919 887 955 1003 943 879 957 940 945 969 937 1001 930 926 962 963 971 915 970 952 943 962 868 986 922 996 979 954 1038 970 955 907 850 942 925 929 920 912 907 931 913 955 926 925 913 909 936 904 967 931 883 956 932 892 843 888 851 950 904 865 895 871 924 982 875 868 923 923 937 887 903 893 886 872 928 908 873 881 891 877 875 927 930 927 921 927 889 934 897 965 912 935 1027 959 974 1007 982 1012 962 1062 969 1019 1044 1023 1065 1008 1015 1050 979 1044 992 1007 990 1040 1032 946 1126 1014 1111 1088 1078 1078 1094 1062 1060 1074 1108 1051 1078 1083 1046 1116 1101 1150 1174 1172 1080 1176 1166 1113 1179 1201 1193 1246 1184 1191 1127 1183 1126 1155 1118 1142 1158 1124 1052 1180 1129 1162 1073 1130 1101 1045 1067 1093 1137 1077 1116 1168 1135 1071 1139 1117 1064 1069 1049 1087 1155 1108 1109 1107 1088 1003 1052 1090 1032 1076 1112 1030 1071 1100 984 1121 1023 1005 1041 1019 1002 1018 1066 1026 1000 1022 984 1008 914 1010 972 966 994 945 950 914 913 908 915 914 954 908 903 836 928 1007 949 925 858 925 852 914 878 881 865 904 922 914 874 873 864 867 872 901 855 850 836 843 868 804 840 802 834 884 842 951 902 908 856 882 894 947 873 870 878 921 902 866 912 953 887 948 929 933 959 906 943 881 874 876 966 892 905 914 868 918 886 898 928 887 925 897 920 884 924 901 940 964 1012 872 896 934 916 891 913 917 973 919 996 918 929 944 917 924 907 981 913 983 925 963 975 990 962 987 941 997 962 977 978 987 978 1070 1043 1000 1019 1033 973 1011 1071 1004 1111 1040 1065 1055 1120 1135 1138 1063 1073 1106 1124 1076 1117 1105 1228 1124 1138 1092 1104 1144 1131 1088 1138 1087 1136 1121 1139 1150 1096 1152 1124 1117 1137 1116 1160 1117 1136 1097 1092 1138 1146 1138 1093 1091 1119 1133 1112 1139 1063 1148 1120 1158 1162 1083 1129 1138 1174 1168 1160 1176 1198 1147 1121 1168 1163 1203 1110 1252 1214 1193 1157 1145 1156 1103 1159 1135 1144 1188 1174 1130 1160 1114 1079 1128 1110 1101 1077 1104 1101 1123 1112 1100 1144 1107 1064 1058 1153 1138 1113 1039 1074 1058 1077 1118 1065 1127 1111 1070 1050 1030 1086 1029 985 1091 1016 967</counts>
			</dataPoints>
		</scan>
	</xrdMeasurement>
</xrdMeasurements>