File: dataset/precursor_mixture/Li2CO3_Li2TiO3_Bi2O3-beta.12-min.xrdml
<?xml version="1.0"?>
<xrdMeasurements xmlns="http://www.xrdml.com/XRDMeasurement/2.2" xmlns:xsi="http://www.w3.org/2001/XMLSchema-instance" xsi:schemaLocation="http://www.xrdml.com/XRDMeasurement/2.2 http://www.xrdml.com/XRDMeasurement/2.2/XRDMeasurement.xsd" status="Completed" recordIdentifier="{8B67C18D-31DC-4E75-9C7A-F57F8384F6DD}">
	<comment>
		<entry/>
	</comment>
	<sample type="To be analyzed">
		<id>dara-15-2</id>
		<name></name>
		<preparedBy></preparedBy>
	</sample>
	<xrdMeasurement measurementType="Scan" status="Completed" sampleMode="Reflection">
		<usedWavelength intended="K-Alpha 1">
			<kAlpha1 unit="Angstrom">1.5405980</kAlpha1>
			<kAlpha2 unit="Angstrom">1.5444260</kAlpha2>
			<kBeta unit="Angstrom">1.3922500</kBeta>
			<ratioKAlpha2KAlpha1>0.5000</ratioKAlpha2KAlpha1>
		</usedWavelength>
		<incidentBeamPath>
			<radius unit="mm">145.00</radius>
			<xRayTube id="1010048" name="Empyrean Cu LFF HR (9430 033 7310x) DK437873">
				<tension unit="kV">40.0</tension>
				<current unit="mA">15.0</current>
				<anodeMaterial>Cu</anodeMaterial>
				<focus type="Line">
					<length unit="mm">12.0</length>
					<width unit="mm">0.4</width>
					<takeOffAngle unit="deg">6.0</takeOffAngle>
				</focus>
			</xRayTube>
			<filter id="20010004" name="Beta-filter Nickel">
				<material>Ni</material>
				<thickness unit="mm">0.020</thickness>
			</filter>
			<sollerSlit id="21010002" name="Soller slits 0.04 rad.">
				<opening unit="rad">0.0400</opening>
			</sollerSlit>
			<mask id="22031000" name="Fixed mask 13 mm">
				<width unit="mm">9.00</width>
			</mask>
			<divergenceSlit id="22120001" name="Divergence slit 1°" xsi:type="fixedDivergenceSlitType">
				<distanceToSample unit="mm">50.00</distanceToSample>
				<height unit="mm">1.52</height>
			</divergenceSlit>
		</incidentBeamPath>
		<beamKnife id="29030100" name="Beam knife low"/>
		<sampleMovement xsi:type="spinningSampleMovementType">
			<spinnerRevolutionTime unit="seconds">1.0</spinnerRevolutionTime>
		</sampleMovement>
		<diffractedBeamPath>
			<radius unit="mm">145.00</radius>
			<antiScatterSlit id="22090040" name="AS slit 9 mm" xsi:type="fixedAntiScatterSlitType">
				<height unit="mm">9.00</height>
			</antiScatterSlit>
			<sollerSlit id="21020003" name="Large Soller slits 0.04 rad.">
				<opening unit="rad">0.0400</opening>
			</sollerSlit>
			<filter id="20030001" name="Large beta-filter Nickel">
				<material>Ni</material>
				<thickness unit="mm">0.020</thickness>
			</filter>
			<detector id="7010019" name="PIXcel1D-Medipix3 detector" xsi:type="rtmsDetectorType">
				<phd unit="keV">
					<lowerLevel>4.0</lowerLevel>
					<upperLevel>11.3</upperLevel>
				</phd>
				<mode>Scanning</mode>
				<activeLength unit="deg">5.020</activeLength>
			</detector>
		</diffractedBeamPath>
		<scan appendNumber="0" mode="Continuous" scanAxis="Gonio" status="Completed">
			<header>
				<startTimeStamp>2024-03-24T19:10:55-07:00</startTimeStamp>
				<endTimeStamp>2024-03-24T19:23:23-07:00</endTimeStamp>
				<author>
					<name>AutomatedUser</name>
				</author>
				<source>
					<applicationSoftware version="1.6 (94)">PANalytical Aeris Instrument Suite</applicationSoftware>
					<instrumentControlSoftware version="3.0.0 20211014">AERIS</instrumentControlSoftware>
					<instrumentID>2879380</instrumentID>
				</source>
			</header>
			<dataPoints>
				<positions axis="2Theta" unit="deg">
					<startPosition>9.99043322</startPosition>
					<endPosition>100.09495370</endPosition>
				</positions>
				<positions axis="Omega" unit="deg">
					<startPosition>4.99521661</startPosition>
					<endPosition>50.04747685</endPosition>
				</positions>
				<commonCountingTime unit="seconds">18.249</commonCountingTime>
				<counts unit="counts">3884 3880 3921 3902 3903 3833 3916 3931 3998 3795 3903 3921 3911 3867 3877 3790 3951 3780 3844 3911 3795 3844 3799 3760 3940 3836 3928 3763 3824 3748 3862 3808 3893 3757 3907 3814 3822 3761 3679 3764 3808 3699 3740 3822 3861 3805 3693 3712 3722 3680 3652 3798 3697 3740 3681 3556 3772 3643 3641 3708 3746 3650 3554 3541 3721 3645 3736 3678 3593 3695 3644 3610 3581 3600 3632 3570 3587 3626 3469 3630 3631 3586 3609 3489 3583 3517 3605 3488 3602 3507 3446 3576 3421 3644 3554 3515 3552 3424 3426 3558 3450 3511 3552 3409 3482 3590 3474 3519 3472 3382 3429 3422 3391 3397 3463 3373 3441 3362 3375 3352 3479 3255 3367 3583 3398 3443 3405 3431 3411 3300 3237 3306 3288 3398 3393 3345 3415 3285 3441 3290 3427 3353 3347 3266 3320 3228 3329 3364 3172 3285 3224 3265 3314 3173 3237 3264 3108 3274 3256 3204 3216 3260 3240 3255 3253 3245 3195 3125 3267 3307 3298 3213 3190 3174 3227 3303 3162 3200 3276 3179 3072 3155 3212 3220 3193 3240 3153 3152 3195 3180 3192 3174 3141 3212 3080 3103 3141 3154 3074 3138 3053 3160 3098 3017 3096 3059 3034 3077 3026 3042 3016 3113 3128 3023 3097 3102 3197 3002 3089 2983 2971 3053 3056 3083 2923 3066 2994 3147 3073 3113 3019 2973 2893 2992 3115 2888 2976 2924 3112 2908 2983 2968 2946 2954 3027 2957 2905 2899 3011 2837 2997 3020 2958 3028 2917 2875 2955 3061 2898 2998 2960 2974 2939 2912 2914 3033 3029 3028 2908 2918 2906 2984 3034 3094 3012 2916 3027 2926 2932 2940 2881 2887 2891 2914 3004 2844 2881 2958 2835 2831 2891 2899 2813 2811 2813 2840 2863 2823 2791 2826 2758 2817 2827 2848 2748 2759 2774 2719 2761 2758 2751 2820 2716 2793 2711 2747 2810 2787 2728 2770 2711 2786 2734 2830 2728 2698 2757 2700 2737 2674 2732 2705 2739 2728 2700 2721 2662 2688 2730 2678 2644 2693 2735 2661 2639 2741 2715 2587 2738 2706 2701 2725 2714 2716 2659 2739 2658 2669 2761 2671 2635 2767 2602 2648 2726 2641 2637 2574 2692 2658 2582 2614 2729 2593 2631 2625 2652 2557 2532 2575 2673 2604 2606 2620 2599 2621 2594 2588 2593 2582 2693 2614 2509 2569 2611 2647 2645 2680 2588 2549 2659 2580 2586 2676 2633 2555 2541 2599 2501 2684 2548 2654 2663 2646 2650 2599 2595 2538 2631 2539 2586 2596 2546 2577 2556 2593 2570 2617 2578 2502 2675 2473 2611 2565 2612 2593 2459 2615 2535 2467 2547 2556 2488 2468 2555 2620 2460 2568 2459 2579 2408 2590 2459 2501 2514 2550 2505 2543 2494 2450 2484 2401 2548 2469 2479 2514 2484 2474 2527 2456 2467 2485 2470 2512 2463 2472 2463 2441 2454 2484 2486 2440 2466 2557 2532 2582 2535 2459 2370 2464 2480 2541 2427 2439 2479 2387 2424 2521 2472 2400 2562 2400 2510 2490 2419 2512 2397 2382 2469 2569 2425 2521 2411 2468 2494 2458 2446 2412 2382 2386 2444 2417 2537 2375 2470 2461 2443 2469 2481 2500 2449 2479 2392 2452 2400 2458 2440 2419 2494 2323 2472 2446 2414 2439 2416 2480 2463 2606 2510 2437 2445 2473 2450 2519 2533 2555 2467 2583 2602 2575 2556 2604 2610 2710 2735 2725 2912 2837 2933 2894 2989 3021 3042 3225 3020 3128 3066 3018 2977 3015 2899 2867 2773 2630 2507 2497 2509 2440 2523 2410 2402 2421 2362 2395 2272 2422 2400 2353 2329 2379 2355 2302 2493 2324 2421 2385 2407 2315 2404 2267 2327 2379 2381 2356 2273 2357 2360 2349 2383 2389 2423 2405 2391 2433 2302 2351 2360 2291 2358 2324 2325 2399 2375 2244 2341 2457 2251 2298 2354 2406 2237 2406 2315 2342 2269 2364 2302 2367 2328 2378 2330 2369 2303 2348 2232 2368 2294 2399 2321 2339 2214 2320 2323 2381 2256 2371 2289 2378 2264 2294 2291 2324 2354 2217 2280 2248 2312 2316 2336 2356 2277 2324 2290 2292 2319 2310 2340 2359 2339 2305 2340 2293 2324 2215 2211 2318 2345 2259 2350 2246 2182 2331 2341 2284 2264 2259 2353 2323 2291 2304 2259 2218 2171 2256 2266 2306 2278 2304 2219 2347 2233 2342 2349 2288 2307 2285 2279 2327 2265 2365 2314 2282 2332 2329 2275 2400 2304 2352 2406 2291 2265 2327 2368 2390 2344 2360 2399 2368 2340 2355 2465 2430 2377 2329 2477 2395 2494 2372 2384 2533 2426 2490 2435 2452 2509 2516 2511 2550 2552 2589 2638 2693 2578 2616 2752 2662 2760 2790 2756 2920 2743 2788 2746 2737 2840 2791 2842 2892 2728 2672 2776 2705 2612 2674 2570 2582 2448 2578 2547 2593 2525 2375 2450 2432 2419 2326 2361 2317 2362 2324 2225 2287 2330 2284 2256 2290 2210 2289 2305 2297 2336 2210 2210 2274 2274 2287 2168 2138 2286 2151 2272 2208 2156 2149 2241 2192 2181 2170 2172 2281 2173 2175 2138 2212 2103 2237 2207 2193 2177 2207 2144 2131 2119 2144 2055 2131 2120 2164 2170 2110 2133 2076 2147 2274 2126 2178 2175 2090 2129 2047 2065 2101 2090 2112 2044 2132 2059 2132 2100 2091 2076 2037 2189 2109 2195 2034 2139 2055 2098 2221 2145 2031 2112 2119 2111 2036 2138 2090 2020 2070 2115 2096 2098 2081 2078 2062 2131 2081 2086 2083 2039 2032 2012 2045 2071 2084 2067 2076 2154 2062 2106 2068 2151 2080 2117 2066 2148 2053 2084 2074 2246 2074 2140 2163 2063 2074 2084 2046 2066 2112 2136 2140 2099 2087 2136 2055 2081 2101 2142 2184 2167 2087 2192 2184 2037 2195 2139 2175 2055 2108 2117 2047 2110 2137 2155 2073 2082 2103 2094 1992 2023 1981 1948 2020 2081 2076 2022 2046 2006 2024 2033 2036 2050 2036 2038 2089 1973 2031 2012 2038 2034 1898 2080 2046 2020 2120 2048 2011 2088 2085 2081 2037 1982 2004 2020 2084 2066 2065 2135 2089 2063 2034 2079 2052 1942 2080 2006 2017 2093 2033 2072 2065 2050 2074 2132 2220 2153 2205 2205 2302 2244 2339 2367 2474 2486 2503 2673 2693 2813 3026 3138 3364 3435 3747 3915 4143 4390 4583 4793 5080 5093 4960 4899 4614 4367 4152 3793 3290 3057 2664 2550 2434 2227 2142 2105 2104 2047 2069 2026 2045 1984 1875 2058 1959 1913 1938 1903 1899 1820 1875 1897 1902 1906 1908 1870 1901 1839 1841 1822 1763 1822 1831 1844 1839 1825 1846 1807 1793 1821 1859 1867 1804 1884 1878 1865 1799 1740 1811 1803 1797 1881 1801 1795 1825 1810 1816 1796 1887 1818 1881 1827 1852 1842 1829 1984 1838 1858 1796 1766 1742 1764 1828 1847 1821 1822 1759 1841 1721 1712 1770 1805 1823 1826 1889 1688 1735 1768 1792 1849 1831 1839 1801 1838 1792 1803 1718 1786 1778 1777 1744 1678 1764 1798 1759 1818 1728 1846 1708 1781 1811 1706 1790 1685 1731 1733 1781 1765 1772 1780 1775 1651 1755 1716 1783 1815 1822 1872 1854 1767 1764 1812 1965 1835 1856 1845 1877 1867 1824 1972 1866 1889 1809 1883 1908 1844 1806 1790 1841 1809 1808 1795 1744 1783 1761 1751 1745 1748 1792 1722 1728 1730 1754 1767 1824 1786 1857 1753 1718 1744 1830 1828 1871 1850 1864 1946 1929 1877 1853 1959 1986 1965 1960 2075 1989 2061 2044 1967 1928 1967 1893 1882 1975 1827 1801 1756 1769 1745 1766 1795 1684 1771 1746 1680 1719 1636 1714 1686 1722 1749 1738 1726 1741 1815 1665 1658 1723 1766 1704 1668 1761 1714 1844 1801 1814 1777 1833 1768 1801 1828 1806 1743 1742 1749 1753 1723 1711 1646 1671 1713 1630 1763 1593 1741 1703 1692 1645 1709 1649 1680 1713 1598 1618 1669 1657 1611 1773 1672 1667 1604 1583 1614 1716 1652 1604 1650 1594 1683 1634 1773 1566 1623 1572 1629 1580 1620 1594 1531 1615 1590 1646 1568 1660 1631 1664 1735 1755 1672 1651 1637 1623 1611 1533 1618 1718 1624 1630 1577 1625 1610 1633 1592 1561 1595 1541 1611 1567 1649 1625 1660 1650 1682 1592 1647 1546 1632 1678 1591 1574 1592 1527 1557 1601 1634 1651 1645 1614 1701 1670 1661 1639 1709 1686 1716 1680 1783 1830 1763 1862 1828 1833 1877 1967 1785 2013 2013 1973 2102 2124 2088 2112 2063 2002 2050 2031 2033 2005 2017 1951 2119 1934 1993 1888 1975 1904 1878 1863 1956 1906 1947 1922 1897 1912 1941 1967 1911 1882 2016 2028 2170 2123 2232 2403 2435 2486 2669 2825 2884 3070 3178 3411 3557 3605 3734 3721 3667 3617 3452 3243 3157 2884 2849 2688 2442 2259 2128 1991 1978 1864 1810 1832 1791 1741 1744 1773 1747 1720 1693 1588 1684 1663 1671 1614 1623 1634 1640 1661 1568 1611 1575 1549 1557 1579 1526 1559 1586 1675 1563 1599 1603 1564 1562 1561 1558 1521 1544 1522 1564 1597 1622 1613 1603 1576 1551 1584 1525 1585 1541 1606 1597 1590 1620 1596 1567 1588 1565 1652 1632 1665 1585 1579 1547 1625 1534 1685 1608 1559 1628 1605 1589 1621 1673 1632 1583 1555 1563 1663 1652 1708 1669 1650 1685 1619 1723 1673 1665 1601 1734 1774 1773 1834 1744 1786 1813 1888 1859 1854 1923 1912 1952 1994 1963 2060 2058 2059 2014 2074 2057 2071 2056 2086 2135 2002 2092 2098 2082 2114 2080 2066 2136 2227 2250 2291 2253 2290 2307 2359 2426 2399 2555 2531 2537 2684 2760 2714 2687 2779 2806 2887 2876 2948 2931 2975 3044 3209 3179 3210 3308 3362 3371 3446 3491 3568 3732 3763 3858 3945 4031 4191 4432 4609 4660 5168 5352 5861 6181 6666 7358 7974 8742 9855 10906 12092 13824 15795 18078 20227 23721 27232 31307 35694 41398 47789 54306 61455 68651 76832 83930 90056 94957 96847 95544 89520 82722 74968 67393 60300 53154 46918 39349 32218 25826 20556 16825 13556 11624 10197 8579 7759 6871 6499 5949 5695 5262 5106 4733 4550 4304 4067 4101 3910 3852 3609 3653 3309 3335 3184 3064 2896 2765 2843 2598 2621 2582 2394 2481 2403 2323 2273 2249 2210 2151 2160 2233 2053 2149 2116 2144 2138 1963 2056 2122 1987 2034 1986 1944 1957 1929 1903 1844 2004 1844 1906 1970 1799 1795 1870 1811 1855 1888 1804 1807 1739 1775 1841 1821 1730 1798 1838 1853 1799 1803 1770 1814 1746 1803 1717 1829 1698 1819 1778 1741 1779 1814 1738 1728 1752 1813 1699 1720 1770 1843 1758 1789 1788 1735 1767 1696 1761 1756 1800 1746 1877 1777 1852 1862 1854 1981 1978 1975 2034 2099 2114 2114 2158 2277 2243 2295 2319 2337 2181 2163 2164 2052 2124 2058 1971 1922 1899 1827 1853 1820 1750 1814 1729 1744 1717 1770 1666 1711 1774 1635 1647 1686 1682 1576 1657 1618 1671 1619 1644 1589 1560 1648 1660 1592 1621 1614 1608 1639 1637 1712 1594 1651 1638 1697 1659 1711 1731 1700 1789 1765 1832 1867 1886 1863 1921 1860 2026 1991 2144 2163 2304 2372 2436 2453 2646 2738 2914 3031 3094 3273 3526 3702 3696 3686 3585 3402 3239 3254 3072 2949 2992 2906 2727 2592 2514 2420 2323 2422 2488 2527 2652 2674 2906 2918 3234 3226 3445 3642 3828 3812 3920 4000 3779 3872 3733 3651 3672 3426 3261 3119 3026 2737 2755 2486 2377 2277 2093 2025 1982 2014 1833 1912 1814 1890 1691 1723 1787 1699 1700 1673 1806 1716 1651 1726 1640 1662 1681 1629 1639 1544 1644 1613 1671 1609 1668 1668 1717 1684 1672 1607 1680 1645 1661 1692 1616 1657 1676 1727 1719 1690 1699 1749 1775 1830 1765 1837 1847 1868 1878 2004 1949 1914 1966 2044 1999 2148 1996 2172 2241 2167 2391 2429 2426 2567 2635 2694 3039 3150 3314 3688 3824 4221 4607 4927 5488 6127 6702 7510 8363 9524 10822 11951 13481 15039 16531 18092 19763 21035 22029 22476 22296 21058 19794 18228 17083 15763 14700 13428 12247 10731 9387 7866 6620 5942 5168 4658 4221 3706 3482 3219 3118 3023 2862 2783 2659 2505 2389 2370 2357 2318 2296 2222 2284 2169 2229 2237 2067 2029 2074 2048 2017 2018 2107 2155 2169 2133 2039 2074 2095 2084 2163 2226 2182 2161 2204 2400 2360 2483 2421 2696 2724 2791 3044 3078 3397 3687 3849 4304 4803 5410 5858 6723 7371 8254 9349 10871 12269 13936 16020 17937 19915 21591 23596 24877 25168 24686 23480 21874 19925 18241 17157 16198 14693 13230 11444 9963 8205 6923 5881 5155 4374 4077 3814 3396 3213 3023 2905 2725 2596 2633 2374 2377 2290 2211 2270 2172 2149 2120 1983 2069 1969 1910 1883 1884 1856 1836 1838 1777 1691 1747 1788 1661 1713 1753 1702 1675 1616 1672 1690 1591 1595 1519 1601 1550 1571 1548 1592 1521 1436 1496 1461 1493 1472 1491 1537 1485 1457 1458 1428 1506 1397 1448 1421 1475 1435 1457 1387 1446 1393 1366 1440 1376 1433 1409 1410 1396 1412 1426 1432 1450 1357 1409 1378 1407 1398 1448 1412 1390 1484 1404 1523 1473 1603 1554 1499 1587 1474 1504 1617 1576 1598 1597 1620 1726 1814 1800 1880 1882 1990 2016 2052 2111 2107 2124 2132 2130 2101 2065 1957 1837 1927 1763 1770 1757 1608 1553 1566 1503 1463 1469 1330 1413 1372 1370 1370 1396 1365 1340 1246 1272 1276 1244 1325 1254 1295 1284 1289 1215 1235 1259 1310 1301 1246 1262 1299 1201 1239 1280 1222 1250 1208 1233 1279 1250 1239 1272 1277 1166 1260 1294 1210 1199 1261 1212 1273 1262 1254 1297 1258 1231 1255 1283 1269 1252 1210 1306 1211 1301 1301 1296 1273 1263 1234 1258 1196 1208 1256 1261 1283 1254 1270 1266 1202 1238 1236 1187 1212 1217 1207 1243 1167 1259 1152 1288 1213 1205 1276 1238 1253 1261 1307 1229 1231 1196 1298 1203 1283 1264 1232 1233 1328 1231 1256 1276 1238 1267 1266 1253 1324 1258 1232 1234 1228 1283 1236 1255 1227 1239 1231 1220 1266 1226 1266 1262 1254 1292 1287 1372 1303 1327 1375 1396 1331 1365 1404 1436 1372 1422 1372 1462 1453 1454 1486 1502 1609 1572 1612 1581 1552 1678 1564 1683 1683 1686 1704 1830 1931 1981 2196 2376 2516 2716 2850 3140 3336 3556 3419 3381 3154 2907 2674 2552 2397 2399 2342 2295 2132 1854 1766 1646 1491 1336 1422 1340 1320 1346 1274 1318 1179 1323 1201 1318 1248 1220 1161 1227 1155 1175 1175 1177 1135 1153 1136 1184 1136 1253 1173 1188 1216 1198 1240 1114 1220 1209 1156 1247 1196 1238 1288 1171 1272 1199 1264 1213 1181 1221 1243 1238 1328 1334 1339 1347 1353 1428 1411 1469 1548 1511 1653 1717 1753 1994 1926 2004 2032 2083 2143 2076 2013 2047 1916 1945 1846 1820 1769 1647 1612 1580 1540 1454 1448 1348 1324 1308 1266 1244 1198 1193 1163 1115 1147 1092 1118 1094 1090 1131 1171 1190 1094 1159 1120 1107 1130 1119 1150 1115 1124 1081 1092 1092 1140 1164 1107 1095 1097 1090 1159 1124 1157 1174 1197 1103 1203 1195 1125 1191 1218 1158 1129 1149 1069 1093 1191 1140 1114 1148 1095 1124 1122 1093 1093 1141 1104 1110 1166 1155 1128 1114 1111 1101 1142 1135 1162 1119 1103 1136 1088 1172 1106 1044 1127 1073 1075 1038 1075 1078 1037 1114 1111 1004 1128 1086 1012 1065 1051 1122 1141 1128 1151 1134 1093 1153 1175 1111 1192 1204 1243 1222 1308 1258 1374 1414 1482 1470 1477 1458 1355 1361 1348 1341 1334 1332 1333 1352 1338 1249 1171 1155 1112 1150 1147 1114 1065 1073 1060 1092 1043 1077 1070 1054 1002 1094 1039 1058 1029 1032 1067 1087 1041 1046 1027 1048 1026 1026 1044 981 986 1007 975 1053 986 1088 1068 1010 1051 1037 963 1003 1021 978 1037 962 1061 956 1009 1005 1041 1037 1029 948 1078 1015 998 988 1044 1024 991 1032 1016 1118 1043 1024 1069 998 1066 980 1072 1096 1033 1110 1026 1084 1038 1054 1063 1051 1077 1070 1086 1080 1142 1115 1116 1137 1213 1139 1177 1240 1298 1298 1366 1342 1456 1445 1521 1571 1572 1604 1643 1519 1519 1465 1396 1450 1396 1395 1339 1320 1329 1279 1259 1185 1175 1139 1095 1012 1142 1074 1082 1175 1190 1194 1168 1231 1200 1266 1288 1302 1301 1309 1291 1404 1308 1298 1250 1230 1218 1257 1194 1237 1190 1239 1261 1275 1232 1289 1310 1292 1263 1210 1254 1210 1186 1210 1135 1167 1161 1188 1151 1145 1044 1048 1057 1019 1064 1025 1013 1011 1036 1082 1001 1019 982 969 939 971 997 1001 1031 1035 1026 982 975 1018 953 988 954 1002 978 998 1057 953 992 937 930 995 982 1007 945 1025 975 964 1042 887 960 919 1017 1027 995 987 1028 988 1036 947 1010 1027 1000 971 1031 1048 1051 1030 989 967 962 950 965 953 1012 1076 986 997 1079 1086 1059 1065 1082 1055 1120 1124 1098 1215 1202 1202 1244 1315 1417 1403 1449 1626 1684 1883 2080 2145 2261 2341 2553 2421 2383 2309 2154 2007 2014 1983 1859 1825 1871 1815 1657 1639 1485 1445 1359 1259 1222 1195 1280 1162 1178 1142 1136 1192 1171 1103 1122 1041 1095 1066 1007 1060 988 1069 995 988 1008 1007 1029 1055 1070 1036 1028 1089 1000 1062 990 1114 1024 1060 1058 1145 1058 1076 1059 1125 1107 1109 1073 1142 1148 1252 1356 1347 1440 1414 1449 1468 1397 1379 1335 1259 1338 1308 1232 1226 1296 1261 1267 1214 1220 1141 1156 1154 1146 1085 1179 1067 1054 1082 1054 1115 1020 1067 1038 1051 1070 1138 1024 1082 1037 1043 983 1063 1045 989 1049 1048 1031 1029 1069 1031 995 1082 1111 1014 1084 1017 1088 1069 1058 1066 1088 1114 1088 1135 1074 1165 1038 1090 1066 1089 1078 1052 1138 1074 1117 1079 1124 1113 1023 1056 1051 1027 1063 1021 1043 1008 1055 1068 1010 1088 1034 1047 1077 1107 1001 1084 1097 1084 1099 1124 1074 1094 1103 1158 1073 1072 1208 1136 1166 1158 1243 1201 1209 1213 1210 1253 1378 1349 1358 1387 1441 1438 1397 1475 1413 1484 1610 1683 1729 1816 1864 1999 2021 2138 2284 2256 2302 2320 2278 2443 2493 2623 2675 2725 2802 2882 2976 2986 3063 3207 3145 3144 3193 3247 3215 3232 3121 3054 3103 3020 2821 2882 2876 2808 2644 2605 2483 2537 2341 2275 2214 2089 2012 1841 1879 1895 1761 1740 1768 1559 1556 1519 1490 1446 1308 1402 1327 1331 1336 1327 1245 1305 1187 1225 1207 1236 1217 1192 1161 1116 1181 1138 1141 1155 1114 1111 1096 1048 1207 1142 1048 1046 1060 1091 1015 1052 1036 1086 1022 1047 1026 1068 989 1026 1033 1062 1015 1026 1003 1048 1019 1001 967 1039 1025 987 1027 968 1010 1085 1072 1017 986 1031 1029 1039 1025 1029 1055 1006 1057 1047 1055 1096 1002 1123 1018 1054 1020 1078 1035 1124 1052 1133 1068 1053 1098 1096 1064 1103 1104 1112 1130 1143 1172 1151 1214 1234 1222 1302 1236 1417 1389 1485 1536 1669 1751 1846 1902 2058 2021 2126 2046 1947 1807 1779 1683 1651 1629 1596 1639 1654 1560 1629 1440 1449 1372 1315 1279 1226 1145 1208 1188 1179 1182 1227 1195 1158 1165 1061 1186 1094 1174 1153 1122 1107 1129 1144 1207 1196 1160 1157 1236 1159 1137 1225 1242 1221 1213 1257 1256 1258 1310 1249 1364 1368 1357 1363 1464 1430 1448 1419 1530 1536 1541 1619 1605 1741 1775 1789 1826 1855 1945 1919 2093 2256 2426 2317 2464 2653 2795 3034 3254 3430 3826 4218 4643 5195 5969 6938 8083 9135 10816 12749 14658 17012 19017 20715 21992 22436 22141 20312 18132 16485 14729 13936 13550 13515 13493 13550 13099 12583 11272 9930 8324 6950 5794 5036 4424 3971 3571 3338 3037 2831 2621 2602 2428 2344 2284 2145 2197 2111 2068 2046 2022 2078 1976 1941 1983 1997 2059 2134 2046 2170 2307 2399 2439 2599 2735 3006 3303 3663 4201 4688 5267 6175 7033 8166 9016 10013 10595 11279 11075 10574 9506 8505 7688 7193 6958 6818 6854 6883 7120 6621 6322 5607 4731 4282 3701 3097 2770 2501 2220 2167 2028 1940 1818 1717 1607 1610 1563 1549 1543 1372 1389 1404 1330 1328 1385 1241 1307 1290 1293 1270 1231 1203 1153 1193 1174 1177 1158 1186 1220 1196 1180 1146 1201 1222 1042 1124 1180 1106 1160 1139 1170 1129 1195 1060 1118 1144 1110 1092 1136 1105 1121 1070 1186 1147 1080 1109 1076 1117 1091 1103 1126 1035 1106 1043 1098 1115 1065 1107 1161 1095 1099 1073 1085 1093 1179 1080 1140 1178 1143 1101 1159 1103 1111 1156 1150 1214 1097 1166 1104 1063 1194 1177 1098 1116 1099 1182 1128 1174 1154 1155 1096 1078 1156 1167 1172 1191 1180 1210 1271 1253 1328 1374 1475 1529 1605 1821 1759 1793 1853 1795 1859 1803 1632 1612 1491 1517 1672 1556 1527 1578 1608 1528 1514 1527 1423 1382 1400 1492 1422 1381 1380 1357 1361 1435 1318 1368 1450 1375 1426 1413 1428 1391 1353 1274 1319 1256 1357 1270 1313 1245 1205 1228 1179 1226 1198 1127 1162 1056 1094 1027 1081 1053 1091 1086 1041 1010 988 1033 1026 1030 990 1031 956 977 994 1047 989 1028 972 994 1016 1005 1026 1038 1020 1055 1133 1098 1084 1035 1021 1029 1043 1037 1026 980 997 1023 1031 1021 1043 1025 1017 1050 993 1021 966 1013 990 1026 978 954 901 974 995 1030 1011 966 949 993 989 965 985 1059 959 1067 1029 1067 1050 1107 1095 1095 1028 1098 1055 1059 1023 1092 1027 1091 1046 1155 1118 1157 1212 1182 1228 1281 1313 1250 1224 1171 1197 1164 1108 1156 1129 1191 1151 1134 1155 1164 1072 1080 1070 1109 1010 1040 1075 1004 1020 1008 1009 1060 997 1115 1054 1054 1005 1069 999 1074 1023 1037 1068 1015 1099 1041 1036 1067 1065 980 1009 1041 962 1002 989 949 970 1029 938 982 992 996 912 924 977 946 880 921 921 961 924 950 955 924 951 947 932 976 916 1008 924 953 960 886 972 1024 957 953 944 932 988 986 959 1036 977 976 989 1076 988 1057 982 1039 1068 1091 1124 1045 1065 1137 1074 1163 1214 1167 1306 1234 1375 1412 1490 1619 1798 1928 2110 2246 2486 2563 2693 2666 2754 2517 2336 2154 1992 1935 1886 1813 1876 1814 1952 1972 1937 1801 1668 1568 1441 1377 1240 1219 1178 1153 1148 1089 1085 1104 1026 1022 994 1000 1021 1025 1037 963 995 1003 1035 1041 1017 995 1010 983 972 1023 955 992 1063 959 990 955 1040 960 986 1002 978 939 992 980 986 917 981 987 1015 968 937 934 1018 981 963 994 975 977 1034 978 966 1048 948 1017 957 998 975 989 1020 967 951 971 992 983 1051 959 961 935 1037 930 1006 986 1010 1071 993 1046 983 1001 1041 993 1013 1007 971 1042 971 1043 1043 963 988 1010 971 1012 985 961 987 1022 985 974 917 931 998 974 948 956 932 1037 987 963 940 912 980 962 979 987 985 979 940 961 1011 986 1005 980 1009 1033 959 1014 1008 1025 1039 1068 907 999 1033 1020 993 943 1027 900 1040 1034 1007 932 973 965 982 957 987 1000 1001 932 968 932 985 976 994 1024 929 922 998 928 971 1004 952 1009 1031 939 1001 1013 1039 1005 1048 951 1002 1066 1069 1064 1093 1026 1069 1119 1148 1097 1170 1137 1131 1181 1189 1206 1276 1318 1285 1344 1488 1462 1611 1575 1595 1454 1470 1398 1456 1325 1377 1427 1352 1392 1431 1443 1465 1459 1471 1354 1380 1389 1371 1375 1343 1342 1385 1388 1392 1495 1412 1489 1528 1496 1610 1643 1648 1696 1710 1828 1866 1943 1868 1980 2125 2239 2347 2492 2714 2988 3251 3751 4118 4424 5241 5861 6923 8040 9085 10334 11424 11932 12223 11794 11136 9779 8421 7617 6952 6525 6517 6393 6776 7118 7166 7259 7085 6547 5715 5053 4234 3687 3246 2940 2609 2417 2184 2138 1920 1840 1776 1777 1658 1676 1540 1574 1526 1439 1476 1358 1379 1394 1281 1380 1324 1390 1254 1279 1351 1272 1251 1183 1204 1267 1240 1279 1314 1199 1238 1254 1251 1234 1295 1366 1370 1381 1346 1359 1423 1414 1443 1491 1473 1535 1507 1495 1542 1494 1652 1682 1659 1820 1791 1869 1841 1967 2002 2104 2131 2165 2354 2483 2412 2421 2669 2952 3083 3264 3473 3791 4184 4774 5341 6052 6939 8045 9444 10871 12728 14777 16524 18259 19309 19644 19046 17181 15498 13462 12266 11228 10375 10581 10595 11056 11527 12136 12247 11966 11102 10012 9229 7810 6684 5790 5056 4535 4004 3644 3366 3123 2998 2914 2785 2743 2578 2364 2270 2154 2031 1932 1822 1854 1780 1712 1646 1606 1571 1529 1533 1455 1394 1328 1373 1298 1356 1257 1319 1293 1250 1245 1209 1225 1231 1213 1149 1166 1099 1139 1179 1157 1084 1044 1041 1158 1069 1103 1065 1061 1061 1136 1115 1011 1087 1067 1092 1097 1000 1067 1094 1008 1014 1068 1069 989 1023 1024 1024 1031 1057 993 1072 1035 1016 1045 1071 1036 1035 990 1034 1037 1025 1128 1082 1031 1131 1181 1159 1126 1245 1278 1344 1282 1226 1331 1216 1228 1150 1119 1127 1168 1106 1201 1190 1158 1190 1265 1179 1173 1140 1166 1110 1197 1070 1114 1118 1159 1084 1089 1085 1068 1122 1058 1050 1067 1069 1148 1056 1051 1051 1067 1099 1088 1128 1061 1095 1139 1095 1132 1195 1169 1112 1236 1167 1193 1188 1267 1151 1235 1279 1290 1236 1309 1305 1367 1383 1440 1414 1495 1508 1587 1519 1622 1724 1638 1775 1819 1959 2092 2207 2393 2668 2883 3282 3542 4135 4573 5380 6011 6916 7630 8443 9186 9277 8904 8329 7279 6557 5729 5193 5061 4875 4867 4967 5251 5292 5582 5608 5448 5109 4632 4017 3518 3099 2740 2427 2183 2134 1927 1886 1763 1633 1585 1626 1491 1503 1364 1415 1326 1357 1389 1359 1249 1250 1265 1240 1258 1279 1292 1211 1206 1244 1164 1204 1216 1152 1139 1206 1185 1132 1098 1134 1158 1095 1158 1081 1066 1092 1158 1125 1118 1084 1048 1063 1009 1098 1057 1051 1045 1100 1081 1089 1114 1043 1080 1131 1124 1121 1037 1124 1058 1083 1062 1026 1056 1051 1102 1104 1021 1139 1094 1086 1134 1123 1103 1154 1175 1169 1191 1191 1265 1242 1260 1198 1327 1326 1358 1448 1423 1512 1654 1599 1754 1755 1926 1963 1916 1898 1776 1704 1522 1449 1461 1457 1355 1433 1432 1444 1396 1432 1564 1447 1384 1357 1266 1243 1194 1158 1146 1139 1095 1085 1036 1073 1039 995 1076 981 1049 1113 1023 995 1024 1128 1035 1084 1098 1149 1137 1108 1181 1201 1306 1385 1493 1481 1508 1629 1567 1679 1645 1535 1497 1530 1415 1362 1359 1377 1365 1418 1323 1338 1333 1324 1371 1298 1241 1250 1256 1170 1180 1127 1093 1119 1057 1034 998 981 1048 1014 1018 987 930 914 929 932 871 879 902 838 866 890 950 894 894 931 911 842 852 868 966 930 871 937 817 881 896 903 895 876 874 927 880 935 888 861 862 958 856 898 918 905 868 930 905 887 908 939 907 889 895 910 884 942 804 835 950 895 831 878 863 904 893 810 920 835 843 896 865 912 875 879 843 878 901 883 899 874 929 954 897 953 943 916 975 983 982 1002 984 1043 1070 1005 996 1008 983 994 966 985 1034 1008 964 922 958 1002 999 980 992 967 1053 1012 1024 965 935 985 982 998 900 938 891 1003 947 997 956 954 928 988 989 973 973 943 976 975 952 913 953 935 967 940 966 948 929 947 890 947 944 936 868 920 860 949 910 891 949 927 918 925 933 923 902 873 895 927 866 925 908 913 979 892 894 912 938 944 933 901 972 963 988 938 949 978 903 974 985 964 1010 1103 1079 1121 1200 1239 1320 1392 1473 1484 1524 1539 1458 1409 1327 1296 1259 1152 1164 1164 1174 1193 1259 1303 1303 1322 1296 1279 1224 1181 1226 1147 1083 966 1039 967 994 1059 1024 1045 974 975 1002 932 931 929 897 912 920 911 925 883 844 906 970 952 970 927 946 932 948 981 902 935 874 913 910 906 1003 927 939 927 925 982 935 953 1031 932 1007 938 973 1002 978 933 947 949 1033 995 1074 1050 988 1055 1066 1019 1056 1057 1024 1034 1055 1068 1045 1085 1154 1116 1120 1213 1193 1260 1241 1285 1264 1275 1315 1371 1375 1433 1367 1546 1411 1528 1517 1579 1565 1633 1651 1715 1823 1712 1837 1744 1783 1853 1887 1826 1902 1877 1832 1940 1834 1825 1817 1774 1778 1800 1849 1815 1807 1661 1681 1656 1626 1543 1451 1365 1525 1431 1385 1357 1400 1348 1296 1277 1246 1219 1170 1187 1133 1147 1050 1060 1035 1084 1083 1042 953 957 964 1021 942 937 951 955 936 947 958 978 896 960 834 947 862 828 885 887 876 907 815 837 891 857 898 901 865 829 851 831 830 884 827 870 834 863 800 823 867 822 848 790 800 843 783 877 763 871 816 815 778 802 824 799 806 820 772 794 759 828 792 826 809 857 897 815 863 816 880 791 862 863 894 859 848 887 874 916 968 979 948 945 933 923 935 855 927 912 848 833 894 942 876 959 886 876 904 851 880 887 868 829 849 902 898 871 812 801 866 809 855 820 830 838 805 822 837 797 850 790 832 853 804 835 878 786 910 850 885 856 811 877 812 911 939 927 839 901 948 969 936 972 912 881 887 931 867 813 890 872 917 907 899 850 858 941 891 885 894 909 881 827 862 853 846 870 876 805 820 819 775 839 910 908 847 879 833 902 842 868 868 868 904 929 880 907 881 933 910 953 936 966 999 1060 1085 1111 1074 1174 1117 1115 1089 1109 1087 1006 1107 1080 1040 1053 1131 1128 1154 1076 1162 1247 1233 1270 1378 1546 1530 1640 1771 1955 1970 2129 2193 2281 2044 2004 1763 1701 1483 1483 1418 1352 1353 1313 1403 1446 1477 1581 1533 1588 1604 1602 1457 1375 1218 1216 1083 1066 1040 1041 965 999 986 946 975 939 958 905 940 920 905 906 934 907 917 895 914 931 897 973 914 919 900 881 904 923 896 896 904 995 855 895 916 883 923 916 990 929 947 960 895 942 991 964 936 908 978 951 978 915 855 905 856 898 881 840 905 874 933 938 924 856 947 850 856 894 865 904 822 856 861 890 865 888 890 812 863 932 860 899 927 959 869 964 966 974 993 920 927 939 909 888 843 850 749 840 847 878 857 883 850 900 861 864 893 878 879 869 814 901 795 777 813 841 808 784 822 782 819 832 787 832 816 808 826 899 862 907 832 884 901 867 914 874 911 869 887 885 864 867 956 893 900 931 921 936 924 935 908 1007 1010 1004 1015 1014 1065 1133 1151 1232 1198 1360 1399 1578 1653 1809 2085 2213 2475 2644 2744 2738 2740 2492 2380 2160 1964 1925 1710 1606 1574 1545 1570 1601 1684 1785 1839 1861 1927 1916 1874 1742 1654 1525 1440 1354 1250 1165 1214 1184 1081 1077 1027 1070 1031 1038 997 919 980 990 971 922 908 932 958 831 926 924 965 964 967 965 962 992 978 1043 1039 1133 1155 1263 1257 1422 1450 1417 1428 1403 1459 1342 1298 1248 1158 1103 1112 1004 1107 1041 1130 1160 1177 1120 1144 1146 1160 1179 1167 1098 1039 1021 999 979 948 945 905 843 884 913 815 857 934 865 878 812 884 811 876 794 870 793 873 783 859 796 827 785 840 812 840 792 861 816 801 809 780 740 818 796 798 758 807 786 820 803 814 856 785 786 755 786 781 756 785 782 815 793 789 797 786 819 772 820 775 739 788 781 773 759 789 795 798 785 823 815 767 841 799 853 828 833 824 874 827 888 882 867 916 908 884 965 813 872 889 908 821 836 875 838 807 854 805 861 883 759 869 838 868 826 861 872 863 808 860 811 829 788 809 806 821 815 858 755 810 848 868 857 897 922 899 944 932 990 1057 1047 1161 1197 1163 1255 1339 1226 1205 1170 1081 1065 999 979 918 954 963 919 1032 1030 1042 992 1078 1045 1014 1021 1009 985 986 977 894 899 897 830 863 828 866 788 821 793 773 788 830 820 814 801 814 816 837 815 812 833 822 785 770 774 755 815 754 789 791 822 773 805 753 775 783 810 787 808 808 714 811 828 778 794 785 807 817 807 750 741 791 837 772 854 809 798 787 821 789 781 776 723 807 810 834 792 782 771 823 793 793 830 774 782 818 824 723 839 804 811 830 838 779 838 756 816 771 806 874 797 819 804 784 806 752 828 801 801 756 856 796 871 892 892 874 877 974 947 936 952 1008 1007 969 946 916 932 820 861 878 866 831 874 893 893 782 916 911 894 880 873 929 921 883 834 791 842 857 766 863 831 832 879 826 814 779 811 819 778 764 792 811 776 826 779 782 746 829 779 897 833 822 794 814 800 874 831 818 768 756 852 791 790 882 826 891 889 896 899 980 870 862 915 925 867 838 949 858 840 864 848 822 870 843 881 865 909 817 818 935 892 899 845 853 823 858 838 875 886 842 861 827 794 866 852 892 860 814 909 839 901 906 856 872 869 868 880 910 902 910 838 928 951 881 910 900 946 932 876 940 908 936 1032 934 1039 992 1021 1055 1038 1049 1055 1079 1198 1180 1129 1127 1114 1118 1099 1064 1088 1054 1124 1108 1148 1102 1231 1186 1205 1181 1250 1205 1236 1241 1246 1310 1295 1321 1259 1347 1390 1465 1484 1512 1541 1576 1636 1681 1859 1970 2155 2244 2645 2755 3005 3374 3763 4331 4843 5536 6047 6560 6869 6711 6709 6113 5538 4939 4296 3698 3424 3186 2994 2966 2907 2936 3184 3146 3538 3666 3892 4034 4202 4033 3983 3728 3266 2985 2636 2439 2222 2036 1866 1756 1602 1514 1506 1531 1395 1450 1372 1379 1304 1252 1292 1285 1142 1205 1201 1167 1175 1157 1153 1140 1124 1090 1123 1119 1134 1108 1141 1104 1162 1095 1202 1113 1160 1147 1100 1153 1187 1153 1185 1178 1175 1171 1279 1212 1164 1301 1254 1328 1308 1414 1464 1534 1656 1692 1858 1905 2173 2369 2579 2932 3142 3465 3563 3435 3360 3107 2917 2617 2534 2251 2149 1950 1916 1914 1891 1935 1923 2012 2175 2291 2432 2429 2535 2484 2567 2419 2382 2251 2166 2183 2116 2122 2148 2210 2245 2536 2653 2801 3079 3385 3584 3751 4071 3823 3759 3469 3091 2821 2487 2354 2179 2120 1970 1908 2003 1989 1967 2130 2171 2234 2343 2432 2449 2464 2559 2328 2092 1969 1838 1756 1528 1470 1364 1402 1301 1245 1211 1176 1120 1205 1090 1052 1065 1063 980 1064 1025 1035 1025 1052 988 1058 1016 1013 992 1052 1023 1071 1061 1055 1089 1112 1075 1221 1195 1315 1277 1414 1451 1490 1457 1456 1435 1360 1258 1212 1175 1175 1129 1102 1074 1124 1101 1084 1097 1139 1099 1165 1185 1138 1162 1186 1201 1176 1120 1146 1080 1022 1000 1061 982 1028 987 992 979 1022 1079 952 1051 1015 975 1000 1063 1073 1062 1079 1018 1053 1055 1120 1114 1138 1069 1122 1203 1172 1153 1257 1341 1310 1439 1428 1459 1679 1706 1847 2042 2251 2540 2708 2907 3038 3131 3057 2914 2727 2571 2325 2134 1942 1855 1752 1703 1690 1694 1733 1714 1819 1884 1929 2120 2127 2191 2108 2138 2034 1992 1939 1815 1711 1615 1560 1500 1535 1493 1426 1497 1604 1504 1608 1741 1824 1950 2141 2306 2595 2779 2822 3017 2983 2846 2720 2539 2292 2178 1892 1775 1729 1639 1603 1584 1557 1525 1672 1655 1746 1721 1910 1873 1987 1967 2008 1845 1761 1692 1531 1471 1324 1343 1215 1267 1056 1141 1084 996 1001 985 1015 971 937 955 938 927 977 904 927 889 878 935 880 930 936 880 913 877 818 809 802 789 882 808 809 852 824 855 851 834 838 816 865 812 814 846 836 920 839 862 800 889 878 806 827 798 806 810 845 786 784 819 865 804 810 874 791 835 864 834 803 831 840 843 841 878 864 890 878 882 864 908 804 814 854 836 829 794 850 819 856 852 829 787 839 860 797 799 804 799 868 840 864 888 832 832 782 892 819 779 836 797 839 789 807 802 800 820 744 780 810 829 760 858 832 831 762 860 840 857 779 789 825 836 900 783 839 892 875 810 829 878 836 877 853 823 897 860 905 910 886 836 906 887 884 902 891 939 982 938 931 957 973 944 1042 1058 1013 1033 1017 1047 1061 1197 1104 1146 1104 1171 1172 1160 1100 1194 1160 1186 1220 1162 1210 1183 1258 1282 1231 1227 1099 1159 1117 1130 1037 1125 1057 1113 1087 1010 1019 1033 995 1012 1021 992 1046 1076 1087 1047 1038 967 1032 918 954 1018 947 889 881 869 831 831 829 912 890 792 862 747 784 883 792 835 853 828 833 841 839 825 797 828 791 781 840 810 829 826 852 889 856 817 858 801 783 808 813 844 805 794 808 781 835 827 820 794 828 840 804 845 893 874 889 944 981 991 987 1129 1037 1131 1180 1190 1178 1107 1065 981 994 940 943 885 984 951 923 906 928 901 893 932 889 994 971 1000 1009 1050 954 979 923 933 929 903 893 938 922 960 916 938 976 971 959 1003 1014 919 971 963 925 918 873 848 848 889 822 872 932 880 866 860 896 902 863 847 905 860 904 877 944 932 917 919 883 914 930 885 862 837 900 861 864 836 847 847 887 797 791 864 843 813 847 772 843 803 796 848 821 833 811 817 842 761 806 805 781 796 800 766 779 751 839 788 771 707 794 738 755 743 841 795 804 860 775 821 760 780 867 762 796 853 746 798 776 813 778 847 814 804 816 828 793 808 850 793 799 840 814 823 782 808 811 864 799 829 815 871 796 861 883 886 855 896 912 877 912 901 896 933 980 979 948 1000 1067 1099 1181 1199 1152 1258 1282 1366 1420 1355 1337 1320 1271 1202 1138 1094 1073 1000 1056 975 940 939 941 1008 1036 947 983 1035 1102 1115 1024 1100 1174 1086 1139 1093 1026 1033 948 939 926 868 940 878 963 921 983 921 865 893 960 945 995 968 943 1011 992 950 947 928 902 921 837 845 878 871 887 845 842 840 857 854 795 862 864 794 907 866 844 845 884 873 890 831 891 839 843 824 744 744 827 810 817 780 748 794 746 826 794 786 781 795 809 766 792 763 737 799 777 751 739 791 780 789 806 752 740 766 830 811 802 823 832 793 755 764 781 826 778 798 780 802 771 813 814 847 816 801 844 861 832 910 828 812 860 848 856 868 870 855 928 924 883 841 960 941 951 977 973 1003 1054 1063 1028 1064 1029 1040 1092 1018 1111 1132 1098 1128 1203 1184 1217 1300 1264 1391 1500 1652 1796 1938 2002 2289 2408 2562 2588 2687 2478 2349 2154 1944 1739 1720 1549 1529 1486 1372 1333 1306 1399 1270 1375 1385 1477 1586 1547 1606 1711 1666 1646 1764 1636 1578 1556 1470 1326 1256 1253 1164 1210 1164 1081 1040 972 913 985 1003 975 964 919 920 984 975 949 949 953 943 954 939 977 1005 1008 1042 1100 1120 1122 1203 1175 1297 1344 1316 1357 1347 1304 1299 1232 1190 1109 1124 1147 1045 1031 981 1050 1073 1008 1032 1068 1046 1099 1174 1208 1139 1258 1198 1295 1264 1301 1220 1241 1131 1236 1181 1205 1165 1180 1271 1247 1283 1318 1326 1343 1256 1266 1224 1260 1217 1205 1195 1237 1219 1243 1255 1277 1273 1394 1361 1470 1501 1624 1585 1831 1907 2121 2282 2400 2598 2944 3143 3353 3530 3803 3562 3549 3376 3153 2760 2587 2416 2156 2010 1872 1900 1732 1703 1674 1722 1711 1760 1707 1774 1965 2056 2160 2251 2267 2415 2295 2241 2161 2003 1879 1731 1640 1472 1361 1286 1163 1156 1147 1069 1109 1068 1060 1012 995 1036 948 1010 993 932 916 959 901 953 886 930 913 893 905 826 914 845 890 836 866 800 875 877 862 911 849 908 888 913 905 865 943 924 883 888 800 824 813 818 850 809 868 884 831 885 825 882 824 816 823 850 872 914 929 942 919 956 930 921 991 972 997 899 906 886 937 877 839 774 825 817 832 814 834 817 809 869 847 829 852 812 823 877 876 863 820 800 836 864 865 779 822 838 862 785 749 748 799 740 759 720 690 770 716 751 809 743 695 781 772 795 738 722 721 748 751 721 815 733 777 743 731 751 715 787 696 747 728 737 767 738 761 749 781 700 749 790 703 753 726 735 713 669 732 696 712 740 688 751 719 757 718 741 688 722 764 733 711 742 699 709 713 676 697 735 747 726 691 727 707 772 721 779 662 762 733 779 715 744 695 681 724 774 700 710 665 750 684 712 728 720 765 771 729 726 762 732 757 746 762 741 781 753 768 758 741 774 733 688 735 794 714 695 692 732 768 765 727 721 745 787 751 733 712 751 784 728 712 710 746 774 746 776 808 749 792 771 690 738 718 732 736 683 785 812 731 761 780 766 744 785 727 776 718 781 699 757 750 768 767 728 757 706 800 759 760 780 761 749 766 727 756 758 726 806 755 740 788 749 698 797 835 749 702 782 828 784 762 831 730 834 793 848 791 834 831 855 813 784 755 825 797 780 796 843 813 865 865 803 809 913 878 856 901 858 981 942 954 892 975 907 1040 904 1003 943 1010 961 1080 1057 1038 1140 1109 1254 1277 1329 1381 1414 1571 1656 1821 1874 2134 2166 2273 2342 2241 2092 2023 1840 1742 1595 1518 1442 1344 1287 1197 1174 1199 1179 1186 1177 1245 1231 1231 1326 1317 1389 1497 1539 1548 1484 1590 1525 1490 1376 1360 1208 1180 1153 1102 989 988 994 1025 976 896 924 923 972 948 904 899 878 895 912 883 853 860 804 808 841 873 842 837 850 834 797 830 801 812 835 803 825 846 878 771 806 833 784 827 800 844 820 839 806 765 874 790 821 819 870 836 817 860 825 836 777 771 857 838 894 863 850 906 848 884 886 916 853 941 911 903 933 904 901 918 852 818 852 885 822 902 854 884 838 899 875 925 936 905 1032 1072 1069 1121 1108 1162 1134 1124 1235 1167 1146 1086 1128 1078 1009 990 967 986 885 946 964 903 875 927 919 964 984 946 968 987 924 1050 1029 1074 1086 1157 1077 1143 1121 1138 1118 1125 1160 1164 1204 1198 1391 1413 1458 1466 1602 1819 1875 1909 1926 2043 1973 1990 1849 1787 1732 1529 1497 1367 1380 1218 1218 1165 1163 1187 1146 1130 1119 1208 1211 1157 1258 1160 1368 1325 1464 1491 1487 1477 1514 1419 1407 1383 1226 1189 1213 1023 1118 1070 1000 1029 982 977 1027 1002 961 1027 971 1026 927 993 929 983 936 961 904 987 918 999 998 1021 953 1073 1005 1018 1055 944 1045 1050 1055 1057 1106 1080 1104 1075 1170 1164 1240 1258 1338 1368 1534 1635 1705 1804 1961 2145 2335 2454 2727 2831 2841 2783 2695 2457 2416 2334 2172 1949 1859 1840 1751 1738 1756 1803 1741 1679 1597 1640 1606 1628 1577 1597 1702 1735 1781 1854 1948 1859 1960 1911 1892 1674 1759 1636 1511 1494 1396 1345 1295 1289 1243 1324 1192 1215 1117 1160 1059 1104 1017 987 940 983 901 922 913 926 879 896 881 896 845 867 842 839 827 846 863 866 823 897 799 791 788 839 814 793 810 809 771 817 783 743 804 822 745 788 803 860 824 830 763 774 793 788 818 839 770 738 821 859 848 806 856 825 853 816 864 779 827 782 834 829 840 802 840 809 852 799 835 798 837 831 783 812 811 800 776 830 821 863 835 830 959 877 960 901 930 880 953 1001 1020 1013 1068 1000 1017 1037 1017 990 976 898 888 913 913 844 843 806 866 830 863 848 841 800 866 857 836 908 869 869 845 853 892 864 877 868 886 912 888 864 910 871 808 801 840 853 811 805 813 822 898 803 819 794 819 819 781 855 822 831 778 783 815 799 812 830 852 879 777 785 801 787 800 792 761 835 774 840 772 795 829 812 811 807 847 713 842 770 835 775 828 787 814 807 754 792 814 839 809 829 800 817 801 795 851 749 807 916 870 794 865 855 845 835 843 857 831 784 820 796 848 747 790 819 778 748 749 745 808 737 758 807 793 803 867 790 812 780 751 752 807 824 755 741 761 769 827 775 779 750 724 741 775 757 729 691 738 745 746 783 724 772 734 688 756 781 751 704 745 783 719 756 742 766 716 712 788 756 806 742 767 761 768 795 717 735 772 710 748 789 774 734 780 748 769 751 699 731 751 715 691 779 758 741 722 756 773 697 732 725 723 735 761 740 808 779 752 708 774 768 802 755 795 742 806 749 799 816 753 763 762 750 782 732 773 722 764 751 771 789 813 769 850 844 782 864 818 811 842 824 812 789 822 781 757 765 781 774 769 761 705 759 724 812 749 789 752 759 793 762 780 814 756 779 827 810 768 815 799 850 853 790 820 799 813 839 867 803 915 884 931 858 939 983 906 995 969 944 925 924 835 846 850 902 803 856 828 838 842 816 806 845 786 820 833 815 857 804 854 740 866 889 885 835 875 861 845 869 828 827 850 825 869 789 801 789 779 789 827 766 806 726 788 742 747 727 754 762 697 742 788 767 769 738 720 712 731 758 730 819 786 728 754 747 761 699 769 744 729 751 739 756 741 714 734 711 740 768 691 752 733 730 716 731 735 760 769 790 797 797 711 723 747 725 759 746 769 717 734 700 788 748 728 695 808 781 736 753 778 759 722 771 774 770 792 736 769 819 815 797 811 774 832 800 841 807 757 862 790 753 803 804 754 794 749 775</counts>
			</dataPoints>
		</scan>
	</xrdMeasurement>
</xrdMeasurements>