File: dataset/precursor_mixture/Li2CO3_0p9001-ZrO2_0p1000--2min.xrdml
<?xml version="1.0"?>
<xrdMeasurements xmlns="http://www.xrdml.com/XRDMeasurement/2.3" xmlns:xsi="http://www.w3.org/2001/XMLSchema-instance" xsi:schemaLocation="http://www.xrdml.com/XRDMeasurement/2.3 http://www.xrdml.com/XRDMeasurement/2.3/XRDMeasurement.xsd" status="Completed" recordIdentifier="{4041F11F-33AF-4F42-A13D-A3D2028FA53F}">
	<comment>
		<entry/>
	</comment>
	<sample type="To be analyzed">
		<id>Li2CO3_0p9001-ZrO2_0p1000--2min</id>
		<name></name>
		<preparedBy></preparedBy>
	</sample>
	<xrdMeasurement measurementType="Scan" status="Completed" sampleMode="Reflection">
		<usedWavelength intended="K-Alpha 1">
			<kAlpha1 unit="Angstrom">1.5405980</kAlpha1>
			<kAlpha2 unit="Angstrom">1.5444260</kAlpha2>
			<kBeta unit="Angstrom">1.3922500</kBeta>
			<ratioKAlpha2KAlpha1>0.5000</ratioKAlpha2KAlpha1>
		</usedWavelength>
		<incidentBeamPath>
			<radius unit="mm">145.00</radius>
			<xRayTube id="1010048" name="Empyrean Cu LFF HR (9430 033 7310x)">
				<tension unit="kV">40.0</tension>
				<current unit="mA">15.0</current>
				<anodeMaterial>Cu</anodeMaterial>
				<focus type="Line">
					<length unit="mm">12.0</length>
					<width unit="mm">0.4</width>
					<takeOffAngle unit="deg">6.0</takeOffAngle>
				</focus>
			</xRayTube>
			<sollerSlit id="21010002" name="Soller slits 0.04 rad.">
				<opening unit="rad">0.0400</opening>
			</sollerSlit>
			<mask id="22031000" name="Fixed mask 13 mm">
				<width unit="mm">9.00</width>
			</mask>
			<divergenceSlit id="22120001" name="Divergence slit 1°" xsi:type="fixedDivergenceSlitType">
				<distanceToSample unit="mm">50.00</distanceToSample>
				<height unit="mm">1.52</height>
			</divergenceSlit>
		</incidentBeamPath>
		<sampleMovement xsi:type="spinningSampleMovementType">
			<spinnerRevolutionTime unit="seconds">1.0</spinnerRevolutionTime>
		</sampleMovement>
		<diffractedBeamPath>
			<radius unit="mm">145.00</radius>
			<antiScatterSlit id="22090040" name="AS slit 9 mm (PIXcel)" xsi:type="fixedAntiScatterSlitType">
				<height unit="mm">9.00</height>
			</antiScatterSlit>
			<sollerSlit id="21020003" name="Large Soller slits 0.04 rad.">
				<opening unit="rad">0.0400</opening>
			</sollerSlit>
			<filter id="20030001" name="Large beta-filter Nickel">
				<material>Ni</material>
				<thickness unit="mm">0.020</thickness>
			</filter>
			<detector id="7010019" name="PIXcel1D-Medipix3 detector" xsi:type="rtmsDetectorType">
				<phd unit="keV">
					<lowerLevel>4.02</lowerLevel>
					<upperLevel>11.27</upperLevel>
				</phd>
				<mode>Scanning</mode>
				<activeLength unit="deg">5.542</activeLength>
			</detector>
		</diffractedBeamPath>
		<scan appendNumber="0" mode="Continuous" scanAxis="Gonio" status="Completed">
			<header>
				<startTimeStamp>2024-11-14T14:29:49-08:00</startTimeStamp>
				<endTimeStamp>2024-11-14T14:31:54-08:00</endTimeStamp>
				<author>
					<name>AutomatedUser</name>
				</author>
				<source>
					<applicationSoftware version="1.7b (136)">PANalytical Aeris Instrument Suite</applicationSoftware>
					<instrumentControlSoftware version="3.2.00000000 20240306">AERIS</instrumentControlSoftware>
					<instrumentID>950485</instrumentID>
				</source>
			</header>
			<dataPoints>
				<positions axis="2Theta" unit="deg">
					<startPosition>10.02173288</startPosition>
					<endPosition>99.99585608</endPosition>
				</positions>
				<positions axis="Omega" unit="deg">
					<startPosition>5.01086644</startPosition>
					<endPosition>49.99792804</endPosition>
				</positions>
				<commonCountingTime unit="seconds">10.965</commonCountingTime>
				<counts unit="counts">2434 2406 2283 2246 2253 2210 2325 2329 2376 2320 2300 2332 2215 2205 2242 2326 2218 2228 2218 2179 2119 2193 2184 2181 2192 2155 2173 2115 2203 2009 2091 2096 2046 2127 2085 2126 2109 2022 2114 2066 1936 2014 1948 2035 1928 1945 1912 1952 1963 1956 1888 1974 1891 1915 1934 1900 1949 1895 1965 1892 1905 1858 1774 1862 1828 1869 1789 1878 1876 1953 1783 1801 1854 1869 1837 1877 1853 1897 1864 1935 1874 1819 1869 1714 1887 1786 1843 1832 1781 1904 1832 1905 1864 1910 1844 1856 1931 1913 1898 1924 1868 1887 1905 1915 1959 1935 1868 1904 1998 1866 1838 1824 1885 1892 1805 1842 1943 1867 1899 1852 1987 2026 1887 1864 1870 1825 1810 1872 1856 1874 1876 1904 1900 1772 1823 1809 1812 1817 1938 1744 1749 1822 1876 1814 1838 1876 1780 1839 1893 1820 1827 1769 1797 1719 1776 1733 1817 1801 1757 1830 1729 1808 1786 1719 1839 1832 1888 1788 1740 1863 1940 2020 2072 2010 2006 1984 2024 1972 1999 1879 1876 1762 1828 1761 1822 1724 1822 1731 1730 1786 1793 1706 1744 1708 1720 1679 1687 1707 1652 1655 1685 1675 1589 1661 1746 1675 1634 1641 1736 1663 1644 1676 1680 1692 1670 1569 1633 1585 1642 1594 1645 1643 1663 1697 1602 1661 1617 1656 1625 1570 1563 1580 1598 1663 1543 1550 1571 1615 1569 1568 1579 1658 1635 1638 1648 1630 1592 1623 1619 1708 1746 1832 1873 1804 2032 2277 2645 3217 3917 4765 5881 6961 8137 9206 10030 10363 9527 7786 5847 4349 3659 2961 2574 2220 1980 1859 1850 1795 1610 1541 1566 1570 1623 1615 1632 1540 1475 1578 1573 1499 1647 1559 1525 1526 1561 1535 1538 1461 1546 1574 1623 1563 1623 1690 1770 1792 1921 2091 2320 2442 2657 2876 3033 3021 2871 2816 2529 2289 2104 2089 1978 2010 2202 2221 2319 2467 2596 2596 2700 2680 2431 2416 2367 2285 2368 2191 2268 2303 2207 2062 1903 1844 1654 1528 1608 1491 1413 1463 1461 1511 1448 1498 1449 1460 1498 1418 1484 1529 1428 1478 1497 1438 1493 1397 1456 1379 1347 1408 1459 1454 1364 1391 1259 1411 1365 1311 1405 1421 1314 1409 1406 1452 1401 1303 1409 1399 1438 1351 1367 1394 1404 1444 1363 1367 1466 1394 1410 1476 1405 1527 1466 1572 1471 1530 1516 1571 1568 1638 1699 1669 1850 1954 2091 2331 2746 3200 3864 4618 5387 6438 7390 8118 8540 8384 7804 6522 5320 4500 3695 3028 2747 2461 2188 2034 1958 1825 1836 1716 1800 1798 1781 1873 2009 2054 2250 2552 2743 3180 3619 3978 4094 4421 4331 4077 3461 3222 2789 2445 2325 2193 2057 2044 2005 2031 2115 2116 2237 2442 2629 2978 3679 4280 5130 6186 7456 8419 9530 10345 10512 10038 9168 7761 6371 5411 4552 4019 3453 3355 3306 3551 3891 4176 4866 5723 6616 7649 9001 10333 11657 12767 13741 14687 15844 16668 17121 16752 15624 13602 11206 9051 7201 5761 4694 3981 3228 2883 2565 2416 2103 2028 1941 1784 1840 1791 1648 1762 1624 1705 1687 1641 1674 1635 1553 1565 1607 1652 1521 1545 1541 1588 1599 1645 1637 1646 1648 1709 1796 1891 1996 2152 2340 2828 3227 3778 4651 5339 6022 6828 7258 7424 6960 6442 5507 4895 4197 3627 3408 2930 2701 2360 2168 1908 1887 1737 1713 1670 1671 1767 1734 1748 1839 1981 2082 2312 2336 2559 2457 2440 2378 2193 2043 1909 1896 1806 1784 1797 1981 2170 2452 2747 3435 3599 4064 4426 4297 4172 3694 3154 2627 2303 2052 1824 1905 1755 1856 2001 2131 2512 2811 3355 3672 4261 4686 5309 5073 5151 4724 3993 3424 2911 2344 2024 1863 1660 1576 1481 1454 1293 1407 1319 1326 1210 1176 1258 1136 1327 1276 1263 1251 1263 1250 1253 1219 1259 1334 1346 1482 1418 1452 1536 1625 1592 1566 1530 1509 1509 1346 1436 1263 1336 1409 1381 1406 1401 1411 1475 1676 1803 2084 2383 2602 2997 3311 3707 3966 3855 3837 3538 3145 3023 3132 2943 2957 2697 2579 2343 2164 1844 1648 1542 1400 1433 1474 1561 1534 1646 1621 1856 2016 2029 2100 2193 2124 2028 1901 1801 1738 1675 1670 1680 1776 1721 1758 1760 1700 1619 1619 1675 1535 1532 1381 1243 1294 1180 1096 1137 1154 1184 1134 1110 1075 1095 1094 1137 1116 1085 1186 1134 1104 1152 1118 1311 1294 1446 1475 1616 1529 1523 1434 1371 1292 1311 1256 1193 1194 1215 1221 1322 1371 1551 1592 1638 1911 2012 1989 1965 1718 1622 1408 1256 1277 1284 1123 1087 1134 1089 1085 1077 1054 1064 1034 1150 1076 1021 1103 1127 1160 1085 1170 1243 1323 1350 1505 1551 1509 1667 1625 1640 1546 1459 1442 1444 1294 1407 1275 1372 1341 1382 1444 1483 1514 1431 1449 1409 1349 1275 1246 1121 1181 1080 1053 1046 983 1013 1030 1102 1028 943 978 950 951 987 1020 981 957 899 1005 1001 927 961 953 1020 1033 1037 1019 1034 990 1047 1014 984 1131 1077 1120 1111 1133 1069 1152 1164 1152 1140 1079 1113 1175 1125 1153 1208 1222 1159 1298 1323 1270 1290 1237 1348 1298 1392 1535 1591 1752 1996 2265 2444 2653 2944 3146 3159 3219 3130 2984 2751 2757 2443 2431 2602 2524 2631 2605 2729 2691 2454 2272 2051 1880 1708 1625 1587 1509 1492 1555 1646 1842 1926 2143 2458 2674 2958 3139 3321 3211 3178 3003 2903 2749 2473 2500 2425 2355 2365 2140 2133 1924 1754 1577 1446 1463 1356 1334 1418 1285 1406 1386 1428 1411 1376 1341 1309 1175 1202 1131 1085 1047 1024 1097 996 935 998 984 1044 973 1023 978 971 945 922 991 944 944 974 920 962 907 926 898 886 917 952 902 928 942 956 829 926 858 961 980 964 949 994 971 919 1056 932 973 970 956 971 1083 1071 1119 1097 1086 1248 1250 1398 1504 1648 1759 1796 1841 1811 1645 1654 1549 1429 1291 1183 1214 1075 1088 1118 1042 1106 1041 1108 1091 1181 1214 1102 1206 1218 1286 1427 1495 1599 1752 1868 1987 2076 2119 2134 2037 2136 2082 1941 1946 1966 1745 1783 1866 1798 1699 1707 1534 1486 1341 1319 1235 1257 1138 1157 1178 1100 1182 1144 1316 1341 1424 1538 1698 1790 1839 1807 1736 1740 1764 1721 1712 1693 1813 1649 1739 1694 1629 1705 1564 1577 1616 1686 1835 1955 2127 2262 2426 2333 2320 2308 2249 2228 2148 2081 2007 1980 2074 2201 2072 1955 1978 2016 1910 1907 1905 1909 1749 1833 1779 2004 1975 2031 2054 2129 2035 2049 1998 1906 1828 1758 1706 1622 1591 1589 1736 1832 2064 2259 2430 2740 2943 3125 3095 3244 3102 2987 2783 2619 2389 2129 1995 1844 1609 1557 1417 1307 1316 1180 1163 1176 1113 1084 1100 1129 1168 1269 1232 1365 1510 1506 1603 1730 1765 1923 1865 1905 2012 2136 2227 2156 2094 2060 2003 1906 1726 1549 1546 1544 1509 1490 1534 1638 1600 1639 1512 1438 1413 1330 1322 1311 1221 1214 1144 1137 1128 1156 1283 1281 1355 1371 1484 1658 1656 1733 1567 1766 1605 1589 1477 1383 1399 1383 1368 1463 1459 1452 1516 1541 1539 1493 1465 1549 1382 1296 1281 1252 1260 1195 1166 1171 1099 1157 1188 1214 1155 1135 1214 1144 1182 1098 1053 1132 1079 1046 1006 1054 1069 1119 1180 1154 1097 1165 1161 1176 1094 1259 1204 1406 1399 1560 1574 1782 1863 1963 1911 1943 1823 1833 1820 1591 1528 1461 1476 1327 1313 1260 1091 1067 1050 972 983 935 932 956 915 902 913 949 915 867 897 883 921 888 835 862 894 963 961 910 937 925 982 998 980 979 978 990 976 915 933 976 889 882 879 828 860 884 815 838 897 845 834 867 908 906 908 874 843 841 841 878 837 816 865 831 816 828 839 909 896 935 922 923 915 926 964 949 1017 979 931 983 1004 1026 1038 978 1021 1045 1090 967 984 989 869 941 952 830 859 890 834 843 877 901 875 843 913 919 862 957 838 881 943 904 901 849 891 920 908 909 947 1016 1014 1095 1046 1166 1174 1201 1158 1195 1157 1028 1057 1114 1024 1014 1058 1078 1071 1051 1028 1101 1124 1055 1065 1081 1083 1063 1055 1079 1065 976 1094 1010 1045 949 1012 998 978 1003 998 946 969 918 872 790 826 862 867 838 773 809 816 792 854 870 886 878 986 1016 1023 1044 1100 1127 1185 1186 1228 1256 1262 1337 1335 1306 1216 1107 1158 1082 1095 1047 956 1001 950 940 917 995 1009 1051 1036 1055 1103 1128 1188 1297 1346 1315 1404 1364 1408 1347 1291 1251 1185 1197 1221 1116 1036 1027 1051 983 917 953 939 905 891 827 786 793 822 798 828 818 773 832 931 842 762 859 844 887 914 933 921 850 885 839 792 857 877 811 844 825 796 876 854 833 802 851 892 858 950 920 920 877 911 875 834 840 824 855 787 817 775 768 825 824 802 785 799 832 828 787 808 793 737 809 856 746 838 868 900 888 879 946 819 903 906 856 915 861 859 843 813 786 787 754 650 740 677 723 740 693 714 651 734 747 744 702 748 741 739 704 713 760 688 697 741 763 771 771 738 769 776 798 687 760 769 773 808 807 802 753 763 781 779 735 773 786 776 820 817 821 856 897 891 925 916 891 911 954 937 895 953 979 916 952 880 898 821 830 885 871 893 891 909 867 932 832 948 955 939 931 943 886 934 915 884 932 895 964 937 979 923 908 992 1051 996 950 975 923 943 963 888 933 929 824 857 853 852 859 926 914 833 942 882 924 946 975 885 906 838 806 858 821 782 785 780 793 758 777 810 777 849 871 820 817 833 772 811 812 836 766 773 771 772 813 819 871 713 778 785 746 764 809 807 914 951 906 940 984 946 1125 1069 1063 1097 1093 1019 1077 1137 1052 1015 961 905 892 877 872 865 809 770 834 825 815 757 742 786 745 771 785 827 912 861 894 919 902 828 834 860 922 805 889 842 846 845 830 849 900 899 922 937 986 902 925 995 960 974 1044 983 1007 998 955 879 947 871 880 799 820 766 855 837 774 773 768 795 733 759 830 857 809 843 824 804 910 860 870 930 941 899 925 883 882 936 908 810 802 779 822 805 709 750 765 757 733 755 728 707 712 656 714 732 738 722 742 778 717 720 695 724 695 754 741 776 765 719 709 704 730 612 697 699 735 761 679 691 714 719 730 757 832 758 805 797 896 862 917 900 979 977 910 880 900 893 852 879 832 824 759 805 809 830 802 815 841 837 838 824 832 816 890 875 876 850 801 880 853 844 865 829 808 785 815 798 860 804 785 808 797 769 736 788 764 704 727 701 761 731 695 788 785 819 795 846 804 782 827 878 798 829 781 904 864 777 823 859 870 871 910 866 874 863 889 778 846 834 825 871 822 825 830 884 883 899 884 960 888 946 1030 984 1033 1003 1026 1082 1070 1066 1068 984 1039 966 1021 932 1068 991 950 994 928 983 953 907 940 842 866 897 898 847 825 787 717 824 810 807 764 864 890 811 806 878 882 770 892 912 845 854 835 907 904 832 901 855 876 962 964 941 988 1014 1064 1020 996 976 992 1015 1035 1030 1066 1066 1058 1125 1131 1037 1078 1053 1073 1022 1095 999 961 1025 987 993 960 948</counts>
			</dataPoints>
		</scan>
	</xrdMeasurement>
</xrdMeasurements>