File: dataset/precursor_mixture/Li2CO3_NaHCO3_CuO.12-min.xrdml
<?xml version="1.0"?>
<xrdMeasurements xmlns="http://www.xrdml.com/XRDMeasurement/2.2" xmlns:xsi="http://www.w3.org/2001/XMLSchema-instance" xsi:schemaLocation="http://www.xrdml.com/XRDMeasurement/2.2 http://www.xrdml.com/XRDMeasurement/2.2/XRDMeasurement.xsd" status="Completed" recordIdentifier="{BB7D2C0E-A2F4-49F8-9F42-C4F243B496B5}">
	<comment>
		<entry/>
	</comment>
	<sample type="To be analyzed">
		<id>dara-4-2</id>
		<name></name>
		<preparedBy></preparedBy>
	</sample>
	<xrdMeasurement measurementType="Scan" status="Completed" sampleMode="Reflection">
		<usedWavelength intended="K-Alpha 1">
			<kAlpha1 unit="Angstrom">1.5405980</kAlpha1>
			<kAlpha2 unit="Angstrom">1.5444260</kAlpha2>
			<kBeta unit="Angstrom">1.3922500</kBeta>
			<ratioKAlpha2KAlpha1>0.5000</ratioKAlpha2KAlpha1>
		</usedWavelength>
		<incidentBeamPath>
			<radius unit="mm">145.00</radius>
			<xRayTube id="1010048" name="Empyrean Cu LFF HR (9430 033 7310x) DK437873">
				<tension unit="kV">40.0</tension>
				<current unit="mA">15.0</current>
				<anodeMaterial>Cu</anodeMaterial>
				<focus type="Line">
					<length unit="mm">12.0</length>
					<width unit="mm">0.4</width>
					<takeOffAngle unit="deg">6.0</takeOffAngle>
				</focus>
			</xRayTube>
			<filter id="20010004" name="Beta-filter Nickel">
				<material>Ni</material>
				<thickness unit="mm">0.020</thickness>
			</filter>
			<sollerSlit id="21010002" name="Soller slits 0.04 rad.">
				<opening unit="rad">0.0400</opening>
			</sollerSlit>
			<mask id="22031000" name="Fixed mask 13 mm">
				<width unit="mm">9.00</width>
			</mask>
			<divergenceSlit id="22120001" name="Divergence slit 1°" xsi:type="fixedDivergenceSlitType">
				<distanceToSample unit="mm">50.00</distanceToSample>
				<height unit="mm">1.52</height>
			</divergenceSlit>
		</incidentBeamPath>
		<beamKnife id="29030100" name="Beam knife low"/>
		<sampleMovement xsi:type="spinningSampleMovementType">
			<spinnerRevolutionTime unit="seconds">1.0</spinnerRevolutionTime>
		</sampleMovement>
		<diffractedBeamPath>
			<radius unit="mm">145.00</radius>
			<antiScatterSlit id="22090040" name="AS slit 9 mm" xsi:type="fixedAntiScatterSlitType">
				<height unit="mm">9.00</height>
			</antiScatterSlit>
			<sollerSlit id="21020003" name="Large Soller slits 0.04 rad.">
				<opening unit="rad">0.0400</opening>
			</sollerSlit>
			<filter id="20030001" name="Large beta-filter Nickel">
				<material>Ni</material>
				<thickness unit="mm">0.020</thickness>
			</filter>
			<detector id="7010019" name="PIXcel1D-Medipix3 detector" xsi:type="rtmsDetectorType">
				<phd unit="keV">
					<lowerLevel>4.0</lowerLevel>
					<upperLevel>11.3</upperLevel>
				</phd>
				<mode>Scanning</mode>
				<activeLength unit="deg">5.020</activeLength>
			</detector>
		</diffractedBeamPath>
		<scan appendNumber="0" mode="Continuous" scanAxis="Gonio" status="Completed">
			<header>
				<startTimeStamp>2024-03-24T15:55:03-07:00</startTimeStamp>
				<endTimeStamp>2024-03-24T16:07:31-07:00</endTimeStamp>
				<author>
					<name>AutomatedUser</name>
				</author>
				<source>
					<applicationSoftware version="1.6 (94)">PANalytical Aeris Instrument Suite</applicationSoftware>
					<instrumentControlSoftware version="3.0.0 20211014">AERIS</instrumentControlSoftware>
					<instrumentID>2879380</instrumentID>
				</source>
			</header>
			<dataPoints>
				<positions axis="2Theta" unit="deg">
					<startPosition>9.99043322</startPosition>
					<endPosition>100.09495370</endPosition>
				</positions>
				<positions axis="Omega" unit="deg">
					<startPosition>4.99521661</startPosition>
					<endPosition>50.04747685</endPosition>
				</positions>
				<commonCountingTime unit="seconds">18.249</commonCountingTime>
				<counts unit="counts">5665 5338 5404 5437 5373 5431 5416 5333 5397 5357 5451 5423 5351 5276 5400 5400 5428 5264 5376 5467 5252 5278 5383 5311 5309 5488 5311 5253 5386 5280 5401 5182 5219 5228 5336 5282 5413 5264 5258 5290 5347 5186 5262 5257 5240 5320 5310 5255 5208 5154 5268 5187 5294 5370 5203 5315 5231 5065 5197 5197 5231 5144 5293 5184 5174 5161 5165 5167 5215 5183 5267 5206 5252 5259 5129 5194 5116 5110 5050 5226 5205 5113 5154 5053 5112 5140 5173 5130 5077 5051 5206 5038 5024 5211 5090 5137 5105 4930 5048 5083 5060 5002 5082 4945 5074 5034 5206 5161 5096 5035 5058 5052 5039 5100 5077 5055 5086 5036 5078 5062 5029 5050 4856 5035 5033 4943 5064 5001 5003 5070 4905 5020 4995 5015 4955 4940 5004 5031 5121 4938 5074 4940 5002 4923 5042 5019 4938 4915 4939 5000 5045 4891 5042 5016 4955 4955 5057 4900 4879 4860 5004 4925 4961 4862 5054 5016 4878 4905 4779 5012 4887 4847 4927 4897 4742 4978 4846 4751 4964 4872 4965 4876 4969 4891 4860 5006 4930 4946 4886 5002 4910 4816 5078 4855 4982 4981 4871 5022 4845 5003 4919 4798 4742 4872 4801 4817 4924 4824 4938 4779 4802 4799 4771 4952 4783 4882 4791 4807 4854 4967 4915 4922 4772 4817 4857 4788 4827 4590 4798 4831 4946 4766 4848 4955 4832 4799 4817 4807 4793 4844 4845 4996 4765 4754 4897 4857 4742 4799 4763 4860 4868 4711 4675 4893 4806 4818 4914 4710 4748 4858 4868 4864 4819 4797 4663 4760 4742 4747 4592 4650 4776 4694 4669 4777 4713 4805 4724 4645 4775 4758 4741 4757 4673 4626 4624 4783 4810 4732 4744 4860 4910 4695 4800 4804 4645 4781 4627 4805 4746 4712 4706 4729 4852 4792 4631 4898 4680 4758 4637 4727 4699 4864 4690 4633 4750 4707 4610 4753 4806 4723 4731 4818 4612 4681 4625 4792 4690 4829 4762 4738 4689 4632 4756 4662 4623 4736 4701 4608 4674 4716 4585 4672 4637 4752 4728 4728 4691 4693 4652 4744 4702 4655 4717 4828 4640 4769 4629 4700 4687 4735 4647 4743 4753 4717 4787 4662 4627 4734 4754 4665 4728 4652 4670 4738 4661 4673 4759 4709 4635 4679 4712 4635 4707 4715 4620 4701 4627 4582 4553 4716 4620 4571 4771 4659 4644 4787 4683 4779 4692 4744 4585 4749 4733 4716 4708 4666 4636 4770 4650 4810 4798 4650 4713 4833 4772 4723 4688 4682 4747 4679 4847 4714 4758 4782 4808 4715 4811 4641 4678 4749 4681 4819 4761 4870 4717 4790 4846 4864 5015 4863 4897 5006 5063 4933 5108 5220 5065 5299 5150 5474 5390 5486 5720 5745 5862 6007 6165 6157 6173 6413 6318 6280 6127 6002 5796 5671 5590 5404 5172 4980 4953 4919 4880 4715 4831 4632 4639 4629 4747 4751 4766 4734 4639 4668 4748 4557 4793 4716 4683 4733 4671 4626 4600 4637 4626 4702 4663 4722 4670 4742 4697 4661 4645 4724 4534 4683 4683 4537 4635 4748 4607 4699 4772 4669 4637 4786 4744 4745 4748 4757 4689 4749 4664 4583 4668 4780 4691 4743 4735 4730 4828 4546 4706 4749 4754 4719 4756 4706 4652 4699 4764 4725 4781 4631 4714 4783 4663 4764 4622 4592 4718 4689 4750 4799 4715 4643 4696 4679 4586 4654 4754 4756 4612 4807 4667 4711 4668 4643 4647 4708 4690 4643 4778 4716 4673 4659 4608 4580 4663 4626 4790 4662 4714 4716 4614 4756 4638 4707 4793 4538 4755 4751 4761 4902 4755 4808 4621 4767 4767 4642 4749 4742 4949 4694 4696 4772 4797 4637 4550 4716 4679 4651 4817 4693 4644 4637 4745 4749 4635 4719 4658 4751 4757 4673 4661 4680 4778 4693 4714 4696 4455 4694 4723 4748 4673 4686 4643 4749 4699 4752 4676 4803 4669 4684 4696 4645 4668 4626 4609 4704 4790 4691 4765 4689 4790 4758 4713 4669 4598 4769 4670 4773 4790 4827 4652 4716 4771 4673 4818 4725 4713 4738 4811 4787 4784 4608 4780 4733 4694 4722 4625 4744 4764 4733 4776 4727 4669 4716 4658 4734 4706 4744 4750 4695 4685 4820 4563 4632 4807 4909 4775 4767 4855 4714 4756 4908 4646 4853 4807 4895 4763 4694 4802 4761 4846 4765 4724 4757 4872 4851 4841 4867 4814 4841 4829 4806 4978 4931 4831 4787 4911 4887 4882 5000 4929 5060 4996 4908 5013 4982 5185 5088 5191 5149 5159 5382 5378 5501 5775 5818 6018 6224 6408 6785 7051 7631 8028 8673 9350 10105 10988 11598 12449 13056 13876 14590 15045 14922 14583 13811 12901 11739 10808 9421 8251 7180 6419 6051 5492 5253 5257 5017 4925 5156 4801 4886 4796 4942 4768 4841 4847 4954 4752 4789 4928 4868 4882 4830 4790 4830 4895 4862 4720 4795 4768 4855 4828 4762 4790 4656 4783 4721 4716 4769 4785 4884 4812 4747 4751 4616 4823 4834 4764 4779 4697 4840 4737 4720 4729 4728 4799 4631 4683 4701 4797 4774 4930 4788 4744 4854 4727 4832 4753 4965 4695 4626 4764 4686 4686 4788 4723 4791 4710 4672 4756 4737 4787 4791 4748 4701 4863 4678 4724 4775 4744 4722 4692 4652 4792 4661 4770 4667 4646 4729 4631 4693 4630 4623 4726 4675 4657 4846 4718 4797 4658 4751 4729 4701 4724 4698 4833 4812 4750 4670 4567 4677 4634 4736 4676 4772 4751 4774 4628 4662 4735 4762 4681 4687 4774 4788 4723 4639 4704 4659 4767 4642 4594 4586 4839 4783 4777 4527 4767 4686 4591 4706 4794 4825 4693 4590 4662 4684 4706 4536 4612 4651 4687 4675 4773 4754 4640 4696 4793 4808 4619 4698 4726 4854 4635 4763 4804 4857 4793 4772 4836 4647 4736 4689 4657 4651 4564 4802 4818 4739 4750 4761 4658 4750 4603 4837 4774 4698 4776 4775 4702 4707 4640 4750 4812 4801 4770 4755 4771 4773 4927 4997 4643 4775 4710 4728 4721 4708 4840 4699 4800 4955 4830 4941 4932 4818 4908 4866 4808 4921 4945 4879 4951 4883 4883 4947 4895 5014 5048 5008 5070 5208 5221 5368 5216 5500 5565 5753 5779 5938 6099 6170 6595 6909 7063 7444 7719 8350 8731 9362 10075 10801 11588 12275 12918 13938 14768 15390 16226 16643 16772 16476 15779 15030 13889 12507 11391 10187 9064 8018 7030 6551 6126 5703 5557 5296 5233 5283 5136 5150 5029 4981 5060 5014 4958 4957 4922 4854 4996 4962 4865 4841 4908 4943 4955 4962 5102 4924 4950 4994 4924 5038 5154 5137 5085 5210 5300 5130 5399 5321 5307 5386 5120 5063 5199 5151 4859 4976 4864 4766 4712 4670 4705 4566 4634 4568 4747 4640 4687 4723 4649 4661 4674 4633 4680 4729 4607 4564 4788 4533 4644 4635 4471 4547 4666 4521 4590 4641 4724 4636 4587 4539 4577 4625 4609 4725 4625 4542 4526 4713 4762 4712 4623 4689 4500 4728 4730 4646 4624 4612 4671 4708 4611 4611 4647 4659 4656 4540 4580 4694 4652 4671 4750 4485 4554 4596 4550 4725 4553 4483 4548 4551 4583 4656 4626 4537 4485 4586 4592 4644 4691 4606 4726 4611 4612 4510 4548 4742 4638 4672 4609 4644 4629 4423 4585 4475 4753 4588 4699 4588 4681 4586 4718 4690 4881 4588 4666 4686 4664 4786 4719 4776 4888 4797 4981 4978 5039 5100 5118 5258 5230 5433 5625 5568 5801 5893 6154 6389 6373 6576 6585 6590 6672 6529 6606 6450 6305 6114 6036 5938 5952 5622 5348 5212 4937 5084 5186 4977 4902 4751 4923 4783 4908 4883 5015 4817 4780 5093 5201 5278 5259 5175 5554 5529 5762 5861 6152 6224 6377 6729 6879 6919 6984 6845 6661 6569 6314 5977 5903 5365 5417 5154 4999 4941 4809 4862 4734 4682 4657 4503 4499 4548 4626 4547 4551 4620 4533 4633 4526 4517 4512 4514 4439 4526 4494 4473 4558 4527 4593 4501 4564 4552 4452 4465 4477 4604 4452 4491 4497 4495 4444 4421 4505 4361 4478 4476 4552 4463 4381 4393 4417 4455 4585 4465 4370 4534 4560 4513 4503 4432 4479 4509 4291 4356 4436 4600 4426 4559 4500 4568 4474 4425 4545 4452 4406 4510 4520 4538 4527 4460 4533 4456 4416 4469 4562 4516 4552 4505 4402 4453 4555 4439 4427 4544 4552 4598 4423 4494 4557 4479 4626 4538 4642 4474 4558 4596 4457 4461 4564 4535 4507 4480 4587 4561 4575 4556 4651 4673 4601 4798 4766 4781 4748 4783 4803 4845 4941 4948 5004 5043 5307 5175 5433 5617 5713 6031 6122 6785 6934 7338 7772 8236 8778 9599 10104 10814 11547 12356 13247 13737 14021 13967 13849 13134 12177 11581 10295 9691 8733 8400 7200 6664 6063 5847 5528 5219 5102 5008 5058 4873 5020 4881 4915 4946 4906 4919 4805 4725 4890 4907 4964 4901 4872 5015 4860 4920 4852 4856 4934 4821 4851 4751 4615 4587 4576 4536 4484 4467 4498 4458 4512 4478 4502 4475 4541 4435 4631 4595 4501 4406 4545 4489 4425 4471 4480 4422 4422 4371 4371 4472 4491 4510 4501 4437 4362 4473 4415 4414 4488 4409 4504 4286 4514 4358 4366 4413 4426 4423 4435 4390 4387 4467 4397 4314 4344 4304 4349 4366 4257 4391 4379 4348 4380 4444 4388 4474 4338 4333 4324 4380 4458 4482 4384 4422 4374 4352 4384 4538 4502 4484 4498 4481 4399 4406 4457 4448 4413 4479 4410 4350 4455 4342 4516 4420 4519 4408 4515 4513 4501 4431 4602 4555 4526 4698 4444 4620 4868 4826 4762 4888 5018 4852 4980 4909 5075 4955 4911 4972 4933 4819 4695 4704 4564 4671 4712 4586 4502 4521 4596 4633 4491 4644 4571 4553 4471 4637 4460 4609 4585 4653 4670 4731 4756 4752 4944 4834 4951 4987 4987 4786 4990 4965 4937 4871 4919 4850 4927 4699 4775 4630 4516 4590 4434 4419 4410 4486 4378 4432 4392 4511 4475 4450 4377 4474 4431 4369 4336 4294 4349 4348 4274 4352 4396 4466 4370 4262 4203 4363 4394 4394 4239 4334 4316 4438 4350 4263 4410 4276 4442 4308 4392 4303 4316 4385 4257 4361 4320 4309 4296 4437 4388 4353 4304 4371 4366 4452 4346 4337 4335 4493 4406 4426 4392 4424 4323 4360 4457 4444 4491 4431 4448 4481 4461 4361 4428 4446 4463 4363 4283 4446 4453 4580 4565 4480 4521 4359 4593 4508 4519 4738 4553 4645 4750 4721 4680 4662 4822 4864 5008 5225 5394 5463 5616 5714 5939 6094 6367 6620 6778 6917 7194 7408 7728 7742 7669 7632 7386 7359 7083 6860 6811 6898 6771 6630 6535 6491 6600 6352 6429 6631 6640 6659 6472 6387 6316 6372 6217 6275 6018 5954 5948 5852 5793 6126 6228 6102 6276 6389 6563 6800 6991 7061 7329 7503 7556 7518 7575 7668 7473 7460 7289 7071 7152 6718 6447 6306 6191 5732 5819 5595 5582 5495 5244 5157 5044 5145 5114 4894 4962 4819 4896 4823 4802 5005 4864 4822 4936 4811 4903 4874 4849 5066 5013 4981 5011 5115 5056 5212 5206 5292 5451 5521 5682 5775 5943 6061 6426 6676 7038 7486 7689 8132 8816 9433 10251 11109 12030 13403 14412 15598 16811 17565 18382 19051 19572 19676 20182 20485 20609 20160 19130 18191 17417 16696 16148 15628 15617 15777 15860 16357 16910 17791 18713 19899 21127 22450 23908 24423 25156 24511 23358 22477 21761 21168 20950 20486 20181 19362 18660 18100 17736 17059 16641 15942 15598 14885 14237 13525 12730 12063 11258 10633 9905 9071 8601 8036 7578 7119 6734 6354 6097 6026 5941 5722 5732 5503 5312 5351 5242 5308 5129 5065 5189 5075 4995 5061 5022 5140 5045 4895 5007 4886 4960 4856 4758 4791 4801 4890 4757 4801 4762 4844 4726 4741 4776 4783 4720 4842 4857 5010 4874 4925 4821 4935 4927 4959 4870 5014 5037 5029 4850 5012 5006 5119 5204 5230 5192 5280 5326 5334 5538 5490 5875 5640 6058 5931 6131 6323 6754 6867 7167 7605 8019 8151 8613 9429 9890 10321 11142 11669 12676 13109 13672 14452 15305 16141 16563 17036 17064 17355 17285 17479 17006 17077 16673 15931 15223 14436 13555 12939 12088 11393 10776 10025 9212 8735 8020 7575 7376 7096 6678 6566 6315 6133 6014 5902 5797 5654 5555 5404 5395 5413 5481 5285 5225 5169 5290 5074 5313 5165 5248 5133 5386 5259 5266 5511 5471 5270 5394 5635 5666 5699 5755 5919 6045 6018 6364 6466 6581 6811 7073 7062 7386 7575 7751 7744 7612 7853 7824 7697 7742 7715 7408 7237 7205 6760 6537 6414 6281 6025 5944 5817 5676 5313 5205 5187 5136 5010 4906 4759 4823 4769 4649 4688 4723 4659 4615 4820 4582 4750 4541 4585 4608 4735 4575 4577 4541 4515 4585 4462 4595 4490 4476 4404 4607 4519 4400 4351 4593 4589 4558 4520 4562 4625 4527 4555 4715 4724 4591 4615 4722 4796 4931 4973 4958 4932 5180 5253 5299 5591 5777 5830 5851 6109 6075 6334 6228 6278 6307 6105 6037 5773 5691 5521 5466 5300 5240 5234 5089 4885 4769 4687 4781 4659 4536 4532 4563 4602 4650 4707 4676 4685 4611 4540 4729 4597 4667 4574 4640 4737 4740 4625 4856 4533 4787 4821 4780 4797 4772 4878 5117 4870 5050 5073 5106 5164 5312 5417 5497 5794 5823 6130 6365 6475 6848 7135 7265 7753 7945 8220 8513 8658 8708 8826 8762 8712 8575 8617 8222 8033 7882 7690 7334 7080 6930 6696 6681 6415 6361 6238 6227 6288 6271 6412 6474 6714 7016 7448 7723 8271 8819 9167 10017 10755 11634 12819 13816 14743 15669 16474 16414 16482 15282 14291 13220 12358 11692 11304 10711 10258 9598 8583 7895 7053 6389 6018 5807 5732 5565 5480 5569 5547 5459 5461 5300 5403 5487 5283 5377 5330 5287 5319 5463 5389 5396 5399 5537 5473 5589 5665 5628 5550 5688 5688 5712 5782 5832 6017 5964 6120 6126 6229 6382 6431 6520 6677 6849 6839 6965 7360 7554 7677 7875 8320 8470 8862 9214 9822 10173 10952 11323 12244 12927 13792 14946 15659 17107 18510 19803 21124 22989 24760 26113 27810 29535 31181 32499 33733 35222 35999 36654 37972 38695 38828 39337 39185 39439 39261 38503 37771 36449 34941 33418 31659 30317 28428 26511 24996 23061 21877 20086 18719 17330 15852 14869 13803 12831 11745 11387 10589 10260 9713 9426 8908 8636 8282 8185 7910 7603 7611 7295 7386 7248 7136 7354 7403 7379 7409 7610 7675 7893 8078 8405 8369 8579 8702 8804 8794 8483 8280 7848 7527 7224 7141 6969 6799 6655 6373 6250 5951 5673 5445 5198 5385 5223 5163 5026 5285 4959 5011 5043 5060 4904 5006 5088 4961 4905 5061 4871 4951 4886 4802 4999 4919 4816 4833 4856 4828 4801 4910 4947 4926 4742 4874 4753 4977 4964 5068 5038 5036 5068 5102 4963 5205 5104 5198 5307 5166 5564 5636 5542 5820 5986 6158 6255 6515 6893 7307 7722 8005 8188 8867 9103 9406 9776 10086 10223 10091 9764 9817 9540 9246 8800 8627 8292 7976 7593 7375 7088 6750 6617 6157 5931 5813 5660 5582 5450 5438 5430 5467 5350 5316 5465 5530 5561 5702 5779 5797 5775 5759 5825 5679 5762 5760 5577 5608 5471 5447 5453 5232 5275 5310 5158 5230 5117 5119 5171 5167 5057 5092 5050 5033 5113 5167 5079 5171 5060 5080 5078 4900 5032 5133 5060 5080 4983 5048 4941 5040 5184 5017 5121 5193 5133 5187 5153 5223 5085 5133 5180 5221 5262 5328 5312 5373 5261 5417 5294 5496 5487 5627 5622 5613 5642 5686 5710 5720 5776 5833 5747 5955 6023 5954 6061 6109 6154 6269 6432 6444 6588 6567 6653 6874 7067 6999 7205 7334 7601 7580 7750 7944 8209 8210 8418 8836 9053 9270 9694 9899 10436 10621 10935 11507 11944 12527 12978 13818 14265 15085 15730 16646 17600 18328 19455 20855 21552 22874 24073 25477 27478 28249 29458 30786 32077 33145 34339 35076 35851 36019 36611 36413 36177 36241 35428 34934 34027 33213 31985 31403 30081 29103 28153 27080 26239 25257 24252 23515 22799 21820 21519 20813 20276 19711 19135 18639 18286 17795 17085 16501 15857 15182 14675 14099 13636 12856 12142 11513 11093 10625 10181 9742 9322 8914 8569 8385 8091 7591 7434 7380 7115 7114 6706 6641 6724 6295 6270 6158 6103 6061 6039 6132 5923 5959 6012 6074 6004 6005 6074 6296 6286 6495 6602 6787 6833 7165 7164 7360 7354 7339 7279 7546 7200 7085 6903 6785 6664 6424 6471 6219 6237 5877 5877 5644 5614 5508 5332 5217 5364 5229 5283 5326 5325 5634 5489 5578 5761 6020 6085 6317 6270 6398 6270 6281 6265 6077 5925 5687 5674 5585 5521 5599 5402 5332 5122 5119 5042 4745 4823 4794 4719 4624 4637 4621 4560 4602 4566 4455 4544 4576 4501 4559 4575 4558 4580 4522 4508 4522 4505 4513 4505 4709 4495 4612 4586 4560 4527 4572 4559 4593 4699 4802 4584 4701 4724 4916 4769 4880 5105 5168 5236 5466 5436 5627 5846 6288 6427 6952 7235 7706 8228 8586 9323 10098 10810 11666 12007 12660 12686 12767 12509 11763 11352 10680 9991 9599 9385 9041 9109 8512 7941 7640 7199 6435 5984 5683 5359 5094 4968 4839 4772 4766 4720 4618 4609 4534 4660 4556 4519 4389 4421 4448 4458 4451 4266 4325 4259 4386 4275 4207 4231 4168 4325 4267 4259 4227 4194 4245 4167 4280 4221 4312 4319 4217 4251 4204 4244 4223 4316 4263 4112 4255 4103 4141 4050 4006 4105 4262 4122 4180 4045 4201 4078 4189 4174 4124 4115 4240 4210 4202 4240 4201 4179 4143 4247 4075 4174 4189 4172 4196 4113 4207 4087 4048 4144 4124 4206 4186 4171 4119 4247 4201 4159 4098 4105 4130 4081 4138 4170 4084 4111 3987 4114 4051 4208 4120 4181 4086 4105 4098 3905 4034 4105 4088 4197 4002 4135 4001 4072 4021 4114 4095 4032 4118 4168 4130 4105 4078 4184 4090 4092 4054 3977 4033 4121 4101 4158 4102 4050 4024 3920 4089 3915 4088 4057 4130 4053 4195 4200 4128 4129 4082 4228 4066 4176 4130 4233 4294 4415 4403 4400 4386 4545 4354 4505 4513 4520 4564 4567 4659 4509 4400 4445 4404 4429 4370 4268 4272 4342 4264 4253 4249 4136 4270 4136 4072 4090 4172 4052 4098 4107 4088 4073 4026 4150 4199 4014 4021 4066 4023 3950 4113 4058 3993 3948 4100 4035 4048 4122 4082 4065 4046 4046 4121 4155 4085 4166 4142 4086 4172 4240 4218 4178 4141 4339 4317 4336 4546 4749 4619 4668 4872 5026 5102 5051 5191 5157 5239 5173 5050 5025 4961 4764 4773 4570 4695 4610 4648 4644 4470 4539 4230 4300 4346 4135 4110 4097 3999 4015 4001 4023 4046 4097 3999 4017 4024 4090 3949 4031 3973 4028 3969 4019 4082 3970 4122 4200 3932 4020 3920 4053 4076 4067 4045 4078 4068 4066 4011 4047 4025 3941 4131 4141 4064 3923 3984 4004 4016 4164 4089 4167 4026 4140 4072 4079 4176 4056 3979 4032 4184 4134 4094 4264 4288 4274 4232 4365 4445 4509 4614 4632 4910 5014 5055 5323 5558 5811 5858 6229 6251 6375 6622 6811 6822 7037 6996 7310 7494 7779 7768 7960 7656 7567 7387 7090 6620 6371 6127 5922 5825 5721 5679 5608 5417 5267 5119 4830 4705 4464 4466 4350 4302 4248 4236 4271 4385 4259 4223 4293 4160 4216 4171 4225 4162 4239 4194 4167 4227 4327 4150 4238 4168 4255 4258 4205 4128 4106 4197 4212 4194 4099 4066 4139 4135 4022 4109 4114 4016 4059 4034 4102 4090 3944 4085 4121 4023 4072 4099 4065 4006 4036 3901 4125 3932 4085 4050 3903 4012 3914 4039 3995 4045 4074 4049 4078 4142 4082 4181 4266 4298 4458 4467 4435 4626 4628 4755 4836 4742 4780 4692 4537 4700 4564 4515 4446 4559 4503 4449 4524 4416 4438 4356 4349 4392 4260 4389 4376 4297 4464 4382 4566 4522 4783 4895 4828 4925 5185 5411 5500 5741 5878 6057 6387 6338 6646 6802 6627 6694 6641 6460 6463 6465 6176 6225 6063 6119 6003 5917 6043 5868 5765 5569 5378 5417 5215 5101 5147 4907 4886 4757 4872 4747 4769 4731 4761 4542 4580 4557 4500 4335 4328 4345 4323 4314 4227 4151 4235 4132 4259 4254 4125 4153 4158 4070 4127 4198 4011 4075 4062 4136 4039 4131 4141 4127 4145 4169 4051 4237 4120 4100 4279 4293 4276 4263 4490 4521 4628 4926 4858 4852 4808 5031 5156 5226 5039 4993 4790 4676 4690 4637 4656 4659 4542 4631 4550 4455 4467 4450 4225 4299 4045 4378 4098 4103 4035 4021 4103 4019 3962 3941 3989 3875 4092 4176 3940 3963 4040 4026 4024 3988 4085 4060 4041 4072 4057 3999 4194 4110 4173 4173 4326 4279 4119 4441 4321 4346 4317 4334 4476 4616 4533 4353 4497 4440 4583 4453 4592 4638 4626 4657 4932 4820 5046 5334 5233 5294 5451 5800 5626 5885 5897 5971 5919 5899 5687 5408 5313 5204 5207 5299 5163 5075 5135 5236 4966 4886 4731 4740 4608 4391 4402 4496 4461 4462 4355 4399 4379 4420 4336 4225 4449 4355 4299 4392 4300 4557 4254 4363 4331 4292 4391 4437 4403 4489 4373 4304 4407 4525 4552 4481 4528 4554 4587 4640 4785 4820 4867 4963 4910 5137 5130 5202 5254 5561 5597 5677 5981 6309 6472 6633 6835 7231 7502 7804 8053 8081 8209 8365 8335 8657 9077 9443 9673 9955 10690 11000 11490 12053 12402 12555 12619 13139 13318 13595 14082 14132 14298 14328 14090 14371 14123 13867 13577 12919 12780 12571 12151 11935 11446 11083 10780 10379 9970 9580 9138 8843 8415 8048 7881 7521 7405 6992 6785 6502 6470 6280 6153 6074 5842 5611 5652 5366 5654 5387 5238 5341 5194 5022 5016 5013 4913 4769 4727 4710 4712 4694 4651 4712 4526 4618 4666 4420 4349 4357 4357 4322 4247 4342 4367 4218 4281 4445 4321 4308 4279 4298 4239 4108 4217 4239 4152 4229 4188 4294 4121 4053 4321 4136 4049 4084 4114 4038 4090 4116 4254 4216 4077 4170 4263 4208 4113 4109 4194 4112 4036 4106 4116 4224 4019 4109 4250 4146 4137 4140 4189 4174 4250 4187 4169 4098 4213 4054 4211 4134 4107 4148 4124 4168 4121 4207 4230 4069 4267 4279 4224 4181 4214 4185 4234 4242 4340 4264 4411 4290 4358 4349 4277 4296 4229 4299 4330 4313 4333 4255 4180 4248 4239 4185 4243 4157 4228 4110 4083 4024 4050 4056 3922 4066 3919 3946 3938 3906 3938 3932 3957 3968 3850 3916 3901 3990 3947 3992 4073 3873 3841 3881 3869 3941 3866 3899 3840 3814 3778 3890 3876 3919 3925 3830 3902 3962 3927 3865 3901 3959 3981 3909 3922 3958 4088 3906 3955 4034 4038 3887 4035 4038 3949 3903 3988 4024 4055 4036 4064 4052 4235 4037 4074 4198 4054 4037 4324 4171 4210 4395 4347 4519 4433 4549 4556 4679 4667 4532 4633 4514 4550 4591 4396 4368 4419 4337 4290 4240 4521 4390 4211 4286 4253 4172 4006 4274 4066 3953 4024 3927 3973 4092 3861 4074 3971 4028 3879 3984 3927 3899 3813 3860 3831 3833 3876 4029 3876 3801 3919 3891 3888 3830 3959 3847 3831 3888 3830 3700 3787 3915 3725 3912 3853 3880 3785 3876 3863 3753 3871 3903 3848 3784 3855 3871 3857 3819 3919 3756 3843 3882 3956 3883 3798 3807 3862 3953 3910 3944 3879 3907 3836 3770 3913 3876 3898 3894 3836 3865 3997 4082 3942 4056 3995 3979 4017 4122 3995 4239 4130 4252 4254 4262 4282 4426 4593 4480 4751 4840 4925 4755 4971 4904 4921 4986 4928 4934 5008 4984 5207 5216 5200 5351 5259 5406 5368 5216 5289 5173 5095 5014 5011 4785 4661 4729 4577 4643 4499 4605 4527 4586 4472 4426 4361 4389 4243 4244 4268 4274 4204 4352 4187 4339 4153 4315 4266 4332 4309 4372 4432 4366 4504 4446 4546 4485 4495 4642 4537 4549 4660 4695 4695 4727 4871 4938 5021 5062 5128 5056 5060 5321 5153 5180 5360 5342 5472 5366 5666 5751 5493 5816 5708 5747 5759 5651 5745 5807 5857 5642 5791 5780 5800 5677 5630 5545 5681 5460 5417 5318 5261 5278 5398 5079 5070 4985 4845 4835 4841 4829 4671 4629 4495 4523 4486 4440 4436 4537 4389 4343 4379 4118 4304 4162 4183 4209 4145 4196 4157 4116 4078 4025 4089 4089 4041 3930 4025 3913 3946 4037 4037 3908 4117 4110 4092 4054 4163 4168 4039 4191 4182 4241 4291 4351 4175 4283 4289 4348 4312 4228 4375 4344 4231 4314 4290 4243 4228 4199 4208 4065 4140 4071 4108 4070 4007 4040 4044 4084 4114 4015 3858 3906 3901 3893 3795 3902 3808 3819 3786 3986 3794 4038 3755 3888 3816 3709 3714 3769 3786 3684 3858 3753 3808 3755 3742 3732 3761 3723 3719 3700 3759 3734 3865 3781 3835 3789 3831 3831 3718 3760 3783 3695 3787 3795 3865 3806 3815 3875 3825 3778 3822 3822 3920 3857 3778 3840 4090 3868 3884 4111 3960 4228 4168 4312 4394 4472 4655 4632 4653 4660 4838 4686 4795 4794 4552 4529 4531 4342 4375 4267 4324 4241 4334 4392 4407 4327 4263 4274 4181 3973 4042 4021 3989 3910 3819 3830 3810 3854 3750 3724 3773 3826 3788 3981 3767 3882 3747 3819 3795 3737 3875 3656 3714 3774 3709 3829 3812 3812 3716 3756 3875 3774 3836 3862 3801 3723 3893 3768 3732 3819 3835 3821 3794 3845 3780 3904 4024 4027 4015 4082 4090 4110 4052 3973 4037 3942 3990 4027 4012 3997 3925 3897 4031 4000 3939 3993 3907 3948 4091 4011 3912 3853 3958 3889 3951 4022 3793 3885 3808 4030 3925 3964 3880 3841 3946 3910 3898 3776 3959 3890 3878 3866 3882 3968 3896 3965 3921 3977 3901 4026 3945 3994 3968 4057 4083 4151 4037 4069 4260 4274 4327 4461 4384 4478 4553 4571 4728 4660 4755 4791 4851 4734 4678 4809 4705 4716 4840 4975 5100 5166 5545 5873 6205 6525 6598 6834 6880 7329 7606 7868 8184 9040 9210 9439 9519 9169 8265 7913 7055 6476 6422 6147 6016 6099 6296 6425 6505 6602 6516 6239 5926 5600 5215 4950 4586 4453 4353 4315 4178 4133 4132 4173 4042 4035 4058 4074 4172 3871 4044 4187 4057 4046 3950 3999 4149 4009 4038 4103 4176 4131 4084 4093 4174 4144 4158 4160 4270 4301 4440 4466 4517 4512 4656 4778 4801 4817 4879 4953 4908 5034 4995 4987 5056 5010 4870 5011 4889 4915 4927 4929 4915 4931 5034 5105 4993 5126 5062 5034 5054 5128 5150 5265 5284 5346 5428 5625 5634 5821 5911 5846 6041 6041 6350 6371 6552 6775 6847 6988 7050 7205 7273 7682 7718 7529 7931 7769 7853 7863 7778 7805 7805 7843 7752 7755 7681 7849 7689 7627 7501 7405 7352 7265 7125 7093 6830 6924 6621 6544 6430 6257 6222 6001 5985 5839 5793 5745 5654 5474 5479 5344 5330 5330 5082 5230 5043 4943 4981 4987 4865 4851 4875 4776 4729 4771 4822 4730 4674 4762 4634 4718 4730 4745 4616 4654 4716 4843 4775 4871 4666 4838 4841 4885 4865 4732 4783 4741 4673 4695 4587 4638 4680 4574 4466 4557 4473 4446 4488 4331 4415 4214 4358 4391 4421 4266 4234 4268 4296 4192 4088 4160 4094 4129 4117 4060 3982 3939 4025 3982 3989 3943 4226 4004 3986 4093 4077 4005 4191 4153 4032 3961 4210 4276 4109 4115 4131 4186 4216 4220 4382 4450 4368 4387 4445 4674 4554 4741 4670 4711 4733 4768 4833 4739 4790 4817 4624 4583 4720 4715 4675 4664 4614 4477 4489 4644 4445 4375 4470 4414 4437 4299 4299 4265 4236 4337 4314 4291 4234 4184 4136 4084 4063 4005 4086 4086 4064 3907 3949 3935 3911 3897 3892 3988 4049 3903 3893 3914 3868 3871 3969 3945 3882 3808 3897 3803 3931 3741 3820 3821 3801 3821 3869 3826 3856 3938 3929 3978 4043 4027 4158 4053 4125 4169 4180 4293 4274 4243 4237 4241 4384 4288 4239 4223 4267 4295 4313 4370 4345 4470 4464 4380 4533 4495 4675 4713 4719 4862 4832 4754 4784 4806 5035 5054 5150 4919 5238 5226 5192 5159 5152 5024 5004 4801 4908 4894 4803 4878 4750 4808 5013 4991 5050 5063 5167 4933 4944 4804 4891 5007 4859 4947 4865 4892 4961 4917 4980 4912 5154 5109 5159 5203 5036 5387 5256 5484 5417 5463 5758 5900 6013 6114 6150 6499 6606 6740 6823 7011 7108 7210 7401 7625 7911 8069 8230 8181 8584 8751 8708 9019 9006 8876 8989 9003 8887 8733 8672 8457 8384 8288 8083 7907 8155 7643 7677 7679 7403 7210 7033 6824 6593 6721 6559 6292 6158 5920 5779 5709 5480 5428 5253 5097 5060 5089 4939 4832 4738 4693 4695 4477 4558 4505 4459 4490 4373 4430 4242 4309 4143 4165 4101 4248 4066 4040 4158 4064 3949 4008 4083 4030 4068 4043 3754 3978 3980 3927 3929 3838 3936 3806 3890 3981 3871 3867 3774 3874 3858 3927 3858 3843 3777 3741 3840 3853 3880 3909 3852 3891 3822 3850 3845 3870 3965 3967 3914 3931 4161 4100 4186 4210 4283 4437 4324 4398 4400 4398 4498 4241 4275 4358 4230 4167 4017 4131 4094 4112 4047 4130 4113 4177 4225 4192 4227 4089 4082 4085 4074 4126 3949 3962 3969 3993 4099 4037 4005 3940 3983 3985 3892 3795 3959 4098 3995 3764 3971 3864 4058 3974 4011 4118 4064 4093 4017 3965 3945 3944 4132 4134 4173 4119 4272 4252 4185 4309 4323 4260 4354 4298 4110 4359 4145 4217 4135 4206 4200 4217 4114 4233 4302 4222 4501 4242 4296 4284 4170 4266 4191 4144 4149 4122 4158 4158 4162 4174 4013 4043 4066 4087 4029 3992 3904 3983 3885 3936 3932 3889 3914 3916 3812 3900 3887 3810 3867 3845 3787 3568 3738 3811 3749 3760 3711 3810 3777 3773 3803 3678 3664 3823 3734 3742 3667 3714 3904 3812 3830 3820 3732 3737 3915 3744 3766 3877 3803 3728 3891 3840 3814 3831 3830 3831 3965 3782 3744 3820 3567 3752 3796 3716 3802 3787 3864 3724 3725 3693 3788 3764 3872 3853 3862 3904 3938 3968 3930 3862 3933 4030 3805 3948 3900 3866 3826 3802 3864 3925 3833 3835 3922 3977 3984 3881 3811 3762 3856 3969 3918 4004 4003 3947 4050 3893 3983 4085 4071 3908 4028 3929 4111 3863 3963 4112 4019 3926 4020 3994 3973 3947 4005 4045 4149 3995 4084 3925 4029 4117 4066 4060 4170 3998 4205 4043 4167 4113 4038 4111 4183 4323 4102 4135 4213 4425 4327 4263 4427 4432 4462 4595 4722 4692 4794 4753 5014 4979 5034 5102 5214 5372 5467 5298 5429 5509 5334 5438 5393 5421 5598 5462 5505 5650 5634 5695 5614 5745 5780 5944 5883 6038 6034 6059 5939 6118 6218 6160 6273 6223 6211 6336 6575 6409 6307 6455 6595 6462 6364 6487 6566 6476 6546 6521 6379 6572 6415 6514 6476 6564 6557 6291 6417 6393 6430 6343 6392 6314 6300 6368 6283 6351 6357 6408 6498 6549 6644 6608 6753 6798 6979 6947 7201 7228 7309 7527 7672 7668 7649 7731 7834 7906 7974 7648 7807 7604 7533 7765 7708 7533 7309 7267 7171 7152 7114 7099 7036 6947 6750 6645 6427 6395 6245 6309 6115 6152 5887 5773 5701 5664 5485 5504 5343 5232 5173 5118 5025 4902 4854 4821 4864 4783 4661 4634 4480 4532 4477 4492 4405 4433 4425 4438 4441 4386 4281 4200 4276 4186 4347 4185 4203 4104 4140 4216 4134 4102 4044 4159 4082 4139 4175 4173 4077 4207 3994 4221 4055 4133 4106 4196 4114 4172 4226 4195 4240 4065 4205 4173 4153 4179 4077 4092 4004 4298 4194 4252 4123 4270 4224 4203 4302 4322 4258 4287 4380 4370 4281 4365 4449 4466 4445 4605 4383 4510 4471 4384 4448 4580 4642 4532 4749 4578 4764 4811 4905 4832 5045 4961 5109 5245 5030 5131 5278 5276 5390 5472 5420 5546 5635 5801 5796 5898 5844 5999 6050 6193 6102 6468 6479 6618 6507 6657 6863 6820 6831 6919 7104 7184 7317 7357 7507 7542 7422 7684 7520 7817 7834 7711 7722 7838 7883 7706 7627 7522 7549 7407 7224 7392 7226 6905 6756 6745 6753 6345 6418 6423 6168 6206 6113 5921 5755 5864 5528 5528 5317 5298 5093 5006 5093 4972 4883 4788 4693 4517 4653 4449 4345 4379 4348 4193 4246 4175 4190 4177 4154 4138 3989 4031 4088 3977 3877 3917 4058 4019 3916 3887 3926 3935 3865 3900 3847 3809 3877 3763 3846 3872 3696 3741 3857 4004 3932 3832 3903 3884 3874 3817 3950 3890 3979 3916 4093 4117 4008 4069 4076 4038 4017 3817 3851 3748 3928 3807 3916 3924 3823 3952 3849 3886 4037 3826 4027 4019 4090 4000 4071 4225 4117 4343 4301 4329 4329 4324 4378 4421 4481 4337 4363 4363 4454 4230 4279 4178 4164 4150 4220 4183 4248 4238 4181 4152 4188 4200 4172 4178 4220 4188 3903 4006 3898 3976 3846 3857 3941 3816 3907 3733 3766 3721 3810 3819 3811 3985 3905 3762 3758 3802 3747 3740 3696 3708 3772 3692 3689 3700 3741 3796 3803 3829 3750 3936 3760 3791 3728 3766 3763 3767 3759 3811 3715 3672 3658 3654 3732 3612 3686 3640 3768 3673 3685 3692 3615 3673 3696 3681 3733 3642 3785 3649 3738 3611 3695 3637 3622 3665 3790 3695 3634 3612 3667 3553 3744 3718 3765 3719 3829 3745 3813 3714 3774 3836 3929 3932 3934 3777 3852 3688 3729 3764 3664 3680 3700 3729 3663 3616 3700 3686 3692 3695 3699 3759 3754 3691 3513 3601 3622 3609 3659 3491 3562 3500 3595 3467 3575 3526 3572 3471 3495 3537 3470 3489 3487 3529 3439 3470 3552 3511 3421 3443 3495 3577 3532 3526 3559 3394 3468 3536 3408 3617 3503 3440 3613 3470 3665 3495 3548 3437 3427 3425 3451 3528 3438 3442 3476 3468 3481 3426 3484 3546 3494 3509 3480 3573 3572 3632 3537 3524 3544 3576 3560 3526 3567 3517 3557 3526 3520 3383 3649 3633 3519 3555 3667 3660 3510 3578 3731 3597 3576 3624 3689 3705 3677 3813 3703 3747 3668 3737 3654 3751 3888 3829 3815 3744 3733 3721 3769 3738 3835 3724 3796 3789 3846 3848 3764 3830 3736 3883 3920 3881 3871 3925 3804 3839 3886 3937 3938 3893 4090 3928 4026 4052 4161 4079 4217 4062 4053 4190 4281 4131 4135 4293 4363 4544 4406 4523 4446 4436 4621 4711 4820 4753 4847 4777 4950 4840 4876 4856 4920 4868 5002 4720 4876 4854 4853 4713 4829 4658 4751 4648 4575 4770 4524 4677 4607 4604 4535 4533 4446 4402 4404 4514 4304 4342 4349 4344 4310 4292 4315 4238 4217 4269 4072 4064 4058 4088 4074 4111 4169 4027 3963 4048 4047 4063 3995 3834 3799 3889 3816 3906 3765 3924 3866 3756 3747 3740 3849 3832 3837 3664 3784 3725 3661 3710 3594 3667 3691 3652 3686 3574 3487 3579 3590 3529 3525 3533 3631 3595 3567 3696 3593 3722 3468 3611 3529 3709 3581 3441 3543 3443 3531 3505 3584 3478 3494 3586 3578 3635 3581 3445 3678 3605 3592 3578 3554 3583 3553 3704 3747 3620 3592 3675 3664 3590 3691 3715 3645 3801 3735 3705 3712 3755 3678 3582 3665 3652 3712 3742 3826 3701 3748 3791 3752 3796 3856 3873 3858 3815 3893 3958 3830 4019 3920 3868 3751 3807 3783 3805 3730 3716 3665 3618 3891 3711 3741 3615 3630 3692 3733 3668 3771 3621 3679 3672 3749 3736 3603 3517 3660 3568 3604 3633 3526 3722 3771 3593 3761 3589 3642 3681 3714 3597 3666 3624 3740 3725 3735 3698 3751 3640 3782 3754 3792 3771 3832 3824 3801 3815 3870 3932 3848 3898 3967 3916 3999 3933 3889 3897 4044 4092 4082 4141 4048 4105 4326 4338 4413 4382 4493 4441 4554 4619 4730 4815 4947 5124 5116 5122 5328 5258 5308 5412 5613 5609 5667 5568 5656 5488 5610 5503 5482 5456 5323 5462 5315 5346 5408 5473 5408 5461 5506 5604 5547 5492 5428 5532 5463 5526 5350 5393 5331 5255 5267 5238 5179 4977 4901 4970 4855 4799 4809 4880 4725 4828 4659 4495 4584 4545 4557 4580 4333 4442 4323 4288 4172 4232 4261 4193 4169 4121 4057 4042 3876 3885 4011 4001 3872 3783 3942 3827 3688 3706 3750 3806 3744 3667 3666 3669 3677 3632 3632 3549 3626 3644 3589 3581 3553 3560 3677 3576 3510 3572 3543 3478 3470 3482 3580 3485 3603 3581 3450 3363 3491 3488 3457 3592 3523 3493 3424 3489 3472 3440 3380 3496 3420 3519 3388 3498 3580 3493 3511 3488 3413 3391 3498 3503 3449 3501 3409 3500 3431 3469 3487 3392 3588 3445 3671 3514 3563 3643 3674 3583 3701 3698 3551 3689 3745 3765 3799 3741 3989 3754 3807 3786 3684 3748 3645 3602 3708 3523 3651 3672 3620 3684 3600 3632 3587 3552 3655 3619 3641 3532 3650 3647 3526 3552 3607 3564 3463 3569 3503 3463 3386 3421 3484 3466 3401 3394 3405 3386 3432 3399 3336 3313 3476 3500 3419 3438 3441 3469 3511 3501 3561 3496 3445 3360 3572 3478 3422 3411 3524 3516 3522 3486 3455 3563 3456 3539 3353 3559 3561 3463 3477 3447 3495 3428 3530 3420 3407 3484 3453 3416 3547 3568 3511 3359 3446 3430 3415 3416 3393 3473 3422 3356 3429 3390 3353 3333 3484 3444 3432 3527 3413 3290 3377 3461 3339 3411 3305 3392 3306 3302 3351 3345 3330 3307 3419 3412 3425 3271 3381 3344 3401 3389 3369 3392 3332 3362 3339 3404 3377 3227 3344 3363 3475 3355 3362 3483 3382 3324 3406 3277 3449 3487 3282 3446 3407 3428 3336 3465 3449 3490 3546 3521 3576 3474 3554 3501 3530 3526 3650 3427 3455 3482 3480 3450 3425 3372 3327 3423 3444 3356 3441 3357 3345 3389 3457 3492 3414 3388 3373 3365 3460 3433 3426 3435 3291 3253 3384 3331 3370 3387 3388 3375 3378 3426 3477 3438 3289 3315 3405 3331 3307 3455 3363 3408 3366 3429 3415 3386 3457 3388 3474 3405 3473 3375 3564 3551 3565 3542 3532 3814 3732 3544 3665 3577 3734 3657 3791 3700 3681 3795 3771 3667 3653 3664 3660 3581 3483 3416 3420 3521 3452 3527 3479 3482 3392 3571 3482 3555 3703 3661 3583 3519 3641 3445 3494 3470 3484 3537 3501 3399 3557 3487 3369 3429 3559 3417 3303 3449 3472 3445 3294 3403 3304 3319 3306 3326 3406 3481 3537 3477 3444 3387 3369 3449 3402 3434 3289 3553 3302 3440 3388 3281 3339 3442 3389 3477 3427 3421 3524 3499 3435 3381 3433 3429 3400 3496 3463 3435 3437 3482 3435 3445 3524 3472 3490 3520 3543 3495 3637 3617 3528 3652 3648 3686 3695 3739 3718 3787 3861 3793 3767 3885 3875 3807 3740 3828 3786 3804 3834 3732 3857 3821 3917 3769 3724 3785 3836 3828 3766 3814 3803 3615 3775 3660 3696 3715 3722 3673 3641 3707 3680 3543 3532 3635 3586 3523 3531 3559 3436 3586 3531 3539 3539 3562 3403 3534 3515 3486 3432 3503 3591 3352 3423 3543 3340 3473 3387 3481 3493 3444 3391 3459 3564 3500 3375 3335 3463 3524 3461 3365 3402 3453 3420 3331 3483 3273 3443 3366 3433 3494 3312 3557 3576 3466 3452 3519 3432 3428 3510 3496 3475 3477 3558 3588 3503 3422 3538 3498 3346 3543 3483 3490 3507 3542 3618 3552 3606 3555 3611 3553 3586 3479 3569 3577 3435 3538 3421 3559 3479 3382 3616 3328 3389 3431 3424 3562 3411 3502 3492 3468 3500 3544 3386 3471 3498 3425 3486 3527 3412 3415 3554 3542 3497 3404 3437 3500 3627 3504 3571 3361 3432 3546 3452 3473 3594 3466 3486 3513 3483 3495 3449 3454 3519 3501 3560 3563 3532 3570 3555 3569 3544 3515 3605 3496 3609 3570 3635 3722 3612 3687 3616 3585 3691 3740 3750 3671 3801 3745 3766 3824 3667 3957 3874 4049 3914 3969 3967 3932 4040 4029 4080 4226 4138 4030 4136 4171 4246 4232 4284 4208 4150 4188 4310 4223 4188 4320 4203 4118 4124 4263 4110 4083 4107 4102 4162 4223 4156 4132 4170 4201 4364 4136 4147 4111 4237 4111 4120 4189 3998 4096 4149 4026 4052 4173 4081 4182 4146 4110 4058 4191 4067 4090 4118 4125 4102 4009 4025 4066 4126 4144 4155 4068 4175 4095 4136 4118 4187 4095 4205 4204 4091 4173 4037 3968 4124 4100 4116 4122 4203 4074 3981 4089 4040 4026 4045 3979 3994 3960 3963 4032 4151 4028 4045 4221 4104 4147 4127 4136 3918 4123 3914 4009 4018 3976 3999 4102 4127 4128 4108 4086 4170 4214 4131 4126 4160 4016 4026 4116 4046 3993 4088 3909 4168 3946 3922 4063 3875 3972 4054 4003 3863 3946 3892 3955 3974 3792 3846 3921 3924 3897 3992 3761 3867 3849 3809 3884 3874 3947 3822 3742 3712 3695 3714 3711 3620 3683 3662 3616 3722 3692 3641 3441 3617 3541 3673 3536 3480 3589 3545 3632 3507 3501 3531 3508 3619 3566 3306 3397 3407 3377 3424 3420 3434 3345 3349 3400 3420 3395 3504 3385 3306 3283 3425 3450 3420 3385 3438 3288 3445 3322 3380 3431 3154 3332 3448 3227 3386 3305 3295 3356 3362 3200 3334 3350 3414 3294 3325 3380 3188 3382 3436 3254 3414 3254 3334 3299 3439 3352 3372 3400 3427 3351 3327 3380 3475 3544 3395 3513 3401 3311 3477 3372 3478 3424 3412 3459 3376 3372 3475 3578 3314 3479 3363 3364 3306 3356 3290 3434 3375 3391 3370 3291 3370 3420 3356 3385 3340 3362 3398 3332 3392 3327 3370 3397 3360 3324 3311 3478 3294 3393 3408 3321 3433 3362 3372 3422 3382 3334 3387 3498 3298 3313 3372 3326 3265 3189 3316 3301 3435 3378 3272 3377 3296 3390 3378 3316 3302 3253 3213 3305 3378 3407 3314 3260 3368 3366 3379 3308 3233 3213 3271 3310 3311 3253 3438 3315 3335 3305 3285 3218 3335 3328 3298 3374 3325 3412 3407 3290 3316 3464 3385 3378 3580 3517 3362 3560 3548 3528 3541 3579 3588 3601 3568 3486 3653 3638 3625 3658 3621 3758 3665 3621 3570 3535 3632 3618 3676 3709 3634 3613 3531 3596 3614 3540 3553 3643 3563 3674 3580 3642 3647 3674 3585 3627 3664 3699 3654 3626 3597 3626 3614 3551 3640 3438 3561 3562 3647 3452 3553 3574 3536 3531 3522 3482 3527 3564 3522 3549 3564 3572 3567 3492 3497 3409 3649 3430 3452 3496 3548 3514 3512 3624 3390 3622 3363 3528 3500 3522 3407 3504 3458 3519 3527 3413 3461 3375 3462 3424 3567 3446 3409 3404 3378 3370 3414 3482 3348 3439 3377 3406 3275 3406 3461 3351 3390 3407 3350 3421 3438 3315 3388 3380 3333 3329 3373 3277 3305 3340 3425 3392 3404 3524 3402 3426 3378 3451 3454 3373 3378 3376 3389 3353 3277 3318 3442 3434 3352 3337 3399 3405 3365 3340 3457 3419 3398 3437 3568 3511 3520 3665 3577 3532 3519 3508 3429 3355 3425 3369 3419 3434 3305 3390 3301 3230 3351 3428 3430 3378 3448 3352 3409 3339 3312 3429 3497 3313 3425 3322 3399 3332 3503 3315 3257 3316 3272 3421 3320 3272 3356 3352 3277 3354 3325 3365 3245 3357 3364 3248 3340 3257 3398 3328 3306 3294 3381 3369 3323 3409 3304 3363 3310 3255 3308 3328 3288 3322 3375 3252 3323 3340 3275 3390 3400 3429 3396 3277 3366 3335 3337 3369 3396 3365 3389 3231 3366 3356 3421 3342 3345 3350 3375 3334 3488 3366 3450 3389 3397 3343 3477 3449 3404 3340 3375 3368 3444 3414 3367 3465 3433 3463 3441 3386 3436 3520 3399 3391 3372 3389 3456 3476 3334 3416 3492 3530 3509 3508 3537 3439 3575 3410 3455 3506 3564 3664 3441 3418 3554 3499 3466 3534 3556 3545 3448 3599 3563 3491 3568 3504 3610 3615 3684 3625 3667 3621 3548 3745 3596 3835 3686 3658 3706 3817 3714 3693 3791 3839 3754 3694 3797 3774 3775 3823 3864 3815 3814 3771 3697 3929 3845 3904 3870 3984 3840 3900 3921 3851 4017 3848 3879 3760 3850 3884 3861 3888 3878 3784 3915 3922 3931 3901 3893 3983 3836 3952 3886 3881 3925 3808 3819 3866 3804 3758 3902 3825 3875 3673 3806 3836 3797 3758 3640 3679 3621 3610 3662 3636 3544 3654 3555 3468 3415 3537 3594 3560 3626 3611 3545 3556 3509 3456 3580 3571 3519 3481 3462 3476 3569 3538 3365 3452 3318 3408 3427 3468 3417 3435 3432 3366 3413 3407 3434 3332 3538 3436 3361 3474 3472 3332 3366 3251 3434 3348 3400 3333 3356 3353 3419 3355 3356 3262 3309 3289 3293 3370 3252 3253 3364 3335 3102 3319 3412 3433 3366 3276 3386 3355 3313 3359 3355 3345 3339 3377 3373 3191 3302 3275 3283 3294 3356 3454 3292 3273 3392 3342 3415 3424 3380 3426 3395 3385 3322 3428 3338 3320 3381 3391 3501 3363 3380 3462 3513 3433 3430 3497 3474 3463 3304 3366 3338 3488 3394 3401 3448 3388 3365 3405 3535 3411 3414 3464 3558 3475 3541 3493 3441 3448 3444 3476 3494 3420 3524 3520 3552 3401 3458 3544 3410 3518 3421 3478 3510 3535 3425 3462 3460 3504 3334 3611 3370 3429 3482 3522 3407 3485 3435 3551 3401 3377 3347 3560 3422 3437 3477 3424 3527 3489 3502 3610 3605 3560 3715 3605 3712 3673 3627 3743 3515 3625 3553 3613 3640 3507 3534 3596 3579 3561 3614 3496 3495 3490 3518 3595 3586 3485 3596 3525 3572 3634 3413 3564 3562 3598 3431 3527 3422 3506 3589 3535 3428 3418 3490 3449 3485 3513 3498 3555 3433 3507 3471 3479 3481 3401 3420 3480 3343 3400 3353 3385 3388 3470 3340 3327 3362 3316 3308 3257 3191 3209 3317 3226 3272 3283 3296 3259 3250 3294 3297 3312 3346 3351 3286 3329 3293 3223 3214 3380 3315 3353 3387 3316 3408 3362 3299 3368 3367 3221 3481 3379 3439 3480 3375 3388 3403 3403 3425 3403 3440 3393 3368 3443 3325 3259 3429 3372 3296 3282 3413 3349 3292 3415 3301 3271 3294 3264 3297 3294 3402 3218 3345 3266 3318 3336 3303 3286 3208 3245 3392 3188 3223 3284 3275 3283 3194 3316 3324 3285 3258 3197 3229 3195 3250 3187 3213 3222 3186 3247 3177 3270 3171 3197 3278 3199 3195 3102 3227 3303 3195 3144 3173 3294 3176 3193 3159 3144 3211 3103 3263 3172 3253 3238 3200 3245 3255 3228 3234 3291 3336 3279 3248 3170 3264 3101 3233 3272 3201 3202 3173 3187 3110 3153 3072 3111 3290 3209 3046 3228 3254 3291 3217 3251 3252 3249 3303 3142 3242 3390 3173 3196 3213 3285 3211 3230 3215 3299 3220 3303 3332 3400 3486 3448 3417 3459 3494 3369 3357 3423 3418 3370 3497 3461 3348 3516 3447 3510 3424 3543 3481 3408 3404 3323 3347 3389 3353 3303 3352 3332 3442 3322 3380 3452 3464 3414 3424 3499 3256 3409 3414 3401 3298 3418 3309 3317 3372 3398 3293 3282 3482 3443 3397 3338 3242 3367 3310 3349 3383 3327 3337 3315 3322 3348 3353 3357 3453 3369 3309 3490 3440 3403 3570 3434 3421 3339 3450 3426 3502 3398 3432 3415 3387 3342 3380 3435 3449 3440 3439 3377 3357 3395 3379 3452 3417 3345 3386 3402 3419 3333 3475 3503 3425 3441 3460 3406 3329 3293 3426 3364 3326 3258 3276 3339 3376 3403 3366 3286 3335 3280 3297 3335 3338 3363 3241 3272 3335 3324 3283 3198 3199 3276 3289 3269 3145 3377 3280 3228 3326 3330 3257 3286 3378 3374 3276 3294 3330 3365 3268 3419 3337 3380 3372 3364 3300 3285 3236 3385 3366 3359 3302 3350 3248 3431 3360 3363 3367 3288 3233 3343 3262 3341 3308 3411 3366 3341 3398 3361 3296 3317 3448 3350 3487 3297 3403 3465 3487 3468 3606 3478 3513 3490 3677 3528 3491 3643 3467 3477 3435 3602 3511 3456 3405 3559 3466 3449 3503 3297 3363 3374 3485 3432 3448 3327 3429 3312 3335 3403 3381 3442 3367 3340 3386 3370 3379 3259 3461 3267 3396 3318 3484 3406 3429 3404 3423 3403 3378 3255 3355 3337 3355 3376 3357 3282 3334 3368 3198 3293 3295 3323 3270 3352 3218 3231 3221 3399 3231 3299 3239 3248 3301 3379 3333 3331 3291 3256 3265 3175 3315 3331 3379 3426 3360 3189 3243 3312 3203 3325 3303 3284 3306 3264 3284 3286 3305 3372 3348 3257 3295 3345 3319 3314 3267 3218 3282 3205 3239 3277 3390 3399 3339 3404 3346 3407 3358 3348 3371 3418 3285 3352 3477 3352 3359 3468 3282 3444 3447 3455 3365 3411 3370 3411 3365 3395 3431 3464 3384 3362 3516 3453 3584 3459 3398 3356 3403 3506 3595 3580 3510 3534 3643 3646 3457 3607 3642 3565 3558 3510 3660 3652 3552 3641 3654 3586 3660 3609 3691 3707 3566 3648 3606 3683 3558 3603 3643 3687 3612 3634 3772 3709 3673 3680 3555 3705 3565 3744 3661 3640 3473 3728 3639 3504 3499 3538 3652 3634 3584 3512 3521 3543 3644 3604 3557 3705 3580 3766 3686 3599 3474 3647 3615 3522 3657 3602 3643 3591 3588 3749 3795 3601 3483 3611 3642 3617 3712 3601 3612 3754 3637 3732 3593 3699 3558 3616 3743 3589 3768 3631 3642 3670 3568 3604 3655 3582 3606 3631 3760 3711 3672 3682 3722 3582 3635 3663 3611 3650 3802 3673 3580 3813 3742 3707 3777 3704 3693 3750 3745 3638 3689 3753 3715 3675 3698 3631 3703 3642 3662 3569 3688 3798 3656 3827 3696 3668 3701 3701 3762 3754 3822 3802 3779 3807 3694 3734 3708 3615 3782 3706 3511 3727 3631 3750 3557 3667 3579 3578 3504 3450 3700 3577 3647 3551 3646 3638 3608 3503 3454 3624 3541 3547 3493</counts>
			</dataPoints>
		</scan>
	</xrdMeasurement>
</xrdMeasurements>