File: dataset/precursor_mixture/Li2CO3_Li2TiO3_Y2O3_In2O3.12-min.xrdml
<?xml version="1.0"?>
<xrdMeasurements xmlns="http://www.xrdml.com/XRDMeasurement/2.2" xmlns:xsi="http://www.w3.org/2001/XMLSchema-instance" xsi:schemaLocation="http://www.xrdml.com/XRDMeasurement/2.2 http://www.xrdml.com/XRDMeasurement/2.2/XRDMeasurement.xsd" status="Completed" recordIdentifier="{A39E5B95-E86D-496F-90C8-499EC135AF5A}">
	<comment>
		<entry/>
	</comment>
	<sample type="To be analyzed">
		<id></id>
		<name></name>
		<preparedBy></preparedBy>
	</sample>
	<xrdMeasurement measurementType="Scan" status="Completed" sampleMode="Reflection">
		<usedWavelength intended="K-Alpha 1">
			<kAlpha1 unit="Angstrom">1.5405980</kAlpha1>
			<kAlpha2 unit="Angstrom">1.5444260</kAlpha2>
			<kBeta unit="Angstrom">1.3922500</kBeta>
			<ratioKAlpha2KAlpha1>0.5000</ratioKAlpha2KAlpha1>
		</usedWavelength>
		<incidentBeamPath>
			<radius unit="mm">145.00</radius>
			<xRayTube id="1010048" name="Empyrean Cu LFF HR (9430 033 7310x) DK437873">
				<tension unit="kV">40.0</tension>
				<current unit="mA">15.0</current>
				<anodeMaterial>Cu</anodeMaterial>
				<focus type="Line">
					<length unit="mm">12.0</length>
					<width unit="mm">0.4</width>
					<takeOffAngle unit="deg">6.0</takeOffAngle>
				</focus>
			</xRayTube>
			<filter id="20010004" name="Beta-filter Nickel">
				<material>Ni</material>
				<thickness unit="mm">0.020</thickness>
			</filter>
			<sollerSlit id="21010002" name="Soller slits 0.04 rad.">
				<opening unit="rad">0.0400</opening>
			</sollerSlit>
			<mask id="22031000" name="Fixed mask 13 mm">
				<width unit="mm">9.00</width>
			</mask>
			<divergenceSlit id="22120001" name="Divergence slit 1°" xsi:type="fixedDivergenceSlitType">
				<distanceToSample unit="mm">50.00</distanceToSample>
				<height unit="mm">1.52</height>
			</divergenceSlit>
		</incidentBeamPath>
		<beamKnife id="29030100" name="Beam knife low"/>
		<sampleMovement xsi:type="spinningSampleMovementType">
			<spinnerRevolutionTime unit="seconds">1.0</spinnerRevolutionTime>
		</sampleMovement>
		<diffractedBeamPath>
			<radius unit="mm">145.00</radius>
			<antiScatterSlit id="22090040" name="AS slit 9 mm" xsi:type="fixedAntiScatterSlitType">
				<height unit="mm">9.00</height>
			</antiScatterSlit>
			<sollerSlit id="21020003" name="Large Soller slits 0.04 rad.">
				<opening unit="rad">0.0400</opening>
			</sollerSlit>
			<filter id="20030001" name="Large beta-filter Nickel">
				<material>Ni</material>
				<thickness unit="mm">0.020</thickness>
			</filter>
			<detector id="7010019" name="PIXcel1D-Medipix3 detector" xsi:type="rtmsDetectorType">
				<phd unit="keV">
					<lowerLevel>4.0</lowerLevel>
					<upperLevel>11.3</upperLevel>
				</phd>
				<mode>Scanning</mode>
				<activeLength unit="deg">5.020</activeLength>
			</detector>
		</diffractedBeamPath>
		<scan appendNumber="0" mode="Continuous" scanAxis="Gonio" status="Completed">
			<header>
				<startTimeStamp>2024-03-22T22:34:28-07:00</startTimeStamp>
				<endTimeStamp>2024-03-22T22:46:56-07:00</endTimeStamp>
				<author>
					<name>Instrument</name>
				</author>
				<source>
					<applicationSoftware version="1.6 (94)">PANalytical Aeris Instrument Suite</applicationSoftware>
					<instrumentControlSoftware version="3.0.0 20211014">AERIS</instrumentControlSoftware>
					<instrumentID>2879380</instrumentID>
				</source>
			</header>
			<dataPoints>
				<positions axis="2Theta" unit="deg">
					<startPosition>9.99043322</startPosition>
					<endPosition>100.09495370</endPosition>
				</positions>
				<positions axis="Omega" unit="deg">
					<startPosition>4.99521661</startPosition>
					<endPosition>50.04747685</endPosition>
				</positions>
				<commonCountingTime unit="seconds">18.249</commonCountingTime>
				<counts unit="counts">4198 4162 4216 4187 4161 4119 4083 4159 4093 4196 4101 4239 4185 4125 4091 4170 4105 4094 4080 4134 4091 4239 4018 4059 4112 4141 4054 4012 4100 4178 4013 3969 4188 4141 4105 4055 4011 4046 4045 3942 4059 4010 4116 4080 3943 4041 3931 3888 3894 3859 3940 3943 4033 3939 3926 3830 3901 3990 3970 4028 3858 3885 3981 3906 3764 3929 3875 3776 3827 3984 3824 3969 3902 3970 3844 3902 3912 3810 3900 3880 3771 3951 3883 4012 3845 3954 3821 3841 3832 3739 3877 3795 3818 3804 3754 3907 3656 3796 3782 3743 3782 3790 3830 3748 3798 3706 3654 3792 3746 3766 3668 3619 3676 3688 3785 3771 3759 3744 3757 3668 3627 3599 3632 3692 3643 3762 3675 3572 3564 3648 3621 3576 3640 3734 3601 3699 3576 3626 3563 3672 3615 3519 3604 3557 3590 3606 3491 3556 3615 3536 3538 3714 3551 3585 3517 3545 3633 3550 3541 3533 3635 3434 3499 3525 3410 3587 3354 3476 3567 3403 3416 3440 3434 3335 3458 3545 3364 3432 3485 3371 3446 3383 3433 3459 3443 3411 3343 3417 3438 3339 3482 3407 3399 3403 3464 3371 3414 3347 3313 3440 3339 3411 3395 3371 3281 3271 3412 3177 3345 3334 3309 3349 3271 3298 3378 3316 3433 3391 3214 3344 3322 3410 3267 3300 3259 3495 3321 3248 3292 3243 3279 3229 3215 3278 3222 3264 3224 3259 3350 3168 3218 3123 3255 3282 3206 3183 3168 3215 3129 3314 3241 3300 3233 3358 3255 3156 3222 3232 3179 3123 3120 3203 3110 3253 3286 3101 3168 3257 3258 3176 3210 3101 3222 3134 3094 3238 3188 3151 3095 3173 3051 3070 3156 3061 3247 3140 3074 3125 3121 3095 3126 3111 3063 3173 3073 3139 3102 3120 3204 3143 3123 3026 3155 3081 3034 3024 3088 3144 3064 3009 3049 2932 3058 3019 3060 2976 3044 2914 3020 3039 3003 2952 3011 3105 3016 2952 2986 2968 2915 3127 2947 3031 2983 2980 3014 2955 3002 3004 3072 3088 3033 2992 2846 2952 3076 3130 2955 3053 3018 3039 3091 2861 3013 2857 2975 3019 3123 2944 3042 3011 2978 3004 3004 2961 3023 2962 2890 2992 2927 3002 2958 2896 3014 2943 3100 2982 3002 2981 2926 2884 2995 2991 2880 2913 2957 2914 2966 2937 2917 3037 2996 3065 3068 3026 2854 3007 3014 3009 3085 2896 3039 3001 2944 3010 2935 3003 2880 2929 2949 3050 3112 2999 3056 3049 3025 2998 2960 3000 3003 2960 2981 2888 2977 2923 2946 3002 2935 2991 2945 2944 2835 2862 2978 2960 3048 2921 2969 2988 2863 2852 2886 2928 2944 2989 2879 2965 3002 2838 2927 2877 2936 2945 2967 3046 2910 2966 2884 2858 2976 2834 2951 2899 2959 2989 2913 2927 2943 2853 2752 2878 2890 2868 2915 2929 2929 2867 2853 2876 2912 2881 2734 2944 2860 2948 2900 2924 2797 2891 2870 2879 2877 2916 2894 2896 2892 2836 2829 2742 2859 3020 2865 2741 2874 2818 2864 2886 2747 2830 2803 2902 2825 2799 2812 2779 2713 2851 2781 2894 2797 2896 2960 2840 2846 2870 2896 2808 2827 2838 2794 2786 2836 2824 2889 2805 2868 2756 2780 2731 2823 2817 2852 2860 2853 2892 2830 2796 2827 2852 2843 2755 2840 2747 2790 2751 2837 2838 2770 2847 2811 2781 2871 2710 2792 2859 2780 2765 2693 2792 2783 2816 2793 2688 2822 2732 2799 2699 2774 2701 2700 2788 2842 2756 2841 2776 2857 2730 2793 2673 2727 2906 2759 2733 2916 2856 2829 2745 2816 2871 2784 2758 2837 2819 2847 2883 2792 2794 2880 2777 2813 2865 2746 2876 2746 2857 2830 2858 2765 2850 2853 2831 2853 2858 2838 2765 2885 2748 2836 2871 2836 2719 2846 2817 2750 2912 2833 2821 2729 2837 2835 2643 2763 2723 2776 2768 2738 2644 2814 2800 2817 2794 2729 2709 2790 2713 2694 2751 2763 2658 2744 2795 2818 2836 2703 2765 2677 2659 2807 2770 2634 2701 2706 2821 2714 2739 2647 2779 2671 2650 2774 2862 2736 2618 2834 2750 2775 2877 2837 2809 2815 2871 2877 2833 2808 2801 2841 2864 2792 2810 2871 2807 2714 2752 2695 2749 2786 2795 2695 2684 2785 2691 2684 2709 2772 2611 2723 2745 2574 2778 2751 2670 2768 2718 2704 2710 2650 2733 2688 2702 2783 2660 2768 2723 2746 2785 2766 2802 2821 2683 2745 2789 2772 2810 2782 2717 2825 2720 2661 2690 2770 2740 2740 2791 2790 2886 2743 2819 2821 2932 2768 2802 2863 2884 2817 2956 2883 2865 2965 2965 2966 2739 2970 3117 2951 3054 3118 3027 3093 3096 3067 2964 3049 2967 3054 2997 2894 3029 2937 2966 2875 2879 2969 2754 2886 2793 2784 2805 2793 2778 2678 2730 2766 2729 2678 2668 2658 2628 2664 2658 2629 2763 2743 2732 2702 2633 2576 2584 2661 2708 2765 2607 2554 2588 2697 2639 2675 2508 2586 2607 2581 2612 2527 2649 2610 2549 2594 2580 2565 2609 2558 2545 2667 2517 2620 2605 2525 2596 2474 2577 2609 2490 2534 2465 2583 2534 2599 2605 2602 2540 2552 2540 2614 2485 2522 2512 2621 2482 2453 2518 2553 2451 2547 2425 2549 2471 2541 2492 2548 2463 2560 2536 2569 2420 2569 2448 2425 2495 2465 2518 2480 2450 2329 2457 2476 2555 2476 2537 2493 2557 2485 2550 2478 2508 2621 2551 2506 2441 2534 2481 2521 2526 2593 2544 2458 2507 2475 2539 2557 2567 2541 2534 2620 2621 2527 2568 2627 2595 2677 2665 2653 2547 2599 2629 2823 2729 2625 2730 2694 2757 2724 2869 2878 2836 2885 2911 2970 3039 3034 3143 3064 3162 3359 3411 3651 3770 3806 4044 4046 4222 4470 4549 4745 5026 5330 5333 5463 5779 5752 5851 5909 5929 5586 5391 5126 4858 4499 4276 3919 3635 3376 3174 3127 3071 2950 2857 2804 2869 2670 2712 2688 2630 2607 2617 2649 2594 2614 2572 2693 2554 2550 2480 2631 2619 2442 2689 2513 2525 2590 2485 2552 2464 2491 2559 2686 2528 2631 2587 2577 2639 2563 2636 2599 2640 2678 2726 2689 2743 2829 2934 2934 2996 2919 3113 3217 3370 3523 3475 3726 3871 4118 4129 4384 4632 4998 5272 5320 5518 5595 5515 5434 5654 5569 5709 5751 5702 5875 6158 6572 6817 7255 7106 7061 6752 6327 5897 5326 4939 4379 3997 3547 3359 3123 2838 2695 2628 2575 2501 2519 2544 2360 2397 2388 2392 2362 2424 2487 2400 2272 2316 2328 2355 2342 2375 2257 2388 2385 2460 2230 2306 2285 2211 2346 2333 2408 2371 2292 2325 2359 2313 2354 2271 2236 2310 2273 2315 2229 2273 2280 2374 2249 2290 2308 2277 2246 2178 2256 2189 2153 2369 2264 2124 2224 2289 2178 2344 2165 2287 2234 2265 2311 2251 2306 2216 2243 2258 2265 2276 2276 2158 2227 2260 2200 2201 2168 2326 2223 2162 2236 2298 2244 2284 2273 2214 2228 2178 2230 2152 2166 2247 2151 2184 2182 2203 2193 2226 2180 2160 2287 2159 2298 2173 2148 2182 2229 2189 2168 2239 2166 2144 2141 2106 2091 2141 2096 2060 2165 2172 2134 2169 2153 2248 2050 2182 2054 2174 2072 2195 2076 2158 2126 2136 2168 2137 2217 2147 2208 2189 2129 2185 2180 2165 2223 2076 2102 2190 2290 2175 2158 2227 2200 2250 2215 2214 2286 2385 2315 2329 2434 2405 2452 2303 2308 2355 2293 2352 2301 2223 2164 2166 2224 2186 2266 2202 2160 2150 2158 2184 2152 2163 2262 2035 2070 2095 2076 2054 2139 2160 2156 2085 2182 2097 2086 2147 2115 2060 2059 2076 2052 2067 2105 2087 2145 2119 2125 2037 1973 2155 2220 2083 2111 2123 2081 2065 2169 2078 2128 2019 1994 2123 2056 2079 2104 2097 2068 1979 2158 1962 2087 2090 2101 2082 2160 2040 2075 2099 1984 1981 2001 1997 2041 2027 2014 2025 2045 2036 2013 2022 2072 2149 1992 2084 2015 2060 2047 2056 1951 2063 2063 2056 2046 2076 2073 2030 2041 1977 2058 2063 1991 2094 1988 2054 2029 2065 2008 1996 1968 2084 2047 2084 2103 1955 1975 2026 2147 1976 2039 1927 2015 1986 2006 1997 2051 1939 1964 1966 2142 1986 2056 2015 1936 2072 1964 2075 1991 2038 2051 2087 1959 2011 2032 2054 1990 2056 2006 2088 2013 2043 1983 2051 1994 2206 2102 2108 2038 2127 2092 2142 2050 2109 2113 2182 2108 2173 2183 2204 2248 2169 2089 2169 2149 2124 2105 2097 2132 2104 2099 2058 2001 1893 1992 2082 2056 1937 1949 2003 2033 2034 2011 1913 1997 1968 1939 1990 1991 1888 1955 2024 1886 1950 1859 1956 1897 1903 1981 1955 1951 1974 1981 1894 1992 1879 2024 2009 1929 1898 1905 1897 1940 1969 1861 1951 2022 2053 1917 1905 1953 1967 1904 2021 1988 1939 1963 1957 1973 1948 1948 1860 1919 1934 1899 2002 1909 2006 1987 1967 2010 1980 1992 2057 1962 1918 1986 1974 1998 1944 2013 1974 2026 1932 1963 1918 1857 1924 1926 1847 1914 1924 1931 1901 1895 1821 1970 1973 1902 1831 1915 1888 1892 1938 1976 1893 1940 1770 1864 1880 1884 1864 1931 1826 1885 1849 1855 1853 1882 2011 1845 2007 1945 1982 1915 1881 1967 1900 1954 1894 1925 1875 1876 1904 1876 1838 1905 1938 1935 1878 1894 1928 1941 1908 1939 1839 1850 1899 1808 1811 1812 1917 1961 1939 1923 1858 1789 1842 1795 1902 1901 1891 1956 1879 1952 1870 1876 1866 1884 1958 1871 1870 1806 1944 1856 1808 1885 1836 1823 1923 1913 1894 1963 1900 1952 1909 2020 1945 1986 1965 2005 2015 2055 2024 2056 1987 2044 1934 2026 1910 1982 1955 1946 1885 1832 1915 1930 1897 1972 1958 1855 1845 1902 1831 1944 1858 1847 1829 1889 1942 1888 1919 1948 1952 1795 1971 1904 1954 1825 1955 1910 1956 1900 1800 1953 1866 1849 1931 1909 1870 1943 1855 2042 1983 2076 2076 1996 1955 2070 2044 1986 2052 2089 2021 2105 2057 2146 2066 2108 1960 2036 2083 2062 2037 2083 2091 2100 2068 2089 2175 2133 2196 2145 2107 2067 2081 2105 2092 2154 2135 2199 2149 2184 2209 2284 2266 2292 2312 2328 2238 2387 2349 2393 2399 2557 2489 2491 2572 2589 2555 2708 2571 2798 2787 2893 2947 2980 3073 3019 3288 3325 3463 3553 3848 3866 4056 4246 4576 4955 5168 5882 6227 6766 7462 8186 9031 10161 11455 12737 14294 16114 17839 20065 22156 24468 26686 28597 31058 32075 32937 32755 31912 29975 28019 25921 23882 21752 19471 17042 15004 13097 11190 9490 8323 7225 6511 5904 5278 5078 4592 4444 4481 4221 4088 3946 3750 3751 3707 3608 3521 3550 3298 3319 3232 3076 2948 2889 2904 2777 2845 2789 2643 2643 2516 2591 2514 2444 2539 2376 2442 2383 2478 2314 2309 2434 2366 2373 2321 2312 2230 2316 2231 2246 2222 2224 2280 2164 2221 2270 2268 2311 2344 2323 2178 2285 2370 2388 2264 2437 2392 2345 2445 2381 2517 2307 2473 2370 2662 2390 2505 2640 2623 2694 2604 2772 2760 2677 2711 2638 2905 2768 2882 2901 3049 3214 3411 3516 3508 3625 3908 4201 4491 4950 5372 5939 6524 7236 8065 9333 10668 12333 14215 16772 19321 22688 25946 30127 33702 38073 42066 45248 47355 46787 43537 39245 34597 31210 28403 26135 23631 20615 17283 13669 10480 8499 6747 5708 4846 4488 4094 3903 3641 3546 3377 3214 3209 3093 2938 2907 2901 2927 2778 2733 2684 2530 2571 2530 2445 2461 2364 2359 2255 2323 2293 2250 2210 2176 2084 2141 2097 2123 2074 2052 2034 2134 2062 2070 2042 2138 2089 2028 1983 2082 2083 2022 2065 1968 2012 1973 1973 2035 2026 2043 1956 2091 2081 1969 2026 2043 2050 1957 2072 2040 2083 2060 2138 2179 2188 2171 2308 2347 2292 2353 2430 2459 2478 2575 2610 2763 2800 2980 3192 3310 3411 3471 3599 3886 3929 3941 3962 4048 4106 3838 3918 3717 3630 3635 3422 3261 3156 3068 2928 2834 2737 2641 2449 2371 2236 2259 2185 2093 2081 2034 1943 1980 1964 1955 1931 1943 1853 1916 1884 1819 1745 1777 1773 1747 1767 1841 1857 1834 1806 1869 1794 1782 1897 1757 1764 1704 1790 1794 1853 1837 1751 1770 1846 1703 1811 1782 1753 1795 1771 1753 1722 1777 1786 1709 1747 1703 1894 1788 1764 1819 1810 1738 1668 1771 1681 1728 1781 1764 1786 1841 1757 1750 1714 1776 1718 1797 1753 1831 1808 1725 1775 1588 1789 1710 1714 1737 1787 1762 1770 1898 1794 1809 1828 1860 1749 1784 1791 1863 1792 1864 1863 1950 1935 2010 2113 2076 2171 2237 2283 2305 2378 2236 2261 2229 2124 2081 2097 2016 2074 1960 1944 1862 1988 1905 1925 1862 1829 1885 1784 1854 1911 1927 1854 1795 1857 1860 1885 1875 1887 1972 1995 1987 1922 1936 2016 2043 2147 2160 2221 2272 2291 2385 2426 2451 2512 2681 2751 2921 3159 3463 3664 3974 4266 4524 4845 5509 5974 6563 7097 7582 8051 8502 8781 8749 8756 8203 7846 7312 6770 6405 6288 5854 5527 4839 4438 4002 3620 3458 3144 2999 2778 2836 2780 2642 2670 2600 2613 2589 2701 2689 2577 2727 2603 2662 2511 2432 2342 2411 2302 2343 2177 2210 2058 2025 2023 1954 1945 1854 1919 1876 1869 1840 1828 1787 1793 1677 1755 1775 1708 1708 1745 1697 1782 1799 1772 1704 1770 1765 1728 1784 1672 1727 1806 1769 1700 1716 1641 1666 1627 1714 1749 1687 1689 1623 1630 1663 1674 1603 1733 1759 1651 1592 1718 1734 1714 1627 1755 1686 1750 1736 1680 1694 1742 1715 1726 1738 1758 1704 1761 1769 1769 1724 1758 1760 1770 1784 1698 1793 1744 1776 1724 1854 1776 1834 1885 1854 1905 1963 1852 1836 1894 1938 1950 1954 2032 2136 2166 2305 2406 2514 2641 2739 2973 3253 3456 3997 4245 4902 5491 6392 7302 8430 9526 10899 12139 13017 13935 14247 13723 12417 11260 9996 9355 8677 8343 8251 7572 6806 5824 4846 4114 3329 2887 2745 2538 2421 2410 2354 2281 2307 2231 2248 2280 2232 2257 2276 2448 2419 2503 2708 2645 2815 2884 3096 3066 3266 3268 3307 3302 3310 3143 3264 3131 3020 3072 2943 3024 3078 3065 3016 2986 3104 3148 3207 3158 2998 2834 2723 2590 2453 2402 2368 2387 2302 2126 2157 1990 1957 1832 1781 1795 1757 1740 1696 1659 1660 1686 1624 1753 1589 1677 1647 1695 1618 1744 1681 1644 1634 1507 1765 1545 1636 1645 1509 1638 1694 1554 1704 1603 1702 1620 1662 1617 1602 1608 1604 1666 1595 1525 1580 1617 1605 1599 1583 1594 1654 1641 1645 1640 1674 1705 1738 1720 1781 1842 1892 1915 1997 2007 2141 2214 2237 2290 2233 2354 2335 2285 2207 2178 2178 2105 2065 1953 1984 1963 1874 1861 1739 1761 1694 1675 1667 1681 1653 1579 1602 1595 1606 1583 1566 1530 1529 1508 1545 1546 1530 1615 1538 1541 1499 1535 1522 1550 1630 1552 1649 1610 1564 1538 1583 1655 1610 1632 1620 1728 1706 1740 1732 1866 1805 1814 2008 2073 2144 2375 2451 2805 2970 3214 3289 3634 3795 3777 3658 3386 3225 3096 2904 2688 2855 2674 2806 2489 2547 2366 2161 2095 2003 1911 1881 1875 1853 1918 1971 1899 1847 1854 1758 1887 1759 1778 1737 1728 1649 1722 1520 1724 1568 1598 1567 1559 1578 1541 1520 1544 1483 1523 1522 1519 1489 1522 1446 1461 1460 1503 1447 1462 1527 1469 1448 1520 1400 1461 1463 1473 1378 1447 1424 1460 1405 1559 1528 1453 1466 1423 1405 1450 1504 1443 1511 1435 1515 1433 1468 1434 1486 1487 1463 1448 1452 1445 1411 1382 1457 1507 1358 1384 1473 1465 1463 1462 1435 1430 1384 1481 1465 1385 1524 1438 1474 1389 1531 1491 1509 1417 1380 1388 1408 1455 1382 1414 1309 1519 1371 1545 1455 1439 1492 1442 1488 1396 1444 1384 1433 1440 1473 1460 1495 1390 1485 1377 1500 1394 1511 1483 1471 1517 1523 1471 1470 1488 1578 1461 1508 1497 1552 1488 1522 1549 1422 1534 1546 1511 1696 1615 1624 1616 1733 1705 1840 1830 2018 1901 2077 2078 2111 2040 2058 2016 2036 1904 1924 1957 1979 2029 1988 2019 2086 2211 2306 2415 2402 2666 2772 2943 3168 3313 3500 3552 3576 3594 3539 3446 3401 3210 3258 3220 3083 2972 2881 2698 2560 2394 2208 2217 2017 1991 1921 1857 1738 1708 1664 1561 1618 1585 1532 1625 1504 1561 1597 1495 1409 1473 1429 1548 1449 1506 1381 1446 1410 1450 1392 1438 1449 1360 1393 1456 1481 1381 1420 1359 1358 1408 1401 1398 1392 1417 1421 1439 1334 1468 1383 1435 1332 1354 1393 1384 1430 1321 1266 1377 1331 1320 1355 1353 1369 1388 1363 1467 1398 1417 1359 1369 1411 1341 1336 1388 1423 1292 1340 1409 1356 1382 1379 1400 1424 1379 1389 1347 1427 1288 1367 1327 1391 1354 1410 1359 1465 1363 1401 1405 1391 1391 1369 1393 1343 1406 1399 1335 1326 1319 1374 1315 1424 1405 1440 1322 1412 1353 1334 1439 1388 1388 1451 1442 1386 1496 1368 1407 1481 1383 1389 1407 1434 1452 1283 1436 1419 1446 1417 1387 1343 1440 1453 1426 1400 1480 1439 1421 1514 1490 1518 1540 1494 1579 1682 1703 1656 1747 1720 1821 1855 1881 1886 1984 2067 2121 2379 2440 2558 2882 3049 3241 3440 3357 3391 3181 2835 2687 2476 2440 2440 2434 2436 2441 2242 2290 1958 1834 1804 1684 1510 1568 1495 1517 1438 1470 1422 1494 1365 1424 1394 1378 1385 1441 1442 1408 1372 1353 1436 1459 1347 1405 1380 1400 1377 1445 1377 1420 1452 1395 1389 1379 1385 1323 1396 1371 1368 1404 1410 1346 1392 1374 1436 1430 1358 1412 1363 1421 1372 1421 1458 1390 1503 1448 1491 1390 1354 1479 1445 1468 1416 1439 1410 1436 1470 1483 1472 1398 1443 1512 1478 1467 1466 1449 1483 1443 1424 1359 1372 1420 1428 1488 1380 1468 1406 1450 1413 1467 1494 1483 1461 1512 1456 1455 1482 1480 1502 1457 1390 1516 1523 1521 1586 1555 1613 1542 1641 1659 1666 1694 1659 1742 1781 1797 1854 1806 1906 1996 1979 2138 2132 2172 2439 2585 2609 2888 3082 3334 3659 3796 4186 4364 4472 4594 4574 4641 4576 4441 4280 4371 4191 4245 4299 4247 4353 4098 4080 4073 3845 3791 3696 3679 3584 3394 3292 3250 3332 3259 3187 3200 3115 3102 2966 3003 2900 2723 2725 2651 2472 2359 2493 2348 2261 2268 2164 2003 1882 1959 1795 1780 1699 1691 1813 1677 1689 1663 1636 1684 1560 1573 1583 1601 1549 1571 1591 1626 1513 1518 1425 1453 1488 1415 1427 1444 1332 1380 1367 1357 1374 1378 1398 1452 1387 1455 1382 1429 1348 1370 1442 1324 1360 1322 1404 1406 1313 1384 1363 1339 1429 1345 1354 1232 1367 1370 1356 1310 1347 1286 1354 1417 1325 1349 1306 1380 1266 1352 1349 1339 1365 1403 1296 1259 1354 1331 1347 1338 1370 1276 1323 1352 1369 1350 1376 1366 1387 1429 1361 1343 1384 1357 1306 1408 1332 1257 1420 1340 1359 1331 1290 1274 1286 1328 1322 1350 1267 1424 1390 1332 1283 1315 1335 1372 1430 1419 1355 1417 1386 1375 1389 1297 1357 1338 1368 1354 1433 1346 1317 1323 1442 1347 1414 1402 1341 1405 1449 1446 1461 1501 1362 1567 1553 1673 1619 1729 1682 1798 1979 2051 2280 2482 2812 3121 3459 3900 4249 4621 4768 4723 4379 4115 3708 3333 3078 3034 2980 3161 3089 3101 3027 2959 2704 2322 2049 1865 1639 1639 1612 1505 1480 1478 1355 1513 1435 1361 1376 1410 1332 1396 1325 1426 1347 1394 1336 1361 1372 1296 1390 1374 1381 1343 1347 1266 1330 1310 1245 1237 1285 1281 1237 1249 1324 1263 1274 1323 1319 1267 1317 1257 1331 1299 1346 1312 1253 1294 1343 1308 1269 1352 1295 1341 1213 1277 1339 1320 1330 1382 1336 1286 1314 1252 1351 1353 1384 1362 1351 1353 1372 1404 1304 1470 1423 1431 1419 1448 1448 1438 1495 1489 1574 1602 1650 1661 1817 1889 1872 1925 2013 1965 1948 1940 1963 1934 1860 1834 1845 1793 1832 1747 1762 1679 1783 1636 1670 1455 1575 1445 1467 1402 1408 1426 1386 1342 1414 1436 1355 1431 1363 1365 1312 1380 1342 1457 1388 1363 1386 1330 1377 1347 1336 1336 1280 1324 1439 1373 1365 1334 1418 1335 1394 1348 1380 1360 1373 1399 1356 1295 1330 1349 1351 1387 1395 1357 1356 1403 1412 1324 1418 1376 1341 1466 1371 1332 1416 1349 1370 1470 1328 1374 1374 1380 1393 1379 1424 1417 1507 1462 1455 1504 1483 1423 1539 1454 1499 1483 1501 1525 1557 1595 1642 1545 1537 1646 1594 1601 1648 1633 1658 1739 1713 1675 1669 1654 1694 1738 1805 1845 1795 1838 1869 1859 1976 1935 2004 1995 2064 2182 2122 2320 2425 2528 2629 2832 3031 3278 3361 3732 4123 4615 5143 5759 6536 7433 8611 9541 10634 11394 12256 12749 12739 12456 11916 10890 10217 9524 9027 8640 8563 8721 8531 8324 7865 7380 6924 6156 5406 5040 4383 3944 3571 3268 3010 3013 2804 2573 2532 2388 2311 2358 2260 2134 2047 2010 1903 1940 1868 1831 1784 1795 1768 1762 1686 1691 1689 1631 1554 1567 1529 1532 1504 1533 1468 1500 1493 1437 1494 1550 1502 1569 1572 1591 1786 1855 1928 1885 2043 2252 2309 2364 2281 2342 2218 2104 1978 1837 1847 1830 1816 1887 1950 1893 1900 1842 1783 1631 1631 1598 1475 1468 1461 1471 1432 1438 1348 1439 1257 1359 1371 1364 1342 1353 1381 1479 1364 1383 1372 1304 1348 1296 1355 1325 1297 1417 1350 1370 1353 1370 1340 1376 1359 1367 1272 1316 1379 1348 1335 1385 1378 1363 1386 1448 1412 1487 1486 1534 1568 1558 1583 1613 1757 1711 1794 1830 1844 1936 1940 1872 1956 1864 1818 1753 1775 1749 1757 1743 1726 1693 1684 1647 1708 1648 1618 1676 1555 1562 1478 1505 1564 1524 1475 1478 1413 1466 1403 1465 1455 1435 1461 1429 1493 1508 1426 1436 1548 1451 1488 1476 1445 1534 1434 1478 1517 1458 1522 1541 1496 1576 1584 1615 1605 1677 1589 1672 1783 1688 1877 1854 1908 1893 2063 2044 2074 2344 2338 2618 2725 2935 3417 3823 4477 5268 6345 7387 8972 10565 12348 13738 15053 15601 15024 13853 12000 10033 8587 7514 7350 7466 7630 8236 8639 8881 8581 7990 7142 5961 4774 3998 3318 2948 2605 2333 2174 2179 2050 1928 1903 1846 1833 1696 1730 1648 1674 1565 1600 1576 1515 1493 1487 1443 1502 1405 1347 1487 1459 1489 1383 1469 1445 1434 1366 1445 1414 1379 1479 1381 1510 1405 1459 1410 1420 1473 1394 1399 1444 1440 1398 1405 1317 1405 1328 1312 1448 1304 1414 1320 1366 1334 1340 1289 1297 1236 1252 1254 1274 1275 1336 1276 1310 1298 1264 1304 1316 1245 1290 1262 1322 1312 1231 1345 1304 1247 1286 1258 1302 1329 1325 1340 1300 1309 1346 1327 1244 1209 1296 1213 1268 1307 1263 1247 1349 1268 1283 1319 1262 1325 1254 1276 1251 1323 1232 1241 1257 1304 1234 1292 1167 1402 1274 1369 1344 1266 1427 1428 1403 1398 1392 1547 1568 1779 1715 1942 1946 2030 2063 2145 2090 1949 1825 1752 1740 1669 1574 1629 1710 1770 1775 1816 1693 1650 1635 1515 1458 1418 1426 1379 1415 1381 1336 1416 1441 1429 1413 1540 1454 1424 1511 1583 1587 1622 1729 1764 1788 1976 2038 2033 2259 2252 2549 2531 2489 2413 2440 2292 2228 2201 2004 2097 2038 2022 1997 1990 2018 1987 1936 1900 1811 1746 1669 1663 1569 1424 1492 1373 1485 1345 1354 1369 1327 1311 1344 1238 1310 1272 1367 1249 1227 1257 1235 1297 1269 1240 1262 1246 1254 1227 1259 1229 1279 1201 1261 1298 1193 1295 1192 1246 1225 1194 1232 1225 1251 1296 1282 1217 1198 1230 1297 1245 1260 1307 1345 1265 1254 1276 1198 1323 1256 1215 1281 1240 1249 1230 1304 1260 1246 1239 1220 1294 1271 1250 1298 1261 1230 1285 1294 1236 1313 1279 1308 1334 1358 1327 1332 1454 1331 1452 1414 1442 1319 1407 1368 1344 1272 1352 1275 1286 1252 1319 1296 1330 1298 1361 1412 1343 1266 1281 1216 1347 1301 1368 1368 1392 1482 1340 1469 1475 1538 1483 1501 1512 1522 1474 1431 1436 1289 1438 1347 1341 1411 1392 1401 1396 1352 1429 1267 1371 1411 1283 1303 1296 1271 1265 1306 1176 1246 1283 1307 1219 1243 1279 1271 1249 1270 1186 1233 1199 1205 1184 1202 1272 1210 1235 1212 1298 1282 1199 1249 1242 1270 1178 1262 1193 1244 1187 1218 1184 1217 1177 1204 1267 1186 1185 1240 1249 1277 1249 1264 1332 1291 1315 1263 1350 1323 1335 1203 1355 1217 1289 1342 1232 1279 1216 1226 1276 1320 1379 1246 1348 1245 1390 1365 1312 1367 1323 1363 1336 1303 1306 1335 1421 1411 1414 1405 1528 1560 1647 1696 1805 1914 2095 2276 2421 2730 2934 3229 3255 3257 3033 2887 2517 2475 2350 2288 2325 2277 2491 2660 2777 2916 3002 3104 3048 2964 2809 2679 2432 2402 2199 2123 1973 1962 1910 1833 1908 1838 1909 1948 1913 1808 1844 1760 1591 1587 1551 1521 1513 1472 1392 1393 1372 1406 1340 1337 1383 1357 1309 1320 1323 1321 1322 1327 1321 1293 1228 1329 1278 1367 1298 1395 1307 1367 1281 1359 1329 1397 1440 1423 1538 1475 1522 1413 1490 1436 1420 1322 1379 1344 1349 1431 1374 1409 1438 1425 1390 1420 1355 1341 1406 1348 1334 1322 1418 1323 1369 1420 1405 1413 1406 1449 1428 1479 1284 1307 1475 1421 1481 1532 1496 1507 1468 1576 1497 1470 1564 1599 1558 1683 1581 1729 1620 1735 1677 1800 1766 1870 1989 2041 2134 2198 2226 2440 2463 2771 2969 3247 3515 3866 4503 4991 5543 6169 6881 7379 7969 8310 8550 8551 8370 7772 7201 6594 6253 5940 5707 5644 5616 5796 5710 5738 5607 5554 5271 5049 4539 4148 3711 3376 3089 2763 2655 2475 2465 2301 2084 2029 1950 1875 1873 1826 1637 1766 1755 1694 1657 1614 1513 1585 1488 1453 1519 1439 1572 1475 1480 1419 1421 1410 1471 1370 1400 1401 1424 1386 1322 1405 1440 1398 1382 1380 1344 1317 1412 1407 1386 1466 1268 1331 1446 1375 1392 1341 1327 1401 1347 1423 1301 1388 1265 1388 1374 1442 1299 1362 1383 1378 1321 1384 1385 1408 1438 1381 1430 1428 1404 1427 1397 1388 1391 1410 1461 1460 1482 1394 1454 1479 1467 1511 1547 1560 1567 1596 1582 1658 1732 1835 1810 1953 1972 2098 2203 2310 2540 2586 2757 2951 3107 3294 3290 3457 3358 3420 3376 3599 3597 3663 3643 3546 3290 3194 3059 2946 2691 2683 2627 2427 2410 2340 2323 2435 2380 2379 2218 2134 1946 1927 1692 1692 1613 1477 1497 1460 1453 1466 1351 1440 1294 1374 1395 1389 1460 1438 1374 1398 1375 1366 1407 1396 1351 1381 1392 1364 1396 1445 1449 1412 1450 1410 1468 1507 1458 1450 1491 1517 1500 1521 1424 1399 1346 1459 1316 1416 1390 1431 1344 1397 1393 1385 1343 1379 1356 1292 1341 1309 1394 1294 1330 1335 1282 1307 1303 1234 1268 1269 1327 1296 1311 1380 1387 1416 1432 1398 1391 1432 1423 1434 1457 1523 1471 1538 1565 1531 1563 1701 1741 1825 1843 1912 1968 2167 2211 2336 2440 2547 2595 2696 2827 2863 2877 2768 2708 2686 2756 2769 2937 3132 3315 3602 4051 4586 5310 6139 6963 8003 8970 10008 10724 11298 10789 9819 8503 7264 6091 5504 4682 4630 4506 4703 4937 5352 5657 6199 6248 6211 5755 5240 4497 3837 3231 2901 2539 2262 2104 1925 1891 1747 1745 1679 1599 1633 1538 1538 1504 1514 1577 1499 1529 1501 1581 1550 1451 1461 1387 1448 1381 1450 1363 1313 1391 1348 1349 1428 1388 1384 1295 1368 1324 1329 1414 1274 1288 1307 1373 1319 1380 1330 1334 1327 1347 1343 1315 1292 1302 1329 1294 1377 1215 1408 1289 1335 1359 1331 1307 1340 1296 1342 1387 1331 1423 1374 1353 1333 1345 1415 1480 1421 1518 1524 1610 1666 1616 1772 1706 1813 1756 1623 1640 1675 1588 1572 1479 1550 1576 1535 1520 1513 1495 1660 1574 1622 1631 1526 1595 1589 1652 1647 1677 1732 1801 1961 2018 2307 2487 2748 2896 3111 3234 3292 2961 2758 2505 2204 2102 1959 1842 1806 1946 1945 1935 2005 2073 2253 2172 2166 2086 1964 1881 1656 1606 1594 1329 1369 1302 1318 1294 1264 1318 1318 1328 1259 1240 1195 1298 1239 1233 1229 1262 1240 1291 1283 1249 1253 1217 1275 1220 1201 1308 1180 1277 1211 1215 1233 1244 1260 1287 1229 1176 1186 1180 1247 1216 1288 1265 1271 1228 1323 1288 1284 1347 1341 1354 1340 1351 1390 1370 1356 1330 1434 1374 1418 1430 1513 1543 1572 1589 1579 1682 1720 1682 1742 1781 1755 1783 1785 1729 1804 1776 1781 1756 1733 1800 1851 1907 1966 1974 1947 2027 1933 2001 2041 1952 1995 1975 2012 2099 2044 2132 2130 2098 2119 2150 2155 2091 2206 2273 2301 2512 2622 2766 2946 2958 3365 3455 3633 3527 3281 3001 2783 2662 2337 2220 2192 2039 2193 2081 2114 2173 2203 2280 2373 2288 2203 2100 1994 1840 1746 1612 1523 1471 1454 1444 1411 1318 1403 1233 1360 1411 1245 1337 1252 1267 1321 1348 1216 1240 1202 1291 1309 1231 1304 1152 1246 1225 1290 1253 1267 1236 1199 1223 1262 1211 1142 1274 1227 1269 1277 1327 1301 1249 1276 1342 1398 1288 1416 1437 1531 1545 1620 1697 1766 1789 1973 2004 1799 1837 1873 1743 1653 1651 1603 1589 1543 1560 1519 1530 1571 1612 1602 1592 1582 1580 1514 1521 1419 1417 1430 1323 1337 1288 1342 1282 1190 1275 1189 1270 1241 1283 1201 1289 1233 1220 1201 1239 1210 1285 1199 1254 1255 1230 1291 1364 1376 1354 1400 1486 1636 1659 1765 1793 1872 1761 1699 1682 1624 1504 1478 1359 1414 1263 1337 1326 1414 1541 1505 1535 1460 1522 1501 1462 1451 1425 1385 1415 1325 1327 1260 1307 1261 1396 1240 1287 1298 1249 1269 1259 1222 1188 1311 1235 1215 1303 1182 1261 1181 1299 1240 1216 1245 1219 1159 1183 1174 1193 1196 1233 1171 1198 1322 1309 1307 1419 1333 1400 1508 1430 1484 1481 1419 1417 1418 1293 1253 1353 1336 1337 1234 1247 1196 1315 1247 1285 1273 1334 1341 1259 1282 1249 1287 1219 1209 1145 1120 1126 1235 1134 1155 1173 1136 1162 1161 1145 1087 1103 1136 1165 1212 1122 1106 1165 1070 1182 1080 1146 1079 1125 1114 1151 1216 1130 1193 1208 1191 1187 1250 1243 1196 1183 1277 1356 1425 1445 1473 1549 1555 1503 1544 1496 1375 1426 1259 1303 1273 1295 1253 1305 1310 1321 1331 1414 1344 1390 1358 1402 1300 1260 1302 1286 1221 1217 1207 1204 1179 1183 1184 1175 1061 1149 1151 1138 1087 1185 1105 1198 1134 1152 1172 1138 1151 1185 1138 1076 1168 1109 1141 1133 1139 1034 1151 1125 1134 1141 1117 1120 1120 1154 1098 1078 1160 1101 1132 1118 1065 1135 1132 1105 1084 1172 1136 1145 1121 1119 1133 1119 1155 1081 1087 1149 1098 1108 1084 1215 1048 1142 1128 1141 1159 1061 1195 1141 1118 1129 1173 1155 1103 1213 1127 1112 1109 1101 1121 1127 1142 1112 1148 1102 1113 1105 1122 1176 1154 1188 1209 1196 1237 1101 1232 1301 1341 1396 1524 1585 1634 1767 1893 2034 2100 2070 1990 1803 1755 1623 1479 1445 1394 1363 1378 1332 1448 1426 1543 1583 1580 1628 1667 1571 1522 1454 1334 1362 1282 1252 1213 1198 1147 1127 1159 1170 1174 1125 1136 1116 1135 1080 1146 1006 1116 1199 1093 1152 1048 1160 1117 1151 1054 1055 1154 1094 1099 1126 1132 1094 1117 1063 1119 1037 1078 1072 1156 1045 1101 1072 1095 1101 1011 1040 1039 1077 1049 1065 1038 1069 1164 1051 1078 1033 1035 1026 1100 1070 1064 1080 1074 1068 1110 1089 1147 1084 1081 1143 1110 1106 1042 1138 1104 1097 1144 1062 1006 1010 1108 1112 1080 1076 1101 1087 1180 1117 1101 1129 1074 1125 1102 1210 1140 1195 1139 1184 1122 1227 1220 1233 1430 1389 1502 1583 1624 1704 1766 1678 1563 1527 1507 1333 1361 1298 1308 1354 1311 1373 1349 1321 1397 1438 1453 1546 1493 1504 1514 1516 1441 1523 1511 1517 1532 1649 1552 1685 1587 1495 1468 1484 1382 1370 1322 1299 1256 1322 1271 1262 1264 1268 1308 1316 1350 1266 1307 1283 1201 1276 1185 1179 1147 1186 1161 1166 1111 1134 1080 1101 1099 1056 1118 1033 1135 1069 1048 1106 1088 1148 1093 1153 1087 1167 1109 1094 1010 1087 1101 1124 1063 1094 1075 1104 1098 1080 1056 1118 1066 1150 1073 1124 1044 1067 1087 1053 1105 1085 1128 1215 1044 1143 1069 1091 1128 1099 1093 1066 1098 1090 1156 1206 1109 1119 1083 1135 1165 1125 1172 1137 1140 1173 1142 1102 1118 1165 1127 1201 1222 1236 1263 1257 1294 1353 1313 1380 1418 1467 1524 1635 1701 1830 1894 1872 2009 1888 1938 1811 1826 1739 1736 1684 1471 1546 1427 1477 1423 1509 1601 1550 1579 1540 1582 1588 1503 1494 1464 1393 1368 1318 1360 1273 1290 1308 1183 1170 1150 1162 1193 1127 1238 1066 1155 1117 1135 1156 1165 1059 1094 1160 1091 1092 1100 1108 1042 1078 1032 1069 1024 1067 1131 1095 1058 1071 1102 1063 1070 1069 1120 1083 1042 1111 1043 1098 1073 1091 1084 1082 1095 1095 1082 1159 1132 1091 1105 1111 1087 1068 1080 1134 1129 1114 1107 1098 1021 1133 1101 1183 1098 1127 1242 1178 1170 1093 1150 1047 1179 1112 1222 1284 1229 1295 1400 1341 1391 1472 1516 1655 1675 1748 1753 1770 1809 1776 1739 1728 1719 1545 1566 1434 1427 1456 1400 1450 1433 1481 1422 1467 1485 1420 1489 1521 1524 1522 1490 1345 1353 1233 1254 1206 1206 1186 1145 1223 1103 1121 1133 1127 1064 1068 1140 1112 1180 1076 1085 1095 1073 1040 1112 1078 1033 1077 1040 1073 1031 1055 1109 1098 1103 1118 1075 1076 1020 986 1053 1033 1076 1053 1098 1098 1049 1071 1099 1113 1069 1008 1123 1010 1061 1046 1077 1069 1088 1036 998 1032 1016 1106 1110 1048 1040 1110 1065 1141 1133 1077 1125 1064 1126 1159 1204 1161 1105 1179 1146 1196 1212 1180 1284 1286 1301 1362 1359 1388 1453 1558 1623 1758 1791 1821 1976 1858 2003 2057 2081 1962 1948 1793 1703 1583 1514 1485 1469 1457 1493 1445 1499 1448 1525 1535 1602 1592 1632 1545 1659 1513 1533 1473 1445 1417 1246 1327 1280 1213 1164 1180 1186 1212 1144 1214 1119 1121 1120 1181 1128 1099 1141 1048 1145 1184 1145 1115 1043 1132 1134 1091 1058 1076 1133 1077 1090 1132 1096 1054 1069 1065 1080 1056 1060 1095 1088 1064 1105 1107 1101 1045 1123 1040 1017 1086 1063 1087 1037 1051 1047 1012 1103 1078 1116 1021 1086 1161 1135 1165 1154 1183 1098 1161 1143 1128 1145 1173 1169 1208 1113 1279 1292 1337 1381 1408 1482 1531 1547 1595 1600 1604 1646 1556 1595 1536 1634 1606 1687 1776 1781 1846 1915 2067 2128 2338 2339 2505 2322 2318 2258 2132 1838 1754 1669 1648 1602 1568 1516 1526 1577 1562 1607 1549 1646 1673 1681 1772 1622 1605 1586 1540 1488 1439 1329 1293 1233 1241 1255 1252 1166 1216 1133 1183 1149 1136 1166 1140 1117 1103 1152 1097 1058 1135 1164 1064 1071 1163 1157 1158 1062 1091 1016 1096 1007 1110 1066 1159 1062 1067 1134 1043 1105 1029 1039 1053 1081 1100 1083 1075 1059 1108 1021 1121 1049 1056 1108 1060 1125 1080 1125 1085 1182 1205 1143 1235 1179 1217 1250 1235 1322 1268 1317 1355 1411 1400 1423 1370 1392 1305 1297 1306 1339 1324 1242 1281 1294 1286 1275 1226 1361 1280 1347 1462 1539 1570 1628 1765 1840 1923 1947 2172 2176 2216 2159 1988 2019 1779 1675 1567 1413 1518 1368 1364 1375 1401 1449 1403 1392 1422 1521 1539 1614 1652 1522 1595 1571 1486 1385 1352 1232 1216 1196 1074 1141 1156 1143 1063 1143 1048 1084 1157 1142 1144 1125 1135 1069 1063 1130 1040 1184 1030 1135 1088 1123 1003 1050 1166 1119 1119 1109 1070 1178 1066 1078 1094 1101 1060 1150 1136 1127 1158 1159 1193 1205 1193 1257 1239 1250 1240 1365 1365 1394 1492 1510 1550 1591 1655 1667 1850 1640 1655 1692 1603 1527 1403 1518 1302 1401 1371 1360 1291 1365 1359 1376 1443 1292 1431 1413 1459 1489 1471 1383 1413 1366 1337 1295 1331 1378 1360 1354 1394 1386 1560 1559 1634 1638 1712 1669 1792 1604 1610 1513 1446 1417 1367 1228 1232 1234 1184 1238 1282 1261 1281 1290 1241 1296 1352 1332 1421 1355 1363 1306 1317 1310 1229 1211 1180 1128 1145 1105 1195 1116 1143 1147 1112 1182 1137 1137 1134 1158 1156 1175 1123 1124 1131 1102 1106 1170 1181 1205 1197 1206 1223 1213 1243 1219 1233 1337 1322 1322 1405 1551 1593 1686 1853 1863 1952 2128 2358 2358 2490 2558 2534 2537 2457 2352 2179 2091 2031 1914 1823 1777 1752 1773 1620 1638 1681 1700 1797 1867 1932 1813 1850 1898 1909 1840 1861 1702 1811 1576 1432 1390 1410 1339 1386 1290 1352 1258 1189 1317 1309 1273 1289 1322 1296 1312 1418 1477 1557 1487 1779 1718 1749 1803 1719 1558 1524 1444 1408 1287 1182 1254 1196 1162 1153 1261 1255 1211 1276 1257 1308 1326 1381 1381 1324 1465 1345 1271 1259 1166 1188 1109 1130 1128 1153 1103 1048 1081 1079 1113 1061 1116 1094 1071 1085 1054 1050 967 1118 1005 1071 1053 1055 1095 1110 1078 1089 1096 1035 1038 1064 1057 1108 1120 1175 1066 1103 1063 1162 1116 1062 1125 1044 1150 1118 1115 1120 1172 1095 1124 1126 1122 1104 1113 1166 1130 1233 1118 1182 1137 1118 1191 1195 1239 1184 1171 1164 1185 1276 1224 1256 1239 1235 1215 1217 1223 1230 1306 1228 1156 1255 1182 1179 1269 1329 1242 1274 1247 1273 1325 1388 1306 1379 1469 1572 1500 1580 1538 1546 1473 1431 1404 1393 1294 1278 1280 1292 1145 1159 1163 1196 1248 1242 1292 1276 1298 1349 1320 1409 1297 1222 1284 1275 1302 1260 1274 1263 1269 1224 1247 1209 1280 1267 1271 1220 1344 1344 1311 1410 1452 1549 1567 1626 1741 1730 1896 1988 2022 2067 2020 1897 1978 1768 1743 1669 1572 1470 1460 1454 1446 1457 1341 1455 1460 1470 1488 1495 1499 1543 1526 1565 1503 1525 1470 1456 1418 1339 1328 1347 1282 1231 1253 1174 1191 1200 1172 1126 1176 1143 1198 1133 1124 1110 1060 1158 1156 1201 1116 1153 1156 1081 1104 1094 1130 1241 1189 1143 1182 1205 1231 1186 1369 1420 1364 1524 1627 1675 1797 1896 1905 1998 1950 1823 1725 1711 1549 1547 1441 1337 1326 1307 1325 1247 1297 1253 1302 1340 1304 1411 1449 1432 1539 1514 1534 1446 1417 1431 1400 1350 1342 1301 1305 1291 1242 1292 1320 1332 1245 1256 1313 1256 1250 1187 1278 1228 1171 1170 1169 1226 1145 1196 1175 1171 1203 1117 1092 1177 1132 1158 1117 1196 1111 1155 1146 1147 1056 1115 1107 1132 1096 1101 1087 1084 1112 1118 1118 1136 1072 1175 1090 1137 1113 1129 1096 1166 1077 1089 1077 1097 1104 1066 1163 1168 1070 1107 1185 1075 1115 1108 1205 1113 1203 1106 1100 1102 1198 1266 1236 1301 1304 1315 1281 1373 1501 1607 1656 1791 1976 2268 2361 2574 2843 2920 3072 2932 2920 2617 2493 2205 2067 1856 1707 1718 1543 1539 1457 1485 1605 1520 1635 1669 1739 1871 1990 2131 2136 2097 2170 2214 2126 2058 1813 1728 1649 1606 1546 1496 1412 1355 1342 1284 1269 1170 1265 1135 1141 1156 1147 1231 1177 1144 1143 1200 1112 1181 1115 1172 1138 1117 1154 1147 1087 1129 1082 1100 1032 1061 1039 1120 1021 1051 1058 997 1083 950 1040 1041 1055 1085 998 1063 970 958 1048 1061 1043 1092 992 991 1033 1029 1029 1012 1005 1016 1044 1061 1068 1001 1022 1063 1003 965 965 1003 1000 1037 1003 1011 1078 1062 1116 1031 1072 1003 1032 1053 1019 1070 1042 1042 1040 1076 1096 1093 1135 1087 1087 1106 1195 1106 1211 1140 1153 1152 1234 1212 1215 1285 1375 1422 1411 1420 1463 1404 1441 1421 1434 1415 1379 1293 1390 1264 1157 1155 1095 1208 1173 1173 1172 1248 1195 1225 1195 1171 1192 1203 1225 1218 1194 1167 1218 1199 1118 1156 1086 1072 1128 1111 1096 1077 1064 1086 1122 1077 1034 1059 1009 1043 993 1015 1019 1044 1022 1036 1042 1086 1043 998 1065 1042 1062 1006 1037 1066 1013 1162 1102 1008 1062 932 1014 1056 959 943 1041 1034 1086 1074 1018 1037 1048 1081 1082 1100 1073 1043 1039 1093 1057 1110 1045 1096 1159 1137 1223 1245 1259 1310 1377 1413 1609 1681 1772 1866 2057 2161 2336 2453 2476 2455 2250 2113 1933 1750 1650 1638 1569 1429 1412 1363 1416 1314 1265 1370 1322 1392 1472 1463 1555 1562 1763 1777 1880 1695 1739 1621 1595 1475 1419 1434 1370 1256 1198 1211 1188 1168 1150 1165 1127 1074 1091 1151 1137 1128 1118 1151 1026 1091 1008 1071 1028 1104 1090 1063 1080 1089 1087 1031 1035 1025 1048 1032 1047 1055 940 1115 1031 1037 976 1000 1058 1005 1140 1037 1001 1020 957 1076 987 1037 1080 1039 1073 1038 1002 1038 1084 1069 1022 1029 1034 1055 1062 1062 993 1116 1034 1086 1111 1023 1106 1134 1107 1121 1121 1139 1177 1247 1211 1265 1334 1442 1473 1477 1520 1636 1610 1623 1691 1630 1612 1550 1587 1521 1388 1347 1336 1380 1317 1304 1220 1228 1222 1196 1190 1275 1275 1257 1315 1252 1339 1336 1410 1302 1331 1343 1265 1265 1216 1202 1188 1198 1066 1110 1133 1068 1123 1073 1116 1004 1026 1027 1063 1017 1085 1004 1015 1001 1001 1035 993 1016 1026 1018 985 1009 966 1015 963 997 922 1074 984 1017 1007 967 968 983 1001 951 982 983 966 1026 966 1018 990 1014 981 1005 1001 969 977 960 990 1002 982 974 1028 986 966 985 977 974 962 1019 986 962 996 988 996 1074 1014 982 1021 1056 953 1041 1023 970 1045 1104 1027 1118 1074 1100 1072 1122 1123 1211 1195 1205 1275 1291 1335 1243 1251 1167 1170 1093 1149 1092 1068 1103 1020 1098 1084 1085 1097 1091 1088 1031 1133 1060 1114 1119 1139 1078 1201 1083 1260 1068 1133 1071 1118 1033 1008 1122 1043 1099 988 1042 972 1027 960 1054 1059 1072 1037 1090 1002 979 1019 1036 986 1027 989 1024 979 952 990 998 989 1095 978 1028 942 997 989 1065 990 1015 997 1090 1017 1045 1024 1112 1049 1057 1004 1098 1057 1065 1093 1060 1175 1072 1199 1208 1213 1251 1262 1280 1362 1379 1418 1477 1462 1368 1440 1425 1356 1441 1392 1337 1226 1299 1252 1169 1290 1266 1186 1292 1238 1384 1366 1411 1418 1518 1648 1727 1703 1798 1798 1854 1869 1810 1650 1661 1461 1496 1356 1356 1267 1247 1282 1174 1258 1234 1191 1216 1201 1214 1231 1176 1272 1286 1378 1364 1364 1320 1375 1294 1268 1296 1272 1153 1098 1091 1088 1099 1097 1097 1044 1081 1082 1035 1045 989 1026 1036 974 1015 988 1049 1056 1040 1098 1003 1051 1085 1158 1103 1086 1102 1106 1115 1115 1128 1169 1147 1144 1146 1163 1306 1274 1245 1347 1300 1406 1395 1543 1546 1648 1683 1755 1739 1934 1858 1908 1966 2007 1786 1821 1676 1664 1618 1571 1537 1391 1347 1450 1352 1301 1310 1356 1372 1354 1370 1510 1375 1522 1465 1484 1527 1555 1598 1518 1532 1524 1457 1385 1429 1286 1274 1352 1255 1299 1218 1190 1106 1153 1139 1070 1101 1078 1054 1031 1057 1046 1031 1063 1002 1106 1081 1018 1058 1054 1104 1027 1062 1042 1063 1053 1005 1111 1064 1071 984 1073 987 1039 1027 1020 1077 1126 987 1046 1056 1038 1045 1107 1024 1062 993 1018 1023 1024 1017 1080 1079 1060 1068 1084 1073 1102 1114 1079 1085 1147 1180 1236 1246 1213 1265 1302 1294 1341 1390 1423 1414 1379 1402 1405 1318 1340 1300 1311 1293 1225 1244 1202 1206 1231 1164 1181 1177 1219 1176 1277 1177 1235 1266 1317 1336 1253 1202 1330 1329 1308 1298 1345 1251 1305 1330 1396 1299 1281 1304 1332 1304 1481 1458 1451 1518 1484 1629 1648 1727 1686 1557 1589 1451 1431 1362 1290 1260 1238 1224 1205 1228 1196 1127 1115 1106 1163 1175 1179 1194 1246 1274 1233 1224 1310 1323 1373 1333 1297 1283 1293 1145 1175 1171 1055 1093 1097 1086 1059 1007 1026 1046 1101 1113 1035 1059 1055 1070 1050 1102 1158 1121 1103 1071 1153 1152 1134 1194 1157 1237 1236 1213 1248 1247 1283 1335 1223 1225 1212 1154 1157 1247 1051 1168 1061 1104 1162 1090 1168 1018 1072 1100 1130 1075 1033 1098 1097 1115 1116 1063 1071 1157 1203 1152 1063 1143 1085 1025 1036 1104 1103 1057 1053 1067 946 1065 1033 964 980 1002 996 990 963 1028 969 965 951 975 1006 1017 954 992 982 928 1049 964 1023 969 1047 976 918 958 1012 1015 983 966 985 952 976 974 993 936 1014 1050 987 978 997 963 971 959 1005 950 1039 1010 991 1011 996 1002 1020 1009 1017 997 983 1054 1035 1017 994 1059 968 1059 1060 1171 1163 1105 1174 1123 1180 1136 1093 1087 1059 1041 1013 1049 1055 966 1018 1036 992 1058 1032 1048 1012 996 994 1022 1040 1088 1051 1114 986 1095 1047 1058 1078 1054 1060 1064 1170 1054 1027 1010 1038 1041 1045 991 1011 1039 1034 1041 1059 1114 1046 1029 1058 1041 1029 1107 1027 1151 1073 1132 1139 1160 1186 1170 1257 1332 1334 1397 1415 1495 1612 1598 1551 1591 1446 1478 1495 1390 1356 1306 1244 1230 1174 1155 1126 1160 1158 1116 1157 1175 1108 1301 1160 1252 1182 1296 1325 1347 1451 1470 1524 1504 1493 1476 1581 1475 1539 1556 1485 1545 1630 1593 1667 1626 1652 1591 1628 1604 1546 1511 1394 1375 1312 1333 1322 1266 1246 1213 1276 1273 1245 1265 1230 1290 1249 1260 1280 1285 1327 1348 1301 1362 1380 1389 1380 1319 1339 1355 1297 1258 1222 1320 1220 1212 1197 1178 1169 1243 1108 1149 1140 1096 1075 1138 1066 1160 1092 1112 1142 1107 1098 1167 1097 1135 1156 1158 1156 1144 1217 1156 1287 1212 1260 1253 1336 1346 1507 1489 1633 1681 1824 1949 1959 2078 2164 2227 2103 2085 1910 1893 1769 1676 1545 1542 1342 1381 1358 1302 1302 1291 1258 1231 1238 1261 1353 1336 1305 1408 1382 1530 1519 1709 1699 1777 1735 1700 1724 1647 1529 1536 1454 1385 1386 1212 1253 1231 1208 1092 1207 1210 1194 1102 1084 1153 1126 1093 1149 1097 1115 1129 1090 1135 1087 1060 1087 1153 1116 1098 1130 1052 1098 915 1080 1001 1038 1043 1013 1087 1023 1006 1075 1079 1014 1002 1110 1009 1066 1021 1081 1001 1003 975 1051 1023 1016 1015 1063 1087 1061 1006 988 1076 1065 1120 1014 1101 1088 1063 1106 1078 1100 1064 1113 1117 1113 1147 1177 1242 1264 1300 1287 1420 1359 1453 1644 1620 1699 1677 1725 1644 1702 1659 1575 1637 1577 1548 1451 1470 1489 1546 1529 1576 1676 1670 1761 1808 1826 1936 1973 1854 1844 1756 1791 1844 1756 1714 1764 1712 1706 1583 1599 1521 1609 1400 1424 1360 1408 1299 1369 1400 1363 1351 1322 1396 1487 1350 1495 1420 1527 1401 1393 1381 1305 1387 1279 1308 1324 1157 1203 1223 1173 1199 1148 1147 1133 1042 1063 1088 1077 1080 1044 1072 1018 1033 1001 1082 1024 1057 1053 1092 1037 1062 1067 1075 1038 1094 1048 1046 1012 1061 1007 1084 1061 1035 1063 997 1048 1063 1065 1057 1109 1136 1079 1091 1064 1061 1074 1068 1201 1117 1129 1141 1229 1233 1338 1342 1452 1521 1452 1611 1626 1754 1686 1809 1721 1779 1651 1744 1701 1772 1634 1705 1670 1668 1624 1557 1453 1488 1340 1394 1305 1337 1348 1276 1327 1284 1205 1315 1332 1313 1411 1387 1413 1382 1476 1357 1443 1407 1373 1366 1323 1336 1407 1294 1270 1411 1221 1219 1204 1230 1173 1227 1113 1142 1187 1126 1135 1126 1125 1098 1114 1123 1048 1016 1028 1077 1074 1067 1038 1024 973 988 1017 1049 995 1001 1092 1022 989 1074 1023 1004 994 962 982 1045 1039 1001 1071 980 1054</counts>
			</dataPoints>
		</scan>
	</xrdMeasurement>
</xrdMeasurements>