File: dataset/precursor_mixture/Li2CO3_ZrO2_Nb2O5_Ga2O3.12-min.xrdml
<?xml version="1.0"?>
<xrdMeasurements xmlns="http://www.xrdml.com/XRDMeasurement/2.2" xmlns:xsi="http://www.w3.org/2001/XMLSchema-instance" xsi:schemaLocation="http://www.xrdml.com/XRDMeasurement/2.2 http://www.xrdml.com/XRDMeasurement/2.2/XRDMeasurement.xsd" status="Completed" recordIdentifier="{4D62F6A1-0D8F-42CF-B9B7-091E44D6358F}">
	<comment>
		<entry/>
	</comment>
	<sample type="To be analyzed">
		<id>dara-31-2</id>
		<name></name>
		<preparedBy></preparedBy>
	</sample>
	<xrdMeasurement measurementType="Scan" status="Completed" sampleMode="Reflection">
		<usedWavelength intended="K-Alpha 1">
			<kAlpha1 unit="Angstrom">1.5405980</kAlpha1>
			<kAlpha2 unit="Angstrom">1.5444260</kAlpha2>
			<kBeta unit="Angstrom">1.3922500</kBeta>
			<ratioKAlpha2KAlpha1>0.5000</ratioKAlpha2KAlpha1>
		</usedWavelength>
		<incidentBeamPath>
			<radius unit="mm">145.00</radius>
			<xRayTube id="1010048" name="Empyrean Cu LFF HR (9430 033 7310x) DK437873">
				<tension unit="kV">40.0</tension>
				<current unit="mA">15.0</current>
				<anodeMaterial>Cu</anodeMaterial>
				<focus type="Line">
					<length unit="mm">12.0</length>
					<width unit="mm">0.4</width>
					<takeOffAngle unit="deg">6.0</takeOffAngle>
				</focus>
			</xRayTube>
			<filter id="20010004" name="Beta-filter Nickel">
				<material>Ni</material>
				<thickness unit="mm">0.020</thickness>
			</filter>
			<sollerSlit id="21010002" name="Soller slits 0.04 rad.">
				<opening unit="rad">0.0400</opening>
			</sollerSlit>
			<mask id="22031000" name="Fixed mask 13 mm">
				<width unit="mm">9.00</width>
			</mask>
			<divergenceSlit id="22120001" name="Divergence slit 1°" xsi:type="fixedDivergenceSlitType">
				<distanceToSample unit="mm">50.00</distanceToSample>
				<height unit="mm">1.52</height>
			</divergenceSlit>
		</incidentBeamPath>
		<beamKnife id="29030100" name="Beam knife low"/>
		<sampleMovement xsi:type="spinningSampleMovementType">
			<spinnerRevolutionTime unit="seconds">1.0</spinnerRevolutionTime>
		</sampleMovement>
		<diffractedBeamPath>
			<radius unit="mm">145.00</radius>
			<antiScatterSlit id="22090040" name="AS slit 9 mm" xsi:type="fixedAntiScatterSlitType">
				<height unit="mm">9.00</height>
			</antiScatterSlit>
			<sollerSlit id="21020003" name="Large Soller slits 0.04 rad.">
				<opening unit="rad">0.0400</opening>
			</sollerSlit>
			<filter id="20030001" name="Large beta-filter Nickel">
				<material>Ni</material>
				<thickness unit="mm">0.020</thickness>
			</filter>
			<detector id="7010019" name="PIXcel1D-Medipix3 detector" xsi:type="rtmsDetectorType">
				<phd unit="keV">
					<lowerLevel>4.0</lowerLevel>
					<upperLevel>11.3</upperLevel>
				</phd>
				<mode>Scanning</mode>
				<activeLength unit="deg">5.020</activeLength>
			</detector>
		</diffractedBeamPath>
		<scan appendNumber="0" mode="Continuous" scanAxis="Gonio" status="Completed">
			<header>
				<startTimeStamp>2024-03-24T12:39:02-07:00</startTimeStamp>
				<endTimeStamp>2024-03-24T12:51:29-07:00</endTimeStamp>
				<author>
					<name>AutomatedUser</name>
				</author>
				<source>
					<applicationSoftware version="1.6 (94)">PANalytical Aeris Instrument Suite</applicationSoftware>
					<instrumentControlSoftware version="3.0.0 20211014">AERIS</instrumentControlSoftware>
					<instrumentID>2879380</instrumentID>
				</source>
			</header>
			<dataPoints>
				<positions axis="2Theta" unit="deg">
					<startPosition>9.99043322</startPosition>
					<endPosition>100.09495370</endPosition>
				</positions>
				<positions axis="Omega" unit="deg">
					<startPosition>4.99521661</startPosition>
					<endPosition>50.04747685</endPosition>
				</positions>
				<commonCountingTime unit="seconds">18.249</commonCountingTime>
				<counts unit="counts">4120 3942 4148 4051 4021 4045 4148 4060 4146 4030 4069 4013 4046 4083 4031 3975 4058 3955 4003 3994 4020 3999 3982 4061 4104 3943 3977 3906 3850 3956 3944 3815 3959 4042 3902 3925 4137 3838 3993 3803 4025 3882 3962 3934 3874 3848 3819 3833 3746 3887 3885 3841 3883 3821 3841 3917 3855 3762 3760 3789 3763 3791 3737 3764 3709 3883 3769 3876 3747 3730 3865 3716 3727 3798 3735 3727 3751 3840 3737 3797 3706 3758 3595 3719 3734 3697 3728 3656 3781 3642 3752 3684 3703 3622 3603 3585 3549 3723 3551 3575 3623 3563 3698 3590 3553 3553 3670 3517 3581 3536 3491 3565 3539 3527 3623 3521 3576 3624 3508 3602 3561 3503 3604 3583 3603 3546 3479 3458 3458 3516 3284 3447 3458 3427 3507 3523 3386 3481 3449 3506 3351 3491 3339 3435 3407 3383 3399 3410 3357 3448 3453 3272 3342 3334 3391 3379 3344 3375 3462 3191 3391 3402 3285 3403 3414 3441 3362 3424 3376 3405 3302 3457 3344 3386 3299 3410 3372 3391 3344 3329 3269 3244 3311 3275 3274 3273 3360 3271 3246 3328 3245 3349 3176 3332 3293 3198 3304 3169 3211 3316 3254 3261 3238 3266 3187 3139 3329 3301 3158 3177 3098 3208 3174 3130 3167 3155 3284 3139 3208 3208 3196 3283 3237 3244 3198 3175 3129 3220 3097 3159 3101 3072 3080 3092 3020 3163 3155 3139 3217 3132 3156 3179 3139 3136 3055 3198 3041 3160 3186 3013 3098 3025 3099 3016 3056 3095 2985 3032 3080 3091 3062 3043 3046 3066 3187 3053 3150 3040 3100 3023 3043 3125 3029 3053 3095 3036 3082 3074 3062 3108 3061 2997 2958 3017 2986 3035 3026 3041 2984 2960 2915 3031 2968 3100 3069 2966 2989 3041 2973 3010 3007 2980 2946 3076 2965 2890 3026 2948 3019 2969 3132 2990 2878 2929 3004 2965 2880 3063 2866 3108 2956 3047 2968 2912 2925 3068 2899 2824 2940 2937 2889 2939 3030 2888 3017 2936 2892 2912 2833 2936 2862 2958 2815 2932 2881 2933 2813 2876 2906 2885 2739 2928 2907 2928 2904 2859 2940 2833 2866 2887 2910 2866 2855 2774 2854 2903 2843 2916 2836 2812 2902 2965 2921 2904 2817 2806 2822 2793 2888 2807 2784 2833 2905 2850 2848 2828 2842 2827 2824 2939 2761 2908 2991 2942 2975 2836 2840 2895 2861 2778 2884 2915 2828 2752 2807 2781 2841 2838 2810 2945 2773 2901 2743 2783 2800 2925 2738 2823 2860 2775 2851 2856 2856 2829 2950 2795 2795 2869 2759 2687 2785 2850 2730 2861 2681 2842 2759 2730 2835 2727 2821 2869 2751 2766 2795 2776 2727 2652 2710 2745 2720 2794 2712 2744 2795 2751 2809 2752 2730 2748 2737 2779 2655 2766 2795 2787 2780 2821 2725 2784 2803 2787 2656 2668 2699 2817 2676 2776 2716 2761 2782 2806 2765 2769 2708 2783 2656 2691 2695 2679 2766 2746 2652 2750 2713 2736 2635 2731 2751 2696 2723 2712 2795 2780 2709 2768 2738 2722 2743 2680 2725 2733 2713 2730 2770 2607 2621 2881 2699 2714 2735 2761 2781 2792 2824 2793 2664 2749 2695 2853 2894 2735 2790 2861 2788 2699 2752 2630 2785 2610 2713 2761 2706 2659 2727 2768 2790 2733 2749 2707 2750 2801 2755 2789 2706 2719 2636 2596 2669 2602 2622 2706 2667 2742 2670 2701 2624 2630 2659 2587 2568 2689 2634 2628 2695 2645 2659 2604 2656 2644 2665 2754 2687 2674 2709 2605 2594 2661 2695 2582 2583 2623 2597 2721 2655 2592 2682 2614 2614 2603 2615 2556 2686 2587 2652 2670 2566 2528 2739 2558 2620 2525 2594 2687 2546 2625 2657 2680 2628 2732 2615 2612 2595 2669 2595 2551 2656 2690 2624 2651 2654 2635 2596 2582 2640 2635 2623 2541 2686 2548 2608 2801 2680 2707 2787 2739 2729 2743 2793 2767 2766 2802 2814 2830 2779 2953 2981 2828 2856 2959 2909 2946 2831 2858 2820 2739 2761 2790 2666 2669 2714 2749 2697 2753 2829 2763 2750 2710 2723 2601 2840 2768 2869 2779 2852 2903 2903 2903 2931 2889 3004 2935 2979 2934 3016 2935 2927 2917 2855 2867 2904 2735 2728 2807 2630 2767 2642 2667 2714 2622 2524 2606 2582 2648 2573 2530 2495 2515 2539 2519 2538 2599 2530 2519 2618 2549 2527 2507 2541 2504 2488 2534 2552 2490 2410 2585 2512 2509 2636 2435 2455 2427 2560 2448 2567 2493 2432 2510 2514 2480 2509 2473 2407 2541 2433 2460 2506 2595 2487 2559 2446 2575 2556 2516 2525 2413 2561 2460 2537 2632 2564 2472 2521 2487 2494 2537 2581 2513 2563 2532 2547 2623 2518 2507 2526 2541 2545 2477 2518 2577 2513 2535 2615 2540 2591 2661 2550 2574 2624 2509 2607 2638 2705 2682 2708 2698 2667 2744 2820 2712 2878 2858 2974 3021 3003 3145 3138 3185 3394 3490 3551 3647 3716 3826 3958 4074 4038 4157 4105 4256 4298 4149 4153 4049 4043 3937 3802 3610 3475 3295 3191 3207 3070 3040 2957 2883 2834 2757 2753 2769 2694 2676 2658 2528 2630 2566 2507 2558 2530 2546 2392 2506 2466 2427 2419 2476 2495 2440 2480 2336 2487 2478 2341 2434 2417 2355 2403 2388 2444 2429 2375 2395 2348 2349 2364 2370 2371 2229 2352 2317 2334 2317 2337 2394 2354 2243 2278 2432 2317 2363 2237 2391 2318 2262 2308 2312 2316 2301 2298 2321 2229 2363 2279 2239 2302 2250 2311 2241 2291 2263 2229 2247 2347 2331 2264 2215 2281 2247 2244 2269 2287 2260 2250 2303 2251 2335 2222 2227 2285 2345 2197 2155 2216 2248 2258 2235 2263 2250 2229 2291 2211 2293 2238 2272 2186 2158 2288 2282 2292 2318 2236 2267 2221 2324 2202 2170 2285 2315 2243 2206 2215 2221 2225 2215 2215 2230 2175 2291 2234 2272 2201 2348 2290 2235 2221 2227 2232 2177 2286 2186 2213 2176 2204 2228 2189 2262 2247 2177 2229 2195 2251 2257 2277 2264 2158 2240 2231 2204 2151 2246 2195 2335 2205 2289 2324 2370 2297 2332 2180 2364 2259 2246 2230 2323 2281 2275 2288 2232 2366 2339 2318 2380 2485 2397 2472 2392 2519 2543 2751 2698 2915 2946 3014 3219 3157 3498 3632 3862 4056 4369 4509 4713 4917 4926 4948 4933 4895 4940 4972 4831 4790 4871 5113 5244 5542 5701 5534 5883 5813 5437 5055 4647 4256 4089 3620 3346 3053 2863 2637 2556 2500 2417 2261 2292 2426 2369 2377 2235 2301 2167 2312 2244 2340 2224 2218 2288 2215 2236 2188 2192 2146 2194 2238 2248 2192 2243 2235 2178 2273 2211 2186 2154 2317 2187 2224 2170 2114 2209 2226 2221 2251 2214 2167 2185 2136 2179 2322 2203 2270 2328 2109 2230 2357 2266 2307 2402 2371 2494 2327 2427 2575 2596 2555 2700 2739 2827 2779 2975 3014 3176 3307 3638 3903 4019 4377 4648 4980 5437 5933 6421 6978 7563 8221 8596 9544 10325 10757 11538 11668 11656 11349 10698 9966 9216 8380 7465 6526 5662 4951 4418 3800 3439 3302 3067 2811 2676 2586 2509 2530 2430 2441 2368 2377 2266 2246 2285 2244 2156 2218 2270 2176 2196 2246 2204 2256 2221 2169 2158 2119 2168 2137 2181 2205 2295 2194 2208 2112 2175 2173 2131 2063 2139 2069 2073 2014 2094 2137 2092 2194 2127 2123 2104 2074 2156 2149 2189 2055 2283 2245 2269 2244 2293 2254 2232 2294 2219 2219 2226 2182 2220 2187 2166 2187 2180 2160 2063 2135 2031 2258 2217 2168 2319 2028 2243 2133 2149 2097 2131 2121 2169 2158 2209 2178 2180 2170 2276 2291 2236 2198 2286 2320 2367 2302 2417 2392 2435 2447 2463 2567 2597 2592 2579 2786 2739 2913 2998 3078 3142 3219 3241 3255 3262 3367 3358 3410 3364 3267 3287 3111 3141 3083 2988 2926 2698 2649 2619 2650 2528 2513 2533 2511 2567 2556 2510 2635 2632 2593 2611 2653 2710 2711 2686 2771 2793 2821 2826 2849 3010 2904 2921 2913 2873 2784 2774 2731 2693 2616 2605 2488 2483 2366 2331 2332 2264 2160 2181 2154 2203 2149 2068 2192 2152 2083 2129 2142 2147 2075 2069 1995 2139 2018 2122 2052 2091 2007 2000 1946 2039 2034 2019 2068 1964 1966 1918 1954 1950 1984 1964 1954 1951 1944 2004 2008 1948 1997 1994 1960 1996 1952 1999 1994 1975 2040 1979 1994 1949 1942 1954 1915 2051 1991 1954 1963 2016 2033 1974 1939 2004 1948 1975 2039 2136 2023 2073 1971 2066 1969 2038 2058 2112 2008 2082 2031 2221 2094 2115 2106 2088 2136 2168 2055 2170 2127 2037 2092 2102 2056 2168 1989 2079 1971 2024 2025 2022 1989 1910 2025 1952 1935 1916 1988 1928 1938 1934 1970 1890 1912 1856 1975 1889 1937 1882 1953 1999 1903 1989 1857 1924 1979 1969 1914 1916 1925 1914 1876 1926 1880 1887 1982 1904 1931 1958 1916 2014 1934 1931 1865 1867 1950 1852 1972 1943 1901 1911 1897 1864 1907 1812 1927 1945 1901 1854 1905 1957 1872 1844 1849 1858 1863 1904 1908 1940 1877 1864 1976 1956 1973 1963 1912 1891 1843 1872 1797 1950 1871 1936 1820 1899 1867 1909 1894 1969 1937 1868 1898 1797 1896 1866 1908 1812 1880 1829 1944 1867 1934 1847 1841 1871 1871 1963 1829 1775 2023 2002 1892 1981 1970 1828 1853 1850 1877 1892 1889 1929 1972 1913 1866 1883 1949 1963 1932 1876 1882 1865 1968 1938 1880 1926 1948 2001 1928 1988 1987 1944 2004 1947 2017 1999 1965 1868 2083 1995 2032 2070 2054 1986 2014 2085 2126 2019 2139 2085 2124 2023 2191 2089 2110 2177 2142 2092 2122 2191 2204 2215 2323 2280 2193 2263 2239 2257 2170 2190 2062 2210 2219 2249 2352 2252 2242 2255 2335 2317 2419 2441 2403 2527 2489 2617 2607 2479 2593 2790 2799 2765 2853 2815 2870 3103 3130 3340 3347 3556 3739 3980 3990 4306 4531 4801 4982 5507 5765 6200 6766 7230 7688 8335 8978 9581 10208 10719 11250 11643 12350 12762 12758 13264 13146 13272 13536 13666 13785 13868 13963 14196 14146 14225 13737 13335 12484 11620 11199 10070 9369 8489 7810 6911 6259 5663 5027 4545 4233 3971 3661 3390 3405 3238 3169 3096 2984 2865 2645 2801 2674 2781 2611 2662 2733 2659 2481 2641 2676 2682 2764 2872 2831 2974 2967 3050 3272 3354 3529 3641 3898 3964 4132 4494 4687 5082 5027 5405 5537 5631 5707 5552 5420 5197 4972 4544 4377 4035 3739 3629 3305 3146 2865 2716 2627 2608 2474 2476 2390 2455 2415 2491 2382 2498 2480 2361 2449 2322 2402 2319 2290 2368 2312 2356 2291 2361 2322 2366 2260 2389 2341 2388 2395 2437 2499 2551 2476 2436 2379 2444 2483 2397 2529 2456 2488 2340 2453 2387 2397 2454 2289 2445 2375 2426 2407 2428 2444 2405 2471 2568 2543 2641 2525 2527 2509 2575 2583 2702 2629 2646 2717 2730 2841 2758 2956 2986 2959 3040 3100 2989 3075 3126 3220 3358 3480 3474 3579 3650 3702 3863 3990 3995 4028 4203 4107 4183 4372 4396 4316 4485 4548 4607 4674 4618 4756 4714 4748 5048 5144 5216 5333 5345 5797 5742 6063 6394 6595 6959 7224 7757 7989 8556 9208 9599 10164 11005 11773 12817 13871 15367 16708 18373 20299 22480 24755 27903 30424 33457 36358 38838 40705 41210 39483 36549 32945 29382 26834 24776 22620 19985 17374 14620 11893 9832 8132 6954 6008 5518 5008 4691 4495 4288 4163 4150 3883 3914 3819 3784 3657 3642 3529 3435 3455 3366 3322 3240 3245 3299 3140 3183 3189 3072 3279 3115 3092 3171 3167 3145 3066 3199 3164 3169 3155 3156 3335 3291 3382 3398 3485 3515 3646 3741 3873 3904 4151 4323 4338 4544 4623 5055 5297 5510 5849 6139 6456 6837 7195 7416 7901 8339 8590 8718 9146 9159 9195 8978 9106 8867 8775 8682 8504 8450 8322 8179 8105 8213 7960 7959 8071 8196 8285 8346 8451 8672 8759 8623 8683 8903 8616 8760 8630 8242 7918 7737 7460 6957 6567 6400 6095 5836 5360 5130 4883 4527 4379 4198 3939 3804 3532 3561 3405 3218 3213 3150 3029 2789 2825 2744 2731 2773 2610 2648 2518 2541 2515 2508 2432 2425 2248 2361 2329 2352 2341 2274 2185 2183 2074 2157 2152 2175 2054 2181 2112 2095 2024 2092 2075 2065 2129 2061 2014 1986 1946 1974 1972 2051 1963 1968 2026 1954 1925 2001 1893 1987 1999 1959 1902 1965 2023 1917 1897 1923 1933 1954 2051 2044 2017 2066 2114 2069 2091 2098 2099 2007 2158 2086 2033 2107 2086 1960 1996 1915 2005 1954 2037 1930 1992 1972 1983 1981 2020 1892 1949 1971 1966 2013 2127 2158 2199 2299 2276 2216 2252 2247 2260 2251 2145 2139 2153 2156 2106 2149 1971 2142 2055 2037 1917 2020 2084 2015 2081 2045 1970 2076 2011 2071 2111 2092 2164 2188 2192 2218 2112 2105 2129 2172 2089 2250 2166 2001 2062 2123 2007 2078 2063 2068 2052 2054 2064 2069 2071 1914 2034 2038 2002 1926 2000 1991 1985 1918 1918 1870 1848 1895 1978 1952 1964 2040 2041 1975 2012 1957 2044 2093 1956 1996 2088 2193 2208 2194 2199 2302 2290 2506 2459 2591 2613 2696 2815 3003 3012 3151 3272 3377 3498 3563 3743 3743 3804 3789 3819 3848 3743 3669 3501 3534 3441 3369 3325 3038 3141 3061 3052 2971 2939 2937 2938 2978 2982 2994 2897 2952 3090 2971 2993 2911 2892 2935 2807 2834 2855 2796 2599 2542 2481 2425 2376 2327 2273 2294 2163 2238 2242 2200 2213 2138 2131 2225 1968 2090 1988 2005 2114 2041 1996 2101 2047 2089 2053 2138 2107 2068 2184 2113 2095 2220 2191 2229 2246 2253 2358 2333 2369 2493 2471 2559 2609 2656 2692 2905 2911 3024 3148 3204 3411 3311 3499 3761 3917 3941 4035 4162 4329 4380 4407 4599 4557 4653 4770 5017 4897 5146 5417 5369 5444 5521 5586 5829 6077 6482 6670 7306 7729 8432 9436 10329 11017 11785 12593 12786 12594 11633 10646 9768 8921 8326 7765 7631 7087 6526 5726 4942 4230 3603 3206 2987 2780 2583 2571 2424 2432 2289 2286 2262 2319 2244 2209 2162 2176 2183 2148 2142 2147 2128 2026 2105 2220 2228 2112 2243 2185 2185 2231 2369 2325 2320 2369 2523 2617 2657 2903 3113 3411 3725 4085 4367 4609 4633 4275 3842 3677 3220 3299 3202 3147 3254 2957 2812 2583 2329 2211 2053 1958 1987 1984 1957 1990 2006 1935 2019 2027 2142 2167 2250 2330 2313 2485 2685 2769 2992 3212 3460 3719 3958 4292 4668 4907 5142 5257 5284 5144 5003 4725 4541 4275 4209 4123 3885 3670 3552 3282 3011 2815 2617 2433 2480 2262 2251 2231 2099 2132 2109 2118 2097 2084 2085 2098 2224 2138 2284 2369 2423 2509 2587 2731 2824 3013 2984 3290 3193 3300 3468 3655 3581 3656 3500 3491 3401 3152 3044 2990 2809 2800 2711 2563 2498 2364 2377 2310 2162 2208 2174 2103 2219 2153 2186 2108 2109 2143 2086 2172 2089 2166 2142 2259 2207 2193 2081 2156 2172 2185 2125 2167 2253 2141 2049 2279 2182 2134 2112 2256 2210 2249 2254 2271 2300 2508 2502 2744 2916 3026 3222 3379 3418 3494 3492 3326 3277 3062 2963 2859 2895 2656 2664 2660 2429 2320 2287 2092 2054 1994 1942 1854 1878 1848 1924 1793 1851 1772 1861 1904 1862 1902 1854 1886 1891 1942 1787 1895 1883 2052 1951 2004 2016 1988 2101 2118 2083 2106 2232 2151 2312 2299 2447 2401 2513 2423 2552 2546 2662 2617 2824 2761 2870 2909 3052 2979 3046 3062 3046 3046 3215 3019 2994 2996 3089 2965 2858 2975 2817 2848 2757 2785 2767 2621 2658 2528 2559 2444 2457 2375 2306 2243 2273 2156 2120 2101 2094 2059 1973 1898 1912 1952 1924 1868 1853 1826 1758 1743 1791 1812 1727 1679 1752 1749 1651 1687 1608 1708 1664 1623 1711 1609 1676 1600 1682 1633 1592 1540 1642 1541 1608 1559 1548 1548 1530 1533 1450 1480 1556 1531 1514 1442 1502 1553 1513 1513 1517 1476 1498 1548 1549 1488 1587 1493 1577 1556 1631 1542 1589 1594 1597 1576 1586 1621 1688 1592 1653 1733 1668 1678 1659 1801 1787 1826 1852 1890 1884 1870 1768 1845 1824 1743 1751 1764 1856 1785 1743 1722 1683 1686 1726 1700 1689 1763 1802 1800 1887 1965 1992 1863 1895 1947 1825 1803 1776 1817 1824 1807 1918 1829 1840 1821 1732 1671 1629 1621 1533 1569 1622 1620 1499 1572 1561 1455 1471 1516 1472 1503 1468 1521 1498 1444 1406 1498 1494 1490 1568 1521 1474 1435 1498 1464 1426 1459 1432 1432 1430 1556 1524 1489 1584 1494 1509 1542 1582 1514 1512 1522 1569 1554 1530 1686 1727 1580 1600 1627 1705 1684 1785 1789 1739 1721 1842 1904 1903 1993 2003 2106 2144 2207 2204 2303 2261 2267 2313 2359 2201 2264 2270 2246 2211 2164 2081 2065 2064 1935 1971 1866 1856 1781 1816 1775 1727 1782 1703 1773 1714 1691 1701 1716 1701 1708 1732 1777 1767 1743 1774 1675 1779 1816 1696 1849 1807 1926 1816 1764 1843 1722 1824 1838 1805 1826 1814 1828 1894 1833 1833 1747 1920 1880 1780 1911 1832 1837 1795 1764 1850 1742 1825 1774 1776 1725 1754 1710 1661 1701 1620 1637 1687 1650 1549 1490 1437 1583 1506 1535 1599 1611 1534 1538 1598 1609 1640 1698 1740 1736 1836 1916 2045 2137 2286 2571 2699 2850 2852 3064 2983 2843 2591 2459 2465 2398 2312 2262 2196 2293 2246 2062 2065 1823 1775 1645 1549 1492 1466 1393 1445 1526 1437 1396 1429 1467 1394 1478 1487 1477 1452 1306 1456 1285 1373 1504 1424 1459 1406 1411 1497 1445 1367 1435 1408 1475 1384 1478 1514 1497 1510 1516 1479 1487 1482 1555 1564 1525 1534 1502 1615 1588 1640 1578 1602 1722 1699 1682 1753 1735 1706 1705 1746 1728 1756 1731 1671 1759 1667 1688 1698 1737 1754 1601 1738 1612 1685 1626 1647 1622 1673 1584 1625 1536 1541 1628 1582 1560 1559 1565 1535 1657 1560 1627 1537 1542 1561 1596 1586 1617 1517 1434 1564 1624 1516 1652 1598 1518 1573 1612 1447 1534 1497 1451 1521 1471 1456 1444 1503 1495 1534 1460 1484 1563 1389 1458 1431 1423 1468 1456 1541 1465 1497 1492 1602 1540 1669 1584 1591 1592 1504 1484 1455 1420 1488 1439 1494 1576 1499 1527 1436 1409 1415 1450 1385 1381 1448 1417 1442 1413 1415 1448 1521 1538 1615 1661 1649 1680 1681 1643 1672 1621 1635 1555 1580 1522 1521 1558 1573 1592 1575 1540 1425 1433 1431 1381 1460 1419 1384 1355 1519 1358 1435 1365 1367 1392 1365 1415 1356 1452 1524 1350 1424 1322 1375 1444 1386 1345 1358 1303 1350 1429 1424 1323 1509 1416 1434 1515 1476 1459 1527 1375 1483 1410 1545 1486 1482 1525 1522 1492 1544 1507 1541 1560 1566 1587 1623 1580 1632 1653 1675 1683 1690 1784 1652 1593 1657 1725 1715 1716 1647 1825 1748 1846 1858 1832 1849 1787 1970 1870 1997 2000 1938 2019 2048 2021 2104 1978 2037 2003 1934 2030 1999 2015 2068 2063 2046 1989 2135 2076 2020 1998 2148 2094 2111 2065 2016 2158 2118 2026 2062 2007 1957 1865 1925 1874 1839 1874 1765 1831 1810 1814 1754 1718 1655 1679 1644 1687 1647 1739 1599 1681 1679 1713 1751 1675 1804 1774 1722 1817 1801 1952 1914 2027 2041 2052 2042 2227 2186 2290 2358 2420 2449 2644 2846 2942 3240 3503 3583 4039 4358 4636 4735 4648 4568 4389 3936 3781 3575 3459 3331 3517 3440 3585 3495 3341 3200 3021 2763 2580 2407 2372 2267 2264 2126 2230 2155 2223 2063 2141 2029 2117 2195 2103 2216 2447 2255 2453 2531 2759 2971 3162 3280 3361 3286 3314 3226 3071 3046 2804 2849 2770 2846 2707 2649 2577 2609 2415 2457 2264 2111 2053 1847 1793 1736 1666 1633 1693 1555 1637 1612 1483 1482 1437 1421 1346 1448 1396 1517 1437 1401 1346 1336 1393 1355 1316 1332 1356 1406 1351 1402 1428 1402 1475 1413 1333 1383 1321 1401 1322 1322 1321 1261 1323 1348 1305 1329 1268 1266 1351 1321 1327 1406 1285 1332 1356 1424 1400 1335 1309 1387 1286 1326 1380 1352 1328 1316 1379 1321 1301 1289 1400 1283 1302 1312 1327 1328 1322 1330 1364 1299 1373 1317 1346 1329 1341 1316 1321 1332 1363 1400 1335 1302 1315 1350 1327 1391 1322 1310 1263 1327 1370 1316 1333 1417 1350 1333 1340 1321 1402 1440 1336 1355 1318 1272 1335 1332 1363 1308 1325 1383 1332 1341 1278 1395 1381 1359 1341 1329 1406 1434 1333 1385 1383 1400 1349 1281 1358 1366 1307 1380 1354 1356 1341 1284 1395 1375 1391 1404 1319 1417 1373 1418 1380 1459 1408 1445 1437 1425 1340 1454 1471 1373 1451 1434 1465 1422 1451 1420 1413 1461 1409 1406 1508 1461 1446 1485 1552 1521 1511 1492 1476 1569 1521 1589 1586 1525 1539 1604 1588 1600 1661 1644 1632 1730 1686 1734 1771 1735 1671 1831 1745 1890 1889 1870 1945 1977 1994 2033 2095 2119 2173 2154 2073 2269 2168 2307 2235 2250 2268 2266 2275 2302 2211 2162 2257 2078 2157 2147 2279 2173 2109 2070 2099 2008 2016 1999 1973 2026 2004 1916 1963 1981 1877 1929 1844 1888 1910 1889 1854 1894 1918 1928 2083 1977 2040 2121 2059 2127 2132 2194 2207 2375 2458 2522 2768 2793 2957 3160 3182 3454 3507 3629 3647 3892 3704 3603 3523 3356 3295 3222 3047 3102 3032 3102 3003 3002 2897 2817 2625 2602 2458 2456 2268 2231 2095 2147 2168 2125 2001 2041 2021 2044 2160 2097 2039 2099 2166 2152 2029 2246 2220 2410 2455 2611 2638 2749 2853 2783 2882 2835 2727 2732 2629 2590 2542 2578 2518 2624 2486 2627 2425 2611 2412 2420 2474 2268 2374 2308 2469 2472 2545 2652 2657 2715 2734 3005 3012 3216 3250 3252 3386 3226 3210 3143 3013 3026 3019 2862 2805 2865 2864 2879 2739 2673 2697 2609 2431 2449 2428 2359 2213 2126 2164 2102 2120 2101 2093 2098 2107 2159 2199 2247 2302 2337 2365 2463 2410 2623 2585 2647 2723 2673 2827 2734 2700 2729 2704 2714 2771 2718 2796 2638 2870 2830 2843 2859 3012 2859 2993 2963 3160 3050 3202 3168 3441 3515 3475 3886 4031 4344 4660 5009 5651 6173 6705 7808 8696 9838 10847 12164 13416 14030 14559 14480 13379 11884 10311 9192 8325 7823 7886 8021 8132 8288 8391 8487 7936 7176 6150 5322 4490 3874 3438 3200 2957 2672 2590 2579 2417 2378 2266 2250 2265 2118 2027 2012 1935 1928 1903 1885 1847 1765 1742 1701 1760 1673 1679 1596 1655 1651 1584 1628 1604 1592 1522 1500 1465 1473 1481 1465 1437 1439 1493 1416 1425 1430 1356 1414 1379 1444 1433 1417 1418 1510 1441 1349 1395 1421 1329 1462 1375 1398 1386 1362 1419 1442 1466 1367 1354 1322 1379 1383 1413 1312 1371 1309 1401 1339 1355 1319 1385 1353 1382 1380 1403 1342 1359 1333 1370 1385 1333 1432 1383 1407 1396 1349 1404 1412 1387 1383 1335 1292 1410 1369 1417 1370 1403 1465 1380 1355 1440 1355 1323 1340 1441 1446 1395 1507 1439 1358 1380 1430 1495 1458 1436 1505 1567 1498 1522 1598 1571 1746 1714 1723 1908 1982 2019 2099 2118 2040 2008 1851 1790 1717 1688 1746 1670 1809 1848 1731 1820 1762 1816 1677 1610 1561 1568 1528 1543 1440 1436 1477 1381 1450 1406 1404 1421 1330 1287 1322 1407 1336 1435 1334 1394 1326 1341 1350 1262 1367 1352 1336 1319 1386 1339 1354 1304 1383 1366 1259 1382 1300 1302 1340 1340 1369 1386 1383 1416 1410 1323 1392 1298 1392 1293 1317 1352 1381 1355 1373 1395 1316 1389 1369 1383 1389 1355 1338 1312 1458 1421 1358 1379 1350 1422 1409 1415 1423 1395 1372 1470 1475 1483 1431 1462 1461 1468 1518 1465 1470 1549 1526 1563 1467 1635 1544 1584 1601 1669 1722 1683 1605 1812 1628 1736 1827 1848 1883 1853 1935 1956 2033 2074 2021 2110 2089 2154 2156 2102 2115 2162 2068 2180 1979 1962 2032 2027 1994 2035 2086 1898 1937 1934 1978 1934 1818 1754 1869 1887 1834 1804 1783 1641 1666 1568 1681 1574 1622 1641 1657 1676 1613 1615 1537 1614 1629 1685 1675 1587 1594 1492 1589 1531 1574 1498 1467 1463 1510 1503 1527 1471 1509 1521 1536 1586 1570 1603 1593 1564 1628 1481 1495 1523 1547 1538 1650 1692 1728 1776 1801 1842 1968 1918 2071 2176 2288 2360 2568 2602 2844 2774 3039 2801 2847 2874 2660 2729 2559 2649 2563 2611 2584 2676 2677 2696 2777 2755 2786 2762 2706 2760 2885 2921 2956 3124 3126 3086 3147 3262 3315 3459 3435 3450 3363 3366 3594 3504 3336 3362 3167 3237 3061 3050 2874 3032 2878 2902 2754 2834 2744 2740 2747 2663 2480 2465 2556 2423 2337 2291 2189 2219 2217 2137 2127 2107 2052 2045 2071 2135 2083 2138 2063 2063 2125 2199 2137 2186 2257 2285 2289 2499 2601 2796 2750 2988 3175 3290 3431 3515 3488 3270 3087 2867 2742 2607 2478 2301 2430 2397 2496 2496 2563 2462 2428 2454 2314 2131 2118 1934 1968 1985 1948 1881 1920 1899 1947 1928 1958 1992 2077 2130 2103 2194 2360 2294 2299 2387 2366 2343 2302 2167 2140 2082 2046 1969 2022 1929 1868 1958 1806 1851 1947 1796 1778 1701 1774 1736 1636 1649 1618 1579 1511 1561 1544 1372 1502 1524 1565 1585 1674 1603 1604 1644 1641 1613 1625 1527 1575 1553 1506 1613 1570 1521 1657 1558 1585 1659 1650 1543 1684 1645 1583 1636 1549 1613 1614 1610 1663 1656 1758 1650 1708 1805 1763 1860 1823 1925 1941 1862 1967 2057 1947 1926 1944 1998 1932 1940 1857 1943 1976 1935 1892 1950 1959 1912 1962 1913 1895 1852 2008 1942 1825 1882 1880 1975 1947 1911 2079 2145 2146 2034 2228 2242 2285 2261 2326 2293 2323 2275 2265 2160 2129 2150 2121 2092 2231 2347 2360 2287 2351 2325 2257 2238 2200 2148 2139 2046 2070 2035 2093 2062 2161 2143 2104 2078 2067 2105 1928 1906 2031 1858 1916 1852 1866 1917 1846 1863 1846 1819 1836 1747 1758 1733 1763 1668 1655 1656 1678 1648 1746 1716 1729 1784 1724 1680 1847 1714 1810 1760 1869 1724 1757 1582 1764 1730 1732 1736 1734 1750 1674 1727 1785 1744 1836 1753 1847 1827 1824 1806 1945 1872 2001 1938 1935 2003 2030 2096 2159 2126 2143 2229 2210 2210 2053 2142 1995 1999 2053 1953 1910 1971 1920 2052 2019 1997 1995 1877 1871 1822 1946 1848 1871 1794 1895 1897 1876 1884 1978 1909 1923 1927 1964 2091 2081 2082 2213 2216 2174 2368 2323 2493 2477 2652 2778 3055 3119 3298 3322 3290 3273 3082 3014 2754 2572 2625 2511 2490 2467 2372 2552 2589 2535 2561 2575 2507 2490 2186 2187 1992 2012 1925 1917 1871 1841 1687 1750 1771 1692 1760 1678 1737 1732 1722 1771 1714 1728 1807 1816 1773 1806 1838 1789 1903 1928 1894 1958 1921 1916 2043 2099 2087 2189 2219 2151 2329 2262 2431 2338 2464 2363 2450 2467 2445 2425 2433 2446 2493 2463 2432 2383 2535 2442 2536 2407 2479 2529 2525 2638 2387 2416 2403 2538 2444 2489 2401 2386 2332 2253 2291 2313 2257 2304 2354 2220 2231 2139 2117 2277 2195 2145 2064 2137 2141 1973 2017 2064 2105 2055 2088 2013 2069 2133 2141 2113 2091 2051 2137 2092 2146 2162 2145 2190 2270 2351 2495 2507 2677 2792 3053 3271 3771 4196 4728 5503 6207 7117 8197 9175 9654 10008 9593 8685 7518 6584 5651 5101 4744 4447 4605 4683 4994 5410 5534 5842 6115 5928 5589 5175 4375 4066 3578 3198 3007 2836 2633 2504 2444 2315 2271 2313 2207 2186 2198 2195 2200 2080 2050 2010 1987 2077 2086 2026 2004 1997 1843 1863 1846 1908 1813 1883 1906 1821 1770 1836 1817 1803 1830 1888 1838 1841 1933 1907 1984 1940 1910 1937 1952 2032 1902 1877 1825 1847 1816 1852 1784 1726 1807 1780 1757 1773 1670 1825 1748 1736 1708 1665 1637 1611 1534 1679 1568 1586 1603 1560 1569 1580 1588 1665 1566 1621 1540 1568 1608 1594 1546 1547 1657 1618 1655 1606 1663 1718 1694 1750 1743 1832 1765 1720 1800 1778 1919 1787 1988 1869 1948 1955 2021 2010 2048 2209 2147 2301 2436 2633 2847 3062 3231 3362 3441 3321 3174 2971 2698 2535 2399 2206 2227 2204 2269 2276 2312 2235 2395 2484 2476 2415 2280 2183 2103 2042 1833 1883 1782 1740 1786 1748 1676 1732 1620 1745 1684 1703 1710 1634 1732 1821 1777 1777 1783 1778 1722 1783 1792 1809 1828 1865 1889 1827 1898 1910 1963 1897 2032 1964 1972 2106 2032 2107 2081 2103 2099 2094 2090 2035 2101 2041 1935 1906 1955 1961 1912 1831 1820 1840 1909 1935 1788 1897 1738 1700 1748 1779 1709 1695 1649 1646 1666 1629 1582 1614 1627 1594 1552 1645 1589 1622 1513 1616 1617 1611 1653 1533 1562 1555 1621 1547 1622 1533 1599 1585 1679 1594 1596 1570 1646 1714 1704 1729 1707 1735 1767 1877 1949 1926 1998 2063 2252 2273 2524 2591 2932 3025 3280 3434 3489 3591 3458 3359 3118 2863 2628 2450 2391 2369 2459 2395 2421 2492 2602 2666 2592 2607 2490 2444 2436 2320 2147 2187 1983 1991 1940 1932 1911 1881 1912 1913 1867 1889 1855 2014 1902 1965 1929 1974 2030 2060 1973 2062 1990 2055 2092 2070 2095 2015 2111 2101 1991 2020 2022 2069 2033 2093 2041 2124 2157 2078 2078 2041 2064 2178 2107 2059 2140 2130 2136 2127 2158 2209 2133 2264 2228 2267 2245 2420 2384 2406 2478 2441 2494 2484 2508 2448 2583 2624 2645 2553 2551 2679 2548 2555 2595 2548 2562 2597 2565 2524 2569 2521 2586 2343 2430 2336 2373 2400 2278 2327 2288 2207 2288 2262 2209 2212 2054 2191 2091 2052 2024 2010 2001 1921 1931 1929 1970 1993 1910 2122 2130 2059 2132 2252 2199 2239 2238 2102 2061 1870 1825 1706 1792 1800 1732 1727 1754 1814 1850 1802 1759 1911 1903 1910 1932 1831 1766 1733 1714 1759 1672 1651 1710 1701 1763 1710 1684 1706 1616 1736 1654 1670 1671 1650 1690 1597 1727 1704 1705 1715 1696 1738 1765 1816 1873 1809 1821 1735 1814 1768 1728 1815 1770 1686 1741 1774 1694 1659 1697 1596 1679 1742 1646 1637 1595 1686 1639 1621 1638 1593 1629 1541 1525 1530 1501 1482 1396 1535 1431 1524 1526 1408 1496 1428 1503 1444 1435 1403 1433 1334 1334 1335 1322 1350 1402 1377 1398 1259 1360 1359 1279 1330 1341 1318 1301 1337 1336 1323 1228 1347 1242 1371 1385 1336 1354 1365 1363 1323 1354 1408 1390 1466 1419 1431 1603 1560 1577 1623 1671 1629 1577 1612 1499 1528 1441 1408 1398 1389 1376 1323 1445 1398 1369 1545 1481 1515 1473 1450 1466 1438 1310 1448 1353 1335 1342 1348 1363 1347 1313 1260 1276 1297 1317 1296 1326 1288 1321 1353 1342 1347 1347 1388 1287 1388 1266 1294 1312 1378 1297 1339 1334 1294 1332 1313 1281 1346 1326 1281 1293 1298 1275 1249 1250 1307 1226 1256 1332 1313 1300 1261 1323 1249 1321 1300 1343 1298 1340 1294 1309 1307 1265 1212 1238 1212 1281 1266 1362 1340 1324 1208 1291 1240 1252 1299 1287 1262 1321 1291 1264 1274 1261 1268 1344 1290 1344 1276 1290 1291 1251 1278 1391 1266 1300 1312 1293 1355 1353 1368 1333 1330 1398 1409 1461 1465 1617 1642 1736 1912 1859 2022 2082 2115 2103 2036 1851 1817 1653 1633 1545 1506 1555 1467 1448 1524 1537 1565 1613 1654 1735 1695 1619 1653 1550 1562 1470 1392 1360 1419 1372 1407 1356 1296 1204 1301 1336 1258 1264 1278 1219 1246 1262 1239 1330 1296 1310 1299 1296 1249 1238 1297 1263 1271 1243 1282 1293 1280 1270 1315 1277 1313 1289 1295 1341 1332 1398 1301 1376 1317 1311 1298 1375 1335 1336 1367 1429 1376 1376 1427 1422 1453 1349 1526 1451 1465 1448 1416 1432 1448 1359 1392 1419 1424 1380 1463 1548 1422 1508 1422 1380 1398 1463 1468 1443 1447 1468 1464 1482 1433 1393 1454 1461 1384 1413 1446 1463 1400 1501 1442 1523 1551 1513 1629 1585 1601 1644 1710 1731 1727 1869 1935 2032 1992 2028 2045 1960 1824 1683 1780 1675 1629 1652 1702 1668 1623 1731 1633 1626 1624 1652 1792 1683 1737 1786 1580 1641 1577 1513 1537 1459 1431 1428 1407 1439 1463 1483 1409 1407 1447 1399 1282 1393 1368 1365 1386 1362 1356 1435 1368 1349 1373 1382 1341 1457 1376 1395 1382 1433 1432 1452 1423 1549 1565 1560 1629 1654 1592 1712 1741 1726 1683 1752 1739 1769 1740 1646 1748 1700 1676 1649 1570 1563 1667 1641 1620 1617 1663 1661 1597 1592 1647 1577 1629 1563 1593 1523 1594 1479 1532 1523 1527 1426 1587 1440 1515 1493 1474 1399 1392 1485 1427 1399 1470 1461 1463 1427 1399 1379 1399 1409 1419 1405 1384 1376 1406 1450 1477 1381 1436 1467 1422 1480 1417 1514 1429 1446 1451 1419 1460 1533 1549 1548 1573 1569 1593 1622 1677 1661 1786 1745 1760 1859 1830 1907 1868 1948 1943 2037 2032 1918 1932 1934 1816 1830 1765 1899 1861 1834 1792 1906 1775 1885 1769 1849 1804 1858 1818 1758 1767 1659 1609 1633 1628 1632 1562 1513 1479 1504 1490 1376 1436 1500 1474 1414 1438 1380 1428 1423 1352 1372 1286 1353 1312 1310 1324 1312 1320 1293 1256 1319 1252 1247 1344 1302 1269 1279 1303 1243 1228 1336 1272 1257 1350 1251 1361 1285 1352 1333 1399 1352 1379 1373 1351 1386 1358 1395 1402 1386 1393 1448 1418 1510 1447 1384 1385 1487 1397 1545 1449 1434 1423 1473 1393 1373 1414 1463 1379 1463 1433 1427 1415 1365 1467 1422 1376 1409 1369 1418 1458 1330 1395 1462 1455 1434 1506 1490 1378 1416 1379 1452 1489 1425 1478 1466 1452 1407 1460 1431 1425 1383 1378 1461 1398 1382 1481 1356 1416 1425 1370 1415 1395 1367 1406 1339 1478 1378 1333 1357 1294 1344 1276 1298 1364 1363 1293 1259 1253 1270 1249 1302 1312 1363 1236 1314 1274 1251 1242 1212 1274 1270 1235 1285 1260 1239 1174 1144 1259 1201 1285 1257 1272 1262 1203 1224 1206 1255 1188 1240 1196 1168 1246 1215 1248 1154 1226 1173 1264 1251 1217 1247 1171 1285 1253 1259 1246 1287 1257 1220 1229 1248 1302 1278 1303 1303 1307 1331 1324 1368 1396 1342 1429 1531 1498 1493 1596 1701 1777 1911 1975 1942 1950 1922 1834 1830 1714 1627 1606 1531 1449 1430 1496 1457 1453 1498 1501 1600 1612 1581 1696 1570 1667 1571 1569 1508 1550 1531 1424 1361 1410 1365 1302 1315 1294 1367 1290 1323 1313 1303 1296 1349 1294 1312 1346 1331 1295 1321 1181 1332 1283 1294 1304 1296 1214 1196 1300 1217 1296 1255 1211 1224 1250 1189 1240 1216 1205 1340 1368 1316 1335 1210 1217 1255 1218 1274 1271 1282 1295 1275 1312 1314 1258 1297 1246 1350 1341 1253 1300 1250 1318 1320 1328 1333 1254 1426 1348 1388 1360 1351 1360 1344 1410 1349 1315 1371 1344 1333 1418 1376 1431 1382 1434 1385 1402 1506 1453 1612 1632 1664 1729 1705 1871 1991 2136 2270 2210 2335 2455 2415 2254 2276 2020 1970 1883 1765 1715 1687 1662 1640 1604 1666 1744 1696 1714 1779 1827 1947 1931 1870 1807 1754 1635 1714 1539 1585 1479 1520 1433 1398 1431 1385 1410 1291 1270 1356 1257 1352 1309 1290 1336 1284 1232 1255 1228 1245 1223 1274 1253 1207 1213 1179 1242 1272 1163 1247 1281 1189 1197 1231 1193 1233 1234 1234 1227 1228 1189 1225 1177 1151 1245 1244 1221 1170 1200 1241 1158 1208 1193 1246 1206 1249 1286 1292 1283 1232 1163 1188 1207 1248 1195 1298 1215 1311 1197 1280 1195 1288 1176 1251 1278 1279 1323 1251 1266 1243 1242 1271 1308 1263 1323 1320 1367 1449 1449 1494 1476 1625 1690 1715 1929 2038 2175 2147 2215 2188 2164 2111 1964 1762 1757 1735 1635 1613 1539 1498 1519 1521 1502 1572 1613 1703 1626 1735 1751 1710 1770 1712 1665 1571 1545 1430 1420 1332 1327 1318 1274 1177 1334 1248 1246 1228 1281 1204 1323 1274 1235 1173 1244 1239 1262 1258 1285 1262 1240 1210 1237 1236 1290 1243 1238 1218 1217 1204 1239 1212 1182 1267 1205 1248 1205 1192 1235 1218 1236 1214 1278 1200 1248 1276 1257 1304 1292 1166 1270 1300 1326 1293 1315 1333 1327 1296 1302 1265 1294 1268 1298 1333 1321 1309 1475 1349 1368 1390 1358 1391 1449 1395 1467 1470 1437 1391 1553 1489 1596 1539 1592 1605 1659 1636 1603 1656 1725 1665 1795 1855 1932 1994 1900 2026 2049 1983 1831 1843 1626 1658 1668 1590 1499 1566 1554 1549 1569 1495 1480 1528 1604 1543 1632 1558 1622 1565 1649 1561 1483 1530 1392 1489 1386 1473 1397 1431 1319 1327 1328 1292 1295 1329 1344 1280 1322 1280 1314 1310 1188 1245 1227 1279 1267 1363 1359 1321 1294 1350 1267 1260 1263 1273 1288 1245 1278 1301 1279 1329 1238 1296 1239 1290 1305 1270 1248 1266 1323 1240 1270 1296 1326 1307 1291 1370 1289 1394 1349 1329 1304 1324 1320 1307 1408 1321 1375 1333 1321 1388 1403 1439 1438 1422 1364 1503 1456 1459 1471 1414 1442 1424 1467 1501 1508 1439 1491 1460 1515 1564 1554 1570 1624 1670 1724 1829 1784 1903 1974 1920 1962 1969 2029 1832 1876 1663 1644 1618 1581 1523 1468 1482 1526 1428 1559 1412 1536 1476 1463 1600 1552 1575 1583 1627 1478 1498 1512 1437 1373 1363 1381 1346 1397 1318 1302 1293 1277 1257 1315 1282 1247 1301 1274 1201 1251 1229 1226 1140 1213 1237 1275 1252 1204 1187 1201 1219 1216 1208 1255 1224 1204 1162 1217 1158 1167 1139 1222 1179 1220 1197 1178 1197 1169 1181 1245 1186 1276 1231 1196 1197 1202 1270 1276 1319 1320 1311 1287 1328 1302 1330 1373 1330 1339 1294 1339 1272 1303 1320 1289 1238 1325 1317 1313 1338 1372 1294 1276 1311 1313 1352 1274 1318 1347 1419 1323 1294 1389 1386 1474 1409 1518 1486 1591 1553 1537 1558 1485 1485 1439 1330 1369 1327 1365 1306 1313 1216 1288 1358 1329 1312 1266 1333 1309 1323 1336 1328 1408 1425 1380 1279 1366 1335 1262 1303 1213 1230 1317 1242 1220 1191 1217 1145 1223 1245 1202 1238 1143 1211 1237 1185 1158 1204 1197 1266 1192 1222 1175 1194 1162 1259 1185 1200 1184 1246 1259 1176 1206 1126 1203 1226 1153 1209 1228 1253 1218 1250 1196 1196 1193 1252 1285 1336 1204 1253 1231 1262 1267 1296 1255 1252 1283 1359 1261 1338 1271 1370 1240 1322 1342 1340 1334 1337 1320 1384 1326 1362 1411 1372 1384 1394 1455 1466 1386 1439 1315 1442 1458 1478 1449 1481 1561 1596 1679 1821 1855 1963 2167 2134 2168 2079 1946 1966 1805 1710 1627 1517 1584 1533 1532 1440 1474 1459 1409 1524 1411 1475 1594 1566 1619 1649 1650 1651 1662 1621 1557 1523 1549 1364 1387 1489 1388 1402 1394 1309 1327 1293 1271 1346 1264 1271 1373 1329 1316 1283 1295 1310 1269 1274 1375 1338 1405 1308 1272 1374 1346 1460 1396 1402 1396 1364 1355 1442 1436 1464 1380 1373 1369 1379 1407 1380 1401 1413 1310 1436 1387 1306 1425 1372 1302 1423 1357 1433 1376 1405 1345 1367 1341 1349 1306 1243 1339 1306 1346 1350 1381 1413 1334 1407 1352 1409 1364 1489 1407 1463 1354 1588 1464 1551 1563 1533 1662 1729 1766 1950 1974 2112 2394 2578 2812 2902 3137 3154 3080 3011 2690 2535 2397 2180 2030 1887 1835 1749 1798 1715 1660 1676 1718 1805 1808 2027 2074 2055 2093 2163 2243 2275 2143 2189 1953 1868 1794 1644 1511 1646 1502 1485 1487 1344 1402 1425 1317 1372 1298 1321 1357 1388 1315 1286 1310 1247 1369 1279 1354 1300 1416 1350 1404 1349 1287 1370 1318 1433 1389 1429 1410 1400 1329 1423 1350 1361 1447 1352 1366 1377 1404 1354 1345 1334 1375 1378 1364 1315 1373 1361 1378 1453 1384 1406 1415 1412 1465 1466 1413 1407 1457 1446 1358 1422 1419 1525 1407 1445 1321 1510 1362 1416 1384 1479 1420 1324 1440 1393 1478 1368 1416 1358 1422 1410 1462 1474 1495 1439 1536 1485 1498 1567 1433 1431 1529 1474 1556 1543 1446 1412 1380 1360 1466 1403 1478 1338 1414 1375 1478 1403 1435 1418 1407 1410 1366 1397 1380 1413 1445 1385 1451 1400 1372 1389 1434 1402 1322 1366 1304 1373 1350 1354 1355 1323 1340 1280 1299 1260 1298 1315 1346 1233 1338 1299 1285 1251 1309 1237 1386 1276 1287 1300 1231 1329 1295 1196 1261 1206 1185 1296 1257 1218 1354 1301 1167 1191 1258 1167 1298 1364 1280 1291 1306 1318 1279 1303 1267 1261 1266 1242 1244 1397 1304 1247 1383 1302 1348 1304 1357 1388 1345 1336 1327 1397 1339 1412 1322 1478 1376 1463 1452 1549 1557 1608 1614 1711 1857 1961 2040 2141 2362 2566 2499 2324 2489 2293 2241 2092 1966 1822 1800 1751 1666 1659 1601 1563 1583 1581 1582 1619 1616 1668 1747 1946 1787 1922 1881 1961 1924 1896 1983 1850 1688 1679 1608 1583 1492 1439 1458 1484 1347 1424 1425 1451 1352 1379 1357 1332 1425 1277 1349 1325 1352 1296 1350 1292 1312 1343 1306 1386 1212 1248 1274 1234 1187 1311 1256 1211 1217 1234 1225 1244 1235 1283 1239 1223 1249 1250 1148 1234 1251 1192 1230 1179 1169 1206 1224 1139 1226 1172 1241 1210 1204 1171 1233 1272 1241 1196 1246 1189 1248 1288 1231 1252 1206 1270 1259 1227 1236 1199 1246 1243 1267 1234 1297 1217 1278 1245 1269 1376 1366 1340 1420 1489 1470 1457 1383 1432 1349 1413 1273 1368 1230 1298 1235 1313 1348 1249 1343 1280 1252 1325 1278 1317 1243 1274 1325 1302 1413 1355 1391 1409 1355 1386 1255 1404 1335 1273 1272 1208 1331 1276 1269 1172 1282 1205 1279 1243 1209 1266 1226 1288 1316 1227 1186 1256 1201 1216 1276 1227 1209 1268 1191 1239 1192 1221 1226 1252 1269 1263 1201 1204 1223 1212 1195 1235 1260 1259 1215 1300 1207 1236 1224 1293 1274 1374 1302 1240 1227 1256 1284 1213 1321 1301 1320 1302 1315 1367 1377 1303 1343 1346 1404 1313 1341 1360 1381 1325 1389 1321 1368 1330 1315 1340 1355 1365 1378 1358 1415 1440 1511 1452 1547 1582 1591 1563 1629 1599 1611 1537 1558 1503 1575 1463 1460 1520 1478 1446 1387 1446 1436 1354 1448 1379 1449 1435 1396 1400 1391 1421 1421 1472 1520 1509 1414 1487 1457 1445 1365 1363 1386 1361 1340 1260 1381 1285 1373 1310 1323 1275 1286 1325 1304 1361 1332 1351 1268 1403 1314 1294 1315 1247 1288 1280 1334 1314 1305 1261 1315 1334 1375 1413 1352 1322 1358 1347 1306 1360 1295 1327 1361 1347 1219 1363 1290 1342 1311 1272 1299 1393 1317 1272 1295 1357 1248 1354 1283 1381 1326 1368 1305 1339 1282 1301 1286 1323 1295 1405 1282 1316 1365 1430 1311 1346 1430 1400 1357 1467 1407 1500 1428 1475 1587 1576 1612 1734 1813 1854 1893 1902 1950 1840 1816 1813 1631 1705 1618 1488 1566 1561 1534 1488 1525 1479 1418 1431 1414 1510 1517 1498 1559 1510 1508 1539 1617 1648 1622 1581 1523 1476 1527 1458 1441 1360 1376 1386 1330 1371 1341 1366 1302 1253 1290 1280 1303 1305 1302 1274 1421 1280 1271 1339 1305 1283 1287 1259 1247 1248 1295 1227 1299 1232 1308 1216 1317 1216 1260 1328 1274 1389 1251 1265 1230 1251 1335 1308 1246 1268 1295 1250 1288 1230 1264 1289 1283 1311 1281 1292 1260 1177 1225 1239 1215 1291 1275 1249 1179 1231 1189 1233 1205 1268 1299 1284 1219 1283 1251 1229 1214 1277 1262 1259 1172 1246 1275 1264 1298 1296 1297 1315 1366 1257 1303 1318 1342 1255 1272 1263 1328 1209 1337 1210 1271 1299 1375 1308 1318 1317 1286 1296 1327 1329 1296 1316 1336 1348 1334 1350 1330 1321 1317 1284 1327 1291 1319 1308 1284 1244 1233 1259 1201 1249 1248 1258 1318 1295 1308 1241 1230 1231 1213 1310 1222 1252 1286 1276 1219 1276 1236 1255 1236 1293 1132 1175 1209 1187 1187 1223 1234 1274 1142 1265 1223 1268 1267 1166 1222 1225 1152 1200 1181 1219 1206 1214 1188 1128 1164 1211 1246 1195 1108 1192 1139 1149 1177 1128 1202 1160 1195 1151 1206 1126 1249 1156 1254 1228 1302 1301 1266 1308 1259 1263 1321 1359 1317 1351 1401 1509 1448 1562 1646 1709 1723 1793 1744 1731 1695 1619 1524 1539 1402 1475 1436 1404 1361 1348 1363 1433 1359 1357 1290 1272 1301 1397 1348 1375 1397 1489 1439 1555 1460 1489 1455 1483 1463 1404 1359 1254 1390 1360 1352 1327 1182 1364 1247 1276 1274 1211 1222 1185 1227 1251 1259 1237 1256 1230 1197 1259 1277 1267 1222 1261 1321 1226 1291 1302 1283 1284 1229 1327 1271 1194 1211 1242 1274 1236 1255 1237 1310 1245 1261 1294 1235 1185 1252 1191 1313 1405 1239 1223 1202 1266 1312 1275 1206 1275 1272 1274 1247 1287 1284 1276 1285 1301 1345 1297 1321 1280 1240 1238 1205 1336 1227 1234 1285 1321 1261 1412 1298 1369 1232 1307 1235 1315 1298 1359 1320 1284 1272 1321 1276 1329 1277 1301 1223 1235 1305 1200 1265 1283 1243 1337 1244 1259 1255 1212 1252 1339 1173 1334 1269 1307 1307 1303 1249 1275 1270 1351 1254 1315 1299 1308 1264 1255 1267 1273 1313 1330 1316 1266 1297 1323 1286 1327 1315 1316 1258 1273 1340 1343 1279 1344 1329 1355 1302 1305 1345 1354 1406 1404 1315 1349 1301 1272 1442 1393 1405 1391 1381 1319 1355 1350 1339 1346 1334 1371 1372 1310 1363 1407 1373 1400 1349 1398 1321 1352 1394 1347 1410 1365 1381 1386 1403 1358 1352 1535 1468 1358 1468 1480 1478 1404 1552 1431 1503 1409 1409 1446 1502 1520 1592 1552 1642 1649 1736 1702 1895 1899 1879 1940 1881 1840 1810 1721 1628 1702 1653 1581 1481 1496 1478 1433 1408 1483 1477 1462 1507 1470 1507 1417 1382 1448 1449 1600 1593 1612 1624 1598 1582 1544 1552 1659 1527 1482 1478 1470 1366 1452 1398 1392 1469 1403 1305 1435 1285 1345 1396 1394 1337 1354 1332 1382 1332 1324 1359 1298 1400 1341 1368 1346 1415 1438 1429 1355 1322 1388 1355 1395 1395 1398 1364 1344 1393 1404 1354 1404 1423 1421 1432 1498 1424 1520 1462 1476 1466 1415 1460 1462 1520 1438 1485 1451 1605 1567 1543 1552 1601 1590 1510 1520 1488 1601 1494 1512 1605 1584 1599 1564 1562 1760 1677 1810 1820 1838 2070 1994 2182 2218 2300 2387 2574 2564 2551 2424 2438 2274 2284 2220 1935 2004 1784 1920 1792 1800 1686 1667 1642 1712 1692 1620 1731 1680 1726 1650 1733 1744 1831 1873 1895 1965 1979 1991 1901 1918 1842 1819 1764 1728 1647 1617 1526 1600 1445 1544 1570 1570 1471 1408 1488 1444 1409 1474 1499 1505 1415 1437 1448 1432 1425 1485 1406 1365 1349 1329 1425 1395 1460 1443 1385 1347 1333 1344 1386 1337 1331 1325 1345 1349 1384 1387 1379 1347 1327 1373 1323 1316 1294 1272 1334 1283 1369 1198 1334 1294 1340 1232 1230 1319 1251 1282 1293 1263 1351 1266 1307 1243 1319 1416 1343 1386 1438 1358 1471 1442 1476 1529 1546 1624 1751 1611 1724 1785 1807 1834 1909 1869 1878 1817 1702 1683 1650 1645 1595 1539 1527 1505 1472 1466 1452 1414 1422 1501 1485 1467 1467 1360 1446 1453 1533 1462 1512 1614 1571 1582 1601 1564 1588 1512 1537 1452 1493 1386 1419 1440 1459 1501 1353 1353 1320 1386 1367 1290 1408 1342 1311 1310 1326 1361 1247 1373 1359 1355 1304 1352 1425 1347 1384 1354 1292 1347 1278 1363 1344 1326 1314 1354 1287 1401 1272 1300 1354 1315 1316 1395 1385 1259 1385 1417 1370 1375 1349 1394 1413 1386 1558 1422 1441 1418 1426 1426 1463 1362 1460 1475 1527 1475 1496 1395 1417 1408 1471 1480 1444 1364 1453 1478 1395 1521 1565 1645 1435 1482 1492 1569 1700 1693 1764 1768 1870 1793 1703 1738 1706 1610 1623 1583 1601 1624 1563 1521 1502 1502 1500 1472 1549 1468 1509 1471 1500 1555 1510 1521 1566 1552 1542 1546 1559 1609 1555 1622 1623 1540 1549 1507 1443 1441 1474 1479 1435 1486 1432 1408 1395 1449 1335 1379 1395 1377 1377 1412 1435 1362 1424 1441 1446 1390 1425 1381 1408 1376 1368 1376 1342 1364 1381 1332 1395 1352 1353 1394 1343 1313 1349 1246 1314 1316 1359 1327 1394 1315 1309 1336</counts>
			</dataPoints>
		</scan>
	</xrdMeasurement>
</xrdMeasurements>