File: dataset/precursor_mixture/Li2CO3_ZrO2_Nb2O5_Ga2O3.2-min.xrdml
<?xml version="1.0"?>
<xrdMeasurements xmlns="http://www.xrdml.com/XRDMeasurement/2.2" xmlns:xsi="http://www.w3.org/2001/XMLSchema-instance" xsi:schemaLocation="http://www.xrdml.com/XRDMeasurement/2.2 http://www.xrdml.com/XRDMeasurement/2.2/XRDMeasurement.xsd" status="Completed" recordIdentifier="{DD82022C-17BD-412C-B6B7-808E0524CF91}">
	<comment>
		<entry/>
	</comment>
	<sample type="To be analyzed">
		<id>dara-31-1</id>
		<name></name>
		<preparedBy></preparedBy>
	</sample>
	<xrdMeasurement measurementType="Scan" status="Completed" sampleMode="Reflection">
		<usedWavelength intended="K-Alpha 1">
			<kAlpha1 unit="Angstrom">1.5405980</kAlpha1>
			<kAlpha2 unit="Angstrom">1.5444260</kAlpha2>
			<kBeta unit="Angstrom">1.3922500</kBeta>
			<ratioKAlpha2KAlpha1>0.5000</ratioKAlpha2KAlpha1>
		</usedWavelength>
		<incidentBeamPath>
			<radius unit="mm">145.00</radius>
			<xRayTube id="1010048" name="Empyrean Cu LFF HR (9430 033 7310x) DK437873">
				<tension unit="kV">40.0</tension>
				<current unit="mA">15.0</current>
				<anodeMaterial>Cu</anodeMaterial>
				<focus type="Line">
					<length unit="mm">12.0</length>
					<width unit="mm">0.4</width>
					<takeOffAngle unit="deg">6.0</takeOffAngle>
				</focus>
			</xRayTube>
			<filter id="20010004" name="Beta-filter Nickel">
				<material>Ni</material>
				<thickness unit="mm">0.020</thickness>
			</filter>
			<sollerSlit id="21010002" name="Soller slits 0.04 rad.">
				<opening unit="rad">0.0400</opening>
			</sollerSlit>
			<mask id="22031000" name="Fixed mask 13 mm">
				<width unit="mm">9.00</width>
			</mask>
			<divergenceSlit id="22120001" name="Divergence slit 1°" xsi:type="fixedDivergenceSlitType">
				<distanceToSample unit="mm">50.00</distanceToSample>
				<height unit="mm">1.52</height>
			</divergenceSlit>
		</incidentBeamPath>
		<beamKnife id="29030100" name="Beam knife low"/>
		<sampleMovement xsi:type="spinningSampleMovementType">
			<spinnerRevolutionTime unit="seconds">1.0</spinnerRevolutionTime>
		</sampleMovement>
		<diffractedBeamPath>
			<radius unit="mm">145.00</radius>
			<antiScatterSlit id="22090040" name="AS slit 9 mm" xsi:type="fixedAntiScatterSlitType">
				<height unit="mm">9.00</height>
			</antiScatterSlit>
			<sollerSlit id="21020003" name="Large Soller slits 0.04 rad.">
				<opening unit="rad">0.0400</opening>
			</sollerSlit>
			<filter id="20030001" name="Large beta-filter Nickel">
				<material>Ni</material>
				<thickness unit="mm">0.020</thickness>
			</filter>
			<detector id="7010019" name="PIXcel1D-Medipix3 detector" xsi:type="rtmsDetectorType">
				<phd unit="keV">
					<lowerLevel>4.0</lowerLevel>
					<upperLevel>11.3</upperLevel>
				</phd>
				<mode>Scanning</mode>
				<activeLength unit="deg">1.021</activeLength>
			</detector>
		</diffractedBeamPath>
		<scan appendNumber="0" mode="Continuous" scanAxis="Gonio" status="Completed">
			<header>
				<startTimeStamp>2024-03-24T12:36:15-07:00</startTimeStamp>
				<endTimeStamp>2024-03-24T12:38:37-07:00</endTimeStamp>
				<author>
					<name>AutomatedUser</name>
				</author>
				<source>
					<applicationSoftware version="1.6 (94)">PANalytical Aeris Instrument Suite</applicationSoftware>
					<instrumentControlSoftware version="3.0.0 20211014">AERIS</instrumentControlSoftware>
					<instrumentID>2879380</instrumentID>
				</source>
			</header>
			<dataPoints>
				<positions axis="2Theta" unit="deg">
					<startPosition>10.02173288</startPosition>
					<endPosition>139.98435528</endPosition>
				</positions>
				<positions axis="Omega" unit="deg">
					<startPosition>5.01086644</startPosition>
					<endPosition>69.99217764</endPosition>
				</positions>
				<commonCountingTime unit="seconds">1.551</commonCountingTime>
				<counts unit="counts">393 377 397 411 373 395 406 395 374 385 384 398 373 357 370 354 346 385 386 352 342 364 395 398 347 346 381 370 353 387 348 357 333 331 323 308 342 317 331 334 315 317 344 306 339 298 323 314 304 316 280 267 331 334 273 292 306 278 285 288 294 296 301 287 307 280 286 305 302 288 314 288 265 309 254 298 299 243 275 316 271 266 276 273 235 264 250 250 275 255 257 234 295 259 261 271 268 255 276 239 225 245 224 295 240 283 250 242 237 245 242 230 234 225 250 229 223 222 257 228 255 210 233 213 242 225 231 254 223 254 246 235 213 252 224 228 229 241 259 231 232 195 208 193 231 231 223 244 243 216 194 235 209 217 210 206 222 241 245 241 267 248 235 241 231 208 236 255 244 264 274 215 203 219 212 190 218 221 195 198 202 202 212 225 208 180 190 182 188 201 200 206 206 216 224 239 224 234 244 262 316 348 344 349 341 270 222 235 212 206 200 169 190 190 192 213 180 189 182 218 213 177 162 195 185 222 160 188 200 194 184 207 195 199 201 189 183 153 198 185 171 178 180 208 198 198 185 198 189 213 171 222 204 224 250 342 420 412 418 509 523 382 261 183 192 187 180 177 197 194 160 187 202 166 188 184 171 216 212 246 247 306 420 627 945 1075 758 434 269 212 220 190 191 177 140 185 181 176 162 189 202 182 192 193 209 191 178 164 174 184 148 163 182 229 241 229 257 259 297 280 223 213 196 192 200 244 233 276 248 168 190 181 170 171 170 153 187 169 220 154 170 165 202 186 166 172 188 156 179 166 191 178 182 148 150 155 141 153 180 182 160 163 180 167 179 152 176 162 199 154 165 187 167 157 144 172 151 176 176 164 170 143 160 166 169 155 167 155 151 184 164 162 182 201 157 203 162 175 204 168 224 181 227 246 241 276 338 465 569 821 1024 1163 1194 1251 1148 918 670 375 283 243 227 211 203 226 242 272 407 530 509 400 267 196 208 204 198 222 218 202 248 185 194 223 212 194 206 164 206 226 212 226 306 322 374 334 370 414 428 493 498 610 801 1039 1513 2319 3561 3183 2147 1118 537 415 361 331 309 292 271 293 272 252 319 313 386 376 525 634 753 830 735 734 716 722 825 828 711 583 462 344 289 251 211 226 224 204 180 188 182 174 194 161 161 195 166 126 197 185 182 146 146 146 170 203 183 210 183 193 168 165 181 183 177 225 186 192 178 178 173 144 177 160 168 197 206 194 235 305 299 312 330 232 284 233 230 240 229 211 179 186 187 192 154 158 193 191 215 213 215 261 291 344 403 414 423 474 603 932 1146 823 719 437 265 184 194 177 186 164 183 168 224 289 418 304 281 177 156 187 183 192 272 398 432 485 350 324 229 152 201 180 185 210 292 317 292 261 243 202 191 170 167 171 183 173 174 155 243 234 291 265 227 211 150 173 164 147 134 148 162 174 192 168 256 252 265 247 226 261 225 212 187 162 167 159 128 143 138 126 133 110 131 130 126 109 137 123 119 145 126 138 152 153 144 132 123 134 186 166 179 160 137 145 111 123 154 126 125 114 116 109 114 115 118 123 163 164 200 196 212 163 171 150 112 116 142 137 165 161 178 181 145 172 154 162 137 124 130 154 132 125 184 240 226 192 210 136 124 120 119 127 136 129 123 117 134 137 125 129 152 127 149 144 156 134 134 141 149 127 122 121 124 135 131 142 144 118 101 123 141 120 127 111 110 125 104 150 147 118 127 105 137 133 100 124 124 134 126 147 116 104 98 145 135 123 136 143 156 154 154 170 177 168 179 178 167 191 163 137 157 133 168 128 149 151 195 201 258 325 409 325 259 313 248 202 203 174 188 267 285 236 237 216 180 145 137 145 118 131 101 115 122 119 110 95 90 103 127 96 124 136 112 104 92 105 122 90 108 117 121 107 99 92 107 116 99 120 134 123 106 118 141 113 122 142 134 151 126 121 146 113 136 129 160 202 201 196 242 192 160 157 163 158 143 159 179 159 199 230 283 327 333 256 254 237 188 173 158 181 203 215 231 209 215 199 238 183 228 267 264 240 261 224 208 190 219 159 229 209 220 251 241 259 259 252 307 375 593 947 1300 925 658 762 521 254 236 201 163 153 150 138 141 144 110 104 110 127 104 123 126 98 133 91 96 119 106 122 120 119 111 109 126 106 104 148 155 122 175 166 140 142 137 118 118 108 125 104 125 126 116 111 117 139 101 85 129 137 120 150 121 108 129 140 131 130 149 173 148 169 219 196 146 155 170 169 145 150 150 133 131 125 140 142 126 130 140 173 185 204 222 234 233 240 229 243 258 300 285 296 267 257 250 213 219 171 167 173 179 193 238 295 282 225 200 240 194 158 157 168 200 223 185 192 154 107 139 111 139 138 156 132 136 137 128 133 146 163 147 153 147 159 160 164 178 174 171 201 174 183 196 211 202 170 201 161 151 148 145 142 123 134 129 156 139 154 138 148 145 169 155 197 157 157 170 167 160 151 147 170 202 227 263 237 198 221 220 173 140 137 142 123 124 173 173 175 174 178 189 194 212 210 205 183 206 181 219 196 190 178 182 163 171 206 254 332 700 892 578 411 455 472 349 235 183 164 172 154 164 161 159 152 163 168 163 141 152 123 145 136 102 112 126 140 138 127 162 142 176 188 284 303 198 197 191 238 179 132 154 154 139 152 152 166 190 149 200 185 198 151 143 177 135 139 122 135 122 130 109 127 159 162 193 230 299 295 226 200 211 213 187 166 149 170 167 172 162 166 153 189 167 182 176 190 198 255 199 230 207 192 200 226 185 183 170 165 167 198 185 159 147 135 137 131 160 149 129 139 128 156 137 135 152 174 129 142 135 121 128 138 141 122 102 104 116 106 92 115 124 127 125 142 126 109 97 133 109 121 99 118 106 98 123 127 91 90 94 108 120 92 110 92 101 94 112 119 96 111 111 104 126 129 161 173 163 133 131 147 131 115 103 98 97 138 99 101 104 91 120 101 100 127 109 133 136 115 110 121 110 114 113 124 140 154 149 172 176 126 147 135 129 132 118 114 135 137 153 97 121 122 153 147 138 141 118 155 129 147 159 148 115 117 127 120 117 109 126 134 118 115 123 164 163 167 162 145 180 174 155 131 131 108 111 134 110 106 114 104 88 110 107 128 113 106 111 122 145 125 129 125 118 117 119 127 103 121 123 137 103 107 104 107 93 88 97 89 99 86 95 94 112 80 109 120 101 112 125 112 122 152 164 118 124 128 146 138 119 116 118 115 83 89 107 107 116 97 92 96 104 109 112 118 98 138 115 122 110 135 147 160 200 196 157 126 155 169 147 118 119 99 130 128 81 81 106 127 110 95 101 90 98 108 93 108 92 113 104 140 139 131 153 165 170 141 115 151 146 145 159 105 121 101 108 95 106 113 129 118 125 105 109 120 111 136 107 115 117 116 132 144 161 165 183 158 131 111 111 136 144 123 109 129 111 124 128 110 123 108 120 96 118 116 101 89 112 120 131 119 110 133 138 151 203 135 124 124 115 115 133 105 114 113 99 96 92 112 103 90 107 98 107 92 104 104 104 111 107 96 103 98 111 119 115 142 98 109 119 106 98 128 115 113 95 114 101 82 88 97 104 115 106 106 122 107 110 113 120 96 111 109 121 124 163 173 143 116 111 111 125 142 132 100 103 96 124 114 93 103 126 119 137 114 135 120 113 125 143 102 108 158 131 148 229 266 234 174 131 142 173 186 187 139 102 106 115 120 95 111 80 125 95 127 128 120 106 120 123 114 123 123 106 113 136 115 127 124 97 113 123 106 137 96 135 127 105 99 136 108 108 114 110 130 73 103 111 152 116 128 79 119 92 129 187 198 194 148 138 126 149 184 133 127 142 106 120 109 102 122 105 82 98 121 107 95 93 105 108 108 111 109 106 100 111 101 130 99 97 116 107 124 110 95 108 114 105 87 100 101 78 95 92 102 105 124 118 100 128 118 119 109 107 122 129 125 127 150 114 102 136 108 113 138 113 94 114 99 89 130 150 95 121 90 106 109 97 93 114 91 125 125 123 118 148 159 156 126 111 126 127 136 114 100 115 101 115 105 107 112 78 96 113 113 114 113 117 110 103 94 107 90 108 96 97 106 110 94 121 100 134 123 107 81 104 110 135 121 98 119 105 102 101 94 101 92 108 109 85 99 100 99 101 117 130 140 151 102 145 116 134 145 128 119 105 103 112 94 89 91 103 105 106 114 89 80 104 114 129 94 87 119 115 110 117 109 98 94 120 112 98 134 122 117 103 86 112 116 99 113 119 100 93 97 116 123 132 134 129 105 112 118 124 138 178 146 143 118 100 109 131 137 127 125 137 124 116 98 123 114 85 128 118 128 83 112 114 100 125 133 113 117 139 163 206 202 171 147 140 138 145 157 163 117 128 126 134 123 137 123 95 104 102 111 118 92 118 120 127 98 108 117 117 158 158 151 143 100 128 132 128 130 132 132 124 112 129 87 90 118 117 101 112 125 107 129 99 127 109 111 115 150 139 120 158 146 148 133 131 142 128 149 131 137 116 125 114 87 112 136 121 87 112 95 119 106 138 147 122 132 113 96 106 107 130 116 143 126 118 97 103 107 111 92 123 112 133 131 134 120 110 125 111 133 120 116 136 128 124 109 130 93 123 121 157 188 185 142 139 119 122 97 121 134 162 114 104 115 91 104 117 86 97 97 114 112 110 112 92 99 123 87 91 135 118 107 131 103 109 102 95 113 111 113 140 108 87 124 112 109 116 111 85 76 99 102 88 89 112 97 109 116 120 126 122 142 181 158 150 125 118 110 118 107 154 149 110 112 111 109 101 93 87 89 99 104 90 101 92 108 108 103 100 104 110 111 124 146 130 115 121 104 107 119 124 135 154 122 120 106 119 111 93 101 96 117 125 103 135 110 120 94 105 96 107 106 86 99 111 130 99 100 109 100 103 117 115 98 87 126 76 90 116 109 89 104 101 99 96 124 111 105 79 100 82 106 104 118 120 135 160 166 143 112 115 97 114 114 98 121 120 150 99 98 105 103 118 114 97 113 106 104 102 111 87 133 101 105 127 109 104 148 174 146 172 145 124 113 135 129 136 166 138 133 128 115 130 137 109 121 129 120 119 122 103 120 127 99 106 109 117 118 101 125 150 147 136 111 120 124 113 143 132 133 168 132 120 123 107 102 109 105 115 120 116 102 111 107 129 126 114 115 119 119 133 149 153 152 147 99 111 104 122 97 122 120 111 126 114 102 94 106 103 106 79 98 63 86 99 81 94 113 85 83 79 104 93 122 121 121 100 91 102 126 93 93 106 99 94 118 97 114 96 86 102 92 116 103 93 97 123 92 82 103 131 104 91 114 112 93 90 90 101 118 103 95 128 93 95 111 88 104 130 99 103 112 121 107 123 92 103 113 99 123 114 115 83 102 114 94 92 102 114 112 109 152 154 149 107 91 124 80 125 110 111 122 117 126 120 91 111 113 120 123 117 115 97 107 113 111 89 100 109 93 111 92 126 122 115 134 128 118 98 108 104 95 92 86 98 102 114 118 125 111 141 129 111 107 91 132 117 98 104 101 109 94 95 124 99 120 103 110 123 125 123 113 116 127 100 90 121 91 117 117 110 120 129 96 106 90 114 121 127 109 109 122 96 104 122 109 103 121 108 94 114 102 139 114 106 120 130 100 88 134 111 89 133 109 115 95 132 120 123 110 111 107 105 113 112 132 126 117 119 109 98 98 107 105 118 118 121 133 148 136 133 149 142 126 133 112 100 110 117 109 125 127 121 121 82 115 109 99 94 110 123 130 91 108 107 116 112 108 141 113 122 114 114 126 104 122 119 116 118 112 106 97 103 107 97 117 109 121 113 112 104 81 110 122 130 106 129 103 124 102 98 140 112 112 111 101 110 123 126 120 124 139 173 159 153 133 143 110 110 113 121 138 102 139 132 115 122 130 136 128 103 125 124 85 128 107 108 128 104 108 116 149 93 119 132 161 122 133 138 147 173 159 167 130 131 127 118 117 129 133 128 115 108 129 147 146 126 136 111 126 127 122 98 91 112 111 90 102 119 103 109 94 127 128 93 88 100 126 111 149 128 126 120 120 92 97 107 71 130 120 126 108 122 113 142 118 116 120 116 94 112 117 129 134 97 102 102 108 121 109 113 122 101 116 122 134 112 122 155 119 125 110 134 120 108 129 113 113 109 115 102 98 134 114 151 85 110 110 137 114 120 107 123 123 109 112 150 121 96 118 135 110 120 116 130 137 137 150 155 199 182 158 136 154 112 128 132 127 134 129 115 140 116 125 161 132 148 150 145 136 146 123 127 121 107 102 106 109 134 131 113 130 122 124 99 111 126 114 134 117 130 148 141 132 148 117 151 123 132 134 127 104 126 141 131 147 151 131 140 125 108 126 134 126 124 122 113 99 104 102 118 132 118 105 104 122 126 105 97 99 112 101 111 122 142 122 161 149 121 103 111 117 126 137 112 92 106 108 135 120 117 123 115 144 87 127 104 110 141 112 134 148 116 115 128 120 110 105 130 103 108 122 141 108 126 131 108 121 132 141 183 172 146 162 137 149 135 151 102 117 143 127 122 123 132 136 133 100 128 150 124 162 151 123 137 136 132 114 113 126 123 121 134 130 134 111 123 120 132 153 127 121 125 160 139 146 117 153 123 137 146 146 113 125 129 161 139 136 131 148 132 129 105 112 126 92 116 136 148 136 124 143 131 123 120</counts>
			</dataPoints>
		</scan>
	</xrdMeasurement>
</xrdMeasurements>