File: dataset/precursor_mixture/Li2CO3_CuO_SnO2_Bi2O3-beta.2-min.xrdml
<?xml version="1.0"?>
<xrdMeasurements xmlns="http://www.xrdml.com/XRDMeasurement/2.2" xmlns:xsi="http://www.w3.org/2001/XMLSchema-instance" xsi:schemaLocation="http://www.xrdml.com/XRDMeasurement/2.2 http://www.xrdml.com/XRDMeasurement/2.2/XRDMeasurement.xsd" status="Completed" recordIdentifier="{5DE276C3-F022-4628-8625-90718388B727}">
	<comment>
		<entry/>
	</comment>
	<sample type="To be analyzed">
		<id>dara-46-1</id>
		<name></name>
		<preparedBy></preparedBy>
	</sample>
	<xrdMeasurement measurementType="Scan" status="Completed" sampleMode="Reflection">
		<usedWavelength intended="K-Alpha 1">
			<kAlpha1 unit="Angstrom">1.5405980</kAlpha1>
			<kAlpha2 unit="Angstrom">1.5444260</kAlpha2>
			<kBeta unit="Angstrom">1.3922500</kBeta>
			<ratioKAlpha2KAlpha1>0.5000</ratioKAlpha2KAlpha1>
		</usedWavelength>
		<incidentBeamPath>
			<radius unit="mm">145.00</radius>
			<xRayTube id="1010048" name="Empyrean Cu LFF HR (9430 033 7310x) DK437873">
				<tension unit="kV">40.0</tension>
				<current unit="mA">15.0</current>
				<anodeMaterial>Cu</anodeMaterial>
				<focus type="Line">
					<length unit="mm">12.0</length>
					<width unit="mm">0.4</width>
					<takeOffAngle unit="deg">6.0</takeOffAngle>
				</focus>
			</xRayTube>
			<filter id="20010004" name="Beta-filter Nickel">
				<material>Ni</material>
				<thickness unit="mm">0.020</thickness>
			</filter>
			<sollerSlit id="21010002" name="Soller slits 0.04 rad.">
				<opening unit="rad">0.0400</opening>
			</sollerSlit>
			<mask id="22031000" name="Fixed mask 13 mm">
				<width unit="mm">9.00</width>
			</mask>
			<divergenceSlit id="22120001" name="Divergence slit 1°" xsi:type="fixedDivergenceSlitType">
				<distanceToSample unit="mm">50.00</distanceToSample>
				<height unit="mm">1.52</height>
			</divergenceSlit>
		</incidentBeamPath>
		<beamKnife id="29030100" name="Beam knife low"/>
		<sampleMovement xsi:type="spinningSampleMovementType">
			<spinnerRevolutionTime unit="seconds">1.0</spinnerRevolutionTime>
		</sampleMovement>
		<diffractedBeamPath>
			<radius unit="mm">145.00</radius>
			<antiScatterSlit id="22090040" name="AS slit 9 mm" xsi:type="fixedAntiScatterSlitType">
				<height unit="mm">9.00</height>
			</antiScatterSlit>
			<sollerSlit id="21020003" name="Large Soller slits 0.04 rad.">
				<opening unit="rad">0.0400</opening>
			</sollerSlit>
			<filter id="20030001" name="Large beta-filter Nickel">
				<material>Ni</material>
				<thickness unit="mm">0.020</thickness>
			</filter>
			<detector id="7010019" name="PIXcel1D-Medipix3 detector" xsi:type="rtmsDetectorType">
				<phd unit="keV">
					<lowerLevel>4.0</lowerLevel>
					<upperLevel>11.3</upperLevel>
				</phd>
				<mode>Scanning</mode>
				<activeLength unit="deg">1.021</activeLength>
			</detector>
		</diffractedBeamPath>
		<scan appendNumber="0" mode="Continuous" scanAxis="Gonio" status="Completed">
			<header>
				<startTimeStamp>2024-03-25T11:15:10-07:00</startTimeStamp>
				<endTimeStamp>2024-03-25T11:17:32-07:00</endTimeStamp>
				<author>
					<name>AutomatedUser</name>
				</author>
				<source>
					<applicationSoftware version="1.6 (94)">PANalytical Aeris Instrument Suite</applicationSoftware>
					<instrumentControlSoftware version="3.0.0 20211014">AERIS</instrumentControlSoftware>
					<instrumentID>2879380</instrumentID>
				</source>
			</header>
			<dataPoints>
				<positions axis="2Theta" unit="deg">
					<startPosition>10.02173288</startPosition>
					<endPosition>139.98435528</endPosition>
				</positions>
				<positions axis="Omega" unit="deg">
					<startPosition>5.01086644</startPosition>
					<endPosition>69.99217764</endPosition>
				</positions>
				<commonCountingTime unit="seconds">1.551</commonCountingTime>
				<counts unit="counts">369 378 383 417 421 380 399 384 384 404 355 396 397 363 390 358 365 394 350 360 404 377 340 381 417 408 411 381 364 374 368 376 348 385 370 367 381 337 347 330 355 349 378 353 377 313 345 299 331 317 333 321 330 322 342 292 322 328 297 318 339 350 292 333 334 332 332 302 337 303 299 307 323 258 294 302 318 291 278 271 297 300 303 301 291 315 262 272 321 300 293 293 260 273 287 261 247 287 261 275 269 288 276 287 268 229 270 248 236 284 244 252 272 260 240 264 244 250 248 252 238 250 272 275 223 258 237 271 237 225 228 267 218 294 241 265 239 263 269 319 298 257 236 224 192 221 213 242 265 256 261 222 236 216 251 226 262 225 242 243 253 211 208 214 225 233 220 236 223 231 210 216 237 191 215 238 209 228 190 226 225 189 217 206 216 178 239 224 234 201 217 193 207 204 192 214 229 214 231 198 236 241 223 215 210 217 224 217 208 211 233 193 213 221 172 208 205 183 203 217 223 211 199 187 188 205 208 163 195 208 187 181 218 208 213 186 199 177 206 188 170 233 183 201 208 197 205 208 204 208 200 211 218 240 308 420 446 305 265 180 165 222 192 201 212 176 195 169 198 180 192 185 189 177 201 179 192 184 198 182 173 160 180 163 183 194 155 200 155 187 189 216 198 201 190 184 163 194 181 193 213 188 186 187 155 153 207 166 185 161 184 177 182 199 193 211 192 183 190 179 186 175 196 170 186 204 180 174 173 186 200 188 179 186 185 200 193 177 185 154 182 209 177 164 189 181 190 186 187 189 199 225 222 297 299 301 237 236 208 194 208 227 218 229 223 258 258 300 364 463 577 749 1178 1710 2051 1713 1124 650 543 371 293 322 277 270 245 270 250 221 252 225 237 286 240 247 248 281 307 326 350 490 653 931 1545 2803 4598 4727 3197 1679 762 469 379 413 313 282 227 231 225 199 209 221 196 205 191 223 189 193 166 185 186 195 220 185 194 179 222 204 191 205 218 209 225 204 178 171 192 154 177 183 189 179 202 207 158 197 241 246 307 316 261 260 222 246 234 281 286 329 214 229 217 164 182 192 175 177 150 199 176 212 212 201 175 192 189 198 217 256 285 438 613 971 1313 1384 999 680 409 321 255 247 222 212 216 171 209 207 221 233 265 341 418 589 926 1388 1237 917 554 342 288 234 220 215 211 171 208 202 185 175 200 203 194 225 251 251 290 362 429 591 900 1296 1592 1364 1014 712 494 384 328 283 234 206 198 202 158 176 159 151 177 194 142 144 139 177 156 158 175 167 166 172 215 185 221 242 252 318 419 539 572 596 550 541 447 326 270 226 206 195 223 228 275 358 405 326 283 192 159 141 147 143 138 160 160 152 155 157 169 158 185 180 165 201 193 167 172 139 161 165 138 137 141 154 149 164 163 166 159 163 182 208 231 266 380 442 511 482 385 281 243 223 231 214 231 221 261 288 293 340 385 480 506 550 511 494 469 386 398 384 298 279 222 214 165 178 152 183 180 160 158 161 171 179 144 157 144 134 137 148 154 169 143 153 124 165 154 162 139 134 118 145 121 144 155 128 135 144 123 126 124 132 137 139 104 117 132 128 126 152 190 199 172 199 189 160 134 137 125 138 143 117 118 132 128 157 154 147 137 143 143 136 132 131 135 141 141 144 124 125 149 164 146 135 145 142 129 113 138 141 138 111 101 137 132 140 137 143 139 171 158 143 123 162 134 112 121 108 105 112 131 132 114 108 126 128 141 128 114 132 138 130 134 135 116 114 142 106 114 138 125 114 129 137 140 133 125 148 169 174 143 154 161 133 146 144 143 136 152 143 150 151 132 149 168 156 214 250 235 353 596 1047 1204 865 784 689 346 229 221 199 211 180 184 197 216 311 489 696 517 448 367 256 201 185 177 145 139 153 145 135 154 112 145 121 149 129 147 124 141 126 117 139 123 122 125 140 128 135 128 147 157 181 177 170 179 210 196 200 218 249 263 232 238 218 176 198 184 132 154 145 144 152 126 135 136 147 126 148 114 131 117 134 125 120 137 126 148 147 141 119 140 129 131 135 119 138 188 127 118 148 129 123 123 143 136 142 137 141 120 130 162 143 186 193 227 282 225 212 233 191 218 235 293 322 437 669 1046 1104 897 772 718 486 361 258 245 186 170 157 170 165 157 155 161 154 161 143 143 121 144 147 125 156 155 136 171 130 128 159 151 109 147 146 148 156 156 184 184 206 212 166 186 177 188 148 143 158 143 178 226 201 234 384 557 646 517 407 460 387 260 244 215 190 282 360 355 302 255 279 275 172 213 168 187 160 203 216 206 311 436 732 1051 767 583 695 618 363 237 220 213 176 141 159 136 131 135 161 138 148 142 120 173 147 137 128 141 120 147 132 143 141 133 121 146 143 124 123 121 163 142 133 138 143 149 157 142 154 183 164 230 240 431 651 553 431 434 433 320 264 224 202 197 176 182 170 183 183 180 167 146 173 170 146 131 128 112 129 136 131 163 150 141 175 150 135 159 161 156 158 155 122 150 147 140 141 161 134 154 148 156 148 131 128 129 133 119 130 131 133 104 128 134 111 135 106 117 139 119 121 127 115 116 103 126 125 121 123 152 149 138 139 120 130 166 173 180 182 215 206 204 207 199 226 248 258 362 311 235 254 277 244 237 180 168 159 165 153 152 142 130 132 131 112 163 139 146 131 135 144 125 121 117 136 134 126 108 100 119 126 119 153 119 135 117 138 127 108 142 116 120 112 114 116 121 126 118 132 120 112 140 131 142 118 136 150 131 201 182 250 295 256 285 242 241 226 213 177 169 131 153 122 135 143 127 156 147 142 160 183 203 179 228 217 236 228 292 376 470 315 272 258 300 284 260 257 264 284 222 205 209 183 161 149 149 140 144 136 138 124 130 142 112 145 144 135 129 140 120 114 115 138 125 130 157 154 148 124 158 143 184 164 151 167 180 146 166 210 167 183 143 150 182 147 206 247 191 158 140 159 150 121 138 109 116 131 123 115 134 129 149 147 129 138 146 124 127 122 114 121 120 95 119 109 135 111 110 118 117 147 134 107 119 95 94 116 133 100 119 119 136 116 105 89 107 118 109 89 122 144 162 139 133 137 150 185 162 223 184 173 175 191 185 164 147 153 139 136 145 127 113 109 121 113 123 104 127 110 140 137 138 134 146 143 134 142 109 132 126 136 124 126 131 113 123 127 118 110 127 114 134 99 103 122 117 110 119 132 120 138 124 120 86 123 149 127 141 143 120 154 143 135 104 131 152 132 169 189 223 313 475 358 259 216 270 312 231 204 142 181 187 152 147 169 161 138 156 171 159 176 152 177 215 269 230 211 181 180 203 203 190 183 245 305 205 152 161 174 203 193 154 141 114 124 105 98 119 136 147 150 146 120 132 134 148 138 150 119 130 141 114 122 124 141 129 147 215 229 215 129 163 175 167 188 150 137 133 200 230 227 167 156 180 182 171 171 147 133 134 148 158 138 189 196 250 244 210 162 189 192 217 193 192 157 113 137 123 124 125 124 124 117 110 124 123 135 122 135 117 115 106 107 106 125 120 131 102 129 125 113 134 114 131 105 126 114 145 122 136 130 130 111 124 116 98 117 131 140 150 162 141 153 133 170 163 114 149 129 133 143 121 152 137 134 127 136 124 111 114 103 133 115 103 129 105 136 126 140 137 97 132 123 138 133 112 112 105 132 134 153 121 132 146 119 141 124 161 140 149 145 135 150 174 140 156 172 216 218 241 167 147 163 176 157 160 173 147 135 125 124 117 104 117 108 110 117 123 111 123 124 136 137 129 122 145 140 145 113 135 170 229 170 137 141 137 165 170 170 151 172 130 120 104 103 125 168 155 166 129 123 134 131 144 125 138 132 142 136 160 138 144 179 200 269 255 183 170 140 185 244 213 183 143 148 155 125 162 158 137 153 148 137 152 149 134 138 127 114 124 145 142 116 119 102 103 134 119 125 113 127 108 98 120 116 108 133 100 114 100 126 127 106 112 117 112 120 95 127 119 132 119 130 130 122 134 116 134 126 139 161 151 191 203 206 218 214 171 162 170 177 187 149 176 153 143 140 119 128 146 128 147 135 133 133 147 166 211 268 287 288 229 197 184 191 228 194 211 162 154 156 133 136 117 131 122 128 114 131 130 124 115 114 139 114 121 110 115 111 128 144 157 135 128 133 129 142 142 136 145 142 119 157 173 175 144 138 113 128 168 134 149 162 167 198 147 142 175 126 133 164 171 163 148 161 191 244 199 186 168 160 194 179 173 148 156 127 126 125 124 108 116 135 97 112 115 134 112 117 95 116 113 115 123 117 122 105 129 130 141 138 162 123 125 123 133 114 155 133 138 149 133 126 158 141 170 157 133 123 143 134 126 129 118 129 112 109 112 130 129 109 108 110 132 112 127 123 111 123 128 96 130 123 122 122 134 114 108 116 117 123 107 122 108 115 97 128 95 109 128 129 117 94 113 109 95 107 107 124 108 122 137 120 125 121 126 108 114 120 121 128 114 116 111 105 139 150 121 129 112 100 118 122 112 122 117 119 121 117 113 128 111 130 121 110 114 114 111 129 111 105 125 135 111 103 102 129 102 115 115 137 111 102 108 118 131 113 112 114 105 117 119 107 113 106 89 108 95 109 110 84 127 125 113 130 106 122 131 118 108 129 112 116 116 110 105 118 106 116 117 127 99 108 152 122 134 130 119 121 112 116 134 110 123 125 128 162 134 122 135 140 195 178 157 159 161 143 154 126 140 144 158 146 113 115 135 121 115 123 136 106 112 86 129 125 121 140 121 136 124 119 118 116 119 98 99 99 101 125 112 132 109 98 113 118 129 129 138 143 123 144 121 136 112 111 125 147 124 144 134 126 108 87 114 127 131 135 145 113 116 115 123 112 116 119 125 121 125 120 116 128 113 117 121 126 133 116 113 135 122 112 117 107 148 146 108 124 141 117 111 125 122 124 136 136 129 153 145 160 162 152 192 213 201 199 242 205 152 184 183 180 184 175 198 185 169 187 168 163 132 168 160 175 197 209 269 236 187 194 188 143 161 153 149 190 190 194 154 146 112 141 137 132 139 115 156 149 148 157 150 154 143 137 132 121 127 144 153 131 130 118 138 123 129 125 127 135 160 142 115 142 151 185 214 206 182 171 183 153 148 176 171 203 190 182 168 172 166 151 143 155 132 162 163 165 176 195 240 160 153 140 172 148 153 166 203 213 241 236 165 170 181 175 158 143 153 170 164 152 148 127 147 150 125 144 144 149 134 144 130 148 122 127 118 137 115 154 112 147 148 151 157 159 165 180 183 189 193 167 171 157 167 144 159 187 182 191 187 179 144 146 133 132 166 167 166 152 142 149 157 164 162 216 218 231 253 224 212 189 179 174 203 171 196 204 192 196 178 167 163 141 150 145 130 156 129 137 129 136 136 131 128 131 122 122 119 129 141 121 136 105 127 109 129 109 139 102 127 114 125 115 119 124 112 109 129 131 128 140 89 99 130 105 115 114 131 115 100 146 129 121 128 128 119 129 136 138 116 139 141 172 155 128 144 114 123 122 149 134 136 142 119 126 145 121 127 121 151 157 147 136 162 153 156 174 163 145 155 129 160 147 148 141 131 158 144 158 160 153 137 125 123 143 144 116 149 145 153 155 171 192 222 224 216 195 199 176 196 204 178 192 158 179 212 178 147 179 186 154 167 134 126 154 126 125 147 123 154 118 146 135 139 119 131 115 126 119 125 149 117 92 129 127 116 98 127 98 121 123 122 128 124 136 110 129 116 132 124 110 112 95 123 129 118 101 134 119 126 122 120 122 117 110 133 127 143 127 127 154 144 137 130 130 131 130 132 152 124 126 141 172 145 143 157 146 146 131 117 131 127 111 133 139 129 150 151 158 130 136 131 141 128 130 127 124 107 130 121 111 148 104 118 128 123 136 161 143 142 112 138 136 131 153 110 137 118 128 138 127 136 139 143 142 116 157 142 136 127 132 105 127 121 137 149 136 146 149 160 149 140 146 145 121 122 124 122 144 134 118 117 128 144 160 135 139 130 128 151 134 124 119 126 172 135 103 125 161 137 103 129 115 142 123 141 154 146 155 160 220 226 205 191 257 261 215 191 151 149 170 168 178 182 142 160 181 204 201 191 173 178 173 169 133 167 173 169 172 169 168 172 158 153 161 135 168 153 138 125 151 137 140 159 164 146 161 142 136 130 127 155 152 153 173 136 145 167 167 167 173 193 169 202 168 156 150 132 134 173 151 158 157 154 166 179 196 195 163 160 135 149 166 139 123 142 139 129 157 130 142 148 149 144 141 156 138 140 137 130 132 111 115 125 147 130 115 106 121 140 109 121 140 133 124 139 97 123 126 122 119 127 120 123 122 138 129 136 142 136 152 154 128 127 101 118 102 125 164 131 137 151 123 131 136 121 139 146 143 132 152 161 168 157 182 168 177 165 144 164 154 173 183 186 191 191 165 210 162 185 151 179 176 163 156 143 179 145 172 171 162 181 173 142 160 152 147 126 127 148 131 129 142 148 135 136 139 137 126 150 109 133 109 108 135 132 138 124 128 139 138 125 159 150 100 118 117 132 129 148 125 133 144 105 138 125 130 117 150 127 127 142 138 119 122 147 136 112 131 96 130 138 117 141 96 134 144 144 118 128 116 110 132 157 141 133 144 116 128 117 138 123 151 153 143 153 145 131 113 131 114 125 124 124 141 149 144 132 127 136 133 136</counts>
			</dataPoints>
		</scan>
	</xrdMeasurement>
</xrdMeasurements>