File: dataset/precursor_mixture/Li2TiO3_CaCO3_Li3PO4.12-min.xrdml
<?xml version="1.0"?>
<xrdMeasurements xmlns="http://www.xrdml.com/XRDMeasurement/2.2" xmlns:xsi="http://www.w3.org/2001/XMLSchema-instance" xsi:schemaLocation="http://www.xrdml.com/XRDMeasurement/2.2 http://www.xrdml.com/XRDMeasurement/2.2/XRDMeasurement.xsd" status="Completed" recordIdentifier="{8A23EBE7-0844-424B-BA89-EEDB3DB62442}">
	<comment>
		<entry/>
	</comment>
	<sample type="To be analyzed">
		<id>dara-34-2</id>
		<name></name>
		<preparedBy></preparedBy>
	</sample>
	<xrdMeasurement measurementType="Scan" status="Completed" sampleMode="Reflection">
		<usedWavelength intended="K-Alpha 1">
			<kAlpha1 unit="Angstrom">1.5405980</kAlpha1>
			<kAlpha2 unit="Angstrom">1.5444260</kAlpha2>
			<kBeta unit="Angstrom">1.3922500</kBeta>
			<ratioKAlpha2KAlpha1>0.5000</ratioKAlpha2KAlpha1>
		</usedWavelength>
		<incidentBeamPath>
			<radius unit="mm">145.00</radius>
			<xRayTube id="1010048" name="Empyrean Cu LFF HR (9430 033 7310x) DK430614">
				<tension unit="kV">40.0</tension>
				<current unit="mA">15.0</current>
				<anodeMaterial>Cu</anodeMaterial>
				<focus type="Line">
					<length unit="mm">12.0</length>
					<width unit="mm">0.4</width>
					<takeOffAngle unit="deg">6.0</takeOffAngle>
				</focus>
			</xRayTube>
			<filter id="20010004" name="Beta-filter Nickel">
				<material>Ni</material>
				<thickness unit="mm">0.020</thickness>
			</filter>
			<sollerSlit id="21010002" name="Soller slits 0.04 rad.">
				<opening unit="rad">0.0400</opening>
			</sollerSlit>
			<mask id="22031000" name="Fixed mask 13 mm">
				<width unit="mm">9.00</width>
			</mask>
			<divergenceSlit id="22120001" name="Divergence slit 1°" xsi:type="fixedDivergenceSlitType">
				<distanceToSample unit="mm">50.00</distanceToSample>
				<height unit="mm">1.52</height>
			</divergenceSlit>
		</incidentBeamPath>
		<beamKnife id="29030100" name="Beam knife low"/>
		<sampleMovement xsi:type="spinningSampleMovementType">
			<spinnerRevolutionTime unit="seconds">1.0</spinnerRevolutionTime>
		</sampleMovement>
		<diffractedBeamPath>
			<radius unit="mm">145.00</radius>
			<antiScatterSlit id="22090040" name="AS slit 9 mm" xsi:type="fixedAntiScatterSlitType">
				<height unit="mm">9.00</height>
			</antiScatterSlit>
			<sollerSlit id="21020003" name="Large Soller slits 0.04 rad.">
				<opening unit="rad">0.0400</opening>
			</sollerSlit>
			<filter id="20030001" name="Large beta-filter Nickel">
				<material>Ni</material>
				<thickness unit="mm">0.020</thickness>
			</filter>
			<detector id="7010019" name="PIXcel1D-Medipix3 detector" xsi:type="rtmsDetectorType">
				<phd unit="keV">
					<lowerLevel>4.0</lowerLevel>
					<upperLevel>11.3</upperLevel>
				</phd>
				<mode>Scanning</mode>
				<activeLength unit="deg">5.020</activeLength>
			</detector>
		</diffractedBeamPath>
		<scan appendNumber="0" mode="Continuous" scanAxis="Gonio" status="Completed">
			<header>
				<startTimeStamp>2024-02-18T12:54:49-08:00</startTimeStamp>
				<endTimeStamp>2024-02-18T13:07:17-08:00</endTimeStamp>
				<author>
					<name>AutomatedUser</name>
				</author>
				<source>
					<applicationSoftware version="1.4b (28)">PANalytical Aeris Instrument Suite</applicationSoftware>
					<instrumentControlSoftware version="2.0.0 20210224">AERIS</instrumentControlSoftware>
					<instrumentID>950485</instrumentID>
				</source>
			</header>
			<dataPoints>
				<positions axis="2Theta" unit="deg">
					<startPosition>9.99043322</startPosition>
					<endPosition>100.09495370</endPosition>
				</positions>
				<positions axis="Omega" unit="deg">
					<startPosition>4.99521661</startPosition>
					<endPosition>50.04747685</endPosition>
				</positions>
				<commonCountingTime unit="seconds">18.249</commonCountingTime>
				<counts unit="counts">3751 3787 3808 3763 3657 3788 3680 3733 3668 3729 3711 3636 3658 3751 3700 3683 3626 3699 3537 3726 3664 3654 3560 3592 3640 3577 3638 3440 3561 3596 3637 3568 3655 3684 3530 3596 3594 3482 3622 3563 3563 3621 3554 3532 3498 3522 3427 3488 3398 3476 3451 3509 3490 3439 3515 3517 3467 3435 3477 3440 3378 3310 3496 3436 3415 3420 3466 3341 3296 3267 3401 3450 3430 3502 3325 3469 3492 3413 3433 3301 3349 3301 3371 3412 3324 3396 3285 3352 3304 3387 3318 3365 3280 3360 3391 3366 3241 3222 3320 3305 3257 3304 3321 3222 3224 3206 3311 3239 3144 3323 3311 3221 3204 3296 3204 3291 3305 3298 3186 3155 3171 3185 3280 3127 3287 3216 3203 3010 3135 3109 3188 3201 3242 3264 3183 3293 3198 3179 3124 3208 3112 3178 3033 3267 3180 3116 3220 3084 2992 3093 3149 3015 3132 2984 3144 3098 3143 3093 3026 2953 2969 3119 2887 3007 3001 3008 2954 3169 3002 3028 2953 3040 2976 3061 3054 2937 2982 3020 2912 3015 2937 3145 2828 3007 3035 2900 2918 2849 2906 2923 2927 2932 2899 2942 2926 2945 2932 2861 2919 2942 2971 2866 2858 2859 2916 2884 2902 2821 2942 2879 2818 2904 2875 2806 2944 2902 2747 2905 2900 2789 2851 2873 2875 2767 2782 2774 2855 2872 2785 2887 2829 2778 2870 2834 2796 2899 2834 2745 2763 2769 2781 2825 2775 2763 2707 2807 2792 2724 2799 2755 2747 2819 2801 2715 2617 2811 2741 2820 2720 2766 2718 2701 2725 2651 2618 2797 2598 2653 2674 2696 2705 2579 2618 2697 2696 2613 2630 2678 2716 2632 2532 2611 2633 2668 2656 2728 2592 2683 2485 2574 2668 2543 2536 2706 2605 2569 2642 2699 2660 2536 2633 2616 2597 2660 2553 2654 2514 2611 2693 2607 2607 2576 2681 2623 2602 2599 2550 2509 2581 2577 2425 2516 2540 2491 2566 2594 2610 2495 2568 2501 2445 2591 2487 2527 2558 2507 2597 2468 2502 2526 2489 2501 2420 2411 2474 2516 2425 2493 2491 2536 2483 2460 2423 2338 2446 2375 2410 2460 2451 2487 2483 2473 2365 2362 2508 2467 2505 2414 2479 2452 2494 2438 2500 2468 2370 2504 2419 2430 2507 2423 2408 2485 2445 2434 2375 2298 2423 2342 2483 2420 2397 2471 2432 2374 2390 2355 2379 2302 2366 2381 2400 2475 2360 2419 2386 2439 2402 2367 2434 2512 2401 2412 2404 2444 2372 2392 2364 2349 2331 2356 2315 2371 2408 2320 2529 2384 2434 2366 2321 2387 2330 2337 2369 2301 2467 2307 2305 2336 2350 2297 2368 2281 2412 2295 2396 2433 2284 2398 2333 2359 2379 2312 2305 2336 2251 2336 2272 2255 2311 2287 2290 2251 2260 2310 2192 2301 2357 2323 2285 2405 2310 2287 2244 2294 2323 2193 2277 2350 2387 2201 2338 2364 2327 2256 2294 2272 2286 2251 2208 2156 2344 2297 2222 2265 2282 2173 2251 2283 2290 2265 2333 2302 2229 2139 2307 2331 2215 2268 2254 2306 2225 2270 2271 2195 2151 2205 2184 2256 2133 2155 2262 2113 2252 2301 2155 2270 2231 2230 2220 2244 2175 2318 2188 2150 2219 2219 2276 2201 2232 2270 2199 2248 2281 2170 2148 2179 2208 2146 2189 2197 2124 2149 2294 2250 2237 2210 2236 2146 2151 2216 2221 2170 2183 2187 2200 2165 2176 2269 2313 2238 2186 2191 2197 2304 2102 2128 2181 2254 2182 2182 2204 2306 2214 2275 2186 2222 2156 2210 2282 2232 2259 2250 2282 2196 2255 2324 2279 2182 2280 2234 2214 2298 2271 2310 2313 2263 2250 2349 2295 2446 2366 2372 2292 2328 2402 2390 2384 2404 2406 2558 2625 2523 2559 2770 2636 2743 2801 2792 2821 3080 3018 3111 3013 3159 3181 3236 3312 3272 3292 3344 3371 3267 3259 3150 3173 3037 2898 2791 2654 2584 2535 2565 2462 2418 2468 2405 2278 2442 2210 2253 2175 2204 2283 2080 2161 2189 2165 2089 2199 2141 2126 2085 2160 2215 2229 2039 2102 2163 2195 2143 2155 2115 2030 2095 2166 2189 2055 2155 2251 2096 2054 2168 2091 2061 2132 2145 2169 2081 2082 2077 2069 2081 2061 2073 2119 2177 2194 2127 2019 2149 2037 2150 2096 2127 2122 2132 2128 2145 2134 2174 2116 2132 2103 2154 2144 2201 2042 2183 2182 2166 2141 2087 2053 2164 2183 2212 2113 2145 2209 2223 2192 2194 2231 2196 2159 2198 2226 2214 2354 2303 2288 2302 2311 2298 2327 2346 2422 2436 2484 2604 2558 2531 2645 2634 2661 2646 2681 2758 2809 2707 2914 2876 2874 2953 3067 3109 3024 3143 3021 3028 3146 3052 3032 2962 2988 2909 2967 2850 2897 2732 2724 2723 2560 2617 2524 2607 2466 2441 2381 2332 2296 2290 2330 2301 2269 2176 2265 2219 2124 2112 2126 2197 2078 2098 2270 2089 2135 2112 2036 2032 1970 2025 2036 2075 1985 2125 2032 1962 2039 2055 1994 1975 1941 1998 2005 1984 1970 1991 1942 2025 1859 1955 2008 1925 1885 1956 1889 1959 1911 1858 1916 1895 1917 2027 1898 1913 1842 1967 1901 1885 1933 2006 1894 1877 1888 1864 1872 1871 1884 1845 1969 1846 1877 1919 1881 1889 1905 1950 1949 1906 1888 1942 1902 1894 1854 1876 1933 1945 1933 1846 1830 1943 1884 1887 1823 1963 1879 1868 1850 1907 1947 1850 1929 1973 1877 1982 1956 1893 1854 1937 1951 1856 1999 1909 1829 1928 1999 1938 1922 1979 1895 2051 1966 1989 1991 2025 1952 1984 1958 1963 1982 1984 1964 2028 1969 2022 2047 2013 2023 1975 1997 2053 2006 2050 1984 2031 2023 2128 2017 2078 2044 2023 2045 1935 2028 1984 2093 1925 2029 1950 1954 1945 1915 2032 2033 1930 1913 1900 1946 2017 1881 1955 1942 1914 1951 1956 1905 1857 1974 1917 1928 1803 1909 1805 1986 1905 1901 1778 1792 1804 1859 1887 1868 1895 1935 1848 1847 1918 1826 1876 1877 1843 1869 1863 1908 1882 1885 1805 1881 1861 1843 1804 1896 1868 1852 1832 1815 1752 1913 1786 1800 1828 1830 1871 1829 1815 1819 1871 1832 1794 1855 1763 1827 1799 1825 1760 1834 1811 1814 1881 1772 1777 1902 1771 1834 1786 1846 1820 1835 1773 1872 1799 1817 1745 1842 1748 1778 1837 1813 1757 1740 1784 1808 1787 1842 1802 1827 1751 1770 1764 1785 1858 1791 1822 1856 1891 1821 1889 1825 1854 1822 1851 1837 1808 1878 1867 1901 1876 1862 1872 1875 1900 1952 1903 1941 1977 1961 1959 1986 1994 2109 2119 2117 2024 2247 2103 2225 2168 2295 2404 2398 2412 2473 2520 2600 2774 2833 3132 3044 3292 3360 3470 3591 3964 3858 4198 4477 4588 4992 5112 5437 5794 6004 6110 6359 6549 6528 6657 6671 6556 6287 6084 5853 5348 5116 4793 4334 4126 3850 3555 3396 3151 3088 2905 2761 2588 2625 2476 2397 2417 2435 2296 2346 2123 2229 2131 2098 2097 2103 2075 2076 2084 2018 2022 2006 2127 1979 2045 2086 2048 2060 2132 2122 2123 2172 2148 2265 2341 2258 2339 2413 2571 2643 2732 2874 2953 2876 3226 3462 3518 3733 4025 4163 4242 4353 4481 4461 4550 4494 4634 4580 4624 4555 4618 4783 4807 4898 4952 5040 4881 4963 4866 4744 4707 4720 4598 4642 4629 4434 4634 4559 4553 4541 4425 4589 4322 4227 4199 4112 3685 3701 3335 3265 2970 2822 2698 2498 2320 2247 2221 2084 2079 2008 2002 1885 1965 1916 1844 1794 1733 1880 1798 1830 1742 1717 1709 1670 1668 1719 1729 1655 1654 1704 1640 1639 1593 1558 1631 1667 1635 1591 1619 1614 1596 1596 1618 1498 1617 1612 1624 1503 1548 1608 1508 1535 1591 1542 1524 1551 1500 1516 1571 1541 1458 1670 1436 1486 1567 1634 1557 1576 1515 1563 1558 1601 1549 1609 1550 1572 1592 1555 1572 1590 1639 1655 1675 1610 1719 1704 1579 1693 1595 1717 1719 1706 1695 1659 1779 1806 1833 1776 1844 1953 1847 1909 1875 1928 2011 2005 2025 2164 2202 2238 2403 2325 2418 2536 2635 2735 2832 2736 2934 2969 3144 3148 3280 3184 3224 3187 3275 3425 3332 3173 3163 3197 3187 3142 3187 3097 3112 3186 3057 2975 3020 2956 2867 2750 2761 2736 2444 2515 2359 2266 2158 2074 1992 2005 1905 1937 1917 1905 1841 1870 1938 1922 1897 1839 1899 1959 1927 2001 1988 2021 1996 2026 1899 2053 1954 1907 1934 1822 1772 1761 1702 1722 1586 1633 1565 1567 1564 1530 1533 1511 1425 1461 1403 1537 1449 1387 1381 1408 1323 1442 1351 1375 1420 1362 1364 1342 1280 1309 1385 1326 1337 1263 1312 1315 1282 1325 1242 1245 1253 1308 1336 1309 1334 1285 1280 1276 1329 1258 1280 1277 1251 1245 1236 1329 1271 1307 1304 1281 1275 1262 1284 1242 1217 1314 1270 1244 1276 1318 1257 1279 1234 1272 1250 1228 1250 1225 1242 1237 1283 1294 1220 1208 1238 1235 1258 1245 1243 1314 1285 1293 1248 1280 1291 1386 1460 1369 1432 1597 1551 1550 1530 1560 1482 1403 1398 1288 1260 1227 1237 1220 1181 1263 1224 1226 1210 1205 1255 1197 1187 1234 1217 1183 1259 1185 1211 1212 1250 1172 1219 1124 1247 1176 1256 1150 1166 1185 1205 1160 1144 1154 1199 1214 1143 1202 1208 1246 1146 1206 1128 1198 1130 1231 1199 1196 1169 1186 1177 1143 1116 1185 1095 1151 1211 1218 1145 1154 1120 1159 1186 1216 1141 1186 1197 1177 1190 1144 1186 1110 1089 1148 1173 1159 1145 1088 1120 1117 1052 1120 1152 1147 1140 1165 1129 1068 1115 1131 1089 1145 1107 1166 1268 1127 1145 1118 1143 1123 1082 1129 1164 1177 1104 1124 1104 1068 1156 1175 1116 1108 1113 1139 1179 1083 1135 1105 1201 1176 1117 1174 1114 1111 1101 1139 1126 1152 1121 1035 1122 1087 1163 1061 1154 1123 1180 1112 1154 1136 1176 1181 1121 1154 1148 1161 1181 1142 1142 1187 1132 1222 1181 1139 1223 1162 1123 1197 1305 1269 1270 1305 1360 1387 1385 1484 1443 1641 1597 1594 1691 1678 1724 1697 1751 1645 1722 1723 1704 1746 1736 1698 1733 1734 1710 1757 1740 1801 1837 1837 1896 1884 1924 1889 1955 1953 2013 2073 2039 2156 2265 2216 2265 2242 2516 2481 2634 2635 2718 2761 2942 2950 3056 3190 3336 3311 3305 3403 3541 3601 3556 3697 3791 3746 3983 3984 4035 4039 4066 4173 4304 4446 4678 4906 5142 5310 5900 6168 6755 7240 8084 8869 10212 11637 13531 15802 18374 21732 25897 31113 37573 44748 54269 64542 78403 93073 111813 130885 152132 164354 165110 148284 127801 105720 94535 88932 84267 77011 63949 47593 33419 22544 15293 11232 8779 7464 6630 5928 5474 5144 4615 4593 4392 4189 4075 3755 3671 3619 3577 3366 3261 3162 2950 2857 2789 2643 2506 2387 2257 2201 2058 2114 1973 2023 1735 1900 1780 1791 1741 1685 1740 1689 1708 1684 1701 1728 1733 1632 1661 1626 1631 1541 1671 1553 1625 1498 1616 1569 1547 1572 1548 1503 1480 1452 1456 1475 1482 1496 1512 1450 1454 1420 1494 1423 1417 1390 1462 1432 1380 1369 1419 1428 1424 1360 1379 1410 1344 1345 1349 1362 1368 1404 1414 1329 1329 1363 1299 1330 1356 1268 1245 1332 1298 1329 1334 1244 1302 1251 1348 1327 1245 1248 1243 1328 1275 1225 1239 1249 1257 1283 1268 1252 1216 1154 1278 1328 1200 1224 1240 1236 1243 1191 1195 1255 1238 1188 1241 1243 1204 1162 1156 1233 1210 1238 1159 1199 1204 1194 1207 1239 1253 1171 1202 1148 1213 1197 1204 1255 1236 1237 1297 1268 1355 1329 1378 1477 1503 1493 1684 1598 1764 1835 1970 2025 2049 2130 2181 2119 1942 1810 1846 1750 1718 1604 1572 1527 1396 1326 1193 1150 1193 1222 1242 1226 1198 1175 1245 1175 1218 1160 1226 1148 1233 1168 1239 1175 1197 1165 1191 1177 1261 1179 1099 1189 1196 1153 1089 1126 1107 1219 1160 1177 1140 1245 1160 1087 1187 1148 1151 1161 1108 1113 1124 1167 1186 1201 1184 1130 1227 1131 1129 1186 1116 1088 1163 1193 1128 1107 1131 1109 1074 1124 1077 1046 1148 1092 1092 1046 1086 1177 1089 1018 1103 1126 1083 1035 1042 1094 1059 1004 1040 1073 1097 1060 1024 1028 1094 1079 1052 1049 995 1116 1033 1079 1076 1035 1049 1075 1071 1041 1021 972 1025 1086 1032 1004 1114 1039 1064 1110 986 1122 1081 1038 1128 1047 1019 1001 1062 1057 1036 1037 1000 1026 1023 1004 1012 992 1045 1032 1033 1067 1000 1002 1102 1021 1034 1051 1022 997 1015 1062 1060 974 994 1036 1070 984 1105 1063 1055 1039 1067 1097 1043 1078 1130 1096 1027 1082 1131 1107 1167 1043 1167 1118 1093 1166 1105 1132 1124 1166 1185 1127 1208 1203 1221 1265 1334 1314 1399 1390 1455 1366 1438 1394 1407 1445 1444 1514 1564 1631 1628 1636 1748 1780 1785 2007 2010 2088 2211 2287 2489 2581 2757 2904 3081 3269 3406 3697 3789 3986 4165 4341 4380 4456 4487 4323 4268 4124 3977 3896 3613 3708 3558 3283 3153 3143 3002 2965 2929 2845 2820 2741 2872 2782 2889 2890 2932 2797 3002 2988 2962 2867 2832 2770 2755 2677 2540 2451 2380 2246 2119 2115 1971 1902 1823 1722 1593 1591 1559 1497 1502 1375 1362 1377 1403 1293 1344 1275 1319 1335 1343 1247 1331 1243 1302 1235 1182 1225 1222 1223 1266 1273 1292 1194 1252 1237 1247 1234 1301 1233 1279 1203 1256 1243 1198 1234 1222 1252 1186 1243 1189 1197 1151 1143 1176 1121 1152 1139 1130 1160 1134 1074 1104 1081 1055 1119 1199 1079 1069 1084 1155 1052 1028 1071 998 1040 1104 1033 1085 1086 1068 1076 1077 1060 1050 1084 1047 1060 983 1066 1072 1080 1036 1031 993 1109 1073 1069 1118 1070 1073 1064 1050 1103 1142 1120 1152 1116 1129 1131 1161 1148 1099 1157 1144 1133 1192 1215 1185 1186 1245 1212 1184 1174 1163 1255 1233 1233 1205 1257 1337 1268 1352 1343 1398 1476 1443 1487 1559 1591 1710 1852 1914 2106 2185 2309 2510 2824 2942 3073 3118 3123 3067 2838 2733 2624 2511 2434 2279 2267 2260 2087 1872 1787 1676 1508 1445 1394 1335 1246 1289 1235 1241 1321 1204 1198 1191 1235 1190 1186 1173 1228 1253 1264 1300 1289 1308 1359 1422 1410 1464 1587 1613 1701 1814 1864 1928 1919 2108 2183 2239 2234 2381 2344 2408 2409 2339 2327 2323 2143 2190 2066 2088 2006 1906 1919 1798 1784 1687 1724 1647 1648 1565 1571 1545 1535 1505 1523 1469 1447 1489 1595 1471 1552 1582 1636 1583 1677 1578 1690 1703 1771 1778 1821 1792 1924 1898 1985 1945 1935 1950 1953 1817 1878 1820 1750 1695 1607 1552 1448 1465 1315 1346 1241 1127 1152 1152 1087 1147 1018 1016 993 1030 944 974 948 910 931 926 940 970 905 934 915 901 935 840 917 910 924 849 879 901 882 884 929 887 902 817 846 920 892 808 865 841 850 858 879 845 846 853 855 795 877 832 776 822 833 860 795 895 858 866 887 853 884 879 842 890 934 882 835 810 834 826 894 784 887 845 783 829 817 770 798 766 816 781 788 764 756 808 755 792 842 744 829 752 765 741 845 792 767 780 786 771 814 773 780 779 811 800 802 783 763 782 851 767 831 814 859 791 843 782 838 872 873 811 859 877 858 898 841 886 910 950 937 934 1015 1000 1007 1043 1086 1001 1015 1041 1107 1054 1126 1085 1166 1103 1219 1222 1226 1212 1217 1165 1174 1155 1189 1185 1112 1129 1067 1092 1138 1119 1031 1070 1060 1089 1088 1067 1067 1057 1021 1036 1040 1031 1103 1055 1057 1059 998 1059 1067 1081 1097 1112 1163 1155 1140 1190 1281 1358 1431 1498 1628 1716 2074 2184 2526 2815 3099 3502 3818 4020 4220 4253 3898 3528 3253 2809 2746 2695 2609 2636 2591 2374 2188 1793 1515 1400 1246 1146 1046 1019 936 962 901 894 868 825 870 857 872 840 773 829 771 839 739 756 769 765 699 740 793 691 693 682 724 670 706 703 690 698 730 750 708 767 680 746 674 608 704 706 729 670 722 717 735 686 711 629 652 693 709 690 662 704 654 732 672 736 688 660 700 684 652 702 683 693 678 654 669 653 665 701 706 692 693 692 736 641 721 718 701 773 714 805 741 707 726 712 711 734 703 740 635 702 681 698 661 676 659 703 645 709 714 662 647 657 630 719 668 687 667 632 690 666 690 669 653 671 678 672 627 654 638 635 680 630 685 684 688 649 676 647 620 644 611 651 655 630 639 677 631 645 641 597 575 601 655 617 607 630 639 639 624 617 641 646 615 623 691 644 646 666 595 650 640 652 651 635 668 611 616 654 622 670 651 620 649 675 645 703 675 691 661 727 673 625 693 687 725 654 715 648 695 678 721 726 742 687 708 738 741 681 709 720 699 695 661 755 754 699 722 684 720 688 679 668 654 692 674 689 713 697 683 620 613 712 652 690 693 657 649 691 680 645 687 630 638 658 633 646 667 708 707 677 660 706 705 713 656 718 677 612 682 656 673 659 689 657 673 705 722 639 725 654 704 701 687 734 679 679 700 683 712 712 744 683 709 771 763 767 748 756 731 716 732 771 751 796 731 748 790 813 781 781 891 756 819 781 816 863 869 892 898 899 896 981 984 1023 1112 1001 1102 1121 1204 1207 1352 1514 1677 1820 2118 2279 2704 3015 3314 3626 4129 4051 4203 3935 3537 3274 3038 2860 2786 2984 2970 2969 2994 2900 2692 2431 2249 2113 1959 1993 1990 1972 2018 1999 2115 2062 2158 2339 2376 2556 2597 2667 2888 2871 3180 3222 3320 3469 3759 3924 3893 4023 4166 4244 4429 4491 4522 4644 4663 4413 4747 4419 4599 4388 4297 4224 4037 3947 3692 3681 3559 3332 3226 2983 2869 2706 2541 2400 2306 2168 2098 2035 1887 1904 1718 1686 1643 1515 1441 1424 1287 1262 1198 1274 1241 1225 1062 1111 1071 1042 1052 967 945 963 911 883 924 952 891 865 856 844 829 832 804 739 784 789 714 785 671 689 765 719 733 690 717 703 691 708 693 673 705 660 683 673 629 686 683 708 646 641 669 661 680 621 649 652 654 658 608 640 619 618 618 642 602 607 622 628 569 585 652 625 576 618 623 567 588 597 620 616 612 594 596 608 575 580 577 551 577 555 561 565 632 620 602 581 627 546 601 612 548 536 540 577 577 594 556 551 562 538 570 562 599 577 551 563 547 613 614 577 602 540 581 530 597 600 574 563 562 543 588 569 587 604 559 560 599 574 568 579 601 519 551 559 574 530 550 527 532 564 552 499 548 528 619 566 568 541 530 544 607 608 592 586 542 568 552 579 555 545 553 538 612 602 555 580 604 544 611 534 592 599 571 586 523 609 557 582 575 594 546 566 581 602 550 551 624 564 614 565 579 534 615 563 555 579 598 578 576 546 583 607 580 560 566 548 568 561 570 579 611 577 635 617 538 598 585 564 579 557 616 578 578 621 583 548 589 622 607 648 599 602 612 598 615 671 659 596 589 600 664 629 649 607 642 654 631 633 640 712 638 661 716 693 730 675 696 760 791 770 776 844 845 922 992 1041 1121 1230 1239 1366 1488 1472 1572 1603 1545 1460 1412 1276 1265 1260 1273 1354 1305 1324 1327 1322 1261 1270 1182 1207 1196 1157 1255 1288 1352 1494 1532 1724 1888 2048 2470 2806 3204 3964 4475 5375 6166 6978 6992 7078 6463 5799 4955 4242 3783 3656 3700 3782 3921 4089 4216 3969 3550 2987 2435 2057 1785 1542 1327 1234 1202 1102 1152 1065 1100 944 980 1001 966 986 958 881 947 901 920 895 855 838 893 868 811 913 887 897 906 855 904 923 923 874 848 881 895 917 875 893 887 876 864 886 917 924 933 911 905 855 917 918 915 966 979 947 1036 1061 1034 1153 1162 1195 1361 1457 1591 1825 1995 2252 2710 2946 3563 4164 4665 5260 5683 5695 5557 4815 4160 3477 3002 2978 2881 3019 3127 3236 3341 3310 3052 2736 2183 1778 1496 1301 1140 1083 1016 974 901 883 839 875 858 789 748 779 672 728 717 737 743 681 734 662 708 672 661 662 633 646 663 659 642 605 632 642 573 612 620 617 618 583 632 677 588 623 592 595 625 660 635 623 669 670 605 671 639 621 623 631 581 680 637 652 736 703 660 635 681 653 731 731 706 742 661 648 687 689 689 675 631 603 635 646 650 661 618 661 641 617 548 664 559 598 572 654 562 581 586 614 535 534 592 592 584 532 545 559 539 559 599 544 572 532 546 540 554 519 546 547 485 547 502 527 570 550 537 469 506 571 484 551 533 501 506 510 568 514 538 466 491 547 545 554 501 544 533 541 518 549 517 524 532 541 529 595 527 529 541 509 536 556 578 607 564 546 580 592 572 569 583 585 641 706 656 673 686 669 687 708 687 746 725 807 828 848 852 838 905 914 917 915 905 885 891 899 920 899 887 933 930 895 913 948 869 982 902 904 928 911 896 916 901 902 954 831 881 892 871 900 891 902 926 872 958 985 856 874 871 839 839 885 800 858 778 808 759 790 776 773 825 798 765 740 751 780 744 740 703 699 693 753 739 723 729 693 725 735 712 748 704 776 752 762 767 773 730 786 775 800 811 783 779 844 747 805 741 708 711 712 697 724 695 647 658 634 604 596 568 568 620 570 584 549 535 566 544 500 551 507 501 524 486 509 507 466 499 484 499 523 518 497 483 490 466 503 500 512 496 474 462 528 483 498 458 483 477 494 478 460 498 511 476 483 473 525 506 508 474 517 521 497 518 549 507 515 541 490 501 480 480 505 491 489 499 517 492 526 501 478 493 474 435 468 490 420 472 433 488 462 505 415 468 440 438 431 460 430 465 449 462 410 487 433 443 489 444 416 449 436 478 454 468 465 466 457 450 468 469 494 444 477 439 432 454 446 463 468 512 446 445 450 477 493 449 475 425 485 451 463 435 474 451 480 453 476 457 436 495 404 428 441 448 421 460 469 430 437 441 458 493 459 460 482 446 470 426 464 449 462 464 445 472 451 455 441 453 447 465 477 466 457 481 472 457 452 457 478 479 487 464 481 491 483 533 468 503 478 499 507 479 466 468 531 504 523 515 501 507 518 477 494 486 464 530 518 534 516 536 488 490 495 497 501 526 539 496 518 527 488 465 488 481 467 514 516 519 481 484 508 525 523 509 538 485 461 511 453 509 531 492 511 527 514 521 508 552 577 513 582 600 520 523 558 551 599 605 585 633 563 592 564 627 588 597 587 523 570 539 515 530 542 539 584 540 594 560 569 548 580 539 528 557 512 543 549 541 530 550 516 507 493 533 504 615 561 539 532 539 550 526 515 559 559 622 531 532 580 541 561 576 583 620 545 561 580 602 572 585 553 577 574 578 530 567 574 550 553 556 553 536 543 548 568 537 534 535 544 557 569 566 538 556 541 557 566 511 522 587 520 517 537 540 560 518 537 483 557 543 547 532 577 538 510 562 497 538 553 592 576 583 555 574 594 530 551 554 582 535 572 550 558 585 562 558 552 565 564 548 542 517 554 549 550 541 559 594 519 511 534 526 526 516 531 517 513 512 528 506 544 492 503 549 529 588 519 532 490 526 544 571 566 541 522 626 609 636 659 687 708 717 796 818 912 960 998 1048 1025 981 894 797 721 712 658 710 732 754 734 807 726 801 814 713 749 690 630 607 597 530 566 595 565 563 533 534 522 570 543 599 555 574 565 562 567 581 622 593 618 574 624 593 619 610 612 648 662 645 690 667 711 648 711 722 726 737 790 799 781 850 818 893 920 939 959 1026 1105 1110 1243 1430 1530 1680 1723 1988 1970 1883 1754 1588 1407 1324 1227 1169 1141 1179 1202 1221 1296 1307 1298 1269 1287 1208 1005 982 899 864 822 772 816 753 717 775 722 669 699 685 720 713 657 688 633 683 662 674 705 646 646 636 687 596 643 672 656 669 671 662 669 698 699 737 758 793 824 886 962 1041 1069 1105 1000 913 823 751 787 765 724 748 751 775 850 839 844 820 812 812 772 718 694 644 656 628 637 610 609 615 578 619 632 587 582 543 568 599 563 554 578 506 585 593 558 525 525 544 556 575 521 539 488 508 566 511 501 523 532 482 544 546 547 493 581 526 575 553 549 543 545 529 528 574 551 521 570 573 556 558 552 566 569 615 579 617 578 613 578 633 658 626 636 631 682 601 685 607 622 599 592 563 617 575 594 617 605 585 570 553 539 570 590 592 534 545 586 536 562 506 501 500 503 503 481 488 511 529 473 466 520 513 497 490 537 513 491 483 507 556 486 527 531 504 502 500 486 476 504 514 510 495 531 505 546 507 511 511 546 517 526 520 567 541 559 524 536 548 517 531 545 497 515 543 497 550 520 548 512 482 527 531 501 545 512 529 504 561 548 567 569 517 524 555 577 541 540 559 535 582 580 583 580 615 602 619 668 628 636 654 663 676 736 727 765 746 783 841 865 878 849 996 983 973 1079 1054 1059 1095 1023 1106 1100 1178 1189 1189 1228 1373 1464 1542 1637 1778 1779 1940 1808 1800 1597 1434 1328 1236 1168 1235 1227 1196 1213 1279 1366 1342 1386 1439 1416 1405 1391 1385 1394 1548 1664 1723 2021 2446 2775 3351 3924 4478 4810 4621 3964 3337 2799 2347 2085 2073 2076 2056 2112 2291 2405 2680 2871 3027 2848 2720 2404 2084 1876 1521 1440 1388 1355 1346 1343 1391 1419 1424 1492 1548 1566 1652 1558 1526 1391 1189 1133 989 933 850 912 892 907 857 988 952 1037 1001 950 935 840 804 724 654 662 645 607 605 579 582 600 543 603 564 537 549 542 552 542 540 499 533 542 520 532 548 558 519 483 496 510 524 551 518 533 499 480 535 539 548 494 525 482 512 524 530 492 494 542 512 524 490 503 502 497 494 463 484 420 508 517 457 499 461 521 533 506 487 479 459 475 499 494 488 482 497 495 450 484 462 487 503 516 523 506 499 544 537 533 514 539 479 500 569 525 561 555 588 561 532 571 550 572 554 515 565 581 572 572 601 620 603 621 610 593 621 640 623 670 651 669 672 631 693 687 751 758 748 777 776 848 845 897 1020 1020 1038 1131 1108 1090 1095 1001 975 1001 1020 1007 1041 1074 1080 1100 1224 1211 1213 1351 1391 1368 1333 1463 1459 1443 1481 1485 1539 1528 1672 1617 1778 1704 1784 1894 1865 1896 1940 1977 1975 1984 2018 2050 2029 1984 1935 1903 2041 1883 1943 1853 1784 1792 1703 1780 1685 1596 1620 1493 1517 1471 1401 1351 1297 1297 1266 1282 1200 1120 1098 1035 1012 995 943 889 895 889 860 771 762 735 757 734 697 679 692 645 644 695 664 637 613 607 629 607 614 557 612 560 584 564 575 538 560 558 551 525 585 545 535 527 556 554 551 574 571 582 573 562 549 607 624 564 559 597 610 562 594 586 583 631 665 613 601 627 636 688 699 679 786 706 773 853 858 923 971 985 1252 1276 1373 1333 1269 1267 1171 1008 972 873 846 749 835 833 783 822 880 878 961 913 983 944 925 800 814 684 752 637 676 606 616 572 622 597 595 574 595 583 576 615 597 580 550 588 598 568 590 566 545 577 522 548 547 521 554 533 515 536 579 574 578 515 564 539 560 498 546 544 533 541 533 554 535 541 581 613 618 642 687 760 734 755 849 966 1059 1204 1314 1587 1631 1671 1694 1705 1398 1217 1062 993 899 782 777 834 798 828 910 948 995 1064 1065 1044 997 908 854 763 716 642 580 615 502 558 522 525 536 499 472 497 506 497 486 480 477 486 488 440 438 483 494 466 462 514 494 474 468 463 466 438 483 473 474 463 447 423 443 435 451 466 460 492 433 478 476 448 487 497 469 481 484 484 541 459 523 533 475 539 543 518 550 520 478 503 512 515 546 523 545 536 500 512 505 558 508 548 545 496 578 561 553 568 540 542 519 524 503 552 513 523 507 577 540 523 534 529 529 511 490 476 549 501 506 535 497 534 484 435 535 510 522 510 438 497 443 543 464 462 480 451 494 444 495 506 462 465 440 460 445 475 456 479 462 453 440 385 466 437 451 474 431 465 472 467 451 458 452 435 486 455 494 488 476 481 412 458 445 484 483 456 453 504 492 471 494 491 475 475 474 469 473 490 481 509 492 531 500 490 483 499 507 446 523 511 554 514 522 518 530 532 498 495 563 540 548 531 551 581 498 556 575 517 528 554 489 537 534 526 585 543 496 487 536 504 565 489 509 481 513 507 521 482 457 507 446 483 441 465 453 484 456 435 441 437 441 380 454 398 461 421 416 420 436 386 402 421 383 423 420 380 396 332 385 395 415 410 449 408 410 391 390 384 475 393 382 357 434 412 434 427 386 429 404 420 392 413 394 415 391 426 368 399 399 446 394 401 385 421 447 403 437 378 462 445 434 439 504 479 488 497 563 578 620 634 712 669 692 645 679 559 545 512 539 414 474 473 453 488 502 511 487 574 514 536 540 526 479 480 502 479 468 436 460 416 407 380 395 439 394 415 395 406 382 408 412 406 415 401 419 377 376 418 396 398 423 437 404 418 409 404 378 425 418 411 440 411 388 398 400 406 404 424 393 412 396 420 419 427 427 375 426 441 422 459 426 473 455 458 448 485 459 489 466 537 562 598 661 616 712 715 779 774 777 799 751 738 631 647 601 570 582 531 523 558 555 553 569 610 628 620 628 611 628 563 556 522 499 509 468 476 455 437 408 479 466 442 423 393 419 448 414 447 427 398 398 413 380 404 411 415 396 378 432 426 390 391 373 385 430 416 375 386 409 383 405 418 369 404 362 364 404 373 369 379 402 392 378 393 377 415 394 412 400 384 384 392 419 398 397 395 401 412 370 444 402 415 437 407 433 429 417 417 456 457 462 458 423 424 470 443 469 459 438 417 423 432 406 389 440 412 443 407 401 425 407 387 412 399 422 401 406 418 417 404 417 370 381 404 378 383 373 397 385 372 358 376 315 386 397 354 365 350 361 353 371 393 372 357 386 367 391 372 398 410 370 358 353 371 378 406 348 394 413 333 380 395 355 376 401 382 380 368 365 380 394 412 411 359 399 415 348 378 371 405 373 367 367 358 457 370 373 388 399 367 414 384 388 410 419 408 407 370 405 390 427 385 396 403 385 447 436 417 458 452 425 435 461 417 436 464 510 537 509 543 544 602 614 614 617 661 762 757 858 880 896 955 973 904 919 858 811 742 672 620 631 664 641 697 685 697 701 684 752 784 791 796 877 776 773 763 735 687 684 678 701 668 660 595 673 648 639 644 619 655 700 600 645 658 632 606 642 661 576 601 604 587 628 545 628 624 617 615 611 581 612 601 601 614 563 617 609 652 619 656 680 670 710 734 711 736 727 686 662 702 584 573 580 582 605 618 570 642 545 625 613 650 651 647 684 637 707 639 662 616 621 596 579 645 621 599 587 579 577 595 586 575 589 626 588 534 538 552 620 542 565 552 513 536 514 495 508 522 537 454 474 489 486 461 490 496 512 457 433 451 419 455 460 411 426 452 446 449 439 435 423 427 431 380 431 411 418 414 441 419 426 443 382 444 414 362 389 418 413 409 447 425 406 400 405 400 394 399 410 420 404 442 446 438 392 440 420 420 427 462 430 431 474 454 435 451 416 437 438 493 461 452 446 469 453 436 484 495 445 485 445 484 480 457 464 472 466 461 494 443 483 502 476 479 476 446 427 492 447 439 460 467 443 425 424 430 413 443 474 467 408 394 431 416 418 411 418 473 407 424 448 476 405 464 418 436 424 411 416 400 402 390 414 427 435 409 378 400 379 431 426 393 430 403 424 412 406 393 441 406 431 447 417 385 422 448 424 427 426 470 427 463 448 428 401 451 421 439 429 426 428 452 456 522 441 483 452 496 527 472 526 542 527 551 513 513 547 487 486 468 439 420 416 413 405 423 471 424 435 434 463 448 462 486 447 461 427 438 476 397 409 421 395 405 378 406 415 371 370 373 401 381 367 424 366 411 369 396 392 365 409 381 413 392 401 396 404 399 413 375 358 395 411 396 417 387 440 440 428 451 492 421 481 478 524 557 543 580 654 745 836 871 1015 1056 1097 1133 1018 994 812 748 685 597 562 512 499 501 512 518 563 601 569 606 635 679 676 697 719 670 629 567 540 497 518 510 395 435 392 404 427 388 372 336 388 398 354 354 343 362 345 337 385 337 361 345 343 358 341 339 326 296 340 303 342 347 329 341 349 307 307 337 355 330 345 312 331 335 330 334 307 305 319 326 304 329 315 330 328 347 313 311 314 320 348 292 342 318 331 338 366 329 339 304 328 356 335 312 336 361 348 350 367 335 307 353 363 325 324 341 353 340 377 335 309 322 317 328 339 349 333 387 335 330 345 364 351 360 366 326 397 375 376 343 361 327 334 343 344 328 319 372 313 354 354 363 323 335 341 363 384 323 339 333 374 374 350 343 345 365 379 365 347 365 311 359 324 342 351 358 366 352 354 341 387 327 322 349 331 323 376 373 387 383 353 384 336 371 345 374 387 345 417 335 359 335 379 342 347 341 350 392 376 386 383 364 375 355 392 367 399 390 389 389 420 402 419 394 423 410 413 445 454 402 399 401 433 454 432 418 410 447 471 436 429 457 461 455 460 474 479 530 499 500 509 470 509 510 537 500 494 566 528 518 543 567 543 616 549 559 597 656 580 604 614 581 685 608 686 672 699 689 673 688 714 719 731 714 797 748 733 755 705 773 722 732 736 724 697 721 725 687 745 696 695 686 689 673 675 631 681 708 738 668 688 628 623 662 654 672 731 678 617 605 562 592 597 587 554 563 579 559 547 550 539 524 513 504 512 552 515 506 532 516 527 509 532 520 511 533 523 553 567 531 537 582 581 560 541 573 522 508 476 487 470 471 500 474 429 484 469 441 476 505 523 481 498 475 497 493 469 465 447 464 433 487 460 414 433 439 406 455 437 427 493 443 440 488 517 580 611 607 650 783 865 940 1032 1085 1160 1144 1059 992 883 742 680 627 626 501 500 519 486 505 498 499 546 539 634 667 702 756 737 772 788 691 705 543 538 448 452 454 420 448 440 434 366 440 412 413 419 395 414 426 402 455 426 415 447 454 491 477 482 513 510 517 469 473 440 439 435 421 443 408 474 414 446 420 414 430 462 454 473 446 502 503 521 478 533 492 519 462 470 457 483 468 451 471 446 440 446 436 435 409 456 491 439 477 476 443 460 470 453 469 484 448 452 436 443 461 463 466 403 474 436 458 449 481 468 452 448 450 477 432 443 450 423 457 472 461 454 460 455 468 460 442 427 443 414 460 457 481 444 455 420 455 435 458 478 457 408 438 434 431 466 446 477 425 508 458 437 431 442 421 432 420 448 416 402 449 467 426 432 433 445 474 456 450 423 406 397 430 434 451 433 427 412 443 421 431 456 451 428 437 465 483 457 512 529 544 569 665 672 712 816 823 843 832 822 780 743 687 697 604 551 554 519 494 482 506 491 517 444 529 512 521 544 551 608 637 636 624 627 598 535 526 566 508 474 509 443 409 435 416 422 398 400 372 418 396 365 356 381 370 420 403 343 334 350 373 359 349 336 379 339 354 367 349 386 359 351 368 332 362 371 370 340 317 350 320 350 337 375 374 375 366 329 338 366 392 384 370 380 397 430 428 431 474 503 528 536 590 613 601 580 544 455 481 453 403 420 378 415 386 381 375 365 362 374 370 436 383 482 427 467 474 482 481 518 475 433 416 383 399 370 366 344 375 372 354 344 355 326 344 349 374 330 334 324 338 311 346 352 348 342 346 370 351 345 326 370 362 317 361 319 343 348 305 320 322 329 316 344 343 316 353 290 360 347 304 306 356 306 305 330 342 334 364 341 361 318 331 315 338 327 386 342 340 358 355 333 334 307 315 309 328 304 330 309 335 348 290 331 329 317 287 332 291 344 332 311 341 320 362 336 315 324 333 319 311 334 322 315 359 312 297 327 319 333 332 319 356 309 332 306 284 369 344 346 351 394 363 428 395 386 422 385 403 344 378 373 330 333 330 291 334 313 337 337 349 329 354 361 345 355 332 359 352 355 341 332 383 372 364 377 331 340 345 307 306 316 336 355 316 303 339 345 313 324 313 296 357 290 343 305 336 318 326 324 306 291 342 291 325 323 305 332 282 304 298 319 330 298 347 299 286 337 325 289 311 312 299 341 288 331 271 320 325 310 252 325 275 312 337 312 306 297 308 330 313 325 281 322 291 288 284 309 306 318 285 270 319 308 325 297 322 293 302 284 289 294 284 291 274 278 300 301 321 282 308 298 294 300 282 293 271 292 327 331 329 315 319 311 298 342 298 293 306 297 321 292 268 293 304 302 287 343 331 315 276 295 285 297 269 315 291 329 279 314 307 347 284 326 331 323 319 366 346 324 320 317 336 297 339 310 336 305 312 328 314 303 355 350 318 343 337 357 330 370 333 365 324 359 388 334 379 394 390 357 366 408 397 367 360 385 415 401 386 402 384 379 367 397 375 375 356 355 352 377 363 372 363 374 417 344 330 305 382 337 378 379 338 320 342 352 356 361 327 363 373 347 380 354 344 362 330 321 325 306 336 316 341 325 316 332 345 338 338 289 312 321 283 318 325 313 315 320 297 289 329 315 352 317 342 351 317 318 292 313 332 341 345 333 319 339 317 287 304 296 329 288 319 300 330 326 334 330 324 320 324 309 300 306 289 338 313 320 311 294 340 325 345 335 335 318 308 345 316 355 308 319 316 337 328 316 329 316 324 326 327 322 339 353 384 350 318 360 343 349 342 331 342 308 311 339 322 334 360 336 321 326 348 360 377 348 353 362 317 357 333 345 333 379 332 347 384 364 338 324 359 371 341 333 347 356 332 353 332 333 335 386 363 353 323 338 374 351 327 361 357 344 360 335 375 379 365 379 397 377 350 345 339 367 381 388 366 357 386 357 369 429 374 390 387 371 387 364 352 343 361 350 371 369 355 355 386 340 378 360 374 368 378 407 320 382 369 384 359 354 377 380 396 359 318 346 357 375 372 334 338 358 349 326 331 348 360 291 318 320 356 356 331 367 359 351 321 330 363 325 361 336 320 322 320 338 334 320 347 353 324 324 350 321 341 326 294 328 323 343 343 318 339 340 325 329 312 339 315 337 320 343 329 336 346 328 333 330 326 347 323 334 329 313 327 300 326 302 322 342 305 361 341 337 311 343 335 322 328 343 301 352 322 300 332 312 336 313 319 324 354 324 316 286 332 311 344 322 291 293 321 302 343 319 294 316 313 308 324 352 299 307 306 335 303 312 329 316 324 345 320 311 290 312 297 316 313 323 307 273 342 331 339 302 323 325 325 338 339 356 370 419 409 419 401 453 485 493 555 568 652 601 667 624 610 575 540 472 482 429 409 347 375 371 395 353 361 408 329 351 355 337 396 385 406 430 463 474 429 506 485 421 460 399 371 389 374 347 349 328 376 328 327 347 360 336 330 319 325 329 343 306 305 283 302 308 310 351 321 342 324 326 296 320 311 329 323 332 340 311 310 354 302 280 300 319 282 288 323 310 279 269 282 336 313 319 318 320 296 325 314 315 298 339 325 334 315 293 292 329 334 319 286 331 317 352 288 337 319 313 344 335 346 332 320 319 347 298 311 340 321 320 362 353 321 327 338 320 317 347 345 353 381 351 370 366 376 410 371 366 343 376 411 417 425 448 453 501 511 529 586 572 695 670 724 735 774 693 584 603 638 540 527 517 477 477 534 548 490 537 563 529 550 612 600 751 777 842 950 1058 1084 1164 1270 1197 1136 1024 929 824 725 681 632 597 550 567 475 484 477 525 506 498 469 492 528 568 547 582 607 668 690 711 722 740 694 626 619 593 509 472 477 453 426 444 405 428 413 438 390 422 415 402 383 436 381 413 366 404 412 376 415 418 397 418 407 400 429 384 436 410 356 393 369 430 416 443 351 402 445 427 434 405 395 405 409 423 423 434 446 457 450 503 438 464 477 480 501 555 539 525 608 631 680 647 786 790 831 896 935 937 930 864 843 799 749 673 675 608 610 602 545 571 526 507 506 536 533 494 520 546 538 582 595 617 614 643 677 618 646 665 658 628 588 582 579 560 532 510 447 462 452 431 434 410 397 458 412 430 422 398 409 420 386 411 388 404 397 390 380 382 368 412 364 398 392 402 396 370 313 363 363 341 365 368 362 393 361 331 402 380 342 377 332 361 395 364 383 366 340 343 369 328 374 334 340 351 378 342 303 332 336 339 332 360 368 357 361 380 322 342 360 312 339 356 339 335 385 365 340 380 335 369 376 380 404 365 362 347 378 382 383 369 358 399 396 410 435 430 408 424 452 408 458 398 410 369 386 411 401 425 399 364 376 367 393 401 393 413 370 358 375 389 408 360 406 411 403 443 390 438 434 453 409 400 359 343 357 388 347 376 343 377 356 390 343 397 387 372 406 379 376 381 360 387 370 376 414 399 384 357 345 356 351 358 376 349 372 358 362 367 356 333 350 381 364 407 386 378 337 360 351 344 368 390 385 375 378 341 371 361 369 384 407 387 353 401 344 381 364 390 385 361 378 369 347 364 387 374 370 416 389 412 394 374 395 416 474 458 454 431 485 493 528 522 566 592 648 743 797 898 966 1105 1302 1519 1788 1892 1988 1956 1709 1569 1316 1136 938 823 749 700 596 565 507 555 532 538 522 532 506 557 515 532 622 626 681 715 758 852 963 1090 1121 1132 1105 1055 926 869 756 650 614 586 568 528 469 424 421 408 384 420 397 353 393 400 389 336 393 392 373 363 359 362 395 372 388 362 388 375 380 374 363 357 368 369 346 375 380 397 375 353 380 325 358 376 362 357 338 346 335 416</counts>
			</dataPoints>
		</scan>
	</xrdMeasurement>
</xrdMeasurements>