File: dataset/precursor_mixture/Li2TiO3_CaCO3_Li3PO4.2-min.xrdml
<?xml version="1.0"?>
<xrdMeasurements xmlns="http://www.xrdml.com/XRDMeasurement/2.2" xmlns:xsi="http://www.w3.org/2001/XMLSchema-instance" xsi:schemaLocation="http://www.xrdml.com/XRDMeasurement/2.2 http://www.xrdml.com/XRDMeasurement/2.2/XRDMeasurement.xsd" status="Completed" recordIdentifier="{3F2BE2AF-62DC-4E1C-8B60-B48BC6134088}">
	<comment>
		<entry/>
	</comment>
	<sample type="To be analyzed">
		<id>dara-34-1</id>
		<name></name>
		<preparedBy></preparedBy>
	</sample>
	<xrdMeasurement measurementType="Scan" status="Completed" sampleMode="Reflection">
		<usedWavelength intended="K-Alpha 1">
			<kAlpha1 unit="Angstrom">1.5405980</kAlpha1>
			<kAlpha2 unit="Angstrom">1.5444260</kAlpha2>
			<kBeta unit="Angstrom">1.3922500</kBeta>
			<ratioKAlpha2KAlpha1>0.5000</ratioKAlpha2KAlpha1>
		</usedWavelength>
		<incidentBeamPath>
			<radius unit="mm">145.00</radius>
			<xRayTube id="1010048" name="Empyrean Cu LFF HR (9430 033 7310x) DK430614">
				<tension unit="kV">40.0</tension>
				<current unit="mA">15.0</current>
				<anodeMaterial>Cu</anodeMaterial>
				<focus type="Line">
					<length unit="mm">12.0</length>
					<width unit="mm">0.4</width>
					<takeOffAngle unit="deg">6.0</takeOffAngle>
				</focus>
			</xRayTube>
			<filter id="20010004" name="Beta-filter Nickel">
				<material>Ni</material>
				<thickness unit="mm">0.020</thickness>
			</filter>
			<sollerSlit id="21010002" name="Soller slits 0.04 rad.">
				<opening unit="rad">0.0400</opening>
			</sollerSlit>
			<mask id="22031000" name="Fixed mask 13 mm">
				<width unit="mm">9.00</width>
			</mask>
			<divergenceSlit id="22120001" name="Divergence slit 1°" xsi:type="fixedDivergenceSlitType">
				<distanceToSample unit="mm">50.00</distanceToSample>
				<height unit="mm">1.52</height>
			</divergenceSlit>
		</incidentBeamPath>
		<beamKnife id="29030100" name="Beam knife low"/>
		<sampleMovement xsi:type="spinningSampleMovementType">
			<spinnerRevolutionTime unit="seconds">1.0</spinnerRevolutionTime>
		</sampleMovement>
		<diffractedBeamPath>
			<radius unit="mm">145.00</radius>
			<antiScatterSlit id="22090040" name="AS slit 9 mm" xsi:type="fixedAntiScatterSlitType">
				<height unit="mm">9.00</height>
			</antiScatterSlit>
			<sollerSlit id="21020003" name="Large Soller slits 0.04 rad.">
				<opening unit="rad">0.0400</opening>
			</sollerSlit>
			<filter id="20030001" name="Large beta-filter Nickel">
				<material>Ni</material>
				<thickness unit="mm">0.020</thickness>
			</filter>
			<detector id="7010019" name="PIXcel1D-Medipix3 detector" xsi:type="rtmsDetectorType">
				<phd unit="keV">
					<lowerLevel>4.0</lowerLevel>
					<upperLevel>11.3</upperLevel>
				</phd>
				<mode>Scanning</mode>
				<activeLength unit="deg">1.021</activeLength>
			</detector>
		</diffractedBeamPath>
		<scan appendNumber="0" mode="Continuous" scanAxis="Gonio" status="Completed">
			<header>
				<startTimeStamp>2024-02-18T12:51:56-08:00</startTimeStamp>
				<endTimeStamp>2024-02-18T12:54:18-08:00</endTimeStamp>
				<author>
					<name>AutomatedUser</name>
				</author>
				<source>
					<applicationSoftware version="1.4b (28)">PANalytical Aeris Instrument Suite</applicationSoftware>
					<instrumentControlSoftware version="2.0.0 20210224">AERIS</instrumentControlSoftware>
					<instrumentID>950485</instrumentID>
				</source>
			</header>
			<dataPoints>
				<positions axis="2Theta" unit="deg">
					<startPosition>10.02173288</startPosition>
					<endPosition>139.98435528</endPosition>
				</positions>
				<positions axis="Omega" unit="deg">
					<startPosition>5.01086644</startPosition>
					<endPosition>69.99217764</endPosition>
				</positions>
				<commonCountingTime unit="seconds">1.551</commonCountingTime>
				<counts unit="counts">364 361 344 337 344 365 335 373 314 341 374 364 341 335 339 319 312 352 316 300 293 326 347 323 310 314 333 291 328 281 308 284 284 292 296 287 311 296 302 312 295 267 287 288 282 307 277 309 283 248 298 257 263 280 270 294 250 247 272 268 273 241 245 242 285 279 261 229 257 274 245 277 234 293 228 262 258 185 251 262 235 220 246 229 227 242 234 259 220 236 214 218 240 225 200 230 215 216 209 219 242 214 236 234 209 216 229 208 189 237 211 194 202 193 216 205 199 220 214 188 204 186 195 221 198 183 194 208 212 205 202 191 191 192 173 196 203 179 181 178 208 205 174 177 174 180 189 221 211 206 214 192 229 225 287 289 266 229 218 177 189 187 187 183 213 194 204 187 177 168 163 187 182 196 199 189 194 169 182 200 181 185 219 207 211 202 233 255 244 288 267 253 245 189 214 194 215 202 176 165 136 149 153 166 155 163 156 142 151 163 172 142 143 172 180 180 151 158 158 170 172 156 181 171 187 164 172 155 160 176 183 186 180 167 138 182 181 167 130 157 187 138 185 149 170 155 145 150 129 144 146 155 156 149 147 165 158 147 144 137 154 158 167 151 168 159 164 136 172 194 199 211 217 305 337 405 503 596 557 380 299 263 174 195 182 148 196 196 189 181 201 239 292 318 359 380 382 428 411 390 406 374 312 251 183 183 157 152 115 136 148 139 129 118 158 120 135 157 150 122 136 137 134 121 174 150 155 140 159 166 192 214 293 290 287 248 247 256 251 169 151 166 150 164 183 170 159 133 129 122 113 106 108 114 106 112 116 133 93 99 100 93 113 112 101 119 101 113 91 99 131 157 103 88 102 86 140 98 89 79 113 74 126 105 98 92 99 96 103 117 95 99 95 109 101 95 84 96 81 85 73 77 86 86 90 86 99 102 94 87 87 91 112 124 157 137 145 141 147 168 158 164 168 217 275 311 303 345 337 370 373 535 827 1273 2490 6102 14913 11127 7843 2540 704 512 349 313 270 243 176 215 150 140 145 123 149 104 152 144 104 151 81 124 97 151 125 103 111 93 90 123 116 86 114 110 114 103 114 101 103 114 117 126 127 167 211 151 132 110 85 107 98 97 104 104 118 95 98 72 96 88 98 79 102 97 73 93 88 87 83 83 103 67 82 108 91 95 99 104 82 79 79 77 93 73 64 84 87 83 94 91 120 104 140 113 132 137 157 196 264 359 359 328 334 259 226 259 226 240 204 177 147 126 133 131 123 87 109 90 101 112 117 114 108 89 94 82 82 91 94 85 74 86 114 106 101 80 101 92 76 74 98 89 121 139 168 217 273 202 213 131 86 111 100 86 85 118 128 172 202 174 167 198 184 126 149 133 118 167 152 178 172 158 151 111 93 73 82 71 73 81 60 80 80 75 58 67 65 81 65 82 68 56 74 63 69 69 70 67 72 65 49 63 52 58 51 67 81 84 79 92 106 104 77 90 94 81 83 76 52 56 90 100 201 337 308 237 228 111 74 84 69 67 58 67 51 55 57 52 50 51 70 44 47 57 70 49 60 45 67 56 78 61 45 48 50 38 65 64 50 49 41 46 49 49 37 61 51 51 71 53 41 53 43 68 65 66 52 65 60 51 52 70 53 41 38 61 50 42 55 35 56 61 67 61 60 52 69 74 60 66 59 61 86 73 80 97 157 301 348 221 241 222 170 198 205 237 278 303 375 422 420 355 328 242 201 169 112 123 116 102 78 68 66 55 61 54 65 45 44 53 31 52 53 57 49 49 50 57 45 52 48 37 62 48 59 41 33 42 50 55 52 54 39 43 50 47 35 47 42 47 43 44 38 42 38 47 67 46 64 44 42 40 43 41 47 49 48 50 45 48 58 34 63 63 69 101 119 98 91 103 109 83 113 176 322 573 597 337 367 240 124 97 93 69 70 75 71 66 70 78 81 85 65 78 90 110 189 338 524 330 249 279 138 88 80 59 65 55 57 52 46 58 52 56 39 55 67 52 53 50 54 71 43 44 44 59 41 40 46 52 44 55 39 48 40 36 60 47 34 42 42 42 51 44 54 43 55 76 66 65 80 67 81 74 85 65 82 71 73 67 49 65 41 56 72 70 49 66 51 51 53 53 60 45 46 39 30 35 42 28 29 42 34 34 35 39 45 44 46 50 30 43 42 36 44 29 29 34 54 38 30 34 38 35 43 38 38 28 39 26 50 30 46 32 27 37 41 34 37 19 37 52 38 41 46 44 44 31 35 34 43 51 36 38 49 41 38 41 45 47 48 41 40 41 34 48 35 37 42 35 46 40 44 31 40 56 37 52 54 41 44 40 52 40 58 45 55 54 44 34 28 45 56 40 37 41 33 54 73 86 78 66 52 55 53 37 41 55 44 40 47 44 53 74 73 75 96 129 147 131 90 105 85 67 48 52 48 61 56 46 43 63 57 81 71 49 78 60 54 41 42 47 42 41 36 47 49 41 44 37 43 26 46 48 63 60 52 57 38 40 44 44 40 39 47 33 39 47 53 29 41 28 30 44 44 39 51 40 43 56 41 44 42 47 44 56 52 71 94 89 147 119 189 113 98 129 150 131 194 335 305 202 187 265 176 129 116 156 107 70 69 78 57 63 57 59 55 32 38 30 52 40 44 58 40 53 35 43 33 24 35 47 32 50 48 44 46 35 75 62 48 47 68 60 73 98 91 78 91 103 111 108 132 148 169 162 180 149 152 137 110 111 89 67 73 64 57 59 44 45 48 31 37 39 51 47 44 40 54 52 74 102 106 79 74 77 81 51 55 45 41 41 46 48 37 39 54 35 37 49 60 80 118 114 84 60 72 89 66 57 40 33 32 41 42 38 36 36 41 45 31 37 43 45 41 40 53 34 48 45 43 43 51 40 55 52 46 48 38 25 35 38 28 29 41 29 23 32 26 47 40 28 42 47 57 58 39 30 36 26 40 66 34 50 27 39 46 25 25 31 26 46 25 44 27 23 40 41 31 25 38 35 34 44 54 44 32 34 40 41 28 30 24 31 36 33 30 31 33 31 28 32 42 39 31 39 69 77 50 37 41 50 34 33 34 37 30 41 34 24 29 37 20 36 36 34 34 30 25 25 36 21 26 37 23 37 26 28 39 37 29 31 18 24 37 36 35 26 25 33 35 33 38 23 30 27 18 23 42 39 22 43 29 27 46 52 58 94 49 69 56 58 66 52 69 47 67 38 37 69 64 57 56 49 69 61 46 54 41 60 66 51 58 48 59 47 40 35 28 34 62 39 43 26 28 31 36 35 27 36 34 41 45 41 38 41 60 42 36 45 30 42 24 38 24 28 37 40 33 33 39 21 31 20 36 44 41 18 31 41 26 50 41 48 37 32 47 24 40 33 27 30 30 38 38 33 35 23 39 40 40 56 79 92 62 58 38 50 52 40 37 40 50 17 27 33 33 29 35 24 28 25 25 16 17 18 35 30 15 25 32 26 17 37 28 22 23 23 25 26 41 35 31 42 16 21 24 29 34 21 18 25 19 26 30 23 36 25 24 24 26 37 51 43 38 51 51 53 42 47 64 56 70 51 55 57 72 44 55 36 42 52 58 43 37 41 52 36 44 48 35 34 49 40 40 42 27 30 38 53 70 91 73 40 39 38 66 67 35 27 36 30 39 42 38 34 37 48 36 38 43 40 37 36 51 44 28 28 34 44 35 27 40 34 30 40 36 36 36 45 35 49 31 28 45 42 44 40 41 45 56 68 61 49 43 41 48 42 46 37 57 40 38 43 28 34 31 26 25 13 21 21 25 37 35 57 40 39 22 26 29 35 26 20 31 19 22 20 30 19 18 19 28 27 28 22 17 25 28 26 33 35 35 23 28 23 31 30 32 23 28 19 28 21 20 20 16 28 29 31 19 26 25 21 22 11 19 22 15 11 21 28 17 32 18 18 23 31 21 25 31 26 24 19 20 21 20 34 26 43 20 28 14 24 18 31 17 43 24 18 22 23 32 31 28 31 39 39 23 24 33 21 26 33 23 25 30 30 32 23 21 29 34 24 19 14 22 20 24 16 22 29 20 30 28 20 19 25 30 30 15 18 22 24 39 36 42 22 35 36 34 35 27 38 33 33 29 24 35 28 38 25 19 28 21 23 21 18 23 18 28 30 39 17 27 22 18 21 32 36 39 16 24 37 14 23 20 18 32 20 19 26 25 27 24 24 17 36 35 44 56 35 25 39 25 26 30 40 31 27 17 37 34 31 22 25 24 35 30 16 27 22 27 22 33 32 19 16 16 32 29 27 39 30 28 32 38 49 49 49 46 42 54 85 108 66 46 41 48 38 43 62 44 32 34 37 33 43 27 33 35 39 28 37 41 38 30 40 45 55 75 68 52 36 44 35 47 45 47 37 36 29 32 26 17 29 26 27 29 19 29 32 31 25 25 33 22 20 41 32 21 30 36 31 33 31 36 28 23 36 25 27 26 52 30 27 23 34 34 25 20 29 26 30 29 36 24 28 27 39 27 25 25 35 59 51 63 128 148 100 77 41 43 43 67 93 84 51 28 36 35 27 34 26 37 22 32 21 27 39 29 39 30 36 32 24 28 29 29 29 27 27 26 24 29 30 40 16 20 23 26 23 29 14 33 23 26 37 31 19 13 33 30 19 26 32 21 28 14 39 26 28 28 22 23 34 24 34 34 21 15 28 27 19 28 25 20 32 33 23 20 35 37 42 35 22 38 33 37 33 26 33 34 26 26 45 36 42 42 30 19 23 36 27 39 23 37 43 50 45 43 38 44 33 34 22 23 43 35 31 23 19 30 25 25 22 15 27 36 36 36 23 28 30 23 30 37 25 26 31 23 43 23 30 32 36 27 42 32 43 23 31 34 38 60 39 50 20 42 33 42 32 45 43 42 31 28 27 37 36 41 28 30 28 24 34 26 34 27 29 28 48 48 35 22 28 27 30 30 38 40 23 37 40 27 27 23 34 33 29 28 23 35 30 45 36 34 27 49 27 14 37 34 37 30 28 34 26 33 30 16 45 20 29 29 34 35 33 33 34 27 57 42 42 29 31 45 41 31 22 28 49 39 40 29 31 45 26 32 43 23 41 42 44 31 43 27 37 32 31 29 41 43 24 28 30 27 32 40 31 32 43 39 40 24 33 20 36 39 41 29 37 34 41 31 41 37 31 27 31 46 39 46 44 48 66 39 38 41 32 45 63 54 59 53 51 55 37 49 41 58 36 42 34 40 41 32 34 29 30 35 34 33 32 22 42 44 38 41 32 23 30 31 38 34 33 36 34 37 40 19 39 31 24 31 25 37 31 29 42 35 39 29 41 25 43 26 31 28 32 23 30 22 36 29 21 34 24 25 43 26 30 31 23 30 25 36 27 26 31 37 35 35 31 17 38 31 47 20 23 35 34 27 36 30 46 25 27 21 30 29 17 25 24 19 28 21 34 29 35 28 27 31 32 23 23 27 38 29 27 38 45 37 28 35 33 26 33 35 30 34 22 28 31 34 31 45 34 41 31 29 30 41 26 35 39 23 40 28 57 59 61 35 30 38 28 22 30 33 30 40 33 26 38 36 22 35 25 31 39 22 31 27 40 44 28 47 41 34 21 42 35 39 45 41 45 25 35 32 40 31 36 24 39 30 41 31 40 32 30 29 23 27 33 30 24 31 33 39 17 23 39 43 28 24 37 32 46 23 39 24 34 31 38 36 40 30 28 20 27 33 19 31 25 39 41 22 23 23 20 18 35 38 29 16 23 20 17 37 31 26 29 36 22 30 40 26 23 23 23 33 36 32 33 25 29 46 40 35 33 43 31 25 43 30 21 25 41 35 19 37 35 37 36 34 25 29 16 27 39 23 33 39 21 29 23 37 44 25 24 40 32 33 41 40 21 30 24 27 38 33 33 32 37 35 34 28 33 36 37 38 24 20 27 44 38 32 30 27 36 39 34 25 36 29 42 32 45 25 25 38 27 26 34 44 58 48 39 36 43 38 19 24 26 39 32 35 33 48 34 31 43 52 32 44 41 32 38 33 45 24 32 32 38 44 35 44 48 43 43 32 48 32 42 34 47 36 26 37 35 36 42 50 28 34 48 49 27 47 43 33 44 45 41 41 46 58 45 40 47 47 44 65 70 36 48 45 51 49 53 48 45 52 64 50 50 66 45 51 46 46 44 47 41 47 43 47 50 64 47 31 37 33 41 50 47 28 30 30 29 40 32 51 45 28 31 37 43 35 33 36 51 44 34 35 30 33 40 30 23 39 48 41 31 33 38 41 38 43 40 62 46 41 57 39 39 47 37 35 40 35 31 38 43 54 44 52 41 35 34 41 37 38 27 38 40 32 44 35 45 34 31 40 32 39 41 29 39 42 58 46 32 36 41 37 34 39 38 34 46 39 35 37 41 33 26 27 44 39 45 32 29 45 44 41 36 41 42 27 37 45 23 43 23 35 32 45 31 42 36 38 32 34 29 49 32 50 31 41 38 26 41 30 37 34 43 53 31 39 36 31 43 33 32 32 38 39 27 42 29 35 35 45 40 48 38 39 40 38 39 40 38 41 34 41 31 36 35 34 37 38 26 40 39 38 26 36 32 36 36 51 33 43 38 32 33 41 46 27 33 39 21 28 45 36 32 33 30 33 41 41 46 43 48 43 33 26 31 44 37 36 46 42 30 45 25 32 27 44 43 39 29 30 40 41 37 32 51 44 30 25 43 46 53 48 36 33 26 24 36 51 33 47</counts>
			</dataPoints>
		</scan>
	</xrdMeasurement>
</xrdMeasurements>