File: dataset/precursor_mixture/MnCO3_CaCO3_K2SO4.12-min.xrdml
<?xml version="1.0"?>
<xrdMeasurements xmlns="http://www.xrdml.com/XRDMeasurement/2.2" xmlns:xsi="http://www.w3.org/2001/XMLSchema-instance" xsi:schemaLocation="http://www.xrdml.com/XRDMeasurement/2.2 http://www.xrdml.com/XRDMeasurement/2.2/XRDMeasurement.xsd" status="Completed" recordIdentifier="{FABF4DA3-3708-473F-8972-113ACA96F1C3}">
	<comment>
		<entry/>
	</comment>
	<sample type="To be analyzed">
		<id>dara-29-2</id>
		<name></name>
		<preparedBy></preparedBy>
	</sample>
	<xrdMeasurement measurementType="Scan" status="Completed" sampleMode="Reflection">
		<usedWavelength intended="K-Alpha 1">
			<kAlpha1 unit="Angstrom">1.5405980</kAlpha1>
			<kAlpha2 unit="Angstrom">1.5444260</kAlpha2>
			<kBeta unit="Angstrom">1.3922500</kBeta>
			<ratioKAlpha2KAlpha1>0.5000</ratioKAlpha2KAlpha1>
		</usedWavelength>
		<incidentBeamPath>
			<radius unit="mm">145.00</radius>
			<xRayTube id="1010048" name="Empyrean Cu LFF HR (9430 033 7310x) DK437873">
				<tension unit="kV">40.0</tension>
				<current unit="mA">15.0</current>
				<anodeMaterial>Cu</anodeMaterial>
				<focus type="Line">
					<length unit="mm">12.0</length>
					<width unit="mm">0.4</width>
					<takeOffAngle unit="deg">6.0</takeOffAngle>
				</focus>
			</xRayTube>
			<filter id="20010004" name="Beta-filter Nickel">
				<material>Ni</material>
				<thickness unit="mm">0.020</thickness>
			</filter>
			<sollerSlit id="21010002" name="Soller slits 0.04 rad.">
				<opening unit="rad">0.0400</opening>
			</sollerSlit>
			<mask id="22031000" name="Fixed mask 13 mm">
				<width unit="mm">9.00</width>
			</mask>
			<divergenceSlit id="22120001" name="Divergence slit 1°" xsi:type="fixedDivergenceSlitType">
				<distanceToSample unit="mm">50.00</distanceToSample>
				<height unit="mm">1.52</height>
			</divergenceSlit>
		</incidentBeamPath>
		<beamKnife id="29030100" name="Beam knife low"/>
		<sampleMovement xsi:type="spinningSampleMovementType">
			<spinnerRevolutionTime unit="seconds">1.0</spinnerRevolutionTime>
		</sampleMovement>
		<diffractedBeamPath>
			<radius unit="mm">145.00</radius>
			<antiScatterSlit id="22090040" name="AS slit 9 mm" xsi:type="fixedAntiScatterSlitType">
				<height unit="mm">9.00</height>
			</antiScatterSlit>
			<sollerSlit id="21020003" name="Large Soller slits 0.04 rad.">
				<opening unit="rad">0.0400</opening>
			</sollerSlit>
			<filter id="20030001" name="Large beta-filter Nickel">
				<material>Ni</material>
				<thickness unit="mm">0.020</thickness>
			</filter>
			<detector id="7010019" name="PIXcel1D-Medipix3 detector" xsi:type="rtmsDetectorType">
				<phd unit="keV">
					<lowerLevel>4.0</lowerLevel>
					<upperLevel>11.3</upperLevel>
				</phd>
				<mode>Scanning</mode>
				<activeLength unit="deg">5.020</activeLength>
			</detector>
		</diffractedBeamPath>
		<scan appendNumber="0" mode="Continuous" scanAxis="Gonio" status="Completed">
			<header>
				<startTimeStamp>2024-03-24T14:49:46-07:00</startTimeStamp>
				<endTimeStamp>2024-03-24T15:02:14-07:00</endTimeStamp>
				<author>
					<name>AutomatedUser</name>
				</author>
				<source>
					<applicationSoftware version="1.6 (94)">PANalytical Aeris Instrument Suite</applicationSoftware>
					<instrumentControlSoftware version="3.0.0 20211014">AERIS</instrumentControlSoftware>
					<instrumentID>2879380</instrumentID>
				</source>
			</header>
			<dataPoints>
				<positions axis="2Theta" unit="deg">
					<startPosition>9.99043322</startPosition>
					<endPosition>100.09495370</endPosition>
				</positions>
				<positions axis="Omega" unit="deg">
					<startPosition>4.99521661</startPosition>
					<endPosition>50.04747685</endPosition>
				</positions>
				<commonCountingTime unit="seconds">18.249</commonCountingTime>
				<counts unit="counts">5057 5001 4989 4964 5028 5132 5032 5108 4965 5060 5013 4914 5022 4967 4844 4966 4993 5006 4939 4976 4994 4951 4939 4955 4920 4756 4946 5012 4820 4979 4926 5064 5019 4914 5001 4977 4990 4992 4863 4715 4837 4833 4869 4898 4774 4833 5015 4999 4834 4791 4792 4755 4894 4824 4766 4893 4783 4990 4838 4863 4805 4729 4858 4634 4753 4820 4761 4903 4795 4734 4716 4646 4759 4676 4717 4882 4819 4790 4684 4748 4704 4778 4818 4684 4612 4694 4729 4694 4692 4688 4774 4650 4687 4693 4657 4663 4551 4579 4627 4658 4635 4708 4630 4695 4618 4559 4732 4567 4667 4751 4556 4564 4543 4592 4725 4697 4662 4602 4613 4626 4617 4672 4644 4649 4684 4555 4647 4547 4579 4631 4521 4669 4559 4523 4569 4546 4551 4549 4588 4455 4700 4508 4529 4576 4563 4574 4513 4473 4597 4473 4560 4623 4441 4370 4545 4510 4455 4531 4444 4558 4511 4476 4483 4461 4435 4538 4412 4489 4528 4553 4355 4576 4541 4489 4533 4547 4396 4502 4464 4469 4458 4458 4562 4444 4360 4385 4516 4383 4292 4379 4480 4427 4379 4342 4554 4424 4410 4384 4344 4348 4329 4412 4374 4445 4411 4476 4317 4421 4471 4378 4394 4423 4293 4324 4265 4365 4305 4429 4398 4320 4339 4327 4291 4295 4281 4287 4432 4426 4289 4328 4371 4268 4367 4400 4417 4310 4254 4254 4269 4419 4227 4265 4170 4173 4332 4278 4281 4284 4336 4295 4217 4231 4242 4373 4240 4313 4348 4302 4200 4299 4247 4242 4153 4275 4189 4167 4261 4241 4139 4213 4107 4275 4326 4282 4184 4179 4075 4174 4159 4198 4068 4176 4233 4212 4331 4189 4185 4132 4262 4067 4234 4211 4125 4170 4112 4190 4100 4117 4211 4146 4166 4051 4290 4143 4105 4155 4181 4071 4081 4189 4209 4150 4116 4090 4056 4194 4088 4180 4099 3999 3969 4155 4199 4046 4047 4210 3959 4096 3959 4090 4050 4101 3978 4082 4136 4053 4067 3917 4061 4103 3964 3985 3944 3994 4005 4035 4076 4155 4133 4046 3989 4079 3922 3989 4170 4149 4139 3923 4067 4007 4151 4005 4107 4004 3940 3968 4067 4036 4085 3971 3951 3907 3980 3854 3997 3989 3999 4032 3834 3912 3999 3856 3981 4030 4006 3981 4069 3930 3823 3949 4005 3850 4044 3941 3942 3908 3906 3964 3965 3776 3985 3923 3989 3945 4014 3860 3929 3987 3980 4006 4004 3891 3981 3937 3873 3991 3867 3967 3896 3980 3835 3947 4025 3933 3944 3911 3959 3862 3945 3980 3886 4007 3927 3862 3869 3966 3876 3936 3902 4035 3950 3947 3995 3895 4005 3901 3824 3903 3892 3832 3793 3863 3827 3931 3868 3865 3903 3788 3969 3940 3806 3775 3909 3872 3756 3833 3780 3782 3931 3854 3946 3705 3945 3841 3710 3770 3873 3711 3892 3721 3966 3900 3756 3931 3934 3746 3940 3703 3845 3828 3876 3812 3752 3744 3866 3772 3928 3836 3828 3889 3722 3828 3813 3777 3777 3824 3776 3799 3867 3835 3793 3958 3772 3737 3770 3776 3741 3890 3742 3731 3855 3752 3752 4047 3786 3750 3800 3768 3714 3718 3772 3716 3666 3722 3720 3749 3733 3816 3730 3679 3709 3807 3731 3756 3689 3786 3722 3674 3807 3666 3809 3724 3714 3785 3703 3715 3763 3754 3753 3756 3807 3744 3777 3804 3664 3746 3816 3630 3733 3750 3652 3709 3785 3774 3613 3691 3760 3583 3821 3734 3718 3611 3750 3750 3712 3678 3750 3608 3620 3798 3814 3663 3657 3738 3703 3775 3736 3621 3696 3658 3601 3757 3737 3734 3642 3624 3723 3573 3589 3695 3718 3774 3722 3605 3650 3710 3592 3641 3604 3552 3648 3538 3654 3729 3657 3698 3625 3684 3702 3728 3604 3631 3580 3729 3553 3531 3655 3577 3635 3584 3500 3769 3651 3633 3654 3583 3589 3622 3652 3564 3571 3605 3580 3596 3632 3586 3650 3628 3675 3650 3553 3558 3639 3560 3676 3538 3675 3618 3689 3475 3660 3515 3568 3649 3623 3606 3610 3620 3723 3627 3589 3607 3546 3687 3509 3669 3741 3729 3578 3712 3621 3730 3749 3703 3797 3903 3871 3892 4065 4007 4059 4176 4223 4211 4463 4457 4564 4630 4453 4310 4310 4263 4070 4031 3857 3780 3883 3779 3775 3778 3813 3641 3639 3668 3636 3647 3517 3506 3479 3576 3376 3600 3519 3516 3501 3599 3442 3564 3458 3570 3393 3489 3455 3509 3547 3466 3365 3448 3475 3503 3516 3453 3436 3439 3448 3402 3515 3435 3547 3441 3432 3497 3432 3473 3430 3441 3302 3440 3497 3483 3486 3354 3487 3413 3326 3331 3476 3372 3361 3234 3476 3369 3390 3474 3404 3484 3470 3363 3444 3427 3263 3287 3353 3412 3319 3352 3262 3309 3290 3470 3394 3348 3304 3430 3295 3519 3346 3367 3417 3437 3398 3390 3388 3354 3427 3379 3276 3250 3353 3213 3314 3278 3420 3450 3323 3400 3270 3293 3461 3332 3346 3217 3309 3332 3367 3372 3311 3371 3407 3284 3251 3387 3299 3323 3288 3262 3229 3319 3240 3311 3350 3387 3292 3357 3247 3417 3284 3265 3289 3230 3255 3327 3207 3219 3218 3155 3275 3155 3320 3369 3224 3285 3333 3348 3230 3266 3304 3356 3252 3259 3248 3182 3335 3121 3350 3206 3149 3238 3249 3242 3341 3186 3119 3140 3212 3275 3206 3172 3225 3172 3218 3103 3206 3161 3223 3245 3186 3188 3155 3235 3153 3190 3158 3257 3208 3240 3053 3162 3189 3122 3193 3165 3106 3115 3113 3345 3118 3049 3193 3155 3171 3171 3131 3126 3130 3146 3152 3048 3119 3219 3190 3264 3117 3083 3104 3067 3254 3048 3161 3109 3031 3095 3143 3115 3067 3221 3170 3181 3155 3172 3231 3093 3039 3055 3037 3084 3071 3090 3116 3119 3071 3006 3079 3174 3002 3120 3084 3095 3091 3051 3087 2994 3083 3038 3099 3065 3018 3191 3059 3173 3078 3098 3056 3068 3139 3026 3058 3035 3070 3047 3099 3043 3070 3172 3099 3121 3114 3063 3032 3063 3233 3218 3122 3069 3076 3092 3119 3097 3168 3165 3182 3178 3092 3217 3125 3230 3264 3255 3353 3344 3415 3492 3372 3612 3712 3673 3759 3943 4019 4192 4443 4440 4410 4493 4475 4567 4439 4332 4320 4289 4356 4229 3956 3747 3692 3617 3540 3383 3255 3246 3058 3092 3111 2970 3047 3015 2962 3106 2996 3027 2966 2981 2977 3017 3093 2916 2933 2972 2997 2966 3138 2935 3104 2880 2988 2952 2951 2953 2983 2965 2861 2930 2957 2833 2978 3015 2973 2871 2993 2907 2994 2911 2975 2937 2924 2961 2919 2983 2891 3045 2907 2907 2887 2911 2938 3034 2861 2927 2884 2803 2966 2873 2822 2888 2949 2990 2991 2857 3019 2819 2972 2918 2792 2886 2896 2931 2957 2895 2939 2859 2768 2934 2921 2910 2854 2790 2877 2912 2826 2940 2853 2826 2863 2892 2862 2863 2810 2896 2935 2888 2848 2869 2918 2907 2823 2890 2790 2823 2834 2854 2856 2936 2980 2960 2805 2888 2938 2949 2881 2899 2999 2890 2919 2902 2888 2945 2841 2872 2887 2907 2985 2884 2927 2955 3024 2949 3059 2978 3032 3157 3177 3380 3109 3134 3313 3277 3377 3396 3347 3387 3372 3329 3336 3209 3177 3176 3044 2995 3014 2989 2882 2874 2895 2847 2907 2835 2845 2849 2883 2841 2959 2843 2946 2835 2899 2927 2819 2956 2968 2869 2818 2884 2918 2926 2804 2861 2855 2885 2819 3021 2859 2957 2893 2926 3032 3022 3149 3058 3081 3165 3067 3316 3334 3528 3572 3679 3881 3994 4247 4379 4618 4820 4930 4865 5205 5242 5093 4821 4557 4245 4066 3914 3705 3611 3334 3274 3166 3147 3131 3131 3192 3260 3303 3323 3456 3460 3569 3555 3633 3870 3958 4087 4130 4293 4408 4578 4872 4907 4976 5161 5430 5383 5533 5509 5481 5562 5309 5073 4767 4783 4710 4410 4174 4001 3729 3596 3469 3472 3354 3251 3195 3075 3158 3088 3039 2996 2955 2925 2968 2981 2961 2897 2897 2878 2919 2727 2872 2879 2697 2827 2771 2816 2824 2794 2726 2846 2806 2733 2808 2804 2713 2764 2680 2793 2692 2785 2672 2772 2735 2675 2754 2696 2725 2739 2547 2800 2805 2712 2670 2681 2713 2774 2630 2648 2820 2765 2637 2686 2616 2730 2723 2715 2691 2741 2629 2688 2694 2619 2558 2794 2736 2717 2677 2732 2708 2530 2640 2685 2643 2698 2759 2754 2750 2811 2748 2818 2836 2893 2898 2866 2854 2991 2918 2855 2979 2919 2827 2776 2836 2760 2763 2652 2781 2681 2600 2663 2563 2642 2635 2538 2696 2762 2609 2612 2703 2533 2733 2554 2650 2644 2576 2586 2491 2562 2580 2660 2549 2547 2613 2566 2556 2540 2581 2669 2642 2626 2538 2652 2696 2627 2582 2544 2659 2552 2609 2614 2626 2642 2633 2562 2522 2524 2648 2640 2554 2631 2569 2673 2574 2668 2596 2648 2648 2605 2625 2600 2710 2669 2707 2810 2751 2789 2941 2877 2924 3033 3025 2956 3059 3131 3097 2966 2859 2852 2948 2864 2865 2901 2871 2949 2823 2880 3041 2981 3150 3167 3310 3234 3173 2991 2802 2896 2777 2564 2663 2577 2479 2560 2609 2484 2556 2607 2503 2528 2580 2618 2487 2427 2576 2501 2597 2519 2552 2494 2499 2484 2447 2499 2581 2641 2528 2548 2535 2593 2525 2466 2583 2536 2544 2552 2494 2599 2552 2522 2503 2522 2569 2430 2603 2494 2516 2518 2533 2478 2490 2462 2496 2433 2467 2544 2474 2421 2478 2460 2461 2534 2494 2479 2481 2519 2479 2450 2558 2488 2584 2549 2616 2507 2470 2502 2556 2650 2505 2523 2514 2469 2512 2397 2444 2560 2609 2340 2436 2457 2396 2578 2438 2517 2550 2480 2463 2542 2482 2536 2502 2525 2489 2530 2519 2518 2568 2517 2439 2451 2551 2487 2438 2426 2422 2504 2445 2501 2477 2457 2490 2562 2522 2526 2488 2433 2551 2463 2473 2548 2429 2493 2511 2484 2548 2475 2440 2422 2475 2512 2413 2502 2483 2615 2539 2467 2510 2528 2571 2600 2611 2693 2647 2624 2628 2684 2656 2680 2681 2868 2857 2853 3115 3107 3168 3231 3370 3394 3430 3473 3404 3251 3230 3209 3305 3169 3141 3302 3154 3137 3221 3066 3072 3152 3159 3188 3265 3162 3189 3352 3149 3212 3178 3203 3237 3243 3420 3428 3404 3309 3411 3329 3517 3396 3465 3645 3583 3746 3766 3675 3855 3923 3960 4098 4166 4345 4522 4446 4781 4684 4770 4797 4978 4998 5202 5148 5310 5382 5685 5835 5974 6169 6396 6695 7094 7409 7682 8166 9043 9685 11089 12312 14240 16210 18920 22238 26769 32122 39312 47932 59879 72469 89848 109172 131912 158966 189953 216217 232865 222164 193787 157339 136065 123272 119703 113076 101853 78032 56389 37607 25398 18035 13798 11697 10461 9575 8955 8455 8168 8070 7775 7893 7790 8064 8053 8104 8440 8734 8966 8934 9225 9006 8986 8940 8648 8216 7581 7132 6387 6043 5640 5414 4861 4699 4209 4051 3791 3756 3520 3595 3409 3484 3441 3421 3324 3332 3218 3245 3221 3224 3236 3180 3248 3150 3139 3157 3119 3197 3118 3101 3053 3092 3203 3121 3079 3058 3150 3235 3147 3043 3185 3012 3044 3121 3072 3116 3167 3146 3119 3061 3078 3141 3058 3098 3226 3298 3231 3159 3334 3238 3236 3377 3361 3420 3450 3513 3654 3760 3826 4036 4167 4382 4580 5066 5523 6029 6630 7476 8239 9263 10027 11033 12127 12803 13572 13390 12619 11499 10170 9592 9208 9266 8987 8604 7733 7324 6817 6936 7019 7123 7286 7379 7146 6766 6362 5890 5815 5645 5682 5555 5261 5042 4768 4569 4633 4574 4785 4880 5078 5139 5601 5610 6103 6470 7039 7466 7896 8610 9199 9623 10131 10919 11256 11340 11499 11691 11378 11309 10724 10226 9824 9209 8908 8602 7890 7338 6726 6345 5888 5424 5095 4828 4551 4467 4098 3883 3820 3758 3697 3518 3412 3345 3362 3308 3207 3237 3150 3111 3194 3090 3023 3011 3034 3021 2884 2880 3026 2813 2894 2870 2808 2805 2888 2807 2838 2876 2672 2696 2716 2740 2754 2714 2691 2686 2682 2726 2784 2619 2667 2782 2797 2710 2708 2795 2754 2760 2755 2625 2678 2808 2721 2738 2707 2700 2700 2705 2628 2708 2629 2683 2680 2570 2744 2702 2735 2525 2623 2593 2643 2523 2619 2640 2582 2639 2653 2598 2585 2586 2601 2573 2634 2544 2575 2560 2634 2532 2592 2538 2543 2558 2535 2549 2486 2549 2515 2455 2493 2601 2559 2406 2499 2492 2520 2583 2499 2447 2605 2516 2469 2477 2440 2371 2425 2427 2442 2423 2488 2357 2469 2503 2522 2493 2445 2431 2547 2497 2458 2455 2460 2395 2453 2446 2424 2485 2423 2525 2507 2470 2457 2504 2477 2276 2454 2387 2271 2417 2352 2368 2475 2448 2439 2340 2367 2434 2419 2381 2388 2347 2455 2486 2394 2466 2402 2419 2392 2409 2394 2389 2440 2369 2369 2352 2389 2333 2405 2377 2430 2447 2401 2457 2518 2552 2626 2595 2624 2576 2544 2593 2613 2533 2521 2481 2550 2489 2463 2445 2434 2455 2385 2428 2409 2291 2427 2360 2439 2261 2319 2296 2304 2364 2210 2318 2350 2371 2418 2311 2348 2334 2349 2336 2358 2333 2184 2378 2376 2279 2285 2234 2298 2354 2293 2272 2249 2286 2221 2261 2270 2290 2271 2384 2347 2346 2313 2390 2279 2375 2324 2254 2328 2379 2329 2276 2199 2368 2224 2347 2281 2392 2375 2307 2349 2351 2320 2373 2292 2378 2365 2359 2307 2347 2256 2337 2326 2235 2261 2226 2203 2243 2273 2243 2327 2191 2234 2277 2173 2219 2211 2161 2228 2232 2235 2248 2284 2174 2232 2245 2239 2242 2166 2208 2254 2175 2286 2242 2253 2236 2222 2161 2281 2155 2331 2227 2274 2242 2243 2359 2283 2227 2189 2261 2220 2205 2164 2200 2152 2273 2192 2228 2307 2240 2300 2157 2260 2233 2312 2248 2228 2292 2169 2217 2315 2360 2309 2220 2253 2317 2346 2313 2318 2336 2315 2391 2362 2424 2463 2495 2546 2557 2593 2709 2747 2893 3169 3380 3690 3863 4468 4840 5423 5900 5874 5600 5034 4398 3932 3997 4096 4078 4209 4069 3734 3479 3151 2951 3046 2930 3105 3111 3261 3349 3413 3465 3355 3507 3683 3941 4164 4308 4364 4264 4127 3912 3847 3905 3704 3591 3602 3276 3279 3171 3071 3013 2840 2633 2585 2459 2410 2308 2385 2384 2419 2302 2286 2314 2310 2294 2334 2276 2284 2183 2203 2264 2198 2249 2204 2213 2214 2202 2254 2133 2188 2170 2231 2307 2157 2265 2252 2252 2175 2169 2207 2235 2176 2181 2191 2166 2119 2169 2162 2272 2181 2160 2201 2166 2231 2227 2215 2266 2118 2187 2240 2130 2236 2262 2180 2229 2254 2248 2286 2216 2285 2208 2249 2191 2296 2270 2252 2363 2217 2315 2297 2309 2412 2343 2402 2512 2645 2678 2722 2849 3059 3238 3424 3758 4111 4459 4833 4943 5084 4706 4628 3936 3829 3679 3648 3750 3754 3795 3703 3343 3180 3038 2897 2932 2924 2972 2922 3104 3139 3236 3246 3483 3538 3691 3734 3728 3729 3563 3632 3458 3372 3349 3432 3212 3225 3092 3029 2997 2841 2844 2856 2857 2829 2782 2717 2769 2780 2769 2703 2555 2623 2484 2578 2530 2523 2574 2453 2524 2366 2610 2554 2579 2639 2670 2741 2652 2630 2759 2650 2484 2467 2435 2367 2406 2382 2345 2365 2285 2228 2198 2125 2212 2106 2150 2156 2038 2062 2065 2034 2128 2090 2088 2082 2139 2054 2098 2033 2066 2183 2155 2041 2062 2033 2092 2044 2074 2031 2058 2010 2039 2019 2038 1992 2062 2152 2066 2113 2083 2109 2101 2084 2009 2082 2025 2072 2020 2094 2091 2104 2054 2069 2100 2033 2000 2070 1918 2096 2011 2063 2087 2019 2074 1979 2008 2077 2083 1982 2021 2044 1995 2000 2059 2117 2078 2140 2121 1999 2020 1978 2026 2015 2052 1999 2040 2008 1979 2088 2039 2115 2077 2055 2052 2071 2017 2005 2184 2012 2096 2013 2076 2022 2051 2177 2069 2137 2018 2170 2107 2134 2125 2120 2152 2175 2184 2278 2331 2290 2351 2406 2418 2641 2710 2857 2985 3147 3382 3547 3811 3920 3695 3566 3219 3196 2967 2938 2955 3060 2945 2940 2764 2729 2489 2413 2271 2201 2246 2206 2180 2159 2132 2024 2143 2092 2041 1989 2035 2036 2082 2082 2059 2120 2037 1928 2089 2033 2059 1980 1985 1980 1964 2017 1937 1965 2100 1965 2081 1938 2023 2005 1857 2026 1995 1875 1991 2031 1972 1942 1998 2093 2039 2023 2123 2036 1967 1952 2037 2046 2029 2036 2069 1954 2080 2046 2041 2112 2070 2065 2115 2173 2187 2195 2254 2376 2343 2358 2448 2546 2666 2615 2665 2742 2691 2889 2817 2946 2790 2656 2620 2487 2413 2436 2455 2333 2361 2377 2317 2255 2126 2114 2187 2029 2020 2060 2061 2035 2113 2103 2123 1970 1983 2084 2220 2102 2162 2276 2273 2294 2352 2473 2496 2537 2676 2843 2924 2764 2796 2561 2584 2458 2496 2437 2542 2561 2484 2459 2324 2220 2346 2242 2250 2301 2226 2182 2238 2255 2341 2223 2297 2345 2404 2401 2525 2517 2561 2704 2704 2870 2939 3066 3090 3132 3362 3500 3510 3565 3681 3680 3550 3546 3486 3455 3544 3308 3218 3205 3165 3047 2893 2849 2765 2772 2751 2442 2387 2446 2302 2291 2357 2243 2300 2213 2228 2187 2142 2117 2117 2060 2088 2014 2028 2153 2105 2020 2028 2045 2005 2062 2095 1964 2051 1968 1919 2009 2085 1993 1983 2006 1970 1954 1929 1914 2007 1935 1964 1909 2058 1848 1991 1944 1913 1942 1949 2010 1900 1939 1842 1875 1971 1849 1879 1896 1913 1929 1915 1843 1953 1967 1995 1937 1927 1928 1939 1964 1887 1911 1892 1909 1826 1925 1877 1855 1860 1976 1910 1894 1918 1873 1937 1945 1959 2037 1852 1924 1998 1919 1938 1849 1955 1944 2002 1936 1978 1882 1945 1911 1937 1886 1843 1898 1958 1989 1958 1974 1909 1969 1932 2043 2006 1956 1933 2010 1995 1912 2018 2029 1997 1983 2022 2020 2108 2123 2123 2154 2181 2296 2312 2439 2524 2572 2680 2585 2796 2640 2645 2722 2765 2993 3175 3392 3706 3988 4337 4500 4476 4513 4343 3937 3655 3605 3679 3754 3905 4191 4314 4390 3948 3712 3262 2934 2847 2830 2821 3026 3116 3178 3227 3282 3470 3411 3490 3563 3537 3270 3051 2864 2787 2634 2635 2609 2729 2673 2687 2581 2468 2372 2199 2106 2042 2034 1940 1929 1912 2004 1980 2045 1919 1993 1989 1966 1903 1914 2013 1957 1941 1989 1888 1903 1946 1945 1947 1972 1927 1853 1858 1900 1876 1829 1911 1884 1875 1944 1873 1928 1894 1900 1778 1881 1844 1921 1820 1913 1843 1973 1890 1912 1966 1939 1991 1826 1878 1840 1908 1883 1937 1870 1910 1878 1946 1961 1872 1875 1884 1945 1912 1949 1905 1949 1909 1913 1922 1885 2000 1922 1845 1895 1936 1973 1935 1880 1913 1985 1907 1933 1910 1931 1935 1883 1914 1950 1893 1911 2085 1999 1948 1962 1924 2002 1989 1938 2102 1948 2029 2039 2006 2040 2037 2127 2085 2150 2129 2201 2253 2259 2235 2252 2333 2367 2558 2544 2629 2821 2847 2992 3064 3093 3343 3218 3300 3483 3349 3323 3267 3317 3278 3229 3207 3229 3200 3149 3098 3007 2952 2953 2952 3036 2919 2843 2925 2762 2660 2556 2399 2313 2304 2328 2347 2352 2256 2336 2300 2144 2171 2062 2007 2047 2039 2044 1925 2063 1936 1920 1999 1986 1995 1883 1918 1909 1967 1887 1910 1861 1972 1927 1894 1890 1915 1887 1893 1865 1856 1834 1863 1862 1834 1857 1888 1918 1884 1925 1842 1853 1904 1850 1930 1862 1902 1871 1910 1864 1904 1854 1823 1816 1877 1869 1925 1866 1888 1800 1811 1893 1909 1905 1916 1891 1924 1961 1953 1950 1929 1954 1990 1875 1979 1833 1977 1978 1956 2040 1908 1889 1978 1918 1937 1930 1893 1866 1891 1852 1868 1800 1844 1859 1849 1898 1845 1844 1945 1853 1838 1932 1878 1879 1938 1927 1955 1932 2014 2088 2056 2242 2324 2398 2462 2425 2314 2247 2053 2106 1988 2116 2084 2132 2112 2105 2139 2186 2087 2015 2007 1904 1871 1888 1913 1879 1934 1921 1921 1993 1891 1950 1991 1942 1916 2035 1881 1935 2057 1974 2149 2142 2144 2163 2265 2310 2370 2485 2368 2448 2351 2313 2323 2184 2206 2173 2216 2261 2357 2259 2206 2290 2225 2170 2218 2173 2085 2161 2314 2357 2293 2407 2425 2511 2707 2905 3109 3377 3691 4207 4686 5150 5740 5881 5694 5541 4955 4369 3757 3588 3508 3546 3657 3891 3897 4086 3870 3552 3129 2995 2560 2546 2337 2165 2191 2130 2135 2164 2047 2002 2018 2094 2038 2027 2051 2072 2027 2006 1994 2043 1917 1952 1998 1947 1998 1987 2032 1914 1928 1974 2052 1949 2004 2135 2124 2073 2113 2323 2313 2397 2376 2477 2427 2277 2285 2236 2181 2172 2129 2119 2206 2178 2215 2338 2212 2238 2218 2123 2109 2130 2091 2142 2185 2320 2299 2418 2566 2668 2815 3093 3287 3622 4107 4377 4763 4987 4936 4605 4299 3694 3482 3242 3345 3454 3429 3741 3920 3912 4133 4038 3891 3659 3361 3073 2710 2541 2395 2437 2384 2329 2323 2404 2397 2463 2342 2231 2237 2045 2014 2051 1978 2071 1965 1942 1947 1957 1937 1919 1977 1988 1912 2030 2007 1912 1970 2019 2127 2094 2113 2174 2113 2141 2083 2037 2029 1858 2000 1966 2014 1958 2052 1955 2046 2006 1998 2047 2014 2017 1911 1933 1878 1929 1950 1986 1984 2003 1985 2071 1978 2071 1980 2142 2109 2158 2209 2179 2164 2195 2280 2323 2321 2272 2430 2404 2481 2438 2396 2442 2325 2331 2379 2348 2333 2409 2302 2260 2210 2180 2202 2144 2157 2102 2015 1988 2093 1947 2065 1983 1991 1942 1894 1980 1961 1907 1915 1970 1821 1940 1854 1902 1929 1946 1824 1860 1861 1871 1844 1805 1893 1855 1849 1861 1774 1892 1805 1832 1924 1763 1811 1840 1830 1824 1857 1797 1895 1859 1872 1869 1777 1842 1833 1935 1752 1784 1841 1775 1770 1834 1755 1770 1829 1757 1789 1837 1680 1858 1734 1779 1823 1818 1894 1834 1848 1826 1833 1876 1947 1903 1868 1834 1875 1909 1809 1910 1767 1859 1843 1856 1829 1843 1885 1886 1861 1793 1924 1933 1869 1904 1904 1948 1887 1863 1846 1913 1833 1930 1924 1754 1924 1906 1916 1921 1878 1901 1996 1914 1826 1890 1914 1811 1985 1946 1975 1886 1973 2003 2030 2033 1968 2011 2004 1961 2067 2075 2088 2032 2232 2123 2158 2243 2240 2367 2352 2390 2436 2563 2491 2560 2513 2773 2727 2991 3149 3173 3343 3528 3709 3790 3842 4013 4110 3903 3894 3976 4168 4002 4087 4072 4314 4433 4399 4515 4428 4430 4398 4253 4214 3929 3949 3861 3666 3545 3650 3507 3427 3436 3318 3158 3107 2990 2906 2730 2622 2665 2574 2608 2412 2390 2325 2284 2311 2267 2158 2216 2177 2161 2069 2149 2080 2028 2087 1993 1923 1939 2015 2076 1938 2044 1982 2025 2029 1997 2028 2075 1969 2016 1933 2043 1992 1880 1914 1963 1986 1924 2003 1909 1939 1990 1929 1912 1898 1919 1875 1835 1868 1896 1892 1780 1889 1832 1847 1757 1751 1795 1808 1779 1858 1796 1748 1803 1734 1773 1785 1710 1807 1809 1660 1827 1823 1732 1801 1825 1760 1798 1796 1773 1744 1773 1726 1827 1832 1733 1725 1822 1810 1766 1755 1819 1772 1782 1736 1809 1776 1694 1791 1712 1715 1725 1749 1836 1765 1777 1808 1802 1787 1793 1746 1708 1784 1691 1774 1772 1832 1789 1780 1807 1716 1770 1788 1815 1819 1728 1780 1686 1798 1813 1732 1790 1767 1767 1752 1792 1789 1771 1737 1738 1834 1720 1720 1800 1783 1774 1792 1779 1805 1787 1778 1861 1810 1816 1798 1849 1680 1734 1705 1783 1762 1784 1854 1777 1821 1793 1802 1775 1681 1747 1726 1732 1856 1666 1813 1758 1750 1777 1757 1766 1798 1770 1744 1719 1753 1735 1732 1714 1748 1696 1740 1876 1824 1700 1770 1771 1753 1748 1837 1794 1892 1951 2003 2017 2033 2055 1991 1936 1845 1914 1903 1895 1935 1860 1815 1944 1895 1899 1925 1939 2002 1953 2020 2056 1987 1931 1874 1980 1961 1916 1861 1797 1825 1814 1875 1938 1833 1947 1890 1853 1960 1956 1953 1959 2034 2049 2226 2295 2435 2647 2852 3085 3192 2977 2708 2374 2270 2097 2126 2084 2060 2097 2270 2334 2334 2414 2429 2290 2175 2096 2014 2096 1969 2004 2009 2029 2089 2299 2370 2469 2680 2919 3039 3214 3140 3104 2756 2477 2271 2215 2151 2121 2229 2234 2312 2364 2348 2410 2349 2344 2069 2126 1944 1948 1792 1792 1778 1774 1769 1721 1742 1728 1803 1732 1746 1712 1801 1728 1722 1830 1714 1752 1698 1744 1693 1745 1735 1724 1639 1768 1749 1713 1696 1717 1684 1763 1729 1672 1800 1705 1668 1729 1742 1703 1738 1731 1729 1694 1818 1661 1763 1651 1700 1746 1716 1714 1717 1643 1648 1618 1689 1651 1640 1705 1685 1732 1660 1722 1751 1660 1749 1707 1715 1746 1698 1719 1720 1781 1738 1763 1757 1707 1694 1653 1755 1751 1747 1648 1736 1709 1770 1785 1732 1723 1772 1701 1708 1784 1802 1806 1858 1836 1930 1887 1914 1903 1855 1865 1846 1744 1803 1785 1845 1806 1839 1886 1950 1909 1889 1963 1962 1908 1814 1868 1894 1809 1912 2019 1997 1966 1959 1943 2037 2047 1927 1834 1880 1854 1887 1808 1931 1849 1747 1906 1866 1864 1848 1854 1792 1728 1760 1712 1726 1816 1662 1782 1727 1767 1716 1755 1735 1735 1794 1697 1768 1713 1780 1693 1850 1852 1865 1828 2009 1852 1961 2010 1938 1933 1883 1862 1910 1826 1756 1791 1774 1816 1787 1849 1871 1877 1827 1863 1819 1815 1776 1814 1886 1904 1835 1830 1887 1941 2017 1965 2250 2278 2394 2357 2395 2350 2202 2074 2011 1993 1920 1954 1954 1890 1883 1937 1961 2086 2020 1972 1953 1911 1824 1859 1865 1717 1841 1761 1725 1748 1781 1710 1744 1716 1782 1709 1678 1758 1713 1601 1680 1735 1670 1726 1672 1746 1754 1739 1696 1688 1745 1765 1670 1659 1813 1798 1751 1744 1751 1751 1770 1816 1896 1939 1992 1934 1987 1912 1974 1869 1847 1819 1834 1776 1758 1769 1821 1729 1786 1889 1838 1878 1861 1811 1808 1821 1741 1677 1716 1742 1802 1801 1694 1734 1717 1771 1743 1763 1722 1770 1739 1765 1821 1975 1900 1948 1981 1921 1964 1812 1876 1694 1781 1779 1823 1821 1895 1823 1986 1961 2025 1990 2095 2063 1993 1989 1963 1915 1933 1810 1942 2054 1988 1949 1984 1871 1872 1972 1918 1871 1848 1877 1881 1886 1913 1917 1811 1879 1925 1844 1882 1959 1922 1930 1883 1946 1905 1905 1895 1824 1845 1827 1822 1780 1809 1766 1883 1846 1793 1804 1709 1747 1694 1760 1836 1734 1772 1768 1699 1763 1841 1741 1681 1730 1765 1756 1731 1704 1750 1667 1721 1771 1778 1703 1780 1862 1748 1755 1842 1789 1878 1798 1807 1985 1953 1823 1786 1843 1814 1764 1804 1783 1883 1829 1877 1872 1856 1869 1918 1944 1935 1881 1939 1904 2024 2014 2057 1978 2050 2090 2116 2146 2235 2199 2347 2329 2388 2432 2503 2507 2391 2469 2419 2353 2397 2387 2301 2367 2280 2335 2353 2321 2210 2212 2173 2179 2067 2155 2155 2085 2026 1987 2052 1961 2068 1968 2099 1872 1932 1944 1933 1907 1822 1869 1963 1993 1991 1926 1999 1908 1908 1924 1811 1871 1825 1858 1818 1763 1870 1849 1861 1871 1834 1891 1947 1964 1946 1937 2001 2047 2080 2173 2322 2518 2465 2462 2357 2298 2116 2125 2064 2080 1997 2016 2032 2085 2077 2202 2235 2332 2266 2302 2227 2188 2329 2307 2433 2539 2981 3146 3736 4498 5548 6433 7409 7630 7458 6192 5010 3865 3215 2900 2766 2673 2763 2937 3207 3607 3983 4394 4808 4734 4353 3780 3095 2733 2475 2161 2182 2112 2070 2002 1983 2075 2106 2208 2284 2310 2365 2386 2247 2263 2116 1976 2008 1997 1868 1919 1916 1895 1918 2055 1984 2107 2065 1980 1940 1981 1839 1852 1733 1762 1839 1779 1727 1688 1680 1697 1662 1721 1786 1755 1755 1763 1708 1746 1628 1736 1730 1724 1731 1767 1785 1828 1815 1740 1850 1905 1760 1758 1795 1772 1757 1772 1649 1721 1746 1708 1690 1647 1730 1742 1772 1845 1713 1687 1627 1717 1663 1689 1666 1753 1705 1638 1665 1653 1685 1608 1625 1659 1650 1682 1642 1753 1627 1676 1663 1638 1720 1769 1673 1569 1616 1647 1610 1725 1695 1702 1663 1670 1648 1696 1613 1687 1614 1612 1698 1737 1736 1706 1789 1691 1630 1755 1746 1711 1716 1756 1762 1779 1809 1862 1841 1831 1826 1826 1796 1799 1791 1707 1673 1776 1711 1717 1759 1832 1705 1782 1722 1724 1759 1727 1807 1770 1688 1679 1718 1763 1773 1810 1787 1827 1831 1881 1826 1827 1811 1792 1763 1754 1815 1759 1767 1720 1842 1746 1766 1901 1800 1865 1824 1930 1772 1835 1805 1840 1751 1857 1788 1876 1843 1790 1809 1786 1801 1801 1854 1901 1812 1845 1822 1790 1823 1827 1805 1876 1865 1817 1874 1870 1811 1851 1934 1924 1974 1923 1947 1954 1966 2068 2017 2116 2072 2097 2164 2119 2190 2175 2126 2192 2185 2045 2110 2008 2098 2081 2047 2027 1988 2039 2014 1990 1984 2024 2019 2052 1941 1936 2020 1982 2007 2027 2063 2097 2049 2088 2218 2223 2433 2540 2645 2572 2582 2381 2267 2065 1940 1985 1907 1902 1882 1939 1939 1997 2036 2091 2064 2282 2137 2051 2039 1945 1872 1883 1871 1805 1865 1847 1888 1791 1789 1834 1931 1975 1999 2099 2223 2267 2325 2336 2113 2111 2103 1992 1925 2017 1996 2082 2170 2252 2351 2407 2373 2370 2341 2281 2206 2099 2104 2023 1955 1859 1849 1941 1932 1958 2037 2045 2081 2054 2034 1899 2006 1884 1999 1921 1935 2001 2023 1988 2177 2181 2205 2334 2291 2184 2156 2118 1964 1979 1858 1812 1850 1853 1954 1912 1895 2003 2030 2053 1925 2038 1952 2094 1879 1953 1877 1864 1823 1899 1841 1840 1866 1860 1892 1933 1810 1915 1817 1886 1870 1916 1960 1936 1840 1971 1972 1881 1998 1881 1969 2067 2172 2287 2405 2456 2565 2604 2644 2641 2613 2376 2224 2164 2166 1932 1963 1900 1970 2036 1924 1980 2101 2153 2156 2184 2092 2134 2059 2028 1904 1862 1820 1874 1830 1839 1801 1807 1854 1765 1860 1786 1844 1796 1769 1818 1826 1859 1960 1817 1841 1843 1894 1833 1832 1781 1878 1829 1868 1874 1845 1916 1935 1837 1915 1885 1866 1764 1820 1854 1849 1742 1696 1798 1759 1791 1767 1783 1814 1791 1748 1800 1808 1804 1833 1795 1754 1775 1798 1788 1807 1761 1704 1752 1793 1730 1748 1740 1674 1725 1662 1753 1703 1690 1604 1715 1759 1738 1722 1704 1661 1716 1750 1739 1707 1788 1678 1684 1765 1627 1746 1728 1686 1745 1748 1743 1782 1792 1888 1952 2023 1900 2041 2054 1947 1919 1856 1824 1842 1723 1759 1722 1766 1782 1793 1768 1782 1764 1814 1882 1868 1980 1951 1918 1920 1826 1772 1902 1914 1929 1860 1787 1822 1799 1772 1831 1803 1807 1782 1892 1875 1929 1987 2021 2015 2163 2058 2088 2111 2126 2141 2082 2203 2124 2073 2192 2133 2249 2121 2021 2005 1982 2055 2012 2003 2089 1978 1893 1984 1936 2047 1888 1874 1864 1967 1917 1942 1883 1884 1750 1799 1787 1807 1772 1659 1752 1703 1757 1755 1714 1666 1685 1710 1723 1737 1699 1633 1696 1701 1737 1653 1654 1575 1701 1683 1542 1604 1667 1732 1714 1597 1650 1590 1680 1667 1728 1623 1621 1673 1671 1612 1594 1666 1697 1674 1712 1692 1716 1753 1672 1678 1757 1685 1645 1641 1726 1726 1629 1711 1741 1687 1666 1593 1643 1631 1536 1643 1611 1662 1650 1606 1719 1627 1631 1651 1710 1651 1644 1555 1608 1619 1546 1659 1690 1550 1635 1557 1583 1566 1625 1589 1649 1616 1603 1536 1576 1576 1647 1652 1535 1697 1580 1658 1604 1647 1620 1616 1615 1573 1669 1655 1656 1689 1607 1698 1628 1695 1607 1701 1689 1666 1663 1727 1652 1793 1764 1776 1860 1828 1868 1821 1853 1795 1680 1689 1728 1736 1742 1690 1779 1791 1935 1925 2011 2101 2056 2105 2082 1948 1981 1790 1804 1670 1729 1638 1672 1696 1681 1721 1760 1688 1818 1791 1734 1800 1789 1693 1738 1745 1620 1767 1597 1674 1680 1628 1576 1727 1656 1669 1637 1596 1613 1601 1734 1597 1621 1664 1709 1690 1633 1607 1542 1627 1568 1660 1648 1663 1614 1622 1531 1642 1646 1625 1567 1586 1656 1701 1540 1690 1671 1722 1703 1712 1737 1732 1624 1742 1766 1776 1743 1804 1754 1919 1812 1913 1799 1739 1799 1786 1742 1766 1765 1650 1728 1701 1611 1651 1749 1691 1710 1687 1703 1781 1741 1759 1665 1686 1691 1592 1698 1628 1609 1596 1626 1587 1628 1667 1512 1551 1651 1575 1589 1581 1660 1648 1544 1536 1641 1568 1545 1611 1547 1692 1618 1538 1615 1638 1616 1667 1659 1577 1591 1612 1604 1537 1667 1699 1561 1555 1605 1576 1626 1605 1617 1609 1595 1637 1642 1671 1556 1653 1612 1638 1576 1530 1565 1598 1512 1580 1554 1559 1543 1583 1630 1585 1595 1575 1533 1583 1551 1570 1621 1611 1602 1551 1552 1589 1564 1545 1558 1556 1591 1498 1567 1564 1543 1522 1662 1546 1579 1564 1647 1612 1574 1613 1631 1561 1603 1586 1553 1507 1658 1536 1644 1613 1572 1527 1611 1596 1551 1567 1623 1621 1648 1509 1586 1537 1592 1592 1504 1589 1548 1608 1567 1557 1671 1576 1696 1566 1663 1642 1633 1560 1670 1619 1582 1604 1550 1677 1608 1678 1628 1684 1661 1706 1717 1647 1608 1739 1692 1746 1787 1755 1790 1815 1743 1704 1762 1734 1780 1717 1777 1662 1749 1690 1687 1748 1756 1793 1774 1800 1798 1796 1825 1901 1754 1885 1789 1800 1753 1829 1744 1727 1741 1718 1770 1692 1662 1692 1772 1780 1783 1794 1801 1806 1791 1752 1764 1674 1740 1617 1714 1637 1667 1730 1674 1679 1673 1635 1729 1737 1807 1732 1745 1779 1944 1929 1958 1821 1925 1920 1829 1828 1732 1775 1673 1631 1684 1606 1636 1636 1697 1800 1688 1648 1691 1795 1715 1762 1676 1757 1648 1684 1685 1600 1614 1552 1605 1639 1594 1587 1601 1590 1610 1551 1615 1609 1658 1612 1586 1630 1693 1586 1701 1652 1627 1588 1650 1615 1669 1655 1596 1643 1656 1629 1637 1761 1598 1573 1628 1674 1688 1642 1601 1720 1622 1760 1703 1784 1755 1720 1778 1864 1802 1836 1847 1797 1702 1846 1683 1606 1653 1747 1613 1714 1648 1686 1687 1703 1784 1707 1719 1646 1668 1676 1711 1702 1705 1654 1582 1604 1611 1648 1505 1591 1627 1616 1530 1559 1604 1602 1580 1596 1607 1682 1563 1654 1589 1570 1567 1570 1560 1567 1595 1599 1553 1589 1599 1536 1662 1598 1641 1545 1514 1565 1505 1530 1571 1583 1623 1535 1572 1525 1563 1604 1562 1574 1529 1610 1540 1590 1614 1609 1582 1557 1572 1573 1621 1539 1580 1585 1516 1571 1587 1606 1562 1647 1569 1607 1576 1507 1618 1476 1561 1495 1548 1524 1535 1592 1622 1570 1587 1544 1563 1549 1545 1594 1614 1591 1567 1564 1542 1632 1577 1579 1582 1589 1544 1624 1614 1613 1564 1506 1593 1468 1575 1607 1544 1559 1531 1578 1603 1603 1612 1592 1635 1630 1608 1595 1515 1602 1614 1604 1649 1603 1630 1663 1800 1771 1882 1847 1939 1874 1820 1791 1764 1657 1693 1628 1667 1670 1674 1624 1664 1645 1741 1721 1638 1720 1751 1795 1772 1795 1776 1796 1814 1816 1748 1737 1696 1690 1643 1688 1693 1665 1763 1621 1685 1692 1658 1623 1692 1748 1759 1805 1700 1745 1852 1763 1764 1753 1715 1739 1721 1708 1702 1692 1652 1804 1632 1712 1747 1654 1746 1778 1736 1762 1702 1718 1741 1746 1798 1716 1727 1757 1750 1762 1747 1832 1882 1816 1840 1838 1904 1902 1879 1868 1909 1841 1788 1868 1830 1724 1764 1732 1696 1712 1672 1736 1719 1711 1690 1762 1803 1648 1709 1710 1674 1654 1662 1660 1623 1705 1649 1691 1683 1659 1740 1644 1645 1604 1634 1663 1602 1645 1650 1587 1669 1676 1702 1650 1633 1567 1630 1721 1672 1608 1604 1706 1622 1633 1640 1720 1604 1690 1581 1678 1725 1758 1794 1732 1706 1719 1812 1854 1885 1930 2002 2013 2038 2094 2074 2207 2067 1957 1911 1847 1853 1713 1760 1739 1693 1719 1685 1685 1745 1767 1728 1823 1849 1905 1865 1948 1973 1819 1850 1638 1732 1731 1668 1660 1687 1685 1684 1610 1626 1607 1648 1650 1684 1653 1608 1641 1586 1666 1781 1627 1724 1640 1657 1676 1712 1731 1696 1680 1748 1824 1716 1783 1765 1782 1799 1816 1787 1787 1786 1732 1696 1801 1761 1668 1754 1714 1794 1790 1808 1758 1694 1774 1756 1795 1699 1643 1739 1708 1626 1725 1698 1654 1703 1645 1702 1664 1692 1636 1647 1654 1699 1757 1693 1644 1715 1613 1692 1593 1650 1696 1654 1645 1583 1580 1569 1619 1631 1620 1697 1619 1763 1676 1652 1616 1604 1722 1592 1603 1606 1667 1594 1514 1572 1582 1617 1530 1600 1597 1596 1626 1606 1600 1640 1617 1574 1585 1629 1623 1624 1638 1595 1635 1678 1645 1636 1579 1587 1589 1650 1593 1573 1548 1600 1612 1575 1598 1579 1607 1654 1606 1568 1614 1589 1588 1588 1577 1630 1643 1598 1687 1529 1633 1624 1590 1630 1682 1611 1512 1594 1583 1595 1580 1569 1624 1510 1512 1595 1582 1553 1498 1587 1608 1630 1614 1612 1620 1645 1585 1571 1536 1547 1628 1587 1602 1632 1613 1594 1511 1599 1577 1496 1528 1546 1536 1603 1605 1553 1575 1649 1589 1631 1630 1515 1663 1530 1636 1653 1573 1629 1582 1564 1649 1585 1686 1729 1675 1689 1623 1706 1677 1644 1663 1668 1588 1644 1688 1627 1654 1618 1649 1559 1636 1646 1688 1603 1645 1698 1670 1631 1660 1639 1618 1598 1630 1606 1612 1580 1588 1610 1617 1560 1666 1526 1643 1631 1634 1579 1535 1572 1569 1561 1514 1629 1536 1542 1488 1573 1660 1505 1491 1546 1541 1568 1625 1583 1538 1549 1558 1593 1547 1573 1541 1574 1595 1592 1607 1560 1597 1543 1583 1493 1573 1545 1596 1557 1547 1570 1604 1502 1496 1582 1599 1508 1572 1570 1466 1527 1548 1638 1597 1563 1564 1640 1608 1568 1595 1607 1625 1686 1627 1656 1666 1678 1634 1624 1687 1607 1618 1578 1630 1558 1597 1610 1595 1575 1628 1605 1715 1647 1638 1628 1666 1754 1678 1713 1643 1636 1622 1681 1655 1647 1605 1587 1612 1607 1566 1570 1637 1627 1612 1602 1582 1633 1565 1655 1645 1715 1697 1729 1721 1860 1872 1910 1988 2077 2191 2138 2008 2018 1861 1899 1834 1723 1687 1713 1613 1678 1680 1669 1665 1721 1679 1762 1759 1736 1807 1930 1870 1914 1855 1894 1822 1803 1792 1794 1789 1722 1720 1726 1616 1698 1635 1673 1656 1632 1677 1649 1634 1627 1615 1668 1651 1736 1675 1721 1750 1789 1759 1784 1828 1825 1695 1719 1714 1627 1638 1621 1708 1632 1647 1603 1620 1605 1627 1639 1596 1622 1613 1635 1697 1656 1686 1649 1651 1670 1593 1641 1568 1636 1536 1567 1553 1610 1646 1597 1604 1670 1549 1587 1617 1558 1534 1628 1602 1545 1540 1541 1588 1580 1607 1523 1597 1496 1582 1575 1511 1615 1599 1605 1539 1601 1616 1555 1681 1550 1575 1590 1548 1657 1496 1473 1463 1555 1478 1571 1600 1524 1584 1449 1496 1518 1566 1517 1511 1562 1566 1545 1651 1640 1484 1523 1526 1560 1585 1607 1539 1533 1597 1583 1551 1614 1627 1599 1627 1622 1585 1629 1635 1671 1658 1733 1626 1564 1641 1646 1521 1584 1618 1672 1597 1625 1523 1588 1620 1623 1618 1601 1646 1607 1603 1665 1630 1694 1647 1632 1634 1684 1642 1664 1735 1694 1697 1749 1723 1796 1889 1990 1910 1929 2029 1974 1967 1913 1893 1902 1834 1835 1875 1782 1770 1769 1859 1776 1751 1810 1768 1729 1728 1771 1750 1794 1813 1837 1858 1740 1827 1812 1888 1797 1774 1745 1750 1711 1751 1766 1709 1721 1755 1746 1725 1664 1654 1691 1663 1599 1747 1787 1653 1690 1722 1639 1695 1768 1773 1643 1691 1656 1699 1733 1641 1769 1705 1734 1760 1552 1720 1720 1720 1732 1688 1692 1696 1699 1733 1692 1664 1688 1749 1786 1826 1724 1714 1736 1747 1753 1739 1752 1742 1722 1654 1814 1749 1811 1828 1855 1808 1905 1869 1846 1841 1847 1830 1777 1863 1727 1838 1756 1734 1720 1793 1656 1680 1756 1695 1689 1730 1710 1741 1814 1737 1742 1765 1756 1762 1821 1658 1731 1709 1674 1666 1587 1618 1653 1592 1642 1589 1703 1613 1661 1641 1710 1679 1624 1717 1707 1630 1644 1621 1536 1606 1617 1593 1648 1529 1566 1564 1583 1627 1612 1661 1650 1576 1638 1605 1652 1588 1691 1651 1526 1652 1638 1521 1586 1524 1599 1628 1534 1544 1583 1547 1550 1504 1515 1588 1552 1564 1592 1578 1478 1607 1556 1562 1585 1562 1608 1553 1628 1588 1547 1613 1507 1536 1642 1577 1579 1521 1544 1509 1560 1490 1593 1556 1551 1577 1607 1605 1562 1630 1576 1547 1583 1607 1575 1548 1575 1572 1565 1628 1611 1580 1641 1593 1600 1517 1521 1514 1604 1551 1553 1485 1560 1580 1563 1611 1647 1596 1630 1636 1613 1573 1559 1624 1642 1527 1580 1501 1530 1568 1534 1536 1518 1557 1599 1511 1553 1535 1494 1562 1539 1599 1606 1551 1542 1543 1598 1584 1557 1602 1589 1516 1562 1596 1554 1539 1562 1638 1530 1621 1602 1567 1544 1539 1531 1551 1564 1553 1555 1602 1593 1530 1581 1553 1620 1573 1509 1616 1580 1589 1570 1605 1569 1538 1563 1516 1650 1608 1589 1517 1537 1571 1578 1540 1593 1622 1641 1517 1639 1534 1622 1616 1523 1589 1588 1536 1599 1580 1610 1553 1555 1572 1540 1599 1530 1548 1581 1582 1657 1615 1588 1530 1600 1610 1644 1688 1533 1519 1617 1579 1638 1653 1616 1528 1659 1666 1629 1613 1720 1636 1550 1664 1678 1680 1740 1677 1664 1734 1664 1727 1692 1690 1723 1745 1689 1702 1717 1694 1732 1670 1727 1707 1717 1727 1746 1777 1738 1744 1756 1719 1765 1735 1736 1820 1751 1850 1833 1814 1768 1871 1879 1798 1760 1829 1737 1892 1799 1760 1766 1851 1718 1787 1648 1841 1744 1724 1733 1724 1686 1673 1686 1777 1770 1802 1790 1722 1702 1722 1764 1709 1736 1602 1683 1690 1688 1615 1709 1625 1576 1613 1656 1668 1646 1612 1564 1644 1645 1581 1705 1607 1580 1609 1566 1664 1612 1524 1643 1543 1602 1597 1492 1616 1557 1587 1598 1630 1615 1589 1583 1577 1585 1564 1609 1578 1620 1639 1608 1662 1553 1676 1664 1638 1571 1598 1636 1650 1551 1525 1626 1602 1624 1571 1587 1626 1609 1641 1737 1648 1702 1634 1670 1572 1742 1702 1615 1650 1643 1571 1608 1688 1647 1599 1651 1636 1687 1726 1687 1756 1772 1795 1756 1798 1720 1706 1722 1759 1644 1675 1641 1664 1692 1699 1658 1749 1602 1630 1720 1708 1811 1810 1757 1892 1907 1767 1839 1885 1862 1774 1721 1819 1803 1657 1763 1794 1769 1713 1677 1682 1653 1606 1715 1626 1687 1658 1686 1755 1711 1721 1720 1703 1741 1662 1703 1654 1644 1712 1636 1647 1675 1641 1737 1613 1590 1616 1663 1623 1657 1611 1648 1670 1644 1595 1568 1594 1575 1597 1593 1512 1560 1520 1613 1578 1555 1612 1577 1626 1577 1569 1597 1547 1571 1581 1629 1590 1616 1587 1565 1605 1528 1579 1522 1578 1538 1584 1573 1581 1620 1572 1591 1621 1643 1680 1663 1554 1520 1581 1621 1621 1569 1594 1516 1647 1631 1619 1669 1660 1577 1565 1609 1694 1649 1644 1597 1624 1606 1597 1581 1546 1614 1556 1553 1563 1549 1513 1557 1615 1630 1559 1589 1602 1546 1614 1550 1604 1530 1552 1582 1583 1557 1527 1568 1511 1555 1567 1588 1606 1590 1515 1565 1568 1552 1564 1533 1603 1524 1524 1571 1569 1593 1491 1544 1552 1544 1486 1521 1555 1545 1477 1567 1507 1543 1528 1516 1525 1569 1539 1573 1506 1593 1506 1599 1578 1556 1546 1542 1583 1583 1617 1496 1582 1576 1585 1684 1612 1573 1569 1597 1522 1594 1545 1552 1516 1560 1584 1560 1549 1546 1543 1559 1528 1544 1597 1525 1540 1482 1581 1525 1483 1499 1566 1574 1497 1627 1538 1534 1560 1586 1540 1564 1650 1526 1538 1500 1521 1545 1505 1573 1535 1636 1505 1579 1551 1574 1547 1515 1603 1570 1653 1581 1574 1576 1495 1558 1569 1511 1537 1522 1527 1567 1585 1502 1519 1480 1555 1616 1611 1494 1560 1531 1639 1598 1577 1513 1509 1432 1545 1529 1576 1583 1591 1518 1562 1516 1548 1504 1634 1533 1594 1475 1612 1556 1609 1553 1550 1586 1550 1583 1610 1559 1518 1621 1660 1673 1644 1816 1823 1821 1801 1790 1803 1776 1637 1619 1634 1659 1655 1691 1689 1584 1637 1643 1595 1580 1614 1611 1588 1559 1605 1592 1679 1656 1644 1735 1678 1681 1714 1673 1643 1599 1646 1604 1634 1548 1663 1604 1591 1545 1565 1535 1566 1577 1500 1546 1504 1609 1591 1481 1536 1554 1570 1590 1582 1482 1491 1554 1591 1553 1630 1536 1593 1599 1646 1581 1535 1607 1590 1590 1690 1619 1587 1653 1703 1702 1734 1587 1681 1745 1689 1617 1664 1479 1600 1616 1585 1538 1578 1552 1597 1556 1568 1633 1589 1563 1510 1571 1548 1587 1626 1598 1600 1667 1603 1619 1616 1605 1640 1562 1587 1610 1574 1603 1544 1551 1616 1537 1542 1596 1617 1702 1622 1581 1623 1611 1619 1553 1646 1588 1548 1614 1624 1630 1609 1536 1616 1562 1658 1654 1658 1577 1641 1609 1632 1650 1702 1774 1695 1819 1890 1852 1829 1997 1946 1905 1850 1783 1718 1743 1681 1727 1710 1765 1759 1637 1662 1656 1714 1748 1687 1739 1732 1824 1892 2050 2080 2092 2250 2257 2344 2331 2170 2128 2001 2040 1936 1891 1786 1851 1779 1792 1763 1723 1709 1704 1705 1725 1664 1693 1654 1710 1750 1789 1859 1768 1859 1878 1906 1869 1870 1864 1781 1755 1680 1754 1643 1713 1655 1697 1674 1640 1625 1565 1612 1527 1623 1641 1603 1545 1609 1607 1545 1610 1585 1602 1601 1637 1542 1598 1595 1658 1568 1508 1535 1670 1527 1577 1560 1597 1563 1568 1631 1554 1551 1547 1591 1684 1606 1568 1607 1585 1643 1603 1561 1641 1583 1561 1547 1597 1576 1651 1677 1620 1581 1633 1655 1626 1635 1602 1670 1671 1771 1833 1801 1858 1771 1735 1861 1805 1750 1675 1699 1683 1550 1655 1622 1631 1604 1604 1593 1575 1624 1590 1584 1541 1670 1665 1629 1683 1635 1651 1685 1628 1657 1674 1678 1643 1607 1710 1614 1613 1593 1641 1550 1560 1571 1602 1613 1546 1554 1566 1505 1604 1547 1578 1545 1619 1485 1614 1602 1600 1525 1530 1612 1561 1547 1645 1617 1567 1541 1566 1539 1579 1619 1576 1543 1615 1567 1569 1587 1578 1581 1609 1651 1628 1586 1641 1635 1587 1541 1612 1567 1598 1538 1548 1556 1506 1579 1524 1568 1514 1528 1567 1505 1545 1567 1517 1573 1572 1581 1579 1563 1550 1546 1594 1595 1631 1604 1568 1569 1621 1490 1589 1613 1579 1529 1570 1467 1518 1568 1550 1631 1606 1558 1552 1537 1622 1571 1536 1578 1593 1580 1571 1572 1555 1687 1623 1555 1620 1612 1611 1600 1600 1638 1599 1564 1590 1561 1537 1675 1600 1566 1577 1557 1595 1550 1542 1593 1586 1629 1668 1579 1609 1611 1583 1710 1611 1602 1623 1658 1629 1624 1527 1593 1554 1611 1528 1554 1533 1540 1569 1662 1628 1554 1626 1654 1645 1612 1618 1655 1606 1613 1646 1544 1619 1606 1616 1585 1585 1604 1590 1678 1667 1636 1637 1614 1595 1624 1581 1673 1587 1610 1595 1572 1630 1593 1625 1600 1598 1667 1595 1692 1543 1634 1571 1698 1701 1612 1601 1595 1613 1579 1602 1597 1609 1603 1596 1685 1595 1612 1656 1633 1684 1572 1626 1653 1644 1614 1699 1729 1662 1629 1683 1741 1640 1799 1790 1786 1784 1784 1897 1941 2010 2209 2282 2504 2793 3051 3371 3890 3978 4239 4046 3651 3309 3021 2706 2508 2285 2171 2114 2026 2015 1936 1877 1814 1886 1822 1833 1844 1852 1922 1878 1879 2071 2055 2152 2183 2464 2648 2816 2757 2933 2757 2652 2573 2259 2212 2033 1933 1967 1755 1865 1714 1862 1782 1729 1685 1660 1718 1660 1762 1712 1744 1699 1738 1631 1625 1704 1668 1628 1744 1683 1630 1637 1619 1568 1680 1604 1623 1608 1645 1671 1660 1588 1669 1648 1657 1670 1664 1676 1756 1698 1742 1699 1698 1761</counts>
			</dataPoints>
		</scan>
	</xrdMeasurement>
</xrdMeasurements>