File: dataset/precursor_mixture/MnCO3_Cr2O3_SnO2.12-min.xrdml
<?xml version="1.0"?>
<xrdMeasurements xmlns="http://www.xrdml.com/XRDMeasurement/2.2" xmlns:xsi="http://www.w3.org/2001/XMLSchema-instance" xsi:schemaLocation="http://www.xrdml.com/XRDMeasurement/2.2 http://www.xrdml.com/XRDMeasurement/2.2/XRDMeasurement.xsd" status="Completed" recordIdentifier="{0637A7A1-9E8D-49FC-855F-73AC2EF52FC0}">
	<comment>
		<entry/>
	</comment>
	<sample type="To be analyzed">
		<id>dara-10-2</id>
		<name></name>
		<preparedBy></preparedBy>
	</sample>
	<xrdMeasurement measurementType="Scan" status="Completed" sampleMode="Reflection">
		<usedWavelength intended="K-Alpha 1">
			<kAlpha1 unit="Angstrom">1.5405980</kAlpha1>
			<kAlpha2 unit="Angstrom">1.5444260</kAlpha2>
			<kBeta unit="Angstrom">1.3922500</kBeta>
			<ratioKAlpha2KAlpha1>0.5000</ratioKAlpha2KAlpha1>
		</usedWavelength>
		<incidentBeamPath>
			<radius unit="mm">145.00</radius>
			<xRayTube id="1010048" name="Empyrean Cu LFF HR (9430 033 7310x) DK437873">
				<tension unit="kV">40.0</tension>
				<current unit="mA">15.0</current>
				<anodeMaterial>Cu</anodeMaterial>
				<focus type="Line">
					<length unit="mm">12.0</length>
					<width unit="mm">0.4</width>
					<takeOffAngle unit="deg">6.0</takeOffAngle>
				</focus>
			</xRayTube>
			<filter id="20010004" name="Beta-filter Nickel">
				<material>Ni</material>
				<thickness unit="mm">0.020</thickness>
			</filter>
			<sollerSlit id="21010002" name="Soller slits 0.04 rad.">
				<opening unit="rad">0.0400</opening>
			</sollerSlit>
			<mask id="22031000" name="Fixed mask 13 mm">
				<width unit="mm">9.00</width>
			</mask>
			<divergenceSlit id="22120001" name="Divergence slit 1°" xsi:type="fixedDivergenceSlitType">
				<distanceToSample unit="mm">50.00</distanceToSample>
				<height unit="mm">1.52</height>
			</divergenceSlit>
		</incidentBeamPath>
		<beamKnife id="29030100" name="Beam knife low"/>
		<sampleMovement xsi:type="spinningSampleMovementType">
			<spinnerRevolutionTime unit="seconds">1.0</spinnerRevolutionTime>
		</sampleMovement>
		<diffractedBeamPath>
			<radius unit="mm">145.00</radius>
			<antiScatterSlit id="22090040" name="AS slit 9 mm" xsi:type="fixedAntiScatterSlitType">
				<height unit="mm">9.00</height>
			</antiScatterSlit>
			<sollerSlit id="21020003" name="Large Soller slits 0.04 rad.">
				<opening unit="rad">0.0400</opening>
			</sollerSlit>
			<filter id="20030001" name="Large beta-filter Nickel">
				<material>Ni</material>
				<thickness unit="mm">0.020</thickness>
			</filter>
			<detector id="7010019" name="PIXcel1D-Medipix3 detector" xsi:type="rtmsDetectorType">
				<phd unit="keV">
					<lowerLevel>4.0</lowerLevel>
					<upperLevel>11.3</upperLevel>
				</phd>
				<mode>Scanning</mode>
				<activeLength unit="deg">5.020</activeLength>
			</detector>
		</diffractedBeamPath>
		<scan appendNumber="0" mode="Continuous" scanAxis="Gonio" status="Completed">
			<header>
				<startTimeStamp>2024-03-24T12:07:44-07:00</startTimeStamp>
				<endTimeStamp>2024-03-24T12:20:11-07:00</endTimeStamp>
				<author>
					<name>AutomatedUser</name>
				</author>
				<source>
					<applicationSoftware version="1.6 (94)">PANalytical Aeris Instrument Suite</applicationSoftware>
					<instrumentControlSoftware version="3.0.0 20211014">AERIS</instrumentControlSoftware>
					<instrumentID>2879380</instrumentID>
				</source>
			</header>
			<dataPoints>
				<positions axis="2Theta" unit="deg">
					<startPosition>9.99043322</startPosition>
					<endPosition>100.09495370</endPosition>
				</positions>
				<positions axis="Omega" unit="deg">
					<startPosition>4.99521661</startPosition>
					<endPosition>50.04747685</endPosition>
				</positions>
				<commonCountingTime unit="seconds">18.249</commonCountingTime>
				<counts unit="counts">4514 4491 4520 4558 4517 4496 4282 4521 4491 4354 4394 4492 4479 4337 4495 4425 4364 4446 4407 4365 4539 4406 4385 4526 4435 4337 4398 4389 4371 4323 4294 4439 4406 4301 4397 4328 4384 4362 4314 4312 4310 4282 4213 4279 4309 4426 4332 4342 4341 4310 4292 4353 4238 4165 4224 4361 4231 4277 4252 4260 4270 4224 4335 4365 4394 4134 4195 4221 4160 4310 4077 4271 4120 4188 4245 4204 4261 4177 4236 4164 4179 4148 4175 4052 4012 4243 4244 4143 4139 4098 4160 4148 4236 4238 4079 4094 3976 4041 4076 4007 4125 4042 4140 4107 4122 4019 4001 4033 4201 4098 4204 4127 3956 4041 4117 4066 4107 4145 4105 4086 4030 3960 4135 4101 3996 4170 3956 3963 3996 3961 4060 3894 4021 4060 3902 4014 3938 3861 4011 3889 4081 4017 4043 3922 3918 4079 3891 3932 4009 3856 3986 3947 3872 3860 3918 3756 3906 3891 3804 3876 3982 3935 3906 4012 3970 3874 3866 3983 3857 3824 3788 3948 3915 3744 3811 3896 3765 3755 3786 3919 3768 3816 3814 3806 3749 3672 3893 3723 3746 3781 3806 3799 3858 3871 3695 3678 3706 3798 3797 3719 3795 3793 3811 3691 3850 3787 3656 3757 3706 3793 3692 3797 3729 3766 3779 3854 3704 3750 3700 3670 3812 3652 3803 3589 3662 3798 3653 3729 3597 3664 3740 3810 3706 3653 3560 3636 3602 3612 3645 3847 3671 3715 3623 3698 3620 3609 3604 3613 3461 3554 3720 3687 3726 3646 3644 3557 3554 3689 3607 3674 3634 3586 3657 3639 3675 3604 3526 3497 3622 3630 3693 3529 3625 3608 3514 3574 3583 3502 3578 3576 3498 3550 3474 3492 3534 3471 3510 3500 3470 3490 3562 3525 3474 3510 3525 3558 3565 3460 3399 3481 3511 3520 3378 3467 3529 3499 3500 3521 3546 3499 3374 3469 3467 3552 3487 3477 3401 3524 3393 3558 3451 3500 3395 3450 3448 3413 3433 3421 3401 3351 3458 3394 3386 3404 3382 3504 3453 3437 3460 3523 3300 3491 3442 3512 3442 3296 3510 3385 3429 3437 3441 3373 3452 3422 3409 3404 3398 3366 3465 3397 3408 3406 3384 3401 3359 3406 3382 3407 3340 3395 3389 3481 3386 3324 3361 3322 3200 3395 3300 3373 3437 3428 3246 3391 3372 3331 3234 3434 3293 3392 3391 3400 3273 3288 3353 3403 3299 3304 3305 3577 3335 3404 3313 3349 3362 3314 3305 3252 3351 3314 3318 3322 3302 3357 3295 3371 3293 3230 3223 3296 3339 3237 3273 3298 3305 3225 3348 3336 3361 3208 3284 3268 3325 3253 3307 3200 3405 3370 3358 3247 3398 3242 3311 3311 3296 3290 3396 3275 3288 3298 3213 3328 3344 3281 3268 3213 3320 3281 3239 3222 3152 3230 3309 3177 3283 3238 3285 3201 3174 3319 3294 3361 3258 3237 3237 3299 3291 3176 3187 3268 3342 3293 3262 3269 3215 3273 3230 3188 3265 3258 3277 3213 3193 3191 3145 3227 3285 3156 3186 3207 3141 3252 3308 3219 3195 3220 3144 3210 3235 3190 3229 3249 3128 3279 3142 3281 3229 3242 3188 3086 3211 3301 3169 3201 3224 3155 3239 3100 3212 3285 3143 3166 3187 3222 3191 3107 3176 3159 3134 3201 3159 3170 3195 3111 3277 3116 3097 3216 3139 3150 3049 3295 3137 3130 3165 3098 3187 3236 3253 3228 3110 3190 3222 3103 3208 3065 3127 3099 3185 3226 3169 3181 3226 3261 3192 3209 3080 3120 3113 3108 3233 3163 3192 3078 3161 3254 3165 3152 3183 3280 3141 3120 3120 3153 3122 3045 3127 3077 3103 3104 3027 3087 3211 3078 3155 3075 3196 3123 3121 3031 3141 3051 3069 3086 3068 3127 3107 3159 3150 3089 3086 3126 3053 3152 3127 3223 3018 3171 3090 3110 3117 3165 3133 3044 3019 3034 3202 3143 3174 3152 3105 3167 3177 3093 3103 3135 3160 3101 3067 3054 3031 3105 3028 3130 3088 3133 3121 3100 3000 2944 3124 3145 3113 3123 3108 3120 3057 3063 3060 3046 3015 3002 3090 3121 3010 3087 3067 3127 3094 3100 3004 3091 3032 3002 3038 2904 3089 2989 3044 3099 3070 3023 3047 3053 3074 3100 3067 2930 3095 3064 3052 3000 3025 3012 3086 3151 2928 3089 3047 3054 2994 3026 2989 3073 2981 3019 3035 2971 3026 3037 3056 2962 3127 3036 3027 3045 3089 3049 2954 3050 3001 3070 3076 2988 3073 2888 3041 3025 3057 3062 3016 2886 3170 3001 3065 3185 3004 3014 2948 2963 3029 3034 2967 3156 3005 2995 2870 3078 2945 2986 3086 3007 2986 2942 2944 3053 3126 3003 2965 2922 2929 2960 2996 2966 3010 3016 2973 3046 2996 2969 3000 3006 2986 2885 3029 3003 2934 2943 2944 2895 3024 2871 2953 3013 2931 2906 2829 2979 2941 2877 2991 2976 3067 3042 2838 2920 3032 2979 2972 2917 2883 2903 2870 2874 2930 2877 2811 2931 2941 2869 2939 2938 2946 2887 2918 2908 2846 2936 2846 2915 2895 2896 2916 2935 2845 2876 2939 2831 2877 2854 2881 2898 2831 2923 2770 2831 2931 2957 2890 2960 3028 2846 2910 2838 2878 2941 2908 2844 2808 2860 2937 2854 2822 2926 2914 2931 2871 2878 2946 2911 2923 2865 2809 2816 2791 2842 2848 2938 2796 2835 2904 2918 2766 2850 2837 2902 2877 2761 2827 2806 2954 2796 2845 2826 2751 2822 2848 2915 2864 2908 2850 2748 2819 2854 2786 2868 2876 2734 2795 2888 2786 2826 2742 2902 2916 2793 2770 2817 2804 2765 2794 2800 2747 2847 2758 2832 2877 2819 2793 2757 2845 2836 2800 2773 2807 2808 2815 2792 2674 2709 2820 2796 2760 2692 2702 2786 2714 2791 2758 2752 2820 2676 2812 2790 2793 2826 2837 2756 2818 2722 2808 2722 2789 2761 2702 2792 2697 2705 2735 2758 2774 2787 2758 2805 2772 2820 2727 2754 2682 2607 2640 2788 2706 2762 2722 2802 2840 2769 2742 2745 2703 2766 2658 2789 2745 2679 2752 2636 2698 2845 2788 2671 2729 2683 2743 2587 2778 2800 2781 2715 2709 2628 2757 2664 2795 2809 2685 2634 2609 2709 2638 2733 2726 2704 2680 2616 2774 2606 2726 2644 2710 2536 2662 2731 2639 2685 2665 2636 2692 2730 2747 2663 2698 2754 2629 2743 2608 2739 2665 2690 2723 2636 2654 2680 2694 2598 2670 2675 2666 2609 2631 2636 2695 2718 2526 2677 2684 2685 2699 2713 2762 2621 2605 2594 2677 2722 2624 2808 2589 2655 2718 2837 2585 2658 2715 2685 2650 2651 2634 2689 2638 2533 2734 2544 2618 2624 2590 2624 2547 2756 2573 2729 2564 2605 2629 2573 2588 2696 2614 2545 2707 2619 2568 2600 2594 2736 2623 2602 2690 2697 2577 2632 2564 2537 2671 2645 2546 2618 2627 2582 2591 2612 2553 2621 2606 2618 2631 2648 2602 2521 2557 2609 2656 2516 2569 2688 2627 2570 2596 2609 2565 2615 2583 2517 2516 2582 2539 2550 2552 2524 2494 2559 2607 2598 2625 2470 2484 2540 2576 2609 2626 2590 2634 2548 2581 2575 2601 2494 2540 2572 2628 2578 2581 2562 2557 2506 2664 2594 2587 2590 2510 2537 2547 2521 2535 2457 2571 2616 2726 2553 2657 2572 2553 2573 2621 2590 2545 2542 2582 2614 2494 2508 2596 2597 2441 2570 2542 2462 2551 2556 2597 2569 2539 2633 2453 2562 2635 2534 2475 2596 2580 2550 2477 2592 2529 2538 2498 2621 2626 2596 2543 2577 2530 2516 2460 2584 2460 2534 2566 2645 2578 2592 2585 2587 2603 2546 2521 2573 2508 2591 2607 2646 2586 2587 2617 2626 2581 2640 2557 2601 2576 2620 2568 2658 2657 2683 2665 2584 2685 2628 2586 2698 2659 2716 2745 2676 2792 2737 2788 2839 2860 2861 2863 2851 2865 3110 3050 3084 3103 3130 3398 3326 3436 3513 3570 3664 3669 3863 3898 4059 4134 4129 4051 4145 4049 4031 3904 3952 3954 3802 3751 3695 3776 3778 3737 3760 3956 3975 4024 4274 4421 4571 4880 4986 5262 5611 5963 6227 6503 6753 6819 6546 6447 6168 5581 5201 4910 4490 4212 3934 3551 3332 3230 3027 2935 2880 2796 2760 2767 2649 2633 2675 2666 2654 2672 2571 2670 2591 2568 2565 2596 2510 2559 2593 2555 2449 2512 2552 2522 2435 2456 2436 2556 2486 2521 2424 2432 2452 2482 2468 2514 2522 2531 2471 2446 2498 2463 2448 2598 2367 2387 2479 2504 2467 2416 2424 2433 2449 2407 2404 2550 2429 2433 2458 2496 2458 2328 2508 2498 2509 2395 2383 2482 2454 2408 2498 2525 2423 2553 2340 2518 2434 2465 2497 2362 2458 2528 2472 2465 2554 2500 2492 2459 2509 2510 2528 2476 2493 2493 2492 2551 2540 2587 2663 2493 2563 2656 2483 2539 2617 2676 2625 2535 2672 2557 2559 2606 2563 2570 2606 2656 2649 2634 2637 2669 2731 2728 2761 2850 2761 2745 2785 2702 2731 2841 2849 3007 2846 2871 2959 2974 2936 3008 2970 3129 3107 3240 3230 3230 3270 3330 3444 3528 3736 3784 3893 4041 4225 4410 4492 4813 4960 5178 5692 5960 6404 6800 7332 7888 8472 9241 9834 10855 11752 12631 13877 14813 15922 17039 18044 18944 19439 19730 19655 18782 17934 16826 15773 14469 13215 12242 10967 9782 8719 7711 7047 6366 6023 5475 5176 4791 4492 4389 4278 3945 3843 3868 3662 3559 3590 3436 3399 3323 3133 3046 3093 3080 3000 2954 2957 2956 2808 2883 2796 2786 2717 2752 2724 2673 2686 2676 2604 2684 2667 2599 2645 2552 2465 2588 2623 2530 2532 2508 2464 2503 2488 2538 2433 2438 2411 2397 2457 2392 2477 2439 2488 2379 2487 2368 2476 2461 2423 2507 2389 2481 2400 2357 2463 2374 2393 2387 2391 2359 2423 2389 2454 2327 2341 2410 2376 2367 2326 2347 2296 2292 2312 2403 2301 2301 2354 2307 2341 2307 2450 2366 2399 2273 2267 2329 2332 2315 2286 2386 2340 2326 2326 2327 2247 2364 2309 2324 2403 2286 2223 2296 2310 2238 2389 2238 2305 2307 2271 2257 2400 2343 2271 2402 2246 2316 2217 2317 2249 2305 2376 2208 2231 2322 2366 2307 2263 2270 2264 2283 2332 2224 2278 2288 2283 2177 2318 2303 2191 2220 2269 2224 2257 2280 2321 2209 2221 2251 2254 2242 2220 2261 2203 2251 2289 2276 2265 2276 2276 2264 2235 2245 2283 2172 2219 2205 2267 2230 2278 2217 2236 2277 2190 2288 2336 2194 2233 2330 2247 2262 2195 2228 2191 2263 2180 2211 2188 2207 2328 2206 2257 2205 2218 2214 2194 2269 2202 2161 2261 2297 2193 2244 2301 2316 2215 2110 2212 2160 2157 2259 2235 2289 2253 2255 2227 2293 2226 2240 2206 2267 2234 2223 2245 2253 2277 2187 2252 2133 2224 2141 2255 2215 2180 2292 2187 2181 2236 2225 2181 2219 2235 2151 2229 2155 2268 2121 2182 2235 2277 2240 2182 2217 2217 2248 2111 2260 2211 2174 2234 2160 2122 2202 2173 2244 2161 2238 2176 2205 2230 2159 2274 2093 2259 2217 2221 2180 2203 2149 2197 2158 2128 2092 2207 2237 2220 2154 2130 2214 2165 2263 2145 2278 2151 2189 2111 2123 2234 2178 2179 2179 2130 2239 2196 2255 2278 2249 2208 2122 2203 2193 2235 2208 2214 2218 2199 2153 2189 2257 2302 2286 2293 2232 2330 2325 2199 2273 2218 2174 2322 2219 2159 2296 2329 2246 2287 2276 2200 2216 2206 2232 2244 2194 2285 2313 2333 2235 2365 2240 2335 2263 2226 2316 2255 2227 2294 2283 2223 2293 2310 2295 2221 2305 2260 2383 2295 2408 2314 2280 2345 2402 2351 2478 2415 2430 2555 2453 2470 2635 2559 2597 2567 2696 2685 2742 2918 2926 2885 3009 3150 3303 3533 3695 3971 4028 4261 4446 4635 5060 5270 5614 5714 6034 6358 6548 6510 6472 6385 6184 6132 5866 5647 5261 5128 4888 4418 4219 4104 3726 3505 3278 3160 3017 2879 2870 2795 2784 2711 2607 2552 2570 2555 2475 2430 2502 2362 2373 2442 2294 2285 2267 2290 2260 2255 2279 2278 2155 2238 2245 2268 2386 2262 2223 2295 2235 2196 2264 2223 2179 2216 2167 2226 2080 2268 2131 2252 2157 2198 2224 2226 2221 2226 2129 2232 2304 2129 2235 2154 2224 2116 2136 2187 2157 2146 2177 2145 2132 2115 2103 2116 2158 2190 2133 2161 2185 2159 2161 2183 2142 2219 2082 2157 2140 2145 2178 2220 2259 2236 2114 2201 2186 2161 2163 2195 2262 2095 2147 2149 2155 2150 2119 2163 2204 2206 2209 2148 2238 2185 2195 2217 2169 2181 2260 2167 2210 2250 2169 2157 2175 2197 2176 2209 2170 2278 2211 2177 2163 2148 2158 2222 2217 2224 2219 2224 2264 2238 2235 2324 2297 2251 2258 2215 2211 2231 2278 2252 2343 2272 2313 2321 2287 2368 2354 2319 2365 2294 2372 2362 2364 2392 2363 2388 2469 2504 2526 2441 2536 2572 2629 2615 2652 2535 2666 2725 2802 2953 3006 3092 3105 3243 3346 3541 3816 3988 4139 4520 4820 5443 5657 6370 6713 7345 7957 8559 8841 9214 9332 9245 9135 8490 8430 8208 8234 8124 8208 7999 8171 8159 8345 8349 8938 9453 9904 10825 11562 12751 13564 14395 15169 16074 16220 16253 16384 15510 14662 13913 13091 12261 11766 10921 9881 9235 8179 7451 6710 6095 5506 5240 4934 4460 4380 3961 3923 3718 3497 3439 3207 3163 3173 3022 2980 2938 2817 2815 2802 2655 2666 2759 2538 2523 2602 2510 2430 2449 2462 2424 2329 2322 2320 2373 2378 2316 2226 2214 2236 2206 2252 2246 2230 2271 2234 2225 2197 2194 2218 2261 2177 2103 2127 2122 2137 2138 2133 2156 2099 2084 2152 2116 2127 2147 2107 2168 2117 2109 2064 2171 2133 2072 2041 2083 2112 2051 2074 2018 2120 2119 2050 2115 2108 2053 2092 2081 2006 2116 1982 2021 2084 2069 2109 2056 2036 2062 2017 2132 2071 2092 2107 2016 2077 2134 2036 2040 1997 2020 2004 2034 2060 1995 2108 2011 1919 2196 2094 2032 2021 1965 2030 2051 2049 2022 1983 2021 2002 2003 2032 2042 2017 2054 1985 2053 2071 2025 2050 1996 2039 2064 1949 2017 2049 1985 1974 2118 1968 2043 1993 1961 1942 2004 2123 2052 2127 2029 1972 2037 1995 2097 2062 2100 2052 2196 2158 2096 2160 1998 2100 2113 2057 2061 2198 2100 2202 2159 2295 2186 2361 2367 2402 2443 2565 2673 2777 2917 3046 3214 3429 3663 3954 4320 4504 5072 5526 5888 6306 6498 6821 6628 6497 6335 5795 5598 5256 5077 4891 4647 4463 4117 3799 3477 3107 2994 2734 2612 2591 2388 2368 2249 2339 2204 2269 2210 2199 2111 2196 2124 2113 2148 2059 2040 2149 1946 2101 2024 2055 2048 1995 2013 2066 2035 2062 2023 1980 1929 2042 1979 1878 2012 2038 2011 2049 2059 1980 1991 2028 2096 2050 1952 1975 1967 1980 2026 2015 1945 1924 1982 1979 1965 2039 2006 2055 1941 2027 2038 2104 2029 2085 2067 2032 2026 2069 2114 2011 2067 2041 2107 2076 2119 2024 2077 2134 2129 2245 2225 2221 2157 2278 2397 2529 2465 2499 2507 2673 2679 2780 2818 2924 2940 2886 2946 2902 2865 2910 2894 2808 2800 2751 2735 2798 2507 2652 2638 2434 2509 2489 2464 2505 2447 2403 2437 2388 2444 2343 2341 2404 2427 2475 2529 2509 2509 2705 2766 2866 2776 2975 3086 3193 3420 3397 3905 4127 4259 4622 4958 5249 5459 5755 5860 6013 5936 5747 5426 5297 5008 4827 4770 4670 4440 4129 4020 3698 3520 3179 2958 2847 2751 2585 2567 2507 2402 2345 2228 2281 2211 2254 2279 2133 2229 2178 2110 2170 2071 2151 2028 2151 2086 2033 1994 1978 1934 1982 2012 1950 1932 1933 1981 1986 1973 1987 1968 1894 1999 1901 1962 1924 1897 2040 1961 1969 1939 1999 1952 1955 1983 1892 1964 1943 1990 1889 1976 1965 2016 1940 2052 2056 1994 2022 2074 2086 2177 2169 2132 2172 2261 2215 2354 2422 2423 2541 2525 2682 2656 2742 2646 2688 2632 2459 2477 2533 2405 2328 2418 2334 2246 2262 2198 2188 2010 2038 2153 2022 2004 1894 1888 1913 1895 1922 1925 1939 1995 1856 1897 1956 1953 1858 1830 1863 1914 1968 1932 1873 1821 1851 1871 1903 1930 1855 1889 1983 1816 1787 1917 1932 1887 1836 1869 1878 1944 1821 1898 1914 2005 1936 1936 1972 2023 2008 2056 2131 2029 2119 2063 2217 2198 2272 2256 2208 2042 2028 2098 2020 2039 2036 2051 1981 1897 1957 1969 1924 2002 1941 1892 1857 1952 1820 1915 1905 1828 1908 1866 1805 1903 1860 1896 1831 1844 1869 1856 1856 1793 1822 1819 1867 1786 1771 1817 1829 1762 1901 1820 1816 1859 1925 1841 1844 1835 1776 1871 1809 1826 1823 1833 1795 1832 1892 1737 1875 1854 1780 1832 1907 1909 1876 1905 1980 1851 1831 1802 1771 1818 1854 1777 1811 1845 1772 1972 1797 1840 1886 1805 1823 1947 1807 1965 1946 1823 1872 1825 1831 1849 1816 1862 1781 1764 1848 1933 1876 1837 1828 1909 1929 1885 1930 1925 1843 1893 1969 1903 1876 1945 1909 1935 1946 2005 1871 1990 1980 1947 1983 2005 2006 2165 2106 2183 2111 2144 2231 2235 2331 2424 2456 2517 2630 2633 2678 2956 2793 3053 3051 3104 3060 3197 3248 3222 3340 3422 3450 3693 3730 3831 3929 4071 4057 3979 3848 3682 3417 3375 3319 3211 3077 3026 2977 2835 2841 2579 2559 2394 2307 2243 2155 2040 2134 1999 1966 2022 1918 1885 1995 1912 1951 1912 1856 1882 1860 1890 1853 1874 1866 1826 1852 1887 1819 1827 1787 1826 1813 1875 1768 1822 1744 1766 1757 1839 1829 1863 1799 1742 1772 1726 1792 1749 1797 1788 1840 1756 1789 1773 1780 1795 1810 1847 1825 1761 1817 1837 1830 1782 1778 1776 1834 1799 1776 1831 1815 1868 1887 1808 1822 1802 1756 1773 1828 1800 1846 1783 1841 1872 1877 1887 1984 1902 1985 1944 1918 1937 2018 1968 2021 1984 1942 1945 2008 1998 1970 1948 1935 1913 1895 1893 2003 1892 1918 1879 1827 1847 1839 1793 1760 1760 1776 1784 1822 1839 1739 1795 1735 1734 1783 1784 1828 1799 1671 1855 1801 1786 1728 1821 1709 1762 1765 1906 1737 1731 1735 1736 1728 1773 1808 1722 1833 1799 1786 1788 1747 1806 1753 1742 1787 1835 1790 1729 1762 1769 1742 1824 1845 1749 1803 1862 1743 1789 1747 1794 1723 1761 1741 1762 1779 1790 1719 1741 1755 1724 1743 1736 1784 1809 1693 1718 1751 1718 1766 1671 1699 1774 1738 1773 1764 1668 1819 1710 1767 1748 1681 1819 1761 1780 1812 1740 1739 1754 1752 1739 1757 1755 1670 1731 1640 1817 1702 1788 1812 1682 1797 1829 1726 1702 1815 1787 1803 1812 1837 1863 1867 1984 1886 1995 2005 1985 1931 1978 2030 2016 1982 2025 2028 1945 1988 1924 1938 1892 1958 1838 1875 1844 1905 1915 1826 1829 1802 1865 1842 1856 1775 1799 1704 1817 1724 1738 1761 1762 1825 1864 1701 1776 1733 1801 1779 1733 1786 1813 1836 1877 1762 1775 1748 1897 1778 1797 1752 1775 1772 1731 1812 1834 1888 1887 1862 1887 1798 1896 1874 1930 1909 1998 1915 2037 2011 2051 2053 2155 2189 2230 2300 2285 2413 2513 2525 2562 2621 2693 2628 2621 2649 2607 2600 2511 2563 2537 2440 2514 2363 2331 2373 2234 2287 2218 2207 2090 1966 2027 1919 1961 1940 1974 1891 1889 1821 1882 1902 1852 1840 1745 1885 1780 1838 1808 1781 1819 1732 1795 1740 1746 1858 1740 1744 1801 1756 1785 1791 1761 1710 1776 1822 1771 1792 1664 1779 1765 1769 1775 1721 1671 1708 1730 1741 1733 1724 1696 1723 1702 1741 1699 1607 1748 1770 1839 1704 1723 1704 1710 1740 1696 1681 1776 1746 1742 1754 1765 1696 1728 1682 1691 1672 1749 1649 1699 1751 1730 1739 1632 1701 1692 1688 1708 1661 1765 1764 1699 1718 1845 1702 1702 1695 1704 1721 1767 1767 1679 1741 1697 1764 1727 1767 1772 1732 1751 1686 1775 1743 1710 1726 1690 1804 1666 1720 1730 1783 1723 1777 1731 1732 1718 1691 1724 1671 1694 1667 1741 1728 1801 1661 1677 1726 1702 1723 1650 1693 1777 1685 1717 1667 1699 1691 1684 1700 1748 1686 1688 1724 1650 1653 1731 1740 1680 1690 1668 1704 1670 1690 1702 1737 1723 1645 1713 1713 1682 1811 1756 1775 1684 1678 1696 1720 1738 1726 1753 1665 1722 1626 1749 1656 1701 1743 1625 1746 1677 1756 1677 1561 1618 1704 1679 1666 1673 1685 1713 1733 1800 1742 1717 1673 1688 1684 1702 1682 1608 1689 1678 1677 1650 1684 1723 1683 1685 1673 1695 1746 1666 1744 1745 1659 1702 1695 1753 1680 1708 1671 1621 1648 1708 1663 1674 1643 1659 1633 1726 1726 1800 1683 1663 1694 1681 1755 1721 1717 1700 1670 1716 1696 1633 1621 1685 1687 1689 1658 1693 1736 1742 1719 1637 1739 1671 1644 1669 1697 1761 1693 1616 1686 1723 1723 1704 1653 1664 1692 1674 1723 1735 1618 1690 1714 1600 1695 1745 1711 1678 1694 1680 1682 1678 1694 1705 1620 1707 1727 1733 1755 1712 1656 1719 1675 1633 1741 1687 1722 1727 1676 1754 1711 1677 1679 1785 1707 1690 1697 1672 1747 1659 1718 1603 1697 1701 1719 1727 1711 1695 1700 1752 1709 1756 1667 1693 1683 1692 1701 1802 1731 1670 1740 1713 1697 1683 1729 1723 1669 1684 1717 1684 1728 1802 1762 1772 1693 1736 1698 1746 1745 1739 1768 1795 1762 1723 1697 1779 1793 1755 1781 1735 1768 1711 1773 1763 1699 1733 1743 1715 1788 1779 1849 1847 1779 1888 1853 1808 1946 1922 1891 1963 1978 2006 1947 2083 2097 2027 2063 2060 1922 1934 2046 2037 1987 1997 1961 2092 2005 2008 2045 1931 1954 1970 1904 1971 1921 1898 1920 1879 1888 1820 1844 1844 1814 1807 1853 1878 1854 1904 1826 1854 1875 1862 1838 1942 1864 1956 1947 1929 1914 1962 1949 1982 1902 2104 2100 2225 2209 2332 2625 2738 2913 3088 3252 3431 3704 3690 3734 3759 3495 3274 3238 2948 3026 2958 2772 2919 2914 3009 2795 2832 2736 2607 2522 2354 2187 2148 2080 2122 2005 1979 1932 1931 1917 1887 1994 1834 1915 1914 1816 1854 1764 1855 1844 1828 1761 1819 1801 1824 1855 1839 1734 1812 1809 1850 1917 1873 1838 1868 1792 1870 1812 1773 1858 1792 1833 1853 1893 1835 1872 1879 1876 1829 1819 1861 1824 1906 1857 1914 1932 1881 1940 1861 1844 1866 1858 1897 1948 1917 1945 1983 1979 1984 2043 1991 2045 2079 2034 2029 2114 2134 2198 2089 2125 2345 2210 2299 2338 2415 2326 2402 2427 2572 2589 2800 2772 2869 2971 3000 3057 3158 3233 3357 3311 3390 3604 3628 3748 3835 3983 4281 4345 4395 4783 4893 5226 5440 5625 5876 6369 6551 7161 7878 8404 9246 9979 11017 11863 12638 13160 13597 13373 12708 12341 11158 10408 9861 9514 9365 9144 9000 9064 8946 8675 8374 7656 7104 6376 5748 5159 5027 4481 4143 3897 3644 3516 3273 3115 2956 2914 2842 2779 2659 2553 2597 2501 2456 2337 2338 2267 2288 2184 2258 2117 2167 2130 2091 2073 2041 2026 2024 1978 2017 1963 1938 1947 1930 1855 1923 1952 1940 1846 1829 1859 1845 1923 1800 1841 1883 1850 1862 1882 1849 1798 1787 1788 1856 1753 1772 1709 1870 1761 1826 1803 1785 1736 1758 1773 1787 1843 1741 1803 1735 1788 1774 1808 1759 1714 1627 1807 1788 1818 1746 1738 1714 1801 1714 1719 1733 1746 1738 1759 1732 1765 1718 1813 1673 1746 1804 1734 1766 1774 1754 1737 1746 1728 1742 1745 1781 1726 1837 1827 1783 1717 1768 1690 1773 1671 1666 1749 1742 1779 1658 1704 1693 1706 1720 1700 1783 1772 1675 1772 1667 1677 1790 1795 1711 1738 1723 1721 1751 1739 1661 1715 1740 1778 1690 1699 1732 1573 1677 1725 1617 1745 1740 1699 1709 1752 1794 1697 1725 1719 1763 1768 1685 1709 1755 1743 1755 1714 1723 1745 1683 1757 1762 1771 1722 1716 1639 1777 1786 1721 1705 1679 1628 1689 1724 1790 1785 1736 1711 1728 1786 1748 1724 1759 1753 1742 1737 1810 1832 1760 1721 1830 1742 1739 1812 1819 1805 1760 1771 1717 1765 1815 1853 1740 1880 1853 1865 1892 1927 1917 1908 1814 1921 1828 1959 2012 1956 1967 2016 2095 2085 2122 2152 2196 2223 2248 2312 2457 2556 2562 2641 2726 2897 3014 3292 3468 3801 3907 4395 4816 5180 5487 5781 6206 6468 6661 6863 7215 7547 7724 7961 7726 7883 7185 6893 6508 6204 5789 5618 5516 5193 5245 5118 5004 5005 4672 4434 4178 3632 3457 3185 3055 2852 2743 2570 2384 2311 2255 2175 2137 2071 2127 2016 1989 2011 2010 1940 1876 1844 1846 1825 1787 1837 1879 1781 1852 1741 1760 1865 1743 1752 1817 1804 1767 1686 1767 1682 1709 1770 1681 1751 1771 1657 1725 1777 1681 1714 1700 1686 1734 1685 1700 1759 1696 1684 1737 1603 1700 1594 1690 1615 1645 1617 1687 1727 1702 1639 1652 1671 1665 1738 1630 1746 1695 1656 1697 1629 1666 1683 1656 1624 1725 1645 1598 1746 1649 1646 1696 1638 1672 1696 1697 1742 1680 1666 1686 1602 1650 1678 1626 1684 1666 1606 1703 1649 1681 1615 1615 1619 1681 1672 1649 1579 1718 1649 1705 1625 1653 1635 1677 1620 1654 1598 1567 1635 1584 1621 1609 1577 1661 1661 1684 1687 1645 1660 1698 1683 1686 1687 1627 1664 1656 1616 1704 1626 1717 1599 1674 1635 1674 1664 1651 1651 1612 1660 1637 1652 1670 1656 1729 1661 1708 1668 1632 1709 1688 1607 1692 1666 1770 1681 1563 1602 1604 1679 1681 1699 1683 1639 1724 1644 1613 1668 1646 1672 1698 1726 1685 1672 1755 1701 1633 1686 1673 1675 1671 1722 1700 1650 1683 1694 1666 1652 1623 1625 1731 1705 1741 1614 1653 1630 1613 1646 1685 1686 1662 1700 1665 1722 1679 1792 1755 1808 1743 1619 1722 1723 1711 1721 1685 1796 1810 1752 1791 1803 1801 1849 1815 1822 1842 1873 1982 1976 2015 2095 2089 2049 2190 2273 2337 2484 2526 2615 2685 2696 2784 2692 2618 2713 2533 2418 2416 2404 2378 2361 2419 2395 2317 2354 2340 2314 2301 2142 2105 2105 2118 1929 1909 1949 2003 1884 1861 1854 1792 1795 1869 1869 1822 1760 1775 1823 1827 1809 1809 1814 1793 1881 1809 1895 1926 1902 1893 1901 2014 2010 1964 1947 2039 1995 1966 1940 1891 1919 1854 1820 1863 1836 1872 1827 1934 1939 1872 1927 1790 1779 1758 1861 1719 1663 1741 1679 1708 1701 1655 1629 1707 1766 1691 1705 1640 1683 1611 1684 1738 1578 1646 1696 1596 1647 1654 1665 1724 1763 1648 1705 1671 1716 1714 1759 1705 1713 1793 1770 1843 1714 1751 1762 1803 1772 1716 1766 1745 1707 1745 1660 1629 1634 1692 1676 1711 1718 1673 1740 1673 1692 1669 1715 1637 1742 1576 1676 1732 1574 1629 1712 1596 1635 1633 1609 1691 1581 1705 1711 1635 1653 1660 1713 1637 1609 1613 1628 1684 1710 1714 1673 1645 1640 1708 1655 1680 1625 1697 1697 1631 1686 1691 1709 1771 1677 1709 1626 1761 1773 1787 1737 1703 1770 1792 1859 1889 1776 1965 1918 1910 1983 1936 1974 1975 2095 2015 2079 2121 2008 2159 2067 1985 2042 1957 2037 2008 2016 1980 2020 1984 1950 1952 1981 1894 1968 1934 1833 1844 1874 1839 1878 1734 1819 1814 1760 1787 1687 1706 1734 1799 1716 1765 1656 1675 1706 1634 1708 1791 1678 1707 1595 1648 1674 1669 1692 1659 1692 1657 1679 1726 1638 1695 1618 1680 1623 1602 1631 1610 1620 1616 1633 1615 1660 1694 1574 1625 1532 1661 1610 1647 1635 1584 1638 1607 1607 1617 1663 1562 1689 1681 1597 1574 1682 1668 1642 1565 1595 1657 1626 1650 1532 1612 1635 1645 1603 1580 1600 1606 1616 1597 1621 1585 1560 1646 1623 1627 1662 1597 1589 1646 1620 1620 1636 1600 1664 1602 1627 1701 1655 1636 1670 1728 1637 1637 1627 1585 1655 1688 1626 1745 1705 1668 1717 1706 1670 1715 1732 1689 1654 1754 1743 1822 1749 1804 1707 1750 1744 1875 1774 1931 1832 1937 1798 1867 1847 1864 1939 1931 1978 2116 2186 2105 2160 2312 2409 2477 2598 2862 3064 3069 3318 3490 3612 3854 3869 3726 3560 3548 3385 3285 3182 3007 2900 2912 2806 2868 2854 2888 2792 3016 2917 2906 2791 2618 2592 2449 2334 2258 2114 2171 2149 2041 2028 1934 1835 1952 1876 1947 1763 1829 1857 1874 1778 1832 1768 1760 1721 1789 1646 1816 1788 1773 1694 1749 1719 1617 1680 1678 1689 1641 1661 1691 1669 1650 1708 1642 1729 1686 1658 1712 1613 1739 1632 1708 1635 1692 1643 1705 1658 1636 1710 1651 1662 1648 1646 1665 1672 1617 1712 1660 1714 1662 1654 1673 1639 1660 1645 1765 1600 1621 1664 1648 1606 1624 1642 1677 1705 1661 1630 1632 1758 1735 1683 1705 1697 1703 1761 1706 1717 1699 1783 1703 1727 1704 1737 1915 1861 1784 1878 1798 1821 1781 1831 1912 1918 2043 2011 2074 2153 2201 2153 2309 2366 2350 2510 2764 2920 2900 3083 3082 2983 2943 2853 2691 2681 2613 2494 2530 2480 2299 2477 2553 2528 2613 2635 2526 2515 2514 2358 2455 2337 2302 2301 2200 2108 2133 2092 2121 2017 2065 2065 2064 1960 1994 1944 1890 1910 1937 2001 1923 1920 1898 1910 1835 1800 1897 1802 1760 1811 1762 1776 1749 1753 1775 1759 1769 1743 1760 1703 1828 1728 1665 1750 1772 1769 1685 1697 1655 1719 1782 1741 1792 1700 1777 1701 1856 1776 1758 1718 1679 1746 1835 1857 1834 1794 1774 1848 1871 1927 1859 1829 1844 1912 1866 1967 2007 2054 2033 2055 2017 2051 2147 2156 2299 2376 2477 2423 2615 2727 2773 2957 3090 3312 3289 3550 3660 3786 3831 3776 3536 3525 3265 3265 3169 3071 3007 2937 3037 2974 3059 3024 3111 3073 3156 3159 3065 2892 2934 2774 2901 2807 2822 2860 2896 2979 3023 3175 3237 3343 3482 3651 3525 3346 3191 3222 2951 2971 2841 2742 2777 2678 2741 2642 2776 2780 2790 2745 2729 2838 2645 2521 2449 2484 2338 2302 2223 2124 2126 2098 2059 1979 2003 2014 1956 1955 1938 1832 1965 2037 1930 1914 1850 1906 1907 1872 1833 1872 1908 1895 1788 1883 1940 1993 1938 2010 2023 1965 2069 1967 2122 2038 2112 2150 2232 2190 2350 2367 2391 2498 2701 2709 2796 3013 3366 3402 3592 3761 4046 4218 4277 4427 4243 4157 4057 3697 3475 3385 3363 3200 3160 3036 3235 3127 3186 3290 3307 3388 3215 3145 3057 2961 2757 2651 2513 2402 2357 2190 2254 2209 2070 2091 1997 1961 2058 1970 1994 1938 1807 1834 1868 1809 1848 1757 1902 1826 1753 1859 1752 1808 1737 1674 1775 1792 1760 1744 1732 1768 1704 1766 1671 1672 1636 1692 1677 1678 1748 1714 1705 1624 1652 1596 1627 1645 1646 1761 1627 1611 1656 1679 1689 1646 1648 1649 1630 1611 1695 1597 1639 1555 1575 1591 1550 1618 1617 1616 1615 1609 1588 1570 1652 1613 1610 1677 1699 1715 1604 1651 1676 1615 1598 1672 1620 1670 1634 1631 1636 1684 1716 1672 1661 1706 1633 1647 1672 1700 1725 1718 1724 1712 1680 1732 1748 1829 1815 1820 1891 1895 1947 1848 1965 1901 1875 1822 1929 1858 1902 1938 1869 1879 1834 1888 1800 1885 1777 1855 1781 1809 1799 1752 1750 1775 1819 1770 1730 1787 1779 1728 1715 1722 1743 1672 1721 1675 1633 1636 1672 1657 1622 1655 1574 1585 1661 1661 1554 1643 1629 1599 1625 1667 1571 1545 1596 1619 1556 1629 1599 1510 1534 1586 1557 1681 1651 1638 1555 1619 1575 1560 1524 1610 1504 1607 1601 1630 1576 1549 1596 1650 1473 1547 1584 1554 1528 1605 1507 1672 1592 1509 1609 1556 1585 1580 1490 1649 1499 1601 1575 1548 1579 1627 1550 1614 1593 1523 1603 1481 1526 1552 1495 1510 1569 1613 1564 1509 1590 1593 1542 1585 1590 1569 1525 1509 1591 1519 1552 1569 1498 1466 1604 1592 1581 1645 1464 1546 1576 1581 1540 1616 1596 1528 1642 1565 1534 1592 1544 1579 1528 1572 1539 1583 1534 1538 1575 1608 1609 1561 1563 1534 1553 1489 1570 1640 1583 1575 1538 1525 1593 1642 1630 1588 1590 1522 1546 1505 1536 1557 1529 1619 1510 1575 1606 1557 1563 1544 1547 1595 1627 1543 1526 1544 1579 1584 1578 1544 1537 1622 1617 1567 1530 1567 1549 1509 1532 1531 1541 1560 1567 1528 1601 1563 1614 1509 1584 1560 1549 1551 1494 1516 1501 1537 1636 1549 1586 1533 1514 1588 1607 1594 1555 1524 1641 1571 1494 1527 1626 1628 1542 1577 1463 1585 1527 1515 1571 1517 1573 1609 1490 1533 1612 1606 1519 1564 1557 1582 1589 1542 1591 1687 1525 1501 1642 1485 1504 1614 1587 1551 1568 1617 1535 1492 1588 1529 1589 1503 1577 1544 1549 1551 1521 1516 1633 1558 1559 1551 1537 1602 1448 1598 1541 1579 1533 1592 1509 1539 1602 1530 1655 1563 1601 1524 1561 1503 1589 1574 1518 1649 1545 1553 1625 1599 1586 1633 1632 1625 1635 1562 1601 1637 1605 1560 1654 1691 1568 1660 1659 1726 1673 1698 1639 1725 1688 1757 1780 1806 1804 1811 1810 1818 1865 1891 1989 1999 2166 2254 2202 2443 2461 2608 2597 2592 2635 2600 2489 2394 2366 2289 2245 2092 2122 2043 2200 2104 2084 2056 2177 2137 2195 2106 2114 2182 2068 2042 2042 1934 1861 1883 1804 1857 1764 1816 1732 1772 1768 1703 1718 1669 1702 1624 1673 1680 1678 1611 1640 1589 1614 1596 1613 1590 1662 1564 1569 1641 1645 1637 1616 1625 1607 1571 1555 1647 1576 1613 1582 1620 1642 1640 1635 1575 1570 1659 1684 1563 1592 1603 1544 1642 1621 1592 1615 1538 1605 1582 1648 1627 1607 1668 1584 1652 1564 1594 1620 1587 1504 1569 1575 1588 1630 1620 1626 1599 1619 1566 1526 1602 1586 1573 1621 1647 1553 1608 1520 1612 1603 1587 1589 1568 1643 1604 1584 1543 1591 1548 1596 1567 1608 1516 1656 1579 1625 1649 1594 1655 1660 1666 1558 1665 1621 1677 1671 1644 1744 1785 1795 1745 1937 1868 1962 1952 2058 2137 2194 2138 2237 2092 2137 1967 1992 1992 1902 1961 1874 1885 1813 1848 1865 1893 1861 1928 1851 1930 1923 1927 1982 1942 1888 1837 1829 1718 1782 1749 1706 1753 1805 1770 1690 1855 1800 1700 1784 1792 1693 1756 1666 1589 1718 1652 1629 1632 1574 1656 1656 1570 1607 1564 1680 1682 1634 1666 1628 1716 1665 1562 1560 1571 1659 1604 1616 1541 1584 1610 1572 1581 1540 1563 1611 1474 1633 1611 1606 1527 1600 1515 1566 1516 1569 1509 1525 1597 1507 1497 1532 1529 1567 1581 1541 1527 1520 1606 1516 1515 1523 1528 1596 1584 1507 1515 1549 1553 1538 1536 1513 1544 1575 1521 1608 1498 1568 1526 1556 1509 1580 1539 1536 1555 1494 1528 1515 1579 1459 1530 1507 1467 1521 1567 1564 1497 1552 1487 1563 1612 1538 1578 1594 1547 1628 1564 1639 1546 1608 1560 1603 1552 1559 1602 1547 1504 1570 1563 1568 1521 1496 1538 1544 1474 1528 1535 1544 1539 1550 1529 1583 1568 1588 1503 1582 1531 1473 1567 1453 1552 1545 1524 1436 1477 1572 1535 1576 1486 1499 1580 1488 1528 1504 1516 1535 1546 1520 1523 1484 1480 1557 1570 1541 1514 1492 1591 1536 1464 1520 1466 1515 1520 1550 1538 1552 1570 1510 1517 1458 1544 1578 1577 1583 1554 1514 1529 1509 1541 1555 1553 1573 1487 1542 1513 1520 1549 1580 1496 1514 1503 1579 1611 1515 1520 1498 1556 1484 1528 1606 1576 1586 1563 1626 1465 1501 1508 1517 1566 1553 1552 1551 1595 1507 1605 1585 1463 1622 1576 1582 1608 1606 1637 1550 1576 1625 1550 1615 1624 1616 1582 1532 1600 1573 1632 1565 1614 1657 1644 1569 1571 1532 1612 1615 1553 1607 1584 1600 1518 1594 1572 1586 1556 1476 1554 1558 1647 1619 1548 1571 1673 1508 1504 1512 1493 1523 1487 1571 1499 1528 1494 1539 1535 1622 1572 1520 1520 1540 1558 1531 1512 1594 1568 1561 1608 1546 1587 1628 1564 1550 1559 1596 1618 1621 1527 1630 1581 1591 1661 1635 1632 1654 1629 1691 1759 1709 1738 1806 1814 1826 1843 1863 1869 1801 1799 1826 1779 1746 1762 1724 1707 1838 1753 1748 1703 1717 1730 1668 1620 1693 1605 1677 1746 1708 1683 1652 1668 1631 1592 1691 1665 1639 1607 1607 1507 1524 1528 1606 1510 1624 1511 1575 1613 1550 1511 1589 1566 1583 1520 1557 1510 1607 1531 1521 1596 1551 1693 1610 1537 1524 1504 1561 1545 1570 1592 1593 1627 1519 1618 1602 1568 1648 1580 1606 1620 1631 1534 1565 1613 1609 1579 1606 1658 1633 1660 1676 1648 1677 1649 1676 1653 1731 1579 1593 1626 1622 1664 1684 1622 1655 1645 1676 1726 1589 1605 1661 1671 1684 1638 1585 1665 1661 1594 1646 1622 1585 1595 1657 1630 1660 1678 1686 1667 1613 1565 1662 1617 1657 1691 1680 1634 1556 1681 1616 1678 1674 1584 1666 1726 1677 1663 1664 1620 1682 1715 1667 1686 1664 1653 1726 1693 1660 1746 1784 1790 1815 1856 1874 1921 1930 1936 2047 2061 2093 2157 2244 2413 2556 2590 2813 2754 2993 3181 3139 3258 3256 3109 3051 2837 2651 2569 2498 2477 2415 2359 2398 2336 2381 2256 2328 2416 2429 2481 2452 2543 2560 2487 2519 2513 2457 2409 2281 2362 2226 2201 2220 2240 2039 2107 2011 1982 2015 1926 1866 1797 1866 1830 1720 1704 1671 1772 1738 1731 1734 1727 1778 1749 1693 1756 1771 1787 1686 1661 1587 1548 1653 1610 1614 1564 1593 1606 1624 1574 1637 1572 1571 1592 1566 1575 1555 1487 1588 1576 1614 1550 1575 1579 1518 1575 1572 1610 1550 1675 1548 1457 1617 1550 1573 1636 1546 1582 1560 1558 1602 1535 1558 1581 1618 1588 1542 1559 1615 1564 1632 1628 1589 1588 1583 1588 1571 1596 1563 1636 1509 1561 1614 1576 1570 1596 1568 1610 1598 1560 1625 1543 1571 1585 1670 1596 1570 1571 1615 1556 1673 1582 1607 1614 1569 1644 1582 1612 1544 1506 1556 1507 1579 1517 1587 1558 1613 1547 1631 1587 1632 1624 1554 1622 1521 1552 1577 1553 1564 1557 1555 1525 1478 1591 1506 1475 1492 1589 1548 1574 1594 1535 1591 1549 1608 1568 1528 1563 1559 1530 1609 1613 1587 1567 1585 1552 1615 1608 1533 1565 1551 1585 1555 1567 1651 1566 1627 1640 1629 1659 1675 1629 1683 1715 1668 1752 1786 1764 1753 1870 1951 1849 1916 2072 2028 2003 2000 1928 1968 1956 1908 1847 1795 1801 1782 1706 1739 1831 1768 1770 1820 1752 1731 1770 1778 1761 1753 1865 1803 1788 1782 1773 1714 1688 1710 1682 1697 1634 1514 1648 1659 1612 1641 1579 1554 1719 1658 1531 1540 1596 1521 1639 1447 1600 1580 1612 1544 1558 1604 1532 1535 1643 1580 1524 1635 1619 1522 1542 1512 1485 1586 1586 1514 1558 1502 1537 1560 1511 1623 1543 1548 1676 1613 1594 1616 1644 1617 1605 1612 1692 1605 1724 1674 1687 1677 1738 1603 1616 1606 1610 1580 1631 1586 1563 1588 1548 1579 1600 1604 1616 1629 1642 1640 1609 1655 1574 1604 1578 1496 1534 1571 1576 1627 1495 1581 1506 1562 1517 1493 1548 1475 1558 1592 1481 1551 1533 1437 1480 1464 1522 1469 1537 1574 1502 1481 1601 1537 1556 1499 1550 1581 1537 1517 1548 1534 1525 1484 1523 1534 1560 1555 1506 1485 1539 1544 1551 1487 1609 1444 1527 1485 1521 1482 1583 1508 1503 1483 1488 1550 1557 1538 1495 1552 1512 1482 1583 1485 1538 1534 1524 1530 1530 1595 1500 1547 1507 1517 1553 1580 1611 1584 1578 1620 1508 1514 1561 1558 1556 1616 1586 1665 1609 1655 1609 1603 1615 1659 1602 1681 1609 1706 1697 1702 1759 1684 1779 1805 1788 1874 1854 1911 1856 2067 2042 2133 2235 2317 2365 2489 2687 2603 2718 2585 2562 2485 2494 2341 2229 2181 2155 2107 1993 1972 2035 1993 2011 2079 2078 2013 2060 2070 2084 2171 2138 2257 2261 2209 2221 2064 2179 1957 1986 1927 1959 1864 1927 1809 1874 1784 1801 1819 1846 1943 1905 1841 2014 1958 1931 2017 1982 2001 1885 1861 1954 1832 1886 1847 1823 1775 1752 1857 1756 1765 1705 1692 1746 1727 1666 1713 1730 1748 1857 1725 1742 1762 1739 1687 1726 1696 1713 1620 1660 1625 1633 1571 1666 1610 1617 1699 1596 1553 1569 1575 1539 1598 1580 1556 1663 1587 1627 1566 1578 1498 1583 1679 1606 1551 1558 1548 1529 1508 1640 1491 1613 1562 1569 1601 1557 1618 1500 1550 1510 1592 1614 1531 1558 1540 1571 1498 1571 1532 1602 1551 1567 1616 1597 1605 1573 1556 1580 1505 1611 1563 1515 1492 1462 1552 1513 1584 1538 1593 1592 1622 1518 1511 1527 1538 1559 1566 1498 1477 1608 1509 1574 1580 1544 1557 1501 1535 1549 1545 1567 1533 1527 1605 1551 1588 1555 1522 1660 1574 1683 1652 1621 1539 1624 1573 1562 1501 1520 1558 1556 1593 1576 1503 1595 1554 1601 1598 1556 1551 1539 1547 1567 1505 1568 1594 1541 1605 1600 1568 1581 1555 1523 1600 1521 1532 1562 1555 1568 1471 1505 1611 1554 1557 1571 1613 1580 1569 1554 1505 1532 1642 1505 1472 1556 1585 1589 1513 1651 1572 1523 1559 1557 1573 1585 1626 1636 1569 1573 1697 1577 1612 1703 1779 1759 1729 1787 1823 1764 1788 1752 1770 1755 1813 1748 1699 1677 1673 1692 1676 1680 1698 1690 1694 1692 1664 1711 1622 1640 1639 1743 1608 1717 1731 1760 1625 1715 1624 1646 1648 1677 1618 1631 1665 1598 1636 1594 1556 1532 1654 1553 1647 1579 1691 1554 1624 1570 1672 1675 1675 1662 1641 1644 1699 1814 1721 1749 1754 1768 1851 1932 2025 1999 2033 2074 2041 1989 1988 2024 1909 1917 1826 1832 1786 1781 1745 1781 1729 1722 1754 1749 1750 1728 1739 1726 1808 1812 1732 1800 1859 1868 1758 1789 1759 1758 1678 1728 1658 1663 1592 1558 1588 1704 1644 1664 1628 1627 1632 1669 1659 1639 1592 1618 1634 1623 1612 1619 1581 1570 1660 1603 1607 1602 1676 1583 1618 1624 1632 1624 1644 1639 1642 1650 1598 1637 1675 1629 1612 1722 1588 1655 1648 1653 1727 1587 1715 1662 1671 1728 1687 1709 1825 1745 1706 1736 1675 1777 1669 1686 1676 1692 1678 1634 1671 1720 1722 1558 1618 1620 1537 1672 1644 1624 1658 1647 1613 1605 1652 1600 1597 1606 1636 1589 1555 1616 1633 1613 1566 1683 1608 1603 1561 1612 1571 1563 1621 1571 1612 1586 1513 1571 1554 1614 1574 1569 1584 1555 1564 1540 1571 1681 1482 1523 1536 1533 1558 1626 1545 1512 1535 1607 1570 1559 1525 1591 1616 1483 1475 1613 1536 1632 1590 1535 1563 1566 1591 1533 1584 1622 1577 1554 1563 1629 1536 1603 1603 1522 1574 1545 1582 1592 1618 1638 1589 1611 1564 1576 1607 1562 1638 1627 1638 1625 1656 1622 1651 1657 1611 1638 1655 1629 1651 1655 1717 1783 1739 1702 1873 1735 1874 1820 1834 1865 1857 1893 1946 1970 2128 2031 2163 2292 2197 2434 2467 2539 2657 2657 2858 2846 2981 2899 2693 2770 2645 2531 2463 2420 2273 2411 2365 2229 2157 2151 2256 2207 2188 2213 2211 2305 2379 2342 2351 2473 2456 2514 2565 2541 2508 2478 2464 2413 2511 2478 2461 2388 2330 2420 2359 2369 2238 2289 2136 2140 1998 2092 2006 1991 1897 1999 1983 1989 1930 1931 1917 1956 1914 1901 1902 1953 2028 2025 1908 1981 1927 1983 1965 1984 1937 1893 1862 1826 1875 1790 1859 1860 1789 1792 1861 1710 1804 1755 1794 1876 1925 1809 1907 1892 1920 1980 2041 2000 2123 2179 2241 2321 2373 2486 2557 2685 2788 2710 2835 2811 2758 2785 2615 2576 2474 2420 2352 2242 2285 2126 2151 2089 2122 2100 2085 2117 2071 2066 2174 2099 2242 2142 2214 2236 2235 2263 2262 2332 2199 2145 2154 2056 1997 1930 1886 1896 1870 1889 1732 1780 1711 1752 1738 1725 1623 1677 1633 1652 1636 1672 1689 1613 1636 1604 1617 1537 1568 1588 1632 1608 1537 1580 1589 1581 1608 1487 1646 1558 1619 1563 1536 1507 1535 1661 1551 1576 1526 1555 1513 1547 1496 1563 1546 1522 1571 1482 1525 1544 1546 1470 1524 1509 1576 1444 1590 1546 1528 1543 1487 1524 1631 1528 1569 1485 1490 1489 1398 1504 1552 1503 1565 1541 1603 1471 1575 1550 1532 1572 1550 1483 1478 1541 1428 1426 1551 1468 1522 1541 1476 1519 1471 1485 1503 1509 1442 1544 1512 1508 1492 1543 1501 1528 1527 1568 1541 1515 1559 1507 1561 1507 1529 1531 1514 1511 1535 1548 1620 1504 1498 1616 1539 1550 1502 1600 1474 1542 1530 1542 1536 1558 1591 1514 1631 1541 1612 1569 1494 1561 1586 1589 1627 1600 1574 1572 1616 1531 1577 1567 1566 1586 1600 1654 1601 1645 1625 1644 1687 1650 1671 1672 1656 1703 1740 1766 1714 1694 1811 1795 1868 1878 1904 1895 1966 2023 2074 2080 2046 2143 2221 2102 2082 2050 2044 1987 1961 1953 1898 1852 1893 1778 1941 1767 1769 1827 1762 1721 1819 1819 1815 1871 1724 1855 1824 1840 1905 1865 1832 1856 1903 1834 1845 1764 1690 1792 1699 1772 1747 1723 1729 1652 1672 1568 1627 1503 1638 1597 1563 1507 1564 1566 1516 1517 1631 1507 1537 1530 1554 1603 1542 1519 1534 1528 1585 1460 1513 1484 1534 1571 1525 1445 1497 1523 1612 1528 1559 1548 1564 1534 1465 1469 1472 1551 1585 1478 1465 1516 1502 1514 1509 1545 1486 1574 1482 1487 1501 1490 1498 1525 1488 1516 1576 1487 1518 1524 1504 1543 1543 1546 1554 1497 1548 1562 1509 1503 1505 1525 1532 1514 1544 1527 1522 1590 1462 1532 1517 1521 1407 1477 1460 1465 1442 1523 1563 1562 1530 1441 1517 1559 1532 1547 1481 1567 1491 1524 1487 1538 1533 1505 1509 1591 1533 1588 1512 1625 1600 1582 1586 1564 1491 1582 1530 1554 1610 1631 1590 1590 1608 1634 1596 1629 1625 1630 1624 1692 1700 1725 1773 1788 1741 1853 1896 1928 1991 1977 1939 1947 1976 1928 1909 1790 1863 1814 1796 1820 1772 1757 1698 1671 1792 1782 1764 1660 1706 1743 1636 1631 1772 1760 1860 1710 1865 1726 1789 1751 1832 1750 1770 1703 1730 1678 1762 1791 1702 1725 1691 1680 1640 1643 1642 1737 1756 1636 1698 1717 1741 1771 1748 1713 1732 1805 1874 1759 1865 1857 1905 1894 2022 1951 1999 2013 2031 1973 1877 1872 1905 1844 1867 1826 1852 1766 1747 1669 1647 1800 1660 1709 1757 1694 1751 1705 1792 1808 1691 1746 1676 1777 1670 1738 1754 1733 1842 1735 1694 1818 1694 1694 1660 1685 1647 1621 1651 1656 1554 1610 1604 1554 1559 1549 1546 1617 1560 1598 1589 1558 1621 1602 1556 1551 1569 1511 1543 1615 1563 1571 1618 1613 1502 1564 1575 1579 1519 1510 1553 1476 1602 1462 1562 1557 1589 1593 1532 1537 1535 1516 1519 1546 1501 1538 1421 1609 1542 1569 1501 1572 1634 1583 1515 1561 1464 1594 1525 1536 1559 1519 1498 1586 1539 1488 1533 1588 1527 1492 1528 1471 1474 1537 1561 1574 1541 1547 1578 1564 1552 1582 1537 1508 1547 1583 1499 1493 1516 1487 1529 1581 1581 1535 1540 1551 1556 1477 1568 1580 1645 1651 1638 1621 1545 1573 1511 1626 1567 1563 1572 1492 1512 1521 1491 1468 1541 1523 1506 1493 1548 1580 1522 1554 1661 1493 1493 1481 1547 1492 1546 1509 1512 1578 1559 1543 1576 1540 1543 1528 1542 1537 1531 1505 1422 1450 1442 1577 1485 1424 1521 1556 1441 1518 1485 1514 1531 1471 1543 1508 1462 1452 1512 1472 1527 1508 1514 1487 1564 1525 1486 1556 1490 1558 1506 1518 1464 1486 1498 1496 1540 1467 1517 1471 1480 1524 1529 1427 1501 1483 1507 1514 1449 1462 1512 1532 1510 1499 1440 1400 1468 1581 1532 1606 1488 1499 1489 1546 1541 1473 1532 1461 1567 1472 1481 1562 1486 1570 1469 1472 1565 1464 1406 1490 1529 1477 1533 1539 1513 1453 1546 1524 1517 1504 1588 1487 1438 1485 1520 1604 1448 1533 1537 1484 1482 1521 1509 1528 1516 1473 1551 1529 1525 1489 1518 1488 1577 1574 1497 1426 1405 1499 1520 1539 1547 1504 1453 1571 1516 1573 1538 1514 1543 1475 1522 1619 1557 1525 1515 1472 1526 1602 1534 1473 1428 1417 1460 1510 1575 1469 1465 1488 1510 1512 1531 1530 1561 1461 1486 1422 1494 1517 1502 1555 1570 1467 1501 1485 1491 1555 1507 1550 1505 1516 1543 1475 1583 1585 1572 1616 1569 1557 1538 1565 1513 1610 1563 1612 1638 1576 1514</counts>
			</dataPoints>
		</scan>
	</xrdMeasurement>
</xrdMeasurements>