File: dataset/precursor_mixture/MnCO3_Cr2O3_SnO2.2-min.xrdml
<?xml version="1.0"?>
<xrdMeasurements xmlns="http://www.xrdml.com/XRDMeasurement/2.2" xmlns:xsi="http://www.w3.org/2001/XMLSchema-instance" xsi:schemaLocation="http://www.xrdml.com/XRDMeasurement/2.2 http://www.xrdml.com/XRDMeasurement/2.2/XRDMeasurement.xsd" status="Completed" recordIdentifier="{BDEACC7A-1DC4-4A17-96C7-73DFB99DDB9C}">
	<comment>
		<entry/>
	</comment>
	<sample type="To be analyzed">
		<id>dara-10-1</id>
		<name></name>
		<preparedBy></preparedBy>
	</sample>
	<xrdMeasurement measurementType="Scan" status="Completed" sampleMode="Reflection">
		<usedWavelength intended="K-Alpha 1">
			<kAlpha1 unit="Angstrom">1.5405980</kAlpha1>
			<kAlpha2 unit="Angstrom">1.5444260</kAlpha2>
			<kBeta unit="Angstrom">1.3922500</kBeta>
			<ratioKAlpha2KAlpha1>0.5000</ratioKAlpha2KAlpha1>
		</usedWavelength>
		<incidentBeamPath>
			<radius unit="mm">145.00</radius>
			<xRayTube id="1010048" name="Empyrean Cu LFF HR (9430 033 7310x) DK437873">
				<tension unit="kV">40.0</tension>
				<current unit="mA">15.0</current>
				<anodeMaterial>Cu</anodeMaterial>
				<focus type="Line">
					<length unit="mm">12.0</length>
					<width unit="mm">0.4</width>
					<takeOffAngle unit="deg">6.0</takeOffAngle>
				</focus>
			</xRayTube>
			<filter id="20010004" name="Beta-filter Nickel">
				<material>Ni</material>
				<thickness unit="mm">0.020</thickness>
			</filter>
			<sollerSlit id="21010002" name="Soller slits 0.04 rad.">
				<opening unit="rad">0.0400</opening>
			</sollerSlit>
			<mask id="22031000" name="Fixed mask 13 mm">
				<width unit="mm">9.00</width>
			</mask>
			<divergenceSlit id="22120001" name="Divergence slit 1°" xsi:type="fixedDivergenceSlitType">
				<distanceToSample unit="mm">50.00</distanceToSample>
				<height unit="mm">1.52</height>
			</divergenceSlit>
		</incidentBeamPath>
		<beamKnife id="29030100" name="Beam knife low"/>
		<sampleMovement xsi:type="spinningSampleMovementType">
			<spinnerRevolutionTime unit="seconds">1.0</spinnerRevolutionTime>
		</sampleMovement>
		<diffractedBeamPath>
			<radius unit="mm">145.00</radius>
			<antiScatterSlit id="22090040" name="AS slit 9 mm" xsi:type="fixedAntiScatterSlitType">
				<height unit="mm">9.00</height>
			</antiScatterSlit>
			<sollerSlit id="21020003" name="Large Soller slits 0.04 rad.">
				<opening unit="rad">0.0400</opening>
			</sollerSlit>
			<filter id="20030001" name="Large beta-filter Nickel">
				<material>Ni</material>
				<thickness unit="mm">0.020</thickness>
			</filter>
			<detector id="7010019" name="PIXcel1D-Medipix3 detector" xsi:type="rtmsDetectorType">
				<phd unit="keV">
					<lowerLevel>4.0</lowerLevel>
					<upperLevel>11.3</upperLevel>
				</phd>
				<mode>Scanning</mode>
				<activeLength unit="deg">1.021</activeLength>
			</detector>
		</diffractedBeamPath>
		<scan appendNumber="0" mode="Continuous" scanAxis="Gonio" status="Completed">
			<header>
				<startTimeStamp>2024-03-24T12:04:56-07:00</startTimeStamp>
				<endTimeStamp>2024-03-24T12:07:18-07:00</endTimeStamp>
				<author>
					<name>AutomatedUser</name>
				</author>
				<source>
					<applicationSoftware version="1.6 (94)">PANalytical Aeris Instrument Suite</applicationSoftware>
					<instrumentControlSoftware version="3.0.0 20211014">AERIS</instrumentControlSoftware>
					<instrumentID>2879380</instrumentID>
				</source>
			</header>
			<dataPoints>
				<positions axis="2Theta" unit="deg">
					<startPosition>10.02173288</startPosition>
					<endPosition>139.98435528</endPosition>
				</positions>
				<positions axis="Omega" unit="deg">
					<startPosition>5.01086644</startPosition>
					<endPosition>69.99217764</endPosition>
				</positions>
				<commonCountingTime unit="seconds">1.551</commonCountingTime>
				<counts unit="counts">492 391 410 408 430 394 381 470 415 498 404 422 437 426 364 423 386 429 420 398 401 405 390 391 439 400 384 398 434 390 411 392 369 427 343 353 391 415 357 348 378 379 358 368 368 349 374 401 386 374 334 362 334 362 370 367 341 320 328 359 332 327 288 317 326 351 306 320 314 345 370 354 317 315 323 347 333 322 307 337 308 342 298 303 300 324 297 288 339 327 316 304 283 287 343 328 286 318 304 287 281 337 288 280 290 274 267 281 308 303 306 258 301 301 264 291 277 280 300 260 277 296 266 269 256 263 307 269 255 271 289 250 271 269 217 283 277 269 255 287 251 255 272 282 289 268 265 277 254 248 251 253 284 253 273 280 283 283 242 269 243 260 243 233 240 256 257 275 238 263 258 277 239 282 248 255 240 253 248 254 254 248 269 236 237 254 275 242 245 252 238 250 248 256 251 220 240 217 217 240 238 246 234 240 272 242 251 223 263 210 253 256 254 242 284 234 234 246 231 230 228 240 227 226 261 233 240 233 249 259 235 237 216 207 228 245 218 242 216 235 237 236 230 236 238 244 247 259 250 230 229 231 263 201 199 238 207 221 220 228 215 212 209 218 214 193 212 237 240 218 198 235 206 246 233 207 200 221 222 198 236 211 222 215 217 231 221 235 187 232 218 207 222 232 204 221 208 217 207 224 224 211 217 206 240 188 177 227 225 209 209 218 211 264 202 273 242 287 291 319 340 347 297 321 335 453 543 597 458 301 215 197 186 220 206 235 209 226 204 214 205 186 179 212 194 180 206 194 212 216 214 214 219 217 241 250 235 206 228 194 232 243 225 255 249 275 306 333 376 430 571 777 1155 1602 1738 1343 850 572 400 357 263 291 262 256 247 216 227 205 205 180 232 210 210 192 206 208 187 197 211 210 198 213 178 190 234 218 171 210 212 189 191 183 180 201 196 220 200 190 158 181 190 215 192 185 190 177 182 197 229 203 206 154 200 181 196 190 175 203 194 185 187 200 178 177 199 173 183 170 186 164 204 216 160 176 192 193 176 195 186 184 179 169 168 178 196 203 188 205 187 201 210 164 197 173 248 234 263 323 332 468 549 570 443 357 277 246 208 202 203 213 185 192 202 180 166 192 176 176 166 173 174 212 167 192 199 197 222 179 172 178 175 214 166 185 178 198 184 190 190 177 184 200 181 183 216 210 214 260 320 372 551 760 800 757 680 697 924 1279 1436 1159 899 575 381 323 266 285 223 216 211 197 186 208 190 171 198 193 153 152 180 201 170 172 175 147 166 179 176 184 171 165 194 173 168 161 174 181 151 174 165 161 164 160 178 163 157 195 228 232 303 466 613 516 415 308 213 217 163 192 189 159 167 163 181 155 197 161 176 180 167 169 165 178 161 190 198 221 211 276 243 242 201 224 194 193 216 227 281 288 362 491 503 443 392 287 202 201 183 188 174 172 164 156 162 167 146 142 181 171 145 173 167 189 198 236 224 194 189 147 168 154 164 161 156 161 137 172 158 179 160 165 181 158 182 153 176 141 184 151 156 171 176 152 152 161 162 166 155 148 174 155 158 176 157 156 156 139 156 165 151 150 186 170 180 216 230 242 270 306 338 338 313 240 242 169 158 163 195 157 148 158 174 159 147 152 137 141 146 188 158 127 144 150 160 160 165 149 182 149 155 147 135 136 151 142 155 149 145 145 151 151 157 147 132 148 139 158 148 149 165 157 134 152 139 147 121 145 132 148 166 152 174 159 153 141 135 142 145 126 147 129 125 170 134 177 139 174 164 165 215 212 191 202 199 206 159 157 158 155 163 168 153 142 159 170 155 137 138 130 184 121 131 167 140 138 144 146 162 152 135 144 136 159 141 126 127 148 145 123 152 141 149 123 142 127 143 136 156 160 128 118 126 142 162 144 115 152 139 162 116 142 158 155 116 136 145 146 135 142 152 154 139 137 127 121 159 140 126 124 145 155 131 129 129 148 148 114 159 128 130 143 181 160 147 150 151 135 131 149 140 165 169 172 190 167 160 157 149 141 158 163 152 147 163 196 247 294 303 280 234 267 207 189 151 189 168 135 144 153 132 158 157 181 153 130 158 153 148 179 172 168 195 242 245 227 315 369 402 446 630 767 1077 1075 798 764 640 499 318 283 236 214 183 172 155 142 142 158 164 134 157 146 136 157 166 137 131 137 141 168 147 159 146 171 146 150 143 155 148 182 139 136 155 142 128 135 143 155 121 140 144 135 149 150 158 132 129 157 145 156 180 154 164 150 174 212 205 241 329 433 593 686 717 505 461 433 363 225 200 198 158 147 148 138 151 156 109 138 143 130 142 161 138 149 134 146 157 139 140 143 141 169 142 155 161 122 145 126 147 149 152 123 122 150 129 131 141 166 154 145 112 145 164 128 140 132 154 133 133 118 154 156 130 155 150 168 189 225 241 258 182 195 210 185 172 183 143 160 166 150 168 162 185 137 137 170 167 144 144 143 138 156 139 140 167 152 155 140 154 141 132 159 149 158 130 124 142 168 157 124 143 131 140 140 184 174 167 171 172 169 163 157 179 140 144 154 131 123 160 136 151 143 156 135 144 116 144 134 116 157 139 134 127 129 148 131 137 137 133 123 152 143 141 147 157 143 158 167 229 251 322 277 230 249 276 184 181 174 144 152 147 135 141 135 137 135 149 135 125 141 139 127 154 134 155 134 149 134 159 136 144 163 163 184 227 265 270 220 239 220 218 199 184 156 172 170 153 177 152 150 142 127 109 140 138 149 164 164 182 168 177 190 219 299 302 296 271 233 282 253 223 279 276 291 236 244 233 216 190 190 148 169 164 160 170 165 188 184 192 228 295 335 335 279 285 276 291 241 203 170 177 153 154 156 150 159 126 140 137 126 136 143 152 138 141 137 161 130 151 134 155 149 157 144 158 176 158 155 140 165 148 157 136 130 155 154 137 144 128 147 131 133 136 129 144 123 105 146 131 126 119 115 127 129 120 124 152 130 126 113 142 124 121 133 135 135 125 139 133 141 145 133 134 134 139 121 120 135 143 107 117 141 120 145 162 139 138 122 135 110 117 124 146 139 142 129 125 131 106 134 134 133 130 129 154 137 144 154 145 167 239 212 238 176 152 193 150 160 158 142 148 145 137 137 134 136 147 157 101 115 133 125 120 144 132 135 140 131 144 130 122 133 145 127 141 152 140 175 206 217 160 171 159 148 159 160 150 146 128 149 144 135 154 132 115 118 123 118 126 125 142 121 122 133 160 122 134 109 134 124 124 152 150 146 133 109 99 127 138 120 106 139 130 142 136 127 156 133 149 128 112 113 135 130 105 147 113 146 121 111 133 122 118 144 120 130 153 120 136 147 142 131 120 107 113 120 135 132 125 138 144 146 159 151 156 156 159 134 136 128 177 141 138 130 123 105 125 145 121 139 119 147 105 128 135 118 160 129 137 143 156 140 152 148 139 154 133 115 117 136 147 137 154 143 140 176 169 202 305 293 239 180 182 214 230 208 170 181 144 150 161 120 152 169 121 142 118 110 134 130 127 137 134 136 140 140 149 143 143 117 149 138 126 140 137 134 115 128 135 141 120 133 130 132 127 119 124 137 129 129 154 157 164 177 139 133 149 143 142 174 151 143 132 134 154 117 108 135 144 113 123 130 139 160 134 120 136 143 138 121 136 113 130 120 118 142 127 120 133 141 144 136 125 158 136 125 144 153 130 128 139 121 145 127 120 140 125 150 171 169 214 234 215 183 162 178 186 169 153 161 151 154 158 178 149 156 158 150 153 150 147 133 130 139 116 139 142 136 164 124 134 129 109 121 140 115 135 132 120 124 122 135 122 128 120 146 113 133 121 128 120 132 137 143 132 145 147 123 119 107 133 130 150 179 159 171 142 135 155 149 142 156 135 131 150 139 114 144 150 147 212 178 164 127 151 150 157 172 149 140 136 115 155 114 124 135 121 141 141 108 143 134 143 142 116 130 145 129 121 163 133 126 110 123 124 136 140 120 120 111 122 126 143 126 111 128 130 121 137 136 151 139 142 142 162 147 187 238 222 208 183 194 194 205 193 250 243 191 207 175 161 153 151 148 154 153 142 148 156 159 157 204 230 208 216 210 164 169 195 182 173 165 146 130 137 152 138 123 133 127 128 126 143 144 149 130 132 124 117 138 124 133 130 125 131 123 122 146 134 130 121 142 143 128 114 137 137 129 114 117 139 136 154 148 164 171 178 174 152 134 149 147 144 164 137 154 166 136 141 132 139 136 136 136 109 108 125 145 109 103 107 147 126 95 155 113 124 127 130 132 129 135 138 130 146 121 115 142 128 120 128 135 182 163 128 127 148 154 136 145 122 166 155 124 156 161 153 178 157 159 192 160 139 138 146 146 129 146 132 134 144 117 122 137 123 125 131 112 163 130 123 137 121 108 139 146 118 126 130 117 124 129 142 125 142 116 153 122 119 145 128 126 120 134 132 118 115 123 128 126 126 122 148 110 115 115 128 148 130 145 120 113 143 126 137 140 156 133 140 127 138 135 129 136 110 114 128 124 120 128 151 141 119 136 125 138 147 149 118 138 129 117 141 124 128 144 135 138 134 123 147 103 114 133 110 130 120 121 126 128 122 110 143 123 124 110 151 112 140 107 117 138 125 126 131 141 116 126 132 115 140 139 152 151 117 121 136 135 127 120 125 150 142 133 135 132 127 125 129 133 127 108 116 122 154 114 128 145 131 124 129 130 141 141 130 111 124 125 129 112 132 132 106 118 130 129 140 135 117 108 121 112 139 148 144 125 146 132 145 122 116 119 117 135 149 147 150 122 109 148 135 99 113 129 127 144 144 115 125 115 119 122 147 131 124 133 117 140 113 115 120 131 127 117 135 130 123 117 126 114 120 142 127 152 125 144 116 124 109 118 134 141 137 128 130 115 140 122 123 126 116 137 134 127 140 144 125 141 141 117 144 142 149 147 140 158 134 125 170 142 142 154 185 203 195 216 218 229 206 180 195 229 203 191 168 197 211 202 187 190 176 189 156 147 139 151 150 148 158 134 113 155 144 127 107 146 137 125 120 144 124 131 140 148 138 144 136 119 134 130 128 128 154 154 134 136 147 149 149 140 150 147 126 149 120 137 127 129 133 115 122 124 141 132 117 129 154 139 154 156 139 130 129 128 141 143 166 171 159 164 146 154 116 164 146 146 122 146 153 154 121 127 130 122 133 149 130 148 132 120 150 143 130 124 133 113 126 144 125 141 130 121 106 145 135 120 129 130 127 145 147 122 144 126 97 101 138 130 124 130 115 130 139 152 142 140 136 159 165 158 157 169 153 136 138 163 153 158 155 161 149 163 135 161 131 153 155 128 149 158 154 168 160 155 166 196 184 241 224 234 225 189 189 166 168 196 188 200 199 170 172 140 146 125 134 138 147 149 143 117 148 138 149 131 104 130 134 113 123 121 129 128 109 120 129 137 113 133 121 141 130 138 125 117 126 136 128 125 121 154 139 129 125 157 148 151 151 181 159 130 133 120 155 149 122 135 152 132 131 138 126 151 143 177 130 143 128 121 155 130 128 127 114 140 138 121 138 105 142 126 137 148 143 147 145 149 152 148 140 150 129 147 133 137 141 142 161 128 139 147 144 167 139 149 147 158 167 156 149 148 168 175 166 176 196 209 243 237 200 211 185 175 152 171 170 183 188 182 164 162 171 175 168 144 163 155 121 133 127 138 135 156 130 123 158 175 168 111 118 108 140 112 134 127 134 102 115 130 130 138 131 115 116 150 109 124 118 119 125 129 131 115 119 135 116 142 127 113 126 125 123 114 139 129 152 136 129 134 119 113 125 136 139 145 142 131 144 152 152 160 172 155 159 129 151 163 143 146 160 144 150 169 147 149 127 137 151 180 178 149 141 126 150 126 137 124 146 146 129 119 134 133 144 132 139 148 127 110 151 114 127 130 134 142 129 141 145 117 117 122 110 127 131 127 119 132 144 128 156 129 122 138 151 132 127 143 135 116 116 137 136 129 135 137 120 114 128 121 135 135 150 129 138 138 130 142 144 138 145 125 148 138 105 111 146 139 128 141 130 143 126 136 137 126 120 139 116 138 131 165 158 153 175 213 219 194 197 196 187 165 161 177 150 154 150 138 154 166 163 171 184 166 164 142 143 140 144 128 142 120 114 157 143 142 137 109 161 144 154 139 117 118 137 165 140 152 121 145 150 127 128 143 133 138 149 130 121 149 137 113 142 127 165 146 122 152 124 149 144 147 141 119 168 131 128 145 137 138 160 152 127 119 131 116 141 123 132 131 133 140 135 135 156 134 151 142 135 131 123 141 120 169 163 154 157 152 148 142 160 145 165 151 163 157 155 131 159 138 125 146 170 128 149 146 141 142 134 129 133 155 140 125 137 138 138 144 117 146 136 135 162 148 136 139 131 128 109 109 145 144 131 143 135 141 148 162 160 130 163 167 193 169 169 209 184 192 175 203 176 170 169 148 147 157 164 141 183 165 172 170 162 173 177 175 150 167 168 157 131 130 116 139 136 141 151 155 144 113 113 124 132 152 120 132 145 127 135 131 139 125 129 152 136 119 149 139 110 130 132 141 135 135 138 147 140 146 164 142 112 150 114 130 132 140 135 144 123 146 158 135 128 129 135 145 148 129 141 148 142 133 129 138 131 163 125 135 118 146 130 126 135 152 138 161 144 161 150 131 124 127 124 124 128 134 120 145 136 144 140 134 129 132 138</counts>
			</dataPoints>
		</scan>
	</xrdMeasurement>
</xrdMeasurements>