File: dataset/precursor_mixture/MnCO3_Fe3O4_Ga2O3_Bi2O3-alpha.2-min.xrdml
<?xml version="1.0"?>
<xrdMeasurements xmlns="http://www.xrdml.com/XRDMeasurement/2.2" xmlns:xsi="http://www.w3.org/2001/XMLSchema-instance" xsi:schemaLocation="http://www.xrdml.com/XRDMeasurement/2.2 http://www.xrdml.com/XRDMeasurement/2.2/XRDMeasurement.xsd" status="Completed" recordIdentifier="{76AE67A3-B841-40AD-9124-CD63948400A8}">
	<comment>
		<entry/>
	</comment>
	<sample type="To be analyzed">
		<id>dara-41-1</id>
		<name></name>
		<preparedBy></preparedBy>
	</sample>
	<xrdMeasurement measurementType="Scan" status="Completed" sampleMode="Reflection">
		<usedWavelength intended="K-Alpha 1">
			<kAlpha1 unit="Angstrom">1.5405980</kAlpha1>
			<kAlpha2 unit="Angstrom">1.5444260</kAlpha2>
			<kBeta unit="Angstrom">1.3922500</kBeta>
			<ratioKAlpha2KAlpha1>0.5000</ratioKAlpha2KAlpha1>
		</usedWavelength>
		<incidentBeamPath>
			<radius unit="mm">145.00</radius>
			<xRayTube id="1010048" name="Empyrean Cu LFF HR (9430 033 7310x) DK430614">
				<tension unit="kV">40.0</tension>
				<current unit="mA">15.0</current>
				<anodeMaterial>Cu</anodeMaterial>
				<focus type="Line">
					<length unit="mm">12.0</length>
					<width unit="mm">0.4</width>
					<takeOffAngle unit="deg">6.0</takeOffAngle>
				</focus>
			</xRayTube>
			<filter id="20010004" name="Beta-filter Nickel">
				<material>Ni</material>
				<thickness unit="mm">0.020</thickness>
			</filter>
			<sollerSlit id="21010002" name="Soller slits 0.04 rad.">
				<opening unit="rad">0.0400</opening>
			</sollerSlit>
			<mask id="22031000" name="Fixed mask 13 mm">
				<width unit="mm">9.00</width>
			</mask>
			<divergenceSlit id="22120001" name="Divergence slit 1°" xsi:type="fixedDivergenceSlitType">
				<distanceToSample unit="mm">50.00</distanceToSample>
				<height unit="mm">1.52</height>
			</divergenceSlit>
		</incidentBeamPath>
		<beamKnife id="29030100" name="Beam knife low"/>
		<sampleMovement xsi:type="spinningSampleMovementType">
			<spinnerRevolutionTime unit="seconds">1.0</spinnerRevolutionTime>
		</sampleMovement>
		<diffractedBeamPath>
			<radius unit="mm">145.00</radius>
			<antiScatterSlit id="22090040" name="AS slit 9 mm" xsi:type="fixedAntiScatterSlitType">
				<height unit="mm">9.00</height>
			</antiScatterSlit>
			<sollerSlit id="21020003" name="Large Soller slits 0.04 rad.">
				<opening unit="rad">0.0400</opening>
			</sollerSlit>
			<filter id="20030001" name="Large beta-filter Nickel">
				<material>Ni</material>
				<thickness unit="mm">0.020</thickness>
			</filter>
			<detector id="7010019" name="PIXcel1D-Medipix3 detector" xsi:type="rtmsDetectorType">
				<phd unit="keV">
					<lowerLevel>4.0</lowerLevel>
					<upperLevel>11.3</upperLevel>
				</phd>
				<mode>Scanning</mode>
				<activeLength unit="deg">1.021</activeLength>
			</detector>
		</diffractedBeamPath>
		<scan appendNumber="0" mode="Continuous" scanAxis="Gonio" status="Completed">
			<header>
				<startTimeStamp>2024-02-18T15:21:08-08:00</startTimeStamp>
				<endTimeStamp>2024-02-18T15:23:30-08:00</endTimeStamp>
				<author>
					<name>AutomatedUser</name>
				</author>
				<source>
					<applicationSoftware version="1.4b (28)">PANalytical Aeris Instrument Suite</applicationSoftware>
					<instrumentControlSoftware version="2.0.0 20210224">AERIS</instrumentControlSoftware>
					<instrumentID>950485</instrumentID>
				</source>
			</header>
			<dataPoints>
				<positions axis="2Theta" unit="deg">
					<startPosition>10.02173288</startPosition>
					<endPosition>139.98435528</endPosition>
				</positions>
				<positions axis="Omega" unit="deg">
					<startPosition>5.01086644</startPosition>
					<endPosition>69.99217764</endPosition>
				</positions>
				<commonCountingTime unit="seconds">1.551</commonCountingTime>
				<counts unit="counts">512 466 549 450 514 507 508 517 464 483 449 501 494 522 452 464 507 496 510 480 522 491 464 457 476 460 489 459 512 501 472 466 476 468 482 483 445 480 456 416 455 470 435 466 436 430 471 463 497 496 454 450 508 432 453 444 439 441 443 455 471 485 509 436 435 435 431 437 435 461 444 443 430 449 459 428 426 405 423 461 490 454 450 422 480 434 468 472 430 480 417 418 426 458 444 460 438 387 446 451 430 442 465 414 422 459 429 438 446 442 452 477 459 410 459 422 420 389 425 436 428 442 421 425 439 435 411 427 415 430 438 437 389 453 405 447 384 435 453 439 394 478 400 424 448 410 383 417 407 378 411 410 432 448 439 407 389 366 441 422 426 380 425 371 393 428 430 412 419 431 379 413 421 418 452 415 452 384 414 410 381 443 402 427 434 424 473 474 468 447 413 445 418 426 420 443 437 456 484 494 577 580 610 512 453 468 436 438 401 431 418 437 407 404 416 439 422 401 430 464 499 411 385 389 388 372 411 395 387 432 381 380 447 394 434 401 391 395 402 435 368 398 417 353 364 376 381 386 393 382 439 394 401 392 414 380 396 361 442 404 372 374 415 421 432 408 451 400 366 401 422 334 374 362 350 398 369 370 394 369 374 401 399 392 408 406 389 400 399 404 417 380 383 393 409 368 399 385 369 402 377 359 388 399 416 397 405 401 404 375 379 356 377 391 430 385 358 420 435 504 520 454 515 406 422 403 423 411 550 462 418 435 383 392 372 388 395 404 367 383 366 347 397 366 362 423 414 364 320 368 393 379 423 463 550 613 547 435 364 384 339 379 371 384 397 403 397 384 372 372 388 388 356 403 363 348 394 476 429 483 679 851 777 617 456 413 437 505 546 703 1050 1811 2350 1624 1025 517 447 416 409 388 400 388 428 422 517 643 642 529 447 435 428 368 377 367 344 350 376 380 372 366 402 392 395 379 410 345 399 384 345 375 359 359 377 377 337 375 360 421 349 381 419 347 377 380 407 480 414 446 459 495 572 591 718 754 691 709 691 747 801 913 922 991 956 844 757 717 602 545 520 471 466 460 444 472 486 451 508 532 520 642 797 775 752 682 667 642 701 812 803 822 793 706 616 594 555 530 497 422 469 408 431 384 398 398 382 404 393 437 425 415 384 382 398 417 390 403 475 507 745 917 762 747 706 928 957 735 598 454 388 407 417 360 362 349 334 365 376 390 413 399 414 418 415 372 363 356 374 379 367 337 338 371 365 371 375 361 386 389 374 345 368 402 439 503 595 595 552 525 535 519 656 878 1083 1204 997 875 684 507 479 431 434 427 418 419 456 411 381 380 310 392 377 335 350 345 362 335 362 355 326 371 341 377 332 387 385 359 412 520 415 436 441 390 394 410 378 371 473 465 500 464 490 523 533 455 429 409 386 388 395 381 387 358 389 366 399 414 372 388 415 399 439 460 430 356 378 388 324 326 370 349 372 358 380 343 344 319 320 375 365 368 348 310 337 323 323 389 368 342 300 315 321 327 318 366 330 383 365 428 392 349 349 360 367 365 348 370 317 340 329 350 369 373 350 325 316 342 342 351 371 326 344 343 354 373 389 408 451 412 454 479 390 409 330 355 345 333 363 350 402 388 372 354 334 329 373 343 357 352 410 451 362 366 374 376 358 319 343 358 359 355 317 382 393 449 495 442 459 425 425 395 396 344 354 308 341 364 332 330 315 314 314 350 344 350 343 338 325 332 354 324 319 326 310 386 351 357 339 329 349 347 361 323 350 353 346 342 385 411 380 439 428 488 458 394 398 366 351 326 344 337 369 342 339 336 372 396 365 357 349 371 310 336 377 381 355 398 414 631 737 558 546 542 369 384 386 380 296 355 365 325 324 359 341 331 327 336 364 346 347 342 320 336 330 367 364 334 384 369 320 351 355 343 350 316 337 295 334 332 331 292 331 339 388 365 402 418 428 428 497 471 447 472 414 394 381 345 314 371 363 323 357 336 357 380 370 342 320 406 401 439 424 418 359 363 368 363 329 353 375 355 428 372 360 411 376 325 339 297 353 350 361 335 328 343 327 335 332 365 382 389 329 380 381 380 387 378 348 338 376 313 355 389 382 417 395 418 458 455 511 519 445 455 438 474 464 441 353 379 334 369 345 374 356 507 540 479 372 480 436 365 306 340 338 335 331 317 398 414 504 463 422 409 385 381 347 352 369 346 402 363 397 369 364 340 340 354 315 324 319 339 371 319 334 327 332 323 309 316 325 302 330 360 345 353 322 337 338 398 559 511 409 447 416 362 330 348 320 320 335 330 314 351 380 441 374 414 383 392 395 329 327 343 346 453 395 418 397 398 333 346 331 317 360 334 301 362 375 299 305 320 338 362 365 351 351 439 445 474 486 500 482 421 389 384 349 373 392 356 364 360 319 403 353 359 395 425 425 426 456 440 399 391 374 365 368 361 389 422 397 347 383 400 344 395 363 356 387 344 366 359 344 352 405 477 466 447 439 463 479 413 380 376 359 346 292 354 367 357 351 310 334 362 358 328 362 380 341 351 364 399 386 372 327 342 361 356 335 339 327 350 371 333 374 344 361 349 356 354 343 368 396 330 343 345 350 329 353 333 355 412 392 315 322 398 384 375 374 411 359 374 361 338 368 345 366 346 357 389 407 429 436 556 600 542 552 570 532 470 430 425 404 389 328 384 321 327 347 296 356 343 312 344 339 381 323 351 371 362 372 386 357 373 359 346 342 400 347 377 368 319 350 365 360 366 376 411 430 400 367 414 400 404 392 340 343 402 355 351 381 384 340 346 349 337 333 372 349 372 329 336 332 330 308 347 350 327 329 286 360 319 304 326 345 326 340 354 367 378 331 311 367 344 305 304 320 345 346 357 328 394 344 408 343 349 337 401 336 349 299 311 287 322 336 317 352 385 376 350 346 316 345 338 355 328 357 316 286 351 313 332 326 358 339 318 320 349 345 362 358 413 318 308 333 377 376 382 327 339 312 313 350 307 360 369 335 352 367 367 300 352 336 355 379 376 358 343 380 326 367 331 349 337 350 337 310 352 334 353 343 349 351 322 333 318 335 351 334 343 383 363 368 348 379 358 347 379 384 348 373 347 367 345 413 437 379 354 375 363 366 335 321 309 293 346 310 314 377 345 377 370 340 366 385 351 351 365 346 378 342 348 309 290 355 304 292 285 313 347 293 335 348 320 348 293 328 338 318 337 308 330 320 340 334 303 330 344 354 376 335 353 420 409 431 370 334 344 352 368 355 406 383 298 333 339 326 360 335 329 352 356 312 318 347 321 319 319 354 324 328 290 322 325 309 324 312 346 331 307 304 313 319 319 308 293 311 301 278 322 311 327 339 281 311 303 288 302 322 292 321 280 327 305 303 308 295 307 288 311 342 307 363 306 357 350 333 326 357 351 346 317 382 337 340 366 337 320 342 358 338 340 333 328 329 326 297 319 318 315 344 309 344 282 334 315 328 366 348 362 334 324 351 365 301 338 300 348 341 346 380 375 340 338 323 306 355 335 351 323 320 353 359 363 336 343 312 318 299 339 315 331 342 344 345 376 348 374 363 330 318 302 330 344 353 339 294 291 323 326 308 311 302 301 333 351 341 333 315 300 337 344 354 295 331 325 327 296 302 288 312 326 340 298 322 345 389 374 342 351 316 360 357 346 350 322 322 324 312 344 323 306 310 335 356 291 325 340 322 328 305 323 341 290 319 332 317 312 312 356 309 304 348 324 299 324 317 347 327 313 329 314 308 366 351 347 340 310 360 335 331 308 310 333 310 323 335 329 364 361 293 330 341 368 338 351 319 317 333 375 324 310 336 364 329 329 328 331 314 351 317 329 344 325 342 308 323 320 296 343 337 295 293 378 379 399 351 396 337 332 372 378 333 382 327 331 340 317 347 336 372 334 308 310 318 310 308 291 342 320 346 356 311 345 371 320 319 344 319 343 329 365 331 336 334 319 320 309 341 348 342 346 318 320 339 333 340 335 311 350 338 343 307 346 368 365 331 384 348 350 313 371 360 369 349 340 348 377 392 392 365 359 346 354 370 370 323 341 329 368 288 328 312 314 347 333 315 292 312 276 312 329 332 333 303 340 340 287 312 317 339 333 356 345 350 340 324 333 343 326 329 319 319 303 320 351 374 318 319 327 325 343 357 332 345 303 321 308 310 372 321 300 302 326 302 291 299 326 342 342 322 304 316 304 311 351 304 350 325 306 344 321 323 305 284 298 322 320 347 349 335 328 336 302 324 329 327 308 293 314 346 341 344 350 296 306 339 346 337 317 361 333 333 352 336 300 326 340 322 294 303 330 297 292 333 326 319 309 347 339 305 342 368 346 312 342 317 290 303 360 358 337 346 318 335 336 343 331 309 325 334 297 312 337 332 357 317 330 312 327 301 350 323 324 341 324 268 300 350 304 310 298 314 280 308 315 291 299 336 304 330 332 317 327 342 375 307 343 340 326 325 312 302 294 291 335 332 337 311 324 335 299 311 343 321 302 303 345 324 342 311 308 325 314 354 331 354 327 312 336 343 326 326 299 331 332 336 307 329 373 350 344 349 306 378 359 348 354 351 371 331 335 346 284 320 308 301 334 346 369 345 325 355 333 331 328 331 337 322 346 299 348 352 346 335 330 313 340 324 318 323 362 361 315 351 367 324 351 298 324 307 327 309 338 322 340 338 355 344 345 332 322 326 333 303 345 294 323 320 307 305 354 297 312 336 379 309 317 312 342 338 323 358 354 352 306 323 318 327 361 334 323 308 315 334 354 316 312 337 306 327 318 305 335 304 313 374 343 297 333 349 325 361 334 318 354 339 347 341 366 368 327 316 326 330 347 318 324 314 349 354 345 318 307 321 342 335 349 355 296 319 323 324 328 297 324 287 326 299 327 302 296 319 337 336 293 355 322 327 291 342 287 327 310 326 338 320 315 360 320 330 351 316 314 359 335 330 325 335 368 322 340 320 326 366 334 324 322 308 338 312 338 321 303 327 314 317 317 302 305 337 345 331 333 319 323 312 339 319 295 299 346 323 291 318 346 345 342 355 326 357 337 333 346 347 310 337 356 363 325 360 352 357 375 368 363 349 359 349 318 348 359 318 328 319 299 375 360 332 354 321 343 351 334 337 307 350 342 307 340 334 334 327 319 382 362 330 336 311 336 341 353 330 315 328 319 300 325 322 314 354 371 298 330 316 316 310 349 323 300 324 321 275 307 315 346 297 342 307 304 311 305 338 332 330 342 314 346 315 329 354 305 314 344 323 298 302 326 306 332 307 320 299 335 330 349 302 355 328 344 353 303 330 372 319 346 340 326 319 330 317 308 368 308 301 322 339 299 316 336 350 326 333 329 315 325 312 314 327 364 319 314 331 329 323 333 296 328 319 360 305 314 311 321 327 330 280 307 314 309 320 353 351 356 308 361 342 309 315 335 336 318 351 335 310 318 350 329 323 373 326 331 324 334 320 302 311 312 332 356 324 295 322 298 348 331 317 315 340 323 327 316 342 339 320 324 311 305 315 351 334 338 351 324 357 298 328 297 330 327 319 329 338 348 330 306 283 340 310 308 329 322 328 324 314 299 341 349 354 384 327 304 267 318 329 325 354 324 331 326 324 314 340 313 334 330 345 333 350 298 328 335 335 350 352 342 387 335 367 351 360 319 354 339 322 359 350 364 377 374 340 334 323 334 321 328 348 307 312 356 340 367 327 360 341 333 320 310 326 306 350 326 306 331 288 317 352 308 327 301 336 287 302 307 311 334 311 339 334 328 318 295 330 344 326 365 310 346 324 316 324 317 322 327 311 323 363 321 333 309 328 307 347 323 367 348 322 331 323 337 332 322 337 343 345 318 343 333 326 337 345 333 342 263 341 316 326 314 377 359 312 310 326 338 323 354 356 323 321 331 366 328 320 285 326 342 310 326 334 358 297 330 330 332 311 335 320 350 356 366 339 372 349 366 363 360 368 343 393 344 381 322 341 366 335 363 355 372 346 350 336 354 353 354 368 320 356 303 336 345 345 327 342 322 372 322 362 371 326 332 331 355 330 325 333 323 305 342 340 282 326 326 289 315 321 338 338 326 340 313 310 333 325 322 305 319 304 312 307 336 312 333 310 330 356 325 339 342 334 337 309 311 296 307 349 326 325 336 331 329 355 319 315 340 336 321 298 364 343 342 339 317 314 339 324 369 331 329 333 357 293 353 313 337 343 333 328 316 332 326 342 321 334 333 354 306 351 334 371 307 310 339 370 326 320 341 344 357 322 356 315 333 354 331 332 359 320 359 311 335 331 321 343 334 348 367 357 332 325 325 306 329 347 327 330 332 338 308 341 323 342 333 319 329 342 312 341 369 332 341 335 340 329 322 345 360 340 340 324 344 361 337 326 318 325 317 371 321 355 300 350 345 346 344 344 358 352 349 329 340 342 348 325 326 290 334 346 323 314 315 337 288 336 320 322 346 316 305 340 326 309 336 365 357 341 340 330 363 338 308 315 333 328 380 314 327 304 337 304 341 338 346 333 313 340 375 344 336 324 350 358 327 353 347 328 331 319 289 299 319 321 329 328 351 349 340 332 307 310 310 315 292 329 346 322 334 336 300 339 336 363 332 332 353 356 340 313 334 345 326 351 318 312 344 316 330 354 341 367 331 347 346 308 353 329 345 356 321 329 323 352 339 315 358 327 350 313 362 326 337 328 343 320 318 340 327 336 357 307 300 333 327 324</counts>
			</dataPoints>
		</scan>
	</xrdMeasurement>
</xrdMeasurements>