File: dataset/precursor_mixture/MnCO3_CaCO3_K2SO4.2-min.xrdml
<?xml version="1.0"?>
<xrdMeasurements xmlns="http://www.xrdml.com/XRDMeasurement/2.2" xmlns:xsi="http://www.w3.org/2001/XMLSchema-instance" xsi:schemaLocation="http://www.xrdml.com/XRDMeasurement/2.2 http://www.xrdml.com/XRDMeasurement/2.2/XRDMeasurement.xsd" status="Completed" recordIdentifier="{C5C8A7FE-9F3A-4446-A4D5-95F2597D195B}">
	<comment>
		<entry/>
	</comment>
	<sample type="To be analyzed">
		<id>dara-29-1</id>
		<name></name>
		<preparedBy></preparedBy>
	</sample>
	<xrdMeasurement measurementType="Scan" status="Completed" sampleMode="Reflection">
		<usedWavelength intended="K-Alpha 1">
			<kAlpha1 unit="Angstrom">1.5405980</kAlpha1>
			<kAlpha2 unit="Angstrom">1.5444260</kAlpha2>
			<kBeta unit="Angstrom">1.3922500</kBeta>
			<ratioKAlpha2KAlpha1>0.5000</ratioKAlpha2KAlpha1>
		</usedWavelength>
		<incidentBeamPath>
			<radius unit="mm">145.00</radius>
			<xRayTube id="1010048" name="Empyrean Cu LFF HR (9430 033 7310x) DK437873">
				<tension unit="kV">40.0</tension>
				<current unit="mA">15.0</current>
				<anodeMaterial>Cu</anodeMaterial>
				<focus type="Line">
					<length unit="mm">12.0</length>
					<width unit="mm">0.4</width>
					<takeOffAngle unit="deg">6.0</takeOffAngle>
				</focus>
			</xRayTube>
			<filter id="20010004" name="Beta-filter Nickel">
				<material>Ni</material>
				<thickness unit="mm">0.020</thickness>
			</filter>
			<sollerSlit id="21010002" name="Soller slits 0.04 rad.">
				<opening unit="rad">0.0400</opening>
			</sollerSlit>
			<mask id="22031000" name="Fixed mask 13 mm">
				<width unit="mm">9.00</width>
			</mask>
			<divergenceSlit id="22120001" name="Divergence slit 1°" xsi:type="fixedDivergenceSlitType">
				<distanceToSample unit="mm">50.00</distanceToSample>
				<height unit="mm">1.52</height>
			</divergenceSlit>
		</incidentBeamPath>
		<beamKnife id="29030100" name="Beam knife low"/>
		<sampleMovement xsi:type="spinningSampleMovementType">
			<spinnerRevolutionTime unit="seconds">1.0</spinnerRevolutionTime>
		</sampleMovement>
		<diffractedBeamPath>
			<radius unit="mm">145.00</radius>
			<antiScatterSlit id="22090040" name="AS slit 9 mm" xsi:type="fixedAntiScatterSlitType">
				<height unit="mm">9.00</height>
			</antiScatterSlit>
			<sollerSlit id="21020003" name="Large Soller slits 0.04 rad.">
				<opening unit="rad">0.0400</opening>
			</sollerSlit>
			<filter id="20030001" name="Large beta-filter Nickel">
				<material>Ni</material>
				<thickness unit="mm">0.020</thickness>
			</filter>
			<detector id="7010019" name="PIXcel1D-Medipix3 detector" xsi:type="rtmsDetectorType">
				<phd unit="keV">
					<lowerLevel>4.0</lowerLevel>
					<upperLevel>11.3</upperLevel>
				</phd>
				<mode>Scanning</mode>
				<activeLength unit="deg">1.021</activeLength>
			</detector>
		</diffractedBeamPath>
		<scan appendNumber="0" mode="Continuous" scanAxis="Gonio" status="Completed">
			<header>
				<startTimeStamp>2024-03-24T14:46:58-07:00</startTimeStamp>
				<endTimeStamp>2024-03-24T14:49:21-07:00</endTimeStamp>
				<author>
					<name>AutomatedUser</name>
				</author>
				<source>
					<applicationSoftware version="1.6 (94)">PANalytical Aeris Instrument Suite</applicationSoftware>
					<instrumentControlSoftware version="3.0.0 20211014">AERIS</instrumentControlSoftware>
					<instrumentID>2879380</instrumentID>
				</source>
			</header>
			<dataPoints>
				<positions axis="2Theta" unit="deg">
					<startPosition>10.02173288</startPosition>
					<endPosition>139.98435528</endPosition>
				</positions>
				<positions axis="Omega" unit="deg">
					<startPosition>5.01086644</startPosition>
					<endPosition>69.99217764</endPosition>
				</positions>
				<commonCountingTime unit="seconds">1.551</commonCountingTime>
				<counts unit="counts">455 469 451 476 473 497 465 439 430 440 417 480 457 454 449 459 460 480 502 451 464 421 459 447 407 502 502 474 470 480 431 472 442 456 401 452 453 455 452 414 388 404 439 402 426 447 395 399 411 378 424 404 399 417 402 363 393 370 412 407 355 398 415 404 370 417 393 397 397 398 386 340 380 376 412 399 383 373 368 365 399 370 301 366 395 396 360 362 377 366 348 382 374 377 371 366 393 369 360 319 375 345 354 395 359 346 329 338 337 317 334 347 362 361 356 336 331 348 334 371 354 318 356 327 341 323 344 334 316 334 327 328 314 339 310 338 320 327 334 322 302 345 344 330 339 306 318 343 314 301 306 311 315 312 311 300 314 323 341 302 332 301 306 333 323 306 340 328 296 332 366 377 385 352 315 347 306 307 285 330 344 316 290 280 275 303 322 319 295 345 284 282 285 265 309 286 309 268 259 287 304 289 314 262 262 281 292 277 251 276 257 301 285 306 274 293 284 269 246 277 279 280 285 257 265 282 277 289 291 252 276 286 245 273 254 259 246 244 250 266 255 287 281 265 251 267 234 269 245 253 259 306 275 426 403 390 380 316 261 238 246 251 257 256 237 250 279 254 237 232 217 255 246 246 271 229 240 245 236 242 246 291 274 243 235 222 245 252 238 243 224 217 248 286 302 296 256 235 238 219 240 210 253 228 267 222 255 256 280 320 444 455 340 267 277 265 297 304 381 483 477 462 360 318 250 265 254 240 264 225 242 244 240 220 249 266 229 235 219 219 212 206 234 226 236 220 232 288 200 205 231 246 205 207 201 247 244 215 226 233 217 223 250 230 200 210 244 260 252 260 219 252 311 260 261 238 230 220 205 197 241 214 201 190 202 214 220 233 217 231 220 244 191 221 196 206 198 177 225 178 217 246 209 211 204 219 251 234 229 230 192 238 214 229 267 307 289 295 260 272 272 267 265 277 276 287 327 392 383 397 473 526 650 919 1567 3042 8208 22202 14438 11839 2876 979 750 621 762 834 755 579 424 346 276 296 278 285 261 269 266 281 275 263 268 265 295 306 310 353 509 764 1224 898 767 567 696 545 485 413 392 478 592 783 957 965 836 673 497 404 278 289 251 245 235 246 213 245 242 225 228 236 244 265 224 219 203 223 263 223 212 220 201 226 234 192 236 196 210 207 186 186 183 197 184 209 199 219 182 196 197 194 217 204 210 176 226 235 217 209 199 199 210 178 178 178 206 174 209 194 225 196 196 196 238 196 173 241 198 208 207 193 196 173 185 161 180 190 196 209 183 203 186 179 212 194 206 199 237 233 356 523 347 383 311 247 304 299 429 342 300 281 241 201 199 168 222 202 189 170 200 205 184 200 177 172 167 168 160 155 186 196 218 225 338 400 296 347 257 251 290 277 294 247 251 241 245 226 224 226 206 244 220 227 207 193 187 211 208 181 177 192 168 159 170 182 200 170 154 184 198 173 169 157 192 168 171 195 176 183 187 187 184 184 197 258 330 257 266 240 194 187 188 195 172 172 160 181 165 176 161 172 177 173 151 196 197 178 207 251 282 225 228 206 192 159 157 189 198 232 239 209 233 192 168 183 214 222 269 303 313 271 266 239 220 189 203 179 159 190 166 164 176 174 189 188 172 164 195 147 163 159 167 165 173 143 141 142 172 156 159 158 174 175 182 188 222 265 232 249 360 386 284 343 295 236 274 280 322 227 216 207 167 157 163 157 175 147 164 166 159 157 155 177 162 149 169 153 145 158 158 177 159 154 176 153 180 176 164 188 202 210 252 265 283 255 256 245 250 187 197 167 179 188 143 158 150 159 176 165 132 160 158 147 154 186 158 196 173 169 154 161 123 163 147 156 175 157 168 204 182 169 182 191 163 157 180 163 172 216 185 189 176 156 186 172 198 301 457 436 281 311 277 185 171 181 195 168 152 168 166 201 221 195 173 200 185 203 172 221 325 434 301 306 344 269 181 209 188 178 180 186 160 183 189 165 194 178 173 155 151 157 156 159 179 187 173 178 193 190 188 167 164 162 148 155 159 161 185 165 166 173 164 148 160 115 159 156 174 161 140 148 164 156 132 153 184 179 151 149 168 144 196 177 189 223 260 305 324 359 340 399 400 307 298 262 235 209 216 156 166 176 198 172 150 174 187 187 187 129 148 142 166 171 157 155 130 159 155 148 161 124 130 135 149 149 148 139 145 158 152 164 185 136 131 143 149 159 172 162 151 122 152 145 133 157 163 169 149 156 163 150 179 157 163 174 177 170 219 248 194 181 199 177 160 177 255 223 164 195 239 184 166 138 152 160 138 166 135 139 139 157 142 135 123 145 133 159 154 154 137 145 156 139 153 168 143 154 156 172 126 177 188 191 165 150 154 139 129 137 156 166 141 178 160 135 188 163 155 154 177 197 177 149 141 147 168 146 150 175 147 150 126 142 142 141 179 149 131 129 146 181 165 135 146 159 152 143 165 191 192 183 163 143 153 162 150 170 161 164 147 148 146 150 153 131 171 146 142 154 140 153 148 144 160 161 156 194 212 209 199 201 196 149 183 143 146 159 178 172 172 175 187 169 189 181 162 176 220 185 198 333 619 345 253 299 380 245 182 161 195 191 172 154 185 170 160 157 132 150 163 134 162 124 146 142 140 158 139 148 152 132 145 123 131 131 150 147 138 139 159 147 156 149 181 183 125 162 158 159 132 151 125 162 162 179 140 157 157 146 139 160 175 174 176 188 188 190 174 170 186 199 207 191 171 164 174 183 165 166 186 180 166 191 182 161 172 151 174 175 167 190 160 159 145 153 152 168 158 187 176 192 176 151 147 207 208 177 165 189 159 159 167 161 178 149 179 166 149 160 148 150 145 150 156 171 159 154 148 149 142 144 149 144 146 167 156 143 150 147 159 162 148 168 163 130 165 200 191 169 171 167 153 173 149 151 162 125 163 145 136 142 130 149 143 143 142 147 134 128 162 148 137 147 149 135 145 142 145 131 139 136 128 130 134 141 148 134 145 166 179 176 119 114 156 135 122 148 128 143 123 147 118 118 132 143 117 172 131 131 161 127 141 128 161 151 125 146 140 130 142 157 150 118 140 136 156 134 147 144 125 130 124 142 129 129 131 144 138 163 142 144 126 108 138 136 111 119 134 140 155 146 149 166 153 157 129 139 155 181 136 146 158 139 139 149 133 169 158 149 181 143 151 157 166 146 127 153 139 145 131 148 158 132 151 145 164 140 134 153 129 165 139 138 141 138 133 115 129 125 129 138 136 154 149 139 132 153 114 154 149 160 117 149 131 133 139 118 141 146 130 134 119 115 149 145 163 170 132 136 122 153 161 154 135 153 144 165 149 145 159 121 150 165 156 147 165 141 121 161 181 116 137 131 135 137 113 147 156 134 121 123 133 167 136 191 191 157 144 113 154 150 156 150 181 148 156 154 146 163 147 164 141 144 161 161 136 146 149 139 144 150 146 139 127 148 145 119 124 114 131 150 128 146 133 129 157 129 134 123 132 124 113 123 124 128 130 126 117 143 146 132 137 125 151 150 146 144 140 135 140 139 152 124 145 129 148 143 130 133 123 155 133 115 153 125 169 118 146 119 141 121 145 156 155 153 162 114 128 125 150 148 159 153 142 160 125 161 153 149 143 154 135 143 143 132 142 157 147 154 128 142 121 142 120 141 128 127 134 123 133 143 123 141 117 113 152 120 120 128 123 159 139 128 148 138 128 130 112 144 136 138 138 157 163 151 143 166 166 156 165 121 157 149 125 162 174 144 156 132 153 123 144 160 152 132 136 153 131 163 156 154 136 134 141 149 152 139 137 132 128 153 125 120 134 154 128 124 138 125 146 143 122 136 150 128 152 138 139 158 144 138 139 143 119 127 135 136 132 110 140 130 132 152 137 127 133 134 113 122 127 123 125 127 141 158 130 152 121 144 109 157 143 153 146 127 165 166 147 139 154 138 152 148 156 156 161 152 155 162 143 139 160 133 152 146 134 129 114 135 146 155 133 132 139 137 122 134 149 144 138 137 146 153 140 120 154 137 132 153 159 140 141 152 153 156 144 142 150 138 117 146 144 136 155 132 155 117 118 145 123 116 136 135 131 149 141 116 118 134 126 114 137 138 130 114 144 115 143 103 140 122 126 136 130 122 132 142 140 119 130 111 141 134 143 126 135 153 142 135 121 133 129 106 146 134 150 115 105 134 141 132 134 162 152 135 144 113 124 149 148 152 151 121 136 124 115 147 142 143 137 173 129 136 131 137 124 126 141 143 141 112 143 128 142 135 132 128 154 177 173 164 132 155 141 174 161 211 186 142 165 120 137 174 154 128 147 149 148 129 133 148 120 137 120 131 122 124 120 161 123 149 141 152 147 171 136 124 131 129 149 135 118 142 137 128 150 123 122 143 136 126 120 116 118 131 107 135 144 135 127 149 118 134 124 126 136 115 148 146 144 105 122 136 158 153 126 151 126 138 131 142 166 132 128 131 142 126 138 133 146 150 150 136 144 151 133 183 162 201 360 271 201 169 158 166 158 201 260 228 161 152 148 142 147 160 141 129 134 154 149 129 151 150 132 151 143 124 122 150 137 142 138 141 112 149 159 120 156 132 133 123 155 143 167 133 140 124 142 142 143 120 148 129 136 149 151 142 146 144 157 138 156 154 119 149 132 140 128 142 155 128 98 151 144 147 143 138 124 134 156 123 116 119 148 151 135 137 167 119 158 133 149 154 110 123 119 127 133 115 104 136 150 134 133 112 126 137 153 121 148 126 135 131 145 124 141 131 128 135 118 122 127 142 137 124 113 135 145 145 127 129 141 118 145 129 134 162 128 144 150 131 119 120 155 116 144 129 141 139 141 137 151 121 156 116 141 151 147 151 139 152 117 145 148 132 153 129 141 155 135 128 130 154 142 141 140 148 130 146 120 139 133 153 152 124 154 155 161 123 144 159 144 146 139 146 117 151 117 145 169 150 158 163 133 137 133 120 142 154 145 150 140 141 144 159 153 136 140 158 129 134 127 150 142 124 123 143 138 126 158 133 149 153 131 152 134 129 154 129 143 149 142 146 148 133 146 140 118 148 142 130 126 143 160 147 134 126 146 147 144 123 127 131 130 117 129 142 126 139 151 156 140 139 129 138 145 144 130 129 122 151 134 132 128 142 138 141 135 131 141 140 147 146 157 127 139 141 124 107 142 135 145 129 110 115 128 153 135 139 129 137 154 141 129 144 124 113 129 144 145 145 156 158 139 140 146 158 138 134 131 132 133 127 130 139 150 124 133 135 139 128 140 127 159 119 153 143 129 149 120 151 140 146 142 140 156 142 155 142 133 137 156 138 129 141 139 134 149 128 112 126 130 136 156 133 157 138 123 128 153 160 163 144 146 135 128 130 141 128 167 120 140 146 113 129 146 156 155 134 136 134 140 134 116 115 126 116 131 139 127 142 152 115 129 142 113 131 136 117 151 138 141 137 136 122 143 128 131 124 134 159 151 162 150 158 143 161 141 142 138 149 119 141 155 156 142 124 131 150 130 171 162 165 128 149 146 152 133 133 134 128 157 132 139 155 136 130 160 122 145 139 157 152 158 147 136 126 115 135 110 149 132 116 157 133 169 151 134 138 152 129 153 137 144 151 153 138 140 145 142 150 132 134 118 121 161 136 130 124 139 161 125 139 147 132 129 120 158 129 114 141 134 139 153 124 163 138 113 126 119 133 154 122 155 134 154 147 135 108 118 146 144 136 129 126 130 133 126 141 126 129 139 120 143 123 141 146 124 128 149 138 131 148 119 131 160 141 118 138 130 144 158 120 114 148 133 111 139 130 136 147 136 133 130 149 126 150 154 121 131 143 166 140 119 121 134 143 147 137 134 122 144 134 134 148 131 141 156 112 140 133 158 121 130 136 128 132 116 140 142 153 120 143 139 128 124 125 141 139 116 135 127 129 152 109 136 121 150 128 122 127 171 159 152 145 132 171 147 137 150 160 147 122 157 138 150 144 148 146 134 139 142 166 166 149 135 148 155 147 135 137 129 129 142 151 131 151 143 139 135 142 141 132 152 136 124 126 149 120 130 115 121 135 132 141 143 137 149 123 139 134 146 119 150 121 137 150 113 157 142 147 140 153 128 148 122 137 142 162 145 134 143 147 144 135 145 147 135 135 140 127 150 141 131 131 141 114 110 139 133 111 122 136 123 133 143 131 143 151 121 121 124 126 134 146 148 130 133 124 135 153 128 158 116 146 128 142 129 143 102 129 124 129 135 143 137 141 133 134 134 155 153 155 154 122 152 149 141 155 139 137 146 144 147 151 127 154 187 174 143 133 147 153 130 146 156 144 144 140 140 145 128 137 160 150 121 151 124 164 143 155 143 149 169 139 138 145 133 146 114 123 141 139 153 137 153 164 147 136 136 125 153 144 143 143 136 155 128 124 147 141 129 137 154 143 147 103 127 126 145 139 166 115 139 146 151 147 137 147 113 149 131 124 155 125 141 137 150 146 118 162 142 138 155 151 164 136 112 135 122 131 139 135 122 169 154 143 144 161 153 149 140 115 132 134 145 145 138 168 119 137 144 149 133 126 156 135 153 152 147 141 146 163 146 162 136 143 146 107 167 130 142 142 160 131 131 145 142 150 137 128 138 120 133 139 152 155 158 136 146 160 157 149 140 137 136 137 144 149 158 140 155 139 122 146 148 144 120 156 143 141 134 156 139 134 132 157 148 165 129 141 159 143 147</counts>
			</dataPoints>
		</scan>
	</xrdMeasurement>
</xrdMeasurements>