File: dataset/precursor_mixture/MnCO3_In2O3_Ga2O3.12-min.xrdml
<?xml version="1.0"?>
<xrdMeasurements xmlns="http://www.xrdml.com/XRDMeasurement/2.2" xmlns:xsi="http://www.w3.org/2001/XMLSchema-instance" xsi:schemaLocation="http://www.xrdml.com/XRDMeasurement/2.2 http://www.xrdml.com/XRDMeasurement/2.2/XRDMeasurement.xsd" status="Completed" recordIdentifier="{F2CD18FA-334B-4AA7-B569-728E71DB4290}">
	<comment>
		<entry/>
	</comment>
	<sample type="To be analyzed">
		<id>dara-17-2</id>
		<name></name>
		<preparedBy></preparedBy>
	</sample>
	<xrdMeasurement measurementType="Scan" status="Completed" sampleMode="Reflection">
		<usedWavelength intended="K-Alpha 1">
			<kAlpha1 unit="Angstrom">1.5405980</kAlpha1>
			<kAlpha2 unit="Angstrom">1.5444260</kAlpha2>
			<kBeta unit="Angstrom">1.3922500</kBeta>
			<ratioKAlpha2KAlpha1>0.5000</ratioKAlpha2KAlpha1>
		</usedWavelength>
		<incidentBeamPath>
			<radius unit="mm">145.00</radius>
			<xRayTube id="1010048" name="Empyrean Cu LFF HR (9430 033 7310x) DK437873">
				<tension unit="kV">40.0</tension>
				<current unit="mA">15.0</current>
				<anodeMaterial>Cu</anodeMaterial>
				<focus type="Line">
					<length unit="mm">12.0</length>
					<width unit="mm">0.4</width>
					<takeOffAngle unit="deg">6.0</takeOffAngle>
				</focus>
			</xRayTube>
			<filter id="20010004" name="Beta-filter Nickel">
				<material>Ni</material>
				<thickness unit="mm">0.020</thickness>
			</filter>
			<sollerSlit id="21010002" name="Soller slits 0.04 rad.">
				<opening unit="rad">0.0400</opening>
			</sollerSlit>
			<mask id="22031000" name="Fixed mask 13 mm">
				<width unit="mm">9.00</width>
			</mask>
			<divergenceSlit id="22120001" name="Divergence slit 1°" xsi:type="fixedDivergenceSlitType">
				<distanceToSample unit="mm">50.00</distanceToSample>
				<height unit="mm">1.52</height>
			</divergenceSlit>
		</incidentBeamPath>
		<beamKnife id="29030100" name="Beam knife low"/>
		<sampleMovement xsi:type="spinningSampleMovementType">
			<spinnerRevolutionTime unit="seconds">1.0</spinnerRevolutionTime>
		</sampleMovement>
		<diffractedBeamPath>
			<radius unit="mm">145.00</radius>
			<antiScatterSlit id="22090040" name="AS slit 9 mm" xsi:type="fixedAntiScatterSlitType">
				<height unit="mm">9.00</height>
			</antiScatterSlit>
			<sollerSlit id="21020003" name="Large Soller slits 0.04 rad.">
				<opening unit="rad">0.0400</opening>
			</sollerSlit>
			<filter id="20030001" name="Large beta-filter Nickel">
				<material>Ni</material>
				<thickness unit="mm">0.020</thickness>
			</filter>
			<detector id="7010019" name="PIXcel1D-Medipix3 detector" xsi:type="rtmsDetectorType">
				<phd unit="keV">
					<lowerLevel>4.0</lowerLevel>
					<upperLevel>11.3</upperLevel>
				</phd>
				<mode>Scanning</mode>
				<activeLength unit="deg">5.020</activeLength>
			</detector>
		</diffractedBeamPath>
		<scan appendNumber="0" mode="Continuous" scanAxis="Gonio" status="Completed">
			<header>
				<startTimeStamp>2024-03-24T15:36:44-07:00</startTimeStamp>
				<endTimeStamp>2024-03-24T15:49:11-07:00</endTimeStamp>
				<author>
					<name>AutomatedUser</name>
				</author>
				<source>
					<applicationSoftware version="1.6 (94)">PANalytical Aeris Instrument Suite</applicationSoftware>
					<instrumentControlSoftware version="3.0.0 20211014">AERIS</instrumentControlSoftware>
					<instrumentID>2879380</instrumentID>
				</source>
			</header>
			<dataPoints>
				<positions axis="2Theta" unit="deg">
					<startPosition>9.99043322</startPosition>
					<endPosition>100.09495370</endPosition>
				</positions>
				<positions axis="Omega" unit="deg">
					<startPosition>4.99521661</startPosition>
					<endPosition>50.04747685</endPosition>
				</positions>
				<commonCountingTime unit="seconds">18.249</commonCountingTime>
				<counts unit="counts">4523 4378 4591 4446 4508 4442 4400 4488 4561 4492 4375 4485 4403 4535 4444 4391 4367 4348 4407 4403 4351 4315 4381 4348 4414 4484 4404 4354 4427 4476 4441 4317 4384 4403 4257 4261 4286 4288 4313 4259 4370 4461 4400 4202 4351 4253 4377 4250 4189 4288 4262 4193 4228 4338 4279 4294 4283 4190 4225 4202 4178 4181 4250 4256 4291 4231 4259 4171 4127 4222 4262 4255 4134 4241 4179 4309 4159 4256 4273 4262 4118 4127 4199 4164 4237 4120 4095 4143 4156 4166 4094 4144 4096 4047 4088 4210 4039 4051 4074 4182 4020 4109 4088 4151 4153 4066 4031 4124 4028 4077 4133 4091 4045 4053 4052 4099 3995 4037 3960 3982 4046 3997 3951 4017 3904 3957 4003 3987 4019 3952 4038 3970 3952 3827 3991 3881 3950 4030 3909 3918 4051 3888 4028 4005 3936 3824 3963 3930 3991 3991 3967 3978 3855 3811 3907 3951 3852 3793 3921 3838 3954 3773 3760 3792 3717 3699 3846 3818 3804 3893 3833 3847 3802 3769 3864 3744 3788 3779 3846 3737 3819 3805 3750 3816 3837 3860 3850 3794 3771 3801 3819 3778 3802 3710 3790 3903 3755 3777 3811 3799 3785 3811 3697 3713 3781 3733 3664 3756 3681 3672 3624 3652 3764 3651 3733 3652 3791 3705 3639 3677 3639 3603 3632 3712 3666 3609 3732 3635 3640 3724 3685 3616 3620 3582 3599 3657 3605 3639 3476 3677 3624 3711 3534 3561 3471 3554 3609 3535 3494 3567 3584 3536 3592 3528 3629 3521 3617 3460 3488 3536 3530 3599 3555 3513 3584 3621 3631 3545 3620 3517 3537 3536 3527 3456 3532 3575 3590 3618 3598 3544 3479 3382 3537 3422 3645 3462 3600 3536 3507 3493 3417 3546 3459 3549 3365 3512 3434 3478 3525 3385 3500 3495 3512 3491 3439 3452 3444 3421 3499 3444 3451 3445 3366 3445 3417 3374 3480 3411 3446 3433 3490 3380 3548 3359 3464 3402 3455 3418 3516 3359 3300 3351 3296 3511 3424 3412 3399 3337 3371 3429 3312 3403 3378 3369 3419 3398 3319 3421 3458 3303 3274 3315 3421 3370 3339 3389 3275 3256 3376 3299 3227 3371 3289 3393 3342 3308 3287 3378 3385 3397 3336 3345 3210 3361 3329 3441 3396 3381 3274 3309 3345 3333 3192 3249 3257 3429 3211 3293 3365 3259 3351 3303 3292 3346 3197 3246 3359 3321 3340 3215 3280 3233 3268 3303 3389 3269 3255 3279 3308 3279 3243 3290 3276 3296 3226 3380 3190 3265 3225 3324 3263 3314 3304 3292 3304 3304 3287 3235 3273 3207 3153 3263 3331 3159 3362 3248 3251 3175 3191 3154 3202 3245 3272 3188 3173 3208 3080 3358 3214 3310 3164 3301 3258 3210 3153 3159 3225 3204 3151 3152 3194 3124 3189 3187 3191 3193 3219 3197 3164 3129 3200 3213 3209 3197 3189 3142 3163 3079 3130 3284 3070 3168 3214 3175 3145 3239 3370 3219 3113 3116 3138 3146 3130 3205 3261 3337 3211 3231 3244 3184 3141 3223 3230 3185 3061 3126 3075 3203 3166 3270 3061 3242 3189 3101 3169 3253 3213 3193 3310 3211 3248 3228 3228 3233 3252 3171 3107 3216 3307 3301 3199 3188 3233 3265 3211 3246 3304 3165 3227 3260 3116 3116 3222 3271 3232 3213 3136 3254 3130 3167 3044 3158 3146 3174 3109 3152 3097 3106 3115 3195 3059 3045 3083 3069 3091 3075 3164 2995 3047 3064 2983 3053 3016 3086 3046 3119 3064 3081 3099 3095 3044 2938 3021 3117 3074 3166 3019 3085 3047 3160 3013 3075 2999 2975 3088 3088 3059 3088 3040 2989 3079 2993 3025 3048 3008 3105 3022 3145 3039 2955 3048 3029 3037 3003 3037 3116 3060 3005 3076 2987 3026 2990 3065 3062 2988 3090 3127 3028 3026 3021 2999 2921 3069 3005 3035 2912 2930 2881 3043 2901 2965 3160 3054 2997 3017 2976 2971 2985 3044 3029 2974 3015 2986 2896 3056 2952 2969 2968 2900 3098 2990 2836 2852 3073 3021 2991 2937 2889 3006 3036 2948 2962 2952 2984 3041 3018 3044 3018 3096 2979 2919 3079 3032 3035 2959 3031 3091 3022 2982 2948 3056 2991 3069 3128 2966 3022 3072 3004 3034 3081 2992 3037 2898 3027 2958 2888 2932 2952 2942 2898 2911 3056 2927 2849 2990 2947 3005 2866 2840 2859 2970 2910 2944 2911 2950 2928 2851 2948 2890 2964 2907 3120 2888 2945 3000 2948 2953 2888 2821 3063 2839 3105 2820 3033 2990 2980 2965 2974 3064 2991 2943 2897 2866 3020 3016 2970 2907 2893 2965 2878 2887 2976 2941 3042 2926 2973 2964 2867 3092 3019 2879 3096 2962 3003 2909 2991 2996 3035 2926 2918 2857 3002 2987 3078 2999 3073 3011 3040 3132 2940 3171 3056 3166 3203 3080 3032 3101 3286 3208 3238 3241 3223 3366 3510 3506 3565 3629 3827 3741 3814 3948 4050 4043 4335 4424 4570 4515 4746 4860 5109 5112 5188 5283 5583 5594 5606 5714 5742 5612 5598 5389 5241 5057 5009 4741 4601 4338 4121 3948 3827 3734 3648 3440 3460 3413 3329 3246 3274 3187 3150 3130 3080 3095 3046 2970 2987 3102 2974 2861 2924 2862 2919 3016 2848 2965 2936 2841 2980 2847 2853 2938 2817 2843 2821 2779 2781 2806 2886 2823 2749 2767 2857 2797 2808 2674 2743 2716 2712 2788 2751 2676 2725 2768 2727 2893 2758 2709 2671 2676 2666 2781 2773 2649 2705 2760 2679 2672 2729 2701 2795 2702 2787 2712 2788 2738 2713 2678 2706 2682 2740 2601 2626 2760 2781 2553 2679 2676 2655 2659 2657 2641 2649 2721 2674 2650 2607 2592 2652 2662 2659 2707 2690 2726 2632 2724 2605 2609 2643 2738 2655 2556 2620 2642 2791 2583 2595 2608 2713 2602 2655 2669 2645 2675 2651 2596 2698 2657 2635 2661 2671 2566 2637 2605 2571 2655 2610 2565 2688 2611 2502 2663 2531 2610 2662 2638 2577 2581 2481 2635 2595 2692 2502 2500 2672 2564 2614 2644 2615 2576 2568 2659 2682 2615 2669 2624 2595 2706 2598 2569 2589 2588 2660 2657 2614 2654 2721 2560 2669 2742 2621 2576 2553 2602 2617 2662 2668 2661 2640 2718 2571 2657 2620 2771 2729 2587 2726 2668 2729 2768 2854 2766 2809 2878 2870 2968 3073 3098 3316 3415 3527 3592 3664 3987 3980 4246 4358 4722 4864 5124 5448 5871 5930 6265 6363 6614 6509 6170 5830 5470 4949 4568 4123 3812 3559 3260 3028 2897 2801 2682 2715 2686 2643 2541 2611 2609 2707 2579 2631 2656 2644 2472 2535 2550 2573 2554 2562 2539 2457 2559 2521 2518 2515 2502 2465 2496 2541 2542 2450 2451 2527 2529 2532 2503 2503 2480 2425 2502 2418 2514 2366 2506 2501 2504 2504 2453 2527 2498 2533 2418 2446 2449 2413 2450 2466 2417 2427 2509 2482 2467 2393 2550 2376 2389 2458 2414 2372 2386 2457 2475 2416 2442 2385 2484 2410 2358 2446 2414 2428 2439 2480 2403 2411 2401 2420 2535 2374 2518 2352 2411 2317 2379 2461 2493 2475 2386 2488 2412 2378 2378 2487 2466 2404 2284 2397 2429 2556 2436 2415 2380 2411 2354 2407 2372 2435 2458 2406 2366 2309 2449 2302 2458 2274 2367 2400 2347 2338 2341 2394 2378 2444 2451 2388 2400 2367 2351 2386 2436 2406 2495 2398 2430 2423 2393 2411 2351 2362 2337 2329 2324 2358 2373 2483 2430 2367 2309 2427 2407 2359 2378 2369 2371 2413 2420 2416 2359 2379 2381 2402 2459 2354 2352 2430 2452 2356 2542 2451 2378 2377 2366 2339 2426 2450 2352 2385 2450 2345 2428 2388 2446 2413 2383 2418 2494 2518 2535 2442 2490 2520 2495 2584 2470 2506 2562 2507 2556 2484 2614 2560 2565 2684 2668 2733 2643 2734 2781 2885 2964 2937 3043 3131 3140 3365 3486 3456 3664 3690 3753 3999 4083 4202 4174 4297 4297 4388 4203 4285 4135 3945 3826 3654 3620 3405 3280 3411 3122 2945 2863 2719 2720 2805 2704 2647 2581 2559 2543 2517 2478 2528 2461 2510 2494 2500 2413 2503 2405 2397 2489 2414 2385 2343 2378 2401 2316 2289 2336 2293 2366 2298 2283 2260 2255 2363 2370 2234 2321 2235 2398 2330 2356 2333 2340 2181 2313 2295 2371 2290 2271 2314 2298 2315 2292 2258 2302 2147 2226 2274 2185 2291 2234 2296 2351 2319 2259 2272 2232 2229 2290 2303 2265 2242 2269 2299 2315 2173 2218 2272 2332 2276 2223 2269 2133 2228 2224 2163 2280 2302 2255 2245 2194 2318 2204 2204 2198 2305 2173 2262 2238 2193 2271 2141 2209 2256 2214 2173 2159 2179 2179 2219 2286 2273 2114 2191 2222 2184 2281 2287 2281 2194 2293 2202 2217 2158 2233 2306 2230 2238 2129 2272 2161 2211 2116 2250 2136 2218 2216 2249 2125 2185 2267 2198 2192 2200 2184 2140 2200 2171 2195 2152 2200 2137 2139 2117 2267 2122 2214 2239 2277 2148 2242 2183 2171 2106 2181 2121 2132 2207 2197 2183 2294 2210 2251 2122 2228 2214 2122 2225 2158 2191 2205 2190 2185 2221 2074 2143 2117 2219 2110 2183 2157 2188 2173 2284 2252 2201 2159 2293 2231 2203 2267 2173 2157 2227 2117 2208 2087 2139 2126 2190 2138 2223 2198 2203 2147 2258 2130 2211 2106 2197 2158 2222 2145 2184 2176 2108 2197 2149 2171 2179 2170 2142 2182 2171 2166 2123 2170 2205 2269 2142 2212 2182 2227 2186 2125 2110 2128 2125 2185 2121 2130 2127 2123 2138 2207 2173 2176 2223 2181 2139 2066 2236 2206 2160 2176 2167 2246 2199 2186 2130 2178 2117 2151 2211 2148 2234 2230 2241 2160 2085 2117 2254 2139 2201 2187 2172 2135 2283 2294 2261 2237 2253 2325 2223 2305 2280 2187 2217 2218 2244 2205 2225 2242 2136 2216 2197 2156 2151 2222 2173 2131 2135 2104 2081 2113 2150 2099 2207 2190 2095 2156 2157 2213 2130 2133 2099 2071 2192 2116 2110 2085 2208 2183 2141 2157 2135 2155 2101 2125 2152 2145 2172 2185 2102 2136 2098 2159 2163 2158 2159 2192 2200 2185 2164 2131 2152 2168 2063 2012 2184 2119 2143 2144 2089 2202 2127 2175 2201 2228 2193 2216 2170 2166 2208 2168 2091 2110 2088 2030 2134 2168 2106 2060 2142 2232 2107 2083 2160 2206 2086 2183 2179 2172 2174 2133 2187 2197 2105 2130 2155 2170 2178 2192 2197 2068 2110 2142 2238 2223 2159 2233 2216 2250 2135 2163 2106 2122 2224 2323 2320 2276 2178 2224 2274 2212 2152 2154 2261 2248 2168 2224 2247 2236 2194 2166 2262 2306 2226 2316 2237 2226 2213 2223 2264 2298 2339 2257 2289 2269 2318 2285 2256 2265 2395 2279 2307 2415 2338 2341 2354 2345 2294 2464 2457 2374 2376 2487 2479 2381 2558 2540 2600 2670 2652 2626 2600 2695 2649 2590 2751 2777 2701 2905 2692 2818 2838 2746 2928 2934 2874 3002 2991 3075 3025 3109 3181 3089 3277 3152 3267 3339 3360 3463 3473 3604 3664 3650 3763 3881 4085 4025 4095 4419 4298 4650 4766 4854 4929 5037 5370 5341 5525 5649 5881 5815 5994 6174 6235 6299 6383 6442 6599 6473 6643 6579 6668 6718 6950 7115 7045 7339 7593 7672 8105 8276 8816 9007 9594 9797 10390 11014 11536 12050 12841 13324 14104 14922 15520 16800 18130 19548 20817 22321 24365 26879 29152 32163 35634 38417 41745 45036 46891 47233 45653 42415 37712 33854 30877 28504 26370 23891 20322 17210 13818 11244 9481 8171 7379 6837 6314 6036 5737 5527 5380 5189 5138 4855 4877 4724 4688 4639 4619 4403 4417 4384 4325 4291 4252 4300 4177 4315 4243 4145 4234 4221 4162 4322 4358 4404 4635 4527 4741 4736 4908 5080 5302 5685 5985 6035 6305 6719 7337 7763 8210 8301 9027 9459 9838 10259 10257 10257 10184 10274 10028 9789 9516 9190 8919 8447 8291 8062 7778 7602 7366 7429 7114 7180 7178 7221 7271 7546 7524 7938 7879 8115 8261 8376 8771 8690 8985 9133 9210 9413 9469 9526 9398 9067 9122 9027 8849 8667 8434 8161 7867 7655 7313 7274 6869 6519 6368 6071 5951 5787 5387 5197 5246 4899 4721 4702 4528 4348 4230 4285 4080 4019 3830 3697 3513 3586 3468 3485 3263 3294 3265 3173 3229 3178 3065 3043 2987 2916 2916 2942 2802 2895 2754 2871 2829 2731 2680 2773 2643 2716 2628 2680 2675 2620 2588 2590 2616 2497 2626 2521 2520 2496 2530 2500 2494 2466 2506 2410 2501 2436 2447 2449 2406 2490 2347 2281 2444 2306 2301 2339 2318 2350 2348 2386 2337 2326 2390 2329 2304 2275 2318 2231 2302 2325 2318 2258 2350 2366 2246 2198 2165 2256 2374 2259 2322 2238 2300 2258 2241 2264 2360 2350 2356 2409 2546 2549 2546 2625 2671 2748 2836 2752 2752 2727 2626 2599 2560 2533 2487 2556 2483 2569 2433 2361 2375 2474 2421 2448 2418 2491 2479 2326 2529 2585 2467 2571 2535 2590 2634 2746 2751 2676 2666 2653 2660 2732 2643 2698 2615 2735 2602 2614 2535 2518 2592 2489 2416 2520 2383 2480 2404 2373 2409 2365 2270 2353 2263 2396 2204 2189 2198 2194 2163 2256 2247 2207 2160 2204 2222 2189 2216 2217 2098 2176 2102 2200 2094 2146 2183 2132 2116 2177 2135 2119 2040 2120 2138 2075 2133 2118 2090 2148 2124 2108 2152 2166 2068 2111 2149 2085 2059 2104 2158 2090 2152 2219 2141 2232 2166 2156 2030 2162 2201 2153 2149 2173 2181 2057 2227 2134 2192 2178 2071 2101 2132 2120 2086 2196 2165 2117 2086 2167 2240 2156 2212 2214 2172 2179 2180 2136 2225 2169 2194 2158 2183 2220 2230 2312 2212 2315 2320 2204 2256 2312 2342 2290 2322 2408 2344 2447 2354 2416 2556 2406 2467 2657 2645 2550 2677 2804 2849 2794 2859 2834 3036 3051 3179 3278 3366 3486 3558 3696 3975 3995 4071 4368 4370 4523 4620 4735 4632 4777 4837 5049 5075 5103 5118 5134 5234 5157 5102 5172 5219 5156 5329 5484 5902 6055 6628 7129 7795 8688 9634 10634 11635 12736 13707 14097 13946 13348 11749 10891 9742 9241 8930 8532 8122 7372 6527 5582 4724 4145 3714 3281 3147 2794 2767 2674 2700 2499 2502 2425 2483 2454 2340 2409 2298 2360 2308 2341 2283 2154 2305 2149 2287 2315 2200 2183 2151 2186 2175 2152 2123 2182 2126 2203 2063 2028 2133 2140 2094 2072 2068 2175 2029 2040 1984 2066 2117 2053 2121 2131 2043 2095 2062 2081 1995 2050 1940 2019 2066 1960 2135 2041 2035 1990 2017 2041 2057 2052 1988 2034 1948 2023 1937 1994 2082 1985 2004 2055 1973 1993 2103 1939 2030 2056 2009 2051 2031 2123 2068 1947 1947 1953 1954 1938 2028 1971 1952 1983 1977 2070 2105 1984 1971 1952 2037 2038 1997 2025 2070 2032 2059 2048 2064 2046 2044 2175 2050 2073 2068 2043 2016 2075 2197 2092 2218 2053 2121 2233 2218 2157 2148 2200 2196 2205 2350 2278 2376 2309 2283 2428 2472 2431 2524 2545 2490 2545 2598 2724 2735 2727 2865 3027 2969 3044 3129 3219 3190 3350 3523 3708 3518 3710 3867 3873 3844 3901 3964 3834 3990 3906 3818 3644 3597 3582 3543 3473 3515 3310 3245 3237 3216 3327 3351 3419 3513 3791 3817 4060 4141 4323 4538 4248 4278 4101 3813 3614 3440 3481 3319 3292 3232 3143 2976 2763 2719 2482 2417 2429 2338 2355 2388 2260 2190 2345 2370 2459 2338 2341 2377 2222 2394 2333 2466 2519 2549 2565 2454 2543 2573 2581 2589 2718 2573 2700 2768 2789 2750 2899 2996 2990 3118 3084 3307 3350 3379 3461 3495 3548 3788 3754 3736 3779 3914 3947 3866 3902 3949 3756 3793 3794 3692 3739 3664 3613 3475 3427 3473 3253 3185 3023 2924 2878 2856 2715 2788 2623 2604 2473 2492 2449 2361 2390 2352 2360 2286 2216 2277 2281 2214 2115 2177 2160 2048 2087 2077 2129 2034 2036 1944 1965 2042 1989 1996 2010 1970 1961 1997 2043 1983 1951 1889 1952 1891 1952 1910 1967 1856 1906 1807 1938 2027 1789 1878 1896 1866 1847 1953 1855 1818 1819 1871 1851 1815 1816 1850 1844 1805 1882 1887 1869 1816 1804 1789 1869 1856 1831 1837 1756 1869 1897 1816 1802 1853 1765 1887 1863 1794 1788 1819 1794 1742 1820 1799 1970 1801 1800 1771 1892 1872 1804 1829 1813 1841 1874 1860 1840 1848 1975 2009 2023 2007 2173 2192 2200 2145 2297 2164 2306 2268 2192 2049 2050 2019 2062 2096 2000 1940 1958 1893 1924 1836 1829 1815 1892 1848 1815 1826 1768 1762 1838 1643 1819 1788 1825 1706 1805 1799 1820 1716 1824 1786 1821 1791 1828 1802 1757 1736 1693 1807 1775 1739 1801 1775 1806 1752 1717 1800 1783 1759 1742 1784 1770 1709 1765 1740 1721 1826 1760 1716 1741 1715 1766 1732 1736 1761 1840 1777 1820 1807 1753 1744 1767 1724 1817 1751 1773 1762 1754 1784 1763 1745 1761 1741 1786 1804 1779 1790 1746 1717 1730 1691 1855 1868 1757 1822 1858 1820 1886 1835 1717 1811 1828 1889 1850 1812 1813 1805 1890 1857 1884 1918 1928 1922 1914 1920 1988 1961 1922 1944 2090 2034 2141 2064 2187 2291 2325 2293 2459 2503 2593 2785 2728 2732 2879 2968 2935 3072 2946 2921 3059 2999 2792 2803 2723 2685 2641 2596 2623 2495 2308 2373 2368 2219 2182 2209 2129 2000 2063 2077 2048 1942 1984 2037 1898 1989 1927 2015 1949 2072 2032 2072 2078 2121 2219 2429 2429 2484 2741 2938 3147 3255 3501 3591 3657 3409 3370 2993 2825 2789 2754 2642 2683 2685 2592 2581 2479 2316 2124 1999 1967 1942 1833 1871 1798 1828 1813 1818 1733 1786 1869 1836 1782 1701 1814 1772 1810 1711 1665 1828 1689 1786 1761 1758 1731 1754 1715 1797 1741 1650 1769 1695 1740 1725 1786 1748 1828 1822 1770 1706 1715 1734 1671 1817 1797 1768 1779 1759 1783 1672 1707 1675 1777 1762 1787 1805 1794 1774 1797 1811 1797 1823 1822 1906 1796 1802 1797 1892 1859 1875 1867 1974 1943 1911 1958 1887 1901 1949 1926 1990 1962 1962 1963 1957 1976 2070 2041 1990 1903 1992 1925 1949 1917 2044 1995 2013 1950 2042 2042 2023 1977 1910 1950 1940 1937 1900 1891 1898 2015 1868 1904 1873 1872 1789 1883 1791 1804 1833 1827 1815 1775 1701 1922 1765 1778 1822 1727 1795 1704 1800 1797 1749 1702 1706 1738 1762 1713 1834 1743 1809 1698 1720 1732 1775 1728 1744 1770 1643 1761 1792 1754 1756 1717 1814 1838 1895 1837 1952 1834 1928 1902 2038 1985 2032 2102 2043 1981 1974 1982 1993 1914 1865 1946 1890 1874 1911 1811 1843 1830 1768 1719 1821 1771 1741 1723 1730 1671 1649 1703 1652 1692 1748 1760 1753 1769 1691 1826 1733 1740 1716 1773 1800 1680 1728 1758 1783 1770 1729 1743 1751 1823 1802 1767 1748 1793 1741 1785 1762 1795 1852 1897 1888 1859 1899 1954 1910 1841 1914 1894 1871 1981 1908 1995 2026 1987 2018 2124 2015 1941 2078 2059 2090 2094 2126 2099 2207 2185 2098 2151 2141 2229 2155 2186 2140 2171 2133 2107 2158 2187 2111 2088 2167 2083 2126 2243 2187 2295 2289 2335 2360 2394 2469 2454 2642 2651 2807 2785 2903 2874 2910 2912 2931 3033 2879 2783 2870 2820 2731 2763 2705 2695 2608 2508 2556 2447 2446 2294 2365 2279 2163 2160 2119 2066 2165 2121 1998 2080 2060 2084 2084 2061 2158 2031 2030 2008 2097 2042 2133 2158 2195 2222 2186 2290 2242 2322 2350 2556 2671 2945 2914 3399 3684 3998 4414 4846 5141 5534 5641 5438 5139 4659 4267 4035 4076 3789 4043 4294 4126 4061 3918 3746 3554 3199 2812 2863 2667 2629 2467 2322 2359 2268 2311 2260 2217 2246 2156 2142 2105 2045 2053 2005 2006 2024 2056 1996 1966 1935 1932 1916 1864 1830 1929 1930 1893 1782 1832 1787 1851 1773 1742 1804 1728 1851 1763 1732 1734 1706 1675 1770 1772 1734 1809 1656 1657 1705 1684 1671 1726 1709 1663 1671 1653 1595 1708 1762 1668 1642 1688 1694 1602 1611 1636 1704 1574 1686 1674 1695 1721 1655 1721 1681 1699 1683 1684 1718 1643 1666 1650 1681 1674 1618 1750 1635 1610 1675 1577 1710 1614 1661 1724 1740 1685 1662 1767 1670 1716 1699 1746 1703 1755 1711 1639 1675 1681 1666 1753 1676 1758 1629 1673 1635 1688 1671 1655 1639 1682 1679 1644 1675 1595 1610 1688 1637 1707 1664 1682 1653 1636 1591 1644 1689 1662 1619 1621 1623 1592 1625 1630 1676 1659 1640 1717 1643 1556 1635 1669 1662 1585 1664 1683 1760 1683 1667 1682 1686 1643 1596 1641 1624 1618 1600 1597 1691 1604 1743 1650 1605 1739 1604 1663 1614 1721 1668 1735 1640 1664 1665 1604 1698 1789 1608 1671 1699 1619 1713 1689 1674 1699 1682 1660 1658 1691 1697 1687 1716 1769 1682 1710 1687 1760 1748 1723 1756 1682 1733 1664 1784 1830 1771 1791 1769 1806 1766 1797 1767 1802 1855 1814 1850 1851 1805 1826 1887 1908 1874 1974 1946 1943 1906 2029 2044 2068 2024 2053 2160 2105 2145 2175 2302 2332 2326 2506 2368 2442 2397 2468 2552 2467 2497 2551 2568 2593 2458 2486 2483 2430 2497 2378 2477 2368 2301 2410 2253 2223 2131 2176 2122 2080 2148 2045 1981 2011 1932 1893 1920 1946 1825 1784 1889 1830 1828 1877 1834 1784 1779 1819 1788 1762 1791 1856 1879 1825 1858 1824 1853 1851 1915 1961 2006 2075 2116 2116 2167 2333 2413 2527 2689 2702 2858 2775 2802 2655 2464 2491 2435 2427 2422 2505 2498 2611 2556 2663 2465 2424 2461 2364 2489 2440 2437 2354 2528 2488 2452 2513 2417 2476 2449 2612 2360 2399 2492 2446 2403 2410 2288 2293 2297 2169 2123 2121 2174 2133 2068 2032 1985 1975 1991 1936 1920 1946 1908 1895 1880 1817 1812 1827 1851 1787 1772 1870 1818 1779 1781 1783 1804 1820 1756 1766 1739 1782 1814 1748 1804 1772 1740 1828 1749 1813 1801 1790 1697 1812 1795 1772 1818 1761 1727 1827 1649 1825 1798 1696 1728 1767 1742 1866 1783 1699 1798 1867 1776 1823 1784 1907 1877 1856 1861 1890 1907 1877 1860 1948 1899 1904 1956 1942 1922 1902 2086 2016 2100 2093 2069 2133 2079 2252 2183 2174 2216 2297 2294 2418 2500 2394 2517 2547 2623 2548 2592 2767 2788 2903 3098 3192 3388 3534 3850 4432 4905 5375 6548 7446 8703 10367 12067 13809 15292 16095 16069 14711 13335 11208 9674 8430 7894 7685 8194 8385 9095 9361 9409 8784 8099 7074 5802 4936 4257 3812 3403 3120 2970 2886 2799 2705 2740 2667 2788 2787 2709 2802 2795 2804 2935 2868 3034 3057 3091 3110 3180 3197 3333 3258 3262 3319 3380 3352 3409 3475 3450 3600 3700 3684 3844 3705 3616 3550 3378 3420 3413 3260 3188 3194 3155 2981 3037 2876 2776 2892 2808 2731 2580 2519 2460 2516 2392 2258 2194 2152 2086 2035 2095 2042 2085 2040 2054 1997 1967 1853 1940 1833 1809 1835 1784 1847 1820 1829 1789 1774 1814 1778 1731 1794 1766 1754 1728 1734 1751 1713 1716 1784 1809 1725 1692 1748 1753 1725 1755 1747 1657 1687 1703 1688 1713 1738 1770 1667 1722 1713 1691 1702 1750 1723 1705 1683 1770 1824 1694 1654 1703 1802 1821 1818 1855 1805 1856 1896 2005 1993 2130 2225 2360 2500 2454 2647 2499 2336 2282 2215 1980 2007 2020 2035 1964 1997 2109 2055 2171 2024 1967 1954 1850 1886 1804 1726 1667 1643 1691 1650 1732 1685 1617 1639 1663 1708 1706 1702 1693 1639 1601 1649 1664 1582 1677 1658 1640 1638 1573 1608 1694 1484 1650 1616 1560 1548 1552 1588 1614 1589 1578 1609 1591 1594 1602 1561 1596 1648 1640 1642 1611 1619 1560 1639 1568 1649 1599 1657 1616 1729 1565 1617 1584 1671 1632 1641 1624 1621 1659 1637 1651 1501 1592 1601 1592 1656 1654 1601 1592 1620 1580 1626 1600 1593 1629 1669 1586 1619 1557 1577 1644 1665 1563 1654 1642 1619 1561 1673 1575 1627 1712 1647 1610 1611 1639 1661 1628 1654 1622 1580 1631 1632 1657 1599 1649 1662 1636 1622 1617 1590 1640 1698 1677 1688 1682 1684 1717 1701 1720 1673 1742 1787 1794 1863 1868 1898 1918 1879 1862 1818 1799 1801 1806 1786 1760 1818 1776 1782 1794 1875 1786 1858 1783 1771 1747 1755 1707 1758 1725 1777 1758 1774 1714 1606 1710 1683 1755 1767 1639 1748 1640 1717 1684 1651 1625 1701 1715 1615 1651 1678 1695 1585 1715 1639 1703 1630 1657 1601 1655 1671 1622 1597 1644 1541 1578 1635 1585 1612 1616 1585 1610 1666 1657 1617 1612 1615 1635 1620 1575 1638 1600 1687 1590 1530 1592 1515 1562 1513 1581 1578 1523 1644 1574 1576 1592 1654 1563 1620 1610 1639 1521 1617 1474 1516 1654 1566 1579 1559 1552 1640 1620 1610 1588 1660 1584 1694 1579 1591 1626 1609 1584 1623 1584 1592 1615 1568 1579 1768 1616 1679 1683 1627 1620 1662 1680 1688 1681 1684 1654 1642 1722 1751 1775 1701 1775 1812 1954 1996 2106 2299 2474 2669 2967 3080 3318 3389 3429 3239 2978 2759 2592 2374 2371 2238 2286 2296 2363 2402 2524 2595 2589 2487 2381 2196 2082 1960 1775 1912 1810 1751 1707 1701 1745 1718 1656 1677 1688 1670 1714 1671 1662 1678 1636 1669 1650 1637 1670 1625 1590 1677 1673 1611 1644 1581 1717 1745 1687 1652 1596 1633 1623 1699 1611 1658 1668 1596 1696 1558 1593 1680 1586 1684 1695 1575 1719 1571 1688 1628 1725 1572 1728 1601 1598 1583 1584 1650 1647 1614 1662 1619 1668 1634 1728 1604 1648 1552 1559 1656 1613 1696 1689 1691 1732 1586 1658 1744 1753 1693 1649 1705 1707 1790 1724 1793 1769 1746 1754 1680 1694 1770 1717 1769 1816 1798 1827 1837 1816 1932 1843 1862 1891 1960 1958 1973 2005 2063 2034 1967 2033 2163 2128 2156 2157 2223 2298 2249 2463 2446 2511 2565 2758 2783 2698 2816 2692 2675 2624 2601 2490 2556 2507 2535 2551 2549 2675 2615 2638 2543 2607 2432 2387 2321 2335 2247 2231 2226 2190 2146 2181 2058 2111 2102 1954 2011 1984 1970 1852 1939 1964 1983 1886 1905 1846 1872 1839 1858 1886 1818 1836 1756 1829 1746 1728 1766 1750 1780 1802 1721 1680 1719 1744 1749 1795 1780 1752 1750 1719 1707 1688 1668 1676 1720 1608 1690 1708 1702 1743 1689 1792 1772 1686 1656 1690 1735 1772 1733 1701 1727 1787 1807 1744 1758 1786 1741 1655 1753 1709 1811 1815 1733 1680 1824 1737 1812 1787 1845 1786 1782 1863 1826 1841 1903 1916 1849 1881 1897 1921 1976 2058 2017 2063 2092 2041 2089 2198 2201 2179 2170 2282 2357 2456 2559 2536 2658 2652 2820 2869 2934 3049 3266 3341 3506 3733 4017 4216 4118 4218 3927 3840 3509 3450 3164 3194 2951 3070 3032 3083 3087 3181 3193 3148 3223 3017 2908 2645 2655 2430 2408 2290 2312 2176 2145 2065 2090 2120 2065 2103 2038 2012 1991 1992 2013 1943 2008 2006 1992 1967 1985 1946 2069 2048 1915 2009 2055 1947 2022 2102 1948 2012 2047 2106 2074 2088 2146 2065 2150 2148 2199 2269 2286 2324 2282 2332 2328 2346 2402 2538 2548 2588 2683 2597 2561 2714 2687 2722 2550 2669 2639 2611 2597 2588 2471 2586 2553 2547 2541 2480 2601 2549 2500 2482 2362 2532 2486 2423 2397 2499 2461 2356 2371 2423 2382 2459 2437 2430 2434 2477 2467 2515 2580 2620 2637 2603 2498 2620 2618 2636 2724 2741 2881 2903 2973 3160 3145 3326 3541 3756 4131 4543 5097 5874 6699 7779 9166 10328 11459 11885 11483 10999 9811 8414 7151 6321 5636 5432 5235 5520 5682 6086 6657 7225 7244 7273 7007 6459 5755 5277 4707 4105 3717 3471 3400 3173 3083 3074 2893 2824 2780 2768 2687 2732 2642 2585 2483 2542 2440 2458 2434 2398 2313 2256 2252 2223 2293 2131 2164 2109 2117 2063 2068 1997 2002 1985 1980 1894 1923 1914 1910 1950 1949 1859 1834 1793 1865 1800 1791 1822 1739 1783 1778 1768 1827 1770 1735 1849 1728 1725 1656 1725 1805 1831 1714 1729 1722 1689 1724 1712 1781 1641 1663 1730 1600 1688 1681 1772 1710 1761 1631 1749 1663 1661 1707 1697 1688 1723 1731 1740 1666 1693 1659 1715 1731 1760 1782 1696 1746 1786 1733 1721 1768 1811 1826 1880 1943 1868 2031 2073 2105 2350 2315 2638 2867 3000 3301 3640 3824 3629 3533 3310 2921 2677 2551 2322 2335 2227 2364 2411 2477 2605 2735 2714 2772 2701 2717 2433 2422 2270 2129 2072 2123 1986 1995 1991 1957 1914 1959 1934 1927 1815 1959 1928 2018 1948 1878 1999 2031 2014 2045 1956 2136 2051 2081 2073 2103 2038 2032 2069 2085 2019 1951 2023 1900 2005 2006 2004 2002 1978 2040 1976 1929 1999 1873 1818 1980 1902 1832 1939 1922 1838 1724 1795 1823 1803 1790 1787 1765 1778 1806 1823 1791 1816 1787 1789 1786 1742 1725 1724 1854 1823 1736 1813 1768 1777 1819 1818 1746 1795 1812 1829 1933 1788 1764 1905 1830 1863 1878 1807 1844 1791 1904 1846 1878 1771 1870 1985 1892 1926 1970 1983 2119 2045 2047 2125 2116 2337 2367 2669 2821 3001 3176 3501 3684 3951 3963 3872 3645 3401 3159 3111 2951 2798 2741 2839 2795 2945 3008 2994 3283 3252 3142 3207 3169 2976 2949 2732 2698 2700 2570 2605 2573 2623 2558 2603 2574 2571 2529 2600 2544 2657 2656 2621 2746 2642 2692 2709 2662 2642 2629 2758 2671 2691 2730 2634 2691 2670 2712 2694 2710 2598 2650 2655 2692 2575 2683 2619 2646 2646 2695 2653 2609 2780 2747 2758 2824 2865 2940 2842 2783 2889 3032 2956 3071 3082 3058 3220 3224 3312 3295 3274 3381 3377 3395 3464 3444 3456 3513 3563 3489 3450 3415 3414 3460 3327 3301 3246 3309 3176 3165 3126 3135 3029 3038 2948 2852 2903 2741 2670 2740 2710 2501 2564 2585 2415 2299 2454 2414 2328 2385 2266 2286 2278 2400 2369 2397 2413 2529 2649 2717 2735 2665 2629 2475 2331 2205 2181 2142 2130 2043 2015 2043 2116 2058 2183 2269 2217 2269 2187 2118 2126 2169 2004 1913 1963 1942 1837 1857 1845 1849 1760 1794 1794 1733 1788 1712 1684 1714 1732 1707 1727 1758 1726 1727 1765 1630 1703 1545 1644 1633 1610 1595 1639 1593 1631 1640 1728 1607 1626 1506 1554 1646 1611 1603 1574 1622 1556 1568 1689 1590 1594 1618 1546 1702 1575 1574 1638 1556 1580 1580 1602 1602 1626 1629 1607 1569 1590 1680 1688 1635 1603 1668 1709 1690 1688 1696 1707 1712 1720 1710 1791 1691 1644 1713 1651 1639 1689 1619 1701 1736 1647 1728 1747 1668 1662 1657 1664 1705 1771 1689 1712 1788 1719 1782 1707 1697 1766 1785 1851 1824 1952 1918 2001 2131 2063 2076 2098 2013 1931 1804 1740 1754 1757 1784 1777 1671 1734 1681 1789 1744 1788 1812 1861 1777 1840 1692 1738 1734 1674 1614 1661 1610 1614 1631 1587 1581 1649 1564 1613 1506 1615 1581 1577 1561 1590 1585 1564 1555 1567 1614 1575 1594 1619 1512 1606 1627 1591 1603 1609 1618 1561 1585 1599 1655 1653 1625 1615 1654 1632 1692 1681 1681 1717 1800 1787 1723 1717 1699 1671 1789 1800 1804 1922 1855 1891 1998 1954 1902 1954 2001 1938 1966 1930 1868 1795 1938 1870 1902 1862 1840 1840 1806 1888 1839 1751 1838 1774 1821 1813 1827 1731 1683 1814 1764 1708 1737 1686 1730 1731 1807 1678 1684 1686 1749 1734 1761 1791 1730 1801 1887 1945 2057 2129 2296 2438 2539 2482 2608 2477 2392 2257 2141 1997 1980 1872 1853 1811 1780 1865 1844 1939 1946 2035 2066 2133 2061 2073 1961 1915 1890 1768 1667 1695 1698 1698 1604 1690 1617 1604 1695 1560 1597 1632 1575 1598 1493 1616 1611 1625 1573 1602 1621 1640 1540 1608 1504 1540 1520 1594 1526 1551 1640 1575 1603 1560 1628 1578 1539 1573 1564 1534 1581 1568 1639 1618 1456 1561 1609 1621 1638 1619 1626 1557 1619 1557 1668 1602 1608 1576 1533 1598 1625 1635 1655 1600 1676 1655 1658 1612 1650 1696 1664 1614 1605 1666 1677 1680 1765 1696 1722 1707 1741 1724 1720 1710 1806 1802 1785 1796 1765 1787 1742 1813 1886 1816 1873 1863 1888 1929 2017 2075 2019 2212 2266 2292 2391 2379 2429 2390 2373 2404 2246 2206 2063 2151 2140 2055 2080 2067 2069 2000 2022 2037 2118 2163 2238 2237 2137 2122 2031 2005 1932 1941 1831 1888 1828 1843 1859 1777 1831 1757 1857 1818 1769 1729 1797 1766 1717 1763 1676 1742 1682 1742 1658 1783 1752 1729 1667 1657 1699 1750 1690 1722 1682 1729 1731 1750 1761 1677 1718 1641 1746 1698 1841 1735 1673 1656 1759 1710 1783 1707 1749 1699 1743 1753 1727 1799 1830 1764 1749 1798 1846 1755 1734 1690 1676 1718 1736 1740 1728 1718 1774 1745 1803 1745 1753 1779 1760 1730 1682 1690 1670 1671 1765 1745 1625 1711 1772 1673 1714 1703 1682 1675 1699 1708 1700 1703 1601 1759 1715 1677 1647 1642 1685 1632 1689 1658 1705 1654 1622 1635 1667 1625 1649 1612 1699 1687 1690 1730 1698 1646 1569 1641 1622 1575 1596 1628 1530 1611 1587 1573 1619 1586 1629 1635 1565 1584 1602 1513 1611 1517 1615 1612 1531 1545 1540 1553 1554 1553 1526 1581 1573 1526 1543 1485 1464 1538 1541 1585 1469 1593 1506 1545 1561 1553 1564 1489 1497 1541 1594 1525 1475 1490 1511 1502 1473 1499 1535 1543 1587 1512 1525 1547 1540 1497 1530 1504 1492 1512 1526 1505 1509 1553 1541 1515 1596 1512 1618 1618 1519 1517 1555 1599 1491 1631 1583 1619 1461 1605 1552 1636 1632 1585 1642 1558 1626 1596 1606 1653 1562 1649 1680 1790 1730 1788 1686 1763 1715 1737 1687 1728 1783 1769 1741 1715 1747 1825 1785 1782 1840 1837 1871 1753 1824 1788 1819 1838 1883 1768 1716 1740 1784 1832 1870 1797 1711 1831 1810 1794 1814 1785 1726 1768 1799 1780 1729 1724 1670 1758 1710 1687 1726 1647 1737 1671 1697 1718 1678 1621 1695 1618 1668 1631 1653 1627 1621 1564 1624 1574 1560 1603 1600 1559 1596 1619 1609 1597 1600 1588 1611 1655 1606 1549 1519 1543 1585 1549 1630 1554 1594 1575 1624 1507 1563 1563 1496 1476 1551 1551 1612 1554 1486 1520 1540 1548 1507 1563 1503 1580 1522 1568 1515 1563 1551 1599 1615 1526 1572 1541 1593 1506 1584 1514 1572 1554 1601 1608 1618 1669 1658 1683 1637 1765 1583 1750 1771 1754 1880 1956 2002 2094 2174 2260 2283 2365 2369 2324 2185 2167 2127 2032 1983 1912 1779 1806 1861 1794 1862 1924 1864 1913 1920 1973 1951 2043 1889 1945 1977 1816 1823 1726 1697 1708 1733 1654 1696 1661 1657 1645 1625 1647 1601 1674 1657 1506 1548 1647 1583 1646 1603 1561 1620 1464 1584 1526 1579 1647 1535 1524 1621 1589 1500 1511 1591 1483 1568 1541 1512 1572 1632 1505 1574 1554 1534 1551 1529 1587 1571 1572 1473 1516 1543 1524 1448 1562 1568 1483 1563 1514 1505 1550 1530 1556 1603 1531 1530 1478 1543 1510 1523 1486 1588 1490 1488 1510 1551 1535 1521 1555 1604 1541 1559 1577 1542 1527 1599 1654 1681 1661 1661 1728 1656 1799 1889 1994 2005 2181 2376 2341 2466 2640 2545 2593 2501 2343 2154 2124 1937 1815 1862 1808 1788 1750 1784 1734 1781 1917 1965 1935 1936 2011 2023 2006 1966 1878 1920 1786 1682 1718 1665 1682 1537 1616 1549 1596 1531 1560 1495 1501 1579 1553 1556 1552 1483 1450 1482 1512 1538 1508 1487 1517 1568 1552 1480 1537 1588 1539 1465 1575 1497 1526 1586 1465 1402 1484 1532 1548 1507 1591 1539 1512 1536 1555 1539 1629 1519 1610 1563 1573 1558 1588 1586 1632 1633 1664 1530 1556 1559 1525 1550 1577 1563 1571 1582 1651 1566 1585 1617 1671 1546 1572 1649 1545 1507 1538 1574 1637 1646 1598 1561 1617 1578 1579 1639 1659 1617 1711 1692 1771 1858 1903 2020 2061 2261 2288 2450 2571 2745 2715 2471 2306 2159 2148 2002 1915 1881 1884 1736 1787 1703 1687 1736 1901 1914 1930 1986 2026 2033 2102 2139 1941 1916 1845 1813 1784 1736 1673 1622 1591 1547 1566 1579 1633 1609 1614 1545 1532 1511 1526 1560 1512 1564 1464 1525 1494 1508 1483 1445 1495 1521 1455 1478 1474 1543 1514 1462 1495 1578 1518 1530 1537 1505 1466 1425 1479 1493 1481 1505 1502 1482 1477 1459 1441 1529 1455 1522 1504 1420 1457 1490 1517 1464 1576 1563 1555 1472 1525 1491 1545 1514 1463 1590 1542 1538 1542 1598 1545 1582 1584 1623 1582 1528 1525 1631 1617 1596 1582 1623 1593 1607 1738 1669 1707 1760 1803 1850 1881 1909 2089 2069 2180 2309 2260 2368 2251 2290 2111 2089 1987 1925 1944 1912 1813 1884 1866 1915 1913 1825 1893 1884 1944 2059 1974 1982 1992 1959 1911 1931 1832 1698 1745 1714 1700 1699 1655 1698 1671 1640 1677 1604 1641 1560 1579 1624 1560 1555 1602 1550 1504 1564 1502 1560 1562 1545 1546 1572 1563 1521 1565 1525 1472 1556 1587 1543 1557 1470 1587 1523 1527 1472 1515 1476 1482 1541 1524 1557 1562 1544 1523 1524 1481 1536 1543 1532 1522 1624 1471 1528 1518 1549 1529 1529 1524 1563 1511 1594 1471 1613 1507 1560 1478 1585 1458 1615 1575 1540 1556 1508 1605 1561 1545 1592 1521 1502 1574 1641 1635 1708 1677 1697 1711 1812 1895 1909 1996 2208 2203 2232 2165 2041 2029 1901 1887 1916 1763 1694 1723 1666 1607 1686 1684 1691 1775 1748 1790 1785 1815 1845 1787 1877 1797 1860 1774 1708 1654 1665 1605 1584 1609 1544 1578 1533 1586 1549 1535 1581 1443 1518 1547 1437 1553 1578 1499 1520 1502 1477 1536 1511 1598 1538 1509 1544 1559 1486 1506 1530 1558 1601 1546 1580 1553 1552 1533 1527 1572 1533 1497 1509 1554 1501 1532 1505 1446 1542 1503 1558 1571 1532 1504 1590 1555 1453 1543 1441 1525 1472 1507 1463 1526 1487 1456 1464 1447 1530 1527 1464 1499 1589 1509 1430 1483 1509 1526 1549 1559 1546 1629 1483 1527 1606 1600 1571 1607 1611 1618 1649 1669 1742 1755 1872 1914 1942 1858 1821 1811 1692 1683 1649 1565 1659 1528 1517 1535 1551 1552 1594 1585 1603 1592 1619 1583 1623 1664 1711 1706 1734 1618 1607 1645 1546 1543 1540 1501 1554 1534 1430 1480 1525 1417 1489 1521 1513 1512 1442 1416 1415 1467 1442 1460 1498 1491 1532 1455 1431 1487 1442 1537 1426 1445 1420 1432 1465 1455 1467 1477 1376 1516 1468 1479 1424 1440 1412 1426 1465 1496 1467 1548 1506 1470 1503 1429 1450 1491 1485 1448 1519 1468 1554 1403 1500 1510 1475 1456 1479 1503 1467 1511 1528 1507 1499 1485 1512 1529 1521 1557 1471 1525 1534 1558 1565 1503 1576 1582 1706 1698 1685 1752 1766 1898 1968 2059 2129 2313 2354 2505 2505 2326 2229 2227 2023 1991 1973 1812 1758 1756 1716 1694 1702 1681 1667 1756 1735 1786 1786 1908 1975 2109 2037 1975 1967 1886 1812 1834 1765 1686 1627 1609 1594 1653 1622 1553 1519 1513 1538 1602 1590 1516 1595 1646 1547 1610 1504 1548 1538 1574 1532 1604 1530 1543 1583 1513 1589 1483 1554 1500 1465 1585 1542 1489 1536 1583 1472 1526 1485 1594 1529 1533 1577 1489 1517 1538 1541 1513 1487 1487 1552 1547 1577 1550 1549 1603 1575 1566 1563 1534 1504 1618 1577 1546 1551 1597 1537 1545 1582 1557 1601 1570 1590 1563 1619 1671 1686 1653 1770 1788 1727 1771 1769 1988 1938 2173 2314 2421 2649 2873 3069 3372 3532 3555 3499 3366 3154 2890 2629 2449 2279 2275 2046 2056 1920 1922 1953 1936 1946 2034 2032 2161 2259 2344 2533 2558 2497 2498 2373 2357 2236 2109 2057 1921 1871 1822 1808 1747 1630 1735 1639 1592 1659 1623 1533 1554 1526 1660 1602 1556 1548 1534 1627 1595 1750 1586 1609 1554 1572 1470 1538 1574 1642 1608 1583 1523 1594 1533 1564 1611 1651 1586 1592 1536 1566 1569 1629 1564 1638 1636 1597 1564 1627 1581 1590 1604 1681 1624 1736 1623 1705 1627 1636 1768 1634 1747 1759 1739 1675 1740 1680 1676 1712 1676 1714 1670 1724 1781 1784 1739 1715 1772 1767 1667 1752 1781 1697 1752 1759 1771 1776 1784 1751 1763 1782 1745 1799 1768 1778 1790 1755 1777 1726 1741 1765 1748 1673 1661 1680 1693 1686 1616 1628 1648 1721 1686 1648 1654 1676 1695 1654 1656 1672 1698 1611 1622 1642 1633 1679 1649 1592 1566 1629 1576 1632 1621 1551 1594 1668 1580 1603 1652 1562 1693 1606 1574 1586 1564 1638 1563 1582 1590 1594 1608 1605 1545 1600 1642 1634 1593 1535 1631 1560 1586 1587 1620 1575 1593 1642 1565 1591 1556 1595 1543 1657 1607 1620 1736 1663 1597 1655 1635 1738 1612 1617 1673 1665 1592 1632 1689 1602 1711 1672 1633 1741 1630 1701 1695 1711 1750 1695 1748 1759 1829 1864 1846 1895 1848 1943 2026 2058 2139 2281 2293 2547 2711 2804 2934 3072 3127 2985 2847 2670 2450 2344 2206 2105 2079 1970 1955 1867 1909 1994 1869 1873 1910 2007 1972 2068 2153 2189 2284 2281 2384 2288 2178 2026 1967 1944 1857 1867 1797 1744 1722 1586 1633 1648 1659 1558 1648 1600 1592 1490 1538 1588 1566 1526 1552 1495 1544 1538 1564 1582 1445 1495 1513 1472 1560 1524 1521 1535 1479 1509 1512 1507 1461 1466 1458 1496 1490 1512 1519 1508 1466 1486 1494 1449 1465 1448 1467 1521 1477 1498 1434 1515 1475 1465 1464 1501 1518 1452 1509 1505 1539 1498 1404 1505 1498 1540 1511 1487 1461 1428 1457 1523 1493 1465 1443 1537 1536 1491 1568 1554 1544 1574 1674 1662 1683 1659 1802 1703 1713 1759 1772 1666 1706 1575 1568 1628 1605 1483 1523 1543 1605 1494 1492 1514 1582 1522 1586 1542 1545 1557 1587 1652 1637 1624 1606 1677 1623 1592 1598 1520 1509 1558 1524 1535 1551 1521 1532 1429 1527 1494 1602 1498 1496 1490 1599 1505 1497 1570 1487 1518 1540 1566 1637 1606 1570 1522 1541 1524 1599 1609 1646 1512 1617 1604 1549 1678 1622 1545 1649 1586 1608 1505 1532 1614 1619 1682 1590 1659 1616 1677 1627 1596 1671 1637 1715 1711 1622 1731 1666 1695 1813 1706 1674 1685 1724 1752 1682 1667 1682 1669 1731 1666 1715 1731 1713 1737 1677 1653 1726 1696 1730 1789 1830 1684 1778 1780 1904 1868 1963 1938 1987 1943 1929 1879 1841 1780 1737 1780 1740 1718 1634 1703 1737 1806 1690 1693 1760 1591 1654 1715 1740 1643 1762 1822 1751 1857 1877 1801 1736 1806 1795 1757 1644 1736 1646 1705 1595 1708 1626 1616 1656 1685 1729 1639 1731 1705 1618 1653 1698 1658 1608 1691 1579 1709 1639 1685 1656 1633 1694 1678 1629 1607 1538 1669 1689 1730 1645 1616 1616 1670 1565 1635 1643 1603 1634 1650 1621 1584 1638 1594 1670 1621 1587 1613 1617 1621 1622 1617 1643 1546 1588 1612 1587 1586 1552 1561 1614 1598 1594 1670 1599 1595 1646 1723 1694 1573 1618 1677 1649 1622 1675 1713 1672 1813 1870 1860 1871 1975 2127 2159 2216 2267 2394 2273 2247 2166 2232 1988 1992 1901 1799 1864 1844 1792 1789 1714 1738 1702 1715 1729 1770 1762 1768 1844 1800 1871 1918 1974 1963 1968 1929 1879 1822 1799 1791 1795 1697 1685 1663 1717 1598 1593 1651 1710 1536 1625 1555 1602 1642 1568 1564 1551 1607 1594 1560 1561 1614 1539 1602 1575 1619 1568 1587 1552 1533 1565 1602 1549 1543 1598 1563 1549 1575 1565 1508 1590 1545 1589 1610 1541 1625 1574 1495 1540 1490 1549 1596 1570 1512 1576 1547 1583 1522 1546 1574 1631 1522 1604 1555 1639 1566 1561 1536 1548 1527 1624 1556 1525 1574 1558 1607 1571 1571 1565 1505 1632 1604 1593 1672 1591 1583 1679 1672 1640 1676 1618 1596 1677 1580 1665 1640 1567 1690 1668 1627 1576 1723 1652 1676 1629 1606 1637 1616 1632 1613 1604 1615 1622 1630 1676 1675 1590 1617 1686 1646 1665 1618 1638 1554 1695 1606 1616 1614 1592 1569 1534 1622 1652 1546 1574 1599 1596 1668 1603 1620 1561 1591 1549 1518 1534 1583 1615 1583 1630 1605 1574 1525 1522 1541 1640 1518 1582 1621 1600 1540 1528 1533 1602 1510 1569 1516 1599 1532 1543 1478 1594 1542 1562 1549 1520 1570 1523 1594 1559 1604 1481 1460 1534 1453 1526 1478 1521 1497 1570 1576 1541 1522 1533 1545 1515 1506 1571 1590 1565 1665 1607 1555 1679 1720 1717 1819 1801 1894 2058 2003 2188 2041 2161 2122 2054 2013 1912 1865 1811 1773 1789 1658 1681 1664 1662 1583 1643 1567 1647 1570 1595 1648 1624 1653 1773 1774 1729 1864 1840 1842 1820 1760 1815 1764 1644 1681 1566 1613 1660 1579 1625 1549 1553 1568 1553 1528 1594 1502 1560 1552 1545 1640 1571 1518 1417 1584 1553 1564 1569 1574 1516 1515 1568 1571 1578 1462 1511 1500 1550 1461 1521 1455 1482 1417 1511 1487 1515 1508 1546 1569 1521 1470 1554 1492 1512 1493 1504 1619 1534 1500 1478 1479 1536 1490 1489 1547 1508 1517 1510 1468 1542 1487 1505 1566 1467 1433 1514 1511 1455 1495 1509 1475 1521 1519 1484 1476 1538 1557 1504 1563 1582 1509 1626 1483 1519 1516 1537 1492 1577 1556 1610 1532 1509 1583 1505 1447 1561 1583 1507 1518 1542 1544 1557 1523 1483 1510 1621 1528 1506 1453 1535 1568 1599 1547 1555 1555 1521 1499 1485 1581 1504 1444 1537 1509 1580 1588 1469 1576 1542 1574 1582 1567 1575 1637 1583 1475 1627 1569 1558 1596 1590 1626 1602 1587 1563 1626 1636 1597 1591 1657 1626 1554 1632 1525 1597 1612 1550 1664 1587 1675 1588 1619 1578 1594 1579 1568 1564 1580 1620 1619 1660 1657 1587 1611 1647 1604 1605 1658 1660 1611 1567 1626 1647 1604 1582 1623 1649 1691 1569 1700 1734 1696 1671 1752 1666 1661 1771 1772 1729 1798 1775 1903 2058 2022 2133 2170 2244 2120 2137 2150 2101 1917 1894 1841 1901 1792 1667 1813 1818 1676 1643 1695 1690 1737 1722 1740 1757 1717 1731 1720 1779 1869 1837 1809 1942 1880 1941 1981 1897 1857 1752 1797 1634 1796 1695 1691 1669 1639 1645 1642 1594 1667 1672 1655 1647 1627 1681 1684 1646 1617 1655 1574 1678 1673 1643 1594 1610 1608 1696 1659 1742 1642 1644 1664 1712 1636 1694 1592 1675 1757 1558 1719 1728 1717 1667 1763 1601 1669 1693 1705 1680 1650 1689 1804 1711 1711 1644 1739 1660 1784 1796 1776 1754 1870 1779 1762 1743 1762 1693 1778 1749 1770 1863 1797 1839 1796 1917 1884 2003 1996 2058 2059 2168 2303 2389 2534 2637 2773 2874 2990 2920 2713 2668 2559 2368 2344 2255 2133 2037 2042 1958 1947 1869 1925 1907 1784 1802 1847 1904 1964 1893 1958 1974 2008 2081 2092 2155 2182 2235 2178 2173 2173 2131 1997 2006 1890 1951 1795 1785 1737 1697 1685 1641 1616 1643 1637 1580 1679 1621 1612 1558 1564 1626 1575 1605 1503 1539 1587 1652 1590 1540 1541 1536 1613 1601 1521 1561 1560 1550 1504 1495 1462 1501 1556 1582 1519 1496 1480 1514 1532 1506 1528 1467 1512 1436 1487 1466 1555 1557 1462 1438 1605 1523 1558 1607 1535 1542 1507 1482 1541 1571 1575 1532 1645 1612 1550 1610 1624 1546 1687 1596 1721 1708 1746 1661 1825 1811 1911 1902 2094 2104 2154 2186 2088 2216 2071 1981 1846 1955 1853 1799 1751 1714 1697 1697 1765 1655 1577 1674 1633 1634 1574 1668 1641 1694 1732 1754 1757 1769 1802 1782 1844 1865 1848 1788 1832 1789 1744 1678 1634 1635 1661 1618 1628 1594 1604 1569 1582 1522 1599 1624 1601 1536 1582 1583 1529 1520 1574 1515 1556 1567 1544 1526 1630 1589 1572 1579 1573 1570 1525 1473 1568 1472 1592 1538 1533 1555 1517 1510 1593 1600 1533 1669 1576 1563 1565 1549 1577 1638 1567 1598 1549 1529 1590 1531 1561 1569 1544 1589 1581 1580 1632 1612 1601 1531 1630 1572 1558 1614 1572 1691 1657 1632 1724 1692 1761 1611 1710 1768 1730 1798 1900 1981 1899 1949 2104 1907 1926 2011 2008 1778 1803 1774 1694 1751 1670 1729 1689 1638 1601 1637 1559 1548 1644 1579 1598 1647 1657 1655 1701 1672 1617 1797 1726 1756 1762 1776 1799 1760 1781 1737 1758 1707 1588 1670 1619 1569 1594 1636 1591 1590 1611 1530 1575 1613 1499 1542 1568 1581 1498 1591 1555 1511 1538 1581 1574 1530 1601 1500 1566 1596 1614 1506 1489 1591 1488 1615 1535 1513 1581 1602 1525 1580 1625 1564 1652 1559 1548 1597 1546 1569 1563</counts>
			</dataPoints>
		</scan>
	</xrdMeasurement>
</xrdMeasurements>