File: dataset/precursor_mixture/MnCO3_Fe3O4_Ga2O3_Bi2O3-alpha.12-min.xrdml
<?xml version="1.0"?>
<xrdMeasurements xmlns="http://www.xrdml.com/XRDMeasurement/2.2" xmlns:xsi="http://www.w3.org/2001/XMLSchema-instance" xsi:schemaLocation="http://www.xrdml.com/XRDMeasurement/2.2 http://www.xrdml.com/XRDMeasurement/2.2/XRDMeasurement.xsd" status="Completed" recordIdentifier="{329C06FD-B786-42C8-9A32-FAA6C2F875D7}">
	<comment>
		<entry/>
	</comment>
	<sample type="To be analyzed">
		<id>dara-41-2</id>
		<name></name>
		<preparedBy></preparedBy>
	</sample>
	<xrdMeasurement measurementType="Scan" status="Completed" sampleMode="Reflection">
		<usedWavelength intended="K-Alpha 1">
			<kAlpha1 unit="Angstrom">1.5405980</kAlpha1>
			<kAlpha2 unit="Angstrom">1.5444260</kAlpha2>
			<kBeta unit="Angstrom">1.3922500</kBeta>
			<ratioKAlpha2KAlpha1>0.5000</ratioKAlpha2KAlpha1>
		</usedWavelength>
		<incidentBeamPath>
			<radius unit="mm">145.00</radius>
			<xRayTube id="1010048" name="Empyrean Cu LFF HR (9430 033 7310x) DK430614">
				<tension unit="kV">40.0</tension>
				<current unit="mA">15.0</current>
				<anodeMaterial>Cu</anodeMaterial>
				<focus type="Line">
					<length unit="mm">12.0</length>
					<width unit="mm">0.4</width>
					<takeOffAngle unit="deg">6.0</takeOffAngle>
				</focus>
			</xRayTube>
			<filter id="20010004" name="Beta-filter Nickel">
				<material>Ni</material>
				<thickness unit="mm">0.020</thickness>
			</filter>
			<sollerSlit id="21010002" name="Soller slits 0.04 rad.">
				<opening unit="rad">0.0400</opening>
			</sollerSlit>
			<mask id="22031000" name="Fixed mask 13 mm">
				<width unit="mm">9.00</width>
			</mask>
			<divergenceSlit id="22120001" name="Divergence slit 1°" xsi:type="fixedDivergenceSlitType">
				<distanceToSample unit="mm">50.00</distanceToSample>
				<height unit="mm">1.52</height>
			</divergenceSlit>
		</incidentBeamPath>
		<beamKnife id="29030100" name="Beam knife low"/>
		<sampleMovement xsi:type="spinningSampleMovementType">
			<spinnerRevolutionTime unit="seconds">1.0</spinnerRevolutionTime>
		</sampleMovement>
		<diffractedBeamPath>
			<radius unit="mm">145.00</radius>
			<antiScatterSlit id="22090040" name="AS slit 9 mm" xsi:type="fixedAntiScatterSlitType">
				<height unit="mm">9.00</height>
			</antiScatterSlit>
			<sollerSlit id="21020003" name="Large Soller slits 0.04 rad.">
				<opening unit="rad">0.0400</opening>
			</sollerSlit>
			<filter id="20030001" name="Large beta-filter Nickel">
				<material>Ni</material>
				<thickness unit="mm">0.020</thickness>
			</filter>
			<detector id="7010019" name="PIXcel1D-Medipix3 detector" xsi:type="rtmsDetectorType">
				<phd unit="keV">
					<lowerLevel>4.0</lowerLevel>
					<upperLevel>11.3</upperLevel>
				</phd>
				<mode>Scanning</mode>
				<activeLength unit="deg">5.020</activeLength>
			</detector>
		</diffractedBeamPath>
		<scan appendNumber="0" mode="Continuous" scanAxis="Gonio" status="Completed">
			<header>
				<startTimeStamp>2024-02-18T15:23:59-08:00</startTimeStamp>
				<endTimeStamp>2024-02-18T15:36:27-08:00</endTimeStamp>
				<author>
					<name>AutomatedUser</name>
				</author>
				<source>
					<applicationSoftware version="1.4b (28)">PANalytical Aeris Instrument Suite</applicationSoftware>
					<instrumentControlSoftware version="2.0.0 20210224">AERIS</instrumentControlSoftware>
					<instrumentID>950485</instrumentID>
				</source>
			</header>
			<dataPoints>
				<positions axis="2Theta" unit="deg">
					<startPosition>9.99043322</startPosition>
					<endPosition>100.09495370</endPosition>
				</positions>
				<positions axis="Omega" unit="deg">
					<startPosition>4.99521661</startPosition>
					<endPosition>50.04747685</endPosition>
				</positions>
				<commonCountingTime unit="seconds">18.249</commonCountingTime>
				<counts unit="counts">5284 5244 5247 5275 5250 5208 5325 5072 5321 5258 5254 5275 5296 5356 5284 5345 5364 5263 5322 5294 5244 5245 5267 5263 5207 5258 5282 5359 5330 5157 5243 5182 5165 5168 5141 5159 5243 5200 5262 5238 5276 5162 5348 5310 5191 5233 5306 5145 5281 5070 5103 5164 5093 5165 5060 5141 5142 5246 5173 5142 5082 5148 5058 5222 5320 5305 5229 5015 5204 5212 5060 5120 5163 5129 5146 5080 5235 5129 5151 5198 4990 5191 5115 5064 5138 5196 5107 5149 5010 5047 5156 5168 5157 5222 5127 5007 5039 5073 5158 5066 5072 4954 5064 5199 5238 4961 4989 5013 4997 5063 5126 5010 5031 5118 5079 5052 5151 5008 5006 5000 5087 5091 5026 5043 5111 4914 5074 4974 5079 5023 5112 5126 4814 5030 4941 4984 4993 5111 4993 4982 4954 5047 5048 4884 5016 5062 4994 5099 5070 5101 5100 4971 4994 5006 4960 5011 4986 5044 4955 5065 5025 4995 4918 4982 4951 4989 4948 5028 4991 4907 4940 5023 4995 4905 5060 5050 4937 4991 4871 4989 4864 4936 4883 4994 4946 4950 4912 4834 4912 4945 5017 5096 4967 4962 4948 5035 5022 4930 4946 5062 4793 4828 4979 4965 5041 4954 4918 4877 4883 5004 4905 4851 4971 4762 5012 4850 4906 4966 4831 5040 4961 4976 4825 4978 4934 4911 4777 5143 4919 4956 4872 4945 4845 4935 4915 5008 4873 4853 4886 4830 4811 4991 4941 4892 4901 4847 4793 4951 4884 4963 4875 4853 4900 4964 4910 4834 4803 4934 4857 4776 4909 4851 4784 4829 4717 4810 4858 4929 4956 4899 4828 4815 4879 4799 4878 4809 4857 4899 4895 4797 4834 4760 4870 4888 4790 4983 4811 4910 4633 4678 4781 4837 4883 4795 4860 5009 4872 4943 4857 4882 4779 4847 4823 4885 4993 4831 4805 4865 4749 4699 4833 4861 4836 4876 4852 4803 4783 4891 4860 4793 4796 4877 4824 4828 4866 4755 4757 4782 4830 4819 4813 4904 4725 4709 4880 4826 4790 4740 4818 4684 4849 4880 4874 4727 4873 4951 4736 4818 4690 4703 4812 4774 4891 4794 4806 4789 4725 4867 4677 4861 4729 4863 4766 4938 4833 4811 4862 4846 4862 4809 4773 4750 4821 4876 4843 4701 4876 4965 4737 4920 4725 4857 4941 4842 4885 4825 4749 4768 4773 4768 4764 4933 4789 4866 4861 4714 4749 4844 4955 4915 4839 4817 4879 4815 4812 4849 4795 4740 4775 4770 4953 4756 4820 4910 4882 4703 4808 4796 4861 4839 4804 4913 4836 4863 4757 4682 4775 4702 4842 4809 4942 4852 4977 4665 4911 4806 4866 4725 4863 4810 4840 4780 4776 4890 4734 4839 4831 4922 4818 4888 4685 4770 4793 4734 4821 4790 4876 4855 4994 4799 4864 4790 4699 4865 4817 4821 4927 4871 4793 4810 4840 4816 4804 4778 4865 4918 4786 4900 4818 4730 4910 4825 4945 4729 4759 4883 4852 4756 4807 4833 4838 4706 4889 4783 4917 4707 4840 4754 4840 4990 4815 4792 4774 4831 4811 4860 4817 4808 4996 4850 4854 4847 4815 4875 4918 4827 4891 4812 4863 4757 4816 4949 4818 4781 4752 4916 4802 5056 4757 4954 4827 4949 4861 4983 4868 4806 4854 4837 4825 4881 4753 4795 4880 4868 4796 4922 4775 4878 4916 4921 4873 4846 4837 4819 4710 4801 4863 4862 4802 4791 4777 4893 4782 4672 4924 4822 4873 4738 4872 4825 4681 4889 4989 4857 4832 4763 4914 4913 4884 4926 4823 4958 4900 4846 4764 4873 4777 4719 4729 4914 4755 4839 4774 4890 4718 4755 4771 4868 4999 4823 4762 4806 4851 4819 4775 4839 4781 5003 4800 4677 4921 4875 4866 4945 4815 4762 4845 4932 4819 4839 4852 4810 4883 5001 4927 4980 5026 5006 4819 4979 5078 5079 5061 4890 5076 4910 4964 4789 4910 4948 4900 4798 4869 4767 4878 4713 4693 4759 4839 4864 4905 4832 5044 4832 4667 4787 4731 4797 4732 4779 4778 4808 4669 4787 4771 4794 4672 4737 4808 4709 4725 4677 4906 4760 4793 4923 4578 4701 4828 4782 4873 4873 4644 4893 4805 4717 4880 4800 4787 4696 4808 4774 4900 4949 4757 4744 4805 4773 4694 4733 4786 4684 4651 4836 4778 4771 4700 4799 4741 4759 4789 4742 4867 4731 4661 4756 4669 4747 4843 4751 4777 4731 4644 4743 4745 4818 4736 4749 4719 4630 4827 4825 4769 4726 4742 4796 4792 4898 4692 4687 4663 4775 4885 4840 4808 4745 4877 4780 4941 4847 4854 4891 4945 4898 5029 5004 4948 5084 5005 5067 5053 5006 5049 5219 5225 5270 5306 5359 5260 5349 5364 5288 5200 5276 5133 5107 5103 5106 4867 4931 4901 5001 5005 4925 4852 4795 4865 4807 4970 4781 4840 4977 4854 4909 4934 4788 4927 4878 4866 5031 4982 5136 4947 5178 5046 5057 5173 5278 5285 5232 5465 5567 5617 5512 5686 5837 5880 6103 6119 6131 6221 6442 6430 6565 6734 6856 7011 6968 6689 6685 6637 6657 6593 6353 6161 6025 5867 5778 5517 5510 5389 5354 5402 5253 5094 5155 5266 4980 4965 4855 4885 4904 4902 4910 4873 4957 4857 4749 4667 4796 4809 4882 4755 4748 4837 4773 4808 4835 4661 4612 4680 4767 4769 4888 4863 4730 4704 4702 4713 4687 4738 4707 4742 4726 4794 4857 4723 4751 4729 4709 4649 4901 4865 5095 4909 4964 5011 4974 5185 5066 5166 5214 5310 5119 5169 5173 4954 4953 4829 4817 4620 4896 4655 4681 4485 4548 4635 4588 4581 4636 4661 4553 4646 4642 4562 4694 4562 4623 4688 4595 4597 4703 4629 4697 4559 4543 4600 4614 4618 4517 4582 4538 4549 4644 4562 4639 4534 4547 4665 4547 4660 4600 4608 4686 4688 4572 4514 4669 4701 4551 4561 4561 4596 4604 4584 4636 4600 4464 4547 4500 4473 4613 4548 4532 4630 4678 4522 4540 4568 4495 4524 4619 4507 4491 4564 4439 4615 4562 4548 4465 4471 4530 4640 4587 4512 4558 4566 4513 4619 4513 4515 4567 4717 4546 4469 4625 4567 4639 4528 4633 4554 4543 4628 4615 4622 4404 4610 4508 4581 4522 4554 4635 4619 4477 4658 4449 4591 4666 4568 4553 4542 4568 4575 4566 4520 4473 4505 4547 4489 4505 4461 4479 4667 4639 4524 4409 4572 4513 4688 4502 4523 4426 4579 4513 4630 4600 4532 4538 4620 4414 4607 4613 4608 4598 4612 4585 4513 4542 4624 4644 4599 4717 4671 4663 4673 4861 4796 4777 4778 4865 4900 4888 4963 5025 4956 5049 5083 5199 5150 5214 4910 5163 4921 4903 4940 4715 4686 4641 4537 4489 4409 4570 4429 4591 4565 4494 4516 4414 4541 4524 4550 4630 4435 4528 4523 4544 4536 4616 4455 4560 4425 4505 4723 4565 4495 4370 4567 4521 4493 4438 4440 4459 4524 4562 4429 4517 4484 4562 4517 4494 4437 4376 4448 4423 4551 4374 4495 4609 4437 4412 4489 4505 4617 4487 4430 4462 4595 4486 4406 4463 4529 4393 4320 4425 4522 4367 4378 4472 4417 4502 4476 4413 4646 4566 4441 4412 4478 4410 4461 4561 4458 4414 4407 4410 4445 4571 4367 4432 4563 4511 4448 4418 4476 4498 4615 4447 4358 4432 4321 4446 4460 4411 4450 4515 4507 4470 4503 4486 4498 4431 4488 4430 4392 4479 4442 4484 4379 4312 4415 4505 4313 4362 4525 4431 4507 4326 4428 4467 4466 4422 4621 4478 4448 4471 4414 4492 4509 4494 4465 4497 4464 4432 4363 4380 4393 4549 4321 4361 4495 4404 4489 4402 4518 4468 4493 4396 4353 4431 4482 4347 4459 4492 4500 4445 4458 4422 4351 4511 4552 4446 4422 4432 4538 4464 4467 4491 4617 4492 4626 4489 4550 4512 4633 4576 4570 4589 4520 4644 4612 4712 4670 4642 4805 4614 4698 4634 4950 4822 4876 4931 5107 5079 5024 5324 5283 5363 5479 5370 5448 5590 5769 5842 5872 5682 5775 5785 5759 5822 5608 5450 5284 5167 5167 5151 5059 4934 4920 4735 4700 4824 4791 4917 4952 4852 4870 4885 4968 4840 5018 5155 5194 5239 5355 5257 5380 5368 5548 5549 5409 5274 5129 4996 5082 4905 4766 4648 4645 4568 4513 4514 4565 4598 4525 4563 4477 4484 4450 4513 4458 4433 4496 4267 4302 4491 4403 4408 4385 4404 4405 4339 4380 4389 4503 4447 4338 4233 4439 4300 4319 4359 4251 4394 4412 4393 4374 4429 4465 4408 4421 4371 4413 4419 4304 4423 4302 4369 4414 4440 4466 4369 4458 4370 4511 4620 4470 4595 4599 4487 4329 4440 4418 4393 4370 4419 4473 4460 4519 4390 4329 4432 4549 4484 4416 4479 4545 4615 4424 4613 4598 4577 4663 4735 4711 4915 4875 5164 5189 5391 5452 5754 5989 6126 6368 6525 6762 7006 6839 6674 6603 6324 5961 5787 5648 5421 5120 4832 4789 4539 4555 4439 4428 4296 4445 4430 4393 4420 4276 4399 4346 4370 4466 4411 4400 4324 4430 4363 4425 4415 4384 4382 4345 4310 4311 4361 4319 4270 4316 4205 4386 4253 4283 4434 4313 4243 4378 4275 4448 4378 4279 4269 4389 4316 4389 4372 4403 4387 4365 4546 4411 4503 4415 4474 4450 4478 4392 4438 4435 4451 4456 4435 4502 4540 4506 4522 4509 4385 4524 4633 4599 4660 4669 4611 4665 4827 4679 4710 4872 4897 4927 5202 5231 5487 5664 5883 6240 6656 6862 7291 7564 8279 8636 8885 9277 9462 9387 8852 8597 7885 7540 7208 6838 6493 6091 5750 5516 5307 4995 5119 5064 4915 4921 5113 5200 5211 5344 5470 5570 5767 5846 6102 6355 6869 7249 7959 8502 9197 10064 11277 12767 14086 15478 17276 18887 21250 23070 24779 25720 25504 24116 21786 19478 17568 16550 14819 13128 11542 9664 8158 6971 6195 5776 5513 5261 5098 5023 4954 4864 4844 4792 4895 4692 4781 4626 4701 4652 4563 4518 4644 4660 4718 4573 4706 4754 4689 4670 4685 4694 4743 4816 4838 5018 4898 5102 5154 5376 5535 5751 6018 6282 6742 7000 7323 7529 7365 7363 7064 6642 6501 6234 6027 5835 5578 5292 5082 4814 4733 4521 4550 4444 4532 4415 4356 4421 4370 4455 4306 4339 4492 4352 4294 4291 4333 4313 4383 4296 4478 4422 4341 4303 4360 4496 4341 4303 4280 4358 4356 4330 4324 4370 4499 4308 4350 4365 4339 4339 4312 4352 4358 4355 4252 4316 4342 4331 4249 4282 4341 4300 4310 4301 4311 4244 4186 4317 4256 4335 4226 4302 4251 4280 4338 4278 4357 4191 4353 4387 4463 4276 4376 4311 4325 4309 4352 4340 4301 4360 4351 4284 4321 4376 4243 4331 4335 4259 4412 4311 4380 4313 4314 4393 4319 4383 4435 4468 4379 4300 4266 4345 4430 4313 4343 4337 4217 4440 4497 4358 4286 4415 4438 4481 4430 4483 4400 4492 4471 4389 4472 4523 4519 4459 4557 4532 4519 4454 4570 4623 4621 4654 4675 4571 4713 4558 4532 4610 4754 4601 4676 4601 4801 4660 4752 4660 4799 4849 4795 4697 4938 4934 4976 5040 4975 4940 4967 5225 5212 5257 5329 5406 5624 5519 5662 5696 5915 6016 6304 6472 6674 6863 7014 7341 7525 7769 8014 8167 8568 8424 8705 8429 8331 8622 8416 8306 8234 7976 7941 8071 7980 7746 7919 8031 8077 8000 8122 8340 8373 8819 9080 9074 9285 9621 10022 10299 10532 10762 10852 11300 11314 11404 11825 11709 11700 11650 11310 11205 11045 10956 10697 10184 10088 9630 9359 9069 8686 8439 8014 8037 7730 7406 7052 7166 6763 6501 6457 6297 6249 6176 6018 5901 5867 5807 5787 5502 5680 5558 5523 5513 5634 5485 5481 5390 5421 5351 5394 5312 5379 5279 5358 5346 5165 5275 5501 5519 5425 5418 5502 5287 5517 5439 5587 5553 5588 5790 5867 5951 6111 6304 6466 6544 6687 6863 7187 7305 7618 7754 8249 8325 8552 8808 8850 9136 8932 9065 8970 8585 8825 8469 8509 8260 8145 7992 7862 7877 7686 7520 7623 7636 7701 7586 7837 7836 7848 8016 8168 8272 8577 8669 8575 8898 9009 8958 9051 9126 9264 9213 9287 8996 9080 8915 8794 8731 8538 8485 8181 7898 7782 7568 7311 7287 7066 6948 6906 6622 6492 6416 6245 6224 5979 5929 5826 5734 5561 5431 5426 5474 5328 5358 5318 5209 5192 5147 5113 4972 4996 5013 4810 4895 4834 4747 4912 4875 4789 4767 4848 4861 4674 4568 4612 4587 4658 4544 4636 4763 4673 4836 4748 4666 4662 4660 4772 4839 4896 4879 4995 5114 5104 5247 5288 5201 5280 5194 5113 4899 4974 4821 5016 4858 4912 4633 4568 4646 4490 4524 4505 4425 4477 4503 4537 4406 4344 4552 4488 4460 4601 4412 4513 4698 4597 4647 4611 4694 4745 4930 4876 5015 5135 5204 5502 5679 5945 6291 6777 7192 7764 8433 8821 9527 10104 10112 10546 9936 9641 9048 8857 8750 8714 8637 8907 8637 8809 8992 9022 9406 9668 10421 10686 11080 11018 10952 10409 9721 9022 8517 8197 8008 7632 7312 6600 6237 5799 5440 4897 4897 4881 4712 4797 4595 4634 4707 4685 4556 4566 4657 4462 4467 4457 4457 4481 4644 4460 4401 4435 4307 4459 4329 4327 4238 4335 4479 4432 4299 4415 4382 4165 4279 4402 4173 4323 4262 4230 4326 4297 4353 4375 4528 4588 4531 4716 4881 4964 5188 5067 5066 4834 4957 4991 4762 4676 4562 4680 4649 4652 4564 4306 4391 4502 4331 4301 4276 4249 4294 4129 4110 4264 4291 4282 4169 4225 4264 4135 4163 4225 4223 4156 4484 4262 4169 4176 4220 4251 4275 4195 4260 4176 4158 4117 4195 4280 4207 4173 4165 4168 4250 4277 4200 4328 4260 4318 4158 4353 4185 4253 4252 4237 4269 4260 4221 4327 4294 4280 4141 4217 4362 4213 4189 4349 4218 4361 4407 4275 4478 4509 4280 4554 4451 4401 4593 4525 4761 4796 4819 4885 4875 5104 5255 5393 5710 5822 6145 6374 6646 7118 7030 7233 7062 6850 6811 6564 6480 6430 6555 6472 6410 6314 6254 6132 6004 5983 6053 6113 6165 6239 6425 6488 6669 6983 7220 7672 8145 8568 9114 9888 10524 11266 11998 12808 13229 13365 13208 12992 12837 12820 12462 11778 11558 10965 10576 9770 9452 8601 8022 7573 7243 6795 6528 6208 5921 5829 5662 5372 5268 5093 5151 4915 5033 4851 4767 4801 4709 4698 4898 4582 4559 4589 4678 4676 4776 4875 4910 4926 5118 5110 5023 4931 4916 4850 4789 4629 4663 4639 4645 4507 4613 4547 4325 4331 4348 4267 4386 4214 4238 4264 4277 4195 4192 4188 4184 4306 4175 4100 4245 4133 4200 4179 4124 4244 4082 4165 4050 4040 4111 4160 4107 4162 4182 4203 4154 4223 4120 4041 4112 4029 4181 4096 4086 4211 4214 4085 4074 4070 4211 4166 4123 4048 3991 4196 4046 4071 4193 4157 4153 4144 4115 4122 4194 4087 4126 4121 4031 4020 4237 4173 4091 4284 4211 4242 4126 4295 4320 4340 4373 4435 4598 4624 4725 4845 5029 5299 5373 5477 5434 5249 5312 5308 4986 5241 5138 5125 5138 5155 4956 5041 4730 4795 4689 4652 4756 4714 4641 4765 4663 4494 4632 4602 4514 4561 4657 4750 4789 4794 4828 4896 5047 4895 4933 5123 5201 5281 5242 5245 5357 5310 5304 5233 5224 5277 5333 5227 5413 5520 5410 5518 5647 5796 5849 6051 6074 6115 6281 6067 5902 5666 5557 5336 5209 5239 5178 5160 5066 4782 4710 4513 4510 4385 4325 4255 4265 4263 4334 4306 4243 4167 4391 4289 4224 4246 4272 4241 4178 4273 4153 4208 4224 4149 4178 4313 4254 4265 4162 4296 4219 4223 4274 4296 4350 4325 4333 4372 4350 4400 4290 4338 4548 4421 4641 4594 4573 4603 4747 4849 4752 4797 4875 5059 4914 5249 5137 5128 5100 5201 5153 5097 5277 5106 5145 5012 5156 4940 4891 4997 4972 4806 4806 4754 4700 4604 4685 4467 4479 4468 4256 4352 4310 4396 4190 4252 4254 4234 4143 4175 4200 4061 4253 4091 4155 4042 4119 4096 4036 3965 4035 4050 4121 4056 4107 4116 4125 4004 4060 3991 3995 4121 4056 3922 4018 4081 3987 3928 3998 4070 4066 3979 3928 4001 3914 3883 3996 3999 3897 3987 3937 4041 3985 3957 4006 3989 4036 4074 4000 3928 3984 3945 3969 3955 4009 4022 3918 3930 3916 3964 3955 4008 3933 3841 3776 3941 3963 3906 3882 3954 3935 3898 3796 3991 4030 3845 3810 3932 4014 3945 3932 3871 3845 3892 3979 3854 3939 3887 3903 3981 3869 3876 3995 3973 3908 4006 4051 3870 3810 3919 3928 3945 3922 3830 4078 3932 3974 3941 3950 4018 3943 4000 3907 4124 4133 4167 4135 4193 4262 4439 4422 4733 4737 4695 4796 4746 4557 4479 4451 4401 4241 4241 4236 4349 4267 4207 4218 4093 3999 4001 3967 4045 3884 4006 3923 3951 3869 3900 4006 3889 3941 3859 3934 3891 3914 3895 4001 3995 3910 3785 3874 3891 3880 3817 3828 3977 3990 3919 3927 3966 3923 3972 4035 3977 3989 4099 3984 4003 3899 4029 4037 4025 3937 3981 3880 3887 3957 3936 3966 4060 3963 3892 4103 3895 3873 3883 3934 3881 3991 3952 4015 4108 3950 3973 3925 3922 3951 3967 3958 3992 3959 3897 3918 3965 3978 3808 3947 4074 3853 4006 4041 4000 4118 4036 4100 3952 3961 4153 4139 4239 4258 4319 4377 4387 4398 4483 4469 4666 4686 4764 4697 4761 4715 4822 4788 4787 4842 4892 4860 5079 4997 5110 5100 5137 4981 4945 4916 4871 4592 4468 4548 4433 4542 4508 4345 4256 4237 4136 4181 4128 4080 3990 4048 3990 4055 3947 4091 3884 4017 4007 3906 4061 4057 3929 3987 4038 4094 4154 4156 4392 4347 4398 4433 4511 4441 4348 4414 4371 4255 4309 4254 4093 4265 4352 4094 4188 4239 3995 3982 4151 4024 3916 3806 4002 3967 3957 3909 3882 3866 3944 3999 3986 3983 3983 4136 3968 4045 4142 4217 4287 4322 4583 4686 4760 4930 4945 4852 4849 4843 4519 4491 4404 4443 4272 4400 4429 4469 4370 4439 4295 4213 4087 4011 3990 3942 3935 4014 4133 3986 3952 3934 4032 3947 3866 3938 3963 3906 3990 3996 3984 3919 3904 3967 4071 4082 4081 4113 4163 4057 4065 4136 4123 4139 4231 4219 4300 4370 4424 4294 4565 4472 4636 4865 5030 4998 5137 5314 5378 5589 5366 5459 5457 5470 5491 5527 5499 5213 5337 5208 5080 5061 4857 4969 4787 4595 4677 4366 4463 4433 4248 4215 4215 4186 4175 4078 4050 4040 4016 4077 4093 3973 3965 3964 3948 4089 3946 4007 3840 3901 3910 3864 3978 3853 3941 3765 3939 3822 3995 3903 3932 3916 3956 3860 4033 3906 3992 3824 3897 3862 3816 3900 3838 3843 3908 3964 3792 3863 3924 3718 4005 3803 3819 3957 3912 3864 3794 3864 3821 3927 3791 3908 3878 3939 3948 3796 3855 3855 3831 3877 3902 3800 3892 3820 3920 3822 3904 3809 3861 3805 3809 3858 3867 3961 3737 3917 3876 3895 3935 4006 3936 3972 4009 4039 4170 4065 4132 4235 4158 4115 4111 4097 4047 4060 4018 4119 4093 4010 4033 3964 4142 3968 4085 4012 4107 3971 3948 3956 3981 4032 3887 4120 4066 4038 4137 4107 3935 4191 4043 4169 4117 4004 4108 4086 4086 4173 4017 4121 4023 3959 4121 4058 4049 4064 4067 4112 4144 4163 4137 4159 4135 4255 4115 4413 4304 4335 4428 4461 4455 4576 4470 4706 4662 4826 4956 4838 4950 5088 5165 5307 5236 5319 5173 5259 5026 4882 4861 4864 4705 4810 4916 4635 4661 4505 4404 4565 4333 4344 4221 4228 4084 4134 4065 4063 3991 4076 4075 4061 4175 4002 4162 3914 4142 4053 4055 4028 4019 4065 4007 3939 4054 4011 4131 4078 4048 4046 3928 4148 4096 4113 4030 4055 4092 4124 4060 4117 3993 3986 4086 4040 4045 4146 3981 4097 4194 3945 4293 4127 4061 4182 4262 4140 4168 4003 4134 4101 4295 4213 4019 4027 4052 4032 4026 4160 4064 4121 4102 4005 3991 4047 4051 4116 4157 4163 4124 4107 4064 4177 4365 4430 4614 4749 4994 5092 5420 5831 6326 6977 7283 7887 8043 8426 8122 8046 7441 6958 6379 6261 6339 6164 6219 6289 6403 6304 5831 5533 5279 4954 4635 4485 4384 4256 4136 4128 4080 4002 3996 3994 4006 3882 3991 3929 3861 3994 3926 3829 3993 3832 3903 3861 3862 3986 3929 3898 3953 3909 3864 3788 3957 3840 3793 4080 3925 3880 3905 3905 3834 3923 3802 4002 3782 3895 3886 3897 4016 3873 3979 3896 3840 3824 3867 3777 3891 4002 3826 4034 3886 3974 3911 3867 3906 3916 3905 3815 3847 3903 3966 3859 3910 3990 3965 3812 3950 3802 3773 3962 3878 3980 3957 4014 4073 4044 4042 4198 4204 4122 4170 4137 3925 4069 4087 4199 4186 4189 4302 4450 4343 4369 4477 4327 4279 4068 4118 4053 4075 3962 4084 4105 4028 4146 4030 4057 3893 3972 3890 3982 3925 3892 3838 3828 3805 3896 3977 3755 3911 3803 3864 3912 3915 3880 3870 3864 3854 3800 3787 3856 3914 3979 3927 4002 3931 3940 3957 3980 3874 3852 3764 3898 3765 3914 3980 3927 3946 3835 3924 3961 3903 4071 4072 3998 4112 3980 4148 4093 4256 4256 4419 4649 4658 4761 5031 5024 5284 5183 5256 5009 5033 5035 4774 4684 4936 5079 5150 5300 5505 5636 5735 5945 5968 6002 5977 5854 5728 5472 5200 5083 5231 5066 5149 5102 5201 5144 5087 5061 4880 4702 4646 4696 4359 4402 4357 4289 4191 4266 4128 4122 4153 4163 4048 4067 4064 4002 4098 4024 3985 3879 3970 4068 3939 3999 3840 3838 3829 4038 3963 4015 4014 3903 3968 3875 3926 3930 3901 3876 3900 3871 3914 4022 3844 3916 3913 3880 4057 3991 4036 3988 3990 4166 4213 4130 4186 4257 4288 4403 4605 4608 4867 4972 4974 5005 5141 4869 4864 4781 4872 4807 4646 4926 4846 4795 4914 4745 4767 4702 4605 4616 4434 4396 4364 4362 4312 4213 4253 4153 4293 4237 4111 4105 4178 4103 4138 4082 4168 4131 4042 3986 4039 4018 4308 4222 4146 4440 4340 4377 4680 4648 4788 4644 4421 4461 4377 4312 4223 4216 4122 4247 4301 4326 4487 4346 4344 4114 4184 4104 3984 3912 4022 3953 3833 3930 3929 3961 3751 3968 3761 3817 3982 3917 3861 3870 3977 3936 3989 4000 3990 4008 3951 3923 3945 3964 4030 4003 3949 3977 3919 3939 3957 4131 3895 3968 3976 3949 4056 3938 3940 3942 3997 3931 4005 4032 3873 4078 3966 3957 4092 4074 4085 4110 4099 4073 4072 4023 4208 4088 4111 4095 4180 4254 4172 4141 4136 4163 4267 4199 4223 4199 4196 4060 4228 3990 4105 4180 4154 4112 4061 4167 4060 4108 4121 4018 3943 4184 4113 4105 4089 4011 4252 4134 4089 4089 4124 4044 4068 4178 4154 4120 4194 4264 4341 4393 4305 4531 4407 4419 4417 4284 4475 4305 4330 4543 4537 4554 4660 4679 4595 4842 4805 4782 4802 4710 4701 4857 4770 5012 5026 5114 5140 5156 5422 5405 5643 5607 5583 5731 5753 5746 5747 5766 5647 5471 5055 5014 5021 4987 5016 4928 4961 4987 5058 5022 4997 4968 4962 4899 5015 5218 5259 5266 5223 5051 5006 4839 4614 4529 4423 4531 4578 4443 4477 4494 4581 4499 4637 4390 4333 4395 4263 4109 4222 4127 4015 3988 4121 4090 4027 4137 4123 4208 4292 4454 4655 4775 4923 5092 5510 5792 5844 6278 6501 6361 6074 5687 5305 5117 4763 4731 4817 4766 5006 5037 5226 5150 5007 4887 4775 4545 4369 4089 4162 3956 3958 3990 3954 3968 3927 3852 3985 3913 3797 3945 3834 3818 3918 3875 3874 4009 3813 3944 3897 3946 3876 3966 3956 4015 3993 4207 4193 4267 4422 4514 4726 4820 5088 5083 5516 5516 5482 5602 5272 5175 4780 4757 4640 4551 4527 4615 4608 4651 4687 4727 4651 4470 4486 4292 4106 4071 4092 4103 3996 3972 3969 4009 4032 4130 4066 4230 4129 4261 4372 4187 4437 4180 4291 4340 4426 4307 4376 4423 4383 4434 4504 4319 4366 4378 4208 4090 4139 4149 4167 4202 4114 4182 3974 4002 4170 3948 3935 3959 4077 4008 3828 3990 3842 3819 3888 3969 3868 3951 3907 3782 3913 3917 3890 3844 3846 3935 3879 3830 3901 3799 3937 3755 3805 3920 3765 3873 3802 3829 3944 3804 3794 3869 3812 3849 3810 3782 3825 4068 3866 3737 3913 3867 3931 3897 4048 3902 3947 3903 4024 3896 3986 3804 3896 3761 3875 3953 3887 3862 3833 3833 3905 3789 3849 3858 3945 3798 3784 3850 3810 3853 3956 3912 3795 3821 3979 3981 3962 3944 3814 4004 4029 3923 3954 3924 3949 4015 3910 4072 4051 4200 4196 4276 4292 4581 4900 5103 5430 5895 6233 6444 6488 6322 5655 5573 5095 4860 4876 4780 4692 4694 5003 4999 5097 5193 5153 5057 4740 4499 4337 4203 4092 4041 3939 3927 3865 3939 3951 3921 3833 3922 3882 3871 3782 3837 3935 3825 3844 3694 3798 3743 3874 3810 3818 3854 3974 3795 3918 3957 3929 3838 3872 3880 3937 4101 4087 4192 4360 4653 4704 4864 5006 5047 5122 4904 4880 4682 4570 4580 4389 4396 4417 4335 4356 4368 4506 4490 4494 4322 4255 4125 4183 4044 4108 3988 3798 3967 3966 4035 3992 3965 3923 3912 3849 4059 4070 4159 4375 4421 4407 4654 4718 4951 4860 4991 5125 4938 4617 4457 4330 4166 4241 4307 4161 4157 4277 4332 4342 4268 4280 4294 4313 4097 4065 4052 3998 3872 3828 3802 3839 3731 3812 3880 3829 3852 3914 3794 3849 3818 3842 3877 3856 3862 3781 3872 3830 3840 3843 3847 3846 3930 3889 3838 3877 3989 3980 3995 4064 3964 4019 4081 3874 4062 3888 4030 3878 3972 3906 4004 3951 4021 3978 4054 3983 4072 3942 3963 4060 4027 3897 4124 4054 3965 4227 4142 4202 4285 4430 4451 4594 4700 4754 4809 5028 5085 5304 5180 5324 5307 5229 5313 5456 5470 5433 5324 5347 5387 5348 5360 5372 5225 5198 5081 5113 4877 4942 4826 4791 4819 4780 4638 4658 4405 4574 4363 4361 4305 4214 4255 4107 4188 4206 4092 4087 4129 4093 4160 4207 4048 4004 4062 4087 4130 4068 4137 4187 4110 4091 4181 4203 4076 4184 4256 4124 4201 4132 4275 4136 4102 4348 4164 4187 4317 4222 4114 4149 4228 4315 4490 4349 4449 4487 4646 4712 4854 4790 4886 4816 4820 4856 4769 4765 4861 4977 5034 5070 5025 4895 4891 4915 4792 4695 4724 4638 4653 4560 4467 4512 4537 4474 4459 4334 4336 4346 4208 4242 4093 4126 4137 4085 4069 4153 4106 4151 4157 4271 4278 4465 4480 4548 4921 4862 4989 4980 4813 4628 4685 4480 4441 4381 4334 4277 4263 4301 4328 4390 4487 4497 4399 4305 4129 4357 4248 4330 4125 4262 4266 4251 4252 4288 4327 4363 4109 4135 4184 4077 4017 4122 4030 4084 4069 4130 4232 4106 4256 4222 4172 4157 4126 4074 4089 4162 4222 4061 4063 4284 4196 4255 4375 4396 4475 4460 4536 4750 4743 4964 5047 5200 5317 5489 5713 5617 5645 5643 5566 5424 5343 5326 5229 5181 5203 5134 5106 5263 5066 5181 5216 5121 5197 5071 4872 4827 4601 4602 4572 4563 4487 4556 4367 4314 4459 4253 4239 4278 4235 4081 4175 4145 4171 4133 3938 4141 4107 3999 3950 4008 4000 3928 4007 3955 4047 4039 3975 4005 3886 4008 4022 4016 3896 4051 4004 4103 3965 3875 3983 3999 3857 4018 4165 3997 4070 4115 4161 4091 4121 4221 4195 4262 4325 4284 4207 4406 4403 4490 4353 4371 4488 4289 4403 4434 4539 4445 4245 4371 4421 4339 4342 4408 4409 4443 4224 4368 4284 4134 4273 4376 4266 4236 4177 4165 4164 4157 4167 4119 4077 4083 4162 4104 4130 3992 4153 4051 4032 4195 4076 4054 4036 4217 4219 4013 4193 4076 4150 4114 4055 4101 4154 4176 4054 4003 4029 4136 4188 4165 4086 4181 4119 4194 4112 4071 4094 4011 4065 4146 4058 4058 4012 4178 4059 4036 4093 4010 4180 4125 4172 3961 4120 4058 4183 4195 4110 4222 4219 4261 4224 4364 4202 4230 4156 4169 4277 4257 4172 4158 4217 4208 4133 4105 4225 4182 4059 4128 3953 4005 4101 4041 3995 3961 4037 3988 3979 4065 3963 4061 3983 3944 4030 3921 3868 3913 3980 3938 3885 3891 3950 3922 3984 3863 3957 3898 4064 4096 4215 4238 4418 4554 4677 4798 4864 4713 4631 4635 4349 4281 4121 4121 4064 4167 4175 4187 4183 4072 4243 4325 4246 4207 4220 4202 4171 4130 4130 4135 4171 4199 4338 4254 4582 4572 4651 4515 4514 4379 4388 4205 4081 4124 4023 4065 4003 4092 4084 4031 4151 4250 4217 4212 4229 4057 4099 4041 3991 4019 4028 4025 3936 3935 3886 3874 3944 3884 4076 3992 4052 4072 4073 4108 4183 4157 4142 4331 4497 4599 4615 4702 4596 4746 4562 4587 4597 4924 4924 5238 5193 5408 5498 5885 6302 6247 6403 6384 6432 6303 6420 6520 6356 6424 6325 6270 6379 6436 6431 6398 6372 6335 6294 6093 6079 5999 5803 5793 5576 5732 5762 5460 5421 5253 5146 4996 4844 4792 4765 4663 4765 4720 4650 4485 4619 4411 4406 4343 4219 4165 4237 4169 4219 4187 4231 4185 4132 4074 4033 4122 3976 4028 4014 4032 3877 3987 3840 3922 3809 3986 3766 3936 3838 3936 4005 4010 3882 3952 4035 3999 3930 4071 3930 3993 3937 3964 4010 3886 3908 4007 3898 3955 3956 4103 3978 4009 4039 4013 4165 4111 4108 4222 4124 4252 4373 4441 4504 4439 4529 4520 4396 4270 4282 4304 4259 4308 4229 4291 4255 4369 4470 4376 4475 4501 4320 4401 4231 4376 4261 4210 4114 4268 4129 4114 4297 4205 4235 4155 4210 4198 4180 4205 4243 4331 4241 4146 4391 4086 4380 4285 4199 4353 4335 4206 4242 4429 4297 4312 4228 4240 4374 4264 4265 4190 4242 4167 4266 4337 4252 4206 4217 4372 4198 4384 4358 4314 4334 4290 4299 4209 4296 4332 4216 4235 4311 4311 4347 4305 4327 4418 4337 4448 4424 4514 4507 4429 4424 4594 4343 4598 4661 4595 4600 4578 4620 4705 4613 4673 4642 4822 4725 4737 4748 4669 4731 4629 4472 4570 4646 4522 4655 4457 4492 4251 4439 4331 4421 4423 4370 4285 4287 4237 4209 4200 4223 4184 3983 4135 4085 3948 4065 3955 3946 3942 3871 3986 3982 3929 3963 3900 3952 3920 3898 3966 3843 3869 3857 3876 3853 3962 3934 3892 3903 3867 3882 3855 3907 3967 3910 3957 3898 4004 3943 3999 3962 3866 3994 3861 3986 3841 3857 3895 3893 3895 3818 3822 3868 3824 3912 3911 3873 3883 3741 3834 3777 3800 3820 3805 3798 3807 3873 3818 3851 3740 3748 3741 3863 3841 3778 3777 3787 3723 3767 3725 3768 3810 3796 3730 3870 3760 3887 3597 3825 3792 3858 3899 3777 3731 3639 3850 3813 3710 3911 3842 3796 3805 3725 3834 3871 3775 3750 3773 3738 3897 3832 3824 3916 3814 3923 4020 4006 4067 4139 4242 4232 4136 4224 4134 4135 4036 4053 4021 3959 4013 3966 3893 3947 4023 3952 3969 3859 4091 4067 4073 4007 3922 4022 3989 3972 3982 3967 4086 3947 3871 3916 3960 3997 3901 4014 3888 3678 3924 3788 3867 3755 3766 3874 3885 3985 3943 3995 4051 4053 4169 4166 4231 4249 4347 4367 4230 4240 4275 4294 4270 4180 4293 4160 4076 4079 4032 4173 4052 3981 4149 3899 3899 4020 4044 3957 4017 4010 3943 4012 3937 3852 3971 3930 3870 3892 3778 3824 3737 3691 3855 3810 3778 3794 3594 3834 3768 3731 3843 3878 3826 3817 3854 3896 3892 3938 3901 3966 3907 3997 4021 3938 4103 3988 4010 4055 4017 3970 3882 4055 3998 4032 3921 3926 3947 3902 3975 3880 3946 3943 3814 3898 3823 3951 3892 3886 3816 3778 3832 3884 3864 3827 3924 3903 3899 4023 4057 3996 4189 4234 4147 4140 4058 4070 4019 3822 3926 3794 3921 3873 3762 3839 3920 3959 3908 4051 3985 3953 3959 3994 3923 4011 3939 3921 3870 3779 3844 3742 3872 3768 3704 3816 3796 3854 3775 3761 3788 3717 3762 3695 3844 3917 3843 3718 3791 3745 3866 3855 3784 3829 3774 3734 3699 3638 4003 3796 3975 4045 3996 4137 4041 4319 4226 4470 4381 4343 4178 4093 4026 3951 4011 3926 3869 3869 4025 3895 3940 3994 4072 4247 4118 4114 4256 4202 4202 4188 4020 3884 3896 3936 4074 3962 3826 3904 3963 3935 3989 3978 3968 4076 3939 3902 3929 3978 3938 3987 3803 3768 3858 3818 3844 3850 3828 3910 3962 3842 3909 3939 3913 3856 3793 3924 3835 3880 3808 3889 4010 3861 3947 3901 4005 3938 3878 4001 3869 4027 3940 3944 4131 4092 4034 4077 3975 3980 4168 4083 3964 4024 4107 4034 4070 4031 4073 4023 3976 4061 4250 4176 4204 4140 4224 4241 4205 4194 4279 4285 4157 4168 4186 4150 4057 4148 4302 4095 4143 4203 4400 4241 4280 4260 4295 4121 4240 4060 3932 4118 4034 3998 3992 3851 4008 3829 3925 3934 3853 3978 3971 3964 3897 3815 3927 3879 3932 3682 3809 3838 3720 3795 3819 3753 3807 3796 3772 3837 3845 3738 3799 3757 3818 3883 3720 3760 3752 3734 3779 3855 3724 3778 3764 3738 3861 3926 3816 3908 3956 3870 3890 3877 3976 3943 3851 3891 3814 3864 3879 3836 4014 3875 3977 3827 3845 3950 3939 3959 4015 3905 3941 3918 3853 3890 3851 3829 3935 3949 3923 3985 3903 3925 3954 4185 3958 3910 4061 4016 4134 4202 4234 4103 4154 4103 4205 4055 3968 3883 4089 4129 4068 4078 4036 4064 4030 4056 4052 4103 3972 3982 4041 4014 3970 4094 3964 3832 4003 3869 3892 3844 3939 4043 3801 3898 3787 3865 3882 3966 3920 3965 3966 4080 4095 4159 4398 4536 4674 4686 4918 4916 4982 4877 4774 4638 4591 4552 4415 4363 4244 4350 4270 4337 4230 4216 4233 4300 4340 4300 4363 4463 4369 4258 4248 4228 4078 4033 4095 4028 3954 3958 3912 3981 3948 3840 3868 3830 3834 3846 3719 4063 3792 3787 3810 3754 3772 3778 3893 3862 3831 3808 3871 3941 3949 3894 3982 3944 4031 4060 4052 3935 3965 3961 3914 3995 4032 3803 3895 3875 3899 3891 3891 3910 3980 3955 4005 3993 4127 4182 4253 4149 4173 4257 4194 4353 4429 4439 4420 4292 4183 4085 4112 4081 3994 4066 3997 4017 4177 4064 4049 3999 3962 4179 4011 4174 4176 4116 4074 4035 3921 3856 3949 3918 3810 3986 3858 3776 3857 3864 3839 3735 3847 3720 3699 3822 3760 3767 3727 3687 3727 3771 3848 3888 3756 3679 3624 3638 3661 3784 3798 3784 3740 3697 3763 3786 3594 3692 3698 3601 3737 3719 3674 3830 3701 3736 3720 3700 3737 3806 3642 3729 3775 3728 3717 3720 3781 3628 3631 3734 3852 3677 3750 3731 3698 3602 3786 3815 3664 3695 3799 3766 3737 3816 3793 3752 3751 3872 3783 3780 3726 3840 3876 3884 3707 3789 3706 3833 3696 3791 3823 3827 3726 3711 3758 3693 3783 3808 3927 3882 3788 3899 3854 3824 3899 3802 3891 3908 3884 3774 3943 3999 3947 3987 3993 3991 3918 4141 3963 4025 3985 4134 4053 4061 4170 4180 4111 4115 4157 4312 4372 4392 4407 4287 4483 4224 4203 4202 4247 4247 4157 4059 4023 4101 4111 4016 3902 4049 4049 4082 4103 4148 4126 4056 4092 4097 4002 4033 4094 4073 4052 4162 4216 4307 4228 4414 4271 4182 4210 4048 3924 3999 3860 3723 3854 3745 3846 3921 3853 3802 3956 3901 3987 4005 3827 3981 4004 3946 4026 3867 3910 3844 3785 3722 3783 3848 3791 3680 3794 3787 3728 3758 3749 3787 3721 3850 3797 3825 3906 3930 3908 3955 3855 3933 3978 4083 3853 3895 3838 3792 3868 3808 3846 3946 3751 3785 3767 3777 3795 3868 3865 3809 3866 3908 3855 3887 3947 3908 3877 3717 3740 3758 3797 3870 3765 3885 3723 3738 3696 3699 3743 3734 3681 3779 3720 3548 3749 3582 3630 3670 3584 3717 3637 3739 3737 3664 3704 3710 3730 3686 3747 3681 3672 3738 3757 3762 3599 3729 3729 3667 3700 3647 3827 3647 3641 3621 3733 3642 3752 3730 3748 3689 3644 3648 3714 3718 3770 3802 3754 3710 3612 3718 3681 3604 3672 3632 3640 3650 3742 3631 3687 3648 3690 3654 3665 3601 3682 3701 3781 3764 3839 3830 3845 3773 3661 3691 3832 3785 3673 3670 3747 3576 3632 3771 3625 3623 3713 3759 3674 3749 3711 3768 3634 3759 3733 3706 3745 3749 3608 3614 3713 3582 3640 3661 3677 3671 3703 3712 3669 3705 3688 3736 3700 3709 3587 3663 3630 3643 3729 3731 3678 3610 3659 3656 3703 3682 3709 3708 3646 3646 3619 3702 3679 3608 3694 3719 3642 3812 3696 3563 3670 3532 3632 3734 3667 3662 3655 3643 3755 3667 3722 3675 3735 3600 3776 3642 3742 3807 3732 3827 3820 3812 3835 3830 3932 3971 3961 3933 3868 3856 3869 3821 3767 3805 3892 3739 3781 3719 3888 3705 3830 3859 3776 3711 3797 3864 3833 3842 3836 3769 3797 3699 3823 3925 3811 3833 3885 3869 3811 3940 4027 4044 4017 3916 4129 3906 3874 3895 3901 3821 3822 3962 3753 3882 3841 3773 3794 3902 3856 3928 3905 3867 3840 3830 3800 3946 3854 3796 3994 3955 3912 3898 3773 3861 3819 3863 3739 3790 3813 3882 3728 3837 3768 3904 3794 3882 3817 3834 3847 3822 3744 3697 3713 3708 3910 3780 3719 3697 3796 3758 3729 3697 3783 3722 3858 3712 3630 3712 3766 3740 3698 3729 3780 3776 3755 3713 3785 3748 3748 3712 3806 3782 3728 3644 3893 3665 3706 3790 3758 3763 3691 3677 3738 3731 3580 3876 3721 3745 3837 3747 3834 3808 3882 3871 3875 3721 3890 3929 3886 4035 3988 3947 4035 3928 3956 3853 3767 3813 3843 3776 3826 3909 3869 3868 3855 3848 4010 3901 4043 3874 4006 4021 3911 4055 3979 3828 3869 3924 3828 3767 3831 3790 3831 3928 3795 3872 3856 3862 3935 3868 3782 3962 3925 3871 3914 4018 4069 4107 4161 4160 4113 4174 4204 4115 4192 4078 3978 4017 3941 3943 3935 3802 3923 3992 3758 3908 3927 3867 3797 4049 3868 3989 4074 3965 3945 3884 4015 3956 3945 3839 3824 3775 3850 3881 3788 3911 3749 3836 3889 3869 3814 4001 4059 4172 4154 4240 4184 4041 3999 4059 3970 3848 3904 3831 3836 3719 3916 3756 3987 3911 3885 3885 3929 3893 3921 3872 3868 3899 4020 3953 3838 3949 3759 3942 3838 3768 3807 3774 3790 3660 3901 3861 3899 3992 3930 3886 4035 3976 4064 4049 4154 4072 4088 4034 4179 4031 3997 4056 3883 4001 3889 3796 3866 3862 3956 3922 3930 3967 3916 4102 4265 4112 3945 3975 3929 3886 3918 3878 3839 3844 3767 3867 3807 3736 3843 3799 3819 3612 3810 3826 3704 3877 3848 3803 3786 3696 3733 3668 3692 3706 3703 3659 3653 3651 3608 3736 3700 3730 3682 3805 3835 3628 3714 3636 3598 3690 3607 3667 3584 3634 3675 3695 3534 3695 3655 3579 3607 3696 3695 3731 3824 3716 3712 3690 3661 3649 3630 3626 3706 3755 3749 3585 3761 3743 3890 3805 3808 3758 3975 4029 3945 3866 3855 3800 3827 3803 3803 3706 3744 3676 3830 3713 3705 3612 3652 3796 3713 3786 3781 3689 3713 3800 3836 3786 3691 3802 3655 3756 3682 3724 3681 3672 3666 3796 3630 3696 3795 3727 3654 3646 3766 3645 3688 3670 3692 3664 3743 3810 3733 3704 3727 3649 3720 3683 3581 3812 3681 3755 3700 3746 3696 3693 3702 3606 3787 3674 3765 3780 3734 3718 3725 3854 3772 3877 3796 3911 4022 4012 4129 4120 4349 4341 4385 4412 4440 4442 4506 4294 4255 4290 4066 3855 3974 3907 3930 3862 3785 3870 3792 3937 3882 3934 3961 3924 4094 3990 3948 4099 4005 3994 4049 3970 3847 3878 3735 3861 3749 3722 3691 3724 3739 3656 3692 3695 3713 3664 3703 3761 3728 3657 3675 3711 3741 3723 3610 3628 3716 3647 3810 3597 3725 3620 3678 3774 3683 3730 3659 3588 3758 3676 3758 3820 3797 3774 3897 4007 3901 3910 3874 4010 3999 3701 3716 3753 3722 3778 3757 3631 3747 3901 3756 3766 3627 3696 3781 3760 3752 3805 3713 3773 3842 3891 3782 3828 3797 3903 3725 3790 3648 3786 3565 3719 3724 3586 3592 3688 3625 3734 3744 3662 3751 3697 3719 3805 3653 3738 3605 3770 3630 3725 3591 3786 3736 3627 3892 3663 3675 3599 3770 3646 3831 3739 3812 3881 3755 3836 3808 3887 3761 3848 3759 3836 3769 3730 3832 3683 3658 3700 3714 3639 3740 3771 3726 3730 3680 3646 3738 3776 3766 3805 3797 3855 3811 3766 3792 3708 3823 3705 3871 3856 3795 3820 3918 3777 3969 3835 3983 4025 4053 4139 4188 4336 4327 4355 4294 4192 4230 4177 4100 4105 4036 3950 4032 3831 3770 3914 3857 3873 3910 3821 3905 3939 4010 3916 4022 4096 4035 4043 4128 4031 4081 4045 3851 3949 3878 3952 3877 3778 3815 3805 3769 3832 3855 3742 3899 3820 3793 3824 3794 3788 3819 3706 3786 3775 3791 3788 3822 3771 3861 3951 3781 3854 3920 3922 3782 3924 3885 3803 4002 3870 3880 3894 3787 3761 3899 3850 3698 3762 3833 3833 3777 3924 3869 3794 3842 3840 3769 3750 3896 3827 3922 3801 3829 3889 3896 3844 3798 3819 3943 3883 3838 3676 3807 3770 3800 3793 3839 3974 3835 3912 3872 3886 3865 3766 3823 3897 3923 3805 3801 3826 3882 3802 3775 3997 3968 3917 3921 3794 3866 3886 3843 3899 3758 3786 3695 3805 3836 3805 3831 3898 3898 3849 3887 3822 3838 3859 3873 3793 3816 3756 3667 3760 3785 3788 3845 3746 3798 3714 3819 3760 3717 3736 3566 3698 3784 3800 3734 3842 3761 3739 3717 3701 3757 3793 3669 3749 3672 3783 3693 3643 3669 3704 3696 3772 3751 3682 3743 3696 3711 3724 3684 3753 3821 3769 3604 3801 3772 3661 3782 3779 3795 3828 3942 3928 3850 3917 3976 4132 4125 4174 4307 4207 4375 4202 4148 4235 4169 4014 4132 4142 3914 4047 4088 3950 3919 3980 3964 3920 4081 3928 4101 4104 4091 4175 4096 4192 4290 4159 4282 4282 4330 4278 4187 4182 4250 4149 4039 4020 4005 3994 3899 3896 3956 3878 3752 3853 3870 3915 3899 3798 3825 3922 3919 3830 3830 3822 3844 3904 3776 3829 3769 3917 3866 3777 3756 3901 3724 3689 3673 3687 3567 3583 3672 3730 3771 3658 3750 3839 3855 3535 3689 3847 3776 3748 3730 3697 3830 3622 3752 3640 3699 3760 3769 3683 3718 3837 3830 3804 4018 3985 3900 4118 4077 4176 4191 4084 4191 4085 3984 3884 3990 3796 3885 3881 3859 3970 3862 3838 3926 3907 3923 3968 3955 3907 4028 4005 3931 4015 3995 3948 3981 4031 3957 3961 3843 3981 3934 3849 3901 3871 3854 3827 3726 3912 3911 3946 3857 3889 3833 3878 3830 3916 3946 3914 3880 3894 4074 3854 3910 4015 4031 3989 4042 4076 4068 4088 4249 4271 4161 4200 4143 4007 4003 3952 4006 4012 3920 3954 3846 3915 3884 3927 3997 3865 4009 3822 3938 3872 3878 3798 3883 4085 3978 3943 3934 3885 4041 3860 3831 3927 3926 3943 3838 3875 3816 3827 3887 3922 3927 3925 3994 3955 3827 3877 3893 3933 3886 3920 3896 3855 3949 3922 3867 3956 3870 3883 3898 3917 3895 4096 3892 3960 4064 3934 3938 4024 3854 3970 3913 3948 3885 3779 3810 3956 3963 3877 3906 3865 3929 3967 3778 3907 3865 3823 4019 3860 4059 3930 3922 3880 3840 3928 3955 4027 3928 3950 3915 3928 4049 4016 4039 4047 3998 3971 3951 4054 4001 4076 4111 4034 4067 4072 4172 4183 4184 4222 4175 4198 4155 4293 4286 4240 4406 4442 4254 4258 4366 4375 4335 4335 4226 4258 4152 4293 4140 4158 4198 4255 4162 4171 4151 4114 4123 4174 4188 4278 4203 4331 4216 4227 4193 4232 4135 4223 4094 4080 4008 4050 4131 3919 4055 4030 4009 3996 3968 4032 3875 3914 3948 3887 3930 3930 3976 3966 3823 3861 3901 3843 3814 3836 3804 3924 3935 3793 3755 3810 3851 3842 3853 3951 3910 3951 3945 3880 3938 3925 3923 3956 3863 3885 3990 3837 3662 3921 3798 3735 3835 3803 3690 3703 3772 3797 3797 3733 3701 3770 3660 3805 3683 3819 3853 3782 3876 3738 3762 3813 3786 3794 3858 3714 3790 3702 3768 3712 3706 3798 3638 3590 3746 3714 3645 3707 3683 3756 3763 3706 3721 3792 3636 3680 3627 3776 3811 3751 3758 3749 3805 3817 3762 3792 3816 3857 3872 3839 3840 3837 4056 3983 4033 3905 3986 3892 3916 3977 3900 3981 3952 3931 3980 3900 3918 3861 3948 3860 3847 3947 3809 3855 3881 3798 3753 3864 3900 3936 3854 3844 3854 3683 3729 3807 3894 3872 3888 3815 3789 3877 3789 3912 3767 3860 3818 3827 3746 3749 3791 3929 3795 3798 3926 3802 3793 3830 3958 3982 4026 4028 4066 4018 4083 3917 3985 3913 3929 3929 3899 3936 3881 3887 3901 3835 3879 3760 3807 3800 3891 3783 3905 3822 3885 3879 3800 3858 3796 3883 3891 3902 3876 3823 3883 3830 3776 3858 3747 3811 3831 3809 3761 3739 3800 3816 3837 3722 3621 3706 3732 3678 3824 3665 3753 3605 3751 3763 3648 3669 3698 3696 3696 3659 3665 3703 3712 3739 3600 3704 3635 3663 3742 3799 3651 3698 3717 3523 3888 3707 3771 3803 3821 3770 3806 3790 3914 3839 3849 3705 3856 3918 3921 3730 3956 3883 3875 3934 3776 3802 3766 3721 3730 3757 3649 3837 3891 3891 3778 3727 3852 3851 3810 3793 3872 3772 3791 3693 3753 3786 3816 3773 3899 3830 3788 3697 3726 3760 3748 3768 3810 3725 3744 3729 3778 3732 3895 3837 3691 3759 3686 3801 3796 3838 3781 3691 3957 3740 3898 3817 4023 3939 3992 4049 3967 3904 3947 3975 3948 3937 3722 3830 3695 3844 3846 3905 3869 3862 3816 3835 3846 3808 3703 3710 3736 3747 3881 3816 3869 3716 3830 3760 3799 3790 3760 3795 3881 3901 3744 3782 3750 3864 3820 3906 3876 3846 3911 3963 3994 3791 3821 3734 3882 3776 3791 3800 3791 3619 3762 3787 3795 3829 3718 3829 3773 3840 3721 3787 3822 3799 3782 3812 3770 3952 3841 4017 3880 3920 3916 3955 3831 3789 3807 3981 3961 3939 3859 3821 3898 3980 3883 3872 3863 3797 3997 3927 3848 3877 3757 3747 3857 3910 3854 3841 3729 3877 3852 3800 3786 3856 3890 3810 3893 3971 3814 3711 3899 3963 3880 3903 3826 3814 3820 3908 3957 3901 3846 3718 3893 3766 3768 3745 3811 3899 3718 3703 3844 3792 3816 3737 3678 3749 3672 3721 3625 3852 3699 3621 3698 3660 3759 3741 3710 3710 3720 3840 3811 3735 3680 3748 3690 3736 3761 3718 3815 3829 3710 3775 3732 3663 3697 3805 3778 3793 3676 3858 3776 3822 3802 3749 3807 3704 3677 3768 3726 3769 3773 3815 3798 3740 3727 3790 3896 3899 3780 3901 3828 3894 3962 3978 3987 3953 3955 3861 4051 4020 3964 3992 4003 3959 4004 3956 3965 3905 3969 3854 3906 3870 3862 3884 3726 3840 3903 3942 3906 3923 3916 3946 3868 3897 3914 3987 3883 3970 3856 3999 3820 3861 3921 3952 3907 4031 3827 4041 3997 3997 3971 3960 3922 4023 3801 3987 3861 3861 3872 3756 3872 3874 3944 3795 3810 3811 3842 3677 3781 3674 3878 3854 3758 3766 3798 3732 3807 3778 3818 3801 3848 3772 3751 3794 3737 3778 3805 3801 3755 3753 3753 3806 3796 3782 3686 3706 3691 3701 3748 3546 3770 3741 3686 3738 3755 3672 3595 3664 3751 3664 3618 3601 3749 3722 3700 3714 3731 3614 3614 3787 3607 3700 3676 3664 3818 3631 3630 3715 3732 3730 3698 3588 3655 3764 3609 3670 3646 3653 3789 3714 3660 3776 3734 3648 3660 3728 3688 3628 3648 3704 3707 3626 3682 3682 3682 3659 3648 3638 3679 3712 3684 3781 3662 3622 3714 3604 3766 3686 3706 3601 3660 3538 3743 3615 3650 3627 3671 3663 3633 3663 3590 3711 3738 3576 3753 3541 3646 3661 3617 3652 3619 3617 3627 3725 3657 3839 3756 3725 3659 3715 3681 3702 3585 3631 3679 3724 3843 3795 3602 3792 3759 3868 3845 3806 3813 3803 3744 3735 3745 3662 3611 3743 3856 3753 3759 3629 3725 3763 3680 3690 3787 3720 3662 3717 3657 3793 3735 3698 3766 3839 3677 3825 3766 3779 3825 3772 3698 3703 3616 3803 3698 3737 3783 3765 3759 3699 3742 3734 3724 3734 3635 3744 3697 3588 3689 3585 3782 3767 3607 3714 3686 3689 3648 3623 3655 3689 3788 3695 3830 3672 3689 3716 3715 3700 3703 3653 3700 3616 3715 3711 3677 3704 3770 3743 3762 3662 3744 3665 3664 3648 3691 3723 3813 3700 3644 3679 3800 3755 3653 3648 3869 3665 3731 3747 3669 3696 3694 3887 3840 3805 3684 3857 3729 3680 3847 3691 3804 3832 3776 3838 3788 3690 3662 3751 3572 3720 3675 3662 3730 3712 3837 3797 3914 3644 3767 3732 3843 3847 3741 3668 3698 3645 3796 3802 3810 3748 3763 3687 3792 3566 3686 3674 3769 3690 3763 3719 3602 3704 3618 3713 3684 3706 3658 3640 3873 3779 3859 3870 3949 3888 3792 3877 3812 3936 3759 3825 3835 3850 3834 3684 3705 3787 3794 3666 3739 3680 3732 3713 3785 3860 3806 3898 3929 3800 3833 3852 3909 3987</counts>
			</dataPoints>
		</scan>
	</xrdMeasurement>
</xrdMeasurements>