File: dataset/precursor_mixture/MnCO3_In2O3_Ga2O3.2-min.xrdml
<?xml version="1.0"?>
<xrdMeasurements xmlns="http://www.xrdml.com/XRDMeasurement/2.2" xmlns:xsi="http://www.w3.org/2001/XMLSchema-instance" xsi:schemaLocation="http://www.xrdml.com/XRDMeasurement/2.2 http://www.xrdml.com/XRDMeasurement/2.2/XRDMeasurement.xsd" status="Completed" recordIdentifier="{B66B4125-DB34-41BD-ACEA-ED8AD17099EC}">
	<comment>
		<entry/>
	</comment>
	<sample type="To be analyzed">
		<id>dara-17-1</id>
		<name></name>
		<preparedBy></preparedBy>
	</sample>
	<xrdMeasurement measurementType="Scan" status="Completed" sampleMode="Reflection">
		<usedWavelength intended="K-Alpha 1">
			<kAlpha1 unit="Angstrom">1.5405980</kAlpha1>
			<kAlpha2 unit="Angstrom">1.5444260</kAlpha2>
			<kBeta unit="Angstrom">1.3922500</kBeta>
			<ratioKAlpha2KAlpha1>0.5000</ratioKAlpha2KAlpha1>
		</usedWavelength>
		<incidentBeamPath>
			<radius unit="mm">145.00</radius>
			<xRayTube id="1010048" name="Empyrean Cu LFF HR (9430 033 7310x) DK437873">
				<tension unit="kV">40.0</tension>
				<current unit="mA">15.0</current>
				<anodeMaterial>Cu</anodeMaterial>
				<focus type="Line">
					<length unit="mm">12.0</length>
					<width unit="mm">0.4</width>
					<takeOffAngle unit="deg">6.0</takeOffAngle>
				</focus>
			</xRayTube>
			<filter id="20010004" name="Beta-filter Nickel">
				<material>Ni</material>
				<thickness unit="mm">0.020</thickness>
			</filter>
			<sollerSlit id="21010002" name="Soller slits 0.04 rad.">
				<opening unit="rad">0.0400</opening>
			</sollerSlit>
			<mask id="22031000" name="Fixed mask 13 mm">
				<width unit="mm">9.00</width>
			</mask>
			<divergenceSlit id="22120001" name="Divergence slit 1°" xsi:type="fixedDivergenceSlitType">
				<distanceToSample unit="mm">50.00</distanceToSample>
				<height unit="mm">1.52</height>
			</divergenceSlit>
		</incidentBeamPath>
		<beamKnife id="29030100" name="Beam knife low"/>
		<sampleMovement xsi:type="spinningSampleMovementType">
			<spinnerRevolutionTime unit="seconds">1.0</spinnerRevolutionTime>
		</sampleMovement>
		<diffractedBeamPath>
			<radius unit="mm">145.00</radius>
			<antiScatterSlit id="22090040" name="AS slit 9 mm" xsi:type="fixedAntiScatterSlitType">
				<height unit="mm">9.00</height>
			</antiScatterSlit>
			<sollerSlit id="21020003" name="Large Soller slits 0.04 rad.">
				<opening unit="rad">0.0400</opening>
			</sollerSlit>
			<filter id="20030001" name="Large beta-filter Nickel">
				<material>Ni</material>
				<thickness unit="mm">0.020</thickness>
			</filter>
			<detector id="7010019" name="PIXcel1D-Medipix3 detector" xsi:type="rtmsDetectorType">
				<phd unit="keV">
					<lowerLevel>4.0</lowerLevel>
					<upperLevel>11.3</upperLevel>
				</phd>
				<mode>Scanning</mode>
				<activeLength unit="deg">1.021</activeLength>
			</detector>
		</diffractedBeamPath>
		<scan appendNumber="0" mode="Continuous" scanAxis="Gonio" status="Completed">
			<header>
				<startTimeStamp>2024-03-24T15:33:56-07:00</startTimeStamp>
				<endTimeStamp>2024-03-24T15:36:18-07:00</endTimeStamp>
				<author>
					<name>AutomatedUser</name>
				</author>
				<source>
					<applicationSoftware version="1.6 (94)">PANalytical Aeris Instrument Suite</applicationSoftware>
					<instrumentControlSoftware version="3.0.0 20211014">AERIS</instrumentControlSoftware>
					<instrumentID>2879380</instrumentID>
				</source>
			</header>
			<dataPoints>
				<positions axis="2Theta" unit="deg">
					<startPosition>10.02173288</startPosition>
					<endPosition>139.98435528</endPosition>
				</positions>
				<positions axis="Omega" unit="deg">
					<startPosition>5.01086644</startPosition>
					<endPosition>69.99217764</endPosition>
				</positions>
				<commonCountingTime unit="seconds">1.551</commonCountingTime>
				<counts unit="counts">448 456 447 439 443 423 453 378 402 460 434 390 426 419 385 375 428 382 415 422 415 410 415 409 352 348 407 406 385 369 391 375 381 400 394 367 372 348 402 405 380 411 346 374 381 392 392 346 361 358 351 346 368 300 364 336 350 323 346 324 364 285 360 337 353 310 363 336 341 338 319 326 340 325 317 267 313 329 344 294 323 323 319 302 330 278 292 299 296 317 325 307 310 296 336 286 287 324 250 276 322 316 310 248 305 288 260 285 306 321 334 297 264 277 310 277 305 267 262 251 261 283 288 266 314 291 267 276 287 286 308 276 254 275 262 279 267 259 271 257 234 266 249 254 261 275 247 235 258 253 263 264 257 244 259 250 284 237 250 261 213 261 237 232 275 234 243 281 269 221 269 259 246 279 232 268 282 289 252 247 258 229 253 244 248 261 234 256 258 262 259 235 255 280 263 257 290 303 347 391 421 499 467 400 330 299 291 262 264 236 243 226 244 247 276 232 240 226 260 217 228 209 218 236 249 222 243 201 214 228 228 219 202 206 231 210 238 211 244 195 211 218 256 218 231 237 230 240 239 253 241 238 235 222 232 307 306 360 466 667 494 341 221 239 217 262 224 214 203 238 213 245 220 196 203 223 218 184 190 176 213 193 206 194 198 211 194 185 197 187 210 172 178 200 192 225 206 223 222 190 228 193 192 201 202 186 196 212 206 218 207 232 218 223 240 247 290 244 290 332 398 313 325 252 238 207 213 214 220 215 207 190 220 187 202 187 196 172 183 180 162 205 174 184 160 188 176 177 194 188 183 205 176 205 178 203 176 184 182 208 183 180 194 187 190 177 181 183 200 203 183 179 171 193 180 201 190 195 192 155 166 191 212 178 176 199 165 187 175 207 153 180 200 216 195 173 210 186 166 177 205 192 181 188 168 179 168 164 184 181 176 151 148 191 182 208 202 183 174 189 182 186 190 203 187 193 162 196 182 184 194 190 175 171 220 187 199 188 220 219 201 237 241 237 272 265 299 300 346 376 411 417 515 552 584 583 604 743 875 1055 1351 1651 2346 3868 4021 2790 1723 807 531 461 440 390 342 375 352 358 403 469 593 741 867 921 739 657 625 622 622 721 805 849 778 664 547 477 435 374 291 334 253 286 290 244 204 231 257 216 212 197 231 206 157 179 209 199 210 210 207 182 188 199 210 231 214 224 224 222 215 206 240 210 244 201 212 194 185 170 190 190 180 156 187 201 188 150 183 178 168 162 199 172 178 191 206 203 178 197 225 195 215 183 208 190 198 271 327 359 348 404 413 451 483 554 822 1209 1092 779 523 310 256 214 198 191 179 181 186 190 183 148 164 182 183 178 160 174 174 149 160 147 178 195 181 186 174 186 196 168 185 176 206 205 210 205 208 239 264 281 315 363 356 321 280 304 310 367 356 290 319 228 191 215 197 179 213 198 230 254 282 305 320 337 311 305 277 260 246 239 225 176 217 175 145 189 184 175 144 152 148 133 161 172 167 167 152 176 145 135 147 149 192 157 179 186 171 184 159 159 127 129 186 154 156 138 138 142 165 140 152 161 146 145 171 152 126 167 151 137 145 162 159 162 168 178 174 187 212 273 260 247 244 185 192 161 143 158 211 215 276 306 238 238 200 191 169 144 166 164 139 155 146 164 147 126 143 141 130 174 155 184 149 190 131 177 177 181 155 190 195 147 146 161 140 166 153 141 169 134 128 133 150 147 178 183 167 177 183 149 144 155 128 128 178 150 152 149 159 143 151 165 186 178 183 196 161 171 190 158 174 197 255 256 271 255 235 179 183 176 157 172 216 180 195 221 308 455 432 349 364 285 239 189 193 185 181 166 147 151 160 159 157 159 126 149 147 145 160 145 158 148 118 138 155 127 149 159 131 128 137 130 146 131 126 162 172 128 146 148 142 140 136 121 140 149 136 151 157 136 144 130 144 162 137 150 193 180 180 183 191 184 206 205 224 214 207 205 168 168 177 150 162 142 153 168 173 199 214 213 199 223 193 213 198 221 219 196 168 171 163 155 175 141 155 170 156 149 159 141 166 138 176 172 193 154 143 194 184 181 201 207 231 227 266 395 749 1346 1183 669 850 702 332 260 212 222 224 292 293 298 340 309 321 281 263 224 206 185 175 154 174 157 147 159 131 133 158 156 142 172 143 128 163 173 183 223 221 203 180 150 148 149 130 135 129 132 134 122 139 148 129 155 146 126 145 132 119 141 122 149 124 136 136 150 139 128 146 138 136 130 160 164 168 179 158 162 141 157 164 130 160 136 154 147 118 148 123 146 128 163 152 133 160 146 115 127 135 136 143 137 146 139 123 128 131 159 154 175 228 336 233 176 222 165 160 148 148 154 136 152 136 132 154 149 128 148 136 129 127 138 148 132 124 135 136 142 149 139 133 166 162 150 195 227 249 243 236 205 236 235 200 167 170 161 179 146 137 134 160 146 167 158 153 126 171 139 152 148 128 170 140 170 200 161 154 192 197 248 272 339 360 288 230 256 251 232 182 165 164 161 159 157 160 177 187 181 188 193 205 216 237 238 224 201 229 208 204 210 223 215 237 256 356 558 991 765 488 523 632 500 318 244 239 223 209 182 185 188 163 181 161 148 169 143 165 153 129 126 132 167 162 150 150 167 166 143 188 234 272 254 206 218 229 241 166 167 189 193 152 177 167 180 158 176 186 163 150 177 154 137 131 136 182 162 167 161 169 165 147 169 223 248 326 285 240 251 272 227 233 255 212 238 246 202 224 242 201 224 247 257 221 251 267 299 295 293 287 304 254 276 235 247 218 172 221 218 233 174 194 228 180 152 165 147 157 147 137 164 139 158 152 130 158 147 136 151 145 128 148 139 137 146 135 136 153 151 173 178 198 138 165 145 152 154 143 145 130 138 117 152 138 143 137 150 140 144 162 169 157 151 176 152 148 157 157 155 130 126 156 182 219 184 162 129 153 155 173 121 121 127 139 141 122 134 136 143 118 118 160 143 141 145 143 130 155 148 138 160 172 166 182 186 195 189 180 198 182 192 182 145 141 144 159 141 152 139 166 177 125 145 154 166 157 146 162 148 155 142 124 153 156 152 144 127 123 145 145 138 137 133 127 140 120 135 122 127 146 128 119 123 125 133 119 130 126 123 118 137 154 134 134 144 140 151 139 163 155 142 158 144 147 149 153 142 165 148 146 130 162 124 131 150 142 133 130 137 132 120 137 115 122 114 105 153 154 140 182 205 165 161 179 183 201 140 147 122 129 128 140 108 131 119 145 129 132 145 126 122 123 119 132 126 131 111 136 156 147 210 206 179 158 167 196 168 146 123 140 123 121 136 121 128 107 130 148 128 129 145 145 127 150 147 144 132 148 148 135 184 236 198 169 150 150 205 186 127 136 145 115 135 113 141 112 117 132 124 108 128 119 136 129 127 118 139 142 135 121 137 163 185 183 152 164 166 157 175 142 145 145 133 140 152 134 135 133 130 138 125 120 141 127 119 126 127 122 158 133 147 159 209 193 130 133 155 139 150 132 131 114 112 115 122 122 148 116 141 141 155 119 117 135 113 144 100 128 128 117 145 138 129 152 154 158 133 125 160 143 123 119 113 140 131 134 133 118 116 118 130 116 122 135 110 112 127 128 128 122 135 143 179 196 194 130 134 147 151 176 148 161 125 150 146 142 117 134 123 125 104 125 139 112 116 140 117 124 145 163 146 187 209 287 275 199 166 156 199 226 204 156 141 130 155 119 106 127 125 118 137 119 139 145 146 145 121 132 146 147 119 143 157 152 142 137 135 147 128 139 136 117 127 140 144 145 119 126 137 159 118 121 150 113 131 151 144 171 147 140 191 180 175 233 242 200 187 150 168 189 188 139 141 132 142 119 125 134 143 148 112 131 138 127 124 137 144 130 140 128 134 146 138 137 162 141 135 116 138 146 131 134 148 121 118 133 144 127 121 137 122 142 116 165 139 147 137 155 159 117 149 137 135 151 164 164 124 149 143 152 142 154 113 160 144 153 147 160 119 135 138 145 153 147 142 137 131 120 135 130 139 133 171 203 165 143 171 137 154 158 161 160 134 162 153 123 137 143 135 139 152 116 130 155 130 150 147 121 141 134 124 140 118 125 149 138 135 152 133 139 134 122 139 126 124 144 130 154 118 137 121 121 152 130 145 116 137 128 147 147 138 146 171 209 166 163 117 115 147 148 118 159 123 126 126 117 144 140 127 119 128 126 131 138 152 118 129 122 132 121 109 120 119 137 130 141 112 114 106 119 138 131 120 147 124 133 135 130 148 139 125 141 131 126 146 134 126 129 162 158 138 142 188 171 173 162 152 147 158 181 182 170 146 130 134 133 133 141 158 139 143 129 150 133 148 155 148 154 172 147 206 183 216 254 209 198 150 158 153 154 207 163 133 138 151 138 133 142 124 119 138 137 134 136 129 128 136 123 140 144 130 135 166 179 162 170 128 149 143 153 143 149 142 137 149 120 132 131 141 131 117 121 127 135 143 128 128 114 149 146 133 168 154 160 137 150 147 137 123 129 163 147 128 120 157 145 126 133 143 112 145 134 133 116 137 119 159 124 139 137 131 145 139 161 135 136 128 129 136 135 140 146 149 131 135 148 139 150 115 125 140 138 130 149 155 164 142 159 132 149 147 158 170 188 213 230 174 143 164 150 171 201 194 158 178 150 151 147 132 147 162 144 133 140 124 141 148 118 110 130 120 133 128 133 153 145 160 129 121 125 142 130 130 160 110 124 111 137 133 135 115 124 116 118 118 139 153 152 140 151 142 142 154 148 177 198 221 152 148 153 152 151 155 178 195 154 136 127 149 118 148 139 134 120 114 147 134 146 123 135 140 159 132 146 138 158 187 164 155 130 152 152 129 154 150 152 137 151 139 138 127 143 136 109 98 132 124 134 125 134 123 129 131 142 130 116 156 134 139 121 149 127 129 139 135 142 168 142 166 127 142 131 116 161 153 144 113 140 121 141 139 117 151 148 145 143 129 175 187 191 148 157 162 137 156 145 167 175 161 156 132 138 152 130 140 119 141 151 137 132 119 130 125 127 117 138 131 146 147 177 196 170 198 150 168 137 138 151 161 172 185 152 143 155 139 157 128 155 136 142 129 125 141 151 123 151 141 130 149 148 155 137 170 172 146 144 150 144 136 157 149 153 164 158 156 133 131 145 148 125 142 137 136 121 118 139 124 157 131 153 113 112 153 162 171 158 161 149 136 133 147 139 151 133 148 163 145 147 157 125 122 145 134 127 117 144 123 146 149 165 135 152 149 118 120 137 160 149 177 171 159 147 143 132 128 118 131 138 145 128 148 135 150 111 148 151 131 143 147 138 146 120 124 157 141 140 120 108 129 127 131 132 122 129 130 144 153 111 132 147 168 141 133 120 114 127 152 129 136 139 129 131 150 137 130 120 126 130 128 142 123 128 168 188 185 165 159 161 151 138 131 136 122 152 153 156 162 118 150 137 142 136 131 122 133 133 137 135 131 146 128 154 150 115 127 136 143 140 161 147 139 137 150 164 130 134 139 144 154 145 173 140 150 123 141 148 132 149 120 147 159 149 119 112 121 157 155 133 130 132 142 127 120 120 129 128 143 130 129 129 141 141 142 136 148 135 133 99 118 144 120 143 142 150 144 126 106 107 136 140 136 144 123 154 126 153 153 152 158 137 130 145 149 126 150 142 146 136 123 148 131 139 138 136 125 125 134 129 147 135 146 126 134 135 118 146 130 144 137 154 148 152 160 167 159 146 142 138 128 134 136 120 130 149 158 147 178 149 141 150 129 132 149 146 139 121 127 161 137 144 134 140 123 126 137 127 146 134 148 171 153 162 137 144 163 123 137 133 144 137 139 136 144 142 137 121 117 144 130 147 120 135 137 124 131 122 121 138 123 140 145 147 145 165 151 158 177 166 145 172 147 165 155 153 146 153 140 154 155 163 155 154 167 150 121 131 151 135 116 144 168 139 147 148 153 154 134 147 124 142 144 153 177 184 201 196 163 159 145 141 142 140 157 145 136 161 192 153 168 151 157 130 149 119 149 130 127 124 131 127 156 143 136 146 158 157 107 128 134 148 127 117 141 139 123 164 141 128 117 124 142 159 137 130 142 148 147 131 141 135 115 143 141 119 132 127 146 129 143 142 152 154 142 134 117 121 141 150 145 145 160 138 145 145 125 149 139 157 159 160 149 133 138 154 138 136 149 167 169 136 124 115 113 145 133 153 126 131 135 148 157 117 120 150 135 147 167 156 131 147 151 178 194 186 182 162 161 154 172 163 170 146 175 174 152 156 158 165 163 177 187 147 172 153 130 150 128 166 130 162 167 142 146 155 116 143 126 172 136 146 150 143 144 167 157 207 161 192 167 137 134 145 134 142 135 147 151 147 168 142 167 137 152 159 145 154 147 134 127 150 141 165 129 147 119 128 123 129 137 132 134 137 132 148 170 142 152 158 187 188 181 175 157 115 126 150 127 139 135 142 134 157 137 172 180 149 136 125 134 137 142 134 144 141 143 148 138 134 148 147 137 133 159 113 153 136 142 137 149 166 157 160 192 185 192 190 180 178 170 148 140 153 126 154 149 155 154 142 182 161 185 165 170 154 154 167 148 165 142 151 176 158 182 147 130 145 152 151 170 143 136 151 147 151 140 122 147 161 152 140 169 132 164 148 158 161 138 127 164 130 179 153 134 170 156 151 145 154 139 152 153 129 137 157 144 152 118 148</counts>
			</dataPoints>
		</scan>
	</xrdMeasurement>
</xrdMeasurements>