File: dataset/precursor_mixture/NaAlO2-1.5H2O_Li2TiO3_SnO2_CaCO3.2-min.xrdml
<?xml version="1.0"?>
<xrdMeasurements xmlns="http://www.xrdml.com/XRDMeasurement/2.2" xmlns:xsi="http://www.w3.org/2001/XMLSchema-instance" xsi:schemaLocation="http://www.xrdml.com/XRDMeasurement/2.2 http://www.xrdml.com/XRDMeasurement/2.2/XRDMeasurement.xsd" status="Completed" recordIdentifier="{D60EEB14-FFFB-4E58-98A8-894759836495}">
	<comment>
		<entry/>
	</comment>
	<sample type="To be analyzed">
		<id>dara-28-1</id>
		<name></name>
		<preparedBy></preparedBy>
	</sample>
	<xrdMeasurement measurementType="Scan" status="Completed" sampleMode="Reflection">
		<usedWavelength intended="K-Alpha 1">
			<kAlpha1 unit="Angstrom">1.5405980</kAlpha1>
			<kAlpha2 unit="Angstrom">1.5444260</kAlpha2>
			<kBeta unit="Angstrom">1.3922500</kBeta>
			<ratioKAlpha2KAlpha1>0.5000</ratioKAlpha2KAlpha1>
		</usedWavelength>
		<incidentBeamPath>
			<radius unit="mm">145.00</radius>
			<xRayTube id="1010048" name="Empyrean Cu LFF HR (9430 033 7310x) DK437873">
				<tension unit="kV">40.0</tension>
				<current unit="mA">15.0</current>
				<anodeMaterial>Cu</anodeMaterial>
				<focus type="Line">
					<length unit="mm">12.0</length>
					<width unit="mm">0.4</width>
					<takeOffAngle unit="deg">6.0</takeOffAngle>
				</focus>
			</xRayTube>
			<filter id="20010004" name="Beta-filter Nickel">
				<material>Ni</material>
				<thickness unit="mm">0.020</thickness>
			</filter>
			<sollerSlit id="21010002" name="Soller slits 0.04 rad.">
				<opening unit="rad">0.0400</opening>
			</sollerSlit>
			<mask id="22031000" name="Fixed mask 13 mm">
				<width unit="mm">9.00</width>
			</mask>
			<divergenceSlit id="22120001" name="Divergence slit 1°" xsi:type="fixedDivergenceSlitType">
				<distanceToSample unit="mm">50.00</distanceToSample>
				<height unit="mm">1.52</height>
			</divergenceSlit>
		</incidentBeamPath>
		<beamKnife id="29030100" name="Beam knife low"/>
		<sampleMovement xsi:type="spinningSampleMovementType">
			<spinnerRevolutionTime unit="seconds">1.0</spinnerRevolutionTime>
		</sampleMovement>
		<diffractedBeamPath>
			<radius unit="mm">145.00</radius>
			<antiScatterSlit id="22090040" name="AS slit 9 mm" xsi:type="fixedAntiScatterSlitType">
				<height unit="mm">9.00</height>
			</antiScatterSlit>
			<sollerSlit id="21020003" name="Large Soller slits 0.04 rad.">
				<opening unit="rad">0.0400</opening>
			</sollerSlit>
			<filter id="20030001" name="Large beta-filter Nickel">
				<material>Ni</material>
				<thickness unit="mm">0.020</thickness>
			</filter>
			<detector id="7010019" name="PIXcel1D-Medipix3 detector" xsi:type="rtmsDetectorType">
				<phd unit="keV">
					<lowerLevel>4.0</lowerLevel>
					<upperLevel>11.3</upperLevel>
				</phd>
				<mode>Scanning</mode>
				<activeLength unit="deg">1.021</activeLength>
			</detector>
		</diffractedBeamPath>
		<scan appendNumber="0" mode="Continuous" scanAxis="Gonio" status="Completed">
			<header>
				<startTimeStamp>2024-03-24T12:51:53-07:00</startTimeStamp>
				<endTimeStamp>2024-03-24T12:54:16-07:00</endTimeStamp>
				<author>
					<name>AutomatedUser</name>
				</author>
				<source>
					<applicationSoftware version="1.6 (94)">PANalytical Aeris Instrument Suite</applicationSoftware>
					<instrumentControlSoftware version="3.0.0 20211014">AERIS</instrumentControlSoftware>
					<instrumentID>2879380</instrumentID>
				</source>
			</header>
			<dataPoints>
				<positions axis="2Theta" unit="deg">
					<startPosition>10.02173288</startPosition>
					<endPosition>139.98435528</endPosition>
				</positions>
				<positions axis="Omega" unit="deg">
					<startPosition>5.01086644</startPosition>
					<endPosition>69.99217764</endPosition>
				</positions>
				<commonCountingTime unit="seconds">1.551</commonCountingTime>
				<counts unit="counts">385 420 365 403 399 394 385 381 420 397 344 392 328 375 374 403 359 381 373 349 357 360 320 397 349 359 340 333 353 330 331 308 321 295 306 317 328 301 323 339 301 304 310 294 305 304 287 306 329 312 310 319 302 292 330 285 305 284 250 306 272 285 304 279 300 290 273 284 290 268 238 231 286 292 226 262 256 279 262 274 237 243 277 242 272 239 246 251 259 245 234 280 245 239 227 224 274 232 231 229 249 255 233 216 222 229 232 221 213 226 230 256 216 215 237 195 234 202 216 219 204 239 209 240 186 208 223 248 229 193 190 185 176 182 183 177 190 181 223 182 203 186 203 193 219 221 220 232 219 215 224 229 220 223 236 208 203 204 195 190 219 142 170 180 207 184 178 161 207 193 217 193 186 188 177 185 207 195 169 157 216 191 206 210 214 205 202 198 224 237 224 227 242 200 198 201 190 219 188 169 183 195 178 189 203 183 168 180 182 175 178 176 184 171 168 151 165 174 155 181 152 169 154 166 181 178 162 182 197 173 175 168 185 177 203 216 211 202 188 165 155 169 208 190 167 159 152 164 145 151 156 153 188 174 194 195 187 167 148 163 153 135 130 146 153 144 111 159 122 146 142 144 133 124 133 146 143 128 148 142 138 126 151 126 114 144 133 133 150 167 159 159 157 193 196 174 148 160 141 126 124 113 130 135 128 119 113 137 129 147 133 120 162 165 129 137 148 118 137 119 141 140 131 142 149 118 127 117 127 127 117 122 136 161 124 137 121 118 118 102 124 149 179 164 158 159 165 131 111 129 128 118 134 142 141 142 121 133 156 141 143 149 156 159 224 225 237 295 373 449 684 934 1434 2158 2225 1649 1073 636 455 336 246 217 224 191 157 177 143 171 130 135 134 130 115 114 124 134 126 102 91 102 99 122 118 93 123 115 107 109 116 118 114 116 108 123 128 132 136 119 159 147 153 137 146 139 150 178 187 190 193 223 252 307 365 607 994 2175 6101 11434 6289 4571 951 443 334 264 241 217 210 206 158 130 129 158 118 131 150 125 146 192 192 176 154 154 118 140 135 123 112 128 119 119 107 114 108 110 99 105 112 135 104 113 125 123 118 132 146 139 137 173 139 152 110 99 99 100 113 113 91 98 95 96 110 103 120 117 95 108 107 92 107 85 100 86 87 102 94 110 107 88 105 129 150 143 185 139 144 131 135 145 169 170 237 224 244 336 472 704 1058 1574 1687 1352 1026 606 410 244 249 193 187 200 226 156 149 135 110 124 125 113 126 88 108 118 127 168 176 200 197 157 115 94 87 116 85 90 93 79 93 85 94 109 133 175 132 151 158 133 201 176 168 131 127 145 94 80 86 94 74 88 85 84 93 70 77 90 81 87 86 73 87 69 106 67 79 78 97 86 93 63 102 99 97 82 99 109 107 121 129 159 193 254 359 532 465 411 374 253 154 124 111 116 90 90 99 86 76 84 80 83 102 133 117 106 119 141 146 168 197 200 153 125 88 106 108 186 253 153 132 114 75 71 76 64 58 69 59 78 82 80 48 64 69 87 66 66 48 57 70 73 69 56 60 73 61 64 75 54 80 63 64 55 40 60 67 61 89 55 68 69 54 67 63 62 79 76 80 71 85 72 82 58 53 85 62 71 68 63 62 70 75 57 55 59 63 71 69 82 89 80 79 93 47 87 85 72 76 77 84 136 263 189 146 183 147 116 128 133 163 197 226 207 258 248 198 184 147 147 110 109 92 73 85 60 55 65 94 72 72 82 45 47 54 47 63 49 59 40 42 52 40 51 50 56 40 44 40 57 44 52 59 56 59 43 32 52 54 56 44 51 60 68 49 52 51 64 56 41 40 57 60 53 57 59 73 79 65 62 65 65 53 54 43 58 58 60 59 48 81 75 89 74 80 100 85 103 131 215 461 326 183 250 139 99 78 73 64 50 53 52 57 72 54 67 76 46 70 73 80 121 247 259 166 166 137 87 67 57 71 42 41 60 51 48 44 45 55 57 56 43 69 45 48 64 44 48 74 34 41 38 50 53 39 46 49 51 49 55 55 45 50 60 55 56 55 58 44 64 69 42 73 61 55 51 45 38 50 46 65 68 66 78 73 85 94 78 127 152 148 180 209 317 560 875 1254 1085 765 791 701 408 248 199 154 151 115 80 72 69 75 64 65 65 62 69 61 64 66 62 70 75 62 54 62 75 48 45 40 54 51 46 41 38 49 71 44 52 70 47 50 38 46 35 54 47 53 46 65 64 46 55 60 68 62 56 75 62 80 94 103 146 233 317 282 229 187 205 135 121 93 87 83 65 71 51 82 73 64 70 79 75 63 55 64 74 61 65 54 52 57 48 65 56 43 47 54 56 34 54 44 48 39 56 70 52 52 55 61 49 47 53 41 41 51 50 62 52 55 59 64 75 109 114 89 108 144 115 86 91 104 145 163 152 156 129 150 95 103 91 72 73 59 58 55 59 42 52 48 58 45 41 41 54 47 55 38 42 41 34 34 29 42 42 30 37 37 50 49 42 26 29 44 44 34 39 44 58 41 36 39 34 33 27 57 47 41 36 37 46 49 42 50 53 62 59 116 82 79 75 92 84 118 212 314 118 92 145 135 74 68 58 77 74 72 73 84 93 81 81 79 123 172 237 280 237 182 193 201 136 106 113 112 72 80 53 62 60 75 48 66 45 48 37 37 43 54 43 63 72 61 56 77 85 100 72 87 119 116 120 100 101 112 96 81 100 65 77 73 59 68 55 66 64 60 42 78 73 75 69 82 72 70 90 102 146 192 235 248 243 175 200 175 144 125 96 74 64 65 63 54 53 51 57 50 61 78 100 112 104 103 95 135 165 197 315 330 256 187 203 201 149 114 90 71 60 51 47 58 44 41 41 45 63 34 43 41 61 49 40 42 41 36 29 43 39 39 35 33 32 33 29 35 27 36 31 29 38 34 35 35 32 26 32 33 39 29 42 25 26 30 32 37 42 34 34 30 36 45 47 38 29 45 59 60 68 56 44 54 24 41 30 50 45 41 32 28 31 36 36 32 34 31 37 36 22 39 33 30 38 45 70 56 40 63 44 44 49 28 28 37 40 27 35 41 51 36 48 48 49 51 53 77 80 120 152 99 98 105 108 85 69 59 41 42 47 32 31 49 26 27 37 31 43 45 33 39 39 29 38 33 38 40 47 42 43 29 34 33 26 42 64 49 36 32 32 39 24 24 28 36 32 31 37 45 25 41 39 32 30 39 35 44 36 44 39 31 40 35 28 43 34 40 31 24 36 37 43 28 29 37 24 33 37 54 29 29 35 30 27 25 40 31 38 38 21 20 41 24 31 31 32 47 28 33 36 23 33 36 33 25 27 44 37 33 33 43 51 42 41 36 35 48 37 38 24 38 41 30 31 19 29 43 43 46 42 48 50 67 34 40 41 42 48 31 36 38 42 34 18 29 29 30 42 41 25 31 29 33 33 32 49 44 42 52 45 56 48 53 78 119 149 179 179 131 125 98 146 126 92 75 59 54 62 37 37 30 37 35 38 23 39 33 37 33 48 37 24 42 33 36 45 46 35 45 40 58 44 41 56 43 43 41 50 40 58 41 35 39 39 36 28 35 58 62 57 67 84 91 55 55 65 57 77 61 58 68 47 49 52 65 46 41 46 28 37 41 33 30 38 42 20 40 41 29 42 43 28 26 30 23 22 26 36 19 26 29 36 35 44 34 35 28 37 42 35 58 45 39 39 50 55 73 80 133 152 143 102 89 99 91 105 79 67 57 42 38 34 43 33 44 44 22 44 29 25 32 33 37 37 26 38 30 51 22 33 27 34 27 34 24 32 36 30 33 25 22 24 20 19 41 32 22 36 21 45 31 26 32 25 40 31 28 39 29 27 36 30 25 33 29 46 47 36 28 43 39 26 51 40 41 44 62 67 76 74 46 63 61 40 74 50 48 33 35 39 37 21 29 32 33 24 28 36 26 23 23 38 32 25 34 42 24 36 28 19 26 27 27 30 38 31 28 22 22 30 22 23 37 37 49 45 37 44 37 38 71 55 62 86 127 159 173 113 101 89 96 94 93 74 72 82 70 37 42 46 45 52 61 40 49 47 65 67 96 116 145 150 134 112 74 107 108 82 92 70 71 50 51 37 48 44 36 38 41 23 27 31 24 23 28 37 24 27 36 40 38 22 29 28 21 32 34 43 27 24 39 29 24 30 23 32 35 45 47 60 44 46 48 78 86 101 76 61 61 58 51 66 57 46 42 50 31 50 24 32 35 46 30 35 31 28 26 30 32 38 30 37 37 24 34 55 61 41 37 37 42 54 63 74 56 27 38 36 46 52 54 45 39 34 37 40 31 35 45 41 46 37 45 62 63 91 96 67 90 70 72 71 76 70 63 55 40 45 46 36 29 23 39 42 32 38 31 28 28 27 22 25 27 19 25 26 35 19 28 21 37 24 32 29 39 21 15 36 39 21 22 28 24 35 21 22 30 27 24 22 28 25 23 30 35 30 33 50 30 40 37 23 27 48 58 79 113 90 60 35 38 41 46 68 67 42 36 41 27 24 28 44 37 35 28 37 33 15 26 34 21 26 35 35 30 27 31 28 27 30 35 10 21 22 27 28 19 25 27 20 34 24 30 20 25 19 28 33 39 24 35 24 21 20 29 27 34 26 20 28 30 15 24 27 36 21 25 25 29 21 36 19 30 27 32 33 33 29 26 33 20 44 28 42 34 38 27 27 35 42 34 20 27 23 33 39 33 24 41 30 32 24 21 44 18 22 25 33 35 34 42 31 24 30 37 35 39 22 29 26 27 38 25 23 24 31 27 33 33 21 27 20 40 28 25 31 23 30 26 38 24 21 27 23 27 40 31 33 30 21 20 25 47 42 33 39 27 24 31 32 36 41 47 36 29 28 27 39 21 35 32 25 35 24 19 37 39 35 35 42 48 28 40 38 25 37 36 36 40 32 53 38 50 45 59 43 67 58 72 95 98 132 130 131 148 162 123 126 95 116 111 112 90 80 102 97 72 64 58 47 56 59 34 47 24 40 36 53 27 39 49 41 24 44 36 28 33 34 30 31 27 18 25 31 18 24 36 28 36 38 38 29 29 29 38 38 29 24 36 22 41 25 38 36 28 29 29 40 37 37 35 40 30 43 39 39 44 49 35 44 41 51 57 53 71 68 86 80 47 60 45 54 56 60 56 65 64 52 51 52 52 37 36 36 45 56 45 48 38 42 34 37 33 36 39 29 23 34 43 41 35 26 36 32 43 36 38 32 29 37 49 29 31 23 29 23 45 55 42 52 39 28 40 41 48 51 79 86 102 94 62 58 56 51 57 54 67 68 66 57 60 52 46 45 48 57 59 55 54 64 66 71 68 82 123 163 144 144 92 84 86 84 83 79 77 105 94 104 75 66 55 51 46 42 42 48 39 32 25 36 39 39 31 27 27 31 31 31 42 24 33 27 15 30 34 37 26 40 28 49 50 33 29 23 27 22 30 27 40 30 33 38 35 34 28 42 37 36 47 30 21 32 34 36 36 37 33 44 49 29 38 29 39 39 31 29 19 38 40 28 34 38 38 35 35 25 37 34 24 27 22 38 42 30 45 25 42 33 32 41 30 39 41 55 49 34 37 33 42 35 37 51 47 51 53 51 50 52 67 84 89 126 103 130 118 134 115 112 119 84 98 71 89 116 95 82 95 96 99 83 87 66 47 55 42 32 36 44 49 46 28 38 31 40 38 42 38 35 22 30 37 37 36 38 27 35 35 21 27 27 35 27 21 34 46 24 51 23 21 33 29 25 33 30 28 32 23 40 32 34 36 37 44 33 26 23 25 32 33 37 39 29 28 36 34 25 24 22 34 22 29 38 33 40 27 28 34 54 28 25 34 29 20 30 24 25 36 34 36 20 25 45 29 38 33 25 23 46 24 40 35 39 23 25 33 21 32 30 24 36 42 28 30 36 24 48 35 39 24 32 33 32 31 26 43 39 42 41 33 39 40 38 35 37 24 37 41 36 42 39 38 32 32 32 26 32 35 29 29 36 44 34 45 43 36 36 34 47 44 37 33 33 46 33 42 57 50 47 37 42 36 55 47 41 57 40 54 52 90 82 80 104 124 133 136 114 100 99 95 84 71 80 73 67 77 85 90 113 95 75 75 62 61 66 48 54 44 53 48 54 36 45 40 44 33 41 38 38 34 30 42 45 30 50 29 34 47 38 31 39 37 46 41 44 48 30 31 37 45 51 37 37 39 26 33 34 47 39 44 47 46 38 36 54 68 49 71 61 68 62 58 47 39 47 42 46 38 42 50 48 46 49 42 59 65 57 33 49 51 54 27 47 40 27 45 39 41 37 41 39 36 55 43 48 40 32 46 25 39 41 43 49 39 40 41 47 42 41 44 38 28 50 45 39 38 32 36 43 43 45 44 49 46 37 42 37 45 53 44 45 43 56 44 52 44 49 43 53 83 72 80 81 92 105 101 89 66 88 77 73 61 85 49 56 64 54 48 65 82 85 77 51 74 71 51 63 49 49 46 46 42 35 49 38 33 39 34 44 37 47 27 34 36 46 32 30 42 35 42 53 38 42 40 31 33 35 44 32 36 35 29 37 31 32 28 39 37 40 29 46 28 41 39 38 33 29 42 40 39 49 35 39 43 30 26 29 51 46 35 36 38 41 27 37 32 34 32 37 33 35 24 38 29 31 41 25 48 45 40 46 39 43 37 43 43 24 39 35 41 29 40</counts>
			</dataPoints>
		</scan>
	</xrdMeasurement>
</xrdMeasurements>