File: dataset/precursor_mixture/NaAlO2-1.5H2O_V2O5_CuO_Li3PO4.12-min.xrdml
<?xml version="1.0"?>
<xrdMeasurements xmlns="http://www.xrdml.com/XRDMeasurement/2.2" xmlns:xsi="http://www.w3.org/2001/XMLSchema-instance" xsi:schemaLocation="http://www.xrdml.com/XRDMeasurement/2.2 http://www.xrdml.com/XRDMeasurement/2.2/XRDMeasurement.xsd" status="Completed" recordIdentifier="{AFA9B94A-690F-4C9F-8D9B-88023313EF63}">
	<comment>
		<entry/>
	</comment>
	<sample type="To be analyzed">
		<id>dara-23-2</id>
		<name></name>
		<preparedBy></preparedBy>
	</sample>
	<xrdMeasurement measurementType="Scan" status="Completed" sampleMode="Reflection">
		<usedWavelength intended="K-Alpha 1">
			<kAlpha1 unit="Angstrom">1.5405980</kAlpha1>
			<kAlpha2 unit="Angstrom">1.5444260</kAlpha2>
			<kBeta unit="Angstrom">1.3922500</kBeta>
			<ratioKAlpha2KAlpha1>0.5000</ratioKAlpha2KAlpha1>
		</usedWavelength>
		<incidentBeamPath>
			<radius unit="mm">145.00</radius>
			<xRayTube id="1010048" name="Empyrean Cu LFF HR (9430 033 7310x) DK437873">
				<tension unit="kV">40.0</tension>
				<current unit="mA">15.0</current>
				<anodeMaterial>Cu</anodeMaterial>
				<focus type="Line">
					<length unit="mm">12.0</length>
					<width unit="mm">0.4</width>
					<takeOffAngle unit="deg">6.0</takeOffAngle>
				</focus>
			</xRayTube>
			<filter id="20010004" name="Beta-filter Nickel">
				<material>Ni</material>
				<thickness unit="mm">0.020</thickness>
			</filter>
			<sollerSlit id="21010002" name="Soller slits 0.04 rad.">
				<opening unit="rad">0.0400</opening>
			</sollerSlit>
			<mask id="22031000" name="Fixed mask 13 mm">
				<width unit="mm">9.00</width>
			</mask>
			<divergenceSlit id="22120001" name="Divergence slit 1°" xsi:type="fixedDivergenceSlitType">
				<distanceToSample unit="mm">50.00</distanceToSample>
				<height unit="mm">1.52</height>
			</divergenceSlit>
		</incidentBeamPath>
		<beamKnife id="29030100" name="Beam knife low"/>
		<sampleMovement xsi:type="spinningSampleMovementType">
			<spinnerRevolutionTime unit="seconds">1.0</spinnerRevolutionTime>
		</sampleMovement>
		<diffractedBeamPath>
			<radius unit="mm">145.00</radius>
			<antiScatterSlit id="22090040" name="AS slit 9 mm" xsi:type="fixedAntiScatterSlitType">
				<height unit="mm">9.00</height>
			</antiScatterSlit>
			<sollerSlit id="21020003" name="Large Soller slits 0.04 rad.">
				<opening unit="rad">0.0400</opening>
			</sollerSlit>
			<filter id="20030001" name="Large beta-filter Nickel">
				<material>Ni</material>
				<thickness unit="mm">0.020</thickness>
			</filter>
			<detector id="7010019" name="PIXcel1D-Medipix3 detector" xsi:type="rtmsDetectorType">
				<phd unit="keV">
					<lowerLevel>4.0</lowerLevel>
					<upperLevel>11.3</upperLevel>
				</phd>
				<mode>Scanning</mode>
				<activeLength unit="deg">5.020</activeLength>
			</detector>
		</diffractedBeamPath>
		<scan appendNumber="0" mode="Continuous" scanAxis="Gonio" status="Completed">
			<header>
				<startTimeStamp>2024-03-24T16:57:44-07:00</startTimeStamp>
				<endTimeStamp>2024-03-24T17:10:12-07:00</endTimeStamp>
				<author>
					<name>AutomatedUser</name>
				</author>
				<source>
					<applicationSoftware version="1.6 (94)">PANalytical Aeris Instrument Suite</applicationSoftware>
					<instrumentControlSoftware version="3.0.0 20211014">AERIS</instrumentControlSoftware>
					<instrumentID>2879380</instrumentID>
				</source>
			</header>
			<dataPoints>
				<positions axis="2Theta" unit="deg">
					<startPosition>9.99043322</startPosition>
					<endPosition>100.09495370</endPosition>
				</positions>
				<positions axis="Omega" unit="deg">
					<startPosition>4.99521661</startPosition>
					<endPosition>50.04747685</endPosition>
				</positions>
				<commonCountingTime unit="seconds">18.249</commonCountingTime>
				<counts unit="counts">4723 4621 4671 4668 4567 4698 4565 4620 4676 4602 4636 4629 4635 4561 4660 4643 4469 4560 4577 4466 4583 4625 4568 4570 4538 4748 4670 4606 4515 4630 4470 4541 4563 4528 4566 4378 4567 4490 4529 4476 4548 4539 4502 4645 4419 4454 4522 4523 4445 4523 4412 4484 4480 4388 4538 4402 4483 4398 4427 4361 4507 4496 4427 4466 4493 4354 4437 4402 4417 4398 4378 4442 4325 4395 4375 4306 4583 4416 4233 4353 4400 4441 4349 4484 4288 4452 4448 4335 4256 4442 4255 4296 4281 4350 4225 4325 4378 4290 4344 4268 4356 4206 4379 4243 4334 4168 4210 4259 4342 4166 4235 4085 4184 4312 4246 4346 4334 4238 4158 4263 4174 4281 4222 4263 4228 4226 4140 4192 4200 4164 4292 4230 4169 4222 4135 4093 4204 3995 4118 4245 4170 4269 4112 4181 4202 4160 4099 4156 4145 4187 4146 4050 4109 4070 4085 4083 4105 4098 4143 4111 4047 4025 4136 4080 4135 4053 4041 4067 4069 4137 4089 4052 4051 4053 3867 4131 4078 4040 4024 3973 4056 4144 4112 4102 4116 4019 4028 4049 4133 4030 4066 3861 4049 4091 4099 4061 3927 3979 4004 4029 3992 3910 4070 4065 4131 4003 4017 3913 3902 3868 3916 3852 3954 3899 3969 3936 3906 3972 3914 3883 3955 3889 4070 3935 3923 3882 3847 3894 4003 3927 3918 3998 3808 3783 3970 3929 3877 3883 3905 3830 3750 3888 3965 3935 3873 3830 3913 3993 3784 3845 3873 3943 3968 3807 3833 3868 3846 3789 3925 3875 3765 3851 3817 3806 3890 3911 3955 3967 3982 3965 4178 4009 4121 4120 4266 4158 4066 4042 3976 3870 3871 3802 3854 3738 3875 3790 3895 3726 3837 3678 3894 3739 3820 3876 3893 3790 3734 3870 3730 3868 3852 3816 3758 3772 3763 3757 3656 3787 3708 3780 3691 3789 3748 3802 3793 3736 3705 3738 3574 3706 3671 3662 3685 3731 3755 3673 3741 3756 3801 3736 3644 3746 3650 3735 3798 3667 3706 3633 3685 3674 3677 3517 3710 3676 3851 3583 3672 3685 3684 3630 3720 3602 3802 3745 3729 3548 3666 3691 3672 3763 3510 3678 3611 3726 3694 3740 3713 3604 3616 3675 3763 3636 3550 3779 3727 3723 3618 3531 3535 3655 3590 3621 3556 3586 3607 3706 3658 3660 3676 3656 3563 3583 3594 3624 3625 3667 3645 3552 3577 3585 3658 3672 3641 3533 3568 3657 3583 3606 3516 3659 3422 3619 3566 3671 3589 3483 3660 3631 3580 3602 3507 3618 3559 3573 3608 3565 3623 3507 3518 3621 3563 3558 3559 3499 3560 3538 3535 3575 3560 3655 3561 3689 3530 3583 3463 3507 3601 3560 3452 3507 3544 3684 3563 3587 3562 3456 3687 3552 3613 3533 3569 3586 3521 3641 3578 3554 3631 3717 3564 3699 3758 3674 3695 3675 3643 3664 3755 3747 3787 3912 3703 3906 3915 3963 3938 3946 4076 4117 4308 4181 4349 4401 4521 4584 4714 4876 5050 5310 5287 5391 5608 5724 6082 6076 6316 6400 6592 6757 6873 6744 6636 6478 6126 5707 5287 5031 4823 4422 4274 4120 4067 3930 3832 3765 3884 3855 3916 3837 3784 3662 3839 3650 3664 3856 3589 3768 3669 3637 3683 3554 3573 3539 3547 3532 3447 3529 3520 3595 3453 3553 3507 3571 3575 3538 3388 3521 3555 3495 3443 3468 3500 3573 3440 3477 3617 3408 3550 3471 3517 3474 3612 3440 3413 3561 3518 3489 3471 3448 3548 3563 3494 3584 3439 3624 3464 3406 3469 3588 3540 3504 3526 3399 3505 3441 3492 3611 3557 3571 3664 3611 3675 3559 3752 3591 3659 3640 3547 3695 3629 3772 3825 3810 3896 4024 4034 3937 4041 4088 4055 4181 4267 4264 4401 4328 4228 4160 4067 4115 4051 4130 4037 4085 4054 4060 4103 4380 4259 4399 4337 4424 4572 4520 4582 4628 4629 4536 4676 4467 4569 4549 4470 4331 4404 4291 4112 4156 4076 4004 3900 3909 3714 3733 3659 3650 3593 3570 3548 3624 3616 3442 3632 3457 3512 3467 3440 3430 3534 3606 3639 3609 3514 3369 3413 3470 3424 3441 3484 3409 3471 3429 3411 3503 3398 3466 3374 3378 3501 3397 3449 3464 3517 3475 3391 3459 3468 3428 3399 3516 3265 3496 3461 3469 3496 3444 3474 3429 3414 3442 3393 3490 3504 3350 3358 3365 3502 3273 3330 3472 3378 3374 3420 3322 3367 3379 3320 3434 3399 3331 3328 3399 3343 3295 3347 3396 3320 3347 3391 3306 3345 3269 3351 3351 3351 3376 3448 3341 3358 3247 3282 3141 3235 3247 3410 3234 3323 3217 3253 3363 3317 3292 3341 3283 3329 3410 3309 3412 3306 3364 3349 3458 3227 3252 3283 3293 3224 3319 3196 3265 3229 3159 3300 3192 3286 3340 3302 3293 3270 3315 3405 3255 3386 3228 3235 3299 3226 3211 3281 3318 3198 3258 3285 3272 3328 3266 3311 3285 3375 3429 3413 3333 3516 3353 3458 3470 3414 3352 3383 3380 3322 3407 3355 3283 3296 3209 3295 3253 3198 3203 3264 3225 3085 3220 3336 3238 3117 3137 3179 3235 3222 3151 3185 3145 3256 3070 3188 3223 3171 3174 3097 3304 3214 3161 3164 3171 3180 3176 3112 3063 3275 3104 3073 3267 3137 3172 3145 3244 3242 3166 3180 3138 3188 3253 3207 3308 3104 3166 3236 3127 3128 3268 3263 3222 3212 3282 3233 3299 3220 3257 3310 3400 3299 3250 3264 3370 3317 3319 3286 3301 3357 3258 3312 3426 3362 3416 3309 3385 3373 3514 3479 3583 3543 3629 3507 3554 3604 3648 3648 3801 3783 3766 3928 3892 3999 4120 4161 4176 4423 4591 4978 4999 5137 5377 5641 5837 6296 6520 7111 7397 8130 8629 9165 9768 10521 11244 11861 12381 13125 14003 14134 14512 14648 14299 14018 13388 12573 11632 10614 9654 8514 7626 6850 6283 5956 5647 5421 5041 4953 4730 4480 4423 4240 4231 3856 3883 3721 3617 3585 3654 3541 3529 3521 3606 3557 3649 3522 3652 3705 3577 3719 3699 3672 3710 3627 3609 3611 3555 3594 3289 3429 3271 3307 3316 3237 3284 3241 3095 3228 3128 3198 3117 3249 3282 3219 3155 3224 3266 3176 3233 3335 3314 3164 3330 3299 3378 3468 3466 3466 3391 3663 3498 3596 3705 3685 3658 3685 3582 3406 3403 3263 3244 3305 3311 3232 3168 3297 3238 3292 3266 3135 3230 3216 3275 3317 3267 3342 3317 3269 3521 3391 3429 3528 3481 3572 3781 3659 3865 3868 4069 4320 4427 4521 4672 4826 4912 5155 5426 5732 5869 6030 6040 6137 6260 6264 6219 6087 5871 5638 5444 5135 4993 4547 4301 4175 3962 3907 3769 3674 3705 3582 3642 3546 3518 3672 3448 3560 3595 3588 3614 3645 3689 3880 3661 3826 3866 3904 4143 4198 4178 4164 4388 4352 4576 4546 4784 4871 5189 5426 5347 5670 5798 6064 6289 6463 6606 6677 6876 7015 7034 7086 6954 6668 6530 6355 5977 5747 5558 5153 4919 4741 4508 4409 4080 4106 3920 3808 3641 3658 3595 3524 3609 3599 3576 3372 3438 3356 3333 3186 3272 3320 3308 3292 3294 3232 3215 3261 3233 3183 3246 3255 3237 3277 3276 3273 3286 3325 3250 3241 3314 3290 3274 3375 3291 3461 3411 3484 3376 3413 3588 3656 3786 3846 3748 3920 3887 4193 4200 4435 4399 4532 4787 4885 4951 5050 5179 5271 5475 5462 5554 5736 5616 5581 5540 5474 5675 5503 5523 5460 5385 5355 5413 5110 5363 5342 5273 5132 5155 5125 5054 4882 4654 4510 4362 4226 3972 3909 3802 3717 3524 3574 3371 3368 3272 3349 3307 3186 3115 3190 3157 3105 3193 3153 3165 3042 3101 3029 3197 2968 3048 2971 3080 3083 3011 2996 2985 3111 3048 2968 3005 2966 3029 2955 3043 2902 2942 2957 2952 3102 2910 2939 2903 2844 2916 2960 2914 2911 2856 2829 2901 2851 2974 2845 2981 2846 2945 2841 2905 2939 2917 2888 2911 2891 2827 2916 2812 2802 2883 2928 2847 2970 3014 2893 2924 2945 2908 2950 2941 3114 2914 3010 3037 2924 2933 3047 3173 3067 3073 3075 3104 2985 3091 2995 3210 3207 3268 3408 3267 3348 3364 3229 3393 3544 3482 3467 3596 3409 3669 3762 3752 3787 3933 3919 4127 4177 4096 4268 4316 4427 4358 4393 4290 4487 4317 4447 4279 4186 4284 4331 4291 4209 4255 4132 4122 4122 4102 4065 4180 4017 3945 3909 3913 3682 3720 3553 3573 3523 3481 3520 3564 3430 3565 3474 3517 3461 3357 3380 3373 3219 3159 3183 3067 2997 2939 3079 2937 2925 3014 2945 3008 2826 2965 2943 2983 3114 3003 2977 2938 3186 3078 2982 3022 3238 3191 3212 3255 3260 3254 3158 3123 3177 3202 3131 3094 3014 3076 3077 2933 2948 2952 2951 3069 3030 2919 3031 3091 3033 3082 3036 3104 3123 3028 2980 3048 3082 3042 3065 3124 3141 3214 3200 3260 3410 3514 3592 3708 4050 4089 4292 4688 5024 5521 5789 6389 6762 7356 7964 8443 9121 9472 9850 10096 9881 9492 8805 8177 7423 6924 6471 5868 5235 4578 4150 3838 3553 3356 3260 3107 2970 3037 3068 2979 2953 2911 2890 2819 2926 2803 2850 2783 2831 2857 2766 2826 2777 2843 2793 2808 2824 2765 2838 2825 2749 2751 2721 2867 2851 2911 2890 2942 2953 2996 3113 3109 3289 3169 3196 3106 3096 2953 2988 2835 2924 3017 2903 2753 2661 2720 2774 2773 2739 2709 2660 2722 2727 2616 2644 2664 2812 2650 2708 2635 2675 2583 2643 2678 2624 2556 2693 2667 2672 2675 2642 2516 2649 2631 2579 2572 2598 2553 2616 2670 2737 2737 2644 2675 2612 2630 2665 2619 2573 2695 2714 2703 2693 2654 2624 2666 2629 2719 2686 2677 2664 2648 2550 2632 2688 2685 2594 2631 2637 2602 2555 2580 2686 2683 2668 2643 2573 2638 2656 2577 2677 2658 2563 2602 2594 2639 2686 2593 2642 2561 2548 2640 2719 2669 2633 2662 2635 2561 2631 2522 2513 2613 2601 2620 2530 2650 2525 2575 2473 2454 2682 2551 2607 2583 2572 2612 2650 2567 2577 2584 2590 2588 2602 2621 2595 2561 2671 2574 2588 2533 2453 2686 2570 2493 2525 2649 2549 2544 2553 2680 2512 2579 2464 2538 2562 2532 2541 2613 2650 2547 2604 2580 2555 2465 2632 2639 2554 2580 2622 2509 2726 2631 2605 2616 2658 2653 2598 2763 2608 2733 2704 2722 2699 2728 2754 2733 2690 2718 2740 2927 2884 2810 2886 2946 2878 3070 3098 3007 3046 3040 2955 3047 3025 3256 3137 3059 3124 3240 3221 3219 3147 3184 3196 3218 3273 3285 3252 3335 3258 3322 3354 3410 3457 3493 3580 3592 3705 3740 3796 3797 3655 3722 3795 3607 3575 3532 3313 3282 3210 3151 2954 2919 2946 2843 2847 2693 2705 2627 2658 2686 2623 2670 2553 2589 2588 2581 2532 2614 2563 2722 2673 2581 2582 2577 2633 2616 2573 2615 2505 2503 2518 2587 2583 2583 2535 2519 2382 2550 2610 2558 2606 2525 2428 2620 2464 2546 2477 2525 2608 2563 2514 2543 2545 2555 2525 2586 2618 2625 2535 2653 2540 2615 2714 2529 2706 2687 2649 2700 2782 2789 2747 2809 2678 2874 2869 2842 2965 2890 3055 3029 3062 3091 3130 3268 3323 3432 3532 3676 3778 3915 3971 4124 4143 4053 4063 3931 3826 3740 3632 3538 3463 3407 3309 3244 3209 3074 2941 2992 2843 2844 2846 2838 2896 2879 2838 2885 2816 2874 2757 2825 2849 2770 2783 2718 2735 2838 2733 2835 2807 2811 2814 2913 2963 2962 2981 3042 3054 3256 3229 3363 3553 3700 3915 4111 4216 4687 4739 5146 5343 5900 6113 6531 6936 7298 7540 7671 7937 7877 7914 7814 7711 7241 7062 6403 5938 5694 5329 4828 4614 4190 3977 3684 3427 3363 3206 3042 2845 2879 2804 2671 2707 2681 2691 2712 2732 2699 2573 2673 2670 2665 2622 2648 2570 2577 2731 2655 2664 2674 2674 2739 2623 2719 2764 2847 2805 2933 2896 3001 3288 3154 3198 3244 3179 3295 3330 3448 3210 3175 3132 3051 3062 3068 2909 2877 2827 2806 2687 2698 2611 2580 2621 2647 2604 2558 2693 2634 2483 2663 2479 2529 2605 2665 2710 2648 2658 2732 2653 2648 2680 2737 2818 2723 2694 2799 2643 2813 2706 2807 2830 2837 2865 2866 2913 3020 3022 3059 3055 3125 3257 3355 3408 3498 3598 3855 4101 4328 4499 4763 4915 5209 5380 5424 5624 5539 5503 5402 5196 5223 4964 5119 4985 4803 4764 4665 4250 4254 4094 4055 3774 3701 3679 3579 3391 3247 3239 3165 3016 2984 2866 2860 2852 2714 2721 2670 2672 2684 2743 2654 2558 2510 2548 2623 2510 2543 2493 2635 2593 2622 2515 2614 2684 2583 2573 2564 2639 2633 2724 2649 2667 2724 2807 2714 2741 2777 2817 3087 3003 3093 3155 3258 3348 3507 3522 3635 3681 3725 3848 3800 3826 3907 4003 3926 3861 3919 3948 3966 3830 3825 3888 3768 3659 3494 3483 3386 3413 3279 3196 3124 3012 3110 2986 3067 2971 2978 3075 3155 3106 3220 3194 3188 3167 3144 3210 3209 3064 3166 3098 3285 3050 3200 3161 3127 3249 3238 3224 3269 3406 3421 3489 3685 3633 3710 3921 4097 4305 4380 4466 4635 4785 4997 5214 5305 5409 5516 5566 5589 5551 5472 5566 5517 5358 5282 5339 5299 5128 4812 4638 4635 4562 4507 4599 4564 4505 4591 4801 4716 4753 5062 5129 5298 5614 5801 5974 6363 6517 6921 7236 7493 7508 7785 7770 7517 7267 6856 6442 6302 5786 5540 5360 4999 4799 4445 4171 3809 3666 3677 3453 3423 3406 3268 3253 3139 3090 3238 3125 3249 3199 3152 3341 3311 3273 3240 3294 3270 3236 3239 3238 3327 3194 3325 3280 3351 3263 3198 3383 3493 3400 3631 3662 3836 3958 4083 4132 4611 4599 4896 5046 5262 5447 5581 5450 5385 5402 5281 5186 5037 4904 4827 4840 4662 4510 4511 4615 4328 4292 4190 4016 4122 4219 4135 4249 4340 4407 4540 4625 4704 4904 5075 5244 5555 5809 6264 6616 7220 7511 8221 8820 9393 10263 10657 11319 11985 12600 13020 13580 14027 14302 15026 14773 15528 15840 15887 16019 15724 15504 15172 14653 13958 13440 12799 12104 11555 11009 10440 9858 9253 8701 8274 7851 7339 6830 6380 6033 5596 5188 4945 4820 4598 4524 4234 4181 3722 3842 3729 3622 3513 3384 3353 3350 3375 3380 3304 3217 3203 3309 3334 3298 3240 3265 3258 3121 3219 3104 3144 3156 3165 3188 3149 3040 3190 3017 3026 3085 2924 2929 2878 2775 2876 2828 2931 2829 2755 2854 2765 2842 2805 2789 2795 2948 2854 3020 2986 3062 3076 3126 3224 3410 3401 3492 3543 3592 3680 3701 3564 3660 3719 3652 3664 3609 3632 3620 3634 3622 3450 3431 3284 3298 3306 3190 3063 3055 3044 2979 3030 2923 3001 3011 3080 2890 3005 3065 2967 2979 3020 3036 2990 2992 3037 3048 3026 3028 3115 3044 3132 3121 3229 3285 3251 3368 3185 3428 3279 3384 3261 3154 3269 3145 3107 3088 3009 2995 2868 2934 2790 2777 2847 2684 2728 2738 2678 2608 2679 2803 2719 2829 2743 2816 2796 2869 2852 2969 2916 2789 2934 2860 2888 2802 2965 2939 2938 2829 2913 2726 2819 2742 2783 2710 2763 2767 2822 2723 2644 2734 2613 2722 2600 2677 2657 2625 2651 2500 2688 2625 2691 2706 2716 2539 2653 2696 2635 2508 2685 2645 2561 2732 2739 2615 2668 2741 2584 2696 2763 2689 2812 2838 2778 2811 2761 2881 2815 2803 2975 2913 2875 2924 2928 2980 3040 2913 2975 3038 3093 3095 3057 3158 3100 3203 3163 3086 3169 3221 3268 3363 3429 3427 3412 3496 3675 3734 3796 3807 3887 3953 4091 4189 4339 4497 4615 4799 4947 5144 5411 5740 5991 6144 6403 6621 7031 7578 7986 8456 8836 9325 9905 10515 11249 11493 12288 12930 13424 13922 14506 14595 15047 15217 15478 15209 15123 15209 14658 14204 13672 13310 12804 12421 12182 11398 11218 10758 10298 9925 9677 9343 8965 8642 8443 8181 8046 7755 7764 7581 7364 7218 7242 6750 6899 6704 6633 6262 5888 5649 5240 5144 4809 4602 4530 4385 4171 3830 3862 3572 3484 3361 3276 3167 3126 2967 3006 2868 2932 2980 2822 2794 2698 2715 2717 2796 2617 2747 2652 2608 2659 2583 2586 2624 2513 2578 2613 2614 2545 2539 2430 2469 2472 2525 2505 2374 2491 2425 2509 2484 2503 2422 2541 2471 2397 2482 2526 2473 2397 2455 2370 2430 2484 2364 2414 2434 2427 2390 2462 2417 2508 2460 2466 2442 2383 2497 2480 2418 2597 2446 2543 2440 2572 2585 2480 2552 2513 2488 2433 2505 2424 2472 2453 2492 2447 2507 2490 2481 2363 2405 2420 2340 2341 2350 2411 2299 2310 2309 2387 2456 2361 2275 2313 2283 2452 2318 2326 2398 2510 2361 2424 2362 2333 2326 2389 2285 2440 2341 2389 2410 2328 2322 2348 2279 2411 2304 2330 2274 2326 2326 2304 2353 2318 2355 2186 2310 2366 2219 2268 2276 2336 2229 2360 2245 2251 2214 2326 2308 2288 2375 2218 2271 2261 2347 2314 2351 2386 2340 2333 2348 2328 2466 2305 2286 2391 2345 2385 2459 2405 2536 2485 2549 2612 2585 2631 2732 2934 2872 2959 2960 3165 3263 3278 3330 3429 3499 3514 3726 3586 3611 3606 3519 3421 3309 3325 3196 3143 3128 3135 3003 2908 2827 2713 2824 2703 2667 2665 2633 2536 2508 2594 2549 2553 2510 2635 2559 2655 2622 2697 2663 2664 2629 2628 2568 2577 2543 2516 2459 2471 2528 2423 2499 2441 2450 2492 2486 2517 2420 2495 2511 2598 2566 2618 2701 2674 2536 2677 2716 2640 2732 2799 2870 2801 2870 2949 2861 2920 2970 3012 3002 3021 2874 2810 2829 2799 2763 2819 2702 2746 2773 2696 2653 2675 2741 2600 2560 2526 2568 2457 2547 2368 2477 2434 2520 2378 2409 2355 2402 2309 2288 2313 2381 2233 2208 2306 2257 2148 2253 2286 2319 2290 2226 2253 2205 2303 2221 2239 2248 2227 2198 2167 2247 2171 2190 2176 2143 2145 2195 2252 2231 2189 2184 2191 2142 2213 2157 2292 2179 2256 2256 2212 2234 2217 2204 2198 2132 2126 2284 2221 2195 2254 2298 2254 2298 2199 2311 2259 2223 2161 2299 2194 2183 2219 2181 2230 2235 2246 2221 2258 2241 2275 2278 2216 2325 2246 2194 2212 2243 2258 2331 2245 2336 2342 2311 2356 2278 2324 2319 2314 2308 2342 2222 2369 2310 2369 2389 2426 2385 2331 2287 2347 2237 2182 2357 2265 2286 2350 2361 2256 2244 2242 2292 2179 2277 2281 2250 2206 2302 2244 2305 2263 2260 2333 2236 2283 2367 2376 2411 2391 2354 2369 2309 2388 2371 2406 2305 2257 2274 2234 2286 2305 2205 2262 2210 2170 2174 2126 2171 2237 2103 2186 2213 2123 2164 2225 2163 2220 2210 2158 2095 2200 2089 2113 2170 2130 2158 2113 2142 2136 2137 2226 2158 2195 2153 2163 2130 2150 2155 2249 2174 2220 2146 2094 2104 2199 2191 2080 2128 2206 2154 2182 2097 2039 2202 2001 2141 2123 2135 2082 2157 2165 2086 2221 2129 2226 2132 2095 2083 2059 2197 2123 2031 2152 2196 2075 2102 2179 2111 2054 2141 2155 2103 2088 2130 2115 2063 2199 2116 2096 2091 2065 2140 2164 2134 2224 2148 2090 2099 2178 2129 2200 2109 2082 2113 2190 2162 2145 2175 2168 2126 2155 2229 2092 2147 2180 2155 2206 2176 2181 2162 2241 2160 2246 2186 2205 2215 2231 2289 2317 2313 2244 2436 2361 2473 2527 2437 2542 2633 2781 2851 2890 2975 2961 3074 3146 3174 3100 3112 3026 2990 2954 2824 2844 2818 2968 2765 2774 2749 2744 2732 2556 2568 2463 2513 2308 2369 2413 2299 2258 2213 2205 2283 2241 2200 2266 2277 2280 2256 2162 2232 2122 2203 2140 2200 2160 2255 2120 2281 2199 2256 2203 2290 2248 2289 2199 2272 2263 2166 2164 2161 2144 2280 2251 2295 2225 2236 2245 2279 2252 2361 2343 2332 2378 2358 2497 2530 2527 2519 2496 2540 2540 2523 2537 2622 2632 2632 2613 2642 2595 2768 2658 2744 2725 2791 2719 2641 2639 2688 2696 2520 2478 2530 2496 2505 2581 2396 2548 2341 2337 2325 2254 2250 2244 2183 2238 2237 2208 2219 2108 2184 2231 2194 2187 2150 2079 2153 2114 2166 2121 2213 2111 2193 2109 2163 2203 2214 2137 2247 2232 2176 2199 2167 2204 2174 2208 2256 2169 2274 2218 2181 2177 2243 2303 2202 2250 2277 2252 2294 2278 2295 2338 2351 2354 2334 2380 2514 2527 2646 2855 2858 3036 3155 3322 3521 3663 3748 3818 3821 3874 3651 3505 3283 3295 3168 3229 3169 3183 3232 3089 3067 2957 2790 2672 2697 2512 2495 2573 2268 2390 2405 2385 2367 2418 2238 2312 2342 2357 2395 2472 2406 2468 2465 2527 2549 2668 2807 2684 2906 2801 2933 3080 3056 3134 3175 3259 3159 2994 2863 3014 2722 2734 2799 2659 2850 2747 2725 2756 2513 2579 2602 2408 2402 2445 2418 2431 2391 2275 2386 2343 2302 2388 2266 2328 2280 2349 2336 2236 2329 2345 2312 2399 2357 2345 2462 2423 2331 2467 2415 2422 2424 2428 2552 2454 2635 2657 2711 2717 2676 2780 2758 2723 2759 3020 2896 2972 3070 3029 3189 3400 3251 3381 3373 3420 3714 3720 3867 4010 4148 4321 4410 4757 4687 4864 5125 5217 5318 5550 5705 5736 5657 5693 5758 5726 5868 5777 5669 5462 5427 5350 5214 5145 4924 4773 4606 4513 4371 4241 4047 4006 3795 3633 3621 3345 3310 3242 3213 3008 3045 2938 2906 2853 2823 2726 2832 2664 2622 2673 2684 2550 2632 2568 2499 2515 2540 2517 2486 2536 2531 2587 2469 2467 2461 2451 2609 2546 2378 2607 2577 2450 2554 2469 2583 2580 2704 2510 2587 2544 2474 2513 2457 2395 2527 2443 2391 2437 2479 2413 2378 2368 2321 2337 2362 2340 2252 2277 2233 2303 2103 2187 2214 2234 2188 2190 2209 2127 2262 2196 2194 2116 2151 2191 2150 2168 2120 2206 2118 2166 2124 2139 2145 2169 2206 2174 2089 2142 2196 2180 2141 2204 2155 2131 2061 2069 2099 2137 2156 2148 2117 2113 2134 2189 2141 2135 2177 2161 2232 2127 2227 2264 2189 2203 2158 2230 2232 2277 2111 2238 2284 2177 2302 2192 2301 2230 2391 2433 2355 2333 2351 2284 2236 2336 2277 2341 2296 2287 2329 2334 2309 2358 2425 2343 2372 2453 2395 2403 2430 2482 2463 2347 2470 2472 2521 2406 2460 2457 2475 2485 2464 2446 2444 2458 2423 2531 2455 2497 2450 2509 2525 2526 2580 2524 2636 2600 2585 2491 2625 2661 2662 2751 2689 2751 2757 2847 3009 3035 3242 3194 3351 3582 3738 3973 4139 4192 4231 4224 4126 3966 3690 3618 3543 3530 3247 3485 3537 3455 3528 3398 3305 3285 3102 2872 2889 2808 2776 2701 2716 2676 2694 2772 2613 2632 2583 2599 2596 2574 2576 2562 2573 2517 2516 2550 2515 2465 2520 2455 2479 2451 2425 2364 2401 2393 2426 2307 2335 2377 2355 2400 2255 2375 2346 2371 2432 2436 2483 2521 2629 2624 2650 2812 2883 3033 3155 3077 3243 3196 3199 3203 3047 2937 2932 2940 2837 2773 2668 2792 2689 2633 2729 2734 2628 2512 2527 2497 2446 2377 2387 2242 2273 2270 2165 2119 2184 2196 2128 2140 2250 2133 2187 2070 2183 2158 2127 2221 2220 2164 2190 2157 2294 2143 2263 2302 2243 2108 2174 2189 2302 2257 2240 2180 2194 2164 2257 2188 2153 2137 2209 2232 2148 2192 2128 2260 2245 2233 2218 2197 2321 2234 2229 2283 2370 2460 2311 2419 2397 2420 2324 2330 2258 2296 2283 2295 2319 2349 2303 2354 2339 2416 2358 2368 2381 2303 2324 2270 2311 2304 2301 2254 2330 2260 2291 2345 2241 2375 2386 2344 2372 2408 2427 2435 2463 2375 2447 2495 2543 2563 2591 2655 2665 2626 2704 2702 2778 2790 2734 2789 2808 2877 2860 3040 2941 2994 3061 3001 3077 3000 2941 3029 2867 2822 2808 2875 2774 2732 2779 2751 2695 2617 2770 2587 2557 2645 2640 2568 2617 2598 2537 2431 2437 2450 2482 2547 2480 2435 2345 2372 2268 2259 2325 2288 2233 2267 2340 2280 2289 2231 2240 2230 2206 2119 2123 2200 2115 2114 2125 2133 2089 2058 2110 2115 2230 2157 2193 2080 2086 2082 2080 2118 2187 2084 2111 2200 2140 2072 2053 2088 2023 2116 2109 2036 2083 2094 2137 2164 2164 2190 2113 2075 2085 2086 2078 2103 2137 2133 2126 2235 2120 2155 2186 2196 2159 2165 2158 2186 2124 2188 2124 2207 2234 2195 2174 2237 2288 2182 2226 2269 2122 2253 2233 2119 2198 2234 2220 2048 2072 2098 2258 2147 2142 2075 2149 2200 2127 2229 2145 2067 2100 2095 2092 2142 2099 2200 2222 2229 2156 2296 2251 2196 2273 2300 2299 2403 2292 2306 2375 2356 2406 2330 2433 2300 2270 2266 2261 2283 2291 2297 2291 2306 2300 2314 2338 2266 2222 2245 2278 2260 2273 2211 2196 2327 2281 2333 2292 2229 2409 2434 2548 2637 2706 2667 2658 2700 2759 2706 2824 2753 2829 2773 2909 2889 3021 2947 2994 3036 2831 2924 2892 2741 2719 2778 2737 2782 2755 2682 2638 2637 2683 2610 2473 2484 2432 2466 2443 2343 2344 2269 2310 2245 2232 2249 2214 2304 2254 2181 2167 2179 2171 2086 2080 2079 2108 2161 2128 2137 2144 2250 2208 2098 2191 2117 2199 2233 2264 2289 2238 2339 2233 2400 2386 2329 2378 2256 2308 2300 2312 2299 2218 2178 2170 2223 2236 2212 2231 2195 2152 2203 2233 2189 2088 2082 2151 2037 2046 2097 2081 2066 2125 2126 2062 1983 2040 2114 2146 2129 2139 2060 2140 2027 2088 2088 2198 2113 2150 2112 2156 2172 2127 2059 2069 2106 2148 2016 2149 2081 2129 2142 2094 2103 2083 1987 2165 2148 2140 2123 2116 2023 2113 2084 2174 2090 2165 2057 2057 2154 2119 2183 2155 2141 2133 2158 2220 2200 2200 2266 2293 2270 2251 2229 2298 2295 2313 2309 2330 2488 2418 2455 2463 2623 2640 2559 2585 2553 2618 2568 2473 2497 2520 2510 2609 2608 2646 2700 2681 2708 2723 2664 2721 2670 2599 2648 2616 2640 2505 2496 2532 2476 2483 2469 2432 2409 2447 2420 2427 2400 2436 2342 2356 2385 2367 2245 2366 2245 2310 2389 2333 2440 2370 2460 2394 2391 2400 2496 2562 2442 2528 2542 2587 2578 2611 2656 2639 2608 2799 2825 2926 2915 2932 2938 3004 3112 2927 3141 3018 3263 3190 3254 3253 3243 3217 3315 3388 3385 3415 3414 3440 3397 3399 3261 3481 3366 3362 3252 3179 3240 3330 3183 3017 3064 3116 3144 3086 3140 3122 3140 3067 3022 2893 2868 2900 2895 2636 2680 2615 2624 2637 2620 2600 2509 2611 2538 2595 2434 2457 2465 2445 2511 2390 2486 2384 2504 2423 2447 2391 2472 2482 2362 2484 2347 2475 2462 2526 2592 2605 2649 2659 2760 2752 2741 2750 2831 2771 2696 2743 2685 2637 2665 2670 2566 2521 2532 2508 2566 2611 2556 2400 2489 2483 2515 2475 2338 2338 2272 2325 2250 2208 2212 2086 2147 2211 2129 2161 2239 2122 2050 2141 2103 2045 2129 2084 2251 2013 2090 2035 2051 2117 2089 2125 2055 2141 2025 2113 2088 1965 2148 1962 2094 2119 2185 2103 2107 2040 2074 2150 2096 2047 2147 2105 2020 2027 2064 2136 2104 2115 2110 2086 2093 2102 2190 2128 2235 2127 2109 2086 2243 2287 2253 2170 2218 2192 2274 2246 2342 2268 2314 2302 2329 2334 2358 2332 2286 2272 2295 2299 2231 2345 2311 2215 2341 2286 2295 2341 2304 2347 2219 2345 2324 2298 2208 2355 2249 2237 2210 2299 2350 2239 2355 2355 2357 2395 2427 2347 2463 2403 2574 2515 2545 2580 2500 2599 2550 2575 2486 2580 2642 2621 2634 2558 2594 2598 2566 2556 2543 2495 2449 2474 2496 2511 2468 2478 2405 2375 2545 2487 2523 2387 2523 2454 2488 2414 2596 2511 2633 2634 2573 2574 2717 2791 2757 2710 2857 2878 3006 3068 3156 3223 3304 3389 3396 3590 3736 3696 3856 3953 3877 3821 3759 3563 3566 3517 3422 3400 3309 3350 3388 3352 3413 3259 3500 3361 3405 3242 3266 3189 3148 3160 3090 3184 3130 3144 3126 3188 3311 3328 3590 3535 3612 3731 3878 3869 3989 3950 4110 4272 4177 4136 4133 4135 4067 3934 3990 3830 3969 3772 3649 3731 3584 3785 3656 3653 3754 3423 3509 3486 3260 3389 3384 3270 3308 3157 3287 3306 3293 3201 3231 3170 3104 3145 3074 3028 3035 2854 2972 2836 3025 2991 2972 3004 3090 3163 3190 3246 3456 3427 3495 3568 3542 3349 3310 3409 3183 3141 3056 2893 2968 2830 2955 2854 3035 3068 3155 3105 3085 3087 2930 2737 2867 2708 2551 2514 2371 2382 2349 2360 2321 2346 2343 2460 2323 2312 2343 2253 2205 2232 2158 2116 2167 2146 2116 2027 2091 2082 2109 2106 1982 2102 2177 2086 2150 2151 2146 2051 2052 2059 2079 2074 2119 2056 2027 2080 2070 2057 1995 2030 2106 2104 2055 2113 2065 2067 2167 2028 2070 2070 2057 2124 2093 2100 2131 2147 2137 2160 2160 2116 2309 2144 2153 2230 2225 2155 2168 2053 2133 2135 2106 2141 2134 2137 2175 2136 2160 2085 2179 2140 2056 2137 2119 2220 2123 2188 2131 2178 2090 1990 2139 1906 2094 2134 2138 2167 2142 2107 2149 2061 2123 2140 2117 2153 2093 2184 2098 2119 2180 2147 2170 2162 2111 2183 2245 2247 2234 2287 2209 2268 2231 2333 2286 2348 2364 2347 2396 2397 2343 2370 2253 2340 2279 2252 2239 2325 2243 2157 2238 2234 2205 2161 2189 2218 2197 2174 2141 2126 2127 2101 2163 2153 2145 2137 2192 2071 2134 2064 2085 2161 2139 2112 2082 2071 2200 2089 2198 2202 2242 2191 2276 2234 2412 2291 2364 2393 2389 2375 2321 2493 2431 2458 2435 2407 2476 2423 2446 2347 2412 2383 2399 2384 2414 2438 2534 2481 2410 2583 2539 2587 2505 2564 2513 2468 2336 2379 2446 2289 2250 2341 2237 2284 2285 2433 2311 2361 2309 2357 2269 2391 2247 2290 2304 2219 2192 2164 2223 2242 2131 2215 2243 2243 2268 2094 2380 2249 2252 2223 2293 2269 2212 2257 2204 2362 2312 2186 2345 2338 2352 2311 2356 2412 2318 2329 2263 2293 2285 2298 2345 2249 2216 2325 2339 2365 2359 2180 2339 2393 2321 2310 2364 2245 2387 2404 2373 2355 2372 2360 2422 2367 2384 2533 2473 2559 2467 2501 2475 2546 2611 2602 2728 2701 2715 2688 2748 2710 2836 2855 2818 2928 2936 2978 3092 3019 3051 3078 3197 3204 3229 3247 3257 3299 3252 3267 3302 3377 3392 3221 3384 3250 3355 3329 3171 3279 3331 3227 3377 3235 3360 3396 3365 3428 3498 3484 3490 3413 3571 3479 3449 3402 3381 3532 3388 3484 3579 3516 3515 3595 3631 3684 3838 3826 3859 3891 3994 3821 3810 3803 3756 3665 3763 3700 3510 3615 3476 3484 3402 3463 3280 3396 3387 3315 3315 3228 3154 3103 3195 2999 2882 2892 2763 2799 2756 2793 2676 2614 2611 2601 2579 2513 2396 2438 2392 2468 2415 2453 2453 2359 2422 2341 2347 2387 2360 2288 2287 2241 2234 2326 2257 2313 2315 2274 2332 2311 2279 2293 2431 2351 2356 2347 2323 2363 2281 2260 2296 2145 2166 2194 2169 2191 2216 2149 2185 2200 2220 2223 2214 2222 2146 2178 2202 2174 2257 2101 2221 2215 2202 2198 2185 2171 2164 2176 2167 2267 2235 2259 2165 2240 2217 2249 2240 2320 2282 2269 2308 2352 2347 2330 2355 2396 2297 2262 2383 2327 2403 2443 2500 2444 2498 2537 2507 2485 2615 2645 2714 2763 2765 2842 2761 2890 2998 2976 2972 3126 3276 3110 3139 3167 3116 3373 3422 3359 3140 3347 3355 3461 3527 3444 3541 3564 3716 3620 3571 3719 3717 3778 3861 3971 3788 3890 3803 3819 3835 3731 3753 3912 3824 3716 3743 3676 3633 3620 3477 3434 3411 3342 3338 3296 3219 3214 3261 3251 3140 3035 2977 3007 3008 3029 2890 2774 2736 2659 2559 2619 2623 2508 2524 2525 2540 2502 2431 2491 2388 2454 2435 2454 2391 2413 2383 2325 2362 2432 2347 2403 2449 2367 2452 2479 2415 2487 2514 2572 2565 2563 2546 2571 2525 2548 2559 2584 2572 2497 2500 2464 2546 2521 2549 2571 2528 2560 2478 2515 2520 2389 2348 2481 2514 2564 2492 2501 2549 2450 2460 2314 2437 2344 2352 2373 2295 2288 2275 2161 2246 2139 2245 2134 2197 2241 2204 2185 2141 2159 2207 2116 2113 2057 2104 2080 2081 2104 2067 2101 2129 2104 2134 2140 2138 2125 2138 2117 2098 2140 2090 2081 2105 2204 2196 2248 2169 2173 2267 2238 2302 2318 2318 2239 2300 2250 2294 2251 2196 2227 2161 2179 2192 2184 2227 2225 2106 2224 2260 2299 2202 2168 2196 2108 2144 2230 2208 2147 2142 2123 2161 2140 2047 2106 2033 2125 1971 2101 2109 2141 2147 2123 2116 2187 2144 2113 2106 2115 2141 2154 2220 2167 2201 2168 2185 2246 2275 2170 2208 2274 2303 2235 2253 2197 2252 2265 2306 2273 2329 2393 2379 2383 2374 2283 2305 2257 2238 2287 2249 2239 2165 2181 2161 2194 2125 2175 2212 2118 2158 2020 2091 2166 2098 2119 2057 2015 2032 2060 2088 2119 2081 2002 2004 2032 2028 1998 2017 2006 1981 1960 2057 1928 2010 1984 2025 2037 2052 1916 1945 1947 2056 1985 2078 1946 2009 2022 1997 2045 2004 2002 1974 1940 1995 2005 1918 2015 1966 1977 1998 2058 1950 2045 2059 2041 2015 1999 1981 2077 2004 2026 2088 2121 2004 2068 2085 2001 2024 2006 2065 2069 2051 1988 2130 1983 2061 2057 1956 2087 2032 2138 2002 2090 2075 1976 2068 2085 2120 2045 2115 2120 2107 2171 2174 2167 2171 2215 2069 2170 2246 2122 2210 2194 2247 2267 2263 2251 2281 2371 2284 2298 2369 2218 2305 2209 2263 2272 2206 2190 2256 2135 2251 2277 2267 2237 2270 2171 2274 2233 2230 2233 2204 2207 2238 2317 2203 2199 2285 2289 2313 2240 2310 2291 2319 2302 2341 2430 2560 2462 2624 2611 2665 2854 2759 2811 2930 3001 3024 3117 2979 3152 3027 3089 2969 2908 2918 3030 2956 2970 2880 2897 3036 2939 2820 2893 2915 2956 2958 2895 2793 2859 2822 2974 2802 2796 2768 2766 2837 2667 2723 2853 2841 2793 2722 2781 2822 2658 2707 2513 2581 2573 2552 2516 2441 2411 2495 2467 2477 2413 2470 2428 2444 2340 2403 2350 2403 2412 2314 2288 2272 2329 2267 2301 2205 2232 2269 2125 2267 2215 2214 2132 2147 2197 2231 2152 2148 2152 2164 2248 2159 2210 2176 2237 2198 2231 2158 2173 2226 2186 2080 2142 2227 2145 2203 2307 2208 2232 2104 2151 2162 2164 2282 2229 2160 2248 2173 2125 2260 2258 2228 2163 2139 2143 2210 2121 2359 2179 2255 2165 2243 2278 2224 2265 2197 2191 2153 2277 2242 2301 2251 2240 2259 2170 2233 2194 2294 2401 2221 2338 2215 2288 2279 2324 2247 2371 2263 2367 2280 2298 2326 2360 2302 2307 2341 2320 2317 2327 2292 2316 2320 2238 2368 2309 2279 2224 2357 2414 2379 2302 2266 2263 2245 2169 2201 2161 2360 2237 2280 2196 2121 2186 2186 2319 2217 2195 2163 2261 2281 2242 2245 2247 2351 2321 2292 2425 2393 2512 2468 2446 2466 2453 2386 2460 2452 2561 2401 2354 2350 2336 2256 2338 2341 2416 2267 2277 2310 2358 2383 2405 2346 2462 2383 2457 2426 2424 2499 2446 2488 2434 2520 2516 2559 2392 2580 2574 2532 2686 2733 2771 2713 2695 2749 2860 2837 2830 2782 2762 2798 2762 2777 2783 2747 2752 2668 2685 2745 2719 2650 2795 2693 2667 2766 2827 2673 2698 2769 2653 2688 2743 2684 2715 2705 2679 2686 2522 2579 2528 2678 2487 2559 2500 2484 2548 2487 2350 2469 2546 2406 2432 2384 2338 2433 2383 2339 2259 2342 2279 2290 2242 2191 2168 2201 2200 2104 2115 2061 2156 2027 2232 2094 2181 2122 2097 2085 2014 2117 2079 2154 2232 2058 2053 2120 2128 2060 2097 2095 2064 2047 2031 2171 2155 2097 2177 2163 2317 2190 2217 2230 2275 2332 2287 2234 2207 2182 2316 2215 2159 2082 2029 2072 2109 2164 2199 2229 2111 2110 2101 2013 2112 2157 2155 2109 2043 2165 2115 2108 2056 2002 2057 2122 2013 2011 2045 2000 2040 2091 2085 1976 1958 1968 1889 1987 1953 1962 2005 1970 2032 1970 2059 2116 1911 1948 1977 1981 1899 1962 2027 2009 1930 1978 1994 2020 1957 2060 2050 1999 2036 2026 2011 2054 1940 2009 2042 2054 2010 2059 2085 1976 2009 1951 2036 1991 2061 1911 1968 1992 2065 1952 1946 2075 1932 1989 2017 1959 2022 1951 1902 2088 1958 1969 1973 1938 2032 2102 1952 1933 1897 2006 1925 1955 1969 2102 1973 1997 1994 1999 2034 2026 2002 2060 2068 1997 2014 1978 2013 1922 2026 2117 2030 2005 1970 2050 2008 2103 2099 2097 2079 2085 2028 1983 2029 1967 1977 1993 2012 2056 1975 1924 1923 1944 2025 2021 1933 1992 2094 2004 1964 2041 1984 1979 1913 2012 1928 1977 1969 1965 2011 2000 1921 1997 1954 2073 2009 1968 2000 1963 1990 1932 1955 1985 2067 2019 2003 1937 1929 1986 2104 1999 1977 2034 2097 2034 2114 2082 2132 2180 2164 2166 2136 2114 2181 2141 2091 2099 2078 2126 2079 2040 2078 2005 2010 2121 2043 2048 2056 2077 1999 2041 2008 2013 2032 2128 2009 2080 2002 1994 2024 1996 1970 1868 2074 1983 2014 1961 1903 2032 1961 1965 1959 1854 1936 1975 1971 1919 1902 1981 1905 1931 1896 1867 1940 1934 1949 1927 1956 1835 1856 1881 1878 1957 1857 1828 1885 1883 1954 1843 1921 1925 1922 1954 1962 1891 1871 1922 1905 1903 1844 1902 1900 1868 1928 1914 1897 1924 1854 1950 1928 1910 1885 1983 1925 1913 1888 1964 1896 1922 1992 1927 1910 1955 1939 1856 2004 1902 1894 1961 1884 1973 1995 1966 1924 1958 1929 1919 1967 1986 1906 1911 1975 2026 1921 2069 2004 1949 1976 1955 2000 1932 1996 1970 2020 1997 1983 2024 2004 2052 1965 2035 2055 1960 2008 2004 2012 2034 2089 2000 2078 2025 2000 2007 2024 2039 1937 1984 1931 2002 2033 1991 2015 2006 1954 1978 2042 2011 2028 2091 1985 2046 2061 2097 2130 2046 2007 2002 2067 2041 2088 2069 2026 2156 2148 2113 2036 2118 2077 2184 2120 2182 2178 2208 2115 2144 2105 2036 2190 2226 2153 2171 2105 2180 2120 2070 2197 2116 2156 2106 2118 2111 2091 2121 2200 2073 2146 2076 2065 2092 2143 2156 2067 2088 2088 2127 2082 2131 2157 2085 2033 1988 2064 2030 2043 2093 2141 2055 2074 2104 2033 2101 2052 2031 2062 2094 2110 2108 2013 2057 2076 2129 1946 1943 2027 2056 2027 1965 2018 1919 2032 2052 1971 2118 1970 1957 1989 2024 2024 1989 2058 1950 1972 2026 2020 2002 1966 1985 1982 2134 2091 2080 1961 2034 2102 2124 2157 2070 2037 2110 2124 2140 2253 2187 2130 2142 2129 2071 2031 2087 2162 2091 2007 2095 1971 2062 2001 2048 2080 2041 2143 1966 2109 2061 2061 2045 2130 2017 2099 2065 2059 2066 2033 2090 2031 2144 2095 2084 2119 2008 2006 2092 2055 2081 2082 1996 2133 2007 2034 2087 2150 2100 2129 1937 2050 2026 2039 2089 2086 2066 2102 2017 2041 1965 2070 2124 2171 2167 2150 2044 2122 2097 2033 2109 2092 2045 2008 2007 2105 2115 2099 2197 2225 2070 2096 2147 2132 2289 2126 2245 2255 2151 2231 2341 2287 2326 2262 2336 2281 2316 2393 2349 2359 2504 2343 2366 2271 2378 2364 2363 2415 2354 2317 2426 2337 2288 2462 2374 2321 2442 2417 2396 2479 2329 2331 2474 2318 2422 2428 2384 2334 2411 2366 2340 2350 2454 2455 2370 2334 2416 2358 2403 2450 2300 2371 2349 2265 2319 2345 2349 2426 2291 2358 2333 2307 2446 2276 2328 2367 2392 2273 2321 2327 2276 2360 2322 2275 2267 2373 2337 2314 2288 2293 2268 2301 2317 2288 2181 2221 2274 2230 2236 2201 2220 2287 2318 2145 2167 2181 2307 2246 2329 2235 2233 2236 2260 2165 2184 2200 2170 2241 2231 2253 2222 2261 2259 2171 2231 2327 2240 2302 2168 2201 2229 2259 2323 2276 2260 2197 2330 2153 2221 2123 2172 2179 2219 2124 2151 2190 2147 2113 2199 2133 2194 2093 2159 2073 2156 2243 2110 2139 2183 2074 2175 2140 2148 2191 2125 2128 2246 2111 2055 2159 2181 2035 2169 2051 2023 2077 2059 2096 1956 2077 1983 1994 2097 2099 2006 2012 2106 1991 2055 2077 2013 1993 2082 2008 2068 2116 2121 1961 2090 2031 2012 2014 2030 1954 2006 1968 1910 1974 1999 1958 1932 1910 2053 1923 1982 1910 1948 1799 1924 1862 1911 1935 1954 1968 1863 1927 1920 1952 1909 1904 1925 1865 1938 1942 1919 1990 1978 1880 2021 1900 1969 1911 1964 1927 1956 1975 1960 1957 1925 1882 1931 1927 1835 1903 1960 1888 1856 1918 1987 1850 1966 1847 2011 1888 1936 1957 1987 1884 1976 1964 1990 1893 1903 2001 2022 1920 1927 2033 1909 1980 1949 1969 1916 1969 1976 1935 1966 1918 1986 1935 1973 1926 2014 1988 1974 1975 2002 2049 1931 1955 2057 2024 1964 1974 1919 2054 1963 2026 1944 2027 1982 1954 1969 1863 1869 1950 1911 1925 1955 2053 1926 1998 2055 1995 1916 1910 2000 1972 1975 1940 1893 2064 2041 2031 1949 1895 1880 1918 1934 1986 1924 1837 1941 1864 1944 1920 1848 1930 1910 1953 1907 1940 1972 2070 2025 1953 2069 1875 2000 1975 1984 1953 1946 1839 1886 1992 1943 2010 1988 1921 1996 1942 2034 2076 2044 1998 1944 2044 2001 1966 1967 1945 2075 1981 2057 2076 2050 1997 2005 2044 1979 2045 2033 2144 2031 2063 2045 2069 2115 2139 2030 2076 2183 2127 2134 2174 2203 2064 2092 2187 2212 2200 2123 2121 2117 2199 2111 2164 2040 2296 2211 2095 2180 2243 2169 2200 2180 2288 2145 2223 2178 2126 2141 2199 2110 2136 2115 2130 2214 2185 2136 2141 2178 2211 2152 2146 2148 2043 2080 2060 2068 2100 2037 2088 2091 1984 2149 2070 2021 2028 2007 1979 1952 2000 1991 1928 2013 1995 1994 2023 1968 2094 1952 2014 1914 1999 1912 1936 1980 1932 1969 1967 2016 1888 1925 1920 1962 2044 1962 1985 2008 1945 2114 1955 1917 1933 1872 1944 1855 1817 1916 1873 1972 2003 1913 1904 1835 1966 1922 1862 1881 1875 1964 1935 1953 1919 1915 1944 1902 1836 1940 1850 1962 1866 1948 1902 1913 1861 1885 1924 1924 1896 1963 1890 1919 1912 2011 1918 1968 1917 1884 1964 1869 1942 1999 1852 1952 1883 1944 1876 2008 1833 1953 1908 1934 1927 1943 1860 1893 1995 1902 1947 2001 1846 1899 1919 1911 1954 2030 1977 1977 1906 1984 1965 1990 1960 2044 2118 1981 1987 1979 2080 2105 2168 2067 2099 2072 2002 2090 2046 2035 2125 2028 2052 2109 2054 2013 2054 2057 2114 2074 2075 2155 2090 2127 2017 2114 2017 1990 2000 2054 2013 2044 1975 2072 2051 2022 2049 2071 1983 1990 1968 2112 1999 1973 1991 1993 1996 2118 2074 2075 2035 1956 2017 2012 2007 2041 1944 2047 1986 1995 1981 2005 2020 2001 2018 2072 2030 2029 2005 1969 2027 2091 2038 2095 1956 2045 2048 2029 2088 2023 2127 2019 2016 2002 2013 2014 1987 2076 2087 2120 2056 2069 2149 2134 2186 2141 2151 2119 2179 2281 2149 2263 2182 2140 2220 2245 2226 2215 2193 2173 2291 2387 2337 2316 2333 2398 2361 2306 2380 2269 2337 2259 2153 2281 2306 2243 2271 2306 2200 2244 2304 2247 2251 2233 2263 2315 2254 2228 2220 2193 2234 2141 2126 2238 2130 2153 2227 2186 2162 2141 2127 2106 2121 2166 2161 2178 2048 2059 2063 1989 2163 1950 2158 2012 2066 2086 1987 2003 2088 2079 2007 2119 2035 1996 2046 2009 2019 1969 2111 2067 2055 2037 2008 2047 2122 1968 2036 1986 2023 1993 1998 1998 2064 2066 2047 2012 2139 2070 2055 2163 2128 2203 2070 2052 2086 2152 2074 2100 2079 2114 2105 2062 2191 2040 2032 1997 1955 2071 2041 2050 2077 2016 2079 2089 2004 2036 2039 2012 2061 2041 2018 2031 2073 2037 2033 2038 2033 1990 2040 1961 2013 1916 1988 2005 1964 2041 2069 1910 2025 1993 2018 1996 1923 1967 1941 2029 2057 1928 1982 1988 1921 1951 1991 1969 1970 1912 1954 1986 1962 2023 1988 2017 2000 2050 2008 1969 1978 1992 2071 2056 2081 2051 2026 2113 1981 1992 1941 1972 1963 1981 1933 2081 2056 2034 2042 2103 1951 1954 2055 2006 1961 2093 2098 1951 1978 2059 1984 2029 2036 2006 1993 2026 2028 2029 1968 2076 2006 2056 2005 2069 2009 1997 2005 1991 1951 1968 2080 1963 1952 1958 2043 2010 1996 1989 2066 1996 2111 1986 1960 1968 1990 1938 1954 1859 1940 1905 1944 1953 2022 1968 1994 1905 1940 1967 1941 1968 1948 1921 2014 2032 1946 1867 1971 1965 1982 1979 1947 1915 1951 2070 1968 1992 1957 2058 1985 1905 2060 2020 1945 1992 1953 1920 1991 2032 1978 1976 2020 1942 1982 1994 2001 1999 2007 1985 2043 2107 2002 2031 1990 2030 1988 2066 2109 2174 2116 1965 2069 1992 1967 2063 2027 1987 1960 1960 2005 1961 1856 1997 1955 1849 1948 1927 2002 1915 1987 1944 1992 1956 1910 1977 1966 1967 1954 1927 1970 1988 1907 1955 1932 1928 1944 1985 1980 2037 1936 1996 1915 1890 1896 2007 1977 2023 2116 2002 1971 2017 1995 2106 2019 2014 1993 1912 1949 1995 1933 2005 1908 2043 1907 1959 1922 1976 1914 1922 1997 1864 1935 2009 1902 1971 1981 1931 1955 2021 1984 2035 2011 1992 1971 1966 2012 1943 1934 1979 1905 1937 1865 1985 1969 1981 1930 2042 2022 2021 1908 1989 2010 1877 1909 2074 1989 1931 2011 1940 1949 1956 1964 2025 1968 1948 1944 2010 1968 1870 1901 2010 2021 1892 2021 1989 2028 2077 2062 1965 2010 2042 1992 1995 1997 1990 1952 2019 2045 2003 2015 2023 1988 2012 1979 2044 1945 2022 2049 2066 2036 2022 2061 2005 1938 2022 2083 2023 1972 2097 2130 1902 1970 2058 1985 1990 1945 1987 2007 1936 1994 2006 2063 2030 2001 2024 1913 2022 2027 2074 2024 1944 1978 2031 2081 2066 2007 2103 1955 1995 2034 2040 1925 2030 2007 2050 2037 2032 2002 1982 2006 2097 2000 2126 2096 2038 2124 2080 2106 1965 2046 1981 2007 2057 2049 2029 1951 2026 2006 1935 2061 1989 2015 2032 2070 2056 1992 2008 2060 2024 2052 2032 2058 2095 2024 2051 2141 1969 1980 2014 2048 1995 2035 2058 1971 1971 2083 1997 1963 1930 1976 2078 1951 2011 1927 2004 2011 1931 2016 1970 1940 1978 1989 2039 1989 1988 1928 2072 1935 1999 2028 1902 1972 1970 1895 1972 2051 1899 2009 1961 2003 1891 1922 2011 1999 1908 2007 1954 1890 1918 1876 1923 1922 1888 1861 1930 1926 1976 1841 1884 1894 1935 1928 1993 1900 1943 1879 1933 1924 1802 1850 1867 1918 1871 2036 1846 1914 1872 1936 1928 1895 1885 1948 1957 1954 1874 1927 1913 1949 1928 1877 1979 1994 1908 1850 1862 1861 1960 1914 1874 1969 1911 1887 1847 2051 1937 1954 1981 1907 1921 2001 1980 1992 1931 2027 1889 1998 1977 1937 1885 1965 1940 2028 1907 1932 1865 1914 1905 1855 1882 1969 1890 1930 2017 1914 1986 1931 1929 1935 1896 1946 1936 1941 2028 1995 1937 1864 1963 1950 2016 1954 1987 1960 1940 1893 1867 1871 1926 1920 1871 1978 1995 1937 1896 1933 1929 1902 1989 1980 1843 1936 1886 1912 1992 1929 2013 1985 2031 1917 1991 1917 1970 1974 1915 1972 1969 1946 1865 1936 1954 1970 1981 2005 1977 2010 2028 1935 1979 2054 2046 2090 1996 2006 1979 1959 1970 1964 2000 2037 1979 1988 1926 1972 1991 2054 1972 2019 1960 2067 2085 2039 2004 2025 1980 2117 1995 2028 1996 2013 2001 2044 2048 2047 2035 1935 2090 2019 2112 2025 1999 2026 2010 2043 2109 2035 2091 2014 2129 2089 2040 2026 2046 2067 2062 2055 2098 2121 2032 2085 1971 2038 2088 1994 2110 2125 2109 2095 2054 2058 2186 2083 2141 2065 2121 2139 2120 2016 2171 2102 2063 2060 2003 2036 2087 2058 2062 2022 2015 1991 1989 2021 2067 2060 2020 1974 1998 1969 2029 2031 2030 1974 2033 2021 1965 2049 1985 2001 2039 1966 1970 1993 2055 1986 2051 1956 1949 1980 2018 2007 2055 2059 1918 2032 1990 2012 2020 2049 2054 2038 2035 1995 1923 1994 2047 2115 2035 2043 2060 2030 2068 2128 1992 2088 2118 2084 2090 2102 2116 2081 2100 1985 2124 2070 2027 2106 2064 1950 2127 2024 2154 2175 2161 2137 2175 2221 2192 2263 2161 2172 2098 2174 2161 2198 2307 2232 2323 2264 2215 2230 2165 2211 2220 2177 2300 2295 2246 2108 2228 2158 2183 2161 2172 2123 2157 2182 2076 2091 2159 2197 2141 2141 2187 2144 2155 2190 2133 2159 2120 2194 2112 2092 2109 2071 2175 2145</counts>
			</dataPoints>
		</scan>
	</xrdMeasurement>
</xrdMeasurements>