File: dataset/precursor_mixture/NaAlO2-1.5H2O_NaHCO3_MnCO3_CaCO3.12-min.xrdml
<?xml version="1.0"?>
<xrdMeasurements xmlns="http://www.xrdml.com/XRDMeasurement/2.2" xmlns:xsi="http://www.w3.org/2001/XMLSchema-instance" xsi:schemaLocation="http://www.xrdml.com/XRDMeasurement/2.2 http://www.xrdml.com/XRDMeasurement/2.2/XRDMeasurement.xsd" status="Completed" recordIdentifier="{54D010B9-BBF8-44D5-ABED-2DB6A99AC738}">
	<comment>
		<entry/>
	</comment>
	<sample type="To be analyzed">
		<id>dara-9-2</id>
		<name></name>
		<preparedBy></preparedBy>
	</sample>
	<xrdMeasurement measurementType="Scan" status="Completed" sampleMode="Reflection">
		<usedWavelength intended="K-Alpha 1">
			<kAlpha1 unit="Angstrom">1.5405980</kAlpha1>
			<kAlpha2 unit="Angstrom">1.5444260</kAlpha2>
			<kBeta unit="Angstrom">1.3922500</kBeta>
			<ratioKAlpha2KAlpha1>0.5000</ratioKAlpha2KAlpha1>
		</usedWavelength>
		<incidentBeamPath>
			<radius unit="mm">145.00</radius>
			<xRayTube id="1010048" name="Empyrean Cu LFF HR (9430 033 7310x) DK430614">
				<tension unit="kV">40.0</tension>
				<current unit="mA">15.0</current>
				<anodeMaterial>Cu</anodeMaterial>
				<focus type="Line">
					<length unit="mm">12.0</length>
					<width unit="mm">0.4</width>
					<takeOffAngle unit="deg">6.0</takeOffAngle>
				</focus>
			</xRayTube>
			<filter id="20010004" name="Beta-filter Nickel">
				<material>Ni</material>
				<thickness unit="mm">0.020</thickness>
			</filter>
			<sollerSlit id="21010002" name="Soller slits 0.04 rad.">
				<opening unit="rad">0.0400</opening>
			</sollerSlit>
			<mask id="22031000" name="Fixed mask 13 mm">
				<width unit="mm">9.00</width>
			</mask>
			<divergenceSlit id="22120001" name="Divergence slit 1°" xsi:type="fixedDivergenceSlitType">
				<distanceToSample unit="mm">50.00</distanceToSample>
				<height unit="mm">1.52</height>
			</divergenceSlit>
		</incidentBeamPath>
		<beamKnife id="29030100" name="Beam knife low"/>
		<sampleMovement xsi:type="spinningSampleMovementType">
			<spinnerRevolutionTime unit="seconds">1.0</spinnerRevolutionTime>
		</sampleMovement>
		<diffractedBeamPath>
			<radius unit="mm">145.00</radius>
			<antiScatterSlit id="22090040" name="AS slit 9 mm" xsi:type="fixedAntiScatterSlitType">
				<height unit="mm">9.00</height>
			</antiScatterSlit>
			<sollerSlit id="21020003" name="Large Soller slits 0.04 rad.">
				<opening unit="rad">0.0400</opening>
			</sollerSlit>
			<filter id="20030001" name="Large beta-filter Nickel">
				<material>Ni</material>
				<thickness unit="mm">0.020</thickness>
			</filter>
			<detector id="7010019" name="PIXcel1D-Medipix3 detector" xsi:type="rtmsDetectorType">
				<phd unit="keV">
					<lowerLevel>4.0</lowerLevel>
					<upperLevel>11.3</upperLevel>
				</phd>
				<mode>Scanning</mode>
				<activeLength unit="deg">5.020</activeLength>
			</detector>
		</diffractedBeamPath>
		<scan appendNumber="0" mode="Continuous" scanAxis="Gonio" status="Completed">
			<header>
				<startTimeStamp>2024-02-18T11:44:32-08:00</startTimeStamp>
				<endTimeStamp>2024-02-18T11:57:00-08:00</endTimeStamp>
				<author>
					<name>AutomatedUser</name>
				</author>
				<source>
					<applicationSoftware version="1.4b (28)">PANalytical Aeris Instrument Suite</applicationSoftware>
					<instrumentControlSoftware version="2.0.0 20210224">AERIS</instrumentControlSoftware>
					<instrumentID>950485</instrumentID>
				</source>
			</header>
			<dataPoints>
				<positions axis="2Theta" unit="deg">
					<startPosition>9.99043322</startPosition>
					<endPosition>100.09495370</endPosition>
				</positions>
				<positions axis="Omega" unit="deg">
					<startPosition>4.99521661</startPosition>
					<endPosition>50.04747685</endPosition>
				</positions>
				<commonCountingTime unit="seconds">18.249</commonCountingTime>
				<counts unit="counts">4672 4705 4611 4623 4701 4669 4608 4755 4515 4609 4685 4551 4610 4668 4612 4548 4653 4715 4628 4684 4584 4549 4530 4507 4654 4541 4467 4685 4582 4567 4578 4541 4497 4645 4617 4531 4521 4589 4571 4539 4576 4567 4517 4676 4565 4565 4543 4478 4515 4560 4619 4424 4552 4415 4629 4434 4490 4429 4409 4432 4496 4617 4441 4464 4485 4514 4459 4494 4511 4474 4371 4531 4425 4557 4499 4485 4481 4578 4410 4401 4419 4512 4455 4252 4505 4448 4287 4390 4282 4459 4230 4292 4376 4284 4381 4440 4361 4341 4179 4383 4444 4370 4367 4228 4397 4354 4297 4274 4305 4355 4430 4347 4351 4371 4309 4329 4468 4345 4351 4403 4215 4320 4316 4355 4351 4284 4424 4230 4318 4346 4463 4346 4285 4256 4231 4267 4246 4306 4316 4397 4268 4270 4307 4304 4294 4331 4226 4279 4353 4194 4186 4247 4291 4222 4180 4346 4246 4240 4319 4106 4289 4196 4310 4232 4203 4214 4172 4236 4254 4124 4181 4229 4149 4179 4210 4279 4176 4255 4146 4166 4259 4326 4180 4264 4302 4134 4212 4168 4109 4155 4127 4241 4183 4152 4166 4099 4152 4183 4200 4174 4119 4129 4230 4114 4122 4237 4136 4109 4150 4250 4139 4130 4115 4227 4134 4196 4027 4096 4148 4190 4061 4052 4070 4140 4130 4157 4152 4084 4006 4124 4063 4166 4143 4034 4225 4059 4098 4116 4135 4187 4095 4084 4108 4133 4099 4052 4108 4181 4143 4124 4114 3994 4057 4097 3899 3995 3982 4053 3977 4052 4089 4095 4105 4038 3991 3958 4132 4048 3966 4068 3987 4062 4022 3906 4019 4012 4057 4060 4119 4011 3982 4084 4029 3963 3972 3950 4083 3931 3982 4085 3938 4047 3932 3915 4138 3910 4064 3893 4024 4051 3980 4004 3935 3950 4087 4098 3944 3949 4004 3953 4120 3979 3959 3894 3944 3931 3911 4014 4074 4011 3928 3917 4016 3915 3972 3973 3953 3913 3915 3922 4069 3858 3947 3950 3886 3958 4024 3921 3874 4038 3837 3889 3874 3905 3928 4028 3998 3956 4071 3874 3988 3767 3851 3934 3939 3746 3854 3913 3854 3990 3945 4043 3852 3950 3916 3906 3942 3860 3976 3814 3876 3889 3952 3934 3922 3902 3916 3909 3911 3890 3954 3875 3920 3888 3830 3843 3862 3840 3752 3904 3919 4012 3804 3938 3805 3917 3782 3966 3833 3775 3855 3892 3675 3829 3789 3910 3828 3912 3671 3810 3795 3905 3864 3993 3899 3942 3830 3854 3810 3877 3840 3891 3940 3849 3841 3782 3850 3934 3785 3770 3833 3780 3837 3898 3858 3796 3762 3852 3853 3833 3894 3798 3824 3921 3918 3988 3902 3885 3870 3863 3802 3959 3820 3840 3913 3938 3929 3860 3959 4006 4006 3885 3924 4032 4105 4010 4051 4087 4150 4154 4125 4283 4191 4137 4215 4018 4083 3949 3908 3847 3846 3846 3702 3768 3784 3759 3838 3840 3750 3740 3922 3815 3831 3828 3817 3782 3800 3793 3717 3866 3818 3820 3726 3884 3797 3716 3733 3810 3716 3838 3789 3891 3825 3844 3839 3813 3853 3802 3808 3855 3920 3939 3914 3868 3846 3897 3834 3826 3853 3886 3874 3977 3862 3930 3741 3927 3854 4004 3765 3852 3780 3693 3680 3850 3718 3731 3746 3781 3730 3685 3761 3809 3670 3685 3746 3665 3630 3731 3808 3664 3677 3624 3678 3656 3681 3713 3780 3685 3807 3609 3779 3631 3648 3651 3695 3724 3732 3591 3631 3850 3709 3708 3643 3731 3689 3700 3668 3930 3745 3629 3696 3758 3645 3765 3652 3775 3860 3625 3727 3819 3830 3688 3922 3734 3857 3999 3900 4040 3964 4034 3984 4152 4216 4113 4416 4328 4332 4516 4519 4508 4612 4641 4542 4584 4618 4342 4457 4230 4280 4063 3988 3992 3983 3937 4091 3828 3966 3856 3895 3806 3899 3971 3835 3954 3878 3820 3820 3792 3628 3676 3744 3624 3722 3592 3638 3582 3674 3517 3557 3515 3607 3644 3628 3582 3565 3540 3440 3515 3596 3510 3572 3522 3548 3466 3434 3568 3408 3625 3605 3528 3478 3646 3544 3509 3528 3634 3412 3603 3401 3613 3657 3507 3464 3500 3557 3664 3541 3533 3619 3539 3582 3541 3476 3442 3529 3501 3453 3450 3534 3449 3555 3399 3444 3447 3508 3493 3418 3440 3445 3442 3502 3529 3518 3637 3531 3629 3518 3513 3445 3534 3556 3488 3580 3492 3621 3456 3473 3489 3477 3437 3627 3583 3514 3387 3631 3404 3554 3603 3615 3520 3532 3560 3607 3698 3546 3575 3800 3595 3771 3710 3821 3876 3838 4011 3861 4092 4116 4097 4330 4440 4499 4742 5024 5257 5643 5938 6359 6604 6958 7121 6982 6729 6530 5988 5726 5349 4898 4508 4293 3931 3935 3596 3633 3515 3565 3514 3497 3455 3532 3446 3455 3340 3472 3294 3383 3499 3393 3494 3338 3412 3546 3478 3465 3479 3336 3479 3416 3532 3551 3536 3437 3493 3592 3568 3496 3491 3459 3507 3472 3457 3482 3345 3453 3439 3299 3381 3371 3390 3371 3275 3262 3442 3208 3417 3346 3316 3331 3224 3277 3303 3315 3257 3301 3311 3288 3392 3295 3178 3406 3318 3284 3292 3319 3250 3200 3335 3210 3222 3292 3222 3230 3335 3248 3299 3317 3327 3267 3255 3280 3207 3271 3322 3305 3223 3245 3287 3161 3216 3175 3182 3213 3210 3216 3254 3201 3306 3219 3257 3330 3211 3206 3275 3238 3137 3174 3263 3281 3222 3193 3258 3254 3304 3239 3370 3244 3180 3174 3227 3182 3117 3070 3185 3296 3221 3252 3247 3270 3273 3102 3185 3131 3238 3257 3132 3117 3228 3167 3298 3170 3161 3212 3172 3173 3305 3226 3241 3200 3238 3135 3250 3235 3288 3237 3286 3177 3303 3303 3392 3204 3325 3333 3350 3402 3288 3466 3332 3593 3577 3527 3630 3681 3584 3822 3797 3750 3866 3870 3789 3749 3705 3678 3552 3455 3421 3448 3365 3406 3401 3240 3293 3311 3276 3409 3381 3360 3475 3425 3498 3533 3517 3486 3445 3507 3506 3520 3397 3372 3347 3347 3213 3227 3236 3221 3127 3190 3273 3200 3099 3233 3166 3183 3139 3136 3097 3165 3143 3253 3246 3196 3146 3177 3153 3316 3231 3315 3253 3375 3389 3406 3434 3348 3239 3392 3401 3342 3392 3314 3296 3245 3211 3141 3058 3045 3100 3165 3154 3118 3091 3036 3146 3083 3107 3008 3058 3104 3062 3145 2952 3041 2941 3011 3042 3137 2955 3086 3123 3120 2945 3037 3091 3029 2950 2948 3059 2981 3048 3020 2959 2936 3071 3081 3124 3014 3010 3085 2996 3060 3041 3114 3056 3106 3110 3136 3014 3108 3102 3133 3193 3193 3160 3160 3023 2989 2969 2978 2946 3020 2922 2947 2960 3010 2916 2971 3067 2787 3201 2949 3079 3014 3061 2877 2974 3013 2974 3022 3062 2987 2946 2959 2900 2916 3000 2980 2820 2974 2998 2888 2966 2895 2897 2850 2888 2960 2969 2851 2970 2977 2929 2944 2894 2932 2978 3065 2948 2987 2976 2919 2828 2963 2882 2925 3008 2980 2893 2944 2948 2926 2880 3019 3038 3080 2847 2893 2931 3030 3001 3025 2946 2975 2969 2973 2907 3107 3049 3142 2998 3100 3078 3054 3050 3206 3228 3151 3098 3198 3235 3245 3384 3388 3488 3466 3454 3647 3586 3591 3611 3502 3381 3516 3438 3426 3174 3205 3249 3097 3084 3105 3027 2982 3016 2932 3025 2874 2925 2887 2999 2933 2886 2915 2910 2956 2932 2844 2901 2896 2988 2887 2950 2985 2918 2955 2919 2962 2985 2982 2945 2923 2930 2984 3047 2893 3034 2961 3036 2808 3003 2969 3003 2984 2980 3177 3102 3109 3185 3184 3236 3311 3334 3459 3434 3445 3521 3697 3740 3910 3872 3935 3920 3902 3957 3899 3742 3718 3625 3597 3546 3597 3486 3537 3430 3551 3561 3523 3639 3653 3748 3940 3996 4086 4119 4419 4617 4692 4979 4910 5161 5295 5193 5445 5543 5462 5357 5248 5243 5141 4971 4787 4531 4445 4355 4024 3864 3799 3591 3539 3426 3354 3318 3270 3236 3127 3285 3037 2957 3130 2986 3091 2936 3025 3001 2940 2951 2917 3059 2945 2861 2849 2876 2946 2908 2781 2919 2727 2914 2850 2887 2945 2945 2842 2836 2868 2761 2780 2853 2728 2816 2861 2838 2791 2724 2868 2789 2762 2864 2825 2723 2764 2919 2707 2803 2850 2788 2787 2832 2779 2768 2851 2912 2819 2857 2920 2788 2982 3028 3034 2915 3023 3070 3070 3197 3016 3027 3066 3079 3091 3002 3119 3031 2973 2993 3068 2932 2945 2886 2876 2942 3014 2960 2940 3034 3196 3146 3212 3275 3455 3535 3623 3795 3910 4097 4189 4455 4627 4741 4803 5063 4996 4880 4733 4622 4521 4167 4100 3889 3664 3487 3321 3177 3125 2981 2985 2842 2945 2805 2836 2791 2674 2719 2741 2858 2796 2730 2744 2737 2722 2790 2683 2697 2708 2719 2747 2719 2685 2799 2739 2763 2755 2693 2745 2752 2665 2677 2730 2766 2652 2722 2732 2715 2646 2635 2588 2668 2680 2701 2642 2710 2673 2651 2682 2673 2625 2689 2677 2673 2703 2770 2796 2666 2712 2670 2637 2676 2801 2758 2842 2716 2749 2850 2906 2873 2873 3021 2969 2918 2957 2881 2957 2807 2822 2745 2797 2768 2738 2775 2867 2842 2952 2892 2937 2984 2969 2996 3000 2977 2986 3053 2862 2958 2891 2995 2892 2915 2791 2721 2743 2789 2669 2718 2698 2710 2737 2738 2694 2591 2623 2733 2592 2610 2739 2476 2572 2623 2592 2608 2794 2632 2660 2654 2596 2661 2571 2654 2678 2705 2712 2714 2662 2694 2733 2751 2711 2920 2854 2734 2740 2757 2580 2732 2646 2570 2714 2699 2591 2611 2675 2579 2640 2690 2636 2673 2623 2649 2672 2572 2703 2577 2641 2644 2552 2723 2811 2736 2743 2813 2707 2793 2780 2744 2786 2670 2663 2702 2757 2710 2582 2695 2599 2666 2574 2619 2606 2573 2545 2540 2637 2570 2622 2611 2636 2628 2670 2615 2548 2606 2604 2682 2551 2559 2633 2709 2631 2597 2626 2614 2580 2640 2684 2484 2575 2565 2546 2635 2654 2609 2618 2625 2651 2655 2663 2680 2474 2703 2559 2598 2690 2611 2592 2596 2705 2813 2702 2878 2844 2814 2811 2897 2975 2848 2880 3017 3048 2921 3016 3056 2951 3062 3105 2950 2931 3031 3091 3009 3000 2941 3015 3038 2957 3089 3091 3071 3146 3137 3035 3079 3095 3217 3246 3258 3306 3290 3437 3342 3468 3523 3674 3756 3838 4056 4137 4313 4547 4668 5006 5180 5596 6008 6192 6391 6493 6398 6382 6438 6423 6250 6010 5819 5884 5724 5532 5483 5559 5537 5689 5871 6085 6377 6671 7163 7923 8349 9384 9970 11160 12519 14411 16319 18942 21582 25082 30251 35627 43483 51035 60796 71565 83404 97314 109417 116939 119235 116503 106592 97735 86591 78955 71186 63854 54246 45815 36132 27460 20695 15170 11767 9442 8082 7182 6579 6147 5835 5570 5346 5216 4920 5003 4885 4884 4688 4477 4526 4270 4323 4279 4150 4087 4035 3910 3884 3688 3641 3605 3561 3471 3414 3472 3344 3525 3519 3440 3380 3406 3567 3492 3596 3610 3784 3837 3957 4145 4229 4507 4649 4766 5012 5355 5649 5968 6290 6897 7151 7459 7686 8053 8391 8332 8362 8257 8180 7893 7969 8023 8054 7973 8177 8184 8352 8647 9009 9371 9812 10469 10610 10810 10846 10652 9889 9229 8754 8247 7682 7227 6711 6261 5497 4959 4596 4226 4047 3832 3690 3555 3453 3505 3392 3329 3382 3231 3208 3227 3269 3257 3184 3145 3197 3171 3191 3231 3189 3150 3215 3267 3191 3324 3178 3226 3217 3255 3284 3230 3265 3201 3355 3422 3380 3367 3428 3553 3613 3727 3571 3832 3887 3997 4199 4258 4380 4471 4583 5044 5286 5336 5839 6249 6460 7059 7407 8058 8354 9163 9623 10245 10873 11047 11488 11783 11737 11767 11730 11341 10855 10535 10187 9527 8918 8692 8168 7394 7042 6576 6069 5823 5486 5186 4993 4786 4679 4466 4444 4294 4385 4235 4209 4143 4207 4162 4024 3922 3856 3811 3629 3717 3642 3503 3319 3278 3161 3166 3193 3121 2926 3074 2893 2953 2914 2982 2813 2973 2907 2769 2835 2920 2810 2769 2896 2869 2778 2808 2876 2868 2852 2910 2812 2972 2840 2996 2867 2829 2827 2850 2944 2824 2761 2907 2812 2886 2811 2805 2706 2779 2706 2743 2792 2833 2841 2708 2667 2723 2699 2740 2679 2638 2755 2779 2703 2738 2726 2747 2570 2639 2636 2648 2679 2728 2611 2656 2599 2599 2540 2679 2577 2619 2609 2578 2564 2453 2637 2566 2650 2529 2551 2640 2565 2739 2567 2518 2598 2593 2580 2497 2532 2588 2599 2564 2605 2572 2566 2511 2651 2560 2572 2529 2574 2657 2681 2581 2600 2651 2656 2595 2662 2651 2710 2744 2817 2771 2851 2892 2830 2951 2962 2992 3262 3144 3447 3280 3267 3333 3400 3325 3309 3318 3349 3330 3425 3305 3087 3244 3210 3185 3177 3081 3176 3033 3016 2991 2952 2888 3021 2810 2714 2906 2923 2854 2898 2847 2816 3029 3003 3084 3157 3194 3159 3232 3203 3083 3034 3095 2867 2856 2828 2754 2793 2850 2780 2731 2589 2612 2499 2630 2557 2622 2539 2498 2488 2512 2570 2564 2607 2616 2664 2630 2622 2672 2648 2690 2771 2709 2801 2764 3001 2996 2939 2993 2983 3115 2972 2985 2889 2897 2889 2920 2778 2866 2912 2797 2829 2909 2826 2979 2906 2930 2973 3054 3092 3349 3493 3574 3731 3810 3931 3879 4238 4335 4398 4604 4573 4846 5009 5257 5594 5919 6686 6938 7447 7834 8139 8046 7906 7629 7227 6888 6340 6086 5914 5736 5435 4991 4581 4204 3917 3743 3377 3311 3190 3054 3088 2945 2885 2851 2866 2779 2864 2790 2760 2837 2817 2918 2944 2934 3120 3204 3245 3420 3493 3583 3766 3867 4080 4121 4102 4259 4233 4412 4099 4068 3946 3739 3699 3665 3632 3396 3380 3309 3269 3180 2976 2952 2988 2854 2794 2828 2681 2672 2697 2705 2608 2625 2550 2566 2491 2476 2419 2453 2524 2424 2475 2414 2421 2407 2434 2408 2370 2448 2518 2413 2416 2416 2482 2425 2398 2486 2357 2520 2468 2498 2460 2582 2613 2621 2698 2799 2784 2847 2980 3021 3246 3308 3306 3274 3308 3320 3317 3278 3157 3154 3071 3088 2971 3120 3073 2961 3025 2897 3062 3016 3013 3063 3243 3260 3463 3618 3405 3618 3531 3401 3390 3317 3264 3136 3203 3008 3047 3018 2947 2942 2898 2870 2839 2747 2695 2675 2642 2658 2681 2560 2533 2535 2519 2511 2549 2480 2421 2417 2500 2386 2421 2291 2335 2340 2408 2410 2302 2335 2454 2351 2288 2310 2309 2378 2342 2305 2382 2368 2372 2307 2419 2321 2303 2335 2300 2291 2321 2265 2202 2352 2378 2383 2385 2317 2357 2364 2412 2296 2287 2330 2348 2265 2361 2253 2345 2336 2235 2353 2287 2357 2305 2236 2296 2191 2401 2360 2312 2329 2318 2328 2395 2412 2339 2389 2299 2275 2384 2404 2411 2395 2461 2336 2479 2451 2436 2476 2498 2559 2594 2639 2667 2674 2749 2835 2867 2992 3057 3071 3181 3258 3347 3366 3393 3491 3719 3634 3828 3847 3944 4088 4087 3953 3895 3835 3830 3776 3676 3690 3649 3479 3435 3283 3295 3070 3006 3035 2900 2820 2708 2684 2793 2616 2690 2576 2506 2540 2545 2518 2397 2456 2462 2393 2389 2343 2427 2352 2335 2359 2474 2417 2409 2366 2277 2350 2412 2379 2433 2373 2409 2501 2325 2403 2363 2405 2405 2362 2429 2382 2282 2383 2430 2428 2417 2429 2353 2334 2425 2309 2363 2379 2363 2406 2353 2396 2396 2432 2387 2310 2377 2168 2289 2275 2256 2337 2272 2296 2253 2250 2367 2220 2198 2180 2181 2273 2269 2231 2194 2235 2194 2233 2248 2226 2248 2201 2174 2313 2226 2287 2272 2214 2330 2285 2395 2363 2337 2394 2621 2597 2571 2734 2803 2825 2849 2735 2743 2954 2894 2757 2824 2775 2609 2673 2674 2714 2663 2660 2620 2652 2511 2671 2627 2775 2724 2843 2991 3065 3239 3361 3438 3521 3591 3643 3648 3458 3400 3316 3343 3286 3218 2949 3104 2978 2950 2742 2742 2836 2633 2637 2624 2494 2600 2578 2697 2874 2940 2969 3127 3338 3444 3726 3910 4072 4177 4339 4316 4139 3997 3841 3658 3520 3436 3339 3308 3238 3150 2967 2918 2700 2553 2553 2428 2357 2399 2283 2348 2364 2248 2319 2272 2273 2261 2282 2239 2295 2283 2262 2238 2300 2307 2256 2367 2248 2326 2245 2291 2294 2260 2282 2237 2205 2300 2285 2296 2294 2250 2247 2302 2308 2335 2315 2322 2335 2299 2249 2344 2329 2292 2279 2239 2203 2236 2261 2358 2203 2222 2259 2172 2285 2252 2201 2192 2099 2202 2154 2178 2212 2226 2122 2237 2206 2259 2200 2235 2286 2301 2351 2368 2366 2316 2218 2275 2316 2350 2356 2386 2280 2443 2436 2412 2511 2427 2568 2550 2690 2787 2752 2873 3073 3311 3445 3730 3963 4226 4578 4708 4835 5083 5171 4995 5126 4853 4839 4375 4406 4110 3893 3874 3842 3686 3591 3279 3114 2967 2846 2756 2620 2592 2536 2563 2527 2456 2559 2486 2411 2404 2438 2429 2424 2559 2453 2479 2631 2541 2650 2650 2731 2808 2795 2909 3002 3014 3034 3199 3317 3317 3520 3573 3680 3710 3832 3785 3861 3849 3802 3823 3769 3593 3752 3561 3472 3458 3312 3191 3245 3282 2990 3002 2936 2828 2913 2788 2726 2676 2714 2671 2575 2647 2633 2674 2494 2451 2500 2392 2471 2352 2433 2400 2414 2356 2325 2294 2358 2270 2210 2273 2254 2304 2259 2326 2361 2374 2336 2223 2455 2288 2401 2336 2338 2298 2240 2252 2260 2268 2275 2234 2269 2182 2220 2281 2148 2116 2108 2197 2189 2130 2164 2218 2151 2230 2261 2230 2233 2195 2186 2185 2154 2237 2201 2253 2153 2146 2109 2125 2079 2059 2149 2188 2147 2177 2095 2073 2151 2153 2077 2061 2146 2104 2157 2084 2025 2166 2073 2139 2181 2086 2091 2104 2098 2171 2100 2132 2103 2095 2153 2099 2132 2151 2084 2062 2098 2082 2175 2044 2143 2168 2176 2053 2151 2160 2136 2093 2200 2247 2117 2147 2175 2203 2194 2213 2188 2209 2307 2333 2320 2313 2333 2496 2585 2595 2718 2925 2961 3122 3290 3620 3911 4043 4337 4234 4297 4060 3962 3626 3440 3395 3235 3276 3180 3407 3217 3107 2871 2961 2694 2590 2535 2397 2366 2217 2280 2355 2289 2338 2387 2197 2251 2255 2259 2256 2233 2228 2229 2241 2247 2130 2203 2207 2168 2128 2174 2049 2215 2046 2141 2038 2133 2148 2181 2149 2079 2186 2141 2177 2283 2258 2221 2227 2245 2269 2226 2133 2183 2224 2194 2152 2067 2105 2138 2122 2095 2128 2080 2079 2092 2045 2051 2096 2035 2065 2054 2076 2070 2061 2089 2088 2020 2019 2071 2039 2021 2117 2059 2047 2002 2211 2160 2121 2026 2140 2177 2095 2107 2168 2056 2166 2124 2065 2102 2182 2274 2191 2298 2225 2394 2444 2304 2456 2512 2646 2651 2581 2558 2712 2673 2785 2798 2817 2938 3058 3112 2987 2984 2891 2756 2667 2642 2637 2458 2614 2570 2566 2576 2515 2508 2369 2505 2280 2386 2354 2378 2352 2312 2254 2413 2355 2301 2400 2521 2590 2539 2637 2620 2643 2796 2902 2905 3096 3215 3170 3390 3337 3427 3585 3444 3507 3567 3527 3440 3470 3362 3314 3389 3369 3187 3127 3078 3060 2942 2898 2803 2757 2653 2589 2518 2475 2385 2429 2375 2337 2430 2380 2392 2309 2357 2320 2320 2237 2251 2213 2195 2183 2228 2156 2225 2144 2130 2230 2290 2344 2211 2324 2238 2431 2263 2251 2359 2331 2230 2265 2330 2256 2195 2199 2294 2198 2213 2152 2186 2128 2195 2174 2117 2190 2131 2074 2133 2235 2127 2186 2184 2244 2227 2300 2324 2306 2497 2483 2549 2766 2751 2849 2911 3069 2863 2988 3004 2914 2993 2862 2846 2729 2820 2764 2637 2704 2723 2622 2424 2554 2507 2463 2408 2392 2345 2368 2408 2434 2390 2303 2267 2264 2278 2298 2310 2357 2320 2339 2426 2448 2469 2446 2439 2381 2369 2387 2368 2345 2368 2249 2376 2302 2289 2298 2188 2264 2249 2195 2204 2091 2131 2088 2147 2059 2115 2080 2138 2106 2139 2118 2153 2139 2140 2107 2165 2227 2195 2260 2310 2318 2258 2270 2287 2428 2324 2301 2361 2392 2352 2316 2258 2220 2372 2363 2399 2539 2382 2520 2571 2574 2747 2567 2662 2659 2631 2575 2531 2646 2412 2423 2440 2566 2442 2428 2529 2436 2409 2434 2413 2360 2429 2417 2404 2482 2488 2746 2720 2689 2882 3177 3321 3564 3967 4255 4619 4937 5241 5529 5721 5661 5497 5287 4897 4610 4229 4141 4045 4113 4018 4132 4111 3936 3904 3611 3520 3326 3234 3015 2977 2972 2893 2894 2885 2839 2653 2591 2628 2558 2512 2493 2457 2462 2490 2423 2303 2347 2288 2299 2189 2197 2156 2086 2150 2190 2073 2146 2159 2129 2135 2125 2131 2067 2159 2176 2072 2170 2088 2171 2152 2076 2188 2181 2226 2179 2229 2216 2182 2348 2262 2314 2278 2279 2339 2451 2352 2392 2515 2445 2592 2611 2808 3014 3131 3398 3684 4048 4266 4805 5064 5368 5461 5442 5244 5010 4633 4383 4002 3991 3900 3893 3897 4100 3948 3908 3672 3556 3389 3156 2919 2816 2719 2640 2487 2503 2588 2568 2617 2615 2523 2491 2507 2429 2452 2371 2361 2362 2417 2306 2427 2375 2294 2225 2355 2263 2234 2173 2137 2173 2150 2105 2125 2149 2100 2103 2072 2121 2001 2077 2142 2042 2080 2064 2078 2131 2136 2025 2107 1983 2111 2164 2031 2092 2167 2198 2097 2147 2182 2203 2143 2194 2184 2250 2238 2354 2252 2223 2344 2311 2307 2334 2502 2503 2401 2465 2603 2523 2543 2672 2691 2734 2567 2623 2663 2545 2677 2568 2452 2573 2547 2436 2490 2480 2453 2476 2411 2301 2327 2289 2330 2324 2269 2211 2302 2153 2141 2169 2152 2147 2144 2146 2118 2113 2171 2171 2145 2081 2116 2072 2064 2122 2142 2115 2160 2106 2047 2136 2158 2036 2048 2029 2106 2027 2062 2063 2105 2069 2088 2021 2068 2010 2015 2080 2027 2043 2012 2126 2173 1997 2055 2151 2022 2181 2129 2059 2109 2114 2056 2092 2105 2211 2145 2129 2129 2092 2170 2156 2199 2124 2154 2154 2029 2069 1978 2088 2100 2060 2060 2023 2157 2026 2094 2010 2095 2048 2105 2006 1971 2137 2074 2072 2046 2074 2066 2053 2109 2022 2009 2015 2038 2100 2018 2066 2002 2093 2081 2024 2006 2064 2006 2106 2072 2122 2109 2156 2087 2137 2132 2197 2218 2243 2261 2158 2194 2263 2212 2259 2274 2247 2283 2261 2330 2410 2351 2329 2415 2489 2521 2567 2612 2748 2790 2895 2996 2943 3074 3083 3229 3340 3466 3598 3636 3792 3816 4004 4033 4135 4225 4144 4250 4182 4305 4480 4496 4595 4646 4603 4757 4792 4726 4739 4731 4356 4389 4313 4200 4134 3991 3876 3846 3800 3613 3454 3481 3500 3302 3118 3096 3037 3031 2951 2804 2824 2685 2741 2707 2591 2702 2595 2560 2610 2591 2645 2562 2518 2418 2465 2330 2456 2414 2415 2314 2276 2341 2224 2285 2199 2149 2139 2128 2212 2203 2174 2085 2162 2021 2160 2072 2083 2089 2091 2117 2080 2073 2064 2006 2036 2099 1976 2122 2044 2088 2232 2069 2130 2176 2169 2241 2180 2288 2251 2266 2338 2326 2292 2328 2261 2446 2285 2253 2263 2337 2437 2322 2319 2409 2430 2321 2303 2378 2332 2334 2478 2311 2430 2325 2305 2347 2308 2453 2224 2384 2388 2320 2397 2287 2210 2298 2184 2126 2173 2127 2160 2166 2123 2180 2099 2083 2055 2017 2051 2020 2041 2061 2064 2024 1980 1946 2064 1963 1947 1955 1948 1947 1968 1958 1933 1958 1976 2028 1917 2017 1907 2055 1996 1928 1991 1963 1918 2048 1974 1925 1923 1949 2043 1933 1935 1992 1983 1982 2126 2098 2021 2030 2014 2014 1995 1930 2097 1977 1950 2019 2020 2062 1983 2026 2023 1960 1928 1967 2017 1985 1917 1995 2012 1858 2015 1970 1942 1941 1952 1935 1930 1917 1965 1927 1978 1882 1920 1902 1889 1878 1863 1943 1911 1860 1993 1975 1906 1874 2074 1979 1954 1905 1955 1940 1947 1943 1938 1995 1964 1925 1986 2059 2111 2093 2114 2122 2104 2047 2061 2171 2144 2175 2052 2118 2092 2056 2119 2048 2132 2016 2044 2072 2020 2031 2074 2017 2023 2021 2008 1949 2026 1935 1965 2061 2010 1935 1965 1939 1908 1945 1955 1895 1931 1885 2032 2021 1965 2036 1934 2003 2072 1956 2007 1964 1973 1973 1890 1942 1926 2002 1920 2011 2036 1956 2028 1909 2001 2048 1971 2007 1921 2022 1963 1945 1936 2016 1968 1949 2088 2011 2094 2048 1991 2083 2101 2156 2051 2321 2304 2273 2256 2317 2300 2376 2328 2266 2441 2388 2389 2394 2439 2422 2445 2416 2329 2375 2185 2249 2240 2216 2154 2229 2113 2209 2143 2200 2190 2185 2264 2234 2195 2265 2195 2286 2303 2203 2248 2301 2208 2155 2192 2129 2092 2081 2117 2077 2146 2106 2094 2119 2149 2138 2120 2198 2186 2114 2134 2227 2099 2104 2134 2061 2051 1914 2001 2030 2032 1987 1997 2020 1955 2075 2043 1990 1986 1963 1968 1927 1960 1957 2077 2027 1983 1970 2048 1968 1981 2015 1959 1893 1982 1985 2025 1981 2026 1959 2041 1940 2058 1992 2058 2043 1997 2061 2001 2043 2027 2024 2009 2023 1980 2018 1947 1984 1993 2036 2091 2009 1998 1995 2010 2095 2051 2112 2056 2130 2161 2184 2341 2308 2259 2268 2294 2134 2162 2075 2082 2060 2180 2064 2058 2149 2159 2201 2223 2207 2178 2062 2093 2059 2115 2019 2043 1976 2057 2135 2081 2056 2068 2147 2150 2226 2334 2492 2576 2734 3065 3361 3833 4241 4861 5462 5826 6060 6168 5877 5631 4852 4039 3628 3382 3293 3321 3358 3628 3832 4022 4066 4296 4016 3862 3559 3250 2969 2667 2692 2611 2489 2544 2612 2603 2746 2744 2889 2937 3092 3144 3137 3000 2980 2931 2865 2749 2728 2710 2593 2693 2718 2866 2749 2801 2811 2785 2726 2680 2647 2530 2425 2463 2242 2230 2300 2285 2232 2191 2156 2103 2112 2168 2101 2051 2054 2127 2113 2020 2121 2009 2002 1986 1946 2057 2076 2003 2023 2055 1925 2096 2027 2046 2074 2085 2092 2106 2194 2236 2170 2147 2226 2254 2285 2213 2273 2162 2160 2271 2142 2112 2131 2013 2180 2174 2156 2180 2231 2221 2270 2201 2265 2189 2166 2093 2067 2103 2127 2178 2145 2117 2181 2132 2222 2196 2190 2073 2222 2135 2096 2117 2109 2156 2067 2037 2029 2033 2009 1929 2000 1970 2074 2103 1984 2020 2012 2048 2021 1973 2007 1928 1868 1957 1982 2016 2019 1973 1900 2063 2037 1990 2062 1996 2048 1957 2001 2049 2070 1966 2026 1997 2055 2059 2081 2110 2116 2201 2081 2061 2112 2030 2035 2020 2021 2065 2099 2115 2040 2018 2059 1987 1879 2102 2042 2070 1994 2033 2037 2027 2016 2016 2064 1999 2009 1947 2005 1938 1977 2050 1946 1978 1972 1859 1942 2003 1926 1896 2003 1951 1971 1889 1981 1942 1885 2007 1943 1946 1986 1977 1955 2035 2006 1873 1945 1891 1988 1920 2031 2060 1981 1982 2001 2044 2053 2067 2104 2033 2087 2159 2095 2181 2130 2170 2261 2237 2237 2337 2417 2388 2454 2353 2428 2507 2603 2582 2608 2629 2746 2617 2688 2804 2734 2793 2741 2780 2710 2724 2588 2596 2651 2596 2536 2362 2439 2423 2379 2395 2330 2271 2297 2276 2257 2275 2157 2229 2149 2104 2212 2134 2137 2038 2051 2064 2095 2104 2140 2085 2086 2086 2079 2172 2120 2274 2068 2166 2159 2156 2209 2269 2233 2307 2375 2351 2440 2454 2448 2589 2498 2710 2680 2959 2913 2906 3033 2848 2872 2703 2698 2664 2604 2736 2627 2770 2788 3076 3059 3284 3325 3301 3380 3417 3434 3271 3284 3108 3190 3230 3359 3628 3828 4249 4533 4834 4916 5074 4636 4288 3918 3543 3293 3035 2812 2864 2812 2854 2881 3048 3215 3251 3309 3148 3104 2797 2632 2430 2415 2301 2212 2302 2142 2210 2311 2206 2377 2415 2390 2522 2465 2484 2287 2335 2276 2111 2242 2132 2125 2159 2116 2091 2157 2225 2267 2129 2186 2241 2128 2066 2094 2103 2036 2000 1964 2012 1972 1983 2033 1985 1966 1961 1933 2004 1933 2019 1985 2095 2071 2175 2069 2098 2163 2237 2184 2261 2230 2198 2225 2293 2237 2263 2294 2116 2107 2191 2076 2196 2182 2154 2214 2144 2108 2023 2152 2165 2108 2076 2040 2169 2019 2011 2001 2090 2080 2040 2093 2120 2172 2059 2124 2185 2232 2241 2199 2291 2181 2143 2030 2056 2119 2061 2051 2050 2020 2047 2065 2034 2064 2034 2084 2127 2120 2076 1994 2031 1970 1997 1975 1894 2001 1937 2067 1987 1991 1971 1931 2055 2078 2005 2096 2025 2070 1964 2040 1948 1933 2003 1977 2018 2016 1934 2024 2031 2045 1973 1978 2019 2012 2050 1961 1964 2057 2043 2090 1986 2079 2083 2109 2155 2185 2217 2199 2256 2293 2266 2208 2319 2173 2181 2139 2168 2131 2149 2173 2161 2169 2086 2252 2190 2193 2261 2250 2259 2262 2239 2172 2230 2154 2274 2193 2206 2184 2170 2135 2169 2108 2247 2129 2198 2127 2107 2251 2163 2169 2145 2237 2227 2208 2216 2110 2179 2218 2144 2229 2314 2295 2380 2276 2452 2371 2420 2537 2481 2490 2670 2468 2538 2581 2578 2542 2564 2537 2561 2508 2594 2414 2384 2395 2429 2330 2346 2419 2295 2287 2250 2153 2276 2245 2202 2283 2160 2195 2103 2115 2001 2040 2042 2072 2002 2018 2056 1950 1903 1966 1893 1979 2011 1962 1962 2027 2029 2005 2024 1902 1968 2000 1935 2036 2020 2025 2074 2064 2170 2116 2087 2088 2025 2052 2057 2064 2129 2049 2040 1954 2014 2105 2017 2088 2003 2126 2117 2082 2156 2117 2226 2299 2424 2338 2312 2329 2366 2466 2409 2370 2313 2168 2245 2051 2149 2130 2115 2086 2019 2174 2144 2124 2136 2069 2243 2076 2037 2035 2014 2006 2013 1966 2079 2043 1992 1978 1921 2027 1956 1901 1923 1951 1870 1963 2025 1970 1913 1952 1910 1909 1886 1813 1923 1863 2020 1973 2034 2043 1968 1965 1983 2014 2004 1955 2048 2059 2191 2145 2124 2212 2135 2198 2178 2134 2206 2207 2189 2203 2213 2214 2176 2147 2172 2198 2234 2183 2256 2279 2348 2423 2397 2520 2541 2637 2498 2516 2491 2437 2313 2263 2215 2128 2143 2137 2135 2223 2221 2225 2262 2189 2278 2315 2312 2255 2201 2220 2180 2169 2107 2070 2045 2061 1996 1990 1933 2090 1963 2031 1934 1904 1950 2035 1979 1923 1958 1913 1972 1978 1919 1980 1956 1999 2000 2097 2035 2112 1981 1956 2016 2006 1991 1978 2025 2002 2048 2020 1999 1984 1985 2046 1900 2007 2019 2027 2081 1948 1977 2069 1960 1973 1953 2010 2008 1927 1926 1949 1929 1916 2007 1954 2024 1926 1968 1908 1911 1956 1919 1882 1927 1944 1965 1946 1996 1958 1999 1949 1907 1949 1992 1914 1972 1963 1850 1931 1937 1867 1928 1988 1922 1942 1876 1991 1976 1940 1993 2025 2098 1985 1972 2039 2019 1974 1962 1900 1980 1996 1900 1900 1847 1914 1937 1844 1961 2059 1949 1932 1944 1944 1948 1891 1870 1957 1935 1929 1911 1852 1941 1906 1987 2016 1956 2029 2000 2034 1971 2032 2134 2039 2094 2124 2115 2122 2282 2271 2216 2323 2173 2357 2262 2316 2345 2286 2308 2241 2270 2286 2212 2221 2286 2207 2141 2252 2125 2201 2174 2223 2143 2135 2088 1997 2047 2055 2065 2105 2032 1960 1940 2022 2011 1918 1995 1998 1949 1881 1885 1882 1838 1856 1816 1937 1878 1824 1841 1846 1844 1871 1855 1855 1980 1821 1925 1876 1871 1754 1884 1828 1850 1916 1815 1949 1861 1852 1889 1881 1890 1811 1915 1767 1797 1778 1797 1787 1859 1850 1799 1900 1861 1861 1846 1819 1858 1854 1755 1880 1839 1815 1790 1805 1863 1830 1803 1841 1809 1788 1817 1803 1833 1797 1814 1860 1913 1815 1885 1963 1956 1929 1911 1928 1940 1966 1877 1941 1994 1886 2003 1946 1941 1936 2035 1966 1973 1980 1959 1947 2001 1996 1938 1975 1999 2085 2023 2051 2093 1985 2075 2074 2132 2014 2085 2171 2147 2011 2073 2142 2112 2147 2028 2013 2154 2074 2128 2189 2165 2247 2236 2196 2209 2195 2230 2191 2128 2176 2205 2155 2225 2214 2227 2268 2214 2172 2143 2168 2193 2081 2071 2065 1990 1995 2047 2131 2025 1979 1998 1948 2105 1999 1988 1986 1904 1934 1882 1865 1865 1853 1739 1854 1890 1888 1828 1836 1865 1741 1832 1787 1883 1858 1805 1921 1807 1823 1855 1841 1845 1873 1765 1832 1780 1800 1773 1844 1838 1894 1847 1879 1857 1982 1854 1958 1918 1944 1885 1847 1898 1800 1842 1838 1845 1891 1878 1870 1915 1831 1926 1967 2010 2048 2061 2122 2086 2107 2147 2056 2155 2053 2030 1991 1988 1863 1947 2006 1933 1852 1984 1873 1945 1977 2014 1907 1976 1965 2022 1951 1958 1898 1946 1925 1887 1920 1859 1858 1858 1817 1744 1864 1823 1751 1695 1769 1788 1810 1818 1802 1767 1750 1797 1909 1832 1751 1745 1840 1819 1828 1819 1757 1816 1787 1807 1805 1772 1815 1747 1849 1798 1728 1706 1837 1776 1735 1775 1708 1752 1721 1801 1785 1766 1834 1741 1674 1710 1731 1696 1742 1759 1764 1764 1793 1849 1763 1733 1721 1789 1705 1710 1791 1725 1768 1688 1718 1752 1779 1623 1817 1781 1772 1755 1737 1749 1688 1835 1793 1825 1766 1842 1730 1761 1694 1822 1768 1718 1837 1859 1892 1862 1835 1758 1773 1814 1745 1772 1744 1814 1823 1811 1913 1713 1836 1821 1813 1798 1881 1787 1783 1812 1874 1842 1837 1830 1825 1767 1837 1816 1755 1814 1888 1814 1800 1824 1805 1782 1799 1806 1764 1885 1806 1814 1783 1859 1863 1920 1932 1961 1902 1927 1904 2017 1956 1941 2013 2007 2004 2014 2016 2050 2001 2090 1942 1938 1932 2058 1943 2083 1989 2012 1976 2044 2050 1931 2025 2000 2031 1993 1974 1848 1954 1977 1856 1885 1930 1901 1875 1947 1911 1833 1899 1866 1924 1905 1854 1968 1908 1893 1835 1841 1867 1882 1850 1951 1934 1973 1875 1912 1910 1928 1900 1901 1954 1963 2059 2068 2026 2142 2062 2148 2201 2188 2171 2040 2142 2092 2015 1981 1970 1924 1881 1841 1860 1940 1897 1930 1993 1942 1961 2021 1964 1986 1950 1820 1905 1901 1872 1865 1895 1847 1846 1863 1797 1797 1798 1787 1844 1732 1756 1803 1830 1779 1832 1842 1793 1738 1783 1873 1735 1845 1833 1780 1826 1870 1735 1804 1831 1885 1832 1804 1826 1900 1857 1823 1934 1869 1953 1937 1882 1945 1900 1910 1898 1966 1908 1933 1885 1923 1903 1854 1882 1888 1906 1975 2049 1999 1936 1945 1883 1966 1915 1899 1912 1905 1921 1873 1907 1838 1907 1876 1856 1822 1773 1828 1825 1878 1856 1925 1784 1887 1814 1824 1833 1820 1846 1834 1833 1835 1820 1824 1806 1823 1774 1817 1789 1838 1803 1733 1854 1751 1855 1760 1773 1820 1877 1765 1848 1819 1799 1839 1887 1808 1786 1757 1812 1792 1859 1794 1752 1839 1758 1788 1841 1762 1853 1871 1791 1851 1809 1813 1793 1760 1841 1785 1736 1855 1821 1743 1767 1854 1837 1856 1883 1901 1858 1866 1872 1941 1777 1755 1747 1784 1839 1660 1751 1720 1820 1851 1768 1710 1809 1870 1742 1797 1693 1707 1718 1701 1814 1792 1809 1751 1702 1721 1722 1724 1721 1774 1781 1721 1840 1728 1795 1702 1703 1787 1754 1687 1769 1788 1786 1752 1779 1752 1770 1716 1659 1665 1798 1786 1723 1732 1678 1749 1803 1739 1844 1713 1731 1696 1744 1772 1786 1742 1831 1728 1879 1761 1649 1746 1804 1695 1815 1773 1768 1805 1760 1775 1818 1687 1770 1749 1849 1764 1851 1710 1813 1786 1689 1861 1937 1818 1864 1906 1912 1879 1961 1816 1806 1783 1873 1884 1881 1842 1838 1905 1793 1914 1874 1819 1916 1902 1907 1940 1848 1926 1829 1843 1845 1841 1808 1900 1822 1883 1878 1809 1839 1952 1869 1940 1910 1887 1992 2000 1923 1857 1870 1843 1850 1837 1830 1856 1880 1825 1879 1851 1939 1787 1902 1896 1913 1962 1962 1933 1931 1914 1975 1982 2006 1972 1944 1954 2039 2062 1920 1899 1835 1901 1916 1877 1951 1908 1930 1948 1969 1958 2037 1948 2011 1835 1970 1941 1948 1904 1878 1970 1931 1784 1918 1883 1904 1770 1854 1792 1810 1903 1891 1831 1954 1873 1919 1908 1866 1939 1880 1909 1959 2051 2002 2122 2239 2248 2245 2312 2289 2213 2128 2018 2032 1994 1990 1832 1896 1847 1936 1890 1911 1971 1862 1964 1978 1998 2049 2159 2055 2051 2053 1971 1977 1947 1980 1931 1800 1783 1849 1895 1847 1830 1853 1838 1797 1897 1836 1850 1875 1827 1873 1876 1861 1898 1996 1795 1873 1865 1992 1967 1910 1954 1920 1998 1920 2001 2009 1986 1954 2007 1936 2000 1966 1956 1946 1980 1955 2060 1942 1877 1951 1933 1906 1915 1960 1868 1858 1884 1943 1991 1926 1846 1960 1912 1913 1900 1842 1835 1901 1870 1773 1891 1874 1826 1881 1932 1769 1855 1837 1871 1835 1843 1841 1789 1908 1843 1846 1881 1763 1786 1779 1782 1856 1750 1790 1825 1853 1743 1775 1749 1673 1800 1794 1810 1792 1791 1801 1673 1784 1815 1744 1750 1766 1719 1712 1804 1710 1779 1758 1653 1794 1780 1756 1794 1756 1754 1706 1820 1767 1808 1808 1684 1818 1739 1785 1710 1736 1824 1791 1796 1781 1742 1688 1878 1823 1795 1859 1978 1901 2022 2096 2096 2090 2040 2056 2016 1901 1935 1904 1871 1906 1817 1818 1820 1868 1797 1869 1787 1809 1897 1892 1850 1907 1921 1821 1980 1915 1883 1841 1860 1791 1858 1732 1855 1818 1794 1855 1824 1708 1761 1800 1826 1793 1745 1818 1773 1830 1736 1821 1743 1686 1794 1739 1793 1871 1870 1787 1817 1741 1715 1765 1824 1808 1835 1785 1754 1805 1923 1939 1823 1801 1859 1913 1803 1803 1808 1836 1775 1713 1762 1824 1832 1851 1806 1875 1809 1866 1788 1784 1776 1886 1836 1790 1793 1860 1776 1752 1792 1837 1757 1731 1782 1741 1807 1765 1759 1704 1707 1798 1786 1908 1788 1824 1865 1843 1782 1730 1759 1809 1796 1761 1754 1811 1689 1744 1741 1789 1803 1812 1750 1791 1783 1777 1721 1674 1770 1677 1698 1761 1793 1794 1811 1722 1678 1732 1750 1714 1831 1720 1759 1725 1819 1728 1726 1736 1768 1729 1698 1665 1778 1718 1676 1763 1756 1853 1731 1738 1688 1709 1785 1695 1825 1831 1772 1798 1813 1741 1782 1720 1783 1746 1679 1739 1749 1828 1785 1816 1866 1792 1799 1760 1747 1796 1792 1821 1870 1839 1760 1920 1820 1885 1865 1903 1919 1902 1922 1911 1982 1996 2004 1972 1980 1911 1894 1919 1983 2014 1969 2079 1931 2030 1994 2017 2065 2090 2113 2208 2285 2264 2322 2246 2220 2206 2168 2026 2123 1981 2017 1981 2016 1921 1910 1969 1988 1960 1937 1966 2074 2081 1983 2032 2076 2111 2069 2095 1963 1965 1890 1831 1891 1829 1844 1856 1834 1835 1826 1861 1825 1856 1793 1900 1876 1806 1871 1898 1856 1828 1824 1868 1883 1886 1872 1875 1830 1889 1913 1901 1804 1799 1883 1749 1755 1746 1742 1775 1810 1745 1845 1828 1746 1795 1851 1792 1801 1837 1768 1712 1758 1806 1716 1737 1684 1708 1710 1781 1759 1779 1728 1774 1705 1769 1745 1827 1737 1738 1706 1735 1761 1785 1720 1689 1785 1658 1731 1756 1734 1725 1709 1747 1756 1749 1761 1766 1684 1717 1746 1696 1826 1760 1771 1698 1762 1761 1651 1666 1682 1762 1709 1671 1716 1709 1743 1801 1705 1739 1770 1657 1718 1726 1763 1704 1706 1705 1732 1706 1739 1722 1693 1621 1672 1697 1676 1762 1740 1711 1737 1708 1656 1712 1767 1762 1734 1695 1780 1770 1778 1655 1765 1771 1741 1787 1731 1790 1754 1777 1720 1744 1733 1786 1754 1758 1821 1799 1742 1809 1763 1777 1688 1708 1796 1742 1746 1702 1771 1712 1776 1881 1884 1873 1846 1901 1984 1932 2015 2062 2134 2046 1946 2056 1907 1889 1898 1832 1928 1843 1790 1864 1841 1853 1860 1849 1930 1893 1876 1951 1878 1898 1915 1918 1920 1993 1949 1878 1888 1880 1908 1871 1845 1869 1920 1879 1902 1940 1846 1888 1831 1855 1918 1914 1817 1855 1840 1934 1861 1929 1859 1886 1881 1799 1868 1757 1941 1836 1825 1829 1783 1822 1804 1830 1763 1820 1820 1821 1759 1786 1744 1864 1782 1765 1817 1859 1759 1768 1824 1813 1867 1836 1826 1800 1866 1836 1858 1847 1864 1885 1991 1859 1916 1957 2036 1994 1997 1987 1946 1920 1912 1910 1805 1871 1857 1934 1897 1915 1823 1857 1899 1812 1840 1941 1836 1796 1868 1812 1860 1974 1726 1826 1842 1822 1838 1815 1866 1865 1723 1762 1751 1782 1784 1865 1782 1782 1815 1803 1812 1713 1670 1775 1747 1785 1770 1781 1818 1823 1734 1791 1757 1713 1755 1680 1792 1792 1664 1715 1777 1694 1673 1779 1764 1713 1728 1688 1728 1694 1760 1646 1696 1778 1737 1707 1748 1774 1698 1704 1710 1771 1676 1754 1704 1672 1765 1786 1742 1703 1760 1681 1764 1598 1736 1691 1757 1766 1662 1668 1794 1712 1644 1680 1793 1720 1623 1820 1757 1727 1693 1811 1740 1748 1827 1700 1793 1729 1739 1715 1725 1671 1795 1805 1778 1762 1757 1769 1759 1802 1696 1775 1765 1775 1704 1792 1811 1756 1831 1754 1759 1787 1751 1810 1860 1840 1777 1858 1953 1886 1841 1807 1797 1858 1856 1748 1791 1794 1844 1844 1774 1822 1787 1852 1790 1813 1800 1814 1818 1778 1868 1778 1810 1785 1792 1761 1764 1860 1799 1832 1830 1803 1802 1757 1776 1767 1752 1783 1779 1847 1720 1849 1871 1784 1796 1804 1825 1786 1835 1850 1829 1904 1856 1809 1815 1834 1885 1892 1824 1843 1757 1781 1764 1737 1763 1797 1818 1764 1750 1768 1817 1780 1819 1823 1816 1841 1755 1842 1765 1836 1833 1817 1757 1880 1795 1714 1806 1815 1802 1828 1858 1812 1867 1813 1764 1843 1742 1755 1776 1788 1755 1748 1777 1787 1722 1805 1811 1881 1837 1869 1830 1763 1902 1908 1891 1881 1885 1866 1885 1897 1894 1915 1895 1792 1962 1979 1938 1897 1975 1926 1971 1889 1882 1974 1932 1871 1892 1883 1913 1874 1943 1977 1985 1965 2013 1898 1994 1922 1944 2019 1974 1961 2047 2043 1983 1964 1957 2022 2105 2002 2032 1920 1986 2003 1966 1987 1938 1910 2030 1951 1955 2014 1950 1863 1966 1918 1893 1941 1918 1945 1887 1957 1919 1932 1908 1936 1949 1857 1855 1979 1854 1875 1794 1846 1919 1872 1825 1786 1856 1835 1880 1837 1892 1881 1819 1833 1822 1925 1840 1811 1841 1816 1863 1811 1876 1806 1804 1778 1785 1742 1761 1752 1723 1735 1820 1781 1804 1744 1783 1789 1781 1737 1766 1742 1835 1748 1751 1750 1792 1753 1741 1720 1759 1791 1812 1728 1849 1787 1775 1834 1716 1843 1720 1748 1737 1728 1754 1824 1764 1806 1745 1703 1725 1776 1806 1799 1737 1783 1778 1766 1704 1762 1754 1742 1779 1716 1716 1812 1859 1805 1781 1807 1824 1724 1850 1763 1833 1864 1748 1887 1883 1821 1878 1851 1809 1805 1843 1948 1901 1878 1865 1971 1850 1937 1870 1939 1966 1951 1915 1951 1885 1946 1928 1851 1919 1926 1882 1868 1956 1906 1896 1947 1789 1859 1897 1886 1853 1909 1932 1902 1910 1813 1886 1866 1928 1843 1863 1856 1901 1915 1851 1743 1870 1790 1751 1783 1802 1858 1823 1765 1751 1812 1873 1740 1857 1741 1869 1772 1759 1761 1783 1756 1835 1703 1798 1804 1778 1723 1723 1743 1777 1769 1761 1794 1731 1766 1710 1753 1730 1759 1742 1738 1654 1740 1714 1619 1673 1754 1787 1836 1702 1859 1726 1753 1763 1773 1790 1790 1803 1721 1734 1687 1778 1703 1740 1742 1692 1757 1688 1725 1728 1749 1843 1685 1708 1755 1744 1707 1739 1738 1747 1802 1756 1792 1716 1708 1704 1729 1765 1782 1799 1701 1734 1670 1678 1785 1708 1762 1719 1676 1715 1717 1752 1765 1748 1683 1797 1805 1766 1773 1690 1782 1725 1820 1814 1756 1700 1754 1739 1743 1733 1757 1708 1700 1780 1797 1756 1727 1703 1763 1702 1743 1779 1712 1731 1682 1712 1712 1724 1703 1767 1685 1667 1684 1720 1725 1772 1786 1798 1712 1738 1775 1778 1688 1701 1739 1725 1725 1760 1754 1711 1720 1749 1723 1716 1778 1784 1702 1681 1752 1706 1727 1749 1803 1776 1804 1752 1785 1763 1764 1732 1763 1776 1810 1842 1761 1810 1791 1826 1827 1750 1698 1749 1742 1715 1756 1783 1802 1777 1682 1705 1815 1720 1773 1751 1769 1765 1800 1793 1912 1836 1766 1828 1886 1837 1790 1773 1819 1847 1853 1762 1839 1830 1806 1837 1857 1872 1688 1721 1794 1749 1830 1774 1797 1843 1747 1766 1800 1755 1703 1785 1786 1800 1772 1784 1742 1789 1818 1640 1799 1729 1812 1795 1819 1776 1843 1792 1748 1776 1933 1856 1843 1831 1948 1948 1960 1927 1881 1902 1837 1872 1805 1756 1762 1849 1803 1694 1692 1723 1747 1765 1782 1826 1847 1845 1786 1803 1835 1795 1768 1933 1907 1896 1772 1793 1895 1838 1846 1851 1875 1855 1777 1764 1783 1795 1700 1745 1765 1734 1721 1763 1749 1785 1753 1784 1773 1834 1836 1799 1678 1815 1748 1767 1713 1849 1668 1827 1722 1753 1713 1750 1740 1772 1757 1793 1745 1768 1724 1749 1823 1751 1707 1806 1782 1808 1746 1766 1725 1774 1882 1697 1796 1833 1824 1830 1982 1779 1793 1770 1783 1734 1761 1735 1899 1778 1725 1770 1721 1718 1786 1763 1801 1721 1739 1751 1748 1708 1809 1787 1749 1822 1900 1780 1744 1753 1824 1801 1775 1843 1790 1823 1742 1809 1790 1846 1841 1859 1801 1782 1816 1859 1914 1890 1827 1873 1918 1854 1908 1963 1997 1935 2058 2057 1984 1970 2097 2120 2096 2173 2101 2098 2122 2134 2082 2007 2053 2027 2050 1936 2060 1913 1989 1967 1982 1951 2000 2025 2101 2112 2051 2191 2236 2308 2329 2391 2439 2393 2282 2331 2166 2235 1996 2074 2043 1920 1886 2000 1986 1916 1850 1930 1864 1900 1885 1780 1846 1958 1989 1942 2033 1962 2034 2082 2106 1987 1956 1978 1972 1913 1876 1847 1864 1779 1863 1832 1856 1874 1785 1817 1821 1789 1889 1738 1741 1796 1791 1812 1804 1818 1748 1783 1823 1647 1688 1657 1675 1712 1751 1735 1753 1739 1763 1793 1773 1750 1765 1710 1814 1774 1751 1772 1753 1800 1841 1758 1748 1810 1837 1832 1813 1857 1711 1769 1740 1794 1807 1741 1785 1912 1781 1765 1884 1809 1949 1885 1935 1926 1934 2048 1979 2013 2027 2051 2060 2114 2035 1937 1906 1909 1849 1814 1793 1892 1829 1877 1825 1784 1779 1845 1802 1835 1762 1812 1821 1818 1812 1897 1915 1849 1906 1984 1930 1902 1820 1885 1911 1822 1905 1828 1729 1750 1840 1832 1798 1885 1856 1904 1947 1892 1841 1791 1798 1833 1845 1822 1814 1786 1827 1781 1782 1764 1779 1741 1789 1856 1845 1830 1757 1755 1748 1805 1808 1863 1807 1723 1793 1806 1754 1792 1804 1748 1824 1819 1783 1749 1841 1795 1847 1763 1829 1712 1875 1831 1868 1826 1784 1806 1832 1860 1836 1773 1819 1860 1778 1837 1826 1788 1806 1836 1773 1735 1757 1757 1738 1759 1666 1744 1748 1700 1748 1696 1736 1740 1736 1808 1825 1744 1795 1764 1758 1762 1753 1817 1884 1761 1778 1808 1768 1812 1737 1831 1789 1810 1836 1842 1809 1809 1759 1818 1786 1782 1744 1753 1799 1734 1825 1810 1792 1766 1731 1787 1736 1758 1759 1689 1782 1725 1814 1811 1808 1848 1844 1756 1762 1837 1735 1795 1806 1761 1769 1786 1812 1698 1789 1742 1711 1703 1671 1697 1776 1760 1772 1728 1678 1679 1740 1735 1770 1719 1762 1807 1710 1676 1810 1799 1775 1836 1720 1837 1750 1837 1701 1748 1717 1700 1784 1750 1818 1749 1671 1763 1839 1800 1790 1789 1763 1817 1839 1805 1817 1747 1788 1837 1790 1755 1773 1742 1777 1804 1765 1820 1860 1786 1787 1778 1857 1810 1812 1896 1831 1764 1760 1848 1837 1753 1879 1866 1876 1892 1833 1896 1918 1980 1940 2000 2027 2043 2052 2089 2085 2227 2340 2574 2587 2796 2840 2984 2899 3055 3038 2814 2650 2491 2350 2287 2233 2110 1969 2017 1952 1956 1933 1978 1960 1925 1954 2002 1955 1954 2054 1993 2088 2032 2193 2193 2305 2301 2446 2417 2382 2319 2254 2104 2131 1989 2010 2022 1852 1847 1847 1901 1886 1846 1817 1829 1782 1849 1845 1869 1897 1915 1765 1801 1715 1826 1778 1759 1755 1775 1754 1796 1814 1834 1864 1774 1848 1751 1830 1779 1872 1809 1834 1892 1843 1936 1885 1786 1928</counts>
			</dataPoints>
		</scan>
	</xrdMeasurement>
</xrdMeasurements>