File: dataset/precursor_mixture/NaAlO2-1.5H2O_ZrO2_LiCoO2.12-min.xrdml
<?xml version="1.0"?>
<xrdMeasurements xmlns="http://www.xrdml.com/XRDMeasurement/2.2" xmlns:xsi="http://www.w3.org/2001/XMLSchema-instance" xsi:schemaLocation="http://www.xrdml.com/XRDMeasurement/2.2 http://www.xrdml.com/XRDMeasurement/2.2/XRDMeasurement.xsd" status="Completed" recordIdentifier="{8C39D54E-4C91-40BB-8441-B421B55E78C2}">
	<comment>
		<entry/>
	</comment>
	<sample type="To be analyzed">
		<id>dara-13-2</id>
		<name></name>
		<preparedBy></preparedBy>
	</sample>
	<xrdMeasurement measurementType="Scan" status="Completed" sampleMode="Reflection">
		<usedWavelength intended="K-Alpha 1">
			<kAlpha1 unit="Angstrom">1.5405980</kAlpha1>
			<kAlpha2 unit="Angstrom">1.5444260</kAlpha2>
			<kBeta unit="Angstrom">1.3922500</kBeta>
			<ratioKAlpha2KAlpha1>0.5000</ratioKAlpha2KAlpha1>
		</usedWavelength>
		<incidentBeamPath>
			<radius unit="mm">145.00</radius>
			<xRayTube id="1010048" name="Empyrean Cu LFF HR (9430 033 7310x) DK430614">
				<tension unit="kV">40.0</tension>
				<current unit="mA">15.0</current>
				<anodeMaterial>Cu</anodeMaterial>
				<focus type="Line">
					<length unit="mm">12.0</length>
					<width unit="mm">0.4</width>
					<takeOffAngle unit="deg">6.0</takeOffAngle>
				</focus>
			</xRayTube>
			<filter id="20010004" name="Beta-filter Nickel">
				<material>Ni</material>
				<thickness unit="mm">0.020</thickness>
			</filter>
			<sollerSlit id="21010002" name="Soller slits 0.04 rad.">
				<opening unit="rad">0.0400</opening>
			</sollerSlit>
			<mask id="22031000" name="Fixed mask 13 mm">
				<width unit="mm">9.00</width>
			</mask>
			<divergenceSlit id="22120001" name="Divergence slit 1°" xsi:type="fixedDivergenceSlitType">
				<distanceToSample unit="mm">50.00</distanceToSample>
				<height unit="mm">1.52</height>
			</divergenceSlit>
		</incidentBeamPath>
		<beamKnife id="29030100" name="Beam knife low"/>
		<sampleMovement xsi:type="spinningSampleMovementType">
			<spinnerRevolutionTime unit="seconds">1.0</spinnerRevolutionTime>
		</sampleMovement>
		<diffractedBeamPath>
			<radius unit="mm">145.00</radius>
			<antiScatterSlit id="22090040" name="AS slit 9 mm" xsi:type="fixedAntiScatterSlitType">
				<height unit="mm">9.00</height>
			</antiScatterSlit>
			<sollerSlit id="21020003" name="Large Soller slits 0.04 rad.">
				<opening unit="rad">0.0400</opening>
			</sollerSlit>
			<filter id="20030001" name="Large beta-filter Nickel">
				<material>Ni</material>
				<thickness unit="mm">0.020</thickness>
			</filter>
			<detector id="7010019" name="PIXcel1D-Medipix3 detector" xsi:type="rtmsDetectorType">
				<phd unit="keV">
					<lowerLevel>4.0</lowerLevel>
					<upperLevel>11.3</upperLevel>
				</phd>
				<mode>Scanning</mode>
				<activeLength unit="deg">5.020</activeLength>
			</detector>
		</diffractedBeamPath>
		<scan appendNumber="0" mode="Continuous" scanAxis="Gonio" status="Completed">
			<header>
				<startTimeStamp>2024-02-18T12:00:21-08:00</startTimeStamp>
				<endTimeStamp>2024-02-18T12:12:49-08:00</endTimeStamp>
				<author>
					<name>AutomatedUser</name>
				</author>
				<source>
					<applicationSoftware version="1.4b (28)">PANalytical Aeris Instrument Suite</applicationSoftware>
					<instrumentControlSoftware version="2.0.0 20210224">AERIS</instrumentControlSoftware>
					<instrumentID>950485</instrumentID>
				</source>
			</header>
			<dataPoints>
				<positions axis="2Theta" unit="deg">
					<startPosition>9.99043322</startPosition>
					<endPosition>100.09495370</endPosition>
				</positions>
				<positions axis="Omega" unit="deg">
					<startPosition>4.99521661</startPosition>
					<endPosition>50.04747685</endPosition>
				</positions>
				<commonCountingTime unit="seconds">18.249</commonCountingTime>
				<counts unit="counts">8489 8678 8724 8593 8657 8550 8607 8427 8487 8624 8560 8419 8742 8697 8651 8513 8774 8473 8560 8548 8578 8530 8481 8603 8596 8532 8549 8665 8576 8862 8486 8525 8691 8725 8583 8635 8564 8727 8613 8652 8686 8665 8511 8772 8551 8504 8709 8555 8675 8682 8644 8626 8688 8663 8410 8751 8642 8669 8614 8510 8689 8604 8630 8549 8649 8524 8572 8656 8666 8613 8547 8672 8730 8681 8722 8556 8538 8556 8586 8406 8556 8632 8723 8698 8614 8879 8657 8759 8612 8717 8668 8666 8721 8628 8689 8686 8599 8696 8497 8709 8599 8643 8613 8505 8515 8720 8790 8579 8640 8656 8818 8732 8675 8685 8551 8770 8570 8710 8574 8608 8578 8769 8580 8714 8519 8718 8514 8676 8763 8540 8754 8641 8674 8666 8727 8790 8822 8799 8599 8696 8758 8642 8754 8638 8591 8655 8835 8547 8795 8664 8658 8729 8746 8596 8685 8818 8652 8926 8619 8657 8672 8542 8763 8742 8858 8630 8757 8717 8727 8715 8768 8738 8769 8631 8748 8763 8760 8933 8523 8750 8632 8746 8882 8726 8752 8793 8724 8688 8808 8730 8757 8813 8895 8799 8642 8666 8792 8768 8710 8589 8669 8778 8672 8806 8792 8740 8811 8893 8743 8803 8928 8920 8689 8766 8825 8610 8877 8633 8760 8675 8848 8702 8982 8767 8678 8822 8844 8851 8684 8807 8719 8828 8907 8822 8872 8838 8792 8932 8810 8871 8704 8751 8881 8801 8851 8791 9039 8823 8818 8867 8842 8895 8804 8886 8884 8872 8921 9043 8888 8941 8816 8892 8930 8688 8969 8830 8972 8862 9034 9155 8964 8799 8839 8991 8708 9050 9078 8857 8964 8992 8743 9111 8956 8980 8956 9051 8972 9010 8927 8943 8829 9023 8818 8820 8904 8959 8798 8847 8911 9009 8929 8768 9004 8952 8986 8972 8844 8813 9044 8871 8914 8896 8827 8939 9076 8899 9126 8818 9137 8959 9065 8924 9072 8964 8981 9013 9207 9068 9006 9229 9256 8994 9091 9147 8909 9103 8914 9098 8970 9113 9102 8973 9027 8954 8893 9023 9120 8983 9130 9094 9137 9015 9150 8919 9139 8944 8976 9153 8982 9183 9117 8934 9161 9262 8958 9036 8974 9029 9042 9038 8982 9074 9161 9103 9094 9088 9103 8974 8957 9006 9140 9205 9087 8996 8954 9066 9215 9205 9261 9107 9009 9251 9166 8923 9026 9098 9116 9222 9079 9073 9196 8901 9188 9164 9105 9243 9230 9084 9330 9181 9117 9177 9353 9229 9195 9220 9043 9079 9156 9145 9031 9129 9258 9243 9115 9166 9179 9093 9025 9363 9236 9171 9218 9160 9110 9124 9244 9092 9470 9113 9226 9163 9203 9183 9300 9308 9183 9234 9161 9311 9129 9394 9325 9120 9244 9111 9106 9277 9172 9207 9141 9265 9300 9179 9346 9082 9196 9279 9220 9245 9237 9308 9291 9278 9411 9105 9144 8984 9453 9399 9349 9213 9281 9323 9366 9551 9320 9284 9114 9342 9141 9353 9289 9436 9230 9336 9357 9276 9388 9337 9142 9274 9306 9245 9202 9309 9455 9345 9353 9354 9453 9535 9605 9313 9456 9537 9353 9390 9208 9427 9531 9632 9466 9321 9576 9278 9332 9327 9464 9442 9383 9528 9365 9261 9489 9321 9541 9467 9383 9271 9443 9369 9282 9382 9445 9355 9405 9437 9301 9292 9315 9339 9287 9305 9309 9282 9610 9449 9615 9430 9440 9521 9512 9410 9292 9355 9445 9336 9357 9514 9277 9427 9548 9559 9502 9493 9292 9451 9293 9509 9494 9276 9449 9573 9495 9498 9585 9525 9499 9170 9549 9554 9566 9623 9422 9333 9536 9386 9456 9520 9629 9667 9524 9550 9676 9888 9737 9731 9797 9999 9882 9841 9904 10282 10312 10192 10367 10515 10568 10665 10383 10265 10175 10078 10230 9830 9890 9750 9953 9734 9605 9772 9668 9649 9725 9751 9839 9759 9820 9649 9732 9733 9837 9738 9560 9657 9750 9666 9719 9686 9921 9716 9649 9865 9879 9672 9897 9858 9862 9994 10114 10030 10233 10080 10194 9998 9902 9783 9867 9800 9652 9912 9972 9688 9827 9829 9605 9700 9639 9838 9796 9765 9750 10036 9755 9862 9896 9890 10051 10147 10198 9964 9913 9996 10132 10023 10020 10071 10144 9982 10022 9942 10099 9916 10124 9899 9823 9780 9736 9694 9712 9572 9667 9649 9704 9572 9680 9539 9637 9574 9803 9661 9708 9658 9545 9677 9593 9582 9867 9594 9688 9765 9711 9682 9818 9520 9646 9706 9548 9676 9626 9580 9806 9679 9707 9691 9608 9765 9588 9562 9753 9664 9710 9594 9854 9790 9866 9768 9746 9818 9787 9952 9854 9866 9805 9936 10166 10093 10234 10192 10165 10238 10458 10491 10799 10882 10919 11114 10935 11164 10952 11165 11321 11148 11473 11561 11531 11452 11565 12073 11944 12075 12155 12335 12510 12392 12597 12849 12713 13013 13003 13012 13771 13801 14178 14452 14829 15255 16117 16553 17465 18551 19600 21133 23013 24938 27204 31109 34608 39233 44469 51231 58856 67180 76919 88729 100872 115412 133233 152467 173457 195491 213553 224110 218426 199010 174283 151388 129010 105305 80057 59848 44162 33826 26887 21738 18810 16517 15101 14096 13568 13577 12956 12972 12560 12749 12641 12663 12381 12411 12432 12017 12156 11977 11754 11738 11617 11505 11400 11309 11115 11096 10906 10735 10676 10626 10549 10647 10666 10497 10437 10453 10414 10464 10290 10340 10319 10204 10189 10150 10307 10336 10310 10391 10345 10086 10294 10238 10322 10249 10328 10258 10343 10381 10463 10674 10574 10552 10567 10477 10557 10686 10878 10844 10921 10772 11033 10864 11054 11014 10844 10861 11022 11039 10963 10990 10898 10612 10947 10930 11007 10867 10927 11077 11161 10963 11167 10770 10912 10897 11025 10870 10847 10885 10838 10951 10917 10965 10910 10787 10885 10980 10861 10997 11122 10852 11011 10961 11131 11008 10972 11195 11000 11032 11049 11131 11104 11488 11401 11220 11237 11242 11334 11471 11365 11406 11105 11235 11304 11049 11026 11052 11036 10934 11094 11068 10811 10987 10857 10934 11042 11146 11100 10933 11123 11104 10992 11065 11060 11212 11031 11175 11289 11114 11152 11037 11061 10912 10980 10743 10895 10944 10995 10847 10887 10902 10718 10786 10629 10716 10648 10613 10765 10651 10695 10574 10836 10845 10810 10709 10906 10690 10686 10654 10766 10727 10725 10675 10705 10804 10847 10654 10824 10594 10513 10810 10743 10703 10614 10466 10423 10506 10582 10616 10519 10445 10589 10601 10569 10503 10390 10518 10661 10481 10339 10513 10708 10482 10665 10356 10496 10455 10623 10437 10367 10397 10327 10566 10646 10377 10505 10483 10370 10326 10430 10386 10522 10550 10553 10524 10398 10328 10360 10142 10474 10319 10456 10344 10276 10283 10491 10324 10491 10442 10368 10201 10258 10396 10500 10417 10186 10237 10355 10406 10392 10272 10661 10409 10170 10478 10158 10216 10267 10376 10426 10273 10330 10114 10549 10306 10204 10220 10245 10259 10342 10266 10321 10364 10285 10180 10365 10192 10239 10143 10291 10218 10167 10165 10164 10339 10107 10316 10265 9983 10228 10260 10206 10234 10374 10107 10132 10239 10431 10165 9913 10263 10165 10297 10128 10259 10034 10044 10054 10128 10140 10192 10070 10116 10103 10212 10233 10040 10154 10191 10053 9966 10107 10172 10142 9994 10158 10184 10186 10104 10043 10055 10027 10034 10124 10015 10121 10062 10155 10172 10254 10222 10066 10195 9999 10017 10011 9922 10091 10044 9963 10099 10087 10238 10040 10073 10032 10065 9728 10027 10042 10171 10015 10008 10026 10266 9999 10029 9870 10097 10096 10089 10031 10032 9983 10001 9784 9948 10259 9907 10057 9744 10066 9867 9956 10151 10072 10100 10192 10376 10256 10001 10072 10005 10252 10241 10134 10130 10019 10280 9987 10106 9995 9904 10022 10114 9996 10274 10096 10008 10177 10055 10255 10066 10223 10159 10221 10163 10295 10276 10481 10303 10449 10542 10539 10638 10679 10629 10805 10944 10952 11027 10895 10949 11234 11301 11397 11409 11613 11680 11656 11670 11595 11574 11414 11404 11107 11080 11087 11019 10817 10749 10675 10462 10501 10425 10542 10286 10348 10495 10601 10536 10309 10643 10529 10554 10461 10745 10518 10819 10957 10851 10917 10977 10918 10957 10992 10969 10939 10954 10759 10698 10519 10534 10599 10422 10220 10420 10281 10156 10300 10186 9984 10100 10133 10075 9921 10017 9828 9773 9863 9850 9747 9911 9828 9830 9660 9927 9520 9669 9716 9582 9598 9749 9660 9931 9778 9740 9695 9787 9649 9706 9812 9808 9772 9746 9820 9656 9651 9785 9773 9829 9763 9702 9889 9883 9777 9793 9801 9698 9859 10060 9984 9936 9828 9891 10037 9953 9852 9790 9879 9795 9769 9845 9743 9443 9840 9644 9527 9635 9701 9708 9641 9695 9648 9811 9588 9777 9664 9572 9679 9536 9650 9712 9584 9681 9598 9714 9488 9423 9558 9631 9779 9435 9622 9437 9512 9531 9646 9506 9679 9699 9783 9605 9720 9667 9505 9702 9661 9531 9765 9731 9706 9520 9688 9558 9609 9765 9555 9751 9921 9905 9939 9989 9932 10057 9860 9883 9965 9774 9696 9963 9807 9659 9727 9652 9611 9488 9414 9647 9584 9556 9366 9545 9449 9518 9506 9398 9667 9498 9205 9621 9459 9680 9469 9442 9731 9529 9586 9479 9695 9400 9611 9408 9568 9321 9511 9607 9506 9504 9585 9562 9499 9480 9524 9614 9584 9459 9325 9695 9617 9526 9544 9561 9515 9374 9594 9567 9391 9579 9539 9588 9643 9770 9710 9792 9479 9889 9708 9721 9732 9549 9622 9624 9449 9691 9512 9291 9391 9631 9563 9284 9391 9492 9571 9609 9564 9670 9318 9331 9535 9478 9534 9419 9381 9476 9369 9365 9427 9335 9398 9375 9462 9465 9521 9552 9490 9322 9576 9432 9538 9605 9507 9522 9378 9576 9675 9433 9559 9592 9546 9467 9481 9531 9590 9657 9595 9620 9487 9597 9373 9589 9571 9541 9585 9497 9568 9793 9597 9510 9613 9617 9430 9690 9661 9662 9785 9721 9715 9737 9539 9703 9623 9817 9961 9815 9736 9777 9702 9913 10007 9890 9956 9959 9973 9991 10169 9918 10113 10355 10366 10442 10612 10502 10606 10787 10785 10891 11071 11230 11472 11764 11979 12333 12526 13048 13346 13795 14447 14771 15446 16275 16750 17251 18136 18657 19176 19796 20438 20319 20210 20093 20014 19376 18671 18169 17413 17111 16284 15405 14770 14200 13563 13276 12529 12290 12009 11864 11486 11225 11161 10977 10860 10663 10783 10578 10564 10444 10587 10216 10350 10284 10140 10232 10222 10058 10002 10195 9877 9802 9910 9834 9874 9775 9653 9801 9636 9786 9728 9540 9672 9505 9631 9843 9628 9588 9654 9680 9589 9752 9651 9586 9648 9574 9505 9538 9581 9577 9780 9517 9515 9318 9555 9414 9549 9584 9487 9424 9775 9581 9459 9569 9484 9431 9356 9703 9530 9531 9665 9548 9623 9902 9790 9908 9694 9721 9667 9869 9853 9697 9685 9570 9557 9629 9446 9527 9509 9466 9433 9630 9600 9296 9297 9532 9342 9220 9290 9505 9354 9471 9545 9490 9467 9485 9414 9388 9442 9268 9485 9458 9408 9364 9304 9403 9279 9484 9351 9257 9296 9303 9364 9317 9444 9473 9384 9233 9460 9328 9340 9304 9520 9365 9333 9494 9237 9442 9303 9578 9599 9436 9625 9452 9340 9432 9302 9418 9416 9460 9514 9500 9325 9532 9451 9579 9420 9346 9501 9462 9528 9429 9526 9507 9558 9575 9632 9628 9664 9693 9727 9873 10040 9883 10015 9956 10087 10182 10098 10202 10105 10093 9990 9917 10005 9735 9951 9793 9871 9719 9652 9749 9658 9732 9631 9664 9525 9781 9489 9580 9567 9567 9589 9544 9608 9650 9658 9439 9464 9524 9444 9378 9654 9413 9592 9376 9542 9324 9304 9504 9358 9418 9436 9488 9574 9756 9429 9695 9649 9489 9676 9485 9674 9582 9535 9700 9592 9728 9682 9744 9662 9673 9634 9794 9671 9886 9704 9839 9789 9746 9853 10167 9962 9943 10112 10232 10124 10262 10058 10263 10266 10320 10645 10747 10966 10946 11105 11362 11382 11757 11883 12160 12639 12911 13434 13830 14095 14702 15048 15187 15996 16460 16459 16743 16810 16617 16605 16383 15939 15706 15151 15048 14407 13984 13861 13259 12975 12537 12284 11935 11635 11482 11196 10994 10888 10677 10619 10360 10453 10392 10217 10069 10123 9855 9757 9737 9658 9591 9606 9653 9578 9646 9633 9461 9411 9611 9436 9535 9328 9511 9426 9393 9175 9277 9454 9349 9436 9233 9312 9301 9367 9296 9420 9327 9398 9194 9275 9142 9283 9436 9320 9164 9401 9236 9352 9306 9392 9055 9310 9351 9210 9291 9386 9108 9383 9319 9212 9299 9418 9176 9337 9254 9186 9207 9343 9056 9036 9248 9393 9298 9174 9343 9105 9309 9104 9240 9224 9255 9018 9007 9195 9207 9041 9215 9224 9112 9115 9237 9216 8972 9206 9321 9165 9258 9143 9158 9159 9169 9240 9109 9049 9140 9206 9223 9320 9064 9135 9340 9218 9320 9349 9248 9494 9339 9247 9228 9271 9275 9346 9446 9373 9478 9572 9535 9513 9647 9632 9708 9826 9823 9859 9955 10133 10041 9956 9885 9966 9927 9849 9771 9714 9633 9734 9550 9478 9428 9538 9391 9411 9368 9326 9369 9232 9399 9253 9448 9485 9516 9544 9668 9415 9811 9810 9856 9995 9794 9876 10037 10038 9725 9751 9681 9678 9618 9527 9628 9452 9325 9489 9430 9380 9168 9139 9256 9407 9271 9290 9272 9423 9480 9331 9370 9370 9509 9457 9561 9540 9702 9674 9666 9578 9757 9778 9857 9899 9981 10094 10361 10330 10429 10502 10648 10728 10814 10994 11084 11318 11282 11547 11572 11687 11602 11683 11814 11792 11769 11695 11522 11364 11289 11317 11458 11463 11479 11322 11367 11570 11431 11446 11443 11472 11296 11194 11199 11250 10995 10971 10836 10658 10842 10488 10373 10357 10232 10182 10179 10168 9988 10022 9943 10030 9938 9810 9682 9896 9921 9950 9860 9672 9716 9483 9581 9727 9771 9475 9511 9516 9524 9421 9432 9552 9576 9571 9517 9611 9588 9771 9770 9859 9939 10278 10376 10495 10309 10491 10552 10463 10538 10476 10567 10195 10101 10411 10188 10540 10443 10152 10121 10253 10121 10185 10067 9861 10025 10203 10182 10242 10371 10498 10426 10622 10425 10588 10609 10591 10703 10834 10750 10807 10653 10670 10491 10557 10386 10307 10138 10064 10101 9792 9786 9781 9831 9682 9556 9502 9626 9335 9482 9357 9483 9497 9355 9317 9615 9505 9615 9680 9540 9659 9587 9815 9891 10237 9879 9989 10065 10115 9866 9750 9820 9569 9956 9592 9594 9601 9668 9473 9642 9457 9475 9430 9200 9350 9406 9328 9444 9354 9277 9412 9335 9326 9368 9314 9219 9403 9212 9332 9251 9413 9094 9421 9206 9514 9197 9415 9141 9155 9184 9073 9078 9101 9104 9317 9205 9144 9109 9117 8917 9162 9060 9064 8919 9041 8915 8945 9099 9151 8902 9032 9065 9037 8943 8834 9014 8760 9036 8978 9065 9118 8949 8905 8952 8893 9125 9021 8923 9032 8919 8956 8962 8957 8953 8953 8852 9057 8915 8759 8767 9064 8941 8964 9061 8949 8918 8941 9054 9012 9117 9040 9048 9054 9083 8836 8865 9036 8988 9101 9082 8942 9176 9055 9047 9129 8907 8975 8859 9036 9117 8838 9077 9058 9005 8973 8924 9000 8980 9099 9139 9181 9154 9199 9377 9306 9150 9477 9250 9383 9349 9518 9765 9839 10109 10310 10650 10829 11248 11473 11815 12260 12150 12373 12215 11713 11369 11199 10823 10942 10911 10777 10516 10501 10321 9895 9762 9494 9409 9304 9273 9185 8942 9040 9136 9164 9087 9129 9229 9172 9075 9178 8952 9134 9191 9113 9146 8907 9074 9141 9297 9219 9015 9157 9166 9270 9160 9085 9278 9131 9172 8954 9147 9282 9165 9193 9058 9123 9212 9134 9199 9316 9180 9276 9198 9195 9125 9206 9175 9214 9194 9317 9241 9212 9339 9318 9180 9425 9396 9511 9488 9778 9816 9976 10210 10634 11248 11286 12017 12764 14272 15443 16918 18617 19766 21083 21326 19951 18082 16447 15051 14714 14757 15142 15456 15248 14496 13653 12231 11279 10712 10232 10153 9902 9837 9712 9718 9806 9916 9676 9728 9648 9811 9861 9832 9854 9800 9985 9738 9792 9508 9704 9635 9565 9543 9535 9548 9267 9283 9419 9243 9251 9290 9476 9542 9518 9418 9504 9840 9806 10011 9988 10411 10568 10720 10762 10710 10597 10308 10328 9999 9892 10132 10026 9855 9901 9773 9538 9513 9393 9213 9215 9147 8988 8951 9082 8996 9027 9106 9080 9176 9224 9062 9030 8919 8982 8900 9146 9161 9032 8824 9025 9002 9153 9103 8962 9068 9113 9014 9176 8907 8999 8845 8907 8829 9028 9057 9046 8650 8877 8921 9122 8902 8856 8984 8925 8910 9052 8849 9064 8808 8907 8907 8964 9035 8963 8869 8844 9098 9017 8886 9040 9041 8948 9136 8898 8964 8963 9106 9056 9123 8970 9188 9203 9100 9017 8874 9107 9032 9069 9017 9089 8939 9082 8803 8974 8950 8884 8911 9163 8983 9125 8972 8843 9013 8866 8998 9051 8912 8943 8983 8974 8938 9032 9097 8923 9054 9195 9210 9002 9165 8989 9043 8873 9008 9309 9042 9154 9248 9167 9218 9223 9370 9200 9337 9329 9400 9636 9624 9769 9492 9593 9742 9699 9911 10131 10060 10071 10150 10028 10043 10225 10072 9967 9945 9992 9852 9882 9810 9733 9742 9712 9466 9512 9511 9380 9352 9503 9244 9540 9350 9165 9273 9184 9242 9271 9345 9287 9484 9478 9416 9371 9343 9520 9318 9320 9414 9451 9520 9583 9418 9523 9409 9398 9471 9496 9377 9411 9627 9469 9478 9647 9605 9541 9484 9590 9436 9617 9558 9481 9373 9405 9622 9379 9522 9516 9394 9366 9356 9411 9482 9263 9297 9360 9287 9212 9249 9415 9251 9159 9083 8950 9151 9054 9018 9009 8953 8890 9106 8960 9074 9303 9076 8876 9052 9020 8876 8944 8909 9069 8864 9006 8890 8866 9057 9053 8815 9071 9013 8921 8900 8962 8946 8959 8983 8788 9035 8794 8922 8791 8618 8793 8785 8928 9006 8896 8890 9033 8962 8923 8976 8912 8878 8877 9006 8961 8726 8782 8950 8821 8932 8875 8958 8758 8897 8823 8894 8552 8864 8953 8777 8842 8756 8812 8751 8694 8730 8844 8643 8617 8802 8871 8757 8725 8875 8821 8721 8745 8793 8802 8837 8685 8692 8667 8962 8781 8689 8846 8861 8760 8740 8738 8773 8654 8709 8873 8817 8821 8663 8559 8837 8683 8774 8795 8833 8815 8848 8649 8829 8905 8840 8626 8757 8754 8733 8687 8642 8753 8757 8670 8574 8586 8885 8785 8863 8852 8739 8863 8611 8893 8855 8815 8950 8744 8881 8899 8762 8771 8796 8918 8792 8938 8775 8861 8733 8780 8727 8737 8756 8755 8860 8827 8922 8853 8880 8708 8952 8762 8847 8895 8727 8811 8854 8833 8825 8871 8887 8833 8815 9023 8845 8888 8843 8786 8918 8715 8910 8675 8943 8822 8861 8825 8812 8755 8951 8834 8954 8844 8723 8978 8940 8890 8870 8837 8873 8977 9067 8871 8809 8964 8676 8987 8752 8788 8842 8743 8850 8749 8747 8800 8811 8919 8800 8880 8931 8739 8723 8698 8848 8870 8876 8993 8690 8661 8712 8725 8807 8856 8834 8666 8721 8881 8845 8905 8741 8733 8866 8805 8856 8868 8816 8849 8756 8852 8708 8867 8789 8648 8879 8856 9005 8847 8907 8998 8697 8835 8821 8775 8925 9023 8844 8896 8895 9021 8919 8743 8883 8951 8802 8961 8904 8981 9157 9092 9306 9138 9115 9270 9246 9355 9308 9371 9437 9589 9532 9588 9340 9701 9676 9640 9506 9379 9552 9565 9488 9341 9562 9399 9541 9412 9638 9449 9446 9652 9669 9309 9699 9590 9622 9598 10284 10244 10656 11002 11330 11811 12564 13318 13820 14797 15580 16313 16707 16737 16097 15289 14706 13847 13496 13059 13062 13045 13155 13252 13056 12581 12015 11672 10943 10470 10367 10150 9837 9880 9686 9633 9722 9540 9557 9555 9912 9580 9613 9491 9550 9522 9402 9451 9359 9324 9238 9408 9294 9250 9364 9104 9174 8951 9007 9022 8942 9026 9115 9005 8900 8986 8807 8939 8883 8966 8760 8735 8827 8981 8765 8821 8729 8765 8876 8766 8693 8783 8877 8729 8812 8629 8764 8737 8857 8836 8823 8617 8749 8845 8902 8664 8664 8727 8801 8742 8794 8751 8961 8685 8866 8781 8906 8691 8611 8883 9102 8811 8860 8695 8869 8849 8926 8896 8880 9033 8837 8960 8999 9089 8927 9026 8805 9006 8982 8919 8747 8921 9007 8691 8720 8746 8773 8922 8803 8819 8790 8720 8684 8815 8855 8713 8577 8706 8764 8820 8663 8573 8770 8891 8813 8614 8761 8832 8637 8612 8544 8624 8691 8728 8673 8734 8382 8792 8708 8681 8669 8836 8690 8683 8705 8654 8641 8502 8686 8598 8545 8643 8762 8505 8536 8640 8752 8751 8731 8656 8582 8663 8640 8527 8643 8665 8706 8733 8669 8785 8842 8714 8669 8685 8738 8547 8703 8652 8535 8665 8551 8563 8724 8693 8739 8566 8792 8751 8682 8484 8749 8651 8635 8645 8507 8816 8893 8649 8763 8728 8792 8655 8415 8526 8770 8757 8592 8710 8584 8721 8701 8643 8603 8653 8554 8580 8551 8660 8649 8689 8506 8492 8648 8607 8613 8537 8695 8637 8700 8681 8693 8611 8761 8747 8658 8564 8696 8752 8575 8597 8546 8744 8705 8681 8625 8664 8666 8541 8651 8684 8701 8829 8730 8830 8594 8654 8707 8561 8711 8688 8956 8555 8914 8652 8650 8682 8797 8713 8819 8812 8699 8789 8636 8695 8883 8710 8751 8812 8815 8828 9059 8847 8839 8864 9031 8871 8759 8978 8826 8879 8897 8858 8851 8893 8744 8944 8974 8827 8790 9035 8936 8702 8889 8913 8728 8691 8801 8611 8750 8880 9044 9060 8780 9003 9028 8880 9067 9128 8732 8877 9007 9017 8870 8895 8996 9056 9254 9094 9060 9186 9139 9053 9150 9189 9282 9342 9184 9313 9387 9442 9263 9591 9552 9729 9774 9893 9924 10200 10176 10276 10483 10476 10696 10712 10503 10809 10576 10694 10700 10572 10555 10644 10584 10551 10647 10963 10855 10844 10963 11016 11042 10633 10621 10691 10054 10090 9883 9783 9854 9793 9865 9697 9831 9474 9464 9456 9370 9374 9125 9067 9287 9204 8932 9191 9207 9053 8894 9029 8913 8885 9065 9089 8994 9150 9078 9030 9059 9177 9086 9051 9386 9164 9410 9191 9303 9409 9444 9526 9607 9652 9944 9949 9841 9960 10190 10265 10491 10595 10803 10916 11049 11271 11020 11195 10969 11203 10906 10970 10856 10586 10731 10721 10595 10516 10429 10228 10237 10240 10153 10033 9967 9857 9612 9765 9688 9675 9709 9520 9456 9304 9582 9682 9603 9746 9525 9807 9643 9786 9645 9694 9946 10108 10118 9984 9994 9908 10038 10119 9855 10014 9833 9906 9694 9668 9797 9704 9583 9652 9452 9444 9423 9166 9266 9312 9301 9054 9002 8990 8928 9082 8947 8886 8993 8781 8727 9106 8880 9041 9020 8859 8888 8915 9053 8939 8980 8964 8936 8737 8968 8930 8978 8871 8976 9281 9098 9056 8982 8891 9124 8931 9075 9211 9066 9037 9233 9241 9023 9061 9049 9003 9188 9171 8976 9060 9134 9174 8970 9064 8856 8804 8824 8862 8818 8970 8867 8862 8812 8947 8657 8747 8789 8781 8667 8778 8633 8570 8688 8833 8865 8756 8777 8657 8756 8707 8714 8593 8562 8674 8771 8675 8639 8538 8649 8729 8651 8622 8815 8578 8610 8658 8724 8525 8810 8780 8611 8732 8813 8766 8792 8829 8944 8983 8918 8763 8862 8708 8859 8697 8831 8659 8721 8805 8895 8613 8925 8726 8869 8801 8549 8519 8617 8602 8717 8466 8508 8595 8693 8466 8611 8608 8685 8631 8571 8708 8626 8629 8519 8733 8666 8551 8611 8641 8688 8661 8610 8635 8681 8656 8682 8630 8601 8682 8885 8631 8536 8623 8719 8628 8590 8881 8743 8790 8524 8517 8577 8633 8685 8647 8542 8603 8568 8707 8532 8564 8711 8724 8684 8675 8933 8585 8778 8718 8987 8796 8815 8750 8698 8690 8661 8756 8728 8871 8732 8872 8700 8586 8870 8591 8772 8677 8724 8643 8648 8599 8627 8522 8737 8564 8465 8723 8508 8543 8551 8661 8590 8604 8541 8548 8630 8676 8610 8515 8670 8677 8691 8692 8623 8539 8624 8682 8588 8707 8640 8774 8622 8661 8734 8717 8818 8534 8650 8794 8746 8627 8710 8699 8526 8764 8643 8736 8790 8688 8646 8660 8721 8723 8815 8727 8790 8716 8733 8635 8776 8741 8725 8682 8603 8814 8805 8738 8893 8695 8818 8827 8799 8941 8750 8889 8883 8947 9036 9046 8965 9196 9012 9087 9219 9241 9149 9321 9307 9443 9395 9502 9390 9606 9464 9732 9725 9697 9702 9819 9728 9621 9554 9548 9553 9596 9338 9536 9336 9534 9260 9445 9409 9128 9194 9094 9109 9107 8941 9038 8758 9023 8897 9043 8987 8844 8922 8710 8728 8668 8715 8931 8597 8669 8691 8687 8739 8649 8698 8741 8580 8906 8484 8793 8730 8776 8765 8737 8897 8849 8559 9003 8825 8824 8655 8622 8698 8823 8678 8571 8596 8773 8787 8679 8740 8650 8909 8709 8765 8757 8608 8803 8756 8806 8919 8774 8758 8793 8766 8799 8853 8886 9006 8946 8851 8893 8965 9016 9178 9175 9212 9080 9209 9301 9210 9307 9244 9210 9328 9322 9486 9599 9613 9767 9827 9841 9581 9836 9650 9740 9948 9978 9890 9910 10042 9872 9983 9903 9887 9765 10002 10102 10034 9988 10113 9674 9916 10244 9950 9894 9869 9810 9615 9795 9863 9679 10012 9851 9760 9677 9789 9671 9612 9645 9402 9502 9469 9588 9534 9434 9626 9412 9536 9464 9434 9648 9624 9575 9599 9619 9635 9552 9460 9572 9539 9352 9302 9351 9454 9362 9217 9035 9244 9135 9202 9323 9159 9178 8978 9149 9069 9002 9001 8859 8839 8947 8898 8875 8865 8871 8826 8761 8720 8714 8741 8792 8682 8748 8761 8561 8816 8652 8524 8884 8702 8774 8526 8577 8512 8826 8759 8451 8577 8615 8721 8658 8695 8520 8654 8751 8477 8811 8471 8299 8486 8295 8613 8682 8642 8592 8692 8430 8599 8716 8580 8583 8640 8673 8755 8364 8744 8571 8683 8748 8719 8657 8571 8547 8944 8752 8714 8749 8820 8576 8795 8865 8772 8758 8734 8745 8694 8733 8781 8891 8986 8737 8804 8950 9081 9125 8924 8957 9283 9016 9125 9172 9055 9160 9209 9528 9127 9238 9317 9202 9356 9178 9245 9213 9229 9235 9293 9182 9178 9404 9261 9343 9403 9360 9341 9310 9245 9165 9156 8891 9172 9114 9109 9105 9186 9181 9271 9150 9194 9246 9138 9068 9024 8954 9023 8925 8972 8950 8897 9066 8867 9087 8899 8739 8888 8996 9069 8869 9054 8940 8746 8889 8993 9043 9080 9004 8989 9053 9158 9211 8839 8922 9059 8942 9102 9068 9212 9004 9220 9027 8940 9022 8854 9115 9096 9001 9065 9145 8950 8937 8963 8976 8901 8936 8929 8836 8927 8833 9023 8979 8834 8925 8853 8848 8958 8899 8906 9024 8974 9020 8955 8916 8984 8920 9081 8769 8799 8810 8822 8844 8673 8680 8899 8712 8552 8796 8916 8942 8664 8727 8942 8700 8755 8606 8626 8633 8720 8710 8582 8697 8704 8577 8609 8543 8622 8537 8619 8628 8754 8581 8611 8712 8574 8602 8763 8621 8551 8676 8792 8774 8641 8653 8670 8643 8568 8802 8693 8626 8458 8797 8876 8909 8709 8935 8728 9072 8803 9143 9325 9352 9820 10209 10555 11225 11607 12257 12453 11760 11217 10476 10016 9624 9282 9204 9142 9227 9588 9676 10020 10276 10469 10294 10274 9940 9633 9498 9017 8953 8827 8814 8784 8720 8846 8957 8966 8777 8988 9036 9152 9167 9067 9392 9176 9595 9783 9998 10296 10431 10476 10487 10649 10563 10201 10041 10005 9802 9786 9873 9767 9802 10000 10091 10138 10390 10407 10512 10208 10220 10074 9646 9646 9696 9384 9338 9348 9464 9479 9678 9430 9605 9389 9348 9402 9289 9416 9428 9280 9338 9423 9291 9612 9340 9388 9068 9107 9351 9183 9098 9085 9020 9157 8969 8918 8965 9045 9032 9049 8930 8839 8956 8801 8886 8810 8924 8760 8726 8726 8787 8688 8882 8768 8628 8824 8791 8755 8785 8741 8804 8686 8640 8650 8674 8840 8729 8573 8688 8717 8632 8657 8552 8509 8482 8648 8674 8698 8711 8602 8640 8598 8532 8641 8604 8621 8524 8521 8749 8481 8568 8763 8545 8545 8714 8743 8683 8660 8593 8514 8473 8709 8555 8719 8586 8659 8645 8661 8619 8526 8320 8562 8681 8718 8531 8582 8711 8632 8636 8588 8444 8752 8522 8717 8720 8849 8638 8889 8677 8690 8787 8740 8839 8801 8732 8732 8749 8826 8813 8964 9125 9013 8960 8969 9058 8997 9210 8927 8960 8991 8961 9028 9014 8811 8941 8917 8924 8997 8961 8860 8966 8913 8793 8783 8940 8832 8740 8786 8814 8689 8738 8733 8725 8738 8886 8770 8769 8819 8667 8775 8854 8780 8765 8858 8886 8846 8998 9103 9004 8980 9099 9050 9105 9322 9195 9261 9071 9307 9294 9176 9284 9400 9274 9374 9185 9113 9154 9187 9163 9110 9256 9044 8947 8898 8929 9007 9033 8937 8993 8981 9130 8864 8972 8998 9168 9045 8877 9040 9158 9084 8923 8825 8712 8801 8871 8805 8822 8774 8720 8709 8953 8687 8653 8722 8892 8691 8811 8845 8643 8577 8780 8813 8964 8647 8889 8680 8788 8769 8610 8693 8932 8843 9009 8795 8981 8983 8782 8854 8907 9114 9010 9175 9134 9195 9297 9241 9232 9277 9480 9420 9430 9368 9471 9196 9261 9262 9134 9203 9235 9011 9214 9148 9167 9284 9027 9207 8973 8925 9182 8927 8962 9039 8986 8954 8757 8859 8714 8867 8788 8674 8661 8689 8703 8572 8708 8651 8561 8577 8691 8671 8438 8686 8700 8380 8536 8589 8570 8675 8620 8572 8509 8391 8551 8681 8583 8446 8713 8557 8605 8430 8742 8490 8738 8537 8510 8548 8614 8506 8626 8503 8420 8598 8461 8559 8682 8402 8515 8547 8706 8651 8778 8691 8677 8512 8639 8542 8785 8496 8526 8531 8530 8623 8531 8577 8518 8508 8612 8741 8572 8706 8680 8605 8561 8587 8618 8760 8707 8505 8492 8578 8593 8583 8595 8699 8483 8674 8576 8581 8829 8726 8628 8606 8746 8683 8767 8522 8775 8708 8618 8813 8712 8642 8798 8724 8764 9056 8910 8789 8990 8660 8857 8772 8878 8863 8656 8670 8774 8561 8738 8759 8688 8706 8535 8538 8709 8732 8893 8530 8664 8605 8564 8583 8645 8576 8553 8601 8447 8477 8549 8376 8539 8553 8434 8471 8484 8497 8447 8567 8426 8532 8498 8473 8281 8365 8565 8581 8411 8448 8520 8526 8618 8631 8609 8669 8466 8777 8595 8533 8554 8759 8508 8644 8616 8597 8626 8557 8602 8746 8551 8623 8560 8675 8903 8843 8605 8631 8617 8652 8724 8826 8656 8932 8827 8937 8813 8866 9077 9306 9103 9189 9545 9755 9829 10058 10247 10581 10614 10974 11078 10862 10793 10337 10207 9947 9765 9774 9579 9783 9589 9717 9800 9777 9841 9993 10267 9972 10128 10188 9883 9742 9781 9663 9529 9407 9437 9303 9109 9364 9247 9202 9051 9043 9027 9044 9018 9070 9110 9129 9233 9036 9039 8892 8926 8853 8793 8808 8878 8929 8783 8726 8954 8938 8725 8752 8807 8733 8665 8527 8658 8618 8500 8695 8585 8689 8700 8828 8635 8665 8715 8644 8780 8663 8634 8822 8917 8928 9145 9338 9394 9535 9659 9489 9610 9623 9287 9054 9001 8990 8833 8805 8884 8798 8874 9029 8803 9046 9085 9133 9125 8977 8978 8831 8809 8764 8654 8637 8717 8508 8408 8509 8506 8511 8368 8337 8455 8502 8318 8515 8329 8463 8733 8558 8470 8313 8499 8652 8561 8397 8434 8514 8509 8369 8271 8416 8554 8291 8701 8390 8572 8467 8374 8680 8498 8535 8478 8250 8365 8323 8405 8355 8437 8668 8344 8313 8395 8283 8462 8473 8274 8377 8366 8542 8272 8466 8511 8356 8286 8360 8409 8461 8249 8423 8460 8300 8267 8251 8484 8171 8224 8256 8415 8176 8294 8314 8278 8345 8253 8510 8404 8458 8310 8549 8475 8454 8420 8468 8244 8303 8388 8541 8314 8523 8318 8407 8303 8336 8414 8282 8227 8507 8439 8376 8439 8381 8324 8280 8306 8432 8397 8281 8285 8370 8324 8391 8336 8492 8148 8251 8375 8258 8394 8431 8298 8303 8227 8359 8354 8417 8384 8432 8329 8387 8378 8373 8467 8383 8326 8289 8250 8407 8429 8472 8427 8340 8323 8484 8462 8354 8403 8485 8384 8501 8439 8497 8285 8229 8411 8303 8487 8412 8452 8425 8364 8258 8473 8293 8523 8491 8394 8172 8367 8390 8271 8379 8349 8414 8434 8340 8510 8387 8487 8462 8372 8452 8544 8488 8394 8399 8462 8708 8590 8448 8552 8619 8547 8664 8542 8599 8519 8814 8619 8507 8674 8616 8711 8628 8638 8668 8559 8707 8650 8800 8691 8713 8542 8684 8559 8635 8714 8692 8756 8501 8556 8584 8617 8463 8626 8697 8546 8587 8498 8641 8494 8454 8416 8400 8656 8445 8471 8558 8583 8486 8369 8449 8534 8347 8391 8470 8418 8377 8325 8377 8578 8523 8403 8554 8266 8517 8414 8438 8600 8409 8546 8484 8313 8506 8427 8689 8578 8618 8756 8963 8721 8860 9097 8933 9137 9354 9209 9367 9184 9051 8964 8778 8764 8632 8714 8773 8601 8704 8649 8595 8791 8681 8712 8766 8706 8802 8746 8615 8770 8763 8516 8583 8409 8503 8513 8324 8440 8394 8383 8407 8383 8462 8298 8370 8394 8389 8401 8525 8416 8459 8452 8198 8436 8335 8553 8609 8499 8425 8387 8478 8458 8553 8506 8325 8419 8321 8394 8367 8313 8453 8326 8380 8368 8144 8225 8477 8415 8342 8421 8372 8393 8277 8410 8282 8191 8330 8302 8343 8366 8409 8390 8370 8386 8262 8407 8398 8426 8423 8266 8277 8314 8202 8290 8435 8344 8630 8206 8356 8379 8413 8397 8524 8541 8441 8228 8445 8369 8410 8400 8620 8510 8312 8200 8547 8534 8509 8361 8658 8630 8485 8453 8600 8627 8575 8674 8530 8588 8654 8754 8413 8679 8550 8674 8647 8587 8723 8481 8710 8671 8761 8750 8697 8716 8800 8660 8701 8579 8723 8627 8718 8764 8508 8570 8686 8536 8729 8631 8555 8636 8536 8410 8567 8561 8517 8608 8533 8637 8567 8373 8499 8521 8632 8486 8372 8346 8449 8439 8582 8587 8517 8389 8462 8598 8215 8506 8429 8549 8621 8395 8355 8340 8317 8522 8349 8375 8463 8472 8537 8362 8369 8571 8578 8467 8502 8330 8507 8404 8517 8499 8456 8401 8610 8570 8582 8517 8510 8612 8350 8496 8394 8521 8464 8577 8625 8311 8677 8326 8546 8493 8479 8386 8562 8620 8565 8435 8509 8570 8567 8741 8583 8625 8475 8546 8435 8451 8503 8476 8525 8516 8547 8519 8511 8542 8575 8434 8445 8556 8337 8710 8413 8626 8456 8541 8431 8500 8411 8489 8447 8378 8318 8372 8512 8368 8501 8487 8593 8336 8746 8471 8369 8363 8434 8431 8304 8489 8280 8312 8459 8560 8523 8308 8352 8357 8584 8484 8274 8250 8314 8280 8355 8258 8362 8251 8249 8346 8379 8375 8200 8388 8490 8422 8221 8356 8311 8198 8086 8453 8242 8405 7968 8100 8309 8421 8244 8164 8263 8482 8192 8252 8299 8119 8258 8426 8276 8292 8602 8374 8482 8269 8426 8403 8344 8249 8427 8510 8337 8474 8389 8383 8346 8521 8349 8494 8598 8276 8397 8408 8270 8212 8452 8448 8239 8391 8315 8473 8495 8331 8279 8230 8333 8424 8381 8449 8315 8505 8553 8381 8362 8444 8297 8276 8483 8265 8381 8418 8402 8470 8345 8460 8377 8510 8612 8276 8391 8355 8355 8346 8374 8324 8175 8305 8306 8307 8220 8508 8227 8232 8204 8440 8202 8185 8266 8215 8219 8408 8212 8149 8212 8393 8360 8435 8403 8387 8145 8324 8354 8230 8203 8352 8407 8269 8459 8286 8362 8313 8310 8356 8384 8453 8446 8346 8265 8436 8427 8326 8530 8396 8397 8588 8479 8265 8517 8544 8588 8590 8337 8399 8441 8559 8509 8510 8541 8491 8415 8538 8275 8414 8499 8468 8567 8450 8393 8525 8539 8351 8540 8747 8714 8664 8636 8375 8597 8648 8548 8558 8586 8689 8416 8585 8621 8556 8831 8643 8544 8582 8601 8519 8573 8540 8558 8532 8622 8399 8706 8627 8473 8421 8604 8584 8622 8596 8546 8545 8562 8432 8475 8556 8569 8560 8405 8587 8403 8439 8514 8442 8415 8295 8396 8471 8359 8241 8435 8392 8465 8391 8546 8467 8355 8428 8370 8120 8426 8195 8366 8383 8317 8335 8183 8256 8385 8402 8250 8416 8420 8345 8362 8221 8237 8148 8461 8442 8169 8224 8328 8318 8254 8420 8345 8269 8315 8250 8190 8373 8202 8245 8181 8268 8161 8189 8296 8422 8317 8217 8366 8146 8325 8450 8345 8310 8504 8334 8375 8278 8367 8435 8341 8370 8393 8406 8371 8356 8347 8423 8487 8386 8468 8413 8335 8213 8339 8484 8380 8456 8446 8287 8368 8301 8525 8377 8447 8397 8427 8343 8327 8642 8320 8479 8575 8491 8423 8297 8243 8396 8519 8419 8565 8439 8435 8357 8626 8363 8395 8388 8528 8457 8342 8403 8512 8401 8441 8492 8250 8401 8434 8476 8253 8369 8611 8366 8310 8342 8311 8477 8325 8498 8308 8490 8407 8283 8277 8260 8321 8371 8278 8447 8171 8422 8411 8305 8229 8380 8333 8359 8290 8475 8492 8271 8289 8388 8320 8303 8260 8390 8283 8288 8324 8290 8176 8440 8301 8300 8321 8469 8519 8227 8473 8321 8235 8297 8428 8408 8386 8166 8426 8347 8527 8287 8475 8425 8528 8258 8444 8275 8291 8374 8359 8208 8360 8449 8467 8321 8442 8442 8288 8426 8417 8282 8552 8254 8384 8324 8258 8235 8400 8387 8199 8522 8323 8114 8419 8369 8337 8335 8353 8166 8264 8225 8176 8439 8147 8251 8406 8260 8300 8457 8415 8473 8342 8331 8402 8376 8390 8192 8451 8254 8328 8375 8331 8365 8241 8341 8309 8375 8341 8287 8300 8476 8367 8377 8312 8364 8446 8146 8403 8209 8512 8381 8386 8506 8540 8490 8440 8265 8681 8545 8682 8592 8729 8633 8543 8722 8563 8499 8568 8362 8266 8483 8294 8453 8396 8511 8382 8365 8588 8601 8592 8735 8686 8872 8618 8694 8735 8752 8636 8646 8563 8530 8650 8578 8591 8501 8496 8642 8604 8541 8601 8510 8603 8630 8692 8697 8380 8697 8285 8472 8491 8425 8373 8375 8541 8465 8411 8550 8495 8599 8355 8390 8442 8222 8327 8484 8421 7991 8414 8415 8496 8410 8410 8391 8564 8458 8522 8562 8558 8190 8593 8581 8740 8579 8582 8543 8409 8451 8394 8333 8252 8317 8063 8451 8428 8208 8297 8375 8405 8478 8276 8368 8518 8372 8398 8340 8275 8342 8220 8422 8215 8331 8347 8418 8361 8427 8395 8434 8221 8433 8161 8511 8470 8232 8248 8394 8302 8244 8454 8372 8277 8349 8244 8206 8258 8289 8150 8146 8340 8252 8347 8349 8402 8458 8255 8335 8272 8388 8199 8267 8225 8219 8250 8283 8396 8300 8134 8255 8144 8142 8235 8270 8349 8239 8079 8091 8253 8102 8339 8330 8194 8170 8193 8319 8237 8498 8064 8072 8272 8212 8119 8189 8367 8248 8307 8368 8327 8316 8209 8328 8231 8020 8200 8154 8217 8342 8190 8309 8279 8325 8207 8331 8319 8323 8093 8157 8116 8193 8153 8173 8208 8258 8270 8369 8148 8128 8347 8218 8320 8279 8226 8330 8255 8453 8176 8291 8211 8373 8181 8212 8243 8381 8255 8195 8194 8320 8172 8317 8163 8329 8039 8368 8343 8083 8279 8161 8350 8118 8231 8427 8285 8233 8325 8186 8363 8299 8341 8461 8565 8346 8447 8448 8274 8312 8416 8445 8434 8411 8422 8426 8411 8428 8543 8331 8327 8453 8304 8253 8387 8558 8469 8496 8404 8445 8386 8446 8471 8375 8643 8334 8528 8566 8561 8539 8562 8298 8529 8399 8553 8322 8347 8505 8573 8374 8431 8497 8504 8510 8470 8503 8435 8616 8395 8483 8361 8359 8568 8505 8503 8580 8457 8473 8530 8441 8459 8467 8635 8473 8402 8460 8550 8570 8572 8595 8560 8270 8602 8606 8712 8783 8807 9055 9088 9189 9528 9484 10228 10685 11436 12138 12897 13006 12334 11781 10846 10159 9895 9228 9082 8865 8956 8839 8779 8938 8680 8833 8862 9225 9358 9565 9873 9924 10324 10672 10629 10509 10179 9744 9401 9381 8806 8957 8773 8609 8541 8557 8571 8597 8383 8441 8555 8495 8519 8366 8525 8498 8474 8428 8478 8434 8467 8467 8409 8447 8469 8567 8401 8340 8400 8482 8378 8404 8474 8497 8539 8237 8481 8344 8402 8424 8429 8424 8485 8541 8383 8652 8501 8523 8312 8540 8610 8440 8470 8495 8629 8536 8446 8530 8377 8465 8586 8477 8383 8418 8490 8676 8488 8548 8401 8595 8460 8456 8470 8467 8507 8221 8366 8337 8202 8382 8232 8473 8344 8285 8270 8377 8509 8413 8396 8539 8379 8368 8272 8315 8362 8402 8384 8420 8322 8353 8478 8362 8331 8483 8346 8309 8341 8527 8394 8518 8520 8400 8489 8513 8544 8492 8564 8877 8858 8562 8890 9035 8900 8857 9014 8855 8754 8912 8582 8663 8534 8777 8575 8626 8564 8516 8593 8519 8619 8595 8569 8623 8621 8700 8721 8683 8605 8725 8420 8666 8739 8608 8583 8561 8624 8504 8428 8520 8419 8260 8546 8375 8556 8442 8322 8382 8306 8297 8241 8407 8322 8272 8230 8187 8366 8339 8154 8351 8325 8239 8336 8350 8274 8301 8293 8272 8183 8269 8170 8315 8412 8126 8283 8093 8344 8439 8324 8338 8272 8295 8247 8323 8388 8451 8335 8498 8395 8328 8510 8353 8331 8422 8235 8310 8457 8450 8501 8170 8365 8350 8430 8499 8310 8214 8151 8108 8351 8249 8345 8329 8108 8404 8245 8175 8258 8245 8102 8294 8382 8306 8417 8382 8279 8319 8183 8347 8242 8314 8287 8216 8376 8315 8351 8206 8201 8374 8257 8383 8264 8177 8190 8236 8147 8265 8253 8342 8053 8352 8228 8420 8219 8142 8114 8359 8288 8348 8298 8258 8424 8304 8204 8209 8344 8468 8469 8301 8510 8518 8486 8500 8478 8783 8796 8958 8879 8952 8786 8674 8815 8721 8494 8433 8397 8412 8500 8259 8479 8478 8483 8448 8495 8350 8515 8465 8425 8449 8625 8629 8540 8645 8630 8731 8529 8579 8390 8473 8513 8362 8519 8302 8290 8349 8512 8271 8385 8388 8253 8358 8344 8382 8160 8332 8312 8344 8282 8446 8367 8363 8432 8459 8272 8259 8359 8069 8353 8287 8183 8277 8286 8185 8443 8273 8420 8241 8329 8165 8102 8220 8245 8164 8278 8216 8197 8247 8064 8370 8161 8232 8341 8161 8336 8270 8234 8350 8233 8238 8179 8204 8334 8291 8446 8171 8339 8153 8369 8219 8248 8390 8319 8198 8303 8428 8483 8416 8263 8455 8533 8590 8514 8382 8389 8489 8369 8300 8421 8360 8238 8377 8276 8350 8240 8341 8283 8263 8341 8243 8441 8429 8418 8164 8277 8476 8294 8634 8284 8278 8457 8371 8565 8258 8336 8257 8299 8364 8417 8381 8364 8371 8382 8222 8396 8364 8367 8333 8369 8118 8431 8343 8291 8200 8324 8282 8365 8268 8656 8319 8474 8321 8236 8493 8527 8187 8345 8431 8189 8321 8406 8389 8319 8454 8060 8123 8244 8175 8306 8444 8316 8516 8155 8256 8282 8310 8465 8501 8287 8309 8190 8364 8364 8272 8411 8225 8359 8378 8328 8367 8535 8392 8317 8324 8464 8652 8518 8455 8539 8649 8655 8492 8529 8520 8459 8518 8486 8455 8404 8434 8524 8532 8380 8519 8550 8376 8466 8414 8432 8446 8482 8487 8565 8398 8526 8592 8457 8444 8664 8375 8719 8488 8449 8331 8680 8333 8573 8392 8453 8439 8529 8394 8458 8368 8428 8440 8369 8285 8347 8293 8281 8262 8390 8371 8455 8225 8487 8460 8293 8261 8446 8372 8401 8200 8137 8261 8088 8273 8314 8224 8335 8220 8311 8330 8488 8227 8244 8248 8207 8263 8296 8208 8365 8378 8332 8205 8286 8272 8361 8260 8182 8250 8272 8217 8287 8209 8329 8234 8233 8234 8269 8431 8215 8377 8217 8303 8205 8388 8276 8376 8245 8323 8241 8222 8373 8351 8304 8231 8293 8366 8326 8307 8291 8353 8369 8359 8343 8170 8516 8444 8409 8392 8249 8434 8469 8656 8179 8399 8436 8430 8399 8573 8283 8527 8532 8503 8367 8401 8341 8611 8746 8361 8348 8488 8489 8468 8375 8313 8482 8405 8525 8483 8354 8294 8418 8479 8363 8444 8283 8305 8340 8275 8254 8185 8449 8160 8373 8329 8243 8482 8216 8208 8402 8211 8320 8147 8361 8313 8070 8381 8298 8128 8165 8180 8241 8297 8152 8358 8209 8460 8218 8353 8215 8281 8153 8143 8225 8378 8211 8154 8233 8298 8249 8370 8363 8262 8290 8271 8193 8249 8233 8332 8152 8264 8345 8190 8333 8244 8326 8269 8335 8265 8219 8226 8354 8060 8239 8148 8466 8091 8206 8025 8202 8059 8283 8205 8110 8325 8130 8195 8304 8207 8412 8221 8334 8334 8111 8105 8166 8099 8221 8192 8254 8351 8237 8223 8310 8223 8224 8250 8270 8193 8310 8172 8136 8171 8188 8217 8249 8284 8113 8123 8403 8344 8309 8456 8273 8199 8407 8208 8277 8353 8122 8217 8302 8121 8370 8194 8309 8113 8224 8379 8234 8222 8190 8020 8193 8120 8096 8150 8244 8258 8256 8037 8426 8162 8359 8054 8139 8158 8073 8241 8199 8134 8151 8367 8162 8170 8145 8152 8305 8213 8263 7997 8218 8177 8197 8253 7949 8122 8320 8147 8225 8181 8191 8261 8220 8010 7896 8238 8230 8247 8291 8345 8016 8220 8288 8122 8058 8167 8314 8029 8132 8177 8182 8031 8149 8267 8129 8056 8156 8185 8175 8230 8170 8216 8221 8209 8265 8167 8171 8248 8136 8307 8183 8085 8154 8110 8267 8318 8281 8118 8297 8289 8353 8109 8338 8167 8094 8141 8320 8189 8081 8102 8069 8157 8087 8313 8241 8313 8137 8189 8264 8236 8176 8215 8320 8190 7983 8146 8067 8174 8116 8063 8104 8168 8132 8061 8365 8210 8168 8209 8065 8143 8264 8034 8234 8279 8465 8070 8011 8178 8184 8229 8164 8177 8167 8176 8303 8209 8247 8085 8211 8202 8344 8048 8140 8120 8316 8190 8173 8108 8056 8237 8212 8139 8019 8174 8309 8242 7983 8286 8227 8390 8068 8029 8186 8035 8228 8252 8246 8108 8262 8310 8161 8300 8121 8326 8247 8199 8106 8254 8100 8225 8296 8200 8358 8073 8244 8223 8272 8102 8302 8217 8375 8285 8387 8260 8351 8284 8145 8318 8344 8316 8472 8253 8270 8190 8312 8324 8320 8327 8068 8218 8352 8296 8462 8285 8232 8275 8386 8265 8243 8322 8260 8283 8064 8304 8259 8398 8531 8234 8433 8248 8381 8352 8311 8311 8321 8371 8272 8298 8250 8572 8277 8305 8173 8092 8207 8325 8420 8347 8377 8204 8420 8148 8286 8243 8319 8125 8261 8177 8109 8273 8258 8321 8476 8321 8229 8175 8327 8296 8331 8295 8126 8360 8441 8144 8425 8367 8416 8357 8384 8414 8329 8297 8311 8350 8342 8321 8448 8460 8450 8384 8398 8112 8402 8309 8485 8292 8782 8378 8443 8403 8605 8484 8570 8446 8435 8377 8502 8455 8487 8245 8491 8380 8514 8330 8537 8365 8385 8553 8516 8263 8391 8457 8392 8715 8524 8535 8558 8574 8433 8435 8396 8447 8609 8642 8377 8575 8497 8444 8402 8583 8654 8318 8520 8393 8382 8478 8377 8313 8315 8516 8374 8393 8248 8213 8340 8348 8353 8475 8431 8495 8373 8283 8302 8301 8295 8344 8362 8342 8332 8226 8532 8464 8228 8385 8325 8288 8292 8221 8230 8253 8228 8336 8327 8223 8318 8260 8190 8234 8294 8120 8226 8221 8229 8336 8461 8389 8378 8372 8242 8262 8297 8167 8252 8284 8236 8349 8244 8049 8286 8414 8374 8324 8534 8347 8451 8546 8372 8362 8359 8584 8361 8450 8483 8348 8336 8288 8351 8293 8435 8296 8397 8691 8178 8393 8438 8433 8292 8209 8461 8492 8495 8329 8486 8570 8461 8453 8231 8557 8551 8512 8434 8570 8477 8349 8453 8499 8483 8569 8408 8193 8494 8550 8323 8380 8422 8258 8349 8349 8248 8436 8164 8495 8418 8380 8322 8517 8384 8468 8633 8457 8298 8426 8290 8412 8574 8592 8260 8579 8429 8311 8412 8440 8556 8505 8378 8363 8332 8269 8396 8393 8618 8486 8299 8345 8249 8301 8342 8157 8279 8430 8240 8374 8371 8468 8285 8173 8437 8296 8239 8412 8117 8146 8283 8244 8413 8162 8158 8384 8351 8328 8339 8196 8390 8386 8247 8256 8287 8162 8387 8327 8326 8306 8161 8269 8252 8286 8215 8132 8404 8192 8233 8357 8436 8292 8187 8178 8357 8191 8304 8273 8296 8481 8134 8091 8242 8299 8153 8468 8219 8269 8124 8187 8162 8393 8307 8138 8274 8231 8348 8416 8190 8347 8535 8424 8352 8426 8320 8326 8356 8150 8110 8328 8181 8138 8233 8124 8282 8133 8195 8136 8294 8382 8245 8221 8256 8006 8310 8128 8224 8316 8210 8126 8214 8134 8349 8202 8261 8186 8282 8307 8112 8308 8158 8205 8112 8473 8115 8258 8138 8333 8333 8269 8280 8456 8233 8420 8271 8276 8247 8373 8321 8219 8317 8329 8198 8394 8211 8231 8242 8256 8221 8477 8483 8335 8115 8315 8393 8130 8266 8464 8312 8391 8396 8364 8341 8295 8255 8413 8391 8417 8348 8196 8364 8113 8281 8233 8321 8390 8440 8381 8463 8327 8172 8343 8249 8341 8414 8280 8398 8439 8440 8279 8210 8076 8246 8477 8560 8317 8134 8412 8407 8588 8424 8422 8524 8201 8567 8390 8411 8350 8356 8394 8609 8359 8435 8361 8450 8296 8564 8364 8361 8501 8309 8373 8382 8271 8595 8366 8355 8401 8458 8386 8218 8320 8262 8435 8351 8431 8402 8308 8274 8318 8447 8340 8285 8257 8338 8298 8324 8322 8434 8421 8197 8337 8333 8526 8396 8388 8179 8310 8443 8187 8350 8378 8416 8470 8144 8192 8168 8200 8303 8330 8082 8374</counts>
			</dataPoints>
		</scan>
	</xrdMeasurement>
</xrdMeasurements>