File: dataset/precursor_mixture/NaAlO2-1.5H2O_Li2CO3_La(OH)3.12-min.xrdml
<?xml version="1.0"?>
<xrdMeasurements xmlns="http://www.xrdml.com/XRDMeasurement/2.2" xmlns:xsi="http://www.w3.org/2001/XMLSchema-instance" xsi:schemaLocation="http://www.xrdml.com/XRDMeasurement/2.2 http://www.xrdml.com/XRDMeasurement/2.2/XRDMeasurement.xsd" status="Completed" recordIdentifier="{E545D820-4D39-474D-890B-51D7B9E71244}">
	<comment>
		<entry/>
	</comment>
	<sample type="To be analyzed">
		<id></id>
		<name></name>
		<preparedBy></preparedBy>
	</sample>
	<xrdMeasurement measurementType="Scan" status="Completed" sampleMode="Reflection">
		<usedWavelength intended="K-Alpha 1">
			<kAlpha1 unit="Angstrom">1.5405980</kAlpha1>
			<kAlpha2 unit="Angstrom">1.5444260</kAlpha2>
			<kBeta unit="Angstrom">1.3922500</kBeta>
			<ratioKAlpha2KAlpha1>0.5000</ratioKAlpha2KAlpha1>
		</usedWavelength>
		<incidentBeamPath>
			<radius unit="mm">145.00</radius>
			<xRayTube id="1010048" name="Empyrean Cu LFF HR (9430 033 7310x) DK437873">
				<tension unit="kV">40.0</tension>
				<current unit="mA">15.0</current>
				<anodeMaterial>Cu</anodeMaterial>
				<focus type="Line">
					<length unit="mm">12.0</length>
					<width unit="mm">0.4</width>
					<takeOffAngle unit="deg">6.0</takeOffAngle>
				</focus>
			</xRayTube>
			<filter id="20010004" name="Beta-filter Nickel">
				<material>Ni</material>
				<thickness unit="mm">0.020</thickness>
			</filter>
			<sollerSlit id="21010002" name="Soller slits 0.04 rad.">
				<opening unit="rad">0.0400</opening>
			</sollerSlit>
			<mask id="22031000" name="Fixed mask 13 mm">
				<width unit="mm">9.00</width>
			</mask>
			<divergenceSlit id="22120001" name="Divergence slit 1°" xsi:type="fixedDivergenceSlitType">
				<distanceToSample unit="mm">50.00</distanceToSample>
				<height unit="mm">1.52</height>
			</divergenceSlit>
		</incidentBeamPath>
		<beamKnife id="29030100" name="Beam knife low"/>
		<sampleMovement xsi:type="spinningSampleMovementType">
			<spinnerRevolutionTime unit="seconds">1.0</spinnerRevolutionTime>
		</sampleMovement>
		<diffractedBeamPath>
			<radius unit="mm">145.00</radius>
			<antiScatterSlit id="22090040" name="AS slit 9 mm" xsi:type="fixedAntiScatterSlitType">
				<height unit="mm">9.00</height>
			</antiScatterSlit>
			<sollerSlit id="21020003" name="Large Soller slits 0.04 rad.">
				<opening unit="rad">0.0400</opening>
			</sollerSlit>
			<filter id="20030001" name="Large beta-filter Nickel">
				<material>Ni</material>
				<thickness unit="mm">0.020</thickness>
			</filter>
			<detector id="7010019" name="PIXcel1D-Medipix3 detector" xsi:type="rtmsDetectorType">
				<phd unit="keV">
					<lowerLevel>4.0</lowerLevel>
					<upperLevel>11.3</upperLevel>
				</phd>
				<mode>Scanning</mode>
				<activeLength unit="deg">5.020</activeLength>
			</detector>
		</diffractedBeamPath>
		<scan appendNumber="0" mode="Continuous" scanAxis="Gonio" status="Completed">
			<header>
				<startTimeStamp>2024-03-22T21:55:54-07:00</startTimeStamp>
				<endTimeStamp>2024-03-22T22:08:22-07:00</endTimeStamp>
				<author>
					<name>Instrument</name>
				</author>
				<source>
					<applicationSoftware version="1.6 (94)">PANalytical Aeris Instrument Suite</applicationSoftware>
					<instrumentControlSoftware version="3.0.0 20211014">AERIS</instrumentControlSoftware>
					<instrumentID>2879380</instrumentID>
				</source>
			</header>
			<dataPoints>
				<positions axis="2Theta" unit="deg">
					<startPosition>9.99043322</startPosition>
					<endPosition>100.09495370</endPosition>
				</positions>
				<positions axis="Omega" unit="deg">
					<startPosition>4.99521661</startPosition>
					<endPosition>50.04747685</endPosition>
				</positions>
				<commonCountingTime unit="seconds">18.249</commonCountingTime>
				<counts unit="counts">3859 3926 3842 3980 3936 4099 3888 3993 3926 3831 3910 3820 3924 3939 3917 3977 3958 3765 3822 3847 3884 3751 3948 3832 3781 3856 3824 3677 3812 3742 3866 3807 3782 3852 3893 3770 3740 3757 3833 3796 3830 3714 3825 3701 3724 3820 3676 3711 3715 3826 3619 3749 3743 3729 3775 3715 3756 3635 3650 3688 3611 3686 3579 3647 3575 3585 3658 3695 3605 3653 3609 3568 3661 3526 3609 3593 3504 3655 3588 3512 3657 3559 3593 3471 3562 3558 3617 3484 3647 3513 3575 3478 3464 3412 3637 3457 3475 3514 3521 3619 3418 3509 3345 3473 3416 3467 3407 3428 3443 3467 3474 3435 3473 3322 3409 3469 3599 3338 3408 3386 3434 3470 3396 3405 3512 3363 3529 3359 3390 3362 3425 3345 3366 3418 3388 3404 3409 3451 3239 3382 3338 3352 3294 3331 3219 3305 3317 3188 3176 3266 3334 3219 3138 3290 3260 3147 3142 3350 3225 3235 3196 3160 3115 3161 3244 3214 3249 3226 3221 3292 3179 3273 3169 3164 3192 3155 3101 3099 3316 3110 3020 3168 3129 3196 3100 3185 3160 3019 3117 3127 3026 3129 3039 3127 3097 3164 3060 3045 3070 3051 3068 3044 3046 3081 2957 3021 3006 3003 3040 3069 3030 3121 2956 3046 2992 3084 2979 3027 3007 2990 3043 2974 2937 3048 3061 2957 3058 3025 2977 3023 2929 2960 2996 2969 2958 2899 3008 2971 2925 2887 2912 2925 3005 3023 2985 2996 2829 2873 2858 2841 2853 2850 2930 2873 2872 2833 2905 2992 2875 2921 2927 2854 2889 2844 2852 2837 2766 2840 2833 2891 2882 2854 2935 2838 2835 2782 2801 2752 2790 2837 2887 2895 2820 2800 2777 2722 2855 2769 2820 2899 2715 2770 2732 2795 2754 2835 2817 2778 2773 2804 2797 2795 2850 2749 2705 2787 2778 2682 2722 2709 2629 2804 2737 2626 2715 2595 2693 2781 2739 2744 2720 2793 2783 2723 2631 2682 2665 2679 2655 2619 2671 2660 2711 2648 2679 2620 2553 2631 2672 2602 2689 2684 2674 2646 2650 2666 2642 2675 2695 2614 2563 2668 2662 2728 2581 2667 2606 2601 2608 2633 2613 2660 2559 2679 2665 2619 2654 2534 2692 2563 2637 2598 2597 2637 2522 2618 2669 2640 2626 2600 2616 2500 2630 2632 2559 2610 2539 2616 2515 2641 2643 2580 2543 2630 2593 2581 2717 2603 2603 2635 2595 2447 2615 2642 2690 2562 2635 2548 2565 2538 2505 2418 2508 2567 2607 2600 2574 2508 2558 2529 2562 2467 2491 2425 2689 2513 2530 2546 2477 2547 2524 2453 2447 2657 2561 2537 2613 2483 2554 2457 2543 2603 2588 2542 2478 2605 2565 2571 2542 2474 2525 2624 2521 2646 2557 2555 2610 2589 2641 2661 2704 2575 2681 2747 2694 2745 2770 2723 2795 2762 2719 2774 2750 2834 2842 2891 2849 3009 2919 2922 3059 3131 2971 3211 3184 3281 3296 3315 3291 3418 3497 3518 3605 3693 3876 3860 3947 4113 4316 4385 4448 4703 4829 5032 5027 5331 5583 5783 6046 6398 6488 7036 7365 7666 8235 8648 8955 9575 9986 10624 10913 11575 12039 12655 13008 13389 13868 13981 14126 14152 13939 13662 13773 13027 12640 11812 11261 10231 9857 8862 8364 7456 7106 6737 6207 5753 5440 5088 4844 4700 4494 4206 4030 3863 3829 3573 3518 3542 3502 3370 3425 3201 3060 3074 3159 3070 2958 3045 2970 2855 2795 2910 2832 2883 2772 2743 2752 2766 2716 2724 2687 2620 2597 2625 2639 2695 2496 2560 2505 2604 2567 2587 2568 2545 2554 2448 2570 2485 2604 2520 2529 2532 2520 2450 2474 2562 2592 2577 2613 2630 2552 2579 2587 2522 2628 2690 2726 2765 2773 2773 2699 2713 2671 2606 2656 2539 2535 2416 2480 2493 2409 2503 2498 2531 2466 2538 2471 2421 2462 2480 2477 2388 2571 2409 2328 2313 2331 2358 2324 2279 2275 2200 2304 2309 2287 2329 2223 2243 2238 2252 2246 2286 2251 2206 2226 2219 2284 2215 2179 2270 2257 2247 2145 2224 2254 2221 2153 2267 2191 2272 2259 2283 2205 2241 2229 2113 2145 2123 2164 2300 2294 2136 2195 2081 2206 2146 2129 2134 2212 2239 2235 2091 2151 2148 2278 2201 2096 2140 2140 2185 2104 2179 2167 2100 2095 2027 2027 2177 2010 2077 2097 2125 2171 2116 2079 2157 2100 2036 2168 2094 2063 2135 2129 2085 2188 2119 2039 2077 2113 2066 2017 2052 2062 2184 2048 2113 2091 2053 2005 2160 2064 2109 2060 2040 2145 2040 2040 2123 2104 2032 2075 2079 2028 2019 2092 1993 1962 2008 2024 2074 2047 2001 1971 2102 1998 2074 2032 1968 2141 2036 1998 2033 2049 1976 2018 2065 2100 2047 1994 2049 2018 1980 1992 2052 1966 1983 1981 2068 2010 2016 2006 1993 1971 2028 2069 1992 1975 2020 2026 2062 1914 1980 2001 1948 2063 2021 2090 2015 2156 2091 2075 2035 2066 2058 1999 2047 2087 1988 2061 2029 2020 2015 1901 1964 1968 1964 1968 1945 1934 1871 1872 1900 1805 1842 1801 1968 1908 1962 1936 1956 1905 1927 1892 1936 1917 1932 1936 1887 1889 1909 1902 1923 1886 1872 1940 1940 1907 1840 1728 1937 1901 1927 1918 1913 1845 1856 1869 1928 1833 1818 1879 1932 1882 1851 1853 1870 1842 1848 1850 1827 1877 1833 1895 1854 1828 1870 1846 1903 1798 1843 1877 1811 1877 1805 1835 1906 1840 1770 1953 1790 1841 1873 1793 1829 1844 1812 1816 1821 1780 1820 1783 1740 1817 1784 1893 1769 1833 1815 1744 1856 1799 1757 1845 1852 1801 1897 1848 1853 1788 1785 1910 1762 1809 1847 1831 1773 1809 1888 1813 1795 1830 1795 1931 1846 1791 1868 1868 1898 1941 1924 1915 1875 1994 2009 1941 2080 2101 2082 2119 2092 2107 2172 2198 2170 2073 2261 2099 2132 2007 2074 2033 1974 2008 2019 1827 1857 1841 1929 1924 1827 2006 1967 1948 2010 2031 2012 2029 2009 2050 2063 2097 2090 1975 1995 1948 1967 2025 1892 1831 1855 1786 1796 1850 1768 1769 1764 1720 1805 1881 1855 1805 1818 1859 1885 1921 1975 1996 2015 2000 2033 2088 2168 2137 2237 2309 2383 2368 2510 2655 2683 2705 2817 2877 3104 3124 3251 3429 3656 3730 3763 3965 4166 4395 4482 4502 4326 3982 3826 3603 3281 3107 2764 2625 2341 2176 2042 1961 1889 1777 1828 1783 1720 1625 1671 1674 1699 1646 1732 1716 1750 1698 1696 1633 1641 1648 1660 1668 1700 1643 1617 1635 1636 1633 1632 1656 1651 1649 1598 1635 1570 1617 1556 1648 1625 1665 1610 1610 1692 1580 1573 1630 1543 1682 1597 1596 1588 1585 1551 1516 1658 1548 1596 1566 1646 1609 1569 1591 1590 1600 1577 1574 1555 1472 1533 1563 1588 1603 1586 1558 1505 1627 1607 1560 1560 1638 1533 1551 1586 1526 1381 1590 1551 1597 1593 1572 1465 1566 1548 1498 1521 1566 1550 1557 1542 1577 1550 1562 1475 1555 1524 1468 1480 1580 1536 1462 1588 1537 1524 1528 1559 1519 1542 1495 1466 1544 1511 1540 1463 1538 1558 1543 1491 1555 1476 1546 1440 1532 1510 1478 1506 1452 1524 1477 1583 1399 1466 1518 1413 1641 1506 1458 1540 1479 1543 1492 1451 1517 1448 1534 1421 1511 1549 1566 1501 1509 1552 1523 1529 1523 1596 1571 1606 1558 1688 1557 1692 1619 1597 1631 1778 1742 1707 1779 1857 1857 1897 1852 1777 1931 1734 1794 1702 1629 1645 1608 1656 1579 1587 1537 1563 1512 1479 1486 1489 1498 1570 1557 1484 1474 1384 1415 1493 1450 1527 1454 1469 1449 1388 1493 1445 1478 1385 1422 1458 1475 1528 1449 1437 1446 1410 1459 1469 1436 1424 1386 1496 1401 1468 1441 1399 1452 1392 1373 1420 1404 1404 1349 1385 1348 1390 1417 1522 1407 1420 1412 1478 1433 1381 1434 1409 1426 1357 1426 1417 1402 1375 1432 1435 1437 1355 1412 1425 1403 1404 1406 1370 1436 1415 1378 1420 1350 1317 1436 1384 1405 1357 1403 1424 1410 1457 1345 1379 1395 1412 1429 1374 1428 1368 1423 1403 1465 1365 1426 1386 1393 1393 1335 1347 1367 1369 1424 1358 1413 1365 1367 1385 1358 1383 1393 1421 1396 1342 1350 1455 1384 1394 1352 1371 1396 1362 1419 1407 1364 1385 1402 1449 1388 1396 1424 1486 1458 1530 1518 1613 1513 1582 1597 1616 1702 1591 1611 1524 1606 1606 1482 1487 1441 1481 1476 1472 1441 1392 1373 1405 1331 1281 1342 1360 1385 1299 1379 1306 1365 1359 1438 1315 1332 1311 1371 1344 1318 1298 1386 1313 1372 1300 1363 1341 1314 1275 1338 1409 1355 1382 1317 1348 1298 1386 1373 1283 1367 1387 1377 1377 1350 1328 1311 1306 1335 1383 1317 1370 1249 1388 1296 1401 1298 1324 1303 1397 1309 1256 1353 1315 1286 1347 1443 1393 1404 1331 1393 1364 1372 1322 1409 1310 1384 1428 1407 1380 1385 1384 1406 1379 1378 1356 1316 1353 1415 1394 1444 1452 1455 1444 1479 1485 1389 1443 1449 1448 1498 1516 1450 1435 1451 1516 1490 1547 1469 1563 1482 1495 1558 1586 1593 1566 1578 1645 1624 1588 1665 1667 1704 1699 1749 1846 1859 1934 1928 1971 1980 2008 2019 2024 1996 2124 2029 2031 2093 2043 2119 2123 2156 2290 2306 2319 2466 2390 2509 2659 2618 2816 2942 3004 3106 3280 3542 3625 3842 4133 4264 4485 4912 5400 5488 6076 6312 6791 7112 7509 8011 8586 8966 9383 9799 10231 10415 10812 10821 11050 10804 10853 10658 10191 10024 9592 9236 8763 8321 7681 7248 6848 6402 5965 5424 5262 5134 4779 4475 4291 4038 4081 3819 3802 3781 3797 3694 3495 3466 3496 3429 3588 3700 3605 3805 3787 3837 3949 4235 4318 4558 4696 4981 5256 5517 5719 6373 6764 7146 7755 8208 8846 9570 10085 10819 11607 12306 13103 13815 14338 14746 15276 15878 15774 16005 15762 15827 15403 14805 14111 13351 12539 11731 11075 10122 9447 8758 7981 7310 6685 6317 5724 5356 4889 4659 4228 4042 3721 3526 3376 3210 3057 2949 2974 2640 2699 2624 2531 2415 2356 2228 2108 2182 2080 2012 1988 2011 1998 1940 1913 1827 1774 1763 1754 1710 1753 1567 1593 1575 1593 1577 1574 1601 1579 1539 1553 1552 1477 1498 1544 1466 1492 1387 1450 1512 1468 1448 1431 1406 1454 1479 1404 1468 1399 1398 1391 1342 1420 1342 1375 1417 1371 1393 1327 1322 1288 1323 1387 1361 1371 1348 1355 1329 1465 1341 1370 1374 1340 1448 1383 1422 1475 1503 1535 1577 1589 1587 1616 1700 1638 1674 1650 1704 1655 1640 1609 1628 1635 1642 1636 1666 1624 1681 1660 1671 1770 1704 1847 1830 1811 1736 1834 1794 1794 1711 1681 1636 1610 1549 1459 1480 1483 1436 1456 1340 1252 1311 1260 1237 1265 1238 1294 1300 1257 1236 1189 1275 1295 1244 1261 1236 1244 1202 1185 1176 1184 1201 1206 1192 1196 1167 1254 1184 1247 1256 1258 1217 1264 1308 1191 1286 1258 1276 1219 1335 1321 1314 1338 1309 1384 1374 1396 1427 1400 1430 1420 1503 1607 1595 1675 1595 1667 1858 1932 1904 1995 2130 2177 2244 2319 2391 2345 2276 2368 2262 2258 2153 2239 2210 2178 2184 2202 2259 2237 2317 2342 2463 2676 2739 2769 2865 3080 3085 3263 3271 3345 3218 3297 3148 3057 2827 2796 2591 2464 2411 2245 2242 2126 1902 1667 1671 1564 1608 1479 1474 1441 1262 1367 1293 1356 1289 1261 1310 1266 1276 1340 1194 1308 1197 1321 1271 1281 1297 1253 1245 1232 1192 1259 1249 1296 1315 1268 1258 1279 1318 1283 1269 1349 1277 1302 1324 1256 1374 1403 1432 1411 1473 1425 1542 1508 1577 1619 1561 1617 1694 1646 1856 1859 1991 2152 2181 2344 2323 2336 2557 2601 2788 2938 3106 3198 3419 3638 3741 3924 4006 4137 4422 4674 4657 4740 4851 5026 5139 5192 5074 5207 5148 5431 5482 5626 5471 5462 5648 5432 5414 5379 5005 4806 4530 4330 4072 3925 3591 3401 3148 2964 2770 2573 2395 2316 2133 2035 1943 1906 1734 1681 1681 1551 1571 1536 1541 1486 1457 1391 1472 1430 1362 1361 1357 1384 1243 1316 1329 1282 1258 1188 1205 1242 1218 1255 1153 1178 1201 1121 1163 1147 1128 1030 1101 1103 1158 1091 1098 1086 1090 1121 1076 1096 1065 1013 1080 990 1214 1060 1054 1051 1022 1039 1011 1094 1007 1074 992 1075 1027 988 1079 977 1083 1031 1060 1044 1026 1038 1084 1026 1060 1027 1057 1108 1054 1041 1014 1083 1064 1033 1037 1006 1085 1032 1037 1008 1063 1064 1068 1106 1084 1200 1120 1146 1198 1237 1306 1281 1404 1447 1497 1537 1563 1685 1653 1691 1797 1818 1836 1814 1813 1836 1809 1809 1691 1625 1610 1559 1446 1388 1345 1243 1224 1242 1195 1179 1145 1102 1088 1138 1147 1138 1109 1120 1104 1140 1175 1192 1215 1206 1254 1348 1314 1295 1260 1221 1234 1276 1162 1231 1122 1157 1185 1032 1088 1071 1089 983 1017 1050 997 1065 1032 1077 1049 1089 1086 1120 1065 1104 1104 1075 1178 1232 1173 1274 1256 1410 1384 1497 1599 1552 1653 1709 1827 1936 1936 2027 1958 2031 2104 2101 2029 1986 1983 1873 1898 1849 1806 1774 1850 1785 1723 1801 1769 1704 1798 1884 1948 1980 1958 2064 2102 2101 2000 2071 1880 1886 1872 1734 1743 1584 1628 1571 1464 1372 1271 1283 1153 1165 1179 1153 1155 1147 1149 1137 1078 1100 1156 1159 1156 1188 1201 1155 1201 1153 1171 1122 1142 1182 1138 1180 1177 1181 1145 1262 1302 1413 1340 1341 1496 1566 1666 1741 1899 2036 2190 2312 2492 2484 2640 2590 2614 2407 2457 2317 2256 2229 2068 2085 1955 1883 1762 1800 1671 1494 1551 1389 1387 1337 1231 1231 1191 1247 1194 1182 1112 1176 1140 1172 1027 1058 1033 1028 1063 1069 1029 1034 995 1038 976 1029 1016 1006 1030 1054 985 1070 957 993 1025 1044 1130 1101 1084 1059 1081 1107 1119 1197 1203 1305 1316 1373 1395 1423 1532 1539 1531 1594 1627 1618 1694 1691 1645 1602 1589 1513 1567 1544 1563 1617 1626 1608 1618 1640 1672 1745 1789 1881 1953 1970 2004 2101 2109 2223 2276 2402 2583 2585 2769 2778 2976 3068 3131 2937 2899 2726 2474 2303 2272 2177 2139 1995 1836 1701 1682 1537 1382 1329 1259 1255 1163 1094 1127 1094 1041 1019 976 977 953 908 1030 953 983 935 954 1003 960 966 934 917 908 894 946 967 945 951 940 974 918 936 908 876 891 889 943 985 917 967 888 929 981 944 978 1002 986 1009 1059 1070 1071 1135 1203 1231 1276 1328 1390 1525 1543 1743 1742 1756 1809 1854 1860 1874 1884 1773 1713 1662 1739 1531 1565 1456 1334 1334 1274 1157 1110 1117 1060 1032 1028 960 936 947 942 914 959 874 874 930 917 904 891 887 927 813 858 861 896 851 946 915 935 896 931 935 934 1027 983 969 987 992 1005 1012 964 1004 997 984 932 924 966 942 934 986 860 915 931 926 888 923 912 914 943 898 989 898 902 901 900 933 918 897 910 903 904 942 904 929 929 937 979 955 990 950 940 955 909 969 964 1016 941 1010 959 992 988 941 966 997 989 979 984 974 981 971 938 947 958 986 949 908 982 927 1006 1011 959 967 910 982 932 911 938 925 937 940 934 963 932 931 962 958 917 1018 928 952 982 1007 904 916 972 1007 944 994 1027 1008 1068 1061 1090 1109 1141 1115 1150 1194 1245 1289 1368 1396 1336 1403 1433 1468 1444 1468 1484 1310 1342 1368 1425 1462 1415 1446 1439 1395 1323 1441 1477 1478 1565 1673 1678 1751 1887 1849 2080 2138 2232 2292 2316 2367 2427 2307 2379 2440 2357 2584 2651 2522 2626 2774 2942 2994 3182 3237 3451 3573 3890 4073 4232 4663 4827 5215 5546 5759 6282 6704 7108 7615 7855 8376 8793 8937 9463 9728 9731 9768 10001 9726 9831 9591 9515 9531 9022 8666 8480 8200 7859 7361 6891 6467 6021 5752 5260 4901 4805 4383 4105 3859 3639 3403 3254 2917 2812 2702 2503 2518 2408 2267 2320 2156 2137 2122 1954 1963 2078 2060 1990 1897 1880 1877 1852 1681 1685 1619 1608 1516 1543 1607 1448 1495 1356 1339 1255 1285 1251 1168 1116 1122 1102 1141 1067 1111 1095 1024 1043 1042 1064 988 1001 998 988 998 948 1014 990 964 985 953 940 965 971 936 985 900 949 933 954 942 951 962 919 921 913 944 935 916 908 859 886 881 854 843 889 858 804 823 840 835 871 841 832 859 808 862 849 849 747 802 796 831 818 787 779 849 779 825 850 862 831 822 811 798 842 810 809 839 793 804 850 811 893 800 852 859 793 901 838 812 804 930 826 818 829 840 846 816 822 785 861 807 813 823 836 795 816 850 825 855 798 861 875 875 854 831 858 867 875 889 888 927 951 915 907 946 881 920 894 976 965 1012 976 1017 1034 985 946 963 978 978 919 957 1007 931 1018 868 1015 1043 1008 962 991 957 1048 964 992 1040 1081 1092 1032 1135 1092 1110 1127 1154 1265 1171 1235 1281 1253 1391 1312 1380 1445 1514 1511 1596 1571 1687 1699 1743 1782 1946 1985 2005 2121 2195 2338 2282 2351 2346 2341 2367 2291 2266 2299 2140 2165 2080 2126 1966 1981 1946 1851 1824 1715 1688 1591 1512 1409 1388 1322 1311 1290 1235 1167 1213 1151 1099 1073 1101 1064 1059 1026 1036 1049 1015 1033 985 1047 934 986 917 942 940 938 932 963 961 844 927 854 919 901 810 889 824 841 802 778 844 765 874 821 839 779 785 850 773 794 779 783 737 783 800 791 748 785 763 744 778 776 729 781 730 731 763 777 776 797 743 761 774 781 778 770 784 747 739 724 770 780 799 808 847 823 842 934 966 903 1023 1040 1025 1058 1101 1041 1068 1041 1044 983 916 930 860 917 869 879 920 891 851 847 836 772 747 828 818 724 770 806 773 758 766 800 764 841 810 817 839 826 850 803 844 780 782 750 722 800 747 755 770 701 761 679 706 728 666 664 676 688 686 698 665 695 702 696 719 660 665 631 698 663 699 713 690 661 670 667 666 635 728 674 674 659 736 689 761 700 717 715 681 670 693 715 674 666 675 698 687 699 684 707 714 695 662 682 666 729 677 721 703 680 693 716 693 670 663 633 642 697 666 695 617 651 652 712 721 703 663 653 670 693 663 663 701 680 709 693 691 636 662 720 672 749 686 731 713 660 734 663 754 729 708 742 719 690 699 708 706 714 661 719 727 761 716 691 724 701 716 714 719 689 702 663 712 674 688 683 676 625 698 684 722 733 717 689 704 704 708 696 724 681 751 774 788 751 717 687 754 787 765 715 781 749 755 707 790 758 748 718 689 699 715 737 761 687 712 769 737 734 750 735 752 712 713 672 700 691 713 740 733 742 716 683 730 709 697 727 681 719 753 719 651 674 716 665 700 703 684 703 710 719 747 681 723 729 702 695 702 733 762 721 721 753 799 813 820 822 835 857 852 838 897 890 925 899 940 964 1000 1048 1044 1019 1105 1083 1110 1092 1061 951 954 991 953 986 1004 995 976 911 868 901 878 859 849 915 830 894 956 903 860 891 865 949 905 909 903 924 961 954 979 994 983 1144 1096 1124 1175 1253 1250 1295 1342 1532 1501 1573 1650 1782 1808 1823 1929 2024 2129 2162 2156 2221 2318 2343 2277 2256 2268 2317 2325 2100 2218 2183 1977 2008 1944 1803 1785 1713 1687 1654 1643 1557 1423 1453 1376 1333 1298 1191 1245 1161 1151 1117 1129 1113 1086 1037 1075 1038 1029 1060 1067 986 1009 1061 1007 1052 1024 1030 1109 1022 1027 1011 1007 1005 1036 1057 1058 1082 1081 1123 1043 1079 1119 1117 1138 1167 1258 1209 1202 1211 1262 1322 1320 1393 1407 1431 1451 1505 1525 1558 1644 1688 1667 1708 1837 1974 2028 2135 2246 2288 2484 2536 2621 2721 2893 2973 3151 3293 3484 3582 3680 3840 3981 4018 3981 4149 4117 4190 4253 4152 4246 4245 4272 4323 4254 4157 4156 4174 4178 4118 4218 4171 4241 4280 4470 4365 4515 4567 4722 4820 5176 5308 5374 5666 5859 6090 6155 6665 6816 7059 7378 7421 7382 7712 7969 8099 7990 7966 7970 7867 7856 7372 7413 7269 6990 6874 6612 6406 5977 5977 5626 5361 5078 4816 4544 4399 4182 3856 3653 3564 3340 3155 2920 2797 2623 2531 2416 2328 2262 2041 2042 1903 1807 1782 1790 1618 1662 1590 1467 1442 1447 1513 1243 1274 1290 1260 1217 1190 1206 1259 1167 1125 1157 1072 1122 1090 1140 1069 1057 1077 1001 972 1034 1033 981 956 962 974 952 978 932 1058 1010 960 962 900 932 925 901 951 958 956 965 952 990 983 995 1004 994 980 1021 1003 1075 1056 1055 1105 1103 1104 1257 1228 1344 1254 1330 1341 1403 1467 1464 1499 1557 1573 1634 1692 1715 1799 1701 1734 1755 1744 1778 1658 1660 1674 1610 1633 1551 1539 1456 1473 1391 1331 1325 1249 1271 1260 1161 1105 1074 1142 1060 1117 1087 1083 987 1035 1022 1024 993 982 974 967 966 996 962 907 889 937 885 909 925 904 894 861 875 855 841 896 859 846 782 831 812 763 720 728 737 771 760 740 730 765 793 688 641 687 652 699 693 691 685 665 643 642 673 653 690 659 672 645 645 694 655 660 621 650 658 641 623 673 633 631 641 636 646 591 660 622 566 580 627 617 664 621 638 663 615 672 623 643 646 628 622 649 584 635 619 613 675 651 697 659 640 718 620 660 676 634 661 627 670 616 598 630 610 655 607 629 624 608 636 577 624 580 597 638 602 596 609 579 618 656 631 616 638 589 578 640 617 619 642 622 642 616 606 629 653 688 580 619 657 688 702 705 695 738 754 780 791 801 791 848 855 913 892 843 840 830 788 857 813 815 771 777 778 740 737 753 703 726 782 649 678 668 643 637 627 647 608 602 625 604 600 610 577 593 584 639 631 612 609 602 592 572 603 593 610 573 629 598 609 559 628 586 656 621 656 616 652 624 672 674 649 654 625 670 630 638 623 610 619 594 660 639 671 635 636 654 683 711 691 716 749 735 751 750 720 723 674 765 713 686 730 671 637 665 691 681 666 674 679 685 713 611 612 590 561 586 585 569 593 600 605 591 590 614 567 587 624 585 540 606 597 564 564 594 624 636 550 571 609 590 610 614 588 625 584 594 600 557 653 645 600 658 666 623 679 627 677 658 629 645 626 619 670 650 638 651 634 609 594 635 610 605 619 615 600 563 608 609 591 578 599 569 615 613 600 587 589 554 568 611 608 576 594 601 632 559 608 577 605 582 589 559 640 590 547 578 610 604 613 618 601 625 581 622 611 578 645 629 658 658 617 632 610 647 653 637 638 621 597 633 694 626 644 648 657 625 649 626 653 628 620 649 607 657 670 678 667 653 665 694 638 625 667 659 676 642 668 763 724 704 704 677 704 732 690 679 754 762 758 792 799 764 796 784 853 807 762 836 866 880 883 918 920 907 987 947 1067 964 1047 1036 1095 1138 1222 1217 1372 1353 1401 1557 1592 1534 1613 1809 1915 1898 2036 2125 2210 2240 2339 2432 2454 2550 2561 2648 2578 2776 2738 2681 2784 2688 2609 2595 2561 2504 2386 2468 2308 2391 2251 2177 2186 2071 1915 1940 1840 1871 1762 1723 1681 1689 1543 1572 1506 1377 1380 1343 1230 1210 1281 1137 1162 1137 1113 1090 1075 1048 1091 1046 1042 1046 993 1013 1053 954 955 901 929 933 885 906 852 886 933 871 881 909 922 885 918 905 906 929 900 916 905 986 964 963 1034 1048 1085 1114 1143 1200 1191 1218 1273 1286 1333 1393 1477 1444 1426 1496 1461 1510 1545 1469 1588 1519 1580 1459 1530 1443 1506 1438 1412 1374 1339 1333 1281 1318 1301 1253 1242 1173 1158 1138 1072 1048 1032 1046 974 929 900 831 916 849 838 834 865 806 835 767 799 828 819 852 861 845 868 845 869 914 875 896 869 784 812 737 787 723 753 799 723 794 671 713 709 772 740 694 711 611 692 663 683 713 642 644 644 642 634 631 657 641 663 668 687 671 667 630 708 638 694 669 675 692 698 697 738 725 826 796 791 799 883 919 900 890 895 920 966 922 918 909 925 943 983 1024 1049 1114 1122 1072 1164 1155 1101 1192 1133 1130 1127 1169 1170 1152 1165 1279 1211 1341 1210 1344 1300 1349 1363 1352 1460 1344 1316 1329 1271 1320 1244 1293 1309 1257 1240 1243 1212 1229 1249 1167 1141 1160 1164 1086 1155 1033 1091 1036 940 1030 1002 1021 955 948 895 938 854 875 909 879 800 842 820 783 827 792 748 751 829 772 817 737 801 737 767 748 773 796 747 794 758 811 797 811 760 809 764 806 833 785 831 797 789 818 838 851 813 856 870 860 889 905 933 971 919 1043 916 983 1034 1107 1126 1078 1094 1078 1195 1120 1146 1182 1129 1151 1208 1150 1195 1207 1166 1183 1202 1230 1213 1106 1064 1204 1134 1159 1082 1063 1090 1073 1020 1004 956 926 1007 946 890 866 900 862 804 805 768 805 756 748 755 705 690 689 712 633 747 651 682 624 656 648 638 611 603 563 589 567 596 590 579 590 566 595 574 624 552 593 563 595 638 583 597 606 614 636 630 608 668 671 709 680 694 736 720 776 780 818 752 788 746 764 749 737 737 747 732 757 687 686 716 689 692 670 725 664 646 605 642 650 608 592 603 572 607 607 560 549 585 579 559 583 559 528 542 514 547 536 559 502 514 516 530 497 535 511 506 494 529 519 517 515 520 529 531 531 516 534 560 526 524 583 567 577 590 606 581 526 556 579 555 576 590 580 601 594 608 580 622 594 618 591 621 626 566 604 551 513 549 551 589 526 578 569 519 565 532 512 500 531 534 542 530 555 533 582 562 589 567 627 586 611 561 588 652 610 628 619 574 541 569 602 661 585 614 625 597 656 642 543 601 609 653 579 604 634 589 618 609 597 547 613 592 592 568 600 622 618 632 634 623 610 638 646 616 621 593 612 612 599 647 644 652 639 696 620 647 687 627 655 651 652 619 616 618 620 612 553 582 575 577 624 664 572 670 630 573 627 692 686 690 719 710 841 800 834 813 847 900 901 880 869 944 861 870 842 889 807 781 843 749 801 801 791 797 752 788 719 732 729 706 735 670 648 688 635 653 667 623 687 657 740 669 707 758 746 744 710 683 712 729 709 653 657 602 630 623 591 659 569 639 658 690 601 608 582 591 588 606 554 637 549 517 495 558 525 588 545 472 530 540 542 548 528 560 546 501 538 545 503 520 541 574 518 536 540 554 509 555 537 544 548 555 574 620 563 578 573 577 603 572 596 545 631 612 639 692 678 694 670 682 655 661 689 643 665 661 620 664 617 681 678 729 693 690 727 647 723 678 671 690 675 665 685 735 753 708 650 721 690 756 759 757 732 772 776 807 848 821 883 824 842 921 932 940 1005 1000 984 1017 979 1069 1051 1034 1068 1107 1106 1213 1219 1263 1261 1383 1367 1421 1436 1441 1454 1552 1592 1636 1554 1725 1712 1736 1817 1835 1869 1929 2001 2097 2011 2096 2107 2070 2095 2104 2036 2016 2022 2061 2024 1917 1972 1966 1954 1852 1865 1755 1803 1719 1683 1598 1533 1648 1577 1489 1508 1459 1441 1364 1329 1297 1313 1237 1264 1215 1146 1173 1039 1088 1085 1043 1063 1010 956 940 934 938 879 890 858 896 799 881 800 854 798 833 829 815 753 811 712 719 747 720 755 759 698 708 706 723 789 754 725 766 724 766 725 761 818 743 843 847 836 855 871 880 895 908 940 977 995 1013 1044 1046 1070 1012 1128 1102 1123 1058 1116 1087 1135 1208 1104 1069 1078 1171 1094 1045 1011 1053 1102 1036 1030 1010 986 1017 959 905 973 919 932 933 936 865 846 854 855 829 843 883 881 886 844 862 814 845 854 837 811 752 727 713 747 715 745 688 747 723 701 742 725 728 673 656 732 693 684 661 633 672 668 685 742 712 701 712 744 736 763 774 774 802 724 725 746 777 787 763 784 736 816 766 731 747 780 784 750 771 746 772 749 748 739 740 732 715 725 737 686 654 627 669 664 672 643 659 647 656 577 618 644 637 576 587 572 604 587 569 544 577 572 581 532 564 526 537 571 531 545 531 544 554 488 490 512 489 575 506 525 509 531 502 495 520 490 477 495 486 508 548 507 509 559 496 505 523 531 519 542 544 536 538 488 560 507 565 553 580 566 578 583 556 589 591 608 595 585 563 581 624 495 555 567 539 572 549 598 559 541 582 552 574 556 551 582 519 551 509 583 518 531 546 523 521 528 501 491 538 482 523 519 514 540 501 511 521 513 519 500 512 555 565 493 512 546 485 493 455 475 487 479 486 475 505 498 518 452 464 487 473 459 484 531 484 482 457 510 460 419 445 480 480 451 481 461 502 481 478 478 475 478 497 484 484 494 530 451 493 492 502 560 489 546 509 520 506 535 495 549 480 496 546 539 478 518 510 503 492 503 505 495 502 478 510 502 507 500 516 536 506 498 521 514 494 518 464 503 471 514 469 503 517 541 489 537 504 504 508 520 530 550 529 542 538 558 553 580 581 594 624 626 646 620 671 613 621 679 649 651 684 695 679 695 669 738 692 661 709 661 657 658 698 716 693 690 667 709 706 652 725 725 731 694 717 675 750 653 755 698 664 737 693 664 681 691 685 741 692 725 685 751 709 747 717 800 809 827 810 752 836 851 787 844 848 831 907 887 906 897 910 981 960 1045 1046 1090 1145 1157 1160 1199 1241 1327 1286 1390 1398 1452 1463 1540 1538 1561 1604 1677 1697 1726 1616 1710 1644 1688 1667 1564 1585 1568 1600 1569 1570 1549 1474 1434 1420 1446 1415 1380 1347 1364 1325 1288 1261 1249 1279 1201 1091 1082 1081 1053 971 1000 970 865 910 876 834 837 811 793 788 783 784 816 760 815 735 715 688 709 758 677 687 676 747 656 620 692 630 648 671 656 660 605 650 640 630 578 655 591 628 640 688 594 646 602 583 631 625 603 652 645 634 626 650 599 660 661 636 700 683 639 649 715 703 680 671 737 792 726 755 782 751 762 755 839 830 857 874 836 836 811 814 831 754 859 875 835 831 813 823 795 845 778 786 830 819 758 803 762 803 765 714 707 719 726 671 691 672 648 703 642 673 625 647 627 625 640 625 589 602 628 541 574 604 598 551 567 575 546 557 532 539 536 545 520 513 541 563 536 506 534 514 544 534 507 509 583 519 544 508 534 544 544 518 543 566 535 594 527 497 553 543 535 552 534 552 531 555 585 497 525 523 554 549 480 510 496 488 485 506 474 502 497 499 483 523 527 489 459 523 489 511 494 513 496 497 491 531 470 536 530 560 531 582 525 566 600 567 631 569 607 588 646 591 580 559 618 610 569 608 608 594 589 600 650 623 595 611 562 644 591 573 566 622 615 570 666 576 604 599 647 625 606 633 637 625 630 634 632 625 626 625 671 638 706 674 631 645 628 678 680 627 659 620 599 616 620 568 631 621 636 671 597 643 532 553 582 534 583 583 610 555 525 599 512 554 517 591 527 536 543 501 516 494 461 500 473 536 493 500 473 489 485 556 500 509 463 509 497 504 506 471 504 510 511 502 544 479 512 476 533 471 462 526 508 523 538 527 519 566 557 521 552 533 517 548 510 581 599 597 568 620 552 552 585 594 582 613 610 666 612 614 629 659 666 609 676 663 647 581 652 674 695 657 643 613 642 615 579 657 607 601 582 557 595 608 586 589 576 635 562 544 519 560 548 520 531 560 522 520 495 511 498 450 488 480 486 516 513 528 461 498 483 477 501 481 436 499 472 401 468 447 458 487 437 460 503 453 484 496 493 443 500 478 475 454 463 497 470 487 464 485 490 513 538 513 489 500 529 464 551 463 519 491 502 479 533 497 514 493 521 564 591 592 581 498 524 599 538 570 551 556 574 508 592 525 512 560 550 552 538 541 526 563 581 538 528 519 599 600 560 556 566 551 533 560 523 559 499 594 605 588 544 560 549 552 611 610 593 623 616 589 595 609 644 646 696 645 676 650 669 666 700 708 706 771 753 787 754 749 781 855 813 888 947 937 945 913 977 988 997 964 995 1044 1071 1047 1122 1080 1047 1069 1045 1040 1022 1068 1081 1010 1035 1032 1076 1046 1053 997 1086 1009 1067 1049 1026 1020 997 1011 978 1053 1073 1065 1007 1092 1051 1100 1135 1087 1186 1085 1126 1163 1105 1152 1226 1172 1233 1186 1150 1236 1230 1229 1272 1251 1131 1159 1173 1129 1149 1188 1099 1111 1104 1119 1112 1099 1119 1034 1058 1083 1070 1014 1018 1062 988 1040 992 961 984 900 991 956 960 1007 958 1013 954 972 915 938 914 931 915 941 897 981 978 968 954 1015 1027 966 1049 1034 1041 1022 1075 1040 1136 1090 1133 1147 1163 1180 1214 1257 1271 1342 1247 1292 1305 1397 1408 1385 1460 1461 1560 1442 1547 1562 1486 1560 1555 1604 1608 1557 1627 1660 1628 1661 1682 1768 1773 1735 1690 1814 1752 1783 1902 1746 1953 1947 1847 1926 1883 1994 2002 1866 1904 1915 1854 1846 1824 1820 1763 1868 1731 1709 1571 1688 1598 1671 1626 1600 1667 1533 1469 1469 1438 1433 1445 1378 1381 1341 1387 1331 1221 1207 1201 1210 1077 1133 1144 1044 1014 1025 1038 1000 992 940 926 939 897 899 865 880 790 801 803 838 808 841 777 778 825 802 776 812 785 823 664 713 751 743 754 794 706 761 753 763 703 708 781 771 792 757 772 794 826 778 763 811 821 808 819 832 837 801 823 834 824 844 852 815 842 805 791 832 760 792 779 809 756 710 784 736 745 728 721 721 701 714 744 726 685 653 732 691 720 625 681 658 653 628 613 632 585 540 585 613 574 591 613 555 563 552 536 558 561 523 508 506 520 488 530 480 523 499 535 521 573 485 520 478 533 500 500 489 517 454 526 524 502 534 457 462 467 471 521 523 457 432 487 492 507 448 527 460 493 492 494 523 488 509 482 462 493 442 431 489 483 445 496 488 434 462 494 476 458 481 524 468 445 446 464 473 478 443 473 448 500 433 452 462 468 446 450 490 521 455 444 496 447 481 452 466 514 464 483 463 460 444 485 457 462 454 477 448 459 431 428 453 472 420 484 464 473 455 478 477 425 454 486 462 480 425 458 465 434 426 454 421 445 459 444 481 489 430 452 453 466 413 474 452 448 450 469 439 446 436 504 465 475 437 408 432 436 426 468 438 418 461 457 444 434 474 449 445 397 426 463 449 412 463 439 441 430 417 435 473 438 444 444 433 449 408 440 391 452 463 483 457 425 463 440 446 458 415 450 451 475 438 453 414 456 437 458 456 413 459 511 502 484 491 498 485 497 521 476 500 455 505 520 482 482 513 482 505 465 494 467 504 489 482 493 535 523 509 525 547 477 511 527 550 557 562 535 523 536 557 519 579 532 530 588 558 572 572 571 559 561 554 557 548 556 562 589 595 610 579 586 559 632 633 616 632 613 659 620 688 656 649 637 648 649 688 727 757 724 679 734 720 790 748 759 774 791 826 850 823 821 879 918 857 909 921 920 935 954 918 932 879 927 884 929 862 905 864 885 812 823 880 866 852 841 819 803 837 823 840 820 760 753 779 736 777 755 727 697 684 645 640 649 636 648 584 609 622 650 573 544 551 537 566 591 543 506 512 520 514 514 526 507 514 526 470 507 536 492 474 487 452 485 466 483 455 453 471 479 486 441 474 455 476 450 456 448 449 443 509 490 454 486 504 461 471 444 440 456 461 468 454 448 450 430 456 430 414 493 442 469 437 401 431 415 403 438 472 441 462 439 418 442 414 436 402 458 415 436 411 402 431 387 450 386 381 410 386 395 438 408 437 438 409 424 422 433 451 412 410 430 420 429 457 437 456 433 420 440 426 418 422 447 435 467 442 437 445 424 412 431 416 407 451 466 474 423 436 392 438 417 442 430 459 419 429 426 439 443 410 418 430 415 454 440 386 465 410 440 408 480 428 412 422 414 463 428 447 438 441 427 459 460 406 468 470 494 444 438 467 483 444 455 456 458 494 478 481 478 483 480 467 526 506 499 527 506 502 557 542 544 591 564 519 532 577 557 557 512 568 590 578 542 560 586 586 541 536 518 582 544 558 571 562 557 546 557 512 569 543 563 588 596 539 545 507 605 525 499 534 519 534 521 504 499 516 528 487 508 510 516 535 510 540 491 468 520 493 500 507 536 471 493 501 474 452 474 471 523 503 480 507 537 532 476 488 495 497 508 528 485 472 519 501 542 484 516 510 466 463 474 507 485 474 526 482 515 508 506 478 450 508 474 505 482 472 503 498 459 508 475 488 495 516 517 509 473 474 532 465 530 523 520 516 517 520 529 489 548 505 502 502 543 526 466 505 501 500 488 520 486 522 490 514 576 519 510 495 502 506 559 487 511 512 516 525 516 501 465 469 464 432 466 461 466 471 445 480 446 487 486 461 507 473 461 453 459 463 495 477 440 506 415 461 438 452 469 516 481 502 462 456 502 430 459 469 475 498 525 524 513 515 512 556 516 536 492 505 516 496 486 511 450 486 477 472 473 458 469 489 531 461 466 493 422 491 483 473 488 499 508 483 485 493 418 435 439 446 477 416 470 478 458 405 501 444 448 466 451 450 448 455 420 457 439 437 447 455 396 461 461 425 443 410 470 455 435 423 486 432 447 473 464 451 471 456 434 407 454 453 471 437 461 477 461 467 458 449 449 475 421 501 508 467 506 473 523 513 497 481 513 448 496 476 553 479 536 484 507 499 549 530 564 524 516 610 595 560 521 593 559 566 610 622 608 611 679 653 662 662 697 699 691 737 685 750 803 759 815 781 821 846 856 864 887 896 912 941 967 972 1067 1032 1029 1000 1029 1019 1089 1027 1069 1074 1059 1028 1076 1047 1018 1060 1033 1034 1004 1016 988 1010 975 990 939 959 930 1010 910 890 928 915 893 898 876 877 881 860 799 834 833 782 718 747 768 745 722 740 680 701 680 681 652 686 646 570 669 658 626 629 606 627 586 580 536 577 598 559 572 551 544 531 531 563 534 564 571 556 582 531 571 503 544 546 519 571 548 613 528 562 557 564 567 565 581 634 588 610 568 582 576 594 635 608 634 599 619 566 642 593 566 599 626 579 631 642 620 653 633 661 685 687 718 740 680 701 698 708 698 711 768 703 726 725 725 726 748 716 699 691 742 760 708 718 774 786 790 776 820 772 825 774 791 800 832 783 826 819 799 776 792 746 755 778 700 802 710 760 756 783 717 775 712 742 712 741 698 752 682 677 698 714 691 667 653 684 654 691 634 707 652 648 611 616 648 592 651 623 588 660 609 632 576 542 558 562 635 578 555 551 556 597 573 618 552 591 570 609 579 581 598 566 554 601 571 576 573 543 548 605 551 573 595 603 585 627 602 565 558 623 576 586 606 563 626 608 580 653 665 633 614 611 621 561 637 626 571 595 612 580 588 562 662 603 562 555 578 578 593 621 586 546 579 569 570 590 533 574 594 561 569 560 526 522 550 486 508 538 510 503 541 483 519 538 551 501 500 540 527 553 525 517 510 574 547 520 519 515 503 493 523 490 536 528 516 490 530 504 508 459 525 509 506 514 511 513 558 546 511 520 574 557 579 538 573 537 514 571 556 514 553 531 547 576 549 567 566 554 502 556 511 556 510 580 548 566 540 477 487 488 510 572 521 544 508 479 536 528 501 503 505 506 528 486 482 525 528 467 489 512 439 495 495 501 477 456 448 465 515 486 433 458 434 460 478 464 454 465 444 436 420 457 419 436 399 450 447 405 455 445 472 420 449 440 466 426 445 430 431 433 457 480 454 501 405 471 475 460 437 451 451 442 435 448 474 472 410 428 430 476 446 469 445 452 443 439 479 448 435 440 419 469 464 468 446 441 417 455 432 442 431 444 460 424 420 440 455 439 437 434 417 417 471 436 458 475 443 511 462 447 447 438 381 435 470 473 485 475 463 449 415 455 483 501 453 465 477 471 497 482 493 464 496 431 470 475 467 456 434 479 443 458 481 468 468 466 463 457 472 435 489 442 454 499 487 453 479 533 464 476 498 484 486 506 504 490 458 535 509 497 559 513 517 548 542 507 555 546 530 523 577 554 578 537 563 561 525 548 525 522 469 553 491 503 531 575 552 535 551 585 585 546 526 564 563 543 587 556 568 574 536 521 598 563 621 577 580 618 543 597 583 641 543 611 626 605 600 655 610 663 615 680 663 649 690 693 708 725 691 695 690 750 751 767 791 752 805 784 798 784 754 825 888 909 879 889 933 927 964 1015 965 970 1029 1029 1032 1044 962 1047 1035 1087 1020 1070 1015 1064 1061 1122 1015 1046 1007 1061 1060 1025 1075 1037 986 1001 989 982 1048 1015 953 1027 980 942 951 929 956 945 954 862 914 949 906 934 916 876 837 865 785 836 816 753 784 750 746 801 788 739 782 713 735 730 734 700 734 751 726 780 711 741 710 724 725 661 668 721 738 762 700 733 695 736 719 681 700 692 751 755 731 762 696 764 719 720 769 793 858 778 767 807 801 782 824 846 826 868 872 864 876 909 893 848 900 868 899 903 901 873 867 873 858 911 859 880 887 912 860 807 843 804 795 807 802 817 812 808 794 788 759 794 822 784 775 724 749 712 743 720 772 759 717 752 674 719 705 685 692 666 654 648 655 669 662 661 606 615 597 615 603 573 569 548 582 571 575 514 540 521 562 522 520 537 533 530 578 538 517 511 542 513 516 515 540 532 519 491 518 538 509 459 496 525 496 491 502 467 491 479 449 486 437 448 437 462 461 504 476 425 470 453 446 451 440 472 436 483 439 469 435 451 413 443 474 410 488 489 461 455 472 462 436 479 468 471 454 462 489 469 455 458 485 501 423 452 478 465 484 445 535 457 426 512 471 473 452 507 477 426 483 502 534 497 463 484 511 480 499 492 504 517 537 488 507 460 471 508 471 522 506 454 484 490 527 476 479 487 480 522 472 488 495 502 496 526 533 456 463 523 496 482 488 521 514 493 519 507 502 497 546 510 488 505 512 517 466 510 472 492 543 508 487 481 496 486 462 497 486 481 521 469 500 458 472 449 440 499 481 462 477 490 528 505 472 492 499 533 471 504 492 472 482 507 489 455 455 430 470 453 467 462 446 456 470 471 473 469 474 445 476 474 449 482 410 421 542 504 458 473 435 474 481 464 445 456 417 483 450 446 436 430 470 483 435 479 490 440 470 425 463 462 449 467 452 421 474 480 453 436 437 444 468</counts>
			</dataPoints>
		</scan>
	</xrdMeasurement>
</xrdMeasurements>