File: dataset/precursor_mixture/NaAlO2-1.5H2O_NaHCO3_MnCO3_CaCO3.2-min.xrdml
<?xml version="1.0"?>
<xrdMeasurements xmlns="http://www.xrdml.com/XRDMeasurement/2.2" xmlns:xsi="http://www.w3.org/2001/XMLSchema-instance" xsi:schemaLocation="http://www.xrdml.com/XRDMeasurement/2.2 http://www.xrdml.com/XRDMeasurement/2.2/XRDMeasurement.xsd" status="Completed" recordIdentifier="{6859ED6A-9BC3-46F1-9D70-09C6A453EB2E}">
	<comment>
		<entry/>
	</comment>
	<sample type="To be analyzed">
		<id>dara-9-1</id>
		<name></name>
		<preparedBy></preparedBy>
	</sample>
	<xrdMeasurement measurementType="Scan" status="Completed" sampleMode="Reflection">
		<usedWavelength intended="K-Alpha 1">
			<kAlpha1 unit="Angstrom">1.5405980</kAlpha1>
			<kAlpha2 unit="Angstrom">1.5444260</kAlpha2>
			<kBeta unit="Angstrom">1.3922500</kBeta>
			<ratioKAlpha2KAlpha1>0.5000</ratioKAlpha2KAlpha1>
		</usedWavelength>
		<incidentBeamPath>
			<radius unit="mm">145.00</radius>
			<xRayTube id="1010048" name="Empyrean Cu LFF HR (9430 033 7310x) DK430614">
				<tension unit="kV">40.0</tension>
				<current unit="mA">15.0</current>
				<anodeMaterial>Cu</anodeMaterial>
				<focus type="Line">
					<length unit="mm">12.0</length>
					<width unit="mm">0.4</width>
					<takeOffAngle unit="deg">6.0</takeOffAngle>
				</focus>
			</xRayTube>
			<filter id="20010004" name="Beta-filter Nickel">
				<material>Ni</material>
				<thickness unit="mm">0.020</thickness>
			</filter>
			<sollerSlit id="21010002" name="Soller slits 0.04 rad.">
				<opening unit="rad">0.0400</opening>
			</sollerSlit>
			<mask id="22031000" name="Fixed mask 13 mm">
				<width unit="mm">9.00</width>
			</mask>
			<divergenceSlit id="22120001" name="Divergence slit 1°" xsi:type="fixedDivergenceSlitType">
				<distanceToSample unit="mm">50.00</distanceToSample>
				<height unit="mm">1.52</height>
			</divergenceSlit>
		</incidentBeamPath>
		<beamKnife id="29030100" name="Beam knife low"/>
		<sampleMovement xsi:type="spinningSampleMovementType">
			<spinnerRevolutionTime unit="seconds">1.0</spinnerRevolutionTime>
		</sampleMovement>
		<diffractedBeamPath>
			<radius unit="mm">145.00</radius>
			<antiScatterSlit id="22090040" name="AS slit 9 mm" xsi:type="fixedAntiScatterSlitType">
				<height unit="mm">9.00</height>
			</antiScatterSlit>
			<sollerSlit id="21020003" name="Large Soller slits 0.04 rad.">
				<opening unit="rad">0.0400</opening>
			</sollerSlit>
			<filter id="20030001" name="Large beta-filter Nickel">
				<material>Ni</material>
				<thickness unit="mm">0.020</thickness>
			</filter>
			<detector id="7010019" name="PIXcel1D-Medipix3 detector" xsi:type="rtmsDetectorType">
				<phd unit="keV">
					<lowerLevel>4.0</lowerLevel>
					<upperLevel>11.3</upperLevel>
				</phd>
				<mode>Scanning</mode>
				<activeLength unit="deg">1.021</activeLength>
			</detector>
		</diffractedBeamPath>
		<scan appendNumber="0" mode="Continuous" scanAxis="Gonio" status="Completed">
			<header>
				<startTimeStamp>2024-02-18T11:41:39-08:00</startTimeStamp>
				<endTimeStamp>2024-02-18T11:44:01-08:00</endTimeStamp>
				<author>
					<name>AutomatedUser</name>
				</author>
				<source>
					<applicationSoftware version="1.4b (28)">PANalytical Aeris Instrument Suite</applicationSoftware>
					<instrumentControlSoftware version="2.0.0 20210224">AERIS</instrumentControlSoftware>
					<instrumentID>950485</instrumentID>
				</source>
			</header>
			<dataPoints>
				<positions axis="2Theta" unit="deg">
					<startPosition>10.02173288</startPosition>
					<endPosition>139.98435528</endPosition>
				</positions>
				<positions axis="Omega" unit="deg">
					<startPosition>5.01086644</startPosition>
					<endPosition>69.99217764</endPosition>
				</positions>
				<commonCountingTime unit="seconds">1.551</commonCountingTime>
				<counts unit="counts">468 444 425 403 418 469 457 465 445 397 400 428 444 393 444 436 437 400 419 405 391 412 442 420 424 405 420 415 397 447 401 362 445 418 413 419 395 403 416 420 418 426 401 389 398 384 423 400 410 404 390 410 387 381 386 423 420 364 376 375 358 379 384 389 370 369 406 372 346 377 358 396 390 352 380 390 414 372 382 354 389 350 375 350 376 348 381 349 349 339 337 387 373 383 343 378 334 323 331 388 355 313 357 367 365 353 337 354 341 360 326 355 351 362 392 382 370 326 339 330 323 340 344 327 311 330 349 342 359 347 368 336 331 305 345 325 301 321 305 326 322 317 312 325 299 334 352 349 362 333 381 427 416 315 305 323 342 331 356 276 274 304 315 327 309 289 313 327 296 299 315 295 290 323 330 313 325 293 311 312 280 261 264 278 304 311 332 390 439 512 622 426 348 293 327 314 270 297 293 296 300 284 296 255 273 295 288 255 318 265 293 272 310 301 283 273 284 290 299 271 285 291 260 298 277 275 254 263 304 265 301 284 263 308 293 273 312 314 307 302 254 265 286 304 276 326 252 263 231 280 258 239 288 286 319 297 252 257 255 257 244 267 255 280 267 272 253 264 244 267 260 284 229 270 242 234 260 261 265 296 248 254 276 269 244 239 243 230 243 246 269 263 273 282 249 300 286 292 237 246 253 250 237 265 219 249 246 243 247 260 258 270 270 300 364 339 304 283 292 326 420 481 434 457 357 364 275 261 256 233 280 231 231 272 274 228 212 220 223 249 264 230 248 253 281 317 256 238 269 255 270 342 451 469 361 330 286 250 242 223 239 231 232 233 239 215 263 194 236 226 249 228 219 253 248 208 217 251 249 263 251 271 273 221 211 232 208 220 205 196 220 247 232 221 208 197 204 217 223 239 211 254 184 242 208 195 212 232 261 199 218 246 207 210 206 228 259 251 246 267 281 235 285 292 266 286 346 336 464 534 531 528 498 519 639 895 1434 3074 7515 11848 8047 5416 1747 618 533 458 428 379 321 314 289 323 335 344 353 437 604 714 658 700 716 792 940 830 591 447 302 297 253 269 277 290 265 283 310 295 328 357 410 563 714 920 1009 934 799 649 465 442 385 353 302 333 319 244 243 248 241 281 221 242 247 239 225 201 248 221 232 248 218 216 215 232 248 232 236 205 218 232 255 248 210 238 251 230 296 285 294 278 269 249 255 259 268 275 266 233 237 236 211 212 224 224 241 236 254 246 234 264 256 325 344 357 448 683 718 555 453 316 254 235 234 248 286 348 361 352 314 287 270 235 206 208 220 191 197 207 206 241 231 207 243 275 293 261 219 254 297 275 288 274 253 245 228 223 224 189 196 199 211 183 190 198 200 182 209 212 218 177 190 202 212 198 221 235 239 235 263 294 305 333 307 331 292 280 252 227 193 205 211 181 203 193 216 198 179 217 198 206 193 194 178 176 189 201 183 187 191 248 257 257 226 209 213 222 260 331 295 298 261 254 241 218 247 333 352 340 287 235 195 197 201 169 197 176 196 175 165 205 204 205 183 187 186 197 170 174 207 191 229 233 196 226 256 328 459 400 348 314 249 220 204 229 190 232 246 275 309 390 331 296 267 276 275 239 229 224 208 192 154 164 180 188 196 167 191 168 201 209 190 192 196 200 167 179 163 173 171 150 157 193 192 180 184 187 185 193 239 292 358 370 303 258 228 221 206 234 211 211 199 172 195 173 201 154 186 170 163 178 205 148 189 173 148 163 206 183 191 225 202 221 262 225 215 224 207 194 166 193 248 251 286 303 295 246 264 245 240 176 193 170 182 185 179 161 166 181 191 168 159 178 196 202 211 248 262 230 223 208 202 189 219 210 206 164 190 198 187 178 174 167 167 200 200 192 178 193 243 217 202 218 205 187 218 259 302 434 491 386 343 343 275 229 244 211 229 206 173 208 170 185 189 159 194 201 185 248 244 318 442 440 353 343 288 243 214 204 218 184 209 198 188 185 189 187 165 164 178 183 173 160 151 229 241 217 232 206 215 226 157 195 184 198 179 199 168 185 162 184 162 163 168 174 163 198 169 165 171 192 162 162 194 150 182 176 187 173 172 209 183 188 212 226 209 250 320 303 363 389 426 434 376 350 333 289 227 215 202 236 210 186 189 208 192 175 198 163 177 175 184 204 202 204 189 217 187 205 216 184 190 168 182 185 174 171 172 179 179 168 192 165 174 184 193 160 151 178 151 173 201 178 190 184 181 160 159 205 166 191 182 175 190 164 193 167 170 176 167 152 152 177 155 178 171 164 157 172 180 220 182 202 241 228 200 162 207 214 180 168 190 181 183 189 171 180 162 180 172 181 151 190 177 162 165 166 166 152 171 156 185 167 177 162 184 195 179 191 189 208 229 375 604 545 336 359 358 288 230 265 237 266 225 266 231 218 193 186 202 174 173 153 167 177 186 205 190 198 166 184 171 179 177 213 167 187 158 159 185 165 161 159 173 158 167 174 179 175 153 172 150 152 178 179 164 197 167 149 189 173 172 154 157 169 169 193 203 230 249 200 231 238 214 208 195 209 202 188 161 185 179 187 221 248 257 244 261 271 294 327 311 405 419 306 251 302 264 179 201 212 204 187 191 197 216 172 164 169 169 184 155 185 186 198 177 188 186 168 167 152 183 194 142 177 164 169 182 156 143 181 188 189 178 186 185 167 162 201 183 185 194 191 190 193 182 187 164 187 190 186 180 197 228 230 195 210 196 206 195 200 183 153 181 177 163 147 157 179 177 173 153 163 200 205 234 167 180 175 185 192 166 149 175 148 139 167 163 183 159 215 185 173 208 191 204 201 214 205 177 179 162 170 146 163 169 180 159 176 182 195 162 169 181 173 163 146 147 166 168 157 150 170 181 160 171 158 183 156 170 162 154 165 175 174 159 175 188 188 182 206 184 177 175 166 136 162 185 177 159 157 153 169 172 155 140 167 127 142 157 161 143 154 163 159 162 166 169 152 164 154 166 169 191 190 156 191 185 186 211 196 181 168 146 161 175 149 159 155 176 144 149 140 148 174 169 136 152 160 148 168 171 172 175 175 143 154 163 156 173 157 133 155 145 177 143 147 166 155 144 154 157 148 136 168 158 137 161 152 158 156 163 165 138 134 160 159 158 154 162 137 184 123 165 187 189 174 182 190 165 176 145 161 147 145 183 175 164 173 183 192 168 157 172 175 148 154 169 153 137 151 159 171 153 142 150 153 169 145 135 162 181 142 154 145 156 170 141 146 165 150 143 164 159 155 155 152 171 161 135 153 151 176 164 174 139 150 161 155 148 154 146 142 149 137 141 145 145 149 156 165 142 146 162 172 164 164 162 132 145 171 169 161 150 148 172 180 157 156 190 132 181 177 168 157 151 144 157 163 168 172 152 162 162 158 197 204 209 164 154 200 165 207 154 169 167 141 155 189 179 162 176 167 168 155 162 148 150 174 148 164 166 164 163 168 160 137 151 160 145 146 130 121 168 163 170 158 177 193 216 193 130 178 146 160 183 149 168 144 132 146 163 150 147 163 183 151 153 152 151 158 163 163 164 143 139 158 134 161 141 151 157 153 147 158 152 148 151 132 156 158 143 138 138 157 167 167 151 159 152 163 162 174 182 201 182 171 169 181 173 182 182 178 176 164 151 170 158 142 136 147 141 146 162 144 154 148 156 136 152 145 154 149 136 136 145 150 158 137 142 140 167 144 141 159 148 152 153 163 148 141 134 137 159 186 161 138 156 152 173 163 172 150 170 158 172 155 160 142 162 148 161 156 154 174 137 168 164 158 172 152 127 136 158 166 161 155 163 128 125 145 143 165 143 172 137 151 156 158 136 160 134 140 149 148 172 155 150 149 124 149 161 155 153 154 152 165 149 161 168 139 143 150 135 142 117 180 152 149 145 142 165 162 155 158 144 169 153 164 150 157 135 172 145 160 183 161 185 153 158 159 140 159 170 157 149 163 153 145 166 141 160 175 169 167 165 148 159 151 156 150 147 159 149 160 156 135 136 148 140 168 125 144 170 129 178 174 181 185 152 156 163 150 155 163 145 142 138 166 169 137 152 144 173 150 185 140 146 161 135 130 120 150 153 139 160 133 158 147 155 128 116 132 155 158 125 132 139 153 158 169 127 168 162 152 157 135 132 151 149 161 146 147 121 150 151 136 171 161 144 147 172 174 168 161 134 148 119 162 142 124 164 149 155 147 152 140 153 165 146 144 154 164 138 140 153 177 163 143 139 135 174 140 150 155 140 175 170 150 139 157 134 160 157 163 154 157 140 151 201 210 189 159 180 166 171 200 184 177 163 182 156 153 173 164 152 142 141 154 150 169 137 135 152 134 170 158 138 184 144 120 179 177 187 157 144 161 168 152 155 158 167 151 155 145 142 171 142 168 151 152 161 149 161 147 166 149 145 137 145 167 157 169 150 135 139 130 177 152 161 149 150 179 159 136 161 146 138 147 159 150 137 137 130 137 143 121 165 146 166 144 157 149 156 135 155 165 150 178 205 229 268 218 187 169 193 164 214 206 175 182 182 161 127 147 160 173 161 149 153 163 151 140 171 180 162 149 148 145 143 149 142 169 157 150 148 142 173 168 140 140 160 137 147 157 158 147 167 138 144 157 137 150 152 148 171 174 161 178 154 144 159 157 151 189 135 152 152 161 155 144 168 134 143 153 155 174 141 169 168 140 154 179 142 162 177 172 173 151 151 143 178 159 159 168 156 187 160 152 145 150 162 144 130 150 140 162 151 150 146 150 137 135 160 154 148 157 172 152 138 156 199 184 115 142 156 154 156 151 151 122 147 152 143 141 122 148 132 149 144 144 131 145 141 173 135 141 142 119 174 155 155 153 172 160 168 157 159 150 166 147 158 146 173 155 159 149 158 147 167 158 177 160 161 152 168 151 152 156 164 165 149 156 165 180 168 175 158 174 173 140 146 153 153 177 153 152 157 143 175 165 149 161 165 181 181 150 169 146 154 138 145 159 142 165 176 159 146 171 136 150 154 162 161 133 154 163 158 139 150 142 152 166 157 157 140 161 142 158 170 162 154 168 171 166 151 181 140 175 147 131 125 145 145 169 121 167 152 145 160 148 162 156 155 154 157 155 163 159 139 142 142 148 131 158 167 154 172 166 124 145 136 126 145 141 143 171 157 169 155 155 155 167 158 140 140 162 162 152 145 144 139 154 160 142 143 156 148 155 170 153 138 145 152 148 163 149 173 157 132 127 142 123 125 154 166 120 158 141 147 139 165 164 152 158 164 136 155 150 165 151 144 183 153 171 167 128 148 138 144 155 150 156 141 174 143 166 161 144 182 158 170 147 151 142 163 154 155 166 173 141 165 148 144 168 163 153 161 164 152 174 179 176 165 170 162 153 162 162 166 136 151 157 155 168 155 149 159 148 173 161 150 152 148 157 172 155 137 155 155 146 140 142 163 151 126 162 141 135 161 161 164 154 166 131 137 159 141 145 155 150 152 132 138 160 186 141 156 153 151 139 182 151 141 157 166 158 146 161 143 169 157 164 148 195 175 170 162 168 166 150 148 154 161 156 173 137 144 143 143 164 163 137 158 172 160 167 169 135 121 153 142 143 143 162 174 180 165 152 167 155 165 147 145 178 166 172 169 176 144 166 161 156 146 149 169 148 141 135 148 149 164 174 174 137 155 165 152 154 155 120 143 151 157 131 141 151 125 145 146 127 144 178 152 144 134 168 136 197 160 147 166 144 151 153 168 159 155 161 145 156 133 146 149 160 165 139 158 170 157 145 150 162 140 171 147 153 153 169 160 152 149 145 146 167 148 137 147 164 155 161 155 153 131 122 143 153 166 154 158 166 138 136 141 170 149 143 149 126 144 119 159 136 158 157 126 146 142 153 142 167 161 166 150 131 155 141 146 164 149 138 160 145 143 139 174 163 167 164 152 149 151 157 161 130 167 149 164 142 166 174 188 164 163 171 142 170 158 155 158 187 161 164 166 169 164 160 155 176 162 143 204 156 164 174 180 179 150 172 168 150 146 167 143 145 174 175 151 181 185 161 158 154 195 157 162 151 175 150 150 162 142 146 150 154 152 156 153 139 164 148 166 149 152 151 157 127 169 145 148 141 152 159 164 169 144 160 142 155 142 144 158 152 139 159 171 142 150 161 153 167 152 158 160 128 146 177 160 152 138 174 150 150 141 143 151 145 166 162 160 162 155 145 148 158 129 147 147 145 161 157 170 163 160 161 156 158 176 166 156 163 157 155 144 140 174 156 180 179 148 146 151 141 162 173 157 136 163 165 177 179 161 166 161 164 150 159 164 165 155 176 169 182 182 154 155 146 171 131 180 134 171 175 166 178 154 189 168 159 163 185 168 173 186 167 153 141 145 151 157 165 160 150 159 163 174 162 146 140 157 186 166 149 192 142 163 183 154 156 147 166 185 179 171 169 165 146 152 157 147 138 145 164 135 165 163 187 161 181 158 161 154 158 154 174 167 154 144 157 128 159 151 164 157 165 203 147 161 152 164 142 165 169 141 173 139 161 148 160 152 179 160 152 167 156 139 180 124 131 169 190 160 180 155 156 155 174 146 149 157 159 171 178 161 185 185 153 184 177 178 156 179 173 160 175 159 158 138 158 176 171 136 179 167 153 171 158 156 160 165 132 165 154 148 162 163 142 149 158 150 157 167 180 140 163 162 146 152 168 173 172 163 176 157 158 157 171 154 174 164 171 136 172 171</counts>
			</dataPoints>
		</scan>
	</xrdMeasurement>
</xrdMeasurements>