File: dataset/precursor_mixture/NaAlO2-1.5H2O_V2O5_CuO_Li3PO4.2-min.xrdml
<?xml version="1.0"?>
<xrdMeasurements xmlns="http://www.xrdml.com/XRDMeasurement/2.2" xmlns:xsi="http://www.w3.org/2001/XMLSchema-instance" xsi:schemaLocation="http://www.xrdml.com/XRDMeasurement/2.2 http://www.xrdml.com/XRDMeasurement/2.2/XRDMeasurement.xsd" status="Completed" recordIdentifier="{56CA0CF1-865D-4893-8156-A6B1F0F95DB9}">
	<comment>
		<entry/>
	</comment>
	<sample type="To be analyzed">
		<id>dara-23-1</id>
		<name></name>
		<preparedBy></preparedBy>
	</sample>
	<xrdMeasurement measurementType="Scan" status="Completed" sampleMode="Reflection">
		<usedWavelength intended="K-Alpha 1">
			<kAlpha1 unit="Angstrom">1.5405980</kAlpha1>
			<kAlpha2 unit="Angstrom">1.5444260</kAlpha2>
			<kBeta unit="Angstrom">1.3922500</kBeta>
			<ratioKAlpha2KAlpha1>0.5000</ratioKAlpha2KAlpha1>
		</usedWavelength>
		<incidentBeamPath>
			<radius unit="mm">145.00</radius>
			<xRayTube id="1010048" name="Empyrean Cu LFF HR (9430 033 7310x) DK437873">
				<tension unit="kV">40.0</tension>
				<current unit="mA">15.0</current>
				<anodeMaterial>Cu</anodeMaterial>
				<focus type="Line">
					<length unit="mm">12.0</length>
					<width unit="mm">0.4</width>
					<takeOffAngle unit="deg">6.0</takeOffAngle>
				</focus>
			</xRayTube>
			<filter id="20010004" name="Beta-filter Nickel">
				<material>Ni</material>
				<thickness unit="mm">0.020</thickness>
			</filter>
			<sollerSlit id="21010002" name="Soller slits 0.04 rad.">
				<opening unit="rad">0.0400</opening>
			</sollerSlit>
			<mask id="22031000" name="Fixed mask 13 mm">
				<width unit="mm">9.00</width>
			</mask>
			<divergenceSlit id="22120001" name="Divergence slit 1°" xsi:type="fixedDivergenceSlitType">
				<distanceToSample unit="mm">50.00</distanceToSample>
				<height unit="mm">1.52</height>
			</divergenceSlit>
		</incidentBeamPath>
		<beamKnife id="29030100" name="Beam knife low"/>
		<sampleMovement xsi:type="spinningSampleMovementType">
			<spinnerRevolutionTime unit="seconds">1.0</spinnerRevolutionTime>
		</sampleMovement>
		<diffractedBeamPath>
			<radius unit="mm">145.00</radius>
			<antiScatterSlit id="22090040" name="AS slit 9 mm" xsi:type="fixedAntiScatterSlitType">
				<height unit="mm">9.00</height>
			</antiScatterSlit>
			<sollerSlit id="21020003" name="Large Soller slits 0.04 rad.">
				<opening unit="rad">0.0400</opening>
			</sollerSlit>
			<filter id="20030001" name="Large beta-filter Nickel">
				<material>Ni</material>
				<thickness unit="mm">0.020</thickness>
			</filter>
			<detector id="7010019" name="PIXcel1D-Medipix3 detector" xsi:type="rtmsDetectorType">
				<phd unit="keV">
					<lowerLevel>4.0</lowerLevel>
					<upperLevel>11.3</upperLevel>
				</phd>
				<mode>Scanning</mode>
				<activeLength unit="deg">1.021</activeLength>
			</detector>
		</diffractedBeamPath>
		<scan appendNumber="0" mode="Continuous" scanAxis="Gonio" status="Completed">
			<header>
				<startTimeStamp>2024-03-24T16:54:54-07:00</startTimeStamp>
				<endTimeStamp>2024-03-24T16:57:16-07:00</endTimeStamp>
				<author>
					<name>AutomatedUser</name>
				</author>
				<source>
					<applicationSoftware version="1.6 (94)">PANalytical Aeris Instrument Suite</applicationSoftware>
					<instrumentControlSoftware version="3.0.0 20211014">AERIS</instrumentControlSoftware>
					<instrumentID>2879380</instrumentID>
				</source>
			</header>
			<dataPoints>
				<positions axis="2Theta" unit="deg">
					<startPosition>10.02173288</startPosition>
					<endPosition>139.98435528</endPosition>
				</positions>
				<positions axis="Omega" unit="deg">
					<startPosition>5.01086644</startPosition>
					<endPosition>69.99217764</endPosition>
				</positions>
				<commonCountingTime unit="seconds">1.551</commonCountingTime>
				<counts unit="counts">480 409 481 395 454 482 434 432 437 442 498 451 455 429 430 434 471 428 441 440 411 428 452 379 424 397 407 428 447 416 389 408 378 411 438 397 376 400 393 412 389 404 377 420 372 379 382 373 408 354 359 385 383 358 356 359 384 362 390 380 337 330 338 336 342 399 415 377 366 355 374 371 367 371 338 330 333 357 337 332 317 338 325 317 310 367 315 302 371 354 313 331 347 297 356 343 327 317 332 331 330 287 337 340 330 313 308 329 308 333 323 328 359 335 344 353 330 335 387 362 413 448 527 616 541 409 346 304 341 324 294 366 305 317 303 290 264 285 296 311 312 286 267 269 273 274 295 304 313 323 365 358 362 338 361 344 363 378 377 370 347 331 293 332 259 312 277 302 267 277 295 265 268 343 296 268 299 271 300 273 269 277 280 299 268 325 273 266 276 278 262 252 256 267 284 279 275 277 293 246 224 291 273 277 280 265 277 284 244 257 268 287 248 250 261 260 273 269 266 269 258 291 269 250 299 307 313 339 367 409 544 702 898 1242 1389 991 651 487 413 361 315 320 306 304 373 304 283 255 278 278 273 295 277 353 338 315 309 283 288 272 292 296 298 402 433 510 522 509 413 359 310 307 307 336 361 325 396 487 561 575 634 541 440 350 290 310 289 294 269 296 304 265 300 270 301 311 346 403 435 486 464 475 455 457 403 330 305 312 274 265 266 252 290 268 260 224 275 286 233 236 229 234 278 250 251 240 278 246 262 241 257 285 334 299 336 362 410 342 345 374 344 337 335 277 268 281 266 247 203 247 279 270 278 266 249 286 259 222 259 258 245 261 293 365 545 897 929 639 401 271 252 246 235 255 234 225 263 219 273 306 250 229 246 232 236 235 255 213 220 211 217 213 218 227 231 226 185 239 231 236 217 215 201 243 203 213 221 233 198 220 198 180 212 217 229 211 208 211 218 237 234 240 239 245 257 238 240 279 251 259 277 278 282 302 315 321 312 230 232 235 225 217 237 196 204 214 226 175 214 255 251 220 231 225 258 222 256 292 303 347 359 274 314 253 217 247 220 232 240 241 230 290 360 459 613 728 690 517 399 296 253 221 211 237 210 242 195 241 234 292 251 260 233 236 248 236 228 236 203 231 247 240 255 321 348 453 439 436 459 369 335 285 238 232 226 194 223 210 218 199 217 241 267 304 351 344 338 342 328 262 257 264 267 280 281 244 273 299 352 408 461 445 474 396 372 376 410 504 580 657 595 489 399 308 301 276 278 276 267 260 285 279 355 451 465 436 408 359 404 384 365 434 595 782 1059 1166 1357 1403 1219 974 814 592 452 450 391 302 270 304 308 249 279 269 250 266 260 231 262 280 316 306 329 305 286 245 229 262 243 275 279 286 266 272 273 260 238 213 249 229 236 226 248 250 237 222 227 227 205 215 244 205 188 215 233 214 233 249 285 294 307 324 333 355 425 509 594 744 943 1214 1314 1281 1121 1049 886 764 697 622 619 468 387 319 298 269 231 247 224 222 214 234 214 205 214 183 205 201 195 182 223 225 194 234 220 234 208 227 173 188 192 186 183 213 222 195 236 185 211 190 201 218 183 225 209 213 220 257 232 313 308 282 263 238 209 208 202 235 221 209 216 206 203 227 231 242 233 272 263 248 249 206 191 213 191 180 179 192 210 186 192 197 168 161 187 204 184 171 191 187 194 171 192 201 176 173 181 195 200 236 203 182 213 171 201 184 224 196 164 167 207 204 180 151 165 171 196 201 214 192 173 177 156 176 162 169 185 173 172 178 162 204 170 202 169 215 173 164 192 192 198 208 212 245 257 261 263 237 225 205 172 190 188 182 173 161 168 183 199 195 194 230 233 241 188 231 243 238 239 205 200 243 186 205 184 184 187 172 187 185 212 177 176 188 231 276 352 286 277 285 246 212 186 202 204 191 232 267 247 258 255 249 227 185 195 192 199 203 238 210 226 234 253 287 294 312 351 451 453 550 484 453 368 374 298 250 245 229 220 223 182 178 243 224 219 192 195 204 227 201 190 184 176 168 192 177 164 159 164 199 188 163 205 210 181 183 189 200 179 198 201 203 233 188 180 206 214 217 198 218 255 230 305 327 315 293 282 283 246 232 237 246 206 209 180 183 201 216 220 240 265 250 219 264 222 190 220 206 183 213 187 194 168 218 181 195 194 199 159 176 207 169 209 171 186 188 156 175 195 218 188 204 224 215 261 285 250 221 204 216 197 197 230 209 188 181 166 173 180 184 172 185 157 174 176 155 166 184 189 193 177 167 197 175 192 187 182 195 206 197 177 206 234 185 184 208 212 179 168 198 245 250 236 259 221 234 226 217 193 211 177 205 182 189 178 202 186 185 208 191 187 194 187 153 159 184 178 189 185 190 195 177 162 171 208 179 197 178 189 190 201 214 221 222 255 273 217 228 211 191 183 203 196 188 193 234 232 242 250 267 259 303 270 271 301 260 251 274 228 193 226 262 233 194 228 200 206 215 248 226 213 213 199 194 199 196 163 176 177 169 168 167 179 169 169 166 194 190 168 189 211 211 163 176 185 194 184 187 176 203 216 204 227 228 224 203 203 197 201 222 234 199 223 236 319 318 343 338 314 273 299 264 293 281 327 383 335 324 350 333 326 339 255 283 278 242 240 256 362 259 244 246 277 228 167 176 197 203 190 199 184 168 170 172 210 183 163 179 175 181 179 185 163 170 186 193 187 181 191 204 218 170 175 185 191 184 187 179 186 197 180 193 163 191 183 171 156 183 190 225 215 239 220 208 214 202 177 187 181 192 205 179 195 179 192 223 212 209 214 216 156 221 206 193 204 201 236 229 230 254 277 272 259 285 286 275 299 286 280 309 334 306 335 315 300 276 279 260 230 230 231 206 204 181 206 165 165 199 198 169 193 195 200 197 177 183 179 185 170 204 222 229 205 217 216 260 283 270 289 304 296 307 307 315 332 275 273 279 262 246 213 219 196 177 198 206 199 203 206 232 230 225 236 219 243 225 224 161 205 174 177 156 189 169 185 192 190 190 192 162 181 192 154 162 190 216 182 193 183 177 193 191 193 210 215 210 206 188 191 195 175 163 176 160 155 169 188 172 176 156 173 170 174 162 190 193 176 189 159 176 194 152 204 161 219 180 173 173 190 210 215 233 169 172 204 197 234 250 257 235 270 233 233 267 235 231 216 213 247 208 207 181 194 203 182 196 171 167 187 185 206 211 188 184 164 177 169 192 168 155 190 191 201 197 185 171 193 151 179 187 186 196 195 198 203 231 213 206 208 223 220 196 204 209 209 224 212 230 201 255 242 247 249 226 228 230 177 230 216 192 178 199 191 185 182 188 177 186 146 203 222 182 169 185 162 167 185 175 168 181 167 188 176 143 149 156 169 205 180 158 158 195 189 134 150 176 153 173 166 169 164 177 151 182 148 156 178 164 186 178 155 153 164 183 174 163 162 202 189 168 197 175 217 167 170 183 173 180 165 170 169 166 149 138 157 152 166 139 165 141 171 171 154 167 169 158 163 176 185 163 147 152 188 161 182 157 172 177 180 141 170 199 182 137 162 188 167 189 202 154 193 204 179 147 173 162 177 172 154 179 193 138 163 158 179 188 178 197 196 168 169 199 174 178 192 185 158 169 167 178 169 172 166 167 176 172 157 185 169 186 196 174 184 204 214 213 239 189 211 184 206 224 176 200 209 180 209 192 212 186 229 175 162 196 199 177 197 186 185 167 186 224 184 202 194 195 169 164 174 176 189 215 179 191 182 180 205 177 171 175 188 160 163 176 136 162 159 163 156 166 150 157 173 153 159 153 154 170 154 185 171 157 177 179 174 145 170 157 149 173 147 168 175 163 186 153 158 166 150 154 158 178 168 169 159 171 192 157 170 182 154 192 193 211 199 192 218 181 173 198 191 174 191 189 185 155 172 164 167 133 164 162 146 169 141 159 162 181 169 180 158 159 164 164 169 149 165 162 148 141 182 162 164 172 154 180 203 174 178 172 154 204 197 178 171 167 133 174 172 161 174 157 157 153 169 190 186 206 206 193 205 215 162 214 182 203 187 190 149 181 158 176 167 170 184 170 168 186 167 180 173 177 183 172 190 179 190 188 156 161 148 179 151 163 190 167 144 182 168 159 156 192 152 154 179 160 191 176 180 182 167 177 174 199 168 203 175 151 172 163 167 180 151 163 190 179 180 165 176 167 183 154 160 183 163 136 156 164 155 169 182 163 171 161 160 163 170 148 152 161 156 178 175 161 180 154 159 167 170 148 157 143 171 142 182 169 194 189 181 171 201 162 181 175 170 176 156 173 143 172 180 156 149 138 139 135 164 188 202 160 178 171 167 153 160 166 169 189 153 173 184 187 162 156 126 168 155 162 140 143 170 163 149 162 157 161 160 171 192 170 161 156 159 156 165 161 170 158 144 173 142 166 145 158 178 157 156 133 171 179 175 186 162 179 160 173 175 179 166 178 153 149 176 164 172 163 164 200 151 168 158 176 153 167 176 163 207 168 195 158 171 172 166 179 198 151 166 208 178 198 201 171 178 194 207 205 175 186 194 211 190 171 188 180 152 177 167 156 179 170 218 171 170 187 202 162 152 170 189 163 152 179 177 161 147 166 149 161 152 170 144 196 167 163 164 178 169 191 168 154 156 155 188 180 157 170 144 173 163 179 161 164 191 170 169 165 173 182 146 166 171 194 153 175 170 170 171 169 167 161 217 190 154 205 178 198 184 183 211 222 186 193 212 211 199 191 191 191 165 201 189 176 178 178 168 153 179 201 188 175 175 171 168 169 173 161 165 155 159 159 179 169 182 144 149 169 171 154 156 176 171 167 161 179 169 179 161 179 149 162 171 159 184 128 181 208 174 182 165 186 167 168 179 166 167 164 159 180 172 173 184 162 198 177 171 178 162 182 176 160 179 154 170 196 188 185 202 139 156 179 171 157 184 170 167 154 182 182 158 158 159 128 175 149 164 154 194 158 178 161 159 160 157 151 163 178 180 156 149 173 163 157 169 187 169 175 173 147 174 177 168 159 175 150 161 175 175 166 171 192 174 192 166 183 171 191 206 196 200 176 195 222 198 184 174 172 177 187 174 192 196 177 174 179 181 180 184 203 175 176 172 147 185 181 178 169 188 196 178 200 173 176 154 192 160 187 178 169 167 181 180 182 158 180 166 155 202 183 193 173 170 163 173 158 176 178 149 167 168 166 137 160 181 189 178 153 184 178 176 184 196 192 163 183 154 207 191 171 172 170 184 195 164 190 205 194 180 217 173 173 186 172 165 186 193 177 151 133 193 169 179 169 158 196 178 156 146 183 195 183 167 177 173 163 168 186 189 165 171 177 170 175 158 172 168 161 186 196 193 183 172 176 179 198 156 163 172 182 189 160 180 178 199 185 170 144 166 178 179 167 168 180 187 176 190 171 188 172 200 157 181 176 208 146 168 166 182 154 194 146 156 168 141 180 150 183 148 174 160 179 173 158 191 177 171 174 158 159 191 169 174 147 179 173 146 182 162 183 173 158 183 189 164 162 151 165 187 149 192 164 169 181 177 174 193 151 181 185 182 187 164 178 186 169 216 192 183 201 193 188 222 169 190 233 231 190 206 173 165 198 217 204 170 189 165 185 179 178 173 179 182 198 180 175 151 176 164 180 162 147 201 193 167 194 153 180 158 160 179 169 170 173 199 190 213 158 180 178 170 178 191 187 157 169 169 170 165 162 178 184 185 170 159 204 164 191 162 179 174 189 164 201 177 177 173 163 173 216 188 192 211 165 170 153 164 165 161 174 174 177 176 172 139 176 152 163 173 164 141 167 168 197 140 150 160 183 165 170 143 167 162 161 157 169 168 187 206 192 176 157 147 167 168 184 170 140 157 143 177 188 159 175 163 146 174 163 165 164 157 191 159 161 173 179 154 184 170 180 151 162 154 185 177 171 195 198 188 203 140 174 161 168 207 181 196 182 190 192 170 166 186 189 193 182 172 178 180 188 202 202 196 167 186 192 196 169 172 179 181 196 181 171 195 179 182 179 177 179 180 175 175 179 165 182 179 182 185 182 192 204 179 173 181 201 181 185 180 185 189 177 165 214 182 160 201 188 183 184 204 171 190 182 183 163 184 207 184 199 161 180 209 188 195 189 171 178 166 178 208 200 179 161 214 199 189 192 171 202 205 179 205 189 177 208 183 197 198 177 184 184 178 178 188 186 185 179 206 220 207 166 160 184 192 190 182 178 207 188 201 213 191 207 181 223 181 204 189 185 184 157 186 176 169 205 175 161 181 164 166 158 149 183 161 163 221 177 190 195 168 174 194 167 175 203 183 177 183 168 174 187 189 199 186 188 197 199 172 165 168 183 182 185 176 176 193 184 181 185 183 155 187 178 156 163 167 179 216 211 205 183 159 190 155 173 171 173 164 171 164 172 177 173 196 205 172 166 167 197 188 192 180 198 206 175 175 178 185 158 169 170 171 184 197 175 180 191 173 177 178 166 182 162 177 189 186 164 185 172 177 196 174 174 192 196 194 175 189 209 181 196 178 189 169 179 208 170 173 198 204 183 193 190 154 180 194 146 197 196 170 175 189 170 188 176 179 177 166 193 194 190 197 157 163 187 167 192 197 177 184 195 187 165 167 167 180 205 178 189 198 160 173 164 182 190 163 193 196 152 202 159 201 162 168 176 159 187 165 192 174 166 181 163 174 190 189 188 180 194 181 180 190 180 163 177 173</counts>
			</dataPoints>
		</scan>
	</xrdMeasurement>
</xrdMeasurements>