File: dataset/precursor_mixture/NaAlO2-1.5H2O_ZrO2_LiCoO2.2-min.xrdml
<?xml version="1.0"?>
<xrdMeasurements xmlns="http://www.xrdml.com/XRDMeasurement/2.2" xmlns:xsi="http://www.w3.org/2001/XMLSchema-instance" xsi:schemaLocation="http://www.xrdml.com/XRDMeasurement/2.2 http://www.xrdml.com/XRDMeasurement/2.2/XRDMeasurement.xsd" status="Completed" recordIdentifier="{FDBDD1B2-F69D-4A93-8C90-51C62CA9AC26}">
	<comment>
		<entry/>
	</comment>
	<sample type="To be analyzed">
		<id>dara-13-1</id>
		<name></name>
		<preparedBy></preparedBy>
	</sample>
	<xrdMeasurement measurementType="Scan" status="Completed" sampleMode="Reflection">
		<usedWavelength intended="K-Alpha 1">
			<kAlpha1 unit="Angstrom">1.5405980</kAlpha1>
			<kAlpha2 unit="Angstrom">1.5444260</kAlpha2>
			<kBeta unit="Angstrom">1.3922500</kBeta>
			<ratioKAlpha2KAlpha1>0.5000</ratioKAlpha2KAlpha1>
		</usedWavelength>
		<incidentBeamPath>
			<radius unit="mm">145.00</radius>
			<xRayTube id="1010048" name="Empyrean Cu LFF HR (9430 033 7310x) DK430614">
				<tension unit="kV">40.0</tension>
				<current unit="mA">15.0</current>
				<anodeMaterial>Cu</anodeMaterial>
				<focus type="Line">
					<length unit="mm">12.0</length>
					<width unit="mm">0.4</width>
					<takeOffAngle unit="deg">6.0</takeOffAngle>
				</focus>
			</xRayTube>
			<filter id="20010004" name="Beta-filter Nickel">
				<material>Ni</material>
				<thickness unit="mm">0.020</thickness>
			</filter>
			<sollerSlit id="21010002" name="Soller slits 0.04 rad.">
				<opening unit="rad">0.0400</opening>
			</sollerSlit>
			<mask id="22031000" name="Fixed mask 13 mm">
				<width unit="mm">9.00</width>
			</mask>
			<divergenceSlit id="22120001" name="Divergence slit 1°" xsi:type="fixedDivergenceSlitType">
				<distanceToSample unit="mm">50.00</distanceToSample>
				<height unit="mm">1.52</height>
			</divergenceSlit>
		</incidentBeamPath>
		<beamKnife id="29030100" name="Beam knife low"/>
		<sampleMovement xsi:type="spinningSampleMovementType">
			<spinnerRevolutionTime unit="seconds">1.0</spinnerRevolutionTime>
		</sampleMovement>
		<diffractedBeamPath>
			<radius unit="mm">145.00</radius>
			<antiScatterSlit id="22090040" name="AS slit 9 mm" xsi:type="fixedAntiScatterSlitType">
				<height unit="mm">9.00</height>
			</antiScatterSlit>
			<sollerSlit id="21020003" name="Large Soller slits 0.04 rad.">
				<opening unit="rad">0.0400</opening>
			</sollerSlit>
			<filter id="20030001" name="Large beta-filter Nickel">
				<material>Ni</material>
				<thickness unit="mm">0.020</thickness>
			</filter>
			<detector id="7010019" name="PIXcel1D-Medipix3 detector" xsi:type="rtmsDetectorType">
				<phd unit="keV">
					<lowerLevel>4.0</lowerLevel>
					<upperLevel>11.3</upperLevel>
				</phd>
				<mode>Scanning</mode>
				<activeLength unit="deg">1.021</activeLength>
			</detector>
		</diffractedBeamPath>
		<scan appendNumber="0" mode="Continuous" scanAxis="Gonio" status="Completed">
			<header>
				<startTimeStamp>2024-02-18T11:57:30-08:00</startTimeStamp>
				<endTimeStamp>2024-02-18T11:59:52-08:00</endTimeStamp>
				<author>
					<name>AutomatedUser</name>
				</author>
				<source>
					<applicationSoftware version="1.4b (28)">PANalytical Aeris Instrument Suite</applicationSoftware>
					<instrumentControlSoftware version="2.0.0 20210224">AERIS</instrumentControlSoftware>
					<instrumentID>950485</instrumentID>
				</source>
			</header>
			<dataPoints>
				<positions axis="2Theta" unit="deg">
					<startPosition>10.02173288</startPosition>
					<endPosition>139.98435528</endPosition>
				</positions>
				<positions axis="Omega" unit="deg">
					<startPosition>5.01086644</startPosition>
					<endPosition>69.99217764</endPosition>
				</positions>
				<commonCountingTime unit="seconds">1.551</commonCountingTime>
				<counts unit="counts">885 814 774 749 756 780 786 823 805 850 795 765 786 761 789 779 803 767 825 779 793 754 795 775 802 797 813 802 819 805 777 792 751 783 781 837 801 762 817 792 795 843 770 753 807 849 754 813 840 838 792 804 802 810 788 845 816 803 799 783 891 784 803 803 792 820 823 825 751 838 819 830 828 789 849 847 778 813 824 813 783 787 818 792 814 809 816 793 741 794 822 795 869 803 842 794 829 740 806 840 853 844 827 807 827 840 841 829 810 782 860 902 817 776 841 800 852 850 841 814 794 816 834 841 787 781 770 874 857 873 808 833 857 852 757 804 824 840 890 848 843 834 871 850 857 774 888 872 893 907 926 908 909 864 870 850 948 877 828 897 863 877 919 884 811 879 876 853 883 912 849 833 838 828 816 860 817 857 877 850 852 812 890 833 826 885 874 856 947 945 925 991 1003 994 1050 1191 1214 1374 1802 2426 4061 8185 17487 23226 11897 3089 1323 1201 1124 1220 1062 1068 973 912 908 876 877 876 926 903 877 933 950 985 928 933 970 993 1019 949 1018 988 953 948 947 1034 995 1019 996 976 961 991 977 982 995 987 963 932 942 989 896 910 959 927 915 931 906 868 939 904 891 932 952 935 898 889 959 885 856 887 871 892 901 950 840 850 885 907 883 874 868 894 899 857 878 869 923 942 865 871 897 873 918 813 828 858 902 844 875 872 862 899 875 804 897 881 850 905 867 899 829 839 876 931 924 918 925 970 1011 1045 982 871 875 938 934 945 992 962 909 926 845 837 863 814 834 834 842 895 857 869 868 823 828 889 903 908 893 853 866 845 765 834 833 775 851 857 832 856 820 833 905 862 863 827 824 846 834 845 782 796 835 779 796 837 789 825 817 820 810 848 818 857 810 836 803 806 767 802 863 807 801 854 860 867 794 821 802 895 846 871 868 871 878 857 886 929 947 1054 1234 1427 1630 1803 1618 1358 1156 967 951 930 836 871 878 845 844 880 886 833 849 906 799 791 824 757 816 881 865 849 822 825 736 829 833 841 855 801 823 783 901 821 823 793 811 801 873 830 850 837 843 831 821 896 918 849 831 802 821 808 767 771 822 784 805 826 799 819 790 782 874 873 924 874 895 1049 1096 1239 1434 1459 1372 1195 1057 961 920 862 831 867 781 806 777 794 776 830 798 811 798 832 839 770 788 861 792 756 822 818 826 837 783 801 795 806 740 753 801 764 857 883 839 836 797 735 831 867 812 832 846 837 883 802 806 806 780 866 805 836 830 957 950 1066 1027 1006 1014 944 953 977 973 900 894 894 846 867 855 871 804 871 908 935 916 923 880 888 884 883 956 931 927 908 849 825 770 817 818 857 895 868 825 841 831 899 806 812 879 792 777 832 803 729 780 756 742 802 817 801 740 781 744 800 788 781 853 820 760 786 777 764 836 731 779 812 834 960 1048 988 940 874 825 787 809 776 785 756 736 735 872 775 839 768 795 818 843 863 846 972 1463 1931 1458 1361 1167 846 868 825 896 839 835 824 808 832 865 871 912 865 848 812 802 784 820 800 773 736 787 781 835 729 766 793 790 813 749 753 791 790 744 786 760 805 783 759 787 727 775 808 844 817 797 892 853 924 880 880 880 777 796 854 781 852 839 848 839 840 805 825 812 825 880 772 795 765 771 772 795 778 731 807 758 805 772 786 776 770 720 843 749 796 771 797 732 772 753 746 742 736 732 773 740 749 797 731 765 732 732 755 797 757 816 772 783 789 790 762 791 797 808 773 772 748 763 752 804 707 718 761 751 809 779 714 744 791 761 726 737 761 802 793 787 809 752 781 833 835 852 831 830 823 834 870 952 1192 1497 1356 1151 1129 985 824 853 823 791 814 736 795 757 774 758 767 765 730 731 720 776 733 783 796 743 791 736 833 723 710 798 793 806 743 819 756 776 772 772 740 751 770 673 750 735 770 749 718 702 725 781 736 768 789 749 756 805 742 772 738 746 797 823 720 714 767 745 778 786 741 799 725 748 781 761 766 762 777 663 767 733 776 815 757 832 808 807 778 808 839 931 955 937 989 984 904 972 833 872 872 804 754 801 749 783 787 817 836 812 940 937 919 974 892 929 830 807 799 858 808 867 881 875 855 796 775 788 761 846 779 821 747 772 816 779 807 820 781 785 778 780 809 721 732 770 767 795 722 741 737 690 699 735 761 776 747 756 739 767 712 728 735 719 773 804 743 805 792 727 773 793 801 731 758 777 773 790 717 743 730 756 790 707 745 703 707 797 790 826 770 787 760 762 781 802 793 777 832 799 857 844 791 824 838 780 797 775 757 735 774 755 799 752 763 753 747 736 777 766 740 788 794 802 814 815 832 860 874 876 794 887 881 845 816 873 876 784 857 834 828 809 796 813 846 784 767 765 793 814 718 744 749 709 759 710 768 753 752 723 699 784 760 778 742 758 759 797 791 824 793 784 781 820 779 858 810 795 814 815 808 784 787 728 759 809 745 784 771 788 766 809 757 763 780 773 732 792 732 740 751 790 732 754 731 752 745 744 752 761 778 758 753 889 1112 961 812 871 923 781 751 740 785 800 857 921 913 825 858 882 861 789 793 845 823 823 772 788 811 811 732 763 759 745 766 743 734 752 699 778 758 743 770 765 736 717 683 719 785 789 810 743 775 790 730 817 818 775 766 779 733 763 781 753 739 758 763 801 809 815 770 810 806 802 753 736 721 787 745 754 778 709 722 798 805 756 813 860 850 805 736 800 821 770 766 763 769 772 738 698 710 774 687 761 725 745 727 721 753 769 755 766 729 769 768 736 724 762 762 725 810 743 756 717 715 679 686 723 737 756 756 699 749 763 751 714 753 723 728 733 760 772 761 780 803 874 936 882 874 800 875 862 807 826 746 791 774 748 740 778 804 705 711 743 838 810 789 800 779 703 783 760 741 675 713 753 754 751 744 713 745 735 703 771 696 695 721 744 729 761 698 738 687 743 718 719 701 741 716 734 688 721 734 742 730 745 725 772 734 739 765 692 731 727 738 735 761 747 769 754 719 772 699 745 767 783 740 751 734 731 814 745 689 763 751 674 689 754 702 749 759 817 792 721 694 754 750 718 701 755 769 717 711 772 797 687 723 787 747 743 764 666 730 772 739 703 684 724 661 744 757 755 670 730 706 795 775 785 778 774 748 724 731 713 714 739 754 732 739 719 747 761 708 729 744 754 704 711 761 766 787 771 743 787 702 715 741 706 745 769 727 731 711 678 755 735 722 760 726 729 715 736 728 700 731 704 730 728 752 700 701 732 753 721 755 750 791 757 663 688 688 715 758 750 698 717 734 709 698 709 716 682 749 755 759 762 762 735 742 742 779 789 726 753 714 711 778 713 715 784 734 694 703 727 701 695 707 732 706 731 735 721 742 703 692 772 772 744 707 714 763 721 797 713 732 733 683 700 750 720 714 678 768 736 707 723 747 670 706 759 739 742 716 721 728 738 724 716 745 695 707 766 735 727 713 698 733 726 697 704 740 702 700 703 764 729 753 728 736 727 762 738 724 750 737 737 769 771 715 700 783 749 742 745 725 706 746 722 734 722 776 695 729 733 743 711 719 715 719 678 779 719 760 725 686 705 691 673 718 688 699 742 695 688 747 741 695 728 701 780 696 731 692 756 741 694 733 774 693 768 730 770 718 691 690 721 730 709 739 706 746 750 745 736 804 731 720 729 779 771 749 743 763 811 980 1132 913 751 767 783 897 954 820 731 718 725 753 694 748 743 749 738 751 767 707 740 722 736 763 713 699 766 727 722 693 678 716 762 739 705 753 746 768 790 763 784 764 755 755 758 716 754 707 760 737 662 702 745 665 761 754 792 756 742 714 666 712 722 721 769 701 761 724 704 710 704 695 700 732 701 747 724 702 726 763 703 712 706 775 768 738 782 728 716 766 726 683 722 715 743 687 729 724 692 708 713 711 732 756 752 768 708 738 749 709 697 737 723 769 705 707 741 731 765 680 701 727 738 690 759 739 760 736 719 696 771 765 760 747 728 726 724 774 664 781 709 729 727 715 777 699 723 679 691 742 743 739 698 728 743 716 690 715 742 758 757 691 731 703 721 781 743 751 765 741 752 707 752 716 728 674 741 761 736 683 779 739 719 691 741 711 744 764 699 804 742 681 677 689 737 739 703 730 719 757 678 703 771 739 686 670 743 719 698 749 749 722 720 673 722 678 697 712 728 737 730 730 728 706 704 674 753 723 693 699 761 709 684 726 671 703 715 723 691 689 712 730 730 725 695 759 700 729 733 745 723 702 677 741 706 746 699 688 719 653 744 718 686 748 752 753 737 733 738 723 713 734 716 763 748 718 715 705 728 745 730 716 701 695 726 753 730 746 719 713 753 762 711 744 754 734 704 728 736 732 741 715 764 726 715 683 746 719 722 701 750 770 709 724 740 741 724 765 746 723 757 725 775 733 712 739 738 737 775 738 734 721 686 737 699 801 743 700 756 739 762 696 684 710 745 683 732 719 745 733 733 701 676 713 724 762 729 745 723 686 673 706 721 689 732 715 739 698 749 743 728 695 735 793 727 784 712 741 744 702 738 756 764 741 691 726 750 700 719 769 709 729 710 742 709 749 704 728 707 720 687 709 745 708 730 715 748 691 733 691 718 780 691 751 762 739 693 703 736 765 709 724 726 731 695 692 691 738 718 710 689 745 729 686 738 725 730 731 697 739 701 722 681 701 755 688 716 739 693 757 746 676 717 669 751 700 731 688 724 735 730 751 675 738 699 710 757 731 696 723 753 687 751 695 709 750 683 712 699 692 720 736 638 681 683 718 750 720 711 738 721 660 716 719 700 641 698 657 740 720 700 730 699 739 701 668 703 648 682 681 741 719 679 670 678 699 710 701 665 726 699 686 647 682 695 701 728 747 705 707 682 711 711 736 679 705 762 729 746 696 714 706 738 703 746 722 696 677 709 773 718 720 750 695 714 700 721 686 633 714 698 739 695 759 745 740 693 710 710 725 695 723 696 752 723 739 723 714 750 754 705 684 690 731 697 717 754 732 755 694 699 729 730 744 710 695 725 726 758 677 729 710 673 723 690 694 705 748 717 688 706 691 690 703 662 680 701 696 681 706 717 731 733 698 675 770 745 761 725 753 733 738 725 732 764 671 799 843 881 776 776 755 774 710 715 746 797 772 757 758 744 689 703 722 667 674 717 763 713 776 679 697 708 693 727 737 729 746 722 673 726 752 714 729 727 731 728 752 757 746 702 697 709 731 726 701 679 757 703 709 688 716 680 700 705 711 740 702 688 666 730 721 697 731 695 703 750 717 745 729 739 726 757 704 757 713 739 735 708 676 668 725 675 684 692 768 688 671 700 693 688 703 673 703 677 690 707 714 761 679 759 715 722 740 749 716 714 708 720 723 714 713 753 714 693 754 720 738 723 742 673 729 690 692 706 740 660 665 716 710 682 672 751 708 753 710 714 695 696 729 654 717 690 684 667 722 709 702 713 740 739 711 755 724 769 749 781 737 770 708 697 709 736 701 703 731 722 713 769 731 712 724 734 736 737 713 695 698 682 675 664 728 765 704 672 716 702 670 698 688 709 721 736 759 738 726 783 684 721 755 776 667 713 702 701 689 685 726 734 735 732 687 709 684 777 769 730 724 721 677 720 678 704 715 693 717 688 716 713 711 710 743 771 694 717 735 682 744 706 698 766 665 713 701 737 753 715 764 682 746 732 765 697 710 685 652 664 700 728 679 703 729 716 704 727 704 720 713 695 733 720 686 698 669 667 692 686 736 682 697 705 714 735 724 723 698 750 700 707 683 735 728 771 648 696 712 694 710 704 739 690 733 750 700 688 681 736 695 724 697 740 711 747 672 706 691 757 740 710 725 699 763 729 738 712 706 764 699 752 681 710 712 708 704 705 696 676 696 710 775 685 702 701 704 728 740 732 677 731 764 742 723 716 733 769 724 695 709 723 672 699 692 680 650 718 679 711 744 717 720 663 640 744 682 690 741 734 735 720 772 629 663 739 605 760 768 729 667 738 744 715 699 713 695 748 681 723 718 715 749 701 665 739 698 717 740 661 705 737 689 712 677 690 672 677 724 690 701 695 700 677 692 742 713 705 727 671 711 730 681 734 667 690 724 674 710 742 694 703 717 671 648 721 678 683 706 688 660 759 727 745 734 697 736 737 715 697 711 719 708 732 733 734 724 706 690 696 693 714 644 693 705 719 713 724 711 776 719 749 737 711 732 678 736 733 729 730 702 694 673 680 707 708 680 720 770 673 746 743 696 684 721 681 758 707 702 720 736 688 699 718 747 739 683 763 710 730 722 751 708 691 729 769 722 721 748 659 735 725 746 682 745 724 690 743 746 703 642 710 688 758 685 700 731 677 683 688 721 722 723 758 695 695 695 711 717 702 676 714 707 707 706 733 707 668 743 718 735 711 720 748 718 733 662 749 722 754 686 741 670 682 748 717 671 673 673 729 738 757 685 782 733 699 707 729 709 697 752 698 715 768 755 743 742 731 707 744 700 747 738 686 752 733 734 654 697 742 732 732 699 733 721 733 726 738 716 726 718 714 722 747 710 730 733 723 720 703 720 691 726 704 720 744 693 718 747 720 722 714 721 743 734 670 701 762 706 732 689 738 739 716 705 709 747 736 730 749 726 707 727 739 714 737 768 681 724 701 712 736 706 753 727 699 743 722 791 720 692 711 714 737 679 767 694 738 702 763 731 741 743 733 746 705 734 743 726 732 724 743 687 724 723 716 663 800 711 712 789 686 689 709 714 697</counts>
			</dataPoints>
		</scan>
	</xrdMeasurement>
</xrdMeasurements>