File: dataset/precursor_mixture/NaAlO2-1.5H2O_Li2TiO3_SnO2_CaCO3.12-min.xrdml
<?xml version="1.0"?>
<xrdMeasurements xmlns="http://www.xrdml.com/XRDMeasurement/2.2" xmlns:xsi="http://www.w3.org/2001/XMLSchema-instance" xsi:schemaLocation="http://www.xrdml.com/XRDMeasurement/2.2 http://www.xrdml.com/XRDMeasurement/2.2/XRDMeasurement.xsd" status="Completed" recordIdentifier="{11A147A2-62C1-4BC4-8D4E-BE2F1CE81801}">
	<comment>
		<entry/>
	</comment>
	<sample type="To be analyzed">
		<id>dara-28-2</id>
		<name></name>
		<preparedBy></preparedBy>
	</sample>
	<xrdMeasurement measurementType="Scan" status="Completed" sampleMode="Reflection">
		<usedWavelength intended="K-Alpha 1">
			<kAlpha1 unit="Angstrom">1.5405980</kAlpha1>
			<kAlpha2 unit="Angstrom">1.5444260</kAlpha2>
			<kBeta unit="Angstrom">1.3922500</kBeta>
			<ratioKAlpha2KAlpha1>0.5000</ratioKAlpha2KAlpha1>
		</usedWavelength>
		<incidentBeamPath>
			<radius unit="mm">145.00</radius>
			<xRayTube id="1010048" name="Empyrean Cu LFF HR (9430 033 7310x) DK437873">
				<tension unit="kV">40.0</tension>
				<current unit="mA">15.0</current>
				<anodeMaterial>Cu</anodeMaterial>
				<focus type="Line">
					<length unit="mm">12.0</length>
					<width unit="mm">0.4</width>
					<takeOffAngle unit="deg">6.0</takeOffAngle>
				</focus>
			</xRayTube>
			<filter id="20010004" name="Beta-filter Nickel">
				<material>Ni</material>
				<thickness unit="mm">0.020</thickness>
			</filter>
			<sollerSlit id="21010002" name="Soller slits 0.04 rad.">
				<opening unit="rad">0.0400</opening>
			</sollerSlit>
			<mask id="22031000" name="Fixed mask 13 mm">
				<width unit="mm">9.00</width>
			</mask>
			<divergenceSlit id="22120001" name="Divergence slit 1°" xsi:type="fixedDivergenceSlitType">
				<distanceToSample unit="mm">50.00</distanceToSample>
				<height unit="mm">1.52</height>
			</divergenceSlit>
		</incidentBeamPath>
		<beamKnife id="29030100" name="Beam knife low"/>
		<sampleMovement xsi:type="spinningSampleMovementType">
			<spinnerRevolutionTime unit="seconds">1.0</spinnerRevolutionTime>
		</sampleMovement>
		<diffractedBeamPath>
			<radius unit="mm">145.00</radius>
			<antiScatterSlit id="22090040" name="AS slit 9 mm" xsi:type="fixedAntiScatterSlitType">
				<height unit="mm">9.00</height>
			</antiScatterSlit>
			<sollerSlit id="21020003" name="Large Soller slits 0.04 rad.">
				<opening unit="rad">0.0400</opening>
			</sollerSlit>
			<filter id="20030001" name="Large beta-filter Nickel">
				<material>Ni</material>
				<thickness unit="mm">0.020</thickness>
			</filter>
			<detector id="7010019" name="PIXcel1D-Medipix3 detector" xsi:type="rtmsDetectorType">
				<phd unit="keV">
					<lowerLevel>4.0</lowerLevel>
					<upperLevel>11.3</upperLevel>
				</phd>
				<mode>Scanning</mode>
				<activeLength unit="deg">5.020</activeLength>
			</detector>
		</diffractedBeamPath>
		<scan appendNumber="0" mode="Continuous" scanAxis="Gonio" status="Completed">
			<header>
				<startTimeStamp>2024-03-24T12:54:41-07:00</startTimeStamp>
				<endTimeStamp>2024-03-24T13:07:09-07:00</endTimeStamp>
				<author>
					<name>AutomatedUser</name>
				</author>
				<source>
					<applicationSoftware version="1.6 (94)">PANalytical Aeris Instrument Suite</applicationSoftware>
					<instrumentControlSoftware version="3.0.0 20211014">AERIS</instrumentControlSoftware>
					<instrumentID>2879380</instrumentID>
				</source>
			</header>
			<dataPoints>
				<positions axis="2Theta" unit="deg">
					<startPosition>9.99043322</startPosition>
					<endPosition>100.09495370</endPosition>
				</positions>
				<positions axis="Omega" unit="deg">
					<startPosition>4.99521661</startPosition>
					<endPosition>50.04747685</endPosition>
				</positions>
				<commonCountingTime unit="seconds">18.249</commonCountingTime>
				<counts unit="counts">3989 4060 4052 4216 4033 4055 4017 4056 3906 4037 4031 4086 3931 3896 3960 3917 3842 3905 3885 3875 3940 3965 3924 3848 3930 3851 3859 3877 3852 3896 3848 3896 4077 3951 3960 3796 3800 3789 3890 3811 3763 3843 3812 3815 3788 3817 3773 3808 3822 3764 3790 3754 3702 3747 3859 3763 3794 3745 3766 3618 3797 3763 3758 3687 3712 3680 3672 3621 3608 3735 3846 3668 3722 3658 3495 3700 3637 3553 3671 3701 3677 3559 3618 3636 3664 3556 3652 3664 3645 3581 3581 3502 3509 3705 3647 3617 3535 3560 3609 3569 3656 3512 3538 3464 3490 3509 3526 3559 3603 3511 3561 3506 3370 3495 3489 3364 3557 3465 3515 3425 3417 3373 3446 3620 3482 3468 3455 3392 3383 3399 3369 3444 3564 3503 3444 3350 3445 3428 3412 3417 3258 3409 3390 3357 3398 3321 3318 3396 3350 3456 3317 3280 3188 3305 3335 3387 3302 3292 3273 3360 3335 3273 3195 3226 3291 3215 3326 3309 3284 3269 3304 3348 3273 3186 3303 3263 3265 3226 3178 3300 3192 3238 3133 3254 3185 3099 3268 3225 3100 3243 3148 3161 3166 3133 3208 3211 3196 3198 3085 3121 3027 3146 3109 3241 3263 3207 3126 3066 3175 3157 3019 3112 3104 3078 3066 3003 3174 3085 3073 3129 3048 2984 3074 3107 3051 3020 3078 3071 2965 2955 3067 3121 2889 3063 2978 3046 2980 3099 3081 2982 2975 3022 2982 2970 3011 3078 3066 3074 2962 3078 2972 2972 2999 2935 3011 3005 3021 3027 2973 2944 3000 2925 2889 2896 2943 2882 2891 2877 2906 2894 2982 2935 2829 2917 2834 2858 2847 2888 2899 2972 2977 2938 2847 2859 2880 2838 2870 2826 2883 2897 2900 2885 2804 2893 2964 2824 2903 2820 2815 2882 2797 2757 2899 2765 2810 2854 2843 2841 2917 2726 2746 2871 2741 2892 2863 2843 2806 2685 2785 2705 2843 2738 2746 2824 2763 2692 2729 2738 2807 2755 2768 2763 2790 2740 2858 2719 2701 2784 2773 2797 2720 2656 2697 2747 2711 2744 2747 2760 2692 2698 2681 2734 2720 2764 2641 2669 2731 2673 2770 2662 2694 2685 2611 2767 2664 2734 2674 2647 2624 2784 2706 2700 2698 2627 2783 2781 2675 2714 2680 2704 2484 2591 2699 2668 2725 2656 2583 2642 2626 2656 2581 2671 2646 2608 2554 2647 2630 2629 2561 2665 2501 2616 2586 2534 2621 2575 2594 2520 2665 2623 2507 2634 2627 2533 2480 2582 2559 2609 2588 2629 2591 2616 2628 2722 2543 2562 2486 2628 2577 2499 2537 2576 2520 2476 2509 2403 2592 2553 2449 2438 2439 2598 2619 2555 2473 2514 2540 2537 2535 2541 2450 2591 2443 2616 2598 2440 2545 2519 2520 2576 2651 2503 2462 2404 2588 2498 2523 2438 2506 2532 2470 2455 2536 2469 2515 2391 2497 2482 2514 2531 2473 2566 2415 2512 2520 2503 2454 2565 2472 2553 2526 2450 2442 2388 2500 2457 2448 2523 2509 2451 2452 2600 2393 2447 2451 2593 2384 2562 2405 2501 2489 2521 2515 2461 2510 2490 2536 2473 2482 2525 2459 2513 2482 2442 2511 2410 2468 2408 2484 2467 2476 2416 2444 2449 2364 2399 2435 2477 2391 2378 2390 2481 2328 2433 2459 2374 2428 2419 2373 2359 2407 2328 2443 2381 2382 2382 2395 2337 2479 2333 2201 2320 2297 2409 2297 2420 2464 2300 2338 2276 2433 2496 2414 2490 2411 2303 2398 2378 2300 2408 2378 2391 2456 2370 2391 2331 2396 2434 2359 2550 2380 2416 2440 2337 2410 2389 2463 2456 2343 2513 2538 2575 2643 2646 2614 2582 2625 2639 2778 2736 2744 2847 2900 2911 2826 2900 2791 2817 2708 2564 2591 2429 2572 2576 2517 2481 2539 2512 2484 2406 2504 2467 2532 2651 2502 2478 2635 2422 2510 2428 2440 2433 2378 2336 2305 2329 2300 2335 2267 2355 2276 2323 2305 2326 2211 2295 2216 2256 2189 2261 2256 2211 2214 2261 2279 2290 2252 2184 2211 2256 2291 2283 2295 2298 2231 2306 2113 2257 2294 2189 2254 2245 2250 2265 2257 2288 2319 2224 2265 2220 2240 2172 2189 2224 2293 2305 2203 2192 2286 2201 2178 2244 2249 2242 2198 2274 2245 2219 2195 2187 2246 2232 2229 2258 2298 2288 2242 2271 2307 2335 2264 2243 2203 2192 2334 2192 2241 2241 2232 2269 2231 2335 2290 2173 2212 2254 2279 2247 2245 2250 2269 2295 2214 2327 2203 2263 2243 2361 2311 2336 2261 2347 2293 2380 2342 2324 2414 2435 2373 2407 2349 2403 2429 2404 2539 2459 2574 2592 2585 2551 2644 2477 2516 2564 2619 2626 2726 2745 2700 2744 2542 2737 2577 2729 2658 2727 2697 2704 2653 2663 2572 2588 2581 2601 2489 2491 2482 2389 2474 2396 2325 2400 2435 2321 2346 2328 2308 2405 2348 2319 2354 2299 2299 2318 2271 2322 2378 2302 2366 2338 2280 2295 2231 2245 2255 2176 2203 2204 2050 2151 2027 2127 2119 2108 2147 2058 2038 2067 2066 2091 2035 2019 1960 2015 2156 2090 2055 1990 2088 2086 2047 2113 2027 2071 2200 2097 2108 2035 2081 2071 2118 2114 2126 2076 2033 2003 1934 1968 2107 2129 2131 1970 2091 1990 2029 2002 2069 1985 2055 1968 1973 1902 1926 1956 2033 1938 1933 1964 2000 1958 1922 1953 1969 1886 2076 2032 2025 1925 2082 1868 2033 1956 1970 1986 1946 1990 2000 1999 1934 2051 1932 1972 1951 1986 1890 2009 2010 1938 2024 1896 1998 1950 1976 1910 2054 1973 1924 2026 2004 2006 2050 1954 1982 1999 2004 1994 2007 2029 2045 2079 2003 2105 2061 2097 1971 2019 2084 2102 2077 2136 2089 2148 2133 2183 2155 2193 2232 2225 2261 2255 2281 2308 2434 2349 2385 2465 2466 2449 2517 2549 2478 2419 2300 2316 2180 2162 2152 2090 2058 2045 2110 2012 2122 2054 2080 2081 2100 2128 2133 2060 2134 2094 2221 2170 2133 2193 2093 2139 2135 2063 2033 2049 2014 2014 1934 2005 1894 1891 1890 1894 2005 1936 1969 2016 1873 1891 1966 1940 1958 1998 1886 1892 1966 1889 1960 1953 1939 1998 1983 1988 2119 2010 2033 2101 2101 2223 2094 2125 2098 2085 2009 1948 1890 1964 1937 1955 1952 1905 1944 1808 1835 1837 1859 1819 1901 1844 1762 1855 1756 1829 1802 1816 1798 1705 1726 1796 1807 1794 1797 1749 1775 1744 1755 1795 1765 1860 1766 1821 1809 1768 1799 1714 1755 1851 1826 1691 1790 1737 1714 1764 1860 1681 1706 1736 1658 1750 1756 1755 1728 1675 1819 1683 1758 1729 1720 1729 1810 1702 1745 1723 1695 1677 1672 1769 1701 1733 1610 1661 1675 1727 1699 1656 1662 1605 1685 1701 1715 1732 1706 1706 1703 1665 1714 1715 1674 1687 1808 1578 1665 1705 1592 1664 1682 1598 1673 1773 1715 1751 1645 1664 1696 1652 1582 1677 1640 1680 1781 1651 1682 1578 1658 1732 1618 1751 1641 1706 1662 1675 1691 1642 1759 1692 1663 1681 1594 1636 1646 1739 1640 1686 1720 1586 1720 1741 1675 1696 1724 1653 1671 1717 1711 1713 1770 1796 1812 1835 1900 1836 1933 1963 1984 2131 2140 2198 2304 2363 2380 2340 2286 2347 2185 2057 2058 2004 1936 1901 1805 1769 1720 1748 1625 1679 1626 1620 1609 1646 1576 1621 1643 1638 1612 1645 1612 1627 1640 1577 1562 1559 1584 1578 1631 1622 1545 1583 1577 1602 1599 1578 1613 1534 1602 1571 1613 1654 1583 1646 1665 1589 1593 1627 1584 1598 1643 1655 1618 1586 1573 1648 1613 1582 1649 1590 1629 1620 1634 1595 1558 1577 1589 1696 1589 1647 1578 1707 1730 1646 1635 1678 1591 1671 1603 1634 1651 1592 1646 1553 1529 1557 1481 1529 1597 1571 1476 1547 1513 1492 1514 1495 1476 1532 1519 1531 1469 1515 1495 1525 1470 1541 1501 1545 1546 1492 1540 1546 1508 1489 1451 1441 1501 1589 1457 1502 1465 1462 1534 1492 1507 1515 1506 1497 1529 1492 1549 1418 1527 1422 1562 1474 1533 1533 1463 1515 1414 1501 1533 1439 1426 1483 1549 1518 1430 1401 1507 1434 1502 1472 1486 1445 1504 1496 1497 1508 1500 1526 1512 1459 1525 1446 1501 1505 1480 1444 1504 1510 1504 1559 1491 1539 1527 1490 1593 1460 1580 1530 1615 1611 1683 1664 1667 1775 1827 1793 1801 1856 1940 1884 1917 1855 1899 1789 1800 1783 1839 1771 1814 1751 1794 1806 1733 1739 1840 1739 1691 1638 1612 1676 1630 1561 1598 1569 1609 1556 1607 1599 1619 1553 1638 1547 1552 1516 1564 1564 1631 1511 1564 1587 1573 1554 1522 1632 1630 1624 1646 1570 1601 1628 1660 1691 1693 1639 1685 1632 1718 1743 1688 1647 1744 1719 1682 1688 1783 1759 1781 1744 1718 1740 1860 1845 1963 1910 1984 1947 1988 1976 1983 1930 2064 2070 2184 2165 2262 2258 2282 2304 2382 2432 2460 2622 2734 2712 2852 2863 3034 3140 3232 3529 3639 3942 4102 4452 4637 4923 5275 5825 6175 6965 7545 8206 8941 10129 10873 11880 13130 14563 15937 17252 18676 20341 21482 22702 23424 24249 24370 24162 23081 22198 20647 18998 17805 15927 14491 12730 11552 10108 8885 8035 7111 6591 5808 5430 5053 4565 4287 3892 3774 3574 3464 3150 3117 2952 2852 2736 2608 2550 2541 2357 2416 2324 2269 2131 2151 2158 2023 2047 1973 1934 1967 1879 1864 1816 1835 1774 1753 1772 1734 1674 1727 1682 1668 1632 1601 1566 1623 1545 1584 1573 1624 1523 1553 1526 1512 1574 1646 1469 1469 1552 1519 1434 1532 1503 1440 1479 1503 1467 1426 1451 1449 1440 1449 1527 1420 1446 1366 1390 1434 1451 1429 1384 1418 1381 1409 1468 1431 1431 1466 1446 1411 1335 1386 1404 1391 1411 1284 1389 1327 1303 1349 1345 1407 1285 1385 1360 1341 1298 1323 1329 1354 1287 1284 1327 1310 1333 1330 1367 1383 1313 1302 1267 1382 1303 1315 1366 1293 1295 1345 1348 1323 1266 1321 1255 1320 1323 1287 1262 1303 1359 1337 1380 1393 1348 1405 1364 1412 1387 1349 1455 1463 1490 1582 1572 1646 1601 1603 1691 1589 1674 1679 1542 1648 1570 1659 1593 1604 1543 1631 1622 1602 1657 1604 1526 1620 1619 1666 1666 1581 1609 1652 1716 1665 1616 1643 1671 1738 1690 1729 1661 1764 1748 1833 1742 1885 1857 1959 1961 2031 1999 2103 2066 2142 2294 2342 2393 2339 2425 2435 2516 2584 2686 2745 2730 2913 2842 2969 3117 3226 3351 3571 3725 4010 4453 4769 5353 5806 6310 7353 8210 9437 10869 12722 15044 18125 21799 26889 33314 40713 50215 60432 72701 86534 101897 115245 120117 116205 100263 84097 72541 65345 63800 59302 51970 41031 29059 20082 13404 9671 7554 6119 5612 5051 4527 4252 3980 3684 3631 3454 3403 3195 3085 3038 2945 2966 2856 2799 2684 2561 2555 2419 2330 2179 2180 2114 1988 2051 1983 1773 1846 1795 1718 1718 1689 1735 1623 1658 1691 1595 1577 1623 1610 1586 1585 1551 1652 1683 1561 1665 1609 1603 1690 1663 1576 1676 1663 1713 1746 1655 1754 1714 1779 1839 1859 1955 1946 2100 2136 2114 2197 2156 2096 2117 2025 1915 1985 1909 1852 1712 1814 1771 1727 1770 1711 1624 1655 1623 1590 1567 1627 1534 1590 1554 1578 1520 1521 1536 1421 1442 1484 1402 1407 1450 1342 1360 1375 1357 1378 1340 1368 1285 1309 1281 1341 1306 1269 1326 1308 1321 1305 1319 1371 1309 1328 1317 1330 1333 1285 1297 1185 1315 1261 1339 1229 1252 1270 1242 1258 1262 1196 1246 1248 1280 1243 1281 1283 1242 1302 1277 1306 1301 1272 1276 1250 1268 1274 1329 1308 1430 1295 1361 1352 1339 1452 1474 1569 1536 1544 1643 1649 1741 1748 1801 1694 1705 1566 1620 1577 1570 1604 1568 1534 1629 1554 1576 1571 1690 1705 1764 1832 1823 1869 1783 1765 1682 1647 1667 1568 1602 1477 1484 1446 1344 1378 1357 1217 1256 1271 1241 1230 1243 1233 1192 1243 1267 1325 1200 1193 1182 1243 1240 1181 1260 1224 1223 1218 1211 1282 1221 1265 1185 1317 1259 1230 1245 1264 1262 1260 1215 1314 1241 1228 1293 1269 1235 1291 1242 1232 1300 1226 1256 1294 1237 1229 1207 1222 1259 1172 1234 1224 1189 1154 1150 1209 1139 1184 1219 1136 1278 1145 1233 1203 1211 1198 1238 1187 1111 1203 1181 1257 1140 1179 1137 1191 1198 1144 1172 1226 1178 1234 1210 1282 1204 1203 1231 1175 1235 1298 1286 1275 1235 1243 1270 1248 1249 1299 1227 1263 1270 1275 1342 1265 1339 1373 1332 1331 1339 1428 1401 1404 1503 1498 1533 1498 1556 1537 1661 1648 1743 1822 1847 1971 1884 1955 2005 1934 2054 1936 1925 1956 1892 1883 1785 1766 1784 1707 1757 1769 1744 1759 1734 1734 1746 1718 1892 1860 1959 1911 1945 2082 2087 2173 2249 2381 2394 2488 2695 2698 2815 2915 2984 3088 3230 3202 3466 3588 3732 4012 4388 4668 5038 5336 6054 6453 7137 7867 8663 9827 10779 12068 13051 14603 15942 16916 17979 18654 19211 19447 18578 17870 17080 15928 15165 14174 13190 12302 11564 10157 9105 8136 7351 6453 5724 5378 4763 4391 4039 3725 3507 3323 3207 2985 2743 2776 2565 2440 2479 2375 2373 2283 2304 2264 2237 2287 2364 2355 2367 2352 2352 2290 2245 2166 2165 2072 1924 1884 1872 1833 1718 1738 1578 1538 1575 1470 1442 1455 1375 1380 1370 1375 1385 1454 1390 1429 1413 1476 1385 1468 1440 1488 1425 1464 1373 1382 1279 1350 1322 1279 1392 1357 1282 1382 1387 1449 1461 1439 1614 1641 1643 1762 1877 2011 2121 2295 2371 2546 2519 2411 2440 2409 2417 2260 2215 2162 2069 1983 1960 1957 1871 1824 1763 1596 1537 1513 1455 1401 1330 1349 1344 1319 1281 1240 1281 1216 1187 1142 1178 1209 1100 1111 1083 1068 1094 1095 1151 1064 1110 1116 1056 1064 1032 1038 1107 1061 1141 1095 1076 1117 1198 1146 1175 1220 1136 1224 1232 1340 1361 1381 1419 1507 1604 1522 1719 1695 1815 1828 1796 1842 1732 1723 1727 1589 1607 1562 1710 1575 1633 1696 1562 1521 1606 1630 1684 1763 1933 1986 2100 2170 2286 2355 2379 2243 2061 1905 1812 1785 1853 1832 1804 1780 1644 1616 1512 1442 1402 1347 1365 1312 1318 1224 1251 1187 1168 1201 1196 1129 1107 1030 1092 1084 1074 1029 1020 967 974 986 929 1017 974 938 982 1040 961 960 896 951 977 959 958 1053 973 963 907 969 957 969 946 973 1011 933 959 976 953 944 965 891 922 936 955 961 926 956 966 979 954 983 985 918 995 1020 928 956 898 912 926 941 972 936 976 965 918 914 960 979 892 973 966 1012 1006 975 957 1005 945 933 976 983 990 968 978 959 1017 961 981 934 972 929 968 982 950 948 1001 967 953 1006 987 958 963 987 1073 983 1014 1046 1006 1069 1039 1113 1195 1147 1131 1147 1213 1216 1170 1223 1211 1275 1203 1246 1210 1255 1358 1254 1285 1289 1323 1405 1344 1400 1432 1407 1511 1625 1635 1744 1811 1967 2136 2234 2325 2540 2655 2918 3159 3551 3774 4156 4534 4922 5414 5632 5742 5985 5971 5891 5684 5279 5053 4773 4671 4431 4224 4094 3767 3400 3146 2796 2474 2335 2251 1870 1945 1801 1644 1572 1526 1406 1395 1380 1263 1253 1300 1137 1181 1169 1090 1087 1121 1064 1036 1083 1075 992 995 968 1013 995 1005 951 932 978 1004 932 981 1050 972 894 991 980 992 998 1020 962 1042 1012 1064 1012 1059 1033 1200 1265 1237 1289 1356 1411 1445 1475 1455 1357 1417 1383 1373 1351 1385 1405 1397 1500 1499 1536 1575 1665 1740 1724 1880 1962 2041 2192 2282 2246 2317 2367 2343 2423 2411 2309 2315 2339 2088 2076 1850 1731 1683 1630 1563 1494 1428 1375 1314 1311 1222 1125 1174 1158 1189 1208 1240 1304 1392 1554 1626 1644 1911 2018 2358 2521 2642 2674 2592 2379 2130 1913 1878 1782 1751 1815 1858 1779 1622 1364 1279 1176 1091 1031 971 955 941 983 927 881 911 881 894 895 842 924 849 825 874 897 849 856 805 800 858 830 815 831 833 880 858 815 853 835 869 864 878 826 826 867 884 879 898 906 936 868 923 826 861 882 833 865 820 775 818 820 827 817 739 718 752 742 743 789 783 822 746 748 749 760 806 766 768 748 777 719 790 773 795 749 842 824 799 754 795 769 785 761 792 772 800 771 770 776 731 723 690 776 729 734 737 763 715 687 682 680 743 759 761 703 755 729 758 716 703 761 704 750 741 685 700 727 718 701 741 716 688 723 720 751 700 705 685 701 683 714 739 708 707 738 748 725 768 698 754 681 753 755 715 722 763 736 754 732 816 755 719 703 725 747 760 770 780 760 790 730 797 775 786 771 777 731 750 738 820 758 761 758 836 801 776 798 851 791 779 840 904 965 935 922 993 948 858 890 824 790 846 844 823 839 844 821 796 760 795 764 749 745 788 780 755 789 804 828 836 847 832 839 872 797 817 829 786 801 810 773 828 785 813 817 767 771 821 767 776 810 764 762 782 774 790 813 798 862 778 781 792 800 823 747 811 775 796 758 772 759 764 762 819 807 789 782 724 738 741 802 784 763 787 838 832 838 845 868 842 891 880 920 940 987 985 946 1007 1035 1109 1034 1020 1075 1048 1006 987 1023 974 916 981 984 948 873 869 905 890 856 863 845 889 917 896 929 907 904 892 888 817 894 923 924 902 921 996 978 1033 1077 1164 1242 1321 1532 1654 1877 2083 2354 2720 2853 2927 2825 2578 2273 2081 1846 1867 1935 1962 2029 2037 2056 1946 1707 1616 1483 1403 1379 1410 1447 1412 1493 1500 1500 1502 1577 1648 1629 1688 1688 1767 1898 1878 1986 2082 2128 2161 2355 2340 2424 2497 2510 2646 2692 2736 2697 2689 2790 2825 2721 2774 2757 2673 2654 2541 2545 2342 2445 2304 2302 2167 2101 1987 1891 1855 1741 1766 1612 1477 1477 1385 1382 1350 1233 1238 1196 1066 1152 1064 966 1001 962 970 956 918 889 905 860 864 849 845 903 887 825 851 751 813 766 752 814 749 788 820 780 721 761 763 746 696 727 715 698 711 701 706 672 705 741 709 684 711 680 687 689 662 659 666 698 677 700 642 722 663 716 666 672 681 668 704 738 654 667 660 652 665 671 673 626 680 637 632 663 661 647 694 669 646 633 668 672 601 725 648 664 624 595 638 655 646 652 676 641 657 684 636 704 616 668 688 654 671 719 664 680 622 653 636 620 654 635 688 652 601 628 594 662 662 594 618 627 626 684 653 607 653 673 644 631 626 634 695 670 658 640 670 651 633 656 676 633 617 683 641 679 645 690 655 679 673 719 658 711 686 655 659 638 724 615 709 656 639 652 637 704 619 638 613 657 609 652 706 619 651 653 633 638 652 626 617 681 615 627 615 649 621 612 642 691 657 670 654 688 691 647 715 663 644 628 681 658 684 689 625 703 696 696 709 755 784 737 765 784 725 777 736 796 816 826 821 832 867 896 910 918 887 917 851 819 893 775 821 821 827 755 735 757 789 747 703 722 705 713 664 704 690 701 658 684 668 687 612 656 699 698 700 654 666 620 648 673 683 694 750 635 683 692 657 709 777 703 728 789 738 766 819 783 884 920 911 983 1084 1197 1186 1206 1218 1211 1238 1112 1025 979 996 1035 1026 1013 1038 1089 1072 1074 1024 939 952 918 988 911 980 1095 1063 1186 1218 1405 1586 1765 1936 2270 2728 3069 3636 4207 4862 5143 5342 4656 4064 3360 2727 2526 2370 2458 2571 2816 3044 2998 2877 2568 2160 1843 1415 1234 1098 993 932 918 922 902 906 855 828 829 703 816 849 812 824 757 817 781 764 755 772 752 752 776 792 761 772 706 762 739 804 780 776 781 771 765 779 786 786 806 762 757 748 847 792 835 839 769 817 799 774 826 859 854 881 840 812 939 819 935 950 1016 1082 1219 1234 1362 1550 1740 2046 2327 2593 2965 3194 3356 3282 3117 2657 2212 1946 1857 1818 1869 1883 1909 2111 2118 1934 1788 1507 1381 1221 1037 1001 909 796 815 829 838 797 737 769 739 745 718 718 681 710 674 707 683 617 732 711 653 635 659 661 692 618 614 631 657 658 635 629 660 602 576 577 593 636 607 662 627 639 609 581 627 638 635 630 618 571 632 621 613 668 643 621 633 692 639 604 616 595 615 655 614 607 589 634 635 608 588 630 596 623 592 611 606 604 590 583 583 610 607 566 543 558 564 592 586 591 540 569 583 557 573 533 587 573 569 574 554 547 587 622 545 551 580 576 548 620 588 574 606 559 600 586 609 586 618 589 641 612 566 584 582 620 615 610 622 685 607 633 614 592 641 634 624 659 628 627 614 659 681 647 633 646 703 624 630 680 655 657 646 681 695 665 660 692 681 715 723 744 768 755 737 732 766 656 701 692 722 691 740 666 650 715 702 648 697 671 653 649 686 632 691 667 680 655 661 704 635 674 653 694 639 649 654 702 680 664 651 645 683 652 709 673 642 682 694 699 716 752 695 703 744 769 758 730 750 730 750 760 793 769 795 794 835 811 840 821 811 907 892 900 968 967 985 1043 1022 1080 1014 1108 1125 1180 1131 1141 1270 1267 1211 1273 1370 1508 1382 1465 1494 1621 1639 1765 1828 1891 2127 2195 2349 2391 2680 2794 3239 3463 3676 4170 4592 5198 5816 6321 7125 8271 9370 10413 11545 12698 13455 14044 14208 13961 12960 12260 11465 10601 10098 9795 9520 9388 9575 9551 9283 8853 8362 7595 6967 6231 5497 4909 4290 3919 3395 3098 2999 2838 2504 2308 2309 2093 1990 1841 1833 1670 1580 1525 1442 1366 1322 1305 1202 1243 1200 1130 1132 1061 1153 1039 960 935 949 921 941 930 873 896 869 876 785 808 822 796 812 792 807 802 794 832 763 779 724 773 782 724 734 757 693 743 742 751 722 740 702 711 751 717 797 745 759 740 760 719 733 746 786 838 812 820 810 830 819 807 764 814 816 763 736 753 780 726 723 753 712 670 664 667 646 649 609 644 623 670 596 657 590 586 605 592 634 612 622 577 633 595 646 656 589 584 558 600 596 611 588 618 559 617 616 617 617 611 637 608 590 653 620 679 638 646 630 692 677 731 724 627 646 629 651 678 633 625 639 627 634 638 622 608 589 588 618 624 632 601 602 605 577 627 560 604 616 587 631 593 627 577 615 589 615 621 616 632 605 633 658 652 644 611 598 603 669 649 626 629 615 650 643 652 651 577 671 674 637 636 683 663 730 670 649 649 733 691 676 703 686 701 721 732 678 785 737 769 757 796 795 751 810 809 809 822 895 859 900 881 1000 955 1041 1062 1104 1075 1149 1194 1229 1332 1509 1559 1733 1810 2068 2270 2589 2748 3030 3304 3635 3621 3597 3740 3521 3366 3082 2809 2788 2658 2534 2578 2566 2475 2408 2461 2418 2327 2261 2005 1840 1698 1602 1482 1400 1250 1216 1172 1126 1138 1108 1150 1029 1066 1086 1062 969 1068 1022 1014 972 990 937 868 870 800 851 820 797 801 835 813 853 780 814 814 766 721 751 695 736 761 736 685 758 768 742 784 816 782 807 855 834 903 834 884 843 769 764 737 744 791 715 676 749 775 734 742 760 765 721 743 750 736 744 741 715 698 665 682 637 666 638 583 631 632 652 633 664 601 582 606 598 581 606 562 590 540 594 560 507 536 606 558 562 594 594 539 573 545 540 539 580 536 590 536 555 603 589 613 591 622 625 559 603 587 643 611 567 582 584 551 588 590 581 576 578 601 608 657 677 658 702 696 728 761 867 910 880 811 766 767 709 667 700 690 681 635 658 723 744 707 741 729 722 675 658 607 624 674 604 638 587 590 573 598 584 581 633 550 600 594 568 612 606 597 604 616 626 604 602 593 619 587 588 609 635 630 644 615 614 645 608 635 692 663 679 641 745 720 772 758 805 777 814 877 917 1038 1122 1165 1344 1441 1512 1585 1619 1594 1592 1430 1312 1235 1135 1176 1207 1251 1258 1267 1352 1440 1456 1484 1410 1342 1344 1318 1131 1152 1159 1209 1130 1139 1225 1271 1197 1229 1282 1413 1474 1494 1500 1699 1776 1866 1935 1943 2041 1960 1995 1952 1812 1676 1676 1658 1547 1554 1608 1558 1564 1539 1622 1593 1478 1433 1374 1451 1376 1347 1372 1323 1229 1076 1086 987 913 876 840 814 808 805 825 800 865 798 814 793 716 693 720 676 688 623 660 651 592 642 638 597 632 592 594 600 560 595 609 535 610 591 594 576 610 583 586 529 541 528 550 541 541 568 547 585 630 543 584 541 539 560 569 602 548 569 535 571 569 578 555 566 574 570 561 591 541 568 543 591 528 556 552 613 529 573 564 533 586 533 580 554 514 550 546 581 519 503 509 508 498 539 490 548 520 552 536 522 479 495 470 504 510 482 511 482 539 509 501 483 540 480 499 485 478 499 519 528 554 476 493 501 516 498 551 497 509 528 494 494 548 497 469 530 503 498 520 512 491 494 468 503 504 535 500 478 502 494 486 510 509 519 480 523 479 462 461 533 485 487 543 504 531 481 520 531 512 523 486 510 499 542 529 491 554 490 538 489 479 515 498 488 528 543 528 523 494 514 545 533 563 517 512 542 499 567 568 520 538 527 550 516 542 582 569 545 549 569 584 545 562 559 552 601 627 625 641 647 644 675 661 702 747 772 819 879 841 960 1016 1098 1143 1183 1227 1108 1093 909 891 820 796 769 813 838 806 881 826 924 931 994 987 893 928 916 963 993 1060 1213 1377 1539 1865 2237 2729 3181 3365 3226 2732 2202 1732 1408 1184 1108 1046 1109 1161 1237 1485 1641 1852 2076 1998 1815 1558 1251 1113 934 859 794 791 762 834 820 883 905 981 1007 1124 1141 1158 1093 1045 952 945 831 834 826 857 851 903 877 960 973 1019 995 1094 1016 1010 956 872 896 901 860 881 890 907 970 995 985 988 1032 1145 1092 1213 1369 1420 1538 1693 1807 2055 2164 2378 2646 2878 3053 3328 3485 3493 3249 3101 2991 2869 2621 2474 2342 2289 2189 2327 2362 2394 2340 2278 2189 2330 2141 2072 1858 1811 1608 1539 1464 1307 1292 1170 1225 1075 1098 1011 1127 1010 1070 1005 1047 973 1065 938 973 911 855 833 770 794 794 723 746 725 733 777 747 772 767 739 794 718 676 682 690 647 717 607 596 613 690 665 600 666 618 628 619 641 626 618 617 656 595 613 650 649 662 631 653 639 656 669 629 662 660 631 604 610 646 690 685 699 672 699 711 744 762 780 804 847 898 893 844 936 895 873 887 839 849 805 843 846 880 878 925 918 989 971 994 1001 1012 1027 1028 1088 1022 1087 1092 1122 1101 1170 1224 1258 1178 1214 1281 1271 1332 1335 1383 1347 1390 1398 1380 1408 1406 1449 1388 1369 1387 1318 1344 1252 1239 1253 1221 1302 1209 1248 1219 1131 1147 1194 1113 1117 1089 1115 1070 1106 996 974 1009 974 948 852 873 889 875 851 804 792 794 807 769 758 729 711 738 707 738 746 688 675 686 679 683 655 686 661 640 641 664 626 642 658 648 659 617 667 607 662 649 685 681 722 739 747 729 744 763 859 777 840 830 825 830 903 891 935 910 908 882 932 914 1034 1012 973 1019 1077 1084 1143 1166 1279 1390 1351 1500 1673 1730 1979 2133 2321 2474 2670 2784 2936 3062 3098 3296 3338 3037 3185 2847 2891 2615 2529 2500 2456 2373 2257 2245 2217 2216 2248 2188 2211 2090 2084 1921 1849 1629 1649 1461 1391 1226 1218 1155 1095 1026 990 960 917 929 887 851 814 811 797 828 766 754 762 728 718 690 734 738 657 717 667 659 652 670 660 641 653 719 630 696 666 685 692 640 678 702 741 772 700 767 802 835 884 908 1053 1112 1177 1299 1283 1391 1339 1327 1150 1086 1039 1046 1054 1073 1042 1044 1133 1201 1257 1282 1353 1434 1597 1549 1588 1639 1674 1675 1855 2009 2134 2266 2456 2650 2958 3088 3369 3600 3834 3810 3933 3660 3434 3259 2955 2784 2587 2599 2404 2333 2401 2346 2410 2418 2485 2481 2422 2421 2333 2189 2061 1821 1746 1607 1467 1293 1245 1167 1098 1052 965 961 947 903 855 876 816 787 750 732 752 778 701 660 656 663 683 685 675 666 678 599 605 627 625 637 566 560 595 569 558 533 626 553 621 578 593 594 593 622 628 630 589 574 599 582 634 546 607 615 586 595 567 648 582 637 641 602 647 620 561 634 662 589 570 586 567 566 578 563 543 534 520 558 533 553 526 509 516 516 492 498 514 508 467 453 460 502 474 461 466 454 467 473 485 461 477 475 472 481 471 460 456 463 436 467 428 466 449 431 443 441 439 468 445 470 431 413 466 426 444 432 426 499 432 459 414 445 442 484 463 439 439 414 443 435 454 431 453 439 454 405 488 442 460 442 445 453 401 462 431 439 409 433 419 391 438 441 451 424 432 430 447 457 461 433 447 429 447 461 398 443 432 479 433 414 472 417 455 409 443 433 405 377 413 413 445 470 474 431 390 434 423 406 409 450 447 435 417 428 460 436 456 435 423 419 462 458 436 515 436 498 494 460 478 496 507 512 522 521 535 508 524 559 551 558 567 559 571 574 561 579 562 546 518 547 565 531 517 531 479 551 541 579 521 567 608 536 587 637 589 648 580 640 668 618 575 582 595 529 622 629 634 654 717 658 621 654 643 640 645 596 563 540 561 546 549 511 554 516 541 549 560 537 559 536 564 477 489 509 491 473 436 477 472 466 487 414 453 439 419 411 428 414 426 424 450 402 425 403 472 426 473 387 408 398 410 444 444 423 413 450 380 418 393 433 374 428 436 412 403 399 411 445 434 414 437 443 453 397 418 431 406 425 412 440 422 426 433 494 464 491 507 469 484 515 590 617 655 687 777 732 787 730 645 671 546 592 541 534 500 505 490 494 508 495 566 549 595 613 582 660 585 567 539 540 452 472 490 498 467 469 474 446 466 418 454 455 459 492 433 464 428 432 424 425 479 440 482 487 488 422 448 468 444 433 470 470 471 447 493 487 483 491 516 456 493 441 506 548 510 559 527 640 535 550 527 591 578 617 655 636 676 693 717 800 845 836 950 1041 1085 1149 1287 1351 1494 1569 1668 1680 1748 1756 1618 1463 1400 1273 1209 1159 1174 1182 1051 1080 1078 1070 1127 1168 1167 1201 1182 1126 1161 1092 1060 983 897 875 843 773 698 762 702 661 696 654 638 603 610 567 588 582 558 504 538 503 496 474 445 525 462 508 528 495 516 481 462 458 465 469 459 448 437 426 460 410 452 373 455 392 422 426 447 481 400 420 430 375 486 437 460 457 395 459 436 478 393 437 462 420 450 420 464 478 463 440 437 464 435 483 452 451 466 475 444 459 483 456 434 460 409 427 450 462 452 438 432 481 443 467 462 476 429 436 438 447 427 460 460 444 361 426 409 456 431 447 456 437 426 455 466 488 505 515 536 558 579 649 683 682 665 668 609 611 511 458 483 498 471 449 424 495 482 490 491 484 510 528 564 532 508 533 478 483 439 451 378 421 429 420 418 421 419 409 401 399 387 402 399 407 407 388 359 407 398 408 418 425 386 392 413 374 427 378 432 415 385 406 406 423 428 426 460 434 444 478 505 463 459 481 494 475 466 453 472 440 468 447 463 495 490 443 483 469 481 477 500 535 477 533 527 518 472 513 490 454 474 494 457 503 451 458 428 447 425 471 441 452 433 417 419 481 400 424 411 446 403 435 425 453 455 382 383 408 391 369 423 428 377 436 358 414 404 399 398 394 424 434 434 440 453 453 451 463 428 437 407 451 425 431 433 417 457 392 439 393 424 404 409 400 407 445 443 450 435 450 447 443 425 417 447 421 435 447 403 452 416 427 394 412 422 478 393 421 382 399 392 401 442 393 436 421 456 390 373 396 453 412 434 393 396 412 388 401 394 405 406 395 437 410 416 432 398 382 426 377 390 368 401 410 393 424 352 418 408 394 427 419 393 408 389 412 375 397 407 368 394 416 390 448 347 415 397 353 371 415 381 390 393 392 409 384 380 389 385 400 385 400 417 420 407 406 425 420 377 402 376 346 405 382 424 411 384 365 378 431 394 371 360 405 425 411 444 393 412 409 410 414 467 438 457 446 406 433 430 450 421 459 411 469 474 454 455 474 462 412 459 494 519 487 528 520 533 496 513 496 470 469 464 465 439 435 446 460 441 448 393 460 456 440 493 459 470 455 458 474 430 440 412 428 432 405 418 400 373 438 459 428 456 467 430 443 456 410 383 422 442 451 416 433 451 401 439 393 415 425 448 445 437 470 439 435 418 420 461 465 448 447 466 440 438 512 471 488 520 560 601 650 697 741 817 867 887 866 819 671 633 586 528 541 482 510 416 491 471 450 476 522 490 537 583 606 637 629 642 532 557 501 507 431 423 426 434 445 444 420 409 368 437 407 416 423 434 427 408 376 416 429 379 400 414 400 408 388 421 409 386 396 375 390 385 400 410 389 405 398 394 394 362 407 413 412 395 419 404 389 433 409 447 430 424 416 443 443 410 443 450 443 446 453 447 404 434 469 400 461 448 468 449 430 494 485 449 467 466 466 508 528 542 488 523 540 508 549 546 524 534 577 590 603 604 623 614 669 637 672 787 772 795 828 824 915 968 985 1043 1181 1285 1350 1425 1673 1854 1918 2102 2235 2261 2399 2417 2370 2184 2106 1917 1863 1667 1558 1549 1403 1420 1295 1316 1325 1320 1414 1420 1505 1458 1590 1600 1402 1565 1486 1344 1292 1207 1108 1016 979 949 831 814 777 704 756 656 685 658 634 602 637 525 547 520 532 558 562 516 513 474 506 498 498 478 495 445 467 491 447 466 426 443 484 454 479 445 432 442 479 468 451 460 397 459 419 440 453 467 453 414 457 439 414 479 457 415 407 431 442 438 465 448 448 513 496 445 461 426 474 465 473 478 468 443 457 450 459 445 463 505 478 498 483 482 467 454 502 479 501 508 497 500 543 556 606 519 563 561 554 557 592 531 572 580 563 602 574 576 565 590 613 598 631 568 612 591 540 570 566 592 565 606 521 608 586 553 558 530 498 526 522 490 562 496 548 495 504 477 448 513 495 498 488 458 440 475 448 452 453 458 440 480 479 461 497 467 462 453 490 433 444 473 482 473 495 456 461 476 516 468 519 581 523 551 530 540 542 562 601 626 660 630 651 667 698 689 772 835 868 954 934 985 1013 972 1057 932 927 911 847 814 752 780 737 780 777 760 806 730 721 781 776 763 766 852 878 787 801 818 819 770 804 807 872 867 922 945 968 910 981 830 725 682 654 599 601 535 588 579 555 584 552 586 554 559 559 579 626 648 668 642 671 605 608 516 531 495 503 485 488 466 457 450 446 464 429 473 463 437 453 482 500 467 460 438 465 501 467 493 491 506 521 481 491 417 445 434 405 416 390 399 403 419 418 395 432 423 423 420 416 394 453 401 436 446 395 447 444 384 373 414 399 398 434 396 408 400 397 365 368 392 373 370 399 410 399 428 376 396 430 385 384 355 382 396 396 409 412 410 396 445 420 420 369 395 401 405 404 433 403 396 385 421 420 398 413 411 416 387 421 377 412 407 426 428 463 421 424 409 408 435 367 422 424 411 410 401 431 422 470 397 460 436 439 394 495 481 487 478 449 472 471 503 526 493 493 487 487 499 509 497 538 540 542 504 545 482 547 557 583 580 608 658 666 734 739 760 779 864 897 962 1125 1193 1323 1381 1479 1646 1776 1914 1910 2001 1845 1906 1800 1744 1737 1454 1459 1306 1273 1153 1076 1068 1036 1037 1015 1063 1081 1073 1116 1141 1209 1249 1264 1320 1219 1212 1175 1036 1035 923 889 862 758 744 701 666 629 615 593 618 577 566 549 572 525 506 496 496 497 457 485 484 418 451 439 469 440 418 403 436 413 445 414 437 447 426 440 400 432 360 443 358 374 386 443 404 403 366 400 401 405 393 383 373 405 353 416 378 410 397 429 402 403 483 487 501 484 517 536 504 492 462 491 444 479 407 421 426 411 395 372 367 368 392 386 418 359 410 401 388 444 416 437 449 440 412 408 412 409 368 397 353 407 373 372 367 352 360 382 344 336 352 350 394 345 383 333 364 357 356 368 328 354 331 369 383 335 375 370 331 374 352 394 346 356 358 367 368 327 355 361 369 359 340 321 327 402 377 356 330 358 359 344 349 351 351 354 390 345 380 332 346 359 328 320 362 354 369 344 359 318 340 340 343 343 347 321 386 369 364 378 344 375 344 353 360 371 330 351 358 327 357 361 366 342 361 346 393 380 361 380 377 384 357 345 411 411 384 376 391 379 380 377 396 391 379 399 414 461 380 439 418 432 433 419 413 435 393 420 386 407 395 387 352 413 386 412 406 374 396 378 382 402 421 412 431 438 426 443 418 439 416 397 429 422 406 426 444 404 426 451 403 454 463 479 441 440 448 497 436 569 518 500 528 549 577 531 554 553 571 595 633 649 647 645 693 758 787 875 882 911 955 1017 967 992 872 922 869 823 748 748 703 676 646 648 632 638 676 678 629 679 635 663 646 673 741 741 686 668 638 653 610 630 611 550 516 563 502 455 495 482 470 469 447 420 419 427 414 427 405 385 373 403 361 387 378 401 367 358 348 371 377 352 345 358 376 322 386 370 385 387 376 380 367 339 375 386 399 350 372 322 361 341 363 392 376 370 337 384 369 334 325 379 337 372 353 353 330 319 367 327 407 370 405 361 356 331 341 350 331 334 336 359 377 365 358 375 327 384 367 374 350 353 353 340 337 343 337 363 374 365 362 383 362 379 394 386 341 382 373 377 343 400 373 370 378 368 367 376 430 379 412 360 370 381 370 364 348 378 384 379 381 416 370 385 353 406 374 374 365 420 383 400 373 398 400 377 391 411 407 420 442 433 464 430 432 371 427 459 446 420 452 464 456 451 476 488 476 459 514 471 483 466 537 505 478 523 522 547 559 561 587 533 573 579 655 611 715 691 712 801 764 802 904 936 966 1057 1090 1175 1255 1310 1401 1521 1636 1721 1786 1868 1892 1858 1807 1730 1659 1464 1456 1380 1309 1186 1179 1154 1121 1058 1083 1067 1044 1023 1094 1063 1119 1117 1246 1230 1216 1240 1248 1201 1201 1203 1046 1036 996 949 864 824 795 841 767 680 700 627 625 644 595 589 631 607 586 600 544 554 600 573 561 539 529 557 478 554 535 541 493 512 542 519 556 548 589 554 525 550 538 568 563 583 615 591 604 609 679 693 627 763 716 790 818 798 847 868 895 964 1053 1110 1206 1249 1352 1496 1571 1697 1849 1901 1968 2012 1863 1792 1785 1685 1574 1486 1482 1306 1308 1198 1138 1129 1094 1095 1108 1079 1066 1119 1061 1098 1117 1197 1211 1207 1327 1249 1233 1197 1199 1174 1065 1024 1033 917 839 757 748 772 679 715 677 624 583 582 575 541 531 517 515 496 530 525 517 481 454 452 498 459 426 446 468 452 420 408 444 425 400 408 436 432 406 421 409 397 395 415 412 380 416 407 393 404 413 387 409 392 381 363 396 384 384 377 387 395 378 407 361 389 371 396 376 374 391 398 365 375 389 384 422 366 392 407 427 394 371 379 412 382 381 378 386 440 370 401 364 386 349 366 392 375 392 389 390 391 414 399 419 405 386 414 386 405 456 373 407 410 393 421 407 432 425 409 415 452 392 392 394 410 429 423 413 437 395 389 435 420 373 446 474 399 432 413 477 500 407 443 400 428 417 464 451 445 457 467 468 446 479 482 542 513 600 560 624 653 655 690 647 681 650 642 650 647 646 650 587 640 665 665 686 687 754 793 862 900 975 1059 1010 1088 1102 1158 1156 1165 1115 1135 997 921 931 830 854 717 742 740 729 716 648 632 662 707 675 705 716 715 733 712 768 774 834 778 790 733 683 664 675 656 629 588 585 527 549 539 509 533 504 450 497 438 472 481 472 453 482 448 417 473 433 437 429 390 446 451 439 430 441 428 487 483 452 414 435 432 437 408 434 408 377 407 383 413 395 356 401 392 408 383 406 448 412 408 419 451 424 419 437 448 400 402 362 397 417 416 432 438 419 413 398 427 419 399 418 417 432 441 405 467 438 416 507 429 458 448 492 474 493 514 578 616 636 597 660 679 663 618 601 509 516 524 541 498 500 487 506 482 490 501 463 501 512 551 576 533 626 649 730 829 833 897 879 865 777 731 653 681 583 554 509 478 496 478 450 469 467 443 436 477 478 455 424 454 464 500 525 543 520 567 566 554 547 545 510 519 499 479 479 441 422 417 494 448 466 424 446 412 428 433 422 438 463 450 456 439 465 425 404 465 427 431 453 466 488 465 473 485 458 504 494 528 530 499 549 512 587 575 558 608 633 632 693 690 737 748 753 815 829 846 912 939 1015 1013 1030 1098 1041 1035 965 985 1009 960 954 1031 938 982 1047 988 954 965 895 841 849 822 815 779 770 748 723 776 823 830 790 797 772 815 750 743 758 742 730 717 720 672 633 674 668 665 595 607 585 573 525 564 539 529 500 508 530 484 469 460 420 447 420 430 460 420 478 415 472 426 397 381 393 422 391 398 404 388 404 395 424 394 374 418 379 394 355 396 381 389 361 388 390 386 363 378 363 357 387 338 363 390 347 372 373 357 340 346 352 373 345 349 337 413 348 368 370 349 334 363 341 345 379 351 316 352 325 334 370 315 366 368 369 362 350 379 333 330 361 342 347 343 330 339 317 327 351 321 359 381 368 371 363 381 385 404 426 390 441 355 406 365 362 381 384 371 335 359 342 324 339 356 334 338 331 380 342 351 343 362 339 335 364 361 373 420 362 358 375 375 338 371 366 360 342 345 357 337 349 324 348 408 315 351 359 331 370 313 345 346 336 329 347 338 362 315 333 330 317 331 333 329 339 311 326 367 382 346 395 390 380 396 370 378 360 379 361 379 376 343 365 403 387 379 389 379 352 363 394 397 358 363 359 385 358 369 395 354 387 381 356 377 420 408 375 394 418 388 421 447 391 443 442 425 470 463 456 492 504 556 590 578 665 711 718 784 940 1097 1261 1452 1636 1685 1571 1468 1257 1131 973 854 788 685 643 635 555 511 550 535 518 492 516 494 485 491 555 527 543 594 604 674 764 826 976 937 980 945 925 744 786 655 597 563 511 516 481 444 477 412 410 407 411 418 396 374 379 393 407 403 378 352 359 394 358 348 391 362 328 359 378 354 366 339 360 358 355 343 374 356 350 340 374 412 382 375 342 367 366 370 397 352</counts>
			</dataPoints>
		</scan>
	</xrdMeasurement>
</xrdMeasurements>