File: dataset/precursor_mixture/NaAlO2-1.5H2O_V2O5_LiCoO2.2-min.xrdml
<?xml version="1.0"?>
<xrdMeasurements xmlns="http://www.xrdml.com/XRDMeasurement/2.2" xmlns:xsi="http://www.w3.org/2001/XMLSchema-instance" xsi:schemaLocation="http://www.xrdml.com/XRDMeasurement/2.2 http://www.xrdml.com/XRDMeasurement/2.2/XRDMeasurement.xsd" status="Completed" recordIdentifier="{6D0C5488-662D-4DFC-812A-E82093BCA56B}">
	<comment>
		<entry/>
	</comment>
	<sample type="To be analyzed">
		<id>dara-6-1</id>
		<name></name>
		<preparedBy></preparedBy>
	</sample>
	<xrdMeasurement measurementType="Scan" status="Completed" sampleMode="Reflection">
		<usedWavelength intended="K-Alpha 1">
			<kAlpha1 unit="Angstrom">1.5405980</kAlpha1>
			<kAlpha2 unit="Angstrom">1.5444260</kAlpha2>
			<kBeta unit="Angstrom">1.3922500</kBeta>
			<ratioKAlpha2KAlpha1>0.5000</ratioKAlpha2KAlpha1>
		</usedWavelength>
		<incidentBeamPath>
			<radius unit="mm">145.00</radius>
			<xRayTube id="1010048" name="Empyrean Cu LFF HR (9430 033 7310x) DK437873">
				<tension unit="kV">40.0</tension>
				<current unit="mA">15.0</current>
				<anodeMaterial>Cu</anodeMaterial>
				<focus type="Line">
					<length unit="mm">12.0</length>
					<width unit="mm">0.4</width>
					<takeOffAngle unit="deg">6.0</takeOffAngle>
				</focus>
			</xRayTube>
			<filter id="20010004" name="Beta-filter Nickel">
				<material>Ni</material>
				<thickness unit="mm">0.020</thickness>
			</filter>
			<sollerSlit id="21010002" name="Soller slits 0.04 rad.">
				<opening unit="rad">0.0400</opening>
			</sollerSlit>
			<mask id="22031000" name="Fixed mask 13 mm">
				<width unit="mm">9.00</width>
			</mask>
			<divergenceSlit id="22120001" name="Divergence slit 1°" xsi:type="fixedDivergenceSlitType">
				<distanceToSample unit="mm">50.00</distanceToSample>
				<height unit="mm">1.52</height>
			</divergenceSlit>
		</incidentBeamPath>
		<beamKnife id="29030100" name="Beam knife low"/>
		<sampleMovement xsi:type="spinningSampleMovementType">
			<spinnerRevolutionTime unit="seconds">1.0</spinnerRevolutionTime>
		</sampleMovement>
		<diffractedBeamPath>
			<radius unit="mm">145.00</radius>
			<antiScatterSlit id="22090040" name="AS slit 9 mm" xsi:type="fixedAntiScatterSlitType">
				<height unit="mm">9.00</height>
			</antiScatterSlit>
			<sollerSlit id="21020003" name="Large Soller slits 0.04 rad.">
				<opening unit="rad">0.0400</opening>
			</sollerSlit>
			<filter id="20030001" name="Large beta-filter Nickel">
				<material>Ni</material>
				<thickness unit="mm">0.020</thickness>
			</filter>
			<detector id="7010019" name="PIXcel1D-Medipix3 detector" xsi:type="rtmsDetectorType">
				<phd unit="keV">
					<lowerLevel>4.0</lowerLevel>
					<upperLevel>11.3</upperLevel>
				</phd>
				<mode>Scanning</mode>
				<activeLength unit="deg">1.021</activeLength>
			</detector>
		</diffractedBeamPath>
		<scan appendNumber="0" mode="Continuous" scanAxis="Gonio" status="Completed">
			<header>
				<startTimeStamp>2024-03-24T15:18:17-07:00</startTimeStamp>
				<endTimeStamp>2024-03-24T15:20:39-07:00</endTimeStamp>
				<author>
					<name>AutomatedUser</name>
				</author>
				<source>
					<applicationSoftware version="1.6 (94)">PANalytical Aeris Instrument Suite</applicationSoftware>
					<instrumentControlSoftware version="3.0.0 20211014">AERIS</instrumentControlSoftware>
					<instrumentID>2879380</instrumentID>
				</source>
			</header>
			<dataPoints>
				<positions axis="2Theta" unit="deg">
					<startPosition>10.02173288</startPosition>
					<endPosition>139.98435528</endPosition>
				</positions>
				<positions axis="Omega" unit="deg">
					<startPosition>5.01086644</startPosition>
					<endPosition>69.99217764</endPosition>
				</positions>
				<commonCountingTime unit="seconds">1.551</commonCountingTime>
				<counts unit="counts">733 709 763 784 813 781 733 762 796 809 715 759 708 756 740 724 764 759 746 750 771 748 756 780 740 744 765 742 764 773 735 755 808 764 782 736 764 787 753 759 799 807 763 724 730 730 742 788 719 761 764 756 725 737 777 709 744 767 724 745 701 694 742 741 756 776 762 760 744 790 734 768 751 775 767 801 749 741 705 767 757 726 691 703 761 726 704 761 791 739 762 752 739 720 741 729 744 722 721 761 770 754 801 751 687 756 755 734 771 718 735 739 748 731 747 772 742 794 747 805 900 945 945 813 814 733 751 751 738 772 741 768 711 714 732 730 747 747 737 745 764 764 740 758 745 756 712 739 746 735 750 765 674 679 792 756 768 715 756 792 768 771 758 702 768 775 726 709 762 741 686 736 735 697 725 736 720 722 754 757 693 737 772 728 756 785 726 775 746 750 756 820 874 793 828 945 964 1226 1410 2197 3439 5571 6578 4276 1756 922 864 832 808 824 772 792 745 771 735 730 703 727 750 817 716 785 789 817 770 834 822 814 881 961 999 1196 1405 1293 1124 957 882 833 782 780 812 796 780 777 812 836 750 779 776 745 741 721 756 763 789 790 695 743 760 779 798 779 848 898 870 960 838 792 749 729 688 747 749 720 727 729 742 770 771 806 717 754 700 714 743 766 693 743 727 709 701 735 749 719 727 732 727 697 726 722 710 728 687 711 711 718 747 706 686 736 732 726 697 728 715 764 688 686 657 687 711 752 732 680 714 715 707 702 700 675 703 689 735 720 678 686 639 721 724 677 697 680 675 738 717 688 695 704 702 663 699 705 688 722 705 706 699 659 694 787 784 760 808 963 1104 1018 903 793 804 697 692 717 723 643 657 655 738 708 751 693 623 687 681 688 723 732 719 716 720 685 695 683 679 707 670 674 688 766 694 737 674 652 733 682 706 649 658 653 662 711 690 633 717 662 670 716 665 696 693 645 604 732 691 692 663 721 673 680 692 704 702 631 656 683 755 680 695 703 649 687 689 653 705 698 680 633 641 684 677 633 694 680 676 723 705 689 683 757 730 743 703 771 712 700 731 670 659 661 694 738 734 780 835 933 982 923 780 750 682 696 676 680 624 640 670 656 684 743 730 731 698 651 684 707 678 677 673 614 684 698 703 723 711 780 776 826 737 728 692 692 673 667 685 665 681 627 693 690 682 700 659 735 700 735 768 718 715 723 721 699 682 693 686 636 650 667 634 739 674 676 623 687 711 708 660 709 767 791 845 766 811 744 697 694 665 702 666 639 728 713 681 720 761 765 738 755 744 696 704 578 678 681 649 657 638 671 686 695 677 639 695 689 717 673 659 603 642 679 653 665 650 634 658 690 673 645 672 641 670 674 642 654 633 653 612 604 679 704 668 668 645 654 635 666 711 710 848 894 893 831 776 748 651 659 646 606 618 672 687 676 667 682 667 643 638 630 620 700 715 777 943 854 746 693 694 679 654 678 676 702 673 654 664 685 750 812 818 754 665 633 649 673 683 605 644 681 645 660 618 644 670 665 689 678 636 624 697 633 632 658 665 630 673 639 617 660 653 617 599 633 664 629 612 623 637 649 644 673 622 608 655 654 672 697 657 692 670 687 609 634 667 679 655 678 680 672 576 659 655 671 677 616 668 690 685 657 671 663 613 607 603 668 599 651 629 631 652 579 635 677 633 616 590 669 624 662 585 680 613 630 609 623 580 605 649 660 646 627 649 660 640 636 665 673 614 642 586 618 617 639 619 677 606 583 610 653 621 605 588 615 598 647 625 581 606 663 669 617 638 633 683 699 971 1163 1114 999 971 860 772 746 687 683 645 651 664 639 657 626 676 650 645 637 647 655 598 653 588 646 636 598 619 657 646 644 651 643 677 677 572 642 628 653 630 613 606 605 684 650 628 644 692 719 661 646 654 647 654 726 646 585 651 685 651 648 628 641 632 703 663 606 626 608 710 643 637 625 665 634 622 652 604 653 652 667 659 715 698 631 696 701 659 640 586 619 624 682 678 678 726 689 665 676 675 635 688 636 611 655 642 625 598 612 603 610 620 644 626 617 619 597 653 630 632 640 636 612 629 620 619 583 653 642 626 647 661 651 644 709 706 727 711 671 677 680 668 644 675 627 620 635 627 639 638 613 691 710 685 619 657 612 687 604 617 651 637 674 710 650 643 631 616 602 627 618 599 621 614 613 638 610 604 623 646 587 618 560 595 647 601 652 602 609 636 639 644 569 619 626 629 612 612 585 568 570 588 584 634 664 628 632 586 668 619 605 569 596 642 623 632 613 649 602 602 610 651 656 622 592 602 586 614 598 625 620 610 638 645 643 690 680 635 640 633 605 630 654 584 652 574 590 574 703 578 587 622 587 600 604 624 620 672 603 639 643 649 588 588 667 619 626 606 657 610 659 631 621 618 671 638 614 634 641 623 611 612 579 618 651 625 643 640 611 642 590 618 620 606 610 677 614 600 593 686 635 636 609 634 608 631 638 636 608 658 682 671 665 729 706 637 648 722 650 643 633 648 652 691 803 699 626 659 639 630 652 699 598 658 609 633 581 633 600 617 591 600 595 597 635 631 619 602 650 610 636 651 628 627 652 649 700 621 655 658 662 631 592 629 629 601 624 656 621 597 607 613 634 623 655 639 614 684 631 694 656 657 627 622 617 666 697 655 656 604 653 595 604 599 594 602 664 605 660 601 549 610 626 603 639 605 606 614 620 570 616 600 574 596 612 632 605 634 712 602 649 628 669 664 612 629 652 660 626 618 605 622 598 614 589 665 590 605 623 586 595 627 603 586 566 575 623 589 595 586 608 592 637 648 683 776 741 691 662 685 682 636 619 604 639 644 605 625 600 665 647 628 655 634 722 683 665 636 693 628 627 594 613 622 666 619 556 608 609 619 664 638 549 618 649 631 651 610 590 631 608 629 600 593 613 546 654 646 608 649 628 616 630 624 610 580 645 594 650 579 660 609 568 613 591 624 589 593 643 591 593 671 575 638 626 624 609 639 587 611 598 632 589 636 594 604 564 570 623 622 715 682 618 640 596 654 695 632 580 598 600 650 622 637 615 634 625 617 629 576 615 564 603 584 611 589 645 622 606 616 560 609 601 621 594 603 600 559 602 589 603 607 595 619 626 585 567 600 652 644 607 565 632 582 602 591 588 614 619 637 674 575 629 604 643 631 628 633 655 642 622 581 584 618 612 610 601 614 560 547 608 601 592 586 631 558 624 657 610 638 595 539 625 618 543 564 632 609 586 598 612 631 562 551 628 577 624 656 612 672 612 624 647 614 664 636 623 577 625 593 619 604 585 625 629 617 575 579 566 560 603 593 575 613 606 609 583 582 578 602 580 613 603 618 578 653 635 607 627 591 608 625 570 593 575 601 629 632 634 607 603 593 641 582 571 620 598 581 572 580 620 592 637 621 641 594 594 602 604 630 617 584 628 610 621 602 558 583 595 588 591 607 620 614 617 551 637 632 620 627 577 601 643 597 616 684 620 638 677 570 643 596 586 616 673 635 629 636 614 620 635 584 607 633 591 604 611 614 578 593 607 603 641 646 601 613 613 556 615 599 621 641 581 587 558 584 617 609 590 556 638 596 583 570 620 605 637 578 611 592 607 606 592 597 603 534 594 628 579 605 591 628 614 608 637 618 622 672 600 583 566 575 640 631 661 655 650 559 617 631 692 607 594 629 602 595 593 602 635 600 571 599 620 592 547 608 630 599 581 582 566 584 593 659 595 632 593 619 584 636 628 653 620 648 652 617 647 607 602 620 574 585 595 594 620 566 579 562 575 576 566 627 578 636 581 596 581 634 541 586 598 626 547 623 591 623 575 622 605 580 572 621 617 677 643 638 583 601 603 589 563 585 592 589 630 538 595 558 579 605 571 595 593 576 618 622 640 593 598 603 616 560 596 554 599 545 578 608 609 601 614 587 561 597 629 561 580 565 573 613 612 637 587 546 596 579 579 599 618 645 592 630 592 590 593 643 614 584 541 614 603 627 629 567 583 591 605 596 599 632 596 605 617 593 613 589 654 600 577 618 593 598 605 617 619 630 576 595 598 608 596 584 624 608 588 602 589 607 591 583 623 594 598 595 596 603 605 585 599 608 595 647 583 547 610 600 558 600 615 557 565 604 558 586 621 639 625 623 587 569 612 601 567 624 582 593 570 614 597 636 603 600 556 584 602 603 606 600 635 561 636 614 570 603 611 626 558 613 595 593 575 596 591 552 552 627 609 616 624 568 624 596 609 603 578 578 611 620 610 606 563 582 589 590 624 567 567 621 549 597 572 602 570 597 558 620 544 602 626 617 596 646 624 594 560 607 591 615 635 599 614 631 613 576 631 578 623 611 609 601 584 633 634 597 602 572 624 585 586 572 605 617 572 578 598 583 610 572 585 582 569 585 572 598 581 546 580 590 625 579 565 561 531 606 613 559 563 569 583 581 589 585 597 551 576 586 575 587 587 590 590 578 597 604 557 598 588 605 572 584 609 583 614 582 614 605 577 565 571 611 542 560 561 630 576 613 601 608 578 621 588 547 609 563 600 573 522 563 578 604 629 590 644 620 590 620 645 630 619 601 614 620 636 604 574 601 626 580 647 593 602 588 598 578 563 609 571 639 593 576 571 588 596 631 580 572 593 576 561 596 589 579 598 571 549 560 593 580 606 579 596 544 601 585 592 628 602 591 567 556 628 585 662 548 567 600 619 579 648 575 625 643 570 592 593 611 605 617 588 603 580 652 600 570 609 590 593 603 652 583 580 659 617 650 599 587 582 583 585 586 574 580 622 637 584 640 593 574 598 594 592 598 581 611 543 586 629 550 642 598 573 571 594 629 591 588 632 597 602 585 622 564 575 554 608 566 566 564 578 585 578 609 615 586 618 620 601 569 602 576 637 611 614 555 613 590 591 560 582 578 581 592 609 550 561 567 647 603 548 573 616 554 596 527 573 562 606 565 629 607 559 563 608 576 574 541 572 612 565 606 568 554 585 583 647 575 567 583 582 649 576 582 563 637 646 600 593 601 589 620 618 578 586 588 586 589 593 590 530 580 566 598 584 602 579 580 634 591 629 607 560 596 614 588 618 608 587 611 591 608 611 588 629 615 641 598 547 560 590 597 690 611 631 603 575 616 617 634 590 602 567 584 606 586 642 591 606 574 571 610 620 607 590 626 601 625 588 563 636 530 635 592 568 604 575 604 636 591 651 594 619 584 594 565 625 582 562 601 596 656 589 625 640 591 610 565 612 623 600 600 610 606 645 596 590 579 652 620 604 619 610 605 567 622 625 590 610 533 569 574 589 589 581 628 591 551 570 606 627 558 585 615 600 591 581 607 578 597 606 632 561 585 581 598 585 593 590 630 639 605 601 576 592 632 563 632 578 608 632 608 591 558 597 561 599 553 594 562 603 567 569 586 565 597 596 634 551 544 598 577 605 594 604 576 617 604 567 616 608 628 627 618 607 628 618 606 598 572 631 595 644 600 609 598 626 577 568 592 576 603 583 571 586 571 592 593 573 575 584 617 604 588 577 595 601 622 566 598 592 632 602 623 637 653 594 576 573 620 634 591 579 590 589 615 620 623 631 599 597 576 580 583 564 631 582 573 575 588 609 631 586 582 587 585 581 616 591 611 612 611 627 619 611 589 557 546 567 620 581 574 601 606 583 610 589 597 582 541 550 622 571 593 590 620 594 613 555 602 607 580 601 624 579 594 591 616 625 595 604 565 585 614 606 623 617 653 586 637 593 596 574 613 591 653 596 583 624 601 577 576 614 582 591 637 603 578 575 635 560 596 562 545 599 554 575 623 605 585 613 583 610 581 621 612 589 598 565 562 596 587 577 612 582 623 591 585 569 613 609 602 586 612 648 564 580 572 609 603 638 572 588 585 558 589 533 604 612 599 586 612 605 556 566 570 600 572 577 631 590 614 562 573 579 592 616 564 564 583 602 602 595 557 606 590 613 620 597 544 615 621 581 590 590 576 603 555 601 577 554 596 623 553 609 593 591 601 599 565 566 602 567 586 563 618 564 588 597 609 594 607 614 595 594 608 619 614 615 630 605 637 638 597 575 613 617 618 530 604 620 590 575 614 621 589 639 575 605 605 621 592 577 577 593 576 626 626 555 596 634 594 619 595 622 591 586 569 548 635 578 613 598 579 595 583 575 619 562 626 603 631 563 598 593 593 569 609 563 634 596 602 586 591 587 598 608 625 582 609 569 614 573 620 576 621 608 582 631 570 587 596 576 620 597 594 599 576 655 611 614 598 612 630 615 654 640 575 625 569 603 626 632 599 593 551 582 554 582 605 615 603 603 580 611 583 587 576 595 581 606 622 597 577 602 631 590 593 622 555 623 593 593 591 580 621 614 585 583 595 619 633 630 612 622 640 632 603 561 626 637 585 562 583 596 596 670 600 608 604 581 657 649 589 609 606 638 582 601 654 591 559 636 566 579 640 570 600 621 601 615 681 619 653 617 582 649 631 602 630 633 574 608 641 635 598 694 624 608 625 583 565 629 611 594 566 582 598 675 605 591 584 613 576 602 608 628 537 613 610 674 613 637 619 606 584 687 663 608 624 624 614 579 615 605 563 591 621 598 610 586 642 616 615 600 575 618 565 606 621 612 573 572 637 559 559 637 592 559 615 605 602 618 589 565 592 622 588 600 580 615 591 555 655 579 625 622 644 596 606 576 644 605 623 632 587 618 634 599 560 585 591 599 600 638 566 559 628 620 611</counts>
			</dataPoints>
		</scan>
	</xrdMeasurement>
</xrdMeasurements>