File: dataset/precursor_mixture/NaAlO2-1.5H2O_In2O3_Ga2O3_Bi2O3-beta.2-min.xrdml
<?xml version="1.0"?>
<xrdMeasurements xmlns="http://www.xrdml.com/XRDMeasurement/2.2" xmlns:xsi="http://www.w3.org/2001/XMLSchema-instance" xsi:schemaLocation="http://www.xrdml.com/XRDMeasurement/2.2 http://www.xrdml.com/XRDMeasurement/2.2/XRDMeasurement.xsd" status="Completed" recordIdentifier="{D8E2B722-3EC2-4CC9-8023-94D49B82AD95}">
	<comment>
		<entry/>
	</comment>
	<sample type="To be analyzed">
		<id>dara-43-1</id>
		<name></name>
		<preparedBy></preparedBy>
	</sample>
	<xrdMeasurement measurementType="Scan" status="Completed" sampleMode="Reflection">
		<usedWavelength intended="K-Alpha 1">
			<kAlpha1 unit="Angstrom">1.5405980</kAlpha1>
			<kAlpha2 unit="Angstrom">1.5444260</kAlpha2>
			<kBeta unit="Angstrom">1.3922500</kBeta>
			<ratioKAlpha2KAlpha1>0.5000</ratioKAlpha2KAlpha1>
		</usedWavelength>
		<incidentBeamPath>
			<radius unit="mm">145.00</radius>
			<xRayTube id="1010048" name="Empyrean Cu LFF HR (9430 033 7310x) DK430614">
				<tension unit="kV">40.0</tension>
				<current unit="mA">15.0</current>
				<anodeMaterial>Cu</anodeMaterial>
				<focus type="Line">
					<length unit="mm">12.0</length>
					<width unit="mm">0.4</width>
					<takeOffAngle unit="deg">6.0</takeOffAngle>
				</focus>
			</xRayTube>
			<filter id="20010004" name="Beta-filter Nickel">
				<material>Ni</material>
				<thickness unit="mm">0.020</thickness>
			</filter>
			<sollerSlit id="21010002" name="Soller slits 0.04 rad.">
				<opening unit="rad">0.0400</opening>
			</sollerSlit>
			<mask id="22031000" name="Fixed mask 13 mm">
				<width unit="mm">9.00</width>
			</mask>
			<divergenceSlit id="22120001" name="Divergence slit 1°" xsi:type="fixedDivergenceSlitType">
				<distanceToSample unit="mm">50.00</distanceToSample>
				<height unit="mm">1.52</height>
			</divergenceSlit>
		</incidentBeamPath>
		<beamKnife id="29030100" name="Beam knife low"/>
		<sampleMovement xsi:type="spinningSampleMovementType">
			<spinnerRevolutionTime unit="seconds">1.0</spinnerRevolutionTime>
		</sampleMovement>
		<diffractedBeamPath>
			<radius unit="mm">145.00</radius>
			<antiScatterSlit id="22090040" name="AS slit 9 mm" xsi:type="fixedAntiScatterSlitType">
				<height unit="mm">9.00</height>
			</antiScatterSlit>
			<sollerSlit id="21020003" name="Large Soller slits 0.04 rad.">
				<opening unit="rad">0.0400</opening>
			</sollerSlit>
			<filter id="20030001" name="Large beta-filter Nickel">
				<material>Ni</material>
				<thickness unit="mm">0.020</thickness>
			</filter>
			<detector id="7010019" name="PIXcel1D-Medipix3 detector" xsi:type="rtmsDetectorType">
				<phd unit="keV">
					<lowerLevel>4.0</lowerLevel>
					<upperLevel>11.3</upperLevel>
				</phd>
				<mode>Scanning</mode>
				<activeLength unit="deg">1.021</activeLength>
			</detector>
		</diffractedBeamPath>
		<scan appendNumber="0" mode="Continuous" scanAxis="Gonio" status="Completed">
			<header>
				<startTimeStamp>2024-02-18T15:36:56-08:00</startTimeStamp>
				<endTimeStamp>2024-02-18T15:39:18-08:00</endTimeStamp>
				<author>
					<name>AutomatedUser</name>
				</author>
				<source>
					<applicationSoftware version="1.4b (28)">PANalytical Aeris Instrument Suite</applicationSoftware>
					<instrumentControlSoftware version="2.0.0 20210224">AERIS</instrumentControlSoftware>
					<instrumentID>950485</instrumentID>
				</source>
			</header>
			<dataPoints>
				<positions axis="2Theta" unit="deg">
					<startPosition>10.02173288</startPosition>
					<endPosition>139.98435528</endPosition>
				</positions>
				<positions axis="Omega" unit="deg">
					<startPosition>5.01086644</startPosition>
					<endPosition>69.99217764</endPosition>
				</positions>
				<commonCountingTime unit="seconds">1.551</commonCountingTime>
				<counts unit="counts">342 343 325 351 347 341 363 314 347 362 328 339 329 331 334 325 332 330 317 307 308 350 288 307 331 318 327 327 305 300 285 270 270 293 313 264 261 289 277 284 277 258 299 285 257 266 288 293 261 262 257 295 273 276 292 276 266 255 272 253 268 245 246 275 241 243 270 247 227 274 262 255 245 274 250 242 231 242 232 233 234 235 237 263 231 221 213 205 273 241 216 248 223 214 245 229 207 221 229 214 205 195 197 214 221 227 210 227 209 197 209 219 222 219 200 189 198 210 203 192 192 227 200 207 196 212 209 204 197 211 208 229 207 208 202 203 202 179 216 238 195 203 225 233 200 201 196 227 241 269 256 212 172 196 207 223 181 197 162 186 190 199 158 168 199 178 201 180 176 157 186 182 176 151 158 182 182 171 154 158 168 196 184 170 155 180 157 160 173 160 160 173 188 197 184 192 202 188 217 264 280 320 361 272 229 204 187 157 157 175 157 157 167 162 178 181 141 151 163 150 139 126 173 160 157 152 144 152 143 129 141 167 153 156 163 171 186 144 163 166 152 157 160 184 139 145 130 162 126 126 145 168 150 153 195 178 192 233 276 456 435 282 185 159 166 171 136 156 136 135 140 136 140 125 127 120 113 146 109 127 122 117 115 111 134 116 116 144 150 137 125 133 150 140 139 137 132 135 144 162 167 118 106 131 87 125 126 121 134 93 112 142 125 123 139 122 100 143 137 119 144 112 133 119 152 133 123 117 118 126 114 129 122 112 138 121 129 109 131 119 142 121 132 119 119 155 120 139 138 121 121 157 152 172 218 210 208 142 138 119 143 147 130 147 136 133 97 118 105 109 130 111 138 124 120 117 142 125 168 139 114 145 141 127 148 144 119 146 197 184 188 199 177 232 242 225 225 244 266 313 436 683 1122 2102 3569 4346 3185 1892 767 384 314 267 236 188 164 181 167 138 137 144 130 115 115 118 116 126 113 123 121 129 130 141 151 124 159 145 138 152 169 145 132 137 159 166 154 168 198 208 234 244 267 331 400 384 389 469 511 626 712 874 911 1202 1599 2645 3329 2522 1697 836 425 344 299 285 246 230 232 183 199 223 210 221 246 264 257 319 360 380 459 673 747 916 1188 1173 895 661 440 276 289 225 240 211 172 156 179 164 145 155 201 223 307 450 721 1179 1189 841 585 301 253 165 167 182 209 215 225 206 218 156 196 187 178 181 169 189 216 171 133 128 125 133 125 115 141 143 147 136 135 126 96 129 158 154 134 112 111 106 136 123 126 145 127 135 156 198 200 256 262 304 296 308 314 330 320 356 503 777 901 603 520 315 192 185 180 172 162 126 100 110 83 96 98 106 111 108 112 93 80 82 122 99 137 95 103 93 100 99 75 73 109 94 113 94 93 127 110 133 142 146 160 156 146 161 129 165 175 210 257 178 181 157 112 116 111 116 118 135 127 120 138 167 188 202 204 204 186 179 128 119 116 128 161 123 131 75 103 106 132 132 119 108 75 87 78 74 104 85 92 99 89 82 79 104 82 117 130 95 96 75 83 102 85 84 82 88 73 64 70 105 74 72 95 78 63 85 65 77 59 77 77 77 74 66 84 78 71 104 96 147 113 117 110 64 103 105 100 106 109 105 140 211 198 155 172 119 108 106 102 86 86 67 91 71 71 70 78 104 93 106 96 93 91 85 90 82 103 94 80 98 93 95 91 90 86 87 54 72 95 77 75 59 68 66 73 111 92 95 84 83 73 82 74 73 84 78 72 78 81 61 97 114 62 81 66 89 89 88 73 103 84 104 75 81 96 107 126 114 106 119 131 94 93 104 110 124 184 299 326 266 256 211 190 164 137 181 199 259 449 796 1148 815 654 562 357 244 170 143 149 144 111 144 151 216 336 535 447 339 329 250 142 105 107 105 75 76 95 76 84 95 80 76 68 69 67 84 60 57 59 74 85 76 93 83 96 92 98 96 139 141 136 160 132 159 161 149 134 130 119 95 78 85 87 62 76 72 76 81 113 129 142 103 124 110 98 103 86 92 106 90 65 89 93 88 97 86 75 79 75 91 65 84 73 69 83 82 85 87 114 87 98 89 118 149 139 215 375 774 1011 624 501 631 395 245 184 149 136 120 110 84 65 73 77 77 66 74 68 73 59 103 77 78 88 94 88 59 76 79 81 92 99 65 80 73 103 129 129 118 99 111 97 82 102 72 88 59 65 63 76 80 76 80 65 63 76 93 104 90 85 107 93 90 82 93 84 106 112 105 131 207 370 637 531 345 368 337 209 139 123 96 111 94 107 79 100 83 93 122 103 118 128 120 143 138 140 198 291 543 969 824 564 587 568 385 230 189 141 139 148 196 191 145 137 148 95 81 110 86 89 63 60 58 51 76 76 65 77 78 76 68 67 66 66 58 90 77 96 71 84 113 134 114 128 128 205 210 197 214 312 533 434 299 254 326 236 140 136 117 95 74 82 69 88 85 75 77 81 71 96 98 78 68 81 77 99 91 98 146 151 223 286 222 171 160 163 117 111 83 99 87 90 81 129 104 83 103 125 116 83 104 107 100 100 96 115 94 104 137 107 134 161 147 192 297 553 712 442 311 428 368 248 168 141 151 110 109 115 103 80 83 91 78 75 83 83 81 68 78 93 64 91 90 83 89 102 99 109 133 205 203 165 187 156 163 122 120 101 99 85 107 108 97 96 93 91 94 71 80 90 92 68 69 65 75 61 73 90 73 68 79 85 140 204 164 109 138 134 114 133 113 116 147 126 125 136 106 118 144 130 122 138 155 178 167 164 171 189 157 151 150 142 118 114 113 93 116 109 117 83 80 90 74 58 58 58 64 65 43 65 74 67 60 63 72 69 56 87 71 89 73 64 71 112 128 91 91 65 121 127 76 73 78 74 85 83 53 96 71 67 77 61 69 59 55 73 40 55 57 63 53 62 69 56 74 64 57 51 75 87 116 119 105 82 82 89 96 95 68 84 97 135 126 112 118 110 111 120 109 86 77 97 77 79 84 97 108 103 109 84 79 99 83 140 118 110 90 94 96 87 69 75 62 74 88 69 65 80 63 57 94 81 83 55 74 75 64 69 65 67 75 72 70 63 70 61 81 79 95 78 66 77 74 73 55 54 50 40 66 70 65 56 48 68 45 62 66 51 63 62 72 66 59 68 50 70 53 62 62 84 105 71 77 85 63 81 83 76 74 77 66 63 69 65 69 61 45 73 57 53 64 67 65 53 47 76 81 83 95 96 89 74 100 115 87 103 85 75 70 101 72 78 92 87 114 163 209 333 323 192 178 202 213 174 143 114 82 106 121 158 136 99 101 104 113 94 74 99 98 123 188 184 135 117 101 146 136 134 135 154 184 151 119 99 121 130 125 111 107 136 117 106 86 72 99 127 127 96 93 71 70 59 93 66 67 74 70 74 60 63 78 55 93 109 149 161 135 134 116 153 157 139 109 133 112 139 188 154 122 95 102 109 61 85 68 81 69 65 67 54 58 63 50 45 57 62 60 63 86 74 82 101 74 72 71 77 73 84 75 55 48 57 48 44 51 46 60 45 60 53 60 46 63 76 68 54 54 83 81 93 63 94 73 70 70 67 67 66 57 66 44 64 59 46 45 61 61 48 58 81 89 58 69 67 60 69 67 73 71 72 97 105 135 122 77 79 79 107 97 73 73 55 62 67 62 68 42 56 55 56 55 71 63 53 53 55 57 60 62 72 78 165 228 162 109 127 96 115 117 109 81 85 72 86 48 59 68 59 71 52 57 64 71 74 74 54 46 60 76 69 81 82 64 56 68 49 58 74 70 79 72 67 60 47 93 108 107 156 142 88 99 96 93 109 97 88 80 74 88 97 120 159 189 165 118 98 94 93 111 100 96 90 106 88 83 85 88 104 95 136 208 206 140 110 98 110 135 142 112 90 73 63 85 78 72 51 80 72 80 72 68 71 48 35 77 63 65 49 47 57 68 62 65 47 47 69 52 63 64 48 74 72 81 58 42 51 79 59 56 78 54 71 55 78 63 67 73 58 48 81 55 71 56 60 54 67 60 61 82 65 66 96 96 86 83 51 76 84 102 74 54 62 67 63 53 64 78 74 60 58 65 67 73 73 92 97 120 126 89 90 77 87 115 100 91 101 95 76 80 82 79 67 77 56 72 68 65 59 46 52 41 60 69 57 44 43 52 69 78 91 106 103 104 85 76 80 82 95 116 113 147 101 81 59 83 68 73 110 77 78 71 91 64 69 77 56 81 79 70 95 102 137 172 152 118 108 93 112 103 120 115 95 90 85 80 77 64 67 61 85 64 72 77 59 66 60 76 83 75 70 98 93 105 85 93 84 102 91 106 72 77 82 73 62 69 61 76 68 74 61 60 67 64 70 59 71 70 72 93 90 123 129 133 87 94 80 86 88 129 99 93 64 79 76 60 58 54 68 48 46 46 56 46 56 52 60 59 67 60 55 90 80 98 84 90 65 65 70 69 72 57 63 47 69 58 42 63 54 58 75 52 73 56 70 61 64 46 37 65 56 76 74 85 76 71 79 66 75 59 76 57 71 55 60 59 73 59 59 50 52 51 40 55 54 51 49 50 65 49 62 41 62 59 62 61 84 63 66 57 69 62 67 61 61 48 76 58 67 65 67 54 52 62 63 75 55 60 54 58 76 96 90 136 123 103 88 98 75 81 78 113 104 85 84 80 70 72 75 77 65 71 58 74 59 59 68 48 60 51 47 57 76 74 80 84 82 96 91 127 109 111 104 77 61 73 68 75 96 85 76 72 65 65 70 66 59 56 65 50 63 65 74 95 127 144 128 80 68 79 68 77 75 92 70 75 74 57 71 65 63 74 64 56 61 84 82 55 82 88 70 58 84 99 100 101 129 98 77 71 73 80 74 73 71 77 89 72 59 73 48 74 63 80 76 44 60 58 64 69 54 81 75 61 83 67 69 56 45 66 45 59 75 61 74 68 58 65 54 88 59 71 53 48 71 63 47 58 70 62 51 61 62 67 64 63 69 82 97 86 84 98 107 93 93 88 84 108 72 105 130 120 129 178 141 125 117 112 95 78 82 84 115 123 91 97 76 88 94 95 125 116 106 79 89 85 76 86 91 85 104 99 74 84 77 93 95 97 80 86 82 87 74 99 76 79 83 99 112 128 139 115 125 109 115 103 80 69 84 113 102 106 106 85 83 80 70 76 91 80 84 87 94 126 128 124 123 92 95 93 89 105 110 153 218 195 149 122 127 90 74 97 110 115 122 122 91 61 65 64 78 58 76 70 52 56 85 54 61 73 74 64 67 74 68 92 91 83 96 89 104 93 100 82 79 80 78 78 95 80 84 82 96 80 94 71 59 87 78 80 71 93 85 60 84 77 62 78 85 83 76 79 86 70 82 73 58 61 75 74 67 87 65 59 73 66 74 55 52 62 60 71 73 87 58 71 59 73 71 59 58 72 82 97 85 90 68 69 62 60 63 59 72 76 67 65 73 62 79 60 74 61 76 48 68 76 65 72 66 52 59 66 64 68 80 66 74 79 79 70 73 89 64 71 68 99 82 76 79 85 72 73 84 63 88 47 71 70 78 65 70 67 70 66 81 78 70 94 77 90 101 81 90 85 72 76 79 91 76 63 66 70 87 78 79 70 70 67 63 72 77 75 49 51 81 60 58 63 95 60 70 76 77 72 63 70 79 66 86 62 75 51 62 63 61 73 44 66 69 66 63 67 57 66 55 68 57 62 56 59 56 69 63 73 59 81 70 58 56 65 77 86 88 94 79 77 76 64 67 79 64 62 65 66 78 77 83 68 75 76 52 50 66 76 63 79 66 65 74 61 75 70 69 72 93 93 103 83 119 83 73 73 60 60 73 85 102 96 75 100 96 110 100 68 75 73 86 80 74 90 68 84 108 81 93 89 75 84 72 85 73 75 84 76 84 108 117 90 63 99 94 97 95 75 88 75 83 89 78 96 80 84 85 77 80 79 82 80 69 59 49 61 62 74 63 66 69 77 75 93 108 99 120 129 125 124 126 93 80 73 77 95 77 81 98 86 82 100 87 81 79 67 71 68 62 68 68 72 47 54 65 74 61 70 80 70 60 69 76 64 68 61 70 93 84 80 91 83 101 93 76 85 78 64 67 86 74 72 79 80 78 74 67 60 84 88 82 82 70 84 72 94 94 86 116 115 95 96 95 111 109 114 121 102 76 81 82 93 76 109 94 91 86 66 75 70 113 68 80 82 96 89 95 93 102 95 126 112 116 113 92 89 89 102 99 79 104 101 92 119 93 118 123 130 118 126 112 90 72 80 89 117 92 74 76 111 98 113 93 106 93 91 79 76 90 73 74 93 68 71 63 66 82 90 58 84 84 80 115 81 95 86 89 91 96 106 98 90 75 69 82 79 96 98 84 90 82 102 92 99 103 92 69 93 85 107 88 96 104 78 103 87 109 87 87 99 94 97 115 106 111 105 109 85 103 109 72 117 108 91 114 83 98 96 94 84 97 79 75 91 101 84 89 72 85 98 93 90 62 114 77 67 62 71 73 67 69 84 69 85 82 82 86 75 78 52 68 91 64 81 69 95 127 118 105 97 97 78 73 83 76 84 76 96 84 76 87 84 75 92 85 77 82 88 117 97 86 80 81 74 84 79 88 62 71 71 102 72 88 106 87 72 91 93 75 63 75 83 67 57 81 84 69 73 75 78 88 82 77 72 83 81 87 67 85 66 78 76 84 91 90 97 84 89 82 87 94</counts>
			</dataPoints>
		</scan>
	</xrdMeasurement>
</xrdMeasurements>