File: dataset/precursor_mixture/NaAlO2-1.5H2O_V2O5_LiCoO2.12-min.xrdml
<?xml version="1.0"?>
<xrdMeasurements xmlns="http://www.xrdml.com/XRDMeasurement/2.2" xmlns:xsi="http://www.w3.org/2001/XMLSchema-instance" xsi:schemaLocation="http://www.xrdml.com/XRDMeasurement/2.2 http://www.xrdml.com/XRDMeasurement/2.2/XRDMeasurement.xsd" status="Completed" recordIdentifier="{23079AC1-C57B-4951-AC00-AC0EB62B979E}">
	<comment>
		<entry/>
	</comment>
	<sample type="To be analyzed">
		<id>dara-6-2</id>
		<name></name>
		<preparedBy></preparedBy>
	</sample>
	<xrdMeasurement measurementType="Scan" status="Completed" sampleMode="Reflection">
		<usedWavelength intended="K-Alpha 1">
			<kAlpha1 unit="Angstrom">1.5405980</kAlpha1>
			<kAlpha2 unit="Angstrom">1.5444260</kAlpha2>
			<kBeta unit="Angstrom">1.3922500</kBeta>
			<ratioKAlpha2KAlpha1>0.5000</ratioKAlpha2KAlpha1>
		</usedWavelength>
		<incidentBeamPath>
			<radius unit="mm">145.00</radius>
			<xRayTube id="1010048" name="Empyrean Cu LFF HR (9430 033 7310x) DK437873">
				<tension unit="kV">40.0</tension>
				<current unit="mA">15.0</current>
				<anodeMaterial>Cu</anodeMaterial>
				<focus type="Line">
					<length unit="mm">12.0</length>
					<width unit="mm">0.4</width>
					<takeOffAngle unit="deg">6.0</takeOffAngle>
				</focus>
			</xRayTube>
			<filter id="20010004" name="Beta-filter Nickel">
				<material>Ni</material>
				<thickness unit="mm">0.020</thickness>
			</filter>
			<sollerSlit id="21010002" name="Soller slits 0.04 rad.">
				<opening unit="rad">0.0400</opening>
			</sollerSlit>
			<mask id="22031000" name="Fixed mask 13 mm">
				<width unit="mm">9.00</width>
			</mask>
			<divergenceSlit id="22120001" name="Divergence slit 1°" xsi:type="fixedDivergenceSlitType">
				<distanceToSample unit="mm">50.00</distanceToSample>
				<height unit="mm">1.52</height>
			</divergenceSlit>
		</incidentBeamPath>
		<beamKnife id="29030100" name="Beam knife low"/>
		<sampleMovement xsi:type="spinningSampleMovementType">
			<spinnerRevolutionTime unit="seconds">1.0</spinnerRevolutionTime>
		</sampleMovement>
		<diffractedBeamPath>
			<radius unit="mm">145.00</radius>
			<antiScatterSlit id="22090040" name="AS slit 9 mm" xsi:type="fixedAntiScatterSlitType">
				<height unit="mm">9.00</height>
			</antiScatterSlit>
			<sollerSlit id="21020003" name="Large Soller slits 0.04 rad.">
				<opening unit="rad">0.0400</opening>
			</sollerSlit>
			<filter id="20030001" name="Large beta-filter Nickel">
				<material>Ni</material>
				<thickness unit="mm">0.020</thickness>
			</filter>
			<detector id="7010019" name="PIXcel1D-Medipix3 detector" xsi:type="rtmsDetectorType">
				<phd unit="keV">
					<lowerLevel>4.0</lowerLevel>
					<upperLevel>11.3</upperLevel>
				</phd>
				<mode>Scanning</mode>
				<activeLength unit="deg">5.020</activeLength>
			</detector>
		</diffractedBeamPath>
		<scan appendNumber="0" mode="Continuous" scanAxis="Gonio" status="Completed">
			<header>
				<startTimeStamp>2024-03-24T15:21:03-07:00</startTimeStamp>
				<endTimeStamp>2024-03-24T15:33:31-07:00</endTimeStamp>
				<author>
					<name>AutomatedUser</name>
				</author>
				<source>
					<applicationSoftware version="1.6 (94)">PANalytical Aeris Instrument Suite</applicationSoftware>
					<instrumentControlSoftware version="3.0.0 20211014">AERIS</instrumentControlSoftware>
					<instrumentID>2879380</instrumentID>
				</source>
			</header>
			<dataPoints>
				<positions axis="2Theta" unit="deg">
					<startPosition>9.99043322</startPosition>
					<endPosition>100.09495370</endPosition>
				</positions>
				<positions axis="Omega" unit="deg">
					<startPosition>4.99521661</startPosition>
					<endPosition>50.04747685</endPosition>
				</positions>
				<commonCountingTime unit="seconds">18.249</commonCountingTime>
				<counts unit="counts">8040 8213 8135 8061 7960 8137 7993 7965 8120 8186 7918 8060 8084 8115 8149 8206 8087 8136 8175 8122 8125 8063 8116 8028 8079 8149 8266 8109 8093 8035 8153 8225 8099 8090 8219 8165 8120 8113 7941 8147 8100 7988 7953 8095 8179 8053 8127 8076 8244 8094 8076 8184 8312 8216 8146 8082 8042 8147 8121 8135 8094 8195 8240 7985 8317 8332 8327 8064 8090 8147 8215 8270 8177 8255 8240 8103 8118 8048 8256 8214 8155 7966 8174 8300 8168 8229 8106 8143 8191 7918 8250 8162 8223 8217 8068 8052 8277 8232 8104 8209 8110 8148 8088 8044 8048 8046 8111 8317 8274 8191 8279 8225 8155 8101 8212 8335 8217 8328 8139 8177 8191 8019 8146 8287 8213 8259 8298 8309 8336 8310 8306 8192 8335 8077 8160 8210 8166 8275 8069 8233 8129 8145 8358 8146 8305 8162 8085 8190 8204 8230 7987 8236 8148 8158 8165 8181 8239 8335 8091 7924 8070 8238 8124 8124 8403 8267 8310 8202 8292 8137 8223 8359 8166 8215 8173 8179 8264 8254 8287 7963 8295 8189 8149 8225 8121 8323 8248 8353 8096 8068 8338 8267 8092 8348 8256 8174 8470 8365 8200 8009 8342 8174 8257 8235 8230 8154 8155 8274 8182 8362 8174 8066 8169 8196 8390 8172 8326 8305 8192 8254 8320 8213 8037 8294 8292 8334 8435 8262 8285 8030 8286 8249 8261 8290 8220 8339 8246 8163 8302 8423 8418 8131 8254 8305 8145 8373 8311 8410 8244 8158 8184 8238 8330 8333 8234 8485 8187 8185 8326 8165 8311 8235 8250 8400 8240 8324 8273 8143 8300 8414 8285 8273 8312 8202 8280 8310 8281 8378 8287 8190 8305 8139 8419 8461 8460 8247 8155 8410 8246 8337 8355 8364 8306 8251 8281 8297 8358 8209 8466 8263 8412 8298 8350 8243 8318 8281 8351 8240 8347 8318 8263 8269 8412 8362 8443 8457 8438 8430 8307 8292 8301 8207 8533 8325 8305 8402 8517 8360 8437 8256 8335 8201 8288 8193 8323 8272 8316 8296 8300 8444 8360 8310 8267 8317 8330 8379 8345 8312 8513 8331 8314 8391 8254 8494 8466 8469 8242 8522 8394 8290 8334 8237 8505 8270 8280 8313 8282 8414 8363 8285 8334 8481 8316 8313 8468 8348 8267 8335 8373 8292 8439 8290 8373 8454 8272 8485 8345 8295 8336 8268 8434 8256 8318 8346 8327 8402 8465 8424 8308 8416 8183 8465 8389 8418 8438 8310 8195 8480 8495 8241 8405 8378 8458 8457 8408 8529 8660 8335 8387 8355 8391 8544 8575 8577 8291 8329 8319 8391 8280 8458 8436 8395 8468 8478 8425 8452 8504 8326 8410 8505 8387 8469 8577 8297 8370 8342 8371 8425 8515 8538 8419 8416 8258 8290 8460 8502 8391 8435 8336 8460 8476 8584 8560 8476 8339 8588 8638 8705 8437 8564 8622 8633 8607 8732 8814 8756 8674 8551 8755 8643 8905 8852 8736 8948 8971 8964 9015 9225 9069 9556 9242 9407 9463 9673 9740 9726 9835 9879 10140 10213 10292 10169 10316 10170 10117 10069 9671 9773 9369 9368 9175 8980 9279 9062 8847 8879 8804 8834 8828 8630 8622 8711 8747 8559 8722 8607 8615 8530 8531 8533 8589 8694 8775 8515 8578 8582 8348 8421 8502 8549 8440 8605 8685 8483 8377 8485 8544 8536 8500 8456 8626 8669 8569 8338 8500 8471 8631 8569 8432 8430 8563 8522 8536 8602 8499 8443 8639 8482 8676 8639 8464 8474 8438 8505 8541 8555 8507 8462 8374 8548 8437 8610 8500 8532 8648 8728 8537 8387 8407 8500 8530 8652 8658 8507 8612 8542 8543 8501 8652 8653 8520 8627 8685 8604 8677 8570 8761 8790 8793 8781 8826 8838 8899 9007 9051 8964 9002 8799 8832 8761 8797 8560 8637 8678 8706 8609 8622 8658 8686 8376 8585 8643 8666 8638 8639 8691 8520 8755 8827 8802 8532 8679 8531 8701 8520 8470 8555 8647 8742 8595 8595 8729 8658 8661 8773 8620 8757 8720 8841 8699 8790 8750 8612 8784 8678 8512 8564 8617 8529 8809 8470 8515 8437 8442 8628 8527 8485 8576 8394 8544 8523 8555 8532 8508 8573 8449 8644 8399 8473 8720 8480 8507 8424 8678 8503 8553 8583 8532 8564 8405 8532 8619 8408 8532 8655 8562 8640 8543 8544 8561 8541 8585 8468 8605 8612 8472 8345 8636 8344 8649 8494 8492 8586 8763 8545 8511 8650 8517 8474 8424 8578 8526 8465 8624 8584 8445 8563 8385 8661 8425 8441 8513 8573 8583 8482 8589 8553 8389 8506 8462 8619 8450 8616 8653 8623 8574 8552 8669 8736 8620 8460 8588 8679 8664 8717 8726 8505 8732 8812 8834 8774 8858 8934 9036 8973 9117 9254 9208 9226 9069 9221 9197 9148 9026 9228 9456 9262 9407 9429 9655 9465 9645 9670 9763 9803 10082 10083 10183 10425 10452 10800 10908 11165 11581 11818 12349 12750 13153 13890 14509 15613 16617 18013 19214 20684 22553 24434 26854 29440 32237 35538 39322 43024 47469 52300 56943 61857 67122 71043 72612 71481 67622 61210 53886 47250 40891 33682 27428 22520 18730 15819 13998 12826 11571 10814 10491 9931 9951 9880 9845 9632 9549 9735 9386 9473 9576 9721 9474 9274 9237 9200 8996 9173 9211 9035 9014 9231 9014 9015 9025 9091 8964 8769 8767 8829 8746 8863 8793 8691 8660 8802 8705 8845 8871 8814 8678 8531 8895 8708 8670 8833 8543 8713 8801 8757 8802 8761 8730 8867 8880 8976 8768 8772 8924 8978 9017 8851 8911 9066 9120 9035 9076 9294 9155 9224 9118 9267 9431 9287 9326 9314 9195 9290 9277 9406 9355 9517 9592 9590 9582 9867 9963 9929 10167 10440 10487 10603 10663 10978 11032 11442 11819 11902 12424 12495 13151 13044 13416 13861 14203 14336 14890 14960 15099 15388 14816 14675 14256 13782 13477 12866 12473 11962 11778 11353 10955 10554 10502 10349 10038 9910 9796 9774 9569 9591 9292 9419 9371 9320 9370 9332 9094 8981 9234 9145 9040 9197 9166 9232 9195 9269 9127 9155 8951 9135 9215 8954 9140 9138 9044 9184 9098 8967 8968 8979 8956 8757 9021 8977 8956 8885 8802 8948 8843 9016 8876 9069 8743 8858 8903 8897 8960 8752 8888 9045 8855 9159 8860 8725 8904 8946 8920 8937 8967 9081 9148 9237 9170 9013 9093 9071 8893 8959 8926 8917 8847 8828 8720 8963 9009 8750 8789 8923 8829 8864 8841 8843 8738 8909 8953 8961 8850 8908 8919 8889 9032 8938 9124 9263 9016 9372 9305 9378 9382 9545 9560 9586 9822 10038 9900 10040 10239 10236 10200 10222 10521 10375 10444 10434 10193 10110 9885 9745 9495 9485 9373 9159 9050 9116 8958 8897 8903 8972 8678 8804 8604 8826 8663 8668 8821 8915 8758 8715 8630 8719 8639 8541 8840 8554 8807 8601 8743 8734 8661 8542 8360 8574 8550 8644 8636 8463 8552 8548 8700 8664 8589 8603 8395 8567 8476 8598 8544 8464 8494 8411 8537 8553 8449 8627 8485 8582 8602 8533 8476 8378 8417 8600 8377 8391 8625 8554 8428 8469 8429 8497 8503 8408 8357 8394 8447 8666 8580 8454 8369 8397 8320 8334 8477 8498 8567 8404 8377 8478 8483 8418 8655 8547 8470 8579 8337 8328 8430 8322 8393 8403 8372 8381 8582 8531 8175 8473 8441 8311 8275 8468 8402 8448 8429 8421 8438 8399 8437 8392 8200 8286 8489 8244 8370 8157 8452 8491 8535 8287 8515 8166 8484 8344 8518 8234 8342 8457 8298 8416 8354 8397 8324 8417 8295 8455 8404 8234 8345 8474 8379 8370 8212 8416 8307 8357 8314 8383 8366 8428 8325 8369 8447 8293 8450 8177 8378 8483 8462 8305 8292 8555 8404 8293 8239 8155 8171 8497 8161 8277 8284 8208 8536 8266 8349 8165 8293 8314 8272 8406 8542 8253 8244 8180 8317 8365 8214 8317 8307 8361 8293 8345 8228 8240 8251 8190 8178 8104 8286 8192 8377 8424 8237 8242 8286 8241 8225 8054 8102 8180 8337 8268 8274 8395 8247 8269 8176 8197 8184 8165 8167 8325 8112 8305 8326 8151 8294 8318 8107 8422 8399 8214 8133 8121 8334 8274 8369 8357 8165 8312 8266 7979 8326 8175 8102 8182 8298 8171 8146 8179 8156 8069 8152 8172 8396 8232 8205 8014 8068 8086 8140 8234 8212 8289 8033 8219 8203 8107 8058 8230 8096 8150 8221 8049 8264 8244 8114 8260 8155 8119 8300 8135 8203 8161 8104 8071 8239 8195 8176 8426 8128 8342 8354 8220 8227 8358 8331 8358 8214 8174 8453 8379 8328 8228 8315 8251 8269 8405 8142 8320 8331 8359 8143 8320 8242 8327 8122 8237 8261 8178 8170 8339 8261 8258 8389 8269 8468 8372 8160 8361 8214 8438 8391 8245 8440 8459 8471 8454 8558 8281 8234 8218 8473 8336 8262 8312 8276 8116 8268 8243 8276 8259 8144 8206 8231 8106 8097 8277 8114 8213 8231 8254 8442 8309 8316 8389 8405 8253 8317 8592 8274 8617 8571 8702 9003 9118 9112 9192 9447 9599 9737 9954 10295 10548 10985 11165 11453 11697 11997 12227 12103 12221 11842 11780 11368 11096 10575 10325 10004 9666 9556 9253 8875 8526 8562 8504 8460 8362 8389 8364 8309 8224 8305 8150 8232 8234 8140 8115 8154 8187 7927 8061 8274 8241 8128 8107 8261 7995 8100 8100 8176 8114 8231 7874 8037 8205 8204 8369 8222 8372 8149 8168 8076 8230 8169 8245 8090 8241 8264 8271 8220 8281 8238 8054 8319 8133 8108 8111 7980 8118 8098 8009 7880 8178 8004 7981 8066 8217 8039 8039 7897 8077 8034 7994 7930 8003 8014 8020 7994 8261 8015 7983 8116 8095 8176 7891 8085 7843 8058 8174 8110 7897 8122 7950 7969 8021 8068 7990 8138 8111 8045 8139 7953 7829 7985 8160 7969 8109 8111 8030 7930 8017 7932 8077 7995 7854 7854 8018 7935 7970 8088 8110 7901 7906 7966 7999 8013 8094 7966 7994 8039 8060 8150 8018 8052 7772 7821 7922 7999 8048 7939 7975 7942 7948 7881 7892 8044 7738 7962 7952 8078 7958 7901 8103 7977 7930 7958 7802 7957 7904 7926 8020 7877 7900 7896 8141 7952 7861 7919 7766 7938 7774 7917 8032 7874 8073 8032 8003 7973 7874 7870 7834 8017 7833 7999 8057 7742 7944 7873 7932 7950 7875 7882 7960 7900 8031 7943 7954 8074 7918 7905 7919 8033 8033 7784 7866 7993 7852 7826 7816 7912 7994 7798 7996 7982 7825 7888 7736 7873 7948 7709 7775 7996 7978 7830 7712 7838 7938 7843 7980 7892 7897 7849 7906 7828 7914 7723 8021 7967 7793 7828 7793 8026 7875 7856 8013 7791 7850 7996 7822 7701 7893 7746 7749 7924 7882 7998 7992 7940 8018 7894 8118 8039 8064 7932 7978 8044 7962 8107 8179 7965 8078 8115 8020 7909 8041 8067 8077 8007 8004 7844 8252 7938 7844 7848 7921 7817 7776 7891 7885 7860 7755 7948 7848 7753 7815 7896 7720 7794 7931 7747 7674 7719 7759 7714 7802 8024 7870 7838 7862 7818 7874 7721 7762 7828 7783 7731 7930 7791 7723 7954 7758 7838 7780 7769 7839 7920 7775 7816 7791 7785 7898 7936 7807 7648 7706 7867 7854 7974 7869 7813 8035 7986 7886 8114 7864 7890 7838 7822 7878 7877 7912 7850 8029 7913 7995 7870 7849 8006 8086 8021 8112 8194 8281 8313 8224 8355 8407 8381 8419 8551 8711 8453 8686 8560 8590 8716 8383 8661 8278 8394 8276 8265 8417 8343 8218 8221 8050 8014 8001 8099 8004 8067 8052 7822 7915 7968 8046 8257 8202 8097 7999 8029 8038 8104 7920 8030 8086 8063 7903 8056 7905 8129 8058 8175 8094 8178 8355 8390 8311 8367 8483 8455 8698 8876 9091 9130 9229 9295 9521 9933 9900 10104 10341 10419 10674 10981 11089 11140 11071 10973 10908 10679 10411 10096 9964 9670 9601 9218 9193 8974 8712 8670 8388 8328 8335 8097 8294 8070 8248 8046 8042 7986 7939 7877 7909 7950 7965 7868 7860 7687 7857 7812 7858 7991 7894 7847 7794 7935 7970 8068 7847 7724 7897 7919 7963 7985 8030 8057 8004 7958 8090 8046 8203 8300 8121 8196 7983 8016 8047 8103 8165 8167 7994 7835 7923 7981 7786 7857 7756 7720 7884 7737 7924 7750 7774 7740 7734 8014 7918 7765 7864 7759 8005 7973 7857 7777 7702 7877 7779 7784 7815 7710 7705 7824 7986 7820 7850 7871 7833 7832 7936 7888 7918 8067 8092 8023 8047 8089 8218 8249 8368 8286 8386 8528 8584 8593 8906 8831 9088 9214 9285 9202 9139 9219 9254 8828 8988 8748 8879 8678 8485 8541 8270 8361 8086 8034 7966 7890 7943 7889 7925 7820 7768 7945 7755 7877 7836 7738 7836 7827 7571 7705 7713 7693 7744 7722 7887 7649 7680 7861 7763 7623 7591 7684 7963 7672 7751 7692 7612 7870 7807 7587 7763 7756 7708 7720 7812 7789 7601 7848 7856 7879 7960 7843 7808 7882 8198 7944 7864 8052 8049 8217 8285 8327 8306 8341 8463 8552 8428 8431 8503 8508 8475 8402 8636 8470 8509 8339 8313 8410 8340 8115 8267 8248 8297 8013 8015 8004 8119 8073 8017 7849 7870 7919 7802 7815 7842 7850 7957 7969 7922 7974 7980 7810 7875 7750 7901 8000 7860 7773 7599 7857 7724 7674 7778 7653 7760 7717 7660 7781 7638 7736 7789 7780 7698 7916 7733 7725 7616 7697 7749 7756 7746 7777 7865 7717 7724 7859 7951 7935 7895 7991 7899 8036 7973 7950 7916 7970 7951 7928 7989 7951 8017 7939 8021 8098 7994 8018 8335 8257 8480 8523 8814 8768 9130 9207 9650 9526 9907 9972 9974 10153 9787 9921 9747 9436 9352 9283 8809 8889 8648 8480 8318 8269 8383 8135 7928 7971 7991 7870 7902 8000 7877 7932 7844 7673 7849 7908 7737 8005 8016 7826 7856 7693 7771 7869 7906 7772 7754 7851 7591 7823 7718 7784 7779 7941 7863 7954 7905 8158 8175 8179 8408 8361 8575 8737 8573 8864 8896 9013 8925 8951 8930 8908 8768 8769 8538 8609 8375 8341 8409 8410 8193 8280 8147 8001 8001 7861 7944 7928 7894 7827 7728 7866 7670 7603 7715 7643 7725 7694 7660 7687 7669 7736 7618 7787 7497 7675 7510 7652 7642 7589 7613 7699 7660 7619 7637 7596 7817 7500 7537 7625 7435 7688 7656 7694 7725 7760 7743 7936 7930 7762 7818 7714 7925 8016 7987 8059 8024 7935 8116 7968 8060 8004 7917 7948 8017 7813 7750 7840 7528 7626 7525 7748 7594 7693 7807 7691 7688 7766 7720 7567 7760 7757 7929 7754 7776 7794 7554 7847 7752 7820 7717 7613 7772 7688 7825 7812 7701 7827 7721 7872 7565 7632 7636 7666 7652 7481 7645 7588 7669 7632 7710 7598 7354 7553 7536 7570 7522 7528 7529 7742 7382 7432 7442 7586 7626 7322 7403 7580 7520 7465 7580 7530 7605 7682 7443 7338 7496 7564 7655 7555 7494 7565 7483 7405 7540 7563 7589 7485 7499 7294 7541 7449 7600 7475 7654 7414 7536 7566 7669 7481 7506 7403 7635 7447 7560 7550 7399 7614 7435 7563 7521 7522 7447 7439 7441 7497 7547 7646 7521 7415 7324 7567 7700 7592 7568 7517 7656 7584 7567 7572 7535 7598 7871 7693 7718 7864 7712 7862 7887 8054 8182 8175 8538 8507 8803 9162 9530 9718 10218 10413 10387 11015 10841 10669 10305 10137 9852 9729 9569 9454 9392 9160 9057 8825 8623 8502 8120 7881 7941 7821 7786 7727 7574 7551 7629 7564 7544 7540 7718 7668 7523 7593 7571 7487 7657 7692 7785 7713 7555 7537 7492 7527 7708 7441 7363 7591 7603 7578 7627 7631 7548 7551 7617 7628 7534 7499 7500 7626 7569 7643 7593 7591 7500 7441 7510 7524 7514 7720 7591 7513 7471 7624 7370 7609 7549 7552 7577 7651 7616 7597 7493 7829 7721 7818 7959 8060 8183 8589 8867 8929 9233 9644 10075 10409 10448 10470 10478 10189 9836 9375 9369 9116 9126 9035 8996 8706 8818 8346 8305 7971 7762 7658 7616 7683 7599 7542 7663 7602 7754 7822 7751 7709 7720 7815 7903 8022 7896 7921 7885 7801 7719 7751 7750 8049 7678 7686 7721 7679 7661 7707 7615 7609 7797 7633 7759 7856 7970 8105 8308 8257 8589 8620 8768 8904 9122 9075 9199 9000 8868 8614 8530 8256 8376 8341 8204 8171 8085 7910 8138 7853 7717 7701 7599 7450 7515 7417 7369 7600 7480 7497 7485 7428 7431 7490 7518 7492 7429 7511 7462 7349 7393 7634 7269 7470 7454 7359 7451 7440 7545 7502 7534 7473 7498 7510 7502 7437 7317 7431 7294 7579 7362 7540 7408 7333 7376 7248 7468 7724 7514 7438 7380 7340 7436 7434 7424 7495 7494 7406 7395 7432 7385 7370 7493 7309 7415 7590 7595 7589 7478 7536 7643 7570 7602 7546 7601 7631 7568 7568 7439 7448 7500 7575 7341 7569 7344 7604 7355 7491 7529 7470 7419 7563 7251 7388 7416 7424 7458 7349 7403 7553 7420 7268 7460 7529 7438 7593 7528 7470 7549 7535 7314 7457 7491 7470 7437 7623 7443 7497 7619 7587 7297 7647 7413 7473 7391 7349 7562 7390 7505 7474 7557 7438 7494 7404 7438 7371 7348 7441 7449 7408 7274 7464 7290 7359 7362 7562 7484 7519 7593 7466 7479 7326 7397 7416 7404 7550 7422 7576 7407 7611 7612 7576 7360 7464 7610 7414 7611 7438 7544 7547 7671 7781 7607 7621 7675 7711 7681 7793 7662 7956 7810 8054 8001 8265 8117 8018 8190 8216 8380 8265 8016 8005 8003 7907 8034 7971 8027 8004 8001 7840 7814 7649 7530 7750 7791 7625 7617 7518 7617 7625 7565 7374 7606 7407 7491 7599 7478 7602 7605 7394 7656 7621 7437 7395 7740 7522 7587 7312 7369 7440 7495 7407 7434 7517 7453 7391 7573 7426 7401 7531 7622 7605 7555 7431 7616 7657 7529 7731 7621 7584 7823 7695 7841 7865 7759 7767 7779 7819 7868 7741 7836 7726 7811 7716 7809 7596 7593 7597 7727 7698 7662 7479 7526 7579 7541 7584 7495 7434 7554 7472 7311 7385 7439 7430 7447 7355 7351 7390 7489 7253 7421 7360 7409 7489 7328 7472 7515 7326 7303 7454 7220 7492 7422 7403 7530 7477 7481 7156 7418 7248 7460 7529 7229 7322 7286 7579 7410 7515 7300 7373 7250 7254 7351 7291 7304 7512 7279 7241 7297 7301 7387 7340 7336 7382 7383 7374 7381 7584 7364 7528 7272 7413 7455 7291 7363 7273 7266 7305 7390 7263 7229 7385 7456 7278 7440 7468 7239 7299 7475 7448 7375 7280 7354 7216 7100 7397 7281 7371 7130 7350 7427 7369 7420 7446 7288 7442 7340 7420 7281 7319 7438 7360 7406 7255 7381 7338 7188 7252 7280 7466 7352 7387 7450 7302 7189 7440 7319 7402 7227 7325 7281 7266 7239 7156 7351 7338 7311 7327 7313 7423 7250 7440 7336 7362 7434 7546 7443 7449 7519 7386 7447 7432 7412 7362 7417 7394 7359 7560 7196 7364 7430 7459 7329 7438 7488 7330 7237 7515 7542 7279 7247 7265 7231 7278 7293 7389 7407 7317 7268 7399 7382 7243 7439 7410 7478 7302 7542 7344 7316 7351 7377 7547 7267 7289 7356 7356 7310 7370 7193 7375 7359 7268 7400 7575 7302 7412 7326 7299 7300 7406 7405 7415 7280 7226 7467 7438 7460 7275 7298 7409 7263 7228 7207 7317 7365 7299 7185 7274 7322 7270 7480 7309 7350 7308 7465 7288 7311 7297 7304 7400 7299 7418 7363 7423 7405 7332 7279 7525 7328 7315 7428 7434 7422 7431 7433 7501 7381 7466 7528 7589 7665 7604 7614 7791 7907 7885 7995 8213 8061 8125 8463 8824 8847 9367 9972 10517 11009 11724 12358 13039 13827 14281 14141 13932 13449 12902 12061 11705 11435 11221 11191 11224 11397 11110 11031 10659 10179 9565 9180 9022 8831 8572 8525 8402 8420 8356 8158 8102 8109 8187 7914 8175 7983 7845 7798 7775 7810 7701 7882 7548 7690 7723 7666 7623 7498 7652 7460 7377 7548 7444 7370 7440 7290 7334 7285 7380 7410 7193 7362 7338 7319 7379 7306 7230 7355 7261 7208 7196 7396 7223 7318 7456 7279 7442 7142 7282 7185 7338 7265 7368 7220 7162 7215 7164 7395 7192 7346 7362 7296 7309 7426 7520 7301 7352 7157 7355 7348 7423 7493 7294 7417 7230 7368 7514 7404 7485 7444 7389 7472 7596 7511 7606 7667 7539 7447 7560 7513 7583 7703 7456 7463 7411 7521 7484 7281 7427 7372 7377 7412 7394 7302 7235 7497 7281 7150 7155 7184 7304 7316 7162 7201 7230 7334 7347 7410 7257 7134 7316 7360 7295 7302 7256 7475 7418 7229 7385 7261 7216 7243 7116 7366 7209 7396 7406 7339 7210 7231 7266 7195 7301 7138 7306 7316 7294 7383 7189 7263 7343 7274 7538 7377 7533 7455 7296 7549 7396 7484 7633 7681 7616 7924 8016 8011 8081 8322 8410 8322 8239 8240 8346 8076 8198 7913 7888 7999 7865 7980 7912 7768 7759 7708 7544 7549 7691 7484 7359 7615 7377 7417 7502 7525 7481 7435 7355 7546 7429 7387 7477 7416 7559 7345 7639 7538 7459 7526 7523 7664 7700 7837 7695 7884 7814 7882 7646 7687 7856 7912 7626 7677 7714 7674 7648 7617 7581 7642 7504 7634 7589 7470 7441 7409 7531 7430 7374 7288 7440 7391 7467 7261 7328 7294 7323 7302 7443 7124 7264 7434 7272 7150 7413 7305 7234 7266 7190 7208 7247 7154 7367 7246 7465 7400 7491 7341 7220 7321 7392 7488 7267 7465 7335 7367 7445 7470 7488 7477 7378 7437 7450 7408 7492 7439 7323 7437 7481 7409 7361 7381 7503 7496 7515 7561 7553 7360 7559 7489 7575 7391 7586 7725 7685 7931 7849 7635 7817 7717 7809 7858 7714 7585 7611 7658 7698 7610 7690 7617 7520 7610 7545 7572 7580 7494 7387 7469 7532 7327 7396 7405 7463 7241 7364 7296 7227 7249 7167 7420 7372 7343 7402 7213 7302 7481 7353 7273 7399 7176 7401 7469 7407 7515 7575 7498 7689 7852 7815 7927 8101 8190 8218 8350 8780 8439 8619 8362 8163 8211 8102 7873 7992 7971 7862 7946 7972 7971 7988 7891 7712 7627 7670 7384 7592 7322 7364 7345 7286 7368 7294 7163 7290 7371 7289 7358 7234 7306 7376 7358 7438 7266 7174 7175 7191 7243 7180 7345 7164 7263 7122 7242 7189 7201 7252 7212 7230 7071 7122 7122 7168 7166 7190 7265 7317 7319 7166 7143 7134 7308 7038 7182 7313 7220 7189 7164 7204 7227 7304 7137 7141 7228 7339 7366 7361 7160 7268 7214 7108 7349 7406 7180 7214 7221 7418 7349 7421 7122 7218 7357 7283 7368 7327 7313 7432 7081 7290 7235 7189 7108 7465 7185 7187 7246 7171 7086 7229 7156 7291 7208 7422 7271 7354 7249 7276 7268 7262 7272 7119 7056 7126 7149 7222 7299 7199 7298 7210 7182 7332 7104 7231 7233 7272 7180 7217 7224 7363 7275 7231 7281 7244 7355 7312 7306 7380 7471 7622 7690 7508 7612 7796 7861 7833 8029 8022 8229 8325 8472 8291 8166 8238 8092 8074 7916 7922 7840 7782 8075 7838 7786 7966 7729 7797 7843 7609 7565 7535 7598 7618 7492 7424 7379 7468 7240 7354 7285 7251 7327 7234 7331 7237 7361 7328 7314 7222 7282 7262 7234 7236 7379 7184 7310 7264 7394 7241 7312 7132 7292 7229 7324 7242 7268 7466 7235 7386 7258 7479 7297 7431 7400 7559 7586 7517 7688 7596 7456 7802 7928 8042 7932 7891 7800 7870 7690 7723 7666 7506 7606 7570 7691 7745 7410 7607 7653 7597 7438 7350 7359 7487 7299 7453 7336 7292 7187 7276 7256 7143 7204 7060 7179 7102 7310 7153 7249 7107 7116 7200 7318 7251 7281 7203 7147 7186 7268 7157 7132 7101 7214 7176 7279 7292 7203 7217 7199 7241 7152 7194 7257 7130 7323 7250 7200 7344 7230 7265 7345 7139 7247 7169 7315 7279 7262 7270 7387 7261 7245 7193 7192 7287 7163 7292 7194 7150 7233 7243 7220 7343 7302 7154 7248 7291 7300 7226 7161 7352 7102 7198 7159 7220 7314 7084 7029 7256 7093 7157 7234 7100 7239 7145 7177 7112 7318 7211 7166 7115 7213 7031 7207 7290 7225 7137 7040 7241 7234 7173 7281 7217 7119 7207 7189 7163 7293 7086 7286 7161 7250 7329 7349 7265 7171 7025 7161 7152 7201 7264 7256 7283 7088 7129 7159 7175 7225 7188 7164 7339 7187 7151 7357 7140 7022 7432 7107 7298 7328 7403 7042 7206 7208 7118 7297 7342 7350 7219 7239 7064 7135 7175 7238 7347 7222 7163 7206 7050 7063 7106 7218 7053 7216 7152 7123 7310 7082 7225 7179 7210 7159 7122 7085 7181 7114 7194 7226 7197 7077 7175 7334 7237 7125 7108 7275 7141 7194 7155 7268 7216 7198 7115 7218 7231 7118 7341 7248 7150 7148 7299 7100 7279 7220 7278 7272 7185 7109 7141 7183 7066 7136 7228 7144 7233 7043 7223 7120 7162 7144 7043 7221 7182 7214 7081 7180 7185 7164 7300 7099 7125 7061 7024 7080 7030 7074 7090 7209 7109 7241 7264 7054 7112 7121 7251 7162 6906 7035 7034 7163 7102 7138 7195 7076 7090 7107 7139 7344 7186 7190 7292 7253 7159 7223 7307 7380 7202 7357 7493 7097 7178 7170 7151 7350 7156 7239 7254 7306 7156 7229 7421 7195 7151 7205 7271 7350 7285 7239 7159 7112 7285 7308 7216 7252 7332 7313 7464 7372 7451 7520 7428 7508 7476 7555 7552 7728 7568 7672 7614 7583 7634 7717 7696 7701 7683 7549 7591 7514 7573 7609 7454 7634 7560 7544 7581 7558 7438 7281 7397 7422 7227 7217 7345 7339 7250 7250 7291 7115 7165 7094 7073 7131 7080 7170 7062 7261 7137 7186 7258 7197 7228 7183 7251 7176 7179 7138 7233 7003 7282 7205 7313 7279 7096 7193 7224 7335 7246 7283 7367 7463 7284 7294 7244 7176 7204 7168 7275 7201 7056 7234 7276 7146 7336 7397 7055 7210 7235 7132 7114 7150 7119 6959 7079 7067 7067 7238 7074 6873 7157 7162 7328 7190 7255 7078 7133 7157 7140 7051 7020 7089 6974 6937 7030 7146 7106 7008 7138 7147 7252 7191 6980 7290 7017 6949 7151 7132 7245 7173 7153 7089 7004 7182 7108 7279 7196 7038 7159 7053 7081 6973 7231 7118 7094 7129 6942 7116 7091 7102 7075 7056 7012 7150 7007 7034 7239 7063 7152 7325 7259 7056 7260 6998 7381 7108 7204 7514 7385 7287 7342 7315 7497 7531 7495 7318 7416 7301 7337 7421 7313 7446 7327 7433 7350 7470 7412 7499 7292 7400 7361 7435 7278 7325 7313 7427 7308 7332 7361 7412 7252 7239 7194 7288 7208 7245 7133 7260 7209 7382 7189 7147 7131 7105 7191 7109 7046 7083 7090 7168 7073 7179 7172 7149 7078 7282 7295 7280 7045 7153 7197 7292 7121 7094 7132 7009 7123 7229 7307 7118 7121 7208 7100 7079 7226 7201 7216 7385 7176 7149 7161 7286 7132 6957 7259 7205 7241 7082 7250 7080 7022 6957 7117 7018 7185 7088 7186 7188 7220 7272 7102 7402 7079 7401 7415 7396 7341 7312 7303 7438 7361 7374 7288 7220 7366 7214 7239 7334 7229 7562 7270 7265 7257 7414 7257 7289 7224 7176 7221 7135 7147 7329 7104 7297 7309 7109 7243 7330 7431 7166 7467 7245 7297 7463 7370 7388 7397 7481 7522 7544 7504 7599 7713 7612 7549 7629 7541 7766 7568 7865 7958 8039 8203 8161 8189 8210 7928 7815 7824 7728 7547 7416 7558 7491 7457 7399 7659 7733 7460 7537 7493 7548 7521 7413 7373 7339 7288 7127 7376 7348 7213 7211 7252 7282 7398 7399 7224 7677 7431 7499 7783 7704 7987 8079 8205 8516 8439 8616 8546 8479 8391 7988 8015 7874 7809 7653 7827 7687 7882 7780 7900 7804 7869 7933 7798 7733 7687 7530 7535 7424 7290 7271 7212 7271 7217 7098 7124 7284 7082 7169 7231 7142 7334 7238 7241 7187 7301 7153 7221 7291 7212 7373 7164 7285 7228 7297 7108 7277 7204 7319 7107 7229 7252 7048 7186 7155 7160 7041 7247 7029 7129 7064 7218 7138 7231 7203 7189 7072 7120 7084 7229 7022 7055 7139 7207 7224 7262 6953 7199 7211 6933 7175 7053 7230 7279 7112 7122 7167 7182 7310 7266 7099 7215 7175 7059 7047 7072 6908 7188 7168 7153 7133 7063 7057 7137 7039 7153 7056 7189 7031 7083 7077 7161 7121 7248 7161 7277 7256 7228 7130 7208 7164 7325 7206 7291 7263 7384 7548 7584 7526 7424 7500 7739 7762 7685 7605 7659 7596 7577 7574 7450 7322 7373 7331 7234 7317 7466 7380 7401 7481 7352 7211 7273 7276 7204 7326 7157 7229 7057 7116 7125 7119 7094 7097 7299 7132 7028 7150 7227 7059 7030 7140 7042 7186 7113 7257 7013 7114 7125 7035 7072 7133 7134 7148 7092 7093 7282 7172 7163 7128 7193 7127 7173 7125 7270 7106 7159 7341 7181 7174 7293 7299 7468 7440 7391 7359 7447 7590 7488 7496 7435 7312 7560 7407 7388 7528 7515 7518 7544 7479 7730 7603 7666 7842 7908 7944 7691 7736 7860 7909 7814 7674 7479 7608 7505 7568 7548 7623 7635 7737 7600 7657 7769 7582 7641 7508 7361 7504 7524 7467 7213 7145 7407 7201 7286 7137 7312 7237 7203 7318 7238 7255 7108 7115 7253 7117 7234 7245 7133 7191 7022 7089 7223 6981 6847 7144 6998 7170 6879 7065 7178 6959 7081 6956 7138 6968 6969 7085 7160 7052 7058 7012 7007 7108 6862 7113 6941 7130 6747 7053 7075 7061 7083 6861 7098 7018 7022 7002 7003 7052 7104 7096 7089 7141 7087 7195 7071 7121 7144 7090 6973 7158 7202 7158 7137 7212 7215 7168 7192 6986 6965 7037 7153 6973 7058 7068 7065 7059 7093 7071 6936 7021 7053 7093 7158 6969 6963 6999 7068 7093 7027 7173 7102 7087 7131 7078 7137 6966 7018 7118 6973 7034 6964 6941 7081 7230 7282 7004 6998 7182 7083 7149 7168 7107 7155 7281 7119 7217 7198 7217 7247 7131 7199 7207 7101 7333 7229 6969 7233 7161 7242 7167 7249 7242 7155 7223 7069 7201 7224 7222 6991 7201 6971 7069 6940 7281 6997 7074 6968 7098 7105 7103 7191 6951 7076 7047 7038 7163 7016 7128 6970 7083 7161 7205 7028 6948 7137 7203 7197 7184 7070 7348 7309 7238 7282 7077 7177 7212 7334 7049 7243 7182 7086 7325 7170 7182 7215 7216 7147 7271 7394 7152 7273 7300 7285 7239 7320 7182 7289 7394 7058 7066 7040 7027 7172 7114 7103 7184 7247 7392 6977 7168 7184 7168 7209 7164 7054 7170 7050 7016 7083 7271 7121 7078 7097 7079 7094 7032 7124 7160 7255 7148 7173 7121 7063 7178 7104 7079 7001 7211 7168 7287 7252 7125 7330 7187 7109 7189 7134 7255 7060 7077 7091 7130 7228 7284 7334 7381 7277 7411 7322 7440 7652 7416 7569 7902 7808 7904 8090 8423 8575 8762 9006 9084 8898 8714 8779 8542 8201 7983 7760 7659 7806 7782 7784 7734 7840 8085 8144 7993 8148 8020 8059 7746 7830 7603 7505 7456 7464 7358 7425 7229 7334 7251 7253 6984 7135 7168 7195 6990 7250 7307 7221 7142 7155 7051 7208 7181 7215 7042 7186 7195 7375 7259 7289 7312 7323 7547 7469 7331 7426 7376 7315 7321 7364 7402 7236 7235 7260 7185 7275 7188 7323 7371 7215 7409 7298 7273 7517 7665 7753 7729 8009 7930 8173 8293 8252 8257 8216 8272 7893 7713 7710 7529 7590 7542 7484 7600 7675 7446 7562 7593 7646 7779 7636 7497 7432 7481 7256 7171 7100 7237 7284 7030 7073 6981 6997 7001 7060 7064 7085 6983 7208 7081 7073 7093 7102 7126 7069 7011 6960 6986 7029 7031 7085 6995 7052 6935 7060 7161 7177 6913 7150 7111 7119 6938 7032 7099 6911 7144 7079 7047 7045 7180 7013 7111 6971 7323 7054 6991 7066 7018 7085 6911 7008 7101 7117 7116 7008 7189 7045 6950 7039 6951 7121 6932 6931 6898 6925 7093 6870 6969 6905 7015 7088 6959 7049 6889 7087 6894 6914 6932 6903 6997 6980 6955 7045 7025 6912 6912 6975 7068 6971 6985 7048 6989 7039 6953 6993 7185 6986 7092 7249 7200 7085 7144 7034 6997 7156 7065 7199 7073 7062 7129 7190 7070 7005 6992 7097 7144 7137 7109 7116 7168 7059 7018 6903 7093 7034 7058 7125 7097 7025 7168 6999 6897 7012 7093 7207 7017 7035 7091 7122 6923 7036 7084 6845 7070 7124 6894 6980 7083 7071 6999 7047 7033 7029 7054 7138 7054 7000 7015 7114 7177 7223 7105 7089 7089 7074 7118 7210 7009 7107 6874 7012 7044 7240 7022 7115 7032 7038 7144 7077 7115 6969 6990 7113 7131 7176 7170 6965 7348 7128 7169 7283 7162 7147 7207 7210 7279 7253 7342 7222 7265 7359 7215 7350 7194 7328 7313 7303 7184 7283 7250 7049 7247 7366 7215 7324 7310 7273 7390 7374 7243 7327 7276 7170 7229 7051 7120 7156 7159 7187 7218 7015 7182 7181 7011 7094 7098 7171 7197 7086 7043 7002 7140 7081 7103 7198 7283 7011 6958 7052 7042 6943 7041 7049 7079 7241 7075 6936 7230 7116 7088 7068 6999 7128 7196 7136 7241 7131 7254 7352 7434 7301 7497 7350 7598 7521 7812 7628 7714 7908 7928 8050 8038 7901 7811 7777 7597 7416 7433 7308 7532 7477 7343 7420 7332 7214 7570 7486 7442 7507 7560 7445 7410 7533 7265 7278 7259 7297 7298 7276 7202 7030 7058 7136 7081 7209 7199 7085 6949 7106 7135 7119 7171 7177 6974 7071 7194 7140 7081 7042 7122 7053 7052 7030 6917 7138 7058 7011 7308 7071 7119 7072 7206 7208 7277 7093 7262 7219 7252 7087 7221 7095 7231 7260 7009 7071 7138 7124 7051 7075 7205 7011 7131 7156 7042 7071 6975 7002 7012 7070 7107 7013 7071 7034 6957 6954 7000 7093 7128 7004 6928 6991 7063 6836 7022 6998 7069 7003 6856 7062 6995 6979 7028 6905 6947 6985 6950 6864 6948 6943 6915 7009 7047 6897 6978 6995 7003 6850 7081 7064 6910 6908 7003 7106 6941 6955 7082 6959 6989 6852 6854 7078 6913 6965 7072 7006 6993 7159 7099 6962 6988 7220 6976 6993 6951 6981 6968 7044 6934 6895 7122 6876 6882 6818 6903 7047 7052 6868 6929 7007 6924 7023 6968 7077 6839 6989 7062 6834 6959 7097 6991 7025 7043 7012 7055 6936 7010 7105 7115 7056 7116 7041 7166 7229 7067 7118 7022 7123 7196 7119 7017 7064 7030 7231 7167 7061 7083 6879 7174 7180 7023 7020 7113 7099 7147 7154 7029 6924 6986 7184 7008 6974 7138 7167 6973 7113 7029 7128 6795 6898 6925 7152 7250 7443 7116 7170 7249 7286 7370 7237 7358 7423 7488 7482 7262 7354 7382 7244 7273 7192 7271 7220 7378 7254 7140 7231 7225 7285 7221 7304 7208 7202 7222 7228 7236 7261 7238 7245 7121 7150 7204 7315 7203 7195 7184 7433 7208 7302 7227 7209 7193 7314 7235 7084 7075 7155 7214 7167 7063 6987 7094 7215 6942 7268 7070 7131 6991 7130 7057 7106 7086 7161 7088 6977 7018 6905 7049 6882 6933 7154 6817 6782 6839 6896 7173 6991 6982 6991 6956 6847 7105 7026 7082 6884 7067 6839 7153 6855 6904 6864 6960 7028 6920 6878 6942 6976 6835 6830 7039 7049 7029 6996 6983 7099 6911 6796 7001 6974 6934 6919 6843 6925 6961 7087 6866 6990 7068 7023 6965 6955 7020 6959 6887 6964 6914 6970 7096 7078 7015 6957 6959 7012 6951 6902 7006 7060 7167 6994 7093 7096 7114 6881 7073 7093 7063 7035 7050 7133 7014 7032 7130 7207 7043 6933 7071 6993 7205 6972 7018 7052 7029 7104 7042 7071 7089 6975 6962 7003 6976 7098 7035 7016 7052 7101 7052 6922 7000 6900 6864 7031 7021 7099 7096 7176 7086 6959 7043 6957 7035 7163 6932 7110 7009 7160 6918 7115 7278 7026 7214 7349 7166 7141 7245 7260 7180 7289 7132 7157 7127 7098 7134 7308 7075 7141 7042 7077 7154 6980 7075 7003 7039 7138 7063 7321 7159 7121 7140 7128 6983 6991 7001 7057 7031 7128 6923 6931 6845 6938 6844 6927 7144 7047 6894 6937 6856 7082 6947 7023 6821 6747 6919 6896 6836 7050 6989 6855 7080 6933 6754 6868 7011 6811 6924 6855 6865 6938 6937 6875 6967 6819 6860 7000 6904 6830 6918 6878 6922 6935 6951 6952 6795 6860 6840 6844 6844 6956 6980 7047 6928 6988 6947 6876 7107 6968 7015 6980 6819 6889 6791 6953 6816 6864 7059 6922 6962 6830 6928 6964 6810 7042 6980 7067 7001 6920 6977 6977 6917 6906 6917 7088 6962 6847 6860 6996 6963 7013 7180 7122 6840 6927 6976 6943 6915 7025 7015 7013 7096 7019 7172 7105 7126 7149 7149 7158 7273 7053 7039 7074 6992 7075 6928 6898 7015 6843 7168 7118 7058 6825 7094 7159 6832 6939 7013 7102 7039 7107 6987 7117 6989 7038 6983 6960 6862 6880 7017 6929 7027 7004 7019 6968 7022 6999 7113 7007 6885 6922 6967 6925 6978 6857 6914 6967 7079 6985 7075 6952 6946 6983 6982 7028 7017 7059 6869 7113 6952 6985 6858 6897 7047 6972 7019 7065 6975 6940 6911 6925 6919 7072 6913 6974 6825 6867 6966 6789 6748 6991 6818 6997 6964 6992 6962 6955 7049 7016 7046 6999 6933 6961 6958 6771 6831 6892 6874 7024 6933 7035 6871 7024 6892 6775 6973 7015 6929 6899 6908 7009 6845 7198 6826 7174 6887 7072 6893 7091 7023 6963 6912 7028 6962 6805 7003 6981 6949 6983 6988 6925 6921 6885 6916 7021 6965 6979 6915 6960 6900 7016 6829 7034 6868 6851 6790 7066 6994 7026 7072 6891 6954 6882 6951 7038 6989 6974 6986 7014 6950 7051 6958 7004 6966 7015 6840 7019 6779 6996 6961 7097 7005 7024 6888 7084 6916 6975 6922 6791 6999 6913 7038 7158 7050 6986 6949 6922 7155 7222 7004 6949 7030 6943 6905 6961 7106 7025 7163 7133 7128 7037 7055 7103 7124 7022 6895 7049 6914 7122 7032 7025 7148 7031 7084 6935 6964 7104 6973 6956 6951 7239 7210 7251 7175 7087 7378 7281 7197 7250 7370 7080 7241 7072 6985 7119 6984 7289 7021 7208 7041 7054 6973 7136 7183 7154 7255 7168 7358 7277 7280 7361 7072 7142 7015 7029 7030 7034 6960 6962 6765 6943 7080 7015 6973 6835 7013 7152 7144 7074 7053 7031 6874 7005 6976 6960 6973 6918 6941 6969 6978 6860 6871 6880 6953 7023 7039 6873 6880 6971 6820 6975 6841 6897 7200 6980 6946 7174 7040 7074 7184 7062 6953 7258 7057 7129 7163 7232 7189 7100 7108 7080 7040 7020 7119 6964 6890 7078 7147 7093 7027 7038 6768 6991 7068 6925 7158 6988 7076 7160 6998 6987 7003 6922 6864 6955 6910 6963 7010 6896 6967 7090 7019 7022 7029 7056 6932 7173 6958 6968 7114 6916 6898 7066 6864 7002 6897 6997 6947 6903 6823 6864 7043 7027 6762 7075 7050 7068 7053 7069 6996 6941 6954 6978 6975 6885 6953 6844 7073 7044 6814 6892 6806 6915 6851 6997 6747 6929 7012 6867 6922 6687 6795 6852 6869 6861 6861 7001 6801 6981 6869 6712 6940 6899 6938 6988 6796 6884 6958 6829 6759 6857 6865 6960 6823 6982 6829 6923 6742 6925 7000 6810 6857 6845 6911 6958 6876 6834 6727 7055 6874 6927 7113 6844 6839 6990 6995 6865 6991 6774 6831 6945 6892 6918 6821 6850 6847 7011 6867 6821 6999 6929 6984 6936 6863 6834 6793 6970 6678 6813 6921 6909 6752 6894 6827 6842 6872 6704 6881 6885 6946 6823 6886 6943 6740 6856 6895 6945 6945 6985 6983 6967 6988 6923 6949 6964 6955 6953 7041 7003 7097 6984 6954 7055 7187 7041 6897 7023 6905 7022 6842 6993 6885 6947 6937 6990 6928 7128 7003 6976 6949 6957 6982 6979 6989 7004 6918 6925 6797 7042 6842 6860 6969 6913 7037 7003 6972 6838 6951 7094 6948 6871 6798 6898 6853 7064 6948 6999 7014 6893 6845 6983 6994 6956 7166 6891 6977 6837 6898 7073 7060 6980 6978 7164 6879 6911 6947 6985 6909 6980 6928 7141 6996 7086 7061 7054 7040 6989 7122 7187 7473 7446 7513 7532 7866 7985 8058 8032 7837 7654 7511 7340 7361 7196 7119 6995 6998 7227 7069 7088 7136 6997 7062 7034 7000 7278 7333 7453 7308 7353 7468 7350 7308 7265 7218 7049 6950 6879 7115 6986 7013 6977 6939 7035 6951 6842 6884 7085 6928 6941 6993 7024 7160 6928 6876 7015 6902 6886 6706 7039 7066 7083 6960 6867 6935 6960 6907 7034 6813 6970 7077 6953 6943 6882 7033 7002 7003 6918 6904 6993 6971 6964 6969 6976 6964 6867 6768 6850 7066 6988 7076 6984 6984 6879 6875 6947 7012 6856 6913 6821 6928 6829 6894 6782 6883 6960 7005 6951 6846 6976 7025 6815 6942 6845 6956 6878 7034 6800 6912 6870 6836 6867 6875 6864 7027 6915 6862 6967 6849 6969 6990 6889 6788 6741 6719 6942 6854 6888 6926 6917 6859 6925 7039 6966 6928 6951 6924 7026 7118 6997 6979 7242 7191 7126 7236 7240 7218 7363 7373 7438 7415 7388 7339 7310 7143 7183 7120 7064 7017 7127 6877 6998 6963 7057 6946 7088 7033 6921 7074 7036 7203 7136 7166 7241 7278 7069 6955 7052 7093 6944 7146 6988 6928 7038 6980 6952 6896 6928 6852 6922 6985 7078 6765 6767 6912 6951 6984 6960 6909 7004 6977 6821 7009 6734 6890 6850 6951 6929 6864 6715 6741 6849 6858 7081 6853 6945 6924 6913 6899 6922 6783 6851 6889 6924 6761 7003 6804 6979 6902 6975 6928 6781 6883 6831 6941 6818 6884 6768 7035 6879 6953 6968 6900 6852 6964 6924 6947 6878 6940 7025 6850 6858 6721 6853 6892 7047 6884 6948 7049 6899 6815 6871 6985 6916 6841 6937 6888 6719 6871 6985 6928 6902 6961 6851 6999 6828 7011 6720 6876 6879 6820 7003 7013 6900 6959 6951 7075 6788 6968 6825 6820 6968 6864 7035 6879 6971 6791 6994 6902 7081 6885 7043 6979 7006 7003 7112 7099 6942 6886 7076 7040 7010 7201 7180 7245 7244 7242 7325 7443 7304 7444 7372 7522 7438 7395 7139 7325 6904 7113 7127 6985 7187 6872 7054 7044 7068 7038 7006 6947 7030 7214 7220 6938 7141 7301 7255 7073 7158 6961 7101 7175 6989 6912 6829 6941 7026 7041 6951 6862 6892 6837 6951 6974 7046 6870 6840 6927 6958 6961 6999 7003 6942 6898 6941 7022 7024 6950 6942 6997 6921 6882 7087 6999 6942 7003 6930 6932 6979 6856 7003 7019 7034 7059 6878 6960 7072 7027 7166 6785 6992 7132 6883 6998 6808 7063 6885 6895 7058 7123 7036 7026 7006 7044 7013 7024 7097 6960 7153 6922 7028 6906 6972 7035 6978 7143 6919 7072 7097 7206 7039 7115 7159 7036 7108 7185 7127 7045 7005 6953 7108 7019 7075 7180 7021 6948 7057 6857 7042 6978 6877 6931 7077 7019 6848 7011 7147 7002 7078 6959 6903 6955 7030 6879 6987 6943 6931 6983 6885 6757 6779 6841 6852 6987 6865 6918 6911 7018 6802 6898 6973 6874 6878 6732 6840 6930 6889 6899 7019 6881 6863 7000 6826 6939 6899 6814 6772 6999 6925 6779 6809 6848 6830 6843 6826 7085 6874 6814 6852 6809 6895 6924 6723 6915 6888 6955 6756 6946 6931 6923 6736 6866 6960 6776 6879 6846 6809 6942 7051 7013 6750 6905 6770 6887 6762 6875 6913 6830 6779 6837 6956 6802 6891 6748 6866 6898 6900 6980 6648 6899 6937 6979 6906 6897 6796 6971 6934 7008 6838 6970 6884 6942 6895 7065 6967 6964 6985 6849 6909 6998 6840 6909 7033 7045 6938 6910 6795 6929 7019 6969 6897 6785 7149 6923 6942 6796 6924 6933 6965 6887 6829 6782 6922 6806 6889 6926 6996 6887 6924 7112 6791 6997 6790 7066 6859 6888 6783 6941 6881 6831 6971 6928 6947 6929 6792 6935 6836 7013 7006 6781 6734 6802 6761 6905 6834 6977 6842 6744 6645 6814 6918 6814 6889 6816 6888 6973 6921 6843 6952 6898 6945 6953 6820 6804 7070 6937 6868 6808 6787 6702 7015 6860 6807 6891 7018 6902 6873 6810 6972 6913 6835 6907 6896 6843 6989 6913 6807 6642 6989 6819 6913 6998 6913 6862 6893 6887 6871 6938 6933 6951 7120 6758 7027 6963 6985 7056 6943 6853 6885 6877 7138 7016 7047 6864 6976 6871 6754 6822 6988 6942 6997 6906 6908 7014 6997 6922 6985 6946 6942 6894 6951 6959 6899 6834 6827 6910 6828 6898 6847 6925 6834 6754 6941 6857 7036 6949 6844 6743 6791 6848 6973 6863 6871 6728 6979 6917 6819 6787 6826 7023 6879 6950 6933 6862 6704 6916 6793 6757 6760 6799 6819 7011 6934 6743 6908 7138 6796 6887 6912 6889 6826 6984 6952 6752 6814 6751 6938 6857 6981 6868 7009 6800 6802 7040 7066 6837 6974 7034 6864 6940 6840 6754 6873 6817 6947 6794 6949 6889 6838 6984 6973 6795 6870 6960 6887 6912 6992 6767 7005 6812 6951 6849 6976 7002 6994 6889 6869 6933 6864 6950 6837 6895 6955 6951 6871 6875 6850 6803 6868 6936 6790 6921 6796 6753 6946 6910 6819 6818 6946 6922 6828 6822 6785 6775 6810 6796 6784 6915 6810 6737 6894 6762 6784 6856 6929 6923 6738 6862 6872 6787 6835 6758 6811 6911 6768 6887 6626 6999 6688 6722 6854 6789 6879 6844 6787 6788 6861 6840 6979 6878 7005 6867 6910 6797 6790 6900 6880 6842 6793 6874 6884 7109 6710 6744 6742 6869 6911 6768 6903 6753 6808 6872 6734 6788 6923 6842 6782 6782 6769 6723 6917 7018 6808 6916 6914 6859 6756 6977 6869 6861 7068 6825 6761 6956 6811 6775 6884 6908 7024 6898 6880 6992 6934 6802 6809 6926 6889 6866 6753 6945 6957 6848 6856 6927 6875 6984 6906 6898 7014 6921 7020 6863 6916 6896 6820 6986 7003 7068 6983 7116 6967 6865 6887 6872 6926 7009 6920 6805 7055 6874 7000 6826 6827 6900 6881 6954 7043 6951 6892 6984 7132 7013 6993 6932 7059 6881 6948 7100 6970 6926 6901 7000 6882 6838 6949 6934 6955 6968 6975 6886 6944 6824 6814 6764 6883 6826 6858 6958 7002 6937 6793 6790 6841 6858 6758 6795 6872 6957 6810 6807 6800 6902 6845 6974 6761 6725 6976 6901 6955 7057 6977 6957 6784 6876 6972 7122 6906 6955 6971 6952 6825 6932 6900 6914 7090 6716 6790 6886 6949 6959 7041 6886 6950 7037 6977 6868 7037 6972 6787 6957 6874 7077 6807 6894 6886 7001 7114 7053 6892 6774 6963 6968 6968 6949 6878 7077 6928 6849 6870 6972 6793 7099 6761 6829 6842 7076 6956 6841 6787 6862 6910 6866 6874 6976 6890 6938 6892 6918 6925 6757 6857 6975 6687 7009 6835 6651 6957 6806 6932 6903 7019 6947 6983 6947 6837 6960 6979 6915 6995 6937 6993 6942 7059 6924 6970 6990 6871 6934 6882 6826 7080 6831 6843 6910 7044 6881 6826 7070 6787 6992 7016 6992 6981 7075 6962 6946 6897 6972 7138 6967 6962 6924 7040 7070 6988 6894 6806 6876 6940 7047 7036 6882 7129 6866 7257 7103 7168 7068 7194 7185 7306 7205 7031 7148 7133 7048 6927 6922 7086 6908 7034 6924 7077 7038 6957 7112 7055 7009 6932 6947 6984 7050 7155 7091 6985 7272 7055 7070 7221 7028 7112 7046 7078 7069 7056 7070 7077 7174 7145 7013 6932 7148 6934 6992 7059 7104 6933 7081 6855 6947 6924 6903 6852 7014 6866 6921 6815 6986 6971 6992 6880 6975 6977 6891 7108 6971 7069 6854 6936 6929 6801 7118 6871 6945 6968 6958 7015 6903 6822 6907 6845 6855 6741 6756 6847 6810 6907 6862 6880 6685 6843 6782 6813 6786 6894 6888 6805 6808 6735 6784 6713 6833 6925 6911 6872 6869 6899 6961 6789 6892 6733 6833 6598 6882 6902 6864 6855 6794 6964 6862 6839 6877 6788 6804 6778 6818 6778 6806 6722 6988 6720 6968 6684 6858 6834 6870 6953 6857 6697 6832 6740 6556 6893 6880 6771 6808 6958 6958 7002 6790 6887 6786 6851 6849 6795 6776 6787 6774 6924 6741 6917 6707 6751 6871 6866 6685 6888 6925 6849 6965 6761 6842 6866 6769 6755 6705 6856 6830 6668 6945 6661 6881 6972 6883 6812 6932 6879 6786 6930 6889 6835 6904 6741 6755 6751 6918 6836 6739 6921 6830 6927 6747 6816 6776 6958 6727 6723 6868 6938 6854 6857 6754 6909 6793 6890 6802 6890 6906 6775 6822 6819 6754 6811 6809 6765 6700 7036 6787 6774 6667 6763 6726 6768 6742 6857 6801 6838 6832 6833 6926 6960 6756 6811 6690 6939 6824 6756 6755 6931 6799 6844 6808 6839 6940 6841 6897 6862 6780 6832 6995 6879 6805 6786 6870 6854 6928 6917 6896 6861 6938 6763 6992 6836 6768 6944 6862 6960 6784 6855 6854 6825 6853 6882 6775 6809 6781 6807 6871 6799 6865 6849 6780 6807 6781 6924 6940 6866 6924 6863 6732 6769 6727 6814 6766 6802 6890 6908 6882 6947 6856 6851 6799 6781 6814 6870 6730 7028 6824 6904 6919 7032 6729 6580 6691 6906 6788 6831 6809 6798 6906 7087 6948 7002 6897 6988 6815 6807 6829 6713 6768 6909 6835 6840 6885 6924 6931 6834 6860 6918 6842 6866 6862 6804 6824 6906 6820 6879 6909 6818 6874 6579 6936 6913 6871 6941 6806 6792 6972 6823 6828 6835 6777 6808 6812 6790 6873 6894 6715 7009 6778 6727 6901 6751 6931 6896 6785 6884 6865 6901 6889 6914 6858 6939 6901 6637 6849 6922 6820 6899 6835 6922 6950 6894 6961 6817 6691 6911 6928 6814 6916 6741 6923 6714 6933 7025 7002 6996 6908 6909 6902 6944 6803 6914 7044 6892 6976 6866 7055 6889 6973 7101 6935 6801 6938 6855 6858 6873 6861 6804 6830 6985 6819 6847 6760 6711 6935 6895 6888 6926 6996 6774 6766 6813 6939 6932 6825 6931 6864 6828 6778 6866 6878 6798 6944 6906 6774 6833 6723 6864 6873 6786 6891 6930 6868</counts>
			</dataPoints>
		</scan>
	</xrdMeasurement>
</xrdMeasurements>