File: dataset/precursor_mixture/NaAlO2-1.5H2O_Li2CO3_La(OH)3.2-min.xrdml
<?xml version="1.0"?>
<xrdMeasurements xmlns="http://www.xrdml.com/XRDMeasurement/2.2" xmlns:xsi="http://www.w3.org/2001/XMLSchema-instance" xsi:schemaLocation="http://www.xrdml.com/XRDMeasurement/2.2 http://www.xrdml.com/XRDMeasurement/2.2/XRDMeasurement.xsd" status="Completed" recordIdentifier="{5210F891-5481-46A4-A3DA-E34D981422BA}">
	<comment>
		<entry/>
	</comment>
	<sample type="To be analyzed">
		<id></id>
		<name></name>
		<preparedBy></preparedBy>
	</sample>
	<xrdMeasurement measurementType="Scan" status="Completed" sampleMode="Reflection">
		<usedWavelength intended="K-Alpha 1">
			<kAlpha1 unit="Angstrom">1.5405980</kAlpha1>
			<kAlpha2 unit="Angstrom">1.5444260</kAlpha2>
			<kBeta unit="Angstrom">1.3922500</kBeta>
			<ratioKAlpha2KAlpha1>0.5000</ratioKAlpha2KAlpha1>
		</usedWavelength>
		<incidentBeamPath>
			<radius unit="mm">145.00</radius>
			<xRayTube id="1010048" name="Empyrean Cu LFF HR (9430 033 7310x) DK437873">
				<tension unit="kV">40.0</tension>
				<current unit="mA">15.0</current>
				<anodeMaterial>Cu</anodeMaterial>
				<focus type="Line">
					<length unit="mm">12.0</length>
					<width unit="mm">0.4</width>
					<takeOffAngle unit="deg">6.0</takeOffAngle>
				</focus>
			</xRayTube>
			<filter id="20010004" name="Beta-filter Nickel">
				<material>Ni</material>
				<thickness unit="mm">0.020</thickness>
			</filter>
			<sollerSlit id="21010002" name="Soller slits 0.04 rad.">
				<opening unit="rad">0.0400</opening>
			</sollerSlit>
			<mask id="22031000" name="Fixed mask 13 mm">
				<width unit="mm">9.00</width>
			</mask>
			<divergenceSlit id="22120001" name="Divergence slit 1°" xsi:type="fixedDivergenceSlitType">
				<distanceToSample unit="mm">50.00</distanceToSample>
				<height unit="mm">1.52</height>
			</divergenceSlit>
		</incidentBeamPath>
		<beamKnife id="29030100" name="Beam knife low"/>
		<sampleMovement xsi:type="spinningSampleMovementType">
			<spinnerRevolutionTime unit="seconds">1.0</spinnerRevolutionTime>
		</sampleMovement>
		<diffractedBeamPath>
			<radius unit="mm">145.00</radius>
			<antiScatterSlit id="22090040" name="AS slit 9 mm" xsi:type="fixedAntiScatterSlitType">
				<height unit="mm">9.00</height>
			</antiScatterSlit>
			<sollerSlit id="21020003" name="Large Soller slits 0.04 rad.">
				<opening unit="rad">0.0400</opening>
			</sollerSlit>
			<filter id="20030001" name="Large beta-filter Nickel">
				<material>Ni</material>
				<thickness unit="mm">0.020</thickness>
			</filter>
			<detector id="7010019" name="PIXcel1D-Medipix3 detector" xsi:type="rtmsDetectorType">
				<phd unit="keV">
					<lowerLevel>4.0</lowerLevel>
					<upperLevel>11.3</upperLevel>
				</phd>
				<mode>Scanning</mode>
				<activeLength unit="deg">1.021</activeLength>
			</detector>
		</diffractedBeamPath>
		<scan appendNumber="0" mode="Continuous" scanAxis="Gonio" status="Completed">
			<header>
				<startTimeStamp>2024-03-22T20:56:58-07:00</startTimeStamp>
				<endTimeStamp>2024-03-22T20:59:20-07:00</endTimeStamp>
				<author>
					<name>Instrument</name>
				</author>
				<source>
					<applicationSoftware version="1.6 (94)">PANalytical Aeris Instrument Suite</applicationSoftware>
					<instrumentControlSoftware version="3.0.0 20211014">AERIS</instrumentControlSoftware>
					<instrumentID>2879380</instrumentID>
				</source>
			</header>
			<dataPoints>
				<positions axis="2Theta" unit="deg">
					<startPosition>10.02173288</startPosition>
					<endPosition>139.98435528</endPosition>
				</positions>
				<positions axis="Omega" unit="deg">
					<startPosition>5.01086644</startPosition>
					<endPosition>69.99217764</endPosition>
				</positions>
				<commonCountingTime unit="seconds">1.551</commonCountingTime>
				<counts unit="counts">421 375 362 368 381 360 379 389 394 368 356 378 374 372 376 351 325 349 382 386 356 338 353 339 306 320 310 323 356 315 360 321 313 321 315 332 310 305 320 302 290 313 269 305 294 294 260 293 278 281 267 285 292 289 267 290 272 276 272 295 272 275 283 278 296 242 274 239 284 264 262 250 240 281 227 266 259 242 239 278 271 248 231 243 238 206 225 259 225 246 269 259 251 224 255 253 240 260 261 224 251 227 248 287 235 253 243 234 231 238 245 238 239 228 211 250 231 259 289 308 337 383 442 517 584 711 936 1165 1288 1267 1079 729 564 405 357 293 259 250 218 257 221 225 223 200 201 248 227 206 231 239 255 224 204 222 221 194 199 192 167 191 201 219 180 170 180 165 192 179 191 188 178 182 185 186 189 196 179 192 190 185 164 152 149 184 167 163 195 175 176 169 193 169 154 171 167 137 153 159 166 171 166 153 142 138 165 152 139 166 127 148 166 150 179 168 161 169 169 139 132 160 165 145 142 149 147 145 124 133 132 131 154 123 144 156 181 194 165 178 181 178 174 150 193 191 207 161 139 146 152 176 193 142 171 210 239 281 359 373 259 197 139 137 136 143 152 118 128 156 146 126 125 135 114 115 147 106 155 115 114 117 117 122 123 136 150 137 116 125 119 124 147 123 138 144 152 116 146 119 133 112 118 127 165 148 150 126 134 111 121 123 113 116 114 113 120 102 126 116 143 110 99 114 106 106 118 115 111 102 103 97 113 119 113 139 114 125 104 106 110 110 114 115 129 110 148 151 106 115 94 111 112 115 101 105 103 107 120 121 110 117 109 105 104 114 102 134 108 109 107 126 128 136 117 121 120 145 151 156 190 175 183 168 169 219 267 366 447 549 771 830 969 941 730 582 419 387 367 321 300 329 365 462 620 835 1092 1254 1455 1356 1049 720 511 371 297 241 235 188 165 150 140 157 131 147 113 117 132 113 128 128 127 116 128 115 115 135 155 140 130 130 162 146 159 129 115 104 106 98 103 104 106 107 83 101 86 121 114 114 133 139 191 195 209 184 199 204 258 299 267 200 166 141 119 107 84 105 106 85 143 112 106 122 124 121 114 158 194 225 332 374 453 405 466 459 430 324 266 176 176 129 132 119 110 105 91 89 99 92 81 82 98 91 76 93 78 104 75 93 77 92 90 105 93 119 127 160 177 111 102 122 90 92 115 115 110 91 80 76 84 71 105 85 109 118 155 172 179 174 145 153 172 181 166 146 86 90 91 105 118 83 81 92 118 133 184 235 221 166 136 104 118 80 89 91 83 83 89 75 90 95 85 111 146 136 130 133 150 162 214 229 268 247 190 167 118 94 83 80 53 79 72 73 80 58 60 75 81 80 121 138 167 173 148 101 85 90 80 74 58 61 75 69 63 92 78 68 87 76 74 64 80 87 75 78 97 67 91 84 74 70 84 76 65 79 71 91 91 67 103 100 116 137 102 129 106 125 137 197 193 219 239 286 381 430 533 746 796 896 814 711 566 399 309 247 202 200 168 185 146 124 107 110 80 78 85 93 48 75 77 70 84 68 72 67 51 85 74 74 73 66 72 63 58 66 70 64 55 81 67 61 72 63 54 72 70 108 81 81 88 77 86 90 92 103 132 138 146 184 174 163 180 171 134 128 105 111 109 86 74 60 71 66 66 77 42 73 72 60 72 70 52 52 64 62 65 80 90 58 81 81 59 66 50 64 78 52 57 55 59 47 75 56 61 61 49 56 66 66 65 57 67 45 44 59 57 67 41 58 49 54 55 63 53 60 56 54 53 40 39 52 57 66 65 54 66 46 53 50 60 63 59 64 74 57 72 71 67 63 59 71 55 75 74 77 78 73 79 90 75 90 81 84 87 86 100 130 156 185 175 196 186 159 136 143 88 83 82 77 67 100 80 102 106 105 105 114 126 118 134 207 238 260 350 354 349 345 370 355 377 425 546 606 658 685 645 590 471 398 329 304 215 186 146 126 105 115 107 97 86 87 87 69 61 86 83 74 95 88 100 113 120 142 133 154 133 140 103 115 95 70 80 79 66 78 78 57 66 60 73 51 59 50 72 52 54 48 61 35 52 36 46 59 62 54 62 60 52 47 56 60 35 70 53 51 57 74 48 58 59 57 70 83 65 64 46 55 50 44 55 32 45 43 43 55 61 55 68 48 47 58 53 49 48 30 56 48 35 50 44 50 45 60 42 42 45 45 49 37 44 31 39 46 44 47 50 52 48 55 53 62 59 52 50 44 57 60 61 46 57 55 75 67 58 79 74 84 88 102 117 156 183 224 237 221 215 189 189 129 129 100 101 93 76 104 77 84 70 94 59 64 98 94 107 108 124 138 143 111 82 107 72 59 72 66 57 58 70 66 61 66 46 60 53 40 57 52 49 50 72 88 62 89 74 94 85 78 107 117 131 136 96 82 88 93 93 66 74 58 74 79 53 54 71 58 63 78 83 97 92 95 91 97 96 108 102 88 73 58 67 54 55 53 66 57 55 51 59 46 41 49 53 54 65 60 60 53 47 52 50 47 44 39 50 49 43 35 40 47 40 55 60 53 35 37 43 47 44 51 47 55 51 44 38 48 36 47 36 46 52 36 52 57 44 36 61 46 36 45 59 86 67 75 77 67 79 48 65 63 58 58 62 44 58 51 45 59 48 32 39 37 40 38 50 34 48 46 49 66 40 52 55 51 55 46 51 69 55 58 79 81 87 99 105 127 127 157 153 169 177 183 150 154 162 136 114 113 88 91 75 52 66 46 63 52 49 52 73 66 66 68 84 86 94 105 77 75 84 70 68 71 50 70 74 68 76 56 71 45 57 75 59 74 60 64 59 60 60 60 49 44 55 54 55 44 40 48 38 58 37 33 45 41 39 38 56 46 49 55 49 57 68 37 46 38 55 45 46 43 49 48 38 41 32 46 59 34 43 51 46 41 39 35 22 39 33 39 35 42 39 34 38 33 40 63 60 48 63 46 55 54 41 53 48 49 58 54 63 51 68 74 75 87 81 135 125 155 171 164 138 130 124 107 99 94 82 65 74 74 68 46 64 38 49 60 50 62 63 61 57 59 58 54 81 57 70 69 63 81 67 71 48 50 41 44 38 34 58 51 44 38 41 43 41 44 37 39 35 48 34 45 37 38 37 44 44 48 53 39 46 48 61 67 45 47 56 49 53 52 55 50 45 53 45 43 41 49 32 39 48 33 39 42 42 31 46 40 34 43 58 48 54 43 61 45 44 60 37 51 33 39 41 48 37 35 37 31 40 36 53 38 32 40 33 48 47 56 36 42 36 41 41 57 43 31 46 49 64 59 51 65 63 75 79 81 102 85 96 82 72 96 90 78 87 111 95 101 111 103 101 83 84 90 66 72 80 95 75 73 92 91 109 105 118 92 108 122 127 155 142 141 154 187 197 167 134 145 132 109 110 89 100 74 73 64 76 76 59 66 64 65 74 73 57 70 49 62 77 70 70 63 62 59 61 54 48 51 49 47 40 30 39 35 50 35 43 30 32 38 34 26 37 43 46 48 36 40 24 43 44 35 29 39 48 36 30 33 46 43 37 28 41 36 28 37 31 31 35 33 32 36 31 31 27 31 39 30 27 33 32 40 40 44 47 44 38 41 42 58 42 46 45 47 54 63 48 65 65 69 57 80 80 71 69 64 66 59 66 54 48 37 55 49 34 37 36 42 37 57 48 32 41 41 48 32 38 43 39 27 27 39 39 27 29 27 32 33 29 33 35 31 27 24 39 44 44 38 37 29 58 28 30 33 33 39 49 31 58 52 41 54 47 39 45 37 51 39 37 31 46 33 19 51 27 35 30 48 45 40 40 24 24 45 43 34 35 31 53 48 36 36 44 32 40 37 52 33 33 44 36 32 34 19 48 31 32 58 33 35 36 43 34 37 56 43 28 30 23 45 44 24 35 41 40 24 32 43 36 36 36 45 40 39 50 42 39 52 51 63 45 50 71 76 82 97 85 100 98 83 81 69 70 65 78 52 46 65 48 62 32 46 48 43 39 37 53 37 44 62 53 57 46 52 46 51 70 52 50 66 71 61 75 82 66 65 58 57 63 46 57 46 46 51 47 47 35 47 54 54 64 48 51 48 47 59 49 50 42 56 40 43 36 43 38 58 45 50 44 40 42 37 47 40 45 44 58 43 40 36 43 35 44 47 35 40 44 48 40 43 34 45 35 32 38 36 29 42 44 57 32 28 29 36 40 33 41 36 42 43 39 37 41 32 28 32 40 38 43 27 39 43 46 45 39 41 27 51 44 44 45 43 39 48 55 53 40 35 44 63 54 57 59 69 65 58 66 102 91 81 91 92 100 102 90 83 82 80 72 64 69 71 59 77 61 57 50 44 58 54 55 48 71 65 69 79 74 78 88 80 72 51 72 64 56 70 61 57 45 38 46 43 50 44 39 48 41 41 44 31 51 22 32 47 42 31 29 40 42 38 37 24 37 48 40 33 41 40 31 31 31 36 33 29 30 50 39 49 35 36 31 41 32 50 50 35 36 32 39 41 41 44 41 34 35 34 31 35 33 34 38 33 37 30 38 29 35 36 30 31 32 39 33 36 42 27 30 43 37 34 39 30 30 51 29 29 46 38 41 59 59 60 67 76 52 63 68 47 55 69 64 63 47 59 63 61 59 54 50 48 55 71 43 48 43 37 58 53 45 47 43 44 37 46 43 71 31 74 71 69 84 88 78 72 71 76 69 61 75 76 78 74 61 58 62 47 57 61 51 46 46 57 41 49 52 45 59 46 54 42 50 52 40 39 33 39 43 60 35 44 32 42 22 31 43 34 35 51 39 39 37 36 44 36 33 37 35 37 31 40 29 38 34 41 43 43 39 48 34 40 44 36 42 45 48 39 55 27 37 33 45 35 28 37 40 48 41 35 38 29 38 40 38 42 27 50 37 53 23 32 45 41 37 35 46 38 38 48 45 37 53 57 45 64 42 50 65 70 52 45 51 61 66 71 59 50 48 43 52 55 42 43 61 50 59 41 54 48 51 42 50 46 42 54 42 51 49 49 52 40 30 50 49 38 29 45 36 31 50 41 43 34 41 45 39 39 34 51 25 37 46 53 46 35 37 49 47 48 49 43 58 42 48 43 40 41 47 38 36 55 36 44 38 56 39 43 47 50 38 34 51 38 50 40 51 47 42 41 39 66 39 47 41 54 43 52 64 45 53 59 43 52 76 56 50 56 43 34 40 53 41 35 32 39 34 35 32 27 35 55 41 44 46 51 48 48 40 44 34 35 53 52 56 38 48 59 47 58 52 55 43 64 60 42 63 73 74 66 76 79 84 68 68 74 81 55 70 77 73 65 58 81 61 63 56 64 59 37 49 63 47 74 43 63 63 60 60 69 67 72 74 58 72 61 76 62 81 65 47 66 57 58 72 78 58 67 69 68 53 65 55 75 51 41 38 41 42 56 50 52 42 50 52 41 49 54 56 39 37 39 61 52 42 62 34 45 29 26 39 35 38 42 42 41 29 33 38 30 48 37 36 47 40 37 48 42 30 36 32 42 38 36 34 37 33 36 36 35 42 32 29 37 44 36 38 46 40 44 29 24 33 35 48 37 24 34 50 40 42 39 39 32 37 36 30 42 36 36 38 39 33 38 34 44 27 38 33 28 38 34 27 39 47 43 36 48 35 43 50 52 58 38 43 37 44 39 38 55 38 48 47 36 56 40 39 37 49 51 46 36 37 31 47 48 46 32 32 52 40 42 32 43 35 48 30 31 43 16 49 41 36 47 38 37 37 37 40 35 41 26 44 34 40 38 44 43 42 28 35 54 37 32 31 50 40 25 26 40 40 27 42 47 44 37 45 41 38 24 34 40 41 45 43 39 33 50 37 34 50 41 50 43 38 44 48 43 47 37 26 42 35 52 44 40 50 55 55 55 40 52 48 42 46 62 52 51 55 39 67 51 48 50 69 53 49 50 63 53 53 63 65 52 54 62 48 39 54 58 43 45 54 38 45 41 46 39 28 47 60 52 44 58 53 51 39 48 39 43 54 53 52 49 39 51 60 47 66 62 61 57 53 53 62 61 72 72 54 58 73 67 53 61 48 66 67 59 52 62 46 65 65 65 45 58 56 62 65 65 64 60 53 57 65 52 61 50 74 70 66 61 55 55 63 54 55 63 60 55 56 61 54 60 88 71 75 61 48 53 69 58 83 84 57 74 69 62 46 70 71 57 67 54 59 67 48 70 68 54 62 65 47 51 51 62 60 49 67 57 46 66 46 45 59 44 65 57 34 60 53 67 54 49 44 53 46 60 44 38 57 47 53 44 56 46 65 50 44 62 62 62 47 61 55 64 53 58 52 42 42 66 53 48 74 45 60 65 66 77 53 77 52 52 62 64 61 43 62 60 54 65 47 60 58 57 52 77 63 63 54 42 61 70 50 59 89 55 63 66 53 54 50 60 56 55 56 50 48 47 63 72 59 45 48 57 51 68 63 50 63 68 60 66 71 56 74 66 63 64 57 60 71 87 82 72 74 79 75 123 90 82 90 87 82 88 91 98 105 106 74 99 94 69 91 103 105 97 92 100 87 102 96 81 95 85 85 75 90 70 72 72 87 111 96 77 90 79 75 93 93 74 80 70 92 83 75 75 80 89 92 87 78 65 75 75 74 76 100 92 79 79 78 82 79 67 82 61 84 93 78 59 69 77 85 70 85 77 82 63 100 69 96 92 91 69 73</counts>
			</dataPoints>
		</scan>
	</xrdMeasurement>
</xrdMeasurements>