File: dataset/precursor_mixture/NaAlO2-1.5H2O_In2O3_Ga2O3_Bi2O3-beta.12-min.xrdml
<?xml version="1.0"?>
<xrdMeasurements xmlns="http://www.xrdml.com/XRDMeasurement/2.2" xmlns:xsi="http://www.w3.org/2001/XMLSchema-instance" xsi:schemaLocation="http://www.xrdml.com/XRDMeasurement/2.2 http://www.xrdml.com/XRDMeasurement/2.2/XRDMeasurement.xsd" status="Completed" recordIdentifier="{3178E672-B818-496E-A59E-BC0853348235}">
	<comment>
		<entry/>
	</comment>
	<sample type="To be analyzed">
		<id>dara-43-2</id>
		<name></name>
		<preparedBy></preparedBy>
	</sample>
	<xrdMeasurement measurementType="Scan" status="Completed" sampleMode="Reflection">
		<usedWavelength intended="K-Alpha 1">
			<kAlpha1 unit="Angstrom">1.5405980</kAlpha1>
			<kAlpha2 unit="Angstrom">1.5444260</kAlpha2>
			<kBeta unit="Angstrom">1.3922500</kBeta>
			<ratioKAlpha2KAlpha1>0.5000</ratioKAlpha2KAlpha1>
		</usedWavelength>
		<incidentBeamPath>
			<radius unit="mm">145.00</radius>
			<xRayTube id="1010048" name="Empyrean Cu LFF HR (9430 033 7310x) DK430614">
				<tension unit="kV">40.0</tension>
				<current unit="mA">15.0</current>
				<anodeMaterial>Cu</anodeMaterial>
				<focus type="Line">
					<length unit="mm">12.0</length>
					<width unit="mm">0.4</width>
					<takeOffAngle unit="deg">6.0</takeOffAngle>
				</focus>
			</xRayTube>
			<filter id="20010004" name="Beta-filter Nickel">
				<material>Ni</material>
				<thickness unit="mm">0.020</thickness>
			</filter>
			<sollerSlit id="21010002" name="Soller slits 0.04 rad.">
				<opening unit="rad">0.0400</opening>
			</sollerSlit>
			<mask id="22031000" name="Fixed mask 13 mm">
				<width unit="mm">9.00</width>
			</mask>
			<divergenceSlit id="22120001" name="Divergence slit 1°" xsi:type="fixedDivergenceSlitType">
				<distanceToSample unit="mm">50.00</distanceToSample>
				<height unit="mm">1.52</height>
			</divergenceSlit>
		</incidentBeamPath>
		<beamKnife id="29030100" name="Beam knife low"/>
		<sampleMovement xsi:type="spinningSampleMovementType">
			<spinnerRevolutionTime unit="seconds">1.0</spinnerRevolutionTime>
		</sampleMovement>
		<diffractedBeamPath>
			<radius unit="mm">145.00</radius>
			<antiScatterSlit id="22090040" name="AS slit 9 mm" xsi:type="fixedAntiScatterSlitType">
				<height unit="mm">9.00</height>
			</antiScatterSlit>
			<sollerSlit id="21020003" name="Large Soller slits 0.04 rad.">
				<opening unit="rad">0.0400</opening>
			</sollerSlit>
			<filter id="20030001" name="Large beta-filter Nickel">
				<material>Ni</material>
				<thickness unit="mm">0.020</thickness>
			</filter>
			<detector id="7010019" name="PIXcel1D-Medipix3 detector" xsi:type="rtmsDetectorType">
				<phd unit="keV">
					<lowerLevel>4.0</lowerLevel>
					<upperLevel>11.3</upperLevel>
				</phd>
				<mode>Scanning</mode>
				<activeLength unit="deg">5.020</activeLength>
			</detector>
		</diffractedBeamPath>
		<scan appendNumber="0" mode="Continuous" scanAxis="Gonio" status="Completed">
			<header>
				<startTimeStamp>2024-02-18T15:39:47-08:00</startTimeStamp>
				<endTimeStamp>2024-02-18T15:52:15-08:00</endTimeStamp>
				<author>
					<name>AutomatedUser</name>
				</author>
				<source>
					<applicationSoftware version="1.4b (28)">PANalytical Aeris Instrument Suite</applicationSoftware>
					<instrumentControlSoftware version="2.0.0 20210224">AERIS</instrumentControlSoftware>
					<instrumentID>950485</instrumentID>
				</source>
			</header>
			<dataPoints>
				<positions axis="2Theta" unit="deg">
					<startPosition>9.99043322</startPosition>
					<endPosition>100.09495370</endPosition>
				</positions>
				<positions axis="Omega" unit="deg">
					<startPosition>4.99521661</startPosition>
					<endPosition>50.04747685</endPosition>
				</positions>
				<commonCountingTime unit="seconds">18.249</commonCountingTime>
				<counts unit="counts">3632 3742 3611 3702 3733 3715 3636 3576 3580 3626 3711 3677 3590 3646 3830 3620 3576 3587 3605 3604 3550 3625 3577 3580 3679 3679 3469 3484 3540 3604 3613 3539 3571 3490 3535 3434 3507 3518 3473 3538 3560 3444 3514 3482 3584 3554 3363 3521 3394 3333 3505 3530 3466 3555 3474 3465 3419 3322 3473 3423 3414 3291 3298 3366 3443 3477 3416 3324 3432 3483 3392 3324 3307 3358 3317 3435 3400 3304 3273 3328 3350 3295 3344 3299 3360 3371 3381 3334 3365 3441 3305 3355 3263 3233 3252 3271 3263 3301 3161 3226 3303 3235 3216 3301 3288 3148 3247 3188 3165 3208 3246 3217 3149 3171 3245 3079 3173 3142 3180 3085 3176 3149 3021 3245 3152 3074 3227 3124 3196 3191 3138 3159 3179 3034 3144 3220 3113 3087 3082 3075 3020 3072 3103 3043 2995 2995 3125 3039 3075 3091 3038 3033 3016 3055 3073 2948 3038 2958 2881 3099 3005 2998 3007 2949 2916 3046 2998 2941 2936 2975 2916 3052 2971 2953 2933 2994 2931 2966 3013 3014 2898 2962 2869 3041 2948 2962 2884 2902 2942 2898 2937 2969 2823 2907 2890 2890 2855 2863 2812 2959 2897 2954 2899 2774 2795 2865 2818 2959 2744 2920 2902 2818 2844 2839 2801 2788 2860 2805 2932 2743 2828 2814 2824 2841 2788 2849 2813 2840 2929 2791 2835 2765 2734 2866 2748 2901 2788 2962 2778 2763 2733 2687 2747 2735 2601 2717 2682 2687 2709 2692 2697 2756 2609 2806 2688 2760 2644 2745 2648 2728 2580 2729 2658 2748 2596 2667 2561 2609 2714 2683 2733 2761 2661 2707 2581 2661 2605 2712 2597 2648 2619 2652 2666 2643 2707 2675 2667 2540 2643 2700 2579 2650 2613 2560 2650 2570 2660 2633 2654 2621 2684 2555 2609 2536 2599 2576 2529 2577 2546 2537 2539 2549 2536 2572 2601 2551 2583 2523 2524 2521 2518 2590 2521 2597 2510 2500 2563 2536 2544 2571 2537 2497 2547 2481 2547 2454 2574 2456 2456 2528 2616 2525 2474 2373 2467 2480 2452 2501 2555 2435 2535 2523 2403 2534 2451 2397 2588 2439 2358 2536 2508 2489 2446 2606 2487 2470 2412 2522 2432 2598 2345 2440 2464 2436 2411 2453 2409 2445 2474 2354 2402 2428 2344 2418 2366 2381 2395 2428 2397 2445 2455 2469 2386 2514 2384 2459 2370 2426 2497 2353 2473 2406 2439 2385 2485 2409 2509 2423 2400 2310 2432 2327 2386 2362 2379 2391 2454 2362 2372 2520 2415 2337 2405 2402 2417 2326 2426 2386 2393 2488 2417 2336 2438 2329 2324 2381 2397 2317 2397 2330 2325 2385 2357 2361 2297 2422 2389 2285 2297 2287 2309 2404 2314 2348 2385 2306 2385 2367 2283 2324 2326 2250 2298 2296 2322 2312 2294 2334 2335 2280 2323 2273 2318 2215 2390 2336 2293 2370 2306 2221 2353 2339 2394 2364 2348 2351 2302 2343 2327 2334 2337 2284 2294 2302 2311 2370 2336 2314 2288 2220 2229 2289 2347 2273 2301 2337 2321 2379 2387 2387 2379 2418 2310 2435 2381 2347 2546 2421 2403 2344 2387 2372 2410 2404 2422 2538 2431 2453 2418 2333 2368 2299 2358 2385 2320 2363 2311 2318 2349 2294 2328 2276 2340 2248 2289 2355 2373 2302 2316 2288 2316 2324 2330 2241 2231 2331 2375 2279 2296 2462 2321 2355 2347 2395 2426 2422 2377 2407 2483 2442 2609 2483 2489 2567 2480 2646 2657 2495 2558 2394 2500 2347 2327 2359 2367 2338 2304 2337 2349 2231 2230 2247 2321 2229 2259 2330 2377 2390 2371 2283 2442 2341 2503 2434 2430 2456 2522 2556 2550 2599 2640 2774 2826 2997 2969 2982 2912 2858 2797 2824 2581 2591 2409 2395 2427 2364 2363 2288 2288 2348 2253 2340 2200 2361 2383 2384 2312 2303 2333 2269 2270 2212 2209 2079 2168 2176 2120 2143 2130 2105 2152 2109 2069 2047 2218 2044 2196 2070 2174 2130 2100 2128 2149 2147 2213 2180 2206 2182 2076 2130 2100 2166 2123 2094 2095 2131 2135 2165 2106 2116 2171 2202 2100 2132 2092 2087 2089 2154 2034 2082 2105 2186 2179 2121 2093 2118 2081 2149 2107 2144 2215 2169 2160 2155 2210 2004 2040 2022 2017 2135 1997 2034 1972 2064 2007 2025 2126 2013 2064 2064 2106 1982 2074 2060 2023 2015 1960 2089 2005 2093 2055 1968 2040 1990 1981 1969 2085 2054 1969 2014 2060 2074 2121 1971 2025 2057 1930 2019 2107 2057 2065 2025 2036 1982 1983 1983 2003 2056 2131 2041 1996 2009 2039 2009 1968 2047 2004 2059 2028 1947 1991 2032 2073 1954 2035 2033 2067 2020 2006 2003 2053 1942 2014 2031 2116 2107 2016 2064 1978 2122 2023 2166 2079 2249 2134 2131 2209 2188 2122 2176 2150 2224 2318 2223 2409 2380 2346 2354 2488 2399 2570 2564 2656 2632 2750 2828 2824 2949 3093 3155 3241 3373 3444 3327 3500 3608 3612 3661 3515 3461 3577 3718 3611 3452 3305 3170 2918 2921 2811 2755 2575 2495 2369 2420 2374 2209 2203 2235 2172 2120 2173 2097 2086 2111 2045 2111 2113 1974 1984 1920 2014 1965 1923 1932 1909 1930 1965 1935 1950 2022 1917 1900 1852 1929 1808 1943 1898 1953 1922 1865 1886 1871 1829 1910 1830 1909 1754 1825 1821 1793 1884 1867 1874 1866 1862 1923 1862 1863 1878 1769 1913 1814 1839 1855 1860 1835 1879 1871 1892 1841 1848 1800 1835 1744 1896 1871 1811 1849 1835 1807 1918 1843 1702 1788 1805 1816 1808 1925 1768 1792 1765 1763 1856 1836 1764 1774 1753 1705 1838 1728 1733 1804 1748 1777 1771 1856 1876 1914 1777 1794 1790 1791 1868 1848 1858 1853 1848 1883 1953 1990 1896 1917 1955 2029 2041 2049 2030 2093 2087 2038 2140 2157 2104 2028 2052 1981 1971 1897 1817 1856 1899 1874 1853 1884 1823 1860 1819 1804 1888 1872 1971 1907 1968 1803 1994 1952 1961 2046 1977 1933 1989 1826 1835 1817 1711 1809 1784 1772 1841 1793 1841 1779 1768 1738 1811 1877 1701 1812 1789 1719 1742 1753 1780 1863 1823 1828 1835 1811 1830 1883 1869 1893 1925 1920 2016 2034 1991 1996 1976 2007 2091 2018 2016 2051 2014 2178 2076 2243 2247 2286 2424 2479 2625 2721 2909 2982 3212 3464 3554 3801 4113 4382 4523 4669 4772 4940 4873 4679 4407 4070 3719 3376 3147 2792 2499 2354 2176 2040 1987 1896 1834 1850 1772 1810 1772 1699 1762 1753 1719 1719 1737 1666 1738 1626 1702 1758 1719 1733 1698 1709 1682 1728 1695 1712 1694 1676 1633 1648 1685 1615 1689 1679 1654 1603 1609 1590 1653 1616 1662 1645 1629 1548 1728 1559 1658 1676 1676 1690 1643 1664 1618 1617 1644 1576 1675 1610 1592 1601 1506 1576 1639 1590 1554 1556 1549 1530 1655 1601 1500 1617 1584 1636 1565 1636 1635 1579 1526 1618 1635 1640 1588 1504 1651 1523 1585 1629 1515 1559 1617 1466 1642 1577 1642 1585 1582 1586 1656 1558 1588 1546 1571 1596 1526 1611 1570 1569 1575 1564 1551 1575 1603 1612 1615 1666 1534 1647 1613 1641 1632 1706 1707 1642 1581 1543 1637 1603 1663 1582 1532 1552 1615 1545 1503 1546 1528 1522 1541 1611 1476 1595 1557 1553 1522 1569 1624 1610 1527 1534 1542 1491 1529 1462 1541 1487 1459 1476 1493 1477 1537 1509 1527 1508 1478 1598 1497 1561 1499 1522 1506 1414 1496 1556 1482 1530 1518 1470 1521 1489 1558 1521 1544 1441 1540 1476 1597 1529 1480 1523 1589 1504 1608 1485 1489 1556 1520 1515 1573 1528 1514 1577 1464 1580 1565 1523 1593 1546 1561 1655 1523 1489 1576 1528 1476 1525 1513 1541 1518 1479 1524 1468 1463 1570 1500 1570 1511 1534 1577 1549 1494 1472 1477 1462 1494 1567 1584 1563 1500 1558 1526 1485 1513 1520 1573 1586 1461 1567 1508 1554 1460 1547 1526 1553 1510 1495 1482 1509 1505 1578 1467 1492 1495 1482 1468 1497 1497 1564 1513 1437 1446 1504 1513 1444 1539 1433 1511 1518 1458 1423 1534 1463 1472 1489 1461 1454 1460 1494 1475 1517 1478 1450 1495 1558 1485 1464 1472 1486 1441 1454 1403 1448 1463 1511 1517 1498 1462 1531 1461 1433 1470 1501 1469 1504 1495 1527 1477 1501 1565 1587 1606 1618 1635 1671 1721 1725 1733 1769 1774 1755 1727 1720 1663 1626 1600 1622 1564 1506 1487 1510 1441 1431 1534 1472 1459 1462 1532 1403 1441 1496 1474 1511 1520 1474 1510 1528 1571 1564 1516 1745 1599 1648 1776 1815 1768 1901 1875 2032 2160 2171 2208 2152 2369 2461 2541 2509 2521 2545 2390 2341 2162 2153 2075 1895 1885 1832 1729 1774 1585 1601 1540 1588 1506 1560 1461 1534 1473 1457 1468 1551 1524 1405 1470 1482 1518 1442 1449 1441 1361 1510 1452 1389 1365 1394 1464 1464 1429 1438 1354 1440 1454 1432 1457 1427 1462 1421 1405 1392 1422 1448 1406 1470 1443 1483 1449 1432 1434 1443 1459 1369 1471 1386 1418 1435 1431 1403 1420 1443 1424 1423 1360 1390 1469 1541 1388 1427 1395 1519 1452 1506 1482 1493 1517 1551 1541 1536 1586 1718 1654 1690 1733 1688 1705 1697 1641 1706 1666 1664 1566 1682 1547 1662 1576 1736 1659 1698 1787 1707 1792 1706 1812 1748 1853 1798 1845 1806 1830 1832 1815 1754 1815 1804 1848 1745 1791 1819 1880 1784 1955 1962 1892 1902 1821 1922 1919 1973 2002 2039 2031 2046 2087 2121 2235 2218 2285 2346 2273 2373 2384 2441 2524 2491 2544 2507 2527 2548 2606 2548 2579 2641 2624 2618 2720 2739 2754 2727 2794 2810 2858 2996 2942 3133 3098 3284 3392 3600 3820 4082 4376 4640 5154 5521 6072 6717 7549 8346 9532 10859 12527 14111 16200 18273 20754 23758 27388 30243 34298 37541 41408 44342 46367 46963 45895 43324 40462 36940 33358 29911 26863 23225 19731 16374 13316 11033 9133 7568 6602 5609 4962 4459 4164 3798 3595 3444 3267 3136 2935 2861 2748 2804 2660 2576 2454 2386 2331 2270 2261 2235 2179 2032 2086 1993 1912 1889 1946 1873 1772 1787 1806 1784 1726 1798 1726 1728 1749 1629 1683 1713 1627 1704 1635 1645 1639 1602 1649 1717 1604 1610 1586 1633 1540 1546 1649 1552 1529 1607 1536 1482 1552 1599 1540 1515 1558 1526 1614 1515 1582 1529 1530 1521 1543 1544 1565 1535 1596 1580 1541 1518 1543 1526 1542 1626 1586 1640 1636 1603 1637 1605 1724 1665 1718 1698 1707 1834 1772 1812 1821 1868 1894 1819 1876 1794 1803 1748 1732 1762 1742 1724 1664 1736 1659 1689 1728 1716 1684 1734 1724 1656 1793 1671 1730 1752 1700 1760 1846 1833 1827 1835 1909 1784 1840 1916 1921 1911 1926 1966 1981 2017 1993 1936 2031 2029 2074 2067 2039 2078 2095 2181 2233 2275 2282 2264 2343 2421 2457 2475 2543 2582 2534 2717 2759 2884 2930 3143 3200 3147 3329 3425 3367 3676 3721 3829 3927 4031 4112 4261 4291 4564 4541 4794 4747 4733 4882 4986 5260 5230 5263 5546 5766 5941 5954 6268 6442 6803 7171 7420 7852 8131 8486 8816 9030 9383 9476 10029 10487 11023 11456 11953 12839 13560 14200 15258 16193 17629 19024 20894 22823 25149 27630 30058 32521 35011 36354 37303 36271 33909 30837 27912 25106 23569 21276 19207 16727 14210 11814 9554 8028 6909 5897 5278 4757 4498 4217 4203 3892 3816 3659 3519 3516 3363 3362 3203 3137 3160 3122 2996 3039 2793 2871 2750 2703 2706 2696 2531 2607 2540 2533 2578 2517 2540 2593 2469 2515 2513 2494 2526 2438 2512 2583 2563 2535 2556 2587 2651 2613 2642 2677 2755 2735 2780 2897 2922 2988 2941 3115 3057 3313 3254 3267 3463 3377 3755 3852 3952 3915 4117 4276 4569 4607 4906 5238 5463 5642 5986 6308 6650 7020 7365 7632 8137 8627 9052 9376 9864 10464 10789 11246 11676 12203 12831 12872 13161 13120 12681 12050 11288 10703 10089 9327 8901 8270 7536 6818 6240 5588 5195 4778 4405 4023 3902 3762 3507 3359 3239 3131 2924 2980 2772 2771 2637 2758 2641 2552 2485 2390 2440 2252 2234 2218 2280 2253 2174 2151 2127 2175 2039 2065 2137 1995 2155 1943 2023 1986 2056 2032 2029 2094 2083 2098 2115 2042 2028 2191 2247 2278 2417 2486 2432 2665 2849 2953 3229 3380 3795 4068 4472 4830 5425 6099 6859 7618 8598 9495 10563 11446 12471 12909 13249 12848 12361 11619 10650 10128 9405 8516 8177 7186 6599 5732 4997 4290 3726 3326 3004 2792 2679 2517 2422 2374 2283 2216 2198 2273 2213 2237 2183 2221 2128 2289 2319 2288 2384 2389 2464 2599 2609 2571 2695 2519 2481 2573 2597 2485 2578 2573 2445 2503 2353 2326 2255 2212 2132 2139 2150 2102 2064 1996 1917 1943 1972 1908 1938 1870 2010 1963 1983 1933 1927 2055 2075 2006 2128 2095 2183 2235 2163 2249 2233 2298 2248 2087 2057 1960 1933 1886 1871 1832 1743 1657 1626 1571 1589 1539 1531 1532 1502 1506 1426 1475 1469 1439 1435 1402 1437 1475 1393 1430 1449 1499 1539 1444 1507 1422 1518 1516 1485 1575 1507 1586 1589 1559 1538 1493 1488 1434 1547 1470 1428 1458 1452 1482 1467 1404 1449 1397 1471 1425 1465 1462 1544 1546 1599 1617 1695 1706 1745 1830 1847 1906 1760 1767 1729 1660 1608 1679 1598 1635 1600 1486 1467 1496 1511 1510 1448 1367 1423 1464 1468 1465 1539 1551 1537 1477 1501 1565 1523 1487 1611 1629 1630 1580 1644 1587 1473 1632 1675 1573 1634 1572 1611 1616 1691 1685 1688 1747 1756 1809 1913 2014 2173 2309 2352 2412 2663 2691 2760 2906 2972 2918 2992 3014 3031 2937 3117 3080 3102 3230 3240 3362 3354 3561 3442 3492 3545 3579 3743 3715 3818 3797 3877 3786 3732 3763 3797 3800 3742 3854 3877 4078 4041 4147 4492 4863 5297 5769 6557 7047 7796 8798 9426 10166 10446 10540 9958 9319 8440 7643 6991 6918 6632 6140 5648 5108 4425 3882 3219 2878 2498 2433 2250 2278 2176 2252 2199 2255 2315 2225 2107 2000 1954 1996 1821 1856 1842 1781 1690 1716 1553 1561 1608 1490 1438 1312 1424 1368 1377 1299 1275 1391 1251 1255 1255 1234 1256 1247 1193 1220 1238 1281 1259 1226 1265 1275 1312 1295 1337 1254 1289 1231 1226 1221 1226 1272 1233 1221 1226 1223 1204 1176 1137 1223 1171 1183 1175 1086 1096 1114 1193 1208 1138 1178 1205 1082 1174 1095 1084 1179 1166 1147 1125 1091 1107 1117 1111 1153 1123 1078 1202 1102 1155 1210 1127 1115 1093 1155 1140 1169 1205 1166 1075 1153 1141 1143 1142 1197 1143 1205 1171 1177 1123 1158 1194 1171 1243 1103 1182 1176 1200 1194 1192 1257 1198 1178 1194 1261 1255 1242 1286 1305 1236 1358 1258 1312 1342 1291 1314 1342 1284 1431 1372 1442 1454 1413 1442 1499 1448 1582 1551 1627 1612 1636 1718 1695 1674 1779 1682 1754 1779 1747 1779 1824 1783 1860 1908 1765 1748 1803 1764 1769 1783 1820 1868 1753 1826 1773 1854 1948 1871 2069 2174 2283 2379 2441 2663 2758 2938 2974 3014 2890 2810 2512 2438 2236 2302 2242 2275 2138 2018 1932 1801 1621 1579 1508 1469 1413 1490 1383 1457 1406 1286 1413 1434 1448 1461 1448 1486 1402 1451 1505 1518 1494 1459 1553 1497 1546 1499 1610 1646 1615 1621 1766 1698 1720 1910 1820 1857 1943 2027 2073 1999 2136 2220 2288 2389 2478 2448 2612 2641 2560 2555 2693 2588 2575 2506 2580 2539 2478 2454 2353 2286 2225 2149 2091 2128 2008 1973 1851 1866 1779 1745 1693 1705 1643 1561 1590 1513 1600 1605 1573 1640 1601 1592 1575 1651 1718 1648 1632 1618 1549 1421 1450 1408 1441 1405 1433 1383 1282 1325 1292 1199 1193 1190 1235 1230 1317 1256 1349 1325 1380 1386 1499 1537 1561 1526 1573 1488 1457 1450 1325 1328 1331 1314 1308 1256 1314 1189 1151 1093 1030 1118 1027 1121 976 1049 995 1014 905 981 965 976 939 1023 948 972 1010 1000 956 963 987 989 1015 948 954 988 991 985 930 964 949 987 917 938 949 985 982 1051 990 1005 931 1064 1020 1051 1037 1041 1038 1194 1130 1222 1209 1340 1351 1336 1337 1359 1290 1218 1208 1164 1233 1247 1195 1207 1176 1139 1135 1202 1133 1167 1037 1063 1089 1058 1095 1066 1089 1062 1038 1116 1042 1108 1078 1114 1056 1130 1062 1094 1097 977 1063 1011 1009 992 973 952 973 1013 958 904 983 913 954 955 957 937 956 926 943 958 970 982 909 943 926 950 946 981 936 928 900 893 888 892 889 904 891 892 875 877 925 916 883 981 909 936 874 885 936 862 912 892 889 863 847 938 901 889 882 903 923 885 935 878 941 938 924 875 880 891 962 878 910 924 855 923 929 980 895 957 955 970 974 1002 1004 992 1032 1009 1028 1048 1092 1154 1172 1204 1271 1310 1392 1404 1538 1631 1633 1711 1719 1647 1550 1494 1434 1398 1410 1421 1468 1349 1401 1363 1232 1233 1203 1149 1217 1163 1134 1115 1174 1118 1152 1194 1142 1189 1185 1151 1166 1138 1141 1168 1166 1183 1115 1195 1221 1239 1247 1299 1390 1421 1611 1665 1766 1972 2185 2241 2341 2317 2423 2270 2172 1877 1883 1836 1825 1815 1713 1779 1853 1644 1610 1496 1444 1360 1315 1266 1254 1305 1224 1166 1148 1128 1146 1114 1179 1165 1070 1070 1088 1134 1119 1047 1078 1006 1025 1013 999 980 973 985 1005 982 936 971 907 985 956 991 1013 1029 1024 940 1007 918 928 982 976 924 990 880 957 934 935 917 967 961 945 908 959 951 954 1003 940 945 934 985 951 998 983 990 988 955 1033 1008 978 990 1015 1006 1033 1053 1046 1110 1125 1081 985 1116 1073 1059 1102 1146 1065 1120 1058 1056 1075 1106 1067 1089 1153 1112 1084 1083 1088 1079 1099 1072 1111 1022 1099 1068 1105 1006 995 1050 1027 988 962 957 958 946 913 928 990 955 961 956 997 923 995 942 912 945 988 1013 941 959 981 925 870 884 937 938 947 947 953 919 927 910 916 886 911 824 915 905 909 935 953 958 946 1016 1031 1061 1091 1079 1257 1232 1233 1257 1235 1147 1165 1112 1062 1034 1069 1023 1068 1117 1022 995 954 988 964 1021 857 848 828 946 862 918 844 898 879 905 899 919 890 886 873 917 886 917 819 863 867 900 865 825 850 859 884 856 864 899 902 879 835 867 873 875 958 945 930 965 951 890 923 961 960 973 950 978 992 991 1026 1073 1014 1003 1025 1064 1140 1029 1114 1129 1122 1050 1106 1057 1127 1128 1097 1116 1136 1071 1053 1132 1068 1029 1051 1072 1064 1070 1112 1042 1096 1047 1085 1063 1033 1108 1042 1120 1083 1050 1080 1035 1032 1070 1101 1024 1146 1135 1107 1178 1185 1276 1325 1273 1375 1406 1462 1466 1422 1426 1407 1442 1344 1277 1322 1344 1303 1316 1307 1338 1214 1234 1207 1201 1176 1151 1156 1174 1193 1126 1185 1161 1174 1141 1129 1179 1227 1213 1233 1275 1286 1243 1392 1408 1396 1635 1635 1857 2028 2173 2447 2636 2989 3431 3691 3817 4009 3876 3677 3383 3170 2979 2831 2802 2864 2936 2875 2996 2872 2751 2610 2368 2123 2061 1967 1902 1891 1866 1857 1849 1996 1793 1914 1942 2042 2081 2131 2095 2252 2284 2403 2656 2822 3001 3220 3674 4115 4645 5216 6121 6971 7964 9176 10240 11161 11768 11928 11807 11133 10127 9136 8482 7876 7742 7404 7571 7465 7374 6912 6424 5720 5087 4303 3745 3395 3036 2763 2568 2433 2241 2200 1966 1955 1869 1840 1730 1713 1621 1612 1611 1546 1571 1595 1475 1437 1426 1438 1412 1475 1481 1558 1637 1541 1635 1784 1765 1957 2124 2182 2362 2743 3024 3537 3971 4439 5062 5460 5807 6190 6059 5796 5316 4888 4488 4065 3998 3897 4031 3837 3960 3896 3666 3188 2895 2660 2345 2136 1912 1740 1551 1445 1433 1335 1285 1289 1233 1221 1179 1188 1090 1136 1057 1122 1053 1038 1077 1016 1051 948 986 977 1032 997 987 1007 954 939 925 957 978 956 871 926 910 874 910 922 942 899 911 905 890 890 947 904 975 935 921 947 938 888 876 887 850 892 888 863 901 833 912 888 861 838 890 896 880 934 881 895 904 879 845 887 853 949 825 935 896 910 882 939 910 950 939 949 903 936 929 978 966 968 978 964 968 974 995 966 1000 1009 1043 1050 1112 1128 1044 1100 1126 1147 1167 1152 1169 1240 1271 1298 1255 1343 1399 1518 1495 1576 1597 1693 1710 1626 1678 1629 1658 1678 1745 1721 1764 1822 1746 1796 1762 1797 1752 1876 1808 1782 1804 1761 1724 1683 1559 1575 1648 1619 1604 1479 1508 1378 1381 1395 1313 1337 1283 1279 1277 1274 1209 1164 1159 1092 1072 1088 1042 1032 1072 1115 1006 981 986 949 958 948 1004 1018 1028 1031 944 997 1018 1023 1058 1059 1026 1050 1070 1131 1146 1235 1309 1346 1430 1581 1607 1747 1817 1762 1770 1685 1576 1524 1445 1453 1466 1477 1426 1489 1490 1477 1480 1420 1374 1251 1319 1270 1247 1218 1221 1191 1155 1207 1194 1224 1143 1126 1114 1165 1173 1163 1131 1122 1083 1065 1063 992 1098 1060 1070 1095 1074 1046 983 1004 1045 1009 1038 1013 1024 1033 1054 1002 1068 1049 1028 987 1045 1017 1077 1078 1084 1118 1116 993 1019 981 1008 1021 1010 939 1043 959 969 971 926 970 986 926 966 971 917 952 924 898 1020 950 1026 975 953 1001 914 951 965 985 981 987 981 948 979 1014 1009 1000 1057 1010 1036 1090 1063 1112 1087 1089 1024 1061 1057 1061 1092 1124 1154 1101 1188 1153 1195 1222 1211 1198 1272 1228 1327 1311 1269 1388 1399 1450 1457 1508 1504 1538 1581 1646 1722 1755 1978 1924 2115 2240 2526 2705 3225 3721 4408 4961 5999 7068 8281 9506 10695 11448 11572 10989 10084 8629 7575 6468 5959 5708 5707 6138 6438 6743 6957 6785 6369 5508 4900 4251 3679 3332 3030 2926 2734 2464 2289 2095 1996 1970 1818 1751 1745 1769 1748 1655 1711 1547 1503 1436 1348 1246 1268 1176 1142 1081 1116 1149 1114 1043 1044 1029 975 1032 1007 1022 920 964 907 1021 1021 931 982 992 932 959 974 975 930 937 915 956 950 953 930 971 900 946 1002 947 1028 962 1051 1001 1022 1026 1056 1018 1023 1120 1144 1140 1067 1034 1027 1022 997 1007 951 977 987 966 960 976 1040 965 992 990 1013 924 973 945 903 937 945 965 930 906 938 917 909 918 915 896 973 964 955 912 947 920 947 981 963 879 916 924 944 1055 953 973 892 1001 984 961 937 943 1033 1042 1012 1106 1023 1131 1213 1357 1426 1429 1545 1548 1500 1493 1348 1279 1247 1315 1242 1280 1271 1318 1324 1357 1352 1360 1357 1287 1236 1107 1083 1092 1038 1036 1068 973 998 974 998 989 985 964 952 958 967 893 920 929 880 900 924 966 861 860 898 879 891 859 879 893 915 842 840 871 854 857 867 853 896 898 843 894 855 855 893 879 881 913 905 934 935 923 975 1000 937 964 1003 969 1039 999 1043 1082 1068 1095 1139 1160 1164 1185 1183 1244 1133 1152 1129 1081 1062 1069 1093 1090 1060 1100 1108 1108 1150 1086 1056 993 1050 1078 990 1035 1069 1049 1113 1080 1043 1109 1106 1103 1121 1104 1247 1176 1244 1241 1283 1239 1384 1426 1402 1541 1616 1621 1738 1840 2049 2186 2389 2777 2947 3536 4001 4400 4978 5597 6179 6667 6831 6743 6296 5836 5278 4633 4395 4152 3920 4047 4037 4137 4260 4363 4169 4065 3619 3253 2889 2614 2278 2062 1896 1818 1740 1571 1484 1478 1455 1412 1373 1337 1348 1253 1246 1194 1147 1185 1134 1157 1215 1164 1126 1163 1158 1124 1108 1107 1093 1127 1082 1077 1071 1068 1062 1045 1122 1070 1089 1121 1072 1105 1068 1129 1128 1092 1135 1162 1081 1199 1215 1211 1263 1274 1276 1358 1366 1451 1450 1509 1470 1450 1458 1418 1497 1541 1558 1540 1671 1637 1662 1818 1856 1951 2075 2170 2289 2396 2582 2816 3128 3609 3862 4625 5156 5989 7123 8093 9009 9809 10545 10702 10518 9831 8966 8041 7120 6656 6120 6237 6105 6249 6574 6737 6992 6808 6467 5988 5390 4834 4280 3613 3258 3073 2608 2445 2278 2230 2152 2050 1966 1885 1834 1765 1770 1811 1715 1708 1784 1808 1870 2026 2092 2188 2465 2533 2448 2441 2327 2072 1867 1750 1593 1545 1567 1527 1597 1600 1666 1595 1620 1663 1568 1426 1329 1254 1222 1087 1128 1121 1003 1014 1020 962 990 1027 942 948 997 979 904 972 947 997 963 969 905 927 910 948 948 879 917 937 903 995 908 949 901 908 897 923 848 929 882 889 929 909 848 874 915 918 842 886 891 894 926 845 907 873 848 916 931 857 895 866 895 871 866 934 862 908 873 893 890 856 934 910 900 915 937 939 956 890 941 894 953 881 951 929 1004 973 974 953 937 969 963 1022 1002 1081 1050 1031 1077 1183 1097 1203 1185 1207 1243 1349 1273 1392 1351 1483 1516 1508 1519 1502 1551 1590 1593 1589 1721 1728 1816 1851 2010 2026 2136 2261 2225 2264 2306 2373 2364 2439 2431 2395 2508 2641 2620 2829 3037 3371 3803 4047 4766 4856 5404 5635 5738 5683 5364 4930 4401 3839 3490 3370 3098 3243 3301 3447 3351 3474 3528 3336 3240 3149 2864 2422 2239 2058 1848 1846 1662 1560 1457 1434 1367 1246 1263 1230 1229 1242 1170 1127 1134 1074 1124 1097 1030 1095 1047 1059 1029 1003 1026 1023 948 1017 929 957 943 914 919 1047 1012 1007 1001 914 962 957 996 923 932 960 951 974 992 923 957 949 1012 958 1008 924 978 980 983 905 948 1003 992 932 978 928 937 930 993 942 978 969 1090 1098 1019 1047 1086 1126 1145 1133 1077 1087 1201 1162 1140 1230 1209 1192 1361 1311 1416 1481 1475 1521 1583 1683 1805 1862 2056 2172 2361 2599 2768 2782 2918 3026 2855 2845 2496 2432 2240 2075 1988 2024 2014 2068 2046 2015 2079 2096 2103 2117 1967 1823 1693 1570 1479 1380 1323 1274 1229 1229 1188 1168 1154 1154 1097 1142 1094 1113 1056 1070 1094 1102 1147 1098 1109 1136 1150 1159 1095 1251 1231 1222 1251 1259 1299 1275 1232 1220 1195 1226 1209 1218 1124 1163 1163 1273 1221 1337 1247 1248 1267 1247 1245 1240 1267 1248 1220 1212 1218 1224 1155 1220 1209 1212 1240 1170 1156 1204 1150 1171 1150 1234 1217 1157 1253 1241 1259 1226 1228 1262 1247 1177 1243 1179 1244 1222 1243 1268 1291 1285 1236 1297 1362 1314 1312 1364 1385 1377 1420 1462 1420 1521 1575 1546 1575 1601 1625 1674 1749 1707 1858 1893 2102 2257 2372 2709 2898 3448 3884 4600 5439 6214 6976 7764 8459 8382 8049 7212 6572 5350 4579 4147 3762 3701 3630 3887 4221 4340 4830 5114 5121 4794 4769 4083 3754 3194 2945 2648 2360 2186 2134 1983 1927 1847 1822 1818 1740 1634 1646 1512 1599 1540 1582 1463 1427 1455 1343 1384 1362 1362 1347 1273 1258 1226 1150 1159 1119 1219 1153 1072 1104 1015 1066 1026 1028 963 965 1008 958 973 961 896 890 949 917 912 926 961 991 938 925 921 963 992 936 960 874 954 883 881 901 880 883 870 879 884 908 939 927 888 941 955 904 950 947 940 909 996 974 919 1002 965 1002 1054 1094 1073 1107 1129 1110 1113 1128 1141 1128 1047 1072 1070 1099 1128 1110 1185 1235 1274 1326 1480 1435 1565 1718 1797 1840 1999 2248 2410 2542 2679 2689 2582 2428 2153 2052 1901 1766 1779 1768 1806 1819 1977 1925 1941 1914 1888 1989 1891 1750 1623 1533 1411 1425 1278 1248 1248 1217 1244 1203 1156 1182 1148 1182 1108 1074 1098 1079 1134 1182 1141 1130 1164 1116 1172 1146 1139 1161 1136 1189 1189 1211 1135 1102 1138 1143 1063 1141 1077 1049 1080 1033 1091 1022 1098 1093 1051 1038 959 1011 992 971 1012 1014 1027 969 987 987 964 1000 1051 962 986 936 995 929 890 942 885 958 916 892 893 861 950 872 899 919 966 873 905 907 909 896 911 863 910 910 890 901 866 903 962 922 906 921 955 934 908 966 954 930 1016 1014 1017 1025 1069 1110 1122 1197 1321 1389 1510 1624 1779 1955 2213 2284 2293 2379 2183 2079 1836 1705 1634 1516 1482 1477 1507 1601 1646 1627 1812 1737 1870 1720 1770 1671 1599 1471 1420 1498 1407 1366 1375 1294 1359 1340 1317 1423 1453 1384 1445 1430 1345 1440 1454 1434 1406 1436 1441 1445 1424 1438 1414 1476 1477 1477 1506 1492 1436 1467 1465 1451 1471 1423 1528 1533 1487 1581 1552 1563 1596 1600 1650 1656 1635 1616 1708 1748 1688 1735 1729 1746 1738 1690 1781 1807 1880 1844 2000 1949 1950 1959 2012 2085 2099 2010 2069 2114 2139 2109 2015 2072 2097 2055 2013 2033 2046 2027 1984 2030 1906 1966 1857 1849 1763 1806 1706 1650 1724 1671 1570 1496 1519 1470 1537 1404 1443 1334 1346 1281 1299 1337 1299 1283 1342 1322 1324 1402 1401 1463 1488 1519 1476 1479 1415 1307 1239 1173 1102 1063 1044 1068 1047 1071 1107 1027 1094 1077 1149 1097 1120 1076 1045 976 911 884 855 864 854 829 850 794 819 739 742 723 798 781 826 754 775 759 745 753 771 783 759 756 757 809 749 752 775 748 735 805 777 792 814 764 830 851 782 790 788 790 817 799 852 792 804 742 861 787 836 826 789 839 827 802 872 821 878 913 911 877 913 944 965 942 876 868 857 910 802 798 841 894 945 925 869 928 955 991 1026 1010 1092 1111 1135 1202 1214 1298 1426 1424 1428 1453 1405 1372 1367 1219 1164 1067 1078 1046 1094 1081 1108 1122 1166 1211 1255 1319 1370 1338 1318 1424 1279 1197 1222 1074 1051 1004 1014 919 900 983 926 946 965 939 965 916 980 927 965 934 874 852 852 778 805 840 804 805 828 836 808 877 824 893 800 900 724 825 823 795 757 827 810 840 799 819 740 821 774 846 814 851 842 812 839 771 766 800 777 768 765 734 758 787 784 797 730 733 723 745 713 766 735 740 722 728 714 682 767 702 720 740 696 693 742 749 746 790 776 833 780 758 778 757 817 780 758 761 759 751 713 756 699 748 775 740 799 727 869 727 730 745 716 795 744 729 773 810 797 853 824 893 890 904 923 980 1079 1172 1275 1350 1407 1543 1504 1474 1334 1289 1180 1098 1058 1062 1020 996 957 959 1032 1092 1086 1064 1146 1218 1148 1159 1110 1022 1040 1000 972 896 938 943 913 930 968 1004 1030 1018 1116 1049 1236 1274 1363 1442 1529 1649 1795 1727 1786 1735 1664 1535 1445 1388 1293 1164 1228 1156 1221 1302 1207 1291 1277 1339 1413 1406 1389 1407 1372 1254 1240 1146 1124 1016 1064 1072 1064 1039 998 998 1013 978 1016 1002 961 973 998 960 981 997 914 1033 971 1021 1020 972 1088 1022 1082 1104 1111 1053 1080 1072 1054 1084 1132 1115 1254 1235 1293 1305 1372 1282 1275 1198 1182 1117 1158 1103 1156 1129 1092 1153 1192 1200 1303 1231 1380 1308 1429 1424 1412 1486 1479 1498 1420 1378 1295 1243 1230 1237 1145 1186 1107 1080 1091 1078 1139 1153 1176 1109 1210 1233 1143 1130 1081 1074 1064 1040 998 930 990 984 943 967 937 903 873 884 907 886 936 899 815 871 832 847 891 877 865 911 852 864 845 851 811 788 826 806 853 799 856 748 832 833 822 869 850 809 906 888 928 882 870 864 868 918 948 922 934 881 904 929 967 909 911 899 948 939 947 955 902 928 906 938 980 926 950 883 873 908 926 903 868 891 897 884 903 870 855 917 808 945 899 862 820 867 824 818 784 871 868 896 892 809 892 862 812 874 859 888 875 906 955 932 929 954 971 967 1053 1015 1047 1032 968 1011 1010 956 894 908 864 830 884 868 880 836 806 859 893 855 906 888 873 815 860 835 845 786 788 778 763 723 686 720 753 708 703 738 753 732 720 712 702 705 731 716 707 669 682 675 743 671 708 735 689 718 755 729 729 777 694 714 739 732 722 742 724 700 757 731 725 754 759 756 766 696 705 740 753 684 638 799 735 795 742 764 744 757 752 729 767 767 727 712 740 703 733 687 753 731 738 764 784 762 758 768 778 796 713 748 761 745 812 863 770 767 796 743 830 838 849 848 901 852 862 907 889 895 940 898 879 929 974 940 1035 989 996 1025 954 998 1041 968 971 980 968 946 961 957 934 911 921 938 933 920 939 951 895 937 882 917 893 873 871 840 818 803 817 824 770 751 825 743 780 784 748 779 751 809 725 796 755 707 723 721 747 703 708 717 718 751 726 722 729 725 748 708 743 717 683 763 737 770 728 777 766 808 799 751 799 733 721 783 792 757 748 774 756 759 780 713 723 782 741 757 733 785 776 745 809 822 771 798 773 758 814 808 840 786 814 900 851 873 955 929 993 1095 1011 1153 1149 1201 1340 1388 1401 1352 1275 1225 1155 1154 1065 1038 1058 1090 1088 1004 1065 1082 1093 1098 1093 1140 1234 1247 1236 1186 1138 1057 1134 1064 1059 1078 1052 1109 967 945 1055 993 979 984 967 1026 1000 997 1038 942 996 1016 1030 945 1032 1040 1029 988 1041 991 1017 987 1042 967 1001 1079 1079 1051 1125 1184 1181 1294 1296 1415 1509 1519 1770 1808 2076 2256 2527 2867 3157 3516 3807 3971 4128 3988 3690 3518 3173 2732 2410 2245 2204 2005 2091 1965 2000 1933 2056 2105 2200 2466 2442 2619 2635 2505 2446 2258 2116 1846 1690 1588 1427 1391 1232 1314 1231 1174 1129 1091 1131 1033 1177 1094 1207 1229 1290 1442 1516 1554 1614 1676 1691 1758 1680 1540 1470 1273 1250 1110 1109 1078 1010 1030 1077 1050 1028 1069 1108 1209 1221 1242 1271 1196 1259 1266 1152 1091 1089 1080 1044 985 1072 1003 1070 1070 1066 1162 1121 1223 1292 1419 1585 1668 1751 1896 2013 2070 2141 2243 1978 1913 1711 1607 1498 1458 1354 1279 1308 1260 1286 1332 1337 1443 1430 1463 1513 1520 1602 1513 1632 1511 1487 1522 1390 1372 1335 1403 1390 1428 1548 1647 1684 1822 1988 2066 2242 2314 2373 2307 2151 2066 1942 1759 1645 1472 1431 1343 1353 1338 1276 1299 1389 1407 1502 1626 1531 1666 1689 1692 1657 1529 1466 1332 1363 1232 1228 1196 1142 1088 1217 1173 1221 1331 1395 1501 1580 1596 1637 1669 1575 1505 1376 1341 1197 1210 1098 1079 1035 1016 1053 1063 1013 1080 1142 1135 1226 1230 1332 1429 1402 1306 1305 1327 1328 1232 1266 1105 1094 1069 1107 994 952 963 885 937 888 876 864 861 941 925 970 948 965 916 935 996 907 893 878 811 880 844 835 862 853 816 793 829 821 731 816 730 809 813 807 879 838 789 809 820 880 788 826 841 866 857 864 840 846 882 893 966 931 1002 1014 1057 1068 1098 1179 1398 1441 1577 1766 1750 1952 1923 1941 1889 1824 1749 1640 1571 1444 1336 1235 1228 1223 1255 1238 1298 1299 1412 1373 1471 1566 1646 1789 1724 1714 1818 1822 1794 1705 1730 1568 1528 1404 1341 1375 1297 1230 1312 1296 1329 1335 1448 1434 1666 1668 1870 2019 2122 2137 2070 1989 1919 1801 1649 1549 1395 1344 1278 1241 1224 1177 1205 1183 1211 1195 1239 1320 1316 1407 1376 1295 1334 1233 1220 1135 1040 1105 1052 964 941 899 866 895 809 808 878 830 783 776 806 785 787 772 746 833 796 780 716 802 789 741 796 763 702 765 700 804 733 753 790 750 759 789 728 742 739 764 753 736 806 757 769 765 749 774 806 740 749 777 740 779 727 749 760 741 763 742 745 807 772 795 784 790 865 857 883 925 1028 1101 1091 1173 1246 1272 1241 1247 1213 1156 1036 974 950 905 935 807 811 872 834 873 850 846 960 871 937 956 1008 973 977 919 987 921 847 925 841 793 835 774 749 750 702 780 688 708 675 691 703 776 670 745 739 685 702 709 738 719 717 701 724 691 684 711 741 709 769 711 732 700 683 705 670 715 678 677 714 708 676 694 720 657 662 690 765 706 735 709 690 698 700 740 730 716 715 725 696 720 708 754 675 757 756 751 754 806 788 778 795 815 791 756 788 741 847 852 839 860 898 919 878 819 911 871 866 872 947 971 968 1055 1063 1034 980 1053 1042 971 937 956 904 865 918 832 837 789 774 806 805 819 805 820 811 801 904 890 829 831 863 823 793 742 765 740 746 736 680 691 706 678 717 688 698 695 690 693 655 674 691 670 661 649 634 701 652 680 688 692 654 687 616 693 718 722 734 723 683 730 731 756 731 758 724 814 762 819 887 828 837 910 914 972 930 919 878 922 847 799 815 816 826 815 769 850 853 835 795 791 813 828 812 820 838 863 916 855 902 844 871 899 804 842 895 852 856 931 942 992 1032 1071 1167 1179 1282 1285 1410 1444 1510 1502 1537 1370 1343 1244 1240 1076 1093 945 935 1009 960 932 931 938 1012 1032 1000 1014 1115 1078 1071 1124 1120 1145 1117 1128 1070 957 953 823 871 853 787 787 784 795 778 754 764 737 745 724 798 793 776 777 750 753 786 779 762 736 706 737 730 712 715 742 733 759 732 689 772 760 726 725 745 658 710 690 683 706 695 754 717 678 659 688 712 685 798 726 735 712 697 712 769 703 723 721 722 735 735 712 790 791 705 740 735 728 802 770 764 774 779 771 850 833 925 1002 978 967 1010 1119 1195 1270 1400 1537 1692 1902 2141 2300 2281 2291 2277 2157 2091 1896 1739 1691 1528 1501 1365 1276 1289 1240 1227 1270 1201 1229 1237 1405 1439 1480 1540 1558 1559 1548 1458 1493 1398 1293 1269 1178 1122 1019 997 1010 932 940 933 867 878 819 857 832 826 825 888 846 837 794 833 807 808 836 851 777 798 855 792 748 786 720 783 805 753 732 762 757 765 735 769 802 756 767 792 805 837 802 827 776 803 740 746 762 794 780 729 769 802 813 759 800 733 741 786 790 794 770 840 812 784 767 737 783 812 797 819 777 816 769 858 781 823 793 847 758 886 790 824 801 814 798 830 796 872 842 858 783 850 823 841 821 830 792 756 757 786 818 846 796 844 777 820 803 816 792 798 824 785 833 848 796 760 842 854 906 842 834 866 861 842 880 846 851 929 958 902 905 876 887 902 965 936 995 942 1055 989 1102 1144 1260 1306 1320 1510 1565 1659 1679 1775 1683 1584 1560 1463 1362 1379 1252 1156 1179 1053 1107 1049 1091 1089 1083 1070 1103 1206 1118 1178 1264 1270 1306 1264 1326 1195 1215 1196 1168 1143 1022 1116 1059 1047 1022 967 962 918 1037 952 994 962 988 928 1034 991 1043 1035 1048 1122 1177 1220 1337 1401 1484 1674 1734 1890 2022 2055 1986 1981 1888 1784 1660 1591 1476 1505 1317 1196 1254 1109 1203 1139 1123 1172 1245 1158 1234 1246 1266 1433 1441 1428 1552 1441 1407 1336 1337 1266 1143 1195 1086 1099 1164 1050 1026 1011 1001 1007 1027 1052 1087 1039 1021 1006 971 1024 941 968 994 978 961 968 930 972 970 983 964 1035 1096 1114 1124 1190 1215 1252 1310 1346 1589 1641 1790 1903 1991 2179 2310 2276 2354 2254 2140 1972 1819 1663 1591 1432 1439 1261 1253 1150 1226 1233 1200 1175 1247 1306 1290 1377 1472 1417 1523 1528 1662 1603 1611 1482 1390 1254 1299 1209 1150 1077 952 1023 1022 936 992 982 1012 958 1035 1056 1005 1039 1018 972 872 939 921 905 859 804 846 807 806 762 813 812 794 803 814 818 830 791 813 837 791 828 817 841 797 812 811 793 842 790 731 741 746 780 767 738 691 728 768 665 707 704 730 693 658 730 707 753 704 745 731 736 782 729 786 783 776 780 752 724 753 695 728 751 726 708 728 685 660 732 701 756 711 710 748 735 708 684 749 767 690 692 729 707 692 691 781 668 698 694 684 662 702 656 615 700 678 680 685 669 705 717 720 722 706 674 703 710 734 732 756 723 771 807 833 790 809 857 895 956 895 850 891 827 862 809 799 774 755 739 769 706 792 702 756 729 745 783 799 728 818 812 820 806 836 883 839 861 832 850 808 831 850 796 803 803 736 777 792 769 771 844 787 741 800 782 756 768 764 765 744 767 789 747 810 751 795 747 791 770 746 746 738 775 782 811 771 771 694 801 792 769 755 817 748 809 812 704 756 723 783 779 774 743 791 755 786 758 703 786 786 722 688 780 751 758 746 741 772 768 713 779 761 821 838 792 769 774 784 830 802 817 858 883 911 933 994 1119 1163 1161 1165 1240 1180 1215 1183 1173 1066 1052 1027 935 911 879 891 851 824 846 880 837 918 919 839 861 854 978 930 962 975 942 878 1059 953 924 852 885 850 812 847 833 750 813 780 727 741 757 824 792 770 761 674 733 713 803 775 784 768 785 759 764 715 733 788 780 797 773 792 766 805 751 753 753 791 792 845 823 811 793 846 844 885 824 830 842 844 806 872 836 941 895 1003 968 964 1069 1041 1160 1267 1287 1375 1431 1525 1468 1549 1504 1499 1405 1306 1240 1181 1132 1045 1012 944 950 929 892 954 986 1001 993 999 1044 1100 1005 1148 1161 1214 1235 1206 1222 1200 1124 1125 1092 1127 971 1034 929 936 941 948 928 867 848 839 848 831 872 875 865 818 836 819 860 784 825 835 789 857 819 852 779 799 842 799 833 767 807 781 817 810 743 805 799 817 778 788 761 779 743 778 769 785 775 764 762 767 742 782 750 776 799 777 757 736 771 747 777 767 781 764 792 793 808 808 797 837 742 799 821 814 798 819 789 772 774 778 726 790 823 815 796 768 796 756 808 783 802 813 874 868 939 902 958 964 997 965 1054 994 1002 1019 986 1029 1082 1066 1163 1241 1289 1254 1324 1266 1206 1220 1121 1111 1001 1003 993 999 928 980 908 984 976 1010 947 936 1028 1043 1036 1057 1094 1149 1202 1234 1280 1308 1375 1389 1477 1420 1546 1486 1491 1489 1420 1402 1288 1235 1124 1071 1086 1001 1008 1025 922 953 939 942 904 973 923 935 927 883 978 1074 982 1077 1113 1078 1129 1073 1008 1033 1001 987 940 868 885 924 839 872 867 783 775 727 786 805 793 791 828 772 821 774 748 798 813 896 778 837 804 827 854 839 884 818 852 810 856 848 863 867 820 984 865 913 919 907 912 1022 946 1026 1065 1139 1158 1304 1260 1361 1481 1612 1767 1795 1804 1927 1873 1765 1663 1610 1522 1413 1442 1447 1349 1368 1347 1300 1315 1314 1258 1283 1298 1245 1153 1217 1254 1260 1259 1366 1296 1387 1429 1319 1371 1270 1245 1280 1241 1161 1149 1117 1122 1054 1084 1051 1104 966 998 997 995 987 961 976 898 965 915 914 922 882 864 886 885 877 847 924 866 893 871 877 838 840 815 851 860 836 823 879 868 815 921 785 859 818 850 826 855 827 822 842 835 834 818 794 829 780 823 840 839 855 870 872 854 864 811 890 842 829 866 918 860 931 891 959 931 952 1011 964 958 1047 1102 1238 1176 1219 1285 1262 1204 1169 1054 1047 1009 948 949 929 957 869 848 924 873 910 851 898 925 972 923 996 939 1024 1043 1039 1097 1081 1141 1118 1140 1026 1073 974 883 935 938 943 866 863 801 840 830 812 747 789 823 806 842 772 845 824 828 895 864 905 838 825 880 861 802 824 815 790 754 829 864 882 885 809 919 809 867 840 828 798 853 835 859 847 802 874 834 861 831 803 830 803 843 827 792 861 826 860 896 901 906 842 924 842 926 921 969 867 864 902 904 942 963 913 998 1010 985 1079 1136 1166 1205 1321 1322 1550 1555 1684 1661 1705 1663 1726 1615 1424 1303 1299 1323 1205 1114 1098 1112 1019 1049 984 985 974 910 971 949 1005 991 1017 1061 1114 1033 1144 1162 1208 1180 1236 1209 1214 1092 1040 1028 1024 960 955 915 880 874 876 797 788 757 800 767 730 743 748 726 721 755 729 687 721 706 729 686 719 701 705 693 671 691 687 700 694 754 718 707 718 718 698 712 696 667 674 686 709 736 700 676 746 690 730 699 706 699 739 656 718 680 703 676 684 719 696 723 679 754 664 739 713 669 745 764 752 793 757 828 847 851 886 892 916 926 1048 1039 1114 1177 1128 1141 1200 1139 1048 1019 968 932 893 860 825 853 800 784 813 857 822 836 822 783 845 831 878 893 873 863 953 845 865 930 951 922 940 923 840 904 833 843 804 747 785 847 782 742 709 804 778 729 707 758 736 798 712 754 747 753 816 767 716 811 761 790 801 835 779 814 808 827 811 869 809 849 798 821 800 770 756 731 766 753 758 763 762 715 704 713 732 765 787 744 762 772 710 733 727 781 773 771 834 768 798 807 809 755 837 733 773 821 774 781 760 828 843 741 840 827 825 907 955 927 977 975 1047 1041 1016 1052 1080 1022 1007 1011 875 880 826 834 845 820 788 859 777 771 746 734 778 760 735 824 725 784 727 798 812 852 864 876 834 901 883 861 841 826 793 751 812 767 744 724 734 751 732 732 661 696 722 706 682 707 693 685 652 651 675 769 684 712 713 713 691 626 644 681 653 699 732 699 723 682 702 737 685 737 722 697 659 690 755 667 638 632 698</counts>
			</dataPoints>
		</scan>
	</xrdMeasurement>
</xrdMeasurements>