File: dataset/precursor_mixture/NaHCO3_Li2TiO3_HfO2_Ga2O3.2-min.xrdml
<?xml version="1.0"?>
<xrdMeasurements xmlns="http://www.xrdml.com/XRDMeasurement/2.2" xmlns:xsi="http://www.w3.org/2001/XMLSchema-instance" xsi:schemaLocation="http://www.xrdml.com/XRDMeasurement/2.2 http://www.xrdml.com/XRDMeasurement/2.2/XRDMeasurement.xsd" status="Completed" recordIdentifier="{F88BAE4B-0553-4FCC-BE5B-7D01B28E5F0E}">
	<comment>
		<entry/>
	</comment>
	<sample type="To be analyzed">
		<id>dara-21-1</id>
		<name></name>
		<preparedBy></preparedBy>
	</sample>
	<xrdMeasurement measurementType="Scan" status="Completed" sampleMode="Reflection">
		<usedWavelength intended="K-Alpha 1">
			<kAlpha1 unit="Angstrom">1.5405980</kAlpha1>
			<kAlpha2 unit="Angstrom">1.5444260</kAlpha2>
			<kBeta unit="Angstrom">1.3922500</kBeta>
			<ratioKAlpha2KAlpha1>0.5000</ratioKAlpha2KAlpha1>
		</usedWavelength>
		<incidentBeamPath>
			<radius unit="mm">145.00</radius>
			<xRayTube id="1010048" name="Empyrean Cu LFF HR (9430 033 7310x) DK437873">
				<tension unit="kV">40.0</tension>
				<current unit="mA">15.0</current>
				<anodeMaterial>Cu</anodeMaterial>
				<focus type="Line">
					<length unit="mm">12.0</length>
					<width unit="mm">0.4</width>
					<takeOffAngle unit="deg">6.0</takeOffAngle>
				</focus>
			</xRayTube>
			<filter id="20010004" name="Beta-filter Nickel">
				<material>Ni</material>
				<thickness unit="mm">0.020</thickness>
			</filter>
			<sollerSlit id="21010002" name="Soller slits 0.04 rad.">
				<opening unit="rad">0.0400</opening>
			</sollerSlit>
			<mask id="22031000" name="Fixed mask 13 mm">
				<width unit="mm">9.00</width>
			</mask>
			<divergenceSlit id="22120001" name="Divergence slit 1°" xsi:type="fixedDivergenceSlitType">
				<distanceToSample unit="mm">50.00</distanceToSample>
				<height unit="mm">1.52</height>
			</divergenceSlit>
		</incidentBeamPath>
		<beamKnife id="29030100" name="Beam knife low"/>
		<sampleMovement xsi:type="spinningSampleMovementType">
			<spinnerRevolutionTime unit="seconds">1.0</spinnerRevolutionTime>
		</sampleMovement>
		<diffractedBeamPath>
			<radius unit="mm">145.00</radius>
			<antiScatterSlit id="22090040" name="AS slit 9 mm" xsi:type="fixedAntiScatterSlitType">
				<height unit="mm">9.00</height>
			</antiScatterSlit>
			<sollerSlit id="21020003" name="Large Soller slits 0.04 rad.">
				<opening unit="rad">0.0400</opening>
			</sollerSlit>
			<filter id="20030001" name="Large beta-filter Nickel">
				<material>Ni</material>
				<thickness unit="mm">0.020</thickness>
			</filter>
			<detector id="7010019" name="PIXcel1D-Medipix3 detector" xsi:type="rtmsDetectorType">
				<phd unit="keV">
					<lowerLevel>4.0</lowerLevel>
					<upperLevel>11.3</upperLevel>
				</phd>
				<mode>Scanning</mode>
				<activeLength unit="deg">1.021</activeLength>
			</detector>
		</diffractedBeamPath>
		<scan appendNumber="0" mode="Continuous" scanAxis="Gonio" status="Completed">
			<header>
				<startTimeStamp>2024-03-24T12:20:36-07:00</startTimeStamp>
				<endTimeStamp>2024-03-24T12:22:58-07:00</endTimeStamp>
				<author>
					<name>AutomatedUser</name>
				</author>
				<source>
					<applicationSoftware version="1.6 (94)">PANalytical Aeris Instrument Suite</applicationSoftware>
					<instrumentControlSoftware version="3.0.0 20211014">AERIS</instrumentControlSoftware>
					<instrumentID>2879380</instrumentID>
				</source>
			</header>
			<dataPoints>
				<positions axis="2Theta" unit="deg">
					<startPosition>10.02173288</startPosition>
					<endPosition>139.98435528</endPosition>
				</positions>
				<positions axis="Omega" unit="deg">
					<startPosition>5.01086644</startPosition>
					<endPosition>69.99217764</endPosition>
				</positions>
				<commonCountingTime unit="seconds">1.551</commonCountingTime>
				<counts unit="counts">387 389 414 364 347 406 390 380 379 396 371 355 383 405 357 359 378 397 354 350 372 370 348 371 376 379 365 348 336 334 353 317 325 331 378 329 315 319 338 371 332 328 334 379 350 322 334 313 323 295 331 283 306 313 306 357 305 289 289 289 295 281 312 286 274 245 263 285 278 262 263 292 260 285 263 258 309 287 294 254 289 258 270 252 305 269 280 257 256 238 238 249 229 262 239 235 256 238 236 286 263 231 209 232 260 195 234 266 274 261 215 269 279 305 246 250 241 234 223 226 223 249 221 242 226 230 245 260 240 241 214 231 227 245 245 243 246 202 215 213 218 210 216 204 213 223 213 222 213 199 188 216 211 214 224 204 241 216 206 233 192 234 205 220 230 226 211 273 224 343 371 338 285 257 235 212 200 190 204 205 222 214 252 239 241 295 311 370 396 303 278 254 218 221 260 257 265 301 303 322 310 378 342 326 253 264 246 196 205 202 192 188 175 184 186 185 199 186 175 202 200 184 202 201 177 198 178 176 171 190 210 170 180 186 200 203 185 195 189 179 195 145 187 167 193 198 199 160 189 142 175 203 167 192 180 155 184 171 146 161 164 167 168 179 160 170 157 183 189 194 168 160 175 159 159 150 145 172 178 149 160 161 167 184 161 144 182 154 135 164 161 154 151 141 163 156 159 144 165 169 182 156 168 151 194 161 181 133 143 191 199 230 237 226 227 213 236 338 397 511 549 513 340 275 244 232 271 324 338 482 477 319 246 183 173 179 161 148 152 179 158 179 171 154 169 171 177 203 246 279 406 469 377 276 204 158 153 112 166 155 153 142 149 153 153 154 128 139 150 154 143 135 147 137 143 149 155 124 146 150 128 136 128 141 171 132 146 151 173 164 161 155 153 175 165 171 183 171 178 192 200 186 228 254 250 281 318 343 465 644 868 1277 1784 2315 2246 1819 1236 799 522 429 362 292 266 247 249 236 284 329 299 269 194 218 222 203 195 180 186 193 190 186 183 208 200 206 220 239 225 267 299 329 411 428 490 647 848 1032 1074 904 850 882 1030 969 885 714 541 420 365 320 280 253 279 252 276 260 244 292 286 271 324 304 387 408 506 637 836 1066 1484 1966 2278 2110 1779 1233 948 703 560 444 401 352 286 243 225 187 207 206 188 163 165 189 170 147 168 161 162 156 130 144 144 143 163 120 182 152 179 182 169 179 221 232 245 255 201 226 205 208 162 166 181 182 177 172 174 197 199 234 262 374 462 636 720 743 733 787 675 722 719 613 552 472 360 288 278 262 292 356 369 354 480 531 528 499 477 529 489 524 690 746 616 524 375 289 239 205 188 215 236 231 285 269 327 250 256 207 188 150 153 161 124 124 125 156 127 124 148 144 143 151 151 159 143 128 147 161 193 206 226 254 254 257 259 194 197 210 197 177 146 161 164 124 141 180 168 184 192 197 200 244 239 293 288 343 367 305 296 270 222 218 252 279 351 343 249 249 208 215 193 169 139 173 120 127 106 117 110 141 107 105 109 110 107 118 106 111 101 112 101 113 111 135 112 120 136 135 130 118 107 118 132 121 115 146 199 281 525 575 460 510 402 372 386 358 314 212 222 178 171 176 214 203 212 231 213 202 193 189 187 179 155 131 104 105 112 107 112 116 105 101 103 87 103 123 125 102 90 103 100 104 117 116 123 108 121 121 132 152 139 139 145 149 180 138 141 148 160 200 214 244 263 306 334 311 282 232 272 182 160 147 140 139 131 118 102 105 119 117 134 162 181 187 218 196 202 154 159 149 144 141 126 138 153 184 177 166 170 182 142 146 134 129 137 141 167 172 203 206 260 309 298 297 256 238 255 263 248 213 200 163 134 102 119 123 83 114 109 93 87 104 98 84 82 91 124 106 120 102 98 117 105 90 81 85 110 85 100 90 104 91 101 91 122 125 133 136 123 122 105 98 109 81 122 129 113 118 115 120 123 136 193 194 201 199 213 220 199 201 164 139 161 142 128 127 121 129 173 162 160 183 177 205 268 366 470 489 426 379 343 276 213 146 149 137 139 123 117 124 141 165 160 176 291 392 533 557 553 488 391 282 300 258 234 315 361 338 309 262 224 166 142 135 124 116 131 129 138 166 192 166 158 174 149 160 117 117 109 108 68 105 77 108 89 92 104 94 94 107 83 83 119 114 132 119 126 136 138 120 134 118 123 79 104 107 88 108 89 85 84 104 99 76 84 99 110 79 101 84 95 102 93 91 112 108 86 140 116 112 140 139 151 187 242 268 365 299 298 273 238 213 209 163 132 151 111 147 129 133 132 124 147 147 151 171 156 131 174 173 166 194 248 313 373 393 344 343 347 303 303 266 244 225 209 201 260 285 287 222 253 241 197 149 144 138 101 126 112 106 116 116 141 199 413 346 193 231 347 190 148 151 190 215 267 283 344 297 326 266 281 250 190 195 165 158 165 163 137 157 182 224 267 231 208 221 215 194 180 167 191 201 181 198 147 153 141 159 164 143 156 160 162 152 148 126 154 124 131 113 116 139 116 134 116 120 134 145 154 158 189 198 165 215 261 307 335 299 296 342 331 353 293 273 280 213 231 185 186 177 236 212 209 192 233 182 195 154 159 128 143 145 102 135 118 126 119 154 171 182 221 209 200 218 196 185 179 123 165 157 191 192 187 232 252 254 264 211 223 205 200 186 154 171 166 179 187 168 156 183 180 180 190 267 302 323 322 311 283 250 283 245 209 210 182 159 189 171 166 152 155 167 180 214 188 202 199 165 198 224 212 235 284 317 307 363 351 367 380 308 241 288 231 181 181 147 148 143 126 146 97 95 145 127 137 132 101 106 116 130 139 151 164 155 149 160 171 183 229 207 243 253 219 201 220 190 175 158 125 127 128 102 105 90 77 90 84 98 99 97 80 78 91 92 88 76 71 77 76 61 88 54 64 72 76 92 74 101 69 87 80 98 78 72 77 76 87 68 61 98 88 90 78 77 94 83 79 75 95 87 114 75 84 100 116 95 93 128 135 135 160 190 228 180 159 190 211 179 144 115 110 102 114 118 120 127 114 131 134 115 130 120 106 123 111 120 121 118 117 127 129 122 112 118 107 98 96 99 94 82 69 91 109 78 74 83 97 106 135 130 160 163 197 186 143 159 169 157 116 135 124 111 106 95 119 97 112 111 130 111 110 95 111 142 148 129 135 120 141 130 118 113 100 110 103 118 137 120 116 95 95 96 88 88 94 77 77 89 95 107 95 88 85 96 106 110 115 99 89 80 89 80 109 87 88 73 84 72 98 98 98 88 96 80 85 77 101 109 83 95 83 105 103 107 119 124 103 131 106 131 117 136 169 154 130 115 133 153 125 129 110 80 102 89 88 82 96 78 77 74 78 81 83 86 99 87 90 82 100 104 108 124 114 132 118 115 109 92 108 113 117 102 104 89 79 83 72 76 86 105 110 109 97 97 121 100 106 103 101 121 111 111 104 88 124 94 119 97 105 93 107 118 97 120 93 76 89 80 85 117 109 110 97 111 107 88 112 103 123 137 130 113 118 113 106 108 108 106 99 96 92 71 78 96 93 104 91 114 94 91 85 87 82 81 97 84 81 75 87 68 88 84 77 78 96 86 100 105 77 83 102 88 104 89 84 84 95 79 72 92 59 63 92 105 103 112 117 109 129 127 132 129 119 109 104 105 105 113 81 73 88 103 93 89 69 78 99 98 77 113 125 126 112 114 123 119 97 120 117 129 133 121 109 143 135 121 136 123 150 125 122 127 124 107 101 98 126 131 105 120 135 140 155 158 148 156 158 131 132 151 123 128 136 113 117 112 90 110 104 93 104 92 91 114 100 139 143 104 105 98 114 114 94 110 93 82 90 104 76 69 73 75 63 76 80 87 74 79 88 85 94 102 91 86 88 98 80 87 100 100 77 90 90 97 85 88 79 81 82 108 97 76 85 83 94 76 100 87 91 93 87 113 104 96 110 101 99 88 90 112 109 103 112 104 113 89 134 128 108 140 125 146 131 131 134 141 127 153 128 126 128 117 117 120 106 133 96 106 118 94 87 113 114 94 115 125 140 114 94 118 95 111 114 119 130 140 144 120 134 125 138 127 114 115 112 106 101 111 113 111 94 93 102 107 110 101 102 106 113 102 101 104 79 108 80 101 103 93 98 109 112 94 107 104 95 104 93 92 98 101 80 77 104 63 96 63 89 63 85 80 77 74 59 87 62 83 97 88 75 74 85 95 78 81 88 68 79 90 76 71 78 94 77 96 77 73 91 85 91 86 84 93 98 101 122 98 105 106 98 117 108 107 140 111 120 113 107 109 106 110 96 84 93 119 94 97 89 126 115 115 103 133 127 113 134 134 139 142 144 141 149 152 104 137 128 144 147 129 92 124 122 117 113 115 129 123 134 131 115 139 124 139 128 127 112 133 140 136 129 179 127 144 153 146 130 113 141 139 149 136 156 111 129 130 107 115 120 129 98 77 77 109 93 100 99 94 100 81 81 95 113 106 97 120 125 147 117 112 124 119 114 139 108 113 105 88 113 118 120 114 141 126 107 122 115 92 118 104 137 111 113 130 132 133 118 100 140 116 110 113 130 130 118 119 89 103 107 122 101 84 92 92 103 90 77 100 99 123 112 142 113 125 108 98 116 151 132 123 100 125 115 125 114 127 115 125 106 128 135 146 140 116 115 139 140 127 128 93 104 105 105 103 100 114 80 101 92 86 107 80 73 71 73 73 94 101 80 81 71 61 67 91 74 73 92 83 76 82 91 87 74 65 75 84 77 72 95 87 111 93 68 84 81 81 84 83 77 77 90 97 74 73 74 85 76 77 71 82 80 74 73 74 77 79 75 67 89 86 80 73 68 71 67 73 74 79 99 77 80 83 94 89 113 91 107 117 91 82 91 81 69 91 91 76 104 76 90 110 101 95 69 63 93 101 99 109 115 122 110 90 107 101 94 75 107 107 88 90 91 102 85 80 97 107 83 104 94 94 72 64 82 83 105 107 75 96 77 89 87 79 77 98 105 110 94 94 98 94 94 104 96 102 101 96 106 98 87 97 98 103 74 97 108 110 105 116 93 119 108 108 106 114 109 104 102 99 95 117 116 105 109 110 105 92 114 116 112 142 144 118 103 142 117 130 109 134 105 112 102 125 130 118 124 135 146 145 143 131 137 163 122 120 107 94 118 141 116 122 105 113 121 125 111 123 133 131 114 129 132 115 122 115 122 114 111 114 106 121 115 113 116 115 94 96 100 84 93 80 97 97 85 87 80 83 96 99 78 105 94 107 109 82 119 84 87 95 98 92 82 91 82 82 97 90 70 90 86 79 87 86 66 90 72 78 74 81 97 83 78 101 90 88 95 78 80 91 79 94 95 104 95 110 98 79 98 85 96 91 97 65 87 92 83 81 83 90 98 83 93 75 89 101 78 86 105 71 80 90 82 83 71 101 98 89 112 72 66 99 95 131 96 121 108 90 109 97 118 79 98 79 89 81 110 106 111 77 88 97 99 77 92 81 95 84 76 88 100 89 97 117 98 95 108 115 98 111 126 109 102 120 104 106 123 103 96 104 110 111 105 84 109 104 99 98 92 96 81 101 88 100 93 90 73 91 112 95 108 81 92 77 91 89 108 96 74 89 74 83 103 94 81 102 106 113 126 106 119 135 122 131 126 147 141 130 115 134 131 136 130 129 126 98 110 118 122 108 114 103 107 95 112 91 89 87 80 102 87 96 73 74 85 86 72 98 83 104 82 97 87 86 99 106 109 113 113 102 103 82 102 121 132 104 109 125 105 104 89 112 102 109 100 104 88 125 81 97 114 113 100 110 105 118 107 109 77 87 105 89 101 80 98 93 104 85 97 96 76 122 97 90 91 71 87 109 109 110 129 110 107 107 114 125 105 106 110 117 99 93 124 105 94 100 118 120 99 117 114 122 104 99 110 97 96 79 111 107 127 112 116 135 134 123 108 117 109 110 90 104 108 109 101 108 99 105 84 95 99 110 79 100 102 83 104 106 83 86 93 97 91 76 96 71 97 92 85 77 104 90 84 107 85 113 125 94 85 93 97 85 94 91 105 98 88 101 101 99 93 99 96 103 95 108 128 100 95 105 100 108 94 106 94 105 98 101 98 114 115 80 85 97 96 91 92 108 100 114 112 126 124 118 115 107 112 94 111 92 111 102 105 112 108 127 134 118 102 120 115 136 137 128 126 127 136 124 136 142 111 127 123 122 129 126 118 115 130 110 109 111 122 122 112 120 97 140 113 114 105 103 121 113 113 118 117 114 119 125 101 121 106 107 127 108 108 136 117 124 120 99 133 130 124 139 131 128 161 122 133 166 137 143 151 134 128 119 109 120 109 97 139 116 128 122 100 123 108 123 99 120 110 93 110 110 98 80 109 110 107 100 113 106 103 102 92 93 124 107 94 101 97 93 97 105 113 90 91 101 79 102 88 116 96 110 102 120 84 91 106 104 88 92 118 106 95 114 100 94 97 97 95 103 115 107 102 104 101 103 117 94 110 117 89 104 107 97 90 81 103 124 112 103 97 123 117 109 121 94 96 97 89 95 97 97 104 87 85 95 111 101 117 108 120 95 96 133 102 121 124 112 108 137 113 128 126 125 128 122 95 114 138 114 102 105 106 119 116 104 126 112 123 127 143 120 137 129 138 109 137 111 116 114 123 121 101 114 153 107 88 120 102 119 101 116 103 133 114 129 120 102 143 132 111 131 104 125 128 138 135</counts>
			</dataPoints>
		</scan>
	</xrdMeasurement>
</xrdMeasurements>