File: dataset/precursor_mixture/NaHCO3_Cr2O3_Y2O3.2-min.xrdml
<?xml version="1.0"?>
<xrdMeasurements xmlns="http://www.xrdml.com/XRDMeasurement/2.2" xmlns:xsi="http://www.w3.org/2001/XMLSchema-instance" xsi:schemaLocation="http://www.xrdml.com/XRDMeasurement/2.2 http://www.xrdml.com/XRDMeasurement/2.2/XRDMeasurement.xsd" status="Completed" recordIdentifier="{B1986993-B041-4BAF-A8FC-ADF4CE5F38E0}">
	<comment>
		<entry/>
	</comment>
	<sample type="To be analyzed">
		<id></id>
		<name></name>
		<preparedBy></preparedBy>
	</sample>
	<xrdMeasurement measurementType="Scan" status="Completed" sampleMode="Reflection">
		<usedWavelength intended="K-Alpha 1">
			<kAlpha1 unit="Angstrom">1.5405980</kAlpha1>
			<kAlpha2 unit="Angstrom">1.5444260</kAlpha2>
			<kBeta unit="Angstrom">1.3922500</kBeta>
			<ratioKAlpha2KAlpha1>0.5000</ratioKAlpha2KAlpha1>
		</usedWavelength>
		<incidentBeamPath>
			<radius unit="mm">145.00</radius>
			<xRayTube id="1010048" name="Empyrean Cu LFF HR (9430 033 7310x) DK437873">
				<tension unit="kV">40.0</tension>
				<current unit="mA">15.0</current>
				<anodeMaterial>Cu</anodeMaterial>
				<focus type="Line">
					<length unit="mm">12.0</length>
					<width unit="mm">0.4</width>
					<takeOffAngle unit="deg">6.0</takeOffAngle>
				</focus>
			</xRayTube>
			<filter id="20010004" name="Beta-filter Nickel">
				<material>Ni</material>
				<thickness unit="mm">0.020</thickness>
			</filter>
			<sollerSlit id="21010002" name="Soller slits 0.04 rad.">
				<opening unit="rad">0.0400</opening>
			</sollerSlit>
			<mask id="22031000" name="Fixed mask 13 mm">
				<width unit="mm">9.00</width>
			</mask>
			<divergenceSlit id="22120001" name="Divergence slit 1°" xsi:type="fixedDivergenceSlitType">
				<distanceToSample unit="mm">50.00</distanceToSample>
				<height unit="mm">1.52</height>
			</divergenceSlit>
		</incidentBeamPath>
		<beamKnife id="29030100" name="Beam knife low"/>
		<sampleMovement xsi:type="spinningSampleMovementType">
			<spinnerRevolutionTime unit="seconds">1.0</spinnerRevolutionTime>
		</sampleMovement>
		<diffractedBeamPath>
			<radius unit="mm">145.00</radius>
			<antiScatterSlit id="22090040" name="AS slit 9 mm" xsi:type="fixedAntiScatterSlitType">
				<height unit="mm">9.00</height>
			</antiScatterSlit>
			<sollerSlit id="21020003" name="Large Soller slits 0.04 rad.">
				<opening unit="rad">0.0400</opening>
			</sollerSlit>
			<filter id="20030001" name="Large beta-filter Nickel">
				<material>Ni</material>
				<thickness unit="mm">0.020</thickness>
			</filter>
			<detector id="7010019" name="PIXcel1D-Medipix3 detector" xsi:type="rtmsDetectorType">
				<phd unit="keV">
					<lowerLevel>4.0</lowerLevel>
					<upperLevel>11.3</upperLevel>
				</phd>
				<mode>Scanning</mode>
				<activeLength unit="deg">1.021</activeLength>
			</detector>
		</diffractedBeamPath>
		<scan appendNumber="0" mode="Continuous" scanAxis="Gonio" status="Completed">
			<header>
				<startTimeStamp>2024-03-24T11:17:42-07:00</startTimeStamp>
				<endTimeStamp>2024-03-24T11:20:04-07:00</endTimeStamp>
				<author>
					<name>Instrument</name>
				</author>
				<source>
					<applicationSoftware version="1.6 (94)">PANalytical Aeris Instrument Suite</applicationSoftware>
					<instrumentControlSoftware version="3.0.0 20211014">AERIS</instrumentControlSoftware>
					<instrumentID>2879380</instrumentID>
				</source>
			</header>
			<dataPoints>
				<positions axis="2Theta" unit="deg">
					<startPosition>10.02173288</startPosition>
					<endPosition>139.98435528</endPosition>
				</positions>
				<positions axis="Omega" unit="deg">
					<startPosition>5.01086644</startPosition>
					<endPosition>69.99217764</endPosition>
				</positions>
				<commonCountingTime unit="seconds">1.551</commonCountingTime>
				<counts unit="counts">424 439 412 445 391 419 415 404 376 412 373 407 366 398 393 365 401 422 390 405 418 403 400 406 409 376 429 379 372 355 393 381 405 402 358 347 350 396 333 349 358 331 373 345 361 363 350 349 342 304 367 341 393 328 326 334 320 350 333 331 351 325 307 328 313 335 352 305 297 336 300 320 341 299 288 270 308 293 326 342 317 347 296 319 301 330 325 301 323 306 327 316 334 350 290 315 306 320 292 323 313 308 272 312 289 304 291 267 321 274 309 324 284 276 294 297 345 290 252 295 257 302 268 302 276 271 275 259 324 255 276 292 307 256 276 254 270 258 271 250 249 274 263 295 299 253 265 258 276 305 296 275 283 282 258 246 264 264 270 256 263 264 261 269 263 275 276 276 264 253 249 286 271 251 262 264 251 246 279 255 239 283 274 251 311 310 485 635 440 302 281 280 287 261 254 291 240 212 279 253 299 255 255 272 281 286 242 254 262 233 275 269 233 278 260 269 261 236 241 226 225 264 272 289 248 234 239 262 270 252 287 269 324 383 429 583 602 472 410 262 275 243 278 266 272 260 263 212 219 217 264 211 274 236 236 274 266 251 211 231 203 224 238 226 226 224 225 266 218 243 245 271 246 222 242 229 237 230 202 227 230 206 255 226 242 218 257 265 227 255 192 229 215 212 235 219 223 243 251 221 244 188 205 235 274 223 218 245 270 269 290 325 299 244 252 228 234 218 208 275 256 266 315 375 422 665 935 709 487 271 261 274 239 206 240 236 220 244 228 239 250 221 242 249 242 230 218 253 301 341 397 336 277 248 238 217 201 208 204 233 227 204 220 215 229 227 232 244 236 236 228 227 226 245 205 209 208 206 214 220 206 207 202 251 221 234 218 211 233 227 217 206 216 212 206 194 218 220 225 200 208 208 239 214 188 228 195 234 222 253 210 264 238 254 263 252 225 259 275 275 281 326 348 383 437 536 813 1048 1447 2188 3116 3162 2417 1533 876 529 417 356 342 279 247 260 256 261 221 230 235 273 234 243 237 273 339 410 495 512 510 470 659 826 704 538 369 291 253 222 242 258 214 232 225 223 189 221 202 207 207 225 175 190 202 193 198 221 218 216 207 244 210 208 223 225 193 193 195 180 191 197 195 202 213 216 166 191 199 222 171 210 188 217 237 189 187 217 194 213 191 194 187 216 225 205 230 247 283 270 316 309 386 609 958 1089 1021 962 996 963 807 614 472 306 272 291 239 250 236 255 215 259 321 419 774 824 621 441 300 212 209 196 191 171 184 195 209 209 211 190 200 196 186 180 201 198 211 218 188 199 190 210 213 207 245 330 356 325 334 329 363 403 666 871 807 657 494 307 237 264 185 211 213 180 203 193 206 187 173 210 189 191 192 178 200 213 210 247 247 218 209 203 188 185 210 202 193 175 187 203 181 207 230 187 210 184 172 195 189 186 175 159 215 156 203 171 154 162 188 211 166 160 185 169 185 180 176 214 205 188 182 201 176 185 177 214 162 202 188 206 202 208 244 274 365 394 320 334 294 242 210 197 194 157 155 209 212 189 206 178 202 207 251 252 300 472 518 406 440 278 237 211 216 173 220 152 206 176 214 237 259 350 448 398 371 295 241 278 206 174 194 179 175 187 162 169 184 152 150 159 176 181 174 180 183 170 151 155 165 153 183 148 188 150 138 184 176 162 175 165 142 173 179 201 229 264 340 411 348 299 280 254 201 193 197 183 199 191 168 179 200 188 201 163 214 224 182 199 200 189 210 215 253 222 205 170 195 149 167 192 131 168 156 146 196 141 156 179 141 174 157 182 157 170 177 168 178 158 186 165 153 143 173 232 222 231 253 233 222 220 172 164 211 153 189 163 141 159 149 195 174 191 207 246 255 208 213 217 173 189 185 170 163 178 173 174 174 149 170 168 186 213 178 211 189 193 212 206 189 170 198 200 207 225 222 245 309 338 505 773 1136 1238 932 875 767 506 398 318 287 262 234 227 194 203 157 177 180 197 187 203 193 159 175 171 179 176 175 194 200 183 199 177 208 205 223 224 268 307 415 463 342 355 331 239 247 172 187 197 207 159 166 174 142 192 155 177 182 164 149 192 192 167 154 153 195 172 168 175 161 182 178 198 161 171 158 149 177 169 182 181 176 174 168 160 178 166 157 167 174 177 205 199 194 216 195 194 178 185 195 169 193 169 162 206 208 261 289 245 256 223 211 187 192 165 188 181 176 183 158 163 175 182 166 174 200 165 168 167 186 171 157 181 171 209 187 172 208 183 227 238 307 449 715 753 618 522 500 428 286 195 226 186 225 194 169 185 154 179 166 168 168 151 169 185 166 175 187 190 165 193 188 246 282 283 218 227 206 216 183 189 178 192 177 212 179 194 186 220 205 298 406 896 1168 556 436 631 501 278 257 235 231 259 310 428 639 822 661 561 549 485 365 250 269 204 178 210 210 184 171 173 194 215 234 241 209 189 184 198 217 189 167 196 169 200 204 253 250 300 270 237 234 242 209 169 162 154 152 159 146 189 180 164 162 145 167 151 164 181 162 186 173 188 177 198 170 173 211 227 271 270 235 233 235 222 227 186 167 228 227 227 230 193 209 194 150 166 151 173 153 184 172 157 154 160 149 164 181 162 165 182 208 165 153 181 178 168 169 200 169 186 144 164 152 151 180 123 149 139 194 185 181 184 197 161 179 177 148 170 190 183 247 201 210 208 217 286 330 374 298 296 312 247 217 197 164 178 157 166 151 145 157 176 171 208 155 166 142 173 176 228 236 231 246 207 204 201 200 188 192 172 244 218 261 317 378 334 298 296 302 265 220 198 207 176 199 168 153 145 194 183 192 218 191 167 180 192 193 165 172 162 162 148 174 163 174 163 180 165 150 157 186 171 182 172 159 156 155 145 171 172 150 175 160 161 162 156 147 138 134 142 159 188 155 132 143 120 173 170 151 148 153 137 162 168 140 127 114 140 187 171 155 154 135 154 137 169 162 146 161 155 168 176 165 150 157 172 161 158 178 147 168 170 159 162 172 160 192 182 187 204 181 188 204 179 155 199 167 151 148 159 177 195 181 154 177 157 158 162 162 153 161 144 153 180 154 204 229 198 204 209 224 231 219 169 149 154 153 151 164 156 132 163 184 153 173 160 170 156 163 149 155 140 151 178 204 194 239 240 182 163 173 195 188 177 194 186 164 218 221 261 282 244 192 205 217 193 191 190 196 181 156 160 187 158 184 192 211 188 143 157 146 196 170 150 150 176 168 146 137 182 132 141 175 165 137 154 161 153 143 163 157 164 176 178 196 154 162 177 153 178 166 151 159 140 147 174 154 155 123 153 163 154 145 141 131 168 145 146 153 142 172 176 191 170 159 177 165 193 171 166 172 165 183 195 192 216 159 213 198 189 180 167 188 194 183 145 155 195 237 236 207 203 175 187 229 169 171 150 158 155 155 153 154 164 155 151 118 165 163 185 154 166 159 161 162 231 293 293 247 200 197 258 262 230 223 186 201 257 274 218 185 186 219 230 182 195 183 158 160 167 163 149 138 129 166 148 172 142 153 139 139 155 154 154 143 158 189 170 168 158 157 143 166 166 181 162 164 140 153 154 150 217 249 195 208 188 165 235 176 174 166 162 148 158 151 154 157 149 153 142 158 159 144 157 164 160 189 178 183 203 194 181 154 158 144 149 157 165 156 124 150 135 127 151 147 170 161 148 168 139 156 136 161 156 152 180 164 205 152 164 152 176 147 138 136 147 154 138 137 177 146 147 169 174 181 199 178 182 191 169 176 193 195 165 200 203 193 146 158 168 148 167 164 176 159 167 143 156 174 170 157 148 148 136 152 172 151 149 148 155 174 171 149 166 160 138 140 155 137 170 164 139 133 139 163 158 182 185 161 149 154 180 167 189 167 161 140 171 181 202 183 174 164 189 192 192 191 140 180 152 162 178 148 174 152 154 132 148 152 149 172 141 145 141 130 156 159 163 152 149 173 149 143 133 154 163 133 137 164 144 147 151 137 147 151 134 141 154 146 160 174 156 193 217 211 145 188 164 209 184 169 182 165 148 160 169 173 219 201 227 198 198 183 161 209 225 181 189 239 244 271 219 210 188 191 217 228 223 207 168 179 164 157 137 161 130 162 169 153 131 157 141 135 163 156 181 199 224 177 187 164 149 148 179 160 166 129 155 180 143 175 143 176 149 149 169 158 158 177 137 151 185 161 184 163 185 173 179 162 161 167 152 196 176 172 141 147 182 161 139 149 153 163 122 147 140 133 157 168 158 168 147 156 155 182 164 151 132 160 126 152 184 185 160 132 163 146 158 168 184 154 188 199 200 230 173 175 187 217 227 218 219 176 196 177 143 193 212 184 167 187 155 147 142 185 162 169 171 140 132 141 150 171 149 195 155 149 184 192 161 190 157 144 170 152 178 183 158 155 165 177 146 140 157 152 167 148 174 183 170 193 181 187 227 222 223 207 182 188 182 186 169 194 181 212 176 160 166 157 154 170 147 136 123 126 149 197 164 183 166 168 208 243 204 170 165 171 167 168 176 176 152 136 148 160 168 164 144 157 155 144 142 151 132 144 144 147 158 139 158 149 154 164 148 148 161 161 164 167 144 156 163 167 162 159 159 157 158 151 163 152 155 185 131 143 157 148 164 172 158 181 135 156 144 165 165 125 157 163 131 145 146 153 136 122 167 150 153 180 139 167 147 185 168 199 209 218 177 165 172 140 178 179 156 158 152 156 154 131 109 159 146 147 167 125 126 157 147 162 141 148 171 177 181 179 186 163 165 180 163 149 146 172 149 166 167 140 166 134 174 164 170 133 123 161 131 135 169 153 150 169 187 200 165 166 175 159 160 167 181 151 151 181 137 151 145 153 178 146 121 140 149 145 160 130 148 145 167 180 165 212 189 150 170 146 153 165 149 136 187 173 141 145 168 139 141 132 160 180 163 113 134 140 142 154 126 137 156 167 149 141 141 166 141 145 131 177 150 150 123 162 128 157 165 152 164 141 165 156 167 220 210 182 180 193 202 191 216 216 176 183 187 144 157 176 204 165 161 153 158 154 155 169 130 179 117 154 151 161 134 163 157 141 147 195 204 193 198 172 181 156 187 144 162 161 189 180 177 175 179 154 143 149 146 162 161 124 175 191 162 167 145 176 150 161 150 148 159 176 144 139 164 154 163 150 178 156 165 168 182 159 156 164 130 122 152 137 159 164 136 147 150 141 186 169 164 152 147 154 134 142 124 159 176 156 188 169 162 155 141 142 128 161 147 133 135 151 162 140 135 167 159 166 173 186 152 169 180 154 175 158 184 180 142 158 157 181 159 123 193 155 154 167 129 137 126 148 150 164 127 143 156 162 187 179 155 181 138 129 146 153 173 152 156 148 142 141 147 143 151 148 150 148 147 155 151 169 174 137 127 152 189 178 168 194 187 151 160 152 134 137 143 138 176 163 163 183 135 160 179 169 125 158 150 159 179 147 149 167 161 154 160 184 178 212 218 250 211 239 210 192 184 201 185 188 186 225 193 184 199 162 148 158 147 147 164 145 166 158 153 152 153 177 158 157 160 171 173 163 142 147 164 192 158 160 202 178 162 177 165 149 156 168 152 175 171 159 154 181 166 160 180 189 151 160 182 156 156 198 188 175 174 156 156 149 187 130 177 165 151 158 176 143 160 133 146 117 155 152 131 167 150 155 165 154 178 192 179 143 183 161 174 170 168 152 166 140 208 159 157 153 173 143 173 188 168 140 162 164 146 148 152 146 153 167 158 155 119 146 184 169 194 157 163 156 180 183 174 157 173 165 151 175 155 156 140 151 153 150 142 162 140 149 156 166 159 172 141 151 184 172 191 163 229 228 242 270 212 214 200 214 178 165 193 168 195 199 210 220 205 221 191 167 128 165 171 161 148 175 125 144 166 140 168 167 188 181 156 171 191 164 174 186 180 160 192 162 120 142 153 152 134 178 189 149 150 147 162 135 133 155 137 128 158 152 168 168 134 150 152 170 189 142 163 176 166 166 156 181 168 179 143 130 149 161 165 193 140 172 154 132 176 176 149 159 157 151 159 114 152 137 149 139 163 152 158 149 163 141 163 138 146 140 155 151 142 132 157 166 135 158 169 140 136 132 138 144 156 151 166 146 146 140 167 161 124 133 130 162 154 182 166 159 170 180 202 179 198 166 183 171 171 180 170 190 165 167 172 172 160 187 174 212 188 163 163 162 166 208 171 153 177 156 157 136 158 178 165 157 155 182 208 176 172 168 158 180 170 134 135 169 152 161 189 156 193 160 166 201 146 179 134 167 142 158 160 145 143 173 168 169 175 190 161 173 180 179 225 225 212 180 209 173 173 160 221 197 191 165 192 191 161 175 188 178 181 176 197 162 170 173 185 159 169 144 194 154 176 157 183 148 185 177 159 163 200 185 191 218 230 211 222 219 223 166 166 171 206 179 190 154 181 178 206 194 218 223 201 201 185 202 189 164 167 182 174 160 182 179 193 199 158 171 198 157 203 158 184 197 168 167 187 155 125 187 148 162 167 155 175 158 155 183 143 161 155 158 189 175 165 150 135 163 150 182 181 148 150 160 161 167 142 148 170 157 141 148 171 161 161 194 143 172 192 166 146 195 191 174 192 148 168 177 184 177 168 169 180 175 163 173 163 200 179 135 147 184 173 176 174 166 156 158 141 155 157 152 180 184 163 181 188 184 176 148 181 183 181 179 140 184 172 145 178 197</counts>
			</dataPoints>
		</scan>
	</xrdMeasurement>
</xrdMeasurements>