File: dataset/precursor_mixture/NaHCO3_SnO2_K2SO4_Bi2O3-alpha.2-min.xrdml
<?xml version="1.0"?>
<xrdMeasurements xmlns="http://www.xrdml.com/XRDMeasurement/2.2" xmlns:xsi="http://www.w3.org/2001/XMLSchema-instance" xsi:schemaLocation="http://www.xrdml.com/XRDMeasurement/2.2 http://www.xrdml.com/XRDMeasurement/2.2/XRDMeasurement.xsd" status="Completed" recordIdentifier="{7D84D06D-72DD-491E-ADA6-AF9714A6466A}">
	<comment>
		<entry/>
	</comment>
	<sample type="To be analyzed">
		<id>dara-48-1</id>
		<name></name>
		<preparedBy></preparedBy>
	</sample>
	<xrdMeasurement measurementType="Scan" status="Completed" sampleMode="Reflection">
		<usedWavelength intended="K-Alpha 1">
			<kAlpha1 unit="Angstrom">1.5405980</kAlpha1>
			<kAlpha2 unit="Angstrom">1.5444260</kAlpha2>
			<kBeta unit="Angstrom">1.3922500</kBeta>
			<ratioKAlpha2KAlpha1>0.5000</ratioKAlpha2KAlpha1>
		</usedWavelength>
		<incidentBeamPath>
			<radius unit="mm">145.00</radius>
			<xRayTube id="1010048" name="Empyrean Cu LFF HR (9430 033 7310x) DK437873">
				<tension unit="kV">40.0</tension>
				<current unit="mA">15.0</current>
				<anodeMaterial>Cu</anodeMaterial>
				<focus type="Line">
					<length unit="mm">12.0</length>
					<width unit="mm">0.4</width>
					<takeOffAngle unit="deg">6.0</takeOffAngle>
				</focus>
			</xRayTube>
			<filter id="20010004" name="Beta-filter Nickel">
				<material>Ni</material>
				<thickness unit="mm">0.020</thickness>
			</filter>
			<sollerSlit id="21010002" name="Soller slits 0.04 rad.">
				<opening unit="rad">0.0400</opening>
			</sollerSlit>
			<mask id="22031000" name="Fixed mask 13 mm">
				<width unit="mm">9.00</width>
			</mask>
			<divergenceSlit id="22120001" name="Divergence slit 1°" xsi:type="fixedDivergenceSlitType">
				<distanceToSample unit="mm">50.00</distanceToSample>
				<height unit="mm">1.52</height>
			</divergenceSlit>
		</incidentBeamPath>
		<beamKnife id="29030100" name="Beam knife low"/>
		<sampleMovement xsi:type="spinningSampleMovementType">
			<spinnerRevolutionTime unit="seconds">1.0</spinnerRevolutionTime>
		</sampleMovement>
		<diffractedBeamPath>
			<radius unit="mm">145.00</radius>
			<antiScatterSlit id="22090040" name="AS slit 9 mm" xsi:type="fixedAntiScatterSlitType">
				<height unit="mm">9.00</height>
			</antiScatterSlit>
			<sollerSlit id="21020003" name="Large Soller slits 0.04 rad.">
				<opening unit="rad">0.0400</opening>
			</sollerSlit>
			<filter id="20030001" name="Large beta-filter Nickel">
				<material>Ni</material>
				<thickness unit="mm">0.020</thickness>
			</filter>
			<detector id="7010019" name="PIXcel1D-Medipix3 detector" xsi:type="rtmsDetectorType">
				<phd unit="keV">
					<lowerLevel>4.0</lowerLevel>
					<upperLevel>11.3</upperLevel>
				</phd>
				<mode>Scanning</mode>
				<activeLength unit="deg">1.021</activeLength>
			</detector>
		</diffractedBeamPath>
		<scan appendNumber="0" mode="Continuous" scanAxis="Gonio" status="Completed">
			<header>
				<startTimeStamp>2024-03-25T11:30:48-07:00</startTimeStamp>
				<endTimeStamp>2024-03-25T11:33:10-07:00</endTimeStamp>
				<author>
					<name>AutomatedUser</name>
				</author>
				<source>
					<applicationSoftware version="1.6 (94)">PANalytical Aeris Instrument Suite</applicationSoftware>
					<instrumentControlSoftware version="3.0.0 20211014">AERIS</instrumentControlSoftware>
					<instrumentID>2879380</instrumentID>
				</source>
			</header>
			<dataPoints>
				<positions axis="2Theta" unit="deg">
					<startPosition>10.02173288</startPosition>
					<endPosition>139.98435528</endPosition>
				</positions>
				<positions axis="Omega" unit="deg">
					<startPosition>5.01086644</startPosition>
					<endPosition>69.99217764</endPosition>
				</positions>
				<commonCountingTime unit="seconds">1.551</commonCountingTime>
				<counts unit="counts">377 352 361 401 379 419 411 327 413 393 361 354 357 390 356 366 388 333 366 366 337 356 371 365 338 368 352 351 394 352 329 320 330 300 324 337 305 328 321 271 292 321 300 300 312 339 343 303 279 291 303 310 321 282 306 284 297 290 314 280 296 304 260 332 264 262 243 298 298 272 251 287 281 252 224 267 258 249 245 298 245 248 272 229 253 252 248 242 268 228 248 239 235 249 266 234 253 221 218 247 239 256 215 254 239 240 235 222 234 217 242 274 234 246 224 192 220 215 203 225 213 215 205 208 203 196 207 188 194 221 178 175 184 215 174 185 223 189 196 210 179 203 167 196 198 224 175 205 203 195 190 206 220 209 209 192 180 202 175 192 193 206 168 172 173 178 166 191 214 228 254 284 236 210 224 172 200 174 162 190 171 179 192 186 184 232 332 437 303 197 160 192 181 184 183 157 175 153 156 153 156 168 158 145 168 143 151 152 166 157 178 156 158 162 173 165 178 167 219 235 209 144 143 148 132 144 138 159 136 137 154 138 146 173 156 171 145 152 138 119 136 131 131 147 168 134 151 161 144 126 172 195 218 288 261 258 199 156 127 152 126 145 153 208 214 192 144 168 146 131 121 142 164 130 143 138 117 127 133 123 122 122 100 120 141 130 154 128 104 140 112 119 126 120 133 158 131 154 133 151 132 122 140 119 126 121 146 138 189 235 426 431 298 233 152 138 118 153 123 144 126 134 129 122 175 141 186 274 226 191 151 145 121 121 123 101 118 111 104 112 126 128 107 137 158 159 176 158 198 253 328 346 308 357 535 378 263 168 144 144 164 122 188 183 171 240 280 320 340 458 660 866 1416 1817 1569 1138 695 470 455 576 797 745 511 337 231 233 269 286 443 701 1542 2480 1659 1021 326 188 184 175 217 166 155 175 197 251 425 523 415 283 155 143 125 121 120 127 134 134 122 129 108 112 123 109 138 127 137 187 324 355 289 235 178 183 143 136 121 131 120 110 110 112 163 121 175 220 336 366 279 187 136 137 140 159 213 294 391 502 360 317 295 400 391 349 228 168 196 255 390 919 786 573 377 359 254 209 152 116 119 114 113 104 134 117 121 117 92 96 110 105 77 116 91 85 101 110 105 99 82 118 107 123 102 91 103 95 121 178 195 144 161 127 93 120 131 147 131 208 287 541 796 643 634 509 750 867 579 470 246 216 182 183 181 233 234 329 442 693 1006 1491 1315 1041 696 427 273 229 176 192 148 149 201 221 408 457 336 323 190 129 120 102 107 124 116 144 211 337 314 253 165 138 90 119 143 244 250 219 177 227 432 343 237 180 146 212 256 272 150 152 85 90 88 97 88 79 73 80 82 79 73 90 110 82 93 79 83 91 111 101 169 189 182 214 343 263 237 213 137 139 111 114 144 156 287 357 247 258 229 172 215 265 367 421 387 287 247 163 106 90 111 104 78 99 99 79 79 79 80 74 92 70 102 104 111 144 147 129 143 126 103 71 76 73 82 56 77 65 90 60 86 72 68 73 86 85 86 71 103 124 184 114 123 118 97 73 81 121 121 108 95 107 112 154 167 250 354 237 262 192 112 100 65 54 70 75 77 59 86 82 87 114 129 105 109 117 78 74 75 76 111 118 138 110 90 84 73 69 89 84 98 133 196 139 141 102 90 69 99 98 99 86 67 71 79 61 93 97 97 82 81 69 127 132 92 131 179 177 112 136 104 62 73 56 55 61 79 53 54 57 63 79 61 63 74 87 82 86 84 100 89 83 119 91 83 76 82 82 62 54 70 77 78 94 168 108 110 152 101 78 50 67 72 92 89 73 71 65 93 100 78 90 91 74 127 133 123 151 145 156 301 495 339 287 277 146 82 87 108 71 90 100 78 82 54 61 62 67 76 70 60 65 71 63 64 87 95 101 98 130 96 118 91 120 81 58 66 73 66 71 92 87 76 72 83 101 104 134 205 163 181 223 296 234 212 196 228 145 116 107 115 98 76 88 75 64 73 63 64 66 95 173 141 100 108 106 78 56 74 66 72 81 134 158 112 89 133 93 72 79 73 75 64 66 81 81 99 68 77 55 66 68 64 81 67 65 73 62 63 88 93 73 78 120 131 118 140 160 159 182 250 410 658 951 1020 835 756 789 620 339 266 250 148 182 147 145 219 363 312 173 235 257 133 97 108 107 104 95 96 109 144 211 221 130 156 153 103 72 79 68 55 81 78 82 62 69 59 69 75 57 74 71 49 64 65 80 100 97 98 81 83 88 99 90 98 79 108 166 195 237 345 525 491 280 332 380 235 116 136 116 85 89 123 81 69 116 189 214 153 133 130 118 82 82 82 100 160 189 99 105 136 109 77 73 64 80 71 64 57 65 89 82 82 87 88 87 64 76 96 69 127 286 336 175 156 206 172 81 70 70 79 87 58 75 67 85 95 119 142 215 221 252 204 210 171 157 116 89 115 136 190 123 100 88 165 108 116 105 94 91 107 96 72 73 76 94 120 137 149 107 101 94 77 76 74 60 58 68 59 47 73 60 66 49 54 57 77 74 80 85 64 69 74 66 71 67 66 65 71 59 65 76 59 56 50 66 61 75 85 86 66 71 77 73 71 73 71 75 55 75 77 84 149 142 106 122 126 113 146 208 246 319 258 215 227 186 172 126 109 96 119 104 92 107 143 130 98 112 114 107 93 84 65 76 94 72 69 68 67 74 71 58 72 59 70 64 73 79 91 97 106 78 77 85 80 52 44 62 55 90 86 120 100 70 88 106 107 80 84 79 88 113 122 130 162 228 237 185 162 172 167 128 143 78 83 100 92 71 80 82 84 75 64 65 80 99 98 94 110 108 145 153 226 296 271 208 194 167 166 163 149 123 87 80 90 74 64 65 92 62 64 74 130 103 136 117 89 81 68 79 79 80 66 51 54 57 57 54 42 65 58 62 58 63 52 65 120 74 49 64 65 66 81 39 56 61 57 63 58 72 87 124 97 83 61 77 97 86 58 88 74 72 78 65 63 55 63 68 100 112 93 69 82 92 97 78 78 101 63 98 101 92 71 77 74 63 61 48 43 46 59 69 66 54 48 48 61 52 53 67 56 66 74 90 72 74 76 74 69 74 92 115 142 142 165 156 186 178 148 112 114 106 81 95 79 75 59 59 55 61 72 60 49 71 85 68 101 93 101 52 63 73 82 78 55 50 52 59 60 55 54 45 47 64 48 37 76 50 51 50 43 63 62 49 65 54 60 56 61 47 44 39 43 70 83 79 67 54 57 60 67 92 86 103 70 68 54 75 79 71 63 72 47 50 57 80 55 40 40 60 62 42 43 46 45 57 66 57 47 58 75 53 64 52 55 45 58 48 60 51 67 70 56 50 59 57 65 66 83 76 59 84 79 56 63 44 73 52 75 69 42 59 48 67 86 56 66 64 50 71 70 74 78 84 71 76 61 54 63 59 55 51 48 50 44 55 39 44 39 72 73 58 50 70 86 76 79 100 150 188 200 163 137 111 114 143 121 137 100 93 110 103 118 110 95 67 82 70 74 79 55 83 112 115 68 80 67 69 69 63 71 53 66 92 93 79 82 71 112 77 66 61 70 60 65 57 43 55 53 60 64 60 74 67 100 98 76 91 87 70 87 89 69 77 58 64 67 69 59 49 44 69 46 51 39 53 79 95 118 139 82 82 81 76 81 76 59 54 52 41 49 68 41 64 66 63 64 76 62 52 54 60 70 62 59 73 69 77 68 85 77 131 173 196 130 89 104 98 106 126 100 68 80 78 92 111 78 78 55 86 92 61 63 51 64 60 53 57 60 67 51 73 48 58 47 63 59 89 75 70 62 57 46 58 68 70 48 54 55 74 43 45 45 49 42 58 46 57 62 50 48 39 64 48 67 82 111 67 78 68 72 79 90 106 94 62 71 76 75 71 79 98 116 92 67 79 66 76 96 118 104 106 73 74 62 73 74 72 72 53 71 64 53 55 59 83 90 64 58 61 42 48 62 57 57 62 53 56 60 69 74 76 70 61 52 56 54 79 70 67 77 69 57 67 92 72 98 106 137 149 152 121 97 132 134 117 136 113 89 75 78 67 63 72 76 92 78 46 61 88 77 95 103 96 182 145 102 106 82 119 104 140 118 91 83 80 75 61 67 75 45 63 65 56 59 57 76 65 81 62 62 73 72 93 74 83 83 55 64 77 63 51 53 58 49 63 55 60 62 76 64 52 80 63 68 93 72 126 115 88 66 67 70 101 95 94 68 61 87 45 78 82 69 58 63 70 61 49 77 57 64 59 69 66 41 53 65 69 56 53 53 42 53 47 60 48 67 52 59 47 57 54 50 64 66 67 42 66 55 68 78 78 76 78 74 87 72 98 109 103 104 107 95 72 78 66 81 55 66 65 61 66 70 46 56 46 60 64 76 51 45 52 59 50 37 57 59 47 39 61 60 46 49 45 55 53 60 52 46 62 68 46 58 72 66 48 56 51 55 58 53 52 58 44 47 52 40 60 41 46 46 50 58 54 62 44 47 53 66 57 75 53 66 46 62 66 63 53 64 50 66 61 64 65 71 62 75 50 53 68 73 90 84 85 74 90 76 63 85 69 69 68 56 69 53 63 48 69 81 64 67 91 62 49 78 62 73 76 74 50 70 51 60 59 52 52 56 55 65 43 54 37 37 35 60 45 57 43 50 47 30 38 45 55 56 55 38 36 37 56 63 79 78 61 53 62 65 61 63 76 66 63 57 67 64 48 68 69 83 98 71 51 68 73 63 81 80 86 61 71 71 67 57 46 48 66 63 65 53 62 62 68 40 48 57 59 52 55 59 47 49 63 45 73 60 62 46 65 48 68 51 69 79 68 58 45 37 60 56 64 60 78 55 44 43 56 59 47 49 51 52 40 44 48 66 52 39 38 55 57 40 42 45 48 56 52 48 59 63 61 48 50 44 43 49 62 53 74 75 82 67 77 77 59 83 80 76 86 81 63 79 105 96 119 127 124 143 148 160 174 140 124 130 138 115 90 117 98 112 90 102 83 69 59 73 73 60 68 50 64 58 61 42 69 51 56 78 79 74 74 71 62 65 62 61 79 68 60 48 73 67 56 58 43 71 60 61 60 62 49 66 52 56 68 42 60 43 71 57 75 51 66 65 61 67 76 65 72 66 67 70 76 53 70 84 66 89 112 95 75 109 101 93 69 70 69 93 79 74 89 84 75 62 54 71 68 42 52 56 71 49 53 46 79 54 43 61 39 64 48 54 65 54 49 42 75 64 63 49 54 54 66 65 53 49 59 59 46 64 55 63 82 47 53 69 67 57 72 76 97 108 114 123 114 97 82 81 93 57 105 85 106 94 73 69 81 54 65 68 67 82 81 89 73 82 91 81 98 154 153 137 131 114 95 103 85 72 94 112 84 119 108 79 87 65 94 72 56 67 60 68 58 69 73 62 71 51 61 67 49 57 66 63 58 61 45 66 60 68 75 57 75 84 62 62 53 56 62 52 64 71 50 65 50 52 70 65 66 79 46 63 46 70 56 63 73 61 68 53 55 51 48 55 82 61 60 74 55 51 62 60 59 50 49 50 44 44 73 59 73 73 54 47 67 66 76 66 65 65 92 71 66 65 82 61 71 63 55 62 73 73 78 77 67 62 78 55 69 68 70 89 87 97 83 112 126 175 141 163 171 158 152 124 123 103 121 114 116 137 116 125 134 114 108 85 101 85 87 71 58 69 82 76 60 88 71 64 69 47 61 59 62 51 52 50 60 58 55 43 46 52 58 52 42 53 40 49 53 52 47 64 58 63 53 55 48 56 58 55 51 63 51 48 52 60 61 50 56 58 58 86 66 46 45 42 40 57 63 48 43 57 52 44 46 58 54 56 57 58 39 47 52 42 65 55 60 49 65 72 70 62 55 58 45 56 58 59 53 61 54 68 64 50 54 43 62 44 75 60 52 63 79 62 59 58 71 64 61 40 82 47 66 70 60 74 71 57 52 64 69 67 69 51 64 45 76 56 57 55 63 69 63 52 65 60 78 85 68 53 54 54 57 87 58 78 96 80 85 74 90 71 53 56 53 63 67 84 109 74 61 69 65 62 74 72 73 63 66 46 59 79 94 120 81 101 110 163 145 138 134 112 116 82 101 105 94 108 119 113 105 126 102 110 91 109 91 84 86 77 76 65 79 63 60 62 66 73 62 60 64 57 81 68 71 48 67 76 61 83 75 60 83 76 56 71 50 76 59 56 74 47 65 67 74 56 56 57 61 72 79 72 66 78 80 90 63 66 93 87 98 83 78 93 91 63 59 67 60 61 52 79 60 68 63 55 92 87 52 89 75 54 74 73 63 69 66 81 63 71 59 56 55 61 57 56 47 55 72 72 69 85 71 97 60 81 77 80 75 89 76 72 36 55 55 79 86 78 70 83 63 77 58 85 75 77 74 80 71 72 69 66 88 82 78 64 66 82 86 69 86 88 72 89 90 91 102 124 131 90 78 83 80 75 93 108 92 88 107 91 90 96 115 90 92 94 99 78 75 97 71 70 77 78 91 69 74 87 88 62 81 69 61 70 67 60 59 56 72 60 51 57 53 63 58 61 80 77 69 51 91 72 60 92 71 66 47 75 70 54 73 54 49 50 71 75 81 68 70 47 57 64 66 60 75 67 50 58 69 83 67 63 60 45 64 75 54 51 66 68 48 79 67 83 79 80 56 62 53 54 57 65 61 39 63 64 76 65 49 63 66 60 66 70 52 45</counts>
			</dataPoints>
		</scan>
	</xrdMeasurement>
</xrdMeasurements>