File: dataset/precursor_mixture/NaHCO3_Cr2O3_Fe3O4_CuO.2-min.xrdml
<?xml version="1.0"?>
<xrdMeasurements xmlns="http://www.xrdml.com/XRDMeasurement/2.2" xmlns:xsi="http://www.w3.org/2001/XMLSchema-instance" xsi:schemaLocation="http://www.xrdml.com/XRDMeasurement/2.2 http://www.xrdml.com/XRDMeasurement/2.2/XRDMeasurement.xsd" status="Completed" recordIdentifier="{9EC3DBB1-E10C-491B-A726-193A4C3F6A8D}">
	<comment>
		<entry/>
	</comment>
	<sample type="To be analyzed">
		<id>dara-14-1</id>
		<name></name>
		<preparedBy></preparedBy>
	</sample>
	<xrdMeasurement measurementType="Scan" status="Completed" sampleMode="Reflection">
		<usedWavelength intended="K-Alpha 1">
			<kAlpha1 unit="Angstrom">1.5405980</kAlpha1>
			<kAlpha2 unit="Angstrom">1.5444260</kAlpha2>
			<kBeta unit="Angstrom">1.3922500</kBeta>
			<ratioKAlpha2KAlpha1>0.5000</ratioKAlpha2KAlpha1>
		</usedWavelength>
		<incidentBeamPath>
			<radius unit="mm">145.00</radius>
			<xRayTube id="1010048" name="Empyrean Cu LFF HR (9430 033 7310x) DK437873">
				<tension unit="kV">40.0</tension>
				<current unit="mA">15.0</current>
				<anodeMaterial>Cu</anodeMaterial>
				<focus type="Line">
					<length unit="mm">12.0</length>
					<width unit="mm">0.4</width>
					<takeOffAngle unit="deg">6.0</takeOffAngle>
				</focus>
			</xRayTube>
			<filter id="20010004" name="Beta-filter Nickel">
				<material>Ni</material>
				<thickness unit="mm">0.020</thickness>
			</filter>
			<sollerSlit id="21010002" name="Soller slits 0.04 rad.">
				<opening unit="rad">0.0400</opening>
			</sollerSlit>
			<mask id="22031000" name="Fixed mask 13 mm">
				<width unit="mm">9.00</width>
			</mask>
			<divergenceSlit id="22120001" name="Divergence slit 1°" xsi:type="fixedDivergenceSlitType">
				<distanceToSample unit="mm">50.00</distanceToSample>
				<height unit="mm">1.52</height>
			</divergenceSlit>
		</incidentBeamPath>
		<beamKnife id="29030100" name="Beam knife low"/>
		<sampleMovement xsi:type="spinningSampleMovementType">
			<spinnerRevolutionTime unit="seconds">1.0</spinnerRevolutionTime>
		</sampleMovement>
		<diffractedBeamPath>
			<radius unit="mm">145.00</radius>
			<antiScatterSlit id="22090040" name="AS slit 9 mm" xsi:type="fixedAntiScatterSlitType">
				<height unit="mm">9.00</height>
			</antiScatterSlit>
			<sollerSlit id="21020003" name="Large Soller slits 0.04 rad.">
				<opening unit="rad">0.0400</opening>
			</sollerSlit>
			<filter id="20030001" name="Large beta-filter Nickel">
				<material>Ni</material>
				<thickness unit="mm">0.020</thickness>
			</filter>
			<detector id="7010019" name="PIXcel1D-Medipix3 detector" xsi:type="rtmsDetectorType">
				<phd unit="keV">
					<lowerLevel>4.0</lowerLevel>
					<upperLevel>11.3</upperLevel>
				</phd>
				<mode>Scanning</mode>
				<activeLength unit="deg">1.021</activeLength>
			</detector>
		</diffractedBeamPath>
		<scan appendNumber="0" mode="Continuous" scanAxis="Gonio" status="Completed">
			<header>
				<startTimeStamp>2024-03-24T18:05:28-07:00</startTimeStamp>
				<endTimeStamp>2024-03-24T18:07:50-07:00</endTimeStamp>
				<author>
					<name>AutomatedUser</name>
				</author>
				<source>
					<applicationSoftware version="1.6 (94)">PANalytical Aeris Instrument Suite</applicationSoftware>
					<instrumentControlSoftware version="3.0.0 20211014">AERIS</instrumentControlSoftware>
					<instrumentID>2879380</instrumentID>
				</source>
			</header>
			<dataPoints>
				<positions axis="2Theta" unit="deg">
					<startPosition>10.02173288</startPosition>
					<endPosition>139.98435528</endPosition>
				</positions>
				<positions axis="Omega" unit="deg">
					<startPosition>5.01086644</startPosition>
					<endPosition>69.99217764</endPosition>
				</positions>
				<commonCountingTime unit="seconds">1.551</commonCountingTime>
				<counts unit="counts">589 528 533 580 519 552 517 562 538 593 542 573 550 592 547 510 546 572 559 540 535 531 553 515 534 545 524 529 565 496 490 568 511 481 530 587 546 517 572 513 542 513 527 532 493 508 533 530 526 522 492 515 504 514 513 497 545 500 509 472 453 460 522 452 476 454 490 496 490 485 490 507 438 480 512 459 460 508 440 429 474 481 466 503 464 553 487 512 491 490 512 511 453 500 457 485 428 487 494 484 496 450 452 473 490 458 468 496 479 473 462 444 516 491 489 460 425 462 462 447 469 471 465 500 467 467 440 452 508 452 467 444 452 472 466 504 420 458 465 472 470 453 481 495 447 480 456 483 530 440 439 467 483 481 461 431 409 454 467 440 445 435 494 454 493 478 476 469 464 452 432 449 473 458 483 531 509 463 504 491 467 519 495 493 544 592 818 890 699 478 483 463 467 474 458 458 446 470 495 465 482 503 461 473 457 481 476 487 458 486 517 486 511 483 446 480 444 455 433 484 489 452 492 509 441 467 496 457 480 469 488 474 441 463 514 507 459 461 418 497 497 486 480 517 504 441 490 490 497 480 481 462 411 459 423 501 468 503 493 478 455 467 470 476 456 447 520 499 437 474 471 464 438 490 464 449 434 466 462 464 416 473 461 437 464 486 458 449 489 461 463 485 482 456 469 449 449 477 508 466 428 426 448 444 453 448 439 474 468 469 556 629 575 509 530 460 463 449 449 456 453 507 518 547 629 806 900 734 620 482 437 515 440 456 433 483 457 476 468 436 479 465 446 428 452 426 446 531 503 547 633 563 493 481 455 456 451 444 436 461 505 460 428 416 448 432 421 498 447 419 440 422 429 454 470 461 417 451 413 439 419 440 414 446 442 440 434 454 412 460 461 451 447 398 462 428 409 449 445 412 415 478 436 435 420 425 451 458 424 454 469 439 450 428 443 466 454 439 406 391 429 440 459 440 445 440 549 520 483 485 457 456 467 422 449 477 435 431 450 424 495 463 405 433 436 435 476 495 531 558 624 751 764 885 872 881 758 678 657 681 691 614 512 481 495 451 427 477 442 441 425 463 441 416 432 425 436 436 419 443 454 462 415 421 439 410 439 394 452 385 422 393 432 463 431 424 391 429 419 418 438 445 452 425 419 436 476 451 448 435 422 426 458 425 406 441 450 395 408 453 435 424 447 459 453 477 484 519 537 677 928 1044 849 779 575 531 446 459 426 420 432 439 423 385 429 458 429 471 505 505 614 615 579 523 489 439 441 439 460 436 472 440 461 431 465 490 504 535 612 725 1002 1406 1663 1659 1447 1193 1017 841 658 591 506 512 483 494 463 512 505 593 697 884 779 741 679 486 468 446 425 444 436 446 432 424 435 431 454 422 445 420 413 505 443 418 443 447 438 467 456 434 445 411 438 421 482 449 386 445 412 439 434 417 439 449 431 437 494 434 456 455 480 450 499 541 588 669 758 796 791 797 715 658 584 537 597 541 520 486 471 440 472 471 424 387 423 432 428 380 420 435 429 424 447 430 430 403 407 420 423 408 433 411 420 407 416 415 448 412 409 415 440 438 460 575 587 542 492 487 413 374 426 450 417 425 454 445 414 425 439 520 562 581 468 504 441 417 387 391 400 421 415 409 421 403 412 412 420 363 437 405 389 409 406 407 406 387 400 422 458 439 425 369 437 469 501 581 527 527 586 507 480 434 411 409 438 413 408 444 399 430 402 409 409 410 415 385 438 402 426 411 401 422 420 430 437 435 420 448 418 474 449 439 435 418 419 387 341 391 413 405 402 443 385 417 379 385 387 364 420 389 393 424 422 381 383 392 420 402 393 412 399 444 476 474 453 436 448 417 393 375 383 380 372 399 383 354 377 400 390 411 408 445 377 442 439 420 415 392 413 419 402 383 411 387 379 436 395 410 355 412 406 413 411 379 369 396 397 401 403 395 393 416 414 396 393 417 412 459 486 423 475 473 523 496 621 546 562 541 481 436 417 416 414 442 416 392 398 438 416 430 389 425 391 417 379 420 420 419 422 399 422 432 434 466 425 471 553 605 535 526 481 482 423 441 378 411 382 403 416 393 398 395 387 398 377 364 396 398 374 416 371 398 414 402 377 405 399 424 415 411 402 359 398 391 406 419 448 403 402 404 364 424 407 416 409 412 386 406 407 415 407 434 418 424 433 443 395 428 419 375 389 400 441 417 402 415 459 473 472 510 475 482 468 431 447 416 413 401 416 377 416 412 412 387 438 404 388 413 380 405 396 419 423 391 435 429 438 467 487 591 736 888 714 647 655 586 508 415 436 445 423 406 396 400 394 437 385 421 414 398 434 397 414 360 381 390 391 371 393 416 431 384 388 353 396 431 398 393 421 410 453 446 409 461 455 478 536 577 708 1063 1278 756 678 813 675 472 466 423 417 442 396 358 373 414 447 419 427 388 423 430 414 389 430 401 395 437 428 465 457 476 467 470 429 425 428 439 424 425 376 416 429 392 403 398 433 420 413 410 385 428 397 409 391 408 395 431 396 370 383 402 378 409 393 425 397 409 421 405 410 412 367 346 419 375 393 439 444 401 374 409 416 394 386 429 389 427 458 436 379 398 412 391 423 375 407 415 400 380 408 450 502 523 493 449 448 471 398 438 423 423 410 443 422 436 387 412 403 409 395 427 459 514 558 638 604 654 645 615 550 542 507 504 455 405 426 429 397 415 446 429 364 456 463 486 527 507 499 472 475 488 438 425 391 409 403 408 439 412 387 413 356 436 386 411 424 360 390 361 403 395 399 389 410 379 375 415 426 376 422 436 478 499 537 530 511 510 510 487 438 463 440 446 450 483 441 379 442 432 464 430 453 434 457 399 402 454 463 402 452 465 436 464 459 423 408 466 402 358 380 395 406 382 390 407 396 390 404 389 412 407 372 408 428 397 397 378 387 404 401 393 410 405 417 406 460 419 469 438 433 405 450 408 422 449 416 437 426 419 397 399 383 403 408 397 363 433 424 369 356 388 411 381 389 383 407 423 450 437 395 400 408 413 420 418 412 409 407 388 398 384 380 377 399 372 440 406 388 396 421 386 398 386 374 378 378 361 377 347 435 374 392 438 403 415 397 389 375 378 388 401 379 408 429 423 382 380 363 365 392 394 406 405 398 397 397 406 392 382 401 366 372 408 393 372 439 426 409 405 424 400 425 431 379 379 408 417 461 449 469 441 405 439 417 446 443 414 352 402 404 400 355 419 399 415 413 366 426 381 392 416 431 459 410 424 450 412 414 407 391 415 398 439 454 382 375 408 402 405 382 389 418 404 401 455 415 394 422 421 403 418 419 440 426 458 420 370 442 366 385 367 416 413 366 342 435 443 362 388 433 354 399 371 404 420 382 399 410 384 429 438 448 453 405 439 437 443 437 435 418 396 382 440 397 395 383 400 412 399 387 396 421 400 395 382 448 371 396 386 400 375 393 444 369 374 387 359 411 389 376 414 407 348 380 424 351 381 381 381 391 373 398 382 405 470 438 497 483 391 441 385 451 428 427 380 367 413 392 381 433 373 383 394 436 362 363 359 377 375 360 382 388 437 392 401 377 397 356 393 390 395 385 394 394 385 402 402 377 414 410 396 400 359 366 386 394 406 414 360 402 420 404 365 380 401 393 404 377 403 389 371 367 393 400 397 399 407 360 385 423 383 381 436 414 394 422 398 420 388 374 367 385 386 397 381 388 406 407 382 391 399 378 409 399 386 389 430 395 393 398 398 396 408 398 373 374 389 373 433 368 437 370 419 412 412 375 401 387 381 388 418 356 355 405 404 390 372 380 384 400 404 388 419 389 415 375 396 371 379 400 403 374 377 374 379 413 381 419 414 459 410 438 380 390 391 372 387 434 365 399 388 356 403 427 399 461 438 433 393 422 432 379 472 432 413 385 423 408 388 418 387 389 406 396 397 408 360 363 361 382 409 409 403 396 404 394 378 390 411 412 376 414 384 380 413 400 369 371 376 381 396 403 394 380 375 404 355 358 408 358 361 376 415 397 410 396 414 361 397 382 429 433 425 411 444 466 408 445 443 436 427 423 438 426 458 457 490 463 433 437 467 394 380 425 385 422 418 428 393 404 380 358 400 407 386 379 383 390 398 396 403 393 387 417 386 381 414 371 410 385 379 398 371 382 405 375 399 353 391 358 408 384 373 385 373 371 409 402 391 384 415 381 390 428 405 371 423 415 371 377 383 373 379 420 427 402 407 399 439 388 377 387 386 436 401 403 423 367 419 363 389 417 393 381 408 364 402 330 394 391 352 387 461 369 401 427 415 415 417 431 398 385 387 412 423 403 385 390 385 424 405 421 418 427 401 376 402 440 406 445 407 399 392 430 389 404 429 427 400 388 342 416 379 379 400 383 405 381 424 395 415 382 386 384 417 430 379 352 399 381 385 452 415 387 405 377 395 401 393 377 413 395 422 359 382 387 406 374 381 417 370 364 400 406 401 381 366 371 356 364 410 374 406 428 355 392 371 424 384 426 415 370 363 406 406 405 420 401 400 373 377 424 387 379 368 426 403 385 411 348 413 379 407 412 361 382 412 382 374 405 429 433 376 400 344 411 386 381 420 377 383 411 386 387 359 359 389 405 419 393 391 378 384 374 410 420 415 373 369 418 377 405 352 386 357 383 392 414 423 381 395 399 408 391 384 424 370 386 395 405 423 385 388 405 415 407 405 463 405 333 367 359 376 366 369 416 408 398 379 386 402 377 389 408 396 406 438 412 402 406 420 373 371 364 414 439 383 396 376 416 380 369 370 409 384 365 394 407 415 377 368 413 400 366 363 440 404 400 380 406 409 400 376 362 419 434 428 364 402 435 433 422 423 416 430 397 360 417 411 409 384 390 391 384 393 371 407 393 375 403 413 414 375 406 397 374 421 408 378 375 421 373 394 389 365 391 387 383 366 385 399 398 406 398 395 411 409 376 441 396 390 353 392 385 382 402 412 396 380 412 412 379 415 370 415 410 366 373 380 412 398 411 390 434 407 394 387 382 378 403 427 360 397 382 400 401 438 397 429 411 406 388 392 403 393 427 383 384 452 419 420 399 412 427 419 448 437 409 399 403 438 371 414 429 435 443 437 433 410 417 411 414 396 375 452 382 430 382 386 383 414 409 403 406 395 425 398 399 383 392 409 424 410 410 442 421 380 424 394 425 399 392 380 366 405 379 410 390 394 370 389 383 420 357 385 378 343 383 391 425 434 389 375 381 372 416 385 420 408 398 367 433 409 399 385 397 400 399 403 347 390 393 410 388 339 407 389 389 410 385 433 401 420 388 369 386 376 428 395 408 404 405 387 379 409 382 376 371 428 381 385 388 401 374 426 380 396 409 443 433 392 390 375 400 390 394 394 406 398 393 415 376 369 389 400 404 405 399 411 380 413 406 433 439 408 411 431 405 419 350 383 397 408 366 432 382 392 400 404 399 395 416 420 396 420 389 432 403 363 400 382 375 424 350 408 395 392 447 401 454 408 387 430 426 428 444 410 428 404 443 409 393 407 393 373 425 417 394 417 419 375 364 418 399 389 409 387 406 435 370 401 382 387 398 416 430 409 413 421 434 414 413 416 394 437 400 441 407 402 406 456 416 406 390 376 399 434 415 429 390 389 385 400 407 401 378 386 418 395 409 414 362 445 412 388 399 342 419 432 389 440 378 393 457 428 392 365 421 416 404 459 452 350 444 435 398 423 377 422 411 419 417 412 420 391 393 403 331 382 398 364 368 396 423 402 413 390 416 424 376 366 366 370 369 381 369 424 371 395 424 377 347 380 384 419 378 414 379 395 402 391 404 375 393 379 380 417 420 389 396 434 403 410 425 421 395 367 382 436 405 437 415 463 470 405 423 413 403 405 378 459 416 388 431 414 461 428 413 397 407 426 400 389 418 391 380 373 414 394 407 400 400 386 410 394 439 421 427 408 390 416 407 410 420 395 399 433 427 421 398 401 447 417 467 407 399 416 419 441 437 431 412 441 487 457 433 459 466 434 418 412 399 394 438 438 462 431 413 394 405 423 421 433 478 419 388 400 400 456 372 431 401 426 438 445 388 370 407 433 387 341 399 408 421 392 390 384 433 410 435 405 416 380 365 427 365 408 392 406 393 418 377 391 419 379 469 389 359 402 427 407 432 397 385 437 389 431 423 399 364 407 440 427 399 451 394 422 443 418 430 420 395 466 392 449 394 409 446 386 414 408 412 418 418 418 412 409 397 407 423 436 399 395 391 405 396 386 373 426 388 373 395 432 390 400 401 426 417 416 397 391 393 396 393 355 410 372 365 409 415 382 409 443 428 353 435 420 385 383 415 426 410 395 433 393 396 433 419 432 368 448 407 436 406 416 429 395 413 426 410 410 442 388 384 407 415 420 435 400 379 440 403 406 378 410 389 405 418 383 390 378 413 387 401 392 410 383 396 377 387 434 403 434 392 440 404 389 421 406 393 409 398 403 447 432 432 389 440 432 421 441 384 413 376 420 384 421 413 438 408 405 415 388 395 411 427 393 401 402 439 386 360 427 389 402 373 404 436 366 426 404 415 380 416 402 392 418 444 397 446 435 396 413 394 404 440 388 420 411 384 405 419 424 399 414 409 392 406 418 431 396 385 402 421 422 418 443 389 421 393 399 400 419 399 412 394 410 392 404 412 375 420 401 426 432 459 432 389 418 365 426 387 406 392 399 384 393 436 403 390 411 394 417 396 387 391 429 385 400 422 414 405 379 437</counts>
			</dataPoints>
		</scan>
	</xrdMeasurement>
</xrdMeasurements>