File: dataset/precursor_mixture/NaHCO3_Cr2O3_Fe3O4_CuO.12-min.xrdml
<?xml version="1.0"?>
<xrdMeasurements xmlns="http://www.xrdml.com/XRDMeasurement/2.2" xmlns:xsi="http://www.w3.org/2001/XMLSchema-instance" xsi:schemaLocation="http://www.xrdml.com/XRDMeasurement/2.2 http://www.xrdml.com/XRDMeasurement/2.2/XRDMeasurement.xsd" status="Completed" recordIdentifier="{422A3E29-55F5-4417-80E6-4076E685C2B7}">
	<comment>
		<entry/>
	</comment>
	<sample type="To be analyzed">
		<id>dara-14-2</id>
		<name></name>
		<preparedBy></preparedBy>
	</sample>
	<xrdMeasurement measurementType="Scan" status="Completed" sampleMode="Reflection">
		<usedWavelength intended="K-Alpha 1">
			<kAlpha1 unit="Angstrom">1.5405980</kAlpha1>
			<kAlpha2 unit="Angstrom">1.5444260</kAlpha2>
			<kBeta unit="Angstrom">1.3922500</kBeta>
			<ratioKAlpha2KAlpha1>0.5000</ratioKAlpha2KAlpha1>
		</usedWavelength>
		<incidentBeamPath>
			<radius unit="mm">145.00</radius>
			<xRayTube id="1010048" name="Empyrean Cu LFF HR (9430 033 7310x) DK437873">
				<tension unit="kV">40.0</tension>
				<current unit="mA">15.0</current>
				<anodeMaterial>Cu</anodeMaterial>
				<focus type="Line">
					<length unit="mm">12.0</length>
					<width unit="mm">0.4</width>
					<takeOffAngle unit="deg">6.0</takeOffAngle>
				</focus>
			</xRayTube>
			<filter id="20010004" name="Beta-filter Nickel">
				<material>Ni</material>
				<thickness unit="mm">0.020</thickness>
			</filter>
			<sollerSlit id="21010002" name="Soller slits 0.04 rad.">
				<opening unit="rad">0.0400</opening>
			</sollerSlit>
			<mask id="22031000" name="Fixed mask 13 mm">
				<width unit="mm">9.00</width>
			</mask>
			<divergenceSlit id="22120001" name="Divergence slit 1°" xsi:type="fixedDivergenceSlitType">
				<distanceToSample unit="mm">50.00</distanceToSample>
				<height unit="mm">1.52</height>
			</divergenceSlit>
		</incidentBeamPath>
		<beamKnife id="29030100" name="Beam knife low"/>
		<sampleMovement xsi:type="spinningSampleMovementType">
			<spinnerRevolutionTime unit="seconds">1.0</spinnerRevolutionTime>
		</sampleMovement>
		<diffractedBeamPath>
			<radius unit="mm">145.00</radius>
			<antiScatterSlit id="22090040" name="AS slit 9 mm" xsi:type="fixedAntiScatterSlitType">
				<height unit="mm">9.00</height>
			</antiScatterSlit>
			<sollerSlit id="21020003" name="Large Soller slits 0.04 rad.">
				<opening unit="rad">0.0400</opening>
			</sollerSlit>
			<filter id="20030001" name="Large beta-filter Nickel">
				<material>Ni</material>
				<thickness unit="mm">0.020</thickness>
			</filter>
			<detector id="7010019" name="PIXcel1D-Medipix3 detector" xsi:type="rtmsDetectorType">
				<phd unit="keV">
					<lowerLevel>4.0</lowerLevel>
					<upperLevel>11.3</upperLevel>
				</phd>
				<mode>Scanning</mode>
				<activeLength unit="deg">5.020</activeLength>
			</detector>
		</diffractedBeamPath>
		<scan appendNumber="0" mode="Continuous" scanAxis="Gonio" status="Completed">
			<header>
				<startTimeStamp>2024-03-24T18:08:16-07:00</startTimeStamp>
				<endTimeStamp>2024-03-24T18:20:44-07:00</endTimeStamp>
				<author>
					<name>AutomatedUser</name>
				</author>
				<source>
					<applicationSoftware version="1.6 (94)">PANalytical Aeris Instrument Suite</applicationSoftware>
					<instrumentControlSoftware version="3.0.0 20211014">AERIS</instrumentControlSoftware>
					<instrumentID>2879380</instrumentID>
				</source>
			</header>
			<dataPoints>
				<positions axis="2Theta" unit="deg">
					<startPosition>9.99043322</startPosition>
					<endPosition>100.09495370</endPosition>
				</positions>
				<positions axis="Omega" unit="deg">
					<startPosition>4.99521661</startPosition>
					<endPosition>50.04747685</endPosition>
				</positions>
				<commonCountingTime unit="seconds">18.249</commonCountingTime>
				<counts unit="counts">5815 5899 5864 5735 5880 5872 5825 5793 5830 5886 5806 5904 5856 5926 5863 6087 5660 5808 5819 5779 5748 5871 5792 5769 5800 5844 5835 5785 5760 5699 5720 5761 5680 5855 5766 5750 5653 5666 5721 5743 5691 5835 5547 5706 5700 5725 5682 5636 5657 5636 5705 5687 5613 5659 5699 5774 5744 5668 5633 5815 5667 5702 5675 5699 5669 5730 5712 5667 5759 5769 5750 5642 5703 5615 5684 5623 5604 5590 5569 5681 5700 5523 5597 5491 5690 5554 5685 5642 5719 5746 5574 5568 5558 5564 5595 5577 5517 5637 5588 5610 5681 5669 5630 5680 5523 5708 5681 5436 5647 5667 5505 5534 5597 5611 5582 5550 5528 5532 5486 5679 5573 5585 5571 5695 5589 5686 5548 5576 5627 5475 5533 5569 5474 5641 5509 5451 5555 5535 5372 5515 5455 5549 5485 5565 5446 5396 5448 5651 5558 5403 5493 5415 5457 5408 5487 5497 5394 5346 5547 5521 5391 5435 5529 5450 5609 5431 5524 5317 5418 5527 5374 5402 5574 5520 5406 5500 5341 5400 5427 5412 5419 5417 5365 5408 5552 5569 5502 5545 5431 5326 5286 5393 5549 5471 5340 5451 5508 5364 5373 5458 5434 5540 5372 5455 5417 5481 5304 5443 5313 5503 5643 5446 5376 5466 5445 5362 5433 5337 5493 5253 5331 5316 5282 5331 5418 5243 5375 5480 5415 5496 5365 5328 5335 5257 5414 5377 5406 5435 5312 5419 5491 5207 5193 5184 5436 5346 5410 5368 5348 5285 5269 5368 5240 5274 5356 5313 5428 5268 5410 5352 5398 5209 5416 5343 5372 5369 5287 5291 5276 5356 5353 5481 5250 5402 5238 5377 5323 5391 5353 5305 5389 5343 5333 5285 5336 5398 5352 5368 5273 5356 5302 5504 5299 5403 5321 5343 5338 5416 5396 5362 5314 5324 5425 5329 5299 5360 5256 5265 5354 5293 5226 5151 5199 5135 5424 5292 5221 5383 5385 5350 5400 5403 5392 5157 5303 5348 5348 5234 5539 5330 5259 5250 5283 5298 5412 5426 5332 5268 5082 5405 5217 5270 5240 5346 5329 5227 5270 5291 5383 5402 5439 5387 5329 5415 5423 5284 5434 5253 5364 5330 5219 5384 5298 5358 5325 5419 5358 5403 5308 5289 5223 5246 5185 5217 5299 5427 5371 5125 5141 5265 5217 5256 5345 5202 5342 5246 5269 5186 5323 5300 5296 5241 5185 5262 5285 5374 5303 5383 5206 5289 5294 5169 5326 5197 5359 5328 5303 5288 5183 5191 5260 5309 5434 5490 5377 5323 5288 5338 5274 5244 5419 5301 5333 5185 5418 5319 5421 5386 5252 5351 5281 5394 5279 5285 5269 5263 5376 5319 5452 5365 5498 5347 5330 5272 5356 5267 5399 5343 5406 5301 5339 5442 5418 5398 5470 5476 5397 5490 5533 5544 5549 5582 5489 5609 5498 5495 5431 5408 5389 5314 5419 5532 5284 5334 5462 5347 5503 5322 5466 5397 5177 5239 5339 5385 5395 5310 5260 5293 5262 5427 5420 5227 5455 5365 5362 5322 5303 5212 5571 5278 5348 5243 5239 5436 5502 5314 5514 5505 5335 5337 5420 5475 5334 5407 5406 5375 5341 5371 5310 5320 5352 5333 5572 5302 5392 5406 5369 5490 5266 5333 5345 5354 5393 5427 5452 5453 5284 5346 5476 5550 5310 5245 5598 5346 5349 5413 5423 5553 5389 5389 5497 5456 5520 5468 5458 5436 5347 5441 5327 5416 5437 5282 5382 5388 5447 5333 5325 5328 5311 5318 5489 5298 5387 5457 5473 5269 5545 5319 5382 5358 5526 5551 5452 5438 5420 5402 5399 5403 5466 5392 5317 5453 5251 5417 5486 5487 5502 5468 5428 5404 5603 5469 5422 5267 5450 5384 5475 5429 5477 5435 5554 5509 5393 5462 5477 5347 5489 5471 5447 5417 5425 5359 5355 5322 5440 5572 5375 5308 5331 5301 5382 5389 5539 5566 5468 5395 5442 5449 5426 5489 5467 5344 5461 5436 5432 5399 5305 5310 5442 5390 5389 5500 5536 5423 5495 5569 5492 5489 5554 5411 5464 5485 5390 5417 5532 5478 5544 5539 5418 5292 5674 5451 5520 5467 5400 5416 5492 5576 5392 5381 5441 5597 5500 5666 5392 5494 5515 5557 5398 5505 5479 5469 5642 5578 5386 5420 5495 5598 5642 5476 5554 5495 5554 5518 5534 5412 5451 5429 5470 5375 5437 5604 5769 5552 5563 5466 5419 5477 5574 5468 5524 5596 5491 5618 5595 5690 5608 5434 5712 5595 5607 5566 5518 5506 5634 5577 5595 5590 5686 5583 5601 5658 5608 5640 5829 5709 5763 5726 5883 5835 5957 5954 5801 6038 5999 6245 6229 6514 6509 6730 6887 7115 7283 7454 7859 8205 8800 8855 9314 9468 9029 8519 8044 7708 7304 6722 6316 6185 5977 5757 5715 5616 5610 5638 5696 5661 5500 5632 5380 5591 5482 5652 5713 5563 5665 5576 5536 5514 5668 5469 5591 5626 5568 5452 5556 5468 5588 5582 5663 5437 5326 5419 5526 5453 5529 5481 5661 5534 5620 5506 5553 5490 5536 5518 5436 5481 5469 5419 5488 5447 5538 5610 5532 5537 5534 5425 5468 5491 5406 5441 5482 5558 5590 5600 5485 5584 5580 5499 5618 5519 5513 5527 5513 5533 5740 5500 5661 5541 5549 5450 5512 5587 5487 5246 5497 5593 5513 5498 5490 5514 5480 5509 5499 5509 5551 5466 5549 5514 5559 5573 5484 5436 5609 5659 5566 5562 5448 5424 5483 5528 5416 5578 5433 5528 5373 5466 5578 5457 5468 5600 5564 5568 5453 5573 5527 5630 5546 5492 5608 5431 5387 5533 5403 5521 5458 5585 5586 5623 5531 5588 5520 5670 5530 5506 5450 5492 5417 5557 5476 5580 5545 5489 5626 5478 5447 5421 5642 5478 5359 5360 5356 5482 5572 5356 5491 5439 5420 5475 5438 5455 5602 5526 5543 5368 5575 5457 5487 5388 5333 5415 5449 5516 5408 5337 5410 5451 5433 5426 5461 5568 5481 5481 5330 5422 5556 5443 5462 5467 5558 5431 5443 5422 5644 5513 5455 5326 5591 5309 5577 5499 5522 5479 5618 5496 5362 5406 5416 5478 5573 5605 5421 5445 5500 5483 5638 5521 5377 5453 5449 5495 5527 5570 5352 5436 5479 5477 5497 5505 5530 5426 5528 5522 5409 5461 5515 5431 5536 5340 5403 5526 5483 5544 5578 5438 5596 5470 5571 5522 5441 5518 5498 5400 5404 5537 5429 5497 5523 5559 5427 5466 5361 5451 5418 5450 5418 5540 5454 5365 5515 5477 5331 5362 5374 5414 5371 5399 5426 5485 5504 5411 5476 5497 5567 5423 5469 5471 5449 5328 5432 5578 5536 5539 5427 5621 5463 5542 5576 5425 5470 5421 5477 5675 5426 5414 5445 5350 5665 5520 5576 5417 5492 5597 5661 5494 5271 5358 5454 5533 5391 5487 5409 5554 5466 5433 5326 5488 5472 5487 5578 5460 5465 5436 5404 5508 5338 5384 5409 5470 5438 5434 5454 5355 5477 5365 5444 5428 5365 5384 5401 5370 5351 5540 5429 5326 5501 5383 5336 5438 5301 5363 5439 5371 5311 5534 5469 5381 5344 5378 5360 5372 5331 5355 5504 5459 5296 5419 5375 5489 5402 5359 5371 5307 5422 5462 5456 5405 5372 5365 5396 5403 5323 5529 5378 5331 5410 5267 5407 5580 5268 5424 5331 5361 5519 5405 5399 5414 5402 5462 5449 5531 5387 5425 5457 5217 5409 5469 5380 5370 5258 5433 5400 5526 5394 5373 5327 5382 5421 5465 5412 5396 5406 5238 5484 5466 5248 5356 5246 5423 5435 5401 5469 5428 5329 5492 5265 5342 5373 5360 5364 5416 5456 5359 5270 5177 5326 5320 5492 5248 5320 5470 5285 5381 5445 5492 5328 5533 5305 5512 5503 5474 5517 5548 5517 5431 5632 5552 5605 5832 5848 5868 5967 6243 6237 6201 6485 6507 6827 6651 6536 6352 6304 6207 6126 6049 5975 5834 5713 5867 5555 5559 5455 5651 5520 5476 5444 5422 5496 5576 5498 5584 5553 5432 5351 5513 5442 5473 5513 5377 5611 5458 5506 5464 5558 5661 5630 5776 5644 5779 5868 5964 6004 6131 6205 6348 6581 6728 6859 7264 7386 7840 7979 8212 8999 9124 9444 9763 10089 10122 10154 9775 9397 8924 8701 8085 7716 7527 6828 6523 6198 6075 5874 5798 5751 5643 5515 5657 5514 5507 5313 5508 5444 5428 5429 5462 5400 5610 5363 5545 5301 5293 5360 5346 5524 5389 5411 5430 5419 5456 5404 5300 5232 5211 5305 5226 5369 5215 5284 5361 5421 5382 5395 5183 5221 5316 5376 5137 5418 5300 5310 5406 5397 5293 5192 5301 5340 5342 5423 5436 5351 5440 5402 5245 5249 5420 5243 5350 5391 5279 5408 5492 5444 5703 5596 5675 5480 5846 5944 5932 6167 6461 6379 6441 6679 6996 6805 7104 7015 7006 6988 6692 6597 6491 6307 6174 5973 5771 5652 5509 5516 5480 5352 5387 5253 5422 5406 5297 5309 5356 5422 5255 5384 5241 5305 5224 5198 5323 5290 5333 5191 5318 5059 5183 5191 5349 5111 5301 5210 5390 5291 5216 5290 5349 5209 5266 5222 5196 5349 5177 5245 5224 5249 5204 5235 5141 5244 5388 5279 5303 5165 5223 5230 5184 5367 5162 5290 5332 5284 5164 5178 5227 5200 5159 5303 5221 5232 5192 5251 5138 5062 5046 5158 5170 5139 5051 5098 5160 5047 5266 5121 5256 5222 5276 5090 5185 5121 5141 5263 5169 5126 5124 5140 5179 5238 5118 5083 5154 5171 5233 5122 5205 5101 5089 5315 5087 5177 5109 5229 5029 5091 5319 5076 5163 5260 5098 5263 5136 5236 5145 5171 5238 5284 5114 5072 5247 5206 5199 5182 5325 5230 5281 5202 5240 5087 5223 5271 5221 5219 5215 5247 5192 5216 5214 5189 5183 5191 5118 5240 5150 5304 5230 5281 5195 5135 5234 5228 5112 5115 5057 5256 5134 5150 5153 4977 5130 5031 5144 5137 5075 5085 5224 5164 5270 5175 5231 5142 5196 5057 5099 5227 5204 5180 5063 5122 5289 5131 5143 5107 5109 5177 5123 5114 5191 5182 5070 5168 5134 5120 5070 5166 5119 5109 5182 5176 5127 5126 5143 5063 5074 5127 4978 5166 5140 5056 5195 5067 5081 5074 5141 5166 5031 5277 5131 5217 5022 5084 5059 5051 5202 5129 5096 5160 5069 5242 5120 4971 5129 5180 5141 5119 5045 5238 5030 5188 4988 5186 5121 5180 5105 5120 5133 5111 5181 5044 5254 5028 5055 5160 5044 5114 4976 5045 5098 5038 5057 5071 5034 5078 5252 5141 5077 5100 4977 5202 5102 5073 5136 5029 5142 5141 5104 5080 5257 5144 5322 5333 5137 5451 5472 5446 5390 5539 5598 5706 5834 6226 6297 6318 6509 6615 6770 6530 6467 6073 6087 6005 5748 5862 5611 5643 5481 5402 5360 5247 5303 5214 5334 5189 5257 5277 5284 5144 5137 5185 5225 5238 5166 5217 5224 5278 5121 5210 5105 5109 5106 5041 5225 5115 5119 5032 5202 5084 5099 5097 5144 5175 5004 5130 5101 5117 5188 5001 5083 5157 5206 5121 5235 5119 5157 5088 5013 5212 5140 5067 5070 5140 5051 5242 5195 5218 5142 5240 5131 5134 5329 5331 5380 5258 5361 5345 5368 5447 5518 5537 5566 5546 5812 5708 5979 5992 6102 6390 6684 6876 7087 7264 7604 7853 8289 8429 8589 8762 8921 9098 9179 9319 9655 9450 9577 9697 9609 9653 9865 10032 9820 9707 9333 9055 8623 8337 8067 7789 7811 7667 7320 7162 7176 7053 7169 7396 7460 7714 7960 8170 8015 7620 7655 7305 7071 6897 6718 6460 6334 6174 5992 5787 5533 5585 5426 5442 5186 5275 5266 5154 5111 5137 5099 5119 5353 5066 5096 5092 5127 5218 5134 5066 5059 5122 5052 5081 5139 4997 5017 5017 5061 5088 5139 5198 5061 4949 5127 5158 5084 4894 5142 4970 4934 4975 5161 5036 4953 5036 4970 5091 5141 4991 5048 5158 4954 4929 4899 5001 5033 4971 5049 4991 4844 5068 5036 5089 5038 4977 4980 4925 4999 5125 4994 4939 5054 4955 5032 5040 4976 5011 5001 5096 4948 5056 5002 4953 5003 5066 4918 5052 4945 4936 5038 4954 5116 5077 5092 5038 5162 4974 5008 5015 4966 4998 5072 5116 4874 5050 5080 5033 4979 5055 5094 5080 5072 4997 5030 4918 5112 5032 4916 5075 4958 5125 5048 5128 4964 5096 4978 5010 5139 4999 5016 4896 5060 5095 4871 4958 5033 5094 4929 5058 5011 5023 5080 4891 5071 5001 4973 5013 4902 4992 5151 5110 5086 4969 5067 5035 5099 5088 5085 4990 5078 5024 5225 5110 5281 5017 5101 5153 5298 5074 5229 5304 5196 5469 5394 5292 5355 5320 5563 5512 5568 5233 5388 5357 5324 5322 5432 5245 5287 5176 5393 5160 5154 5142 5034 5068 5177 5144 5127 4996 4997 5028 4969 5098 4986 5094 5017 4969 5060 4992 4981 5011 5093 5111 4970 5174 5061 5033 4976 4966 5002 5051 5116 4949 4990 4972 5045 5081 5026 5131 4937 5080 5089 5069 5075 5017 5034 5095 5126 5106 5154 5088 5112 5145 5073 5230 5250 5061 5202 5342 5246 5068 5303 5198 5237 5319 5320 5381 5359 5469 5520 5574 5463 5790 5805 6010 6281 6433 6591 7068 7165 7656 8007 8650 9266 9855 10597 10819 11425 11413 11682 11438 10946 10460 10042 9567 9203 8989 8618 7953 7666 7137 6562 6424 6088 5820 5633 5423 5385 5415 5426 5182 5278 5251 5416 5208 5221 5249 5206 5080 5179 5299 5179 5013 5139 5195 5066 5067 4967 5141 5092 5068 5024 5039 5056 4994 5095 4983 5029 5061 5143 5170 5010 5053 5008 5060 5070 5089 5179 5095 5249 5172 5210 5299 5269 5356 5414 5429 5568 5632 5712 5848 6147 6172 6262 6402 6885 7107 7191 7143 7402 7425 7271 7035 6791 6664 6625 6295 6242 6198 6009 5816 5670 5586 5458 5217 5387 5298 5308 5141 5169 5181 5173 5163 5221 5225 5273 5081 5302 5097 5305 5172 5179 5169 5149 5208 5248 5308 5095 5236 5108 5203 5268 5309 5257 5374 5354 5332 5265 5367 5374 5430 5222 5407 5398 5462 5502 5554 5543 5662 5685 5584 5844 5868 5917 6085 6044 6258 6530 6462 6750 7123 7395 7555 8065 8466 9151 9818 10555 11543 12342 13529 14538 15575 16347 17088 18057 18565 18699 19097 18848 18660 18491 18368 17719 17441 16933 16144 15643 14971 14147 13473 12615 12111 11497 10583 10260 9888 9381 9011 8551 8192 7897 7564 7282 7209 6808 6761 6448 6502 6244 6186 6104 5924 5799 5894 5905 5763 5641 5651 5505 5452 5575 5618 5651 5538 5592 5550 5626 5706 5664 5811 5809 5911 6007 6115 6331 6363 6604 7067 7010 7741 7973 8561 9018 9464 9914 10207 10579 10606 10127 9866 9571 9257 8750 8715 8447 8061 7830 7410 6980 6772 6296 6261 5950 5757 5671 5514 5531 5351 5290 5190 5158 5057 5132 5215 5123 5203 5195 5223 5209 5113 5306 5116 5089 5213 5046 5042 5050 5012 5040 5088 5023 4966 4926 4924 4982 5163 5007 4966 5055 5020 5150 4971 5109 4962 4850 5079 5036 5044 5079 4960 4965 4952 4888 4993 5166 5056 5082 5223 5180 5328 5264 5371 5438 5373 5483 5375 5395 5465 5523 5397 5401 5408 5307 5318 5226 5263 5236 5275 5169 5291 5215 5266 5371 5177 5220 5154 5283 5225 5210 5190 5278 5158 5157 5185 5148 5073 5075 5080 5082 5061 4953 4983 4855 4967 5025 4976 5003 5004 5080 4969 4980 4944 4932 4911 4913 4968 5014 4989 4929 4986 5084 4946 4958 4923 4961 5006 5001 4955 4824 4920 4866 4972 4903 4909 4947 4940 4922 5093 4950 5156 4883 4922 4998 5009 5082 5057 4986 4949 5042 5025 5099 5006 4922 4978 5000 5009 4968 4920 4929 4947 5106 5016 5105 5010 5104 5048 5224 5090 5205 5032 5154 5065 5130 5148 5132 5146 5337 5201 5261 5176 5273 5273 5299 5350 5397 5259 5515 5411 5536 5637 5549 5646 5750 5841 5866 6052 6079 6194 6339 6439 6563 6563 6841 7033 7197 7375 7450 7808 7853 8104 8296 8463 8838 8470 8947 9102 9191 9390 9474 9141 9214 9082 8887 8890 8874 8733 8433 8332 8167 8060 7885 7675 7660 7546 7363 7148 7204 7079 6922 6781 6741 6667 6605 6453 6321 6376 6420 6210 6259 6067 5908 5923 5790 5672 5617 5675 5575 5504 5310 5360 5256 5286 5219 5139 5070 5115 5157 5020 5141 5092 5081 5137 5096 5169 4946 5144 5023 4945 5086 4917 4972 5041 4826 4924 4899 4957 4923 4982 4989 4911 4968 4879 4889 4866 5022 4982 4909 4932 4905 4865 4888 5016 4971 4837 4974 5028 5086 5118 5117 5093 5109 5269 5181 5183 5233 5253 5241 5236 5158 5071 5021 5103 4986 4999 5104 4996 4927 4869 5013 4855 4818 4924 4878 4818 4721 4863 4793 4850 4818 4873 4756 4773 4869 4903 4784 4917 4794 4726 4776 4837 4773 4933 4842 4774 4947 4796 4833 4706 4775 4849 4866 4810 4743 4639 4851 4916 4906 4777 4738 4777 4860 4771 4851 4932 4967 4985 4859 4802 4940 4726 5136 4908 4821 4876 4832 4938 4925 5045 4930 5109 4916 5005 5025 5225 5174 5201 5305 5593 5692 5929 6084 6226 6714 6911 7018 7251 7366 7193 7170 6755 6476 6350 6201 6266 6313 6074 6118 6019 5776 5578 5529 5353 5212 5110 5117 5068 4929 5012 5009 5051 4890 4951 4958 4984 4968 4963 4974 4854 4905 4704 4935 4957 4919 4859 4843 4787 4850 4896 5001 4897 4973 4925 4811 4880 4897 4918 4961 5010 5038 5122 5159 5289 5344 5362 5560 5619 5827 5895 6122 6284 6554 6528 6680 6802 6719 6428 6248 6326 6034 6116 6103 5987 5982 5714 5779 5606 5432 5422 5204 4991 5031 5043 5021 4992 5034 4939 4935 4937 4897 4765 4868 4877 4819 4709 4945 4694 4898 4883 4766 4776 4916 4881 5001 4729 4682 4803 4761 4887 4874 4814 4760 4818 4733 4844 4781 4693 4769 4749 4753 4869 4758 4852 4733 4784 4822 4809 4764 4739 4649 4812 4773 4924 4669 4668 4718 4705 4769 4843 4671 4780 4741 4707 4747 4735 4758 4749 4852 4574 4723 4772 4679 4742 4808 4781 4836 4785 4730 4760 4888 4750 4818 4726 4789 4784 4712 4890 4833 4777 4778 4722 4804 4787 4790 4785 4901 4826 4759 4791 4874 4873 4819 4848 4754 4696 4725 4873 4853 4726 4901 4973 5006 4998 5073 5185 5230 5135 5283 5393 5531 5841 6030 6084 6303 6431 6630 6668 6831 6822 6754 6675 6602 6609 6609 6539 6348 6330 6418 6238 6215 5849 5956 5740 5620 5623 5510 5488 5294 5303 5203 5145 4989 5117 5145 5077 4925 4898 4927 4888 4922 4939 4942 4831 4850 4895 4783 4883 4786 4808 4928 4830 4865 4812 4682 4807 4825 4729 4711 4744 4699 4756 4622 4779 4812 4802 4752 4734 4762 4743 4691 4804 4752 4755 4815 4860 4695 4769 4809 4819 4751 4562 4755 4684 4651 4770 4764 4798 4833 4690 4651 4764 4668 4763 4752 4801 4804 4741 4809 4798 4768 4782 4679 4682 4734 4650 4876 4971 4774 4890 4930 5014 5016 5036 4938 4921 4978 5057 4851 4865 5012 4918 4992 5012 4970 4896 4878 4975 4969 4843 4876 4879 4942 4877 4887 4953 4797 4872 5035 4928 4899 4949 4974 5146 5146 5080 5177 5225 5377 5243 5255 5167 5098 5005 4976 4893 4859 5045 4976 4915 4943 4871 4900 4819 4844 4794 4777 4737 4716 4695 4708 4731 4654 4709 4658 4637 4641 4725 4712 4722 4824 4684 4790 4751 4693 4820 4732 4683 4728 4730 4701 4759 4731 4668 4637 4555 4738 4763 4782 4750 4703 4696 4627 4776 4625 4699 4734 4643 4691 4782 4665 4715 4677 4761 4706 4621 4761 4724 4602 4654 4795 4672 4648 4702 4637 4772 4648 4679 4667 4699 4610 4651 4692 4664 4689 4662 4642 4584 4688 4633 4742 4672 4809 4713 4707 4748 4570 4736 4744 4825 4744 4708 4688 4691 4831 4711 4639 4863 4708 4770 4741 4681 4656 4683 4850 4736 4899 4628 4800 4816 4787 4816 4711 4928 4886 4963 4906 4974 5137 5225 5337 5542 5377 5541 5492 5337 5295 5458 5449 5148 5197 5217 5205 5192 5042 5201 5083 5059 5028 5150 4955 4798 4771 4900 4797 4910 4814 4904 4676 4877 4819 4819 4739 4707 4815 4779 4859 4841 4882 4914 4848 4788 4746 4815 4680 4612 4645 4718 4763 4693 4792 4802 4641 4789 4640 4651 4825 4724 4698 4795 4691 4727 4713 4650 4515 4655 4592 4637 4729 4698 4738 4768 4719 4585 4831 4638 4735 4722 4722 4703 4737 4642 4675 4715 4849 4756 4723 4645 4716 4756 4725 4671 4814 4725 4727 4830 4634 4819 4771 4706 4731 4620 4773 4747 4866 4723 4722 4708 4762 4755 4689 4741 4598 4657 4676 4769 4701 4771 4664 4757 4775 4691 4703 4745 4810 4696 4556 4648 4731 4679 4656 4647 4669 4639 4783 4674 4632 4578 4682 4651 4721 4769 4739 4688 4701 4776 4630 4753 4736 4693 4733 4757 4788 4689 4658 4747 4794 4977 4812 5015 4783 4855 4789 4743 4732 4684 4676 4916 4817 4668 4833 4659 4907 4664 4681 4749 4648 4674 4615 4718 4623 4602 4708 4573 4558 4613 4611 4627 4639 4759 4666 4706 4689 4701 4672 4805 4779 4735 4702 4730 4725 4716 4748 4622 4699 4759 4726 4769 4805 4644 4616 4726 4678 4754 4706 4826 4729 4741 4787 4720 4769 4741 4826 4789 4955 4925 4835 4906 4964 5144 5314 5250 5100 5273 5250 5263 5125 5237 5326 5188 5372 5284 5315 5547 5488 5586 5735 5647 5716 6005 6025 6238 6430 6625 6602 6897 6822 6782 6774 6795 6481 6275 6154 6017 6084 6086 6165 6165 5950 5982 5835 5687 5634 5460 5456 5371 5369 5316 5229 5104 5094 5203 5017 5077 4850 5018 4990 4967 4984 4920 4960 4905 4919 4761 4816 4780 4851 4924 4758 4720 4770 4753 4799 4785 4701 4756 4615 4871 4771 4734 4688 4759 4764 4677 4779 4722 4623 4756 4685 4757 4805 4658 4639 4654 4832 4652 4684 4705 4618 4639 4665 4820 4805 4526 4782 4724 4770 4687 4561 4809 4630 4715 4693 4630 4602 4715 4769 4749 4689 4679 4840 4727 4705 4879 4774 4871 4612 4895 4778 4766 4747 4678 4769 4744 4826 4773 4755 4753 4836 4789 4789 4890 4899 4962 4947 4935 5187 5121 5082 5343 5510 5474 5845 6122 6216 6581 6678 6733 7000 6807 6793 6533 6277 6106 6003 5834 5919 5899 5859 6054 5904 5962 5794 5692 5463 5424 5125 5117 4867 5048 4891 4913 4924 4848 4914 4798 4789 4896 4781 4708 4761 4610 4639 4752 4699 4729 4787 4790 4687 4632 4515 4642 4751 4707 4662 4687 4788 4637 4622 4576 4633 4593 4658 4598 4678 4562 4546 4762 4605 4587 4596 4629 4576 4663 4633 4627 4594 4695 4607 4680 4611 4675 4814 4602 4630 4675 4631 4760 4811 4770 4741 4694 4652 4594 4712 4651 4758 4636 4739 4705 4812 4603 4670 4651 4789 4841 4664 4729 4684 4767 4617 4613 4720 4690 4548 4669 4652 4624 4783 4678 4719 4653 4652 4754 4663 4803 4608 4633 4613 4702 4717 4729 4514 4780 4512 4570 4742 4570 4733 4595 4678 4764 4645 4590 4600 4743 4567 4579 4574 4572 4550 4574 4673 4541 4656 4484 4637 4609 4648 4635 4514 4709 4712 4638 4644 4561 4631 4677 4669 4697 4726 4687 4536 4712 4538 4648 4533 4680 4639 4642 4638 4565 4575 4525 4652 4726 4700 4630 4608 4769 4681 4580 4645 4624 4612 4589 4632 4673 4622 4583 4739 4645 4659 4633 4656 4656 4671 4589 4724 4663 4569 4667 4758 4828 4809 4774 4758 4848 4815 4928 4976 4945 4959 4988 4900 4748 4642 4874 4876 4966 5015 4812 4893 5003 4949 4788 4952 4921 5067 5005 4785 4944 4763 4867 4934 4685 4785 4750 4802 4873 4614 4683 4853 4813 4795 4755 4791 4692 4693 4737 4717 4702 4870 4870 4721 4748 4709 4687 4909 4777 4669 4760 4843 4672 4709 4836 4751 4747 4758 4725 4747 4804 4865 4981 4921 5019 4830 4954 5029 4982 5118 5088 5271 5265 5270 5275 5369 5366 5322 5595 5632 5594 5504 5786 5574 5557 5569 5661 5585 5499 5603 5644 5592 5454 5483 5495 5529 5365 5404 5296 5379 5141 5352 5078 5208 5179 5134 5095 5033 4873 5056 4847 4916 4786 4898 4890 4919 4759 4846 4929 4854 4755 4843 4864 4679 4835 4854 4713 4781 4671 4853 4733 4605 4799 4730 4702 4678 4619 4526 4720 4578 4623 4662 4754 4681 4573 4760 4653 4813 4826 4691 4683 4694 4729 4692 4644 4736 4618 4803 4680 4645 4763 4626 4767 4755 4809 4789 4817 4720 4720 4811 4775 4769 4836 4867 4877 4719 4847 4785 4743 4728 4844 4855 4674 4880 4894 4818 4916 4836 4945 4907 4898 4875 4980 5018 5016 4933 5025 5280 5316 5369 5542 5585 5913 6122 6245 6702 7189 7205 7953 8370 8985 9335 9872 9752 9685 9262 8574 8441 7872 7621 7489 7343 7278 7543 7403 7544 7449 7469 7271 6873 6688 6221 6046 5824 5590 5425 5280 5187 5254 5124 5022 4883 5035 4945 4947 4882 5059 4798 5067 4979 4969 4966 4960 4991 4887 4781 4866 4782 4719 4708 4740 4799 4712 4783 4791 4717 4786 4872 4679 4724 4706 4746 4791 4749 4716 4562 4529 4595 4570 4576 4783 4621 4709 4615 4763 4758 4655 4675 4617 4664 4732 4567 4610 4544 4605 4707 4574 4670 4647 4623 4617 4550 4723 4617 4719 4660 4668 4617 4549 4556 4715 4631 4574 4615 4617 4603 4553 4628 4711 4631 4574 4700 4575 4644 4779 4570 4722 4755 4672 4634 4528 4784 4686 4746 4863 4725 4750 4667 4593 4655 4727 4647 4701 4751 4841 4673 4719 4690 4663 4688 4753 4654 4674 4671 4645 4677 4731 4634 4688 4688 4572 4777 4886 4729 4731 4730 4870 4765 4750 4853 4813 4822 4780 4789 4884 4843 4822 4717 4794 4837 4867 4907 4884 5006 5033 5092 5101 5284 5403 5242 5388 5362 5444 5498 5760 5736 6015 6118 6475 6545 6729 6796 6961 7375 7708 7962 8458 9067 9746 11053 12405 13615 14368 14839 14144 12614 10983 9786 8725 8203 7949 7912 8006 8277 8717 9266 9829 9802 9634 8817 7991 7253 6567 6170 5859 5467 5489 5249 5239 5299 5203 5081 5050 5013 5041 4994 4945 4840 4832 4873 4824 4880 4843 4852 4825 4759 4805 4825 4596 4744 4806 4692 4776 4733 4761 4792 4639 4793 4740 4732 4780 4741 4618 4727 4695 4731 4663 4669 4740 4675 4793 4706 4766 4740 4716 4770 4656 4706 4774 4739 4891 4636 4743 4828 4671 4736 4772 4702 4704 4743 4712 4859 4684 4803 4825 4854 4751 4795 4892 4922 4879 5031 5005 4841 4840 5091 4960 5066 5096 5180 5118 5099 5021 5181 5245 5174 5350 5262 5327 5261 5266 5295 5357 5333 5520 5439 5442 5485 5375 5498 5441 5443 5557 5531 5316 5220 5277 5346 5185 5089 5112 5130 5031 5030 4954 4950 5018 4912 4925 4998 4886 4819 4811 4832 4812 4791 4762 4721 4640 4631 4678 4703 4588 4708 4669 4701 4689 4827 4758 4657 4687 4727 4611 4538 4613 4633 4742 4626 4777 4684 4575 4645 4625 4564 4580 4542 4682 4643 4672 4682 4681 4536 4654 4776 4571 4593 4700 4658 4640 4721 4569 4601 4744 4756 4598 4578 4794 4568 4619 4574 4662 4528 4737 4599 4693 4583 4573 4734 4567 4656 4630 4675 4737 4712 4630 4562 4706 4532 4539 4597 4421 4673 4601 4810 4577 4605 4577 4662 4579 4517 4699 4613 4705 4688 4715 4630 4621 4563 4485 4585 4557 4614 4732 4523 4628 4708 4555 4582 4570 4650 4548 4767 4692 4589 4682 4657 4588 4594 4541 4566 4652 4646 4617 4644 4685 4682 4608 4806 4716 4716 4762 4803 4772 4826 4751 4747 4660 4794 4674 4629 4619 4713 4719 4687 4703 4729 4712 4527 4630 4643 4708 4685 4584 4600 4685 4584 4711 4749 4602 4559 4548 4588 4536 4670 4687 4553 4485 4680 4637 4582 4655 4771 4612 4715 4661 4657 4796 4710 4645 4541 4669 4726 4590 4859 4609 4659 4652 4584 4707 4663 4848 4704 4677 4856 4737 4758 4687 4837 4821 4850 4834 4799 4852 5015 4767 4809 4856 4800 4938 4935 4835 4744 4812 4789 4737 4634 4694 4767 4931 4764 4766 4885 4890 4798 4802 4870 4791 4757 4619 4773 4816 4736 4598 4756 4871 4694 4838 4654 4776 4696 4721 4651 4713 4669 4815 4699 4841 4767 4769 4833 4841 4959 4881 4869 4869 4907 5031 4903 5089 5051 5194 5041 5247 5370 5313 5267 5287 5360 5324 5336 5287 5411 5497 5320 5352 5332 5312 5287 5287 5296 5258 5313 5234 5273 5225 5001 5037 5247 5160 5112 5012 4994 4811 5002 4756 4868 4811 4879 4863 4789 4828 4712 4865 4847 4747 4778 4715 4774 4782 4838 4745 4901 4836 4770 4576 4766 4862 4799 4803 4816 4804 4919 4716 4745 4775 4741 4800 4653 4780 4919 4851 4858 4829 4919 4840 4849 4779 4867 4926 4840 4903 5169 5151 5222 5235 5519 5569 5668 5815 6124 6046 6435 6517 6579 6720 6872 6876 6928 7053 7071 7127 7150 7200 7251 7062 7307 7328 7305 7144 7246 7241 7145 7252 6936 6796 6695 6724 6538 6401 6303 6267 6106 6159 6032 5894 5939 5767 5728 5706 5647 5514 5384 5293 5325 5293 5296 5083 4996 5216 5134 5057 4964 4964 4861 4935 4892 4960 4860 4929 4817 4824 5024 4803 4827 4800 4796 4787 4753 4814 4870 4849 4909 4796 4895 4869 4957 5049 4913 4787 4884 4950 4919 5077 5026 5093 5181 5219 5374 5363 5554 5593 5641 5900 5916 6045 6082 6043 6103 5897 5873 5777 5522 5435 5561 5358 5438 5359 5358 5407 5501 5471 5569 5519 5407 5450 5235 5052 5078 5120 4933 4857 4815 4767 4876 4799 4858 4748 4716 4780 4647 4698 4666 4692 4647 4699 4681 4634 4616 4707 4663 4699 4562 4659 4742 4691 4674 4697 4524 4765 4678 4522 4637 4654 4554 4667 4658 4714 4827 4582 4691 4634 4548 4597 4625 4619 4710 4705 4698 4714 4640 4559 4664 4628 4586 4619 4612 4624 4733 4575 4707 4766 4630 4580 4628 4704 4685 4544 4750 4492 4684 4594 4592 4735 4688 4645 4629 4580 4589 4727 4550 4772 4767 4534 4529 4720 4760 4593 4659 4591 4602 4623 4702 4719 4677 4733 4609 4683 4676 4715 4752 4642 4758 4721 4828 4587 4806 4787 4786 4778 4736 4916 4820 5024 4964 5074 5002 5232 5277 5247 5282 5511 5809 5820 5854 6063 6334 6377 6537 6436 6297 6171 6099 5935 5909 5791 5733 5473 5507 5707 5681 5846 5783 5680 5819 5886 5703 5659 5770 5588 5476 5406 5266 5291 5145 5197 5017 5093 4978 4967 5053 4821 4962 4968 4989 4919 4921 4984 4949 4954 5043 5080 4999 4892 4927 5085 4997 5009 4934 5007 4993 5110 5042 5072 5087 4975 5130 5049 4972 5149 5005 5125 5057 5065 5135 5142 5138 4985 5117 4937 5167 4878 5163 5075 5084 5180 4982 5009 4949 4985 5000 4992 5059 5232 4956 5117 5008 4965 5081 5095 4990 5081 5093 5066 5080 4999 5077 5164 5254 5104 5238 5215 5189 5172 5323 5348 5332 5182 5232 5263 5271 5182 5227 5155 5140 5156 5007 5010 4982 5017 5051 5043 5066 5002 5107 4947 5024 4937 4979 4845 4835 4946 4867 4777 4862 4849 4876 4705 4845 4755 4793 4756 4667 4793 4628 4624 4670 4635 4677 4752 4785 4758 4704 4789 4712 4647 4795 4619 4786 4757 4649 4610 4622 4504 4675 4698 4656 4678 4659 4722 4641 4670 4477 4630 4704 4621 4673 4709 4595 4579 4629 4633 4507 4649 4701 4631 4649 4624 4670 4634 4659 4749 4523 4678 4628 4646 4628 4691 4667 4650 4696 4769 4509 4648 4546 4697 4616 4627 4604 4704 4570 4620 4697 4802 4635 4633 4658 4605 4669 4595 4696 4714 4696 4701 4743 4799 4764 4594 4747 4815 4713 4980 4717 4710 4745 4883 4882 4746 4833 4965 4856 4850 4909 4953 5070 4817 4877 5074 4991 4998 4925 4962 5156 4979 5052 5243 5060 5113 5090 5177 5063 5193 5189 5257 5088 5144 5223 5121 5246 5048 5316 5394 5107 5193 5307 5120 5288 5160 5250 5218 5106 5194 5193 5083 5250 5011 5071 5027 5081 5018 4856 4922 4926 4893 4902 4983 4754 4938 4917 4875 4845 4796 4621 4708 4719 4794 4607 4670 4760 4700 4656 4616 4609 4611 4671 4587 4534 4642 4484 4617 4600 4634 4616 4631 4677 4592 4645 4719 4596 4656 4686 4413 4707 4583 4606 4639 4611 4599 4522 4670 4597 4702 4520 4684 4529 4588 4686 4623 4706 4679 4592 4515 4759 4665 4714 4742 4669 4652 4600 4577 4708 4718 4486 4807 4576 4689 4569 4570 4627 4673 4681 4501 4618 4748 4639 4651 4821 4732 4896 4796 4855 4895 4883 4818 4857 4939 5012 5012 4866 4850 4829 4736 4898 4629 4729 4726 4715 4743 4751 4814 4735 4705 4785 4695 4733 4751 4628 4820 4559 4493 4679 4743 4657 4680 4516 4443 4504 4483 4558 4526 4566 4632 4594 4539 4641 4617 4528 4605 4636 4590 4595 4554 4631 4385 4668 4587 4526 4546 4541 4577 4662 4620 4629 4620 4765 4542 4597 4680 4678 4605 4565 4598 4671 4571 4528 4652 4552 4597 4552 4506 4473 4522 4598 4559 4557 4570 4536 4512 4527 4551 4669 4494 4542 4568 4507 4524 4687 4568 4525 4540 4610 4699 4539 4460 4391 4613 4534 4528 4600 4586 4567 4597 4559 4483 4569 4552 4527 4665 4676 4596 4534 4615 4615 4618 4573 4629 4573 4709 4574 4575 4535 4578 4534 4545 4604 4589 4671 4551 4516 4762 4594 4715 4648 4679 4613 4718 4719 4660 4740 4646 4633 4748 4738 4768 4817 4618 4832 4751 4682 4702 4666 4817 4752 4725 4722 4837 4662 4820 4740 4646 4739 4713 4544 4738 4630 4583 4714 4780 4632 4715 4697 4566 4559 4604 4591 4602 4654 4557 4614 4583 4625 4574 4625 4587 4683 4509 4655 4599 4685 4516 4562 4632 4606 4501 4528 4535 4520 4492 4624 4521 4500 4521 4668 4532 4501 4726 4577 4500 4488 4471 4522 4610 4614 4639 4622 4572 4666 4628 4496 4551 4655 4577 4538 4581 4646 4641 4538 4556 4563 4531 4651 4699 4539 4566 4683 4490 4622 4629 4458 4610 4607 4432 4650 4780 4659 4609 4664 4601 4559 4550 4486 4632 4536 4630 4678 4559 4628 4525 4635 4662 4646 4680 4682 4592 4797 4627 4754 4593 4679 4777 4744 4878 4807 4642 4801 4758 4769 4664 4816 4858 4859 4737 4794 4865 4785 4732 4841 4794 4769 4774 4618 4778 4691 4742 4709 4744 4777 4868 4732 4730 4817 4804 4833 4750 4674 4784 4780 4825 4777 4903 4804 4836 4771 4861 4726 4838 4779 4839 5010 4945 4972 4992 5028 5199 5191 5242 5379 5236 5255 5360 5232 5131 5123 5223 5023 5034 4924 4935 4941 4904 4882 4874 4834 5090 4986 5029 5027 5061 5003 5006 4905 4926 4882 4720 4911 4818 4762 4740 4743 4719 4775 4737 4792 4592 4721 4775 4692 4684 4620 4622 4875 4584 4671 4648 4611 4580 4654 4620 4702 4644 4640 4702 4604 4729 4638 4674 4724 4615 4700 4730 4530 4570 4694 4718 4702 4712 4623 4641 4541 4565 4664 4634 4520 4653 4517 4604 4709 4688 4702 4759 4770 4716 4670 4929 4879 4844 4773 4875 4887 4822 4889 4971 4870 4986 5006 4998 4945 4925 4974 4921 4931 4987 5066 5049 4986 4940 4927 4890 5018 4866 4855 4744 4912 4819 4940 4691 4915 4778 4740 4738 4809 4769 4774 4730 4748 4810 4777 4584 4596 4770 4705 4622 4594 4768 4608 4601 4647 4627 4649 4679 4671 4686 4607 4680 4771 4624 4584 4570 4570 4610 4593 4703 4692 4545 4578 4703 4679 4591 4714 4701 4611 4699 4702 4543 4746 4718 4727 4682 4713 4652 4683 4632 4707 4849 4776 4927 4920 4846 4918 5057 4885 4986 4950 4843 5042 5102 4949 4952 4886 5119 4982 4935 5022 5025 5022 5010 5030 4832 4877 4910 4907 4927 5088 5244 5138 4946 4992 4974 5015 5064 5011 5082 4960 4938 4973 4894 5049 4845 4835 4863 4820 4795 4764 4802 4792 4713 4747 4840 4839 4800 4787 4678 4625 4656 4673 4669 4867 4665 4612 4640 4631 4715 4545 4521 4693 4625 4692 4510 4538 4589 4599 4691 4467 4549 4639 4642 4523 4492 4446 4724 4592 4557 4664 4540 4657 4555 4587 4508 4673 4590 4521 4478 4469 4533 4498 4653 4529 4505 4564 4544 4514 4381 4531 4508 4615 4373 4413 4610 4541 4572 4614 4529 4579 4497 4568 4529 4592 4604 4525 4549 4468 4576 4557 4564 4535 4526 4559 4689 4564 4687 4702 4602 4603 4566 4590 4637 4623 4562 4546 4786 4761 4891 4742 4711 4862 4861 4989 5110 5108 5085 5266 5069 5107 5151 5063 5076 5039 4839 4872 4938 4985 4862 4922 4728 4858 4898 4994 4854 4937 5176 4987 5100 5189 5106 5238 5053 5014 5046 5058 4915 4885 4849 4846 4884 4657 4630 4774 4761 4708 4827 4786 4741 4770 4764 4694 4841 4675 4772 4846 4640 4841 4690 4736 4706 4625 4562 4644 4633 4656 4647 4587 4531 4598 4581 4659 4565 4629 4671 4584 4618 4506 4541 4622 4599 4426 4471 4585 4629 4676 4473 4499 4527 4515 4662 4603 4611 4506 4406 4552 4636 4558 4592 4464 4526 4588 4584 4620 4467 4600 4579 4486 4603 4613 4545 4546 4516 4418 4631 4585 4563 4574 4505 4558 4580 4550 4661 4577 4409 4542 4535 4583 4657 4549 4530 4407 4479 4575 4452 4519 4459 4476 4436 4469 4661 4603 4525 4531 4461 4587 4492 4468 4691 4562 4540 4439 4540 4639 4520 4525 4528 4533 4529 4604 4585 4557 4625 4592 4518 4692 4548 4606 4570 4464 4469 4551 4391 4682 4503 4592 4498 4594 4577 4401 4404 4500 4521 4567 4572 4598 4507 4482 4710 4548 4528 4689 4603 4579 4426 4594 4638 4601 4444 4725 4573 4563 4646 4480 4664 4634 4633 4621 4428 4623 4672 4624 4665 4604 4704 4696 4796 4668 4681 4602 4541 4597 4812 4750 4769 4727 4725 4864 4905 4888 4902 4970 5206 5163 5351 5589 5741 5574 5693 5714 5520 5331 5218 5110 4962 4916 4880 4854 4815 4785 4690 4866 4914 4934 5154 4875 4982 5087 4932 5063 5108 5098 5015 4963 4930 4780 4650 4705 4737 4636 4681 4607 4644 4637 4519 4693 4531 4607 4638 4609 4659 4589 4706 4636 4670 4506 4618 4540 4447 4590 4674 4410 4598 4575 4505 4530 4607 4468 4578 4536 4650 4519 4741 4684 4606 4425 4653 4614 4528 4537 4642 4619 4561 4529 4511 4578 4549 4483 4597 4651 4500 4499 4531 4585 4582 4542 4567 4560 4572 4670 4507 4432 4541 4679 4576 4797 4684 4629 4667 4733 4608 4622 4640 4576 4674 4685 4626 4733 4639 4713 4665 4646 4562 4752 4663 4676 4622 4572 4664 4654 4600 4668 4700 4556 4494 4684 4667 4519 4570 4622 4635 4662 4682 4635 4524 4459 4654 4639 4622 4420 4559 4445 4526 4514 4414 4530 4500 4558 4673 4589 4504 4555 4418 4477 4585 4590 4584 4576 4496 4489 4610 4488 4446 4590 4533 4584 4473 4625 4412 4506 4465 4474 4442 4479 4462 4533 4607 4435 4488 4553 4444 4561 4549 4543 4436 4448 4539 4680 4523 4538 4560 4652 4631 4504 4496 4497 4560 4633 4436 4546 4631 4499 4595 4613 4589 4549 4584 4605 4639 4414 4534 4572 4527 4537 4546 4446 4571 4534 4527 4524 4482 4576 4679 4531 4545 4626 4724 4590 4616 4544 4662 4527 4698 4507 4639 4554 4574 4582 4546 4463 4508 4553 4591 4657 4460 4605 4700 4544 4511 4563 4613 4494 4720 4544 4524 4459 4615 4572 4544 4561 4605 4578 4616 4638 4620 4633 4708 4715 4667 4576 4647 4749 4528 4629 4670 4676 4705 4701 4682 4689 4756 4777 4607 4604 4717 4703 4634 4617 4667 4660 4621 4706 4679 4749 4690 4604 4786 4679 4685 4741 4679 4656 4793 4887 4613 4754 4681 4677 4748 4707 4621 4788 4691 4770 4675 4736 4714 4720 4568 4666 4593 4637 4672 4812 4589 4557 4530 4653 4734 4682 4611 4739 4702 4659 4715 4688 4636 4590 4666 4675 4614 4566 4741 4630 4683 4649 4726 4659 4676 4735 4652 4612 4605 4730 4609 4596 4614 4640 4583 4643 4633 4673 4608 4651 4702 4648 4684 4666 4761 4586 4710 4655 4560 4608 4721 4635 4664 4769 4808 4609 4760 4621 4643 4532 4680 4571 4540 4544 4615 4743 4684 4672 4718 4620 4635 4526 4591 4710 4700 4595 4670 4530 4652 4572 4831 4734 4510 4581 4570 4631 4622 4696 4662 4690 4553 4695 4698 4605 4690 4639 4635 4700 4567 4606 4620 4693 4693 4525 4551 4585 4576 4749 4661 4833 4735 4613 4633 4683 4645 4709 4610 4692 4697 4617 4694 4650 4680 4701 4632 4697 4548 4525 4689 4695 4596 4718 4523 4744 4550 4569 4726 4684 4663 4601 4801 4553 4721 4702 4742 4707 4985 4847 4857 4835 4852 4819 4901 4874 4884 4696 4720 4738 4759 4742 4761 4623 4693 4647 4602 4741 4799 4577 4715 4667 4722 4680 4761 4744 4679 4795 4879 4672 4700 4755 4663 4644 4610 4639 4622 4587 4651 4592 4552 4702 4466 4527 4561 4551 4572 4542 4683 4464 4514 4616 4415 4612 4555 4580 4541 4490 4523 4539 4557 4563 4561 4582 4591 4554 4450 4603 4502 4546 4477 4628 4493 4448 4536 4554 4646 4464 4536 4549 4528 4479 4596 4473 4643 4617 4546 4351 4547 4588 4575 4555 4574 4488 4514 4580 4496 4539 4554 4397 4529 4599 4580 4420 4395 4559 4586 4480 4515 4467 4473 4585 4507 4540 4542 4525 4554 4429 4648 4537 4586 4554 4618 4476 4586 4539 4535 4634 4599 4555 4526 4511 4670 4517 4463 4473 4473 4751 4476 4575 4461 4457 4494 4535 4556 4539 4680 4552 4478 4602 4588 4584 4718 4523 4581 4573 4510 4612 4530 4574 4458 4592 4528 4478 4554 4588 4383 4607 4595 4480 4545 4640 4629 4558 4485 4361 4516 4512 4450 4514 4687 4507 4586 4608 4614 4605 4628 4506 4480 4517 4628 4562 4636 4649 4640 4620 4654 4586 4541 4598 4614 4713 4606 4645 4693 4709 4798 4800 4928 4918 4860 4961 4922 4943 4928 4881 4821 4832 4877 4852 4854 4855 4823 4877 4803 4822 4773 4803 4849 4835 4836 4900 4719 4793 4825 4805 4904 4844 4852 4855 4841 4859 4850 4860 4861 4827 4775 4878 4819 4791 4661 4695 4682 4743 4737 4771 4571 4654 4694 4746 4636 4669 4687 4586 4737 4744 4672 4661 4559 4705 4561 4560 4724 4690 4521 4597 4656 4573 4626 4550 4566 4469 4575 4492 4453 4388 4562 4548 4475 4662 4456 4515 4641 4404 4486 4569 4608 4619 4595 4587 4558 4501 4508 4653 4633 4501 4615 4569 4578 4482 4651 4581 4540 4476 4569 4620 4476 4527 4640 4598 4639 4762 4536 4464 4552 4607 4531 4511 4600 4559 4551 4453 4578 4539 4604 4450 4681 4574 4597 4588 4557 4482 4576 4473 4544 4558 4567 4528 4563 4577 4538 4621 4542 4624 4578 4600 4541 4545 4461 4462 4496 4451 4524 4562 4567 4492 4533 4506 4453 4560 4639 4596 4532 4412 4548 4548 4425 4441 4494 4577 4586 4452 4587 4424 4499 4615 4481 4462 4431 4476 4547 4700 4559 4531 4531 4574 4582 4632 4495 4660 4450 4466 4614 4501 4570 4558 4470 4637 4501 4543 4602 4512 4423 4531 4535 4572 4525 4579 4551 4624 4508 4580 4450 4449 4532 4601 4553 4497 4657 4521 4603 4648 4598 4601 4379 4526 4409 4457 4473 4723 4546 4575 4492 4605 4590 4561 4601 4598 4623 4644 4559 4626 4467 4651 4669 4512 4529 4648 4512 4667 4551 4544 4536 4623 4741 4653 4670 4660 4700 4776 4710 4688 4673 4690 4833 4648 4704 4774 4811 4869 4752 4889 4900 4985 4981 5193 5027 5025 4973 4913 5079 5034 5052 5083 5191 5157 5124 5151 5220 5126 5198 5120 5233 5327 5257 5167 5236 5052 5196 5295 5296 5153 5092 5193 5348 5067 5185 5154 5118 5079 5118 5118 5114 5024 4999 5078 5124 5126 5051 5050 4937 5081 5035 5060 4981 4947 4939 5034 5150 5067 5200 5105 5106 5186 5260 5325 5180 5289 5232 5391 5424 5312 5338 5179 5137 5011 5057 5016 4927 5048 5054 4942 4834 4903 4872 4954 4754 4848 4870 4951 4845 4945 4843 4859 5021 4939 4889 4920 4889 4791 4841 4766 4868 4838 4854 4690 4559 4595 4731 4596 4674 4593 4713 4617 4584 4701 4562 4498 4561 4622 4555 4669 4561 4555 4535 4695 4673 4521 4555 4584 4622 4559 4598 4467 4526 4490 4570 4555 4615 4617 4525 4528 4635 4479 4484 4489 4538 4633 4676 4515 4482 4595 4533 4516 4574 4546 4537 4552 4558 4617 4537 4577 4606 4600 4451 4603 4531 4572 4499 4404 4630 4538 4598 4713 4521 4574 4550 4556 4599 4679 4575 4532 4636 4612 4598 4579 4436 4580 4541 4617 4639 4506 4687 4555 4488 4555 4487 4650 4445 4585 4603 4677 4624 4542 4783 4654 4458 4497 4582 4602 4598 4544 4605 4576 4571 4568 4488 4435 4541 4560 4643 4626 4493 4612 4685 4750 4698 4521 4605 4528 4598 4622 4607 4671 4534 4523 4407 4701 4616 4498 4428 4676 4417 4629 4534 4515 4553 4488 4492 4538 4478 4635 4653 4472 4510 4614 4497 4524 4529 4618 4441 4532 4518 4417 4422 4631 4511 4505 4675 4479 4522 4533 4462 4517 4577 4606 4628 4482 4510 4626 4580 4561 4550 4517 4481 4573 4464 4544 4454 4620 4585 4555 4524 4684 4606 4534 4637 4590 4530 4567 4611 4574 4477 4500 4546 4524 4502 4574 4525 4597 4563 4583 4629 4478 4491 4462 4541 4676 4686 4545 4622 4539 4527 4691 4507 4510 4620 4580 4669 4642 4509 4531 4642 4548 4613 4646 4636 4532 4535 4580 4537 4518 4567 4577 4591 4589 4527 4741 4530 4521 4591 4420 4577 4598 4595 4610 4656 4583 4518 4642 4580 4468 4605 4605 4500 4537 4566 4538 4557 4560 4527 4512 4499 4613 4467 4723 4515 4515 4514 4454 4703 4552 4534 4561 4631 4620 4570 4501 4578 4490 4537 4583 4585 4488 4484 4507 4575 4533 4570 4419 4627 4473 4610 4542 4422 4383 4491 4489 4479 4468 4511 4475 4515 4554 4498 4546 4560 4500 4462 4613 4535 4415 4525 4599 4585 4487 4600 4412 4504 4477 4544 4521 4538 4657 4649 4557 4577 4702 4461 4616 4653 4576 4615 4676 4548 4662 4572 4648 4559 4584 4692 4711 4770 4796 4660 4639 4796 4717 4754 4758 4759 4702 4723 4716 4665 4705 4721 4729 4646 4831 4783 4763 4642 4619 4701 4649 4607 4690 4662 4771 4746 4803 4747 4761 4749 4810 4744 4809 4838 4666 4665 4786 4782 4734 4688 4714 4745 4705 4691 4807 4783 4741 4654 4705 4616 4776 4744 4675 4605 4675 4512 4688 4543 4661 4586 4614 4696 4547 4616 4613 4538 4658 4682 4710 4743 4694 4611 4688 4712 4756 4698 4824 4779 4797 4763 4757 4853 4958 4934 4907 5033 5198 4924 5005 4994 4959 5041 4836 4914 4864 4703 4692 4749 4848 4788 4838 4776 4856 4796 4555 4708 4818 4796 4760 4696 4891 4916 4643 4799 4776 4728 4671 4854 4796 4721 4719 4656 4754 4724 4704 4825 4611 4680 4545 4575 4676 4627 4672 4725 4675 4509 4483 4550 4578 4476 4604 4611 4579 4449 4544 4586 4565 4499 4555 4480 4479 4581 4596 4466 4487 4561 4513 4510 4487 4390 4547 4525 4543 4595 4371 4594 4348 4498 4531 4537 4519 4558 4495 4450 4528 4596 4539 4462 4647 4468 4509 4557 4541 4573 4497 4415 4580 4579 4535 4557 4529 4549 4612 4546 4595 4655 4601 4505 4510 4369 4570 4550 4580 4552 4551 4571 4664 4511 4410 4664 4588 4673 4630 4627 4526 4736 4602 4606 4786 4634 4564 4618 4645 4613 4609 4456 4679 4583 4586 4510 4611 4507 4597 4587 4605 4584 4563 4538 4638 4610 4644 4625 4538 4603 4555 4611 4647 4584 4535 4625 4568 4568 4581 4459 4558 4700 4602 4538 4635 4707 4563 4640 4577 4747 4599 4624 4378 4544 4604 4591 4614 4599 4541 4497 4584 4506 4524 4637 4668 4511 4590 4506 4607 4617 4476 4712 4559 4524 4648 4533 4574 4602 4414 4504 4780 4614 4558 4568 4670 4646 4614 4720 4620 4690 4620 4651 4702 4457 4571 4667 4551 4426 4550 4670 4513 4375 4503 4485 4518 4630 4539 4469 4619 4565 4510 4595 4565 4582 4428 4572 4501 4697 4690 4556 4546 4545 4617 4658 4612 4684 4731 4526 4434 4546 4603 4653 4583 4579 4693 4632 4538 4553 4595 4678 4690 4722 4589 4569 4616 4542 4539 4570 4588 4677 4600 4591 4547 4515 4528 4573 4525 4668 4585 4646 4684 4577 4536 4571 4502 4779 4514 4545 4620 4581 4519 4659 4492 4616 4571 4593 4604 4573 4568 4738 4611 4667 4503 4464 4627 4498 4681 4527 4592 4735 4509 4621 4455 4579 4534 4559 4518 4509 4484 4506 4566 4606 4499 4666 4533 4652 4642 4570 4673 4540 4641 4528 4607 4492 4682 4733 4701 4548 4802 4676 4632 4570 4637 4613 4709 4702 4722 4700 4662 4743 4594 4576 4591 4687 4621 4660 4667 4681 4507 4665 4619 4550 4557 4687 4601 4582 4491 4617 4628 4641 4569 4681 4676 4734 4726 4638 4576 4614 4620 4599 4622 4637 4405 4678 4605 4671 4667 4513 4610 4688 4762 4634 4560 4531 4639 4587 4576 4617 4586 4668 4503 4631 4550 4560 4638 4637 4556 4595 4620 4606 4558 4712 4643 4597 4525 4639 4504 4641 4503 4608 4543 4523 4602 4592 4538 4478 4640 4633 4661 4695 4747 4575 4688 4541</counts>
			</dataPoints>
		</scan>
	</xrdMeasurement>
</xrdMeasurements>