File: dataset/precursor_mixture/NaHCO3_Li2TiO3_HfO2_Ga2O3.12-min.xrdml
<?xml version="1.0"?>
<xrdMeasurements xmlns="http://www.xrdml.com/XRDMeasurement/2.2" xmlns:xsi="http://www.w3.org/2001/XMLSchema-instance" xsi:schemaLocation="http://www.xrdml.com/XRDMeasurement/2.2 http://www.xrdml.com/XRDMeasurement/2.2/XRDMeasurement.xsd" status="Completed" recordIdentifier="{7A5FB488-9189-4607-94D3-8EBCAB42E0B9}">
	<comment>
		<entry/>
	</comment>
	<sample type="To be analyzed">
		<id>dara-21-2</id>
		<name></name>
		<preparedBy></preparedBy>
	</sample>
	<xrdMeasurement measurementType="Scan" status="Completed" sampleMode="Reflection">
		<usedWavelength intended="K-Alpha 1">
			<kAlpha1 unit="Angstrom">1.5405980</kAlpha1>
			<kAlpha2 unit="Angstrom">1.5444260</kAlpha2>
			<kBeta unit="Angstrom">1.3922500</kBeta>
			<ratioKAlpha2KAlpha1>0.5000</ratioKAlpha2KAlpha1>
		</usedWavelength>
		<incidentBeamPath>
			<radius unit="mm">145.00</radius>
			<xRayTube id="1010048" name="Empyrean Cu LFF HR (9430 033 7310x) DK437873">
				<tension unit="kV">40.0</tension>
				<current unit="mA">15.0</current>
				<anodeMaterial>Cu</anodeMaterial>
				<focus type="Line">
					<length unit="mm">12.0</length>
					<width unit="mm">0.4</width>
					<takeOffAngle unit="deg">6.0</takeOffAngle>
				</focus>
			</xRayTube>
			<filter id="20010004" name="Beta-filter Nickel">
				<material>Ni</material>
				<thickness unit="mm">0.020</thickness>
			</filter>
			<sollerSlit id="21010002" name="Soller slits 0.04 rad.">
				<opening unit="rad">0.0400</opening>
			</sollerSlit>
			<mask id="22031000" name="Fixed mask 13 mm">
				<width unit="mm">9.00</width>
			</mask>
			<divergenceSlit id="22120001" name="Divergence slit 1°" xsi:type="fixedDivergenceSlitType">
				<distanceToSample unit="mm">50.00</distanceToSample>
				<height unit="mm">1.52</height>
			</divergenceSlit>
		</incidentBeamPath>
		<beamKnife id="29030100" name="Beam knife low"/>
		<sampleMovement xsi:type="spinningSampleMovementType">
			<spinnerRevolutionTime unit="seconds">1.0</spinnerRevolutionTime>
		</sampleMovement>
		<diffractedBeamPath>
			<radius unit="mm">145.00</radius>
			<antiScatterSlit id="22090040" name="AS slit 9 mm" xsi:type="fixedAntiScatterSlitType">
				<height unit="mm">9.00</height>
			</antiScatterSlit>
			<sollerSlit id="21020003" name="Large Soller slits 0.04 rad.">
				<opening unit="rad">0.0400</opening>
			</sollerSlit>
			<filter id="20030001" name="Large beta-filter Nickel">
				<material>Ni</material>
				<thickness unit="mm">0.020</thickness>
			</filter>
			<detector id="7010019" name="PIXcel1D-Medipix3 detector" xsi:type="rtmsDetectorType">
				<phd unit="keV">
					<lowerLevel>4.0</lowerLevel>
					<upperLevel>11.3</upperLevel>
				</phd>
				<mode>Scanning</mode>
				<activeLength unit="deg">5.020</activeLength>
			</detector>
		</diffractedBeamPath>
		<scan appendNumber="0" mode="Continuous" scanAxis="Gonio" status="Completed">
			<header>
				<startTimeStamp>2024-03-24T12:23:23-07:00</startTimeStamp>
				<endTimeStamp>2024-03-24T12:35:50-07:00</endTimeStamp>
				<author>
					<name>AutomatedUser</name>
				</author>
				<source>
					<applicationSoftware version="1.6 (94)">PANalytical Aeris Instrument Suite</applicationSoftware>
					<instrumentControlSoftware version="3.0.0 20211014">AERIS</instrumentControlSoftware>
					<instrumentID>2879380</instrumentID>
				</source>
			</header>
			<dataPoints>
				<positions axis="2Theta" unit="deg">
					<startPosition>9.99043322</startPosition>
					<endPosition>100.09495370</endPosition>
				</positions>
				<positions axis="Omega" unit="deg">
					<startPosition>4.99521661</startPosition>
					<endPosition>50.04747685</endPosition>
				</positions>
				<commonCountingTime unit="seconds">18.249</commonCountingTime>
				<counts unit="counts">4216 4017 3985 4031 4024 4038 3933 4024 3974 3996 4140 4097 4008 4039 3919 3984 4075 3983 3943 4015 4117 4119 4052 4086 4020 4001 3940 3930 3936 3970 3979 4005 3901 3908 3891 3915 4088 3915 3908 3970 3981 3846 3919 3915 3903 3886 3790 3812 3932 3856 3859 3793 3798 3839 3846 3696 3936 3890 3796 3871 3783 3822 3794 3769 3905 3697 3758 3774 3769 3822 3898 3772 3716 3673 3719 3669 3703 3728 3776 3747 3690 3665 3669 3647 3700 3666 3611 3817 3571 3670 3653 3682 3729 3649 3698 3608 3619 3602 3648 3741 3573 3588 3622 3618 3751 3680 3561 3597 3592 3553 3501 3441 3548 3562 3488 3667 3567 3526 3426 3506 3466 3629 3554 3505 3532 3428 3538 3441 3431 3456 3454 3415 3504 3546 3374 3487 3534 3558 3425 3720 3424 3462 3455 3396 3445 3509 3426 3311 3367 3420 3317 3428 3415 3353 3431 3482 3370 3428 3389 3391 3401 3401 3366 3401 3428 3315 3319 3315 3411 3483 3334 3309 3345 3437 3364 3412 3339 3328 3235 3292 3188 3327 3122 3241 3216 3282 3301 3235 3231 3334 3250 3307 3155 3260 3290 3243 3191 3232 3211 3184 3150 3204 3204 3184 3263 3233 3257 3203 3311 3196 3221 3244 3223 3172 3179 3141 3204 3131 3270 3117 3125 3128 3211 3108 3099 3174 3208 3139 3084 3160 3124 3206 3132 3156 3111 3127 3200 3230 3194 3066 3153 3103 3022 3165 3115 3088 3078 3059 3029 3166 3171 3031 3144 3094 3128 3033 2982 3067 3111 2964 3053 3060 3083 3084 3005 3106 3022 3111 3134 3126 3062 3118 3080 3079 3103 2950 3133 3093 2964 2983 3010 3025 3151 2923 2962 2972 2951 3047 3020 3002 2940 2923 2942 3043 2945 2958 3011 3001 2982 2945 2956 2962 3010 2913 2911 2886 2995 2882 3008 2845 2798 2863 2982 2801 2897 2766 2936 2814 2815 2898 2868 2858 2862 2797 2867 2909 2960 2832 2892 2830 2849 2803 2926 2935 2854 2933 2853 2782 2869 2901 2833 2917 2894 2781 2878 2829 2775 2895 2865 2907 2787 2844 2935 2849 2853 2792 2824 2786 2793 2859 2798 2793 2876 2860 2763 2901 2818 2747 2760 2803 2639 2782 2736 2826 2780 2850 2759 2788 2656 2743 2684 2871 2745 2646 2810 2737 2689 2670 2762 2726 2765 2645 2731 2761 2820 2618 2714 2766 2792 2691 2661 2766 2804 2684 2723 2757 2833 2713 2682 2700 2702 2656 2763 2706 2640 2762 2715 2663 2789 2759 2684 2705 2757 2703 2746 2720 2698 2725 2696 2762 2651 2741 2679 2820 2647 2733 2809 2773 2779 2700 2795 2818 2699 2752 2782 2686 2817 2654 2792 2898 2842 2851 2850 2838 2775 2871 2934 2917 2996 3012 2976 3105 3081 3139 3228 3203 3116 3043 3047 2896 2983 2796 2765 2764 2708 2751 2702 2649 2576 2655 2650 2702 2717 2606 2714 2649 2628 2703 2619 2687 2652 2655 2699 2665 2570 2616 2670 2670 2692 2651 2602 2684 2612 2709 2633 2550 2661 2592 2694 2736 2543 2651 2660 2708 2694 2660 2603 2663 2674 2599 2673 2656 2721 2780 2675 2731 2700 2741 2686 2806 2624 2724 2680 2717 2674 2818 2574 2597 2677 2647 2557 2556 2680 2569 2609 2554 2630 2591 2566 2611 2622 2586 2506 2646 2594 2536 2540 2558 2551 2538 2640 2538 2613 2469 2453 2495 2541 2558 2498 2521 2543 2594 2520 2505 2565 2497 2500 2529 2624 2497 2553 2592 2538 2582 2445 2480 2490 2596 2566 2463 2541 2523 2511 2545 2481 2516 2399 2423 2491 2532 2489 2553 2457 2540 2484 2512 2413 2493 2443 2517 2501 2437 2435 2430 2432 2458 2467 2488 2533 2386 2436 2481 2539 2456 2478 2490 2453 2496 2449 2457 2543 2497 2512 2454 2472 2472 2495 2447 2470 2565 2453 2485 2503 2478 2395 2493 2440 2407 2436 2518 2462 2443 2477 2561 2433 2415 2483 2535 2583 2474 2503 2459 2468 2570 2444 2543 2441 2453 2456 2536 2609 2508 2632 2618 2561 2655 2684 2631 2725 2723 2638 2826 2880 2854 2913 2899 2932 3069 3026 3154 3248 3300 3324 3487 3575 3503 3685 3758 3753 3810 3819 3859 3769 3708 3745 3516 3449 3342 3287 3168 2972 2933 2872 2718 2730 2737 2649 2611 2635 2545 2544 2645 2467 2542 2579 2589 2503 2545 2546 2492 2476 2513 2453 2557 2587 2556 2533 2550 2504 2584 2503 2545 2584 2490 2642 2639 2528 2554 2697 2644 2705 2778 2769 2824 2958 2914 2957 3031 2988 3152 3145 3211 3366 3456 3575 3733 3912 4066 4259 4297 4488 4598 4742 4523 4646 4381 4041 3975 3686 3680 3525 3394 3358 3228 3214 3163 3257 3152 3174 3134 3220 3096 3050 3184 3120 3085 2963 3004 2896 2907 2913 3088 2971 3043 2970 2933 3025 2972 3097 3133 3096 3203 3236 3394 3321 3330 3463 3538 3638 3790 3820 3981 3953 4018 3981 4060 4092 4124 4191 4101 4055 3917 3899 3817 3541 3459 3397 3157 3172 3168 3046 2988 2783 2824 2752 2737 2649 2672 2523 2475 2471 2479 2519 2492 2455 2459 2411 2357 2336 2383 2383 2379 2334 2273 2313 2388 2344 2276 2309 2272 2286 2270 2331 2303 2251 2230 2300 2244 2266 2283 2260 2196 2226 2248 2235 2235 2232 2261 2296 2207 2186 2265 2275 2256 2155 2287 2180 2301 2091 2220 2198 2201 2245 2170 2243 2254 2271 2181 2157 2166 2214 2126 2079 2236 2200 2289 2159 2256 2211 2237 2227 2166 2260 2119 2287 2204 2250 2122 2144 2246 2246 2243 2269 2197 2217 2205 2201 2202 2262 2263 2263 2286 2241 2181 2263 2296 2305 2204 2279 2302 2203 2243 2301 2251 2250 2263 2325 2243 2291 2314 2188 2269 2269 2235 2166 2237 2206 2168 2242 2203 2175 2194 2320 2151 2259 2202 2109 2233 2139 2185 2280 2262 2205 2165 2147 2110 2189 2190 2094 2164 2168 2180 2120 2126 2125 2101 2182 2114 2140 2057 2077 2087 2040 2201 2103 2163 2033 2091 2132 2130 2172 2063 2075 2086 2106 2102 2169 2204 2150 2167 2097 2104 2097 2037 2086 2077 2201 2164 2118 2154 2104 2121 2136 2096 2131 2157 2061 2124 2080 2064 2082 2032 2131 2085 2088 2166 2089 2088 2106 2170 2058 2105 2108 2100 2090 1974 2179 2055 2172 2126 2011 2048 2037 1966 2130 2069 2044 2062 2044 2035 2048 2000 1994 2110 2013 2013 2030 2091 1977 2036 2040 2039 1990 1980 2035 2007 1986 2042 2032 2046 2142 2130 2156 2105 2149 1979 2127 2148 2150 2162 2110 2058 2147 2105 2021 2008 1944 1969 1952 1992 1969 1964 1899 2010 1964 1956 1906 2031 1970 1951 1937 2007 1901 1902 1960 1976 2026 1946 1954 1961 1877 2016 1950 1842 1900 1884 1896 1930 1911 1939 1824 1931 1979 1857 1902 1851 1942 1932 1913 1896 1917 1916 1847 1848 1868 1865 1935 1942 1879 1856 1868 1881 1836 1882 1959 1907 1839 1901 1966 1853 1888 1928 1797 1843 1857 1827 1932 1821 1898 1874 1889 1961 1881 1823 1929 1783 1863 1986 1918 1845 1935 1860 1877 1893 1927 1928 1827 1882 1907 1834 1875 1758 1863 1806 1918 1867 1835 1874 1782 1739 1900 1814 1771 1844 1802 1857 1876 1940 1860 1931 1850 1800 1837 1861 1850 1914 1864 1852 1790 1906 1873 1865 1924 1919 1891 1953 1903 1826 1927 1930 1886 1930 1911 1949 1855 1841 1868 1894 1918 1908 1796 1880 1928 2018 1988 1956 2023 1894 1902 1940 2015 1977 1978 2039 2012 2029 2125 2142 2187 2157 2243 2358 2279 2452 2493 2506 2796 2835 2971 2941 2886 2995 3017 2899 2886 2817 2681 2810 2599 2479 2631 2666 2634 2762 2774 2984 3024 3196 3353 3407 3690 3783 4049 4322 4536 4778 5021 5288 5541 5885 5883 6242 6046 6172 6190 6062 5846 5553 5247 4896 4574 4274 3866 3849 3581 3445 3213 3085 3034 3004 2957 2854 2853 2987 3123 3095 3215 3214 3477 3528 3700 3767 3932 4243 4450 4481 4849 4839 5175 5193 5171 5195 5093 4996 4739 4478 4339 4032 3815 3493 3254 3060 2957 2714 2663 2455 2359 2294 2149 2184 2163 2040 2106 2012 2082 1944 2004 2006 1946 1955 2050 1858 1943 1888 1856 1848 1831 1884 1929 1927 1944 1838 1915 1797 1892 1842 1915 1932 1836 1852 1906 1986 1954 1939 1995 1932 2017 2068 2088 2048 2092 2182 2153 2159 2223 2236 2352 2301 2283 2257 2367 2492 2443 2394 2462 2619 2600 2755 2867 3097 3254 3351 3732 3946 4264 4628 4994 5160 5336 5623 5318 5218 4658 4554 4142 3915 3625 3328 2949 2627 2437 2166 2052 2093 1952 1944 1921 1793 1923 1896 1770 1807 1786 1739 1793 1693 1804 1773 1817 1757 1695 1789 1767 1781 1836 1825 1746 1722 1711 1721 1684 1719 1688 1693 1675 1699 1758 1636 1753 1702 1742 1639 1716 1738 1648 1627 1680 1707 1696 1660 1618 1606 1678 1654 1569 1707 1755 1638 1650 1653 1720 1700 1713 1591 1654 1702 1700 1631 1714 1643 1708 1669 1596 1605 1620 1703 1654 1596 1588 1649 1618 1665 1673 1774 1699 1645 1709 1630 1668 1751 1629 1663 1691 1781 1736 1689 1624 1719 1602 1645 1750 1674 1658 1705 1708 1724 1682 1682 1664 1608 1675 1699 1714 1662 1698 1751 1698 1580 1735 1665 1709 1764 1733 1665 1721 1695 1745 1770 1683 1751 1734 1761 1750 1794 1783 1785 1814 1879 1792 1817 1832 1889 1809 1916 1863 1891 1890 1851 1936 1847 1853 1881 1850 1892 1825 1954 1904 1909 1935 1933 1943 1955 1975 1958 1955 1996 1915 1991 1991 2043 2015 2056 2037 2038 2057 2119 2218 2147 2191 2188 2115 2278 2163 2208 2346 2240 2279 2214 2234 2292 2344 2386 2312 2292 2422 2509 2508 2678 2535 2607 2582 2726 2784 2793 2832 2946 2946 3093 3099 3104 3253 3356 3470 3626 3722 3915 4173 4110 4424 4708 4923 5299 5380 5820 6313 6746 7153 8034 8523 9209 10210 10912 11918 13176 14276 15483 16932 18402 19797 21213 22582 24041 24831 25596 26145 26454 25954 25100 24362 23106 21574 20145 18244 16940 15263 13807 12531 11103 10145 8987 8518 7566 6909 6413 6078 5583 5231 4943 4688 4468 4386 4223 3920 3778 3616 3538 3438 3353 3350 3214 3073 3075 3064 2945 2904 2874 2842 2763 2789 2839 2721 2878 2912 2920 2979 3056 3148 3319 3506 3718 3842 3787 3782 3652 3474 3364 3323 3170 3197 3109 2930 2834 2752 2770 2599 2642 2571 2665 2627 2665 2629 2519 2532 2471 2533 2513 2293 2432 2302 2318 2327 2178 2209 2158 2162 2100 2123 2085 2137 2181 2159 2151 2175 2164 2126 2146 2119 2132 2232 2213 2231 2150 2253 2235 2117 2195 2259 2257 2264 2327 2230 2293 2324 2317 2380 2401 2452 2502 2438 2610 2471 2639 2660 2683 2615 2717 2719 2825 2943 2904 2943 2970 3042 3227 3298 3281 3494 3634 3570 3806 3978 3920 4035 4302 4535 4733 4891 5078 5298 5436 5771 5960 6225 6540 6831 7406 7766 8292 8926 9277 9832 10393 10852 11216 11814 12333 12686 12525 12533 12043 11343 11231 10577 10492 10216 10314 10281 9962 10041 9979 10252 10674 11103 11413 11697 11885 11954 12068 11802 11260 11098 10660 10352 10025 9554 8955 8438 8165 7634 7242 6826 6321 6160 5773 5532 5249 5006 4879 4642 4502 4308 4291 4043 3979 3868 3881 3658 3615 3516 3409 3495 3384 3429 3314 3222 3126 3139 3246 3174 2959 3149 3065 3103 3105 3041 2978 3058 3023 3127 3030 3016 3011 3143 3118 3044 3253 3229 3117 3293 3380 3238 3236 3424 3472 3461 3515 3520 3631 3650 3731 3812 3965 4027 3991 4054 4351 4286 4385 4652 4765 4917 5085 5272 5407 5659 6103 6223 6730 7079 7511 7906 8196 9005 9503 10136 10925 12008 12847 13947 15142 16273 17229 18826 19792 21192 22776 23423 24627 25312 25837 26088 26036 25553 24959 23711 22764 21577 20507 19195 18046 16746 15414 14620 13108 12208 11302 10506 9664 9091 8522 8059 7504 7197 6655 6205 6067 5696 5536 5188 5080 4887 4535 4509 4230 4267 4031 3823 3713 3614 3489 3373 3356 3242 3184 3112 2953 3058 2860 2886 2820 2733 2736 2570 2527 2557 2530 2501 2491 2380 2394 2303 2221 2314 2208 2205 2243 2174 2156 2197 2198 2145 2088 2123 2048 2002 2080 2092 2038 2007 2022 2030 1945 1988 1866 1915 1934 1874 1882 1830 1884 1928 1808 1752 1921 1798 1783 1869 1800 1862 1883 1843 1839 1878 1829 1778 1805 1822 1805 1780 1840 1881 1802 1814 1807 1793 1759 1741 1758 1693 1865 1857 1789 1867 1797 1743 1846 1754 1800 1877 1802 1758 1915 1806 1787 1909 1890 1832 1978 1997 1940 1938 1974 1997 2113 2136 2070 2093 2182 2235 2398 2326 2331 2485 2575 2709 2702 2747 2615 2693 2738 2683 2810 2797 2788 2746 2748 2733 2703 2686 2559 2653 2629 2537 2563 2619 2471 2468 2285 2474 2344 2386 2258 2172 2146 2190 2231 2080 2005 2201 2136 2144 2058 2040 2104 2014 2117 2129 2086 2108 2145 2052 2091 2065 2122 2198 2078 2206 2210 2108 2158 2153 2142 2134 2170 2287 2217 2244 2337 2331 2337 2422 2457 2464 2620 2751 2912 2837 3052 3267 3393 3481 3712 4168 4242 4476 4780 5331 5580 5912 6339 6862 7284 7497 7905 8335 8464 8697 8751 8968 8845 8849 8630 8673 8645 8705 8742 8832 8751 8879 8575 8466 8245 7949 7875 7805 7893 8148 8018 8501 8233 8222 8051 7968 7630 7680 7132 7078 6800 6409 5987 5894 5453 5092 4880 4560 4138 4043 3806 3674 3447 3311 3307 3146 3094 3011 3010 3046 3057 3069 3014 3048 3109 3103 3223 3216 3303 3378 3647 3727 3905 4112 4226 4339 4510 4838 4905 5020 5284 5474 5756 5788 6094 6248 6170 6246 6336 6457 6230 6279 6406 6076 6112 6226 5960 5873 5699 5666 5644 5613 5499 5418 5438 5682 5753 5914 6203 6300 6721 7088 7385 7693 8127 8329 8534 8578 8706 8598 8182 7976 7615 7266 6760 6528 6108 5664 5234 4866 4586 4079 3985 3674 3300 3177 2962 2790 2738 2710 2689 2584 2561 2470 2475 2447 2496 2555 2491 2438 2482 2470 2464 2533 2441 2620 2590 2640 2717 2745 2869 2934 2994 3108 3059 3293 3345 3411 3433 3456 3483 3486 3319 3259 3117 3137 3051 3010 2795 2719 2535 2499 2475 2269 2224 2170 2076 1975 1904 1949 1827 1822 1811 1792 1733 1757 1768 1726 1705 1722 1666 1604 1663 1687 1627 1617 1641 1635 1572 1585 1577 1548 1575 1604 1530 1612 1584 1625 1601 1589 1562 1607 1613 1666 1610 1687 1575 1560 1670 1642 1622 1657 1644 1681 1721 1724 1717 1691 1715 1662 1704 1696 1556 1663 1680 1692 1714 1601 1660 1623 1669 1738 1728 1816 1726 1731 1796 1802 1793 1872 1836 1936 1977 2017 2009 2080 2049 2019 2162 2195 2252 2202 2368 2363 2479 2612 2739 2799 2885 3116 3164 3210 3165 3199 3168 3064 3145 3179 3075 2895 2929 2975 2864 2846 2830 2753 2696 2619 2567 2554 2474 2486 2382 2391 2345 2324 2146 2234 2154 2121 2092 2085 1983 1970 1931 2005 1876 2041 1966 1826 1809 1878 1880 1866 1858 1763 1847 1850 1847 1776 1909 1871 1877 1865 1789 1864 1841 1866 1835 1923 1913 1913 1911 1885 1978 1925 1956 2030 2012 2087 2021 2134 2128 2166 2093 2149 2252 2249 2321 2345 2502 2591 2488 2660 2715 2677 2797 2889 2952 3045 3101 3254 3224 3426 3510 3609 3630 3693 3817 3734 3804 3804 3824 3788 3821 3682 3765 3649 3582 3570 3443 3474 3378 3246 3320 3123 3148 3021 2873 2953 2886 2851 2921 2721 2808 2871 2805 2877 2885 2970 3184 3194 3394 3390 3508 3628 3815 3825 3824 3866 3832 3757 3685 3527 3458 3347 3271 3143 3063 2937 2774 2630 2656 2580 2471 2312 2380 2307 2304 2246 2234 2179 2230 2145 2101 2033 1994 1912 1854 1886 1802 1847 1739 1642 1625 1621 1610 1525 1557 1494 1462 1498 1466 1439 1382 1386 1430 1396 1393 1460 1375 1361 1418 1358 1353 1410 1346 1376 1410 1361 1378 1337 1338 1358 1335 1311 1339 1368 1326 1389 1360 1381 1314 1377 1344 1359 1310 1325 1335 1400 1414 1339 1351 1345 1387 1252 1336 1271 1329 1271 1295 1347 1279 1365 1296 1372 1286 1234 1359 1255 1309 1283 1367 1327 1334 1405 1365 1381 1400 1369 1326 1319 1328 1374 1325 1361 1404 1424 1507 1400 1388 1440 1462 1439 1498 1478 1497 1505 1587 1519 1551 1568 1548 1583 1450 1489 1413 1576 1418 1461 1512 1507 1495 1482 1418 1485 1495 1462 1511 1450 1477 1458 1436 1428 1439 1557 1521 1562 1551 1645 1638 1732 1759 1860 1818 2018 2102 2203 2273 2519 2738 3165 3496 3803 4595 4983 5673 6134 6453 6542 6633 6007 5588 5285 5059 5035 5030 5114 5222 5342 4914 4905 4622 4683 4274 4431 4402 4446 4466 4451 4461 4278 4276 4202 4115 4137 3913 3704 3566 3572 3333 3238 3205 3054 2897 2655 2645 2574 2393 2335 2155 2283 2191 2148 2206 2249 2235 2205 2172 2291 2180 2307 2306 2356 2443 2365 2403 2390 2543 2424 2465 2377 2303 2389 2351 2332 2319 2306 2236 2191 2227 2249 2204 2249 2244 2288 2261 2326 2274 2270 2225 2341 2308 2278 2105 2196 2062 2056 1985 1990 1900 1930 1814 1771 1682 1625 1628 1603 1574 1464 1464 1399 1442 1429 1309 1340 1335 1315 1318 1349 1394 1314 1237 1283 1286 1315 1312 1230 1241 1289 1320 1272 1187 1187 1203 1235 1296 1296 1259 1247 1235 1186 1215 1278 1245 1185 1268 1243 1267 1257 1277 1189 1161 1279 1222 1238 1252 1238 1295 1278 1200 1301 1287 1270 1273 1301 1246 1349 1269 1319 1271 1269 1308 1270 1272 1325 1296 1330 1314 1361 1348 1361 1372 1347 1481 1407 1408 1444 1432 1461 1411 1434 1498 1502 1483 1558 1545 1495 1615 1572 1628 1573 1654 1597 1666 1736 1670 1655 1709 1704 1731 1718 1670 1724 1814 1751 1785 1737 1715 1756 1745 1737 1818 1719 1690 1864 1676 1799 1780 1727 1826 1828 1751 1798 1763 1795 1749 1825 1780 1796 1734 1860 1891 1776 1842 1788 1838 1880 1937 1922 1918 2007 2092 2061 2186 2183 2244 2284 2297 2462 2408 2602 2671 2808 2854 2889 2992 3074 3200 3331 3275 3450 3500 3465 3597 3629 3723 3593 3574 3626 3610 3599 3405 3366 3372 3236 3209 3089 2964 2870 2925 2777 2690 2554 2408 2322 2321 2235 2160 2025 1989 2058 1817 1768 1871 1701 1693 1689 1733 1717 1593 1654 1550 1555 1608 1583 1423 1495 1411 1496 1402 1457 1339 1434 1430 1418 1418 1401 1355 1416 1315 1448 1276 1364 1385 1428 1440 1357 1416 1439 1425 1459 1473 1521 1626 1583 1677 1716 1891 1936 1903 2011 2075 2071 2117 2178 2287 2283 2357 2371 2451 2535 2381 2191 2159 2033 2070 2041 1911 1996 2001 2022 1829 1976 1788 1757 1697 1713 1709 1623 1607 1668 1560 1593 1544 1644 1563 1571 1547 1639 1617 1698 1701 1648 1741 1662 1843 1851 1834 1910 1944 2010 2053 2137 2122 2164 2287 2297 2354 2285 2335 2351 2230 2190 2142 2082 2187 2063 1923 2018 1937 1904 1842 1770 1814 1782 1704 1704 1648 1594 1602 1616 1572 1622 1558 1498 1520 1555 1492 1557 1654 1639 1693 1661 1672 1696 1774 1869 1908 1851 1893 2009 1932 2036 2156 2222 2258 2473 2444 2582 2676 2641 2805 2943 3066 3154 3253 3379 3344 3401 3532 3421 3448 3543 3579 3449 3361 3396 3400 3183 3250 3146 3023 3006 3138 2977 2954 2838 2973 2939 3015 3023 3099 3128 3185 2980 2990 2840 2687 2595 2532 2494 2374 2357 2337 2313 2394 2051 2095 1903 1830 1718 1661 1576 1585 1552 1519 1516 1406 1486 1319 1366 1272 1344 1322 1277 1261 1286 1236 1251 1197 1221 1240 1230 1164 1207 1101 1163 1218 1134 1144 1251 1183 1208 1185 1173 1149 1176 1146 1118 1179 1193 1190 1178 1114 1154 1109 1169 1075 1128 1181 1134 1167 1239 1228 1164 1220 1256 1222 1255 1297 1352 1362 1373 1318 1375 1335 1267 1221 1242 1225 1262 1236 1199 1214 1304 1265 1232 1199 1201 1189 1143 1155 1120 1182 1101 1079 1148 1088 1169 1155 1138 1132 1117 1082 1128 1154 1150 1074 1127 1117 1080 1154 1128 1047 1120 1092 1130 1131 1109 1097 1129 1214 1152 1219 1159 1105 1229 1195 1292 1214 1243 1144 1223 1151 1197 1179 1251 1164 1290 1255 1325 1329 1405 1410 1348 1495 1516 1610 1520 1723 1603 1750 1648 1591 1549 1539 1474 1453 1434 1415 1430 1478 1462 1464 1436 1409 1287 1294 1301 1343 1275 1300 1283 1285 1316 1235 1278 1231 1296 1332 1329 1299 1379 1376 1259 1345 1304 1327 1333 1353 1341 1323 1391 1372 1400 1429 1406 1335 1395 1424 1482 1414 1465 1418 1463 1443 1452 1530 1512 1484 1583 1570 1612 1627 1632 1689 1784 1935 1972 1983 2135 2255 2411 2360 2429 2267 2316 2173 2259 2143 2267 2217 2336 2330 2333 2438 2369 2364 2314 2234 2238 2199 2321 2354 2396 2322 2438 2301 2261 2224 2036 2073 1987 1876 1858 1859 1762 1779 1753 1863 1713 1751 1728 1578 1591 1520 1522 1508 1485 1545 1516 1493 1530 1467 1530 1573 1486 1651 1623 1613 1642 1612 1666 1759 1762 1765 1809 1838 1791 1852 1849 1804 1852 1908 1954 1980 2096 2114 2109 2162 2304 2304 2461 2628 2693 2812 3016 3143 3340 3605 3956 4166 4418 4912 5082 5399 5650 5726 5804 5879 5556 5439 5252 4989 4860 4673 4689 4409 4312 4337 4057 3942 3826 3425 3381 3096 3050 2712 2458 2367 2274 2255 2054 2089 1942 1832 1861 1795 1751 1757 1684 1634 1623 1662 1595 1641 1527 1604 1549 1621 1598 1570 1565 1539 1622 1591 1594 1610 1682 1651 1639 1661 1691 1649 1669 1672 1734 1866 1858 1839 2016 2035 2132 2247 2338 2493 2596 2891 3044 3361 3766 4235 4455 4929 5501 5909 6257 6470 6657 6832 6826 6523 6342 6110 5912 5521 5448 5420 5122 5136 5018 4957 4705 4540 4240 3973 3692 3598 3434 3067 2877 2950 2890 2919 2878 2918 2826 2851 3004 3064 3257 3239 3621 3754 3801 4071 3982 4048 4154 4128 3955 3878 3866 3647 3543 3575 3347 3339 3206 3185 3165 3148 2946 2801 2676 2550 2442 2262 2161 2060 1984 1872 1851 1706 1726 1654 1644 1603 1583 1511 1573 1583 1485 1533 1470 1550 1528 1596 1520 1590 1598 1538 1637 1565 1624 1668 1615 1692 1688 1757 1874 1849 1989 2012 2024 2087 2151 2116 2194 2152 2168 2155 2016 2093 2030 1967 1983 1882 1881 1836 1802 1820 1710 1728 1722 1747 1493 1609 1413 1434 1440 1367 1400 1306 1302 1254 1237 1232 1207 1245 1174 1155 1196 1149 1134 1196 1062 1144 1146 1200 1077 1204 1134 1109 1135 1101 1127 1146 1108 1110 1022 1104 1090 1050 1083 1081 1093 1084 1068 1114 1107 1116 1089 1144 1137 1054 1057 1102 1091 1105 1117 1084 1100 1170 1121 1108 1123 1103 1151 1222 1176 1161 1181 1257 1264 1369 1460 1438 1452 1584 1563 1532 1497 1450 1508 1406 1467 1428 1413 1491 1507 1532 1534 1566 1566 1668 1620 1619 1675 1638 1527 1589 1399 1344 1339 1305 1336 1364 1289 1325 1291 1307 1290 1332 1294 1191 1185 1145 1168 1139 1185 1118 1120 1082 1092 1076 1046 1078 1077 1013 1122 1026 1070 1074 1063 1011 1071 1076 1056 1051 1064 1099 972 1059 1091 1122 1146 1039 1071 991 1121 1065 1000 1081 1100 1095 1130 1028 1086 1086 1092 1083 1043 1067 1078 1091 1075 1099 1037 1099 997 1047 1027 1118 1079 1077 1069 1100 1052 1052 1090 1060 1072 1094 1069 1141 1102 1145 1124 1136 1085 1101 1096 1123 1136 1162 1114 1185 1088 1189 1093 1207 1212 1249 1160 1241 1137 1189 1239 1177 1188 1252 1195 1332 1264 1338 1313 1327 1396 1309 1375 1395 1420 1418 1425 1444 1465 1464 1473 1555 1581 1681 1643 1710 1715 1797 1837 2006 1929 2100 2035 2245 2304 2437 2555 2695 2626 2656 2890 2969 3161 3269 3317 3476 3543 3653 3687 3759 3785 3747 3563 3638 3471 3391 3242 3343 3093 3082 3008 2892 2846 2891 2748 2663 2522 2484 2401 2216 2209 2100 2038 1913 1902 1913 1729 1778 1774 1696 1610 1664 1526 1611 1559 1416 1518 1497 1517 1435 1464 1481 1468 1482 1440 1517 1465 1542 1581 1589 1535 1540 1514 1534 1469 1583 1615 1548 1540 1483 1494 1620 1529 1614 1533 1587 1627 1638 1689 1730 1704 1879 1803 1864 1914 1930 1934 1862 1879 1750 1726 1655 1704 1724 1741 1755 1831 1790 1824 1830 1934 1951 1896 1971 2053 1955 2085 2262 2261 2320 2454 2579 2746 2798 2999 3195 3245 3534 3687 3830 3970 4192 4033 4284 4317 4273 4317 4358 4203 4277 4028 4174 4080 4060 4098 3903 4031 4059 3934 3995 3866 3965 3802 3981 3761 3513 3519 3297 3227 3231 3117 2939 2873 2906 2789 2751 2723 2571 2652 2611 2506 2537 2460 2401 2439 2515 2481 2482 2598 2706 2722 2977 2963 3027 3243 3154 3259 3311 3206 3228 3067 3085 3046 2991 2972 2825 2744 2840 2762 2735 2674 2543 2586 2460 2381 2260 2192 2044 1966 1962 1942 1825 1823 1762 1722 1649 1644 1578 1592 1571 1537 1476 1482 1434 1461 1444 1290 1379 1390 1314 1309 1356 1369 1300 1343 1405 1359 1386 1312 1353 1381 1358 1446 1455 1456 1507 1641 1623 1774 2050 2209 2596 2917 3348 3739 3879 4039 3827 3178 2730 2361 2205 2084 1971 2055 2218 2354 2472 2690 2905 2797 2747 2500 2351 2128 2021 1952 1959 1917 1787 1842 1994 1898 1950 1954 2033 2196 2174 2193 2345 2362 2504 2573 2749 2806 2956 2964 3139 3284 3410 3538 3643 3644 3790 3716 3877 3604 3798 3700 3663 3694 3671 3636 3450 3400 3432 3392 3388 3250 3310 3211 3008 2993 2865 2801 2744 2572 2575 2451 2547 2344 2316 2263 2202 2143 2213 2110 2002 1981 1979 1883 1974 1910 1783 1802 1791 1800 1889 1826 1777 1795 1693 1842 1792 1842 1902 1926 1987 2037 2017 2049 2186 2265 2335 2518 2525 2610 2669 2740 2765 2708 2780 2808 2717 2597 2646 2555 2549 2592 2457 2617 2636 2455 2477 2483 2477 2448 2417 2386 2267 2305 2178 2149 2073 2205 2114 2162 2210 2283 2240 2269 2266 2319 2274 2308 2321 2263 2273 2211 2209 2069 2104 1975 2043 2059 2041 1961 1945 1889 1900 1870 1908 1847 1885 1785 1686 1834 1813 1749 1728 1697 1681 1685 1678 1734 1729 1735 1767 1744 1832 1802 1787 1822 1800 1830 1790 1879 1933 1790 1821 1896 1799 1760 1736 1835 1862 1835 1750 1812 1750 1774 1741 1657 1709 1601 1702 1552 1684 1521 1535 1582 1542 1505 1592 1581 1588 1531 1504 1524 1472 1515 1446 1474 1517 1453 1451 1488 1408 1419 1446 1441 1503 1502 1477 1440 1447 1452 1525 1485 1551 1560 1601 1585 1663 1638 1707 1704 1677 1693 1829 1806 1829 1845 1778 1822 1824 1844 1876 1926 1976 1998 2042 2062 2132 2066 2120 2169 2312 2378 2313 2387 2439 2483 2456 2524 2591 2639 2781 2842 2895 3111 3203 3338 3552 3681 3646 3675 3780 3826 3747 3723 3662 3635 3538 3601 3647 3668 3686 3568 3815 3575 3708 3663 3806 3761 3719 3562 3787 3607 3512 3455 3546 3347 3291 3234 3316 3322 2999 3048 2966 3077 2940 2935 2831 2770 2814 2705 2553 2632 2498 2338 2385 2419 2521 2357 2318 2319 2269 2199 2154 2350 2313 2317 2356 2418 2375 2497 2616 2695 2512 2548 2555 2476 2479 2330 2359 2321 2348 2279 2267 2329 2275 2328 2268 2292 2328 2217 2057 2082 2060 2065 1966 1913 1903 1976 1961 1912 1840 1755 1779 1779 1743 1741 1680 1663 1631 1662 1605 1607 1596 1513 1560 1624 1557 1529 1508 1487 1511 1621 1488 1582 1567 1499 1446 1503 1476 1665 1576 1552 1618 1592 1648 1659 1742 1723 1783 1824 1845 1919 2010 1952 2036 2123 2182 2210 2256 2330 2428 2487 2601 2537 2542 2476 2552 2507 2560 2463 2322 2436 2234 2315 2203 2254 2216 2233 2293 2146 2180 2120 2192 2016 2148 1968 2005 1938 1951 1923 1909 1915 1918 1892 1858 1797 1735 1863 1867 1893 1908 2009 1962 2012 2117 2101 2287 2171 2324 2400 2436 2494 2594 2636 2754 2851 2973 2891 2940 2954 2918 2955 2802 2854 2829 2724 2703 2624 2576 2548 2539 2493 2514 2401 2452 2415 2392 2365 2415 2369 2330 2247 2168 2271 2299 2308 2322 2283 2401 2380 2203 2184 2007 2072 2044 1975 2029 2011 1915 2023 1950 2076 2047 1958 2113 2012 1963 2104 2034 1879 1979 1937 1942 1866 1994 1885 1938 1962 1996 2034 2029 2003 2074 2055 2079 2132 2175 2118 2219 2391 2445 2641 2675 2753 2800 2898 2991 3082 3261 3333 3442 3636 3627 3759 3733 3742 3699 3703 3732 3540 3645 3554 3510 3448 3448 3381 3509 3377 3389 3489 3335 3527 3246 3268 3218 3081 2989 3020 2872 2869 2604 2625 2644 2518 2443 2426 2353 2402 2275 2250 2250 2109 2090 2128 2056 2003 2024 1984 1964 1967 1890 1974 1896 1917 1936 1868 1919 1803 1859 1796 1848 1781 1800 1820 1851 1875 1843 1919 1902 2001 1996 1983 2033 2078 2030 2134 2162 2095 2122 2149 2148 2156 2144 2180 2177 2202 2258 2182 2230 2182 2178 2213 2190 2308 2282 2168 2208 2309 2306 2331 2301 2369 2363 2503 2464 2465 2465 2693 2635 2639 2897 2695 2918 2954 3028 3172 3108 3296 3390 3291 3481 3567 3552 3736 3496 3802 3881 3924 3947 4164 4226 4145 4208 4149 4189 4250 4094 4084 4086 4004 3914 3783 3827 3803 3597 3426 3512 3340 3329 3156 3184 3042 2976 3072 2825 2700 2727 2593 2462 2402 2325 2155 2232 1995 2065 2055 1899 1868 1743 1739 1782 1673 1638 1661 1595 1588 1549 1463 1499 1428 1551 1504 1406 1346 1371 1394 1446 1286 1335 1344 1358 1364 1351 1438 1454 1422 1506 1471 1497 1550 1522 1491 1474 1497 1425 1440 1369 1495 1454 1402 1424 1381 1436 1376 1486 1433 1357 1440 1415 1453 1472 1394 1405 1490 1455 1520 1511 1530 1607 1617 1614 1685 1716 1737 1792 1788 1863 1846 1820 1838 1884 1817 1729 1703 1784 1804 1840 1878 1797 1898 1856 1854 2009 2038 2097 2032 2021 2231 2311 2267 2433 2489 2442 2662 2723 2803 2803 2890 2914 2871 2821 2739 2726 2603 2573 2478 2439 2448 2449 2364 2459 2343 2288 2386 2366 2299 2307 2256 2257 2099 2086 1996 1895 1833 1848 1849 1701 1636 1673 1578 1533 1585 1448 1520 1488 1433 1469 1412 1436 1379 1304 1340 1265 1306 1364 1326 1317 1332 1221 1210 1235 1185 1231 1191 1211 1206 1232 1175 1136 1151 1163 1088 1138 1177 1111 1104 1141 1192 1122 1124 1111 1163 1052 1105 1019 1042 1062 1053 1065 1056 1054 997 1027 1041 1012 1041 1056 1041 970 989 981 1008 965 1021 1066 1064 994 1003 1001 990 993 1071 1015 1033 1034 1035 1027 938 1075 966 971 1027 1021 1045 994 1023 1000 986 1041 953 1010 962 1007 1006 931 1036 948 946 991 990 956 957 987 930 1004 961 1006 965 1004 1007 973 985 992 1052 967 976 938 991 984 969 1005 948 959 937 973 927 911 940 950 943 977 1001 1017 1026 988 1008 892 938 968 975 997 932 988 950 994 953 933 964 958 951 961 1012 998 942 1022 993 993 1058 1041 1041 956 1021 961 978 987 954 980 949 968 992 1004 1029 985 1016 984 992 981 997 963 978 940 998 936 1002 1003 1007 1023 976 1006 1097 944 950 1053 1005 999 985 1041 1030 941 1021 1022 1047 1071 991 995 970 1019 1027 1087 1070 1139 1060 1075 1035 1050 1109 1136 1149 1084 1114 1145 1151 1192 1199 1145 1277 1312 1247 1277 1281 1341 1226 1250 1243 1236 1264 1266 1250 1257 1348 1393 1296 1282 1397 1344 1382 1489 1481 1528 1503 1557 1547 1595 1680 1751 1809 1837 1975 2049 2221 2180 2187 2165 2201 2204 2190 2286 2149 2269 2193 2116 2062 2130 2057 1988 2116 2094 2089 2042 2034 2049 2071 1996 1933 1899 1865 1861 1840 1834 1751 1715 1691 1607 1645 1567 1620 1553 1567 1493 1476 1530 1516 1414 1473 1467 1396 1409 1458 1485 1430 1376 1414 1417 1444 1542 1455 1427 1457 1519 1478 1508 1455 1508 1412 1468 1382 1487 1448 1433 1436 1411 1445 1436 1490 1534 1467 1508 1513 1489 1488 1508 1468 1489 1468 1454 1488 1489 1461 1487 1454 1524 1468 1426 1492 1480 1434 1476 1368 1371 1379 1411 1359 1382 1439 1359 1461 1428 1502 1402 1372 1358 1413 1407 1374 1347 1438 1409 1399 1347 1380 1384 1324 1361 1316 1359 1341 1260 1302 1269 1267 1316 1270 1264 1294 1232 1227 1200 1229 1233 1277 1276 1200 1182 1199 1218 1158 1130 1198 1130 1179 1141 1135 1178 1082 1149 1166 1143 1106 1106 1096 1142 1173 1128 1136 1122 1148 1162 1096 1127 1152 1110 1120 1129 1119 1143 1090 1140 1129 1192 1149 1198 1245 1198 1210 1215 1235 1295 1328 1315 1273 1346 1395 1428 1471 1450 1523 1506 1630 1576 1496 1681 1802 1791 1810 1829 1909 1921 1918 1968 1909 1901 1902 1937 2008 1953 2007 2090 2084 1998 2191 2137 2138 2081 2010 2114 1950 1853 1857 1779 1801 1657 1704 1595 1636 1562 1610 1559 1545 1545 1512 1501 1553 1447 1415 1406 1371 1367 1260 1276 1197 1227 1207 1245 1212 1217 1215 1157 1179 1206 1132 1139 1232 1225 1278 1216 1230 1203 1238 1298 1206 1278 1229 1323 1347 1287 1343 1385 1410 1493 1370 1419 1421 1391 1471 1429 1468 1410 1438 1457 1437 1549 1435 1540 1534 1556 1517 1568 1610 1604 1503 1627 1587 1617 1645 1564 1591 1541 1518 1472 1486 1420 1426 1502 1474 1446 1409 1453 1437 1427 1444 1437 1400 1399 1368 1384 1285 1388 1355 1327 1441 1316 1354 1346 1343 1466 1416 1352 1354 1327 1408 1430 1339 1452 1459 1464 1407 1367 1305 1398 1350 1306 1399 1339 1429 1350 1368 1309 1279 1325 1254 1305 1289 1261 1281 1236 1229 1198 1209 1255 1216 1234 1178 1187 1112 1145 1132 1127 1088 1106 1084 1095 1048 1104 1133 1050 1094 1133 1117 1044 1138 1075 1083 1088 1157 1117 1092 1121 1090 1181 1144 1145 1225 1131 1104 1112 1173 1189 1098 1189 1170 1170 1145 1173 1126 1173 1212 1129 1171 1161 1168 1147 1192 1095 1161 1149 1119 1169 1127 1148 1142 1165 1159 1183 1085 1104 1131 1106 1124 1135 1154 1159 1092 1067 1118 1166 1050 1084 1065 1058 1070 1012 1014 1093 1072 1062 1056 1066 1108 1060 1027 1059 1044 1054 1045 1084 1025 993 1030 1050 1069 1033 1012 974 1068 997 968 1003 980 1021 950 1083 1007 1117 1060 966 1017 1018 1022 1041 987 1009 997 1036 1026 974 991 994 964 981 991 1030 997 966 965 1015 1008 980 948 1056 1069 1066 963 990 988 1017 1042 1046 1042 1013 1054 1078 1039 1057 1100 1170 1082 1118 1144 1143 1243 1174 1190 1287 1239 1289 1302 1279 1356 1351 1320 1414 1391 1369 1473 1372 1393 1468 1320 1317 1323 1289 1248 1274 1303 1312 1301 1288 1315 1342 1325 1325 1389 1357 1329 1391 1437 1393 1390 1517 1532 1540 1624 1747 1737 1758 1840 1787 1839 1758 1794 1747 1767 1744 1758 1685 1698 1666 1653 1638 1596 1594 1593 1541 1639 1634 1580 1604 1545 1599 1512 1509 1517 1395 1459 1418 1255 1419 1379 1233 1350 1255 1242 1171 1236 1157 1190 1194 1134 1113 1125 1147 1106 1049 1053 1074 1114 1016 1019 1057 1046 1062 1037 1123 1036 1097 1035 1084 1006 1037 1072 1058 1000 1019 990 1029 999 1076 999 1020 1094 1014 1042 1076 1016 1057 1122 1175 1139 1181 1139 1178 1186 1229 1313 1287 1261 1299 1331 1273 1273 1193 1143 1219 1172 1162 1081 1135 1151 1208 1184 1094 1205 1252 1192 1260 1235 1277 1309 1321 1299 1190 1342 1280 1299 1264 1252 1338 1336 1291 1387 1396 1349 1403 1284 1445 1422 1336 1351 1404 1409 1307 1416 1357 1297 1272 1298 1304 1289 1256 1221 1348 1314 1262 1194 1293 1277 1208 1163 1151 1181 1163 1151 1144 1214 1147 1143 1127 1137 1140 1165 1101 1123 1042 1071 1134 1098 1101 1081 1135 1010 1116 1079 1042 1145 1037 1054 1043 1152 1089 1072 1079 1048 1078 1089 1112 1082 1073 1098 1070 1144 1082 1101 1104 1159 1129 1202 1164 1187 1176 1250 1234 1243 1218 1263 1210 1345 1364 1310 1270 1343 1309 1302 1313 1320 1335 1249 1326 1267 1268 1324 1336 1301 1298 1378 1325 1351 1315 1333 1278 1362 1326 1311 1254 1266 1257 1288 1257 1231 1220 1259 1205 1277 1223 1244 1215 1283 1313 1189 1228 1173 1125 1173 1137 1108 1149 1145 1199 1122 1148 1221 1196 1211 1184 1236 1246 1274 1249 1293 1214 1256 1300 1241 1245 1277 1232 1232 1182 1310 1264 1244 1272 1207 1213 1149 1179 1212 1181 1189 1107 1207 1127 1198 1136 1156 1128 1127 1120 1164 1147 1138 1097 1119 1206 1166 1120 1192 1159 1184 1156 1156 1180 1276 1280 1309 1290 1314 1266 1271 1266 1165 1239 1239 1177 1247 1147 1138 1201 1230 1173 1167 1209 1222 1270 1231 1283 1277 1285 1245 1308 1276 1334 1354 1322 1414 1476 1508 1500 1510 1531 1633 1579 1490 1606 1627 1563 1585 1511 1533 1511 1443 1445 1419 1437 1356 1377 1354 1367 1335 1317 1294 1344 1354 1363 1328 1321 1333 1296 1244 1228 1222 1326 1223 1126 1180 1147 1165 1142 1152 1118 1077 1082 1070 1041 1050 1047 1031 1015 1044 1098 1044 1047 1032 1064 1067 1115 1010 1030 1102 1063 1099 1097 1152 1080 1090 1154 1134 1068 1179 1143 1153 1161 1142 1192 1150 1136 1115 1181 1168 1148 1140 1160 1137 1121 1126 1090 1104 1107 1140 1091 1093 1081 1123 1021 1071 1014 1094 1046 1055 1072 1063 1073 1094 1026 1076 1023 967 1008 1033 954 996 980 978 981 879 947 1020 907 1041 991 944 975 1011 1026 966 926 965 953 934 998 919 1017 987 954 1012 1003 1021 989 993 994 1032 1011 992 1014 1034 1026 954 995 969 1132 963 1024 1060 1077 1079 1037 1049 1054 1052 1008 1036 1040 1058 1041 1020 1008 1028 1059 1113 1012 1049 1092 1034 995 1092 1007 1084 1090 1076 1071 1071 1052 1008 988 1018 1058 999 968 1009 979 978 1020 974 955 993 958 1032 1016 958 979 1045 985 995 1026 994 1004 1076 1013 1019 1036 998 1049 1056 1025 1086 1062 1069 1112 1064 1165 1153 1103 1136 1139 1181 1134 1147 1103 1151 1137 1205 1211 1152 1201 1178 1208 1305 1267 1291 1330 1329 1445 1402 1452 1474 1445 1535 1513 1534 1505 1438 1476 1512 1449 1389 1342 1364 1331 1297 1328 1402 1321 1231 1280 1218 1278 1286 1262 1239 1241 1326 1295 1270 1268 1260 1179 1189 1203 1190 1122 1141 1107 1159 1077 1118 1095 1082 1074 1034 1092 1032 1082 1084 1041 1158 1114 1076 1101 1105 1081 1127 1060 1065 1118 1068 1091 1122 1143 1164 1066 1138 1105 1119 1072 1089 1124 1134 1120 1081 1145 1114 1111 1155 1134 1133 1158 1149 1202 1259 1272 1161 1243 1253 1287 1297 1263 1327 1368 1386 1356 1440 1375 1502 1396 1403 1396 1494 1426 1428 1392 1467 1421 1328 1369 1433 1371 1378 1311 1375 1382 1318 1323 1387 1425 1418 1357 1353 1429 1331 1366 1332 1334 1312 1333 1322 1436 1316 1383 1356 1400 1413 1434 1412 1358 1432 1519 1499 1557 1539 1572 1561 1513 1557 1583 1469 1526 1529 1480 1377 1495 1414 1410 1357 1468 1450 1435 1395 1523 1461 1488 1493 1559 1509 1483 1543 1478 1568 1471 1503 1401 1470 1421 1430 1367 1352 1380 1319 1320 1345 1349 1316 1297 1399 1357 1301 1331 1458 1361 1412 1433 1326 1365 1333 1432 1438 1466 1362 1349 1354 1388 1399 1368 1491 1375 1470 1459 1417 1488 1455 1594 1544 1546 1646 1623 1586 1626 1621 1583 1606 1668 1661 1599 1654 1619 1575 1577 1550 1490 1531 1637 1573 1538 1553 1608 1606 1623 1634 1623 1663 1712 1625 1594 1658 1577 1591 1542 1562 1569 1479 1511 1485 1447 1386 1392 1363 1380 1407 1378 1340 1346 1426 1363 1270 1393 1296 1257 1222 1267 1328 1220 1295 1226 1197 1142 1233 1175 1200 1160 1154 1176 1142 1155 1101 1232 1143 1143 1113 1138 1211 1098 1142 1120 1161 1184 1214 1145 1211 1201 1196 1266 1255 1295 1305 1362 1277 1387 1362 1429 1495 1419 1488 1394 1442 1430 1333 1327 1312 1281 1388 1290 1273 1203 1264 1233 1253 1246 1235 1261 1242 1184 1232 1327 1318 1190 1241 1200 1167 1134 1186 1091 1210 1179 1108 1089 1160 1071 1107 1066 1037 1055 1019 1050 1006 1000 1034 1007 1044 981 973 955 974 928 973 984 969 976 987 880 916 949 974 1022 991 940 955 963 1000 934 960 1014 1027 960 940 1008 1007 991 991 927 956 964 1016 994 1022 957 1034 990 995 1010 1062 1058 1053 1081 1123 1062 1087 1077 1017 1146 1093 1113 1088 1149 1149 1156 1165 1216 1147 1104 1159 1165 1194 1151 1180 1217 1163 1175 1189 1192 1130 1169 1166 1053 1127 1114 1053 1180 1094 1083 1051 1075 1096 1140 1180 1060 1109 1062 1140 1066 1014 1020 1056 1058 939 1040 1050 986 1053 984 991 957 1018 981 961 942 940 957 994 933 926 983 951 936 888 923 940 862 889 918 950 850 951 980 963 916 950 947 975 970 959 932 937 936 976 916 937 993 969 1009 940 913 953 1007 973 895 954 990 945 1006 941 995 1022 973 1017 963 1028 1071 1046 1059 1128 1106 1115 1067 1065 1046 1063 1034 1055 1096 1101 1098 1113 1161 1096 1079 1139 1179 1184 1201 1287 1271 1310 1292 1381 1343 1311 1316 1404 1339 1316 1331 1329 1284 1313 1262 1323 1263 1254 1287 1295 1347 1236 1262 1153 1261 1206 1264 1244 1302 1226 1249 1267 1257 1180 1175 1224 1201 1231 1179 1207 1219 1233 1150 1152 1197 1236 1209 1159 1273 1196 1182 1152 1274 1171 1171 1223 1227 1247 1242 1213 1312 1256 1330 1348 1318 1342 1387 1406 1458 1434 1415 1495 1456 1474 1543 1514 1479 1445 1527 1404 1509 1509 1576 1532 1475 1475 1483 1538 1430 1579 1446 1483 1501 1565 1494 1520 1526 1567 1534 1621 1571 1569 1716 1635 1715 1659 1629 1691 1621 1653 1629 1639 1625 1638 1624 1590 1555 1591 1556 1591 1465 1492 1423 1467 1447 1378 1402 1351 1403 1368 1406 1369 1429 1364 1364 1345 1321 1303 1340 1362 1332 1311 1248 1285 1279 1185 1227 1294 1261 1220 1191 1211 1191 1217 1174 1188 1192 1204 1229 1203 1095 1150 1181 1230 1082 1098 1206 1153 1134 1197 1139 1186 1215 1245 1252 1238 1249 1230 1267 1245 1223 1285 1282 1321 1288 1291 1313 1312 1269 1294 1315 1294 1313 1373 1360 1307 1268 1347 1323 1320 1294 1365 1368 1317 1322 1330 1341 1427 1392 1488 1435 1508 1446 1441 1539 1515 1442 1554 1537 1554 1531 1561 1504 1523 1537 1487 1612 1546 1452 1541 1445 1491 1492 1470 1412 1492 1433 1408 1523 1442 1380 1380 1496 1398 1477 1377 1470 1286 1448 1440 1434 1376 1316 1337 1397 1325 1335 1318 1253 1225 1305 1239 1202 1214 1280 1260 1190 1215 1117 1147 1189 1215 1115 1185 1188 1197 1140 1126 1164 1200 1137 1106 1206 1148 1199 1178 1211 1175 1198 1159 1178 1135 1246 1225 1182 1214 1163 1214 1241 1199 1302 1203 1233 1321 1296 1262 1203 1242 1292 1254 1254 1287 1264 1231 1204 1224 1126 1227 1305 1221 1157 1176 1189 1241 1245 1193 1196 1274 1229 1219 1232 1230 1176 1245 1207 1211 1138 1224 1157 1223 1196 1100 1088 1191 1165 1115 1095 1105 1161 1173 1173 1181 1136 1191 1164 1141 1085 1159 1139 1142 1126 1149 1144 1117 1213 1217 1170 1187 1239 1156 1241 1250 1187 1201 1137 1201 1156 1181 1158 1266 1169 1208 1142 1101 1163 1127 1154 1122 1101 1143 1122 1099 1110 1122 1039 1000 1042 1055 1018 985 1057 1030 1038 1048 1064 1011 1026 959 998 1004 998 1040 1066 1049 1024 928 1024 1032 1025 987 948 925 1006 972 1029 1018 1017 958 1037 1006 1002 984 968 982 1018 1022 980 989 956 965 949 971 949 933 950 958 932 955 969 986 1000 981 939 991 961 958 949 995 912 958 978 966 1055 929 911 964 941 967 939 1004 907 953 954 962 963 1008 991 914 959 993 965 1007 1050 975 991 1025 1007 982 999 962 966 976 1001 975 992 942 972 1015 992 985 977 959 995 973 985 971 1022 1008 938 995 1040 991 968 1037 1004 992 1024 1012 957 1037 1013 1074 996 1044 1047 1013 1003 1018 1044 1006 1027 1011 972 990 954 1010 965 1042 1003 1058 1017 997 1000 1001 1129 1051 994 1011 1041 1000 1061 997 1010 1049 1084 1000 1074 1036 1097 1014 1032 1095 1077 1069 1069 1053 1070 1108 1028 1077 1145 1093 1157 1143 1120 1130 1180 1110 1246 1148 1233 1174 1246 1220 1293 1226 1274 1296 1321 1344 1293 1337 1388 1345 1382 1382 1357 1451 1380 1375 1412 1386 1423 1399 1337 1313 1410 1397 1300 1333 1424 1362 1333 1300 1409 1315 1333 1405 1378 1329 1361 1373 1309 1383 1378 1416 1440 1369 1408 1339 1301 1292 1298 1305 1265 1244 1286 1243 1280 1172 1272 1228 1227 1126 1145 1212 1186 1156 1188 1131 1227 1175 1153 1199 1215 1212 1227 1215 1167 1172 1169 1185 1115 1148 1104 1208 1132 1163 1133 1221 1084 1155 1213 1164 1223 1201 1224 1275 1219 1272 1325 1311 1313 1334 1292 1358 1391 1399 1348 1407 1357 1413 1401 1330 1405 1422 1256 1358 1340 1364 1298 1341 1397 1367 1369 1528 1403 1443 1428 1438 1472 1516 1473 1546 1519 1547 1596 1593 1533 1582 1577 1610 1598 1675 1644 1636 1636 1596 1682 1609 1621 1621 1614 1612 1596 1561 1539 1615 1610 1463 1583 1560 1518 1621 1610 1521 1706 1578 1508 1552 1500 1471 1571 1585 1540 1525 1575 1558 1585 1558 1609 1539 1523 1518 1552 1428 1448 1440 1470 1404 1414 1427 1411 1423 1396 1412 1326 1465 1402 1470 1418 1375 1398 1365 1376 1394 1416 1356 1380 1375 1422 1425 1427 1433 1450 1453 1443 1438 1508 1463 1500 1448 1466 1508 1544 1532 1469 1602 1520 1533 1562 1463 1612 1458 1564 1479 1562 1525 1608 1561 1540 1472 1501 1431 1498 1471 1493 1472 1455 1454 1469 1506 1501 1476 1495 1471 1483 1595 1523 1479 1495 1579 1571 1590 1617 1730 1674 1679 1660 1766 1688 1665 1713 1711 1683 1601 1710 1711 1782 1677 1620 1563 1636 1623 1631 1631 1644 1536 1560 1658 1537 1595 1637 1607 1645 1641 1594 1586 1620 1700 1581 1635 1594 1705 1743 1722 1700 1678 1719 1593 1651 1654 1727 1672 1740 1609 1651 1591 1581 1582 1502 1523 1458 1495 1445 1442 1392 1289 1359 1317 1282 1344 1349 1312 1320 1251 1348 1264 1260 1341 1289 1307 1323 1239 1301 1232 1288 1255 1266 1189 1250 1213 1246 1258 1135 1263 1202 1192 1226 1197 1194 1120 1174 1156 1204 1126 1172 1128 1111 1070 1080 1109 1173 1137 1127 1172 1089 1122 1174 1083 1172 1175 1062 1147 1114 1138 1125 1141 1197 1192 1176 1168 1185 1225 1293 1254 1253 1291 1273 1331 1282 1290 1447 1363 1440 1393 1433 1474 1458 1444 1372 1485 1456 1372 1448 1400 1395 1341 1379 1403 1438 1317 1359 1379 1359 1363 1323 1360 1409 1392 1352 1362 1423 1416 1324 1337 1457 1409 1387 1465 1449 1458 1408 1402 1436 1361 1344 1480 1408 1368 1389 1318 1410 1343 1332 1321 1337 1303 1308 1314 1277 1380 1406 1410 1376 1363 1398 1429 1423 1494 1469 1392 1419 1560 1417 1466 1457 1469 1430 1392 1402 1366 1446 1401 1422 1390 1334 1333 1349 1397 1376 1302 1229 1347 1323 1344 1333 1297 1275 1312 1291 1366 1320 1355 1352 1339 1278 1371 1325 1343 1312 1384 1321 1354 1338 1406 1341 1419 1429 1369 1507 1444 1416 1391 1489 1421 1471 1547 1492 1446 1502 1605</counts>
			</dataPoints>
		</scan>
	</xrdMeasurement>
</xrdMeasurements>