File: dataset/precursor_mixture/NaHCO3_Cr2O3_Y2O3.12-min.xrdml
<?xml version="1.0"?>
<xrdMeasurements xmlns="http://www.xrdml.com/XRDMeasurement/2.2" xmlns:xsi="http://www.w3.org/2001/XMLSchema-instance" xsi:schemaLocation="http://www.xrdml.com/XRDMeasurement/2.2 http://www.xrdml.com/XRDMeasurement/2.2/XRDMeasurement.xsd" status="Completed" recordIdentifier="{56DA3E66-A052-419D-8A25-2C2F6FBEE974}">
	<comment>
		<entry/>
	</comment>
	<sample type="To be analyzed">
		<id></id>
		<name></name>
		<preparedBy></preparedBy>
	</sample>
	<xrdMeasurement measurementType="Scan" status="Completed" sampleMode="Reflection">
		<usedWavelength intended="K-Alpha 1">
			<kAlpha1 unit="Angstrom">1.5405980</kAlpha1>
			<kAlpha2 unit="Angstrom">1.5444260</kAlpha2>
			<kBeta unit="Angstrom">1.3922500</kBeta>
			<ratioKAlpha2KAlpha1>0.5000</ratioKAlpha2KAlpha1>
		</usedWavelength>
		<incidentBeamPath>
			<radius unit="mm">145.00</radius>
			<xRayTube id="1010048" name="Empyrean Cu LFF HR (9430 033 7310x) DK437873">
				<tension unit="kV">40.0</tension>
				<current unit="mA">15.0</current>
				<anodeMaterial>Cu</anodeMaterial>
				<focus type="Line">
					<length unit="mm">12.0</length>
					<width unit="mm">0.4</width>
					<takeOffAngle unit="deg">6.0</takeOffAngle>
				</focus>
			</xRayTube>
			<filter id="20010004" name="Beta-filter Nickel">
				<material>Ni</material>
				<thickness unit="mm">0.020</thickness>
			</filter>
			<sollerSlit id="21010002" name="Soller slits 0.04 rad.">
				<opening unit="rad">0.0400</opening>
			</sollerSlit>
			<mask id="22031000" name="Fixed mask 13 mm">
				<width unit="mm">9.00</width>
			</mask>
			<divergenceSlit id="22120001" name="Divergence slit 1°" xsi:type="fixedDivergenceSlitType">
				<distanceToSample unit="mm">50.00</distanceToSample>
				<height unit="mm">1.52</height>
			</divergenceSlit>
		</incidentBeamPath>
		<beamKnife id="29030100" name="Beam knife low"/>
		<sampleMovement xsi:type="spinningSampleMovementType">
			<spinnerRevolutionTime unit="seconds">1.0</spinnerRevolutionTime>
		</sampleMovement>
		<diffractedBeamPath>
			<radius unit="mm">145.00</radius>
			<antiScatterSlit id="22090040" name="AS slit 9 mm" xsi:type="fixedAntiScatterSlitType">
				<height unit="mm">9.00</height>
			</antiScatterSlit>
			<sollerSlit id="21020003" name="Large Soller slits 0.04 rad.">
				<opening unit="rad">0.0400</opening>
			</sollerSlit>
			<filter id="20030001" name="Large beta-filter Nickel">
				<material>Ni</material>
				<thickness unit="mm">0.020</thickness>
			</filter>
			<detector id="7010019" name="PIXcel1D-Medipix3 detector" xsi:type="rtmsDetectorType">
				<phd unit="keV">
					<lowerLevel>4.0</lowerLevel>
					<upperLevel>11.3</upperLevel>
				</phd>
				<mode>Scanning</mode>
				<activeLength unit="deg">5.020</activeLength>
			</detector>
		</diffractedBeamPath>
		<scan appendNumber="0" mode="Continuous" scanAxis="Gonio" status="Completed">
			<header>
				<startTimeStamp>2024-03-22T22:21:38-07:00</startTimeStamp>
				<endTimeStamp>2024-03-22T22:34:06-07:00</endTimeStamp>
				<author>
					<name>Instrument</name>
				</author>
				<source>
					<applicationSoftware version="1.6 (94)">PANalytical Aeris Instrument Suite</applicationSoftware>
					<instrumentControlSoftware version="3.0.0 20211014">AERIS</instrumentControlSoftware>
					<instrumentID>2879380</instrumentID>
				</source>
			</header>
			<dataPoints>
				<positions axis="2Theta" unit="deg">
					<startPosition>9.99043322</startPosition>
					<endPosition>100.09495370</endPosition>
				</positions>
				<positions axis="Omega" unit="deg">
					<startPosition>4.99521661</startPosition>
					<endPosition>50.04747685</endPosition>
				</positions>
				<commonCountingTime unit="seconds">18.249</commonCountingTime>
				<counts unit="counts">4458 4454 4484 4306 4381 4326 4252 4434 4346 4321 4410 4320 4220 4430 4282 4383 4354 4302 4318 4277 4246 4343 4300 4256 4414 4274 4313 4317 4359 4397 4317 4265 4209 4260 4225 4241 4248 4205 4153 4280 4220 4202 4153 4205 4234 4286 4226 4268 4200 4140 4187 4274 4197 4156 4135 4230 4095 4102 4051 4292 4135 4185 4053 3930 4119 4113 4123 4055 4081 4125 4248 4039 4058 4096 4065 4016 4142 4181 4012 4084 4073 4071 4003 4072 3995 4138 4095 4083 4100 4026 3952 4089 3976 3868 3990 3958 4095 4087 4156 3977 3931 3940 4014 4090 4090 4038 4015 3995 3847 3927 4032 3899 3929 4042 3844 3971 3845 3862 3851 3889 3928 3898 3852 3875 3935 3773 3732 3889 3854 3965 3816 3870 3856 3779 3833 3961 3904 3873 3918 3823 3768 3883 3888 3734 3805 3967 3857 3804 3834 3823 3820 3725 3841 3754 3754 3815 3776 3899 3841 3779 3781 3804 3730 3722 3904 3658 3719 3702 3710 3600 3733 3652 3689 3810 3763 3810 3672 3761 3661 3757 3684 3578 3617 3721 3714 3699 3880 3550 3728 3670 3717 3678 3748 3760 3729 3680 3700 3677 3667 3785 3631 3716 3622 3634 3574 3639 3700 3626 3673 3542 3620 3606 3703 3657 3481 3689 3706 3612 3762 3647 3581 3644 3580 3563 3505 3534 3572 3596 3596 3613 3614 3549 3573 3538 3569 3523 3541 3583 3631 3620 3577 3631 3626 3646 3553 3613 3443 3456 3559 3423 3464 3608 3585 3524 3574 3505 3461 3580 3482 3467 3574 3465 3479 3481 3527 3488 3613 3512 3555 3517 3371 3522 3511 3520 3503 3428 3552 3432 3443 3451 3497 3382 3482 3496 3527 3365 3432 3493 3397 3423 3385 3482 3482 3380 3393 3520 3320 3501 3417 3365 3381 3454 3517 3396 3466 3360 3421 3494 3273 3374 3437 3466 3361 3419 3424 3421 3423 3265 3364 3259 3348 3348 3386 3285 3417 3450 3357 3255 3394 3361 3518 3322 3263 3511 3315 3428 3383 3383 3390 3489 3415 3426 3317 3276 3351 3299 3421 3452 3458 3432 3403 3541 3386 3426 3313 3343 3464 3413 3305 3390 3375 3489 3324 3413 3335 3377 3323 3335 3449 3442 3424 3389 3284 3372 3390 3367 3332 3366 3345 3347 3264 3267 3337 3323 3393 3334 3380 3378 3379 3378 3386 3364 3317 3335 3393 3479 3248 3427 3312 3184 3326 3307 3315 3285 3348 3283 3336 3261 3325 3331 3226 3239 3276 3307 3326 3283 3314 3338 3389 3268 3277 3310 3241 3272 3270 3261 3232 3326 3349 3265 3326 3336 3416 3386 3150 3296 3283 3365 3269 3266 3346 3276 3325 3270 3272 3194 3307 3152 3312 3274 3391 3347 3403 3376 3428 3389 3289 3438 3384 3434 3389 3354 3545 3458 3342 3405 3338 3170 3260 3420 3264 3363 3290 3272 3221 3254 3158 3296 3292 3242 3276 3251 3226 3231 3255 3301 3379 3195 3249 3193 3373 3338 3272 3195 3265 3182 3217 3172 3218 3314 3170 3137 3281 3088 3101 3263 3242 3229 3153 3209 3238 3216 3178 3286 3224 3170 3191 3259 3148 3160 3201 3249 3188 3165 3154 3138 3265 3290 3306 3126 3167 3178 3260 3198 3254 3198 3260 3197 3254 3213 3317 3226 3294 3282 3172 3146 3275 3202 3294 3119 3210 3346 3252 3265 3203 3136 3167 3247 3241 3230 3279 3266 3217 3215 3147 3146 3221 3173 3296 3172 3322 3121 3260 3150 3293 3160 3194 3094 3253 3324 3251 3202 3212 3194 3122 3195 3280 3064 3204 3228 3187 3236 3115 3159 3277 3183 3213 3188 3194 3306 3187 3236 3227 3186 3280 3233 3227 3205 3180 3267 3262 3281 3262 3219 3158 3339 3272 3223 3297 3214 3141 3242 3241 3168 3215 3193 3378 3184 3130 3141 3168 3276 3218 3152 3060 3117 3272 3209 3142 3232 3196 3177 3292 3258 3141 3242 3153 3217 3245 3054 3169 3193 3063 3158 3159 3128 3173 3209 3251 3063 3147 3114 3191 3144 3261 3184 3299 3169 3181 3258 3095 3137 3101 3169 3186 3218 3191 3207 3104 3129 3143 3168 3095 3199 3071 3146 3213 3149 3230 3049 3209 3091 3191 3140 3123 3163 3104 3221 3030 3117 3152 3092 3075 3075 3072 3095 3078 3149 3165 3137 3154 3083 3124 3134 3034 3179 3020 3045 3087 3067 3144 2986 3136 3122 3061 3170 3169 3044 3086 3099 3071 3125 3133 3129 3147 3080 3120 3105 3174 3048 3046 3212 3104 3289 3184 3110 3206 3176 3281 3248 3313 3231 3296 3398 3351 3537 3600 3655 3712 3855 4023 4228 4306 4734 5041 5429 5673 6249 6893 7021 6657 6151 5697 5389 4929 4423 3956 3605 3519 3363 3289 3224 3157 3223 3110 3162 3120 3122 3173 3195 3106 3104 3149 3047 3082 3029 3077 3024 3136 3032 3087 3114 2990 2943 2895 2946 3060 3077 3200 3069 3094 3104 3049 2977 2983 3004 2921 2928 3087 3057 3065 2960 2992 3015 3117 3021 3045 3028 3007 3115 2947 3076 2975 3066 2909 3037 3063 2973 3012 2891 2990 3073 2935 3020 2963 2989 2960 2942 3045 2934 3046 3007 3003 3107 3152 2913 3017 3033 2908 3043 2954 3098 3011 2943 2934 2934 3038 2973 3146 3072 2886 2959 2984 3038 3012 3070 3073 3044 3033 3021 2934 3036 3059 2989 3005 3085 2996 2901 3015 2969 3097 2918 2970 2918 3036 2940 2898 2972 3046 2923 2912 3051 3098 3034 2945 3087 2862 2964 2954 2927 2986 2914 2916 2896 3008 2928 3057 2919 3149 3001 3090 3090 3064 2988 3101 3028 3111 3106 3054 3133 3110 3025 2968 3092 3147 3205 3125 3303 3206 3117 3151 3196 3282 3381 3462 3294 3392 3373 3431 3515 3549 3680 3811 3956 4224 4171 4340 4545 4712 4867 5048 5204 5531 5662 5987 6322 6321 6492 6604 6516 6478 6279 6085 6133 5663 5275 5018 4731 4301 4056 3740 3723 3705 3486 3255 3126 3257 3222 3219 3232 3206 3109 3028 2983 3017 3015 3024 3067 3047 2966 3002 2929 2975 2976 2851 2867 2928 2928 2944 2903 2812 3001 2911 2939 2911 2775 2890 2930 2849 2956 2949 2910 2997 2834 2820 2881 2748 2821 2805 2801 2860 2876 2791 2858 2890 2792 2845 2919 2874 2873 2881 2936 2873 2822 2826 2889 2851 2889 2836 2738 2847 2843 2799 2869 2775 2814 2854 2948 2782 2761 2802 2814 2778 2732 2867 2938 2722 2829 2759 2928 2829 2858 2840 2824 2704 2793 2692 2761 2750 2785 2963 2835 2872 2772 2807 2683 2861 2843 2967 2915 2808 2853 2813 2888 2774 2925 2802 2849 2768 2846 2769 2842 2774 2857 2832 2804 2804 2757 2873 2764 2829 2791 2880 2815 2754 2784 2801 2810 2701 2721 2697 2789 2651 2757 2663 2772 2722 2737 2767 2769 2800 2716 2848 2771 2754 2596 2841 2732 2759 2858 2786 2788 2769 2754 2812 2706 2704 2725 2800 2719 2785 2750 2776 2681 2760 2775 2661 2766 2823 2695 2702 2772 2698 2751 2743 2767 2815 2705 2728 2722 2745 2832 2730 2776 2739 2735 2667 2668 2685 2673 2778 2750 2683 2691 2866 2750 2677 2724 2721 2740 2759 2710 2750 2775 2799 2845 2719 2747 2719 2742 2711 2596 2804 2685 2717 2674 2693 2837 2659 2729 2728 2614 2666 2786 2607 2772 2754 2730 2796 2824 2687 2679 2750 2720 2715 2705 2618 2739 2694 2640 2755 2706 2695 2685 2758 2678 2682 2693 2766 2737 2742 2666 2676 2674 2780 2726 2673 2751 2731 2716 2743 2681 2794 2828 2756 2833 2737 2747 2756 2892 2876 2914 2831 2916 2796 3001 3079 3061 3084 3186 3303 3362 3435 3630 3655 3830 3772 3770 3771 3596 3511 3459 3418 3358 3193 3108 3063 2911 3000 2917 2811 2860 2894 2725 2760 2803 2758 2764 2878 2832 2876 2762 2843 2769 2827 2902 2883 2881 2745 2881 2864 2961 3002 3059 3127 3154 3150 3356 3355 3465 3656 3682 3919 3985 4382 4520 4799 4968 5540 5824 6364 6627 7284 7739 8191 8567 8869 9251 9263 9100 8708 7988 7405 6595 6275 5516 5095 4583 4055 3732 3470 3331 3201 3081 2919 2881 2990 2895 2883 2862 2692 2769 2695 2781 2799 2803 2706 2782 2767 2677 2731 2800 2724 2686 2705 2637 2702 2692 2676 2523 2730 2648 2656 2523 2661 2560 2631 2646 2648 2592 2724 2575 2617 2579 2616 2685 2745 2721 2794 2715 2633 2730 2635 2784 2612 2678 2599 2726 2664 2767 2776 2763 2703 2705 2679 2725 2724 2820 2833 2891 2891 2924 3023 3133 3190 3351 3297 3354 3626 3908 3951 4256 4284 4573 4571 4832 4813 4785 4684 4344 4352 3998 3868 3576 3379 3279 3122 2981 2867 2855 2760 2779 2656 2715 2713 2813 2809 2708 2630 2699 2625 2662 2556 2628 2557 2561 2569 2658 2674 2572 2597 2612 2532 2605 2503 2593 2668 2557 2655 2535 2625 2558 2639 2614 2561 2670 2678 2634 2549 2642 2557 2609 2705 2668 2679 2677 2662 2578 2716 2726 2598 2784 2589 2645 2610 2557 2576 2587 2577 2675 2648 2567 2606 2515 2529 2440 2504 2589 2652 2531 2614 2554 2622 2530 2566 2515 2486 2566 2567 2512 2571 2529 2574 2415 2470 2495 2529 2565 2591 2554 2577 2502 2499 2535 2571 2435 2623 2596 2533 2618 2574 2581 2527 2498 2495 2473 2474 2513 2565 2490 2330 2513 2576 2565 2522 2544 2500 2476 2524 2457 2546 2434 2506 2427 2546 2566 2565 2569 2544 2449 2526 2534 2592 2581 2588 2489 2632 2507 2609 2566 2511 2572 2525 2581 2613 2506 2603 2622 2554 2609 2535 2574 2470 2554 2500 2527 2498 2616 2535 2447 2531 2623 2603 2513 2519 2538 2553 2558 2585 2704 2521 2630 2561 2628 2501 2541 2562 2593 2554 2594 2552 2631 2547 2598 2516 2523 2605 2558 2501 2501 2529 2563 2542 2531 2561 2537 2539 2492 2447 2496 2542 2544 2560 2495 2580 2565 2617 2638 2586 2520 2468 2592 2592 2590 2568 2579 2604 2672 2549 2657 2685 2707 2713 2652 2604 2704 2636 2719 2733 2839 2629 2715 2799 2733 2719 2750 2729 2778 2791 2818 2785 2732 2763 2730 2827 2682 2813 2849 2769 2798 2791 2737 2940 2728 2902 2885 2832 2962 2906 2879 2904 2899 3087 3055 3095 3023 3135 3152 3270 3235 3285 3291 3365 3327 3520 3507 3533 3601 3612 3748 3860 3929 4056 4211 4256 4456 4675 4953 5346 5478 5951 6316 6912 7524 8281 8945 9650 10741 11467 11942 12798 13919 14831 15705 17180 18883 20792 22540 24734 26746 29494 31172 34022 35771 36850 37469 37110 35824 33953 31207 28904 26555 23838 22137 19331 16952 14673 12697 11172 9656 8368 7550 6987 6338 5829 5433 5243 4858 4710 4498 4450 4159 4131 4050 4023 3784 3830 3585 3651 3537 3598 3409 3374 3389 3319 3317 3223 3158 3115 3136 3087 3045 3058 3002 2978 2943 2914 2826 2992 2847 2932 2765 2900 2735 2882 2834 2831 2774 2825 2863 2851 2852 2812 2829 2809 2765 2679 2834 2852 2946 2967 2999 2967 3085 3164 3089 3234 3221 3438 3510 3717 3789 4122 4178 4555 4697 5134 5277 5537 5717 6155 6141 6590 6687 6746 6758 6483 6296 6000 5932 5896 6107 6034 6181 6208 6314 6756 7278 7654 8344 8674 9089 9264 9642 9336 8918 8279 7606 7173 6799 6319 5891 5346 4854 4338 3946 3693 3321 3290 3035 2917 2897 2921 2781 2809 2735 2672 2818 2748 2712 2682 2619 2703 2680 2643 2548 2692 2585 2558 2533 2628 2521 2588 2530 2550 2435 2603 2416 2521 2535 2472 2421 2493 2398 2556 2416 2473 2468 2520 2554 2457 2480 2484 2537 2525 2591 2485 2383 2498 2378 2399 2469 2540 2404 2469 2457 2482 2408 2400 2333 2447 2414 2355 2452 2400 2547 2504 2518 2466 2434 2365 2380 2513 2507 2466 2416 2495 2551 2524 2577 2483 2548 2494 2552 2458 2520 2588 2433 2564 2425 2503 2484 2512 2528 2437 2470 2508 2450 2409 2454 2475 2426 2408 2403 2480 2429 2356 2404 2394 2384 2467 2434 2456 2423 2358 2402 2399 2413 2286 2403 2321 2365 2361 2340 2389 2344 2482 2290 2509 2482 2381 2365 2384 2381 2376 2370 2363 2532 2380 2369 2323 2394 2389 2419 2368 2383 2323 2378 2413 2466 2266 2402 2329 2422 2455 2407 2418 2451 2423 2359 2319 2399 2408 2321 2366 2246 2394 2333 2352 2425 2286 2337 2400 2424 2401 2411 2454 2388 2449 2403 2366 2405 2477 2323 2539 2422 2402 2366 2358 2481 2434 2485 2335 2326 2374 2323 2383 2376 2496 2538 2432 2437 2486 2395 2333 2379 2493 2438 2428 2494 2437 2469 2359 2469 2478 2504 2483 2374 2489 2514 2428 2385 2466 2451 2531 2460 2430 2562 2478 2428 2599 2553 2568 2561 2573 2575 2697 2573 2658 2620 2585 2664 2714 2702 2790 2792 2902 2948 2952 3041 2981 3084 3240 3336 3271 3556 3559 3711 3716 3876 4132 4497 4670 5057 5520 5922 6583 7368 8037 8857 9746 10502 11454 12046 12811 12899 13128 12795 12239 11689 11385 11307 11263 11239 11194 11144 11073 10904 11021 11064 10934 11092 10851 10463 10159 9474 8973 8403 7904 7499 7040 6621 5958 5433 5027 4594 4288 3839 3725 3465 3439 3373 3204 3131 3059 3019 2963 2869 2898 2911 2811 2847 2738 2692 2810 2704 2711 2778 2762 2661 2691 2831 2706 2750 2751 2839 2889 2990 2856 2940 3023 3106 3314 3442 3812 4000 4198 4687 5198 5670 6409 6893 7643 8422 9073 9385 9676 9457 8894 8422 7642 7127 6840 6563 6200 5935 5363 4768 4333 3769 3505 3202 3129 2877 2841 2660 2721 2601 2681 2564 2486 2565 2469 2572 2553 2395 2470 2397 2408 2420 2446 2419 2530 2362 2401 2361 2352 2380 2264 2314 2322 2337 2402 2349 2397 2340 2366 2398 2275 2252 2212 2365 2333 2249 2470 2305 2355 2276 2400 2307 2426 2336 2364 2334 2387 2280 2337 2288 2363 2322 2334 2306 2365 2442 2351 2360 2208 2329 2351 2316 2344 2337 2385 2292 2476 2333 2443 2305 2398 2379 2363 2395 2351 2335 2344 2312 2362 2340 2393 2404 2385 2416 2407 2478 2440 2396 2530 2539 2470 2551 2600 2686 2687 2652 2919 2816 2992 3087 3143 3314 3511 3541 3667 3801 3882 3953 3980 4031 4066 4013 4010 3966 3675 3820 3832 3815 3855 3777 3854 3864 3976 4282 4354 4905 5119 5360 5940 6686 7231 7831 8628 9168 9922 10097 10340 10102 9544 9114 8516 7991 7506 7233 6863 6497 6134 5452 4980 4461 4044 3577 3351 3082 3025 2951 2845 2764 2765 2591 2603 2475 2513 2482 2572 2436 2412 2378 2442 2341 2422 2412 2430 2353 2350 2368 2344 2278 2284 2362 2346 2349 2334 2272 2286 2283 2229 2228 2274 2215 2359 2234 2292 2222 2293 2302 2264 2285 2245 2276 2249 2195 2213 2208 2141 2182 2213 2243 2188 2194 2104 2299 2109 2316 2202 2232 2242 2210 2275 2301 2229 2300 2311 2325 2301 2200 2207 2297 2373 2423 2424 2503 2451 2649 2609 2763 2667 2809 2678 2671 2676 2552 2606 2504 2466 2491 2361 2375 2291 2388 2318 2348 2254 2237 2183 2316 2305 2171 2183 2247 2278 2244 2245 2190 2189 2254 2188 2160 2184 2171 2171 2211 2148 2187 2287 2180 2171 2256 2301 2310 2202 2262 2240 2338 2336 2303 2277 2400 2492 2353 2453 2504 2436 2553 2525 2548 2465 2441 2415 2389 2273 2365 2372 2332 2336 2233 2328 2263 2273 2262 2226 2154 2175 2124 2196 2213 2239 2173 2212 2211 2099 2194 2090 2099 2207 2162 2129 2124 2121 2110 2133 2132 2207 2162 2073 2171 2057 2083 2113 2000 2096 2108 2146 2134 2145 2162 2184 2138 2146 2129 2124 2166 2127 2147 2174 2164 2060 2154 2127 2146 2096 2055 2121 2147 2065 2128 2117 2096 2032 2198 2080 2188 2099 2192 2103 2128 2093 2113 2129 2153 2086 2183 2145 2052 2214 2268 2123 2229 2177 2217 2097 2238 2217 2157 2231 2293 2341 2320 2407 2357 2301 2277 2291 2247 2236 2227 2238 2301 2232 2269 2223 2190 2150 2249 2170 2110 2083 2209 2204 2179 2188 2149 2168 2140 2133 2140 2170 2196 2166 2113 2173 2083 2086 2175 2140 2192 2240 2235 2131 2245 2104 2140 2221 2316 2213 2224 2252 2334 2327 2371 2408 2439 2441 2398 2641 2682 2780 2796 2904 2975 3080 3446 3441 3642 3706 3852 4008 4091 4087 4276 4429 4368 4367 4125 3908 3918 3711 3637 3576 3485 3469 3220 3142 3050 2825 2793 2627 2583 2468 2476 2442 2290 2319 2321 2389 2353 2243 2245 2238 2179 2318 2298 2266 2306 2164 2128 2214 2145 2237 2158 2219 2189 2185 2184 2238 2076 2154 2191 2088 2254 2237 2280 2035 2203 2217 2177 2240 2167 2285 2191 2254 2312 2311 2243 2315 2332 2253 2399 2374 2452 2481 2630 2722 2718 2904 3078 3099 3464 3632 4105 4483 4920 5396 5693 5955 6068 5641 5430 4948 4752 4587 4436 4504 4361 4488 4110 4032 3654 3318 3237 2830 2741 2607 2492 2479 2358 2393 2285 2361 2304 2308 2300 2276 2218 2280 2167 2197 2148 2293 2253 2148 2177 2170 2207 2151 2242 2157 2203 2220 2210 2239 2242 2347 2352 2397 2379 2415 2519 2562 2626 2644 2775 2928 3062 3319 3585 3823 4039 4428 4529 4843 5045 4999 4772 4773 4482 4295 4170 3864 4032 3855 3753 3719 3662 3481 3343 3089 2994 2943 2827 2774 2635 2589 2503 2555 2432 2520 2333 2465 2400 2352 2358 2286 2313 2240 2237 2285 2240 2217 2056 2123 2107 2171 2160 2106 2119 2072 2057 2144 2162 2040 2109 2169 2065 2067 2102 2145 2182 2123 2176 2154 2098 2075 2035 2141 2077 2105 2067 2050 2031 2101 2034 2007 2065 2094 2069 2101 2121 2038 2004 2067 1979 2063 2152 1972 2074 2123 2133 2057 2058 2132 2109 2166 2079 2056 2003 2037 2095 2052 2059 2117 2129 2083 2037 2052 2106 2020 2087 2098 2036 2054 2028 2084 2088 2039 2029 2111 2077 2046 1967 1979 2103 1964 2080 2050 2151 2002 2105 2143 2162 2131 2093 2101 2136 2020 2138 2040 2052 2096 2102 2083 2092 2027 2099 2035 2103 2158 2170 2072 2203 2125 2139 2079 2135 2074 2141 2187 2214 2182 2160 2224 2228 2264 2202 2301 2236 2298 2355 2355 2447 2361 2535 2519 2643 2858 2966 3036 3267 3439 3490 3797 3951 4134 4279 4568 4488 4641 4429 4400 4102 4121 3997 3897 3723 3767 3593 3610 3463 3267 3108 2962 2785 2662 2543 2521 2406 2412 2439 2331 2289 2174 2237 2198 2227 2219 2173 2220 2125 2112 2229 2112 2144 2091 2124 2118 2053 2130 2226 2043 2126 2036 2153 2104 2180 2136 2153 2032 2182 2139 2252 2192 2151 2219 2268 2256 2236 2337 2455 2477 2472 2498 2488 2558 2538 2431 2412 2321 2392 2380 2354 2272 2326 2252 2367 2314 2324 2244 2169 2102 2257 2253 2206 2296 2278 2237 2296 2330 2292 2396 2470 2432 2526 2525 2606 2673 2819 2919 2970 2856 2699 2608 2524 2417 2413 2514 2395 2523 2454 2425 2440 2283 2298 2107 2142 2127 2126 2140 2114 2109 2066 2068 2007 2054 1984 2003 2039 2071 2068 2049 1984 2111 2015 1961 2094 1997 1983 2000 2026 2085 2062 2005 2057 2051 2063 2134 2050 1987 1969 1956 1970 2063 1995 2020 1964 2028 1963 1965 2015 1973 2017 2032 2036 1979 2108 1985 2052 2011 1998 2009 2065 1945 1961 1995 2042 1969 1998 1989 2027 2113 2018 2066 2023 2018 2035 2039 2009 2066 1989 2024 2087 1992 2114 2091 2125 2144 2185 2120 2113 1979 2069 2169 2161 2023 2127 2027 2109 1992 2056 2065 2018 2019 2022 2069 2168 2090 2081 2118 2091 2171 2111 2259 2237 2318 2316 2429 2510 2573 2815 2848 2840 2855 2850 2917 2741 2660 2656 2643 2653 2606 2650 2565 2594 2557 2575 2491 2397 2273 2347 2208 2178 2253 2214 2127 2205 2104 2069 2073 2024 2116 2055 1996 2021 2031 2040 2070 2024 1970 2023 1953 1942 1911 2049 2046 1967 2020 2011 1998 2016 1988 1957 2089 2055 2038 1945 2041 2061 2073 2112 2099 2062 2054 2128 2144 2167 2065 2201 2197 2239 2327 2313 2271 2446 2581 2553 2610 2631 2829 2821 2915 3017 2955 2946 2765 2858 2597 2686 2716 2689 2570 2583 2481 2504 2447 2506 2395 2323 2359 2248 2222 2248 2214 2246 2106 2142 2080 2215 2195 2159 2124 2174 2149 2131 2003 2080 2081 2088 2075 2129 2155 2015 2090 2029 2064 2023 2074 1972 1985 2075 2126 2042 2105 2030 2082 2187 2084 2144 2056 2075 2156 2150 2087 2191 2152 2144 2151 2152 2265 2234 2231 2290 2382 2300 2336 2450 2466 2469 2498 2516 2569 2448 2395 2366 2319 2389 2361 2409 2372 2373 2327 2426 2354 2344 2281 2259 2357 2286 2244 2306 2214 2243 2212 2218 2269 2296 2282 2395 2232 2288 2272 2348 2444 2282 2534 2424 2494 2444 2448 2407 2549 2606 2525 2680 2691 2665 2795 2771 2914 3092 3053 3323 3279 3548 3596 3759 3984 4302 4533 4997 5515 5983 6705 7618 8365 9283 10489 11512 12863 14020 14520 14869 14783 14486 13581 12621 11865 11302 10762 10240 10332 10075 9950 9669 9367 8838 8079 7220 6696 6074 5561 5340 4822 4591 4463 4182 4201 3821 3738 3545 3486 3282 3193 3217 3126 3125 3028 3051 2845 2847 2780 2767 2560 2508 2473 2529 2377 2391 2361 2366 2364 2217 2205 2199 2244 2236 2285 2267 2292 2248 2222 2189 2206 2144 2211 2094 2205 2055 2090 2228 2070 2193 2133 2105 2051 2067 2057 2137 2096 2070 2008 2170 2057 1991 2094 2134 2057 2117 2046 2071 2095 2024 1996 2125 2059 2010 2119 2119 2070 2142 2193 2073 2045 2057 2034 1997 2153 2091 2115 2089 2106 2111 2122 2173 2202 2233 2124 2224 2159 2115 2157 2161 2091 2133 2139 2196 2147 2207 2228 2203 2279 2180 2355 2277 2402 2334 2379 2419 2490 2544 2597 2672 2843 2819 2969 3177 3294 3598 3558 3791 4038 4218 4521 4792 5211 5585 5498 5734 5684 5440 5191 4797 4487 4312 4212 4078 4096 3891 4109 4143 3836 3794 3441 3271 3104 2902 2738 2622 2430 2500 2338 2306 2269 2296 2336 2151 2147 2179 2119 2075 2048 2052 1986 2021 2128 2119 2149 2084 2078 1988 2122 1997 1965 1965 2022 1853 1964 1928 1978 2037 2002 1960 1994 2005 2101 1992 1945 2025 2000 1985 1962 1943 1943 1925 2011 1966 1959 2049 1920 2016 1883 1993 2077 1988 2046 2028 2088 1932 2143 1975 1985 1973 2022 1896 2027 1980 1935 1955 1923 1972 1955 1966 1957 1987 1889 1939 2004 2048 1963 2056 1991 2033 1943 1976 1982 1957 1995 2040 1945 1884 2031 1993 1900 1958 2099 1979 1936 2126 2026 2065 2065 2085 2046 2024 2039 2023 2019 2054 2076 2053 2072 2138 2113 2007 2031 1998 2130 2036 1996 2003 2059 2015 2030 2001 2011 2093 1990 1947 1979 2072 1934 1919 1909 1925 2027 1978 1914 2008 1977 1881 2010 1984 1956 1968 1989 1908 1868 1980 1930 1973 1962 1987 1942 1978 1983 1963 1985 1950 1925 1990 1952 1907 1866 1980 1899 1929 1978 2011 1984 1906 1884 2000 1943 1922 1970 2031 1972 1946 2031 1979 1934 2105 2115 2129 2098 2157 2213 2203 2321 2305 2402 2345 2293 2291 2260 2327 2309 2332 2267 2288 2342 2392 2446 2422 2398 2578 2433 2432 2386 2436 2378 2217 2224 2221 2275 2237 2174 2294 2245 2239 2250 2249 2170 2165 2076 2089 2153 2069 2095 2213 2268 2156 2192 2193 2250 2120 2287 2301 2219 2420 2296 2368 2492 2584 2722 2803 2830 2909 3111 3254 3350 3397 3525 3395 3277 3314 2983 3023 2884 2819 2891 2703 2844 2772 2794 2812 2642 2644 2570 2483 2379 2350 2251 2176 2186 2182 2163 2255 2066 2078 2056 2007 2082 2036 2094 2054 1979 2056 2005 1966 1995 1993 1928 2009 2006 1965 1959 2050 2043 1959 1950 2068 1980 2039 1940 2012 1947 1923 2023 1869 1939 1949 2005 2024 2019 1967 1989 2016 1992 1978 2048 1996 1937 1920 1975 1900 1946 1946 2021 1965 2056 2073 1981 2030 2001 1966 1963 2100 2075 2007 1997 2064 2049 2068 2019 1998 1981 2035 2102 2101 2148 2012 2091 2094 2025 2105 2191 2231 2203 2098 2279 2160 2074 2144 2090 2243 2196 2202 2251 2239 2253 2165 2193 2282 2308 2315 2538 2420 2401 2420 2480 2523 2594 2630 2713 2820 2964 3091 3247 3437 3534 3671 3966 4207 4643 4976 5454 6238 6828 7601 8290 8957 9402 9575 9325 8778 8350 7645 6976 6507 6155 6140 5999 6119 6115 6351 6162 6120 5705 5528 5067 4556 4095 3764 3428 3292 2996 2995 2745 2719 2681 2465 2535 2485 2472 2451 2494 2389 2274 2382 2443 2357 2456 2281 2308 2202 2229 2236 2167 2126 2127 2172 2158 2172 2159 2147 2152 2184 2125 2130 2081 2169 2001 2080 1974 2002 2054 2059 2051 2013 2019 1979 2082 2090 2092 1956 2032 2021 2037 1964 2035 2054 2079 2032 2118 2042 2062 1982 2006 2019 2006 2009 2134 2039 2058 2134 2060 2012 2024 2012 2069 2038 2173 2051 2093 2059 2150 2203 2191 2218 2288 2233 2321 2407 2316 2385 2445 2649 2633 2868 2801 2907 3023 3153 3069 3077 3139 2912 2866 2817 2999 2680 2751 2682 2785 2571 2721 2670 2587 2661 2521 2559 2450 2462 2309 2245 2228 2266 2089 2012 2117 2021 2162 2091 2098 2161 2158 2089 2160 2069 2151 2037 2105 2208 2118 2081 2188 2048 2217 2088 2243 2279 2204 2134 2244 2178 2287 2237 2320 2320 2335 2277 2259 2279 2267 2381 2339 2339 2452 2485 2525 2715 2846 3067 3421 3833 4267 4936 6094 7077 8812 9735 11204 11734 10917 9912 8071 6850 5579 4878 4562 4597 4719 5114 5853 6245 6847 7100 6853 6253 5609 4805 4013 3479 3222 2969 2979 2765 2813 2803 2735 2736 2726 2672 2685 2717 2786 2862 2946 2981 3158 3155 3405 3541 3774 3881 4197 4561 4916 5399 5881 6470 7317 7950 8380 9098 9427 9825 9440 9037 8746 8125 7521 7009 6693 6361 6414 6266 6319 6470 6344 6411 6307 6166 5700 5231 4873 4528 4196 3790 3635 3416 3123 2991 2898 2819 2699 2647 2596 2548 2463 2520 2475 2449 2321 2294 2336 2278 2342 2276 2240 2204 2326 2205 2292 2275 2231 2228 2186 2212 2214 2340 2318 2225 2215 2228 2228 2318 2287 2322 2400 2335 2421 2415 2535 2519 2608 2575 2634 2566 2655 2653 2602 2574 2516 2470 2388 2450 2355 2312 2347 2459 2413 2406 2318 2326 2344 2338 2307 2178 2266 2208 2221 2177 2174 2081 2157 2080 2144 2065 2095 2170 2138 2124 2209 2184 2097 2163 2136 2165 2173 2171 2236 2333 2199 2317 2313 2419 2435 2564 2681 2821 2966 3098 3142 3421 3449 3589 3579 3627 3558 3327 3196 3116 2998 2922 2861 2860 2789 2821 2867 2938 2857 2862 2764 2834 2632 2557 2466 2451 2377 2290 2210 2129 2156 2081 2083 2105 2002 2135 2031 2041 2027 1980 2040 2021 1935 1969 2000 2010 2006 2007 2038 1920 1995 1912 1956 1959 1996 2050 1878 1926 2013 1893 1954 1959 2006 1892 1940 1961 1944 1959 1887 1927 1985 1961 2058 1968 2043 1973 2021 1997 1996 1948 1874 2011 1986 2001 2006 1989 2076 2068 2039 2168 2165 2194 2253 2209 2215 2203 2206 2218 2173 2210 2063 2122 2078 2070 2082 2093 2063 2144 2112 2127 2208 2163 2199 2089 2165 2147 2163 2172 2229 2263 2208 2300 2353 2307 2549 2622 2606 2749 2778 2935 3069 3237 3227 3344 3310 3196 3013 3018 2774 2836 2808 2738 2799 2950 2765 2739 2780 2760 2835 2742 2658 2537 2624 2684 2520 2476 2310 2438 2457 2443 2379 2388 2420 2475 2517 2554 2675 2712 2848 2960 2963 2971 2932 2847 2730 2676 2686 2569 2556 2502 2412 2432 2410 2462 2538 2490 2545 2505 2441 2498 2299 2381 2182 2101 2109 2155 2073 2070 2044 1947 1947 1988 2078 1963 1940 2010 1991 1991 1928 1951 1853 1917 1901 1941 1922 1951 1980 1917 1928 1816 1945 1955 1877 1956 1820 1949 1829 1953 1865 1985 1952 2006 1928 1902 1902 1946 1871 1935 1999 1902 1885 1903 1966 1958 1934 1995 2013 2009 1990 2074 2032 2161 2086 2267 2321 2308 2307 2406 2440 2340 2374 2428 2351 2412 2168 2242 2189 2128 2138 2172 2137 2131 2193 2086 2143 2241 2252 2168 2150 2087 2024 2054 2011 1900 1999 2009 2012 1881 1972 2009 1924 1841 1954 1886 2011 1940 1930 1941 1904 1871 1970 1951 1967 1883 1868 1892 1940 1885 1980 1885 1962 1918 1831 1838 1902 1908 1904 1926 1905 1849 1897 1800 1875 1872 1933 1869 1875 1933 1926 2009 1985 2003 1917 2042 1982 2002 1970 2059 2038 2121 1994 2075 1996 1999 1883 1983 1998 2036 1992 2114 2015 2014 2088 2008 2020 2055 1974 2079 2051 2064 2048 2046 2086 2093 2114 2136 2056 2104 2114 2156 2169 2133 2149 2164 2155 2156 2083 2205 2177 2314 2230 2335 2345 2320 2474 2328 2449 2513 2356 2464 2352 2328 2435 2378 2483 2503 2485 2476 2669 2801 2854 2806 2938 3039 3108 3217 3422 3743 3758 4065 4122 4188 4201 4139 4003 3699 3537 3439 3216 3221 3150 3110 3109 3061 3066 3220 3114 3151 3230 3040 2961 2902 2668 2616 2490 2352 2381 2330 2225 2220 2127 2091 2084 2034 1994 2038 2044 2018 2006 2056 1941 1949 1985 1942 1920 1991 1966 1972 1915 1936 1864 1977 1950 1898 1924 1892 1944 1906 1899 1977 1924 1915 1934 2030 1905 2042 1922 1952 1874 1898 1962 1965 1967 1934 1903 1972 1919 1937 1890 2026 1910 2001 2045 1976 2033 2079 2040 2044 2119 2182 2148 2221 2349 2390 2483 2507 2644 2659 2704 2826 2701 2607 2493 2538 2456 2484 2344 2419 2396 2340 2494 2355 2381 2398 2367 2512 2418 2437 2382 2330 2338 2271 2312 2169 2106 2147 2137 2077 2131 2176 2213 2127 2230 2240 2207 2242 2258 2325 2322 2456 2406 2608 2759 2851 2891 3098 3286 3576 3798 3837 4149 4262 4357 4512 4609 4442 4299 4035 3821 3496 3465 3287 3352 3227 3322 3394 3303 3450 3496 3429 3487 3393 3403 3232 3267 3081 2774 2768 2683 2697 2516 2408 2396 2258 2277 2257 2242 2174 2206 2126 2063 2142 2066 2076 2060 1978 2032 2088 2087 2001 2096 2050 2006 2029 2040 1947 2049 2019 2050 2023 2039 1913 2058 2124 2102 2085 2120 2138 2090 2173 2218 2251 2288 2238 2234 2158 2067 2106 2145 2136 2059 2134 1977 2098 2016 2046 2064 2078 2055 2036 2071 2008 2048 1960 1945 1937 1931 1881 1896 1897 1919 1898 1955 1892 1908 1915 1874 1851 1777 1897 1831 1843 1761 1925 1825 1894 1889 1753 1899 1836 1782 1824 1798 1843 1817 1860 1867 1731 1804 1808 1835 1801 1854 1883 1884 1780 1824 1849 1813 1775 1814 1849 1879 1823 1793 1857 1803 1839 1787 1787 1820 1884 1794 1830 1799 1893 1814 1870 1835 1824 1793 1832 1865 1869 1802 1837 1903 1882 1899 1801 1798 1763 1842 1775 1887 1828 1805 1886 1869 1842 1871 1834 1763 1846 1814 1881 1887 1767 1849 1873 1813 1761 1893 1845 1837 1833 1855 1771 1824 1799 1805 1780 1849 1814 1838 1801 1780 1786 1788 1795 1752 1814 1847 1797 1822 1829 1770 1824 1812 1848 1839 1899 1807 1876 1867 1811 1880 1837 1935 1872 1842 1810 1898 1733 1829 1798 1825 1800 1820 1867 1789 1813 1752 1851 1780 1792 1884 1856 1834 1778 1887 1799 1786 1877 1805 1798 1798 1925 1925 1844 1827 1799 1812 1850 1838 1840 1774 1816 1784 1859 1756 1917 1848 1792 1794 1785 1863 1798 1859 1880 1775 1857 1818 1798 1845 1886 1835 1906 1911 1746 1933 1856 1842 1787 1947 1778 1841 1871 1777 1821 1873 1842 1833 1877 1752 1831 1812 1796 1834 1850 1775 1852 1803 1864 1804 1781 1735 1813 1777 1817 1767 1746 1869 1775 1776 1834 1767 1845 1847 1830 1861 1854 1759 1832 1790 1830 1845 1708 1803 1781 1863 1805 1801 1821 1768 1732 1780 1802 1832 1860 1832 1856 1848 1878 1878 1795 1874 1876 1869 2032 1911 1992 1844 1836 1938 1873 1910 1935 1874 1888 1787 1921 1956 1954 1943 1912 1848 1933 1945 1862 1908 1899 2029 1930 2057 2049 2250 2043 2187 2223 2087 2231 2165 2221 2094 2123 2032 2073 2010 2046 2035 1973 2036 1948 2078 2031 2087 2085 2046 2086 2081 2068 2059 1969 1993 2062 2069 2017 1907 1987 1882 2053 2100 2068 2046 2065 2132 2267 2223 2291 2234 2320 2338 2361 2352 2347 2269 2221 2153 2098 2089 2109 2080 2158 2143 2282 2221 2200 2263 2359 2278 2223 2261 2208 2201 2117 2126 2063 2001 1986 1942 1986 1930 1965 1936 1904 1981 2037 2036 1922 1886 2063 1868 1936 1857 1823 1939 1878 1899 1830 1792 1857 1847 1851 1912 1778 1853 1851 1912 1931 1852 1789 1878 1808 1874 1932 1898 1810 1826 1835 1878 1873 1772 1867 1824 1932 1852 1830 1922 1875 1852 1826 1891 1873 1936 1953 1909 1854 1906 1919 1992 1862 1826 1865 1883 1933 1872 1896 1936 1981 2020 1965 1939 1925 1924 2021 2009 2009 2107 2102 2247 2196 2205 2328 2355 2472 2528 2686 2750 2844 2823 2754 2848 2683 2574 2589 2529 2416 2362 2328 2289 2307 2214 2313 2207 2332 2316 2320 2426 2397 2412 2333 2360 2229 2200 2044 2026 2081 1946 2041 2047 1982 1920 1862 1919 1867 1978 1852 1916 1916 1896 1857 1801 1795 1876 1863 1877 1802 1831 1842 1762 1879 1811 1766 1822 1840 1722 1755 1787 1938 1910 1854 1799 1845 1846 1758 1886 1743 1888 1783 1920 1869 1832 1816 1840 1852 1737 1953 1832 1771 1780 1875 1732 1760 1844 1802 1829 1868 1912 1935 1870 1947 1822 1893 1954 1839 1901 1943 1941 1860 1927 1924 1943 1937 1931 1955 2001 2046 2140 2196 2211 2357 2374 2492 2472 2638 2742 2698 2625 2643 2593 2488 2339 2419 2355 2234 2346 2188 2360 2268 2315 2224 2318 2289 2249 2375 2348 2313 2394 2263 2259 2224 2212 2146 2210 2078 2219 2132 2080 2106 2203 2040 2085 2056 2095 2148 2143 2174 2154 2219 2217 2247 2272 2242 2367 2380 2543 2603 2628 2797 2816 2869 2915 2877 2862 2806 2731 2671 2646 2577 2436 2525 2424 2441 2400 2370 2244 2243 2447 2441 2428 2560 2511 2471 2439 2404 2239 2263 2329 2206 2171 2170 2161 2091 2076 2154 2095 2195 2142 2181 2095 2155 2042 2114 2054 2086 2108 2099 2122 2009 1981 1952 2019 2010 2121 2121 2130 2106 2229 2381 2224 2351 2258 2253 2305 2277 2332 2182 2250 2149 2187 2144 2081 2078 1996 2114 2014 2064 2072 2057 2033 2031 1988 1961 1993 1960 2012 2017 2100 1870 1892 1851 1904 1823 1863 1894 1825 1785 1926 1791 1853 1773 1849 1898 1813 1774 1809 1832 1763 1782 1808 1731 1870 1855 1839 1843 1829 1770 1804 1805 1765 1804 1739 1781 1768 1755 1801 1858 1776 1877 1773 1877 1789 1796 1830 1877 1784 1790 1903 1867 1902 1816 1894 1789 1793 1872 1816 1850 1815 1880 1849 1865 1767 1807 1768 1905 1884 1918 1783 1904 1894 2047 1845 1889 1909 1888 1900 1982 1981 1975 2113 2025 2111 2156 2087 2164 2241 2298 2295 2249 2287 2248 2179 2197 2176 2149 2108 2089 2076 1967 2055 2018 2085 1931 2020 2007 2075 2086 2063 2064 2072 2056 2058 2049 2013 1981 1913 1884 1979 1846 1850 1840 1790 1835 1825 1850 1875 1792 1844 1860 1783 1782 1897 1812 1839 1857 1743 1781 1788 1832 1832 1798 1790 1831 1810 1790 1750 1837 1841 1725 1830 1764 1764 1845 1829 1857 1794 1768 1764 1820 1712 1727 1768 1727 1855 1783 1725 1738 1733 1863 1782 1767 1879 1784 1836 1783 1751 1887 1814 1847 1807 1831 1845 1819 1804 1857 1768 1809 1891 1801 1863 1861 1871 1876 1889 1891 1909 1953 1949 1994 2064 2059 2092 2061 2068 2075 2069 2066 2070 2021 1979 2080 1900 1978 1903 2081 1885 1884 2003 1927 1995 1969 2004 1941 2014 2102 2015 2009 1946 1910 1968 2004 1969 1951 1994 2108 1979 2079 2067 2055 2162 2145 2254 2165 2361 2179 2241 2252 2208 2221 2178 2165 2092 2205 2205 2170 2083 2177 2118 2209 2271 2179 2165 2353 2241 2387 2414 2478 2395 2339 2543 2566 2463 2404 2512 2338 2289 2274 2246 2285 2238 2151 2223 2112 2106 2105 2218 2157 2062 2157 2157 2222 2228 2227 2151 2118 2174 2058 2105 2109 2035 2032 2010 2027 1998 2016 1985 2063 2119 2156 2196 2179 2364 2399 2343 2509 2477 2594 2426 2651 2533 2513 2430 2382 2336 2279 2224 2234 2225 2193 2115 2161 2147 2091 2136 2116 2224 2104 2235 2244 2294 2231 2201 2210 2125 2068 2093 1957 2077 1959 1943 1895 1924 1855 1863 1866 1779 1954 1870 1920 1909 1832 1851 1876 1924 1851 1875 1930 1906 1830 1818 1819 1915 1857 1817 1751 1817 1799 1922 1864 1898 1820 1777 1829 1896 1780 1764 1806 1878 1853 1956 1846 1793 1814 1795 1930 1985 1864 1884 1946 1921 1906 1930 1943 1993 2010 1907 1893 2081 1986 2004 1932 1988 1975 1970 2079 2139 2116 2133 2291 2268 2422 2400 2532 2617 2718 2858 3052 3147 3279 3368 3565 3399 3622 3332 3475 3250 3129 2973 2752 2803 2749 2629 2705 2625 2574 2604 2656 2614 2672 2725 2779 2777 2826 2766 2740 2672 2601 2616 2540 2454 2414 2332 2330 2279 2280 2240 2326 2400 2382 2556 2702 2838 2862 3084 3131 3212 3122 2972 2774 2630 2568 2411 2398 2369 2239 2231 2169 2134 2181 2154 2163 2247 2287 2362 2468 2443 2493 2487 2460 2461 2277 2170 2201 2057 2110 2020 2030 1905 1949 1942 1967 1869 1898 1872 1958 1938 1842 1864 1924 1853 1894 1906 1794 1829 1865 1845 1780 1743 1859 1833 1862 1891 1802 1736 1881 1899 1837 1731 1783 1814 1888 1802 1830 1845 1789 1764 1854 1714 1761 1855 1777 1831 1772 1740 1865 1776 1855 1901 1834 1750 1773 1801 1758 1767 1768 1899 1841 1788 1825 1789 1854 1807 1866 1902 1870 1920 1854 1934 1886 1859 1951 1923 1916 1930 1825 1871 1890 1809 1854 1796 1817 1790 1908 1789 1817 1793 1788 1932 1829 1837 1822 1858 1798 1885 1747 1842 1895 1889 1854 1848 1887 1852 1757 1818 1808 1924 1844 1876 1833 1770 1777 1838 1813 1828 1885 1891 1909 1805 1791 1860 1789 1681 1889 1844 1871 1885 1965 1887 2026 1836 1951 1920 2080 2031 2170 2011 2068 2088 2209 2252 2351 2448 2527 2543 2672 2711 2778 2857 2887 2862 2740 2700 2645 2541 2442 2489 2324 2251 2263 2418 2230 2296 2299 2307 2234 2334 2279 2343 2438 2411 2405 2448 2377 2272 2340 2272 2232 2175 2191 2038 2095 2033 2007 1978 1887 1900 1895 1964 1924 1818 1830 1900 1935 1925 1859 1899 1892 1796 1873 1757 1848 1859 1858 1891 1889 1765 1896 1811 1878 1777 1833 1714 1846 1805 1748 1806 1733 1838 1759 1751 1835 1847 1794 1792 1818 1893 1879 1849 1918 1938 1893 1822 1865 1862 1893 1919 1910 1968 1972 1946 2033 1923 1997 1978 1998 1920 2053 1926 1996 2017 1989 2002 1945 1890 2035 1960 2070 2022 2081 2144 2162 2162 2043 2107 2143 2070 1988 1951 1988 2013 1911 1924 1898 1961 1898 1852 1990 1887 1913 1896 1983 1997 1876 1924 1954 1870 1819 1828 1800 1792 1968 1787 1875 1792 1735 1843 1759 1822 1773 1791 1740 1743 1795 1754 1751 1718 1751 1792 1747 1698 1785 1773 1745 1806 1762 1762 1819 1831 1791 1801 1747 1774 1746 1752 1738 1792 1810 1726 1813 1769 1759 1711 1839 1702 1760 1767 1744 1745 1719 1785 1834 1874 1782 1796 1842 1802 1818 1808 1741 1833 1812 1806 1785 1817 1826 1793 1838 1775 1828 1859 1871 1893 1771 1893 2013 1927 1912 1811 1967 1993 1928 2004 1933 2008 1970 1946 1969 2028 1828 1968 1879 1929 1910 1839 1803 1866 1835 1835 1933 1840 1792 1860 1839 1926 1915 1794 1952 1854 1880 1833 1887 1869 1884 1871 1914 1842 1746 1950 1865 1834 1864 1916 1867 1859 1839 1955 1839 1727 1883 1804 1854 1910 1835 1883 1881 1959 1848 1953 1849 1892 1920 2073 1984 2038 2024 2037 2188 2115 2185 2305 2290 2279 2243 2218 2244 2226 2099 2154 2105 2043 2073 1991 2089 1985 2099 2031 1948 1963 1955 1961 1989 1995 2123 2052 2184 2076 2125 2125 2073 2109 2125 2082 2165 2008 2112 2053 2153 2175 2110 2220 2236 2235 2272 2299 2286 2273 2313 2291 2165 2185 2108 2094 2063 1962 2057 2027 2071 2061 1926 2017 2037 1988 2056 2076 2073 2074 2022 2036 1994 2077 2006 2021 2055 1985 2051 1985 1948 1844 1891 1837 1884 1882 1825 1743 1815 1805 1953 1833 1860 1886 1745 1772 1837 1772 1899 1847 1800 1762 1765 1715 1757 1731 1751 1786 1845 1805 1793 1783 1696 1795 1781 1778 1819 1814 1786 1817 1746 1809 1871 1744 1726 1751 1735 1794 1845 1743 1824 1805 1851 1835 1765 1906 1817 1803 1909 1900 1909 1868 1889 1899 1825 1848 1834 1826 1947 1821 1871 1856 1868 1903 1871 1817 1808 1831 1898 1896 1882 1953 1812 1970 1856 1914 1815 1790 1824 1838 1843 1846 1778 1771 1838 1779 1841 1880 1845 1906 1732 1847 1814 1805 1810 1764 1848 1868 1917 1768 1842 1936 1900 1840 1881 1763 1901 1863 1939 1878 1821 1851 1906 1878 1904 1846 1854 1944 2065 2147 2149 2151 2187 2127 2168 2267 2188 2305 2096 2128 2098 2126 2069 2016 2068 2009 2003 1961 1964 1986 1997 1947 2000 1920 1998 2040 2004 2005 1993 2012 2011 1969 2052 2092 2019 2057 1912 2041 1857 1992 1958 1856 1898 1898 1982 1977 1883 1950 1949 1962 1962 2043 2022 1979 2125 2170 2105 2188 2216 2247 2289 2236 2289 2156 2141 2173 2189 2186 2080 2003 2003 2026 2031 1940 1954 1954 1985 1899 1956 2002 2041 2002 1963 2025 2034 2128 2002 2052 2009 1982 1902 1930 1931 1941 1987 1786 1947 1855 1921 1913 1838 1805 1785 1839 1723 1800 1753 1817 1817 1808 1760 1824 1755 1837 1835 1838 1755 1805 1838 1866 1831 1824 1870 1840 1910 1827 1853 1777 1808 1787 1751 1815 1746 1694 1681 1774 1844 1731 1778 1895 1817 1857 1781 1884 1784 1839 1759 1743 1744 1729 1796 1771 1740 1837 1730 1702 1722 1690 1772 1841 1835 1712 1830 1710 1757 1781 1787 1791 1770 1734 1759 1802 1788 1623 1814 1726 1742 1820 1812 1810 1722 1820 1755 1747 1800 1741 1716 1773 1700 1713 1769 1702 1810 1746 1770 1806 1662 1761 1774 1820 1797 1733 1710 1763 1790 1678 1739 1737 1731 1780 1837 1694 1834 1729 1770 1665 1803 1820 1807 1759 1775 1764 1801 1796 1773 1775 1719 1702 1826 1779 1800 1769 1808 1781 1824 1764 1810 1710 1738 1809 1767 1747 1824 1771 1799 1777 1741 1800 1794 1834 1737 1744 1763 1733 1777 1840 1774 1785 1757 1813 1813 1886 1780 1779 1924 1890 1940 1827 1921 1961 1869 1962 1985 1992 2097 1978 2044 2078 2146 2222 2210 2257 2261 2290 2263 2309 2264 2215 2234 2159 2135 1959 2049 1995 2048 2072 2012 2045 1993 2015 1890 2058 2013 2007 2023 2001 2111 2094 2043 2075 2142 2140 2077 2066 2095 2057 2022 2023 1894 2115 1947 2004 1997 1934 2019 2017 2037 2076 1994 2084 2047 2109 2231 2223 2409 2350 2378 2428 2425 2545 2723 2590 2721 2811 2817 2670 2661 2540 2566 2467 2409 2375 2313 2228 2260 2190 2307 2237 2254 2240 2178 2297 2254 2221 2395 2290 2373 2450 2411 2371 2416 2380 2361 2250 2217 2223 2243 2246 2230 2246 2155 2312 2192 2236 2342 2328 2369 2535 2434 2628 2690 2793 2878 2872 2909 2879 2880 2970 2790 2665 2591 2609 2546 2447 2407 2396 2246 2267 2147 2324 2129 2157 2152 2276 2296 2259 2206 2318 2285 2250 2462 2316 2324 2376 2313 2308 2243 2150 2082 2082 2025 2099 1960 2008 1905 1968 1865 1904 1973 1826 1781 1896 1832 1848 1845 1894 1773 1828 1829 1777 1807 1801 1827 1878 1822 1829 1828 1843 1843 1789 1733 1773 1779 1821 1717 1897 1754 1874 1854 1821 1836 1778 1766 1807 1794 1804 1771 1730 1853 1835 1860 1743 1880 1850 1864 1831 1820 1798 1823 1859 1827 1855 1898 1872 1987 1924 2034 1957 1979 2072 2061 2118 2172 2241 2186 2321 2237 2194 2225 2141 2131 2058 2157 2102 2034 2032 2013 2060 1958 1954 1948 1922 1979 1895 2015 1891 1980 2025 1965 1984 2085 1982 2132 2062 2014 2107 1962 1988 2005 1904 1921 1862 1873 1956 1878 1853 1890 1787 1832 1839 1817 1786 1735 1762 1750 1807 1827 1877 1751 1762 1825 1713 1790 1863 1704 1832 1776 1893 1812 1797 1846 1703 1790 1804 1741 1831 1725 1838 1661 1865 1722 1759 1792 1735 1795 1785 1765 1857 1824 1824 1828 1898 1817 1792 1840 1855 1854 1877 1817 1883 1822 1821 1892 1963 1891 1922 1930 1961 1902 2033 2019 1995 2145 2020 2272 2166 2166 2220 2143 2072 2189 2182 2145 2104 1998 1935 1973 1991 1966 1970 1945 1938 1830 1911 2009 1992 1963 1956 2042 1925 1979 2062 2049 2024 1949 2023 2036 1988 1951 1918 1880 1920 1979 1775 1943 1816 1906 1897 1823 1792 1915 1842 1820 1820 1863 1794 1809 1857 1781 1749 1814 1773 1737 1791 1799 1739 1740 1744 1797 1799 1862 1836 1735 1795 1679 1783 1786 1758 1694 1835 1808 1752 1860 1713 1748 1690 1777 1734 1812 1783 1778 1850 1769 1756 1739 1762 1751 1903 1751 1846 1781 1783 1778 1806 1855 1814 1779 1803 1752 1879 1832 1836 1802 1903 1843 1948 1777 1980 1832 1951 1913 1890 1844 1853 1882 1784 1824 1821 1904 1856 1851 1823 1731 1833 1801 1821 1799 1864 1809 1777 1828 1759 1827 1907 1809 1868 1855 1894 1873 1864 1840 1842 1932 1887 1843 1802 1858 1807 1893 1942 1803 1897 1863 1826 1862 1856 1827 1818 1842 1870 1745 1833 1848 1754 1863 1869 1918 1875 1884 1938 1824 1920 1875 1945 1865 1852 1925 1978 1961 1990 1999 1987 1975 1986 2107 2031 2221 2205 2182 2307 2295 2429 2358 2581 2463 2596 2452 2556 2367 2401 2373 2297 2285 2379 2258 2300 2289 2322 2346 2370 2396 2388 2355 2340 2388 2521 2507 2678 2607 2843 2755 2827 2798 2784 2608 2667 2635 2461 2414 2306 2328 2229 2228 2140 2171 2161 2094 2272 2100 2185 2055 2040 2148 2090 2051 2100 2158 2141 2112 2199 2207 2180 2079 2024 2072 2046 2062 2009 1948 2084 1966 2007 1891 1943 1899 1833 1884 1859 1807 1904 1871 1760 1897 1773 1817 1855 1741 1826 1784 1879 1782 1858 1788 1843 1846 1844 1843 1762 1877 1728 1792 1777 1795 1740 1826 1776 1777 1844 1737 1799 1883 1805 1825 1780 1796 1777 1833 1708 1796 1732 1844 1784 1848 1799 1905 1899 1936 1854 1929 1964 1958 1904 1978 2009 1919 1999 1984 2076 2054 2115 2004 2052 2025 1994 2007 1990 1932 2052 1921 1916 1898 1878 1924 1903 1865 1960 1847 1810 1823 1947 1961 1886 1963 1946 1934 1928 2030 1933 2003 1952 2011 2017 1988 2020 1991 2026 2041 1991 1933 1927 1960 1906 1918 1968 1880 1842 1924 1761 1919 1873 1928 1927 1828 1874 1837 1848 1857 1763 1840 1943 1962 1819 1877 1845 1895 1932 1976 1955 1903 2009 1987 1918 1915 1902 1904 1963 2010 1992 1872 1910 1849 1872 1978 1884 1934 1895 1915 1876 1932 1820 1938 1915 1918 1931 1994 1979 1991 1962 2040 2048 1999 2177 2145 2183 2275 2306 2348 2436 2389 2513 2532 2721 2644 2640 2698 2620 2791 2682 2596 2547 2481 2405 2365 2187 2261 2118 2141 2110 2146 2123 2066 2067 2064 2113 2066 2022 2092 2130 2148 2149 2211 2225 2175 2211 2197 2211 2202 2215 2207 2274 2151 2095 2022 2003 1890 1968 1896 1945 1846 1858 1899 1855 1944 1907 1869 1902 1803 1851 1796 1909 1850 1814 1926 1855 1821 1853 1788 1826 1796 1805 1847 1834 1812 1704 1815 1774 1831 1770 1731 1844 1783 1836 1798 1779 1794 1861 1782 1929 1836 1842 1798 1828 1800 1797 1867 1865 1994 1932 1985 1921 1916 1962 2004 2090 2029 2012 2031 2024 2108 2185 2141 2101 2345 2280 2367 2301 2301 2382 2275 2378 2365 2212 2252 2192 2199 2106 2166 2008 2105 2114 2020 1980 1947 2004 1954 1946 1955 1892 1937 1957 1991 2030 2059 2095 2018 2019 2064 1979 2050 2114 2036 2114 2000 1947 1963 1947 1870 1858 1904 1891 1836 1816 1843 1879 1848 1861 1916 1790 1742 1768 1741 1835 1822 1813 1805 1730 1729 1726 1801 1768 1745 1754 1798 1709 1817 1809 1723 1722 1613 1766 1692 1679 1792 1719 1717 1759</counts>
			</dataPoints>
		</scan>
	</xrdMeasurement>
</xrdMeasurements>