File: dataset/precursor_mixture/NaHCO3_SnO2_K2SO4_Bi2O3-alpha.12-min.xrdml
<?xml version="1.0"?>
<xrdMeasurements xmlns="http://www.xrdml.com/XRDMeasurement/2.2" xmlns:xsi="http://www.w3.org/2001/XMLSchema-instance" xsi:schemaLocation="http://www.xrdml.com/XRDMeasurement/2.2 http://www.xrdml.com/XRDMeasurement/2.2/XRDMeasurement.xsd" status="Completed" recordIdentifier="{2460526C-0939-4E3F-9394-3CD80F171D23}">
	<comment>
		<entry/>
	</comment>
	<sample type="To be analyzed">
		<id>dara-48-2</id>
		<name></name>
		<preparedBy></preparedBy>
	</sample>
	<xrdMeasurement measurementType="Scan" status="Completed" sampleMode="Reflection">
		<usedWavelength intended="K-Alpha 1">
			<kAlpha1 unit="Angstrom">1.5405980</kAlpha1>
			<kAlpha2 unit="Angstrom">1.5444260</kAlpha2>
			<kBeta unit="Angstrom">1.3922500</kBeta>
			<ratioKAlpha2KAlpha1>0.5000</ratioKAlpha2KAlpha1>
		</usedWavelength>
		<incidentBeamPath>
			<radius unit="mm">145.00</radius>
			<xRayTube id="1010048" name="Empyrean Cu LFF HR (9430 033 7310x) DK437873">
				<tension unit="kV">40.0</tension>
				<current unit="mA">15.0</current>
				<anodeMaterial>Cu</anodeMaterial>
				<focus type="Line">
					<length unit="mm">12.0</length>
					<width unit="mm">0.4</width>
					<takeOffAngle unit="deg">6.0</takeOffAngle>
				</focus>
			</xRayTube>
			<filter id="20010004" name="Beta-filter Nickel">
				<material>Ni</material>
				<thickness unit="mm">0.020</thickness>
			</filter>
			<sollerSlit id="21010002" name="Soller slits 0.04 rad.">
				<opening unit="rad">0.0400</opening>
			</sollerSlit>
			<mask id="22031000" name="Fixed mask 13 mm">
				<width unit="mm">9.00</width>
			</mask>
			<divergenceSlit id="22120001" name="Divergence slit 1°" xsi:type="fixedDivergenceSlitType">
				<distanceToSample unit="mm">50.00</distanceToSample>
				<height unit="mm">1.52</height>
			</divergenceSlit>
		</incidentBeamPath>
		<beamKnife id="29030100" name="Beam knife low"/>
		<sampleMovement xsi:type="spinningSampleMovementType">
			<spinnerRevolutionTime unit="seconds">1.0</spinnerRevolutionTime>
		</sampleMovement>
		<diffractedBeamPath>
			<radius unit="mm">145.00</radius>
			<antiScatterSlit id="22090040" name="AS slit 9 mm" xsi:type="fixedAntiScatterSlitType">
				<height unit="mm">9.00</height>
			</antiScatterSlit>
			<sollerSlit id="21020003" name="Large Soller slits 0.04 rad.">
				<opening unit="rad">0.0400</opening>
			</sollerSlit>
			<filter id="20030001" name="Large beta-filter Nickel">
				<material>Ni</material>
				<thickness unit="mm">0.020</thickness>
			</filter>
			<detector id="7010019" name="PIXcel1D-Medipix3 detector" xsi:type="rtmsDetectorType">
				<phd unit="keV">
					<lowerLevel>4.0</lowerLevel>
					<upperLevel>11.3</upperLevel>
				</phd>
				<mode>Scanning</mode>
				<activeLength unit="deg">5.020</activeLength>
			</detector>
		</diffractedBeamPath>
		<scan appendNumber="0" mode="Continuous" scanAxis="Gonio" status="Completed">
			<header>
				<startTimeStamp>2024-03-25T11:33:34-07:00</startTimeStamp>
				<endTimeStamp>2024-03-25T11:46:02-07:00</endTimeStamp>
				<author>
					<name>AutomatedUser</name>
				</author>
				<source>
					<applicationSoftware version="1.6 (94)">PANalytical Aeris Instrument Suite</applicationSoftware>
					<instrumentControlSoftware version="3.0.0 20211014">AERIS</instrumentControlSoftware>
					<instrumentID>2879380</instrumentID>
				</source>
			</header>
			<dataPoints>
				<positions axis="2Theta" unit="deg">
					<startPosition>9.99043322</startPosition>
					<endPosition>100.09495370</endPosition>
				</positions>
				<positions axis="Omega" unit="deg">
					<startPosition>4.99521661</startPosition>
					<endPosition>50.04747685</endPosition>
				</positions>
				<commonCountingTime unit="seconds">18.249</commonCountingTime>
				<counts unit="counts">3957 4022 3917 4022 3900 3940 3872 3848 3899 3865 3870 3875 3958 3935 4020 3914 3955 3897 3882 3841 3881 3910 3811 3875 3937 3959 3888 3845 3835 3856 3926 3850 3839 3906 3721 3802 3828 3849 3828 3758 3824 3852 3976 3702 3801 3819 3767 3720 3732 3772 3750 3635 3730 3723 3813 3815 3670 3836 3614 3645 3641 3772 3568 3832 3619 3681 3655 3676 3753 3588 3661 3703 3636 3613 3526 3667 3524 3540 3706 3568 3480 3536 3537 3566 3635 3529 3733 3496 3588 3533 3500 3503 3460 3616 3534 3541 3585 3660 3625 3471 3531 3433 3522 3470 3548 3423 3407 3480 3408 3518 3480 3466 3421 3457 3307 3368 3514 3454 3397 3418 3448 3295 3425 3492 3495 3369 3449 3401 3276 3419 3434 3310 3219 3324 3301 3358 3291 3346 3395 3278 3378 3218 3301 3298 3283 3330 3229 3414 3272 3342 3314 3231 3293 3335 3242 3298 3332 3328 3198 3344 3230 3265 3266 3269 3289 3169 3297 3225 3229 3292 3218 3237 3158 3225 3198 3156 3295 3223 3124 3248 3181 3242 3152 3274 3279 3262 3186 3259 3218 3204 3115 3156 3163 3142 3170 3188 3109 3009 3142 3161 3116 3083 3151 3053 3061 3113 3040 3139 3104 2998 3108 2999 3097 3074 3072 3024 2971 3047 3057 3043 3100 3080 2974 3020 3090 2894 3092 3100 3059 2992 2994 3020 2995 3012 3032 3010 2885 2988 3112 3089 2937 3027 3104 2927 2911 2955 3007 3103 2931 2969 2923 2825 3019 2938 2940 2880 2873 2873 2888 2934 2983 2939 2917 2848 2971 2784 2957 2869 3017 2893 2895 2786 2870 2813 2831 2908 2896 2845 2861 2802 2843 2852 2874 2898 2778 2749 2845 2849 2815 2869 2801 2859 2795 2782 2815 2775 2672 2817 2806 2768 2876 2708 2760 2758 2801 2807 2670 2758 2780 2728 2782 2736 2733 2809 2809 2838 2728 2816 2713 2723 2809 2802 2704 2700 2613 2697 2777 2618 2679 2749 2736 2638 2676 2683 2642 2652 2667 2669 2759 2720 2726 2743 2639 2761 2679 2656 2679 2695 2643 2747 2692 2720 2697 2689 2714 2770 2598 2719 2559 2705 2621 2615 2647 2636 2623 2748 2700 2657 2658 2605 2664 2628 2612 2614 2651 2575 2632 2614 2679 2570 2617 2589 2614 2525 2707 2496 2546 2460 2653 2560 2579 2580 2534 2619 2515 2599 2568 2486 2557 2555 2575 2542 2576 2570 2593 2607 2632 2526 2623 2548 2612 2564 2582 2545 2542 2588 2436 2515 2579 2574 2468 2497 2617 2502 2507 2477 2579 2552 2558 2584 2630 2495 2550 2509 2563 2587 2475 2512 2573 2474 2515 2467 2615 2401 2491 2527 2577 2489 2601 2529 2523 2638 2587 2634 2680 2601 2602 2715 2620 2828 2724 2752 2673 2725 2808 2720 2719 2721 2482 2572 2499 2573 2545 2557 2474 2522 2472 2476 2469 2418 2428 2360 2347 2501 2436 2471 2372 2403 2358 2328 2480 2437 2361 2389 2353 2370 2381 2416 2326 2343 2418 2426 2330 2457 2467 2417 2479 2346 2373 2355 2376 2383 2374 2382 2355 2372 2368 2402 2391 2439 2379 2366 2355 2323 2395 2378 2370 2417 2367 2357 2362 2277 2346 2361 2375 2344 2344 2355 2450 2377 2297 2380 2479 2362 2286 2302 2296 2301 2358 2327 2427 2280 2372 2356 2315 2352 2308 2329 2329 2228 2247 2289 2275 2442 2343 2249 2321 2264 2286 2358 2295 2232 2254 2308 2354 2299 2303 2361 2297 2332 2317 2295 2357 2251 2187 2263 2319 2306 2269 2290 2309 2243 2284 2260 2296 2358 2290 2293 2321 2250 2308 2257 2457 2324 2353 2295 2331 2409 2284 2416 2192 2333 2299 2356 2387 2283 2307 2384 2455 2394 2402 2462 2459 2438 2459 2445 2537 2424 2495 2467 2507 2392 2340 2337 2413 2318 2289 2258 2270 2304 2242 2227 2255 2164 2273 2234 2209 2174 2201 2188 2160 2286 2282 2170 2191 2134 2172 2228 2162 2161 2215 2212 2267 2302 2206 2148 2252 2119 2193 2175 2216 2186 2232 2174 2146 2200 2233 2207 2264 2194 2237 2240 2227 2236 2195 2261 2240 2275 2318 2315 2299 2395 2392 2455 2417 2730 2526 2726 2806 2901 3076 3110 3147 3140 3097 3023 2901 2871 2796 2676 2605 2611 2485 2559 2384 2353 2376 2308 2282 2210 2217 2195 2145 2145 2093 2264 2165 2219 2101 2122 2199 2139 2193 2175 2216 2123 2172 2167 2139 2073 2168 2052 2156 2167 2140 2105 2203 2183 2174 2234 2133 2242 2195 2281 2332 2300 2395 2382 2568 2511 2696 2913 2929 3019 3280 3451 3466 3817 4012 4052 4072 3871 3734 3373 3188 2871 2686 2473 2345 2232 2178 2138 2144 2026 2045 2080 2087 1979 2053 2069 1971 2048 2077 2002 1975 1944 2095 2040 2047 2009 2041 1971 1992 2101 1971 2007 1977 1946 1973 2039 2082 2017 1979 1973 1979 1950 2002 2004 1923 1893 2008 2021 2025 2068 2022 1978 1907 1941 1935 1976 1942 1960 1934 2009 1970 1925 1930 1987 2003 1942 1941 1961 1997 1986 1959 2034 1963 1954 1997 1900 2015 1990 1931 1958 1951 1982 1854 1935 1881 2053 1981 1894 1893 1883 1874 1890 1881 1854 2014 1967 2000 1936 2008 1962 2014 1979 1987 1848 1866 1942 1968 2024 1978 2030 1976 2048 2083 2140 2148 2123 2140 2264 2263 2198 2326 2344 2383 2488 2490 2582 2561 2355 2256 2303 2252 2068 2033 1996 1917 1890 1920 1893 1911 1793 1851 1824 1857 1883 1901 1842 1795 1885 1882 1848 1821 1855 1866 1943 1846 1808 1796 1748 1767 1862 1830 1839 1801 1817 1784 1769 1814 1767 1911 1799 1749 1776 1814 1865 1886 1801 1849 1766 1780 1814 1809 1800 1786 1700 1906 1840 1755 1771 1773 1770 1802 1789 1780 1686 1724 1770 1813 1772 1774 1669 1782 1774 1839 1693 1726 1791 1770 1707 1752 1719 1693 1772 1633 1779 1796 1757 1795 1832 1803 1765 1752 1702 1731 1726 1739 1892 1822 1693 1804 1775 1812 1814 1799 1776 1848 1772 1816 1766 1856 1840 1800 1801 1774 1757 1794 1795 1759 1825 1824 1830 1866 1908 1934 1983 2023 2124 2116 2223 2248 2318 2440 2573 2693 2835 3054 3187 3109 3178 3002 2958 2996 2982 2825 2887 2722 2557 2492 2327 2294 2182 2031 1962 1923 1860 1893 1837 1757 1765 1700 1794 1766 1716 1854 1748 1775 1844 1826 1862 1896 1901 1886 1869 1843 2042 2046 2020 2150 2240 2227 2308 2407 2352 2346 2220 2163 2114 2026 1942 1936 1906 1832 1717 1769 1798 1724 1645 1710 1632 1657 1655 1617 1704 1664 1714 1667 1720 1656 1682 1579 1629 1630 1621 1664 1604 1649 1652 1615 1682 1618 1738 1561 1618 1605 1637 1586 1669 1530 1626 1588 1660 1587 1574 1593 1623 1607 1535 1635 1633 1659 1544 1597 1635 1538 1581 1552 1521 1611 1590 1598 1578 1593 1648 1572 1570 1536 1577 1575 1568 1633 1670 1541 1622 1583 1557 1568 1609 1510 1580 1534 1524 1571 1528 1561 1576 1555 1638 1544 1553 1533 1621 1574 1662 1616 1535 1646 1552 1591 1554 1572 1535 1547 1463 1539 1524 1498 1550 1542 1507 1526 1542 1570 1581 1530 1520 1505 1598 1624 1587 1559 1540 1562 1642 1547 1589 1533 1563 1522 1620 1495 1516 1547 1521 1556 1467 1501 1554 1611 1528 1544 1473 1519 1576 1620 1555 1588 1546 1517 1560 1552 1677 1640 1662 1598 1629 1610 1616 1625 1716 1655 1640 1722 1774 1806 1783 1852 2002 2069 2137 2267 2445 2648 2960 3088 3394 3590 3782 4174 4426 4434 4299 4247 4042 3891 3922 3717 3409 3071 2741 2397 2445 2183 2080 1997 1914 1794 1742 1725 1686 1677 1665 1621 1675 1626 1648 1621 1593 1601 1641 1593 1557 1594 1518 1647 1586 1622 1557 1624 1477 1561 1567 1533 1591 1618 1564 1531 1580 1542 1630 1627 1593 1676 1549 1667 1727 1680 1712 1788 1805 1936 2036 2170 2186 2232 2448 2501 2710 2750 2924 3074 3106 3003 2859 2744 2573 2328 2369 2068 1970 1915 1856 1743 1600 1634 1600 1614 1500 1561 1546 1532 1511 1571 1505 1504 1483 1499 1522 1500 1444 1540 1472 1501 1447 1448 1496 1458 1535 1533 1527 1580 1481 1572 1496 1417 1424 1565 1531 1534 1526 1505 1543 1489 1600 1516 1559 1509 1490 1517 1589 1660 1691 1581 1704 1672 1745 1780 1750 1852 1869 1940 1934 1986 1887 1969 1866 1951 1958 2072 2051 2118 2053 2119 2163 2131 2405 2453 2561 2702 2970 3125 3260 3570 3578 3654 3821 3740 3606 3667 3659 3556 3623 3794 3860 4089 4300 4486 4686 4876 5369 5389 5429 5169 4848 4379 3993 3791 3508 3306 2864 2573 2291 2045 1898 1921 1870 1873 1834 1792 1818 1885 1849 1938 1872 1876 1931 1911 1953 1944 1971 2024 1964 2013 2009 2158 2031 2129 2132 2258 2171 2394 2445 2359 2499 2589 2593 2728 2824 2859 3094 3115 3216 3368 3514 3701 3845 4142 4343 4534 4917 5381 5680 6026 6749 7268 7934 8707 9391 10437 11302 12277 13591 14710 16083 16979 17957 19088 19640 19625 19610 19018 18051 17091 15783 14698 13500 11973 10834 9672 8855 7766 7020 6566 6194 6000 5689 5655 5507 5809 6001 6199 6499 7046 7404 7822 8389 8845 9263 9300 9079 8408 7680 7138 6556 6126 5452 4771 4276 3751 3470 3138 2826 2728 2617 2598 2674 2671 2700 2732 2801 2914 3215 3277 3526 3835 4203 4618 5188 5675 6527 7118 8387 9745 10950 12742 14177 16307 18548 20672 22971 24949 26194 26098 23916 21093 18688 16591 15130 13493 11638 9442 7571 5822 4475 3686 3141 2718 2548 2530 2358 2299 2135 2271 2141 2095 2097 2100 2045 2054 2010 1953 2007 1954 2035 1931 1936 2022 1951 1966 1915 2067 1952 2051 2150 2172 2340 2387 2607 2818 3048 3303 3621 4028 4361 4673 5285 5574 5977 6180 6066 5636 5019 4418 4288 3846 3673 3340 2915 2451 2137 2004 1823 1729 1635 1617 1701 1526 1666 1538 1580 1632 1532 1528 1563 1535 1532 1548 1524 1522 1543 1637 1621 1558 1602 1609 1640 1638 1654 1536 1661 1533 1651 1524 1530 1411 1420 1444 1467 1462 1469 1360 1448 1375 1453 1391 1405 1346 1418 1407 1458 1383 1396 1358 1456 1397 1429 1445 1419 1415 1448 1395 1495 1563 1635 1641 1698 1803 1868 1949 2196 2324 2617 2871 2991 3376 3867 4005 4031 3923 3687 3415 3312 3078 2912 2742 2606 2380 2330 2226 2080 1935 2012 1839 1897 1810 1852 1778 1746 1809 1627 1602 1556 1504 1459 1542 1481 1453 1466 1464 1427 1392 1498 1404 1378 1447 1456 1415 1404 1402 1444 1328 1414 1445 1413 1407 1433 1530 1432 1428 1422 1512 1544 1612 1640 1702 1703 1748 1787 1967 2002 2191 2274 2523 2649 2915 3239 3609 3760 3908 4053 3910 3977 4140 4130 3804 3544 3128 2966 2743 2568 2500 2279 2024 1874 1774 1728 1633 1714 1599 1620 1683 1720 1694 1730 1762 1855 1958 1968 2090 2269 2360 2649 2740 2962 3306 3791 3889 4242 4365 4819 5147 5253 5449 5263 4962 4545 4303 4176 3947 3905 3783 3702 3701 3664 3605 3689 3941 4200 4477 4889 5180 5275 5178 4895 4513 4349 3965 3835 3617 3508 3206 3077 2669 2472 2337 2182 2235 2296 2357 2413 2587 2758 3092 3348 3699 4315 4885 5849 6674 7230 8468 9461 10703 11105 10812 9227 8711 7281 6964 6781 6755 6394 5836 4912 4563 3967 3944 3771 3884 3781 3728 3542 3340 3022 2956 2652 2594 2474 2264 2118 1933 1784 1619 1586 1525 1558 1508 1445 1470 1394 1365 1331 1314 1356 1302 1328 1317 1295 1215 1267 1271 1304 1261 1264 1274 1270 1277 1277 1200 1269 1244 1344 1254 1273 1207 1286 1192 1285 1331 1222 1251 1216 1215 1317 1217 1237 1237 1232 1127 1267 1209 1181 1117 1200 1256 1225 1217 1185 1129 1154 1188 1222 1224 1195 1276 1178 1164 1178 1188 1229 1225 1146 1175 1209 1195 1173 1189 1168 1222 1206 1232 1190 1194 1207 1143 1211 1227 1254 1254 1203 1258 1202 1243 1223 1169 1307 1210 1331 1273 1224 1201 1241 1219 1205 1238 1174 1248 1151 1328 1286 1242 1279 1300 1276 1309 1337 1360 1310 1402 1334 1452 1484 1559 1633 1668 1810 1833 1958 2070 2230 2234 2308 2310 2147 2085 1986 1861 1830 1789 1796 1790 1655 1637 1568 1491 1388 1486 1435 1474 1432 1432 1526 1538 1464 1457 1428 1485 1505 1541 1666 1633 1722 1763 1803 1875 1878 2003 2186 2344 2467 2700 3080 3415 3870 4236 4948 5719 6517 7146 7999 8770 9038 8778 8471 7816 7196 7058 6669 6760 6959 6872 6958 6852 6894 7295 7952 8368 9117 9668 10102 10010 9618 8806 7985 7224 6802 6247 5889 5559 5006 4462 3851 3399 2880 2556 2324 2327 2204 2084 2145 2081 2096 2117 2140 2029 2206 2166 2140 2251 2273 2457 2495 2580 2676 2794 2877 2967 3136 3257 3427 3695 3952 4075 4522 4991 5399 5963 6449 7231 7888 8716 9771 10693 11745 12661 13924 14821 15430 16181 16092 15855 15400 14670 13972 13146 12588 11709 10708 9850 8902 7853 7156 6336 5601 5101 4573 4051 3736 3380 3164 2865 2678 2635 2474 2482 2287 2376 2130 2157 2118 2051 1938 1959 1880 1885 1858 1884 1853 1882 1851 1972 1924 2050 2163 2378 2514 2674 2969 3272 3753 4100 4598 5079 5482 5735 5577 5268 4741 4273 3954 3760 3625 3440 3511 3095 2765 2288 2051 1777 1602 1610 1509 1467 1474 1415 1364 1434 1390 1381 1281 1335 1271 1365 1389 1293 1299 1346 1356 1388 1411 1452 1548 1479 1527 1668 1741 1822 2053 2253 2490 2806 3018 3384 3729 3926 4157 4031 3961 3606 3372 2994 2933 2810 2729 2647 2465 2189 2102 1819 1680 1543 1516 1414 1445 1411 1475 1388 1418 1558 1548 1683 1729 1926 2022 2209 2356 2422 2675 2858 2949 2926 2708 2639 2447 2310 2229 2399 2414 2382 2316 2384 2484 2568 2713 3069 3497 3849 4349 4392 4418 3878 3497 2992 2742 2770 2831 2890 2746 2684 2330 2146 1833 1828 1755 1819 1880 2035 2183 2316 2376 2518 2665 2620 3037 2925 3036 2790 2695 2431 2154 2076 1971 2001 1925 1809 1688 1510 1379 1319 1259 1244 1128 1126 1097 1133 1049 1073 1131 1121 1088 1040 1069 1091 1091 1099 1090 1040 998 1047 1096 997 1132 1053 1078 1022 1039 974 1025 1036 1058 1089 1058 1069 1097 1015 1051 1028 1011 1002 1046 1091 1068 1025 1064 1098 1070 1079 1047 1081 1062 1067 1022 1114 1012 1127 1034 1057 1161 1092 1119 1113 1076 1067 1081 1142 1153 1111 1134 1137 1163 1188 1207 1294 1312 1431 1513 1637 1687 1888 1966 2169 2315 2292 2396 2266 2221 2106 2155 2148 2180 2323 2477 2682 2949 3114 3349 3493 3541 3376 2871 2552 2259 2180 2238 2371 2485 2419 2364 2039 1940 1666 1724 1562 1550 1523 1443 1487 1426 1343 1314 1429 1368 1423 1420 1466 1393 1464 1504 1476 1607 1630 1759 1873 2095 2368 2645 2872 3200 3458 3635 3847 3909 3888 3627 3338 3106 2968 3016 2795 2790 2721 2645 2548 2321 2164 2119 2116 2095 2224 2290 2433 2608 2736 2807 3076 3405 3395 3792 3890 4223 4536 4733 4938 4985 5052 5138 4735 4553 4334 3980 3853 3871 3603 3444 3269 2988 2775 2448 2248 2030 1946 1773 1691 1658 1525 1427 1429 1359 1297 1286 1354 1238 1259 1189 1178 1117 1143 1119 1089 1057 1049 1063 1042 1041 1171 1071 1056 1020 1093 1066 1054 1005 1025 959 977 956 996 1039 1002 1055 985 1014 1007 980 1062 1023 969 1020 941 997 979 944 965 1002 942 992 973 948 1031 1000 1004 1082 1041 1105 1109 1164 1161 1200 1251 1297 1340 1419 1499 1545 1623 1697 1730 1799 1833 1888 1805 1772 1742 1725 1554 1660 1659 1518 1526 1429 1405 1299 1313 1235 1168 1183 1154 1077 1112 1036 1024 979 998 1030 983 999 947 1012 935 948 913 914 987 978 939 927 950 979 928 889 918 932 908 909 912 1014 915 912 909 908 904 960 856 920 843 965 932 928 926 947 957 914 898 868 910 868 932 901 940 901 898 877 900 892 876 879 916 955 947 868 954 976 929 926 1013 1036 1006 1100 1061 1174 1243 1360 1419 1574 1733 1866 1895 2051 1897 1713 1592 1470 1419 1420 1421 1375 1496 1431 1300 1230 1056 1110 1057 1042 1049 1009 1008 948 1025 964 1111 1046 1123 1163 1214 1215 1253 1243 1351 1346 1391 1328 1389 1403 1302 1290 1196 1209 1203 1195 1187 1147 1179 1280 1222 1200 1309 1316 1378 1445 1536 1628 1688 1919 2155 2381 2647 2859 3366 3585 4057 4037 4011 3780 3387 3089 2863 2807 2918 2956 2937 2953 3053 2557 2423 2072 1782 1464 1501 1371 1384 1319 1276 1296 1152 1124 1073 1010 960 1017 919 900 903 952 889 906 918 883 899 902 880 935 884 908 899 908 867 878 869 891 880 907 859 909 932 994 972 975 1024 1144 1135 1254 1324 1399 1547 1692 1776 1653 1578 1523 1363 1410 1293 1347 1215 1256 1285 1319 1247 1159 1102 1085 1002 1002 977 992 953 942 925 924 955 941 902 865 935 978 961 1043 1091 1094 1203 1362 1419 1513 1505 1596 1617 1556 1480 1343 1371 1280 1230 1293 1258 1249 1220 1182 1167 1129 1026 1011 995 872 962 865 920 923 937 907 873 901 916 954 933 1046 1021 1043 1132 1073 1223 1255 1380 1515 1703 1836 1965 2182 2293 2241 2211 1994 1849 1623 1537 1510 1539 1559 1547 1603 1611 1486 1274 1249 1123 1022 1030 1083 1027 1004 1059 1098 1066 1131 1070 1071 1033 1100 1099 1028 1086 994 1013 968 967 950 928 926 961 921 921 850 900 906 883 925 824 937 831 940 884 926 951 989 1016 1073 1107 1100 1207 1181 1287 1247 1127 1147 984 1083 1067 969 1049 1044 1115 1134 1075 1064 1064 1138 1183 1284 1356 1528 1548 1821 1821 1800 1836 1585 1554 1365 1412 1329 1467 1522 1655 1749 1855 1831 1922 1983 2175 2228 2259 2009 1764 1494 1370 1326 1291 1410 1428 1437 1538 1378 1392 1074 1069 977 951 931 828 908 828 826 826 848 769 815 826 850 827 850 796 789 820 827 804 756 830 841 798 846 772 854 779 810 821 820 752 797 798 789 829 763 802 728 870 812 747 787 770 787 850 810 770 784 785 781 826 811 821 809 828 899 919 923 985 1023 964 1016 980 1086 1037 1044 996 985 926 1027 1004 978 1074 1075 1064 1080 1105 1027 1078 1084 1061 1148 1152 1140 1214 1276 1269 1242 1221 1249 1137 1112 1081 1068 1089 1042 1011 1055 1037 991 961 907 904 848 856 888 913 787 771 755 851 806 863 799 890 812 790 777 867 778 881 856 850 847 877 901 895 1006 971 976 1078 1153 1190 1313 1507 1631 1755 1897 1821 1690 1569 1495 1314 1381 1379 1361 1420 1543 1615 1599 1548 1445 1299 1116 1061 967 976 997 1026 998 978 990 987 951 911 938 871 912 933 871 875 873 913 821 867 835 894 840 854 863 906 932 883 899 888 889 862 881 854 819 884 795 848 840 825 877 849 860 854 837 885 794 857 845 885 870 851 881 903 889 922 1048 1072 1099 1026 1218 1290 1391 1433 1452 1552 1666 1544 1548 1521 1395 1419 1363 1475 1516 1599 1533 1609 1642 1733 1673 1787 1921 2176 2420 2681 3147 3659 4135 4710 5200 5653 5634 5449 5020 4490 3895 3463 3281 3232 3255 3409 3481 3433 3310 2970 2542 2348 1928 1685 1434 1391 1266 1227 1182 1170 1234 1167 1214 1211 1221 1267 1131 1144 1108 1113 1019 972 1017 1020 1000 988 1036 1039 997 955 973 959 879 893 933 914 936 956 932 892 859 894 919 931 922 932 925 930 918 951 952 956 908 859 860 896 859 844 837 779 864 880 850 843 833 829 825 832 799 856 857 836 812 796 821 830 888 829 872 876 879 876 903 926 951 1005 1075 1126 1156 1164 1173 1126 1094 1074 1086 1071 1150 1155 1231 1349 1405 1440 1417 1410 1353 1220 1202 1069 1104 1087 1081 1134 1187 1192 1234 1281 1214 1197 1144 1081 950 1008 967 944 916 919 977 970 933 936 894 915 885 879 836 861 836 803 841 825 842 842 877 907 920 958 962 971 1061 1150 1118 1151 1150 1059 1047 1042 1064 975 975 958 1032 1052 1025 1082 1035 1051 1164 1067 1144 1179 1289 1471 1495 1593 1793 2004 2255 2326 2369 2210 2014 1931 1723 1685 1788 1877 2043 2237 2494 2753 2952 3063 3286 3322 3307 3161 3063 2779 2644 2587 2631 2515 2585 2553 2450 2346 2383 2286 2317 2124 2216 2202 2168 2075 2073 1764 1544 1479 1356 1290 1337 1277 1272 1327 1343 1270 1285 1185 1122 1037 1041 962 975 884 909 892 941 1033 1014 1003 1022 1002 1070 954 917 895 862 895 888 902 920 953 945 933 888 886 808 867 845 836 823 836 861 898 908 1002 1115 1164 1306 1364 1472 1715 1683 1953 1886 1802 1678 1563 1379 1360 1254 1274 1280 1324 1363 1369 1379 1294 1251 1166 1119 1027 942 903 933 911 921 873 845 896 894 865 871 898 883 868 932 877 904 939 932 1005 1094 1086 1158 1353 1415 1558 1730 1928 1946 2030 1978 1826 1552 1417 1237 1237 1201 1227 1335 1341 1397 1463 1280 1332 1190 1160 1015 918 916 848 856 856 852 822 855 824 857 793 812 828 871 852 831 845 862 921 905 911 925 972 1025 879 884 830 892 906 881 851 887 870 975 865 882 817 835 835 851 852 875 841 784 836 857 868 804 809 862 801 848 834 796 819 812 804 846 790 874 889 800 835 850 904 841 830 789 893 909 851 855 849 911 880 898 849 933 913 857 857 887 919 916 892 911 964 908 927 976 984 939 959 924 1003 1052 1085 1091 1020 1108 1156 1161 1244 1291 1358 1471 1513 1555 1550 1505 1441 1371 1421 1419 1594 1599 1622 1682 1781 1923 1906 1975 1952 1961 1933 1992 2029 2125 2232 2388 2492 2662 2916 3212 3583 3895 4184 4679 5276 5813 6654 7301 8101 8805 9678 10174 11043 11612 12086 12548 12250 11848 11173 10401 9698 9283 9009 8957 8851 8848 8818 8974 8844 8575 8027 7141 6405 5617 5018 4443 4011 3683 3508 3408 3269 3234 3116 2898 2729 2615 2440 2240 2095 1988 2013 1876 1777 1730 1651 1649 1614 1666 1619 1708 1784 1810 2032 2134 2520 2765 2984 3467 3811 4119 4206 4125 3733 3262 2679 2340 2080 2177 2169 2272 2318 2621 2732 2701 2726 2478 2202 1983 1670 1465 1372 1357 1292 1292 1241 1251 1237 1267 1287 1299 1273 1310 1221 1262 1295 1182 1061 1089 1178 1129 1055 1114 1103 1133 1172 1223 1230 1283 1235 1457 1486 1748 1909 2152 2372 2499 2750 2881 2913 2970 2552 2370 2003 1834 1650 1602 1665 1696 1767 1898 1894 1919 1844 1708 1504 1385 1154 1087 1027 966 935 950 894 955 897 930 903 819 885 867 945 819 862 818 839 883 821 853 830 851 849 847 868 913 955 863 956 892 812 795 816 856 794 883 833 826 847 822 888 829 828 844 831 815 780 780 852 849 846 763 816 824 828 794 814 863 843 826 828 822 798 832 776 801 797 842 884 849 918 870 825 881 868 991 928 960 1030 1059 1013 1052 1043 1023 1057 1063 1079 1147 1105 1162 1098 1079 1084 1066 1051 1102 1108 1049 1090 1109 1127 1094 1159 1177 1143 1095 1053 1116 1072 1053 1040 1141 1084 1154 1137 1147 1245 1233 1283 1311 1288 1501 1607 1769 1826 2127 2263 2584 2528 2585 2355 2395 2318 2403 2740 3003 3380 3801 4265 4986 5491 6014 6377 6634 6453 5732 5042 4410 3988 3530 3495 3440 3443 3752 3973 4302 4466 4606 4451 4083 3558 3094 2570 2107 1888 1722 1602 1656 1555 1605 1696 1677 1660 1527 1541 1406 1251 1256 1137 1104 1093 1034 1034 1082 1128 1174 1088 1113 1106 1137 1075 1045 1038 1072 1146 1157 1168 1257 1389 1515 1757 1975 2248 2331 2558 2556 2564 2347 2147 1887 1864 1699 1673 1529 1580 1667 1617 1685 1757 1685 1669 1541 1477 1396 1352 1231 1095 1053 1009 965 948 891 949 926 961 1035 1026 1080 1177 1170 1347 1415 1598 1790 1922 2125 2264 2263 2238 1977 1696 1430 1306 1257 1231 1232 1230 1402 1441 1547 1541 1519 1478 1340 1223 1120 1047 970 931 828 875 876 857 874 891 887 908 879 888 927 904 921 798 865 824 834 856 887 869 887 915 980 964 939 974 996 1006 1011 959 997 964 995 1047 1070 956 1003 947 958 934 883 952 881 945 881 922 937 932 929 921 918 920 862 814 840 849 832 900 897 773 837 911 918 877 837 889 895 990 924 984 1117 1108 1300 1521 1698 2192 2580 3219 3850 4262 4382 4217 3817 3080 2449 1982 1656 1581 1472 1624 1856 1964 2376 2526 2638 2583 2319 2064 1684 1407 1269 1086 1023 977 929 867 867 884 834 900 844 827 831 788 822 819 860 800 839 817 857 868 800 862 825 874 900 916 891 850 921 873 947 950 1018 1077 998 992 1085 1150 1117 1282 1308 1499 1575 1632 1883 2049 2308 2463 2554 2701 2742 2682 2734 2839 3072 3030 3044 2932 3042 2786 2646 2560 2477 2420 2406 2378 2227 2139 2160 2009 1959 1973 1965 1824 1674 1541 1430 1341 1326 1222 1286 1216 1212 1188 1236 1219 1256 1279 1445 1591 1704 1916 2122 2186 2251 2116 2012 1872 1620 1542 1396 1299 1284 1230 1336 1464 1492 1624 1606 1643 1556 1627 1433 1342 1245 1208 1208 1252 1249 1252 1339 1379 1414 1237 1184 1185 1098 1042 1048 1148 1046 1074 1019 1035 1061 1051 1064 1108 1074 987 907 971 972 922 906 886 921 885 944 901 949 911 1013 1028 1166 1232 1281 1356 1475 1530 1601 1631 1885 1880 1890 1917 1616 1558 1423 1297 1286 1231 1210 1146 1190 1234 1210 1193 1245 1271 1275 1204 1088 991 893 904 849 861 786 829 702 739 707 695 774 671 715 729 744 748 793 691 751 685 756 716 739 720 728 722 760 714 741 738 777 719 711 732 696 738 721 694 714 769 782 735 746 769 725 714 734 736 743 686 774 732 745 808 727 726 780 873 895 887 916 890 868 881 882 884 852 919 916 1001 948 931 916 816 981 864 866 887 758 793 821 786 838 764 839 862 761 776 789 730 735 802 735 758 757 732 703 767 800 813 792 850 814 837 838 812 793 746 755 733 752 819 812 734 846 848 879 838 879 884 878 816 806 746 791 723 799 798 809 764 801 844 821 877 779 863 808 839 845 880 870 953 1021 1047 1101 1091 1091 1061 1101 1092 1012 934 911 911 840 866 825 876 861 968 858 925 908 917 904 857 831 815 850 770 765 742 799 765 749 778 838 756 731 760 760 774 767 793 787 798 807 825 804 829 872 774 831 832 881 939 947 984 1059 1085 1219 1354 1470 1670 1676 1861 1937 1847 1814 1548 1449 1308 1282 1206 1191 1205 1207 1252 1315 1453 1516 1551 1618 1538 1477 1523 1531 1465 1486 1594 1672 1880 2077 2176 2503 2734 2872 3150 3251 3239 3445 3438 3240 3196 3004 2865 2773 2568 2508 2418 2319 2444 2535 2418 2435 2290 2302 2276 2201 2115 2053 1830 1652 1580 1438 1357 1274 1290 1221 1172 1191 1136 1142 1192 1193 1230 1292 1352 1394 1490 1450 1454 1435 1336 1291 1236 1196 1247 1196 1279 1378 1402 1620 1686 1771 1816 1654 1618 1543 1424 1328 1293 1221 1280 1268 1225 1193 1184 1250 1284 1259 1366 1333 1310 1331 1192 1311 1179 1206 1102 1053 950 924 917 849 937 901 940 943 1018 980 951 926 976 916 938 963 877 847 821 836 789 846 863 773 838 784 773 828 755 727 761 741 741 785 754 756 800 820 710 723 698 807 759 745 684 767 783 742 777 751 776 795 777 774 806 708 806 794 803 800 807 839 783 850 882 925 961 973 988 1078 1121 1180 1235 1214 1211 1338 1331 1414 1333 1193 1106 1070 1001 980 947 952 1007 985 1010 1069 1045 1096 1085 1010 1039 961 971 897 802 847 787 805 797 722 837 773 807 769 769 748 728 810 800 769 826 878 875 892 946 998 1188 1265 1566 1751 1794 1767 1655 1439 1247 1101 1031 947 982 915 906 980 998 1092 1080 1302 1265 1366 1324 1299 1136 1065 982 887 877 924 851 923 931 1016 930 1019 1003 1047 1096 1151 1178 1287 1272 1275 1303 1262 1207 1202 1322 1258 1366 1358 1515 1628 1672 1701 1899 2119 2257 2434 2549 2602 2869 2860 2889 2675 2658 2419 2339 2210 2013 2059 1968 1939 1994 1936 1903 1915 1956 2008 2056 2076 1933 1838 1879 1796 1814 1836 1556 1493 1480 1297 1224 1187 1081 1124 1064 1014 1053 1039 1046 1093 1045 1043 1022 997 1013 933 981 921 852 864 838 860 871 925 850 896 908 966 962 1049 1076 1058 975 1019 971 993 938 894 862 908 921 901 986 943 1004 987 1013 1176 1183 1123 1241 1177 1203 1148 1103 1022 1081 1013 1050 975 1044 1043 1080 1143 1164 1142 1206 1285 1332 1392 1387 1465 1523 1622 1642 1821 1903 2107 2200 2435 2685 2949 3076 3147 3308 3340 3335 3066 3006 2809 2572 2503 2254 2259 2269 2176 2170 2184 2191 2291 2336 2341 2291 2259 2145 2047 1961 1879 1841 1904 1794 1736 1737 1632 1544 1524 1324 1279 1210 1106 1086 1000 1030 1028 982 1045 1109 1038 1121 1089 1055 1028 977 918 886 881 864 830 877 877 921 894 944 994 983 863 857 844 864 799 856 798 773 844 889 929 965 1033 1039 1202 1230 1354 1434 1493 1457 1365 1426 1354 1409 1384 1446 1522 1380 1423 1388 1331 1241 1149 1192 1118 1183 1120 1104 1045 1040 966 1062 1031 1050 1054 1100 1022 962 948 947 864 863 850 853 732 835 841 760 698 717 721 692 719 714 678 731 688 736 716 777 730 758 726 777 769 770 725 788 790 740 759 737 693 728 671 617 698 623 674 685 758 742 661 717 742 690 736 716 736 696 664 710 704 680 749 721 777 798 813 835 839 937 1013 1060 1197 1213 1172 1139 1107 989 907 892 750 791 806 847 821 775 873 828 883 911 946 1010 928 975 865 918 837 802 768 731 693 691 762 699 694 721 713 681 668 734 667 693 651 688 703 700 757 737 710 734 754 743 753 748 785 740 807 846 886 915 969 996 1074 1224 1386 1366 1389 1495 1302 1231 1157 1017 922 818 847 858 835 874 901 899 1017 1051 1114 1254 1184 1225 1180 1127 1105 1045 999 926 774 872 840 853 864 881 900 853 895 919 923 921 886 900 884 892 795 775 820 733 796 748 783 802 776 761 831 744 767 817 818 786 815 776 860 918 913 919 968 1031 1073 1150 1165 1205 1276 1291 1269 1210 1156 1107 1079 1066 1000 976 958 945 941 960 963 974 1038 1042 1060 1101 1107 1102 1111 1045 1142 1066 1038 1080 1063 1051 1120 1119 1017 1085 1023 1027 969 1016 992 989 1003 1097 1075 1198 1190 1211 1212 1194 1118 1052 1026 946 917 889 877 802 854 832 818 885 868 873 914 929 860 896 831 774 736 711 726 720 755 661 708 722 678 732 691 682 667 678 717 700 652 661 653 623 640 663 643 648 677 682 706 737 656 723 723 696 748 737 685 739 740 743 787 765 820 712 750 777 727 685 752 786 789 818 823 831 790 793 747 772 730 802 743 753 767 717 781 785 807 839 875 879 910 893 987 886 968 1003 958 989 927 954 907 904 893 843 791 818 805 828 903 845 895 914 901 965 900 911 981 942 945 962 998 1008 966 1038 1071 1156 1134 1240 1322 1383 1561 1647 1698 1797 1817 1900 1711 1727 1766 1709 1750 1833 1959 2031 2183 2321 2266 2279 2267 2247 2111 2157 2091 1984 1811 1765 1631 1550 1506 1494 1464 1478 1454 1560 1532 1487 1392 1396 1273 1284 1147 1100 1119 1099 948 985 965 913 873 833 787 770 825 739 725 709 779 721 690 692 700 722 766 747 742 786 788 838 825 847 861 888 969 1046 969 992 927 858 791 769 770 725 754 735 693 746 722 736 759 826 851 891 922 1012 993 1043 1000 1073 1115 1186 1261 1324 1225 1169 1095 1085 1014 990 869 921 959 918 896 861 795 872 819 921 895 968 1026 960 941 977 900 920 863 915 857 845 856 843 832 762 815 775 742 772 706 705 716 678 652 705 691 678 731 714 717 742 743 730 673 736 653 615 692 628 628 692 634 635 604 608 644 654 639 660 637 627 588 637 627 625 636 666 567 637 564 621 625 614 626 637 619 628 599 605 669 635 568 619 622 606 609 627 614 651 689 674 732 682 740 719 767 714 735 739 708 667 717 674 637 648 667 664 677 712 690 651 683 697 747 682 721 746 813 739 765 683 725 671 733 649 698 649 679 665 661 614 649 638 624 675 683 636 700 737 776 733 756 809 814 843 946 971 1051 986 988 945 924 836 778 704 698 720 732 730 696 677 725 799 781 801 769 856 819 823 865 814 804 828 831 864 816 978 1026 1019 1092 1086 1076 1096 1074 997 947 903 894 845 821 812 788 719 822 744 774 781 806 834 886 948 900 881 887 837 836 819 773 729 717 769 729 680 706 683 665 640 678 692 649 700 643 675 674 694 708 688 729 840 760 785 826 757 756 747 698 689 677 708 634 697 616 604 633 655 661 667 649 690 700 756 686 695 640 628 602 654 626 616 613 616 611 583 607 574 612 601 643 652 686 670 722 770 812 828 891 828 860 767 681 708 632 625 684 619 624 668 634 675 673 686 713 655 768 738 814 765 753 760 773 772 766 728 693 668 702 611 598 638 632 612 589 672 623 659 649 682 635 697 684 699 684 700 703 658 701 672 640 615 655 678 614 674 649 625 681 673 704 737 717 715 731 654 700 631 659 679 738 673 650 702 687 673 688 752 688 746 755 822 709 725 743 808 722 717 695 757 728 731 752 804 806 856 828 898 886 918 911 1022 1012 1013 970 1003 988 956 887 838 851 849 860 817 748 768 804 744 810 810 782 764 736 880 863 804 787 833 780 786 746 738 733 714 679 657 630 664 699 611 662 736 691 639 688 702 734 754 784 804 870 890 923 970 902 1034 935 898 845 850 787 785 739 725 742 721 800 707 767 812 814 787 780 788 827 800 837 815 780 759 789 815 771 805 803 909 865 904 914 1005 916 894 921 904 907 914 847 965 883 870 946 826 777 769 773 757 716 772 750 736 822 770 850 814 759 855 741 769 763 786 784 792 668 717 717 657 650 646 661 664 693 626 679 651 630 704 666 694 686 650 667 605 653 623 666 635 674 683 665 660 706 702 691 703 761 743 747 750 780 796 815 807 885 813 808 834 776 743 774 758 738 804 802 849 847 829 874 880 864 903 890 943 1033 934 977 986 1027 1083 1111 1232 1325 1403 1503 1658 1726 1846 2009 2135 2265 2315 2512 2534 2550 2484 2342 2199 2125 1835 1815 1639 1620 1498 1522 1407 1514 1550 1593 1577 1644 1702 1729 1792 1691 1733 1761 1680 1683 1579 1502 1506 1506 1444 1461 1469 1329 1296 1216 1242 1064 1044 1106 1008 1103 1062 1178 1116 1286 1211 1235 1282 1344 1392 1386 1321 1359 1280 1227 1111 1014 956 897 925 937 869 909 879 900 889 944 958 953 973 965 1000 908 982 849 859 858 844 837 834 762 808 773 783 856 873 947 981 1139 1133 1257 1290 1262 1245 1136 1122 958 949 910 869 830 831 803 732 789 758 785 766 798 833 877 902 915 938 971 958 932 862 859 825 842 787 741 745 764 780 703 782 794 802 891 936 956 1053 1164 1156 1149 1204 1195 1112 1110 1202 1147 1122 1081 1080 997 981 912 947 946 964 1042 1069 1077 1083 1147 1167 1145 1078 1062 978 1016 976 937 897 831 833 891 773 784 781 801 775 795 841 793 798 817 787 762 791 705 671 729 711 660 731 684 667 649 670 681 673 744 697 714 698 752 746 700 723 793 758 760 746 720 712 784 765 788 809 771 813 840 906 915 958 982 988 1106 1134 1137 1192 1108 1160 1100 1172 1155 1041 1065 1053 1075 1083 1169 1137 1130 1206 1134 1157 1130 1092 1065 1060 1041 1054 1032 955 976 892 878 856 885 857 834 773 863 859 918 916 872 821 854 785 806 757 777 745 715 705 650 659 710 749 685 701 676 673 663 681 738 709 709 703 728 730 716 721 743 745 783 744 709 695 690 666 658 685 739 673 719 711 690 700 718 733 733 744 805 877 932 884 904 999 1069 1200 1195 1252 1380 1379 1437 1461 1502 1422 1326 1198 1101 1073 877 884 839 845 828 812 792 841 833 857 863 949 954 1053 1052 1077 1086 1067 1042 1039 877 858 773 756 760 730 675 735 696 645 633 655 623 635 627 626 648 621 650 609 649 597 642 666 652 635 641 580 652 646 597 614 656 668 678 676 695 707 668 701 754 790 760 818 845 878 878 867 842 789 828 767 743 740 717 667 742 687 707 690 703 693 698 696 722 763 723 770 799 786 847 826 817 827 801 784 780 697 723 736 724 751 700 726 793 737 763 772 775 849 781 762 821 859 845 877 891 896 961 929 933 953 1048 1118 1186 1242 1360 1444 1624 1719 1827 2063 2057 2130 2072 1904 1760 1708 1569 1424 1381 1230 1326 1274 1253 1191 1199 1261 1226 1270 1294 1308 1317 1396 1376 1405 1453 1449 1365 1312 1260 1242 1099 1026 1054 1038 900 939 959 919 949 946 949 893 926 923 1012 1051 1115 1137 1234 1293 1357 1263 1170 1116 1107 968 959 879 834 854 800 818 802 770 780 823 764 851 873 873 866 928 977 970 996 974 939 919 864 869 870 822 800 827 787 759 766 743 699 697 689 669 659 678 713 674 713 731 640 716 695 698 667 719 742 800 756 851 861 825 854 781 892 875 837 890 873 840 798 801 735 691 704 718 713 718 689 688 658 716 690 712 701 641 736 683 732 764 723 752 768 736 745 774 755 730 782 728 730 776 749 741 710 702 730 705 679 650 665 687 655 699 649 681 715 694 784 795 802 784 740 802 755 724 780 731 686 672 645 658 670 677 671 653 663 614 613 611 602 639 622 613 655 653 622 664 645 652 607 618 594 571 615 600 586 628 610 612 620 613 608 577 608 583 630 593 583 600 622 618 623 638 610 670 602 577 597 594 622 606 626 577 580 673 628 615 641 645 645 628 629 631 661 610 683 714 683 729 798 789 876 929 905 892 1007 1061 1129 1171 1172 1169 1209 1160 1059 1060 967 1015 948 923 922 906 879 817 809 867 829 830 901 875 936 955 1015 1041 1145 1208 1194 1179 1159 1183 1151 1081 1119 1107 1061 1036 1025 961 921 839 791 843 806 756 706 803 850 788 791 853 899 846 923 937 917 930 943 997 1012 1030 1018 1113 1067 1243 1108 1225 1177 1146 1095 1075 1069 1005 945 937 889 849 862 882 869 821 815 844 867 815 861 820 885 889 889 975 912 896 933 922 968 1001 930 989 1048 1088 1061 1112 1166 1213 1150 1143 1008 930 852 843 853 781 832 850 781 863 837 862 862 827 839 860 857 814 879 867 902 980 929 924 940 932 936 901 811 879 823 760 824 757 790 770 747 712 782 748 707 704 726 755 737 709 719 728 723 840 747 800 819 873 879 866 850 945 1031 1084 1060 1037 1030 964 932 837 841 811 750 732 724 745 750 707 695 699 685 684 684 758 715 744 721 771 830 864 841 836 784 761 704 710 728 720 752 670 693 710 690 696 714 737 751 722 743 677 728 744 701 710 693 730 754 723 775 741 824 750 795 780 809 865 839 817 781 782 764 716 741 745 696 691 724 710 688 741 750 717 719 799 767 743 841 805 814 800 830 828 791 797 802 801 789 708 697 737 751 759 735 799 815 831 815 874 846 870 880 874 850 870 853 934 862 903 939 914 934 906 993 1049 1042 1087 1198 1239 1316 1344 1424 1521 1581 1764 1807 1810 1885 1843 1883 1907 1870 1819 1659 1545 1539 1433 1466 1403 1360 1267 1337 1339 1294 1331 1351 1367 1400 1454 1473 1459 1463 1410 1445 1492 1498 1492 1434 1449 1416 1362 1285 1272 1190 1172 1044 1014 1083 1068 1036 956 958 959 956 1000 910 925 841 882 845 864 867 859 887 889 935 866 891 927 998 1021 975 1022 987 972 961 967 874 881 860 843 849 828 883 875 873 815 863 821 867 904 924 967 916 987 1000 1043 1095 1070 1199 1158 1250 1238 1392 1364 1466 1500 1631 1618 1727 1821 1898 1904 1937 1885 1782 1788 1642 1642 1536 1418 1323 1256 1251 1229 1130 1175 1212 1169 1173 1278 1180 1177 1248 1279 1314 1318 1456 1404 1482 1443 1409 1457 1437 1429 1392 1315 1273 1253 1230 1171 1102 1091 1038 1078 1078 1065 1023 932 902 836 889 850 880 857 780 850 770 847 864 835 848 879 859 811 809 782 811 768 732 777 730 788 785 791 736 757 726 743 757 703 796 738 715 747 704 774 817 846 884 846 895 948 992 950 993 936 979 940 942 900 960 883 876 848 891 828 844 777 781 813 785 841 838 838 815 849 858 849 902 862 814 900 907 863 814 808 802 777 848 807 786 745 762 753 722 728 783 726 757 714 631 791 717 752 740 732 715 717 701 653 636 686 682 691 716 665 654 654 701 661 697 678 704 722 680 744 677 596 719 731 685 729 729 742 775 805 839 809 829 843 829 838 889 892 934 859 922 892 887 796 840 835 776 795 739 817 831 831 861 880 871 905 909 823 892 956 870 919 917 919 968 997 1054 1055 1094 1086 1120 1210 1235 1245 1309 1293 1299 1350 1242 1176 1206 1158 1121 1018 1045 987 1056 971 971 976 1002 1062 1036 1146 1089 1149 1188 1234 1247 1261 1215 1126 1190 1123 1171 1148 1121 1059 1075 1087 1054 1021 972 921 931 923 844 868 873 831 909 805 919 972 959 928 974 930 867 826 806 821 800 812 871 863 824 843 907 897 877 878 942 920 884 841 787 777 796 698 687 737 720 712 765 737 668 748 654 683 689 646 686 673 659 736 724 743 730 765 788 788 752 688 714 662 683 706 685 690 603 650 629 675 598 617 605 646 615 636 633 639 642 619 665 663 668 708 685 685 727 669 685 691 655 639 658 664 701 679 686 718 718 715 768 754 692 720 671 674 713 621 697 690 682 667 745 696 709 724 758 609 750 703 686 681 690 689 698 691 687 680 668 709 706 705 701 639 635 686 627 661 642 659 655 619 656 712 731 703 782 684 694 741 700 709 731 700 698 769 719 690 699 691 652 730 713 727 714 720 740 690 642 674 686 699 725 725 796 797 838 783 872 844 861 898 869 949 968 995 1044 1033 978 995 1125 1049 1066 1082 965 954 987 941 939 949 948 1007 947 1058 1093 1158 1125 1181 1216 1145 1282 1312 1171 1189 1185 1130 1269 1190 1104 1133 1084 1167 1041 1088 1043 1078 1034 1048 1011 1034 970 978 1000 955 1024 929 938 996 957 931 952 895 905 902 884 832 789 840 792 785 785 817 764 813 779 773 752 714 693 703 771 736 691 723 716 715 696 678 687 715 659 700 710 656 663 678 685 639 679 674 685 645 623 687 627 646 611 649 655 643 663 664 625 602 574 600 630 632 672 665 692 689 689 679 670 680 629 664 631 635 621 626 667 679 625 702 669 709 744 684 729 676 712 672 724 676 662 690 642 657 643 659 671 606 623 614 617 641 639 570 643 639 595 605 680 619 619 650 651 610 633 623 630 633 642 614 618 649 615 641 600 621 585 605 612 615 587 607 630 641 648 650 638 630 674 640 611 625 607 620 645 646 734 695 674 713 679 840 726 767 768 728 830 774 743 683 727 704 691 673 666 645 649 621 623 677 646 646 635 658 692 669 687 652 677 666 710 722 690 715 698 663 701 683 650 703 667 613 622 645 627 622 631 664 597 581 621 595 641 598 562 597 576 591 587 586 627 570 620 620 602 589 626 601 630 561 558 572 612 621 585 595 583 681 564 584 603 608 648 573 621 597 619 631 580 603 532 600 601 662 650 618 646 612 653 620 625 640 717 709 691 676 704 778 749 754 756 710 677 692 684 707 635 677 645 668 610 655 617 655 620 667 648 669 580 683 627 672 640 718 715 713 705 723 684 713 709 717 680 673 656 613 687 620 631 689 631 634 615 604 642 648 610 645 682 627 720 687 678 729 777 781 808 851 845 878 866 831 840 810 756 766 761 746 750 735 696 682 623 692 660 672 650 656 688 713 716 706 740 756 717 762 816 841 881 922 955 1054</counts>
			</dataPoints>
		</scan>
	</xrdMeasurement>
</xrdMeasurements>