File: dataset/precursor_mixture/Nb2O5_CuO_LiCoO2.12-min.xrdml
<?xml version="1.0"?>
<xrdMeasurements xmlns="http://www.xrdml.com/XRDMeasurement/2.2" xmlns:xsi="http://www.w3.org/2001/XMLSchema-instance" xsi:schemaLocation="http://www.xrdml.com/XRDMeasurement/2.2 http://www.xrdml.com/XRDMeasurement/2.2/XRDMeasurement.xsd" status="Completed" recordIdentifier="{49E7EBE0-52B3-453C-963F-964389A27979}">
	<comment>
		<entry/>
	</comment>
	<sample type="To be analyzed">
		<id>dara-33-2</id>
		<name></name>
		<preparedBy></preparedBy>
	</sample>
	<xrdMeasurement measurementType="Scan" status="Completed" sampleMode="Reflection">
		<usedWavelength intended="K-Alpha 1">
			<kAlpha1 unit="Angstrom">1.5405980</kAlpha1>
			<kAlpha2 unit="Angstrom">1.5444260</kAlpha2>
			<kBeta unit="Angstrom">1.3922500</kBeta>
			<ratioKAlpha2KAlpha1>0.5000</ratioKAlpha2KAlpha1>
		</usedWavelength>
		<incidentBeamPath>
			<radius unit="mm">145.00</radius>
			<xRayTube id="1010048" name="Empyrean Cu LFF HR (9430 033 7310x) DK437873">
				<tension unit="kV">40.0</tension>
				<current unit="mA">15.0</current>
				<anodeMaterial>Cu</anodeMaterial>
				<focus type="Line">
					<length unit="mm">12.0</length>
					<width unit="mm">0.4</width>
					<takeOffAngle unit="deg">6.0</takeOffAngle>
				</focus>
			</xRayTube>
			<filter id="20010004" name="Beta-filter Nickel">
				<material>Ni</material>
				<thickness unit="mm">0.020</thickness>
			</filter>
			<sollerSlit id="21010002" name="Soller slits 0.04 rad.">
				<opening unit="rad">0.0400</opening>
			</sollerSlit>
			<mask id="22031000" name="Fixed mask 13 mm">
				<width unit="mm">9.00</width>
			</mask>
			<divergenceSlit id="22120001" name="Divergence slit 1°" xsi:type="fixedDivergenceSlitType">
				<distanceToSample unit="mm">50.00</distanceToSample>
				<height unit="mm">1.52</height>
			</divergenceSlit>
		</incidentBeamPath>
		<beamKnife id="29030100" name="Beam knife low"/>
		<sampleMovement xsi:type="spinningSampleMovementType">
			<spinnerRevolutionTime unit="seconds">1.0</spinnerRevolutionTime>
		</sampleMovement>
		<diffractedBeamPath>
			<radius unit="mm">145.00</radius>
			<antiScatterSlit id="22090040" name="AS slit 9 mm" xsi:type="fixedAntiScatterSlitType">
				<height unit="mm">9.00</height>
			</antiScatterSlit>
			<sollerSlit id="21020003" name="Large Soller slits 0.04 rad.">
				<opening unit="rad">0.0400</opening>
			</sollerSlit>
			<filter id="20030001" name="Large beta-filter Nickel">
				<material>Ni</material>
				<thickness unit="mm">0.020</thickness>
			</filter>
			<detector id="7010019" name="PIXcel1D-Medipix3 detector" xsi:type="rtmsDetectorType">
				<phd unit="keV">
					<lowerLevel>4.0</lowerLevel>
					<upperLevel>11.3</upperLevel>
				</phd>
				<mode>Scanning</mode>
				<activeLength unit="deg">5.020</activeLength>
			</detector>
		</diffractedBeamPath>
		<scan appendNumber="0" mode="Continuous" scanAxis="Gonio" status="Completed">
			<header>
				<startTimeStamp>2024-03-24T18:39:31-07:00</startTimeStamp>
				<endTimeStamp>2024-03-24T18:51:59-07:00</endTimeStamp>
				<author>
					<name>AutomatedUser</name>
				</author>
				<source>
					<applicationSoftware version="1.6 (94)">PANalytical Aeris Instrument Suite</applicationSoftware>
					<instrumentControlSoftware version="3.0.0 20211014">AERIS</instrumentControlSoftware>
					<instrumentID>2879380</instrumentID>
				</source>
			</header>
			<dataPoints>
				<positions axis="2Theta" unit="deg">
					<startPosition>9.99043322</startPosition>
					<endPosition>100.09495370</endPosition>
				</positions>
				<positions axis="Omega" unit="deg">
					<startPosition>4.99521661</startPosition>
					<endPosition>50.04747685</endPosition>
				</positions>
				<commonCountingTime unit="seconds">18.249</commonCountingTime>
				<counts unit="counts">9252 9467 9334 9416 9396 9316 9120 9314 9258 9375 9333 9084 9179 9307 9254 9341 9389 9262 9357 9304 9391 9289 9426 9125 9365 9406 9322 9146 9335 9374 9350 9147 9258 9348 9319 9298 9142 9322 9268 9323 9381 9262 9345 9206 9178 9250 9097 9417 9292 9211 9124 9270 9180 9143 9300 9291 9297 9301 9195 9334 9207 9267 9269 9135 9268 9257 9473 9318 9227 9377 9034 9145 9372 9235 9291 9292 9285 9330 9356 9296 9172 9416 9188 9310 9159 9247 9342 9217 9149 9355 9360 9414 9257 9485 9246 9195 9378 9054 9357 9343 9417 9267 9536 9264 9274 9163 9174 9149 9445 9250 9275 9173 9353 9426 9257 9211 9330 9322 9156 9326 9248 9193 9547 9230 9154 9115 9335 9328 9505 9148 9074 9413 9344 9339 9347 9484 9192 9273 9299 9418 9372 9198 9241 9097 9264 9318 9406 9224 9209 9278 9157 9070 9374 9084 9330 9099 9159 9242 9276 9381 9288 9387 9211 9253 9323 9156 9160 9308 9223 9194 9356 9551 9313 9300 9216 9237 9218 9187 9257 9488 9246 9268 9195 9389 9253 9379 9363 9426 9187 9330 9430 9170 9214 9233 9292 9310 9344 9274 9503 9285 9418 9438 9310 9272 9449 9320 9590 9439 9299 9451 9332 9289 9299 9279 9319 9222 9335 9305 9346 9333 9478 9519 9388 9253 9467 9417 9340 9398 9578 9413 9458 9384 9293 9349 9280 9341 9266 9373 9489 9318 9329 9503 9594 9317 9329 9406 9387 9376 9427 9489 9410 9391 9314 9422 9229 9361 9565 9311 9302 9561 9534 9457 9408 9280 9140 9367 9244 9348 9507 9465 9478 9433 9455 9378 9351 9579 9360 9458 9323 9433 9410 9423 9346 9401 9465 9449 9506 9459 9321 9397 9354 9200 9500 9395 9449 9529 9300 9476 9399 9464 9414 9537 9409 9316 9604 9175 9508 9309 9614 9333 9561 9299 9546 9387 9612 9391 9478 9508 9445 9457 9556 9576 9357 9581 9411 9483 9668 9456 9512 9492 9401 9463 9428 9504 9525 9680 9337 9434 9416 9351 9482 9475 9409 9518 9521 9469 9316 9681 9461 9610 9439 9636 9657 9563 9487 9482 9526 9513 9625 9579 9523 9442 9436 9318 9413 9509 9556 9431 9606 9465 9616 9554 9654 9555 9603 9615 9507 9524 9519 9607 9649 9319 9730 9603 9604 9568 9574 9404 9669 9510 9521 9620 9644 9610 9496 9561 9580 9577 9680 9630 9560 9388 9461 9662 9667 9647 9519 9586 9654 9735 9434 9677 9596 9375 9544 9560 9578 9680 9565 9698 9615 9498 9607 9641 9744 9689 9698 9606 9723 9720 9700 9723 9692 9769 9776 9627 9598 9451 9530 9776 9805 9795 9767 9622 9679 9699 9711 9742 9489 9541 9524 9832 9706 9500 9713 9609 9557 9812 9811 9732 9675 9762 9742 9750 9549 9611 9493 9690 9634 9803 9647 9727 9575 9648 9734 9643 9623 9835 9653 9644 9640 9773 9716 9706 9705 9662 9825 9824 9664 9997 9784 9659 9788 9788 9782 9719 9741 9837 9779 9717 9963 9605 9711 9830 9959 9657 9920 9764 9827 9808 9697 9878 9817 9955 9828 9798 9898 9761 9945 9625 10005 9845 9856 9847 9807 9712 9985 9745 9825 9845 9931 9921 9793 9742 10014 9689 10007 9944 9760 9914 9890 9820 9912 10119 9916 9845 10058 9995 9748 9977 9884 9832 10034 9727 9779 10009 9667 9945 9793 9821 9837 9955 9879 9940 9827 9739 9794 9954 9816 9953 9977 10173 9865 9891 10004 9931 10023 9912 9852 9876 10030 9934 9898 10095 9992 10101 9915 10043 10017 9989 10235 9928 10046 10054 10004 10016 9968 10073 9792 9904 10137 9993 10015 10108 10156 10043 10229 9972 10149 10032 10070 10035 9939 10090 10030 10217 9934 10029 10020 10001 10278 10103 10211 10194 10198 10184 10052 10175 10210 10139 10179 10247 10188 10104 10250 10204 10223 10293 10127 10362 10231 10461 10332 10335 10346 10533 10506 10713 10586 10791 10672 10750 10894 10916 11104 11286 11110 11242 11319 11422 11376 11636 11410 11258 10914 10749 10683 10551 10481 10388 10490 10229 10331 10353 10112 10304 10005 10075 10098 10293 10155 10224 10095 10372 10006 10108 9976 10283 10229 10245 10256 9984 10298 10124 10122 10121 10234 10071 10125 10147 10110 10159 10209 10101 10300 10144 10127 10207 10316 10195 10347 10234 10101 10302 10160 10295 10193 10244 10087 10227 10149 10094 10192 10094 10145 10197 10131 10402 10149 10399 10233 10129 10205 10340 10225 10216 10236 10263 10290 10269 10320 10433 10194 10241 10451 10242 10302 10308 10300 10271 10185 10476 10471 10406 10229 10316 10338 10423 10649 10584 10589 10704 10674 10637 10770 10999 11090 11005 11371 11429 11537 11451 11685 11991 11872 11985 12152 12148 12254 12258 12474 12527 12571 12884 12850 12991 12752 13086 13100 13498 13764 13577 13857 14055 14529 14335 14842 15357 15305 15786 16206 16492 16979 17281 18042 19054 20191 21233 22798 24726 26615 28788 31763 36064 40159 44933 51137 58054 66556 75548 86083 98601 111552 126791 144142 163413 184845 208312 232872 258068 278585 286977 277786 252009 221029 190678 160926 129477 98724 73108 54032 40642 31659 26087 21989 18978 17312 16247 15661 15176 14914 14779 14740 14302 14320 13918 14064 13899 13980 13586 13664 13600 13421 13279 13227 13091 12735 12833 12368 12187 12216 12135 11910 11662 11565 11470 11673 11632 11395 11355 11220 11258 11236 11408 11264 11242 11203 11039 11265 11165 11272 11177 11076 11101 11471 11116 11184 11172 11218 11299 11343 11268 11482 11304 11512 11537 11649 11674 11841 11900 12024 12127 12060 12121 11936 11855 12008 12016 12001 11967 12073 11730 11759 11989 11706 11990 12010 12207 12085 12064 11832 12087 11972 11769 11870 11930 12132 12001 12007 11836 12102 11926 11937 11918 12128 11935 11854 11822 11839 11984 11983 11950 11699 11860 11920 11928 11819 12015 11962 11882 11873 11887 11981 11834 11754 11847 12042 11756 11820 11906 11851 11899 11965 11681 11938 11822 11738 11764 11838 11883 11829 11712 11804 11829 12054 11730 11649 11798 11666 11635 11779 11756 11968 11817 11795 11710 11888 11738 11949 11785 11894 11863 11738 11741 11742 12089 11705 11695 11750 11964 11891 11705 11661 11749 11813 11755 11598 11625 11544 11585 11664 11693 11542 11481 11529 11547 11466 11513 11607 11492 11429 11596 11523 11293 11695 11233 11318 11584 11404 11799 11451 11416 11576 11436 11380 11436 11657 11367 11410 11677 11495 11445 11241 11434 11433 11413 11448 11358 11428 11356 11131 11400 11302 11392 11192 11365 11327 11249 11345 11307 11447 11395 11472 11443 11380 11208 11147 11332 11511 11382 11435 11453 11245 11473 11355 11113 11404 11577 11323 11319 11244 11402 11448 11264 11231 11408 11447 11417 11232 11454 11353 11190 11492 11428 11132 11321 11236 11359 11362 11211 11366 11280 11389 11254 11223 11280 11389 11414 11348 11243 11382 11299 11307 11442 11386 11303 11207 11270 11349 11531 11570 11593 11499 11372 11371 11529 11512 11735 11798 11826 12000 11933 12013 12122 12182 12248 12482 12725 12761 13096 13693 13948 14422 14696 15499 16068 16930 17622 18337 19828 20792 21796 22808 24400 25455 26692 27134 27718 28276 27289 26236 24881 23441 22211 20836 18929 17545 16416 15232 14310 13526 12984 12610 12133 12022 11675 11670 11561 11388 11555 11443 11407 11305 11370 11274 11321 11170 11166 11317 11247 11133 11167 11166 10947 11036 11145 10984 11094 11017 10877 11060 11215 11037 11048 10951 11021 10958 11106 10750 10943 11100 10869 10937 10816 10927 10889 10946 10759 10968 10838 10821 10830 10956 10838 11145 10870 10843 10796 10701 10825 10699 11004 10853 10979 10964 10836 10829 10887 10966 10871 10886 10826 10753 10878 10977 10787 10885 10814 10760 10924 10881 10834 10883 10874 10834 10743 10713 10797 10842 10780 10893 10719 11063 10812 10823 10808 10836 10997 10936 10976 10773 10873 10854 10722 10803 10730 10800 10715 10728 10777 10676 10864 10601 10859 10565 10769 10609 10868 10766 10684 10511 10475 10707 10513 10726 10448 10695 10643 10691 10665 10709 10710 10681 10608 10634 10675 10698 10637 10617 10569 10433 10540 10763 10729 10757 10632 10672 10737 10636 10751 10640 10663 10671 10821 10697 10574 10620 10672 10576 10612 10743 10391 10768 10746 10607 10747 10694 10586 10723 10708 10580 10552 10710 10739 10548 10655 10637 10512 10665 10577 10592 10609 10431 10476 10532 10591 10458 10722 10795 10691 10477 10626 10393 10562 10637 10571 10375 10447 10533 10603 10352 10369 10538 10539 10674 10506 10590 10389 10567 10515 10640 10430 10661 10308 10654 10436 10188 10476 10385 10490 10488 10530 10648 10652 10571 10548 10523 10560 10558 10523 10485 10632 10502 10550 10503 10878 10535 10408 10482 10303 10495 10546 10455 10464 10802 10612 10716 10729 10496 10586 10533 10640 10608 10540 10838 10678 10570 10751 10624 10785 10727 10572 10784 10531 10764 10634 10733 10686 10686 10534 10666 10545 10468 10452 10478 10695 10293 10472 10338 10520 10491 10493 10311 10545 10349 10501 10499 10487 10666 10563 10328 10436 10444 10556 10570 10475 10668 10522 10895 10568 10598 10506 10397 10523 10371 10494 10280 10365 10463 10300 10233 10429 10390 10445 10472 10265 10447 10360 10410 10421 10390 10121 10406 10474 10422 10460 10354 10384 10360 10184 10405 10377 10343 10446 10163 10491 10448 10509 10128 10444 10273 10418 10425 10311 10223 10462 10198 10257 10229 10376 10283 10488 10302 10374 10307 10412 10255 10406 10232 10380 10191 10310 10298 10473 10192 10393 10322 10553 10363 10313 10177 10324 10287 10529 10504 10353 10490 10214 10325 10141 10392 10341 10430 10192 10297 10094 10425 10368 10312 10415 10497 10434 10376 10410 10187 10406 10443 10292 10465 10350 10355 10442 10303 10353 10387 10251 10403 10374 10273 10330 10183 10274 10382 10581 10511 10283 10463 10401 10357 10424 10663 10507 10640 10269 10414 10533 10404 10382 10496 10329 10224 10393 10307 10343 10517 10334 10437 10393 10357 10512 10517 10396 10493 10374 10449 10414 10375 10409 10335 10360 10443 10308 10536 10451 10452 10335 10622 10367 10357 10568 10244 10655 10366 10376 10450 10555 10594 10511 10623 10500 10503 10611 10571 10847 10682 10729 10721 10790 10759 10712 10823 10729 10793 10670 11079 10851 10927 11068 10849 11216 11318 11336 11402 11542 11596 11757 12021 12413 12459 13070 13509 14115 14409 15433 16344 17268 18126 19129 20540 21736 23125 24342 25049 25786 26452 26756 26290 25361 24492 23445 22248 20913 19932 18743 17258 16315 15307 14195 13679 13083 12523 12057 11935 11654 11578 11534 11145 11104 11078 11126 11050 11011 11008 11054 10926 10736 11271 10908 11144 11330 11330 11162 11376 11622 11723 11739 11899 12171 12320 12433 12900 13202 13309 14092 14323 14880 15308 15616 16025 16309 16408 17045 16411 16453 16098 15513 15139 14549 13921 13707 13271 12602 12417 11859 11561 11328 11288 11168 10968 11057 10844 11045 11086 10769 10606 10857 10727 10811 10823 10601 10663 10604 10617 10816 10535 10606 10547 10418 10526 10408 10332 10533 10658 10466 10201 10371 10449 10337 10390 10284 10353 10366 10184 10235 10226 10266 10186 10134 9943 10293 10372 10294 10135 10260 10255 10488 10290 10274 10147 10155 10419 10312 10270 10312 10134 10189 10255 10140 10348 10222 10244 10236 10305 10335 10323 10325 10273 10128 10127 10200 10344 10182 10255 10025 10251 10301 10175 10016 10115 10224 10327 10144 10284 10303 10175 10233 10290 10215 10103 10267 10136 10236 10256 10223 10192 10192 10297 10158 10273 10232 10221 10248 10297 10153 10304 10218 10221 10398 10242 10136 10282 10169 10206 10183 10200 10064 10227 10359 10165 10095 10275 10096 10016 10287 10179 10153 10118 10169 10021 10357 10149 10187 10033 10026 10008 10126 9984 10073 10417 10026 10035 10120 10120 10013 10214 10230 10126 10194 10196 10053 10042 10024 10283 9992 10302 10273 10071 9930 9894 10001 10254 10142 10209 9959 10037 9940 10111 10034 10045 10138 10180 10137 10111 9877 10048 9809 10128 10214 10250 10148 10111 10060 10033 9987 10166 10179 10067 10124 10186 10101 9981 10159 10012 10338 10352 10119 10082 10029 10243 9992 9980 9961 10137 9893 10264 10215 10102 10175 10278 10316 10115 10194 10063 9929 10028 10108 10040 9979 10182 9998 9957 10035 9925 10111 10001 10116 10112 10108 9974 10104 10087 10248 10084 10074 10071 9859 10009 10026 10080 10191 10119 9957 10083 10163 10120 10151 10024 10000 10330 10147 10190 9991 10054 10122 10075 10333 10086 10072 9970 10077 10173 10285 10124 10170 9973 9997 10007 10182 10017 10137 10058 9979 9976 10084 9993 10246 10052 10078 10049 10069 9872 10037 10275 9951 10015 10051 10093 9982 10182 10134 10163 10314 9939 10141 10133 9964 9944 10087 9953 10167 9876 10237 9956 10183 9984 9941 9954 9823 10031 9997 9938 9891 10034 9854 9996 10040 10125 10023 9996 10267 10206 10147 10446 10467 10181 10197 10326 10291 10228 10240 10405 10287 10527 10398 10593 10313 10541 10364 10347 10335 10321 10307 10192 10220 10347 10108 10203 10159 9993 10138 10147 10006 10028 9988 10086 10057 10179 9852 9912 9932 10113 10070 9981 10063 10138 9890 9991 9916 10085 9982 10157 9913 10173 9985 9936 10182 10009 9930 9891 10072 10161 9738 9798 10007 9984 10215 9995 9800 10181 9775 9968 9978 9948 9948 9822 9934 10029 9796 9830 9990 9981 9902 9959 10166 9903 10206 9934 10128 10169 9901 9959 10013 9894 10116 9949 9966 9972 9946 9982 9821 9931 9959 10130 10006 9941 10061 9967 10071 9842 10029 9853 9777 9897 9876 9992 10059 10012 9913 9926 9804 9810 9828 9965 9940 10012 9929 9758 10051 9996 10114 10083 9814 9889 9816 9943 9931 9882 10066 10085 9949 9857 10135 9877 10029 10081 9836 9884 9850 9969 9942 9833 10003 9935 9964 10047 9979 9933 10149 10149 10047 10147 10009 10061 10158 10192 10031 10148 10277 10144 10358 10123 10346 10090 10266 10409 10214 10401 10178 10302 10059 10283 9964 10117 10312 9943 10062 10032 9836 10032 9854 10079 9873 10011 9857 9775 9930 9978 9943 9862 9872 9919 10079 9888 9894 9962 9735 9812 9733 9811 9980 9973 9940 10000 10075 9982 9870 9859 9941 9871 10030 10041 9812 9974 9995 9855 10021 9964 9838 10027 10014 10028 9946 10042 10071 10047 10208 9956 10054 9948 10027 9911 9920 9939 10191 9997 9918 9901 9995 9929 9946 9932 9977 10014 10081 10221 10070 9933 10026 10075 9930 10101 9882 10045 9875 9966 9773 9636 9833 9923 9896 10159 10026 10132 9783 10040 10026 9981 10132 10072 10021 9965 10071 9844 9810 9964 10065 9838 9758 10080 10154 10138 10010 10111 10020 10082 10024 9950 10141 9965 10119 10110 10029 9963 9881 10207 9917 9941 9876 10078 9854 10154 10119 10078 10027 10285 10185 10203 10080 9928 10086 10077 10109 9980 10016 10096 9983 10112 10053 10046 10066 9985 10220 10050 10121 10153 10225 10317 10239 10278 10235 10401 10498 10541 10712 10750 10706 11009 11352 11477 11774 11992 12551 12843 13562 13914 14697 14967 15650 15743 16283 16099 16006 15768 15705 15106 14883 14412 14222 14143 13650 13192 12906 12562 12169 11576 11423 11171 11066 10790 10745 10682 10466 10706 10408 10487 10539 10551 10506 10543 10744 10637 10578 10640 10798 10999 10976 11233 11547 11611 11913 12020 12053 12512 12535 12535 12774 12686 12355 12558 12169 12071 11809 11686 11729 11395 11280 11229 11156 10896 10609 10778 10495 10406 10393 10383 10492 10526 10599 10442 10599 10804 10892 11044 11346 11845 12059 12374 12631 12814 13136 12759 12724 12222 11975 11888 11618 11790 11682 11562 11482 11368 10922 10705 10374 10357 10228 10119 10163 9986 10148 10076 10135 9990 9776 10167 9875 10083 10040 10049 9904 10133 10072 9866 10021 9928 9941 10041 10017 9898 10069 10114 10090 10044 10081 10033 9938 10081 10019 10099 10153 9924 9873 9967 9865 10036 9982 10075 10111 10126 10071 10046 9965 10209 10064 10017 10051 9924 10204 10296 10227 10079 10243 10331 10382 10391 10482 10528 10729 10725 10986 11088 11484 11987 12465 13166 14180 15356 16947 18702 20446 22250 24018 25163 25329 23332 20652 18446 17264 16586 16861 17200 17282 17301 16218 14705 13320 12069 11222 11016 10649 10357 10293 10300 10169 10270 10123 10263 10162 10207 10065 10109 10287 10068 10047 10016 10195 10004 10166 9949 9970 10005 9821 10050 9980 10081 9994 9906 10112 9955 10085 10047 10030 10063 10121 10014 10163 10371 10557 10582 10833 10943 11074 11097 11392 10645 11002 10962 10724 10665 10665 10265 10380 10508 10404 10300 10314 10279 10248 10052 10024 9812 9853 9910 9873 9750 9966 9895 9909 9988 9823 9859 9847 9846 9936 9826 10105 9820 9918 10029 9763 9813 9984 9854 9909 9793 9852 9933 9906 9683 10007 9958 9940 9898 9635 9518 9920 9772 9936 9777 9983 9839 9744 9597 10048 9921 9864 9872 9864 9836 9963 9645 9950 9912 9983 9703 9973 9783 9834 9749 9780 9866 9795 9893 9885 9922 9890 9733 9884 10000 9923 9596 9832 9692 9919 9866 9861 9743 9743 9901 9764 9903 9836 9710 9776 9932 9738 9866 9732 9688 9845 9830 9767 9775 9685 9892 9823 9649 9949 9864 9778 9929 9748 9945 9895 9768 9890 9829 9695 9796 9532 9861 9923 9751 9725 9976 9680 9868 9999 9822 9878 9926 10068 9946 9845 9848 9695 9949 9884 9941 9999 10153 9840 9872 9814 9898 9845 9851 9889 9765 9822 9991 9786 9907 9865 9760 9881 9783 9960 9807 9918 9708 9726 9840 9991 9687 9861 9905 9560 9902 9827 9788 9967 9776 9911 9842 9732 9902 9732 9994 9866 9869 9826 9702 9778 9723 9850 9821 9720 9942 9840 9931 9910 9845 9748 9895 9739 9812 9927 9786 9719 9679 9774 9822 9879 9628 9710 9963 9751 9791 9949 9754 9772 9864 9676 9773 9771 9823 9858 9717 9879 9845 9664 9762 9826 9938 9830 9747 9924 9742 9900 9873 9718 9904 9952 9596 9843 9924 9871 9779 9736 9818 9857 9831 9762 9873 9684 9944 9794 9845 9623 9898 9903 9990 9807 9807 9926 9483 9873 9866 9806 9681 9941 9787 9751 9694 9532 9914 9765 9880 9783 9850 9775 9782 9929 9726 9991 9920 9880 9987 9806 9764 9804 9890 9773 9902 9713 9856 9752 9802 10010 9880 9970 9813 9709 9837 9908 10100 9795 10079 10059 9968 9995 10057 10109 10144 10040 10211 10017 10147 10054 10314 10188 10183 10263 10158 10411 10157 10383 10410 10279 10391 10266 10229 10114 10110 10100 10068 9988 10231 10177 10339 10169 9889 10180 9970 10039 10027 9783 9927 9870 9892 9919 9797 9909 9701 9922 9708 9859 9779 9700 9846 9832 9799 9777 9771 9847 9745 9640 9806 9974 9794 9900 9722 9560 9957 9766 9855 9733 9849 9965 9907 9889 9769 9713 9532 9772 9643 9743 9914 9822 9913 9791 9818 9913 9917 9877 9676 9641 9680 9738 9627 9822 9809 9701 9809 9933 9709 9789 10055 9769 9828 9938 9894 9584 9748 9912 9850 9751 9974 10019 9767 9708 9904 9795 9645 9886 9615 9794 9851 9801 9811 9751 9745 9742 9767 9730 9969 9844 9883 9894 9777 9923 9701 9718 9751 9767 9901 9704 9581 9854 9933 9744 9964 9772 9813 9882 9711 9856 9729 9930 9781 9693 9879 9799 9929 9924 9927 9835 9955 9700 9964 9984 9761 9835 10070 9836 9907 9792 9764 9973 10089 9875 10005 9863 9902 9863 9844 9901 9914 9931 9802 10035 9985 10074 10069 9955 10026 9916 10067 10028 10226 9992 10082 9945 10068 9826 9940 9901 9900 9901 10002 9909 10038 9962 10088 9988 10119 9873 9853 9851 9847 9908 9964 9738 9849 9823 9873 10173 9936 9978 10056 10018 10195 9977 10041 10233 10120 10355 10107 10160 10164 10284 10452 10287 10604 10468 10507 10741 11065 11013 10910 11117 11315 11381 11422 11546 11758 11703 11981 12163 12306 13035 13417 14063 14510 15502 16366 17375 18133 18309 18403 17647 16699 15593 14796 14007 14014 14027 14101 14480 14003 13866 13692 12824 12111 11656 11227 10989 10574 10660 10550 10198 10211 10098 10055 10240 9985 10067 9945 10164 9977 10022 9915 10032 9911 9977 10206 9943 10126 9749 9933 9999 9827 10046 9944 9869 9906 9864 10013 10042 9882 9956 10037 9945 9941 10034 10073 10048 10200 10265 10463 10097 10282 10192 10309 10429 10168 10415 10515 10319 10688 10629 10667 10989 11114 11252 11381 11862 12045 12478 12796 13074 13172 12989 12883 12777 12227 12364 12247 12273 12145 11896 12079 12171 12026 11663 11541 11237 11153 10841 10696 10536 10428 10329 10284 10220 10003 10309 10110 10121 9987 9894 10132 9837 10020 10059 9954 9793 9945 9910 9643 9777 9891 9811 9748 9862 9619 9975 9741 9657 9788 9886 9624 9666 9684 9958 9732 9781 9683 9905 9680 9909 9982 9938 9699 9713 9763 9803 9742 9844 9722 9705 9884 9630 9809 9747 9622 9807 9898 9659 9732 9679 9770 9819 9817 9610 9730 9716 9865 9764 9884 9894 9854 9707 9791 9970 9716 9786 9613 9844 9919 9736 9751 9779 9793 9849 9819 9754 9769 9660 9742 9919 9788 9771 9838 9903 9867 9719 9913 9817 9842 9863 9828 9634 9820 9855 9948 9809 9792 9717 10067 9805 9632 9746 9813 9844 9972 9913 9892 9707 9974 9717 9944 9811 9886 9754 9547 9656 9702 9894 9827 9579 9780 9931 9668 9918 9891 9829 9805 9888 10094 9741 9813 9748 9920 9719 9953 9838 9773 9810 9851 9919 9812 9690 9869 9759 9599 9898 9822 9949 9862 9921 9903 9915 9893 9892 9836 9934 9650 9935 9925 9889 9780 9953 9898 9792 9964 9982 9994 9760 10108 9695 9963 10101 9827 9892 9924 10021 9713 9998 9916 9787 9940 9905 9964 10079 9843 9799 10054 9895 10174 9804 9899 9909 10022 9880 9991 10030 9845 9746 9883 9755 9939 9972 10040 9960 10126 9949 9996 9917 9837 9949 10074 9967 10074 10059 10182 9913 9829 9799 10032 9971 9953 9910 9878 9813 9909 9910 9917 9871 10068 9839 10092 9835 10047 10017 10166 9990 9867 10085 10095 10082 9976 10070 10097 9968 10229 10003 10269 10109 10214 10264 10173 10327 10138 10301 10082 10213 10218 10051 10535 10357 10408 10361 10262 10292 10441 10534 10573 10434 10652 10688 10729 10887 11020 11223 11194 11235 11198 11237 11164 10992 10634 10544 10720 10631 10584 10663 10571 10558 10562 10547 10481 10473 10484 10455 10378 10553 10737 10824 10963 11100 11151 11417 11683 11775 11924 11821 11822 11604 11507 11301 11505 11365 11215 11293 11359 11292 11281 11305 10992 10990 10827 10760 10627 10451 10484 10354 10346 10231 10150 10235 10095 10262 10101 10044 10068 10062 10018 9837 9941 10033 9967 9910 9873 9846 9818 9834 9869 9888 9798 10057 9937 9978 9879 9864 9840 9967 9889 10019 9760 9848 9907 9875 9795 9905 9932 9742 9986 9885 9803 10134 9976 9743 10035 10159 10343 10076 10143 10061 10265 10150 10111 10205 10117 10363 10057 10226 10388 10280 10359 10244 10518 10385 10212 10731 10541 10700 10766 10823 10746 10762 11167 11212 11105 11319 11543 11661 11945 12072 12314 12219 12488 12592 12792 12391 12517 12322 12094 11920 11760 11631 11688 11709 11636 11460 11469 11220 11435 11057 10990 10739 10659 10682 10497 10250 10336 10223 10287 10294 10233 10228 10083 10267 10136 10101 10117 10181 10108 10126 10150 10035 9956 10038 10050 10015 9879 9855 9810 9786 10040 9960 9836 9961 9866 9869 9607 9983 9790 10125 9843 9958 9773 9673 9585 9922 9799 9808 9691 9810 9874 9918 9866 9847 9819 9810 9933 9773 9803 9633 9828 9597 9770 9849 9777 9848 9803 9713 9817 9757 9758 9728 10126 9781 9781 9995 9641 9627 9819 9728 9825 9758 9842 9683 9854 9702 9823 9651 9803 9929 9861 9806 9786 9809 9692 9779 9950 9843 9786 9881 9764 9667 9842 9827 9788 9885 9816 9808 9773 10001 9874 9888 9764 9759 9979 9861 9797 9867 9712 9769 9997 9791 9865 9773 10049 9965 9685 9875 9843 9845 9726 9805 9845 9769 9789 9942 9772 10010 9702 9598 9732 9757 9782 9932 9573 9817 9865 9940 9823 9762 9904 9911 9950 9908 9734 9833 9890 9778 9871 9940 9974 9947 9886 10062 9876 9768 9782 9788 9920 9846 9971 9879 9933 9800 10080 9813 9811 9808 9789 9987 9612 9772 9778 9722 9950 9876 9768 9870 9816 9796 9863 9766 9910 9713 9784 9822 9866 9866 9786 9921 9921 9754 9944 9763 9747 9910 9907 9882 9861 9698 9863 9681 9850 9830 9706 9911 9745 9870 9619 9714 9922 9951 9830 9790 9643 9636 9717 9722 9871 9832 9870 9751 9772 9768 9778 9825 9972 9556 9776 9877 9806 9818 9810 9881 9708 9810 9768 9693 9849 9684 9990 9879 9739 9811 10071 9906 9827 9681 9938 9925 9793 10022 9910 9902 9788 9926 9867 9866 9800 9775 9918 9838 9579 9934 9685 9943 9877 9720 9860 9884 9829 9714 9925 9915 10002 9819 9779 9791 9827 9879 9704 9818 9709 9773 9810 9742 9868 9673 9841 9739 9864 9640 9877 10068 9683 9788 9934 9807 9815 9863 9831 9745 9888 9756 9787 9869 9812 9940 9959 9992 9883 9756 9974 9874 9935 9971 9807 9790 9930 9909 9774 9755 9672 9855 9637 9860 9809 10100 9801 10128 9901 9947 10091 10102 10098 10125 10050 10032 10130 10260 10459 10862 10798 10906 11344 11352 11617 11710 12083 12360 12232 12305 12104 12247 11747 11691 11566 11516 11754 11548 11822 11669 11756 11781 11792 11511 11759 11441 11291 11459 11658 11511 11645 11758 11818 11920 12008 11967 12046 11885 11968 12035 11967 11894 12021 11731 11878 11792 11720 11643 11521 11495 11421 11340 11284 11196 10958 11168 11065 10917 10918 10693 10465 10468 10398 10510 10327 10147 10369 10114 10372 10166 10051 10116 9998 10108 9969 10193 9967 9965 9935 9989 9755 10055 10075 10013 10009 10065 9921 9964 10063 9973 10066 9916 9894 10086 9722 9924 9867 9955 9804 9812 10042 10028 9765 9851 9879 9925 9793 9953 9754 10157 9855 10217 9872 9890 9994 10016 10090 10039 10314 10212 10385 10305 10316 10400 10579 10694 10651 10913 10842 10994 11210 11231 11410 11427 11216 11432 11280 11216 11050 10880 11047 10777 10750 10729 10669 10615 10582 10713 10744 10516 10468 10424 10441 10419 10313 10208 10176 10132 10079 9843 9935 9907 9863 9773 9818 9786 9798 9898 9767 9690 9962 9780 9887 9836 9763 9744 9780 9519 10000 9827 9647 9910 9712 9746 9722 9705 9834 9863 9786 9832 9880 9803 9785 9865 9851 9744 9706 9794 9811 9946 9668 9918 9850 9737 9947 9814 9777 9782 9696 9770 9609 9805 9729 9829 9951 9815 9609 9790 9818 9815 9849 9899 9897 9866 9846 9718 9736 9863 9727 9669 9836 9803 9775 9817 9843 9679 9887 9587 9763 9766 9832 9609 9737 9834 9625 9875 9751 9757 9846 9806 10069 9804 9889 9760 9825 9637 9656 9817 9619 9771 9767 9919 9777 9707 9846 9608 9667 9655 9653 9794 9713 9775 9804 9655 9721 9703 9935 9569 9599 9916 9598 9801 9816 9762 9886 9743 9877 9957 9793 9833 9839 9873 9669 9740 9861 9731 9662 9683 9965 9806 9756 9762 9721 9641 9721 9852 9729 9906 9933 9882 10025 9740 9946 9996 9951 9817 10099 9991 9983 10006 9870 10198 9884 10159 9937 10308 10263 10287 10289 10443 10352 10532 10575 10892 10765 10807 10984 10909 11048 11106 10795 10876 10699 10717 10707 10580 10779 10455 10521 10555 10645 10442 10463 10489 10477 10379 10369 10133 10186 10017 10247 10063 10075 10076 10002 10064 9985 9925 10042 10114 10209 10121 10219 10124 10162 10109 10303 10618 10554 10865 11026 11407 11723 12629 13381 13910 14255 14606 14102 13056 11887 11473 10870 10807 10770 10874 10867 10773 11445 11660 11966 12060 12170 11965 11531 11133 10603 10287 10320 10009 10182 9964 10001 9983 10247 10158 10208 10214 10335 10158 10075 10479 10598 10680 10776 10854 10982 11510 11525 11806 11919 11697 11670 11250 10915 10782 10721 10374 10629 10594 10734 10639 10884 10997 10894 10764 10849 10597 10692 10480 10440 10165 10403 10222 10217 10251 10348 10184 10132 10057 10090 9939 9982 10306 10226 10217 10183 10157 10162 10114 10058 10013 10107 9984 10100 9944 10074 9912 10086 10056 10131 9915 9928 10169 9920 9961 9858 9963 9936 9660 9946 9837 9714 9643 9802 9879 9707 9751 9666 9747 9835 9756 9531 9831 9789 9731 9786 9713 9825 9723 10051 9774 9850 9936 9635 9892 9813 9542 9712 9526 9626 9880 9783 9645 9653 9810 9625 9835 9856 9787 9574 9772 9850 9810 9802 9746 9715 9781 9818 9944 9771 9825 9950 9609 9866 9841 9809 9680 10109 9775 10081 9880 9777 9760 9749 9964 9999 9876 10005 9728 9838 9919 9686 9620 9911 9739 9691 9782 9657 9675 9788 9785 9869 9772 9895 10026 9633 9890 9757 9648 9820 9935 9697 9691 9742 9707 9712 9632 9804 9808 9907 9684 9818 9782 9688 9781 9867 9757 9805 9882 9736 9893 9831 9862 9759 9887 9827 9656 9801 9792 9759 9857 9863 9678 9691 9839 9732 9813 9592 9567 9622 9754 9700 9673 9904 9741 9822 9623 9924 9966 9617 9937 9623 9798 9783 9873 9832 9787 9793 9723 9796 9865 9741 9579 9704 9545 9767 9684 9672 9662 9749 9845 9585 9824 9808 9663 9710 9814 9919 9783 9913 9871 9780 9648 9785 9771 9870 9739 9925 9863 9985 10007 9826 9973 9926 9806 9869 9918 9838 9910 9749 9729 9632 9795 9843 9861 9932 9824 9502 9758 9582 9861 9608 9649 9721 9646 9696 9841 9664 9587 9771 9743 9729 9640 9546 9690 9769 9574 9892 9750 9752 9928 9730 9731 9842 9790 9784 9887 9904 9484 9761 9736 9585 9747 9744 9745 9726 9585 9677 9688 9679 9649 9788 9825 9809 9447 9733 9790 9859 9759 9704 9881 9596 9920 9620 9680 9834 9787 9907 9810 9840 9775 9616 9867 9865 9821 9690 9768 9748 9743 9800 9941 9999 9988 9639 9993 10034 9963 10080 9868 9918 9935 9899 10094 9848 9918 9854 10183 10146 9982 9758 9981 9856 10139 9909 10051 10249 9952 10409 10304 10294 10282 10340 10471 10632 10648 10855 10753 10982 10976 10697 10676 10713 10645 10543 10499 10634 10395 10459 10527 10493 10280 10325 10346 10312 10339 10318 10294 10434 10180 10145 9974 10123 10067 9979 9996 9909 9879 10074 9795 9888 10063 9968 9983 9904 9846 9913 9830 9863 9843 9886 9902 9871 9753 9768 9979 9772 9907 9944 9815 9744 9717 9855 10078 9794 9684 9883 9889 9975 10032 9733 9686 9781 9699 9917 9855 9811 9795 9637 9579 9829 9723 9746 9877 9741 9677 9758 9745 9701 9762 9745 9610 9704 9588 9745 9842 9697 9781 9830 9784 9788 9866 9776 9715 9749 9796 9874 9908 9774 9768 9897 9786 9608 9735 9830 9716 9725 9709 9810 9832 9793 9875 9877 9726 9751 9658 9878 9909 10085 10001 10037 10064 9947 9930 9848 10033 9947 9918 9963 9917 9898 9843 9749 9878 9948 9899 9973 9838 9941 10060 10153 9936 9856 9887 10074 9912 9986 9881 10000 10167 10204 10014 10259 10056 10393 10404 10501 10415 10575 11003 11141 11267 11555 11955 12272 12230 12445 12528 12113 11628 11399 11186 10988 10720 10700 10744 10743 10823 10704 10806 11205 10977 11176 11168 11187 10789 10645 10585 10295 10251 10078 10077 10035 10167 9958 9992 9931 10133 9997 9979 9992 9886 9896 9981 9863 9868 9846 9983 9902 9891 9901 10047 10039 9915 9762 9638 10068 9863 9973 10014 9795 10046 9776 9837 9829 9848 9998 9808 9982 9954 9932 9603 9815 9625 9956 10034 10034 9935 9909 10252 10023 10249 10051 10484 10291 10377 10818 10731 11134 11144 11265 10841 10733 10327 10389 10119 10236 9997 10216 10009 10182 10284 10108 10496 10331 10332 10564 10429 10355 10257 10171 10334 10007 10029 9874 9985 10010 9943 9894 9635 9814 9709 9721 9798 9690 9971 9930 9684 9789 9575 9740 9833 9760 9875 9774 9830 9809 9853 9899 9921 9804 9824 10032 9745 9892 9864 9924 9880 10042 9618 9765 9789 9927 9845 9981 9752 9972 9741 9765 9831 9863 9805 9879 9567 9887 9879 9812 9737 9699 9906 9837 9958 9728 9689 9916 9810 9696 9720 9749 9640 9761 9944 9955 9861 9888 9688 9775 9878 9790 9868 9763 9859 9929 9863 9751 9854 9718 9844 9749 9714 9525 9793 9717 9802 9719 9787 9810 9778 9688 9743 9834 9827 9552 9692 9663 9765 9762 9907 9783 9837 9789 9885 9500 9827 9715 9820 9703 9763 9858 9832 9699 9722 9755 9690 9430 9741 9758 9611 9716 9706 9656 9652 9700 9655 9557 9898 9834 9632 9648 9772 9748 9775 9735 9819 9640 9613 9593 9595 9762 9693 9781 9809 9696 9770 9739 9656 9661 9635 9837 9797 9793 9742 9782 9701 9753 9832 9529 9513 9736 9692 9695 9611 9803 9768 9680 9795 9761 9629 9686 9643 9761 9806 9576 9912 9726 9822 9787 9749 9888 9598 9938 9674 9613 9633 9794 9675 9677 9865 9639 9830 9768 9784 9813 9666 9745 9939 9747 9870 9695 9684 9649 9668 9733 9962 9878 9886 9801 9774 9906 9978 10007 9735 9684 9864 9640 9841 9815 9851 9754 9813 9655 9816 9783 9850 9759 9755 9712 9657 9560 9519 9701 9932 9769 9749 9741 9891 9664 9766 9505 9685 9454 9692 9787 9533 9650 9805 9527 9828 9751 9659 9693 9615 9898 9736 9744 9803 9701 9869 9793 9817 9727 9735 9735 9972 9873 9753 10038 9822 9990 10099 10013 10210 10229 10212 10586 10615 10838 10557 10527 10270 10380 10270 10133 10167 9887 10029 9918 9944 10012 10012 9961 9912 10132 9945 10196 10150 10375 10106 9975 9824 9897 9856 9981 9902 9899 9781 9871 9606 9825 9773 9800 9870 9981 9967 10015 9722 10091 10125 10337 10389 10261 10397 10284 10372 10343 10301 10271 10275 10016 10111 10026 10048 10000 10044 10096 10064 10133 10148 10137 9946 10184 10115 10024 10048 10167 9863 10060 10111 9995 9880 9789 9846 9924 9912 9825 9808 9904 9768 9849 9799 9872 9875 9884 9769 9853 9915 9627 9624 9741 9729 9789 9945 9791 9789 9708 9817 9722 9913 9756 9880 9536 9788 9818 9932 9746 9687 9625 9941 9720 9881 9828 10021 9902 9831 9935 10003 9958 10045 9999 10217 10170 10270 10287 10260 10329 10449 10515 10535 10752 10705 10789 10674 10518 10604 10501 10338 10484 10420 10492 10431 10072 10206 10312 10135 10262 10245 10323 10244 10129 10249 10362 10312 10153 10192 10247 10173 10114 10087 9919 9657 9851 9777 9843 9901 9678 9838 9693 9656 9664 9893 9623 9882 9942 9748 9662 9371 9720 9735 9615 9719 9593 9655 9807 9610 9767 9780 9642 9753 9709 9867 9779 9699 9764 9754 9555 9606 9585 9582 9657 9725 9733 9840 9673 9807 9863 9705 9759 9923 9902 9676 9718 9812 9720 9907 9684 9737 9779 9726 9656 9604 9730 9597 9663 9716 9758 9744 9701 9782 9775 9568 9832 9857 9730 9909 9693 9484 9703 9678 9563 9763 9597 9774 9725 9638 9617 9806 9755 9739 9723 9852 9753 9536 9614 9794 9691 9896 9612 9788 9655 9585 9615 9602 9582 9599 9753 9652 9648 9621 9609 9588 9522 9615 9808 9617 9672 9713 9684 9875 9774 9776 9701 9571 9729 9620 9755 9658 9513 9778 9714 9874 9533 9685 9688 9689 9723 9749 9637 9608 9636 9710 9760 9688 9634 9598 9749 9612 9684 9589 9702 9675 9712 9656 9651 9581 9706 9854 9514 9662 9718 9739 9659 9634 9545 9846 9609 9491 9720 9720 9551 9670 9688 9845 9651 9535 9699 9851 9585 9567 9609 9652 9714 9554 9867 9574 9467 9705 9563 9658 9575 9648 9683 9727 9654 9487 9678 9775 9737 9611 9560 9542 9719 9627 9518 9430 9540 9544 9642 9556 9777 9644 9814 9601 9810 9547 9843 9610 9654 9724 9452 9750 9468 9661 9755 9467 9682 9615 9645 9723 9688 9554 9743 9645 9643 9682 9605 9637 9737 9525 9690 9512 9531 9512 9589 9750 9690 9753 9650 9590 9683 9624 9632 9697 9635 9612 9697 9642 9705 9635 9778 9696 9523 9854 9670 9820 9655 9744 9648 9634 9546 9674 9579 9824 9446 9788 9704 9641 9614 9636 9773 9605 9687 9645 9725 9640 9589 9794 9715 9719 9700 9541 9567 9674 9676 9638 9477 9702 9728 9797 9542 9719 9788 9576 9752 9710 9686 9600 9598 9736 9726 9546 9677 9590 9659 9438 9638 9538 9593 9653 9667 9629 9751 9805 9598 9754 9552 9730 9882 9659 9705 9621 9778 9814 9678 9562 9670 9789 9473 9555 9652 9691 9702 9591 9636 9692 9763 9766 9606 9583 9762 9459 9831 9741 9687 9676 9799 9702 9738 9713 9613 9492 9708 9446 9569 9597 9510 9630 9745 9770 9576 9765 9752 9765 9381 9662 9538 9635 9791 9581 9597 9743 9653 9666 9597 9656 9564 9810 9712 9586 9891 9608 9560 9653 9712 9542 9673 9825 9627 9789 9531 9480 9587 9712 9605 9733 9732 9700 9566 9620 9575 9436 9625 9640 9721 9651 9588 9686 9520 9420 9686 9617 9626 9854 9725 9636 9759 9792 9778 9547 9569 9672 9690 9416 9587 10036 9698 9726 9707 9722 9641 9542 9570 9748 9628 9602 9747 9655 9774 9593 9854 9689 9749 9628 9803 9480 9803 9867 9690 9589 9589 9577 9684 9717 9691 9540 9748 9605 9635 9555 9866 9754 9616 9714 9576 9596 9653 9636 9604 9618 9636 9841 9772 9525 9485 9615 9529 9766 9597 9610 9843 9550 9787 9671 9676 9754 9685 9612 9829 9650 9557 9595 9495 9921 9679 9509 9609 9740 9670 9611 9708 9558 9514 9552 9720 9565 9592 9671 9687 9662 9874 9616 9557 9661 9570 9535 9669 9617 9422 9795 9811 9565 9696 9687 9521 9691 9794 9652 9730 9864 9770 9744 9825 9651 9552 9813 9657 9901 9693 9822 9761 9708 9672 9717 9866 9891 9737 9789 9860 10003 9886 10022 9745 10004 10076 9972 10226 10207 10024 10174 10092 10235 10111 10174 10056 10038 10021 10158 10046 10007 9904 9901 9945 9891 9865 9945 9980 10024 9981 10023 9976 9997 9921 10242 10074 9834 10015 9641 9989 9748 9760 9843 9647 9727 9646 9825 9944 9857 9668 9772 9810 9850 9874 9670 9747 9985 9897 9909 9770 9740 9640 9853 9723 9728 9741 9826 9769 9716 9839 9787 9684 9907 9933 9840 9861 9839 9981 9774 9992 9888 9813 9873 9862 9983 9826 9914 10144 9921 10073 10357 10211 10333 10137 10170 10154 9939 9844 9934 9864 9767 9821 10130 9899 9890 10057 10146 9917 10151 10219 10057 10401 10110 10052 9958 9931 10026 10015 10040 9990 10028 9901 9758 9838 9989 10153 9984 9867 10045 9844 9703 9959 9952 10038 9806 10285 10126 9986 9927 9920 9873 9804 9951 9995 9863 10071 9933 9920 10102 10020 9892 9835 10018 9858 9826 9851 9808 9818 10032 9800 9868 10081 9957 10008 10004 10066 9990 10131 10223 10155 10191 10037 10103 10020 10045 10082 9882 9897 9997 10148 9801 9909 9935 9755 9703 9845 9857 9781 9906 10019 9945 9670 9841 9970 9875 9852 9848 9780 9888 9775 9833 9701 9686 9806 9755 9837 9701 9891 9773 9561 9918 9872 9819 9689 9798 9756 9814 9790 9474 9773 9862 9585 9733 9787 9939 9800 9824 9736 9880 9971 9813 9808 9850 10041 10038 10137 10023 9890 9985 9835 9881 9843 10000 9964 10018 9793 9772 9869 9905 9832 9675 9845 9779 9802 9779 10099 9835 10085 9877 9649 10012 9651 9983 9875 9848 9829 9750 9701 9715 9695 9713 9780 9616 9795 9799 9720 9720 9815 9585 9751 9662 9726 9714 9668 9923 9703 9662 9796 10046 9688 9610 9719 9666 9588 9808 9644 9559 9672 9760 9928 9477 9645 9795 9746 9600 9687 9655 9775 9642 9555 9591 9679 9524 9593 9803 9679 9688 9572 9507 9533 9811 9663 9783 9623 9573 9862 9787 9778 9545 9566 9463 9610 9694 9870 9767 9813 9415 9590 9650 9752 9695 9857 9788 9743 9800 9710 9869 9808 9648 9958 9779 9782 9729 9906 9769 9947 9805 9798 9661 9802 9780 9714 9649 9682 9629 9644 9756 9943 9697 9654 9895 9840 9827 9792 10010 9816 9875 9671 10037 9785 9608 9957 9849 9831 9621 9764 9730 9681 9694 9687 9757 9787 9671 9860 9938 9866 9955 9838 9944 9796 9633 9568 9811 9733 9774 9608 9838 9675 9726 9575 9809 9802 9809 9713 9994 9801 9847 9904 9957 9862 9858 10012 10167 10094 10282 10209 10068 10231 10284 10503 10763 10801 11162 11336 12239 12961 14207 14848 15598 15345 14859 13846 12923 12174 11438 10923 10809 10731 10533 10354 10253 10400 10378 10373 10501 10676 10798 11384 11499 11983 12383 12570 12464 12164 11929 11586 10846 10621 10236 10290 10066 10028 9946 9826 9891 9760 9828 9731 9658 9901 9951 9808 9669 9663 9772 9770 9757 9836 9842 9857 9971 9743 9695 9642 9769 9869 9905 9636 9843 9905 9791 9648 9561 9618 9852 9793 9851 9742 9696 9633 9622 9681 9600 9504 9659 9787 9615 9816 9655 9709 9849 9572 9583 9530 9755 9587 9656 9682 9777 9601 9626 9615 9644 9655 9810 9594 9760 9585 9726 9586 9593 9459 9589 9807 9764 9758 9735 9643 9765 9577 9542 9712 9609 9626 9672 9682 9608 9635 9666 9629 9680 9606 9549 9708 9739 9640 9606 9668 9511 9668 9781 9713 9582 9552 9702 9721 9861 9657 9678 9810 9646 9657 9778 9954 9717 9896 10090 10097 10096 10121 10317 10440 10392 10214 10097 10111 10111 10183 9744 9836 9750 9748 9791 9918 9647 9771 9895 9644 9811 9860 9802 9909 10119 9979 10085 9971 9955 10084 9928 9842 9893 9788 9626 9758 9723 9824 9876 9860 9737 9686 9545 9898 9786 9783 9706 9770 9767 9764 9971 10006 9924 10012 9811 9850 10035 9967 9891 10029 9937 9867 9785 9722 9641 9824 9841 9682 9812 9938 9867 9863 9960 9709 9766 9785 9759 9958 9871 9869 9986 9674 9580 9916 9521 9902 9831 9777 9913 9789 9797 9736 9658 9656 9702 9711 9792 9677 9804 9781 9632 9777 9870 9680 9589 9669 9840 9816 9620 9629 9588 9791 9596 9528 9568 9490 9715 9732 9672 9622 9607 9870 9502 9633 9486 9779 9653 9564 9707 9617 9803 9735 9517 9567 9562 9760 9643 9714 9561 9452 9476 9504 9621 9738 9586 9545 9675 9709 9660 9742 9812 9707 9878 9526 9465 9680 9780 9796 9646 9713 9695 9943 9693 9800 9809 9798 9677 9958 10065 10303 10146 10338 10362 10376 10668 10434 10534 10384 10126 10477 9974 10111 10028 9965 9803 9940 10077 9759 10038 9848 9823 9780 9968 9963 10031 9986 10273 10051 10144 10172 10190 10088 10288 10075 9818 9789 10018 9870 9695 9733 9719 9709 9730 9584 9743 9729 9780 9749 9682 9651 9834 9798 9651 9880 9771 9785 9650 9902 9852 9677 9799 9754 9750 9673 9886 9707 9624 9667 9685 9543 9677 9664 9676 9564 9649 9818 9698 9669 9651 9552 9653 9430 9669 9526 9862 9673 9816 9608 9762 9677 9781 9720 9988 9624 9621 9656 9745 9768 9618 9829 9549 9768 9592 9730 9924 9669 9874 9766 9759 9721 9734 9746 9817 9625 9851 9581 9822 9721 10002 9738 9867 9816 9715 9546 9684 9580 9615 9670 9565 9767 9866 9701 9734 9554 9677 9732 9815 9560 9756 9779 9629 9860 9623 9748 9635 9650 9557 9801 9643 9675 9562 9630 9621 9872 9949 9696 9599 9631 9715 9437 9639 9777 9600 9646 9614 9650 9681 9643 9558 9599 9608 9627 9483 9663 9636 9646 9505 9758 9607 9743 9665 9644 9615 9545 9540 9593 9615 9539 9699 9693 9742 9706 9707 9715 9677 9537 9514 9586 9700 9642 9473 9466 9580 9805 9537 9667 9608 9641 9511 9713 9661 9709 9737 9804 9729 9603 9551 9644 9721 9687 9617 9740 9608 9702 9512 9565 9607 9680 9676 9702 9669 9785 9537 9487 9813 9691 9526 9481 9538 9548 9581 9661 9549 9466 9831 9604 9564 9542 9584 9675 9590 9570 9703 9694 9709 9509 9688 9822 9545 9610 9704 9781 9802 9616 9494 9825 9462 9552 9521 9662 9739 9648 9788 9697 9638 9612 9690 9717 9707 9602 9429 9677 9605 9551 9641 9474 9601 9616 9492 9504 9809 9590 9642 9549 9763 9572 9769 9465 9617 9660 9536 9505 9654 9596 9522 9593 9677 9566 9649 9334 9599 9715 9464 9637 9663 9444 9513 9624 9611 9680 9668 9600 9577 9603 9552 9652 9610 9826 9724 9554 9464 9568 9571 9698 9603 9628 9677 9541 9642 9586 9788 9584 9819 9600 9600 9598 9444 9434 9645 9718 9610 9747 9722 9757 9642 9534 9523 9446 9549 9433 9611 9491 9687 9657 9637 9640 9488 9622 9581 9560 9557 9727 9799 9457 9643 9441 9584 9565 9765 9697 9659 9657 9662 9816 9673 9565 9323 9565 9650 9454 9732 9778 9506 9558 9733 9713 9544 9683 9415 9784 9736 9532 9538 9396 9724 9403 9520 9596 9505 9646 9554 9734 9646 9711 9525 9669 9554 9674 9711 9692 9482 9691 9527 9663 9581 9634 9524 9730 9572 9645 9619 9471 10020 9720 9748 9837 9669 9549 9552 9827 9673 9711 9706 9524 9577 9609 9441 9723 9800 9687 9656 9470 9801 9716 9663 9667 9684 9447 9703 9662 9689 9708 9557 9678 9618 9683 9801 9622 9661 9685 9637 9468 9703 9624 9725 9595 9590 9763 9687 9817 9738 9873 9591 9715 9639 9582 9664 9706 9589 9448 9629 9646 9733 9615 9617 9540 9696 9713 9578 9606 9621 9710 9763 9511 9704 9455 9580 9511 9458 9470 9769 9660 9501 9583 9651 9583 9564 9639 9809 9548 9839 9667 9616 9766 9508 9538 9697 9584 9655 9554 9509 9640 9716 9541 9730 9345 9531 9591 9624 9664 9741 9632 9566 9752 9692 9508 9612 9708 9636 9627 9495 9564 9486 9455 9501 9635 9547 9715 9400 9549 9664 9532 9571 9643 9609 9602 9515 9710 9548 9392 9590 9676 9612 9471 9693 9570 9597 9782 9445 9793 9577 9662 9573 9691 9705 9599 9430 9652 9645 9565 9672 9642 9429 9740 9359 9627 9446 9564 9701 9559 9609 9778 9550 9687 9811 9699 9617 9442 9633 9816 9682 9652 9767 9810 9545 9461 9548 9651 9775 9629 9688 9685 9925 9681 9686 9613 9836 9828 9498 9633 9686 9801 9668 9579 9685 9662 9665 9801 9709 9651 9633 9648 9560 9722 9738 9719 9745 9789 9831 9807 9769 9814 9785 9612 9906 9577 9516 9592 9598 9707 9573 9726 9714 9643 9539 9734 9618 9702 9692 9627 9797 9813 9774 9606 9774 9498 9809 9706 9759 9753 9844 9875 9742 9737 9595 9588 9692 9721 9719 9520 9664 9520 9747 9731 9652 9888 9868 9839 9639 9919 9687 9714 9683 9598 9899 9457 9689 9643 9867 9855 9868 9584 9802 9721 9834 9615 9716 9711 10003 9638 9697 9576 9567 9755 9632 9774 9664 9534 9655 9746 9723 9652 9548 9789 9578 9731 9702 9750 9567 9488 9629 9933 9827 9670 9819 9574 9728 9684 9717 9676 9672 9678 9496 9598 9856 9692 9590 9608 9668 9626 9613 9667 9756 9766 9592 9683 9761 9708 9638 9687 9821 9711 9737 9707 9658 9678 9697 9618 9856 9615 9729 9750 9897 9481 9760 9786 9600 9626 9491 9730 9596 9763 9638 9941 9720 9884 9767 9782 9736 9754 9770 9862 9680 9910 9843 9827 9700 9685 9817 9733 9720 9763 9671 9808 9704 9769 9572 9820 9642 9735 9811 9832 9852 9884 9711 9734 9523 9591 9697 9920 9928 9819 9802 9738 9643 9792 9745 9652 9871 9939 9939 9822 10020 9878 9795 9776 9781 9833 9792 9780 9637 9527 9624 9780 9657 9844 9757 9730 9940 9887 9786 9765 9710 9869 9641 9821 9822 9874 9829 9899 9873 9802 9890 9969 9848 9851 9848 9993 10041 9939 9956 9816 9953 9958 9869 9780 9836 9772 9679 9629 9841 9864 9774 9828 9736 9602 9662 9910 9737 9618 9750 9738 9811 9767 9775 9413 9975 9847 9941 9839 9723 9942 9731 9851 9891 9790 9603 9739 9793 9612 9742 9726 9498 9628 9453 9821 9801 9686 9603 9666 9544 9636 9675 9720 9629 9899 9809 9605 9657 9679 9750 9715 9570 9617 9672 9647 9663 9657 9691 9545 9800 9579 9698 9679 9665 9681 9841 9724 9528 9739 9535 9729 9676 9689 9773 9682 9670 9703 9708 9595 9541 9619 9772 9596 9696 9543 9643 9810 9667 9738 9588 9544 9565 9572 9680 9582 9514 9790 9738 9612 9701 9667 9700 9720 9636 9731 9586 9767 9771 9837 9699 9686 9473 9608 9468 9379 9687 9608 9572 9589 9644 9779 9713 9481 9780 9603 9645 9589 9620 9672 9763 9662 9684 9648 9694 9549 9481 9683 9629 9556 9842 9495 9658 9576 9672 9444 9684 9447 9682 9698 9699 9645 9756 9647 9766 9580 9581 9704 9762 9597 9540 9395 9482 9712 9572 9586 9670 9802 9544 9567 9614 9764 9701 9651 9531 9591 9673 9639 9688 9460 9736 9743 9549 9769 9730 9669 9689 9705 9448 9763 9889 9735 9724 9642 9687 9658 9589 9623 9682 9717 9560 9734 9914 9726 9715 9828 9753 9805 9698 9855 9887 9826 9819 9828 9861 9841 9835 9841 9661 9741 9749 9830 9736 9760 9694 9794 9776 9723 9755 9802 9847 9558 9725 9723 9650 9750 9740 9644 9754 9938 9718 9682 9896 9720 9826 9728 9742 9600 9740 9633 9578 9859 9653 9688 9855 9730 9784 9791 9825 9597 9703 9680 9650 9535 9649 9580 9682 9793 9654 9656 9677 9799 9711 9487 9694 9748 9669 9475 9625 9631 9600 9741 9687 9612 9666 9736 9679 9774 9699 9728 9779 9742 9762 9573 9684 9648 9701 9777 9732 9620 9749 9601 9640 9674 9559 9831 9606 9691 9859 9732 9508 9679 9783 9784 9706 9661 9699 9760 9788 9741 9784 9783 9591 9807 9633 9682 9713 9757 9750 9664 9758 9724 9883 9729 9890 9840 9575 9834 9778 9763 9677 9805 9719 9766 9795 9779 9889 9669 9768 9906 9979 9636 9794 9894 9786 9679 9676 9799 9636 9791 9896 9798 9761 9679 9741 9785 9705 9660 9642 9854 9638 9674 9678 9671 9670 9830 9723 9708 9728 9945 9667 9643 9546 9874 9614 9641 9578 9692 9853 9647 9880 9627 9824 9813 9523 9626 9808 10010 9746 9792 9924 9779 9825 10106 9747 9841 9974 9627 9727 9813 9756 9793 9693 9758 9992 9757 9653 9626 9731 9740 9736 9765 10025 9926 9790 9686</counts>
			</dataPoints>
		</scan>
	</xrdMeasurement>
</xrdMeasurements>