File: dataset/precursor_mixture/Nb2O5_CuO_LiCoO2.2-min.xrdml
<?xml version="1.0"?>
<xrdMeasurements xmlns="http://www.xrdml.com/XRDMeasurement/2.2" xmlns:xsi="http://www.w3.org/2001/XMLSchema-instance" xsi:schemaLocation="http://www.xrdml.com/XRDMeasurement/2.2 http://www.xrdml.com/XRDMeasurement/2.2/XRDMeasurement.xsd" status="Completed" recordIdentifier="{11B16BEA-334B-44BE-B973-FC834F733158}">
	<comment>
		<entry/>
	</comment>
	<sample type="To be analyzed">
		<id>dara-33-1</id>
		<name></name>
		<preparedBy></preparedBy>
	</sample>
	<xrdMeasurement measurementType="Scan" status="Completed" sampleMode="Reflection">
		<usedWavelength intended="K-Alpha 1">
			<kAlpha1 unit="Angstrom">1.5405980</kAlpha1>
			<kAlpha2 unit="Angstrom">1.5444260</kAlpha2>
			<kBeta unit="Angstrom">1.3922500</kBeta>
			<ratioKAlpha2KAlpha1>0.5000</ratioKAlpha2KAlpha1>
		</usedWavelength>
		<incidentBeamPath>
			<radius unit="mm">145.00</radius>
			<xRayTube id="1010048" name="Empyrean Cu LFF HR (9430 033 7310x) DK437873">
				<tension unit="kV">40.0</tension>
				<current unit="mA">15.0</current>
				<anodeMaterial>Cu</anodeMaterial>
				<focus type="Line">
					<length unit="mm">12.0</length>
					<width unit="mm">0.4</width>
					<takeOffAngle unit="deg">6.0</takeOffAngle>
				</focus>
			</xRayTube>
			<filter id="20010004" name="Beta-filter Nickel">
				<material>Ni</material>
				<thickness unit="mm">0.020</thickness>
			</filter>
			<sollerSlit id="21010002" name="Soller slits 0.04 rad.">
				<opening unit="rad">0.0400</opening>
			</sollerSlit>
			<mask id="22031000" name="Fixed mask 13 mm">
				<width unit="mm">9.00</width>
			</mask>
			<divergenceSlit id="22120001" name="Divergence slit 1°" xsi:type="fixedDivergenceSlitType">
				<distanceToSample unit="mm">50.00</distanceToSample>
				<height unit="mm">1.52</height>
			</divergenceSlit>
		</incidentBeamPath>
		<beamKnife id="29030100" name="Beam knife low"/>
		<sampleMovement xsi:type="spinningSampleMovementType">
			<spinnerRevolutionTime unit="seconds">1.0</spinnerRevolutionTime>
		</sampleMovement>
		<diffractedBeamPath>
			<radius unit="mm">145.00</radius>
			<antiScatterSlit id="22090040" name="AS slit 9 mm" xsi:type="fixedAntiScatterSlitType">
				<height unit="mm">9.00</height>
			</antiScatterSlit>
			<sollerSlit id="21020003" name="Large Soller slits 0.04 rad.">
				<opening unit="rad">0.0400</opening>
			</sollerSlit>
			<filter id="20030001" name="Large beta-filter Nickel">
				<material>Ni</material>
				<thickness unit="mm">0.020</thickness>
			</filter>
			<detector id="7010019" name="PIXcel1D-Medipix3 detector" xsi:type="rtmsDetectorType">
				<phd unit="keV">
					<lowerLevel>4.0</lowerLevel>
					<upperLevel>11.3</upperLevel>
				</phd>
				<mode>Scanning</mode>
				<activeLength unit="deg">1.021</activeLength>
			</detector>
		</diffractedBeamPath>
		<scan appendNumber="0" mode="Continuous" scanAxis="Gonio" status="Completed">
			<header>
				<startTimeStamp>2024-03-24T18:36:45-07:00</startTimeStamp>
				<endTimeStamp>2024-03-24T18:39:07-07:00</endTimeStamp>
				<author>
					<name>AutomatedUser</name>
				</author>
				<source>
					<applicationSoftware version="1.6 (94)">PANalytical Aeris Instrument Suite</applicationSoftware>
					<instrumentControlSoftware version="3.0.0 20211014">AERIS</instrumentControlSoftware>
					<instrumentID>2879380</instrumentID>
				</source>
			</header>
			<dataPoints>
				<positions axis="2Theta" unit="deg">
					<startPosition>10.02173288</startPosition>
					<endPosition>139.98435528</endPosition>
				</positions>
				<positions axis="Omega" unit="deg">
					<startPosition>5.01086644</startPosition>
					<endPosition>69.99217764</endPosition>
				</positions>
				<commonCountingTime unit="seconds">1.551</commonCountingTime>
				<counts unit="counts">896 825 922 855 878 853 886 829 844 874 867 813 884 902 892 858 854 874 856 813 850 815 804 831 855 829 872 853 894 837 811 835 826 880 861 854 892 879 860 848 875 914 878 900 841 833 837 836 900 871 842 828 896 837 871 867 872 798 781 847 859 835 906 825 847 839 896 797 871 868 856 897 804 873 854 851 838 860 853 861 826 852 773 810 819 804 859 824 891 886 903 859 842 867 822 867 879 857 830 800 814 917 872 823 814 843 872 856 853 824 848 841 936 829 873 876 848 889 874 867 834 884 944 832 855 862 912 856 909 817 867 871 871 848 832 869 818 853 886 841 837 909 880 874 850 882 850 879 857 910 842 874 865 863 842 873 870 931 877 955 1035 957 950 907 906 846 907 946 886 924 866 887 873 864 837 923 864 825 898 944 885 892 938 954 865 956 928 1031 1015 1042 1013 1088 1163 1263 1303 1366 1664 1844 2712 4230 8369 16568 28274 20726 7197 1803 1411 1255 1264 1193 1169 1078 1068 953 978 988 954 968 945 974 966 1023 970 996 1054 1038 1076 1033 1027 1040 1048 1068 1010 1019 1008 997 1016 1017 1025 975 1067 1005 1030 1035 1006 1017 1041 971 1024 1018 1047 1038 984 987 993 907 969 979 953 975 953 994 963 986 953 945 993 936 982 990 1028 1005 993 992 1012 1000 1024 1016 1040 1067 1115 1216 1484 1906 2555 2492 1797 1301 1163 1006 993 959 969 1038 990 954 972 968 931 952 996 965 916 942 952 996 942 884 919 875 989 942 848 925 952 906 899 914 944 960 944 895 932 909 925 895 912 924 922 912 927 948 923 887 884 882 925 911 923 900 957 958 865 950 851 951 912 926 891 864 943 960 920 944 906 893 977 931 959 882 951 882 864 850 889 924 902 866 901 873 959 885 878 873 875 883 886 868 864 856 894 911 856 841 826 989 857 905 839 853 867 852 952 892 971 837 849 887 890 930 896 887 892 976 935 978 917 959 955 996 1181 1342 1761 2351 2205 1851 1416 1110 1042 969 906 969 1033 955 1075 1120 1262 1494 1405 1234 1007 941 932 903 965 915 904 938 870 838 936 881 942 916 878 871 899 819 890 911 888 884 908 855 882 861 908 896 894 882 925 846 860 886 893 907 890 892 901 868 917 885 820 882 870 905 869 907 880 878 830 877 885 837 879 920 847 910 868 900 846 861 872 871 872 902 890 874 855 846 844 870 875 866 898 895 868 873 899 876 847 906 903 904 924 894 943 883 858 906 875 846 815 913 847 805 816 840 894 834 928 906 845 853 937 887 839 888 863 862 878 851 866 885 858 882 864 915 800 869 850 862 837 915 908 858 844 920 946 871 865 786 876 866 858 833 920 884 856 857 848 811 832 855 810 857 905 889 865 864 904 866 872 866 916 888 880 829 886 888 842 896 893 881 918 971 1082 1264 1462 1408 1164 1101 956 919 883 941 953 994 1045 1147 1045 1047 930 915 956 920 1026 1051 1086 998 969 947 852 841 881 831 827 837 870 927 851 843 873 906 862 876 900 933 1064 1337 2109 1793 1493 1461 907 909 930 847 930 858 843 859 867 898 895 960 901 924 905 863 833 845 873 874 824 866 846 837 926 841 870 844 804 878 800 864 916 858 825 900 833 882 893 843 875 861 885 843 825 854 911 874 908 840 879 808 877 830 921 859 848 819 833 863 881 835 874 813 916 844 874 850 888 812 804 803 896 868 875 845 862 905 878 821 861 840 835 920 880 851 897 880 921 914 878 902 868 865 819 884 843 852 792 855 814 825 868 829 835 839 890 867 852 867 858 867 855 825 881 835 883 853 838 812 815 878 895 830 860 909 875 847 880 843 923 850 807 842 902 838 862 864 858 859 826 849 871 858 874 951 985 1082 1156 1464 1579 1277 1299 1111 983 917 859 879 857 877 837 846 881 877 864 921 885 940 975 1113 1137 1165 1035 1025 988 835 906 896 918 864 862 842 804 869 865 802 862 901 899 882 856 843 820 824 850 846 843 789 887 832 850 885 870 791 867 825 815 872 860 917 842 850 797 838 888 837 844 821 795 795 824 861 826 868 842 889 836 945 869 828 842 825 863 876 779 868 912 834 914 867 911 893 980 875 903 943 938 940 938 873 965 1020 1025 993 974 935 966 874 908 919 855 904 870 872 869 856 827 815 838 852 872 946 907 892 931 990 1019 1014 1113 1028 1030 1009 966 921 917 875 874 830 854 853 834 848 820 906 883 876 778 839 862 865 828 864 855 814 828 881 828 808 862 859 864 863 852 805 842 844 837 859 825 855 905 864 868 867 875 798 855 863 840 800 869 770 849 849 794 859 852 865 835 911 865 835 834 813 858 832 846 863 863 776 880 790 873 866 822 883 879 812 901 897 839 839 815 866 862 879 836 921 933 969 1074 1044 1055 1039 927 1016 1012 1079 1062 1008 1012 985 948 932 889 868 849 867 851 872 893 855 896 899 834 894 848 878 919 875 952 953 919 922 897 938 857 870 844 896 880 850 884 922 894 872 843 832 855 837 832 891 816 867 836 869 853 817 837 865 838 845 790 803 850 846 799 926 864 871 817 815 830 833 905 836 850 827 863 893 876 905 917 934 878 874 830 906 866 872 905 1029 1109 1182 946 957 1025 1041 924 901 855 900 947 1030 948 911 930 959 962 882 918 805 867 844 888 894 860 871 907 892 882 865 813 878 878 889 811 837 892 880 879 850 830 857 847 882 831 877 831 847 845 845 848 822 865 850 858 858 884 804 865 844 824 835 914 881 858 856 870 848 904 840 877 857 857 875 883 829 863 888 881 871 838 866 846 834 819 823 923 829 862 804 813 855 875 883 873 849 848 772 878 902 870 925 914 888 915 944 918 893 879 855 801 871 901 859 810 912 779 825 885 833 797 838 918 865 834 868 840 847 827 864 839 890 842 871 883 840 810 850 894 914 936 908 1059 1003 955 951 1005 922 892 847 870 875 868 827 785 855 847 824 860 890 880 887 944 953 919 897 896 898 874 861 849 870 901 859 835 879 940 881 811 878 877 849 884 913 853 852 890 846 855 856 867 886 828 835 841 895 853 815 778 828 882 878 808 840 845 866 836 844 822 815 827 859 828 873 793 855 877 801 804 848 831 837 847 817 881 824 867 844 821 844 835 827 833 859 859 842 883 871 895 919 877 862 876 855 829 813 826 864 893 919 887 866 911 923 857 888 853 815 889 846 827 782 854 833 875 867 876 919 875 896 901 929 882 926 911 899 860 835 846 858 830 849 799 894 854 840 834 853 840 881 887 809 799 793 850 834 795 837 799 795 816 867 837 844 822 824 794 852 839 862 810 792 806 837 831 837 836 812 868 848 867 868 848 848 801 828 850 887 799 853 830 873 860 858 820 829 885 869 866 853 890 872 875 833 829 812 816 860 794 884 874 818 827 906 822 831 822 860 835 779 828 787 817 842 825 804 862 821 850 866 818 825 794 878 807 849 821 766 850 818 821 854 851 876 856 846 836 870 836 837 858 810 838 839 862 834 872 841 867 805 807 883 865 821 864 799 859 799 839 845 878 841 883 859 807 876 906 857 888 898 857 845 840 838 812 807 833 796 868 821 831 848 878 856 880 885 854 822 881 877 910 909 844 854 846 850 857 894 871 852 936 841 843 861 860 807 860 932 816 863 848 864 804 829 849 910 827 893 832 848 866 928 891 876 852 863 821 837 832 831 855 851 868 787 817 895 819 883 869 821 858 852 874 855 838 846 852 821 897 812 896 841 913 815 811 862 818 870 846 872 846 859 860 874 919 829 885 890 880 949 1043 1286 1179 955 914 929 991 1095 984 931 848 830 825 812 865 850 865 818 830 839 860 870 867 824 814 819 795 847 835 823 853 840 828 833 849 780 886 875 916 886 842 847 842 822 889 886 857 890 871 794 825 815 826 846 882 820 842 856 850 830 864 838 813 847 833 845 805 825 797 807 797 816 801 860 856 838 787 864 834 880 905 917 883 855 853 800 886 865 868 858 854 796 856 854 833 829 904 765 856 868 832 799 840 857 869 829 760 884 900 857 866 845 833 805 837 866 853 791 799 828 808 883 859 839 866 864 862 823 802 785 823 886 798 859 790 817 761 818 851 835 790 812 865 828 853 835 819 837 869 877 825 878 839 826 825 862 831 805 891 850 851 858 830 822 820 843 848 846 833 886 849 824 851 889 798 821 849 832 855 800 894 860 868 774 801 883 853 863 791 804 837 822 840 852 821 769 781 880 795 853 827 795 849 774 821 839 866 808 814 840 776 831 817 860 801 830 816 791 762 848 838 845 812 807 867 839 865 822 838 847 839 882 879 867 909 841 807 831 791 786 795 812 802 806 798 829 851 848 813 833 857 882 875 829 831 851 805 832 823 774 878 873 845 864 861 909 847 850 845 845 840 832 826 796 881 824 863 859 852 848 851 882 858 861 822 879 861 882 856 809 876 841 849 857 845 816 844 861 817 841 829 845 858 865 839 840 885 831 832 848 812 862 873 825 808 815 820 855 844 842 762 866 869 862 836 834 817 820 855 838 815 828 794 821 791 847 797 861 814 797 821 872 854 889 862 842 842 809 850 870 851 834 836 826 857 841 852 825 821 774 834 797 839 848 850 820 785 816 855 875 854 806 829 867 817 878 861 836 876 836 908 879 882 837 860 874 838 813 847 832 847 864 877 799 830 868 860 854 877 893 907 876 915 845 866 872 892 874 868 804 796 839 889 883 842 850 848 834 876 849 852 839 876 845 837 821 866 855 844 812 825 855 791 846 828 862 884 845 897 836 834 807 824 830 805 796 816 877 860 831 795 830 804 871 807 829 864 860 800 805 834 780 783 844 841 817 835 795 847 835 871 813 784 891 859 828 866 847 837 874 876 891 814 751 809 884 829 810 824 861 865 798 868 867 825 838 791 847 862 861 860 872 835 775 871 752 783 854 826 841 854 811 875 842 864 792 862 871 881 817 849 846 902 849 858 830 822 867 792 792 834 841 865 820 832 856 845 857 844 827 807 851 813 819 792 793 802 824 810 872 842 910 812 874 840 840 868 855 820 787 904 856 840 874 788 805 868 812 816 809 808 805 798 834 810 828 826 881 845 818 833 857 862 819 833 787 824 878 853 810 837 881 881 832 848 817 833 823 860 844 843 839 828 852 798 830 831 823 852 843 783 903 848 870 812 883 838 830 883 834 827 826 829 860 876 850 866 850 855 888 896 844 795 818 845 846 862 865 897 1029 963 883 844 797 884 813 842 884 882 863 879 883 839 859 826 829 862 806 836 785 808 828 865 835 818 902 789 813 761 834 874 849 857 887 853 850 832 779 834 845 827 856 880 851 840 834 910 834 860 804 881 851 831 835 814 811 802 820 898 833 813 831 849 810 867 882 845 819 832 899 834 844 851 845 850 895 858 806 831 801 833 826 867 865 836 833 825 787 833 866 871 840 834 839 841 862 796 877 837 897 856 836 802 799 798 874 854 802 839 835 790 843 844 840 909 801 799 856 844 827 827 819 770 847 840 865 834 814 794 825 880 878 823 864 812 839 852 865 843 900 804 866 829 837 867 853 826 807 897 791 902 904 893 891 839 847 903 947 930 847 880 853 917 862 844 843 864 847 915 847 900 894 814 837 865 819 869 846 828 819 849 833 837 851 808 830 862 832 886 839 853 829 849 862 860 805 828 846 834 821 912 857 886 831 830 900 825 880 923 855 865 886 848 838 852 870 856 857 894 865 843 790 867 854 783 843 815 852 862 878 864 875 860 847 864 820 798 871 848 947 823 870 902 864 911 822 841 859 828 816 853 830 871 808 858 795 896 784 825 826 833 861 860 831 859 865 819 816 882 870 833 881 805 830 831 839 863 810 845 832 854 886 881 846 848 863 833 834 852 833 802 877 931 899 844 873 845 830 852 794 836 844 872 805 798 804 843 797 815 789 836 902 857 863 862 851 836 819 873 817 801 860 841 867 921 918 822 840 833 834 861 861 851 837 792 814 873 882 858 863 827 870 868 912 836 828 835 859 833 825 894 870 809 819 868 819 840 838 826 900 886 858 833 898 850 866 821 864 872 826 867 831 846 853 855 864 877 800 862 823 820 877 855 834 879 859 815 868 850 856 862 868 834 881 859 787 808 821 869 808 817 840 848 875 874 855 775 879 899 822 869 827 855 845 867 904 841 808 882 818 845 836 896 848 826 842 827 840 804 863 852 820 845 799 843 843 805 806 864 833 775 826 820 832 823 838 773 816 822 856 864 869 871 861 794 780 855 853 820 835 855 853 863 831 829 846 848 845 857 791 890 813 890 842 822 876 861 903 909 839 808 844 826 811 835 862 831 822 805 856 842 831 878 827 853 830 814 841 853 843 879 781 811 868 833 881 896 863 848 837 833 863 893 771 855 870 805 819 865 841 800 838 908 840 855 851 857 809 836 890 821 920 839 827 881 835 799 876 823 869 830 808 825 835 834 857 859 831 891 819 808 866 855 866 843 898 801 833 826 812 877 832 844 849 866 820 859 840 816 840 869 821 850 867 821 834 821 853 824 822 832 857 855 867 835 817 809 850 868 847 874 871 852 890 835 861 817 838 859 768 804 832 872 856 917 902 881 911 902 948 806 815 858 891 907 828 894 840 878 850 855 892 867 853 859 811 874 873 837 886 839 858 845 882 888 881 820 835 854 790 831 800 783 850 847 840 868 860 777 806 806 872 836 841 861 794 859 802 812 841 848 865 841 802 859 845 836 816 843 827 874 811 870 806 844 858 847 813 848 845 811 801 830 858 864 873 815 819 836 840 862 832 841 889 806 840 843 872 833 842 861 813 853 888 792 839 863 840 845 851 837 819 867 831 904 838 826 830 895 831 834 804 848 848 890</counts>
			</dataPoints>
		</scan>
	</xrdMeasurement>
</xrdMeasurements>