File: dataset/precursor_mixture/NiO_0p6007-Bi2O3_0p4008--2min.xrdml
<?xml version="1.0"?>
<xrdMeasurements xmlns="http://www.xrdml.com/XRDMeasurement/2.3" xmlns:xsi="http://www.w3.org/2001/XMLSchema-instance" xsi:schemaLocation="http://www.xrdml.com/XRDMeasurement/2.3 http://www.xrdml.com/XRDMeasurement/2.3/XRDMeasurement.xsd" status="Completed" recordIdentifier="{AE023D12-AEEC-4545-81F7-CAEA6C659F74}">
	<comment>
		<entry/>
	</comment>
	<sample type="To be analyzed">
		<id>Dara_redo_1-2min_manual</id>
		<name></name>
		<preparedBy></preparedBy>
	</sample>
	<xrdMeasurement measurementType="Scan" status="Completed" sampleMode="Reflection">
		<usedWavelength intended="K-Alpha 1">
			<kAlpha1 unit="Angstrom">1.5405980</kAlpha1>
			<kAlpha2 unit="Angstrom">1.5444260</kAlpha2>
			<kBeta unit="Angstrom">1.3922500</kBeta>
			<ratioKAlpha2KAlpha1>0.5000</ratioKAlpha2KAlpha1>
		</usedWavelength>
		<incidentBeamPath>
			<radius unit="mm">145.00</radius>
			<xRayTube id="1010048" name="Empyrean Cu LFF HR (9430 033 7310x)">
				<tension unit="kV">40.0</tension>
				<current unit="mA">15.0</current>
				<anodeMaterial>Cu</anodeMaterial>
				<focus type="Line">
					<length unit="mm">12.0</length>
					<width unit="mm">0.4</width>
					<takeOffAngle unit="deg">6.0</takeOffAngle>
				</focus>
			</xRayTube>
			<sollerSlit id="21010002" name="Soller slits 0.04 rad.">
				<opening unit="rad">0.0400</opening>
			</sollerSlit>
			<mask id="22031000" name="Fixed mask 13 mm">
				<width unit="mm">9.00</width>
			</mask>
			<divergenceSlit id="22120001" name="Divergence slit 1°" xsi:type="fixedDivergenceSlitType">
				<distanceToSample unit="mm">50.00</distanceToSample>
				<height unit="mm">1.52</height>
			</divergenceSlit>
		</incidentBeamPath>
		<sampleMovement xsi:type="spinningSampleMovementType">
			<spinnerRevolutionTime unit="seconds">1.0</spinnerRevolutionTime>
		</sampleMovement>
		<diffractedBeamPath>
			<radius unit="mm">145.00</radius>
			<antiScatterSlit id="22090040" name="AS slit 9 mm (PIXcel)" xsi:type="fixedAntiScatterSlitType">
				<height unit="mm">9.00</height>
			</antiScatterSlit>
			<sollerSlit id="21020003" name="Large Soller slits 0.04 rad.">
				<opening unit="rad">0.0400</opening>
			</sollerSlit>
			<filter id="20030001" name="Large beta-filter Nickel">
				<material>Ni</material>
				<thickness unit="mm">0.020</thickness>
			</filter>
			<detector id="7010019" name="PIXcel1D-Medipix3 detector" xsi:type="rtmsDetectorType">
				<phd unit="keV">
					<lowerLevel>4.02</lowerLevel>
					<upperLevel>11.27</upperLevel>
				</phd>
				<mode>Scanning</mode>
				<activeLength unit="deg">5.542</activeLength>
			</detector>
		</diffractedBeamPath>
		<scan appendNumber="0" mode="Continuous" scanAxis="Gonio" status="Completed">
			<header>
				<startTimeStamp>2024-11-21T08:10:27-08:00</startTimeStamp>
				<endTimeStamp>2024-11-21T08:12:32-08:00</endTimeStamp>
				<author>
					<name>AutomatedUser</name>
				</author>
				<source>
					<applicationSoftware version="1.7b (136)">PANalytical Aeris Instrument Suite</applicationSoftware>
					<instrumentControlSoftware version="3.2.00000000 20240306">AERIS</instrumentControlSoftware>
					<instrumentID>950485</instrumentID>
				</source>
			</header>
			<dataPoints>
				<positions axis="2Theta" unit="deg">
					<startPosition>10.02173288</startPosition>
					<endPosition>99.99585608</endPosition>
				</positions>
				<positions axis="Omega" unit="deg">
					<startPosition>5.01086644</startPosition>
					<endPosition>49.99792804</endPosition>
				</positions>
				<commonCountingTime unit="seconds">10.965</commonCountingTime>
				<counts unit="counts">2157 2152 2152 2016 2080 2081 2105 2107 2087 1991 2026 1992 2018 2056 2032 1927 1966 1943 1964 1958 1955 1970 1953 1900 1826 1917 1864 1907 1851 1900 1833 1841 1893 1793 1874 1864 1856 1808 1800 1860 1859 1785 1783 1717 1837 1863 1746 1816 1738 1673 1729 1795 1725 1747 1810 1784 1753 1752 1780 1755 1739 1672 1692 1729 1692 1584 1659 1668 1625 1701 1595 1703 1724 1716 1690 1631 1665 1650 1656 1666 1611 1625 1697 1661 1554 1546 1586 1659 1631 1634 1659 1528 1614 1661 1586 1640 1678 1685 1675 1714 1605 1625 1700 1577 1631 1565 1643 1616 1614 1623 1619 1630 1596 1623 1694 1605 1616 1626 1595 1556 1667 1605 1608 1651 1674 1635 1643 1589 1638 1625 1687 1615 1633 1589 1631 1642 1634 1675 1613 1683 1662 1714 1574 1624 1629 1683 1568 1668 1616 1670 1694 1679 1644 1656 1648 1644 1692 1723 1716 1668 1657 1719 1712 1677 1780 1685 1730 1691 1616 1723 1716 1687 1647 1720 1669 1706 1638 1666 1728 1718 1686 1680 1743 1745 1750 1689 1654 1666 1635 1646 1656 1676 1619 1678 1750 1699 1661 1734 1709 1679 1787 1694 1787 1645 1810 1694 1740 1617 1683 1684 1736 1836 1715 1715 1725 1712 1730 1780 1757 1762 1717 1859 1831 1817 1811 1821 1787 1942 1855 1919 1820 1888 1850 1747 1867 1682 1774 1852 1813 1811 1715 1790 1856 1648 1703 1709 1805 1791 1784 1772 1756 1790 1720 1723 1810 1803 1725 1712 1813 1760 1794 1843 1847 1836 1839 1812 1879 1762 1900 1862 1909 1939 1957 1931 1907 2029 1846 1914 2069 1819 1860 1871 1862 1843 1852 1847 1905 1779 1848 1882 1767 1849 1835 1876 1857 1836 1833 1724 1859 1864 1904 1812 1780 1843 1795 1810 1807 1847 1892 1887 1846 1827 1842 1795 1832 1936 1837 1891 1955 1880 1915 1992 1923 1875 1912 1979 1923 1854 2042 1943 2027 2059 2113 2072 2219 2204 2235 2347 2368 2345 2406 2312 2470 2425 2319 2170 2017 1988 1933 1978 2088 1957 1964 2061 1995 2081 2088 2070 2222 2326 2485 2751 2788 2810 2859 3063 3075 3180 3311 3313 3435 3215 2815 2351 2108 2140 2062 2074 2115 2074 2082 2191 2180 2196 2285 2512 2619 2856 3239 3394 3649 3788 3920 4297 4529 4998 5678 6414 6829 7054 7051 6991 7340 7806 8400 9171 9901 10215 10083 8732 6409 4448 3298 3065 3204 3329 3385 3427 3569 3507 3700 3932 3856 3571 3137 2606 2248 2176 2139 2064 2149 2032 2143 2121 2185 2020 2123 2093 2036 2093 1990 2101 2095 2122 2019 2163 2142 2030 2110 2030 2159 2044 2090 2123 2155 2127 2157 2153 2144 2041 2152 2177 2113 2147 2141 2127 2143 2136 2193 2105 2148 2189 2237 2126 2156 2172 2034 2122 2122 2072 2074 2115 2103 2168 2038 2122 2131 2109 2000 2012 2063 2026 2098 2068 2108 1996 2107 2084 2119 2031 2052 2091 2036 2121 2070 2104 2131 2097 2018 2158 2129 2126 2120 2134 2173 2171 2327 2385 2432 2414 2417 2387 2473 2571 2571 2778 2863 2994 3251 3495 3704 4142 4642 5139 5728 6182 6837 7020 7433 7167 6764 6337 5948 5454 4570 3618 3035 2593 2349 2307 2399 2372 2369 2419 2439 2523 2498 2593 2498 2462 2398 2360 2293 2213 2260 2141 2181 2127 2172 2203 2254 2207 2267 2319 2336 2492 2598 2696 2882 2922 3058 3200 3339 3425 3540 3430 3167 2914 2785 2646 2777 2746 2877 2756 2697 2603 2439 2434 2529 2541 2614 2543 2536 2675 2596 2505 2381 2202 2177 2127 2208 2176 2161 2142 2267 2211 2289 2187 2274 2325 2465 2574 2739 2945 3316 3691 4306 4911 5323 5926 6208 6805 7350 7929 8202 8025 7237 5945 5001 4197 3804 3661 3757 3450 3258 2846 2547 2337 2400 2160 2241 2177 2174 2153 2124 2134 2112 2131 2162 2211 2139 2188 2174 2159 2173 2193 2085 2090 2134 2189 2150 2122 2173 2162 2153 2119 2064 2062 2102 2149 2080 2081 2190 2112 2189 2134 2147 2211 2111 2204 2245 2275 2232 2359 2382 2420 2501 2500 2542 2571 2470 2454 2348 2126 2153 2137 2155 2214 2123 2295 2182 2062 2165 2221 2217 2183 2133 2117 2177 2165 2195 2239 2228 2270 2316 2343 2406 2253 2379 2492 2476 2590 2601 2636 2459 2544 2455 2471 2502 2540 2642 2629 2654 2649 2514 2618 2652 2591 2702 2670 2978 2896 3025 2789 2743 2541 2521 2430 2353 2441 2378 2627 2865 3376 3948 4702 5561 6393 7293 8744 9835 10891 11798 12545 11996 10036 7402 5693 4185 3154 2815 2559 2310 2352 2384 2339 2265 2284 2330 2282 2288 2287 2265 2195 2269 2292 2398 2304 2256 2342 2204 2219 2186 2199 2164 2244 2355 2258 2278 2296 2409 2488 2493 2642 2633 2759 2615 2672 2507 2402 2341 2258 2165 2218 2273 2272 2202 2199 2202 2230 2285 2333 2389 2504 2622 2843 3085 3100 3269 3560 3862 4117 4572 4437 4305 3815 3184 2982 2476 2369 2322 2238 2330 2312 2260 2293 2317 2299 2320 2308 2383 2299 2341 2397 2308 2355 2430 2346 2541 2533 2486 2577 2405 2461 2406 2383 2273 2297 2253 2236 2253 2353 2308 2409 2506 2517 2739 2800 3075 3245 3348 3510 3583 3516 3570 3488 3202 2870 2657 2521 2421 2289 2244 2274 2331 2302 2274 2307 2457 2463 2487 2587 2603 2778 2733 2776 2741 2572 2598 2606 2574 2501 2551 2632 2613 2677 2882 2912 2789 2704 2504 2486 2314 2259 2312 2339 2303 2346 2230 2342 2171 2243 2209 2275 2287 2210 2255 2292 2285 2284 2285 2262 2314 2304 2236 2358 2347 2473 2435 2591 2650 2767 2828 2967 3195 3285 3481 3597 3344 3392 3417 3346 3338 3238 3092 3098 3133 3157 3171 3252 3595 3820 3892 3754 3419 3102 2848 2719 2561 2621 2767 2761 2877 2944 3026 3403 3359 3447 3233 2927 2723 2666 2457 2385 2347 2290 2255 2177 2216 2223 2262 2214 2300 2281 2262 2304 2290 2222 2272 2242 2284 2233 2277 2337 2312 2310 2343 2380 2349 2450 2618 2631 2849 2885 3167 3215 3546 3655 3779 3383 2952 2982 2679 2580 2534 2575 2445 2649 2761 2860 3016 3124 3229 3226 3248 3078 2963 2886 2860 2773 2691 2890 3027 2974 2902 2749 2703 2716 2550 2440 2345 2341 2375 2375 2372 2296 2427 2346 2344 2384 2338 2379 2323 2297 2345 2265 2217 2262 2332 2284 2286 2351 2333 2312 2301 2204 2212 2284 2446 2375 2477 2631 2823 2772 3008 3184 3408 3282 3205 3305 3245 3058 2993 2944 2832 2836 3038 3043 3076 2985 2706 2736 2705 2667 2558 2566 2503 2517 2651 2584 2539 2627 2657 2882 2883 3071 2898 2826 2641 2517 2484 2366 2347 2311 2349 2299 2226 2254 2290 2244 2235 2278 2341 2257 2379 2297 2297 2362 2345 2233 2241 2259 2201 2317 2237 2296 2235 2236 2268 2433 2336 2330 2225 2241 2287 2273 2303 2211 2332 2239 2180 2273 2265 2339 2378 2483 2431 2448 2707 2716 2789 2945 3104 2965 2812 2775 2832 2807 2738 2971 2832 2783 2698 2625 2644 2658 2509 2631 2842 2923 3063 3030 3155 3392 3628 3917 4057 4424 4656 5315 5935 6584 7130 7514 7219 6764 6021 5257 4662 4176 3570 3083 2814 2752 2709 2734 2720 2658 2784 2802 2836 2688 2594 2604 2455 2383 2360 2345 2357 2284 2199 2241 2276 2301 2391 2233 2243 2281 2264 2246 2272 2277 2267 2356 2258 2342 2342 2309 2311 2348 2284 2327 2217 2295 2271 2248 2259 2252 2305 2381 2311 2237 2259 2272 2334 2347 2297 2268 2260 2320 2282 2204 2371 2294 2291 2388 2409 2464 2460 2475 2527 2616 2541 2491 2490 2596 2571 2563 2550 2491 2604 2760 2694 2841 2869 2860 2793 2659 2663 2604 2525 2302 2367 2325 2272 2414 2346 2323 2316 2404 2410 2439 2384 2381 2381 2453 2460 2648 2550 2523 2512 2562 2516 2472 2493 2313 2337 2446 2437 2402 2540 2641 2762 2722 2748 2780 2658 2679 2669 2538 2554 2527 2484 2383 2433 2433 2405 2460 2330 2493 2456 2453 2332 2417 2482 2528 2584 2653 2639 2675 2646 2651 2776 2686 2510 2479 2390 2450 2345 2320 2417 2265 2375 2345 2305 2385 2428 2356 2480 2444 2369 2284 2439 2414 2485 2533 2516 2400 2541 2448 2428 2445 2527 2443 2573 2560 2724 2794 3051 3119 3041 2873 2887 2748 2827 2754 2569 2529 2427 2382 2458 2481 2473 2621 2659 2581 2549 2560 2640 2726 2831 2742 2697 2538 2480 2383 2423 2394 2338 2349 2270 2330 2244 2305 2293 2265 2316 2345 2298 2399 2333 2293 2374 2310 2353 2350 2294 2412 2342 2325 2331 2326 2312 2392 2380 2444 2513 2434 2559 2594 2596 2480 2535 2537 2564 2563 2619 2694 2685 2643 2604 2556 2543 2504 2519 2389 2454 2444 2518 2592 2558 2580 2585 2798 2743 2899 3082 3438 3635 3922 4141 4175 4124 3738 3711 3556 3443 3218 3000 2652 2705 2601 2476 2358 2392 2362 2378 2361 2421 2320 2308 2359 2372 2209 2422 2261 2416 2345 2342 2350 2278 2305 2331 2440 2352 2379 2379 2403 2430 2510 2510 2579 2547 2522 2506 2501 2464 2606 2612 2588 2625 2537 2500 2500 2453 2428 2410 2454 2412 2328 2305 2374 2341 2459 2368 2280 2369 2437 2405 2483 2447 2494 2537 2511 2529 2622 2620 2695 2546 2485 2601 2709 2582 2785 2817 2858 3070 3124 3368 3631 3677 3856 3939 3922 3678 3764 3780 3490 3490 3414 3204 2882 2812 2707 2876 2758 2729 2774 2783 2788 2798 2917 2962 2939 2713 2791 2649 2763 2700 2592 2462 2515 2492 2498 2334 2355 2524 2394 2385 2446 2375 2430 2529 2480 2553 2532 2589 2554 2510 2438 2471 2466 2525 2492 2275 2397 2516 2392 2432 2480 2545 2554 2592 2468 2617 2675 2874 2998 2872 2735 2704 2551 2569 2640 2599 2486 2343 2412 2364 2512 2354 2422 2509 2502 2468 2513 2488 2472 2449 2487 2471 2447 2383 2406 2351 2364 2352 2463 2463 2435 2353 2397 2448 2489 2400 2332 2419 2445 2497 2463 2500 2472 2740 2667 2814 2715 2675 2500 2459 2563 2661 2575 2482 2464 2501 2363 2414 2492 2482 2584 2544 2476 2402 2472 2392 2494 2444 2549 2434 2428 2480 2406 2406 2474 2547 2475 2473 2447 2421 2406 2368 2315 2301 2297 2391 2367 2350 2360 2348 2430 2543 2525 2565 2607 2619 2789 2908 2804 2791 2829 2741 2764 2873 2680 2875 2676 2626 2495 2511 2476 2558 2378 2505 2453 2362 2393 2427 2520 2519 2470 2508 2583 2657 2609 2615 2583 2614 2631 2561 2635 2623 2530 2480 2468 2541 2517 2607 2656 2721 2659 2572 2487 2520 2496 2563 2513 2547 2530 2406 2526 2537 2551 2432 2454 2439 2357 2403 2338 2425 2451 2393 2343 2276 2329 2349 2422 2492 2435 2406 2440 2468 2443 2514 2512 2474 2533 2529 2500 2527 2347 2425 2450 2521 2514 2528 2467 2452 2594 2477 2525 2403 2565 2505 2383 2407 2412 2379 2389 2447 2418 2396 2450 2491 2592 2550 2539 2629 2570 2551 2586 2521 2484 2543 2605 2598 2567 2544 2592 2679 2641 2659 2635 2677 2518 2640 2607 2627 2613 2537 2427 2486 2447 2453 2424 2494 2394 2452 2477 2577 2504 2575 2533 2564 2553 2572 2597 2578 2522 2592 2453 2518 2525 2517 2619 2572 2538 2624 2634 2597 2543 2584 2632 2600 2500 2575 2458 2570 2595 2645 2633 2418 2485 2448 2416 2546 2449 2563 2515 2415 2414 2480 2416 2420 2484 2569 2511 2659 2591 2733 2821 2866 2974 3007 2935 2806 2744 2696 2701 2775 2769 2791 2703 2603 2585 2601 2595 2719 2656 2699 2700 2699 2607 2620 2612 2640 2591 2591 2579 2572 2486 2479 2490 2462 2408 2443 2524 2414 2435 2286 2392 2476 2363 2357 2414 2412 2341 2265 2379 2372 2325 2414 2320 2319 2391 2383 2380 2305 2362 2343 2431 2413 2309 2395 2408 2453 2473 2469 2409 2532 2413 2482 2566 2409 2356 2424 2471 2381 2397 2394 2368 2402 2295 2389 2392 2356 2390 2419 2396 2442 2347 2395 2388 2429 2457 2481 2446 2517 2359 2487 2292 2499 2463 2429 2461 2492 2420 2382 2559 2588 2664 2604</counts>
			</dataPoints>
		</scan>
	</xrdMeasurement>
</xrdMeasurements>