File: dataset/precursor_mixture/NiO_0p2030-Li2CO3_0p2999-TiO2_0p5025--2min.xrdml
<?xml version="1.0"?>
<xrdMeasurements xmlns="http://www.xrdml.com/XRDMeasurement/2.3" xmlns:xsi="http://www.w3.org/2001/XMLSchema-instance" xsi:schemaLocation="http://www.xrdml.com/XRDMeasurement/2.3 http://www.xrdml.com/XRDMeasurement/2.3/XRDMeasurement.xsd" status="Completed" recordIdentifier="{0F07D0C8-E462-41FF-A091-34AAC9F9EA01}">
	<comment>
		<entry/>
	</comment>
	<sample type="To be analyzed">
		<id>NiO_0p2030-Li2CO3_0p2999-TiO2_0p5025--2min</id>
		<name></name>
		<preparedBy></preparedBy>
	</sample>
	<xrdMeasurement measurementType="Scan" status="Completed" sampleMode="Reflection">
		<usedWavelength intended="K-Alpha 1">
			<kAlpha1 unit="Angstrom">1.5405980</kAlpha1>
			<kAlpha2 unit="Angstrom">1.5444260</kAlpha2>
			<kBeta unit="Angstrom">1.3922500</kBeta>
			<ratioKAlpha2KAlpha1>0.5000</ratioKAlpha2KAlpha1>
		</usedWavelength>
		<incidentBeamPath>
			<radius unit="mm">145.00</radius>
			<xRayTube id="1010048" name="Empyrean Cu LFF HR (9430 033 7310x)">
				<tension unit="kV">40.0</tension>
				<current unit="mA">15.0</current>
				<anodeMaterial>Cu</anodeMaterial>
				<focus type="Line">
					<length unit="mm">12.0</length>
					<width unit="mm">0.4</width>
					<takeOffAngle unit="deg">6.0</takeOffAngle>
				</focus>
			</xRayTube>
			<sollerSlit id="21010002" name="Soller slits 0.04 rad.">
				<opening unit="rad">0.0400</opening>
			</sollerSlit>
			<mask id="22031000" name="Fixed mask 13 mm">
				<width unit="mm">9.00</width>
			</mask>
			<divergenceSlit id="22120001" name="Divergence slit 1°" xsi:type="fixedDivergenceSlitType">
				<distanceToSample unit="mm">50.00</distanceToSample>
				<height unit="mm">1.52</height>
			</divergenceSlit>
		</incidentBeamPath>
		<sampleMovement xsi:type="spinningSampleMovementType">
			<spinnerRevolutionTime unit="seconds">1.0</spinnerRevolutionTime>
		</sampleMovement>
		<diffractedBeamPath>
			<radius unit="mm">145.00</radius>
			<antiScatterSlit id="22090040" name="AS slit 9 mm (PIXcel)" xsi:type="fixedAntiScatterSlitType">
				<height unit="mm">9.00</height>
			</antiScatterSlit>
			<sollerSlit id="21020003" name="Large Soller slits 0.04 rad.">
				<opening unit="rad">0.0400</opening>
			</sollerSlit>
			<filter id="20030001" name="Large beta-filter Nickel">
				<material>Ni</material>
				<thickness unit="mm">0.020</thickness>
			</filter>
			<detector id="7010019" name="PIXcel1D-Medipix3 detector" xsi:type="rtmsDetectorType">
				<phd unit="keV">
					<lowerLevel>4.02</lowerLevel>
					<upperLevel>11.27</upperLevel>
				</phd>
				<mode>Scanning</mode>
				<activeLength unit="deg">5.542</activeLength>
			</detector>
		</diffractedBeamPath>
		<scan appendNumber="0" mode="Continuous" scanAxis="Gonio" status="Completed">
			<header>
				<startTimeStamp>2024-11-14T17:00:26-08:00</startTimeStamp>
				<endTimeStamp>2024-11-14T17:02:31-08:00</endTimeStamp>
				<author>
					<name>AutomatedUser</name>
				</author>
				<source>
					<applicationSoftware version="1.7b (136)">PANalytical Aeris Instrument Suite</applicationSoftware>
					<instrumentControlSoftware version="3.2.00000000 20240306">AERIS</instrumentControlSoftware>
					<instrumentID>950485</instrumentID>
				</source>
			</header>
			<dataPoints>
				<positions axis="2Theta" unit="deg">
					<startPosition>10.02173288</startPosition>
					<endPosition>99.99585608</endPosition>
				</positions>
				<positions axis="Omega" unit="deg">
					<startPosition>5.01086644</startPosition>
					<endPosition>49.99792804</endPosition>
				</positions>
				<commonCountingTime unit="seconds">10.965</commonCountingTime>
				<counts unit="counts">2244 2155 2247 2279 2215 2208 2240 2261 2136 2297 2174 2154 2171 2079 2102 2139 2169 2131 2073 2090 2123 2058 2130 2066 2114 2114 2055 2062 1969 2006 2004 1984 1979 1971 1974 1979 1952 1953 1988 1949 2024 1972 1947 2062 2021 1923 1897 1973 1999 1868 1877 1953 1775 1881 1854 1907 1835 1850 1833 1878 1761 1869 1942 1861 1888 1862 1875 1840 1880 1804 1831 1833 1913 1848 1843 1844 1824 1840 1781 1750 1723 1769 1798 1809 1804 1783 1790 1857 1780 1683 1803 1766 1792 1757 1735 1744 1780 1703 1795 1760 1741 1686 1798 1809 1685 1736 1746 1690 1781 1765 1766 1830 1792 1809 1835 1735 1756 1765 1695 1720 1731 1749 1713 1781 1747 1690 1762 1808 1753 1721 1749 1694 1753 1741 1697 1740 1724 1693 1656 1719 1605 1734 1738 1696 1729 1641 1857 1720 1735 1658 1739 1758 1704 1709 1744 1758 1748 1759 1693 1810 1635 1768 1626 1683 1728 1699 1725 1688 1783 1786 1714 1731 1696 1710 1796 1712 1693 1626 1683 1727 1716 1691 1691 1681 1703 1723 1625 1708 1704 1594 1725 1722 1687 1733 1676 1690 1697 1674 1690 1704 1695 1622 1610 1585 1732 1730 1653 1659 1702 1585 1639 1673 1628 1696 1605 1615 1603 1681 1574 1632 1702 1601 1603 1610 1631 1697 1575 1638 1668 1651 1679 1638 1699 1683 1714 1608 1664 1740 1642 1634 1616 1683 1713 1632 1616 1640 1599 1683 1564 1658 1632 1658 1670 1625 1758 1804 1814 1927 2142 2233 2460 2441 2428 2325 2293 2226 2011 1901 1687 1603 1667 1632 1731 1658 1676 1630 1578 1720 1576 1639 1652 1604 1577 1567 1539 1655 1582 1630 1677 1563 1578 1587 1614 1577 1629 1592 1603 1630 1599 1608 1652 1668 1582 1565 1616 1560 1659 1609 1551 1646 1695 1746 1717 1635 1645 1701 1574 1559 1545 1628 1640 1588 1515 1647 1532 1520 1512 1538 1608 1609 1633 1628 1698 1656 1683 1617 1693 1733 1748 1803 1850 1855 1897 2008 2097 2361 2693 3370 4704 6541 8668 10689 12361 13005 12616 11768 10461 8843 6573 4354 3028 2359 2119 1973 1817 1811 1809 1699 1636 1728 1623 1632 1674 1607 1660 1655 1605 1577 1573 1637 1613 1614 1574 1566 1639 1597 1534 1551 1480 1568 1498 1573 1550 1545 1475 1542 1547 1506 1518 1586 1561 1601 1504 1552 1571 1565 1596 1610 1473 1536 1570 1550 1540 1508 1544 1461 1499 1540 1505 1483 1526 1520 1464 1468 1512 1473 1509 1419 1486 1515 1542 1532 1419 1511 1407 1511 1523 1506 1478 1540 1493 1507 1490 1491 1600 1635 1626 1637 1720 1626 1783 1771 1693 1668 1536 1481 1493 1487 1510 1537 1442 1403 1534 1526 1496 1483 1497 1634 1650 1593 1742 1791 1822 2071 2088 2178 2100 2123 2071 1868 1814 1803 1681 1671 1593 1584 1517 1464 1559 1611 1581 1654 1654 1592 1671 1793 1857 2084 2383 2556 2838 2989 3067 3160 2905 2779 2673 2284 2012 1891 1768 1630 1670 1629 1548 1519 1588 1426 1428 1409 1527 1509 1442 1425 1485 1395 1427 1453 1428 1422 1404 1444 1459 1404 1378 1441 1450 1427 1424 1452 1416 1441 1478 1378 1426 1473 1515 1449 1417 1438 1447 1576 1599 1698 1708 1736 1716 1747 1680 1681 1569 1536 1433 1458 1517 1398 1477 1496 1398 1388 1448 1455 1444 1462 1371 1388 1361 1376 1407 1369 1369 1360 1393 1397 1370 1471 1377 1384 1400 1370 1373 1318 1357 1412 1472 1464 1472 1563 1746 1856 1896 1950 2020 1981 1846 1755 1657 1609 1472 1449 1489 1465 1484 1574 1507 1643 1658 1859 2005 2269 2444 2641 2872 3104 3340 3733 3806 4162 4433 4328 4423 4073 3655 3091 2791 2456 2534 2837 3105 3536 3922 3897 3884 3655 3435 3116 2486 2071 1822 1710 1543 1521 1613 1548 1619 1721 1857 1981 2131 2136 2149 2068 1927 1871 1679 1523 1468 1365 1410 1390 1379 1459 1373 1406 1387 1353 1380 1463 1509 1529 1552 1600 1625 1578 1626 1557 1552 1528 1536 1518 1464 1401 1395 1464 1432 1447 1361 1441 1316 1366 1341 1346 1359 1321 1370 1299 1361 1328 1439 1397 1354 1287 1354 1355 1334 1325 1392 1339 1411 1387 1374 1245 1227 1356 1316 1439 1277 1367 1349 1386 1253 1345 1333 1298 1394 1294 1329 1300 1340 1356 1275 1326 1359 1447 1399 1381 1385 1328 1356 1318 1348 1474 1415 1503 1391 1563 1565 1607 1527 1705 1846 2029 2251 2952 3823 4650 5572 6178 6409 6311 5943 5102 4167 3344 2614 2131 1822 1649 1579 1437 1509 1419 1440 1448 1326 1350 1334 1359 1368 1354 1283 1281 1325 1357 1362 1328 1391 1286 1268 1329 1320 1355 1327 1280 1276 1353 1362 1357 1326 1369 1293 1409 1324 1307 1316 1347 1289 1373 1349 1263 1377 1307 1217 1255 1266 1328 1300 1247 1303 1286 1332 1308 1344 1299 1281 1320 1330 1349 1396 1329 1314 1318 1279 1258 1373 1402 1321 1347 1334 1402 1359 1299 1367 1361 1346 1300 1323 1389 1420 1350 1361 1294 1405 1420 1334 1408 1487 1429 1456 1630 1638 1892 2149 2706 3265 4158 4483 4803 4836 5022 4401 3508 2796 2335 1904 1635 1618 1491 1476 1494 1500 1494 1431 1514 1411 1498 1444 1434 1438 1382 1342 1410 1376 1345 1299 1342 1331 1328 1312 1293 1270 1340 1323 1252 1323 1293 1307 1288 1205 1333 1312 1285 1309 1343 1244 1289 1347 1331 1343 1334 1350 1267 1290 1330 1330 1322 1327 1345 1310 1255 1271 1341 1310 1324 1339 1277 1261 1363 1325 1246 1328 1234 1239 1264 1309 1330 1245 1310 1350 1267 1271 1327 1357 1224 1255 1285 1292 1245 1220 1225 1275 1272 1277 1251 1299 1334 1280 1274 1321 1274 1220 1276 1265 1307 1277 1305 1257 1266 1225 1357 1272 1409 1317 1313 1300 1264 1336 1341 1336 1268 1329 1399 1461 1473 1464 1637 1695 1945 2367 2769 3066 3267 3538 3695 3435 2984 2589 2250 1924 1668 1536 1523 1414 1388 1330 1392 1391 1397 1425 1463 1416 1450 1594 1633 1936 2399 2710 2962 3258 3497 3588 3366 2889 2464 2208 1920 1703 1461 1318 1351 1321 1349 1346 1309 1362 1378 1253 1281 1307 1296 1289 1336 1275 1260 1323 1245 1294 1256 1264 1267 1277 1305 1308 1290 1335 1361 1340 1348 1324 1382 1460 1340 1272 1333 1302 1299 1280 1269 1278 1259 1239 1272 1270 1327 1285 1290 1306 1282 1442 1348 1339 1363 1494 1340 1314 1263 1375 1368 1282 1336 1317 1274 1314 1349 1284 1354 1395 1361 1262 1360 1359 1384 1346 1360 1314 1372 1333 1415 1352 1312 1353 1369 1349 1384 1275 1356 1307 1319 1339 1344 1244 1347 1336 1299 1359 1409 1415 1397 1446 1428 1346 1329 1332 1330 1328 1335 1272 1316 1294 1250 1311 1271 1263 1281 1343 1308 1292 1293 1327 1317 1252 1339 1333 1329 1323 1315 1281 1383 1294 1361 1406 1362 1287 1342 1318 1336 1340 1390 1325 1290 1405 1283 1235 1421 1359 1362 1450 1502 1543 1616 1669 1679 1761 1810 1670 1634 1720 1724 1750 1861 2122 2563 2926 3400 3722 4040 4557 4370 4254 3952 3913 3611 3168 2823 2481 2211 1979 1743 1669 1546 1514 1513 1451 1473 1353 1439 1402 1371 1471 1393 1320 1369 1296 1272 1343 1312 1246 1311 1298 1265 1300 1299 1339 1260 1196 1250 1233 1267 1276 1298 1319 1259 1293 1246 1280 1266 1218 1323 1348 1238 1257 1290 1327 1275 1252 1256 1277 1343 1356 1284 1259 1335 1253 1312 1352 1256 1279 1279 1238 1228 1249 1228 1240 1274 1230 1279 1216 1300 1293 1244 1304 1209 1259 1264 1272 1214 1234 1227 1291 1228 1256 1220 1237 1210 1293 1253 1323 1254 1305 1281 1358 1263 1170 1319 1243 1280 1228 1191 1235 1300 1259 1302 1207 1248 1279 1253 1273 1308 1303 1226 1275 1228 1263 1303 1260 1177 1298 1264 1410 1386 1617 1727 1748 1822 1943 2037 1899 1780 1684 1578 1499 1437 1422 1349 1287 1242 1308 1285 1236 1345 1248 1309 1328 1285 1279 1245 1219 1296 1250 1310 1289 1327 1422 1340 1538 1530 1663 1855 1896 2064 2002 2041 1968 1775 1575 1602 1479 1385 1321 1317 1280 1252 1247 1238 1239 1246 1275 1188 1260 1217 1226 1296 1313 1231 1240 1271 1218 1276 1232 1223 1246 1255 1244 1244 1295 1279 1291 1261 1287 1271 1247 1238 1234 1270 1256 1269 1277 1219 1221 1266 1226 1166 1255 1170 1272 1336 1207 1275 1309 1239 1290 1221 1289 1178 1260 1242 1225 1223 1260 1229 1307 1276 1261 1273 1249 1278 1291 1293 1280 1307 1321 1325 1313 1383 1337 1368 1348 1385 1319 1304 1287 1378 1335 1256 1251 1287 1315 1310 1373 1292 1309 1395 1408 1530 1691 1842 2131 2290 2418 2625 2561 2457 2356 2301 2422 2371 2269 2158 2013 1997 1920 1754 1776 1630 1627 1529 1509 1458 1529 1548 1649 1584 1573 1567 1473 1433 1434 1409 1432 1374 1321 1241 1229 1236 1216 1229 1212 1288 1250 1207 1150 1257 1235 1218 1205 1229 1230 1240 1186 1294 1224 1299 1241 1287 1180 1279 1232 1256 1229 1273 1233 1218 1296 1253 1235 1289 1231 1253 1201 1264 1256 1253 1250 1178 1227 1260 1230 1226 1227 1274 1234 1199 1316 1221 1253 1280 1266 1217 1338 1324 1326 1380 1383 1376 1490 1469 1531 1664 1679 1587 1592 1565 1551 1560 1557 1514 1445 1428 1427 1382 1312 1352 1335 1311 1324 1288 1178 1259 1248 1263 1195 1242 1235 1195 1221 1323 1252 1293 1317 1299 1265 1337 1230 1334 1303 1221 1230 1246 1283 1256 1265 1229 1156 1229 1319 1223 1222 1249 1189 1233 1262 1285 1249 1223 1275 1240 1344 1313 1257 1316 1399 1354 1419 1287 1363 1269 1306 1372 1376 1397 1548 1558 1700 1837 1845 1827 1599 1559 1634 1618 1588 1582 1533 1592 1514 1572 1445 1409 1421 1393 1391 1393 1349 1352 1254 1300 1261 1258 1240 1194 1223 1228 1271 1218 1229 1207 1242 1192 1282 1205 1167 1232 1255 1259 1238 1167 1261 1244 1229 1215 1236 1171 1204 1188 1168 1255 1178 1199 1197 1254 1216 1239 1214 1273 1249 1283 1220 1223 1172 1201 1172 1207 1250 1205 1223 1231 1253 1256 1233 1263 1215 1226 1253 1257 1224 1207 1298 1200 1213 1252 1198 1267 1222 1193 1277 1227 1199 1192 1206 1206 1318 1209 1306 1165 1234 1284 1211 1254 1234 1160 1201 1222 1195 1213 1181 1222 1187 1203 1236 1167 1211 1143 1286 1200 1169 1184 1195 1206 1210 1199 1165 1186 1218 1226 1138 1204 1164 1187 1196 1200 1217 1178 1225 1196 1233 1163 1178 1228 1126 1198 1166 1215 1185 1212 1146 1201 1193 1209 1268 1213 1174 1223 1192 1195 1205 1177 1211 1211 1208 1192 1187 1169 1175 1266 1232 1209 1224 1227 1219 1215 1158 1202 1226 1216 1185 1192 1212 1201 1224 1210 1260 1234 1241 1193 1242 1262 1265 1223 1272 1205 1209 1237 1272 1189 1241 1157 1246 1172 1174 1197 1257 1212 1137 1272 1216 1284 1151 1227 1282 1168 1257 1177 1254 1246 1237 1225 1167 1215 1213 1242 1230 1268 1261 1254 1267 1301 1261 1203 1269 1259 1240 1250 1183 1170 1346 1297 1312 1315 1272 1336 1252 1228 1328 1279 1303 1249 1225 1234 1253 1225 1302 1264 1293 1255 1298 1332 1361 1485 1471 1471 1531 1389 1405 1377 1361 1388 1483 1355 1374 1450 1323 1231 1307 1314 1443 1406 1492 1538 1615 1631 1782 1774 1706 1664 1555 1495 1492 1527 1422 1437 1346 1368 1296 1368 1253 1307 1250 1198 1268 1192 1215 1233 1235 1230 1220 1191 1151 1188 1258 1185 1198 1246 1220 1207 1190 1240 1209 1205 1234 1236 1244 1220 1193 1169 1232 1253 1213 1178 1262 1237 1232 1271 1290 1247 1277 1182 1235 1310 1274 1221 1214 1196 1320 1213 1237 1207 1295 1275 1226 1259 1304 1314 1410 1460 1411 1446 1427 1359 1333 1304 1373 1293 1322 1247 1335 1275 1310 1225 1238 1258 1176 1235 1244 1210 1233 1249 1221 1238 1218 1177 1250 1244 1275 1226 1240 1304 1325 1364 1425 1331 1306</counts>
			</dataPoints>
		</scan>
	</xrdMeasurement>
</xrdMeasurements>