File: dataset/precursor_mixture/NiO_0p3035-Bi2O3_0p3016-Li2CO3_0p3997--8min.xrdml
<?xml version="1.0"?>
<xrdMeasurements xmlns="http://www.xrdml.com/XRDMeasurement/2.3" xmlns:xsi="http://www.w3.org/2001/XMLSchema-instance" xsi:schemaLocation="http://www.xrdml.com/XRDMeasurement/2.3 http://www.xrdml.com/XRDMeasurement/2.3/XRDMeasurement.xsd" status="Completed" recordIdentifier="{F4408F37-F6F8-4A34-B720-A0B2A1228766}">
	<comment>
		<entry/>
	</comment>
	<sample type="To be analyzed">
		<id>NiO_0p3035-Bi2O3_0p3016-Li2CO3_0p3997--8min</id>
		<name></name>
		<preparedBy></preparedBy>
	</sample>
	<xrdMeasurement measurementType="Scan" status="Completed" sampleMode="Reflection">
		<usedWavelength intended="K-Alpha 1">
			<kAlpha1 unit="Angstrom">1.5405980</kAlpha1>
			<kAlpha2 unit="Angstrom">1.5444260</kAlpha2>
			<kBeta unit="Angstrom">1.3922500</kBeta>
			<ratioKAlpha2KAlpha1>0.5000</ratioKAlpha2KAlpha1>
		</usedWavelength>
		<incidentBeamPath>
			<radius unit="mm">145.00</radius>
			<xRayTube id="1010048" name="Empyrean Cu LFF HR (9430 033 7310x)">
				<tension unit="kV">40.0</tension>
				<current unit="mA">15.0</current>
				<anodeMaterial>Cu</anodeMaterial>
				<focus type="Line">
					<length unit="mm">12.0</length>
					<width unit="mm">0.4</width>
					<takeOffAngle unit="deg">6.0</takeOffAngle>
				</focus>
			</xRayTube>
			<sollerSlit id="21010002" name="Soller slits 0.04 rad.">
				<opening unit="rad">0.0400</opening>
			</sollerSlit>
			<mask id="22031000" name="Fixed mask 13 mm">
				<width unit="mm">9.00</width>
			</mask>
			<divergenceSlit id="22120001" name="Divergence slit 1°" xsi:type="fixedDivergenceSlitType">
				<distanceToSample unit="mm">50.00</distanceToSample>
				<height unit="mm">1.52</height>
			</divergenceSlit>
		</incidentBeamPath>
		<sampleMovement xsi:type="spinningSampleMovementType">
			<spinnerRevolutionTime unit="seconds">1.0</spinnerRevolutionTime>
		</sampleMovement>
		<diffractedBeamPath>
			<radius unit="mm">145.00</radius>
			<antiScatterSlit id="22090040" name="AS slit 9 mm (PIXcel)" xsi:type="fixedAntiScatterSlitType">
				<height unit="mm">9.00</height>
			</antiScatterSlit>
			<sollerSlit id="21020003" name="Large Soller slits 0.04 rad.">
				<opening unit="rad">0.0400</opening>
			</sollerSlit>
			<filter id="20030001" name="Large beta-filter Nickel">
				<material>Ni</material>
				<thickness unit="mm">0.020</thickness>
			</filter>
			<detector id="7010019" name="PIXcel1D-Medipix3 detector" xsi:type="rtmsDetectorType">
				<phd unit="keV">
					<lowerLevel>4.02</lowerLevel>
					<upperLevel>11.27</upperLevel>
				</phd>
				<mode>Scanning</mode>
				<activeLength unit="deg">5.542</activeLength>
			</detector>
		</diffractedBeamPath>
		<scan appendNumber="0" mode="Continuous" scanAxis="Gonio" status="Completed">
			<header>
				<startTimeStamp>2024-11-14T16:26:38-08:00</startTimeStamp>
				<endTimeStamp>2024-11-14T16:34:45-08:00</endTimeStamp>
				<author>
					<name>AutomatedUser</name>
				</author>
				<source>
					<applicationSoftware version="1.7b (136)">PANalytical Aeris Instrument Suite</applicationSoftware>
					<instrumentControlSoftware version="3.2.00000000 20240306">AERIS</instrumentControlSoftware>
					<instrumentID>950485</instrumentID>
				</source>
			</header>
			<dataPoints>
				<positions axis="2Theta" unit="deg">
					<startPosition>10.00943322</startPosition>
					<endPosition>99.99442286</endPosition>
				</positions>
				<positions axis="Omega" unit="deg">
					<startPosition>5.00471661</startPosition>
					<endPosition>49.99721143</endPosition>
				</positions>
				<commonCountingTime unit="seconds">12.495</commonCountingTime>
				<counts unit="counts">2667 2762 2728 2623 2656 2741 2669 2765 2666 2709 2724 2683 2547 2620 2671 2728 2729 2759 2564 2742 2652 2749 2672 2621 2648 2612 2612 2657 2633 2663 2663 2649 2663 2537 2675 2653 2594 2630 2617 2662 2636 2555 2525 2578 2707 2520 2651 2661 2546 2547 2689 2583 2563 2627 2564 2612 2496 2602 2550 2560 2575 2526 2611 2578 2604 2528 2553 2562 2543 2568 2568 2518 2581 2556 2570 2522 2484 2543 2506 2514 2531 2565 2476 2515 2557 2490 2525 2457 2495 2495 2502 2507 2559 2487 2423 2440 2466 2427 2493 2363 2454 2451 2475 2384 2494 2401 2499 2479 2482 2344 2489 2478 2427 2365 2477 2479 2407 2493 2451 2416 2512 2422 2432 2395 2503 2462 2396 2489 2348 2436 2399 2424 2436 2371 2441 2427 2461 2483 2388 2413 2513 2360 2411 2423 2317 2397 2384 2483 2462 2356 2428 2448 2407 2440 2458 2392 2432 2390 2379 2341 2347 2313 2442 2352 2463 2372 2429 2319 2330 2305 2400 2325 2425 2327 2375 2375 2495 2374 2424 2464 2379 2396 2398 2308 2424 2379 2247 2439 2344 2285 2331 2267 2295 2388 2323 2341 2378 2297 2352 2226 2432 2333 2371 2245 2294 2262 2300 2337 2388 2280 2346 2298 2184 2328 2291 2377 2208 2337 2296 2290 2400 2383 2366 2329 2191 2285 2310 2342 2425 2254 2326 2233 2354 2398 2397 2268 2364 2252 2314 2306 2439 2308 2330 2352 2467 2367 2318 2338 2422 2377 2386 2311 2358 2413 2433 2317 2318 2416 2483 2414 2426 2463 2430 2401 2432 2518 2466 2415 2364 2402 2478 2428 2475 2364 2513 2501 2480 2549 2411 2391 2391 2317 2321 2388 2345 2332 2351 2293 2341 2304 2339 2362 2413 2326 2298 2202 2339 2252 2325 2299 2323 2348 2349 2347 2287 2349 2259 2237 2201 2255 2307 2228 2284 2245 2250 2239 2271 2174 2229 2212 2202 2300 2240 2221 2287 2190 2204 2185 2209 2259 2211 2239 2259 2240 2202 2187 2245 2145 2247 2258 2281 2195 2241 2212 2158 2109 2222 2203 2226 2249 2281 2216 2254 2201 2205 2086 2238 2269 2183 2298 2229 2262 2168 2272 2259 2171 2139 2198 2258 2196 2235 2193 2298 2230 2212 2178 2319 2116 2199 2128 2191 2233 2277 2175 2240 2174 2281 2220 2201 2151 2274 2180 2299 2170 2210 2233 2192 2136 2180 2237 2193 2216 2234 2171 2214 2245 2200 2162 2135 2119 2183 2213 2246 2230 2224 2225 2197 2254 2108 2191 2251 2177 2198 2214 2192 2200 2177 2315 2195 2254 2301 2248 2174 2250 2193 2201 2210 2194 2281 2270 2188 2261 2194 2229 2176 2204 2156 2247 2168 2202 2215 2246 2180 2207 2325 2167 2226 2208 2136 2153 2144 2194 2184 2252 2217 2167 2179 2066 2164 2228 2166 2148 2163 2167 2194 2255 2117 2148 2231 2195 2276 2267 2266 2283 2191 2246 2163 2248 2178 2238 2262 2229 2185 2164 2263 2190 2186 2270 2230 2195 2175 2224 2177 2211 2187 2280 2225 2187 2275 2124 2229 2233 2256 2162 2175 2256 2082 2181 2116 2291 2226 2340 2210 2178 2261 2275 2181 2234 2240 2123 2239 2172 2165 2152 2181 2208 2278 2231 2186 2218 2219 2200 2316 2215 2187 2180 2239 2154 2256 2223 2174 2215 2157 2167 2249 2321 2190 2128 2233 2236 2183 2252 2203 2162 2255 2201 2199 2176 2214 2186 2162 2194 2237 2249 2230 2293 2253 2167 2240 2327 2300 2201 2255 2184 2104 2148 2328 2206 2273 2216 2243 2184 2254 2287 2249 2252 2327 2295 2219 2229 2156 2304 2265 2348 2332 2224 2218 2285 2277 2224 2228 2190 2170 2349 2299 2253 2317 2302 2287 2353 2312 2375 2394 2375 2352 2402 2281 2371 2412 2360 2396 2447 2397 2384 2360 2374 2408 2327 2253 2302 2309 2255 2279 2239 2224 2266 2247 2302 2231 2205 2230 2314 2249 2250 2222 2311 2211 2308 2147 2304 2204 2262 2234 2221 2196 2110 2193 2234 2208 2203 2241 2264 2335 2213 2232 2260 2314 2290 2307 2195 2240 2137 2321 2196 2279 2231 2223 2221 2280 2298 2189 2302 2183 2247 2163 2207 2263 2196 2132 2243 2221 2297 2208 2228 2237 2280 2221 2242 2213 2185 2314 2224 2269 2211 2310 2302 2241 2255 2274 2261 2329 2195 2217 2297 2189 2269 2192 2259 2252 2216 2213 2238 2203 2256 2195 2145 2211 2217 2264 2163 2238 2321 2237 2235 2347 2200 2241 2190 2183 2253 2223 2248 2271 2218 2186 2179 2309 2254 2256 2217 2121 2240 2257 2203 2307 2180 2189 2284 2270 2194 2324 2204 2168 2182 2229 2196 2199 2225 2301 2163 2175 2335 2329 2199 2246 2315 2318 2226 2153 2345 2340 2191 2169 2286 2252 2245 2268 2279 2210 2230 2236 2327 2269 2147 2180 2248 2250 2315 2186 2216 2298 2136 2230 2286 2197 2184 2236 2152 2278 2247 2288 2274 2260 2337 2162 2315 2248 2396 2328 2246 2234 2277 2302 2290 2230 2210 2186 2239 2279 2188 2296 2108 2296 2253 2149 2251 2321 2201 2191 2224 2268 2319 2192 2168 2339 2200 2185 2225 2198 2283 2183 2185 2290 2224 2251 2262 2243 2255 2284 2315 2192 2290 2217 2256 2175 2313 2247 2306 2268 2252 2143 2452 2319 2262 2380 2346 2400 2303 2374 2437 2464 2431 2569 2534 2563 2607 2524 2632 2626 2555 2536 2493 2499 2581 2615 2611 2522 2642 2447 2410 2421 2433 2417 2379 2266 2313 2341 2360 2247 2288 2176 2223 2279 2287 2266 2362 2280 2282 2273 2254 2273 2291 2166 2190 2279 2188 2267 2208 2178 2253 2241 2198 2210 2273 2242 2296 2251 2208 2222 2152 2178 2197 2191 2229 2256 2247 2298 2238 2288 2281 2226 2281 2268 2222 2246 2242 2213 2262 2265 2217 2301 2185 2250 2120 2299 2228 2211 2184 2239 2153 2287 2190 2234 2254 2217 2336 2243 2229 2319 2148 2283 2250 2345 2290 2273 2304 2250 2213 2223 2247 2289 2227 2224 2285 2239 2311 2219 2234 2234 2200 2290 2180 2219 2263 2190 2360 2281 2267 2320 2252 2345 2289 2484 2408 2291 2417 2390 2461 2475 2435 2614 2524 2431 2608 2705 2568 2725 2801 2903 3020 3096 3124 3165 3256 3233 3323 3350 3368 3418 3455 3284 3288 3309 3291 3149 3124 3095 2975 3009 2888 2725 2652 2665 2598 2467 2456 2569 2440 2437 2333 2497 2390 2350 2494 2532 2506 2400 2555 2532 2570 2538 2542 2547 2561 2588 2533 2621 2550 2533 2562 2520 2610 2638 2542 2568 2447 2452 2439 2362 2416 2384 2259 2338 2292 2236 2357 2257 2222 2323 2246 2209 2367 2365 2313 2321 2238 2302 2242 2192 2335 2253 2164 2265 2265 2291 2329 2235 2232 2212 2311 2291 2200 2290 2203 2251 2240 2273 2248 2188 2243 2214 2216 2267 2263 2242 2151 2198 2297 2257 2286 2393 2229 2333 2267 2225 2245 2235 2314 2201 2240 2219 2312 2331 2335 2261 2290 2296 2153 2309 2237 2266 2170 2266 2256 2283 2191 2287 2300 2282 2235 2280 2356 2213 2356 2356 2370 2250 2308 2250 2293 2187 2244 2260 2146 2252 2380 2365 2357 2266 2269 2155 2221 2259 2342 2318 2315 2347 2309 2292 2320 2192 2291 2244 2319 2318 2357 2283 2332 2300 2314 2256 2215 2290 2328 2351 2311 2356 2336 2326 2335 2413 2290 2361 2380 2466 2426 2429 2414 2457 2382 2411 2365 2400 2370 2395 2441 2588 2386 2399 2400 2427 2462 2370 2443 2489 2335 2413 2418 2390 2438 2413 2390 2436 2527 2427 2419 2440 2526 2482 2544 2512 2545 2686 2605 2704 2775 2594 2739 2678 2753 2873 2785 2839 2795 2776 2845 2859 2746 2799 2753 2747 2819 2789 2845 2696 2720 2594 2523 2522 2476 2557 2522 2533 2521 2492 2433 2462 2392 2407 2388 2465 2419 2435 2336 2428 2410 2421 2314 2440 2414 2381 2493 2458 2408 2484 2502 2598 2593 2600 2680 2666 2676 2708 2830 2821 2946 3055 3119 3156 3361 3264 3389 3340 3311 3413 3423 3307 3423 3396 3207 3355 3084 3148 3035 2898 2844 2761 2753 2644 2603 2497 2611 2447 2466 2442 2425 2485 2369 2347 2344 2411 2221 2364 2365 2385 2410 2260 2257 2301 2319 2399 2319 2351 2326 2249 2319 2353 2341 2307 2324 2300 2347 2312 2302 2318 2308 2335 2280 2405 2361 2494 2432 2350 2319 2385 2461 2497 2492 2498 2408 2475 2509 2420 2458 2558 2513 2478 2516 2508 2539 2499 2522 2453 2535 2542 2483 2453 2533 2576 2610 2506 2672 2741 2669 2738 2839 2940 2967 3020 3143 3248 3425 3607 3696 3887 4074 4327 4477 4677 4752 5046 4935 5217 5056 5247 5259 5256 5094 5038 5043 4806 4609 4547 4225 4100 3798 3630 3524 3479 3201 3084 3027 2945 2751 2721 2728 2739 2757 2564 2683 2635 2500 2688 2547 2572 2566 2619 2592 2520 2511 2576 2488 2554 2511 2521 2473 2426 2531 2496 2455 2430 2468 2412 2493 2517 2489 2462 2451 2490 2467 2435 2500 2528 2547 2567 2387 2530 2439 2479 2617 2617 2562 2622 2626 2580 2622 2670 2587 2540 2762 2606 2746 2749 2749 2670 2837 2850 2828 2895 3044 2993 3222 3253 3420 3587 3671 3884 3973 4240 4454 4616 5011 5318 5651 5967 6465 6651 6984 7125 7180 7476 7279 7598 7492 7353 7430 7303 7104 6881 6673 6398 6059 5753 5325 5042 5133 4851 4581 4458 4424 4371 4383 4526 4578 4980 5160 5384 5896 6085 6564 7232 7806 8518 9492 10345 11368 12419 13593 14673 15782 16605 17329 17912 18330 18764 19048 18872 18636 18425 17936 17320 16540 15765 14371 13293 12160 10853 9521 8637 7846 6848 6230 5661 5002 4741 4241 4026 3882 3745 3628 3625 3483 3477 3430 3269 3281 3272 3302 3278 3369 3240 3246 3383 3350 3428 3452 3531 3626 3685 3918 4063 4220 4467 4562 4913 5238 5253 5584 5574 5698 5970 5889 5836 5886 5983 5744 5725 5436 5283 5262 4877 4511 4274 4135 3938 3761 3450 3325 3257 2958 2898 2841 2855 2724 2752 2622 2662 2622 2616 2542 2653 2477 2613 2493 2505 2368 2474 2431 2548 2454 2550 2441 2583 2421 2451 2402 2426 2405 2523 2419 2464 2409 2388 2372 2360 2433 2434 2353 2382 2396 2429 2443 2434 2284 2410 2344 2448 2398 2405 2442 2394 2380 2404 2390 2408 2292 2404 2483 2325 2330 2280 2253 2425 2367 2391 2366 2337 2467 2430 2322 2407 2350 2360 2344 2416 2395 2397 2405 2483 2520 2443 2373 2460 2403 2397 2470 2408 2360 2357 2456 2450 2452 2488 2378 2464 2498 2430 2538 2524 2516 2539 2546 2602 2577 2625 2581 2585 2651 2683 2643 2680 2664 2742 2735 2790 2809 2688 2757 2725 2768 2655 2748 2679 2769 2714 2697 2696 2621 2590 2569 2609 2626 2566 2515 2548 2611 2543 2516 2487 2521 2497 2622 2542 2624 2638 2541 2655 2549 2632 2587 2639 2690 2542 2596 2675 2708 2648 2727 2661 2720 2694 2818 2775 2751 2859 2768 2854 3033 2880 2974 2922 3029 3146 3072 3209 3258 3411 3306 3544 3526 3657 3621 3677 3638 3683 3964 3860 3808 3878 4043 4033 3852 4029 3869 3971 3861 3963 3677 3815 3583 3590 3592 3648 3478 3406 3352 3351 3398 3366 3348 3297 3456 3423 3395 3468 3433 3520 3444 3417 3679 3519 3413 3420 3472 3451 3471 3352 3379 3352 3266 3142 3028 3099 2973 2981 2834 2970 2815 2745 2783 2637 2565 2618 2656 2545 2606 2491 2478 2508 2473 2476 2506 2435 2457 2605 2407 2448 2333 2425 2338 2345 2422 2321 2482 2451 2389 2456 2412 2384 2475 2393 2370 2483 2312 2375 2379 2404 2427 2422 2406 2393 2388 2378 2396 2442 2455 2386 2428 2447 2442 2495 2459 2428 2480 2460 2463 2493 2451 2406 2575 2466 2497 2486 2645 2717 2538 2668 2658 2776 2627 2813 2852 2921 3090 3186 3226 3212 3337 3554 3463 3632 3730 3832 3726 3963 4018 4251 4216 4220 4282 4102 4255 4156 4058 4044 3985 3968 3925 3702 3565 3445 3431 3234 3310 3124 3084 3063 3103 3010 2923 2828 2816 2715 2726 2585 2638 2629 2562 2664 2564 2565 2430 2512 2584 2502 2517 2570 2544 2606 2617 2583 2561 2535 2509 2506 2444 2608 2581 2703 2544 2682 2676 2728 2617 2766 2833 2855 2977 2961 3053 3025 3110 3197 3221 3207 3246 3277 3336 3353 3360 3337 3335 3492 3366 3279 3241 3245 3151 3219 3284 3253 3178 3310 3406 3324 3464 3503 3281 3494 3483 3623 3391 3633 3671 3815 3667 3851 3969 4041 4228 4249 4427 4940 4964 5478 5762 6133 6334 6847 7142 7306 7613 7984 8115 8482 8631 8943 8839 9191 9256 9489 9378 9339 9579 9474 9545 9496 9733 9789 9779 9764 9838 9640 9834 9549 9382 9316 9063 8817 8616 8160 7972 7351 6859 6440 6015 5607 5234 4972 4580 4426 3900 3875 3615 3469 3284 3077 3055 2960 2916 2776 2880 2857 2759 2684 2701 2731 2554 2674 2617 2610 2614 2573 2589 2661 2536 2503 2513 2588 2689 2510 2684 2552 2741 2632 2629 2614 2747 2753 2859 2880 2961 2986 3146 3112 3131 3253 3334 3343 3402 3393 3265 3412 3432 3449 3481 3316 3384 3197 3174 3234 3181 3218 3103 3100 3068 3072 2903 2924 2824 2788 2810 2718 2741 2647 2648 2596 2630 2649 2531 2461 2535 2396 2503 2348 2400 2469 2547 2405 2424 2435 2380 2448 2364 2334 2452 2473 2393 2388 2450 2335 2360 2378 2386 2330 2380 2360 2329 2368 2324 2361 2423 2376 2324 2435 2339 2317 2442 2416 2388 2385 2465 2406 2501 2417 2516 2473 2552 2561 2539 2464 2701 2690 2716 2758 2903 2884 3102 3209 3340 3402 3627 3773 3895 3977 4070 4281 4302 4387 4380 4498 4392 4507 4603 4536 4517 4386 4254 4048 3853 3831 3738 3512 3390 3398 3262 3150 3196 3089 3137 3108 3106 3126 3202 3279 3268 3320 3387 3448 3584 3469 3599 3673 3644 3495 3472 3593 3591 3402 3428 3420 3352 3188 3153 2900 2947 2797 2846 2750 2767 2696 2617 2634 2434 2554 2435 2474 2474 2535 2540 2507 2510 2536 2590 2612 2598 2605 2671 2692 2810 2859 2931 3062 3069 3083 3149 3186 3259 3218 3302 3375 3396 3368 3443 3395 3407 3430 3441 3365 3294 3256 3336 3347 3421 3371 3319 3230 3209 3338 3091 3132 3136 3071 2903 2918 2805 2725 2725 2602 2682 2534 2578 2545 2459 2409 2362 2432 2489 2485 2377 2338 2284 2421 2491 2334 2435 2454 2432 2320 2352 2356 2309 2406 2354 2298 2413 2429 2388 2411 2418 2398 2430 2383 2372 2310 2458 2357 2463 2508 2401 2549 2556 2543 2517 2546 2560 2654 2609 2702 2691 2761 2798 2856 2980 2933 3067 3221 3263 3391 3531 3546 3754 3764 3918 3955 4098 4165 4150 4320 4354 4383 4503 4666 4719 4665 4712 4826 5019 5028 5230 5580 5708 5981 6249 6599 6822 7081 7344 7666 7766 7977 8068 8145 8461 8414 8464 8398 8398 8161 8110 7795 7372 7296 6887 6764 6381 6087 5924 5671 5654 5227 5148 5091 4854 4789 4854 4871 4890 4856 4864 4911 4965 4827 4878 4960 4935 4863 4780 4773 4559 4467 4454 4218 4004 3918 3682 3706 3422 3339 3346 3223 3218 3033 2897 2821 2689 2646 2674 2644 2594 2535 2572 2470 2484 2444 2434 2397 2436 2343 2437 2339 2424 2409 2323 2378 2293 2278 2250 2252 2338 2363 2282 2331 2379 2245 2336 2295 2340 2328 2225 2286 2396 2333 2358 2246 2221 2300 2430 2315 2288 2318 2193 2329 2258 2268 2223 2316 2230 2262 2206 2223 2252 2289 2257 2218 2249 2245 2319 2388 2231 2285 2242 2267 2291 2255 2273 2218 2242 2291 2228 2254 2266 2285 2294 2269 2209 2271 2229 2240 2327 2261 2290 2318 2276 2288 2226 2190 2248 2204 2307 2281 2261 2277 2263 2322 2260 2303 2270 2327 2270 2268 2349 2386 2296 2315 2296 2392 2294 2241 2144 2394 2209 2271 2312 2313 2169 2294 2342 2329 2355 2243 2321 2305 2287 2282 2302 2347 2331 2365 2290 2295 2369 2301 2420 2321 2309 2374 2357 2432 2424 2373 2379 2412 2536 2512 2533 2546 2681 2612 2725 2645 2624 2659 2733 2679 2823 2642 2746 2696 2806 2750 2718 2749 2658 2718 2703 2702 2551 2601 2574 2523 2566 2398 2576 2552 2474 2434 2374 2440 2376 2449 2529 2478 2408 2590 2516 2585 2533 2621 2567 2821 2797 2799 2796 2944 3020 2934 3066 3032 2984 3007 3077 3133 3040 3029 2998 3137 3003 2847 2825 2832 2766 2661 2670 2631 2633 2642 2496 2451 2432 2467 2485 2441 2460 2291 2250 2330 2402 2336 2270 2353 2322 2284 2326 2319 2311 2297 2302 2166 2254 2286 2368 2354 2358 2384 2362 2286 2335 2450 2299 2345 2253 2340 2316 2415 2313 2393 2314 2376 2292 2331 2329 2383 2248 2286 2308 2265 2189 2259 2375 2291 2261 2354 2300 2259 2276 2267 2257 2310 2304 2224 2201 2312 2313 2297 2308 2233 2225 2199 2199 2293 2223 2184 2274 2233 2241 2283 2161 2296 2350 2327 2281 2231 2254 2130 2317 2267 2388 2225 2312 2355 2379 2305 2349 2373 2386 2398 2465 2527 2491 2533 2485 2611 2640 2814 2776 2826 2799 2904 2744 2950 2899 2905 2850 2842 2787 2915 2863 2816 2685 2777 2646 2647 2706 2518 2581 2702 2475 2576 2673 2381 2490 2439 2449 2423 2403 2570 2483 2570 2567 2646 2696 2700 2815 2795 2773 2806 2873 2933 2950 2865 3040 2957 3043 2986 2984 2980 2946 2876 2834 2797 2798 2745 2779 2863 2746 2692 2737 2704 2722 2682 2719 2704 2669 2806 2638 2775 2788 2964 2846 2891 3059 3058 3085 3300 3269 3341 3448 3495 3521 3568 3631 3670 3671 3573 3689 3643 3644 3521 3439 3500 3305 3338 3206 3161 3085 3088 3039 2922 2882 3014 2754 2697 2695 2672 2637 2701 2552 2636 2565 2605 2659 2565 2610 2508 2598 2633 2518 2640 2570 2595 2623 2545 2647 2607 2633 2677 2640 2659 2746 2698 2773 2765 2862 2841 2911 2977 2902 2937 3084 3076 3133 3232 3230 3478 3526 3558 3717 4004 4170 4338 4595 4827 5155 5716 5969 6718 7139 7871 8344 9213 9596 10232 10782 11079 11462 12121 12047 12389 12663 12849 12815 12976 12644 12491 12234 11699 10726 10286 9877 9312 8907 8414 8084 7526 7056 6561 6115 5778 5134 4947 4528 4377 4241 3960 3807 3638 3566 3435 3282 3270 2990 3145 2972 2933 2909 2754 2824 2708 2658 2608 2741 2615 2573 2567 2585 2573 2372 2594 2418 2460 2438 2419 2378 2415 2299 2357 2410 2359 2387 2406 2320 2345 2427 2341 2398 2343 2308 2409 2372 2367 2287 2276 2334 2306 2352 2277 2287 2331 2337 2326 2395 2354 2442 2381 2365 2418 2395 2373 2417 2286 2454 2451 2371 2385 2375 2448 2482 2486 2388 2453 2458 2372 2455 2401 2356 2409 2304 2261 2333 2395 2347 2252 2359 2263 2359 2249 2366 2281 2232 2284 2315 2147 2243 2325 2319 2371 2336 2353 2298 2207 2251 2309 2340 2252 2285 2301 2281 2282 2221 2300 2372 2345 2394 2246 2329 2397 2202 2310 2404 2306 2394 2448 2457 2474 2517 2444 2613 2651 2619 2788 2694 2827 2891 2948 2927 2914 2909 2960 2960 3101 2955 2869 2924 2976 2925 2941 2794 2774 2753 2681 2676 2769 2643 2553 2512 2553 2482 2488 2413 2452 2386 2420 2391 2339 2412 2269 2358 2305 2361 2374 2407 2312 2387 2298 2386 2299 2231 2343 2336 2317 2275 2398 2316 2320 2337 2332 2349 2431 2344 2447 2277 2392 2349 2308 2262 2408 2284 2363 2318 2347 2408 2496 2412 2353 2378 2462 2373 2335 2301 2475 2384 2389 2408 2384 2467 2375 2448 2503 2462 2595 2447 2527 2534 2657 2618 2683 2687 2794 2868 2974 3024 3188 3359 3521 3550 3783 4129 4307 4496 4747 4962 5106 5427 5454 5506 5481 5724 5769 5665 5834 5940 5694 5565 5520 5266 5045 4772 4521 4270 4153 4066 3863 3793 3658 3534 3383 3270 3173 2944 2846 2747 2745 2692 2597 2586 2575 2479 2541 2534 2592 2577 2499 2560 2404 2495 2455 2529 2410 2443 2485 2413 2459 2465 2475 2482 2400 2505 2457 2485 2569 2521 2567 2612 2565 2511 2636 2702 2702 2673 2698 2595 2795 2655 2586 2639 2534 2661 2637 2604 2462 2651 2539 2613 2475 2600 2520 2517 2490 2435 2551 2412 2530 2458 2458 2518 2396 2502 2474 2456 2474 2562 2554 2548 2485 2527 2590 2629 2544 2693 2595 2722 2677 2694 2709 2776 2817 2702 2814 2768 2778 2680 2768 2711 2838 2754 2791 2742 2707 2736 2705 2630 2720 2581 2593 2534 2456 2475 2460 2524 2464 2503 2475 2422 2397 2370 2402 2314 2403 2232 2388 2397 2340 2273 2321 2293 2376 2385 2360 2305 2370 2287 2361 2395 2288 2314 2346 2416 2347 2373 2358 2392 2315 2418 2402 2393 2385 2386 2435 2465 2400 2389 2558 2508 2656 2621 2658 2639 2790 2906 3022 3127 3130 3158 3128 3361 3389 3434 3368 3440 3497 3662 3701 3719 3831 3922 4011 4064 3999 4089 4080 4083 4185 4055 4243 4094 4218 4147 4104 4236 4050 4051 3927 3813 3632 3586 3542 3389 3362 3414 3215 3211 3164 3136 2974 2963 2918 2864 2793 2697 2704 2745 2633 2644 2619 2584 2580 2528 2508 2574 2588 2464 2442 2522 2436 2494 2501 2446 2447 2460 2425 2497 2339 2445 2347 2378 2351 2403 2383 2380 2449 2430 2303 2413 2426 2473 2355 2536 2394 2402 2542 2543 2523 2622 2653 2728 2730 2919 2821 2981 2931 3054 3052 3020 3051 3042 3086 3201 3035 3062 3171 3101 3134 2970 2926 2817 2917 2788 2824 2813 2712 2798 2735 2601 2584 2547 2517 2495 2428 2552 2422 2414 2402 2488 2546 2471 2557 2463 2526 2570 2579 2661 2739 2743 2893 2966 2983 2989 3021 3058 3126 3034 3178 3168 3285 3083 3082 3097 3080 3101 3004 3008 2909 2755 2859 2814 2691 2759 2856 2763 2706 2596 2641 2579 2564 2420 2508 2506 2521 2514 2468 2520 2451 2459 2333 2508 2496 2395 2367 2494 2548 2491 2407 2572 2439 2436 2535 2440 2404 2412 2448 2369 2365 2424 2400 2367 2329 2376 2394 2405 2298 2260 2439 2299 2382 2359 2337 2239 2334 2288 2283 2247 2261 2281 2339 2259 2291 2374 2239 2330 2320 2316 2334 2378 2338 2355 2255 2263 2281 2309 2284 2339 2210 2235 2333 2371 2316 2354 2325 2192 2277 2324 2311 2243 2256 2431 2369 2311 2359 2326 2379 2339 2357 2433 2404 2344 2400 2430 2491 2543 2422 2406 2519 2495 2554 2452 2574 2402 2541 2530 2642 2620 2619 2557 2493 2634 2479 2591 2512 2518 2549 2556 2592 2609 2666 2657 2762 2845 2720 2937 2994 3060 3099 3078 3284 3335 3403 3418 3553 3670 3606 3686 3663 3702 3829 3794 3835 3848 3789 3905 3751 3676 3696 3830 3713 3748 3937 3858 3944 3780 3943 3891 3904 3919 4030 3750 3939 3918 3768 3882 3707 3671 3734 3613 3557 3487 3456 3434 3483 3328 3391 3230 3244 3248 3295 3279 3311 3250 3317 3159 3340 3388 3465 3694 3716 3959 3935 4094 4337 4466 4629 4590 4688 4605 4661 4760 4738 4782 4867 4776 4619 4610 4368 4200 4250 4035 3924 3825 3781 3752 3574 3481 3317 3340 3306 3289 3190 2974 2964 2841 2780 2740 2792 2667 2651 2668 2637 2706 2664 2584 2548 2613 2586 2682 2703 2698 2722 2785 2890 2961 3077 3027 3116 3313 3404 3489 3561 3633 3780 3825 3909 3820 3900 3965 3990 4058 4102 3912 3961 3890 3744 3743 3659 3341 3310 3296 3342 3219 3149 3033 2976 2899 2855 2806 2758 2679 2587 2668 2532 2550 2631 2506 2545 2521 2507 2503 2566 2548 2601 2547 2542 2465 2519 2372 2545 2438 2473 2529 2478 2402 2471 2395 2405 2374 2503 2500 2366 2384 2399 2336 2329 2339 2322 2281 2320 2387 2434 2375 2329 2328 2279 2299 2303 2317 2315 2279 2286 2306 2365 2288 2301 2398 2306 2395 2359 2344 2293 2275 2296 2266 2339 2362 2350 2308 2369 2387 2385 2347 2398 2294 2411 2379 2395 2425 2332 2414 2394 2386 2434 2372 2456 2492 2407 2328 2395 2479 2392 2432 2374 2422 2445 2369 2490 2516 2381 2437 2422 2383 2436 2428 2478 2414 2411 2543 2550 2516 2524 2434 2541 2539 2516 2487 2496 2431 2523 2544 2550 2604 2646 2725 2708 2830 2908 2976 3134 3178 3254 3530 3638 3760 3909 3954 3939 4222 4171 4241 4259 4232 4378 4468 4426 4339 4257 4087 3920 3842 3682 3659 3476 3589 3430 3377 3310 3253 3287 3112 3063 3017 2841 2721 2657 2604 2533 2542 2517 2525 2512 2511 2554 2517 2384 2525 2575 2391 2519 2514 2528 2502 2612 2486 2518 2592 2622 2772 2769 2765 2900 2833 3108 3140 3137 3278 3319 3432 3501 3558 3558 3589 3561 3610 3677 3662 3676 3749 3580 3423 3518 3432 3290 3340 3180 3191 3145 3145 3148 3028 3000 2884 2988 2888 2772 2850 2884 2743 2794 2843 2749 2835 2930 2871 2991 2959 3011 3109 3206 3232 3242 3281 3314 3162 3221 3159 3371 3344 3339 3243 3183 3170 3126 3074 3059 3016 2909 2866 2896 2860 2818 2798 2756 2708 2632 2566 2582 2470 2459 2456 2467 2404 2389 2368 2449 2357 2354 2335 2427 2400 2396 2405 2394 2447 2370 2431 2293 2501 2364 2483 2473 2413 2521 2485 2407 2412 2547 2503 2435 2443 2512 2421 2543 2504 2481 2483 2520 2420 2579 2528 2485 2415 2558 2519 2610 2551 2645 2655 2655 2659 2645 2754 2696 2747 2622 2679 2698 2702 2657 2734 2834 2746 2641 2734 2757 2692 2728 2741 2738 2792 2719 2719 2649 2653 2677 2591 2649 2576 2565 2575 2552 2591 2539 2610 2491 2532 2513 2421 2417 2580 2556 2384 2411 2412 2429 2429 2375 2405 2411 2458 2364 2378 2470 2392 2396 2427 2412 2433 2337 2417 2425 2432 2435 2466 2492 2387 2441 2466 2371 2422 2343 2483 2449 2412 2362 2404 2557 2439 2566 2486 2518 2653 2665 2818 2894 2851 2970 3063 3171 3171 3139 3184 3340 3400 3497 3631 3599 3573 3748 3704 3773 3866 3828 3788 3795 3769 3716 3595 3632 3699 3530 3581 3535 3507 3254 3361 3258 3145 3174 3063 3142 3166 3096 2966 3028 3058 2859 2996 2983 2963 2957 3013 3004 3095 3092 3188 3294 3247 3391 3246 3351 3368 3380 3382 3470 3377 3419 3331 3322 3136 3188 3191 3038 3077 3113 2982 2938 2876 2990 3006 3002 3054 2897 2941 2900 2902 2915 2829 2785 2808 2743 2761 2776 2614 2773 2594 2647 2812 2665 2520 2558 2668 2665 2683 2598 2526 2518 2607 2675 2587 2541 2589 2641 2614 2603 2590 2738 2663 2861 2805 2894 2876 2863 2926 3090 3085 3232 3248 3308 3172 3212 3268 3228 3378 3296 3137 3166 3245 3116 3170 3112 2995 2987 2927 2876 2777 2805 2743 2727 2734 2642 2557 2606 2522 2609 2582 2493 2471 2326 2375 2407 2370 2342 2292 2343 2322 2317 2485 2332 2320 2400 2226 2463 2355 2333 2372 2388 2404 2388 2289 2297 2384 2434 2287 2416 2407 2441 2381 2411 2312 2324 2346 2445 2480 2398 2422 2484 2443 2427 2498 2494 2457 2453 2621 2315 2539 2500 2498 2449 2548 2530 2513 2429 2431 2504 2497 2442 2404 2396 2368 2350 2451 2434 2368 2340 2348 2284 2358 2288 2388 2328 2452 2316 2347 2255 2294 2289 2333 2279 2276 2320 2307 2237 2344 2259 2216 2258 2303 2307 2209 2352 2341 2214 2260 2216 2227 2251 2268 2288 2258 2354 2282 2223 2323 2311 2316 2346 2274 2299 2318 2292 2295 2230 2357 2237 2242 2298 2289 2210 2343 2312 2271 2247 2236 2308 2349 2327 2319 2326 2245 2414 2227 2231 2323 2239 2342 2250 2371 2261 2236 2296 2337 2255 2266 2259 2266 2313 2383 2304 2379 2349 2238 2316 2386 2423 2323 2447 2370 2325 2384 2375 2390 2350 2358 2323 2444 2252 2451 2371 2385 2368 2350 2364 2380 2442 2496 2461 2486 2506 2458 2483 2569 2567 2618 2524 2692 2648 2728 2683 2814 2940 2972 3044 2958 3121 3075 3057 3102 3031 3153 3103 3061 3040 3024 3122 2972 3029 2937 2946 2962 2996 2979 2885 2842 3032 2874 2871 2939 2977 2994 3064 2863 2943 3054 2922 3032 2944 2970 2960 3043 2951 3076 3020 2964 3045 2880 2801 2836 2810 2848 2840 2860 2719 2787 2767 2737 2734 2688 2720 2659 2762 2637 2634 2636 2629 2587 2594 2605 2578 2684 2701 2703 2717 2717 2719 2806 2849 2845 2843 2930 2939 2957 3051 3094 3060 3072 3145 3224 3230 3350 3373 3383 3338 3395 3487 3375 3403 3402 3489 3631 3749 3614 3598 3644 3599 3539 3475 3705 3614 3604 3675 3702 3841 3805 3976 4030 4006 4188 4206 4455 4493 4593 4726 4855 4920 5137 5250 5313 5582 5433 5685 5993 5972 5977 6123 6141 6043 6202 6018 6130 5973 6055 5902 5824 5643 5709 5664 5495 5331 5395 5171 5153 4987 4852 4645 4547 4422 4401 4212 4083 3982 3800 3691 3553 3620 3438 3455 3351 3245 3294 3193 3098 3127 2953 2991 2948 2895 2903 2882 2930 2859 2926 2800 2942 2958 2872 2949 2795 2875 2962 2928 3060 3018 2896 3052 2865 3106 2955 3038 3098 3006 3029 2954 2945 2855 2970 2898 2826 2806 2878 2800 2728 2589 2913 2668 2733 2631 2665 2612 2509 2667 2547 2536 2584 2406 2403 2421 2513 2415 2342 2313 2307 2358 2348 2280 2299 2392 2281 2350 2267 2361 2332 2310 2231 2320 2345 2321 2238 2303 2300 2337 2338 2322 2304 2270 2263 2312 2206 2241 2309 2226 2314 2285 2274 2296 2240 2279 2307 2324 2307 2335 2287 2179 2249 2194 2265 2245 2220 2233 2246 2216 2218 2179 2227 2233 2245 2285 2243 2192 2170 2348 2241 2231 2301 2268 2266 2192 2289 2231 2293 2396 2283 2347 2387 2211 2264 2301 2323 2260 2243 2268 2249 2252 2290 2297 2221 2288 2334 2258 2249 2278 2321 2274 2261 2291 2340 2251 2219 2202 2366 2345 2291 2237 2320 2352 2204 2194 2248 2192 2257 2242 2265 2247 2244 2286 2222 2247 2245 2272 2242 2309 2253 2266 2266 2226 2363 2316 2315 2347 2356 2291 2280 2285 2304 2407 2399 2332 2390 2382 2352 2372 2404 2360 2385 2275 2380 2442 2290 2439 2383 2338 2372 2419 2378 2343 2345 2356 2313 2358 2297 2313 2358 2277 2315 2302 2290 2342 2294 2360 2316 2367 2291 2245 2289 2317 2318 2253 2236 2272 2218 2384 2293 2341 2331 2286 2295 2274 2371 2307 2357 2300 2300 2307 2164 2347 2354 2354 2252 2320 2436 2333 2329 2467 2322 2391 2412 2375 2461 2417 2551 2501 2531 2615 2535 2581 2634 2622 2709 2596 2641 2676 2579 2677 2534 2601 2550 2527 2508 2558 2473 2473 2467 2542 2350 2498 2466 2493 2545 2466 2480 2501 2471 2592 2537 2464 2422 2498 2498 2479 2490 2447 2478 2518 2407 2443 2460 2474 2541 2693 2636 2660 2629 2717 2754 2788 2742 2919 2881 2981 3034 2795 3023 2922 2985 2964 2828 2898 2808 2814 2766 2804 2816 2821 2758 2728 2641 2638 2737 2749 2658 2550 2652 2582 2577 2547 2551 2416 2538 2463 2427 2459 2456 2366 2277 2330 2348 2334 2292 2301 2312 2287 2248 2355 2354 2411 2260 2295 2295 2409 2343 2291 2342 2332 2320 2338 2258 2453 2319 2340 2249 2349 2317 2291 2294 2357 2266 2307 2243 2309 2328 2229 2306 2286 2342 2443 2426 2348 2350 2289 2312 2373 2502 2382 2442 2522 2391 2541 2557 2594 2593 2540 2644 2588 2505 2617 2644 2636 2743 2628 2639 2575 2582 2550 2592 2455 2516 2416 2604 2532 2495 2457 2476 2540 2407 2485 2396 2503 2552 2378 2586 2413 2325 2389 2448 2477 2292 2398 2348 2424 2292 2290 2347 2461 2372 2422 2302 2347 2367 2407 2417 2382 2331 2428 2374 2539 2518 2576 2571 2644 2588 2640 2652 2728 2798 2789 2844 2833 2792 2905 2959 2866 2781 2746 2750 2790 2754 2784 2695 2765 2702 2786 2781 2699 2752 2775 2684 2842 2685 2764 2678 2697 2638 2641 2640 2629 2501 2607 2580 2596 2541 2499 2508 2545 2465 2550 2389 2422 2371 2415 2324 2397 2368 2427 2360 2357 2404 2363 2346 2370 2330 2303 2402 2362 2423 2323 2413 2433 2380 2418 2441 2381 2325 2347 2414 2384 2310 2432 2334 2438 2319 2429 2506 2434 2377 2330 2383 2327 2478 2305 2454 2465 2414 2391 2381 2436 2449 2430 2438 2525 2455 2655 2518 2593 2541 2652 2560 2623 2609 2585 2685 2636 2627 2715 2639 2709 2642 2738 2655 2644 2714 2742 2736 2651 2700 2708 2731 2571 2685 2663 2557 2519 2592 2562 2442 2537 2506 2469 2483 2433 2391 2428 2385 2517 2437 2357 2359 2391 2389 2312 2253 2342 2408 2362 2280 2342 2280 2342 2236 2329 2264 2305 2323 2209 2319 2308 2341 2284 2250 2293 2346 2337 2309 2365 2322 2268 2363 2258 2319 2324 2336 2332 2364 2253 2324 2378 2477 2354 2365 2285 2392 2321 2359 2331 2326 2410 2365 2312 2342 2368 2437 2355 2213 2370 2355 2454 2427 2451 2374 2406 2296 2412 2424 2479 2433 2553 2413 2385 2511 2493 2540 2485 2559 2532 2442 2525 2535 2315 2450 2420 2383 2520 2424 2473 2415 2504 2452 2389 2428 2448 2424 2484 2438 2307 2395 2399 2474 2437 2422 2368 2463 2473 2445 2497 2379 2478 2516 2557 2604 2645 2681 2758 2856 2871 2974 2880 3006 3073 3171 3208 3160 3088 3204 3173 3176 3182 3051 3159 3109 3048 2977 2834 2918 2857 2986 2898 2881 2838 2850 2795 2881 2796 2854 2755 2620 2723 2759 2692 2647 2514 2553 2508 2481 2523 2379 2494 2468 2440 2431 2409 2454 2468 2421 2409 2370 2435 2447 2466 2517 2484 2507 2445 2465 2486 2707 2572 2561 2568 2604 2515 2547 2544 2459 2514 2379 2492 2514 2401 2461 2543 2498 2520 2503 2611 2643 2536 2553 2593 2683 2653 2577 2721 2770 2661 2642 2666 2747 2786 2726 2740 2714 2704 2661 2644 2497 2639 2638 2601 2497 2485 2579 2431 2477 2577 2541 2450 2499 2567 2572 2433 2423 2396 2410 2316 2375 2405 2411 2386 2265 2282 2261 2400 2246 2340 2224 2325 2361 2211 2437 2365 2275 2304 2323 2232 2315 2388 2336 2351 2228 2276 2338 2283 2291 2332 2276 2295 2297 2285 2230 2283 2285 2248 2245 2353 2284 2245 2317 2245 2297 2390 2232 2361 2188 2269 2178 2239 2268 2268 2291 2312 2283 2259 2340 2228 2311 2253 2357 2313 2274 2249 2340 2362 2268 2343 2328 2322 2314 2312 2337 2347 2411 2328 2362 2366 2334 2314 2327 2306 2376 2397 2301 2272 2380 2231 2440 2366 2338 2373 2455 2332 2336 2435 2319 2339 2265 2397 2382 2359 2373 2330 2223 2258 2373 2334 2407 2416 2435 2470 2480 2423 2435 2407 2433 2545 2517 2481 2549 2582 2541 2599 2566 2508 2702 2508 2640 2545 2660 2578 2540 2511 2505 2541 2519 2528 2436 2490 2445 2514 2555 2547 2563 2552 2549 2588 2559 2626 2562 2618 2642 2746 2678 2647 2672 2679 2600 2644 2650 2610 2611 2551 2670 2543 2537 2631 2541 2497 2514 2523 2579 2515 2455 2501 2493 2535 2620 2430 2539 2380 2437 2463 2482 2462 2462 2444 2432 2397 2394 2315 2479 2476 2414 2311 2432 2480 2493 2451 2398 2438 2494 2401 2523 2544 2470 2507 2572 2567 2469 2507 2499 2470 2601 2491 2583 2558 2545 2527 2577 2527 2597 2676 2674 2590 2678 2648 2689 2702 2699 2811 2725 2822 2791 2779 2955 2920 3046 3010 2952 3111 3091 3156 3202 3392 3230 3396 3368 3330 3527 3484 3511 3542 3512 3507 3554 3515 3323 3427 3421 3439 3281 3288 3393 3323 3325 3237 3208 3285 3126 3234 3131 3191 3153 3067 2986 2909 2853 2931 2880 2846 2782 2778 2819 2733 2622 2641 2620 2628 2622 2534 2520 2510 2483 2467 2463 2459 2358 2388 2336 2432 2400 2470 2416 2379 2358 2396 2440 2316 2420 2369 2442 2319 2307 2345 2291 2369 2295 2350 2327 2248 2238 2417 2330 2285 2343 2250 2290 2354 2317 2323 2251 2322 2272 2253 2298 2317 2256 2311 2333 2381 2301 2279 2193 2253 2379 2263 2257 2284 2221 2351 2299 2239 2218 2301 2173 2278 2280 2314 2187 2226 2227 2281 2231 2315 2249 2387 2238 2281 2267 2248 2319 2251 2315 2273 2292 2356 2313 2227 2281 2341 2479 2383 2319 2278 2315 2348 2385 2259 2265 2306 2408 2326 2363 2349 2434 2449 2422 2436 2415 2468 2457 2511 2472 2537 2530 2497 2593 2561 2541 2461 2471 2447 2493 2481 2540 2449 2508 2560 2403 2486 2450 2477 2460 2460 2479 2409 2402 2464 2450 2457 2527 2441 2504 2452 2449 2579 2599 2522 2599 2563 2566 2610 2584 2541 2564 2607 2533 2551 2608 2601 2543 2608 2545 2618 2555 2497 2491 2462 2481 2550 2462 2443 2434 2353 2385 2417 2471 2340 2464 2400 2392 2368 2496 2423 2438 2353 2342 2342 2384 2286 2353 2349 2390 2254 2315 2375 2387 2299 2330 2367 2365 2388 2286 2371 2330 2377 2307 2320 2339 2316 2429 2351 2389 2423 2321 2360 2328 2495 2399 2386 2320 2451 2451 2461 2390 2346 2377 2419 2402 2394 2388 2347 2350 2256 2379 2355 2383 2383 2395 2285 2368 2414 2341 2473 2436 2520 2500 2410 2496 2463 2520 2442 2503 2591 2610 2616 2607 2528 2527 2569 2678 2591 2671 2690 2554 2567 2532 2553 2642 2557 2511 2497 2529 2527 2445 2612 2486 2489 2432 2559 2481 2613 2530 2652 2598 2570 2638 2568 2618 2541 2594 2536 2580 2671 2490 2488 2747 2775 2744 2633 2641 2717 2813 2701 2863 2841 2987 3019 3079 3171 3121 3228 3127 3128 3335 3316 3431 3417 3379 3344 3444 3465 3411 3353 3446 3392 3332 3559 3346 3460 3412 3375 3421 3322 3314 3264 3293 3251 3339 3332 3224 3262 3192 3148 3232 3272 3269 3208 3356 3332 3371 3274 3299 3193 3176 3163 3189 3213 3246 3149 3126 3026 3042 2871 2880 2898 2904 2713 2772 2763 2753 2784 2751 2706 2743 2769 2692 2682 2776 2667 2648 2715 2685 2643 2695 2509 2651 2631 2619 2558 2680 2594 2705 2784 2808 2733 2735 2747 2848 2834 2855 2831 2803 2831 2820 2827 2836 2798 2884 2837 2898 2831 2899 2746 2824 2709 2694 2787 2718 2806 2740 2762 2764 2754 2745 2732 2710 2646 2723 2627 2569 2492 2639 2558 2606 2471 2327 2464 2533 2542 2524 2388 2308 2422 2355 2344 2401 2332 2363 2456 2292 2397 2361 2476 2344 2300 2355 2370 2316 2264 2425 2265 2307 2276 2357 2242 2345 2300 2251 2285 2312 2324 2417 2260 2357 2318 2300 2314 2239 2217 2225 2281 2255 2374 2279 2266 2419 2364 2351 2345 2386 2346 2449 2375 2391 2535 2466 2449 2420 2461 2497 2495 2478 2440 2471 2555 2357 2403 2370 2317 2412 2374 2279 2323 2370 2390 2330 2336 2451 2404 2353 2374 2397 2330 2409 2395 2359 2485 2384 2399 2392 2359 2308 2361 2259 2357 2322 2359 2290 2304 2309 2328 2286 2335 2337 2336 2415 2312 2301 2319 2321 2361 2303 2321 2245 2338 2356 2347 2250 2386 2428 2376 2360 2395 2447 2419 2377 2328 2401 2441 2478 2507 2496 2496 2656 2618 2595 2779 2767 2821 2850 2905 2829 2935 2913 2842 2928 3040 2859 3018 2835 2787 2671 2698 2659 2652 2672 2658 2689 2519 2585 2603 2576 2707 2640 2638 2827 2598 2635 2573 2551 2606 2677 2524 2591 2490 2424 2413 2411 2431 2400 2374 2382 2303 2349 2329 2298 2342 2257 2341 2315 2207 2415 2348 2233 2274 2245 2362 2254 2329 2303 2272 2363 2347 2376 2366 2334 2312 2349 2451 2449 2470 2466 2359 2512 2454 2464 2362 2474 2398 2455 2406 2389 2513 2401 2343 2395 2397 2337 2401 2441 2371 2414 2272 2380 2349 2296 2405 2416 2371 2328 2322 2392 2386 2425 2400 2296 2391 2373 2353 2312 2276 2301 2306 2377 2280 2382 2318 2293 2291 2312 2413 2330 2323 2379 2333 2279 2318 2286 2266 2311 2334 2420 2236 2337 2308 2330 2279 2330 2364 2325 2427 2363 2350 2361 2348 2391 2324 2365 2386 2311 2366 2432 2411 2413 2324 2403 2388 2352 2309 2461 2335 2266 2359 2329 2361 2417 2330 2469 2336 2412 2342 2398 2437 2468 2375 2349 2326 2371 2578 2531 2551 2550 2378 2485 2569 2569 2572 2581 2701 2719 2683 2793 2749 2645 2690 2729 2746 2706 2779 2600 2650 2583 2577 2621 2557 2498 2561 2567 2595 2496 2523 2624 2593 2599 2614 2534 2583 2577 2478 2469 2440 2491 2541 2474 2496 2432 2478 2376 2388 2402 2406 2414 2323 2346 2394 2343 2380 2302 2412 2374 2344 2275 2299 2360 2398 2387 2363 2440 2416 2365 2460 2442 2448 2421 2479 2579 2509 2433 2550 2487 2461 2523 2467 2437 2298 2438 2460 2465 2303 2332 2404 2417 2337 2417 2421 2332 2417 2359 2397 2417 2448 2430 2381 2369 2352 2444 2315 2360 2307 2344 2365 2365 2415 2371 2343 2399 2442 2367 2378 2377 2339 2353 2391 2439 2423 2274 2457 2366 2435 2387 2327 2342 2376 2453 2410 2363 2342 2452 2381 2335 2426 2192 2388 2303 2345 2346 2370 2212 2310 2330 2399 2299 2306 2330 2342 2280 2360 2282 2390 2311 2257 2395 2304 2329 2259 2337 2336 2305 2264 2182 2295 2284 2292 2303 2251 2298 2218 2307 2279 2288 2341 2232 2352 2433 2314 2334 2285 2299 2348 2345 2316 2332 2327 2260 2386 2373 2309 2399 2331 2422 2358 2357 2326 2327 2338 2503 2461 2479 2458 2419 2502 2554 2596 2584 2537 2693 2795 2787 2742 2746 2739 2819 2787 2813 2802 2832 2740 2685 2662 2691 2676 2620 2721 2676 2504 2549 2593 2570 2650 2526 2565 2699 2643 2676 2809 2876 2727 2756 2752 2701 2853 2721 2674 2870 2818 2673 2774 2625 2670 2501 2591 2639 2522 2500 2497 2465 2424 2328 2457 2520 2426 2446 2482 2458 2390 2444 2457 2487 2507 2457 2396 2405 2407 2382 2385 2383 2412 2306 2404 2347 2303 2233 2264 2418 2236 2344 2305 2310 2326 2361 2237 2336 2299 2283 2362 2217 2354 2348 2355 2322 2309 2371 2462 2419 2480 2426 2490 2507 2578 2529 2571 2595 2592 2605 2617 2504 2591 2517 2586 2577 2569 2545 2499 2419 2382 2389 2493 2469 2556 2553 2561 2592 2541 2529 2518 2558 2595 2482 2622 2505 2537 2469 2425 2411 2507 2514 2504 2392 2411 2416 2538 2430 2378 2344 2383 2369 2401 2324 2437 2483 2428 2376 2429 2322 2446 2398 2484 2463 2508 2492 2516 2508 2562 2545 2537 2645 2650 2691 2626 2572 2551 2534 2553 2470 2441 2421 2479 2452 2405 2398 2415 2412 2356 2403 2375 2434 2431 2406 2555 2431 2446 2524 2380 2441 2382 2406 2361 2294 2345 2387 2395 2400 2375 2326 2429 2345 2437 2290 2389 2372 2342 2441 2351 2431 2435 2384 2420 2332 2345 2296 2392 2352 2353 2279 2419 2385 2341 2458 2325 2303 2321 2438 2355 2242 2274 2378 2286 2375 2329 2304 2283 2344 2285 2365 2267 2248 2244 2316 2320 2320 2252 2340 2422 2380 2275 2218 2329 2295 2301 2318 2145 2274 2351 2213 2227 2306 2271 2158 2257 2228 2187 2370 2325 2225 2269 2305 2249 2329 2351 2325 2296 2379 2335 2268 2291 2296 2301 2384 2358 2322 2406 2324 2423 2343 2348 2440 2352 2357 2332 2333 2304 2350 2336 2335 2350 2321 2282 2343 2250 2357 2345 2397 2332 2412 2445 2522 2500 2497 2464 2589 2481 2482 2455 2502 2373 2355 2385 2454 2342 2379 2364 2385 2342 2316 2374 2337 2299 2300 2362 2322 2299 2343 2260 2374 2459 2404 2324 2357 2393 2433 2382 2376 2410 2394 2369 2426 2466 2387 2455 2517 2410 2386 2376 2458 2524 2433 2371 2427 2408 2387 2357 2302 2381 2312 2337 2277 2402 2293 2370 2332 2227 2288 2348 2289 2228 2328 2227 2296 2356 2319 2369 2445 2272 2290 2332 2304 2364 2253 2244 2296 2299 2333 2227 2362 2220 2348 2254 2433 2313 2335 2342 2310 2306 2361 2276 2244 2354 2329 2317 2369 2448 2326 2353 2300 2415 2327 2481 2408 2461 2516 2486 2489 2446 2438 2457 2527 2506 2653 2590 2633 2610 2574 2657 2578 2618 2492 2536 2538 2581 2538 2475 2527 2521 2453 2547 2452 2463 2459 2439 2458 2444 2545 2488 2452 2524 2399 2459 2462 2510 2519 2484 2445 2500 2400 2426 2309 2429 2389 2389 2390 2400 2423 2377 2482 2460 2465 2404 2417 2489 2613 2548 2523 2613 2553 2593 2529 2550 2627 2600 2606 2600 2595 2721 2546 2536 2615 2602 2518 2473 2515 2525 2577 2566 2405 2527 2594 2554 2475 2474 2455 2487 2577 2603 2550 2558 2584 2499 2503 2487 2547 2461 2563 2414 2566 2550 2493 2495 2456 2426 2495 2475 2480 2440 2453 2485 2357 2480 2428 2375 2456 2385 2412 2402 2392 2403 2256 2353 2422 2379 2415 2294 2457 2320 2379 2312 2406 2327 2316 2384 2338 2368 2396 2462 2381 2327 2348 2424 2400 2406 2427 2472 2436 2391 2513 2528 2493 2523 2441 2524 2483 2483 2533 2480 2477 2440 2418 2441 2387 2450 2391 2397 2462 2483 2467 2433 2525 2414 2500 2461 2405 2348 2433 2446 2380 2351 2387 2408 2331 2411 2310 2361 2418 2373 2354 2469 2337 2409 2284 2294 2522 2327 2440 2417 2383 2402 2355 2484 2496 2478 2484 2476 2553 2529 2579 2631 2588 2557 2582 2600 2621 2576 2537 2627 2498 2535 2440 2553 2631 2426 2479 2493 2489 2454 2561 2527 2440 2475 2468 2473 2439 2357 2514 2462 2474 2481 2490 2465 2445 2450 2505 2451 2493 2504 2543 2477 2513 2392 2466 2522 2492 2486 2523 2484 2449 2446 2552 2332 2435 2358 2417 2312 2330 2321 2287 2363 2383 2285 2361 2391 2353 2307 2315 2384 2309 2414 2357 2364 2347 2495 2368 2364 2342 2324 2309 2355 2340 2434 2356 2303 2311 2335 2368 2269 2314 2316 2391 2265 2327 2274 2261 2315 2360 2321 2362 2252 2345 2192 2264 2306 2345 2350 2330 2319 2385 2396 2384 2316 2360 2400 2442 2469 2409 2490 2521 2502 2338 2423 2383 2466 2452 2501 2477 2596 2383 2523 2376 2581 2487 2482 2557 2649 2594 2727 2721 2646 2723 2749 2607 2656 2664 2715 2593 2621 2699 2638 2577 2601 2704 2679 2598 2518 2548 2553 2598 2547 2644 2582 2520 2590 2543 2676 2677 2696 2669 2507 2653 2754 2570 2596 2677 2536 2636 2586 2588 2590 2564 2463 2513 2478 2529 2439 2506 2476 2562 2442 2521 2521 2524 2508 2496 2507 2632 2565 2625 2529 2557 2644 2666 2721 2702 2688 2684 2642 2638 2657 2599 2549 2576 2607 2614 2564 2558 2517 2580 2594 2447 2498 2516 2530 2582 2472 2484 2392 2492 2451 2437 2518 2488 2523 2504 2486 2427 2431 2527 2479 2492 2610 2496 2499 2527 2466 2385 2418 2406 2449 2456 2341 2427 2313 2485 2368 2341 2393 2332 2306 2322 2282 2319 2313 2253 2312 2310 2313 2354 2236 2366 2297 2380 2364 2280 2313 2288 2330 2352 2246 2293 2252 2251 2223 2272 2277 2255 2256 2199 2297 2309 2238 2352 2296 2231 2284 2228 2203 2372 2203 2318 2226 2219 2333 2279 2179 2237 2272 2180 2252 2366 2296 2240 2251 2294 2237 2288 2314 2205 2168 2280 2212 2221 2170 2170 2252 2237 2242 2234 2177 2182 2233 2198 2247 2196 2221 2240 2222 2148 2248 2190 2298 2311 2215 2187 2260 2351 2179 2249 2258 2320 2302 2281 2192 2277 2293 2206 2286 2238 2280 2240 2305 2302 2243 2252 2288 2281 2222 2268 2151 2237 2164 2316 2268 2262 2274 2316 2282 2236 2242 2292 2336 2266 2267 2287 2340 2160 2262 2305 2202 2271 2269 2325 2218 2307 2372 2326 2360 2235 2314 2407 2483 2289 2366 2396 2309 2382 2432 2349 2318 2336 2359 2274 2259 2293 2354 2302 2383 2323 2268 2223 2297 2292 2271 2353 2276 2257 2270 2289 2302 2298 2301 2317 2284 2393 2363 2391 2392 2210 2363 2277 2295 2321 2303 2306 2302 2386 2247 2281 2249 2331 2250 2259 2226 2225 2295 2194 2261 2211 2222 2275 2270 2206 2160 2192 2216 2287 2132 2111 2250 2335 2277 2302 2325 2207 2171 2277 2365 2250 2321 2269 2201 2173 2258 2330 2171 2193 2242 2241 2307 2289 2299 2294 2253 2330 2239 2202 2326 2270 2304 2269 2275 2231 2347 2331 2261 2287 2361 2408 2324 2305 2305 2325 2319 2280 2280 2313 2359 2284 2300 2263 2270 2291 2269 2352 2328 2294 2238 2274 2210 2370 2241 2336 2366 2257 2330 2353 2312 2245 2317 2403 2335 2371 2348 2302 2296 2429 2340 2407 2355 2325 2374 2261 2352 2356 2244 2307 2347 2447 2302 2333 2356 2315 2456 2336 2358 2440 2301 2400 2453 2463 2441 2361 2455 2429 2340 2477 2371 2428 2540 2425 2446 2446 2448 2356 2336 2396 2395 2458 2402 2384 2478 2476</counts>
			</dataPoints>
		</scan>
	</xrdMeasurement>
</xrdMeasurements>