File: dataset/precursor_mixture/NiO_0p6007-Bi2O3_0p4008--8min.xrdml
<?xml version="1.0"?>
<xrdMeasurements xmlns="http://www.xrdml.com/XRDMeasurement/2.3" xmlns:xsi="http://www.w3.org/2001/XMLSchema-instance" xsi:schemaLocation="http://www.xrdml.com/XRDMeasurement/2.3 http://www.xrdml.com/XRDMeasurement/2.3/XRDMeasurement.xsd" status="Completed" recordIdentifier="{3DE795C0-BA45-4233-BBBE-596A2E265D00}">
	<comment>
		<entry/>
	</comment>
	<sample type="To be analyzed">
		<id>Dara_redo_1_manual</id>
		<name></name>
		<preparedBy></preparedBy>
	</sample>
	<xrdMeasurement measurementType="Scan" status="Completed" sampleMode="Reflection">
		<usedWavelength intended="K-Alpha 1">
			<kAlpha1 unit="Angstrom">1.5405980</kAlpha1>
			<kAlpha2 unit="Angstrom">1.5444260</kAlpha2>
			<kBeta unit="Angstrom">1.3922500</kBeta>
			<ratioKAlpha2KAlpha1>0.5000</ratioKAlpha2KAlpha1>
		</usedWavelength>
		<incidentBeamPath>
			<radius unit="mm">145.00</radius>
			<xRayTube id="1010048" name="Empyrean Cu LFF HR (9430 033 7310x)">
				<tension unit="kV">40.0</tension>
				<current unit="mA">15.0</current>
				<anodeMaterial>Cu</anodeMaterial>
				<focus type="Line">
					<length unit="mm">12.0</length>
					<width unit="mm">0.4</width>
					<takeOffAngle unit="deg">6.0</takeOffAngle>
				</focus>
			</xRayTube>
			<sollerSlit id="21010002" name="Soller slits 0.04 rad.">
				<opening unit="rad">0.0400</opening>
			</sollerSlit>
			<mask id="22031000" name="Fixed mask 13 mm">
				<width unit="mm">9.00</width>
			</mask>
			<divergenceSlit id="22120001" name="Divergence slit 1°" xsi:type="fixedDivergenceSlitType">
				<distanceToSample unit="mm">50.00</distanceToSample>
				<height unit="mm">1.52</height>
			</divergenceSlit>
		</incidentBeamPath>
		<sampleMovement xsi:type="spinningSampleMovementType">
			<spinnerRevolutionTime unit="seconds">1.0</spinnerRevolutionTime>
		</sampleMovement>
		<diffractedBeamPath>
			<radius unit="mm">145.00</radius>
			<antiScatterSlit id="22090040" name="AS slit 9 mm (PIXcel)" xsi:type="fixedAntiScatterSlitType">
				<height unit="mm">9.00</height>
			</antiScatterSlit>
			<sollerSlit id="21020003" name="Large Soller slits 0.04 rad.">
				<opening unit="rad">0.0400</opening>
			</sollerSlit>
			<filter id="20030001" name="Large beta-filter Nickel">
				<material>Ni</material>
				<thickness unit="mm">0.020</thickness>
			</filter>
			<detector id="7010019" name="PIXcel1D-Medipix3 detector" xsi:type="rtmsDetectorType">
				<phd unit="keV">
					<lowerLevel>4.02</lowerLevel>
					<upperLevel>11.27</upperLevel>
				</phd>
				<mode>Scanning</mode>
				<activeLength unit="deg">5.542</activeLength>
			</detector>
		</diffractedBeamPath>
		<scan appendNumber="0" mode="Continuous" scanAxis="Gonio" status="Completed">
			<header>
				<startTimeStamp>2024-11-21T07:43:37-08:00</startTimeStamp>
				<endTimeStamp>2024-11-21T07:51:44-08:00</endTimeStamp>
				<author>
					<name>AutomatedUser</name>
				</author>
				<source>
					<applicationSoftware version="1.7b (136)">PANalytical Aeris Instrument Suite</applicationSoftware>
					<instrumentControlSoftware version="3.2.00000000 20240306">AERIS</instrumentControlSoftware>
					<instrumentID>950485</instrumentID>
				</source>
			</header>
			<dataPoints>
				<positions axis="2Theta" unit="deg">
					<startPosition>10.00943322</startPosition>
					<endPosition>99.99442286</endPosition>
				</positions>
				<positions axis="Omega" unit="deg">
					<startPosition>5.00471661</startPosition>
					<endPosition>49.99721143</endPosition>
				</positions>
				<commonCountingTime unit="seconds">12.495</commonCountingTime>
				<counts unit="counts">2408 2451 2443 2492 2408 2479 2352 2483 2378 2373 2355 2444 2340 2458 2500 2522 2395 2364 2439 2424 2435 2483 2338 2370 2383 2321 2411 2369 2378 2374 2407 2259 2301 2415 2313 2386 2235 2343 2283 2377 2229 2321 2331 2344 2393 2307 2320 2461 2320 2335 2358 2256 2316 2367 2328 2285 2339 2290 2245 2281 2286 2287 2321 2232 2195 2226 2331 2261 2220 2254 2258 2201 2312 2369 2226 2218 2161 2325 2235 2175 2261 2203 2224 2315 2168 2255 2159 2184 2157 2215 2214 2142 2220 2276 2179 2176 2222 2195 2173 2257 2212 2217 2190 2300 2185 2175 2156 2151 2134 2145 2248 2134 2187 2203 2204 2188 2162 2155 2111 2133 2248 2109 2192 2048 2072 2139 2209 2109 2184 2173 2069 2092 2163 2136 2172 2089 2096 2020 2031 2107 2170 2098 2095 2096 2051 2175 2121 2106 2166 2108 2046 2034 2053 2104 2115 2148 2206 2071 2130 2090 2149 2108 2172 1996 2063 2013 1977 2029 2111 2010 1983 2005 2066 2137 2108 2064 2068 2051 2026 2126 2031 2034 2083 2063 2001 2037 2067 2016 2145 2064 2063 2058 2002 1929 2115 2025 2021 2020 1986 2010 2019 2044 1995 2011 1983 1970 1906 1989 1992 1948 1960 2021 2036 2043 1873 1919 2007 2031 2003 1983 2021 1876 1939 1944 1949 1971 1930 1913 1991 2091 1960 2021 2038 1942 2002 2038 1970 1910 1967 2042 1888 1966 1898 2045 2084 1995 2003 1875 2028 2011 2041 1968 1949 1954 1852 1870 1931 1955 1918 1964 1850 1938 2001 1964 1908 1975 1921 1912 2004 1892 1936 1925 1870 1949 1863 1906 1946 1880 1956 1873 1950 1958 1876 1964 1972 1883 1924 1887 1931 1906 1849 1930 1937 1929 1911 1906 1878 1877 1881 1873 1860 1879 1882 1929 1853 1859 1849 1866 1890 1877 1859 1881 1847 1799 1907 1949 1832 1845 1872 1860 1860 1777 1808 1842 1989 1818 1928 1959 1881 1849 1885 1970 1923 1893 1894 1837 1893 1874 1962 1887 1910 1902 1893 1872 1899 1842 1877 1836 1754 1835 1884 1858 1941 1834 1827 1965 1829 1855 1901 1811 1860 1886 1835 1829 1901 1814 1777 1854 1826 1889 1966 1899 1811 1915 1858 1873 1851 1837 1809 1920 1849 1846 1866 1905 1873 1910 1886 1881 1854 1864 1819 1823 1799 1787 1751 1848 1850 1847 1873 1853 1823 1869 1797 1872 1824 1878 1903 1874 1884 1815 1832 1863 1822 1841 1896 1791 1856 1875 1890 1784 1893 1841 1860 1811 1846 1893 1867 1808 1835 1905 1836 1880 1836 1838 1883 1770 1813 1872 1849 1785 1802 1837 1874 1806 1815 1903 1836 1782 1761 1846 1883 1886 1825 1812 1876 1766 1850 1838 1825 1915 1900 1875 1864 1917 1844 1828 1881 1913 1965 1775 1834 1851 1827 1869 1871 1864 1849 1841 1906 1865 1860 1844 1787 1879 1882 1890 1840 1891 1868 1856 1850 1807 1810 1863 1912 1807 1888 1797 1920 1822 1837 1910 1859 1867 1843 1811 1837 1907 1886 1736 1809 1809 1882 1873 1873 1857 1870 1814 1782 1757 1891 1875 1885 1788 1851 1871 1843 1842 1845 1841 1928 1811 1843 1911 1765 1848 1860 1857 1841 1848 1806 1812 1805 1776 1823 1899 1807 1801 1866 1874 1853 1873 1876 1862 1816 1865 1958 1923 1872 1884 1935 1881 1910 1928 1939 1889 1927 1917 1815 1867 1887 1929 1867 1875 1913 1849 1853 1914 1887 1897 1890 1873 1879 1919 1860 1916 1819 1923 1845 1821 1920 1908 1835 1796 1799 1938 1820 1877 1852 1971 1905 1867 1954 1823 1845 1906 1873 1939 1890 1888 1956 1888 1874 1987 1837 1959 1928 1918 1909 1928 1935 1968 1807 1890 2030 1791 1914 1950 1994 1890 1978 1894 1942 1910 1941 1918 1926 1921 1942 1922 1968 1940 1913 1948 1968 1916 1968 2033 1956 1980 1893 1998 1982 1964 1955 1909 1975 1995 2069 1980 2028 1980 1921 1930 1899 1878 1906 1938 1921 1908 1886 1833 1854 1863 1908 1910 1923 1871 1852 1863 1883 1945 1898 1921 1939 1922 1921 1867 1862 1955 1845 1882 1943 1969 1945 1924 1887 1959 1946 1895 1991 1885 1918 1830 1939 1901 1985 1900 1882 1952 1876 1938 1869 1871 1955 1981 1958 1909 1913 1961 1894 1919 1908 1882 1878 1899 1896 1943 1905 1878 1873 1977 1916 1898 1968 1869 1888 1937 1939 1873 1915 1814 1971 1970 1957 1960 1905 1965 1954 1870 1895 1907 1832 1815 1911 1896 1948 1891 1883 1931 1946 1950 1910 1894 1888 1833 1972 1889 1909 1889 1907 1936 1994 1918 1948 1935 1909 1891 1945 1946 1928 1900 1879 1998 1945 1948 1926 1963 1861 1908 1959 1989 1890 1886 1825 1935 1949 1939 1897 1919 1950 1926 1895 1929 1940 1923 1952 1968 1946 1872 1891 1956 1939 1949 1896 1972 1992 1827 1949 1997 1999 1938 1992 1915 1972 1974 1930 1987 1903 1947 1955 1951 1883 1969 1937 1919 1862 1945 1934 1859 1933 1987 1879 1853 1888 1924 1902 1853 1890 1960 1913 1886 1858 1861 2058 1945 1984 1946 1998 1930 1968 1962 1923 1988 1926 1936 2019 1962 1997 1949 1912 1957 2073 1999 1933 1993 2000 1917 2086 1952 1978 2029 1967 2022 2025 2009 1976 2027 2053 1983 2074 2039 2067 2070 1960 2135 2099 2143 2117 2090 2077 2090 2070 2065 2041 2131 2054 2031 2058 2070 1988 2134 1988 2056 2120 2145 2220 2059 2138 2093 2102 2130 2083 2197 2151 2124 2185 2177 2133 2203 2119 2129 2114 2128 2091 2095 2047 2076 2028 2013 2086 1976 1983 1903 2005 1945 1966 1918 1978 2004 2019 1916 2039 1893 1939 2000 2037 1978 1922 2023 2073 1928 2013 1973 2020 1940 1973 2032 2006 1898 2040 2044 2012 2029 2020 1900 2050 2059 1941 2004 1993 2029 2023 1915 1925 2010 1952 1884 1894 2027 2015 1951 1992 1896 1969 1997 1988 2006 1973 2015 2097 1941 2010 2000 1975 2003 1965 1942 1984 1988 1948 2074 2003 1923 2053 2055 1934 1989 2009 1955 2041 1965 1947 1956 2015 2035 1995 1967 1977 1940 2045 2109 2053 1980 2020 2050 1992 1997 1947 2014 2111 2020 1994 2004 2049 1987 1968 1997 2072 2022 2044 2014 1980 1947 2046 2041 2000 2067 2009 2018 2001 2079 2064 2086 2044 2141 2053 2157 2045 2030 2067 2129 2073 1949 2113 2133 2101 2087 2119 2170 2024 2104 2219 2124 2221 2181 2157 2134 2144 2145 2127 2180 2068 2239 2058 2174 2099 2176 2183 2156 2112 2164 2220 2129 2191 2175 2158 2186 2128 2199 2212 2171 2248 2284 2137 2216 2167 2138 2153 2204 2151 2123 2037 2050 2104 2111 2047 2097 2034 2050 2069 2134 2013 2072 1997 2022 2106 2040 2146 2067 2052 2109 2027 1985 2059 2073 2012 2010 2059 2051 2045 2052 1963 2048 2000 2113 2059 2043 2171 2003 2087 2067 2081 2032 2118 2038 2092 2074 2020 2144 2055 2017 2012 2019 2103 2089 2065 2021 2086 1999 2076 2039 2019 2130 2028 2121 2104 2134 2100 2073 2118 2024 2067 2042 1991 2075 2078 2096 2065 2024 2194 2058 2074 2082 2066 2116 2021 2047 1978 2091 2055 2063 2060 2084 2064 2106 2107 2056 2166 2079 2051 2071 1980 2032 2084 2109 2107 2021 2045 2046 2021 2118 2128 2084 2116 2056 2081 2085 2143 2041 2161 2059 2050 2128 2142 2156 2120 2112 2148 2092 2075 2039 2146 2170 2118 2094 2077 2062 2087 1993 2106 2124 2149 2147 2147 2101 2112 2093 2024 2161 2134 2174 2165 2134 2194 2127 2153 2154 2151 2181 2062 2110 2130 2118 2148 2115 2149 2214 2078 2102 2205 2174 2186 2171 2170 2115 2061 2136 2182 2158 2195 2122 2067 2148 2140 2151 2211 2071 2044 2072 2167 2217 2103 2103 2204 2190 2183 2190 2174 2226 2173 2216 2257 2279 2254 2261 2189 2323 2324 2317 2314 2354 2346 2407 2369 2474 2453 2417 2585 2477 2504 2485 2541 2622 2545 2560 2504 2556 2587 2532 2602 2627 2414 2533 2501 2566 2474 2530 2650 2586 2542 2676 2613 2666 2707 2665 2693 2641 2701 2590 2751 2665 2600 2609 2609 2670 2553 2536 2490 2446 2471 2351 2323 2311 2293 2279 2147 2254 2307 2240 2132 2182 2263 2162 2184 2210 2148 2285 2180 2158 2206 2234 2231 2157 2250 2159 2270 2292 2260 2131 2251 2205 2238 2238 2195 2278 2284 2254 2286 2310 2257 2256 2295 2272 2360 2305 2432 2379 2426 2330 2391 2409 2564 2421 2561 2594 2543 2575 2802 2730 2847 2886 2945 2899 3056 3040 3094 3230 3221 3326 3227 3167 3304 3302 3170 3253 3222 3294 3172 3066 3317 3224 3208 3218 3297 3367 3295 3433 3283 3397 3390 3592 3516 3476 3493 3590 3622 3545 3560 3619 3564 3416 3634 3571 3545 3391 3500 3350 3267 3123 2996 2908 2674 2657 2525 2507 2388 2330 2275 2352 2241 2377 2354 2278 2260 2281 2201 2290 2318 2351 2431 2333 2231 2337 2351 2241 2281 2425 2354 2255 2299 2255 2319 2245 2320 2270 2320 2410 2368 2532 2436 2403 2383 2459 2527 2482 2597 2572 2702 2720 2714 2807 2873 2898 2948 3163 3242 3311 3364 3471 3690 3719 3773 3830 3949 4023 4116 4266 4133 3959 4200 4267 4198 4240 4141 4116 4162 4174 4381 4384 4293 4508 4412 4605 4623 4604 4690 4829 4938 5132 5265 5596 5579 5831 6040 6235 6623 7003 6980 7484 7747 7906 8424 8227 8385 8593 8653 8721 8777 8632 8492 8511 8590 8466 8340 8257 8226 8136 8092 7937 8080 7988 8279 8283 8328 8455 8634 8553 8825 8941 8994 9163 9107 9493 9502 9756 9859 10079 10162 10128 10311 10527 10354 10321 10094 9856 9440 9037 8500 7925 7365 6622 6068 5698 5232 4913 4627 4279 4091 3829 3763 3747 3783 3674 3879 3697 3709 3806 3775 3776 3792 3713 3752 3755 3834 3635 3753 3696 3627 3832 3744 3753 3772 3721 3739 3821 3789 3746 3892 3857 4011 3927 3880 3991 3920 4093 4055 4077 4077 4132 4007 4013 3975 3737 3669 3618 3490 3399 3212 3069 2971 2869 2749 2717 2603 2566 2528 2389 2433 2514 2466 2386 2381 2405 2382 2392 2338 2362 2365 2236 2370 2427 2399 2371 2345 2408 2412 2395 2420 2430 2316 2315 2336 2327 2285 2324 2362 2224 2336 2372 2363 2376 2262 2360 2375 2429 2336 2374 2326 2300 2401 2252 2291 2370 2401 2378 2336 2295 2357 2362 2266 2371 2283 2305 2204 2364 2430 2394 2373 2313 2294 2317 2322 2276 2287 2254 2315 2306 2224 2298 2358 2312 2305 2283 2303 2298 2250 2260 2266 2381 2291 2387 2337 2300 2365 2254 2352 2351 2405 2411 2317 2288 2388 2322 2383 2356 2298 2365 2356 2255 2291 2370 2301 2329 2338 2395 2259 2361 2355 2316 2340 2414 2290 2343 2342 2343 2331 2278 2361 2292 2410 2376 2408 2352 2300 2306 2429 2433 2316 2403 2389 2313 2413 2230 2320 2346 2329 2382 2371 2386 2421 2395 2289 2409 2413 2371 2374 2509 2427 2472 2375 2425 2358 2474 2405 2395 2469 2354 2371 2420 2369 2326 2425 2398 2383 2384 2404 2402 2477 2408 2355 2424 2362 2387 2386 2362 2297 2379 2399 2391 2349 2334 2335 2391 2324 2344 2360 2437 2368 2411 2379 2318 2363 2351 2346 2430 2390 2292 2318 2240 2373 2316 2337 2273 2341 2430 2349 2318 2348 2360 2399 2325 2361 2367 2293 2300 2259 2352 2269 2269 2367 2326 2271 2390 2307 2343 2339 2330 2264 2236 2439 2256 2386 2239 2344 2359 2281 2454 2344 2332 2284 2353 2305 2274 2294 2406 2293 2368 2189 2309 2374 2336 2311 2267 2263 2368 2290 2315 2361 2275 2378 2308 2177 2404 2295 2246 2334 2380 2275 2290 2314 2330 2391 2248 2385 2393 2431 2332 2307 2275 2296 2316 2293 2346 2386 2290 2380 2355 2340 2293 2362 2349 2412 2357 2349 2315 2365 2318 2268 2243 2277 2319 2319 2470 2379 2379 2345 2255 2328 2399 2350 2313 2378 2270 2314 2345 2342 2335 2300 2298 2434 2407 2328 2334 2311 2332 2356 2361 2342 2309 2366 2305 2284 2359 2271 2416 2367 2373 2378 2403 2399 2499 2427 2402 2438 2458 2447 2513 2511 2409 2557 2654 2513 2465 2603 2579 2631 2543 2642 2657 2663 2690 2740 2693 2685 2783 2700 2712 2514 2698 2576 2801 2670 2703 2747 2787 2715 2682 2785 2775 2732 2867 2847 2806 2926 2880 2910 2922 3091 3027 2999 3209 3163 3177 3339 3249 3426 3454 3423 3600 3657 3711 3807 3954 3976 4165 4243 4253 4537 4564 4728 4718 4846 5017 5039 4950 5280 5344 5545 5606 5741 5945 5928 6180 6445 6509 6666 6702 6720 6965 6913 7052 7243 7085 7336 7457 7547 7542 7633 7752 7836 7842 7698 7856 7620 7620 7515 7572 7438 7214 7007 7031 6719 6691 6717 6539 6309 6363 6142 6220 6101 5972 5964 5814 5504 5348 5106 4955 4502 4367 4179 3935 3770 3596 3403 3242 3143 3035 2938 2795 2788 2751 2755 2658 2636 2749 2741 2759 2715 2706 2772 2765 2734 2716 2786 2824 2741 2639 2749 2752 2692 2663 2695 2757 2712 2793 2696 2798 2825 2740 2845 2818 2806 2920 2863 2776 2837 2742 2858 2787 2743 2794 2810 2789 2780 2823 2789 2768 2930 2754 2797 2763 2666 2679 2710 2663 2574 2571 2658 2560 2483 2474 2401 2462 2423 2427 2450 2349 2347 2462 2454 2489 2462 2415 2452 2411 2422 2471 2326 2397 2393 2371 2357 2388 2495 2384 2450 2457 2398 2390 2411 2413 2497 2413 2489 2477 2510 2533 2477 2682 2594 2586 2570 2674 2708 2760 2885 2814 2941 2954 2977 3004 3042 3123 3120 3166 3160 3198 3172 3278 3254 3254 3243 3310 3191 3281 3153 3268 3272 3388 3330 3459 3418 3544 3476 3520 3686 3532 3535 3573 3659 3924 3690 3860 3971 3979 3807 4054 3947 3850 3921 3864 3712 3674 3609 3554 3485 3344 3325 3207 3152 3060 3186 3011 2962 3114 2958 2991 3002 2937 2981 3041 2976 3090 3032 3039 2956 3070 3252 3088 3146 3105 3080 3107 3127 3019 3080 2917 2977 2999 2954 2940 2963 2921 2879 2857 2891 2846 2761 2873 2745 2839 2757 2681 2703 2762 2789 2761 2834 2905 2783 2743 2889 2790 2962 2818 2801 2842 2959 2828 2981 2883 2888 2925 2900 3004 3009 2959 2892 2869 2917 2820 2799 2720 2704 2743 2481 2548 2516 2508 2558 2551 2448 2450 2452 2467 2353 2451 2454 2353 2326 2419 2465 2516 2425 2393 2558 2439 2485 2469 2378 2542 2423 2447 2466 2488 2473 2510 2521 2539 2442 2500 2458 2553 2487 2599 2470 2507 2587 2653 2568 2664 2738 2647 2717 2775 2828 2923 2784 2901 2820 2905 2990 2946 3023 3084 3006 3147 3155 3250 3336 3493 3753 3683 3719 3916 4055 4187 4399 4562 4867 5007 5120 5240 5527 5773 5939 6246 6038 6223 6440 6581 6660 6667 6812 6836 6945 6844 6985 6951 6927 7066 7125 7192 7324 7231 7491 7524 7507 7628 7697 7923 8067 8094 8293 8568 8522 8710 8735 8561 8619 8483 8294 8092 7916 7538 7242 7105 6718 6356 6093 5784 5725 5475 5163 4959 4688 4571 4486 4295 4241 4053 3945 3986 4022 3907 3902 3828 3917 3867 3847 3908 3786 3848 3715 3472 3612 3423 3351 3286 3219 3116 3068 2918 2956 2883 2703 2723 2633 2667 2577 2540 2557 2509 2460 2594 2517 2413 2519 2437 2528 2423 2377 2429 2438 2405 2567 2466 2419 2566 2424 2412 2452 2473 2391 2458 2453 2517 2396 2374 2402 2457 2379 2417 2415 2397 2450 2417 2387 2401 2411 2370 2524 2326 2431 2384 2503 2403 2395 2436 2392 2431 2421 2417 2453 2436 2454 2400 2449 2514 2394 2400 2361 2500 2509 2448 2323 2423 2344 2418 2427 2382 2414 2522 2356 2360 2467 2399 2412 2481 2354 2514 2379 2316 2352 2467 2476 2341 2455 2376 2363 2476 2527 2403 2442 2511 2422 2452 2454 2498 2369 2441 2444 2426 2333 2366 2467 2406 2359 2537 2288 2377 2447 2471 2384 2408 2460 2375 2324 2364 2419 2393 2423 2425 2440 2423 2528 2420 2465 2488 2418 2474 2393 2443 2377 2459 2496 2401 2375 2495 2408 2329 2434 2409 2320 2489 2406 2411 2364 2385 2361 2359 2487 2487 2377 2417 2389 2381 2387 2382 2488 2511 2531 2507 2507 2533 2500 2497 2560 2505 2589 2618 2641 2672 2630 2645 2598 2632 2725 2721 2679 2763 2601 2740 2580 2736 2728 2667 2781 2603 2656 2707 2649 2710 2711 2844 2712 2832 2719 2718 2873 2787 2881 2790 2820 2862 2831 2894 2845 2786 2843 2854 2703 2746 2754 2762 2781 2621 2666 2564 2585 2715 2503 2586 2570 2497 2451 2471 2427 2435 2379 2528 2507 2444 2524 2437 2523 2526 2454 2539 2493 2407 2510 2484 2467 2410 2477 2413 2481 2531 2453 2502 2441 2516 2524 2509 2583 2529 2447 2447 2561 2505 2498 2468 2493 2503 2412 2561 2431 2451 2578 2483 2507 2411 2430 2438 2448 2488 2448 2457 2370 2332 2491 2533 2355 2458 2423 2465 2507 2482 2492 2471 2428 2496 2431 2556 2463 2536 2544 2484 2537 2579 2549 2493 2656 2523 2681 2656 2642 2692 2693 2595 2667 2722 2622 2733 2748 2720 2787 2613 2731 2621 2754 2742 2791 2826 2761 2843 2832 2736 2737 2995 2924 2921 2940 2889 2947 2940 2993 2980 2921 2784 3002 2924 2892 2864 2906 2778 2880 2851 2897 2821 2860 2810 2851 2871 2936 2737 2790 2843 2844 2896 2838 2837 2828 2782 2838 2843 2813 2823 2856 2937 2945 3077 2972 2972 2977 2969 3017 3049 3034 3034 2993 3023 3063 3035 3041 3112 2973 3096 3002 2991 2969 3072 2995 3080 2944 3040 2937 2996 3063 3063 3017 3106 3064 3045 3080 3152 2959 3175 2977 3134 3226 3255 3275 3232 3192 3322 3324 3244 3218 3331 3224 3156 3181 3195 2967 3040 2888 2902 2921 2869 2884 2850 2855 2781 2744 2749 2776 2709 2735 2795 2719 2873 2816 2817 2831 2780 2860 2812 2779 3045 2944 3028 3198 3250 3396 3435 3563 3770 3985 4230 4317 4651 4812 5245 5610 5778 6206 6424 6739 7075 7489 7593 8029 8042 8295 8747 8630 8922 8983 8977 9354 9407 9654 9861 10043 10259 10364 10276 10464 10769 10698 10862 11069 11348 11410 11786 11904 12308 12693 12544 12606 12775 12705 12544 12643 12167 11643 11271 10663 9979 9567 8658 8187 7577 7038 6829 6320 6028 5611 5177 4821 4401 4038 3771 3597 3437 3253 3196 3100 2957 3015 2923 2989 2836 2811 2816 2769 2823 2818 2715 2823 2688 2679 2657 2703 2577 2624 2590 2721 2566 2635 2582 2589 2609 2493 2659 2560 2501 2474 2547 2498 2577 2536 2542 2544 2535 2556 2625 2586 2563 2547 2646 2540 2568 2570 2576 2471 2513 2509 2600 2599 2558 2573 2548 2533 2563 2499 2621 2609 2627 2575 2614 2634 2634 2531 2581 2539 2554 2538 2629 2620 2547 2537 2608 2545 2590 2496 2506 2469 2569 2475 2631 2531 2563 2466 2572 2461 2528 2454 2452 2480 2532 2440 2532 2533 2618 2614 2549 2557 2416 2588 2509 2630 2632 2658 2672 2737 2645 2693 2784 2689 2627 2712 2677 2735 2789 2815 2815 2735 2923 2822 2723 2950 2769 2812 2834 2856 2928 2842 2887 2830 2970 2999 3000 2895 3027 2947 2990 2935 2964 3092 3031 2980 3042 2966 2981 2933 2850 2885 2870 2796 2708 2787 2839 2629 2711 2728 2644 2750 2592 2629 2597 2556 2572 2630 2553 2468 2570 2583 2645 2572 2472 2509 2578 2504 2513 2606 2577 2586 2497 2490 2554 2579 2528 2549 2479 2602 2540 2623 2551 2543 2506 2599 2529 2616 2587 2612 2610 2622 2544 2645 2672 2662 2702 2612 2727 2798 2819 2866 2808 2953 3024 3088 3094 3180 3253 3369 3506 3520 3638 3652 3668 3723 3708 3743 3847 3890 3854 4048 4052 4044 4141 3960 4161 4234 4253 4214 4070 4356 4226 4513 4446 4650 4401 4656 4771 4611 4676 4679 4808 4811 4932 4702 4861 4580 4489 4225 4191 4022 3953 3890 3731 3622 3631 3564 3364 3283 3196 3151 2965 2932 2784 2800 2728 2644 2708 2710 2823 2631 2667 2597 2653 2654 2599 2671 2536 2440 2606 2574 2507 2647 2579 2594 2592 2624 2517 2504 2591 2555 2621 2581 2529 2524 2599 2529 2541 2671 2647 2573 2567 2644 2646 2581 2595 2592 2584 2658 2607 2614 2578 2682 2780 2682 2664 2578 2685 2678 2670 2761 2790 2743 2583 2763 2780 2704 2631 2907 2783 2712 2784 2813 2743 2749 2800 2782 2968 2720 2822 2847 2826 2809 2856 2857 2816 2856 2821 2769 2889 2820 2780 2791 2786 2811 2823 2834 2801 2791 2815 2827 2748 2774 2714 2667 2691 2785 2686 2625 2632 2659 2542 2657 2614 2643 2591 2589 2559 2660 2534 2712 2546 2519 2568 2566 2544 2522 2533 2602 2608 2688 2570 2659 2486 2620 2691 2746 2664 2742 2772 2809 2793 2813 2850 2892 2917 2987 2979 3085 3090 3011 3028 3132 3144 3224 3361 3356 3343 3412 3458 3514 3519 3546 3641 3734 3602 3579 3659 3731 3815 3893 3752 3846 3769 3943 4086 3977 3796 3878 3850 3938 3839 3851 3714 3740 3870 3767 3824 3786 3793 3808 3716 3767 3511 3649 3509 3316 3351 3345 3172 3136 3157 3015 2884 2908 2883 2856 2817 2787 2835 2759 2787 2702 2632 2589 2494 2608 2647 2566 2645 2555 2494 2495 2506 2531 2609 2626 2674 2570 2616 2583 2656 2628 2700 2815 2703 2759 2720 2767 2703 2856 2838 2744 2746 2812 2890 2811 2889 2854 2850 2916 2808 2901 2980 2917 3004 2828 2870 3043 3046 2944 3085 3011 3078 2997 3169 3149 3192 3127 3282 3146 3130 3179 3128 3131 3163 3154 3124 3029 3053 3113 3082 3056 3063 3037 3118 3022 2976 3026 2932 2842 2907 2993 3004 2869 2995 2943 2889 2996 2934 3092 2989 3010 2992 2994 3016 2996 3041 2942 3067 3075 3104 3088 3162 3140 3218 3245 3175 3097 3131 3103 3087 3012 3103 2929 3041 2922 2883 2951 2861 2881 2966 2789 2804 2711 2710 2724 2660 2692 2577 2580 2520 2610 2657 2699 2640 2781 2681 2641 2512 2549 2546 2685 2532 2623 2614 2588 2644 2728 2701 2617 2588 2653 2664 2670 2482 2621 2532 2560 2600 2624 2659 2527 2600 2547 2476 2547 2570 2581 2672 2627 2600 2504 2516 2601 2517 2487 2619 2501 2509 2595 2592 2622 2605 2497 2534 2472 2607 2591 2575 2578 2588 2607 2622 2564 2659 2510 2627 2636 2539 2584 2670 2540 2726 2664 2727 2639 2584 2655 2681 2546 2622 2767 2621 2674 2650 2763 2664 2654 2683 2661 2730 2732 2689 2768 2822 2830 2748 2914 2887 2914 2891 2943 2914 3109 2948 3106 3141 3118 3175 3052 3238 3152 3170 3219 3295 3338 3253 3477 3419 3439 3469 3451 3451 3514 3578 3451 3681 3721 3858 3787 3804 3807 3886 3947 3973 3929 3817 3885 3880 3940 3924 3907 3959 3843 3868 3693 3783 3632 3795 3691 3700 3816 3814 3780 3754 3735 3733 3798 3869 3742 3785 3798 3678 3711 3707 3691 3650 3776 3728 3727 3882 3783 3816 3744 3719 3893 3771 3729 3764 3735 3898 3793 3883 3764 3770 3885 3818 3903 4002 3901 3901 4083 3978 3991 4085 4236 4331 4336 4229 4167 4158 4092 3964 3946 3820 3809 3776 3589 3534 3472 3377 3334 3380 3417 3285 3183 3351 3100 3191 3105 3184 3108 3088 3114 3083 3094 3135 3329 3213 3193 3108 3093 3185 3089 3217 3320 3351 3419 3326 3343 3378 3464 3368 3513 3440 3553 3428 3581 3604 3637 3702 3769 3811 3793 3703 3719 3773 3850 3673 3732 3651 3533 3548 3444 3379 3323 3175 3169 3225 3063 3101 3121 3031 2952 2968 2951 2799 2738 2747 2685 2658 2638 2748 2700 2596 2657 2581 2588 2618 2727 2600 2640 2656 2592 2597 2545 2604 2592 2538 2626 2508 2685 2673 2615 2575 2576 2624 2535 2548 2622 2504 2603 2560 2570 2596 2541 2502 2567 2500 2603 2575 2640 2570 2678 2619 2683 2604 2529 2548 2646 2636 2683 2701 2703 2581 2603 2607 2695 2445 2615 2569 2663 2521 2651 2647 2627 2542 2708 2683 2617 2642 2655 2703 2571 2612 2653 2698 2704 2701 2626 2569 2650 2602 2726 2641 2642 2613 2667 2734 2634 2619 2840 2654 2671 2587 2626 2767 2803 2653 2814 2784 2805 2899 2774 2978 2848 3089 3081 3041 3152 3077 3102 3220 3217 3280 3245 3449 3278 3372 3265 3405 3481 3524 3514 3583 3515 3637 3623 3737 3728 3567 3671 3730 3804 3924 3855 4011 3853 3988 4055 3937 4044 3852 3969 3892 3844 3637 3543 3416 3480 3417 3474 3395 3362 3339 3281 3186 3091 3090 3052 3015 3011 2952 2992 2943 2973 2947 2922 2956 2947 2969 2939 3085 3019 3165 3110 3112 3091 3205 3147 3168 3209 3226 3272 3300 3295 3303 3367 3465 3367 3305 3408 3374 3443 3437 3533 3548 3612 3466 3523 3628 3735 3769 3551 3740 3636 3585 3532 3505 3484 3438 3517 3489 3493 3431 3258 3422 3277 3361 3370 3288 3202 3137 3173 3252 3246 3194 3065 3141 3136 3194 3192 3377 3301 3194 3260 3283 3223 3404 3396 3226 3310 3325 3373 3253 3301 3360 3153 3187 3192 3044 2979 3022 2894 3063 2947 2859 2918 2967 2871 2974 2796 2760 2751 2780 2674 2682 2678 2645 2668 2577 2640 2581 2606 2666 2622 2730 2716 2737 2691 2647 2732 2672 2674 2618 2682 2601 2607 2586 2639 2792 2751 2662 2642 2752 2699 2731 2675 2687 2698 2691 2699 2726 2705 2666 2664 2608 2596 2657 2662 2668 2565 2591 2524 2575 2659 2627 2650 2634 2588 2562 2589 2595 2567 2701 2614 2601 2615 2635 2599 2636 2623 2743 2633 2593 2512 2596 2576 2646 2654 2473 2618 2558 2642 2557 2626 2641 2555 2635 2555 2601 2597 2664 2558 2579 2498 2563 2587 2692 2573 2651 2605 2572 2638 2557 2662 2653 2647 2737 2567 2666 2587 2666 2581 2589 2689 2664 2666 2702 2711 2695 2746 2765 2837 2872 2892 2954 2977 2942 2971 2947 2954 3072 3046 3119 3032 3170 3216 3237 3275 3193 3281 3479 3343 3447 3285 3475 3448 3520 3574 3490 3599 3676 3619 3748 3612 3708 3632 3746 3766 3804 3863 3798 3880 3785 3633 3729 3707 3678 3699 3577 3603 3535 3459 3370 3423 3379 3382 3509 3406 3379 3284 3240 3342 3312 3370 3378 3189 3339 3213 3288 3358 3335 3404 3296 3413 3408 3438 3447 3405 3475 3564 3451 3470 3340 3390 3265 3224 3208 3185 3152 3076 3117 3090 3146 3147 3117 3135 3156 3024 2946 2970 3081 2980 3041 2876 2968 2901 2878 3048 2979 2945 2947 2922 2864 2959 2902 2942 2901 2937 2970 2941 3025 2973 3113 3043 3038 3047 2968 3021 3032 2999 3109 3102 3075 3086 3058 3269 3216 3223 3274 3144 3191 3305 3265 3430 3322 3372 3294 3402 3409 3343 3263 3360 3185 3218 3161 3320 3205 2945 2947 2992 2986 2926 2885 2927 2848 2915 2815 2767 2797 2726 2725 2676 2750 2756 2625 2613 2642 2654 2613 2699 2520 2574 2706 2591 2607 2603 2508 2658 2672 2585 2582 2471 2566 2523 2510 2534 2625 2567 2551 2621 2681 2609 2648 2570 2689 2609 2554 2661 2533 2708 2656 2677 2596 2674 2653 2543 2729 2533 2744 2612 2612 2625 2630 2695 2625 2694 2656 2685 2774 2659 2655 2575 2595 2698 2663 2624 2629 2656 2656 2617 2599 2546 2691 2637 2648 2649 2545 2582 2640 2673 2572 2619 2630 2537 2592 2607 2474 2600 2569 2559 2594 2576 2613 2623 2655 2643 2663 2554 2625 2536 2560 2626 2609 2565 2619 2648 2630 2623 2581 2647 2518 2667 2640 2640 2629 2612 2592 2613 2689 2615 2580 2631 2600 2524 2659 2559 2594 2563 2644 2649 2615 2728 2649 2546 2551 2591 2503 2653 2607 2541 2582 2525 2590 2570 2673 2608 2606 2617 2643 2567 2634 2647 2544 2637 2642 2683 2662 2549 2657 2658 2706 2586 2694 2576 2750 2630 2708 2666 2746 2706 2789 2779 2799 2728 2789 2853 2853 2866 2733 2837 2922 2950 2903 2915 2896 2899 2949 2919 3032 3003 3055 3037 3079 3213 3002 3101 3136 3214 3346 3340 3266 3313 3302 3402 3340 3361 3429 3324 3367 3321 3368 3172 3381 3321 3207 3153 3206 3087 3072 3274 3266 3458 3227 3215 3154 3268 3164 3194 3212 3214 3188 3215 3136 3274 3134 3172 3275 3118 3024 3157 3162 3066 3139 3112 2951 3000 2984 2959 3026 2992 3008 2940 2960 3071 3139 3002 3058 3094 2984 3014 3071 3181 3171 3076 3125 3110 3114 3268 3226 3181 3176 3272 3350 3437 3390 3453 3472 3453 3414 3680 3582 3613 3605 3697 3825 3724 3728 3815 3841 3934 4026 4215 4148 4393 4461 4509 4596 4711 4929 4879 4976 5125 5328 5316 5281 5492 5645 5668 5676 5962 6036 6227 6246 6377 6511 6696 6748 6892 6968 7047 7377 7546 7493 7801 7616 7841 7940 7923 7991 8044 8223 7923 7931 7829 7773 7418 7325 7227 7010 6767 6765 6594 6359 6128 5890 5686 5478 5570 5235 5067 5024 4689 4624 4417 4367 4097 4115 3942 3848 3814 3703 3545 3456 3309 3289 3356 3141 3204 3283 3183 3106 3192 3142 3201 3172 3151 3149 3122 3026 3019 3042 3075 3091 3177 3143 3070 3168 3124 3113 3186 3118 3139 3179 3124 3170 3159 3145 3147 3012 3065 2986 2993 2889 2973 2809 2854 2944 2857 2839 2862 2909 2837 2913 2908 2798 2860 2760 2753 2760 2773 2751 2659 2672 2704 2653 2633 2682 2582 2617 2695 2715 2634 2726 2682 2627 2633 2625 2535 2595 2652 2483 2633 2607 2568 2570 2618 2620 2651 2608 2568 2604 2676 2628 2645 2703 2712 2620 2582 2494 2560 2659 2562 2546 2605 2703 2693 2609 2615 2608 2565 2615 2584 2577 2654 2637 2615 2595 2685 2593 2605 2514 2670 2638 2659 2625 2602 2709 2588 2662 2605 2679 2594 2695 2679 2721 2583 2700 2568 2696 2681 2685 2573 2711 2595 2630 2626 2629 2636 2587 2649 2601 2541 2561 2490 2509 2610 2688 2619 2609 2696 2626 2632 2534 2647 2623 2668 2579 2565 2647 2581 2575 2605 2604 2612 2549 2630 2649 2635 2531 2569 2628 2716 2647 2696 2590 2694 2619 2651 2583 2583 2589 2647 2541 2684 2645 2642 2704 2545 2718 2656 2624 2736 2607 2591 2657 2593 2589 2568 2566 2584 2600 2620 2539 2577 2635 2556 2710 2696 2579 2565 2651 2559 2561 2652 2519 2637 2560 2587 2610 2587 2645 2674 2633 2560 2544 2579 2447 2533 2624 2589 2562 2565 2556 2617 2694 2773 2679 2653 2668 2737 2692 2653 2666 2747 2735 2742 2659 2739 2622 2739 2687 2751 2729 2740 2712 2785 2800 2793 2781 2808 2793 2793 2886 2827 2874 2867 2971 2890 2822 2982 2948 2907 2930 2902 2932 2945 2900 3029 2923 2940 2872 2874 2889 2807 2895 2832 2805 2869 2906 2832 2965 2874 2935 2881 2980 2924 2908 3004 3013 2908 2920 2950 2937 3076 2981 3015 3035 2981 3087 3065 3008 3122 3129 3056 3171 3043 3143 3024 3224 3180 3360 3173 3192 3304 3188 3289 3211 3221 3118 3136 3120 3141 3018 3164 3058 3108 3098 3064 3067 2962 2853 2990 3008 2922 2832 2923 2903 2873 2756 2796 2795 2798 2722 2603 2680 2729 2745 2644 2749 2625 2617 2637 2641 2630 2627 2708 2659 2610 2657 2722 2629 2628 2662 2682 2586 2696 2723 2657 2629 2696 2656 2759 2691 2678 2667 2820 2696 2768 2696 2754 2811 2806 2711 2725 2761 2815 2803 2744 2675 2704 2788 2818 2810 2879 2852 2786 2799 2785 2777 2841 2953 2959 2979 2931 2995 2890 2950 2900 2920 3017 2956 2992 2912 2850 2911 2975 2860 2806 2767 2897 2838 2820 2840 2822 2810 2871 2918 2724 2784 2942 2932 2765 2815 2766 2784 2748 2857 2769 2814 2764 2786 2702 2837 2932 2804 2789 2860 2833 2841 2869 2863 2886 2879 2869 2883 2942 2766 2861 2950 2917 3077 2867 2955 2962 3101 3086 3034 3094 3081 3174 3049 3170 3253 3168 3253 3102 3075 3129 3069 3091 3066 2954 2957 2993 2993 2967 3045 2950 3060 2963 3002 3068 2996 3026 2935 2955 2952 3092 2942 2962 2838 2892 2815 2841 2879 2828 2771 2867 2860 2906 2795 2782 2846 2795 2770 2720 2749 2781 2704 2705 2743 2723 2687 2755 2779 2779 2690 2799 2846 2748 2810 2849 2713 2736 2755 2713 2740 2786 2884 2724 2846 2851 2743 2864 2844 2890 2850 2910 2818 2690 2782 2858 2834 2846 2906 2923 2908 3013 2887 3024 2924 2888 3008 2929 3003 3011 2918 3049 3035 3009 2927 2990 3067 3073 3070 3113 3095 3018 3146 2995 3046 3084 3057 3056 3039 2997 2948 2959 2972 3014 2976 2981 2943 3006 2784 2927 2824 2740 2830 2749 2621 2779 2707 2769 2737 2669 2763 2664 2745 2669 2727 2689 2649 2749 2784 2665 2742 2571 2625 2696 2630 2608 2622 2609 2602 2725 2697 2682 2730 2695 2692 2593 2655 2707 2684 2591 2616 2638 2877 2811 2659 2700 2686 2630 2728 2686 2762 2714 2722 2855 2739 2725 2739 2744 2744 2807 2848 2787 2710 2800 2765 2729 2841 2871 2762 2793 2831 2804 2844 2831 2813 2813 2844 2783 2837 2820 2864 2896 2903 2902 2958 2858 2887 2826 2951 2893 2899 2764 2853 2842 2927 2834 2794 2779 2780 2820 2819 2843 2853 2786 2847 2906 2902 2894 2987 2903 2879 2937 2902 2986 2918 3063 3094 2995 3008 3023 3106 3122 3128 3160 3264 3161 3135 3166 3263 3418 3270 3242 3179 3312 3423 3323 3356 3450 3565 3460 3484 3510 3471 3372 3357 3374 3356 3277 3232 3323 3189 3202 3156 3212 3149 3102 3129 3126 3138 3108 3048 2972 3047 2976 3050 2952 2940 2942 2961 2912 2898 2881 2887 2790 2730 2787 2718 2742 2844 2779 2718 2889 2766 2739 2869 2871 2831 2890 2862 2863 2970 2945 2997 2899 2926 2976 2922 2936 3025 3005 2915 3000 3018 3015 2962 3009 2903 3015 2936 2908 3006 3009 3101 2993 3055 2987 3045 3123 3006 3023 3034 3059 3092 3028 3001 3062 3003 3120 2985 3038 3020 2826 2909 2833 2760 2869 2822 2750 2859 2877 2875 2721 2757 2813 2876 2835 2858 2790 2768 2794 2801 2781 2744 2814 2727 2735 2675 2709 2627 2616 2681 2669 2720 2709 2663 2649 2649 2677 2577 2600 2597 2654 2666 2668 2534 2699 2548 2578 2722 2564 2612 2662 2613 2785 2614 2665 2696 2683 2625 2667 2636 2647 2653 2670 2700 2688 2704 2771 2636 2616 2617 2635 2665 2675 2590 2707 2528 2698 2687 2700 2678 2703 2717 2763 2700 2685 2780 2635 2810 2758 2749 2700 2773 2721 2703 2742 2700 2624 2745 2769 2790 2750 2647 2697 2633 2801 2635 2762 2728 2710 2725 2660 2642 2650 2765 2732 2706 2659 2675 2612 2757 2760 2837 2743 2788 2815 2761 2791 2669 2807 2752 2788 2858 2773 2809 2823 2809 2915 2799 2811 2855 2764 2884 2952 2872 2890 2982 2803 2934 3013 2972 2949 3017 2964 2900 2939 2941 2944 2947 2905 2870 2879 2867 2937 2864 2895 2951 2958 2958 2991 2859 2921 3004 2993 2901 3046 3019 3024 3013 2988 3001 2957 2976 2959 3056 2988 2972 2981 2982 2863 2879 2848 2901 2823 2852 2922 2854 2911 2830 2929 2927 2846 2897 2825 2843 2825 2767 2821 2670 2862 2830 2764 2816 2785 2808 2802 2738 2809 2783 2835 2886 2818 2875 2801 2839 2816 2943 2880 2984 2831 2904 2993 2920 2927 2997 2945 2993 3100 3114 3070 3017 3028 3227 3146 3293 3243 3300 3378 3313 3421 3426 3536 3573 3707 3565 3767 3786 3881 3858 3926 3970 4035 4224 4161 4228 4198 4410 4573 4454 4485 4643 4540 4622 4822 4782 4807 4790 4704 4686 4576 4425 4585 4336 4393 4385 4299 4137 4218 4049 4170 3933 3782 4020 3713 3858 3716 3787 3672 3556 3693 3509 3465 3406 3297 3332 3272 3094 3175 3014 2909 2941 2971 2952 2913 2870 2940 2830 2780 2828 2779 2866 2819 2756 2753 2771 2705 2776 2717 2737 2744 2720 2685 2711 2726 2742 2824 2886 2759 2782 2789 2700 2743 2705 2635 2709 2673 2779 2665 2658 2693 2670 2705 2655 2702 2704 2661 2646 2643 2725 2677 2715 2617 2662 2642 2750 2667 2631 2704 2646 2608 2662 2727 2612 2576 2723 2660 2573 2721 2656 2626 2632 2673 2547 2729 2660 2557 2664 2660 2775 2695 2618 2790 2723 2690 2646 2671 2725 2737 2711 2609 2778 2758 2751 2719 2712 2780 2704 2749 2707 2777 2702 2721 2766 2828 2823 2882 2766 2865 2867 2839 2861 2816 2902 2803 2917 2847 2890 2845 2883 2900 2930 2865 2936 2876 2858 2881 2945 3001 2907 2952 2867 2808 2805 3016 2867 2815 2883 2934 2918 2897 2804 2910 2854 2911 2914 2990 2978 2984 2980 2850 2948 2934 2926 2997 3055 2993 3082 2989 2991 2998 2941 3032 3016 2901 2981 2991 3047 2948 2781 2941 2908 2836 2836 2890 2917 2814 2872 2825 2911 2765 2799 2880 2884 2766 2859 2875 2824 2766 2881 2699 2786 2781 2693 2639 2700 2738 2653 2748 2723 2732 2680 2711 2751 2689 2837 2733 2731 2690 2766 2689 2799 2703 2730 2723 2683 2883 2664 2818 2796 2836 2691 2746 2686 2768 2663 2894 2719 2716 2775 2684 2826 2762 2728 2754 2756 2828 2748 2776 2842 2807 2924 2802 2809 2825 2896 2772 2849 2911 2783 2918 2849 2934 2871 2829 2904 2946 2950 3025 2944 3018 2944 3016 2969 2876 2965 3074 2955 3016 2982 2984 2897 2917 2933 2973 2913 2863 3020 2882 2916 2905 3046 2954 3033 2995 2915 2957 3037 3035 3125 3156 3089 3141 3263 3067 3180 3125 3203 3200 3208 3292 3312 3353 3377 3344 3466 3592 3554 3652 3503 3606 3703 3882 3896 3960 3873 4023 4083 4064 4110 4222 4171 4284 4272 4399 4315 4373 4400 4481 4442 4423 4472 4448 4465 4412 4258 4267 4353 4257 4226 4202 4093 4243 3994 4055 4094 4134 4189 4187 4051 3833 3881 3916 3900 3890 3798 3790 3739 3727 3694 3703 3730 3567 3546 3635 3417 3488 3421 3429 3314 3288 3309 3233 3149 3261 3255 3161 3073 3071 3203 3124 3179 3197 3154 3136 3157 3116 3159 3245 3157 3089 3059 3180 3044 2989 3086 3094 3170 3123 3137 3154 3264 3203 3120 3260 3252 3276 3263 3233 3222 3274 3286 3184 3143 3167 3185 3170 3271 3217 3115 3163 3208 3147 3102 3213 3151 3211 3144 3188 3146 3044 3075 3042 3085 3045 2999 2991 2989 2884 2910 2883 2844 2861 2882 2826 2822 2789 2767 2700 2757 2782 2747 2744 2747 2797 2715 2793 2811 2761 2714 2714 2734 2841 2802 2756 2706 2770 2749 2834 2772 2820 2761 2706 2776 2759 2742 2645 2707 2780 2720 2810 2738 2833 2808 2784 2725 2730 2732 2842 2901 2747 2745 2862 2926 2860 2881 2814 2878 2818 2856 2878 2907 2838 2856 2914 2828 2933 2897 2929 2849 2810 2942 2854 2877 2726 2888 2862 2744 2820 2805 2764 2759 2785 2773 2771 2858 2792 2748 2746 2813 2835 2715 2805 2799 2853 2746 2854 2667 2668 2727 2663 2693 2779 2758 2674 2745 2769 2765 2702 2800 2771 2679 2751 2709 2763 2721 2844 2763 2861 2880 2731 2768 2880 2857 2870 2894 2872 2847 3020 2894 3041 2878 3032 2950 3010 2985 3073 3014 3178 3098 3166 3106 3107 3255 3152 3199 3261 3242 3276 3213 3352 3262 3297 3290 3268 3163 3180 3123 3030 3101 3021 3028 2971 3044 2929 2910 3018 2883 2963 2875 2938 2973 2971 3021 3014 2944 2849 3050 2928 2942 2921 2845 2860 2810 2707 2804 2765 2831 2813 2590 2775 2754 2729 2744 2716 2858 2751 2823 2810 2771 2781 2754 2768 2827 2795 2914 2783 2791 2760 2713 2820 2842 2847 2808 2909 2755 2939 2828 2907 2916 2898 2868 2835 2871 2858 2890 2865 2799 2806 2952 2832 2799 2844 2867 2816 2817 2884 2753 2733 2800 2741 2871 2849 2847 2897 2828 2803 2937 2724 2811 2720 2936 2811 2738 2832 2719 2764 2632 2764 2741 2736 2723 2723 2634 2804 2723 2701 2861 2734 2808 2733 2688 2731 2740 2743 2670 2759 2734 2770 2777 2794 2772 2773 2757 2771 2788 2813 2745 2891 2854 2730 2832 2784 2826 2723 2792 2788 2851 2823 2718 2769 2891 2847 2756 2796 2768 2812 2725 2790 2802 2798 2793 2891 2821 2776 2794 2808 3010 2856 2884 2918 2925 3020 3019 2961 2958 3006 2990 2966 2998 3050 3021 3046 3160 3092 3098 3178 3068 3168 3129 3164 3084 3192 3090 3133 3058 3110 2934 3011 2951 2997 2924 2955 2877 2788 2965 2827 2910 2898 2957 2999 2934 2975 2925 2824 2857 2909 2883 2849 2838 2740 2899 2749 2815 2818 2773 2843 2718 2788 2710 2787 2733 2758 2767 2750 2788 2845 2785 2777 2888 2716 2822 2827 2702 2819 2952 2917 2833 2860 2796 2883 2846 2871 2902 2852 2818 2865 2896 2876 2917 2889 2816 2768 2818 2817 2907 2861 2761 2910 2767 2847 2820 2816 2762 2773 2762 2981 2947 2815 2781 2805 2866 2730 2846 2789 2770 2758 2782 2754 2838 2804 2811 2816 2770 2766 2832 2732 2895 2887 2834 2719 2829 2796 2663 2753 2861 2801 2762 2762 2777 2855 2818 2874 2818 2921 2871 2807 2827 2780 2763 2784 2780 2793 2778 2648 2862 2783 2677 2751 2773 2815 2736 2741 2754 2806 2703 2760 2723 2772 2687 2763 2648 2769 2738 2686 2639 2730 2756 2673 2671 2737 2843 2766 2719 2717 2720 2746 2709 2816 2732 2797 2780 2617 2736 2726 2775 2911 2821 2855 2846 2746 2812 2873 2848 2884 2853 2861 3003 2886 2861 2889 2961 2983 2928 2982 3088 3063 3056 3018 3196 3070 3242 3139 3119 3228 3212 3276 3281 3278 3222 3206 3303 3227 3244 3222 3159 3185 3202 3214 3195 3219 3082 3148 3117 3116 3119 3148 3223 3174 3113 3125 3287 3103 3205 3135 3159 3220 3174 3191 3234 3163 3109 3029 3005 2999 2897 2984 2858 2886 2871 2883 2907 2926 2798 2825 2846 2876 2812 2942 2852 2817 2896 2811 2712 2854 2859 2877 2860 2811 2791 2831 2822 2730 2902 2775 2810 2800 2849 2833 2846 2779 2708 2828 2759 2725 2831 2790 2832 2758 2833 2760 2795 2846 2852 2886 3013 2952 2835 2918 2881 2895 3067 2975 3078 2962 3058 3043 3151 3206 3110 3066 2998 3105 2954 3075 2932 2963 2907 3056 2891 2950 2925 2783 2942 2931 3005 2892 2965 2991 2875 2857 2963 2989 2928 3032 2988 2867 3040 2984 2938 2946 2895 2967 2915 2918 2819 2848 2888 2859 2963 2830 2884 2995 2835 2871 3000 2889 3008 2910 2950 2901 3015 2922 3006 3064 2985 3018 3030 2965 3028 2957 2945 2976 3056 3096 2973 2996 3045 2990 3003 2941 2895 2823 2888 2838 2858 2903 2871 2894 2775 2824 2919 2827 2847 2900 2899 2846 2767 3000 2806 2862 2912 2908 2893 2843 2789 2926 2779 2892 2881 2870 2754 2804 2896 2791 2945 2840 2741 2850 2890 2851 2860 2813 2838 2846 2830 2891 2847 2873 2874 2734 2846 2782 2899 2854 2936 2803 2763 2832 2791 2724 2775 2780 2758 2892 2811 2793 2704 2765 2805 2762 2792 2831 2695 2713 2682 2731 2775 2655 2734 2704 2787 2820 2706 2751 2787 2761 2692 2752 2782 2791 2797 2809 2750 2763 2806 2797 2826 2739 2778 2760 2756 2745 2796 2781 2841 2797 2764 2794 2781 2867 2642 2720 2705 2762 2754 2769 2922 2740 2877 2801 2914 2839 2880 2801 2911 2845 2866 2783 2851 2895 2834 2857 2827 2804 2834 3027 2840 2811 2996 2962 2954 2810 2937 2979 2921 2939 2847 2902 2924 2880 2874 2780 2839 2776 2754 2982 2868 2867 2832 2794 2857 2909 2843 2828 2792 2886 2739 2909 2892 2862 2876 2949 2981 2810 2921 2871 2812 2933 2976 2920 2754 2863 2872 2864 2942 2782 2905 2890 2946 2907 2868 2835 2829 2780 2839 2835 2740 2795 2821 2886 2854 2766 2860 2882 2714 2767 2796 2799 2808 2796 2867 2841 2843 2885 2759 2731 2823 2767 2793 2836 2840 2827 2846 2784 2763 2752 2714 2891 2721 2815 2711 2715 2740 2860 2785 2766 2804 2783 2772 2827 2735 2848 2782 2871 2760 2808 2783 2914 2841 2853 2829 2849 2898 2982 2862 2976 2914 2853 3046 2952 2944 3037 2961 2927 3037 3081 3003 2927 2923 2895 3078 2999 2987 2962 2920 2863 2911 2892 2990 2926 2857 2855 2853 2845 2895 2904 2839 2888 2862 2905 3017 3003 2826 2966 2914 2834 3004 2945 2864 2835 2879 2941 2867 2926 2906 2968 2922 2906 3016 2962 2974 2974 2937 3024 2937 3085 3000 3048 3111 2991 3148 3112 3100 3149 3086 2986 3019 3021 3047 3005 2931 3080 2851 3033 2968 3022 2975 3032 2861 3035 2926 2995 2880 2945 2962 2948 2885 2849 2869 2942 2916 2982 2880 2864 2878 2873 2965 2897 2950 2851 2920 2870 2833 2889 2922 2763 2872 2852 2790 2762 2881 2925 2770 2852 2782 2781 2801 2843 2818 2828 2823 2852 2746 2855 2924 2817 2806 2854 2821 2808 2796 2848 2880 2977 2809 2781 2894 2854 2867 2915 2930 2869 3034 2951 2949 2958 2947 2924 3052 2971 3085 2860 3004 2942 2919 2980 2915 2916 2931 2929 2976 2881 2918 2896 2911 2898 2882 2851 2836 2997 2834 2953 2925 2986 2845 2839 2835 2907 2844 2922 2883 2915 2919 2875 2957 2925 2953 2750 2920 2876 2785 2818 2925 2934 2890 2952 2969 2943 2946 2947 2939 2907 3029 2997 2955 3051 3130 3086 3057 2999 3002 2962 3079 3025 3075 2948 3074 3054 3039 2995 2831 3047 2892 3026 2917 3008 3064 2827 2978 2945 2906 2969 2941 2882 2943 3011 2904 2922 2903 2959 3036 2902 2996 2884 2898 2928 2854 2917 2984 2987 2952 3042 2843 2955 2949 2949 3034 2990 2863 2873 2983 2862 2888 2864 2858 2816 2771 2790 2778 2893 2807 2804 2926 2762 2816 2782 2816 2892 2863 2775 2888 2846 2771 2785 2918 2777 2822 2817 2868 2728 2670 2812 2877 2871 2780 2732 2745 2848 2770 2747 2905 2757 2802 2753 2746 2844 2825 2849 2873 2760 2882 2774 2683 2795 2848 2900 2860 2772 2874 2893 2971 2937 2951 2885 2947 2936 2956 3049 2984 3018 3098 3160 3040 3138 3129 3141 3286 3228 3187 3306 3158 3271 3360 3239 3332 3377 3319 3421 3438 3499 3464 3404 3272 3428 3414 3278 3239 3271 3362 3268 3210 3182 3134 3137 3195 3147 3070 3090 3141 3194 3144 3143 3125 3292 3099 3154 3128 3095 3144 3140 3201 3130 3159 3149 3090 3093 3072 3047 3133 3072 2806 3109 3078 3030 3023 2963 3018 3023 3022 3051 2995 3020 3049 3094 3137 3032 3013 3123 3121 3038 3123 3089 3047 3187 3131 3036 3128 3003 3152 3012 3009 2957 3056 3000 3026 2928 2940 2993 2993 2978 2910 2999 2847 3039 2882 3022 2993 3014 2894 2937 2943 2986 2956 2866 2886 3014 2941 2947 2921 2928 3036 2979 2994 2977 2985 2913 2992 2887 2939 2849 2826 2848 2877 2821 2824 2842 2807 2814 2871 2811 2858 2796 2760 2858 2737 2823 2824 2777 2732 2873 2708 2752 2776 2788 2786 2761 2782 2820 2798 2861 2748 2860 2728 2690 2783 2755 2791 2716 2712 2757 2732 2741 2776 2685 2743 2758 2711 2682 2683 2695 2712 2725 2654 2669 2804 2745 2712 2836 2649 2711 2741 2675 2794 2736 2745 2831 2724 2699 2728 2709 2814 2761 2831 2627 2692 2698 2780 2749 2730 2725 2689 2767 2784 2751 2730 2606 2709 2686 2686 2733 2774 2782 2794 2578 2714 2754 2647 2724 2746 2721 2878 2735 2650 2771 2634 2769 2794 2757 2741 2700 2775 2662 2798 2746 2811 2799 2767 2787 2761 2726 2737 2782 2746 2803 2673 2884 2803 2757 2793 2663 2699 2819 2731 2710 2731 2801 2849 2817 2809 2791 2804 2837 2811 2772 2853 2805 2883 2712 2787 2812 2898 2854 2795 2953 2914 2878 2889 2871 2786 2831 2714 2797 2809 2744 2854 2732 2799 2759 2674 2882 2770 2798 2820 2768 2875 2827 2718 2826 2758 2718 2776 2761 2735 2860 2827 2724 2791 2694 2802 2849 2645 2700 2740 2837 2695 2709 2718 2759 2752 2705 2737 2762 2774 2718 2700 2638 2696 2764 2813 2705 2627 2786 2761 2837 2740 2675 2766 2738 2667 2769 2769 2757 2688 2765 2703 2712 2734 2750 2750 2797 2699 2735 2761 2690 2799 2733 2743 2741 2757 2684 2783 2680 2762 2749 2750 2889 2730 2805 2750 2860 2809 2790 2849 2760 2779 2797 2785 2785 2824 2752 2780 2764 2681 2757 2849 2800 2749 2785 2794 2725 2876 2800 2876 2813 2758 2850 2790 2761 2760 2703 2802 2708 2860 2707 2720 2757 2876 2775 2761 2868 2825 2819 2771 2788 2821 2774 2751 2884 2764 2793 2849 2848 2777 2815 2906 2907 2855 2821 2791 2998 2825 2802 2765 2881 2912 2914 2799 2855 2868 2936 2870 2980 2885</counts>
			</dataPoints>
		</scan>
	</xrdMeasurement>
</xrdMeasurements>