File: dataset/precursor_mixture/NiO_0p7028-La(OH)3_0p1010-ZnO_0p2000--2min.xrdml
<?xml version="1.0"?>
<xrdMeasurements xmlns="http://www.xrdml.com/XRDMeasurement/2.3" xmlns:xsi="http://www.w3.org/2001/XMLSchema-instance" xsi:schemaLocation="http://www.xrdml.com/XRDMeasurement/2.3 http://www.xrdml.com/XRDMeasurement/2.3/XRDMeasurement.xsd" status="Completed" recordIdentifier="{6D3324AC-FDF8-4851-8C49-2EEEB38297EC}">
	<comment>
		<entry/>
	</comment>
	<sample type="To be analyzed">
		<id>NiO_0p7028-La(OH)3_0p1010-ZnO_0p2000--2min</id>
		<name></name>
		<preparedBy></preparedBy>
	</sample>
	<xrdMeasurement measurementType="Scan" status="Completed" sampleMode="Reflection">
		<usedWavelength intended="K-Alpha 1">
			<kAlpha1 unit="Angstrom">1.5405980</kAlpha1>
			<kAlpha2 unit="Angstrom">1.5444260</kAlpha2>
			<kBeta unit="Angstrom">1.3922500</kBeta>
			<ratioKAlpha2KAlpha1>0.5000</ratioKAlpha2KAlpha1>
		</usedWavelength>
		<incidentBeamPath>
			<radius unit="mm">145.00</radius>
			<xRayTube id="1010048" name="Empyrean Cu LFF HR (9430 033 7310x)">
				<tension unit="kV">40.0</tension>
				<current unit="mA">15.0</current>
				<anodeMaterial>Cu</anodeMaterial>
				<focus type="Line">
					<length unit="mm">12.0</length>
					<width unit="mm">0.4</width>
					<takeOffAngle unit="deg">6.0</takeOffAngle>
				</focus>
			</xRayTube>
			<sollerSlit id="21010002" name="Soller slits 0.04 rad.">
				<opening unit="rad">0.0400</opening>
			</sollerSlit>
			<mask id="22031000" name="Fixed mask 13 mm">
				<width unit="mm">9.00</width>
			</mask>
			<divergenceSlit id="22120001" name="Divergence slit 1°" xsi:type="fixedDivergenceSlitType">
				<distanceToSample unit="mm">50.00</distanceToSample>
				<height unit="mm">1.52</height>
			</divergenceSlit>
		</incidentBeamPath>
		<sampleMovement xsi:type="spinningSampleMovementType">
			<spinnerRevolutionTime unit="seconds">1.0</spinnerRevolutionTime>
		</sampleMovement>
		<diffractedBeamPath>
			<radius unit="mm">145.00</radius>
			<antiScatterSlit id="22090040" name="AS slit 9 mm (PIXcel)" xsi:type="fixedAntiScatterSlitType">
				<height unit="mm">9.00</height>
			</antiScatterSlit>
			<sollerSlit id="21020003" name="Large Soller slits 0.04 rad.">
				<opening unit="rad">0.0400</opening>
			</sollerSlit>
			<filter id="20030001" name="Large beta-filter Nickel">
				<material>Ni</material>
				<thickness unit="mm">0.020</thickness>
			</filter>
			<detector id="7010019" name="PIXcel1D-Medipix3 detector" xsi:type="rtmsDetectorType">
				<phd unit="keV">
					<lowerLevel>4.02</lowerLevel>
					<upperLevel>11.27</upperLevel>
				</phd>
				<mode>Scanning</mode>
				<activeLength unit="deg">5.542</activeLength>
			</detector>
		</diffractedBeamPath>
		<scan appendNumber="0" mode="Continuous" scanAxis="Gonio" status="Completed">
			<header>
				<startTimeStamp>2024-11-14T16:47:52-08:00</startTimeStamp>
				<endTimeStamp>2024-11-14T16:49:57-08:00</endTimeStamp>
				<author>
					<name>AutomatedUser</name>
				</author>
				<source>
					<applicationSoftware version="1.7b (136)">PANalytical Aeris Instrument Suite</applicationSoftware>
					<instrumentControlSoftware version="3.2.00000000 20240306">AERIS</instrumentControlSoftware>
					<instrumentID>950485</instrumentID>
				</source>
			</header>
			<dataPoints>
				<positions axis="2Theta" unit="deg">
					<startPosition>10.02173288</startPosition>
					<endPosition>99.99585608</endPosition>
				</positions>
				<positions axis="Omega" unit="deg">
					<startPosition>5.01086644</startPosition>
					<endPosition>49.99792804</endPosition>
				</positions>
				<commonCountingTime unit="seconds">10.965</commonCountingTime>
				<counts unit="counts">2649 2648 2575 2601 2664 2644 2497 2666 2615 2630 2737 2637 2550 2659 2665 2575 2538 2607 2653 2577 2577 2480 2595 2602 2616 2591 2588 2496 2515 2569 2484 2429 2461 2469 2436 2516 2530 2533 2514 2553 2486 2470 2516 2467 2439 2496 2473 2436 2380 2321 2383 2445 2456 2457 2460 2414 2449 2424 2456 2377 2449 2287 2463 2510 2446 2352 2367 2378 2367 2396 2506 2386 2422 2335 2339 2433 2442 2357 2371 2392 2392 2408 2353 2329 2391 2320 2424 2377 2375 2385 2387 2458 2265 2359 2434 2414 2414 2414 2461 2504 2305 2356 2273 2394 2356 2316 2323 2307 2395 2390 2398 2380 2422 2528 2498 2443 2533 2473 2443 2606 2602 2599 2794 2821 2733 3026 3137 3417 3865 4078 4147 4212 4036 3688 3336 3037 2826 2660 2657 2525 2638 2587 2472 2474 2453 2596 2487 2506 2497 2542 2509 2556 2612 2466 2518 2408 2480 2538 2413 2482 2433 2561 2492 2549 2504 2579 2568 2498 2549 2502 2611 2467 2575 2504 2542 2466 2588 2537 2619 2577 2438 2621 2608 2567 2568 2599 2654 2552 2532 2525 2570 2595 2541 2526 2580 2581 2544 2569 2529 2530 2586 2623 2508 2608 2593 2529 2611 2513 2574 2525 2567 2661 2625 2608 2605 2604 2630 2580 2610 2657 2638 2621 2515 2614 2606 2584 2625 2612 2573 2622 2624 2631 2637 2673 2571 2569 2616 2623 2698 2584 2701 2650 2592 2634 2594 2508 2610 2665 2610 2732 2736 2699 2709 2691 2631 2705 2620 2670 2673 2709 2666 2671 2706 2598 2734 2575 2720 2590 2734 2691 2591 2579 2596 2750 2739 2655 2650 2808 2665 2776 2849 2664 2697 2748 2759 2790 2757 2736 2739 2792 2830 2660 2789 2733 2762 2715 2848 2785 2729 2768 2709 2705 2800 2716 2653 2731 2779 2805 2746 2840 2739 2785 2758 2854 2748 2797 2773 2804 2864 2737 2813 2815 2791 2798 2831 2730 2937 2745 2809 2836 2832 2839 2826 2885 2840 2852 2851 2837 2819 2772 2744 2790 2832 2817 2787 2783 2778 2793 2828 2869 2795 2857 2887 2861 2724 2845 2915 2765 2842 2862 2863 2894 2901 2814 2906 3003 2784 2789 2798 2856 2797 2941 2861 2853 2896 2921 2936 2972 3010 2955 2914 2941 2942 2887 2976 3035 3075 2991 3038 3059 3283 3239 3302 3536 3784 4090 4449 4769 4821 4856 4675 4267 4046 3778 3631 3528 3451 3475 3566 3864 4258 4788 5138 5459 5695 5877 5399 4949 4293 3967 3610 3400 3348 3128 3162 3082 3050 3013 3014 3045 3132 3074 2957 3019 2992 2992 3010 2895 3032 2860 3040 2944 2913 3067 2988 3029 3017 3015 2891 2968 2921 2962 3082 3069 3053 2974 3094 2977 3046 3032 2985 3150 3114 3125 3072 2968 3051 3010 3051 2998 3118 3015 3102 3072 3076 3006 3070 3052 3092 3135 3145 3084 3038 3177 3056 3180 3191 3081 3143 3240 3222 3266 3337 3403 3470 3834 4016 4323 4706 5642 6455 7170 7659 7234 6194 5083 4218 3574 3490 3344 3217 3271 3196 3202 3099 3160 3065 2964 3030 3155 3074 3072 3140 3134 3003 3052 3106 3116 3124 3115 3014 3167 3030 3009 3115 3210 3045 3180 3105 3075 3136 3180 3127 3146 3106 3062 3117 3115 3041 3017 3099 3102 3199 3146 3197 3165 3297 3292 3571 3927 4462 5320 5998 6457 6194 5400 4638 3967 3338 3321 3226 3277 3071 3192 3142 3182 3183 3266 3126 3143 3244 3215 3183 3111 3137 3223 3238 3215 3179 3228 3128 3191 3305 3381 3538 3386 3574 3616 3886 4144 4564 5258 6298 8175 9656 10723 10741 9191 7350 5757 4641 4023 3861 3750 3640 3701 3581 3740 3888 4041 4170 4512 5137 6179 7774 10127 12890 15619 17028 16696 14282 11682 9145 7122 5535 4814 4402 3980 3846 3524 3454 3454 3254 3306 3246 3286 3242 3275 3192 3264 3191 3206 3308 3285 3205 3153 3340 3272 3296 3205 3289 3151 3227 3236 3213 3221 3338 3372 3362 3322 3441 3444 3561 3688 3887 4204 4415 4805 5118 5247 5267 4993 4616 4223 3893 3910 3589 3531 3342 3350 3313 3314 3252 3333 3156 3136 3155 3147 3210 3152 3226 3237 3104 3196 3283 3177 3172 3146 3177 3135 3117 3132 3131 3108 3093 3266 3091 3157 3131 3059 3183 3184 3144 3128 3193 3167 3231 3190 3242 3205 3231 3299 3270 3257 3311 3370 3300 3346 3535 3587 3627 3655 3560 3642 3681 3644 3555 3511 3554 3485 3521 3548 3499 3559 3716 3926 3857 4079 4249 4448 5109 5926 7339 9817 14022 19540 24699 28182 27315 22945 18038 13417 9375 6956 5736 4957 4432 4216 4011 3851 3579 3546 3569 3440 3448 3269 3443 3419 3433 3289 3321 3372 3202 3264 3212 3197 3266 3346 3251 3341 3270 3342 3255 3293 3278 3280 3226 3218 3341 3232 3234 3232 3141 3163 3179 3224 3198 3048 3183 3225 3282 3329 3114 3070 3191 3135 3190 3150 3123 3170 3188 3220 3186 3104 3139 3250 3172 3259 3235 3272 3139 3189 3201 3241 3329 3245 3279 3317 3183 3242 3303 3414 3509 3536 3725 3535 3616 3562 3555 3498 3568 3690 3969 4361 4693 4881 4871 4478 4343 3951 3674 3559 3571 3432 3443 3593 3632 3672 3892 3965 4035 4061 4142 4096 4141 4201 4359 4502 4642 4815 4875 4769 4704 4451 4400 4105 3902 3674 3602 3376 3351 3317 3386 3265 3338 3296 3261 3211 3334 3263 3300 3378 3178 3157 3253 3312 3333 3327 3392 3412 3412 3369 3296 3298 3293 3395 3294 3121 3131 3312 3100 3216 3182 3106 3283 3151 3237 3240 3045 3138 3163 3160 3160 3123 3134 3080 3233 3168 3092 3084 3111 3187 3052 3226 3155 3119 3215 3157 3145 3194 3108 3000 3209 3157 3179 3214 3068 3239 3258 3180 3142 3103 3094 3178 2985 3100 3172 3207 3169 3146 3095 3107 3206 3127 3218 3171 3111 3148 3091 3214 3103 3185 3206 3114 3152 3028 3183 3190 3180 3183 3142 3102 3169 3152 3106 3188 3124 3137 3126 3157 3184 3071 3125 3179 3106 3066 3290 3134 3186 3167 3161 3217 3155 3212 3112 3134 3135 3246 3112 3196 3180 3230 3209 3143 3218 3193 3199 3215 3324 3379 3453 3629 3626 3670 3668 3613 3450 3446 3448 3432 3211 3240 3284 3280 3292 3270 3254 3225 3197 3364 3325 3389 3380 3542 3466 3482 3511 3626 3649 3807 4147 4704 5463 5901 5612 5110 4955 4752 4302 3663 3476 3344 3113 3237 3276 3264 3286 3193 3131 3224 3130 3132 3169 3147 3421 3325 3217 3226 3245 3206 3316 3267 3334 3249 3348 3241 3341 3239 3184 3311 3165 3288 3073 3191 3207 3083 3208 3123 3207 3226 3263 3395 3236 3292 3275 3186 3220 3224 3323 3262 3147 3138 3092 3225 3186 3258 3177 3173 3160 3033 3067 3136 3244 3135 3184 3147 3162 3228 3146 3126 3130 3172 3150 3151 3130 3202 3100 3155 3232 3101 3229 3139 3190 3128 3168 3171 3253 3188 3234 3313 3238 3138 3246 3251 3142 3133 3195 3110 3218 3194 3209 3150 3117 3279 3288 3168 3297 3279 3251 3198 3284 3313 3149 3240 3284 3329 3317 3225 3383 3353 3405 3507 3505 3368 3574 3731 3783 3927 4128 4408 4639 5111 5632 6557 7880 9829 11902 13639 13848 13271 12222 11291 9952 8599 7011 6063 5233 4754 4344 4202 4035 3911 3806 3681 3584 3642 3498 3630 3529 3592 3632 3584 3659 3629 3716 3626 3660 3688 3508 3373 3377 3562 3365 3308 3326 3393 3324 3355 3247 3181 3392 3382 3355 3267 3261 3249 3324 3304 3204 3342 3363 3227 3306 3344 3253 3144 3337 3404 3314 3351 3259 3285 3186 3172 3403 3205 3284 3276 3318 3249 3269 3361 3221 3268 3236 3352 3427 3372 3457 3494 3407 3406 3319 3357 3377 3192 3171 3087 3114 3149 3206 3240 3187 3319 3138 3272 3200 3235 3283 3276 3264 3273 3230 3187 3295 3338 3219 3261 3349 3496 3398 3698 4176 4437 4955 4969 4525 4187 4228 4278 3918 3641 3442 3287 3269 3290 3184 3376 3369 3249 3266 3248 3254 3271 3219 3288 3368 3422 3617 3959 4069 4070 4018 3773 3711 3804 3709 3535 3461 3516 3427 3451 3416 3453 3444 3375 3503 3526 3425 3398 3348 3446 3304 3339 3323 3244 3185 3083 3146 3222 3124 3228 3231 3210 3315 3284 3145 3264 3352 3299 3152 3350 3301 3325 3292 3226 3178 3104 3265 3212 3365 3100 3176 3164 3178 3187 3145 3086 3212 3235 3178 3120 3157 3139 3041 3212 3253 3368 3097 3255 3171 3163 3209 3121 3198 3173 3130 3187 3182 3289 3259 3289 3308 3307 3329 3387 3278 3157 3167 3121 3206 3224 3215 3314 3259 3192 3072 3222 3129 3250 3092 3118 3214 3192 3122 3032 3119 3229 3195 3376 3125 3168 3172 3316 3197 3217 3277 3166 3126 3156 3281 3174 3278 3185 3168 3302 3250 3231 3261 3341 3276 3284 3331 3398 3447 3615 3499 3553 3740 3767 3882 4189 4605 5003 5638 6165 6142 6037 5773 5551 5422 5278 5082 4568 4422 4082 3988 3793 3821 3681 3527 3490 3491 3511 3475 3467 3378 3462 3374 3440 3389 3386 3324 3342 3356 3400 3362 3503 3486 3502 3486 3736 3689 3498 3517 3553 3552 3597 3687 3503 3485 3646 3580 3479 3595 3546 3579 3542 3440 3554 3472 3439 3307 3431 3321 3336 3238 3211 3266 3308 3307 3304 3364 3413 3234 3282 3278 3386 3446 3385 3337 3261 3366 3391 3392 3509 3493 3419 3471 3646 3792 3745 3932 3988 4386 4607 5130 5048 5070 4778 4885 4820 4733 4667 4336 4018 3908 3786 3682 3553 3407 3443 3486 3412 3375 3479 3300 3251 3362 3239 3249 3134 3183 3189 3229 3213 3192 3215 3215 3257 3182 3238 3287 3235 3208 3138 3231 3214 3248 3234 3266 3285 3320 3218 3294 3332 3255 3204 3342 3265 3345 3165 3160 3209 3132 3247 3195 3182 3192 3224 3197 3220 3293 3214 3318 3279 3269 3272 3284 3388 3263 3236 3271 3303 3327 3237 3144 3237 3142 3208 3149 3180 3183 3116 3220 3174 3211 3180 3150 3097 3136 3144 3289 3118 3052 3218 3251 3168 3111 3103 3091 3146 3125 3253 3268 3147 3155 3284 3235 3283 3177 3137 3138 3052 3182 3246 3131 3043 3060 3078 3133 3150 3204 3144 3216 3192 3274 3192 3244 3194 3148 3233 3169 3153 3192 3169 3154 3153 3118 3172 3252 3233 3122 3231 3131 3145 3248 3179 3223 3197 3158 3160 3144 3199 3116 3091 3103 3086 3074 3207 3100 3184 3114 3181 3234 3213 3225 3139 3122 3291 3178 3235 3160 3146 3155 3090 3158 3252 3107 3254 3141 3168 3206 3261 3180 3191 3178 3230 3141 3186 3254 3210 3216 3308 3214 3112 3130 3122 3171 3232 3147 3194 3355 3251 3254 3165 3275 3275 3274 3303 3311 3366 3442 3356 3306 3351 3299 3402 3411 3345 3261 3250 3340 3209 3263 3322 3338 3331 3287 3306 3341 3462 3664 3817 3677 3448 3399 3513 3550 3523 3473 3495 3402 3246 3295 3317 3288 3355 3337 3373 3176 3378 3240 3291 3266 3321 3279 3151 3276 3312 3215 3216 3221 3196 3257 3245 3210 3194 3204 3185 3137 3286 3235 3255 3230 3196 3191 3212 3138 3212 3279 3184 3218 3171 3239 3241 3151 3162 3233 3230 3119 3193 3234 3249 3151 3301 3275 3247 3125 3349 3155 3195 3222 3293 3350 3261 3299 3378 3290 3292 3142 3151 3289 3225 3253 3306 3156 3243 3145 3257 3139 3274 3203 3179 3150 3168 3189 3203 3144 3202 3108 3171 3276 3282 3235 3205 3187 3139 3197 3256 3223 3257 3125 3278 3301 3153 3368 3299 3245 3344 3408 3384 3410 3519 3659 3702 4007 4182 4209 4207 4058 4078 4278 4339 4357 4334 4116 4024 3771 3874 3889 3748 3719 3519 3476 3396 3412 3408 3383 3334 3311 3269 3326 3180 3274 3290 3325 3354 3311 3265 3216 3339 3325 3266 3281 3398 3331 3376 3398 3153 3211 3293 3204 3243 3350 3333 3295 3280 3225 3231 3374 3345 3167 3202 3182 3282 3198 3243 3212 3186 3224 3211 3207 3207 3247 3126 3214 3228 3241 3190 3289 3219 3262 3187 3181 3185 3408 3379 3343 3645 3590 3518 3402 3353 3233 3346 3454 3352 3437 3276 3184 3200 3342 3238 3197 3260 3285 3113 3157 3180 3203 3256 3186 3206 3190 3217 3112 3094 3361 3289 3199</counts>
			</dataPoints>
		</scan>
	</xrdMeasurement>
</xrdMeasurements>