File: dataset/precursor_mixture/NiO_0p1031-La(OH)3_0p2025-TiO2_0p7014--2min.xrdml
<?xml version="1.0"?>
<xrdMeasurements xmlns="http://www.xrdml.com/XRDMeasurement/2.3" xmlns:xsi="http://www.w3.org/2001/XMLSchema-instance" xsi:schemaLocation="http://www.xrdml.com/XRDMeasurement/2.3 http://www.xrdml.com/XRDMeasurement/2.3/XRDMeasurement.xsd" status="Completed" recordIdentifier="{F03A36BB-8508-4545-9CD6-94D2B3EFC07B}">
	<comment>
		<entry/>
	</comment>
	<sample type="To be analyzed">
		<id>NiO_0p1031-La(OH)3_0p2025-TiO2_0p7014--2min</id>
		<name></name>
		<preparedBy></preparedBy>
	</sample>
	<xrdMeasurement measurementType="Scan" status="Completed" sampleMode="Reflection">
		<usedWavelength intended="K-Alpha 1">
			<kAlpha1 unit="Angstrom">1.5405980</kAlpha1>
			<kAlpha2 unit="Angstrom">1.5444260</kAlpha2>
			<kBeta unit="Angstrom">1.3922500</kBeta>
			<ratioKAlpha2KAlpha1>0.5000</ratioKAlpha2KAlpha1>
		</usedWavelength>
		<incidentBeamPath>
			<radius unit="mm">145.00</radius>
			<xRayTube id="1010048" name="Empyrean Cu LFF HR (9430 033 7310x)">
				<tension unit="kV">40.0</tension>
				<current unit="mA">15.0</current>
				<anodeMaterial>Cu</anodeMaterial>
				<focus type="Line">
					<length unit="mm">12.0</length>
					<width unit="mm">0.4</width>
					<takeOffAngle unit="deg">6.0</takeOffAngle>
				</focus>
			</xRayTube>
			<sollerSlit id="21010002" name="Soller slits 0.04 rad.">
				<opening unit="rad">0.0400</opening>
			</sollerSlit>
			<mask id="22031000" name="Fixed mask 13 mm">
				<width unit="mm">9.00</width>
			</mask>
			<divergenceSlit id="22120001" name="Divergence slit 1°" xsi:type="fixedDivergenceSlitType">
				<distanceToSample unit="mm">50.00</distanceToSample>
				<height unit="mm">1.52</height>
			</divergenceSlit>
		</incidentBeamPath>
		<sampleMovement xsi:type="spinningSampleMovementType">
			<spinnerRevolutionTime unit="seconds">1.0</spinnerRevolutionTime>
		</sampleMovement>
		<diffractedBeamPath>
			<radius unit="mm">145.00</radius>
			<antiScatterSlit id="22090040" name="AS slit 9 mm (PIXcel)" xsi:type="fixedAntiScatterSlitType">
				<height unit="mm">9.00</height>
			</antiScatterSlit>
			<sollerSlit id="21020003" name="Large Soller slits 0.04 rad.">
				<opening unit="rad">0.0400</opening>
			</sollerSlit>
			<filter id="20030001" name="Large beta-filter Nickel">
				<material>Ni</material>
				<thickness unit="mm">0.020</thickness>
			</filter>
			<detector id="7010019" name="PIXcel1D-Medipix3 detector" xsi:type="rtmsDetectorType">
				<phd unit="keV">
					<lowerLevel>4.02</lowerLevel>
					<upperLevel>11.27</upperLevel>
				</phd>
				<mode>Scanning</mode>
				<activeLength unit="deg">5.542</activeLength>
			</detector>
		</diffractedBeamPath>
		<scan appendNumber="0" mode="Continuous" scanAxis="Gonio" status="Completed">
			<header>
				<startTimeStamp>2024-11-14T14:42:23-08:00</startTimeStamp>
				<endTimeStamp>2024-11-14T14:44:27-08:00</endTimeStamp>
				<author>
					<name>AutomatedUser</name>
				</author>
				<source>
					<applicationSoftware version="1.7b (136)">PANalytical Aeris Instrument Suite</applicationSoftware>
					<instrumentControlSoftware version="3.2.00000000 20240306">AERIS</instrumentControlSoftware>
					<instrumentID>950485</instrumentID>
				</source>
			</header>
			<dataPoints>
				<positions axis="2Theta" unit="deg">
					<startPosition>10.02173288</startPosition>
					<endPosition>99.99585608</endPosition>
				</positions>
				<positions axis="Omega" unit="deg">
					<startPosition>5.01086644</startPosition>
					<endPosition>49.99792804</endPosition>
				</positions>
				<commonCountingTime unit="seconds">10.965</commonCountingTime>
				<counts unit="counts">2090 2115 2070 2166 2083 2055 1972 1952 1986 2021 1969 2015 1989 1961 1940 1847 1879 1932 1832 1862 1880 1934 1882 1845 1838 1787 1849 1819 1801 1816 1831 1755 1801 1775 1768 1828 1768 1780 1803 1813 1720 1789 1713 1754 1749 1692 1663 1669 1557 1613 1589 1639 1606 1609 1633 1551 1651 1556 1625 1671 1593 1606 1604 1590 1534 1529 1513 1616 1503 1533 1490 1447 1467 1483 1498 1432 1494 1489 1473 1471 1485 1411 1492 1417 1480 1475 1380 1417 1397 1444 1373 1443 1372 1419 1354 1417 1392 1320 1421 1345 1436 1351 1379 1340 1386 1420 1369 1383 1381 1347 1477 1395 1401 1413 1370 1401 1454 1417 1343 1428 1522 1523 1584 1604 1768 1931 1960 2145 2499 2751 3048 3363 3405 3255 2911 2515 2109 1926 1737 1627 1483 1497 1370 1424 1317 1369 1314 1294 1319 1349 1275 1305 1225 1299 1311 1310 1280 1279 1261 1280 1262 1310 1264 1319 1236 1218 1268 1306 1308 1280 1269 1248 1219 1277 1250 1235 1243 1308 1220 1211 1241 1228 1212 1250 1206 1239 1192 1228 1255 1172 1172 1197 1192 1198 1166 1160 1209 1154 1206 1169 1156 1165 1206 1186 1189 1158 1144 1167 1118 1115 1117 1086 1129 1116 1188 1103 1129 1185 1119 1162 1158 1073 1100 1116 1096 1071 1071 1173 1128 1132 1101 1055 1095 1132 1130 1147 1034 1075 1158 1118 1137 1054 1021 1058 1080 1135 1140 1089 1075 1064 1057 1089 1046 1032 1021 1091 1061 1059 1080 1110 1035 1096 1111 1113 1082 1096 987 1078 1016 1050 1045 1027 1002 1054 1030 1062 1095 1007 1061 952 1036 984 1013 1045 1008 979 1026 922 971 996 1056 1050 1046 995 998 1040 974 1031 969 979 954 1054 1064 977 1021 1052 992 975 997 978 1038 897 993 965 1012 928 1008 1025 972 928 956 1009 1012 969 915 957 961 943 970 933 923 979 974 956 979 1057 1052 1085 1102 1040 1046 1070 1141 1185 1260 1281 1438 1634 1925 2467 3687 5114 6926 9324 11339 11447 9767 7063 4492 2830 1860 1448 1389 1262 1205 1152 1017 1103 1004 977 964 992 905 974 926 953 941 974 964 979 981 930 985 880 1059 949 1004 1047 1012 1007 1099 1117 1227 1300 1516 1594 1961 2266 2596 2757 2877 2835 2499 2151 1888 1627 1522 1377 1470 1439 1635 1863 2176 2545 2936 3296 3536 3278 2894 2422 1977 1634 1389 1324 1112 1111 973 961 1022 996 910 915 896 890 867 928 868 892 916 876 849 847 880 806 834 848 807 882 764 790 893 815 812 876 791 777 784 848 813 825 835 791 811 793 823 803 799 793 816 765 791 876 806 766 743 824 810 769 819 793 807 773 759 743 784 751 808 789 771 791 812 868 844 815 900 982 986 1065 1151 1255 1204 1183 1107 1036 962 867 809 843 705 791 750 815 744 718 780 734 752 752 749 738 782 754 728 727 781 748 778 756 703 721 703 700 726 701 703 733 726 683 663 694 679 743 692 682 659 657 678 698 697 724 680 681 727 699 609 709 708 725 719 702 685 689 653 678 658 659 714 685 635 705 727 707 683 693 635 679 736 668 692 661 703 620 674 664 647 642 678 692 688 687 705 677 749 681 721 730 740 788 778 817 819 870 916 833 810 697 731 710 715 732 644 704 693 682 669 729 717 700 818 887 1000 1088 1312 1399 1332 1289 1223 1344 1478 1541 1655 1508 1397 1244 1099 976 971 1001 1178 1519 2070 2718 3048 2943 2559 1945 1475 1159 951 851 775 760 717 725 780 817 816 947 1074 1349 1352 1418 1160 1029 887 815 806 762 770 855 775 865 844 984 1046 1205 1309 1635 1895 2188 2266 2379 2357 2120 1854 1614 1371 1090 972 907 880 810 769 723 752 673 661 731 667 646 659 639 676 576 625 673 606 627 612 653 636 640 644 653 623 659 577 588 602 642 569 652 618 598 654 598 591 658 610 584 597 543 649 651 639 608 743 670 663 775 766 788 855 930 964 933 944 849 817 748 649 713 668 650 677 643 762 693 709 689 714 735 745 810 917 1161 1365 1778 2087 2100 1948 1846 1458 1179 991 894 745 684 642 631 665 623 646 607 625 602 599 609 578 617 616 536 605 605 586 581 586 582 570 607 608 578 599 587 605 597 560 564 530 604 602 544 581 603 575 603 594 602 554 553 574 588 559 592 564 600 509 601 548 639 560 529 556 535 583 583 596 577 556 564 573 553 539 600 608 635 608 560 581 666 654 687 744 790 816 891 883 899 891 866 772 767 729 712 671 688 718 689 742 755 809 870 924 1091 1385 1891 2872 3852 4285 3979 3832 3217 2648 2215 1783 1671 1535 1703 1682 1810 1981 2062 2042 2009 1835 1664 1582 1320 1141 1032 908 842 776 700 700 656 676 601 659 663 631 643 597 636 659 610 643 641 666 732 701 739 809 799 764 721 643 656 603 584 538 595 580 563 570 565 601 585 615 520 545 561 596 584 565 567 535 568 519 514 566 507 543 542 568 539 517 592 544 532 536 566 600 517 571 535 542 522 538 551 554 532 510 545 548 519 595 494 538 571 584 497 564 554 586 540 563 495 507 558 558 540 536 555 551 499 546 577 590 562 587 594 590 622 586 669 731 749 794 1076 1511 2009 2452 2320 2242 1930 1730 1307 1067 844 695 714 647 646 621 659 653 594 587 649 655 721 704 763 732 888 1093 1442 2201 2503 2538 2431 2365 1959 1691 1411 1175 992 947 868 859 701 664 624 644 653 585 584 633 632 613 593 682 665 725 702 739 693 759 784 694 742 672 661 629 623 629 616 586 540 555 579 543 523 544 519 577 544 549 523 482 547 585 534 564 538 570 561 622 595 627 622 616 659 612 567 611 607 585 591 527 506 557 544 555 574 538 584 561 522 570 648 541 659 627 629 613 591 673 605 596 569 547 546 514 551 546 513 535 471 498 492 499 552 546 508 546 479 469 501 533 456 538 481 510 511 571 513 510 488 472 471 485 528 502 537 555 553 501 518 527 514 507 486 517 503 534 468 527 473 509 496 543 561 488 531 519 553 539 557 523 548 569 504 579 588 581 605 630 678 784 843 837 789 810 770 786 747 683 759 772 901 1188 1608 2018 2114 1951 1971 1896 1783 1597 1293 1102 984 941 779 764 662 716 636 631 618 574 592 606 643 624 613 658 657 696 754 838 839 858 835 838 834 808 767 708 682 679 677 592 600 599 590 557 551 574 574 558 556 585 607 605 615 579 618 640 642 643 633 626 564 625 535 471 577 581 559 504 532 531 575 561 486 561 563 549 560 578 580 531 559 512 487 505 529 502 561 535 467 534 482 489 508 490 479 483 470 516 499 474 483 474 550 501 457 492 493 528 464 532 514 489 476 424 546 508 465 508 503 471 516 486 482 472 493 503 475 466 493 539 526 526 520 541 540 573 716 822 1017 1175 1082 933 914 914 830 800 690 644 604 601 647 560 586 585 647 649 643 724 693 701 778 721 735 773 678 716 727 698 662 686 613 715 869 1024 1170 1218 1054 943 864 926 852 716 658 626 590 593 583 545 567 601 589 560 552 546 536 532 528 528 548 552 537 534 529 488 497 498 474 476 524 465 514 513 445 540 479 529 489 503 448 466 561 468 505 540 510 553 535 553 518 529 537 500 521 558 570 582 552 506 509 520 530 437 485 495 459 448 495 503 475 471 562 500 515 492 525 498 543 512 504 532 512 514 581 534 553 547 535 560 505 524 560 482 558 539 518 539 530 572 566 668 721 862 1166 1482 1594 1419 1231 1113 1163 1217 1013 1005 875 826 741 751 738 697 687 728 683 690 715 670 776 818 874 869 877 801 727 833 809 749 704 667 668 655 599 671 658 641 605 561 607 596 610 658 600 616 654 645 688 732 791 725 787 777 798 756 817 793 797 791 770 722 682 698 663 670 619 604 563 550 554 566 542 541 586 566 581 584 568 579 557 597 559 582 557 575 565 537 498 570 535 484 516 527 484 569 604 603 582 639 642 613 593 558 561 607 573 574 564 528 573 526 514 505 504 475 499 462 492 474 479 524 497 488 487 458 476 486 490 534 520 538 546 517 520 543 479 517 527 490 500 460 475 472 467 463 440 451 476 476 518 461 525 468 442 473 482 530 479 547 529 543 586 608 660 644 545 668 636 635 686 681 709 841 1003 1063 938 859 721 706 813 823 733 700 682 716 733 670 607 584 572 618 559 601 552 506 462 534 464 509 475 496 463 479 476 461 451 485 483 504 514 436 485 480 455 453 451 466 490 487 438 460 477 460 505 523 509 512 475 472 544 493 544 472 480 490 502 490 493 489 514 501 485 504 486 453 512 517 448 446 461 459 504 490 482 452 507 452 489 469 482 497 441 448 433 477 454 495 476 435 490 502 485 444 448 452 426 460 467 478 462 477 468 487 472 465 463 484 475 486 444 471 450 455 460 431 480 516 483 509 465 455 524 495 454 521 513 516 539 522 559 577 658 537 588 635 573 592 602 578 584 548 598 545 545 511 503 502 496 539 511 524 518 478 530 503 513 553 484 501 496 519 525 545 586 534 553 535 593 519 601 533 557 522 571 546 544 561 504 536 534 540 498 567 492 486 444 513 489 434 515 532 514 498 532 514 507 538 515 519 476 508 505 492 516 513 506 473 448 493 453 492 459 499 538 470 454 440 484 506 495 500 482 442 505 488 458 455 463 406 475 482 482 479 473 468 534 522 552 531 534 505 455 485 492 499 493 469 497 450 495 520 480 475 470 467 557 620 627 641 719 675 671 578 543 557 578 647 584 539 583 517 607 535 556 529 549 556 608 674 730 835 863 832 793 756 744 743 706 780 757 739 697 707 599 634 629 573 594 644 612 589 571 553 610 561 519 535 509 485 542 555 550 535 518 556 593 590 582 575 545 550 578 556 569 563 545 541 554 513 554 547 527 480 487 492 578 454 475 486 544 429 490 508 468 501 487 464 497 530 566 549 570 591 698 669 632 599 525 556 589 553 569 593 561 565 547 474 483 535 491 513 448 534 476 431 435 476 514 500 509 475 477 515 504 516 553 535 565 597 640 583</counts>
			</dataPoints>
		</scan>
	</xrdMeasurement>
</xrdMeasurements>