File: dataset/precursor_mixture/NiO_0p1031-La(OH)3_0p2025-TiO2_0p7014--8min.xrdml
<?xml version="1.0"?>
<xrdMeasurements xmlns="http://www.xrdml.com/XRDMeasurement/2.3" xmlns:xsi="http://www.w3.org/2001/XMLSchema-instance" xsi:schemaLocation="http://www.xrdml.com/XRDMeasurement/2.3 http://www.xrdml.com/XRDMeasurement/2.3/XRDMeasurement.xsd" status="Completed" recordIdentifier="{091228E2-16DF-4BCD-B2AA-B37975FF6249}">
	<comment>
		<entry/>
	</comment>
	<sample type="To be analyzed">
		<id>NiO_0p1031-La(OH)3_0p2025-TiO2_0p7014--8min</id>
		<name></name>
		<preparedBy></preparedBy>
	</sample>
	<xrdMeasurement measurementType="Scan" status="Completed" sampleMode="Reflection">
		<usedWavelength intended="K-Alpha 1">
			<kAlpha1 unit="Angstrom">1.5405980</kAlpha1>
			<kAlpha2 unit="Angstrom">1.5444260</kAlpha2>
			<kBeta unit="Angstrom">1.3922500</kBeta>
			<ratioKAlpha2KAlpha1>0.5000</ratioKAlpha2KAlpha1>
		</usedWavelength>
		<incidentBeamPath>
			<radius unit="mm">145.00</radius>
			<xRayTube id="1010048" name="Empyrean Cu LFF HR (9430 033 7310x)">
				<tension unit="kV">40.0</tension>
				<current unit="mA">15.0</current>
				<anodeMaterial>Cu</anodeMaterial>
				<focus type="Line">
					<length unit="mm">12.0</length>
					<width unit="mm">0.4</width>
					<takeOffAngle unit="deg">6.0</takeOffAngle>
				</focus>
			</xRayTube>
			<sollerSlit id="21010002" name="Soller slits 0.04 rad.">
				<opening unit="rad">0.0400</opening>
			</sollerSlit>
			<mask id="22031000" name="Fixed mask 13 mm">
				<width unit="mm">9.00</width>
			</mask>
			<divergenceSlit id="22120001" name="Divergence slit 1°" xsi:type="fixedDivergenceSlitType">
				<distanceToSample unit="mm">50.00</distanceToSample>
				<height unit="mm">1.52</height>
			</divergenceSlit>
		</incidentBeamPath>
		<sampleMovement xsi:type="spinningSampleMovementType">
			<spinnerRevolutionTime unit="seconds">1.0</spinnerRevolutionTime>
		</sampleMovement>
		<diffractedBeamPath>
			<radius unit="mm">145.00</radius>
			<antiScatterSlit id="22090040" name="AS slit 9 mm (PIXcel)" xsi:type="fixedAntiScatterSlitType">
				<height unit="mm">9.00</height>
			</antiScatterSlit>
			<sollerSlit id="21020003" name="Large Soller slits 0.04 rad.">
				<opening unit="rad">0.0400</opening>
			</sollerSlit>
			<filter id="20030001" name="Large beta-filter Nickel">
				<material>Ni</material>
				<thickness unit="mm">0.020</thickness>
			</filter>
			<detector id="7010019" name="PIXcel1D-Medipix3 detector" xsi:type="rtmsDetectorType">
				<phd unit="keV">
					<lowerLevel>4.02</lowerLevel>
					<upperLevel>11.27</upperLevel>
				</phd>
				<mode>Scanning</mode>
				<activeLength unit="deg">5.542</activeLength>
			</detector>
		</diffractedBeamPath>
		<scan appendNumber="0" mode="Continuous" scanAxis="Gonio" status="Completed">
			<header>
				<startTimeStamp>2024-11-14T14:33:42-08:00</startTimeStamp>
				<endTimeStamp>2024-11-14T14:41:49-08:00</endTimeStamp>
				<author>
					<name>AutomatedUser</name>
				</author>
				<source>
					<applicationSoftware version="1.7b (136)">PANalytical Aeris Instrument Suite</applicationSoftware>
					<instrumentControlSoftware version="3.2.00000000 20240306">AERIS</instrumentControlSoftware>
					<instrumentID>950485</instrumentID>
				</source>
			</header>
			<dataPoints>
				<positions axis="2Theta" unit="deg">
					<startPosition>10.00943322</startPosition>
					<endPosition>99.99442286</endPosition>
				</positions>
				<positions axis="Omega" unit="deg">
					<startPosition>5.00471661</startPosition>
					<endPosition>49.99721143</endPosition>
				</positions>
				<commonCountingTime unit="seconds">12.495</commonCountingTime>
				<counts unit="counts">2425 2335 2373 2388 2347 2330 2375 2351 2364 2336 2365 2369 2262 2408 2344 2327 2303 2332 2364 2277 2261 2285 2317 2333 2338 2380 2275 2231 2379 2315 2265 2251 2169 2312 2271 2241 2275 2292 2224 2248 2250 2281 2300 2215 2189 2176 2228 2172 2198 2302 2254 2181 2292 2203 2199 2207 2230 2256 2213 2204 2341 2215 2227 2229 2164 2199 2149 2191 2120 2187 2153 2217 2248 2148 2095 2167 2153 2182 2124 2148 2129 2124 2184 2150 2073 2239 2111 2083 2146 2137 2102 2125 2048 2101 2098 2119 2059 2094 2030 2211 2149 2114 2147 2140 2101 2075 1980 2019 1973 2013 2126 2031 2062 2055 2133 2007 2096 2005 2059 2035 2033 2142 2053 2132 2151 1962 1976 1983 2011 2007 1971 2001 1938 1994 2090 1991 2056 2044 2025 2073 1929 2052 1959 2036 1973 1975 1981 1881 1893 1986 1996 1975 1947 1931 2008 1926 1958 1927 1955 1907 1967 1938 1967 1971 1930 1943 1962 1983 1953 1906 1928 1998 1929 1881 1985 1880 2045 1821 1956 1894 1953 1937 1901 1856 1914 1892 1956 1935 1991 1928 1869 1917 1882 1949 1889 1911 1863 1906 1943 1895 1906 1921 1847 1900 1881 1797 1864 1851 1884 1884 1924 1782 1847 1901 1868 1846 1803 1905 1860 1885 1801 1905 1845 1866 1864 1795 1924 1772 1852 1790 1830 1829 1800 1750 1748 1787 1812 1799 1833 1799 1899 1744 1798 1856 1825 1828 1706 1823 1782 1757 1773 1764 1867 1805 1788 1698 1795 1827 1802 1656 1787 1838 1758 1747 1763 1737 1722 1646 1723 1745 1757 1763 1698 1696 1737 1825 1754 1728 1755 1717 1751 1717 1701 1616 1695 1667 1720 1765 1684 1738 1682 1757 1641 1681 1697 1676 1717 1764 1799 1675 1705 1750 1791 1668 1684 1700 1701 1612 1711 1669 1708 1698 1709 1764 1766 1661 1652 1740 1711 1722 1620 1706 1694 1702 1688 1703 1697 1609 1725 1725 1697 1619 1673 1661 1708 1673 1670 1756 1619 1697 1733 1692 1608 1664 1659 1706 1662 1658 1672 1673 1757 1622 1634 1651 1665 1701 1678 1618 1623 1683 1611 1632 1648 1577 1683 1641 1594 1718 1665 1612 1688 1618 1569 1593 1615 1612 1619 1647 1627 1656 1690 1626 1644 1671 1530 1651 1632 1668 1630 1594 1588 1647 1620 1521 1644 1616 1591 1628 1606 1646 1605 1606 1578 1648 1608 1640 1677 1600 1568 1689 1643 1544 1543 1686 1613 1579 1562 1569 1654 1615 1582 1579 1563 1591 1629 1616 1599 1606 1584 1506 1543 1588 1609 1616 1622 1570 1584 1504 1557 1630 1584 1564 1586 1650 1543 1586 1568 1598 1588 1518 1574 1607 1558 1592 1575 1578 1654 1500 1591 1600 1613 1561 1621 1660 1710 1644 1628 1587 1590 1599 1674 1647 1575 1692 1641 1633 1677 1661 1682 1667 1749 1714 1720 1664 1750 1688 1798 1738 1725 1780 1857 1785 1797 1879 1851 1849 1872 1958 1904 2095 2114 2084 2215 2123 2249 2281 2399 2464 2461 2538 2667 2759 2738 2820 2895 2987 3170 3235 3257 3351 3331 3512 3579 3704 3864 3784 3882 3904 3852 3944 4031 3915 3841 3837 3754 3525 3490 3288 3234 3132 3180 2912 2804 2634 2574 2431 2397 2296 2211 2150 2022 2003 1956 1940 1964 1918 1913 1845 1859 1737 1722 1706 1741 1748 1718 1642 1618 1684 1615 1586 1598 1558 1561 1624 1596 1625 1608 1580 1592 1593 1603 1640 1531 1551 1554 1550 1547 1537 1461 1601 1568 1528 1510 1459 1507 1462 1513 1452 1509 1541 1527 1499 1529 1484 1501 1512 1577 1510 1539 1457 1497 1512 1538 1565 1430 1422 1510 1537 1519 1497 1492 1522 1404 1542 1441 1432 1468 1496 1497 1380 1508 1485 1521 1468 1471 1472 1417 1464 1472 1441 1479 1483 1529 1572 1525 1430 1490 1522 1521 1437 1492 1471 1407 1496 1475 1382 1484 1520 1486 1460 1497 1392 1422 1434 1389 1444 1450 1428 1402 1499 1420 1439 1473 1383 1430 1444 1441 1529 1461 1507 1392 1448 1497 1537 1439 1518 1462 1377 1418 1505 1436 1382 1453 1387 1476 1356 1453 1515 1422 1406 1404 1515 1431 1451 1441 1416 1429 1395 1441 1429 1446 1389 1428 1437 1521 1424 1431 1423 1417 1379 1408 1344 1439 1428 1356 1505 1384 1358 1388 1445 1439 1420 1400 1425 1409 1475 1428 1430 1426 1403 1390 1380 1324 1368 1326 1340 1282 1369 1357 1353 1318 1381 1411 1417 1397 1327 1303 1367 1364 1392 1349 1399 1398 1302 1437 1396 1374 1413 1336 1402 1373 1430 1358 1404 1430 1427 1324 1388 1324 1397 1355 1291 1399 1294 1359 1398 1383 1381 1341 1312 1375 1362 1297 1330 1319 1410 1355 1409 1388 1428 1355 1300 1324 1325 1390 1350 1389 1406 1340 1285 1379 1380 1321 1351 1340 1263 1315 1340 1394 1349 1326 1333 1294 1345 1326 1303 1302 1328 1296 1361 1302 1334 1297 1318 1338 1330 1325 1374 1272 1397 1250 1402 1385 1356 1304 1343 1294 1299 1321 1341 1336 1373 1323 1367 1311 1315 1298 1280 1275 1305 1362 1318 1327 1340 1278 1354 1327 1326 1374 1330 1294 1335 1257 1356 1277 1317 1298 1335 1327 1324 1317 1284 1347 1289 1343 1289 1296 1283 1368 1314 1324 1322 1307 1278 1304 1323 1331 1263 1309 1269 1343 1269 1336 1243 1302 1259 1350 1265 1288 1299 1386 1260 1358 1295 1293 1329 1297 1330 1255 1271 1334 1285 1317 1324 1202 1271 1280 1219 1344 1286 1223 1296 1319 1247 1195 1236 1312 1198 1235 1308 1236 1262 1222 1269 1208 1212 1258 1279 1265 1278 1238 1266 1244 1288 1274 1294 1337 1263 1260 1321 1193 1277 1208 1222 1253 1263 1208 1254 1281 1269 1230 1280 1308 1235 1268 1260 1266 1273 1254 1260 1211 1262 1212 1217 1266 1239 1281 1274 1214 1210 1229 1257 1219 1293 1267 1238 1268 1235 1260 1258 1223 1249 1166 1226 1270 1251 1220 1235 1262 1261 1267 1172 1200 1231 1231 1221 1279 1233 1235 1273 1201 1219 1190 1170 1240 1198 1226 1227 1259 1202 1111 1237 1202 1186 1187 1228 1241 1170 1181 1253 1241 1263 1164 1213 1212 1157 1178 1251 1230 1226 1234 1256 1206 1143 1226 1219 1224 1210 1214 1170 1215 1188 1242 1184 1271 1142 1156 1150 1228 1197 1194 1237 1228 1214 1241 1118 1137 1164 1162 1209 1224 1192 1212 1145 1206 1162 1172 1190 1167 1236 1198 1206 1181 1185 1182 1213 1252 1171 1203 1190 1192 1186 1231 1221 1241 1182 1147 1143 1216 1200 1176 1200 1163 1121 1172 1190 1217 1183 1146 1180 1160 1122 1187 1175 1196 1203 1175 1194 1212 1177 1206 1243 1122 1160 1212 1178 1209 1162 1193 1171 1176 1148 1137 1146 1173 1203 1159 1113 1128 1163 1121 1134 1146 1109 1139 1187 1211 1160 1202 1120 1177 1206 1203 1186 1140 1206 1203 1172 1164 1163 1130 1152 1126 1097 1165 1110 1110 1113 1238 1162 1175 1137 1177 1183 1177 1176 1147 1182 1138 1183 1072 1127 1150 1204 1207 1134 1188 1141 1149 1179 1138 1104 1122 1117 1169 1165 1111 1153 1183 1131 1116 1113 1164 1127 1114 1208 1140 1214 1105 1174 1122 1202 1127 1149 1117 1072 1196 1110 1176 1168 1113 1140 1142 1089 1133 1147 1126 1137 1126 1132 1123 1184 1091 1178 1098 1110 1161 1105 1114 1106 1071 1090 1096 1132 1124 1121 1145 1103 1106 1178 1147 1053 1133 1151 1084 1156 1147 1115 1144 1111 1106 1143 1076 1107 1055 1077 1073 1090 1073 1118 1156 1066 1103 1078 1158 1107 1075 1176 1051 1102 1063 1176 1133 1160 1120 1072 1079 1034 1087 1121 1106 1092 1117 1113 1060 1080 1165 1031 1070 1121 1090 1135 1162 1078 1117 1112 1136 1116 1164 1129 1108 1133 1120 1131 1085 1090 1155 1156 1167 1120 1142 1132 1107 1137 1178 1133 1115 1110 1227 1152 1188 1209 1228 1169 1244 1189 1260 1224 1146 1220 1123 1227 1152 1243 1205 1272 1232 1236 1225 1236 1225 1231 1310 1243 1240 1272 1283 1235 1300 1243 1362 1328 1290 1337 1399 1378 1480 1472 1480 1480 1442 1490 1489 1507 1520 1605 1626 1717 1734 1803 1851 1935 2008 2180 2373 2525 2675 2927 3157 3397 3703 4024 4356 4765 5169 5744 6129 6871 7422 7885 8605 9374 10100 10762 11405 11997 12579 13270 13386 14119 13871 13678 12868 12856 11867 11328 10570 9705 8936 8036 7324 6591 5916 5206 4582 4040 3600 3256 2923 2588 2368 2096 1985 1818 1777 1678 1712 1609 1565 1519 1530 1479 1444 1392 1405 1358 1305 1365 1239 1290 1284 1348 1281 1337 1223 1318 1263 1255 1184 1174 1210 1195 1096 1155 1138 1155 1160 1119 1143 1172 1130 1118 1103 1167 1154 1164 1117 1104 1149 1063 1180 1027 1123 1099 1222 1144 1111 1130 1126 1190 1126 1187 1086 1102 1118 1120 1182 1136 1051 1117 1126 1156 1034 1083 1102 1097 1151 1140 1101 1142 1108 1140 1068 1120 1086 1126 1139 1062 1126 1093 1089 1133 1109 1191 1156 1192 1129 1097 1151 1147 1041 1127 1117 1098 1181 1129 1102 1165 1124 1153 1176 1172 1235 1168 1247 1209 1181 1174 1206 1219 1238 1257 1244 1244 1302 1305 1402 1369 1358 1420 1410 1444 1507 1544 1542 1631 1606 1610 1747 1715 1828 1944 1904 2028 2057 2181 2269 2377 2426 2577 2618 2838 2880 2954 3052 3060 3078 3200 3173 3301 3461 3334 3405 3285 3201 3190 3195 2987 2998 2949 2836 2720 2646 2437 2507 2412 2270 2210 2201 2036 1949 1901 1931 1820 1794 1714 1736 1745 1669 1716 1714 1647 1609 1684 1641 1636 1668 1679 1841 1740 1799 1881 1958 1915 2065 2080 2211 2255 2428 2610 2614 2719 2885 2908 3049 3227 3354 3459 3558 3718 3778 3768 3910 3925 4002 4081 4118 4011 3980 3890 3740 3541 3487 3397 3302 3191 2936 2786 2645 2504 2398 2262 2199 2120 2089 1858 1834 1757 1704 1622 1607 1565 1466 1518 1432 1393 1349 1338 1296 1361 1272 1232 1214 1204 1184 1212 1159 1155 1155 1105 1111 1134 1111 1158 1110 1058 1057 1115 1078 1061 1030 1099 1102 1002 1007 1054 1056 1012 1050 1019 986 1021 1040 1017 1004 980 1050 1039 1008 1030 991 994 972 1006 1008 1047 981 1021 977 998 992 1015 1028 988 978 1007 1053 942 986 957 942 969 966 976 989 972 990 990 1019 956 936 955 999 954 958 936 951 1003 962 990 965 944 976 967 995 966 998 1037 981 1006 925 944 933 979 961 975 937 975 945 947 921 932 959 973 972 957 956 957 929 982 960 978 975 958 965 985 928 973 975 961 940 970 936 957 914 965 1000 966 962 906 849 891 905 901 883 949 915 987 908 943 946 902 913 845 915 982 866 947 872 956 894 891 1001 835 905 890 901 986 903 928 930 872 932 933 935 891 910 915 960 919 949 948 931 923 915 937 965 882 977 916 927 839 890 931 937 884 935 901 891 922 944 931 899 949 884 938 938 931 897 885 910 874 947 913 952 941 906 944 880 912 960 947 876 952 858 957 966 896 893 862 910 925 904 903 871 857 902 869 895 942 898 870 910 928 898 869 933 941 891 919 928 883 942 917 957 930 962 928 903 889 867 912 877 914 892 922 870 966 931 910 936 914 973 922 965 976 926 945 1007 1003 990 994 998 1001 1009 1034 1028 1029 1036 1066 1088 1119 1121 1117 1149 1178 1250 1278 1240 1258 1296 1367 1369 1370 1407 1409 1373 1399 1405 1428 1389 1400 1417 1339 1371 1377 1312 1309 1230 1272 1296 1212 1146 1247 1127 1099 1067 1084 1047 986 1040 999 991 989 889 890 1039 981 990 989 902 976 905 895 834 859 901 915 947 902 906 877 866 912 927 892 826 859 850 881 917 937 838 888 847 915 854 856 908 885 842 893 883 854 867 828 835 799 816 824 852 886 847 838 861 830 804 916 863 851 871 837 848 849 808 854 836 907 907 885 872 832 811 871 850 822 891 818 805 848 828 846 761 799 837 832 896 869 786 833 855 842 835 823 885 832 862 803 814 848 789 834 826 850 788 797 832 798 794 876 844 846 822 838 821 793 790 798 835 853 831 811 855 827 795 795 860 787 791 797 816 839 813 818 726 744 838 832 811 773 761 836 729 770 836 751 785 786 795 772 843 797 772 802 865 788 817 782 814 836 798 811 810 825 757 799 779 775 779 824 804 730 824 829 827 781 784 802 780 777 803 763 798 828 799 756 823 802 776 815 797 843 803 795 757 816 820 842 835 848 803 797 788 820 786 793 771 781 792 777 767 823 779 846 772 780 716 834 820 792 811 750 739 824 722 813 807 824 762 805 769 773 769 791 868 733 808 803 822 794 759 829 753 761 765 830 743 769 737 766 756 795 736 797 808 762 752 762 784 781 774 771 775 794 741 793 812 768 798 776 810 765 791 757 786 786 777 802 760 789 796 744 772 767 770 746 751 799 755 765 794 762 764 743 727 730 786 768 757 793 755 765 741 789 749 781 764 774 777 813 797 721 832 792 820 793 803 800 747 763 715 748 758 798 765 768 794 783 750 777 836 755 794 769 769 769 769 794 817 788 771 761 810 745 746 777 769 771 791 801 766 758 770 820 793 827 824 825 792 821 816 863 799 839 846 781 854 852 820 869 911 897 873 903 958 965 941 946 951 959 934 1012 964 1041 969 960 976 1003 958 1022 1001 992 974 922 1018 886 955 929 906 857 861 911 924 860 819 876 875 869 852 924 775 795 838 788 818 781 824 817 759 792 809 787 825 789 800 836 835 803 782 746 788 798 801 809 771 768 850 861 807 809 863 833 832 831 830 834 834 845 844 819 884 920 962 896 940 914 966 952 1033 1031 1038 1110 1190 1264 1277 1344 1423 1451 1497 1574 1600 1581 1693 1681 1593 1561 1584 1588 1540 1477 1556 1466 1491 1439 1417 1492 1408 1503 1516 1570 1544 1544 1613 1660 1677 1757 1761 1887 1869 1877 1822 1820 1766 1863 1859 1714 1713 1635 1609 1589 1468 1459 1385 1345 1347 1310 1316 1281 1174 1173 1122 1216 1116 1133 1127 1168 1105 1110 1079 1206 1237 1229 1304 1351 1487 1555 1646 1798 1898 2014 2185 2379 2607 2735 2950 3054 3247 3468 3504 3370 3473 3466 3422 3273 3228 3164 2964 2892 2798 2615 2370 2318 2028 1982 1787 1623 1540 1467 1360 1263 1213 1139 1085 1049 989 1028 925 885 932 886 923 861 867 888 833 852 836 866 870 832 853 874 875 884 819 854 820 904 863 854 921 939 924 923 992 1029 949 1029 1076 1109 1113 1188 1190 1273 1401 1418 1491 1505 1505 1645 1567 1633 1594 1553 1617 1524 1519 1457 1515 1428 1318 1234 1276 1223 1133 1129 1100 1003 1011 992 923 964 970 956 876 842 836 867 892 903 864 882 844 894 837 889 914 906 927 922 882 933 905 941 917 971 942 985 931 989 1009 1060 984 1060 1180 1133 1167 1177 1226 1222 1371 1405 1428 1489 1541 1542 1633 1674 1695 1807 1946 1974 2047 2220 2288 2331 2399 2559 2449 2646 2704 2614 2815 2756 2804 2730 2733 2612 2649 2688 2637 2607 2512 2404 2318 2247 2189 2071 1937 1953 1844 1774 1678 1671 1554 1515 1436 1384 1315 1272 1230 1203 1210 1165 1070 1029 1076 1043 955 967 998 968 935 978 945 924 909 939 842 874 840 814 801 899 796 806 798 804 791 740 797 801 792 822 765 814 755 773 759 831 795 750 780 791 736 744 728 779 719 760 751 741 748 739 742 731 727 703 713 800 754 723 743 741 714 709 726 778 684 737 767 724 702 694 666 710 695 712 753 738 765 737 746 673 705 694 727 723 728 697 702 697 743 724 674 719 693 710 675 738 675 734 739 753 712 729 670 718 755 702 719 695 680 714 745 753 736 708 754 759 738 698 703 713 716 690 690 655 722 671 718 759 768 700 728 712 747 736 749 740 749 719 751 744 762 717 758 753 738 729 678 727 718 756 739 730 709 705 692 719 708 715 695 716 761 739 702 722 695 700 744 707 740 739 719 693 705 704 754 767 698 707 751 701 711 726 734 732 753 749 714 761 751 772 768 758 788 797 777 717 806 787 784 824 793 825 791 825 806 884 870 875 901 921 905 948 973 940 1051 1001 1032 1072 1027 1094 1068 1112 1123 1102 1054 1111 1090 1075 1043 989 1040 1130 1041 1016 1027 977 986 981 927 948 929 885 912 831 889 860 843 851 787 843 785 792 803 750 771 762 712 786 766 754 703 730 744 691 756 776 743 718 706 803 725 741 746 748 752 743 726 754 749 729 720 777 736 751 794 769 761 760 810 872 834 806 854 812 868 863 894 906 910 980 952 1021 1020 1065 1089 1184 1240 1289 1379 1456 1496 1586 1718 1825 1933 1995 2112 2158 2352 2407 2481 2394 2399 2354 2423 2363 2353 2312 2218 2138 2050 1953 1903 1760 1704 1565 1494 1424 1344 1307 1273 1264 1104 1059 1007 1062 982 965 903 876 909 879 839 819 808 809 746 766 813 783 770 753 766 779 758 750 772 758 731 706 700 761 714 691 718 686 712 700 730 727 675 703 745 696 656 684 715 660 702 688 688 671 706 699 659 664 722 656 675 665 679 640 749 666 705 658 676 699 684 619 655 664 621 683 698 714 708 659 667 668 695 657 690 673 727 660 674 646 626 672 708 699 660 663 652 663 690 672 617 665 699 627 663 669 674 708 647 654 691 687 652 639 653 658 667 655 669 669 614 686 683 668 691 652 650 699 638 671 654 706 671 636 690 653 703 679 667 629 666 673 631 709 622 622 664 652 689 677 691 665 634 648 673 668 652 661 674 620 646 679 671 656 630 700 616 650 665 681 656 665 669 637 638 680 650 671 640 601 636 650 658 627 668 676 672 626 679 661 643 649 654 638 705 640 667 611 672 693 637 689 616 640 623 694 663 681 702 661 619 672 681 619 636 669 621 577 657 622 666 687 683 627 671 617 646 615 649 659 630 654 655 656 648 676 669 682 681 646 670 662 654 652 689 675 680 611 639 659 654 640 634 647 665 685 679 679 666 658 656 707 687 695 688 635 680 686 648 698 632 656 698 669 662 691 677 689 680 676 665 746 710 669 734 687 691 694 673 693 664 671 643 715 749 696 682 703 713 762 695 722 669 750 731 825 773 687 784 800 786 769 871 799 872 845 776 796 823 847 882 910 924 968 952 946 977 999 989 1005 997 1074 1013 992 994 1036 1046 1035 1035 996 1039 977 1036 992 1011 987 935 981 951 877 914 923 876 877 865 845 807 853 837 835 828 795 827 778 793 788 784 790 772 784 772 843 823 795 879 771 816 822 850 834 840 837 923 873 850 863 881 886 898 942 889 932 948 944 999 1042 1005 1050 1068 1154 1202 1223 1338 1353 1482 1602 1667 1880 2050 2295 2463 2695 2994 3270 3662 3924 4305 4466 4661 4893 4972 4804 4919 4685 4706 4508 4518 4600 4465 4423 4185 4147 3835 3550 3470 3109 3048 2855 2776 2580 2549 2430 2164 2238 2067 2102 2020 2008 1880 1818 1815 1832 1843 1825 1855 1787 1760 1779 1978 1878 1878 1914 2015 1998 2035 2063 2093 2131 2241 2278 2318 2372 2286 2373 2418 2319 2387 2328 2351 2349 2393 2288 2322 2262 2137 2115 2017 2052 1943 1911 1861 1813 1736 1657 1668 1509 1514 1412 1430 1322 1323 1296 1238 1214 1213 1166 1106 1077 1028 1054 994 946 926 897 941 884 911 886 909 867 896 852 849 854 800 778 781 774 806 795 800 778 846 722 766 766 743 781 734 760 734 730 724 731 718 743 717 741 706 721 733 711 751 684 731 730 765 740 729 708 724 765 690 719 720 740 719 768 743 737 750 708 762 740 733 698 756 806 800 826 795 794 795 877 858 815 824 902 883 900 848 905 857 868 836 865 885 925 890 909 893 816 879 834 835 787 808 796 737 849 797 790 779 744 744 720 699 720 730 672 707 697 695 683 686 710 759 684 684 685 679 682 655 723 671 658 672 668 687 682 671 731 676 614 675 628 682 628 656 636 660 634 647 637 622 569 647 648 688 657 625 643 613 583 674 640 585 622 668 646 619 611 628 643 635 604 601 665 586 543 628 631 625 629 614 665 636 626 625 613 649 659 630 638 645 720 617 638 660 632 597 632 637 607 650 641 645 672 617 623 639 636 613 627 612 638 648 700 568 647 614 600 653 634 578 617 639 631 612 671 591 627 621 636 585 624 664 603 571 589 609 626 607 603 593 622 624 604 599 632 604 630 619 614 596 654 631 639 645 636 648 637 642 605 626 640 547 584 584 640 613 609 683 593 624 596 606 678 616 629 642 614 631 601 607 628 610 617 608 659 647 637 615 624 611 616 604 617 659 614 603 641 611 666 607 586 652 602 689 613 566 676 621 632 642 673 599 672 578 633 598 645 648 582 638 627 584 624 593 566 596 623 618 638 596 646 607 581 632 611 604 602 619 599 651 687 612 601 653 599 585 638 625 657 651 614 639 643 644 669 642 597 674 650 590 645 635 613 591 661 628 632 641 617 596 655 609 649 638 642 652 607 659 633 662 594 666 616 656 608 608 633 623 652 662 637 625 682 638 630 620 686 668 664 669 648 637 662 631 713 643 635 658 662 673 694 695 690 699 714 722 698 750 714 717 697 711 720 735 742 780 783 797 774 785 811 831 841 865 994 942 996 1018 1120 1160 1237 1415 1502 1625 1733 1883 2051 2200 2394 2624 2751 2785 2784 2867 2800 2808 2593 2656 2553 2522 2484 2381 2361 2318 2211 2163 2045 1896 1803 1670 1631 1580 1391 1357 1320 1235 1161 1056 1047 920 866 902 910 859 820 831 804 797 806 796 781 819 747 798 753 730 807 772 731 718 701 733 725 758 690 691 710 784 724 731 678 699 679 710 694 693 680 751 729 758 749 756 734 687 725 754 719 712 758 767 843 808 768 810 799 817 807 818 844 787 831 909 922 966 983 1072 1072 1187 1225 1354 1483 1669 1739 2052 2148 2366 2505 2658 2891 2854 2990 3141 2959 2970 2996 2825 2836 2653 2688 2723 2612 2638 2620 2514 2369 2362 2242 2211 2104 1967 1855 1879 1815 1752 1620 1600 1430 1372 1367 1333 1236 1208 1102 1129 1107 1116 1069 1056 1023 964 951 951 908 956 878 887 889 826 828 749 823 804 801 756 772 798 749 714 708 736 750 723 696 742 721 713 640 702 678 691 670 675 679 716 685 688 680 718 667 728 707 707 769 723 742 716 714 736 720 761 736 689 775 775 777 784 802 755 761 779 759 834 783 902 779 854 799 852 860 879 804 870 859 902 827 867 842 860 829 828 835 868 833 833 804 808 781 835 810 792 747 754 713 820 718 751 769 739 733 747 735 683 693 703 699 698 668 718 705 640 706 673 683 647 639 681 642 599 665 623 663 665 692 627 635 637 633 667 660 608 613 639 612 588 637 617 593 605 666 594 645 649 594 646 610 577 596 622 606 589 649 639 577 579 618 636 594 593 622 631 599 611 607 625 651 618 600 629 617 610 586 653 640 580 603 617 614 571 608 642 645 659 624 657 653 636 625 620 621 633 660 641 647 610 693 660 649 664 655 696 678 688 707 698 702 694 674 659 707 681 701 676 697 714 754 708 700 709 735 714 716 707 721 740 751 702 747 738 687 666 669 643 732 653 666 678 648 650 672 665 617 648 683 619 662 598 690 630 646 621 604 596 636 593 615 610 614 598 607 652 611 548 611 639 609 620 659 586 643 628 642 652 612 612 658 652 635 687 653 650 655 679 712 693 688 664 684 678 665 657 691 674 679 704 702 742 717 717 699 716 725 723 754 705 752 670 711 691 696 681 691 653 712 756 734 698 685 651 684 691 677 714 698 698 644 638 689 686 695 630 675 638 622 622 608 635 586 644 671 576 591 664 610 611 640 605 635 633 618 590 659 587 654 587 623 533 665 553 588 608 550 588 583 584 645 521 560 549 612 593 619 608 570 567 587 574 612 640 558 568 561 593 594 589 572 578 592 572 592 559 634 575 554 572 612 558 605 621 522 587 561 545 589 592 579 590 587 652 597 608 604 559 635 584 535 575 568 571 599 591 635 574 570 575 592 516 616 628 581 613 536 600 608 537 583 573 604 586 554 548 564 589 574 600 580 615 608 581 646 615 574 571 593 614 624 584 582 558 596 562 609 601 587 594 574 631 594 577 558 633 568 588 612 606 618 581 539 600 578 625 630 598 596 593 562 577 608 583 621 569 549 594 593 557 585 566 620 600 582 564 612 580 555 565 579 573 576 588 589 600 562 580 618 589 539 564 570 604 569 595 576 572 602 559 588 571 562 581 605 604 600 633 624 568 579 562 570 591 600 606 539 618 578 560 603 572 577 591 581 589 562 555 588 644 608 636 615 596 576 577 598 597 632 619 625 579 614 586 624 562 592 584 620 596 631 637 617 580 638 598 616 636 670 627 645 590 613 597 635 640 644 609 652 699 674 654 689 718 718 746 799 840 799 858 883 909 966 954 976 1000 1011 966 970 890 932 928 906 906 868 892 894 877 953 881 920 881 904 814 874 814 840 863 813 819 828 806 798 791 834 766 850 859 865 806 894 880 924 987 1039 1161 1166 1234 1348 1506 1572 1667 1848 2059 2103 2268 2377 2307 2461 2356 2423 2351 2249 2256 2286 2166 2243 2255 2147 2212 2254 2160 2192 2145 2090 2084 2005 2019 1924 1839 1748 1686 1737 1655 1496 1458 1389 1313 1302 1157 1137 1144 1136 1150 1060 1001 1047 988 993 968 899 895 871 840 850 832 850 827 769 724 783 718 744 709 729 772 726 672 731 721 689 702 676 699 647 667 671 679 618 688 664 623 649 750 679 678 664 738 641 645 689 678 682 721 681 696 677 733 706 755 714 720 720 728 733 690 775 785 762 779 826 754 830 785 833 854 849 891 835 841 932 907 936 922 934 951 944 930 1006 900 1001 972 940 957 933 921 919 902 971 967 947 926 908 911 886 920 873 865 843 824 793 881 819 818 811 846 777 780 805 734 761 740 723 745 739 708 771 707 673 682 687 711 669 667 642 716 692 640 645 644 643 662 604 652 626 650 603 642 626 636 625 680 661 660 662 611 600 635 656 647 642 622 644 670 653 679 667 670 702 628 651 643 692 734 682 706 678 684 682 674 738 691 662 725 702 714 716 712 708 744 729 699 743 679 679 734 741 705 690 677 755 691 677 704 656 697 651 659 649 710 633 637 688 716 706 657 646 636 624 635 612 654 618 618 626 605 592 633 632 615 619 605 613 598 610 613 612 623 616 599 642 620 579 615 628 613 566 611 572 608 599 613 594 608 621 623 629 630 585 658 626 657 575 595 643 631 637 659 624 643 632 682 612 641 608 617 602 645 614 630 616 667 684 637 661 584 570 592 620 639 615 635 598 657 615 557 628 592 590 606 568 604 609 581 596 565 594 624 639 589 617 579 556 578 593 603 591 546 579 601 560 591 617 550 593 577 637 571 600 562 582 593 580 553 543 572 588 556 559 562 563 563 600 597 602 572 584 532 570 559 524 591 591 658 543 608 531 617 559 542 572 554 613 577 568 603 551 614 556 588 511 582 569 576 535 574 550 554 603 537 547 585 568 567 583 553 579 562 503 571 561 549 589 568 574 548 573 582 579 563 573 603 570 517 591 543 538 561 591 542 574 550 582 583 593 547 575 559 558 565 557 612 593 586 612 569 612 563 587 561 570 560 561 626 553 630 573 624 579 561 537 552 606 537 554 578 595 574 584 528 530 568 544 605 586 590 563 573 587 543 574 602 588 613 582 607 613 581 596 582 582 596 580 575 591 570 601 573 611 555 590 595 577 610 576 573 595 593 586 547 624 598 606 599 603 623 597 631 652 632 646 671 679 668 653 636 632 650 682 686 705 724 783 750 795 837 876 889 936 1033 1055 1124 1190 1210 1183 1268 1328 1281 1273 1242 1203 1156 1195 1108 1067 1100 1053 934 910 1028 1027 1021 1014 979 998 970 974 892 945 918 909 821 829 815 748 739 735 745 722 670 680 670 655 672 668 620 661 637 685 667 666 612 691 632 629 617 661 668 674 704 651 671 680 721 689 747 715 698 673 726 722 743 749 740 758 750 792 748 796 790 825 775 774 867 845 818 844 810 814 879 855 843 871 841 889 909 848 884 836 875 927 865 839 837 875 769 855 821 818 748 841 812 778 801 771 811 774 821 841 752 802 782 775 730 705 738 712 794 727 782 785 771 828 836 838 867 888 928 983 1057 1022 1167 1241 1211 1342 1312 1448 1421 1237 1350 1407 1271 1276 1243 1119 1154 1152 1045 1101 1074 1100 1076 1092 1074 1120 1042 1091 1007 973 994 985 922 858 927 801 821 789 805 758 721 717 730 679 698 672 644 663 713 724 661 674 679 610 655 729 658 677 666 682 694 693 648 676 674 648 677 691 681 626 723 655 687 666 621 643 658 630 596 620 673 666 644 672 696 679 649 615 645 654 629 588 597 630 651 642 584 619 626 605 618 555 605 576 635 571 561 551 617 578 597 620 609 565 551 570 573 555 589 566 594 538 554 562 584 532 579 582 527 555 541 548 524 566 539 614 558 591 580 563 568 563 572 563 541 605 548 557 582 571 576 579 550 593 621 573 567 578 582 586 587 593 577 563 525 553 563 564 573 564 600 547 587 559 562 566 571 576 563 580 555 580 543 574 591 581 601 536 567 599 568 556 544 549 563 556 595 553 543 579 580 556 553 595 606 568 592 573 570 572 575 576 546 586 577 588 593 568 574 566 622 561 539 594 620 620 588 586 580 594 588 591 631 593 612 651 621 604 578 555 603 621 594 617 608 601 597 605 607 613 561 632 617 580 595 555 614 618 568 599 610 564 583 596 589 578 577 603 605 618 621 597 570 559 521 583 571 525 591 567 579 580 553 550 536 560 593 613 594 577 549 578 564 594 580 557 557 559 570 551 574 594 580 544 585 611 603 631 611 546 565 594 608 547 503 617 551 595 581 578 590 552 587 559 578 586 567 569 556 565 576 584 609 600 590 635 572 640 569 588 524 612 592 594 596 591 623 593 628 630 649 680 656 623 624 629 617 611 600 622 620 612 640 618 609 587 667 626 595 597 611 590 638 588 642 626 603 626 605 632 607 586 631 565 624 587 607 623 591 625 628 582 570 617 582 585 599 597 592 607 578 571 586 578 563 639 592 592 619 598 605 654 681 658 653 640 637 635 663 620 637 668 667 613 669 728 677 704 721 759 797 854 844 920 959 1027 1078 1133 1256 1322 1472 1514 1631 1752 1740 1802 1740 1700 1651 1701 1584 1591 1440 1453 1352 1285 1329 1270 1287 1208 1253 1255 1322 1345 1295 1268 1330 1277 1320 1248 1314 1195 1257 1219 1113 1149 1032 999 1015 992 963 917 937 896 903 896 895 878 874 830 818 858 866 856 791 841 877 862 819 828 781 815 839 842 799 858 782 827 798 827 775 784 791 827 734 792 804 796 818 776 791 847 793 896 815 795 870 848 912 881 941 991 1023 1008 974 1062 1041 1065 998 1092 1009 1019 918 1001 920 910 872 923 905 858 898 891 879 891 858 943 878 974 913 912 921 900 907 849 894 804 853 804 826 807 761 820 765 785 740 803 702 725 780 758 738 736 764 773 691 713 760 706 711 714 748 689 662 706 677 725 739 723 702 719 730 733 727 714 693 685 724 663 654 690 689 718 696 746 657 730 685 727 712 701 739 707 713 739 718 716 730 738 772 774 798 796 711 757 718 796 833 793 857 738 839 826 815 863 861 872 841 780 892 840 896 855 870 853 872 927 852 945 884 938 891 946 907 907 887 942 908 912 924 953 922 944 970 959 915 912 963 911 913 915 908 871 920 905 861 838 878 898 896 817 795 823 826 857 792 776 746 814 860 753 835 767 750 750 764 728 753 730 665 714 663 722 637 720 709 695 675 659 697 700 691 684 602 683 620 645 655 662 682 666 701 636 700 626 638 595 674 665 652 626 672 642 644 603 642 590 702 706 633 674 660 670 671 619 610 623 647 604 613 652 626 610 651 679 665 633 622 701 693 640 650 611 687 662 663 658 601 633 663 609 638 612 616 624 659 637 599 624 635 615 655 596 615 611 634 579 607 593 612 629 593 622 615 604 610 628 611 626 587 604 607 613 572 592 591 627 593 581 590 581 612 566 572 588 605 621 579 631 605 656 687 646 645 659 682 645 686 664 689 681 700 675 648 706 707 719 699 744 677 668 690 695 679 681 704 706 656 675 686 665 640 696 587 670 658 664 687 643 640 631 578 695 633 626 647 625 648 641 615 647 590 614 592 583 573 625 610 628 596 598 573 565 561 579 553 561 606 570 570 578 598 609 634 575 549 604 577 575 577 583 536 614 560 533 576 548 566 565 547 612 536 630 521 550 554 528 533 537 560 570 562 565 548 518 601 533 597 549 529 552 562 563 586 544 542 587 522 564 572 593 589 577 577 579 551 605 591 599 601 550 568 580 565 602 612 606 629 575 609 609 639 666 544 610 593 560 590 643 613 578 585 534 544 599 562 558 616 596 588 560 581 532 584 551 561 556 555 572 524 567 541 550 534 579 580 551 542 575 578 559 521 565 541 564 494 515 559 546 534 547 543 580 562 510 548 547 539 517 526 627 518 546 538 573 523 595 551 580 531 597 562 569 572 557 517 577 569 561 503 534 564 586 576 566 561 567 566 568 568 565 561 607 560 566 557 570 595 554 525 590 591 579 573 568 583 554 581 553 597 601 627 627 590 627 621 607 611 649 603 650 657 621 627 657 693 707 688 711 711 767 748 757 702 760 662 753 734 678 724 686 716 728 659 716 733 758 748 720 689 757 781 726 747 711 779 719 742 689 759 705 774 764 748 833 814 804 820 847 936 922 967 1106 1072 1097 1080 1143 1143 1150 1193 1109 1164 1078 1046 1026 945 978 927 862 833 858 886 847 826 821 826 902 881 918 925 895 918 870 902 907 852 866 793 805 812 761 720 797 801 788 790 730 800 816 800 813 862 758 788 764 807 784 774 712 753 728 734 696 654 720 631 678 654 611 639 674 644 664 655 699 658 695 658 691 651 662 651 639 656 616 559 592 610 585 583 554 583 588 579 560 624 601 558 586 566 571 543 551 574 566 552 569 573 558 600 528 578 545 513 529 553 580 544 554 572 564 553 535 574 600 561 569 570 532 546 540 539 561 521 511 560 570 596 572 550 528 541 539 539 573 600 545 542 541 546 547 524 505 547 515 538 540 557 528 526 484 515 544 515 497 612 550 599 549 561 541 563 534 530 527 507 539 542 552 577 530 536 558 562 560 563 547 569 562 556 604 539 556 514 539 578 554 562 561 549 563 553 567 530 611 548 535 514 581 580 538 601 546 582 581 596 608 549 615 611 556 556 589 566 574 566 598 598 573 539 605 513 602 553 570 580 574 550 527 570 568 555 558 613 588 583 580 542 549 564 593 543 512 577 533 604 614 551 537 558 542 520 526 526 586 542 537 552 569 540 564 578 579 564 554 554 566 571 580 537 526 559 561 542 530 542 557 525 544 557 608 530 587 550 572 547 602 541 576 569 559 546 551 558 576 548 558 554 569 526 553 565 557 545 545 509 539 567 561 527 569 529 516 537 574 547 565 519 566 524 525 527 583 491 543 479 524 519 538 525 515 577 528 526 542 504 483 564 522 553 527 530 529 527 618 518 507 575 554 578 548 498 556 544 567 541 601 563 529 540 520 495 544 531 583 528 545 496 549 549 548 513 546 593 527 561 516 534 537 527 566 526 522 534 525 490 508 556 537 541 496 504 553 539 528 528 552 488 512 537 526 525 540 548 542 562 558 518 537 484 550 527 534 531 552 570 500 551 540 549 550 563 570 553 576 528 536 540 517 533 552 517 541 529 527 546 525 502 539 528 553 555 554 550 562 557 568 553 565 538 549 561 543 533 545 548 518 538 548 509 546 590 594 487 513 531 531 586 559 529 566 544 493 545 554 549 560 552 557 557 569 562 555 574 519 514 531 513 575 592 602 506 570 583 563 593 558 569 545 581 607 560 559 535 508 587 602 580 618 581 626 572 575 622 621 629 583 551 571 627 555 576 614 580 640 577 605 619 585 623 611 578 621 656 631 661 634 622 675 690 694 639 688 658 665 675 694 676 653 718 714 731 711 696 682 675 738 692 668 702 692 685 660 712 685 717 677 726 703 681 695 709 677 694 665 685 661 640 647 626 626 627 640 634 649 636 643 590 577 640 597 623 630 618 622 583 609 587 580 578 621 627 602 617 566 564 615 561 590 525 640 575 583 575 571 573 560 594 590 576 606 544 528 591 589 557 612 533 533 586 583 551 576 591 557 548 551 550 607 572 577 582 590 589 640 564 616 568 602 578 577 551 584 601 600 571 576 635 595 614 611 578 607 596 616 642 619 606 596 639 588 619 640 639 603 603 662 629 632 656 604 613 639 656 615 648 650 664 619 629 615 656 654 668 645 626 705 666 611 649 558 622 660 604 585 613 640 647 653 615 674 652 634 611 577 643 664 615 601 614 627 639 627 613 568 633 631 630 623 602 627 625 581 587 616 586 656 607 564 589 625 617 613 609 610 597 620 603 618 572 591 586 598 602 602 543 594 604 577 586 587 560 534 555 578 591 559 579 617 548 598 568 600 600 602 551 568 563 613 574 597 560 546 590 563 613 642 562 632 605 617 634 601 580 589 567 600 610 594 613 593 584 621 584 603 565 603 552 530 561 607 613 595 580 575 614 610 549 572 559 607 590 597 561 583 578 607 576 570 607 575 619 536 589 547 557 596 559 546 580 549 571 590 555 549 590 548 586 495 532 543 566 554 530 545 511 553 528 574 541 544 594 552 550 575 523 585 587 565 557 598 543 559 572 590 555 513 581 539 551 554 552 552 572 539 559 559 555 528 559 542 528 512 516 502 568 552 571 536 530 618 539 553 543 582 556 571 538 535 563 506 553 543 530 607 566 520 545 557 586 582 547 518 538 542 543 579 546 541 528 526 536 561 554 525 509 597 604 570 536 548 526 508 557 568 555 577 547 569 546 564 540 525 582 554 599 572 523 574 561 597 582 610 606 597 621 622 598 597 614 615 580 580 646 639 592 578 628 581 557 514 593 574 567 568 587 582 592 552 609 557 594 616 592 598 585 602 595 528 586 570 607 541 583 547 528 571 582 529 592 565 567 550 550 543 559 616 567 583 555 542 551 533 574 559 584 593 569 598 569 589 538 618 547 610 620 610 589 590 613 571 576 591 633 616 645 640 667 659 699 715 746 769 757 814 793 823 834 838 866 770 832 748 816 753 738 697 684 721 696 668 685 698 650 699 654 657 630 676 662 671 640 695 688 710 699 744 698 751 684 708 689 660 673 660 630 659 617 642 621 598 582 636 550 601 602 616 591 621 591 623 584 609 598 601 608 611 644 654 607 626 595 613 606 647 674 678 618 645 732 699 685 669 714 773 781 789 766 768 861 901 860 988 938 973 950 937 959 886 957 946 876 902 844 875 810 789 753 836 781 828 784 803 826 808 815 849 785 769 863 834 849 888 861 842 901 865 865 872 813 856 799 814 750 784 775 796 758 737 805 772 744 716 746 736 712 685 698 672 718 730 705 717 725 731 693 792 705 716 730 679 692 655 708 687 697 647 695 666 636 720 659 644 660 656 712 652 634 640 628 618 617 676 588 606 616 607 610 596 656 608 614 646 645 593 630 591 612 606 557 604 614 626 590 612 630 672 620 626 639 629 592 640 632 627 654 649 627 616 629 647 599 643 655 662 608 654 676 640 633 634 602 632 639 678 704 716 666 616 688 663 663 703 689 659 666 647 643 630 691 640 658 623 656 624 606 651 657 665 663 663 612 632 625 620 637 620 676 614 617 616 629 662 638 579 641 588 639 628 652 623 627 589 653 605 600 641 595 581 607 600 629 637 619 558 584 584 579 566 576 598 579 612 571 557 618 611 556 555 549 584 552 611 606 586 559 577 557 567 618 541 597 588 602 525 536 531 593 529 540 575 583 548 611 550 541 657 554 586 522 592 555 566 596 537 598 551 613 590 559 612 533 538 549 623 523 588 550 576 550 604 567 634 576 593 567 599 625 609 573 603 597 628 567 655 657 651 644 645 632 667 671 719 729 746 760 754 756 782 734 705 703 704 709 680 681 694 667 670 669 633 673 632 623 644 610 601 632 603 587 633 642 630 659 629 629 679 666 637 704 659 612 609 665 642 583 628 615 564 555 626 603 635 587 605 609 577 573 579 585 570 503 543 572 538 545 613 546 564 595 615 563 527 521 561 564 539 505 581 523 549 568 604 552 558 600 569 508 554 565 545 577 601 576 563 534 544 530 580 576 565 506 604 549 516 590 544 550 577 526 554 582 578 611 590 523 547 521 570 547 572 561 588 556 606 614 593 546 588 604 570 585 590 579 583 594 592 636 581 674 636 584 689 647 650 631 676 690 672 654 638 639 606</counts>
			</dataPoints>
		</scan>
	</xrdMeasurement>
</xrdMeasurements>