File: dataset/precursor_mixture/NiO_0p3035-Bi2O3_0p3016-Li2CO3_0p3997--2min.xrdml
<?xml version="1.0"?>
<xrdMeasurements xmlns="http://www.xrdml.com/XRDMeasurement/2.3" xmlns:xsi="http://www.w3.org/2001/XMLSchema-instance" xsi:schemaLocation="http://www.xrdml.com/XRDMeasurement/2.3 http://www.xrdml.com/XRDMeasurement/2.3/XRDMeasurement.xsd" status="Completed" recordIdentifier="{EDA03B92-5B19-4328-B12A-D59A3430DD21}">
	<comment>
		<entry/>
	</comment>
	<sample type="To be analyzed">
		<id>NiO_0p3035-Bi2O3_0p3016-Li2CO3_0p3997--2min</id>
		<name></name>
		<preparedBy></preparedBy>
	</sample>
	<xrdMeasurement measurementType="Scan" status="Completed" sampleMode="Reflection">
		<usedWavelength intended="K-Alpha 1">
			<kAlpha1 unit="Angstrom">1.5405980</kAlpha1>
			<kAlpha2 unit="Angstrom">1.5444260</kAlpha2>
			<kBeta unit="Angstrom">1.3922500</kBeta>
			<ratioKAlpha2KAlpha1>0.5000</ratioKAlpha2KAlpha1>
		</usedWavelength>
		<incidentBeamPath>
			<radius unit="mm">145.00</radius>
			<xRayTube id="1010048" name="Empyrean Cu LFF HR (9430 033 7310x)">
				<tension unit="kV">40.0</tension>
				<current unit="mA">15.0</current>
				<anodeMaterial>Cu</anodeMaterial>
				<focus type="Line">
					<length unit="mm">12.0</length>
					<width unit="mm">0.4</width>
					<takeOffAngle unit="deg">6.0</takeOffAngle>
				</focus>
			</xRayTube>
			<sollerSlit id="21010002" name="Soller slits 0.04 rad.">
				<opening unit="rad">0.0400</opening>
			</sollerSlit>
			<mask id="22031000" name="Fixed mask 13 mm">
				<width unit="mm">9.00</width>
			</mask>
			<divergenceSlit id="22120001" name="Divergence slit 1°" xsi:type="fixedDivergenceSlitType">
				<distanceToSample unit="mm">50.00</distanceToSample>
				<height unit="mm">1.52</height>
			</divergenceSlit>
		</incidentBeamPath>
		<sampleMovement xsi:type="spinningSampleMovementType">
			<spinnerRevolutionTime unit="seconds">1.0</spinnerRevolutionTime>
		</sampleMovement>
		<diffractedBeamPath>
			<radius unit="mm">145.00</radius>
			<antiScatterSlit id="22090040" name="AS slit 9 mm (PIXcel)" xsi:type="fixedAntiScatterSlitType">
				<height unit="mm">9.00</height>
			</antiScatterSlit>
			<sollerSlit id="21020003" name="Large Soller slits 0.04 rad.">
				<opening unit="rad">0.0400</opening>
			</sollerSlit>
			<filter id="20030001" name="Large beta-filter Nickel">
				<material>Ni</material>
				<thickness unit="mm">0.020</thickness>
			</filter>
			<detector id="7010019" name="PIXcel1D-Medipix3 detector" xsi:type="rtmsDetectorType">
				<phd unit="keV">
					<lowerLevel>4.02</lowerLevel>
					<upperLevel>11.27</upperLevel>
				</phd>
				<mode>Scanning</mode>
				<activeLength unit="deg">5.542</activeLength>
			</detector>
		</diffractedBeamPath>
		<scan appendNumber="0" mode="Continuous" scanAxis="Gonio" status="Completed">
			<header>
				<startTimeStamp>2024-11-14T16:35:19-08:00</startTimeStamp>
				<endTimeStamp>2024-11-14T16:37:24-08:00</endTimeStamp>
				<author>
					<name>AutomatedUser</name>
				</author>
				<source>
					<applicationSoftware version="1.7b (136)">PANalytical Aeris Instrument Suite</applicationSoftware>
					<instrumentControlSoftware version="3.2.00000000 20240306">AERIS</instrumentControlSoftware>
					<instrumentID>950485</instrumentID>
				</source>
			</header>
			<dataPoints>
				<positions axis="2Theta" unit="deg">
					<startPosition>10.02173288</startPosition>
					<endPosition>99.99585608</endPosition>
				</positions>
				<positions axis="Omega" unit="deg">
					<startPosition>5.01086644</startPosition>
					<endPosition>49.99792804</endPosition>
				</positions>
				<commonCountingTime unit="seconds">10.965</commonCountingTime>
				<counts unit="counts">2360 2426 2317 2334 2367 2409 2309 2387 2242 2334 2285 2349 2325 2301 2236 2328 2144 2239 2235 2247 2226 2215 2308 2256 2135 2210 2126 2165 2213 2245 2135 2147 2093 2101 2039 2087 2175 2153 2114 2214 2086 2065 2197 2118 2049 2116 2181 2045 2086 2090 2115 1954 2032 2012 2061 2042 2057 2010 2029 2069 2127 2037 2120 2184 2094 2120 2205 2135 2276 2228 2150 2066 2135 2073 2035 2023 2009 1981 2044 1909 1925 1941 2011 1913 1936 2013 1932 1944 1935 1947 1878 1904 1991 1919 1931 1929 1992 1892 1981 1937 1957 2052 1893 1983 1937 1978 1931 1991 1983 1895 1986 1957 1999 1935 1925 1941 1952 1910 1981 1949 1997 1892 1967 1989 1863 2005 1912 1987 1913 1814 1950 2033 2017 1960 2050 1939 1890 1954 1948 1966 1910 1992 1925 1906 1945 1968 1902 2055 2049 1983 1990 2047 1994 2038 2047 2172 2155 2120 2012 2122 2063 2000 1939 2016 1949 1978 1944 1999 1970 1957 2024 1980 1917 1936 1969 1880 2003 1922 2033 1932 2015 2054 2017 1905 1939 1947 1969 1914 2037 2041 1955 1985 1924 1964 1968 2019 1899 1998 1922 2030 1925 1984 2054 1933 1918 1929 1960 1952 1998 1927 2001 2007 1903 2004 1953 1920 1897 2119 2064 2109 2143 2148 2175 2217 2327 2327 2282 2201 2012 2054 1998 2054 2001 2001 1898 1970 2043 2013 2021 2020 2022 2012 1999 1953 1981 2019 2032 1953 2045 1980 2025 2017 1956 2043 2081 2035 2128 2148 2344 2499 2715 2916 2950 2946 2683 2550 2259 2157 2225 2361 2254 2294 2317 2247 2151 2090 2005 1999 2044 2034 2023 2013 2062 1991 1949 2003 2037 2028 2021 1972 2012 2014 2089 2059 2006 2002 1970 2024 2028 1984 2035 2003 1996 1997 2031 2071 2083 2068 2171 2190 2151 2152 2268 2100 2202 2163 2197 2277 2341 2479 2466 2484 2419 2455 2326 2251 2158 2141 2158 2165 2221 2285 2237 2558 2825 3038 3032 2910 2702 2487 2263 2233 2250 2041 2108 2051 2037 2156 2132 2075 2153 2118 2138 2238 2236 2259 2260 2338 2412 2774 3137 3679 4260 4532 4534 4258 3579 2961 2475 2476 2342 2332 2226 2195 2216 2180 2225 2271 2221 2204 2324 2451 2345 2509 2618 2885 3258 4217 5078 6063 6585 6701 5822 4836 4100 4062 4732 6359 8771 12177 15170 16574 15932 12969 8590 5455 3758 3268 2893 2843 2963 3131 3501 4181 4865 5181 5221 4623 3672 3002 2601 2275 2338 2240 2316 2214 2127 2231 2140 2216 2025 2175 2098 2139 2105 2201 2147 2100 2186 2154 2144 2221 2221 2183 2305 2248 2347 2378 2473 2510 2395 2357 2303 2262 2146 2191 2255 2252 2323 2427 2515 2505 2719 2845 3051 3191 3391 3558 3430 3349 3176 3079 2981 2915 3090 3149 3078 2772 2770 2453 2340 2324 2225 2203 2173 2192 2175 2082 2041 2091 2114 2095 2066 2158 2149 2275 2381 2503 2800 3082 3239 3480 3658 3626 3461 3047 2864 2639 2384 2313 2273 2228 2217 2310 2324 2406 2543 2666 2882 2955 2899 2920 2847 3100 2997 3093 3441 3845 4638 5605 6670 7614 8437 8523 8406 8595 8384 7691 6148 4610 3604 2829 2619 2477 2311 2308 2307 2240 2330 2447 2724 2847 2945 3050 2961 2822 2843 2645 2506 2320 2187 2138 1996 2114 2118 2167 2074 2110 2095 2100 2246 2209 2268 2495 2816 3111 3647 3924 4103 3754 3346 2933 2711 2881 2972 3047 3153 3201 2688 2562 2474 2236 2262 2349 2435 2652 2775 2909 3009 3084 2994 2976 2770 2568 2411 2209 2239 2148 2125 2114 2110 2037 2153 2121 2191 2217 2264 2447 2583 2903 3284 3606 3909 4147 4460 5126 5952 6956 7533 7411 6689 5807 4900 4384 4279 4323 4419 4162 3701 3199 2699 2400 2324 2126 2111 2157 2035 2093 2067 2000 2016 2037 1909 2101 2079 2016 1996 1970 1992 1957 1964 2020 2008 1958 1960 1973 1899 2131 1984 2054 1956 2074 2076 2033 2124 2031 2093 2061 2157 2224 2309 2402 2484 2360 2380 2293 2108 2235 2260 2256 2444 2560 2669 2791 2657 2505 2326 2251 2035 2112 2134 2090 2010 1982 2145 2050 2078 2088 2093 2050 1959 2031 2010 1931 2001 2069 2050 1999 1970 1997 2043 2157 2145 2344 2437 2547 2619 2425 2322 2277 2171 2132 2278 2367 2449 2536 2685 2555 2550 2479 2460 2397 2528 2791 3008 3154 3258 3132 2903 2600 2551 2397 2279 2265 2258 2316 2340 2379 2517 2513 2819 3037 3628 4603 5962 8044 9977 11359 11513 10179 8072 6356 4899 3857 3157 2802 2569 2454 2274 2163 2050 2173 2140 2125 2023 2074 2002 2021 2116 2113 2123 2069 2134 2033 2120 2063 2064 2010 1982 2008 1985 1978 1919 2004 2055 2168 2227 2432 2482 2599 2563 2665 2387 2293 2135 2103 2123 2141 2033 2104 2104 2050 2039 2071 2054 2076 2111 2091 2091 2212 2174 2300 2562 2759 3501 4132 4754 5136 5064 4350 3727 3271 2705 2407 2289 2160 2192 2195 2289 2158 2184 2300 2272 2317 2360 2247 2139 2266 2181 2231 2184 2278 2302 2396 2356 2532 2462 2370 2295 2153 2246 2079 2039 2010 2037 2182 2097 2133 2181 2114 2217 2281 2427 2681 2920 3328 3446 3564 3574 3828 3676 3234 2900 2735 2515 2337 2290 2346 2318 2089 2092 2183 2150 2143 2119 2237 2307 2483 2620 2798 2755 2602 2455 2412 2261 2227 2169 2213 2366 2635 2789 2882 2729 2602 2387 2340 2195 2156 2209 2140 2259 2159 2150 2133 2037 2044 2129 1982 2024 1969 2015 2013 1985 2008 2025 2013 2104 2108 2083 2098 2167 2211 2326 2351 2262 2351 2436 2544 2633 3003 3307 3360 3259 3208 3319 3465 3470 3328 3119 3072 2929 2933 2999 3051 3415 3879 4258 4295 3852 3397 3172 2907 2451 2441 2360 2356 2378 2531 2769 3133 3419 3470 3431 2931 2896 2709 2411 2387 2188 2166 2234 2163 2175 2187 2068 1957 2084 2095 2197 2102 2070 2033 2009 1919 2007 2038 2059 2109 2156 2154 2180 2226 2256 2179 2268 2230 2210 2430 2549 2835 3326 3672 3817 3612 3312 3021 2850 2439 2297 2187 2265 2211 2287 2358 2536 2811 3061 3261 3166 3010 2944 2696 2547 2418 2473 2591 2827 2827 3031 2922 2630 2550 2492 2262 2059 2241 2032 2117 2071 2133 2214 2211 2181 2241 2211 2300 2303 2254 2403 2397 2420 2341 2316 2442 2261 2229 2118 2168 2144 2106 2085 2109 2117 2172 2125 2083 2180 2447 2573 2748 3005 3308 3323 3245 3252 3037 2905 2677 2593 2728 2792 2910 3072 3003 2811 2654 2576 2532 2538 2424 2290 2293 2311 2258 2282 2238 2436 2633 2759 2954 2977 2633 2591 2498 2329 2337 2196 2079 2130 2064 1965 2028 2141 2090 2079 2147 2227 2076 2144 2186 2183 2118 2084 2171 2013 2070 2012 1918 2014 2029 1979 2009 2012 2023 2009 2000 2097 2056 2018 2025 2050 1998 2039 1992 2065 2053 2011 2145 2090 2097 2060 2188 2159 2393 2536 2616 2708 2698 2640 2492 2476 2535 2580 2671 2700 2638 2453 2443 2364 2431 2281 2296 2326 2488 2600 2729 2788 2916 3026 3155 3130 3225 3284 3609 3946 4171 4866 5151 5552 5393 5176 4718 4406 3953 3647 3140 2867 2823 2676 2508 2520 2511 2603 2647 2720 2641 2476 2421 2410 2307 2099 2177 2085 2076 2004 2031 1933 2000 2042 2083 1961 2023 1962 1996 2005 1971 1977 2015 2041 2106 2027 1971 1987 2053 1976 2011 1965 1964 2030 1972 1997 2027 1947 2002 2053 2014 2062 2095 2112 2008 2002 2021 2000 2004 2099 1957 1965 2085 2033 2020 1921 2080 2141 2166 2216 2263 2299 2334 2202 2196 2190 2196 2146 2220 2139 2195 2379 2437 2399 2753 2613 2407 2384 2414 2381 2241 2154 2050 2054 2000 2106 1918 2019 2027 2090 2045 2024 2112 2070 2073 2147 2279 2217 2380 2280 2238 2250 2307 2269 2174 2076 2095 2137 2013 2147 2174 2303 2317 2495 2523 2431 2367 2476 2410 2397 2306 2249 2165 2121 2123 2057 2126 2072 2062 2060 2082 2221 2034 2117 2049 2186 2227 2245 2290 2319 2356 2405 2420 2319 2297 2083 2136 2198 2120 2030 1978 2063 1960 1944 2030 1919 2001 2091 2015 2058 2010 2075 2062 2157 2048 2176 2229 2230 2188 2138 2069 2131 2168 2042 2065 2236 2398 2472 2643 2793 2771 2590 2614 2518 2587 2334 2261 2138 2114 2154 2149 2179 2231 2259 2263 2183 2233 2111 2303 2441 2410 2389 2353 2203 2202 2217 2158 2090 2183 2034 2059 2025 2048 2000 2045 1985 2077 1975 2044 2065 2060 2009 1964 2038 2072 2038 2047 2031 2061 2056 2036 2055 1992 2067 2040 2115 2148 2162 2292 2339 2338 2198 2148 2192 2150 2259 2247 2328 2227 2260 2164 2136 2225 2131 2216 2134 2115 2141 2152 2215 2182 2234 2239 2240 2285 2342 2479 2533 2758 2763 3094 3134 3171 3028 2888 2837 2859 2651 2579 2382 2322 2265 2145 2134 2084 2113 2061 2064 2079 2015 1946 1998 2073 2007 2085 1974 2007 2013 2048 2028 1975 2048 2052 2036 2099 2003 2110 1979 2039 2121 2234 2231 2149 2188 2169 2233 2186 2261 2368 2381 2272 2206 2138 2160 2142 2289 2138 2114 2050 2014 2062 2120 2057 2181 2095 2035 2200 2139 2050 2189 2052 2099 2094 2240 2301 2289 2214 2283 2311 2337 2253 2297 2282 2228 2343 2339 2508 2558 2708 2884 2898 2979 3018 2973 2879 2918 2841 2885 2936 2865 2807 2677 2445 2396 2297 2430 2406 2408 2314 2340 2481 2509 2536 2477 2461 2438 2496 2403 2294 2195 2239 2205 2125 2069 2108 2047 2045 2028 1999 2076 2138 2035 2093 1965 2192 2097 2231 2214 2085 2090 2164 2037 2091 2115 2049 2114 2068 2155 2124 2089 2097 2062 2078 2234 2284 2450 2584 2565 2549 2415 2272 2279 2297 2360 2241 2118 2115 2036 2028 2063 2037 2032 2077 2118 2211 2208 2164 2101 2036 2126 2174 2163 2138 2005 2106 2138 2010 2014 2027 1993 1980 2111 2194 2063 2064 2204 2074 2002 2079 2077 2090 2090 2234 2359 2418 2431 2333 2140 2238 2153 2272 2224 2148 2127 2013 2055 2123 2135 2076 2191 2116 2234 2112 2097 2011 2156 2049 2089 2061 2089 2086 2091 2134 2063 2171 2132 2082 2014 2043 2029 2081 1986 2020 1954 1988 1978 1981 2022 2042 2094 2090 2028 2142 2235 2289 2359 2420 2458 2326 2308 2319 2313 2421 2441 2488 2387 2246 2209 2133 2113 2220 2113 2091 2116 1966 2082 2013 2030 2080 2149 2156 2293 2304 2291 2100 2133 2174 2248 2333 2147 2131 2014 2072 2169 2168 2106 2218 2235 2310 2208 2126 2108 2197 2074 2223 2161 2082 2001 2109 2022 2086 2079 2081 2132 2012 2052 2111 1971 2064 2080 2055 2019 1970 2043 2011 1959 2022 2014 2078 2060 2140 2057 2018 2146 2113 2142 2212 2073 2062 2131 1987 2044 2116 2044 2117 2131 2142 2086 2160 2134 2038 1938 2063 2046 2157 2103 1987 2064 2131 2047 1980 2088 2018 2116 2169 2222 2218 2251 2295 2136 2128 2180 2287 2117 2168 2141 2128 2167 2182 2273 2336 2393 2371 2224 2268 2204 2285 2277 2217 2180 2114 2138 2119 2106 2059 2064 2087 2067 2130 2057 2195 2259 2184 2175 2193 2253 2223 2230 2126 2232 2129 2164 2135 2170 2176 2130 2227 2206 2216 2279 2309 2274 2155 2190 2252 2208 2166 2204 2297 2203 2123 2074 2068 2010 2013 2026 2046 2056 2048 2002 2017 2014 2067 2053 2066 2091 2113 2214 2172 2088 2222 2278 2301 2363 2360 2334 2285 2245 2225 2297 2291 2284 2293 2293 2193 2235 2219 2282 2366 2374 2252 2269 2165 2151 2237 2147 2186 2225 2125 2231 2149 2138 2083 2050 2034 2100 2082 2035 2046 2022 1989 1981 2006 1989 2074 1993 1997 1923 2111 2044 2020 2047 1986 1972 2010 1929 1984 2000 1980 2011 2019 1950 1990 1991 1971 2083 2054 2062 2082 2055 2127 2008 2152 1951 2007 2021 1985 2048 2012 2073 1937 1970 1965 1908 1957 1993 1945 2003 1933 1998 2043 2107 2052 1973 1979 1960 2038 2002 2003 1992 1983 2039 2056 2065 2065 1989 2087 2024 2058 2064 2110 2176 2290 2136 2064 2074</counts>
			</dataPoints>
		</scan>
	</xrdMeasurement>
</xrdMeasurements>