File: dataset/precursor_mixture/NiO_0p7028-La(OH)3_0p1010-ZnO_0p2000--8min.xrdml
<?xml version="1.0"?>
<xrdMeasurements xmlns="http://www.xrdml.com/XRDMeasurement/2.3" xmlns:xsi="http://www.w3.org/2001/XMLSchema-instance" xsi:schemaLocation="http://www.xrdml.com/XRDMeasurement/2.3 http://www.xrdml.com/XRDMeasurement/2.3/XRDMeasurement.xsd" status="Completed" recordIdentifier="{D09AE51F-8B6C-4648-A8F2-236189C583AA}">
	<comment>
		<entry/>
	</comment>
	<sample type="To be analyzed">
		<id>NiO_0p7028-La(OH)3_0p1010-ZnO_0p2000--8min</id>
		<name></name>
		<preparedBy></preparedBy>
	</sample>
	<xrdMeasurement measurementType="Scan" status="Completed" sampleMode="Reflection">
		<usedWavelength intended="K-Alpha 1">
			<kAlpha1 unit="Angstrom">1.5405980</kAlpha1>
			<kAlpha2 unit="Angstrom">1.5444260</kAlpha2>
			<kBeta unit="Angstrom">1.3922500</kBeta>
			<ratioKAlpha2KAlpha1>0.5000</ratioKAlpha2KAlpha1>
		</usedWavelength>
		<incidentBeamPath>
			<radius unit="mm">145.00</radius>
			<xRayTube id="1010048" name="Empyrean Cu LFF HR (9430 033 7310x)">
				<tension unit="kV">40.0</tension>
				<current unit="mA">15.0</current>
				<anodeMaterial>Cu</anodeMaterial>
				<focus type="Line">
					<length unit="mm">12.0</length>
					<width unit="mm">0.4</width>
					<takeOffAngle unit="deg">6.0</takeOffAngle>
				</focus>
			</xRayTube>
			<sollerSlit id="21010002" name="Soller slits 0.04 rad.">
				<opening unit="rad">0.0400</opening>
			</sollerSlit>
			<mask id="22031000" name="Fixed mask 13 mm">
				<width unit="mm">9.00</width>
			</mask>
			<divergenceSlit id="22120001" name="Divergence slit 1°" xsi:type="fixedDivergenceSlitType">
				<distanceToSample unit="mm">50.00</distanceToSample>
				<height unit="mm">1.52</height>
			</divergenceSlit>
		</incidentBeamPath>
		<sampleMovement xsi:type="spinningSampleMovementType">
			<spinnerRevolutionTime unit="seconds">1.0</spinnerRevolutionTime>
		</sampleMovement>
		<diffractedBeamPath>
			<radius unit="mm">145.00</radius>
			<antiScatterSlit id="22090040" name="AS slit 9 mm (PIXcel)" xsi:type="fixedAntiScatterSlitType">
				<height unit="mm">9.00</height>
			</antiScatterSlit>
			<sollerSlit id="21020003" name="Large Soller slits 0.04 rad.">
				<opening unit="rad">0.0400</opening>
			</sollerSlit>
			<filter id="20030001" name="Large beta-filter Nickel">
				<material>Ni</material>
				<thickness unit="mm">0.020</thickness>
			</filter>
			<detector id="7010019" name="PIXcel1D-Medipix3 detector" xsi:type="rtmsDetectorType">
				<phd unit="keV">
					<lowerLevel>4.02</lowerLevel>
					<upperLevel>11.27</upperLevel>
				</phd>
				<mode>Scanning</mode>
				<activeLength unit="deg">5.542</activeLength>
			</detector>
		</diffractedBeamPath>
		<scan appendNumber="0" mode="Continuous" scanAxis="Gonio" status="Completed">
			<header>
				<startTimeStamp>2024-11-14T16:39:12-08:00</startTimeStamp>
				<endTimeStamp>2024-11-14T16:47:19-08:00</endTimeStamp>
				<author>
					<name>AutomatedUser</name>
				</author>
				<source>
					<applicationSoftware version="1.7b (136)">PANalytical Aeris Instrument Suite</applicationSoftware>
					<instrumentControlSoftware version="3.2.00000000 20240306">AERIS</instrumentControlSoftware>
					<instrumentID>950485</instrumentID>
				</source>
			</header>
			<dataPoints>
				<positions axis="2Theta" unit="deg">
					<startPosition>10.00943322</startPosition>
					<endPosition>99.99442286</endPosition>
				</positions>
				<positions axis="Omega" unit="deg">
					<startPosition>5.00471661</startPosition>
					<endPosition>49.99721143</endPosition>
				</positions>
				<commonCountingTime unit="seconds">12.495</commonCountingTime>
				<counts unit="counts">3016 3102 3060 3153 3012 2960 3080 3060 3123 3016 2996 2932 3137 3018 2946 2994 3100 2990 2954 3080 2964 3099 2947 3022 2983 3026 3010 3016 2999 3062 3017 3029 3002 2969 2997 3113 3037 3002 2944 3025 2954 3001 2951 2950 2961 2899 2941 2892 2901 2961 2899 2919 2916 2930 2898 2908 2960 3055 2893 3080 2964 2877 2901 2881 2919 2908 3005 2938 2981 3003 2947 2894 2947 2928 2903 2941 2880 2985 2954 2911 2818 2839 2900 2891 2893 3021 2951 3104 2851 2992 2871 2857 2876 2924 2914 2987 2941 2825 2929 2866 2916 2782 2838 2961 2823 2900 2785 2868 2871 2897 2873 2944 3021 2871 2872 2907 2886 2853 2908 2824 2808 2840 2911 2928 2896 2908 2935 2861 2910 2912 2778 2927 2810 2824 2848 2884 2847 2712 2700 2796 2683 2851 2773 2773 2784 2809 2849 2861 2828 2803 2887 2828 2800 2850 2769 2821 2854 2750 2814 2849 2907 2829 2800 2663 2799 2791 2740 2851 2761 2688 2792 2721 2729 2774 2836 2790 2792 2714 2784 2711 2805 2857 2720 2750 2747 2714 2829 2767 2739 2815 2814 2849 2776 2722 2807 2700 2681 2732 2818 2796 2776 2725 2857 2676 2790 2694 2758 2691 2701 2801 2719 2675 2701 2719 2607 2721 2732 2766 2790 2758 2708 2803 2802 2752 2719 2734 2697 2654 2731 2737 2797 2693 2687 2734 2773 2774 2790 2772 2751 2665 2679 2765 2814 2754 2716 2703 2676 2700 2729 2824 2782 2656 2668 2611 2816 2701 2673 2742 2752 2818 2677 2716 2648 2698 2847 2697 2701 2621 2724 2725 2739 2666 2728 2754 2787 2771 2744 2740 2808 2713 2679 2640 2759 2663 2685 2811 2663 2680 2684 2748 2679 2681 2666 2812 2595 2679 2770 2659 2681 2687 2703 2781 2674 2738 2620 2624 2701 2725 2691 2794 2668 2660 2644 2797 2655 2647 2797 2750 2766 2690 2585 2683 2696 2649 2712 2692 2701 2751 2642 2693 2644 2789 2699 2719 2724 2688 2762 2673 2697 2705 2686 2655 2684 2576 2686 2695 2620 2725 2688 2758 2560 2758 2668 2647 2614 2680 2658 2732 2598 2649 2696 2755 2640 2601 2698 2689 2794 2639 2627 2678 2711 2611 2726 2734 2596 2688 2572 2656 2717 2678 2608 2621 2625 2707 2715 2699 2652 2694 2695 2574 2579 2669 2685 2617 2698 2625 2654 2647 2605 2653 2683 2694 2653 2697 2741 2619 2578 2735 2692 2704 2642 2684 2669 2639 2628 2783 2739 2740 2721 2707 2731 2679 2628 2696 2739 2701 2781 2661 2683 2609 2796 2709 2760 2819 2650 2636 2615 2641 2665 2703 2696 2766 2781 2762 2637 2724 2796 2781 2767 2798 2666 2766 2683 2757 2753 2749 2795 2722 2806 2814 2735 2735 2739 2765 2792 2702 2810 2743 2743 2913 2834 2723 2926 2798 2920 2871 2883 2780 2959 2924 2898 2839 2861 2910 2982 2864 3050 2988 3038 3002 3030 2982 3043 3001 2974 3082 3111 3197 3170 3299 3327 3331 3440 3410 3578 3515 3611 3642 3777 3903 3843 4018 3875 4121 4263 4289 4431 4394 4517 4561 4524 4637 4692 4575 4673 4776 4748 4711 4745 4652 4506 4485 4381 4295 4040 3977 3872 3781 3515 3630 3480 3471 3325 3308 3226 3120 3070 3055 3089 3118 3089 3043 2959 2948 2931 2923 2912 2925 2810 2897 2944 2936 2913 2890 2856 2876 2923 2762 2776 2807 2978 2845 2882 2767 2907 2930 2916 2812 2828 2862 2899 2800 2922 2869 2903 2789 2722 2909 2815 2826 2723 2802 2817 2879 2797 2816 2843 2757 2845 2826 2816 2801 2892 2851 2823 2816 2776 2882 2818 2848 2863 2855 2713 2774 2814 2783 2807 2891 2855 2770 2821 2771 2903 2821 2774 2716 2720 2946 2692 2808 2794 2864 2831 2774 2785 2826 2887 2886 2825 2958 2915 2776 2802 2855 2846 2856 2754 2954 2842 2820 2901 2849 2814 2843 2813 2898 2829 2784 2836 2823 2781 2859 2777 2811 2805 2802 2911 2901 2886 2903 2806 2810 2832 2772 2851 2759 2840 2766 2856 2820 2847 2791 2748 2788 2829 2815 2853 2730 2871 2807 2889 2827 2820 2840 2808 2701 2716 2852 2855 2847 2854 2766 2872 2813 2820 2731 2836 2877 2888 2872 2785 2847 2892 2895 2785 2848 2852 2784 2835 2826 2909 2790 2810 2879 2756 2886 2803 2743 2877 2827 2761 2897 2764 2775 2781 2861 2762 2781 2852 2897 2834 2822 2806 2692 2872 2858 2895 2938 2718 2876 2810 2849 2804 2852 2863 2816 2861 2867 2804 2772 2972 2842 2862 2872 2872 2888 2965 2883 2867 2866 2844 2880 2869 2929 2892 2824 2756 2893 2918 2822 2853 2872 2867 2827 2920 2919 2869 2940 2741 2866 2884 2887 2772 2917 2933 2840 2844 2977 2919 2973 2814 2830 2963 2953 2838 2922 2879 2877 2951 2851 2918 2919 2846 2924 2797 2943 2833 2857 2970 2945 2894 2794 2922 2921 2900 2929 2858 2918 2953 2798 2982 2890 2973 2834 2826 2943 2959 2840 2826 2844 2897 2905 2841 2898 2837 2842 2839 2829 2776 2822 2841 2955 2861 2856 2839 2901 2857 2999 2911 2762 2891 2861 2906 2826 2960 2988 2894 2890 2919 2822 2887 2925 2928 2832 2841 2870 2901 2824 2896 2963 2921 2999 2936 2890 2924 3008 2909 2838 2875 2913 2875 2933 2933 2916 2862 2884 2889 2903 2922 2971 2940 2964 2930 2938 2821 2921 2849 2857 2992 2857 2889 2928 2935 2978 2925 2905 2857 2870 2967 3035 2894 3026 2886 2965 2940 2867 2848 2885 2903 2921 2951 2911 2949 2922 2939 2909 2893 2852 2964 2909 2931 2919 2930 2950 2862 2982 2924 3004 2885 2916 2995 2993 2886 2873 2889 2858 2901 2958 2890 2933 2959 2864 2931 2964 2910 2840 2963 2984 2949 2934 2949 2989 2840 3022 3036 3031 2936 2917 2886 2908 3018 2908 2945 2858 3083 2983 2926 2953 2945 2983 2894 3023 2917 2933 2956 2901 2811 2936 3013 2964 2988 3017 2953 2877 3030 2966 2946 2915 2947 3056 2964 2993 2985 2923 3036 3058 3007 2956 3079 2999 2871 2919 2926 2988 3037 2962 2961 2984 2940 2943 2881 2879 2926 3028 3039 2924 3045 2889 3009 3064 2950 2954 2973 2974 2992 3027 3077 2960 3012 2977 2996 2890 3039 2888 3008 3010 3044 3019 2979 3052 3052 3011 3030 2974 3071 2959 2953 2892 2914 2973 3019 3121 3028 2978 2990 2957 2979 3049 2980 3166 2975 3066 2874 2870 2935 2909 3024 3057 2952 2958 3026 2959 2988 2935 2995 3074 3035 2967 3008 3020 2992 3035 3101 3028 3048 2933 3035 2930 2944 2981 2962 2954 3062 2990 3011 3018 3035 2996 2976 2962 3029 3011 2954 3023 2971 2944 3138 3048 3057 2964 3090 3165 3008 3072 3022 3085 3039 2954 3121 3036 2990 3121 3024 3037 3166 2842 3105 2959 3020 2991 2954 2987 3126 3002 3049 3012 3044 3036 3055 2918 3041 3088 3095 3076 2978 2990 2961 3089 2999 3101 2923 2953 3164 3032 3063 2989 3058 2969 3081 3020 3029 2970 2966 3043 3041 3069 3057 2938 2990 3009 3086 3072 3065 3124 2929 3046 3026 3053 3052 3070 3119 3157 3078 3040 3033 2974 3003 3068 3060 3120 3088 2989 3007 3059 3122 3137 2986 3010 3061 2984 3114 3065 3095 3183 3018 3067 3092 3100 3048 3106 2991 3078 3097 3033 3141 3032 2978 3166 3109 3043 3104 3122 2983 3170 3121 3097 3160 2996 3058 2959 3066 3084 3047 3078 3057 3020 3128 3021 3032 3124 3149 3012 3067 3026 3162 3143 3054 3075 3181 3070 3088 3140 3076 3117 3063 3024 3145 3050 3120 3084 3002 3175 3064 3111 3016 3095 3022 2999 3054 3085 3091 3108 3078 3180 3068 3087 3074 3241 3231 3162 3095 3085 3144 3176 3143 3137 3092 3197 3117 3156 3097 3097 3124 3053 3069 3131 3069 3109 3014 3170 3158 3063 3153 3165 3084 3011 3103 3063 3101 3039 3095 2938 3118 3247 3190 3098 3094 3222 3155 3099 3156 3200 3121 3088 3051 3147 3014 3055 3063 3205 3118 3141 3183 3156 3203 3082 3272 3108 3131 3191 3106 3192 3198 3058 3102 3068 3214 3059 3071 3142 3046 3180 3105 3227 3127 3257 3203 3148 3077 3091 3045 3074 3137 3133 3084 3209 3030 3101 3064 3191 3081 3097 3095 3156 3158 3148 3150 3094 3154 3163 3259 3135 3163 3190 3184 3179 3132 3185 3090 3097 3098 3125 3123 3144 3160 3200 3306 3132 3020 3079 3060 3159 3202 3261 3122 3157 3133 3173 3169 3128 3224 3136 3143 3158 3162 3177 3096 3128 3070 3190 3157 3122 3206 3097 3266 3195 3214 3144 3088 3073 3166 3184 3165 3195 3101 3224 3181 3133 3124 3119 3205 3233 3137 3267 3129 3261 3186 3228 3140 3141 3265 3102 3230 3121 3206 3230 3170 3258 3179 3177 3219 3178 3219 3233 3233 3203 3117 3201 3259 3195 3228 3174 3199 3200 3222 3271 3299 3201 3313 3166 3231 3154 3275 3160 3125 3339 3167 3235 3265 3100 3188 3257 3232 3245 3255 3265 3195 3202 3173 3274 3213 3173 3362 3242 3285 3238 3226 3271 3223 3230 3177 3319 3202 3137 3311 3301 3193 3335 3325 3265 3357 3328 3347 3314 3343 3291 3323 3291 3370 3423 3484 3372 3302 3347 3321 3372 3411 3530 3461 3420 3639 3584 3588 3493 3547 3618 3656 3647 3682 3806 3677 3881 3923 3930 3970 4010 4019 4153 4288 4299 4407 4566 4661 4664 4822 4850 5033 4979 5178 5100 5404 5346 5360 5502 5514 5444 5462 5420 5475 5464 5260 5204 5176 5114 5023 4897 4759 4702 4603 4512 4268 4254 4300 4041 4141 4048 4043 4009 3858 3792 3826 3894 3840 3775 3873 3821 3848 3777 3936 3889 3848 3963 4029 4063 4035 4197 4246 4166 4299 4459 4521 4527 4694 4725 4801 4969 5125 5232 5402 5409 5701 5805 5968 6073 6095 6296 6334 6209 6505 6471 6404 6499 6264 6264 6301 6145 6084 5776 5707 5603 5218 5125 5036 4971 4909 4702 4521 4428 4155 4370 3943 4111 3908 3810 3871 3924 3772 3708 3702 3611 3700 3499 3624 3503 3596 3639 3388 3453 3520 3531 3431 3426 3459 3486 3443 3264 3422 3354 3377 3270 3377 3429 3388 3412 3361 3430 3397 3278 3339 3236 3445 3358 3344 3270 3319 3357 3358 3282 3310 3329 3394 3222 3376 3314 3378 3403 3330 3273 3332 3441 3300 3307 3262 3342 3378 3238 3327 3339 3276 3246 3318 3320 3364 3275 3334 3416 3467 3328 3336 3325 3287 3284 3294 3383 3328 3356 3244 3400 3340 3323 3275 3347 3333 3390 3421 3301 3386 3305 3247 3205 3322 3213 3273 3304 3237 3431 3239 3416 3319 3265 3224 3339 3312 3341 3318 3192 3334 3208 3476 3321 3348 3287 3392 3230 3314 3346 3392 3271 3285 3262 3241 3294 3322 3398 3236 3124 3373 3224 3304 3352 3237 3387 3370 3262 3415 3294 3225 3414 3314 3284 3392 3403 3405 3282 3212 3336 3271 3305 3240 3305 3269 3342 3341 3282 3288 3322 3317 3323 3333 3258 3385 3296 3229 3370 3178 3334 3267 3303 3352 3182 3293 3392 3282 3332 3293 3304 3356 3294 3393 3321 3340 3290 3377 3407 3397 3347 3287 3289 3333 3342 3315 3470 3306 3347 3385 3322 3329 3289 3368 3377 3362 3359 3400 3290 3424 3398 3282 3399 3356 3303 3339 3358 3283 3357 3497 3262 3349 3270 3268 3354 3374 3399 3396 3310 3333 3391 3393 3343 3418 3287 3272 3436 3348 3377 3338 3457 3364 3454 3508 3509 3346 3392 3303 3318 3328 3387 3426 3407 3479 3422 3433 3450 3475 3312 3376 3367 3457 3407 3369 3426 3446 3400 3425 3451 3488 3485 3506 3453 3489 3476 3506 3486 3583 3546 3606 3571 3603 3664 3683 3758 3628 3771 3710 3726 3717 3769 3885 3723 3854 4050 4045 4177 4013 4246 4321 4329 4390 4411 4489 4516 4829 4885 5010 5141 5257 5526 5696 5887 6114 6283 6636 6863 6991 7174 7595 7879 8039 8091 8441 8427 8504 8439 8252 8107 7912 7728 7585 7109 6534 6498 5843 5794 5371 5178 4914 4692 4417 4383 4125 4071 3890 3922 3810 3805 3772 3829 3666 3654 3632 3695 3518 3598 3609 3607 3628 3488 3441 3503 3526 3556 3428 3418 3525 3313 3473 3484 3480 3496 3390 3429 3497 3397 3387 3446 3412 3485 3520 3408 3343 3386 3391 3277 3289 3376 3457 3459 3393 3415 3439 3430 3394 3406 3386 3401 3392 3467 3429 3503 3540 3380 3299 3370 3443 3383 3441 3461 3352 3378 3361 3500 3470 3468 3548 3342 3425 3400 3402 3381 3396 3436 3462 3392 3359 3476 3403 3366 3440 3366 3376 3420 3401 3384 3451 3370 3414 3378 3442 3379 3453 3254 3412 3350 3481 3415 3502 3460 3473 3407 3467 3400 3417 3406 3422 3385 3313 3400 3477 3450 3342 3369 3492 3333 3385 3424 3387 3376 3445 3389 3410 3484 3357 3383 3319 3425 3419 3435 3343 3426 3317 3388 3394 3368 3401 3500 3372 3345 3442 3449 3389 3439 3428 3432 3329 3312 3480 3503 3515 3409 3433 3428 3422 3499 3625 3443 3393 3504 3414 3400 3466 3390 3424 3574 3500 3523 3402 3443 3553 3453 3445 3479 3446 3525 3532 3367 3528 3469 3617 3540 3438 3531 3552 3469 3678 3478 3493 3677 3603 3665 3726 3645 3611 3692 3828 3841 3792 4030 4202 4148 4197 4380 4661 4727 4854 5044 5414 5483 5850 6048 6203 6435 6681 6836 7092 7203 7278 7335 7052 7186 6976 6885 6596 6271 5789 5513 5404 5093 4982 4816 4629 4413 4269 4051 3996 3906 3812 3706 3753 3719 3660 3549 3636 3625 3630 3599 3564 3665 3569 3598 3522 3634 3511 3654 3545 3524 3448 3425 3452 3435 3457 3460 3478 3501 3340 3501 3448 3484 3439 3424 3466 3497 3518 3415 3517 3436 3463 3439 3644 3458 3518 3509 3591 3542 3486 3582 3555 3554 3435 3452 3514 3558 3482 3446 3451 3561 3447 3536 3511 3493 3589 3615 3556 3483 3540 3508 3519 3571 3577 3531 3509 3498 3557 3499 3562 3547 3585 3497 3582 3529 3629 3521 3631 3518 3552 3526 3583 3677 3553 3496 3601 3599 3626 3628 3606 3794 3667 3720 3608 3825 3797 3719 3813 3844 3849 3825 3975 3980 3956 3900 3918 3999 4021 4120 4064 4342 4221 4231 4273 4344 4490 4708 4707 4932 5021 5186 5338 5498 5839 6123 6227 6682 7168 7682 8083 8309 9056 9514 9952 10407 10900 11223 11442 11656 12250 12226 12445 12338 11819 11679 11212 10482 9989 9346 8836 8284 7851 7492 6996 6687 6178 5794 5538 5128 4870 4695 4553 4614 4295 4384 4335 4183 4259 4123 4131 4097 4128 4020 4022 4105 4088 4166 4033 3997 4008 4122 4100 4082 4039 3999 4135 4006 3980 4110 4195 4333 4108 4215 4284 4369 4335 4473 4538 4438 4650 4539 4907 4865 5046 5136 5183 5425 5680 5963 6160 6410 6737 7163 7701 8169 8658 9239 9810 10601 11341 11943 12896 13499 14439 15125 15931 16673 17431 18218 18574 19086 19242 19295 19176 18915 18690 17804 17161 16506 15907 14901 14295 13532 12841 12257 11101 10475 9558 9094 8402 7998 7425 7002 6586 6339 6146 5737 5566 5285 5201 5177 4892 4857 4874 4645 4628 4449 4381 4367 4290 4254 4270 4186 4109 3943 4126 4009 4025 3927 3831 3766 3877 3846 3855 3807 3783 3895 3762 3791 3683 3836 3692 3700 3796 3668 3639 3628 3670 3628 3697 3667 3646 3642 3544 3592 3609 3612 3553 3531 3612 3589 3572 3585 3584 3588 3654 3592 3613 3523 3581 3619 3559 3608 3677 3556 3708 3635 3669 3530 3548 3548 3604 3509 3668 3613 3544 3545 3619 3595 3652 3608 3588 3559 3517 3596 3624 3577 3522 3683 3592 3603 3616 3618 3618 3419 3626 3535 3614 3609 3550 3606 3595 3673 3602 3548 3499 3591 3632 3486 3619 3657 3673 3670 3594 3621 3768 3540 3652 3613 3638 3793 3597 3704 3746 3686 3717 3611 3589 3564 3681 3722 3701 3821 3692 3703 3706 3719 3747 3838 3746 3767 3896 3902 3997 3892 3995 4027 3902 4044 4091 4111 4042 4185 4213 4408 4361 4333 4430 4509 4596 4783 4928 4968 4966 5094 5196 5306 5335 5414 5540 5570 5817 5642 5698 5939 5774 5858 5825 5794 5848 5783 5732 5687 5441 5368 5290 5147 5146 5024 4937 4798 4841 4611 4556 4513 4452 4357 4361 4408 4296 4074 4021 3906 4010 3993 3916 3940 3865 3944 3840 3798 3881 3828 3905 3611 3718 3678 3755 3704 3628 3745 3667 3700 3576 3712 3678 3654 3690 3591 3693 3653 3721 3629 3645 3720 3577 3561 3667 3597 3624 3516 3526 3563 3667 3682 3479 3559 3643 3507 3552 3611 3539 3537 3621 3536 3473 3611 3562 3592 3529 3570 3601 3669 3648 3522 3598 3503 3456 3501 3463 3748 3527 3574 3514 3551 3527 3600 3559 3451 3596 3569 3641 3538 3492 3533 3618 3628 3574 3616 3484 3585 3542 3617 3520 3583 3507 3451 3668 3599 3553 3521 3506 3588 3533 3479 3475 3558 3519 3549 3540 3531 3552 3596 3621 3521 3552 3564 3530 3526 3565 3480 3636 3525 3468 3420 3447 3557 3448 3485 3472 3476 3574 3541 3631 3568 3517 3434 3485 3487 3487 3511 3489 3541 3489 3419 3468 3410 3486 3558 3473 3437 3483 3498 3443 3466 3539 3503 3598 3499 3555 3602 3587 3499 3474 3497 3547 3599 3492 3608 3520 3565 3533 3570 3596 3562 3520 3533 3586 3482 3552 3550 3505 3577 3626 3668 3533 3575 3626 3670 3622 3616 3508 3579 3680 3638 3667 3690 3675 3746 3559 3711 3700 3805 3603 3728 3807 3666 3713 3743 3752 3836 3848 3837 3879 3919 3919 3981 3932 3885 3933 4101 4042 4005 3910 4026 4021 3948 4141 4151 4089 4022 4050 4046 4063 4051 4102 4102 4058 4041 4134 3998 3978 4003 4062 3948 3919 3936 3856 3859 3886 3866 3892 3842 3806 3711 3913 3870 3772 3849 3845 3950 3775 3931 3896 3951 3956 3866 3955 3828 3968 3997 4052 3967 3955 4036 4299 4120 4143 4205 4197 4200 4239 4331 4288 4363 4686 4478 4649 4493 4633 4850 4818 4920 5030 5089 5200 5206 5274 5448 5683 5924 6047 6441 6737 6961 7397 7694 8145 8827 9615 10114 11079 11859 13274 14120 15349 17007 18404 20169 21777 23509 24982 26552 28308 29455 30725 31161 32212 32510 32427 31509 30804 29597 27885 26628 24715 23499 21798 20904 19716 18617 17190 15916 14318 13379 11829 10716 9632 9059 8402 7706 7473 7031 6692 6486 6187 5839 5751 5567 5302 5203 5274 5080 4931 4764 4775 4719 4717 4493 4410 4443 4408 4335 4294 4202 4258 4062 4190 4073 4008 4064 4055 3859 3987 4026 3961 3984 3898 3910 3915 3824 3769 3717 3671 3730 3807 3635 3774 3775 3797 3747 3742 3604 3868 3706 3791 3887 3738 3753 3638 3657 3580 3819 3544 3793 3710 3671 3764 3534 3647 3677 3629 3807 3621 3683 3626 3551 3602 3671 3656 3772 3657 3704 3655 3624 3573 3550 3621 3651 3646 3679 3619 3606 3577 3552 3590 3601 3653 3650 3592 3560 3556 3510 3652 3568 3548 3563 3514 3606 3687 3621 3579 3592 3558 3560 3534 3647 3579 3649 3519 3573 3466 3603 3605 3649 3652 3582 3447 3504 3648 3718 3509 3492 3578 3673 3543 3539 3575 3643 3490 3574 3542 3510 3651 3492 3567 3576 3580 3554 3606 3686 3661 3557 3612 3620 3666 3565 3530 3611 3660 3579 3535 3538 3509 3605 3508 3551 3569 3651 3511 3636 3631 3522 3523 3532 3443 3507 3650 3600 3562 3522 3430 3576 3492 3590 3560 3443 3648 3526 3518 3593 3604 3554 3622 3525 3618 3512 3538 3620 3486 3589 3648 3481 3581 3589 3620 3574 3571 3517 3467 3465 3556 3606 3576 3514 3661 3674 3520 3507 3533 3501 3559 3587 3463 3535 3527 3533 3565 3531 3635 3435 3577 3488 3653 3507 3541 3600 3623 3587 3589 3385 3575 3572 3576 3542 3639 3578 3638 3667 3506 3496 3579 3621 3592 3623 3498 3441 3524 3573 3578 3554 3552 3736 3562 3565 3546 3632 3561 3574 3502 3615 3546 3490 3552 3551 3585 3585 3608 3592 3578 3642 3534 3604 3695 3584 3625 3577 3668 3566 3663 3570 3610 3545 3607 3544 3582 3702 3594 3671 3577 3565 3728 3692 3729 3638 3730 3622 3770 3653 3707 3823 3920 3789 3767 3800 3921 3844 3985 3765 3999 3967 3985 3975 3950 3996 4101 3984 3931 4092 4096 4133 4000 3978 4041 3996 4070 3997 4074 4016 4000 3976 3969 4056 4080 3928 3973 3885 4036 3967 4049 4038 4263 4128 4145 4116 4275 4311 4499 4537 4672 4902 4876 5020 5056 5197 5262 5383 5544 5566 5605 5648 5537 5481 5302 5212 5195 5061 5066 4906 4878 4871 4825 4603 4633 4508 4605 4292 4312 4184 4104 4113 4032 3891 3840 3915 3823 3999 3928 3966 3956 3812 3874 3945 3914 3999 3964 4019 4026 3996 4013 4010 4026 4084 4142 4205 4110 4088 4377 4227 4281 4137 4317 4407 4284 4511 4380 4487 4454 4549 4471 4522 4562 4568 4504 4606 4544 4579 4575 4606 4631 4692 4583 4632 4647 4575 4674 4689 4597 4761 4661 4644 4712 4826 4842 4802 4830 4853 5070 4856 5056 4926 5205 5420 5291 5406 5378 5453 5406 5550 5452 5336 5372 5441 5419 5356 5240 5325 5160 4952 5014 5140 5092 4918 4778 4748 4685 4726 4611 4592 4531 4477 4258 4388 4242 4189 4250 4131 4279 4127 4073 3980 3897 4042 3989 3920 3887 3886 3761 3765 3893 3804 3738 3838 3566 3794 3706 3663 3649 3747 3724 3780 3615 3745 3482 3717 3634 3607 3625 3784 3700 3599 3668 3616 3683 3566 3705 3503 3583 3688 3655 3558 3593 3616 3670 3676 3636 3565 3685 3586 3656 3500 3577 3613 3580 3547 3660 3578 3615 3668 3528 3538 3674 3624 3587 3566 3480 3626 3680 3562 3588 3651 3672 3709 3655 3674 3719 3799 3732 3732 3813 3677 3830 3738 3767 3812 3826 3813 3888 3820 3788 3806 3819 3771 3738 3752 3815 3773 3739 3680 3741 3661 3636 3611 3759 3677 3706 3732 3572 3709 3660 3567 3596 3590 3673 3605 3788 3591 3735 3629 3520 3614 3615 3583 3567 3631 3623 3521 3540 3556 3555 3548 3565 3553 3561 3502 3546 3526 3593 3607 3592 3473 3479 3590 3560 3549 3599 3476 3632 3407 3491 3550 3581 3578 3475 3473 3552 3643 3526 3544 3432 3529 3551 3563 3559 3564 3530 3571 3595 3623 3520 3513 3503 3452 3459 3434 3433 3561 3542 3542 3545 3486 3465 3444 3501 3480 3558 3461 3599 3526 3502 3596 3626 3478 3522 3447 3404 3472 3588 3522 3470 3647 3631 3589 3507 3449 3513 3578 3565 3492 3545 3453 3542 3472 3594 3453 3586 3615 3560 3585 3547 3532 3476 3510 3614 3507 3551 3502 3513 3538 3564 3556 3426 3418 3429 3553 3504 3475 3637 3681 3558 3436 3521 3459 3514 3497 3513 3464 3545 3562 3571 3596 3495 3588 3554 3487 3560 3548 3554 3523 3509 3575 3466 3500 3477 3585 3590 3481 3557 3507 3471 3443 3540 3504 3479 3431 3479 3437 3432 3466 3545 3548 3519 3552 3484 3543 3475 3630 3612 3547 3527 3469 3571 3489 3521 3472 3492 3511 3573 3516 3492 3514 3463 3496 3564 3494 3449 3413 3442 3574 3442 3575 3496 3433 3453 3502 3504 3521 3585 3450 3573 3518 3492 3565 3517 3652 3419 3513 3502 3520 3530 3478 3390 3490 3435 3365 3522 3561 3451 3580 3511 3498 3458 3556 3476 3560 3464 3341 3455 3441 3487 3575 3470 3403 3534 3588 3541 3512 3459 3504 3572 3523 3481 3454 3515 3523 3395 3544 3529 3525 3415 3471 3512 3434 3537 3477 3469 3486 3419 3504 3425 3511 3555 3448 3600 3431 3417 3579 3548 3519 3402 3534 3480 3551 3510 3519 3538 3493 3453 3496 3638 3510 3580 3470 3543 3469 3488 3331 3544 3450 3456 3454 3546 3520 3529 3537 3469 3409 3494 3524 3479 3528 3547 3587 3484 3564 3544 3566 3540 3522 3553 3528 3584 3484 3606 3470 3425 3497 3429 3502 3516 3537 3421 3502 3484 3542 3529 3490 3568 3477 3537 3431 3569 3546 3494 3417 3430 3525 3509 3646 3528 3438 3414 3544 3452 3556 3516 3496 3564 3523 3534 3404 3483 3511 3506 3448 3490 3525 3533 3522 3506 3383 3470 3585 3457 3499 3571 3523 3601 3440 3514 3496 3476 3525 3518 3521 3563 3509 3605 3422 3444 3444 3600 3489 3628 3600 3587 3547 3577 3631 3572 3514 3574 3524 3416 3532 3532 3562 3478 3581 3594 3590 3456 3500 3579 3462 3569 3434 3518 3524 3613 3596 3618 3470 3601 3558 3443 3618 3478 3532 3601 3646 3594 3647 3608 3542 3513 3557 3732 3601 3589 3778 3589 3649 3617 3657 3585 3761 3718 3845 3800 3752 3799 3734 3748 3817 3794 4034 3809 3956 3987 3963 3888 3925 3997 4030 3926 3917 4066 3976 4048 3944 4020 4165 4148 4071 4145 3989 4030 4006 3858 4037 4001 3931 3840 3867 3878 3944 3848 3837 3822 3831 3732 3760 3786 3853 3806 3694 3683 3618 3706 3751 3714 3658 3676 3653 3674 3629 3558 3734 3615 3678 3677 3703 3599 3586 3608 3692 3647 3503 3619 3712 3598 3650 3567 3673 3621 3643 3578 3685 3650 3581 3706 3527 3565 3686 3654 3712 3592 3678 3664 3562 3823 3701 3655 3676 3745 3840 3778 3777 3800 3873 3930 3757 3972 3862 3867 3951 3958 3910 3967 3990 3971 4020 3919 4005 3991 4023 3987 4107 4081 4050 4220 4215 4109 4257 4310 4363 4485 4516 4615 4730 4859 5136 5308 5523 5639 5922 5899 6164 6400 6442 6515 6651 6726 6677 6605 6360 6132 5956 5796 5760 5610 5542 5431 5436 5307 5208 5302 5105 4878 4865 4665 4563 4395 4304 4210 4161 4061 4029 3915 3913 3828 3709 3732 3776 3659 3748 3828 3738 3741 3657 3638 3667 3645 3646 3646 3653 3538 3624 3632 3657 3431 3649 3740 3606 3629 3478 3650 3607 3653 3624 3669 3489 3508 3627 3641 3585 3570 3523 3579 3574 3601 3668 3491 3591 3547 3662 3559 3547 3565 3592 3629 3652 3626 3601 3561 3577 3535 3581 3666 3539 3450 3487 3656 3668 3555 3593 3673 3640 3673 3587 3598 3682 3610 3660 3738 3604 3557 3668 3680 3756 3628 3553 3696 3775 3675 3623 3616 3606 3624 3787 3607 3627 3775 3649 3601 3579 3574 3691 3597 3680 3712 3639 3553 3558 3647 3666 3558 3623 3460 3601 3540 3638 3555 3569 3554 3542 3594 3533 3433 3717 3432 3595 3602 3514 3634 3564 3559 3550 3404 3554 3558 3475 3588 3697 3520 3540 3466 3582 3559 3524 3479 3577 3551 3618 3628 3709 3581 3593 3611 3591 3542 3622 3730 3666 3672 3698 3601 3604 3670 3572 3641 3519 3708 3620 3609 3537 3588 3651 3729 3653 3724 3701 3593 3851 3592 3743 3674 3681 3818 3532 3617 3689 3632 3646 3608 3675 3644 3595 3668 3569 3617 3638 3582 3546 3596 3601 3539 3666 3455 3627 3558 3481 3509 3536 3552 3619 3495 3624 3449 3691 3614 3518 3663 3615 3570 3475 3524 3508 3510 3575 3446 3541 3550 3536 3569 3457 3642 3615 3531 3572 3605 3627 3570 3550 3523 3572 3562 3489 3634 3525 3531 3607 3479 3549 3523 3473 3547 3554 3543 3505 3550 3442 3554 3520 3527 3569 3412 3512 3432 3607 3638 3568 3446 3392 3588 3448 3541 3531 3563 3499 3718 3329 3478 3634 3583 3471 3559 3590 3551 3516 3501 3497 3542 3456 3591 3478 3482 3511 3529 3456 3452 3510 3538 3500 3531 3467 3404 3501 3517 3522 3463 3587 3604 3554 3438 3564 3551 3363 3560 3573 3456 3558 3522 3519 3471 3506 3542 3479 3578 3543 3594 3517 3579 3660 3511 3501 3588 3599 3638 3555 3553 3569 3482 3519 3598 3549 3626 3589 3641 3591 3615 3532 3651 3462 3558 3699 3520 3670 3565 3597 3600 3527 3597 3649 3524 3645 3583 3552 3503 3450 3466 3518 3509 3644 3431 3576 3592 3621 3541 3621 3542 3613 3548 3512 3630 3545 3552 3644 3607 3602 3581 3616 3689 3490 3546 3574 3508 3596 3581 3549 3643 3712 3592 3629 3546 3534 3554 3581 3577 3549 3598 3634 3606 3571 3772 3594 3582 3658 3636 3555 3525 3517 3696 3580 3586 3669 3690 3599 3741 3713 3660 3560 3597 3601 3667 3623 3713 3644 3622 3591 3518 3639 3598 3675 3638 3698 3562 3646 3612 3724 3644 3659 3595 3605 3481 3601 3649 3527 3630 3732 3631 3715 3703 3592 3645 3607 3719 3726 3662 3736 3625 3703 3598 3773 3795 3653 3609 3738 3736 3774 3677 3680 3742 3741 3793 3832 3697 3770 3810 3825 3710 3887 3920 3891 3819 3811 3897 3914 3955 4010 3884 3924 4038 4011 4080 3991 4132 4030 4116 4086 4243 4124 4296 4333 4387 4334 4447 4479 4510 4485 4476 4567 4782 4884 4665 4986 4824 5070 5227 5297 5599 5577 5608 5729 5974 6087 6290 6503 6640 7007 7392 7612 8101 8507 8889 9355 9953 10793 11021 11736 12606 12877 13681 14355 14683 15312 15668 15784 15829 15809 15753 15518 15328 15126 14656 14324 14015 13438 13526 13215 12833 12661 12421 12220 11831 11557 11053 10754 10428 9983 9418 8781 8454 8136 7851 7476 7122 6969 6568 6394 6208 6072 5788 5508 5406 5409 5099 5032 4996 4977 4846 4712 4530 4559 4557 4668 4484 4395 4538 4362 4368 4293 4162 4278 4254 4282 4143 4169 4152 4078 3949 4179 4123 4126 3860 4005 3972 4006 3967 3946 4037 3899 3943 3924 4013 3887 3942 3934 3922 3875 4019 4024 3952 4081 4009 4070 4072 4033 3974 4032 4018 4027 3993 4132 4111 4075 4032 4088 4079 4080 4060 3971 4107 4000 4177 4098 4079 4077 4000 3959 4011 3964 4046 4023 4006 3981 3942 4084 3915 3957 3927 3915 3904 3915 3918 3704 3890 3959 3857 3868 3800 3888 3794 3863 3686 3710 3636 3704 3730 3717 3626 3665 3755 3747 3693 3719 3699 3646 3624 3684 3655 3731 3617 3630 3635 3560 3668 3655 3636 3706 3673 3703 3618 3643 3608 3749 3658 3674 3706 3628 3732 3648 3669 3593 3606 3623 3708 3634 3720 3787 3650 3703 3708 3741 3702 3571 3695 3770 3803 3643 3699 3681 3651 3767 3675 3730 3798 3699 3840 3734 3798 3729 3732 3818 3730 3654 3660 3716 3732 3685 3662 3667 3686 3653 3781 3860 3752 3655 3707 3738 3760 3516 3692 3636 3569 3693 3603 3624 3730 3631 3537 3543 3624 3660 3584 3572 3579 3716 3619 3584 3619 3639 3510 3629 3630 3528 3597 3623 3545 3615 3721 3663 3688 3657 3688 3647 3587 3665 3541 3700 3640 3595 3692 3640 3542 3559 3556 3538 3484 3538 3689 3699 3626 3597 3648 3711 3748 3623 3799 3688 3600 3459 3568 3699 3509 3553 3561 3629 3580 3672 3727 3623 3699 3608 3575 3708 3647 3583 3703 3623 3683 3631 3658 3767 3690 3630 3702 3708 3628 3868 3593 3890 3718 3831 3911 3902 3979 4029 4031 3898 3944 4036 3904 3976 3821 3952 3781 3923 3862 3751 3762 3780 3824 3785 3773 3756 3784 3812 3707 3906 3738 3712 3691 3673 3665 3767 3679 3602 3622 3563 3622 3575 3616 3624 3621 3580 3641 3499 3522 3574 3626 3526 3484 3628 3654 3637 3614 3595 3594 3739 3557 3579 3582 3604 3574 3650 3544 3589 3551 3574 3550 3556 3500 3643 3547 3504 3569 3589 3498 3577 3552 3529 3627 3524 3595 3573 3616 3551 3600 3585 3624 3580 3644 3509 3549 3654 3629 3598 3707 3599 3649 3475 3600 3543 3557 3584 3677 3647 3532 3479 3585 3632 3737 3665 3730 3647 3717 3581 3616 3553 3753 3572 3671 3681 3742 3595 3888 3783 3750 3772 3767 3792 3657 3638 3865 3938 3829 3908 3959 3868 3995 4147 4235 4236 4447 4348 4540 4624 5013 5044 5175 5382 5536 5624 5670 5735 5657 5731 5646 5493 5431 5145 5115 4971 4737 4777 4823 4624 4761 4849 4761 4709 4857 4692 4818 4589 4546 4593 4433 4479 4230 4081 4077 3917 3898 3894 3923 3807 3750 3856 3784 3819 3661 3684 3673 3599 3672 3609 3815 3614 3715 3588 3627 3542 3632 3636 3622 3660 3686 3722 3670 3606 3546 3728 3520 3547 3519 3635 3617 3533 3604 3657 3640 3692 3657 3731 3654 3772 3680 3613 3596 3601 3609 3730 3687 3789 3677 3750 3682 3766 3695 3695 3738 3722 3709 3821 3892 3984 4108 4004 4025 4062 4130 4291 4269 4303 4532 4551 4539 4589 4677 4623 4603 4748 4515 4417 4366 4275 4230 4244 4139 4088 4155 4068 4214 4200 4340 4267 4161 4168 4241 4093 4146 4165 3951 3951 3997 3903 3963 3962 3878 3903 3740 3839 3798 3868 3800 3817 3737 3815 3850 3808 3801 3890 3873 3801 3910 3895 3889 3902 3896 3892 3892 3838 3831 3825 3839 3927 3967 3854 3932 3889 3947 3919 3840 3835 3798 3950 3850 3785 3765 3796 3858 3721 3891 3732 3785 3728 3786 3894 3774 3691 3756 3744 3766 3722 3574 3690 3665 3668 3707 3732 3735 3554 3637 3640 3689 3669 3655 3707 3614 3621 3685 3725 3536 3674 3569 3544 3578 3606 3600 3553 3525 3507 3531 3659 3662 3510 3578 3557 3494 3520 3628 3648 3421 3569 3699 3491 3553 3629 3652 3560 3693 3522 3643 3441 3577 3702 3627 3585 3653 3547 3607 3537 3622 3627 3645 3539 3623 3534 3664 3580 3521 3674 3620 3678 3609 3658 3644 3640 3659 3679 3664 3599 3726 3636 3721 3648 3626 3644 3615 3712 3739 3732 3701 3714 3556 3609 3656 3725 3699 3587 3665 3630 3568 3667 3591 3612 3721 3584 3673 3630 3691 3698 3655 3510 3672 3532 3678 3552 3532 3653 3577 3653 3511 3653 3543 3472 3593 3651 3572 3485 3539 3520 3616 3564 3495 3543 3504 3570 3549 3622 3583 3544 3456 3496 3584 3498 3470 3581 3473 3598 3582 3615 3521 3554 3631 3461 3574 3565 3643 3655 3557 3481 3544 3560 3609 3674 3551 3543 3591 3608 3523 3596 3574 3432 3442 3479 3620 3519 3533 3518 3505 3559 3600 3595 3622 3509 3562 3510 3556 3570 3614 3565 3565 3689 3661 3470 3637 3633 3613 3567 3598 3650 3446 3497 3541 3575 3566 3547 3546 3553 3649 3597 3601 3596 3667 3466 3605 3501 3548 3579 3498 3666 3633 3571 3636 3652 3592 3636 3692 3682 3588 3725 3557 3669 3877 3761 3776 3731 3754 3684 3765 3748 3677 3732 3783 3656 3708 3797 3769 3722 3812 3638 3677 3797 3711 3590 3701 3768 3662 3762 3661 3692 3584 3653 3602 3685 3640 3722 3534 3546 3582 3653 3590 3626 3574 3591 3640 3619 3560 3654 3656 3559 3611 3730 3631 3546 3625 3487 3591 3698 3577 3574 3692 3613 3677 3589 3717 3622 3573 3591 3589 3568 3632 3570 3616 3673 3496 3530 3594 3581 3595 3571 3637 3606 3735 3577 3595 3487 3478 3572 3602 3631 3417 3637 3605 3501 3679 3581 3511 3594 3623 3555 3570 3479 3630 3592 3530 3597 3487 3616 3552 3618 3481 3629 3472 3499 3551 3597 3660 3487 3626 3618 3558 3474 3570 3556 3554 3567 3502 3708 3515 3571 3696 3543 3652 3539 3572 3633 3517 3655 3451 3487 3577 3506 3605 3591 3519 3546 3578 3523 3551 3533 3565 3659 3618 3702 3673 3622 3745 3574 3454 3497 3568 3499 3524 3657 3576 3735 3610 3695 3691 3656 3655 3604 3650 3703 3519 3630 3533 3574 3642 3582 3659 3615 3691 3589 3577 3525 3718 3658 3607 3773 3715 3598 3679 3669 3557 3598 3505 3647 3637 3537 3687 3728 3604 3750 3723 3798 3705 3701 3762 3649 3664 3702 3756 3885 3663 3724 3752 3792 3766 3873 3846 3960 3896 3725 3929 3837 3836 3947 3943 3973 3938 3947 4060 4011 4072 4081 4080 4098 4110 4232 4278 4275 4315 4378 4393 4421 4569 4508 4788 4866 4904 5027 5117 5346 5421 5632 5648 5904 6093 6107 6508 6542 6716 6715 6954 6921 6918 6976 6821 7019 6785 6867 6939 6746 6633 6601 6381 6359 6334 6292 6155 6283 6189 6298 6151 6095 5939 5963 5800 5820 5726 5566 5426 5477 5456 5261 5166 5154 4982 4756 4904 4739 4760 4636 4515 4535 4446 4361 4234 4289 4291 4274 4241 4241 4277 4025 4167 4190 4176 4181 3945 4091 3913 3912 4116 3961 4132 4030 3992 3964 3852 4005 4073 3931 3893 3905 3860 4003 3943 3941 3854 3917 3926 3889 3883 3913 3847 3774 3736 3986 3950 3949 3838 3799 3769 3881 3786 3888 3927 3857 3861 3891 3952 3884 3792 3863 3828 3867 3936 3737 3751 3865 3919 3909 3758 3766 3809 3720 3877 3736 3688 3811 3783 3771 3806 3757 3781 3909 3869 3745 3836 3725 3811 3808 3804 3747 3843 3872 3874 3787 3804 4002 3880 3996 3921 4099 3981 4036 4120 4068 4171 4231 4075 4140 4142 4018 3973 4018 4009 4024 4071 4007 3982 3946 3980 3998 4069 4129 3995 4089 4286 3928 4111 4074 4073 4056 4072 3939 4067 3984 4023 4057 3845 4010 4019 3982 4011 3956 3961 4033 4062 3982 3947 4117 3991 4090 4037 4038 3957 3996 4026 3917 4023 3918 4087 4043 4011 4041 3947 3894 3917 3896 3882 3990 3871 4029 3954 3860 3836 3923 3877 3867 3844 3896 3807 3924 3859 3864 3964 3853 3844 3840 3776 3816 3825 3832 3745 3752 3745 3766 3598 3763 3817 3714 3721 3643 3643 3743 3766 3749 3735 3706 3630 3759 3725 3704 3619 3657 3697 3616 3717 3734 3741 3568 3736 3718 3683 3683 3661 3714 3746 3745 3661 3670 3609 3662 3654 3639 3751 3749 3766 3771 3660 3734 3763 3734 3727 3737 3809 3800 3672 3681 3672 3859 3780 3700 3765 3732 3725 3707 3795 3900 3719 3848 3772 3724 3804 3745 3702 3703 3727 3650 3767 3802 3835 3945 3782 3621 3700 3859 3722 3863 3747 3765 3818 3812 3833 3789 3792 3845 3837 3924 4015 3935 3940 4008 4011 4004 3964 3986 4014 4077 3998 3979 4072 4097 4081 4207 4231 4325 4253 4295 4320 4336 4361 4472 4625 4636 4670 4723 4896 4944 5089 5206 5042 5307 5445 5578 5646 5510 5564 5789 6038 5817 5696 5640 5605 5647 5583 5493 5440 5435 5309 5400 5389 5383 5390 5335 5303 5339 5433 5333 5284 5302 5142 5273 5142 5051 4923 4795 4769 4769 4796 4729 4624 4540 4530 4557 4411 4429 4384 4247 4414 4215 4223 4135 4138 4046 4130 4017 4066 4033 3926 4075 3962 3943 3792 3858 3883 3961 3891 3776 3849 3954 3817 3757 3834 3830 3731 3656 3722 3765 3759 3663 3645 3736 3694 3743 3791 3758 3649 3679 3769 3816 3773 3678 3654 3680 3611 3582 3659 3703 3615 3597 3721 3630 3671 3766 3608 3621 3584 3669 3587 3546 3739 3638 3630 3648 3568 3614 3598 3650 3655 3554 3561 3561 3550 3529 3690 3623 3485 3589 3581 3679 3461 3635 3517 3549 3533 3688 3556 3673 3525 3580 3626 3498 3545 3658 3555 3695 3547 3588 3554 3534 3574 3535 3515 3594 3541 3707 3604 3518 3554 3636 3474 3655 3656 3604 3519 3666 3666 3463 3720 3504 3590 3632 3593 3586 3479 3622 3582 3640 3551 3642 3589 3604 3627 3611 3668 3628 3647 3620 3647 3661 3693 3650 3721 3772 3664 3870 3816 3696 3603 3763 3622 3729 3612 3615 3635 3660 3704 3514 3609 3676 3635 3608 3541 3607 3735 3615 3638 3679 3579 3533 3669 3534 3492 3572 3660 3581 3553 3569 3704 3680 3582 3630 3704 3496 3621 3447 3609 3529 3581 3680 3543 3561 3580 3533 3532 3591 3519 3536 3562 3585 3576 3683 3658 3659 3553 3704 3628 3562 3592 3577 3596 3648 3605 3727 3585 3582 3720 3721 3568 3603 3645 3666 3571 3698 3710 3813 3646 3661 3677 3757 3626 3703 3689 3506 3657 3727 3575 3747 3811 3872 3707 3612 3664 3754 3656 3623 3594 3611 3629 3641 3651 3554 3788 3561 3659 3644 3690 3577 3721 3658 3699 3603 3537 3676 3624 3646 3760 3631 3678 3536 3637 3601 3533 3625 3457 3592 3603 3562 3686 3639 3601 3583 3513 3524 3634 3525 3606 3491 3534 3574 3497 3573 3534 3549 3516 3658 3485 3628 3643 3546 3557 3443 3573 3594 3572 3586 3644 3546 3529 3575 3564 3652 3545 3507 3498 3563 3595 3505 3544 3546 3584 3541 3573 3610 3610 3541 3605 3491 3505 3485 3522 3400 3551 3611 3563 3725 3575 3484 3563 3598 3487 3502 3605 3538 3538 3526 3514 3592 3613 3670 3564 3537 3605 3628 3619 3528 3628 3586 3672 3502 3503 3554 3427 3541 3630 3584 3537 3572 3471 3518 3580 3519 3748 3537 3468 3479 3469 3530 3563 3633 3593 3540 3544 3484 3509 3456 3518 3585 3552 3495 3543 3491 3528 3615 3487 3571 3542 3506 3563 3571 3419 3530 3504 3649 3541 3603 3507 3569 3568 3547 3519 3508 3643 3515 3585 3656 3585 3472 3611 3541 3629 3453 3529 3509 3558 3647 3604 3617 3507 3748 3503 3548 3641 3628 3583 3648 3537 3614 3572 3617 3552 3664 3721 3569 3458 3594 3528 3550 3508 3577 3501 3556 3483 3567 3642 3668 3560 3550 3540 3525 3541 3500 3582 3665 3588 3603 3503 3542 3628 3538 3514 3580 3580 3577 3598 3614 3495 3641 3591 3566 3594 3481 3583 3569 3642 3503 3557 3571 3736 3612 3517 3618 3545 3541 3615 3570 3527 3643 3615 3608 3577 3554 3659 3525 3593 3572 3547 3683 3556 3710 3574 3450 3665 3641 3623 3646 3578 3615 3603 3589 3519 3669 3547 3524 3511 3566 3586 3598 3554 3540 3538 3563 3650 3580 3558 3521 3592 3615 3617 3642 3550 3625 3538 3674 3543 3671 3519 3438 3504 3530 3537 3560 3545 3525 3354 3524 3639 3484 3648 3607 3582 3589 3557 3660 3545 3474 3670 3612 3573 3663 3590 3596 3640 3509 3645 3413 3517 3511 3587 3625 3627 3646 3567 3579 3481 3636 3538 3694 3645 3578 3541 3532 3532 3459 3558 3558 3518 3413 3524 3508 3521 3596 3535 3674 3563 3531 3506 3559 3532 3585 3602 3497 3637 3599 3623 3557 3403 3581 3511 3494 3558 3550 3525 3453 3583 3706 3589 3563 3588 3577 3611 3622 3552 3583 3395 3593 3564 3507 3560 3572 3604 3571 3536 3601 3584 3632 3656 3578 3544 3617 3578 3625 3555 3520 3662 3653 3533 3397 3635 3495 3423 3553 3532 3513 3605 3489 3490 3486 3520 3591 3677 3520 3529 3549 3598 3586 3505 3510 3729 3520 3646 3457 3639 3581 3512 3593 3512 3618 3484 3515 3538 3538 3542 3449 3614 3572 3511 3475 3430 3693 3551 3548 3569 3575 3545 3626 3622 3609 3636 3655 3482 3640 3547 3689 3657 3482 3690 3490 3623 3577 3517 3511 3630 3577 3578 3492 3492 3651 3640 3520 3611 3583 3478 3511 3588 3684 3542 3544 3473 3550 3603 3544 3491 3666 3574 3588 3523 3648 3699 3610 3630 3669 3555 3654 3617 3602 3684 3589 3704 3428 3489 3417 3591 3633 3619 3583 3532 3512 3632 3503 3665 3637 3568 3628 3583 3547 3598 3646 3501 3619 3612 3546 3660 3598 3668 3632 3606 3614 3559 3602 3583 3658 3710 3747 3603 3592 3716 3664 3750 3680 3761 3677 3689 3642 3654 3794 3720 3668 3760 3749 3689 3778 3774 3799 3736 3819 3668 3711 3707 3697 3794 3664 3764 3680 3739 3737 3772 3736 3741 3751 3749 3769 3789 3767 3646 3629 3703 3784 3812 3705 3771 3707 3703 3770 3701 3698 3718 3693 3658 3642 3750 3682 3646 3649 3706 3646 3650 3617 3702 3732 3607 3603 3738 3668 3643 3661 3581 3604 3557 3604 3739 3669 3653 3656 3676 3659 3612 3642 3733 3688 3643 3809 3648 3774 3705 3789 3928 3751 3951 4033 3900 4054 3935 4165 4152 4180 4122 4374 4180 4343 4223 4273 4329 4257 3993 4146 4054 3999 4083 3952 3892 3932 3928 3713 3930 3865 3853 3861 3963 3877 3965 4017 4021 3947 4111 3975 3869 4045 3968 3973 3962 3891 3871 3769 3907 3724 3700 3774 3712 3806 3801 3743 3604 3739 3658 3706 3752 3745 3703 3593 3580 3722 3802 3754 3762 3763 3618 3619 3807 3686 3788 3701 3720 3651 3711 3634 3745 3618 3801 3749 3702 3663 3664 3737 3702 3636 3669 3638 3605 3695 3666 3711 3722 3689 3702 3632 3681 3571 3765 3623 3689 3746 3668 3569 3696 3529 3687 3584 3714 3644 3621 3681 3598 3721 3572 3644 3716 3688 3624 3617 3652 3647 3577 3563 3642 3604 3528 3592 3636 3677 3607 3770 3570 3535 3702 3702 3624 3522 3512 3571 3604 3671 3590 3615 3560 3591 3658 3647 3607 3651 3449 3739 3613 3588 3683 3615 3758 3729 3676 3640 3673 3677 3652 3637 3549 3592 3505 3678 3516 3618 3688 3492 3696 3608 3593 3765 3673 3579 3679 3554 3597 3666 3751 3493 3631 3606 3632 3657 3586 3643 3709 3555 3576 3552 3747 3604 3531 3683 3574 3550 3579 3690 3654 3589 3581 3587 3533 3629 3679 3738 3664 3510 3632 3535 3629 3556 3606 3581 3498 3581 3700 3658 3557 3657 3621 3724 3577 3567 3615 3602 3688 3539 3547 3576 3467 3580 3503 3611 3563 3601 3601 3678 3503 3502 3557 3564 3670 3616 3510 3583 3595 3591 3551 3559 3540 3621 3661 3617 3550 3492 3636 3670 3633 3570 3615 3642 3593 3538 3682 3568 3715 3542 3586 3517 3559 3738 3511 3540 3643 3677 3624 3575 3584 3618 3617 3584 3607 3544 3613 3652 3749 3698 3621 3721 3785 3671 3802 3822 3780 3859 3699 3746 3674 3734 3792 3919 3857 3828 3810 3665 3668 3793 3721 3788 3705 3681 3672 3591 3587 3494 3705 3717 3580 3818 3723 3700 3626 3769 3721 3753 3723 3824 3696 3669 3674 3670 3711 3713 3596 3523 3617 3631 3725 3696 3557 3598 3626 3470 3555 3686 3593 3551 3653 3588 3498 3553 3551 3606 3628 3482 3574 3562 3704 3684 3627 3512 3567 3557 3508 3547 3584 3584 3529 3673 3733 3639 3567 3545 3536 3591 3597 3495 3523 3527 3643 3622 3632 3610 3448 3560 3601 3472 3433 3616 3649 3654 3637 3573 3537 3630 3572 3647 3519 3660 3589 3598 3616 3655 3556 3576 3547 3534 3696 3624 3526 3606 3536 3502 3634 3552 3647 3661 3602 3670 3612 3625 3533 3694 3700 3602 3653 3545 3722 3640 3682 3516 3732 3524 3583 3559 3643 3630 3580 3706 3630 3489 3637 3648 3594 3599 3655 3563 3616 3586 3591 3663 3604 3626 3561 3813 3679 3682 3692 3743 3643 3719 3637 3756 3803 3672 3657 3731 3668 3640 3731 3808 3578 3843 3792 3762 4014 3749 3738 3904 3881 3799 3915 3972 3770 4031 3853 3933 3933 4055 4044 4126 4083 4151 4220 4175 4430 4361 4300 4482 4603 4597 4603 4783 4696 4737 4877 4696 4822 4857 4730 4622 4644 4665 4701 4632 4580 4630 4516 4546 4657 4629 4619 4694 4778 4886 4963 5020 4990 5037 5043 4966 4971 4986 5012 4893 4850 4723 4693 4524 4601 4536 4390 4348 4466 4315 4435 4276 4206 4192 4343 4231 4202 4483 4188 4330 4361 4297 4260 4337 4303 4196 4141 4204 4211 4069 4007 4108 3993 4001 3955 4041 3916 3870 3872 3827 3904 3850 3835 3953 3806 3920 3852 3803 3773 3766 3771 3855 3799 3865 3775 3771 3696 3684 3697 3801 3824 3696 3773 3701 3889 3814 3765 3748 3763 3668 3687 3700 3703 3706 3714 3733 3713 3809 3569 3692 3669 3673 3621 3676 3749 3619 3632 3696 3697 3657 3708 3729 3724 3634 3698 3681 3716 3743 3778 3637 3688 3696 3716 3689 3696 3644 3791 3716 3617 3711 3614 3602 3657 3742 3742 3639 3685 3690 3850 3670 3687 3731 3773 3739 3646 3661 3627 3717 3684 3669 3771 3797 3730 3728 3744 3709 3653 3621 3702 3561 3688 3717 3700 3692 3607 3756 3649 3696 3667 3753 3648 3698 3673 3688 3804 3720 3709 3708 3738 3686 3717 3676 3636 3722 3674 3527 3691 3659 3757 3738 3770 3580 3616 3658 3693 3654 3592 3614 3583 3767 3649 3534 3621 3609 3754 3759 3596 3579 3667 3534 3777 3630 3559 3625 3613 3614 3590 3549 3623 3576 3599 3722 3624 3574 3622 3623 3623 3565 3647 3535 3573 3690 3577 3530 3681 3608 3667 3552 3681 3585 3662 3619 3630 3591 3632 3642 3592 3559 3472 3645 3660 3540 3677 3579 3627 3674 3647 3518 3643 3601 3548 3691 3487 3549 3468 3584 3569 3512 3664 3654 3625 3598 3576 3635 3565 3569 3707 3657 3645 3598 3612 3630 3711 3636 3662 3572 3653 3728 3628 3604 3581 3583 3595 3640 3570 3657 3605 3601 3598 3706 3617 3671 3633 3676 3854 3654 3749 3645 3808 3800 3816 3795 3912 3966 3907 3891 3946 3905 4007 3991 3798 4070 3888 3981 4012 3806 3751 3792 3887 3700 3683 3692 3774 3688 3778 3683 3716 3702 3718 3724 3742 3797 3608 3747 3801 3780 3731 3830 3696 3722 3834 3902 3719 3759 3804 3772 3641 3703 3619 3514 3654 3647 3684 3719 3685 3656 3592 3712 3699 3601 3529 3624 3542 3621 3669 3555 3599 3575 3645 3543 3565 3543 3572 3635 3458 3675 3649 3629 3690 3679 3600 3578 3602 3769 3586 3615 3654 3644 3563 3649 3599 3648 3521 3655 3615 3656 3570 3646 3498 3671 3541 3631 3644 3630 3600 3579 3778 3563 3562 3622 3649 3603 3533 3558 3497 3567 3443 3445 3544 3585 3663 3598 3703 3591 3483 3601 3597 3719 3564 3542</counts>
			</dataPoints>
		</scan>
	</xrdMeasurement>
</xrdMeasurements>