File: dataset/precursor_mixture/NiO_0p2030-Li2CO3_0p2999-TiO2_0p5025--8min.xrdml
<?xml version="1.0"?>
<xrdMeasurements xmlns="http://www.xrdml.com/XRDMeasurement/2.3" xmlns:xsi="http://www.w3.org/2001/XMLSchema-instance" xsi:schemaLocation="http://www.xrdml.com/XRDMeasurement/2.3 http://www.xrdml.com/XRDMeasurement/2.3/XRDMeasurement.xsd" status="Completed" recordIdentifier="{34D22A99-E5EE-4E67-BA2D-52802F0C84B0}">
	<comment>
		<entry/>
	</comment>
	<sample type="To be analyzed">
		<id>NiO_0p2030-Li2CO3_0p2999-TiO2_0p5025--8min</id>
		<name></name>
		<preparedBy></preparedBy>
	</sample>
	<xrdMeasurement measurementType="Scan" status="Completed" sampleMode="Reflection">
		<usedWavelength intended="K-Alpha 1">
			<kAlpha1 unit="Angstrom">1.5405980</kAlpha1>
			<kAlpha2 unit="Angstrom">1.5444260</kAlpha2>
			<kBeta unit="Angstrom">1.3922500</kBeta>
			<ratioKAlpha2KAlpha1>0.5000</ratioKAlpha2KAlpha1>
		</usedWavelength>
		<incidentBeamPath>
			<radius unit="mm">145.00</radius>
			<xRayTube id="1010048" name="Empyrean Cu LFF HR (9430 033 7310x)">
				<tension unit="kV">40.0</tension>
				<current unit="mA">15.0</current>
				<anodeMaterial>Cu</anodeMaterial>
				<focus type="Line">
					<length unit="mm">12.0</length>
					<width unit="mm">0.4</width>
					<takeOffAngle unit="deg">6.0</takeOffAngle>
				</focus>
			</xRayTube>
			<sollerSlit id="21010002" name="Soller slits 0.04 rad.">
				<opening unit="rad">0.0400</opening>
			</sollerSlit>
			<mask id="22031000" name="Fixed mask 13 mm">
				<width unit="mm">9.00</width>
			</mask>
			<divergenceSlit id="22120001" name="Divergence slit 1°" xsi:type="fixedDivergenceSlitType">
				<distanceToSample unit="mm">50.00</distanceToSample>
				<height unit="mm">1.52</height>
			</divergenceSlit>
		</incidentBeamPath>
		<sampleMovement xsi:type="spinningSampleMovementType">
			<spinnerRevolutionTime unit="seconds">1.0</spinnerRevolutionTime>
		</sampleMovement>
		<diffractedBeamPath>
			<radius unit="mm">145.00</radius>
			<antiScatterSlit id="22090040" name="AS slit 9 mm (PIXcel)" xsi:type="fixedAntiScatterSlitType">
				<height unit="mm">9.00</height>
			</antiScatterSlit>
			<sollerSlit id="21020003" name="Large Soller slits 0.04 rad.">
				<opening unit="rad">0.0400</opening>
			</sollerSlit>
			<filter id="20030001" name="Large beta-filter Nickel">
				<material>Ni</material>
				<thickness unit="mm">0.020</thickness>
			</filter>
			<detector id="7010019" name="PIXcel1D-Medipix3 detector" xsi:type="rtmsDetectorType">
				<phd unit="keV">
					<lowerLevel>4.02</lowerLevel>
					<upperLevel>11.27</upperLevel>
				</phd>
				<mode>Scanning</mode>
				<activeLength unit="deg">5.542</activeLength>
			</detector>
		</diffractedBeamPath>
		<scan appendNumber="0" mode="Continuous" scanAxis="Gonio" status="Completed">
			<header>
				<startTimeStamp>2024-11-14T16:51:45-08:00</startTimeStamp>
				<endTimeStamp>2024-11-14T16:59:52-08:00</endTimeStamp>
				<author>
					<name>AutomatedUser</name>
				</author>
				<source>
					<applicationSoftware version="1.7b (136)">PANalytical Aeris Instrument Suite</applicationSoftware>
					<instrumentControlSoftware version="3.2.00000000 20240306">AERIS</instrumentControlSoftware>
					<instrumentID>950485</instrumentID>
				</source>
			</header>
			<dataPoints>
				<positions axis="2Theta" unit="deg">
					<startPosition>10.00943322</startPosition>
					<endPosition>99.99442286</endPosition>
				</positions>
				<positions axis="Omega" unit="deg">
					<startPosition>5.00471661</startPosition>
					<endPosition>49.99721143</endPosition>
				</positions>
				<commonCountingTime unit="seconds">12.495</commonCountingTime>
				<counts unit="counts">2566 2652 2528 2571 2617 2634 2632 2479 2595 2460 2539 2599 2443 2583 2553 2589 2493 2549 2541 2588 2574 2572 2568 2573 2564 2548 2548 2535 2451 2514 2446 2464 2557 2547 2605 2527 2531 2555 2505 2609 2481 2445 2523 2518 2592 2472 2487 2533 2548 2475 2494 2506 2518 2497 2480 2465 2469 2450 2361 2485 2499 2468 2457 2503 2329 2386 2398 2472 2519 2433 2504 2503 2372 2480 2426 2363 2500 2388 2385 2405 2392 2406 2414 2466 2434 2371 2433 2371 2407 2395 2400 2404 2406 2438 2380 2412 2337 2421 2334 2467 2431 2278 2412 2396 2383 2343 2407 2380 2373 2332 2340 2348 2368 2372 2458 2345 2394 2370 2401 2343 2330 2385 2330 2377 2403 2267 2321 2393 2289 2244 2310 2319 2350 2348 2337 2358 2306 2345 2268 2313 2348 2304 2272 2271 2319 2251 2232 2281 2256 2269 2314 2261 2415 2264 2255 2268 2299 2333 2267 2300 2254 2271 2293 2221 2300 2235 2238 2226 2262 2211 2272 2255 2252 2319 2276 2329 2288 2267 2284 2288 2309 2292 2205 2281 2230 2280 2266 2327 2223 2165 2281 2221 2240 2179 2194 2224 2155 2248 2223 2138 2205 2234 2232 2126 2242 2191 2216 2260 2136 2243 2231 2119 2216 2184 2331 2279 2114 2145 2183 2145 2251 2212 2211 2110 2147 2212 2147 2195 2169 2182 2222 2148 2140 2147 2138 2130 2117 2172 2141 2191 2147 2092 2203 2146 2121 2141 2234 2120 2264 2221 2236 2166 2143 2134 2152 2172 2130 2173 2105 2142 2122 2139 2089 2161 2153 2122 2143 2114 2119 2130 2135 2055 2084 2170 2171 2147 2073 2125 2147 2166 2106 2085 2141 2094 2006 2033 2083 2126 2052 2148 2056 2116 2077 2151 2039 2065 2116 2129 2186 2048 2114 2067 2099 2202 1996 2096 2104 2052 2038 2094 2085 2116 2030 2073 2115 2144 2050 2069 2078 2016 2023 2130 2009 1999 2114 2062 2156 2183 2103 2077 2148 2094 1988 1992 2040 2024 2017 2086 2016 2050 2014 2025 2019 1998 2122 2068 2137 1979 2038 2002 2104 2036 2085 2036 2102 2084 2012 2017 2069 2059 1993 2026 1997 2033 2134 2112 2030 2028 2145 2016 2097 2071 2067 2025 2104 2033 1986 2132 2008 2086 2054 2027 2038 1951 2050 2040 2038 2044 2069 2009 2085 2073 2075 2048 2059 2075 2072 2020 1990 2006 2060 2048 2048 2139 2143 2074 2029 2062 2120 2046 1999 2050 2011 1934 2060 2002 2071 2042 2064 2037 2122 2088 2025 2090 1945 2041 2038 2011 2084 2112 2017 1965 1968 2012 1918 1992 2021 2055 2097 2032 2019 2061 2096 2008 2002 2080 1964 1995 2039 2003 1973 2044 2065 2133 1989 1951 1983 2067 1993 2023 2016 1959 2026 1981 2021 2087 2086 2030 2069 1937 2057 1914 2070 2006 2079 2075 2006 1965 1994 2037 1994 2023 1904 2044 1922 2100 2107 2036 2000 2036 1932 1996 1971 2050 2019 2066 1966 1967 2045 1964 1999 2069 2101 2037 2001 2119 2003 1990 2022 2058 1913 1957 1979 1960 2004 2034 2015 2026 2051 2008 2109 2042 1994 2043 2051 2039 1923 2029 1975 2009 1998 1964 2104 1941 2036 2020 2094 2043 1954 2000 2062 2001 2043 2037 2037 2049 1999 2016 2039 2023 2034 2034 1950 1924 1966 2019 2060 2004 2057 2034 1973 1961 2079 1967 1981 2015 2002 2061 1999 1961 2040 1986 2023 2050 2040 2048 2041 2013 1994 2038 2035 1982 2050 2023 1991 2045 2024 1979 2015 1961 2103 2029 2035 1974 1986 2015 2044 2029 2003 2015 1939 2023 2011 1986 2032 1859 2016 1979 2010 2009 2054 2028 1963 2023 2007 1952 2038 1987 1949 2042 1981 2039 1977 1939 2010 1979 2049 1892 2088 2065 1990 2101 2049 2060 1959 2043 2016 1883 2093 1968 1975 1953 1876 1971 1961 1952 2001 2007 1974 2062 1953 2005 2075 2054 2016 2040 1947 1948 2028 2013 2015 2061 2067 2030 1986 2002 1976 2006 1997 1995 1999 2082 1998 1954 2014 2002 1982 1980 2037 1959 2093 1984 2001 2004 1886 2070 1913 2034 1961 1872 1918 2024 1974 2065 1990 1983 1943 2036 2006 1986 1996 1974 1960 1876 1976 2030 2001 2030 1994 2052 1925 1891 1988 1937 2030 1999 1953 1930 1962 1987 1953 2022 2046 1971 1946 1986 1962 1973 1946 1996 1936 1982 1917 1969 1970 1884 1993 2021 1959 1970 1984 1954 1954 1903 1943 2008 2040 1925 1964 1992 1990 1949 1992 1976 1992 2013 1972 1977 1987 1923 1959 1956 2028 1931 2045 1898 1948 1963 1935 2037 1907 1915 1980 2041 1955 1963 1830 2036 1937 1973 1953 1938 1933 2017 1953 1999 1937 1929 1917 2009 2061 1965 1979 1977 1933 1961 1936 1904 2000 1946 2013 2034 1987 1897 1902 2010 1919 1948 1916 1972 1986 1876 2041 1992 1929 1846 1981 1968 1936 1921 1947 1864 1857 1871 1881 1915 1898 1924 1867 1936 1907 1995 1983 1970 1898 1953 1965 2012 1915 1966 1958 1891 1947 1893 1921 1984 1944 1940 1949 1924 1965 1953 1908 1924 1914 1901 1996 1874 1910 1899 1917 1945 1967 1924 1929 1881 2017 1866 1956 2008 1876 1899 1962 1919 1930 1923 1912 1966 1910 1957 2022 1879 1922 2020 1982 1862 1953 1921 1954 1951 1888 1947 1907 1921 1850 2005 1910 1939 1907 1888 1916 1911 1945 1917 1933 1945 2002 1959 1873 1863 1920 1981 1918 1853 1888 1959 1935 1895 1935 1903 1942 1914 1880 1886 1866 1939 1915 1866 1855 1879 1853 1933 1916 1905 1959 1975 1930 1862 1805 1827 1955 1890 1867 1899 1839 1884 1871 2013 1902 1800 1919 1889 1943 1921 1983 1942 1928 1917 1895 1960 1834 1895 1958 1983 1931 1877 1917 1905 1890 1916 1979 1931 1827 1802 1840 1914 1917 1831 1915 1839 1915 1879 1914 1846 1924 1913 1883 1871 1904 1862 1892 1947 1887 1930 1884 1845 1886 1939 2004 1910 1911 1932 1915 1930 1942 2009 1926 1897 1925 1981 1990 1926 1959 1946 1984 1930 2005 2012 1999 2055 2022 1948 2029 2094 2115 2139 2068 2167 2230 2196 2290 2279 2342 2335 2556 2449 2507 2506 2707 2656 2764 2779 2956 2890 2888 2800 2913 2984 2905 2975 2802 2841 2884 2678 2771 2867 2792 2668 2566 2597 2540 2479 2482 2535 2436 2374 2359 2236 2240 2134 2110 2144 2069 2036 2061 1870 1909 1999 1938 1962 1909 1917 1997 1850 1963 1923 1981 1909 1880 1911 2041 1823 1851 1880 1861 1809 1868 1878 1888 1890 1887 1956 1844 1800 1938 1928 1967 1862 1918 1819 1847 1905 1937 1859 1905 1958 1873 1799 1856 1892 1849 1875 1909 1905 1886 1872 1847 1850 1935 1857 1841 1811 1824 1849 1890 1858 1856 1769 1869 1828 1842 1885 1928 1925 1828 1844 1773 1906 1831 1841 1905 1881 1865 1884 1867 1777 1813 1887 1833 1877 1851 1790 1719 1869 1899 1954 1842 1859 1874 1844 1871 1850 1951 1848 1910 1886 1940 1849 1927 1827 1938 1815 1865 1949 1921 1798 1831 1920 1832 1814 1920 1833 1900 1924 1860 1871 1912 1892 1886 1900 1981 1855 1864 1899 1896 1854 1863 1907 1811 1818 1777 1869 1879 1847 1917 1892 1952 1934 1772 1876 1902 1830 1880 1863 1948 1916 1881 1899 1883 1873 1971 1887 1918 1978 1966 1963 1923 1976 1945 1982 1941 1964 2020 1977 1921 2030 2006 2010 1969 1908 1992 1951 2007 1964 1894 1951 1891 1986 1908 1893 1917 1897 1921 1882 1868 1870 1889 1914 1868 1831 1907 1881 1877 1868 1812 1865 1870 1867 1839 1755 1858 1863 1921 1747 1868 1854 1885 1835 1856 1888 1862 1820 1751 1847 1857 1852 1777 1813 1871 1718 1842 1839 1849 1881 1799 1844 1864 1748 1857 1785 1861 1839 1803 1772 1881 1836 1830 1830 1874 1854 1828 1954 1886 1876 1891 1882 1880 1857 1892 1863 1922 1929 1954 1901 1937 1937 2020 1932 1867 2016 1940 1958 1918 1957 1979 1984 1921 2001 1992 1993 2073 2043 2072 2058 1962 2063 2028 2138 2062 2072 2105 2130 2077 2141 2225 2275 2093 2190 2118 2230 2222 2322 2249 2346 2421 2388 2409 2515 2572 2582 2622 2756 2996 2956 3112 3293 3394 3548 3596 4012 4357 4524 4950 5405 5824 6175 6801 7236 7862 8613 9113 9877 10516 11256 11855 12616 13246 14070 14677 15042 15635 15854 16175 16404 16188 16395 15938 15572 15388 14965 14069 13667 13233 12679 12298 11903 10931 10874 10150 9813 9304 8519 8018 7228 6498 6042 5472 4860 4389 4037 3671 3328 3147 2909 2872 2581 2540 2498 2394 2371 2270 2390 2348 2232 2287 2198 2213 2103 2117 2063 2125 2025 2087 2082 2006 2057 2101 2088 1974 1851 2054 2002 1946 1976 1978 1979 1968 1919 1922 1881 1941 2000 1872 1836 1864 1888 1879 1891 1894 1856 1943 1843 1915 1940 1867 1913 1907 1921 1945 1854 1866 1847 1861 1876 1866 1878 1870 1886 1817 1898 1819 1850 1885 1904 1798 1858 1781 1874 1803 1852 1830 1803 1780 1803 1872 1819 1785 1773 1846 1811 1846 1850 1764 1782 1805 1805 1817 1817 1815 1841 1860 1792 1860 1843 1875 1796 1859 1826 1821 1827 1849 1781 1812 1787 1838 1775 1817 1787 1823 1860 1872 1885 1810 1752 1751 1770 1896 1822 1796 1782 1808 1853 1759 1860 1768 1727 1773 1718 1770 1764 1757 1754 1783 1824 1803 1822 1748 1864 1843 1791 1874 1781 1755 1786 1817 1837 1857 1899 1821 1796 1805 1821 1819 1811 1723 1840 1853 1909 1851 1945 1885 1916 1909 1847 1825 1834 1825 1817 1886 1786 1860 1791 1829 1785 1823 1765 1795 1729 1827 1809 1781 1748 1817 1853 1828 1819 1795 1752 1814 1723 1761 1802 1744 1803 1727 1843 1728 1769 1742 1751 1838 1682 1750 1692 1667 1731 1708 1757 1789 1727 1799 1766 1735 1757 1773 1715 1768 1808 1779 1740 1751 1729 1659 1722 1729 1753 1699 1774 1743 1788 1695 1761 1757 1721 1770 1769 1750 1687 1768 1759 1698 1730 1755 1744 1735 1703 1723 1731 1714 1713 1768 1711 1730 1786 1712 1650 1755 1779 1806 1764 1703 1746 1832 1726 1691 1860 1742 1711 1712 1717 1801 1714 1763 1736 1754 1702 1753 1775 1796 1699 1779 1627 1779 1748 1729 1683 1740 1679 1734 1792 1764 1714 1775 1680 1731 1693 1741 1739 1723 1778 1790 1765 1718 1783 1734 1757 1816 1792 1754 1722 1851 1717 1707 1740 1826 1767 1773 1761 1810 1793 1793 1830 1823 1738 1833 1802 1804 1839 1823 1859 1810 1872 1853 1894 1924 1873 1889 1842 1968 1938 2037 1890 1998 1986 1932 2010 1983 2088 2022 2102 2035 2034 2011 1899 1931 1911 1995 1901 1908 1871 1895 1937 1811 1913 1901 1799 1837 1897 1920 1781 1813 1839 1772 1792 1764 1739 1849 1804 1836 1803 1760 1740 1749 1774 1761 1770 1771 1824 1826 1794 1750 1694 1735 1733 1665 1728 1676 1721 1691 1714 1749 1767 1818 1754 1713 1809 1725 1744 1757 1734 1784 1736 1782 1723 1758 1768 1754 1825 1780 1779 1824 1780 1857 1886 1766 1905 1886 1891 1856 1902 1961 1856 1931 1997 2041 2039 1988 2083 2151 2272 2215 2307 2297 2401 2428 2410 2414 2410 2424 2484 2415 2568 2573 2545 2582 2545 2481 2392 2476 2439 2421 2400 2404 2356 2337 2267 2325 2299 2321 2096 2045 2174 2091 2127 2000 2033 1987 2076 1854 1866 1884 1916 1908 1882 1928 1825 1802 1911 1837 1795 1835 1832 1803 1799 1779 1743 1779 1824 1791 1856 1754 1871 1698 1772 1719 1836 1786 1801 1785 1808 1809 1763 1837 1793 1772 1820 1923 1927 1881 1816 1860 1946 1871 1916 1908 1954 1896 1962 1891 2023 2032 2087 2106 2174 2151 2185 2238 2295 2338 2375 2357 2453 2604 2583 2774 2757 2807 2925 3015 3181 3297 3302 3399 3377 3545 3522 3671 3595 3691 3630 3638 3700 3684 3645 3564 3567 3539 3462 3353 3342 3224 3153 3231 3177 2987 2830 2860 2694 2766 2666 2668 2468 2356 2346 2301 2210 2275 2129 2057 2034 2062 1922 1953 1917 1946 1870 1878 1945 1887 1819 1902 1846 1789 1789 1847 1767 1790 1859 1732 1919 1728 1674 1874 1733 1818 1764 1741 1817 1633 1769 1753 1692 1729 1698 1636 1641 1684 1672 1739 1776 1642 1730 1680 1647 1643 1709 1682 1673 1643 1602 1687 1700 1734 1669 1644 1691 1645 1763 1653 1673 1595 1695 1660 1621 1622 1627 1701 1672 1658 1659 1636 1667 1668 1635 1562 1621 1673 1699 1734 1586 1705 1681 1684 1663 1643 1662 1649 1590 1716 1598 1693 1695 1640 1636 1653 1617 1627 1640 1658 1696 1636 1627 1708 1591 1564 1664 1617 1694 1646 1671 1629 1571 1633 1653 1669 1583 1640 1717 1625 1570 1702 1661 1714 1612 1685 1544 1624 1641 1623 1612 1645 1709 1633 1593 1661 1591 1614 1646 1616 1606 1757 1635 1704 1700 1631 1571 1630 1649 1727 1640 1633 1639 1682 1754 1611 1628 1666 1637 1664 1721 1681 1698 1734 1736 1786 1698 1840 1759 1771 1923 1843 1866 1813 1921 1885 1941 1961 1952 1978 2060 2056 1968 2003 1932 2033 1975 2044 2094 2049 1968 2040 2036 1969 2003 1898 1918 1961 1927 1934 1939 1866 1818 1853 1786 1805 1788 1806 1788 1751 1776 1757 1708 1696 1746 1682 1705 1729 1714 1638 1617 1617 1601 1620 1652 1687 1569 1544 1639 1660 1571 1504 1631 1690 1679 1549 1615 1624 1608 1611 1661 1586 1670 1601 1563 1640 1628 1625 1647 1570 1619 1541 1663 1667 1722 1627 1589 1573 1606 1684 1588 1645 1653 1656 1558 1655 1578 1625 1583 1548 1590 1587 1642 1553 1666 1576 1640 1628 1582 1628 1636 1558 1557 1545 1588 1596 1521 1607 1588 1584 1539 1682 1571 1650 1686 1588 1526 1575 1616 1604 1623 1665 1626 1615 1593 1643 1609 1607 1594 1527 1597 1579 1571 1602 1535 1477 1630 1604 1620 1621 1591 1547 1569 1545 1628 1668 1601 1628 1566 1651 1605 1571 1650 1583 1621 1631 1580 1614 1649 1638 1605 1694 1668 1602 1748 1663 1688 1701 1763 1796 1889 1766 1892 1804 1907 1850 2031 1988 2069 2205 2129 2175 2196 2320 2278 2341 2263 2459 2376 2290 2341 2315 2287 2279 2203 2252 2263 2120 2266 2215 2144 2115 2032 2028 1996 1946 1931 1995 1831 1802 1867 1767 1812 1835 1703 1744 1673 1774 1813 1669 1605 1629 1705 1745 1739 1690 1646 1656 1704 1690 1656 1719 1779 1693 1793 1697 1747 1832 1772 1739 1857 1845 1802 1795 1896 1890 1958 1927 1951 2017 2033 2131 2206 2225 2269 2339 2446 2545 2528 2624 2642 2781 2855 2999 2925 2997 3026 3171 3134 3222 3371 3429 3395 3354 3552 3420 3658 3687 3753 3809 3957 3982 4055 4250 4339 4310 4436 4648 4674 4926 4974 5127 5176 5324 5104 5157 5310 5179 5222 5048 5230 5191 5147 4934 4872 4797 4654 4609 4511 4274 4183 3882 3816 3725 3569 3462 3301 3200 3161 2999 2973 2995 2879 2805 2746 2765 2810 2851 2986 2938 2968 3090 3284 3392 3563 3684 3754 3848 4105 4258 4398 4473 4528 4723 4778 4854 4856 4787 4720 4689 4685 4600 4405 4377 4363 4295 4296 4043 3831 3836 3739 3498 3276 3204 3055 2891 2840 2645 2495 2451 2295 2170 2206 2091 2001 1925 1880 1830 1889 1834 1743 1748 1825 1785 1725 1758 1793 1768 1708 1751 1728 1719 1832 1762 1833 1758 1731 1807 1865 1804 1803 1963 1993 2005 2074 2043 2106 2274 2195 2382 2389 2480 2473 2493 2559 2607 2537 2610 2625 2495 2568 2438 2518 2502 2452 2473 2374 2437 2396 2370 2255 2210 2190 2116 2080 2043 1998 1871 1936 1838 1867 1845 1748 1724 1852 1648 1739 1639 1703 1688 1592 1644 1664 1678 1592 1650 1605 1656 1603 1581 1559 1612 1677 1570 1622 1597 1616 1578 1612 1556 1631 1569 1570 1616 1627 1597 1599 1599 1595 1615 1593 1613 1670 1637 1594 1580 1654 1660 1701 1658 1699 1641 1692 1661 1762 1688 1768 1821 1793 1813 1830 1891 1781 1933 1845 1790 1868 1882 1882 1831 1862 1960 1898 1905 1915 1899 1889 1906 1879 1869 1845 1831 1848 1850 1815 1778 1799 1783 1779 1701 1736 1773 1754 1747 1776 1731 1771 1630 1746 1702 1716 1685 1730 1690 1703 1685 1686 1671 1698 1683 1674 1687 1656 1705 1701 1715 1635 1690 1646 1607 1655 1564 1550 1630 1598 1605 1582 1581 1630 1614 1580 1597 1610 1614 1600 1599 1577 1604 1565 1584 1567 1549 1526 1636 1537 1594 1486 1541 1580 1605 1528 1537 1501 1537 1561 1581 1576 1589 1540 1537 1588 1570 1539 1533 1553 1537 1552 1515 1601 1507 1515 1591 1567 1574 1537 1524 1586 1536 1504 1530 1516 1490 1538 1533 1532 1608 1541 1523 1517 1512 1548 1564 1566 1537 1559 1579 1598 1517 1558 1556 1482 1487 1542 1560 1566 1574 1502 1574 1510 1569 1586 1546 1621 1553 1467 1573 1501 1622 1544 1566 1573 1498 1575 1598 1581 1586 1542 1507 1521 1555 1523 1507 1557 1575 1533 1553 1505 1582 1539 1521 1561 1539 1532 1593 1552 1568 1608 1541 1523 1583 1478 1534 1579 1495 1563 1589 1494 1610 1530 1579 1481 1533 1576 1564 1487 1518 1497 1480 1549 1595 1558 1579 1668 1502 1621 1590 1584 1507 1565 1560 1487 1556 1557 1604 1556 1594 1504 1568 1559 1514 1526 1641 1600 1552 1560 1542 1574 1571 1641 1517 1561 1542 1511 1595 1578 1604 1547 1715 1558 1552 1516 1575 1608 1577 1541 1598 1518 1580 1534 1528 1517 1573 1599 1659 1593 1551 1582 1592 1597 1595 1614 1599 1545 1567 1597 1608 1543 1622 1626 1593 1631 1590 1610 1624 1659 1666 1576 1572 1580 1673 1720 1654 1702 1655 1703 1741 1655 1674 1731 1791 1755 1714 1784 1793 1824 1830 1719 1829 1726 1813 1812 1863 1799 1804 1826 1774 1925 1950 1917 1908 1968 2089 2016 2053 2202 2194 2264 2400 2433 2609 2551 2741 3043 3142 3242 3377 3754 3949 4234 4452 4834 5029 5461 5716 6094 6491 6793 6750 7146 7239 7528 7544 7534 7578 7711 7499 7475 7610 7360 7457 7305 7243 6965 6795 6538 6124 5908 5384 5275 4865 4647 4217 4304 3989 3808 3502 3348 3294 2994 2833 2687 2561 2366 2351 2205 2248 2147 1993 2033 1962 1936 1888 1948 1901 1757 1798 1800 1717 1764 1772 1688 1685 1683 1687 1713 1710 1696 1700 1604 1648 1683 1614 1638 1629 1626 1573 1576 1603 1578 1607 1602 1587 1632 1624 1593 1590 1659 1610 1557 1564 1665 1569 1588 1568 1604 1609 1612 1587 1584 1594 1545 1532 1541 1590 1518 1557 1592 1563 1597 1497 1580 1523 1549 1539 1581 1593 1532 1534 1584 1461 1536 1539 1567 1567 1555 1584 1674 1557 1577 1569 1536 1521 1611 1502 1541 1476 1518 1496 1535 1588 1501 1489 1498 1520 1547 1533 1552 1561 1534 1487 1503 1528 1512 1530 1541 1555 1501 1498 1540 1534 1468 1507 1553 1566 1492 1504 1449 1534 1514 1471 1574 1483 1534 1517 1561 1477 1642 1501 1569 1532 1521 1529 1504 1584 1505 1511 1542 1522 1513 1509 1551 1569 1545 1565 1508 1536 1503 1553 1521 1543 1470 1548 1519 1512 1506 1583 1465 1581 1432 1542 1564 1475 1541 1519 1504 1485 1503 1566 1468 1546 1519 1511 1542 1561 1560 1503 1529 1498 1520 1638 1461 1409 1525 1484 1490 1544 1512 1501 1474 1507 1499 1508 1527 1533 1560 1481 1489 1524 1553 1535 1531 1555 1522 1544 1515 1513 1483 1549 1503 1468 1560 1543 1486 1473 1492 1489 1469 1517 1501 1543 1510 1518 1493 1583 1500 1587 1525 1577 1495 1584 1564 1463 1547 1540 1417 1508 1487 1504 1497 1502 1486 1549 1439 1562 1506 1522 1557 1443 1446 1513 1497 1477 1513 1534 1525 1497 1532 1525 1479 1520 1599 1516 1509 1509 1484 1484 1564 1504 1547 1556 1481 1558 1553 1480 1534 1465 1553 1543 1491 1538 1519 1512 1493 1541 1474 1537 1550 1528 1532 1402 1510 1523 1518 1533 1536 1450 1494 1495 1534 1594 1606 1540 1506 1508 1523 1549 1500 1591 1491 1532 1537 1576 1609 1525 1515 1580 1549 1570 1497 1604 1478 1596 1556 1555 1506 1506 1527 1529 1493 1574 1517 1572 1523 1621 1550 1548 1544 1563 1588 1492 1539 1571 1556 1560 1579 1638 1561 1564 1622 1550 1585 1590 1590 1601 1703 1619 1590 1669 1714 1669 1679 1617 1683 1708 1712 1666 1830 1741 1777 1794 1870 1807 1901 1913 1933 1964 2027 2112 2222 2198 2365 2388 2758 2899 3022 3228 3403 3675 3766 4064 4441 4610 4764 5074 5247 5394 5725 5718 5823 5689 5805 5765 5616 5777 5803 5795 5818 5848 5666 5596 5504 5205 4943 4673 4379 4229 3890 3619 3353 3233 3242 3080 2870 2822 2529 2487 2307 2279 2251 2000 1935 1874 1869 1827 1734 1730 1765 1735 1664 1748 1718 1741 1671 1672 1701 1649 1726 1747 1666 1664 1680 1730 1633 1663 1693 1730 1673 1698 1723 1724 1732 1713 1715 1694 1769 1806 1698 1664 1760 1720 1661 1725 1778 1731 1767 1651 1644 1552 1692 1688 1736 1583 1652 1638 1640 1585 1639 1607 1620 1599 1553 1540 1548 1655 1522 1597 1599 1606 1503 1508 1547 1572 1539 1581 1534 1520 1486 1576 1504 1521 1509 1561 1477 1508 1462 1582 1443 1515 1510 1558 1532 1557 1541 1531 1546 1505 1574 1525 1539 1547 1554 1559 1542 1542 1527 1514 1431 1536 1507 1450 1450 1482 1463 1438 1444 1469 1555 1507 1482 1506 1506 1469 1498 1550 1459 1500 1499 1526 1503 1536 1566 1551 1485 1506 1466 1477 1424 1487 1487 1501 1492 1448 1512 1465 1486 1509 1505 1578 1438 1547 1505 1453 1478 1513 1532 1554 1466 1548 1601 1545 1471 1475 1484 1501 1476 1498 1505 1603 1519 1437 1513 1552 1590 1535 1550 1521 1535 1513 1521 1506 1564 1542 1523 1539 1501 1545 1501 1526 1465 1490 1511 1517 1455 1569 1568 1562 1505 1468 1535 1528 1457 1547 1475 1516 1434 1524 1522 1505 1497 1470 1519 1553 1597 1533 1508 1456 1447 1466 1531 1488 1497 1445 1472 1533 1501 1533 1472 1506 1433 1498 1454 1408 1486 1524 1471 1473 1505 1501 1511 1482 1456 1437 1535 1497 1485 1471 1491 1498 1478 1500 1454 1461 1466 1440 1510 1494 1487 1428 1467 1465 1442 1510 1493 1459 1468 1473 1453 1504 1526 1480 1527 1512 1541 1446 1480 1471 1542 1495 1446 1429 1439 1508 1453 1513 1512 1518 1473 1459 1529 1568 1567 1507 1458 1544 1443 1449 1443 1427 1470 1501 1547 1487 1492 1488 1406 1474 1477 1524 1517 1494 1504 1491 1529 1501 1482 1516 1487 1484 1495 1435 1524 1425 1524 1475 1475 1480 1479 1543 1545 1514 1456 1427 1399 1463 1478 1501 1510 1542 1474 1517 1526 1498 1440 1514 1431 1491 1559 1444 1504 1496 1486 1441 1507 1489 1563 1444 1510 1535 1492 1533 1485 1520 1510 1530 1476 1524 1463 1464 1482 1473 1561 1533 1489 1438 1437 1488 1494 1497 1518 1523 1603 1468 1546 1522 1404 1489 1386 1482 1515 1484 1424 1434 1513 1452 1556 1502 1480 1510 1467 1432 1479 1553 1570 1463 1539 1486 1513 1437 1433 1480 1416 1516 1482 1529 1496 1498 1511 1531 1471 1480 1479 1452 1485 1428 1481 1537 1463 1579 1433 1552 1557 1511 1468 1543 1510 1489 1504 1472 1504 1487 1511 1498 1623 1456 1537 1489 1540 1510 1513 1510 1530 1595 1573 1535 1596 1544 1587 1550 1569 1539 1602 1499 1586 1558 1556 1545 1558 1521 1548 1594 1600 1619 1644 1599 1543 1620 1605 1646 1698 1670 1683 1747 1775 1766 1874 1886 1904 1992 2001 2013 2054 2230 2330 2524 2515 2775 2877 3008 3203 3367 3526 3633 3682 3887 3958 4082 3947 4049 4087 4128 4107 4085 4110 4159 4113 4128 4038 3920 3969 3808 3754 3523 3316 3220 3117 2847 2827 2721 2712 2566 2545 2444 2387 2258 2180 2150 2087 1910 1920 1901 1813 1793 1724 1732 1696 1706 1787 1741 1642 1653 1627 1715 1652 1620 1657 1751 1614 1694 1634 1622 1580 1633 1560 1597 1599 1646 1580 1600 1649 1593 1584 1637 1597 1696 1629 1606 1637 1657 1583 1594 1630 1615 1623 1588 1670 1627 1649 1659 1695 1678 1743 1764 1696 1888 1891 1852 2026 2042 2143 2318 2303 2413 2524 2728 2696 2909 3017 3192 3423 3488 3647 3794 3823 3948 3863 3992 3957 3991 3984 3995 4023 4143 4001 4130 4011 3906 3910 3897 3745 3518 3353 3260 2959 2835 2767 2671 2613 2573 2422 2520 2376 2195 2157 2080 2080 1948 1905 1803 1667 1710 1670 1690 1643 1628 1568 1503 1545 1592 1582 1602 1581 1508 1600 1471 1634 1603 1528 1624 1518 1540 1561 1516 1498 1513 1583 1552 1528 1575 1451 1533 1467 1584 1550 1485 1541 1462 1520 1459 1508 1472 1468 1572 1479 1446 1566 1543 1476 1443 1508 1475 1441 1492 1494 1504 1502 1525 1431 1500 1590 1583 1505 1516 1496 1457 1499 1451 1505 1449 1504 1510 1442 1475 1559 1490 1471 1453 1512 1461 1486 1521 1537 1456 1501 1405 1466 1420 1533 1465 1507 1526 1440 1542 1545 1504 1428 1518 1545 1495 1520 1527 1438 1495 1494 1549 1551 1553 1472 1557 1505 1500 1539 1496 1499 1561 1558 1538 1589 1580 1587 1588 1654 1598 1634 1603 1631 1635 1602 1665 1639 1577 1591 1602 1574 1560 1536 1581 1603 1550 1636 1550 1508 1524 1579 1489 1475 1476 1409 1391 1502 1469 1530 1556 1482 1451 1461 1500 1477 1553 1524 1442 1576 1528 1506 1460 1451 1482 1487 1499 1461 1483 1502 1451 1407 1428 1500 1497 1447 1442 1494 1462 1456 1438 1490 1414 1489 1507 1498 1476 1578 1482 1448 1482 1479 1432 1547 1514 1457 1487 1525 1501 1559 1557 1522 1584 1649 1524 1583 1608 1617 1458 1632 1637 1540 1568 1561 1551 1617 1627 1642 1525 1610 1562 1618 1566 1509 1538 1584 1565 1571 1597 1576 1624 1559 1553 1566 1548 1572 1555 1534 1534 1554 1526 1512 1590 1503 1501 1502 1522 1489 1548 1572 1576 1450 1522 1471 1504 1430 1559 1510 1614 1516 1536 1538 1468 1569 1499 1572 1549 1512 1513 1568 1582 1510 1507 1565 1536 1568 1560 1458 1565 1523 1522 1546 1580 1590 1501 1582 1528 1554 1590 1556 1556 1552 1549 1532 1491 1486 1507 1506 1509 1532 1558 1557 1533 1504 1519 1514 1521 1604 1565 1511 1536 1514 1571 1542 1599 1550 1593 1524 1503 1586 1507 1553 1531 1498 1529 1525 1525 1550 1554 1589 1562 1610 1538 1494 1537 1535 1525 1579 1558 1513 1574 1567 1503 1528 1495 1475 1522 1503 1570 1500 1494 1482 1524 1473 1523 1530 1421 1556 1469 1501 1509 1476 1479 1471 1544 1421 1551 1438 1526 1458 1519 1472 1519 1454 1626 1552 1564 1557 1501 1521 1589 1561 1614 1555 1500 1572 1603 1631 1563 1544 1639 1639 1514 1593 1548 1601 1619 1629 1620 1716 1599 1601 1633 1624 1626 1599 1539 1643 1588 1598 1610 1515 1610 1530 1559 1593 1516 1545 1571 1500 1500 1527 1532 1472 1466 1574 1476 1550 1482 1510 1489 1506 1443 1483 1477 1524 1485 1478 1427 1532 1463 1491 1460 1457 1462 1539 1512 1458 1513 1439 1493 1515 1401 1494 1439 1368 1530 1462 1491 1446 1540 1404 1435 1480 1480 1416 1423 1545 1400 1472 1457 1429 1472 1455 1447 1519 1485 1483 1495 1432 1503 1489 1480 1452 1423 1460 1488 1519 1509 1430 1500 1478 1442 1474 1546 1517 1516 1555 1524 1491 1438 1515 1558 1386 1520 1478 1528 1458 1571 1471 1509 1478 1555 1463 1573 1519 1527 1524 1552 1441 1547 1506 1546 1529 1566 1571 1521 1526 1520 1569 1464 1540 1554 1552 1519 1615 1490 1597 1558 1501 1577 1575 1554 1564 1505 1519 1549 1613 1559 1520 1592 1550 1584 1594 1567 1636 1555 1520 1588 1572 1540 1490 1574 1505 1582 1454 1507 1507 1523 1470 1517 1591 1483 1481 1517 1524 1540 1489 1613 1541 1502 1558 1566 1512 1556 1539 1551 1666 1569 1596 1611 1486 1575 1645 1510 1590 1684 1629 1654 1747 1677 1803 1754 1868 1802 1797 1916 1856 2003 1855 1886 1962 1957 2004 1904 2056 1972 1985 2043 2019 2001 1962 1974 2046 2078 1983 1981 2045 1940 1877 1907 1884 1923 1928 1908 1894 1923 1979 1951 1940 1925 1984 1987 2039 2101 2114 2103 2083 2248 2325 2482 2446 2594 2675 2777 2956 3078 3249 3327 3578 3676 3859 3920 4019 4116 4177 4328 4374 4416 4599 4614 4808 4866 4795 5111 5027 5172 5130 5098 5054 5100 5088 4927 4887 4882 4802 4710 4727 4735 4661 4615 4460 4397 4423 4299 4109 4041 3871 3788 3700 3440 3341 3217 3229 3080 2936 2917 2867 2781 2728 2491 2638 2402 2438 2348 2274 2281 2064 2207 2020 2073 1932 1943 2018 1854 1860 1879 1814 1784 1739 1784 1707 1718 1808 1708 1627 1667 1666 1728 1650 1652 1598 1660 1630 1604 1632 1673 1697 1670 1555 1576 1622 1621 1661 1621 1645 1512 1606 1597 1570 1544 1506 1543 1570 1566 1546 1550 1537 1479 1490 1549 1542 1537 1566 1504 1587 1513 1488 1503 1500 1465 1507 1482 1498 1565 1463 1498 1468 1523 1528 1494 1520 1488 1565 1494 1515 1420 1504 1454 1416 1436 1502 1457 1421 1509 1495 1496 1530 1466 1462 1491 1535 1444 1505 1510 1409 1420 1430 1432 1527 1445 1537 1416 1495 1407 1527 1445 1503 1477 1463 1546 1513 1412 1464 1472 1479 1529 1449 1503 1417 1455 1458 1410 1526 1491 1512 1481 1520 1450 1508 1525 1461 1485 1495 1506 1480 1454 1449 1475 1509 1484 1391 1434 1466 1413 1471 1516 1558 1490 1481 1502 1498 1466 1544 1560 1459 1508 1521 1478 1460 1404 1427 1483 1437 1473 1473 1472 1521 1542 1467 1496 1395 1490 1519 1474 1498 1439 1485 1485 1429 1511 1440 1420 1511 1444 1485 1494 1434 1528 1416 1475 1535 1597 1455 1554 1500 1436 1505 1542 1473 1506 1520 1458 1536 1516 1504 1460 1580 1569 1524 1507 1539 1549 1493 1618 1545 1538 1377 1524 1523 1497 1488 1476 1534 1441 1551 1452 1476 1529 1445 1484 1465 1457 1509 1471 1500 1475 1506 1415 1472 1528 1447 1472 1472 1503 1516 1409 1459 1455 1478 1422 1501 1422 1458 1483 1481 1484 1439 1534 1503 1423 1428 1431 1449 1518 1481 1434 1437 1372 1479 1447 1521 1436 1466 1465 1479 1467 1395 1441 1435 1412 1437 1475 1499 1428 1483 1481 1469 1402 1496 1476 1478 1574 1489 1526 1439 1424 1475 1501 1490 1437 1458 1422 1415 1487 1432 1468 1491 1458 1423 1420 1389 1443 1434 1409 1421 1423 1450 1398 1436 1468 1523 1506 1485 1453 1482 1488 1466 1531 1537 1395 1517 1396 1493 1457 1467 1536 1444 1378 1505 1408 1469 1438 1459 1466 1418 1493 1364 1473 1509 1477 1457 1460 1477 1467 1481 1526 1448 1436 1478 1388 1475 1472 1380 1435 1522 1429 1463 1454 1467 1428 1445 1362 1434 1458 1561 1494 1480 1487 1461 1477 1500 1394 1457 1443 1411 1453 1446 1457 1483 1452 1407 1467 1424 1440 1381 1485 1501 1468 1426 1432 1381 1464 1480 1415 1426 1434 1462 1443 1444 1460 1526 1445 1471 1492 1436 1493 1452 1458 1452 1399 1391 1378 1419 1541 1451 1426 1426 1432 1508 1443 1535 1402 1467 1454 1475 1460 1530 1458 1419 1463 1460 1435 1474 1438 1383 1465 1398 1472 1425 1504 1527 1477 1522 1532 1443 1576 1467 1411 1443 1453 1515 1517 1450 1470 1506 1423 1516 1463 1484 1535 1494 1429 1513 1514 1446 1558 1561 1514 1460 1584 1538 1612 1527 1564 1661 1633 1696 1707 1695 1788 1849 1750 1815 1910 1952 1992 2095 2072 2195 2249 2278 2214 2340 2258 2225 2323 2241 2270 2263 2201 2195 2259 2170 2270 2214 2234 2262 2074 2094 2009 2043 1963 1987 1955 1842 1850 1911 1884 1761 1891 1783 1722 1681 1682 1721 1641 1660 1637 1559 1575 1625 1570 1552 1528 1444 1532 1505 1513 1526 1574 1509 1552 1516 1404 1513 1516 1401 1519 1464 1491 1487 1469 1424 1518 1501 1450 1494 1500 1494 1476 1463 1417 1500 1485 1507 1509 1436 1496 1478 1488 1482 1441 1491 1381 1463 1528 1524 1538 1548 1509 1531 1492 1547 1496 1497 1517 1502 1529 1462 1481 1454 1578 1504 1511 1542 1544 1499 1525 1478 1488 1522 1463 1500 1511 1453 1529 1545 1560 1573 1546 1578 1543 1600 1582 1562 1672 1650 1696 1756 1826 1654 1805 1879 1863 1953 1999 2064 2119 2130 2275 2247 2173 2242 2391 2272 2232 2345 2296 2316 2307 2329 2310 2317 2322 2330 2298 2288 2133 2110 2080 2071 2103 1932 2038 1998 1856 1867 1776 1903 1823 1787 1824 1749 1773 1730 1676 1623 1589 1611 1580 1523 1576 1467 1550 1487 1523 1544 1472 1548 1494 1460 1507 1477 1533 1512 1503 1470 1490 1441 1410 1530 1487 1445 1348 1527 1476 1398 1412 1389 1485 1480 1429 1425 1364 1442 1488 1425 1454 1399 1465 1426 1482 1458 1450 1447 1394 1472 1497 1431 1435 1512 1430 1423 1452 1425 1454 1481 1430 1509 1380 1395 1376 1445 1371 1424 1433 1473 1491 1463 1436 1395 1447 1408 1433 1467 1427 1356 1429 1428 1377 1481 1487 1405 1490 1420 1372 1475 1475 1425 1435 1431 1524 1461 1459 1462 1431 1468 1430 1511 1459 1514 1467 1471 1463 1470 1480 1462 1455 1429 1449 1513 1401 1483 1521 1406 1435 1426 1498 1398 1441 1445 1429 1399 1455 1495 1461 1500 1436 1537 1516 1482 1406 1415 1413 1506 1383 1432 1403 1343 1409 1495 1486 1466 1538 1483 1391 1483 1518 1418 1407 1414 1410 1440 1422 1466 1386 1566 1494 1412 1427 1441 1394 1462 1554 1479 1489 1465 1439 1426 1392 1414 1423 1458 1464 1441 1450 1459 1438 1452 1488 1470 1394 1443 1479 1420 1460 1488 1386 1526 1430 1408 1397 1460 1355 1388 1411 1443 1430 1434 1439 1412 1415 1534 1456 1449 1385 1467 1457 1485 1473 1399 1464 1444 1414 1455 1383 1444 1458 1412 1456 1346 1470 1450 1417 1474 1379 1444 1384 1412 1449 1447 1493 1479 1460 1438 1446 1467 1403 1432 1484 1483 1490 1423 1467 1451 1413 1402 1457 1428 1444 1369 1445 1407 1481 1443 1431 1420 1507 1436 1500 1496 1459 1434 1468 1474 1429 1514 1525 1512 1434 1486 1478 1412 1522 1487 1472 1486 1510 1470 1497 1501 1487 1488 1467 1510 1423 1542 1460 1545 1547 1509 1575 1516 1500 1590 1453 1501 1488 1560 1527 1512 1602 1535 1578 1450 1580 1579 1621 1586 1591 1564 1510 1598 1566 1541 1536 1592 1512 1555 1528 1511 1556 1576 1608 1594 1485 1460 1515 1602 1524 1540 1460 1506 1514 1467 1579 1525 1526 1549 1533 1478 1527 1479 1492 1485 1505 1454 1457 1528 1466 1507 1539 1502 1522 1433 1527 1470 1539 1478 1541 1551 1521 1464 1576 1538 1507 1598 1513 1610 1529 1494 1576 1616 1571 1585 1674 1600 1631 1643 1553 1692 1707 1695 1733 1793 1906 1952 1916 2017 2153 2088 2222 2235 2411 2570 2512 2628 2752 2812 2860 2787 2834 2922 2913 2788 3004 2863 2915 2957 2851 2939 2917 2844 2902 2798 2814 2778 2715 2700 2737 2729 2740 2605 2709 2742 2808 2652 2702 2736 2839 2763 2749 2712 2740 2691 2557 2510 2477 2579 2508 2404 2443 2500 2425 2432 2356 2333 2215 2278 2274 2235 2255 2192 2169 2133 2090 2051 1993 2023 1968 1989 1958 1930 1946 1898 1820 1867 1857 1774 1819 1782 1792 1673 1659 1751 1768 1770 1746 1663 1763 1750 1709 1869 1794 1897 1810 1798 1826 1887 1791 1884 1864 1897 1837 1909 1895 1828 1821 1872 1821 1885 1891 1882 1791 1793 1709 1769 1789 1748 1701 1699 1661 1712 1681 1670 1592 1691 1638 1637 1641 1612 1669 1654 1615 1582 1588 1537 1522 1540 1470 1643 1487 1523 1480 1495 1509 1488 1474 1520 1499 1502 1464 1474 1433 1471 1413 1432 1493 1454 1415 1485 1427 1422 1422 1443 1459 1381 1473 1482 1414 1410 1483 1386 1445 1475 1434 1450 1460 1359 1423 1436 1508 1425 1419 1440 1450 1442 1459 1447 1487 1522 1349 1478 1434 1488 1447 1391 1461 1370 1487 1420 1480 1473 1471 1432 1399 1478 1505 1469 1469 1432 1423 1420 1412 1449 1435 1400 1418 1403 1393 1389 1391 1447 1383 1507 1410 1446 1518 1464 1436 1435 1474 1452 1459 1398 1527 1375 1431 1497 1512 1492 1388 1395 1454 1396 1422 1351 1465 1419 1488 1503 1446 1466 1532 1437 1458 1406 1459 1415 1440 1473 1424 1435 1440 1410 1516 1387 1438 1437 1441 1449 1437 1413 1387 1411 1413 1370 1501 1447 1439 1500 1518 1495 1439 1398 1471 1401 1406 1407 1427 1400 1413 1457 1445 1399 1436 1457 1465 1416 1408 1488 1427 1408 1410 1424 1389 1355 1515 1460 1401 1447 1468 1460 1466 1412 1391 1400 1416 1451 1519 1443 1477 1421 1306 1420 1493 1412 1386 1496 1445 1437 1410 1413 1427 1484 1395 1414 1435 1408 1420 1425 1413 1431 1441 1481 1457 1439 1467 1434 1452 1406 1478 1411 1421 1415 1463 1488 1501 1415 1415 1475 1360 1455 1425 1553 1472 1492 1504 1496 1458 1489 1536 1514 1535 1450 1502 1478 1507 1521 1514 1498 1573 1557 1544 1582 1506 1637 1549 1564 1587 1538 1626 1630 1654 1693 1766 1679 1679 1748 1818 1777 1819 1840 1856 1800 1930 1965 1959 1948 1985 1929 1953 1963 1961 1989 1986 1943 1893 1937 1957 1926 1985 1924 1870 1881 1944 1881 1956 1882 1804 1827 1894 1842 1846 1822 1825 1756 1834 1866 1674 1751 1675 1669 1740 1652 1679 1706 1651 1638 1642 1646 1544 1628 1601 1550 1603 1572 1662 1578 1564 1518 1510 1522 1533 1467 1417 1519 1478 1485 1494 1482 1484 1477 1504 1517 1396 1493 1493 1508 1440 1474 1450 1490 1406 1506 1519 1478 1416 1452 1559 1527 1497 1470 1488 1473 1423 1417 1427 1433 1401 1434 1434 1386 1434 1418 1424 1459 1421 1435 1454 1447 1439 1401 1426 1432 1410 1413 1441 1434 1507 1431 1477 1466 1427 1440 1468 1528 1501 1494 1409 1494 1470 1401 1490 1414 1481 1493 1486 1524 1520 1556 1530 1508 1508 1504 1551 1436 1443 1461 1551 1435 1448 1461 1483 1547 1444 1423 1432 1433 1512 1464 1474 1423 1420 1433 1457 1428 1451 1504 1431 1423 1372 1463 1446 1471 1471 1467 1457 1454 1518 1389 1381 1384 1371 1417 1496 1401 1416 1493 1487 1386 1451 1416 1405 1376 1448 1419 1432 1491 1440 1509 1351 1413 1447 1476 1418 1441 1440 1379 1434 1467 1433 1424 1474 1394 1522 1280 1412 1430 1401 1395 1412 1474 1393 1437 1332 1414 1459 1414 1466 1447 1504 1461 1436 1424 1450 1514 1469 1433 1418 1426 1491 1371 1454 1456 1434 1477 1485 1473 1488 1495 1447 1485 1419 1537 1463 1512 1435 1507 1522 1515 1457 1505 1547 1429 1544 1563 1578 1500 1612 1493 1510 1536 1540 1552 1583 1531 1512 1508 1462 1544 1422 1403 1560 1578 1576 1547 1520 1457 1543 1512 1563 1603 1608 1612 1638 1656 1562 1678 1694 1711 1821 1744 1795 1948 1908 1882 1988 2044 2057 2151 2129 2134 2162 2052 2069 2090 2035 2112 2015 2099 2125 2131 2043 1998 1965 1950 1885 1870 1784 1899 1869 1932 1868 1841 1909 1914 1835 1841 1860 1902 1840 1804 1819 1831 1776 1845 1718 1787 1776 1715 1771 1834 1771 1769 1788 1765 1806 1752 1782 1755 1753 1751 1724 1692 1684 1695 1708 1676 1649 1651 1600 1596 1647 1616 1646 1615 1625 1589 1678 1664 1606 1595 1605 1618 1591 1592 1582 1610 1519 1552 1522 1558 1486 1560 1447 1435 1467 1484 1428 1505 1472 1442 1416 1491 1469 1415 1391 1380 1459 1400 1455 1398 1454 1422 1526 1467 1422 1365 1517 1445 1410 1459 1485 1389 1419 1421 1432 1486 1503 1412 1407 1420 1435 1408 1383 1416 1400 1407 1458 1420 1406 1356 1444 1419 1440 1475 1401 1383 1366 1398 1399 1460 1467 1424 1443 1471 1403 1402 1377 1372 1460 1422 1388 1399 1417 1426 1404 1410 1409 1422 1426 1379 1438 1449 1410 1389 1485 1420 1464 1414 1446 1437 1396 1375 1393 1416 1428 1419 1473 1411 1395 1432 1465 1403 1385 1357 1398 1433 1466 1434 1378 1383 1404 1518 1459 1459 1460 1356 1336 1397 1418 1520 1368 1375 1397 1319 1419 1398 1437 1401 1372 1390 1342 1428 1433 1415 1437 1480 1371 1391 1461 1380 1431 1388 1384 1490 1435 1464 1455 1431 1475 1491 1408 1413 1410 1431 1376 1465 1426 1472 1446 1446 1391 1342 1369 1438 1379 1444 1381 1455 1494 1376 1461 1378 1422 1516 1443 1443 1403 1408 1468 1470 1396 1405 1376 1418 1451 1501 1464 1370 1432 1452 1435 1392 1415 1351 1365 1394 1417 1425 1478 1371 1393 1403 1416 1427 1355 1419 1436 1411 1425 1385 1403 1345 1379 1448 1480 1388 1443 1486 1361 1444 1445 1384 1476 1411 1379 1461 1470 1414 1422 1314 1404 1412 1388 1412 1449 1420 1469 1479 1425 1469 1475 1364 1413 1445 1435 1291 1395 1396 1370 1457 1387 1416 1395 1401 1420 1377 1463 1410 1411 1412 1424 1452 1441 1422 1484 1482 1463 1446 1412 1480 1464 1450 1483 1382 1496 1395 1394 1452 1410 1405 1425 1418 1390 1554 1454 1490 1427 1412 1479 1439 1423 1459 1383 1429 1373 1439 1453 1322 1391 1402 1442 1400 1400 1473 1420 1414 1386 1440 1469 1394 1407 1454 1397 1420 1389 1428 1498 1402 1517 1451 1386 1468 1448 1441 1456 1455 1410 1393 1469 1381 1418 1408 1377 1455 1477 1442 1367 1350 1444 1380 1408 1406 1395 1419 1445 1415 1369 1398 1380 1366 1470 1380 1366 1324 1450 1391 1353 1390 1453 1383 1452 1468 1385 1394 1422 1507 1367 1406 1477 1457 1493 1414 1412 1441 1349 1417 1372 1412 1418 1461 1360 1354 1400 1400 1425 1490 1390 1399 1409 1477 1439 1474 1406 1478 1354 1468 1372 1454 1454 1388 1389 1422 1459 1431 1399 1405 1486 1451 1419 1510 1422 1416 1366 1376 1437 1392 1407 1421 1378 1501 1394 1371 1314 1424 1447 1430 1426 1378 1399 1424 1350 1489 1421 1468 1406 1324 1444 1362 1389 1415 1410 1401 1424 1461 1396 1324 1389 1462 1377 1379 1433 1451 1434 1470 1366 1443 1456 1515 1405 1462 1401 1465 1425 1410 1463 1334 1415 1377 1402 1364 1395 1378 1415 1464 1400 1382 1416 1367 1415 1435 1420 1463 1398 1366 1397 1398 1471 1418 1429 1354 1442 1358 1481 1397 1480 1369 1378 1393 1422 1433 1441 1342 1396 1362 1446 1369 1379 1425 1470 1416 1417 1424 1434 1424 1401 1373 1386 1470 1410 1414 1446 1385 1340 1372 1439 1330 1400 1374 1363 1415 1430 1409 1397 1401 1384 1448 1419 1433 1416 1403 1440 1448 1370 1446 1390 1320 1375 1441 1409 1304 1394 1414 1419 1443 1474 1392 1446 1387 1470 1452 1476 1446 1372 1391 1449 1459 1343 1342 1364 1391 1434 1398 1400 1360 1406 1408 1377 1488 1449 1481 1376 1486 1386 1376 1369 1414 1445 1393 1433 1344 1449 1473 1405 1408 1400 1444 1385 1353 1380 1435 1351 1379 1434 1397 1420 1472 1419 1420 1425 1372 1367 1394 1425 1378 1409 1361 1439 1363 1369 1425 1427 1513 1353 1399 1414 1413 1365 1405 1440 1396 1386 1363 1407 1401 1419 1460 1372 1482 1430 1389 1381 1376 1336 1385 1320 1373 1444 1413 1415 1385 1387 1377 1456 1396 1367 1379 1402 1378 1367 1312 1389 1429 1369 1380 1348 1377 1378 1433 1426 1335 1421 1431 1532 1442 1369 1408 1436 1432 1458 1464 1405 1363 1399 1374 1337 1444 1446 1359 1353 1385 1398 1449 1406 1436 1353 1428 1439 1385 1401 1423 1405 1447 1351 1332 1477 1416 1433 1474 1350 1362 1398 1421 1422 1420 1410 1397 1396 1425 1396 1331 1311 1376 1479 1414 1381 1335 1442 1341 1419 1421 1426 1387 1422 1384 1438 1376 1358 1314 1469 1383 1450 1441 1409 1437 1440 1453 1451 1400 1437 1407 1365 1386 1383 1393 1451 1340 1407 1553 1447 1417 1338 1434 1461 1441 1440 1405 1508 1407 1494 1420 1425 1398 1438 1388 1420 1381 1368 1437 1455 1390 1349 1467 1350 1423 1413 1387 1374 1396 1349 1410 1409 1387 1426 1383 1389 1444 1407 1465 1438 1449 1385 1385 1472 1414 1459 1372 1434 1435 1563 1438 1451 1428 1458 1455 1471 1397 1426 1493 1372 1383 1389 1449 1424 1368 1426 1448 1412 1449 1394 1462 1535 1477 1483 1396 1443 1432 1437 1415 1384 1405 1418 1468 1488 1471 1463 1377 1461 1437 1390 1438 1440 1429 1391 1410 1484 1389 1422 1454 1429 1457 1412 1431 1388 1397 1463 1445 1400 1423 1404 1486 1403 1394 1482 1442 1443 1405 1437 1501 1465 1421 1457 1489 1501 1498 1501 1480 1470 1516 1576 1514 1495 1527 1473 1527 1492 1507 1450 1494 1441 1524 1513 1517 1444 1543 1502 1530 1512 1474 1440 1472 1466 1573 1531 1490 1583 1408 1467 1488 1455 1511 1463 1529 1442 1425 1485 1484 1531 1506 1421 1387 1410 1449 1464 1533 1417 1485 1466 1427 1430 1486 1441 1413 1391 1448 1458 1446 1466 1477 1411 1461 1486 1347 1420 1451 1363 1410 1481 1421 1471 1520 1538 1473 1423 1464 1463 1530 1574 1534 1572 1684 1655 1600 1569 1635 1659 1736 1654 1779 1851 1702 1819 1718 1848 1715 1825 1773 1827 1752 1732 1626 1653 1626 1667 1599 1673 1560 1590 1587 1603 1590 1618 1618 1584 1568 1599 1626 1627 1653 1645 1654 1688 1569 1637 1568 1603 1599 1513 1609 1579 1619 1545 1583 1497 1551 1513 1652 1535 1516 1504 1503 1550 1428 1516 1476 1587 1464 1551 1482 1565 1522 1510 1542 1608 1499 1559 1588 1542 1623 1724 1637 1645 1746 1769 1703 1771 1793 1759 1865 1927 1905 1927 1960 1929 1936 2019 1879 2021 1977 2077 1961 2033 1958 1946 2019 1814 2025 1821 1856 1858 1897 1830 1811 1720 1774 1780 1724 1679 1812 1786 1773 1761 1770 1820 1842 1818 1783 1798 1729 1729 1705 1720 1719 1727 1754 1678 1682 1650 1615 1558 1596 1538 1535 1555 1505 1589 1514 1528 1514 1483 1482 1523 1470 1443 1481 1453 1486 1393 1470 1402 1466 1397 1492 1501 1443 1515 1436 1426 1440 1438 1475 1415 1428 1503 1410 1438 1421 1432 1400 1423 1390 1415 1459 1435 1406 1369 1445 1449 1417 1451 1550 1433 1384 1423 1404 1416 1407 1418 1484 1422 1386 1497 1473 1493 1372 1425 1356 1407 1446 1459 1382 1437 1447 1510 1443 1477 1401 1381 1374 1436 1394 1406 1359 1443 1426 1440 1334 1427 1392 1450 1427 1453 1411 1407 1439 1475 1357 1479 1426 1458 1443 1434 1385 1415 1418 1391 1389 1436 1381 1370 1366 1423 1439 1393 1485 1412 1400 1311 1413 1407 1421 1422 1414 1409 1447 1309 1425 1452 1461 1439 1385 1442 1485 1403 1446 1382 1412 1493 1395 1432 1472 1342 1512 1343 1399 1403 1411 1456 1454 1495 1442 1381 1455 1424 1488 1447 1417 1499 1456 1490 1436 1344 1380 1389 1390 1428 1418 1456 1468 1426 1457 1446 1430 1398 1379 1378 1481 1412 1479 1395 1461 1488 1491 1464 1412 1519 1410 1513 1383 1416 1462 1419 1376 1409 1441 1480 1417 1425 1360 1462 1379 1505 1398 1455 1438 1450 1365 1401 1371 1371 1462 1517 1458 1460 1440 1385 1427 1525 1467 1388 1504 1415 1539 1460 1431 1428 1501 1393 1437 1461 1492 1491 1479 1528 1484 1476 1534 1507 1523 1584 1572 1571 1572 1557 1643 1617 1579 1663 1584 1726 1649 1649 1726 1622 1720 1618 1632 1604 1591 1646 1654 1591 1673 1565 1612 1578 1616 1568 1680 1563 1586 1550 1567 1577 1530 1526 1585 1526 1552 1528 1548 1494 1520 1560 1495 1542 1576 1559 1551 1627 1526 1570 1582 1500 1542 1487 1484 1448 1517 1437 1466 1455 1530 1470 1594 1519 1503 1473 1462 1475 1453 1473 1360 1516 1461 1474 1429 1442 1386 1430 1434 1446 1472 1393 1446 1466 1500 1456 1425 1453 1436 1414 1424 1404 1378 1499 1379 1366 1452 1434 1388 1452 1459 1426 1494 1462 1481 1484 1476 1473 1428 1490 1409 1502 1457 1449 1398 1380 1462 1470 1466 1486 1440 1418 1447 1447 1520 1470 1500 1407 1459 1492 1466 1541 1514 1458 1514 1517 1531 1450 1627 1581 1551 1585 1618 1622 1611 1632 1581 1589 1611 1569 1560 1580 1607 1518 1513 1572 1513</counts>
			</dataPoints>
		</scan>
	</xrdMeasurement>
</xrdMeasurements>