File: dataset/precursor_mixture/SnO2_CaCO3_Li3PO4.2-min.xrdml
<?xml version="1.0"?>
<xrdMeasurements xmlns="http://www.xrdml.com/XRDMeasurement/2.2" xmlns:xsi="http://www.w3.org/2001/XMLSchema-instance" xsi:schemaLocation="http://www.xrdml.com/XRDMeasurement/2.2 http://www.xrdml.com/XRDMeasurement/2.2/XRDMeasurement.xsd" status="Completed" recordIdentifier="{7898A3CF-6608-438E-A448-2A31FEAC3758}">
	<comment>
		<entry/>
	</comment>
	<sample type="To be analyzed">
		<id>dara-45-1</id>
		<name></name>
		<preparedBy></preparedBy>
	</sample>
	<xrdMeasurement measurementType="Scan" status="Completed" sampleMode="Reflection">
		<usedWavelength intended="K-Alpha 1">
			<kAlpha1 unit="Angstrom">1.5405980</kAlpha1>
			<kAlpha2 unit="Angstrom">1.5444260</kAlpha2>
			<kBeta unit="Angstrom">1.3922500</kBeta>
			<ratioKAlpha2KAlpha1>0.5000</ratioKAlpha2KAlpha1>
		</usedWavelength>
		<incidentBeamPath>
			<radius unit="mm">145.00</radius>
			<xRayTube id="1010048" name="Empyrean Cu LFF HR (9430 033 7310x) DK430614">
				<tension unit="kV">40.0</tension>
				<current unit="mA">15.0</current>
				<anodeMaterial>Cu</anodeMaterial>
				<focus type="Line">
					<length unit="mm">12.0</length>
					<width unit="mm">0.4</width>
					<takeOffAngle unit="deg">6.0</takeOffAngle>
				</focus>
			</xRayTube>
			<filter id="20010004" name="Beta-filter Nickel">
				<material>Ni</material>
				<thickness unit="mm">0.020</thickness>
			</filter>
			<sollerSlit id="21010002" name="Soller slits 0.04 rad.">
				<opening unit="rad">0.0400</opening>
			</sollerSlit>
			<mask id="22031000" name="Fixed mask 13 mm">
				<width unit="mm">9.00</width>
			</mask>
			<divergenceSlit id="22120001" name="Divergence slit 1°" xsi:type="fixedDivergenceSlitType">
				<distanceToSample unit="mm">50.00</distanceToSample>
				<height unit="mm">1.52</height>
			</divergenceSlit>
		</incidentBeamPath>
		<beamKnife id="29030100" name="Beam knife low"/>
		<sampleMovement xsi:type="spinningSampleMovementType">
			<spinnerRevolutionTime unit="seconds">1.0</spinnerRevolutionTime>
		</sampleMovement>
		<diffractedBeamPath>
			<radius unit="mm">145.00</radius>
			<antiScatterSlit id="22090040" name="AS slit 9 mm" xsi:type="fixedAntiScatterSlitType">
				<height unit="mm">9.00</height>
			</antiScatterSlit>
			<sollerSlit id="21020003" name="Large Soller slits 0.04 rad.">
				<opening unit="rad">0.0400</opening>
			</sollerSlit>
			<filter id="20030001" name="Large beta-filter Nickel">
				<material>Ni</material>
				<thickness unit="mm">0.020</thickness>
			</filter>
			<detector id="7010019" name="PIXcel1D-Medipix3 detector" xsi:type="rtmsDetectorType">
				<phd unit="keV">
					<lowerLevel>4.0</lowerLevel>
					<upperLevel>11.3</upperLevel>
				</phd>
				<mode>Scanning</mode>
				<activeLength unit="deg">1.021</activeLength>
			</detector>
		</diffractedBeamPath>
		<scan appendNumber="0" mode="Continuous" scanAxis="Gonio" status="Completed">
			<header>
				<startTimeStamp>2024-02-18T15:52:45-08:00</startTimeStamp>
				<endTimeStamp>2024-02-18T15:55:07-08:00</endTimeStamp>
				<author>
					<name>AutomatedUser</name>
				</author>
				<source>
					<applicationSoftware version="1.4b (28)">PANalytical Aeris Instrument Suite</applicationSoftware>
					<instrumentControlSoftware version="2.0.0 20210224">AERIS</instrumentControlSoftware>
					<instrumentID>950485</instrumentID>
				</source>
			</header>
			<dataPoints>
				<positions axis="2Theta" unit="deg">
					<startPosition>10.02173288</startPosition>
					<endPosition>139.98435528</endPosition>
				</positions>
				<positions axis="Omega" unit="deg">
					<startPosition>5.01086644</startPosition>
					<endPosition>69.99217764</endPosition>
				</positions>
				<commonCountingTime unit="seconds">1.551</commonCountingTime>
				<counts unit="counts">398 379 363 344 360 356 366 333 375 317 328 346 321 356 353 336 376 352 331 336 345 322 306 346 358 330 354 372 359 286 335 326 276 310 282 309 302 286 297 291 317 312 311 279 291 293 294 276 264 245 243 279 308 293 289 323 275 304 298 281 268 266 271 280 285 247 269 246 240 267 292 280 259 265 249 248 240 241 251 248 230 245 253 239 227 267 213 261 237 245 252 253 215 263 226 226 224 204 216 245 271 244 223 230 238 207 231 223 223 210 216 235 242 206 191 215 205 225 215 200 231 209 219 194 210 209 237 225 248 192 231 201 195 195 194 213 213 224 192 191 189 177 187 194 237 231 199 176 176 172 189 174 199 237 236 225 242 176 210 192 217 194 177 178 188 196 183 178 194 174 193 176 143 170 180 169 154 161 175 176 200 184 163 178 150 183 179 147 198 147 175 176 147 189 169 180 154 164 170 144 163 181 166 155 162 173 188 185 158 163 179 148 173 140 162 145 156 169 167 151 140 182 161 161 163 154 163 127 155 157 116 143 152 141 154 147 133 165 143 131 152 158 138 132 155 152 151 141 136 146 132 135 152 144 170 138 148 165 134 149 156 130 130 155 165 155 144 145 155 169 171 150 201 187 220 266 304 328 319 260 229 216 163 139 156 153 133 148 144 160 144 155 212 218 250 229 259 259 247 258 263 258 233 172 143 154 119 128 127 123 142 131 136 134 144 139 140 104 134 152 125 117 101 132 130 157 129 127 148 154 163 148 196 179 203 195 188 210 166 162 159 123 144 116 97 132 129 131 113 132 133 122 138 139 143 148 184 150 120 159 165 199 208 230 214 243 254 337 474 674 952 1497 2244 2854 2407 1746 1056 654 457 334 281 221 195 150 190 166 147 148 136 157 127 130 118 126 118 110 126 115 110 140 115 111 119 99 125 107 101 107 86 118 107 106 96 132 138 118 151 167 149 160 141 155 150 175 201 206 215 247 281 251 296 347 433 724 1331 3354 9808 9107 6154 2333 609 396 295 284 229 224 188 128 161 146 128 141 122 108 91 126 144 130 112 126 129 152 118 132 120 120 105 112 101 91 129 89 94 105 103 114 89 88 99 115 95 136 130 129 132 108 108 105 104 127 94 91 82 104 89 99 100 112 85 85 93 97 108 99 92 102 78 89 90 89 89 120 95 103 102 116 110 112 111 102 125 134 114 134 156 166 130 143 186 219 223 286 358 491 691 1122 1794 2270 2027 1630 1068 743 473 345 316 253 243 201 171 179 163 130 120 109 119 124 123 97 116 114 96 110 97 106 89 92 74 91 96 87 88 91 81 79 81 79 80 90 99 74 86 85 92 105 149 136 128 128 95 75 81 92 84 91 117 127 139 126 152 140 119 96 104 115 110 95 109 98 162 127 105 88 79 99 87 94 102 106 93 78 87 110 110 119 134 186 221 340 573 654 530 429 284 216 147 132 112 101 104 80 98 80 76 55 69 81 102 114 107 125 135 162 180 192 160 130 108 98 109 105 127 192 198 133 155 95 82 82 66 69 49 68 49 61 74 53 62 64 65 45 80 58 61 60 66 62 72 56 64 50 54 55 61 68 60 63 41 60 49 64 54 52 50 50 56 55 47 50 61 42 50 47 52 49 47 64 35 43 51 71 43 46 72 47 54 69 55 59 43 65 47 61 74 73 70 65 109 77 80 57 69 82 73 69 76 158 170 142 130 135 66 60 58 47 69 53 59 52 61 61 62 51 55 52 54 60 56 47 37 41 47 43 53 47 55 51 58 57 40 50 45 53 35 54 49 47 46 49 43 43 45 66 60 28 70 43 38 57 51 46 40 40 49 53 48 50 34 36 48 39 39 37 44 60 38 49 51 42 52 66 40 54 47 38 46 35 43 61 47 47 63 55 52 67 81 89 64 88 94 50 67 90 131 296 319 192 212 129 81 65 64 47 69 52 55 37 40 49 53 66 60 71 73 74 71 167 268 195 137 149 107 74 67 56 61 63 61 47 40 62 62 50 39 43 59 47 70 54 49 56 56 36 46 47 59 46 41 51 46 52 46 33 28 53 46 54 57 45 45 52 54 55 47 56 54 79 75 64 60 66 81 54 67 81 89 74 98 97 102 105 98 125 137 204 218 262 343 452 791 1294 1629 1235 1059 1032 687 455 273 190 147 148 119 102 92 80 78 66 68 67 70 51 57 50 55 49 47 52 51 47 53 55 47 37 58 48 41 33 47 57 42 40 35 37 39 59 49 42 52 41 43 50 53 52 39 47 38 60 51 67 64 68 66 73 76 132 161 222 305 371 357 274 257 221 145 122 82 66 80 64 39 42 44 52 53 50 44 48 59 47 41 40 48 45 46 31 48 43 47 41 39 41 43 50 49 53 48 53 48 56 63 50 59 60 39 33 42 39 48 51 45 52 57 74 70 62 63 69 115 84 81 78 83 80 84 83 133 172 190 170 123 116 134 102 92 77 71 58 61 61 49 49 45 37 52 44 53 38 47 48 51 32 42 38 45 46 43 46 52 40 29 40 39 38 25 32 47 19 40 44 45 56 26 49 51 43 35 40 37 43 34 33 36 50 36 52 57 67 44 50 79 96 110 74 60 89 68 73 140 263 291 138 147 205 161 79 91 86 88 83 72 74 93 73 70 92 126 158 236 325 297 244 237 224 174 110 101 84 72 58 48 59 47 58 43 36 37 44 49 33 36 44 45 47 48 55 54 40 32 46 42 43 47 46 35 48 40 53 39 41 44 49 55 52 54 41 47 38 41 51 39 61 53 45 69 61 51 84 91 107 124 221 217 278 341 234 240 216 182 149 139 75 79 77 55 73 56 61 52 54 56 64 89 122 86 82 124 131 172 226 310 369 328 257 234 218 209 144 106 90 84 68 57 49 58 46 45 36 33 38 35 39 24 36 34 43 39 38 40 35 35 39 38 29 41 32 27 37 23 36 31 34 38 38 34 40 52 32 43 48 39 32 34 28 40 39 22 30 44 45 31 40 30 21 25 27 29 28 35 36 26 33 28 48 45 34 36 57 36 30 42 28 25 30 39 24 32 34 31 20 30 43 22 38 29 30 47 36 44 36 39 44 41 32 46 42 36 34 36 30 25 34 38 49 45 57 73 70 84 121 163 213 146 118 106 114 103 86 62 59 40 30 31 35 47 49 25 29 24 32 42 33 17 37 51 45 40 29 36 29 34 33 25 35 35 42 51 63 42 35 34 35 41 51 41 47 40 43 42 41 40 37 33 46 42 40 49 44 41 38 43 40 49 51 40 27 37 39 33 29 25 39 30 34 35 38 36 47 23 21 20 25 29 39 26 33 41 42 28 34 28 19 20 34 21 31 26 18 26 27 36 21 35 30 30 33 34 22 20 24 39 32 35 49 30 36 29 32 20 32 40 31 34 39 31 39 29 30 34 40 40 47 67 69 47 33 36 46 51 41 39 21 29 21 27 24 20 33 31 36 29 36 24 22 31 28 31 34 40 36 43 47 58 55 43 101 133 235 264 193 161 144 148 144 133 91 81 61 51 44 40 46 38 38 41 31 38 40 30 38 27 34 37 35 18 49 21 39 48 31 23 23 39 36 33 33 37 30 40 41 25 35 41 43 33 49 42 47 47 37 50 63 100 84 70 66 71 59 76 69 66 90 64 46 42 44 68 43 39 31 39 35 30 40 33 38 37 39 31 35 35 29 35 29 26 41 36 32 35 19 29 40 27 36 30 29 34 23 27 33 34 44 47 51 55 49 58 54 87 141 183 187 142 119 111 117 129 106 83 73 48 50 34 29 33 37 29 34 32 31 36 37 27 30 43 42 41 33 30 40 37 38 25 26 26 19 31 29 18 28 40 30 27 19 26 29 26 26 22 34 45 27 22 35 28 20 35 25 26 33 34 34 31 23 40 19 33 29 38 28 26 34 26 42 40 49 47 51 51 92 103 64 69 58 60 53 58 50 44 43 23 33 19 30 25 32 39 30 37 13 33 29 28 29 38 18 22 21 42 26 28 22 26 31 28 33 45 41 29 35 25 27 44 39 35 25 30 41 41 49 42 47 45 93 87 127 187 178 189 126 96 105 97 124 135 93 74 63 51 57 49 43 56 44 45 61 47 55 82 70 129 146 206 175 150 121 98 103 130 134 122 81 63 47 36 49 43 32 47 44 33 43 23 33 31 27 24 25 39 41 24 35 36 35 37 35 40 22 24 29 36 29 24 22 29 41 31 28 40 25 52 63 53 56 90 87 94 101 84 65 71 67 71 74 60 39 32 39 25 32 38 31 33 20 18 20 21 30 16 26 15 35 25 35 25 37 40 39 38 46 30 27 39 51 59 68 49 31 37 32 45 43 32 40 37 30 17 25 31 22 35 49 43 43 48 61 69 80 94 108 85 95 76 62 75 59 51 53 61 52 46 23 33 36 31 33 31 39 24 26 30 34 34 31 31 24 24 38 32 24 44 39 32 42 26 35 34 27 27 23 25 19 34 23 32 25 21 23 23 27 37 19 13 19 28 16 30 24 29 20 26 41 29 31 32 42 54 108 140 120 68 51 35 48 54 91 84 66 36 34 34 34 32 30 21 35 24 24 26 32 27 23 29 22 27 28 24 36 37 29 28 23 25 28 25 22 27 27 34 26 30 23 27 31 38 37 16 29 28 15 21 34 35 22 26 16 23 21 19 29 25 20 26 21 15 10 16 24 27 38 22 21 14 13 33 24 26 26 34 30 21 28 35 22 34 35 30 19 32 27 31 22 26 27 38 31 33 16 29 26 27 30 30 29 28 32 31 45 43 40 36 29 29 19 14 19 29 45 30 31 34 32 28 22 21 29 21 21 23 31 25 25 22 30 27 21 29 27 30 31 18 29 19 38 23 23 23 22 25 27 41 45 32 35 48 39 18 28 45 32 26 25 19 22 28 34 41 30 30 25 32 37 23 20 23 31 33 28 23 42 31 29 39 38 35 26 34 36 39 17 31 26 28 46 49 55 47 25 53 62 64 77 122 136 150 178 168 199 158 164 120 119 102 116 117 117 107 81 82 59 67 42 59 34 32 41 43 35 33 36 35 34 38 40 34 38 31 32 36 40 36 43 24 32 33 21 19 27 30 44 18 35 38 31 35 23 30 37 45 36 34 52 24 30 33 31 36 32 33 33 27 34 22 27 32 28 38 31 37 43 42 40 38 52 68 74 78 94 83 73 57 43 45 54 49 53 71 74 48 51 36 39 26 37 37 32 32 18 22 27 32 24 27 23 36 22 35 35 29 34 21 28 29 25 27 35 31 37 26 24 38 22 37 31 43 36 43 33 24 27 38 32 34 62 61 53 50 60 81 79 87 80 84 66 65 52 50 63 79 71 99 81 58 49 48 35 35 46 60 40 45 74 60 69 96 131 157 179 176 156 116 93 102 85 94 83 122 94 84 107 90 80 59 47 46 47 47 56 45 34 46 38 51 26 35 15 17 32 27 28 18 30 18 21 37 25 32 39 29 29 45 45 23 31 28 36 31 31 31 34 33 38 36 36 35 37 32 46 51 24 40 29 35 37 30 27 43 31 40 33 66 37 40 39 28 29 32 39 44 43 32 23 26 37 23 31 40 34 28 30 23 31 19 35 38 23 34 45 29 32 39 44 57 43 53 48 46 41 41 48 45 40 35 45 43 64 50 40 49 69 68 86 125 128 143 149 170 155 141 141 135 136 99 97 105 104 98 115 95 107 97 104 73 67 56 46 40 40 45 40 43 29 41 32 29 38 37 22 46 32 21 29 28 43 21 26 25 26 26 42 26 16 21 40 26 30 36 25 40 33 22 29 24 31 41 36 22 25 20 34 30 20 25 28 20 26 14 28 18 30 25 34 30 26 21 26 32 29 24 33 36 23 32 33 29 34 23 42 29 32 29 36 36 31 28 20 38 28 30 24 35 36 40 34 19 36 22 23 35 22 28 44 40 34 22 38 29 38 24 37 21 36 28 30 29 20 23 40 29 25 33 40 22 36 38 25 39 42 37 41 36 32 32 26 24 23 31 39 40 34 33 35 45 27 45 31 24 32 27 34 29 35 28 26 41 35 43 33 28 44 38 27 32 23 36 35 33 41 37 40 39 36 37 50 53 41 56 66 71 57 77 115 127 121 158 175 111 116 105 99 73 84 89 78 84 64 75 85 118 117 97 73 80 52 49 60 46 46 50 49 43 40 40 36 40 29 36 45 32 36 45 33 38 37 32 38 40 32 36 25 32 33 35 40 28 38 20 32 33 35 40 23 36 32 35 32 36 35 36 32 47 44 48 41 39 45 60 62 60 58 56 62 66 36 41 53 40 48 43 38 52 52 53 41 44 38 38 49 44 38 16 32 27 24 43 27 38 41 28 36 41 30 22 25 24 28 29 45 34 23 33 35 30 38 26 26 35 43 31 27 39 24 38 19 43 34 41 27 47 45 32 27 39 45 30 26 43 45 42 38 45 46 38 41 51 52 50 54 63 51 81 97 101 117 117 110 113 94 104 90 76 65 58 59 71 75 72 67 60 72 73 76 67 88 65 49 57 59 48 42 47 41 34 43 37 34 36 32 43 41 39 41 35 44 35 22 36 37 33 32 38 46 43 28 37 30 33 41 19 35 36 39 30 33 31 24 38 58 34 33 38 32 32 33 44 25 26 44 49 24 26 30 36 39 41 33 26 40 46 38 32 41 35 50 13 31 30 50 25 32 42 39 28 29 40 33 35 21 43 29 37 27 29 34 35 39 39 36 34 31 27 33 35</counts>
			</dataPoints>
		</scan>
	</xrdMeasurement>
</xrdMeasurements>