File: dataset/precursor_mixture/SnO2_CaCO3_Li3PO4.12-min.xrdml
<?xml version="1.0"?>
<xrdMeasurements xmlns="http://www.xrdml.com/XRDMeasurement/2.2" xmlns:xsi="http://www.w3.org/2001/XMLSchema-instance" xsi:schemaLocation="http://www.xrdml.com/XRDMeasurement/2.2 http://www.xrdml.com/XRDMeasurement/2.2/XRDMeasurement.xsd" status="Completed" recordIdentifier="{91C273C0-F274-4C7D-8C5C-57C5600306F6}">
	<comment>
		<entry/>
	</comment>
	<sample type="To be analyzed">
		<id>dara-45-2</id>
		<name></name>
		<preparedBy></preparedBy>
	</sample>
	<xrdMeasurement measurementType="Scan" status="Completed" sampleMode="Reflection">
		<usedWavelength intended="K-Alpha 1">
			<kAlpha1 unit="Angstrom">1.5405980</kAlpha1>
			<kAlpha2 unit="Angstrom">1.5444260</kAlpha2>
			<kBeta unit="Angstrom">1.3922500</kBeta>
			<ratioKAlpha2KAlpha1>0.5000</ratioKAlpha2KAlpha1>
		</usedWavelength>
		<incidentBeamPath>
			<radius unit="mm">145.00</radius>
			<xRayTube id="1010048" name="Empyrean Cu LFF HR (9430 033 7310x) DK430614">
				<tension unit="kV">40.0</tension>
				<current unit="mA">15.0</current>
				<anodeMaterial>Cu</anodeMaterial>
				<focus type="Line">
					<length unit="mm">12.0</length>
					<width unit="mm">0.4</width>
					<takeOffAngle unit="deg">6.0</takeOffAngle>
				</focus>
			</xRayTube>
			<filter id="20010004" name="Beta-filter Nickel">
				<material>Ni</material>
				<thickness unit="mm">0.020</thickness>
			</filter>
			<sollerSlit id="21010002" name="Soller slits 0.04 rad.">
				<opening unit="rad">0.0400</opening>
			</sollerSlit>
			<mask id="22031000" name="Fixed mask 13 mm">
				<width unit="mm">9.00</width>
			</mask>
			<divergenceSlit id="22120001" name="Divergence slit 1°" xsi:type="fixedDivergenceSlitType">
				<distanceToSample unit="mm">50.00</distanceToSample>
				<height unit="mm">1.52</height>
			</divergenceSlit>
		</incidentBeamPath>
		<beamKnife id="29030100" name="Beam knife low"/>
		<sampleMovement xsi:type="spinningSampleMovementType">
			<spinnerRevolutionTime unit="seconds">1.0</spinnerRevolutionTime>
		</sampleMovement>
		<diffractedBeamPath>
			<radius unit="mm">145.00</radius>
			<antiScatterSlit id="22090040" name="AS slit 9 mm" xsi:type="fixedAntiScatterSlitType">
				<height unit="mm">9.00</height>
			</antiScatterSlit>
			<sollerSlit id="21020003" name="Large Soller slits 0.04 rad.">
				<opening unit="rad">0.0400</opening>
			</sollerSlit>
			<filter id="20030001" name="Large beta-filter Nickel">
				<material>Ni</material>
				<thickness unit="mm">0.020</thickness>
			</filter>
			<detector id="7010019" name="PIXcel1D-Medipix3 detector" xsi:type="rtmsDetectorType">
				<phd unit="keV">
					<lowerLevel>4.0</lowerLevel>
					<upperLevel>11.3</upperLevel>
				</phd>
				<mode>Scanning</mode>
				<activeLength unit="deg">5.020</activeLength>
			</detector>
		</diffractedBeamPath>
		<scan appendNumber="0" mode="Continuous" scanAxis="Gonio" status="Completed">
			<header>
				<startTimeStamp>2024-02-18T15:55:38-08:00</startTimeStamp>
				<endTimeStamp>2024-02-18T16:08:06-08:00</endTimeStamp>
				<author>
					<name>AutomatedUser</name>
				</author>
				<source>
					<applicationSoftware version="1.4b (28)">PANalytical Aeris Instrument Suite</applicationSoftware>
					<instrumentControlSoftware version="2.0.0 20210224">AERIS</instrumentControlSoftware>
					<instrumentID>950485</instrumentID>
				</source>
			</header>
			<dataPoints>
				<positions axis="2Theta" unit="deg">
					<startPosition>9.99043322</startPosition>
					<endPosition>100.09495370</endPosition>
				</positions>
				<positions axis="Omega" unit="deg">
					<startPosition>4.99521661</startPosition>
					<endPosition>50.04747685</endPosition>
				</positions>
				<commonCountingTime unit="seconds">18.249</commonCountingTime>
				<counts unit="counts">3887 3726 3847 3681 3823 3798 3729 3895 3695 3817 3862 3738 3677 3772 3781 3808 3833 3610 3758 3733 3709 3746 3837 3710 3672 3807 3782 3771 3709 3768 3687 3712 3620 3757 3721 3763 3649 3644 3830 3621 3683 3731 3604 3629 3633 3587 3766 3590 3559 3552 3631 3631 3661 3635 3607 3514 3572 3627 3692 3557 3543 3591 3576 3685 3545 3558 3533 3504 3561 3495 3574 3574 3525 3502 3542 3632 3535 3552 3506 3442 3463 3455 3444 3536 3467 3469 3399 3560 3542 3484 3525 3450 3412 3457 3372 3433 3434 3402 3396 3455 3429 3380 3479 3491 3403 3388 3336 3372 3247 3428 3356 3384 3254 3421 3325 3278 3385 3278 3448 3316 3416 3333 3313 3332 3297 3355 3388 3230 3335 3335 3248 3290 3285 3270 3362 3312 3336 3218 3199 3250 3235 3211 3162 3207 3220 3243 3227 3176 3192 3171 3282 3221 3215 3095 3124 3147 3262 3209 3200 3205 3259 3250 3248 3184 3142 3223 3235 3234 3056 3080 3224 3186 3099 3143 3073 3098 3162 3136 3082 3046 2999 3073 3141 2991 3020 3030 3138 3048 3043 3090 3021 3017 3024 3008 3089 3110 3131 3046 3034 3029 3008 3076 2926 3023 2998 3030 2972 3021 3062 2990 3052 2985 3001 3086 3027 2998 3032 2875 2928 2891 2966 3088 2992 3059 2974 2856 3031 2931 2904 2973 2924 2905 2954 2974 2972 2989 2935 2915 2873 2878 2804 2890 2906 2980 2888 2838 2892 2983 2969 2855 2936 2838 2819 2904 2862 2847 2890 2883 2835 2850 2857 2826 2860 2762 2865 2948 2859 2904 2755 2854 2798 2873 2749 2834 2626 2742 2826 2850 2774 2700 2796 2816 2816 2759 2741 2784 2724 2785 2795 2800 2700 2785 2773 2767 2715 2721 2760 2668 2713 2747 2779 2811 2717 2657 2730 2691 2757 2615 2683 2728 2532 2699 2696 2669 2721 2748 2800 2714 2691 2615 2771 2611 2684 2660 2685 2670 2656 2628 2682 2686 2705 2665 2651 2612 2554 2706 2716 2651 2541 2597 2731 2682 2645 2619 2578 2594 2537 2683 2666 2737 2738 2647 2651 2671 2632 2632 2579 2642 2526 2760 2604 2685 2557 2650 2591 2647 2510 2645 2532 2593 2518 2681 2523 2555 2668 2592 2522 2517 2672 2608 2610 2625 2555 2591 2565 2524 2629 2523 2619 2642 2569 2599 2585 2635 2579 2590 2573 2558 2423 2490 2436 2477 2517 2484 2496 2558 2532 2533 2608 2560 2447 2404 2482 2550 2560 2525 2542 2480 2438 2516 2602 2448 2498 2555 2543 2478 2537 2379 2515 2514 2448 2490 2504 2515 2492 2560 2440 2628 2535 2534 2512 2510 2495 2492 2475 2525 2491 2448 2325 2377 2449 2470 2486 2492 2392 2373 2450 2486 2430 2516 2489 2406 2559 2376 2427 2479 2433 2420 2511 2490 2533 2444 2414 2405 2428 2456 2522 2456 2335 2314 2385 2368 2452 2514 2477 2350 2392 2425 2417 2447 2445 2459 2440 2465 2405 2447 2329 2374 2373 2442 2342 2414 2393 2410 2374 2344 2416 2426 2368 2339 2375 2379 2312 2461 2339 2376 2392 2345 2343 2476 2484 2328 2429 2351 2361 2299 2307 2425 2357 2407 2325 2424 2319 2373 2233 2355 2422 2308 2380 2341 2353 2317 2307 2337 2362 2307 2312 2350 2344 2390 2369 2353 2311 2351 2236 2214 2289 2295 2295 2272 2192 2252 2254 2285 2231 2270 2296 2308 2292 2164 2314 2408 2270 2330 2384 2245 2310 2310 2253 2326 2344 2410 2334 2395 2360 2282 2239 2354 2349 2337 2318 2353 2416 2375 2328 2274 2308 2265 2330 2173 2434 2338 2312 2340 2299 2348 2240 2275 2329 2260 2336 2276 2366 2263 2335 2405 2373 2399 2398 2358 2349 2520 2460 2500 2493 2491 2457 2556 2521 2636 2553 2644 2649 2633 2641 2628 2753 2710 2701 2734 2717 2723 2734 2666 2544 2494 2545 2634 2452 2355 2500 2400 2432 2280 2387 2282 2292 2312 2243 2274 2273 2250 2167 2227 2204 2174 2182 2178 2215 2254 2226 2184 2218 2196 2240 2276 2191 2179 2105 2091 2158 2165 2145 2060 2273 2119 2131 2141 2084 2123 2168 2153 2061 2099 2036 2163 2091 2109 2085 2088 2036 2120 2096 2103 2044 2159 2071 2162 2128 2094 2094 2075 2100 2097 2041 2123 2020 2076 2053 2085 2080 2110 2130 2078 2152 2121 2088 2046 1998 2009 1994 2178 2125 2115 2046 2093 2089 2081 2034 2119 2040 2071 2022 2038 2068 2009 2064 2098 2008 2025 1995 1954 2093 1983 2033 2049 2051 2076 2039 2058 1987 2088 1982 2058 1970 2035 2074 1956 2036 2007 2011 2012 1963 2013 1992 2067 2059 1989 2059 1972 1917 1952 1992 2083 1940 1975 2009 1936 2017 1893 1933 2034 1950 1964 1993 1985 1935 2031 2036 2038 1983 1996 2035 2002 1905 1950 2028 1887 1993 2052 1938 2035 2056 1946 1902 1849 1993 1938 1988 1876 1966 1976 2032 1986 1952 1960 1909 1853 1923 1996 1945 1844 1974 1971 1953 1939 1976 1948 1885 1939 1835 1888 1872 1925 1937 1820 1943 1771 1909 1845 2022 1890 1914 1941 1872 1856 1899 1895 1956 1889 1880 1888 1823 1859 1877 1953 1884 1884 1851 1904 1880 1904 1905 1865 1859 1827 1927 1844 1875 1834 1925 1837 1871 1783 1867 1772 1888 1858 1865 1827 1916 1876 1830 1872 1912 1846 1855 1830 1831 1813 1857 1870 1936 1879 1870 1801 1815 1821 1780 1841 1859 1815 1880 1853 1898 1744 1818 1824 1827 1867 1734 1927 1838 1849 1839 1847 1869 1848 1769 1783 1846 1851 1849 1843 1843 1857 1767 1883 1825 1776 1826 1803 1806 1790 1849 1844 1792 1677 1748 1799 1774 1896 1752 1801 1766 1747 1827 1760 1786 1812 1762 1815 1816 1705 1732 1708 1742 1867 1767 1775 1770 1671 1805 1766 1720 1863 1748 1834 1749 1752 1744 1790 1777 1854 1657 1832 1762 1709 1777 1799 1754 1795 1726 1728 1782 1748 1770 1779 1717 1773 1669 1755 1685 1798 1703 1806 1663 1778 1644 1768 1851 1733 1652 1728 1676 1686 1728 1724 1714 1639 1705 1725 1663 1686 1757 1677 1804 1733 1789 1747 1733 1661 1743 1655 1704 1693 1682 1761 1734 1670 1648 1686 1772 1736 1688 1763 1641 1665 1677 1664 1724 1696 1703 1648 1757 1686 1710 1712 1723 1681 1694 1739 1708 1719 1638 1675 1740 1726 1697 1734 1739 1701 1682 1819 1731 1703 1680 1752 1804 1710 1660 1667 1743 1734 1694 1703 1710 1789 1685 1759 1760 1866 1732 1747 1713 1798 1749 1808 1820 1808 1801 1901 1801 1875 1857 1893 1885 1864 2003 1925 2053 2064 2067 2123 2106 2099 2208 2157 2256 2290 2268 2447 2487 2564 2687 2775 2838 2996 3022 3228 3218 3408 3485 3507 3585 3674 3785 3826 3836 3734 3775 3716 3609 3490 3355 3117 3174 2956 2752 2696 2485 2372 2302 2232 2187 2209 2042 1968 2044 1984 2002 1933 1887 1892 1832 1840 1811 1836 1845 1836 1773 1856 1771 1814 1809 1783 1771 1817 1791 1773 1767 1758 1830 1829 1820 1815 1876 1903 1911 1943 1948 1980 1967 2026 2062 2248 2159 2261 2291 2415 2404 2540 2667 2736 2738 2828 2964 2981 3018 3023 2963 3009 3010 3086 3041 3076 3096 3013 3094 2942 3168 3137 3051 3060 2988 2936 3049 2879 2917 2852 2899 2865 2906 2992 2957 2870 2796 2722 2687 2677 2554 2470 2309 2299 2175 2070 1932 1934 1888 1856 1862 1843 1815 1722 1735 1689 1630 1696 1587 1626 1635 1687 1626 1763 1659 1706 1624 1604 1600 1650 1561 1515 1602 1693 1571 1610 1685 1618 1543 1545 1621 1633 1590 1645 1648 1668 1631 1642 1640 1626 1664 1622 1621 1571 1545 1563 1568 1642 1561 1610 1556 1602 1541 1568 1511 1502 1533 1580 1493 1527 1555 1528 1583 1518 1571 1567 1570 1638 1527 1597 1528 1627 1624 1591 1649 1587 1533 1645 1700 1640 1657 1607 1653 1647 1585 1604 1588 1611 1565 1712 1592 1670 1678 1640 1769 1731 1702 1723 1769 1790 1849 1805 1879 1775 1874 1855 1811 1944 2000 2098 2139 2120 2153 2334 2300 2222 2323 2311 2393 2426 2350 2304 2275 2267 2314 2234 2285 2255 2238 2245 2164 2128 2098 2208 2208 2190 2134 2058 2088 1984 1961 1918 1844 1822 1736 1713 1754 1696 1686 1667 1642 1574 1571 1571 1517 1505 1587 1515 1532 1464 1475 1588 1522 1483 1532 1501 1549 1571 1556 1576 1532 1576 1528 1565 1539 1576 1550 1528 1517 1484 1477 1419 1582 1516 1596 1539 1621 1596 1568 1635 1519 1642 1681 1627 1601 1617 1734 1629 1669 1664 1662 1642 1808 1770 1756 1691 1713 1832 1747 1765 1751 1743 1793 1771 1841 1926 1845 1863 1868 1874 1911 2005 1957 2012 1952 1972 2090 2018 2034 2160 2075 2223 2262 2250 2216 2178 2414 2431 2399 2533 2560 2567 2763 2674 2906 2910 2965 3026 3179 3371 3465 3487 3764 3956 4120 4457 4731 5139 5423 5926 6361 7001 7538 8123 9006 10187 10976 12059 13407 14778 16427 18078 19661 21692 23147 25254 26949 28278 29692 30623 30316 30407 29374 27648 26445 24389 22089 20283 18077 16229 14489 12428 10998 9747 8692 7557 7003 6352 5885 5374 5025 4634 4299 4109 3812 3621 3501 3368 3208 3172 3019 2927 2765 2644 2689 2474 2397 2448 2397 2262 2188 2174 2183 2126 2027 2007 1879 2005 1836 1871 1892 1802 1842 1791 1818 1760 1695 1636 1706 1681 1679 1684 1621 1634 1681 1657 1679 1588 1592 1568 1591 1587 1566 1532 1531 1641 1567 1468 1496 1420 1415 1501 1429 1552 1473 1430 1453 1476 1447 1445 1457 1511 1474 1369 1420 1437 1429 1394 1434 1462 1437 1422 1412 1402 1375 1363 1428 1387 1431 1449 1435 1391 1363 1361 1264 1291 1365 1335 1327 1401 1366 1392 1363 1329 1356 1352 1380 1418 1347 1414 1343 1326 1377 1344 1388 1291 1258 1327 1282 1397 1354 1224 1359 1316 1365 1374 1355 1349 1340 1360 1321 1334 1420 1365 1393 1321 1293 1347 1380 1355 1464 1393 1452 1562 1454 1568 1640 1650 1641 1639 1635 1627 1722 1625 1617 1553 1626 1605 1624 1570 1584 1626 1662 1711 1771 1745 1669 1733 1796 1736 1709 1782 1763 1779 1764 1724 1878 1804 1823 1865 1926 1814 1948 2006 2046 2096 2137 2200 2157 2248 2367 2364 2409 2491 2562 2529 2664 2761 2676 2680 2784 2804 2839 2947 2917 3013 3027 3084 3012 3256 3039 3255 3412 3521 3706 3857 4058 4426 4745 5144 5520 6104 6752 7877 8928 10385 12321 14818 17452 21346 26082 31526 38936 46615 56943 68148 82063 95686 108829 113329 108677 94475 77298 66857 61844 59693 56913 49319 38245 27503 18823 12820 9491 7176 6065 5240 4692 4456 4001 3836 3626 3462 3301 3087 2939 3020 2873 2749 2788 2710 2612 2502 2492 2348 2253 2184 2089 1969 1930 1894 1809 1814 1835 1732 1634 1624 1578 1617 1542 1505 1562 1559 1485 1609 1562 1521 1475 1445 1375 1443 1545 1527 1500 1508 1506 1441 1377 1474 1461 1398 1410 1372 1284 1414 1394 1470 1399 1421 1372 1372 1346 1440 1420 1378 1388 1387 1376 1329 1379 1420 1368 1483 1402 1326 1386 1331 1401 1376 1370 1358 1331 1412 1446 1369 1367 1348 1330 1337 1346 1352 1371 1338 1324 1320 1240 1331 1232 1264 1285 1304 1342 1246 1317 1282 1256 1268 1201 1338 1283 1270 1242 1293 1254 1251 1230 1230 1214 1215 1202 1285 1180 1300 1163 1202 1266 1250 1198 1216 1226 1241 1241 1214 1215 1213 1279 1263 1212 1182 1237 1213 1248 1222 1208 1236 1219 1233 1223 1260 1263 1202 1214 1244 1304 1334 1264 1273 1283 1307 1363 1448 1355 1444 1486 1503 1580 1524 1528 1464 1445 1397 1423 1364 1404 1312 1349 1308 1355 1239 1240 1269 1222 1199 1176 1208 1200 1142 1171 1171 1176 1175 1196 1229 1304 1182 1250 1191 1204 1274 1147 1212 1113 1188 1177 1126 1157 1150 1160 1150 1180 1162 1194 1218 1171 1118 1194 1224 1278 1129 1163 1180 1119 1119 1111 1198 1233 1135 1212 1178 1181 1209 1186 1187 1245 1121 1230 1163 1233 1214 1153 1156 1189 1140 1168 1153 1156 1198 1113 1201 1152 1177 1095 1163 1118 1164 1166 1176 1173 1176 1124 1107 1153 1137 1153 1199 1142 1143 1122 1190 1154 1159 1175 1188 1152 1150 1160 1165 1214 1204 1184 1184 1250 1219 1212 1180 1246 1281 1244 1256 1320 1254 1245 1220 1307 1303 1187 1248 1295 1257 1249 1232 1342 1214 1297 1313 1257 1378 1234 1351 1287 1279 1229 1270 1304 1260 1344 1307 1359 1245 1396 1448 1414 1392 1344 1420 1321 1382 1504 1398 1432 1414 1525 1486 1487 1528 1553 1569 1580 1648 1654 1669 1625 1777 1740 1698 1849 1849 1843 1890 1958 1936 2074 2043 2110 2204 2180 2219 2322 2398 2531 2591 2680 2737 2878 3033 3135 3273 3611 3835 3963 4248 4559 4951 5432 5952 6279 7141 7528 8415 9193 10376 11386 12822 14142 15908 17589 19205 20977 22811 24077 25069 25351 25533 25044 24112 23128 21887 20601 19618 18477 16882 15697 13991 12430 11283 9943 8959 7966 7372 6645 5913 5592 5043 4888 4481 4326 4168 3965 3864 3714 3692 3394 3403 3378 3140 3030 2996 2907 2806 2716 2580 2580 2417 2303 2251 2098 2037 1972 1956 1772 1772 1719 1750 1760 1614 1659 1632 1576 1523 1458 1530 1498 1512 1478 1467 1453 1440 1329 1419 1384 1387 1346 1414 1301 1477 1314 1429 1263 1307 1252 1265 1257 1224 1312 1290 1281 1265 1229 1307 1220 1225 1205 1243 1242 1284 1128 1247 1175 1192 1163 1195 1119 1181 1183 1189 1145 1089 1189 1157 1186 1129 1078 1181 1125 1111 1123 1140 1155 1130 1049 1127 1119 1123 1089 1067 1101 1147 1127 1136 1145 1088 1173 1062 1087 1078 1154 1074 997 1076 1072 1093 1079 1057 1060 1021 1059 1114 1086 1114 1086 1048 1103 1038 1093 1050 1048 1085 1042 1040 1052 1096 1011 1072 1005 1053 1049 1081 1067 1011 1078 1054 1044 1095 1062 1013 1068 1060 1038 1082 1072 1118 1172 1139 1231 1220 1224 1309 1346 1456 1544 1587 1751 1783 1828 1807 1847 1774 1597 1581 1547 1508 1587 1429 1449 1359 1342 1270 1178 1131 1139 1110 1051 1055 1089 999 1046 1002 1016 971 1073 991 1001 1015 989 1086 1089 1030 1111 1069 1111 1196 1180 1209 1195 1293 1258 1349 1345 1437 1484 1548 1513 1533 1602 1661 1627 1658 1694 1654 1619 1623 1604 1618 1609 1603 1573 1510 1461 1513 1360 1399 1355 1305 1311 1231 1326 1295 1283 1280 1225 1229 1182 1209 1294 1238 1298 1208 1256 1252 1268 1296 1285 1387 1313 1371 1327 1409 1388 1436 1390 1402 1501 1483 1405 1431 1392 1421 1392 1326 1330 1287 1287 1257 1197 1216 1196 1155 1062 1128 1036 1111 1030 1078 1007 1057 953 1020 1000 1020 1030 1008 1066 1051 1067 1047 1040 1087 1011 1020 1104 1097 1128 1100 1132 1063 1201 1079 1088 1207 1127 1205 1164 1185 1214 1206 1199 1307 1240 1310 1270 1472 1427 1485 1416 1506 1608 1656 1723 1880 2090 2120 2167 2425 2655 2907 3114 3346 3725 4233 4415 4994 5468 5755 6374 6737 6904 7362 7254 7236 6944 6621 6164 5846 5764 5253 5015 4817 4499 4093 3725 3389 2936 2758 2479 2230 2051 1982 1844 1765 1585 1572 1479 1420 1378 1335 1299 1320 1243 1198 1123 1191 1165 1140 1125 1123 1101 1026 1000 971 1054 1030 1073 980 1020 977 1043 981 992 1013 986 958 1041 1002 953 944 976 1040 987 996 955 987 1011 1035 1041 1079 1025 1068 1024 1086 1115 1092 1176 1208 1209 1192 1287 1320 1302 1262 1394 1507 1523 1572 1664 1713 1864 1809 1995 2232 2114 2351 2194 2320 2202 2034 2131 1970 1989 1848 1829 1696 1663 1680 1488 1525 1398 1410 1337 1256 1216 1156 1175 1181 1092 1132 1120 1152 1171 1217 1263 1258 1382 1510 1607 1709 1932 2038 2187 2389 2498 2548 2376 2242 2146 1966 1908 1835 1796 1761 1701 1660 1472 1446 1283 1222 1132 1100 1064 937 964 894 906 854 874 892 901 840 836 813 784 806 829 852 756 787 783 734 772 758 796 762 764 802 765 785 754 765 731 752 761 822 817 761 751 743 769 777 796 755 717 752 768 734 718 713 736 704 719 725 696 761 725 768 721 729 719 728 737 697 784 768 742 726 736 742 748 771 761 734 790 739 747 732 769 743 735 792 786 786 746 772 797 726 762 777 817 727 789 761 731 680 748 734 758 740 760 737 718 699 694 697 726 738 701 705 729 664 718 655 688 699 700 697 709 736 750 714 720 665 661 692 688 690 640 693 661 708 698 708 682 663 660 704 714 704 688 674 732 710 673 718 688 681 666 707 659 661 631 686 688 726 692 716 692 720 702 755 665 687 683 698 676 640 637 702 656 722 639 675 676 688 681 684 699 674 665 720 702 696 656 647 662 650 719 735 687 698 671 662 707 644 727 684 711 751 714 716 730 705 722 686 734 674 758 709 667 738 746 737 703 748 687 711 708 696 620 696 647 738 744 659 679 685 626 667 648 644 665 681 693 665 618 675 701 668 669 686 695 689 689 734 668 663 689 667 697 632 712 706 656 703 727 714 741 689 691 707 720 737 683 716 731 682 762 756 744 802 831 787 911 835 870 926 963 990 1036 1079 1078 1076 1054 1049 1002 1013 993 975 995 991 894 927 901 866 823 789 820 796 845 739 789 770 750 761 713 753 758 768 792 799 763 809 805 823 876 870 932 937 951 1002 1180 1199 1393 1457 1652 1948 1994 2143 2203 2206 2013 1746 1574 1487 1461 1516 1488 1548 1581 1518 1459 1240 1152 1033 893 922 808 861 811 808 776 755 731 769 736 784 743 739 774 729 711 686 729 721 741 715 747 691 713 688 647 695 701 699 663 717 677 704 635 625 633 613 664 659 634 626 692 646 672 653 595 617 667 610 678 642 666 599 646 617 619 587 588 623 629 629 656 630 625 608 623 588 676 602 596 622 647 631 624 613 602 577 624 663 636 597 638 639 616 648 582 588 621 656 609 628 597 581 594 580 648 587 600 620 580 556 587 606 643 620 587 631 613 597 657 607 606 645 591 640 600 553 607 571 570 633 666 638 627 557 610 607 604 590 560 604 601 590 593 566 611 613 630 633 594 636 558 590 614 612 578 630 603 568 594 626 560 588 577 579 626 560 540 576 605 579 616 609 579 582 580 599 600 569 607 602 562 580 613 591 631 572 552 585 572 566 603 593 557 570 578 584 581 601 560 555 576 590 545 575 600 599 566 581 551 553 550 581 581 611 578 604 606 531 568 608 573 587 567 525 584 591 550 572 555 599 573 617 544 581 576 564 559 590 542 588 602 555 567 572 582 606 587 631 596 595 606 604 558 583 621 614 605 596 580 548 552 585 528 562 577 598 588 579 659 558 591 579 571 540 569 577 618 565 631 594 598 587 642 595 594 585 613 609 618 618 571 597 639 650 627 658 622 634 623 677 607 676 608 588 613 634 633 634 653 578 600 569 555 605 672 562 568 619 605 589 621 568 566 597 621 627 627 645 668 614 632 617 628 595 658 610 638 709 640 635 695 700 655 678 689 732 784 794 845 855 903 973 951 1027 1072 1147 1164 1114 1138 1073 979 1012 978 950 950 931 1036 1048 979 1023 919 885 905 853 905 905 903 891 983 1083 1164 1253 1314 1557 1715 2104 2248 2713 3147 3545 3879 3956 3960 3442 3166 2729 2368 2224 2104 2218 2204 2232 2389 2336 2245 1956 1625 1425 1245 1116 1090 891 858 829 828 757 804 783 745 760 748 717 709 734 714 659 694 703 674 674 688 631 685 609 639 676 678 673 640 624 641 640 558 697 582 655 639 669 665 624 647 691 677 644 642 629 722 646 686 687 699 712 710 690 761 759 736 779 798 835 899 893 1040 965 1127 1284 1382 1643 1817 2144 2525 2868 3057 3291 3304 3182 2647 2287 2001 1755 1676 1762 1844 1982 2030 2104 1970 1863 1642 1428 1198 1021 946 835 816 746 801 707 716 678 676 678 644 669 703 655 627 680 663 622 592 642 634 607 632 648 652 632 585 583 545 604 597 616 630 644 605 601 625 617 625 588 612 590 591 646 572 627 615 624 621 632 613 607 598 573 594 597 623 606 635 620 588 618 624 638 607 618 640 651 683 649 640 642 617 627 657 619 588 676 642 595 627 611 610 595 611 585 579 582 610 589 562 623 583 531 576 553 536 581 558 581 587 567 603 615 614 566 589 584 611 629 620 584 632 634 564 615 661 629 643 662 618 647 611 626 659 626 623 624 639 582 615 605 652 615 575 601 607 616 669 621 637 538 639 676 674 630 642 604 635 623 651 637 619 598 608 678 624 675 625 678 667 676 655 651 645 690 702 686 692 656 731 679 708 724 767 770 782 817 749 854 739 823 842 863 906 925 810 934 812 860 870 876 883 927 884 903 872 848 909 830 924 918 916 927 923 957 907 867 939 914 941 945 984 986 1005 941 1016 1001 1052 992 999 971 1039 1077 949 1002 1021 1091 1023 1110 1003 1098 1099 1112 1155 1172 1209 1142 1198 1289 1211 1288 1200 1373 1340 1388 1433 1437 1471 1529 1614 1682 1797 1786 1895 2029 2017 2161 2213 2341 2421 2613 2713 3021 3075 3377 3619 3958 4342 4695 5031 5840 6356 7351 8326 9286 10327 11798 13173 14941 15843 17331 17886 18222 17647 17104 15972 14995 13695 13045 12511 12314 12115 11949 11792 11627 11092 10592 9543 8663 7742 6684 5882 5346 4666 4285 3826 3557 3247 3024 2738 2591 2394 2234 2138 1889 1821 1760 1751 1564 1591 1445 1438 1301 1300 1242 1244 1123 1144 1091 1103 1062 1020 1008 990 998 999 955 926 878 885 842 862 885 838 843 866 782 857 777 810 769 764 765 695 695 720 747 699 690 671 689 702 719 704 748 672 694 663 681 665 709 717 646 676 681 686 666 634 614 643 639 687 607 644 641 593 659 664 594 622 601 677 634 629 624 642 611 615 593 581 597 659 605 590 596 586 601 637 593 575 628 582 615 586 575 605 594 595 602 605 583 610 610 588 569 631 590 602 596 618 574 607 582 600 549 575 499 556 558 570 552 558 564 584 568 574 616 614 574 583 535 589 564 555 573 615 564 532 562 572 575 586 599 570 585 556 563 572 566 591 550 572 565 575 596 574 588 611 589 575 594 562 587 531 566 590 544 581 621 569 616 631 622 569 555 596 602 594 586 630 588 560 612 597 639 664 689 631 710 661 671 655 715 695 697 687 726 675 683 767 801 769 720 773 809 862 818 851 879 837 950 894 953 1018 1025 1087 1041 1116 1105 1302 1272 1445 1545 1662 1861 1994 2074 2214 2490 2811 3066 3336 3801 3941 4391 4573 4633 4556 4619 4363 3923 3626 3383 3196 3057 3122 3059 3119 2942 2926 2966 2833 2677 2414 2302 1960 1796 1544 1500 1448 1263 1163 1077 1057 1030 990 948 944 857 863 842 777 780 763 741 773 753 696 709 698 675 633 682 673 686 646 639 624 620 636 618 640 610 609 594 570 616 595 618 619 648 584 572 605 602 606 578 624 541 562 550 530 568 561 593 556 533 595 532 528 532 551 542 564 548 550 532 549 553 529 579 581 566 579 620 533 563 571 592 580 590 594 589 580 587 576 529 545 543 590 585 553 553 551 560 565 560 552 531 540 540 534 569 508 552 577 565 530 507 514 496 457 544 508 522 524 543 549 521 532 540 553 553 543 536 523 550 535 543 533 555 558 596 611 579 579 655 692 670 698 747 772 803 819 722 757 670 665 633 619 626 619 603 665 682 710 673 649 638 600 584 575 533 584 590 539 575 550 565 562 588 578 545 533 564 565 600 521 545 566 562 548 585 542 577 571 553 535 588 611 590 547 542 608 600 616 653 672 634 623 653 637 673 672 629 682 755 706 730 767 751 843 845 909 1022 1084 1259 1297 1442 1412 1378 1273 1238 1078 968 994 908 887 942 961 967 1020 1097 1094 1070 1020 1061 962 944 906 903 934 984 1002 951 1015 1146 1153 1210 1315 1421 1550 1595 1738 1948 1994 2136 2236 2212 2295 2266 2110 2010 1905 1882 1822 1652 1793 1688 1766 1720 1722 1641 1715 1615 1638 1508 1467 1336 1436 1308 1333 1289 1157 1118 977 911 903 854 895 854 916 877 843 836 807 793 885 778 735 721 683 689 699 669 637 675 627 625 650 586 605 594 606 611 611 612 537 565 557 573 539 554 548 579 527 474 506 540 526 527 584 499 540 526 541 517 532 484 483 536 470 544 499 532 516 517 516 475 477 534 531 529 579 518 500 588 596 522 540 564 593 575 572 585 565 566 584 601 613 545 599 558 595 605 551 607 596 534 608 549 637 531 591 555 558 520 573 481 495 544 530 533 524 470 532 530 501 536 495 508 511 495 471 497 515 484 478 474 457 513 473 518 445 535 467 526 482 459 481 513 497 490 510 501 521 536 513 512 500 510 519 504 528 516 516 521 492 483 511 512 496 519 499 505 532 527 533 492 553 521 555 542 506 547 519 538 544 518 511 482 498 534 510 547 546 501 535 538 541 520 507 540 560 518 552 537 548 536 606 563 588 550 579 563 612 553 582 567 614 638 631 600 610 679 680 644 708 701 743 737 775 795 835 780 834 859 799 881 819 867 855 933 912 1007 1078 1157 1239 1250 1255 1297 1284 1175 1092 982 974 922 942 859 981 923 995 994 1049 1081 1040 1056 989 1047 1105 990 1112 1171 1282 1491 1665 2077 2391 2920 3264 3638 3758 3467 2846 2348 1976 1591 1477 1469 1433 1507 1643 1666 1964 2256 2270 2324 2276 2035 1694 1539 1312 1231 1065 1071 1044 1105 1042 1050 1101 1113 1165 1273 1178 1221 1165 1114 1056 958 943 881 847 852 901 856 888 940 952 936 964 977 987 931 949 900 907 902 937 883 982 961 955 998 1045 1054 1100 1122 1265 1391 1369 1536 1637 1893 2019 2201 2424 2768 2943 3234 3562 3727 3842 3857 3850 3774 3476 3196 3130 2817 2806 2613 2600 2490 2485 2615 2665 2644 2620 2453 2455 2256 2143 2000 1819 1697 1517 1393 1325 1214 1098 1099 1049 934 927 963 893 797 795 722 757 711 766 695 678 738 652 640 642 580 632 591 623 618 600 600 601 576 576 587 544 561 551 575 582 589 545 579 551 585 564 572 542 522 562 517 539 523 528 537 543 534 535 471 543 516 509 517 528 480 499 481 504 502 493 535 517 508 527 531 525 546 584 573 517 561 579 649 606 631 665 598 629 579 609 578 567 538 546 539 593 523 562 557 544 553 549 625 557 598 558 543 535 545 516 497 500 512 520 533 516 546 532 566 455 547 524 504 557 519 470 488 474 521 490 528 544 457 549 501 514 546 499 542 488 540 494 523 518 494 544 515 484 515 458 503 532 452 509 459 493 508 520 524 545 493 561 554 537 505 558 587 531 563 536 516 496 563 583 522 536 561 540 534 590 573 577 530 566 558 592 532 604 579 608 624 642 623 614 640 653 705 670 736 696 702 759 695 696 706 822 776 863 826 829 841 879 878 921 965 895 975 1038 1012 1087 1209 1233 1249 1328 1331 1487 1599 1825 1927 2052 2269 2481 2713 2933 3106 3243 3465 3656 3655 3913 3893 4016 3796 3739 3542 3368 3126 2967 2937 2896 2869 2733 2735 2713 2694 2594 2615 2594 2478 2440 2209 2095 1859 1797 1673 1525 1443 1380 1336 1169 1144 1051 1103 963 1000 977 851 905 811 895 808 768 796 791 787 745 830 708 695 723 735 738 713 730 719 716 762 686 754 705 642 700 741 737 738 744 743 795 773 836 846 880 938 994 1014 1082 1158 1287 1339 1393 1462 1335 1319 1182 1118 1187 1069 1088 1150 1127 1230 1185 1293 1370 1418 1480 1676 1683 1741 1773 1818 1959 2110 2302 2393 2558 2848 3155 3424 3739 3960 4319 4701 4683 4610 4547 4287 4120 3861 3522 3339 3207 2854 2890 2997 2899 2796 2937 3110 3083 2979 2909 2713 2671 2508 2211 2098 1793 1711 1539 1463 1414 1268 1183 1141 1033 1079 984 961 922 845 837 850 774 752 760 747 708 726 637 665 643 701 679 651 632 627 626 617 550 571 538 562 559 567 534 573 524 528 524 511 499 481 532 493 493 511 547 499 495 484 456 476 480 466 477 444 439 467 494 511 448 476 444 470 431 460 454 473 490 479 457 431 450 468 475 459 473 410 449 480 457 490 442 455 439 444 441 459 480 436 470 453 433 466 462 409 439 470 465 437 464 464 456 426 396 425 459 462 453 471 469 432 456 450 456 454 443 442 478 448 472 479 479 436 484 482 433 510 399 447 475 422 444 459 499 460 472 462 482 445 450 469 463 468 464 497 504 478 477 434 477 432 480 488 457 487 472 524 488 451 461 524 495 452 448 422 495 433 450 461 480 496 471 475 474 469 442 482 455 480 462 478 460 463 464 444 484 440 434 415 422 437 435 419 439 415 440 389 382 436 436 445 436 438 440 426 431 425 416 404 452 404 403 442 385 421 401 408 413 428 408 409 395 398 423 412 377 407 408 411 431 393 388 400 435 395 413 436 396 428 396 454 429 409 422 417 391 387 394 440 399 456 400 468 391 428 408 452 449 386 467 478 477 456 553 550 605 574 640 647 643 542 533 529 508 483 518 493 524 469 503 482 485 459 528 483 483 531 515 513 530 442 461 510 454 467 414 468 410 472 460 438 381 436 435 433 448 401 394 425 393 389 431 480 430 397 453 395 415 411 451 412 404 421 419 438 406 431 407 455 404 452 406 437 403 425 443 445 477 450 458 451 439 414 409 445 459 387 436 438 410 445 490 458 481 482 456 473 515 494 549 609 550 615 628 660 659 610 554 571 505 492 458 499 507 472 492 503 502 548 532 518 521 557 548 533 510 484 496 515 487 444 443 463 449 448 430 439 484 435 446 480 455 446 459 469 421 427 441 434 467 433 456 445 475 500 441 439 510 438 486 480 476 485 500 461 490 515 538 487 509 514 549 544 541 553 601 604 579 592 622 656 659 718 714 779 859 793 848 906 978 1069 1216 1232 1363 1541 1550 1771 1967 2045 2070 2047 2137 2015 1926 1777 1719 1583 1505 1436 1465 1335 1315 1373 1367 1391 1382 1432 1446 1511 1409 1368 1356 1194 1165 1063 1063 956 884 821 776 774 736 709 682 652 629 613 625 593 562 560 544 518 500 504 462 515 510 482 484 505 458 472 451 440 441 459 437 434 495 501 462 444 450 449 434 430 419 436 412 457 430 442 395 407 407 416 402 392 411 416 409 414 360 395 409 411 407 378 369 413 368 398 381 401 392 399 391 378 418 426 367 392 393 419 377 415 386 417 380 402 410 419 382 421 388 412 386 410 458 455 406 406 408 405 404 401 447 475 441 445 439 397 456 457 450 513 495 510 512 557 519 543 541 644 700 697 709 743 751 725 626 596 548 554 568 535 512 555 532 522 601 519 560 590 545 613 589 655 604 591 545 563 505 621 532 552 540 552 512 487 538 544 531 543 562 509 529 519 544 551 518 475 504 546 510 503 483 529 480 491 510 492 563 475 517 497 477 520 470 524 544 522 512 552 521 547 602 583 542 600 600 567 529 564 501 529 488 462 490 515 521 507 466 512 528 479 516 529 574 529 514 522 553 526 552 486 502 503 505 486 496 522 501 541 473 526 501 486 484 486 493 472 492 468 478 487 429 434 509 480 426 490 420 455 406 452 436 452 427 462 413 444 440 447 443 443 436 459 461 497 446 443 424 426 457 400 470 447 440 411 411 403 396 421 388 441 427 398 470 423 440 436 383 453 415 407 414 407 380 395 409 364 384 394 444 418 412 347 423 351 387 414 394 462 373 377 444 384 405 382 380 374 428 378 389 370 398 401 412 416 424 399 409 372 409 375 365 401 395 427 434 372 411 359 395 411 374 357 381 366 404 421 423 350 383 388 354 382 379 380 413 395 387 422 395 384 355 416 374 390 375 371 400 381 346 370 376 346 360 380 388 391 392 393 389 356 396 373 364 346 385 383 365 378 365 349 402 364 377 389 351 360 383 324 437 349 383 360 387 359 373 381 371 377 359 381 392 392 378 364 363 421 371 370 360 362 353 384 355 405 396 424 417 378 382 424 383 401 434 386 446 397 432 380 396 405 403 349 348 385 353 368 362 353 391 391 413 366 436 388 402 355 413 390 418 402 369 359 356 393 375 330 368 385 417 396 405 392 377 366 376 364 351 376 349 388 421 361 378 369 387 398 418 364 367 403 379 411 349 413 368 403 359 409 426 401 411 428 459 471 443 468 472 546 604 596 703 696 752 814 779 710 664 672 577 543 488 488 454 450 479 500 420 462 461 479 515 513 585 591 643 567 602 517 509 464 498 445 443 403 406 410 409 408 374 416 379 405 399 366 335 382 404 347 366 400 385 344 360 402 380 368 391 354 428 378 403 396 337 386 399 397 391 393 386 371 361 379 337 366 367 365 361 395 368 396 388 396 401 392 387 419 423 436 381 450 414 469 431 419 401 452 438 447 450 484 461 485 455 458 469 490 503 513 488 514 547 502 538 544 505 553 536 554 568 597 628 638 650 695 713 725 705 741 800 815 855 932 965 972 1153 1179 1362 1426 1544 1726 1808 2005 2255 2427 2592 2924 2902 3002 2919 2797 2642 2438 2301 2102 2001 1847 1723 1661 1592 1522 1565 1561 1561 1621 1711 1744 1761 1856 1707 1758 1729 1686 1565 1456 1375 1282 1137 1092 962 1003 844 822 757 750 685 679 632 641 606 597 551 571 586 551 525 539 508 529 465 453 495 477 471 493 456 414 426 439 445 404 454 421 406 464 433 445 423 413 389 422 393 422 386 414 373 419 393 412 367 370 414 417 430 383 407 387 386 402 396 383 389 452 414 400 370 396 410 381 353 392 396 419 388 433 390 404 367 387 374 386 421 401 413 369 367 387 407 363 397 414 388 420 424 374 408 428 372 411 394 378 430 378 424 434 381 367 375 390 375 374 386 394 383 375 422 390 402 438 365 426 399 417 422 451 355 412 401 420 444 415 366 422 410 473 416 464 411 485 453 422 429 437 486 436 464 424 456 468 479 459 477 433 431 491 460 436 467 472 497 472 471 481 505 515 511 519 542 551 599 546 593 610 593 632 689 632 682 696 683 739 775 741 763 880 894 955 1070 1054 1079 1173 1218 1152 1160 1180 1041 1124 1017 931 853 825 762 783 744 828 773 703 760 703 818 823 852 901 848 839 844 900 807 818 849 808 836 877 881 947 993 960 978 824 807 715 669 617 572 495 491 475 525 487 493 498 544 511 531 522 613 639 563 599 607 615 563 536 475 449 422 413 425 438 442 406 385 437 403 425 400 406 402 421 401 448 396 413 415 396 410 425 436 465 481 398 471 458 442 436 373 402 437 393 379 397 395 400 414 400 410 419 418 432 388 413 407 415 455 443 440 444 407 412 419 426 439 359 445 426 429 377 417 378 439 383 411 443 419 391 430 402 432 381 407 389 374 434 406 395 423 416 395 420 420 373 426 380 391 387 423 417 384 420 399 393 409 422 400 395 397 395 409 409 389 396 395 394 417 385 412 419 404 424 402 383 431 414 446 447 422 432 408 434 409 481 464 433 466 396 414 441 446 460 463 474 455 511 533 447 506 508 526 516 507 543 537 547 562 558 556 625 650 637 661 726 750 791 766 815 860 890 983 1080 1157 1298 1383 1495 1706 1826 1968 2075 2239 2382 2307 2275 2295 2184 2003 1829 1666 1585 1429 1401 1224 1270 1211 1183 1162 1213 1248 1274 1277 1368 1341 1501 1479 1532 1466 1447 1405 1300 1273 1130 1053 982 939 816 775 776 754 730 635 642 589 583 605 559 585 548 531 539 480 481 503 471 497 466 500 451 464 462 428 450 439 469 440 436 429 414 412 421 426 425 395 396 404 428 439 384 389 433 375 396 402 342 366 400 371 364 364 379 362 383 387 409 429 430 440 496 495 539 555 466 529 475 490 460 407 379 380 416 392 398 370 419 393 434 410 392 388 370 376 404 411 382 417 383 398 430 422 403 391 364 411 386 361 421 347 355 363 367 373 340 328 362 348 321 358 381 354 367 332 371 328 376 332 386 363 315 354 356 308 342 327 349 332 362 346 338 346 339 334 331 331 357 332 321 350 346 377 344 329 339 364 336 374 377 344 365 346 336 361 350 337 341 368 361 340 370 328 380 337 345 346 315 363 317 330 322 351 358 341 324 368 306 353 337 339 340 318 333 312 355 318 361 330 351 347 335 350 323 397 345 362 336 332 336 337 358 357 361 378 312 366 348 369 367 409 400 351 385 406 397 357 404 410 393 362 363 364 359 346 393 377 351 381 359 357 398 357 351 346 360 405 408 387 397 397 397 435 398 427 378 418 418 405 391 367 457 427 401 383 409 419 429 429 431 444 421 404 416 437 460 433 399 520 488 452 499 497 510 547 561 567 570 625 689 793 755 827 860 879 1018 984 1079 1062 1157 1084 1075 1079 942 923 912 819 811 820 668 698 737 668 736 650 630 663 748 638 717 737 771 796 780 776 778 766 733 718 667 640 590 523 495 516 514 521 470 454 488 440 452 422 418 407 430 374 398 386 426 391 400 380 345 415 406 387 337 361 346 399 385 388 340 397 357 384 356 348 349 373 381 342 356 349 346 321 328 354 339 383 337 341 379 348 379 329 332 342 362 338 332 361 349 353 356 366 345 375 411 323 374 368 409 381 354 358 407 355 366 382 349 383 383 364 366 337 349 395 399 367 375 394 396 373 371 397 415 383 401 395 428 395 426 367 401 411 417 413 415 381 423 414 426 407 373 449 403 415 402 393 407 412 391 411 421 446 392 376 378 415 417 434 422 419 393 459 436 408 449 375 386 404 402 383 411 397 421 387 435 450 471 459 414 481 421 455 462 488 470 490 456 484 457 492 483 511 503 537 532 541 553 575 579 559 587 605 569 576 624 626 672 660 687 772 752 815 871 948 973 984 1065 1088 1190 1249 1395 1435 1563 1735 1881 2053 2179 2134 2293 2302 2142 2173 2003 1894 1822 1689 1599 1526 1470 1429 1388 1348 1250 1265 1209 1250 1190 1201 1275 1280 1343 1301 1445 1433 1434 1506 1424 1450 1284 1243 1228 1087 1088 1002 945 946 875 852 790 792 723 779 754 747 671 673 656 646 670 637 625 629 623 597 578 556 591 563 557 594 610 610 622 615 558 565 594 604 585 587 637 618 628 620 663 636 671 682 677 733 776 741 834 858 830 926 977 994 989 1091 1219 1286 1360 1461 1562 1704 1822 2004 2103 2242 2376 2448 2375 2359 2254 2211 2133 2006 1822 1695 1556 1568 1443 1409 1295 1295 1221 1224 1260 1259 1343 1242 1319 1394 1464 1531 1504 1511 1510 1520 1425 1468 1335 1266 1186 1196 1051 986 969 883 781 764 760 709 666 665 626 627 580 577 558 551 541 538 537 501 504 486 455 436 469 472 460 507 433 446 445 450 462 442 452 417 438 416 428 364 400 369 421 383 425 387 415 413 413 379 410 379 374 381 406 388 416 410 375 358 347 395 373 375 351 385 384 389 411 365 360 370 352 359 352 367 402 412 375 395 379 389 378 379 394 376 354 367 361 350 368 372 353 370 375 369 358 326 381 378 372 377 385 365 324 372 404 414 350 370 363 379 332 337 332 350 364 387 351 359 374 383 368 378 388 382 339 366 385 402 389 358 345 396 401 424 332 378 392 387 384 414 426 422 431 425 437 425 391 460 460 456 459 487 454 461 487 522 518 584 619 672 633 727 702 683 695 635 623 593 646 649 701 726 738 803 790 792 932 958 1037 1104 1186 1279 1338 1328 1380 1336 1301 1314 1243 1166 1086 1035 956 954 857 830 739 741 743 687 752 734 795 750 811 781 811 811 828 830 788 864 861 774 812 777 770 749 722 647 594 618 571 586 565 541 485 510 472 515 451 455 418 402 440 401 418 451 428 426 418 418 395 363 385 400 372 338 360 383 375 406 343 412 409 387 375 386 360 341 369 345 365 365 330 356 372 337 356 357 380 340 349 321 371 389 355 361 371 361 414 372 400 367 369 404 343 364 367 347 400 359 412 377 394 363 374 374 401 384 402 389 406 421 415 433 426 431 445 460 514 581 550 578 609 602 586 517 537 496 482 444 431 415 412 423 459 470 432 474 453 488 503 537 532 612 624 728 736 804 832 764 777 735 686 667 580 527 534 482 494 477 425 436 421 404 412 425 459 446 432 433 467 495 490 504 522 546 533 553 516 526 519 477 483 464 418 382 428 437 423 400 379 434 394 383 377 392 392 461 409 431 392 445 397 429 422 469 440 448 444 472 490 463 476 465 451 472 508 495 479 520 549 537 507 549 529 604 523 599 616 618 701 716 761 865 873 899 926 1006 1007 1144 1064 1127 1152 1170 1102 1044 1086 1073 1046 1005 982 1019 1025 1046 985 987 959 1030 939 920 891 823 798 803 801 759 804 815 757 836 783 813 885 819 724 765 725 705 768 739 736 708 703 665 659 686 604 607 558 528 527 550 492 463 445 481 436 459 474 427 426 419 469 407 434 369 447 399 435 371 431 388 328 382 369 384 407 400 398 369 358 401 329 385 354 367 390 399 365 336 382 332 369 365 381 368 324 379 351 335 356 367 359 345 359 338 315 333 348 364 340 363 324 351 369 357 342 318 351 335 372 349 356 329 372 339 360 342 330 348 370 347 362 369 325 340 338 359 340 322 341 341 353 387 336 320 372 376 346 405 364 361 370 408 373 394 393 387 374 389 386 349 382 364 374 353 393 372 358 325 370 408 397 391 371 374 341 325 344 382 394 369 354 361 380 358 357 396 359 394 357 367 384 380 381 361 356 351 367 352 359 400 344 373 342 362 343 361 374 373 345 325 360 323 378 359 332 351 345 320 374 340 378 317 345 339 372 309 346 330 358 329 318 328 358 344 357 347 341 371 369 353 366 364 377 378 332 344 364 362 319 338 353 337 353 314 364 391 354 405 409 351 383 390 376 360 388 405 403 401 400 432 445 430 414 414 474 440 520 580 538 647 631 707 815 855 1012 1219 1433 1576 1726 1757 1731 1443 1221 1109 1002 840 715 632 614 576 579 541 549 511 479 455 499 500 522 512 483 526 546 633 678 721 807 910 887 988 988 985 887 807 710 665 580 581 508 499 466 442 400 445 389 403 349 360 347 363 359 386 352 379 391 347 380 370 327 358 383 370 369 375 352 334 356 349 344 333 363 356 351 365 358 346 378 374 378 356 382 383 355 348 400 349</counts>
			</dataPoints>
		</scan>
	</xrdMeasurement>
</xrdMeasurements>