File: dataset/precursor_mixture/TiO2_V2O5_Nb2O5.2-min.xrdml
<?xml version="1.0"?>
<xrdMeasurements xmlns="http://www.xrdml.com/XRDMeasurement/2.2" xmlns:xsi="http://www.w3.org/2001/XMLSchema-instance" xsi:schemaLocation="http://www.xrdml.com/XRDMeasurement/2.2 http://www.xrdml.com/XRDMeasurement/2.2/XRDMeasurement.xsd" status="Completed" recordIdentifier="{5C6136DC-09E3-4BD7-9821-A44C1B72B1BF}">
	<comment>
		<entry/>
	</comment>
	<sample type="To be analyzed">
		<id></id>
		<name></name>
		<preparedBy></preparedBy>
	</sample>
	<xrdMeasurement measurementType="Scan" status="Completed" sampleMode="Reflection">
		<usedWavelength intended="K-Alpha 1">
			<kAlpha1 unit="Angstrom">1.5405980</kAlpha1>
			<kAlpha2 unit="Angstrom">1.5444260</kAlpha2>
			<kBeta unit="Angstrom">1.3922500</kBeta>
			<ratioKAlpha2KAlpha1>0.5000</ratioKAlpha2KAlpha1>
		</usedWavelength>
		<incidentBeamPath>
			<radius unit="mm">145.00</radius>
			<xRayTube id="1010048" name="Empyrean Cu LFF HR (9430 033 7310x) DK437873">
				<tension unit="kV">40.0</tension>
				<current unit="mA">15.0</current>
				<anodeMaterial>Cu</anodeMaterial>
				<focus type="Line">
					<length unit="mm">12.0</length>
					<width unit="mm">0.4</width>
					<takeOffAngle unit="deg">6.0</takeOffAngle>
				</focus>
			</xRayTube>
			<filter id="20010004" name="Beta-filter Nickel">
				<material>Ni</material>
				<thickness unit="mm">0.020</thickness>
			</filter>
			<sollerSlit id="21010002" name="Soller slits 0.04 rad.">
				<opening unit="rad">0.0400</opening>
			</sollerSlit>
			<mask id="22031000" name="Fixed mask 13 mm">
				<width unit="mm">9.00</width>
			</mask>
			<divergenceSlit id="22120001" name="Divergence slit 1°" xsi:type="fixedDivergenceSlitType">
				<distanceToSample unit="mm">50.00</distanceToSample>
				<height unit="mm">1.52</height>
			</divergenceSlit>
		</incidentBeamPath>
		<beamKnife id="29030100" name="Beam knife low"/>
		<sampleMovement xsi:type="spinningSampleMovementType">
			<spinnerRevolutionTime unit="seconds">1.0</spinnerRevolutionTime>
		</sampleMovement>
		<diffractedBeamPath>
			<radius unit="mm">145.00</radius>
			<antiScatterSlit id="22090040" name="AS slit 9 mm" xsi:type="fixedAntiScatterSlitType">
				<height unit="mm">9.00</height>
			</antiScatterSlit>
			<sollerSlit id="21020003" name="Large Soller slits 0.04 rad.">
				<opening unit="rad">0.0400</opening>
			</sollerSlit>
			<filter id="20030001" name="Large beta-filter Nickel">
				<material>Ni</material>
				<thickness unit="mm">0.020</thickness>
			</filter>
			<detector id="7010019" name="PIXcel1D-Medipix3 detector" xsi:type="rtmsDetectorType">
				<phd unit="keV">
					<lowerLevel>4.0</lowerLevel>
					<upperLevel>11.3</upperLevel>
				</phd>
				<mode>Scanning</mode>
				<activeLength unit="deg">1.021</activeLength>
			</detector>
		</diffractedBeamPath>
		<scan appendNumber="0" mode="Continuous" scanAxis="Gonio" status="Completed">
			<header>
				<startTimeStamp>2024-03-22T20:54:12-07:00</startTimeStamp>
				<endTimeStamp>2024-03-22T20:56:34-07:00</endTimeStamp>
				<author>
					<name>Instrument</name>
				</author>
				<source>
					<applicationSoftware version="1.6 (94)">PANalytical Aeris Instrument Suite</applicationSoftware>
					<instrumentControlSoftware version="3.0.0 20211014">AERIS</instrumentControlSoftware>
					<instrumentID>2879380</instrumentID>
				</source>
			</header>
			<dataPoints>
				<positions axis="2Theta" unit="deg">
					<startPosition>10.02173288</startPosition>
					<endPosition>139.98435528</endPosition>
				</positions>
				<positions axis="Omega" unit="deg">
					<startPosition>5.01086644</startPosition>
					<endPosition>69.99217764</endPosition>
				</positions>
				<commonCountingTime unit="seconds">1.551</commonCountingTime>
				<counts unit="counts">377 415 393 400 407 398 427 375 414 423 396 405 420 393 376 384 410 418 392 380 391 363 382 317 362 398 391 359 329 354 380 375 379 405 365 349 350 356 340 354 339 345 375 350 285 343 335 355 293 341 303 312 303 303 343 307 291 302 305 304 290 356 299 323 293 266 297 296 294 266 262 290 306 307 265 286 274 282 258 305 276 296 302 259 278 281 291 250 259 273 284 271 242 275 308 259 298 281 285 289 256 263 256 211 258 252 272 227 225 218 243 235 260 268 261 248 261 261 295 355 354 359 316 262 254 259 267 239 213 258 250 245 229 254 229 224 212 247 206 228 232 232 246 223 231 227 195 207 202 235 219 208 241 197 232 224 230 231 280 278 281 207 218 192 183 235 197 208 186 238 229 222 240 231 234 207 214 186 201 226 212 213 211 194 179 194 195 225 222 210 226 192 191 248 201 187 241 215 194 168 220 184 180 225 205 200 218 213 192 170 213 178 211 180 198 189 213 226 203 186 228 191 213 245 226 248 300 315 434 558 780 1051 997 618 344 287 256 250 233 206 183 218 206 187 185 229 191 186 188 205 185 175 190 179 203 196 207 199 219 197 239 295 325 392 366 337 248 233 180 231 198 185 188 192 200 207 232 192 292 330 469 701 1146 1563 1420 842 389 265 246 233 225 214 207 183 198 199 168 190 186 199 180 192 206 199 193 201 165 168 176 199 175 171 177 193 187 153 215 201 165 174 180 157 185 158 188 171 174 159 159 186 188 218 187 219 224 208 237 231 277 299 359 527 914 1415 2034 1792 1053 559 345 299 296 299 221 194 197 195 172 192 206 192 264 246 372 484 397 299 194 179 164 192 160 194 170 190 165 201 190 161 178 177 163 150 156 181 178 186 167 167 187 150 177 181 182 179 161 169 186 160 170 168 170 225 173 230 227 211 213 243 282 420 641 1044 1542 1411 1015 601 324 256 253 219 207 206 267 328 416 560 695 603 431 257 235 214 199 177 199 146 171 150 135 135 183 177 162 156 147 174 186 140 150 165 148 141 155 134 128 172 190 154 145 141 138 162 151 166 142 150 131 170 185 185 258 278 364 389 358 267 219 185 187 153 166 142 164 149 127 159 164 163 152 123 130 144 157 153 147 131 156 117 118 142 159 168 223 261 239 215 210 156 129 163 161 153 153 167 114 148 124 148 110 99 136 140 143 146 177 179 166 170 132 143 119 141 131 121 122 122 127 124 117 116 142 120 127 158 152 151 219 219 220 202 177 140 138 119 103 133 102 134 124 127 134 123 120 127 138 128 153 147 117 141 142 135 132 124 154 143 114 133 126 132 143 119 133 126 163 147 168 145 127 147 139 174 141 185 230 347 517 636 553 429 307 213 188 158 198 238 293 398 406 343 269 203 191 129 130 138 157 158 121 137 123 134 185 228 320 440 381 331 240 187 149 121 116 107 136 128 111 110 107 133 160 151 234 216 181 173 162 124 109 140 119 92 116 128 96 123 124 111 103 137 152 110 134 92 89 104 106 114 111 112 91 119 106 102 115 116 98 118 108 118 119 123 115 100 118 109 106 104 106 107 106 119 134 114 106 110 109 117 119 134 120 152 171 194 204 165 167 117 131 116 89 129 106 89 120 95 126 148 106 151 118 141 129 139 129 110 128 117 132 129 120 159 142 145 155 150 117 91 120 118 100 109 89 95 115 97 121 87 108 105 129 90 111 122 99 95 108 114 81 127 116 110 100 124 120 127 111 110 82 105 90 94 123 122 142 119 120 114 118 116 106 102 129 110 107 131 137 146 178 181 151 142 162 127 132 108 129 118 145 117 127 137 135 115 124 146 130 150 129 160 122 195 304 373 283 276 254 181 134 120 103 108 111 94 82 117 123 122 133 123 99 116 124 111 108 118 104 124 143 153 155 205 159 191 128 124 141 135 122 142 163 184 196 221 320 509 570 460 374 356 212 178 142 143 141 132 122 138 126 157 135 139 123 169 143 136 148 155 129 137 107 131 112 119 140 126 126 134 119 153 149 132 171 190 265 275 208 247 213 159 133 141 113 126 109 114 106 117 118 117 119 137 118 121 95 141 178 177 195 256 276 312 308 254 279 251 193 234 214 152 206 166 128 119 125 129 124 102 88 116 114 113 116 138 123 175 149 94 141 114 127 112 108 123 100 119 79 111 100 123 117 110 126 142 105 113 113 104 103 104 96 117 101 107 104 109 112 83 107 115 108 102 111 124 157 211 253 362 358 283 243 249 203 135 122 125 122 125 125 111 102 112 114 120 94 122 112 144 126 140 143 228 356 532 495 369 401 405 356 326 293 257 289 245 247 166 194 178 156 159 140 132 139 123 111 128 123 115 135 113 134 136 193 220 254 196 181 176 157 131 117 100 111 107 124 131 89 92 86 116 103 113 89 115 98 104 100 145 107 102 104 92 113 103 98 128 96 103 93 103 107 106 114 102 121 78 117 137 111 107 122 157 222 186 195 174 162 186 169 138 144 135 119 130 122 146 120 107 107 102 122 105 101 98 95 114 117 96 110 128 121 109 99 121 131 120 155 138 138 135 112 93 119 96 123 107 105 90 94 108 95 105 118 100 111 124 107 113 124 149 153 152 107 142 112 121 98 108 127 107 96 114 90 127 89 116 98 97 112 123 123 174 195 168 152 146 159 151 113 119 121 100 128 120 221 296 281 193 168 168 191 129 101 119 114 116 116 114 101 108 129 125 120 144 137 155 189 153 140 135 152 147 120 116 108 89 105 108 106 88 130 108 91 128 103 101 110 118 130 82 97 112 104 103 93 114 98 137 94 127 103 119 102 94 91 111 115 92 122 94 105 111 103 101 100 92 103 125 83 119 149 109 101 99 127 98 101 114 115 114 95 96 87 95 102 105 98 101 90 131 105 82 96 102 86 87 98 86 105 105 118 91 102 100 98 108 106 87 93 91 105 115 94 93 94 122 100 108 110 100 82 81 100 115 101 122 106 109 122 126 127 148 182 166 135 143 151 134 117 95 107 90 87 91 105 99 86 125 103 108 92 96 94 119 105 81 107 103 108 118 106 106 137 148 153 206 212 218 173 183 149 158 117 103 115 127 119 97 105 104 100 86 93 99 157 167 147 134 159 150 120 98 95 117 104 89 119 110 108 99 104 116 100 95 113 102 118 97 82 98 98 106 119 112 125 99 110 95 105 109 115 107 100 82 109 118 105 97 112 93 90 79 79 74 92 90 67 89 76 94 92 101 96 95 97 105 96 89 80 89 78 96 83 92 82 81 111 109 106 103 135 109 109 109 110 106 93 112 116 76 105 111 192 212 209 169 119 135 169 150 108 118 74 95 85 82 118 83 82 89 98 104 110 77 133 114 123 112 107 107 119 113 85 112 99 90 102 85 85 91 76 88 86 84 81 103 112 108 92 110 81 110 83 114 92 101 94 110 101 100 110 131 107 120 106 122 124 114 107 94 98 96 87 100 96 121 86 105 79 101 97 86 94 111 117 95 100 91 111 112 109 104 105 129 116 103 107 95 87 120 98 99 116 106 99 77 84 79 92 90 86 81 96 111 75 107 91 84 92 113 89 77 91 103 90 93 112 98 87 95 87 78 87 108 110 85 108 100 77 84 96 74 88 108 90 77 92 86 100 83 83 98 91 111 100 87 85 99 86 80 69 89 99 89 116 96 106 117 117 111 110 93 97 127 159 154 138 135 119 123 112 113 119 103 100 123 125 132 85 80 80 117 94 109 118 80 84 77 90 79 93 93 69 74 81 79 78 95 74 85 107 107 83 113 112 102 92 127 130 109 102 113 75 95 80 100 108 85 83 97 90 78 92 74 84 69 91 63 89 93 71 74 59 77 71 96 72 88 106 86 96 82 91 90 101 92 75 82 115 102 100 83 95 73 94 84 81 108 116 117 94 109 98 95 87 70 100 75 89 100 96 64 86 78 101 81 79 78 79 90 95 84 89 75 88 84 83 66 81 93 57 91 71 75 66 72 73 67 94 90 102 80 87 74 86 82 83 88 91 80 92 92 90 71 86 92 82 78 84 75 102 86 65 83 90 69 65 74 101 71 81 83 72 82 89 98 83 95 97 92 77 78 81 92 99 94 76 70 103 92 75 94 65 76 90 102 66 84 60 86 89 80 98 83 87 75 93 81 66 75 97 92 90 66 86 88 86 78 74 89 84 67 107 72 103 87 79 78 112 89 88 91 78 86 93 80 110 92 101 90 112 97 102 99 105 73 87 111 106 99 102 84 88 94 103 106 86 81 83 87 90 110 119 109 119 115 96 108 109 114 111 111 111 105 89 73 103 117 95 92 93 102 97 124 99 117 114 139 123 87 80 86 80 110 88 89 99 68 94 89 89 91 82 73 103 91 90 63 81 67 72 86 69 92 93 99 83 81 68 95 66 94 84 90 87 78 89 84 76 64 89 94 84 88 80 73 87 79 93 64 89 74 96 96 96 88 114 105 81 116 101 113 95 106 114 111 92 109 84 86 73 93 99 110 107 74 80 95 88 80 97 98 107 89 99 89 88 115 108 83 94 92 78 82 101 114 102 92 117 103 114 105 103 104 77 84 92 106 108 114 116 97 107 98 103 75 102 101 113 83 83 89 69 72 77 91 99 90 86 72 60 97 96 99 105 80 75 79 87 80 66 74 91 74 93 86 85 67 66 66 78 67 66 96 65 82 94 86 86 71 99 71 59 87 90 78 94 83 107 74 95 97 101 84 60 104 85 87 72 96 77 88 79 93 102 68 88 94 103 99 90 95 95 112 98 102 99 95 92 85 93 72 69 78 92 70 69 86 65 92 82 64 70 94 76 78 79 78 84 74 98 85 86 113 96 100 78 76 86 87 71 69 86 87 79 76 77 70 79 82 88 109 77 97 90 102 105 81 85 60 83 67 78 74 80 97 104 120 105 99 85 100 86 98 83 98 85 90 77 91 96 89 117 93 102 116 91 94 82 90 85 112 103 95 102 86 99 92 111 95 79 95 87 94 63 78 72 80 99 71 82 81 80 87 86 105 120 117 120 82 96 92 88 87 70 87 101 97 74 97 61 64 87 74 95 67 88 92 84 80 77 75 79 88 114 104 97 82 92 105 102 102 91 99 81 70 96 83 84 79 77 76 85 92 74 92 89 74 60 71 96 75 91 124 75 99 93 93 70 90 95 88 91 86 96 75 70 77 90 103 79 99 98 96 87 79 88 105 120 88 89 100 81 100 100 104 81 103 84 91 89 82 93 90 81 89 73 87 88 78 80 84 83 110 95 107 134 122 117 104 100 86 80 84 90 99 102 99 87 113 130 94 102 98 86 94 120 69 105 98 132 112 89 100 94 84 85 79 77 80 86 94 90 95 103 104 78 92 72 70 78 72 72 85 66 76 81 93 79 83 91 102 73 84 92 75 107 101 116 103 101 80 102 96 89 83 79 74 81 93 86 100 92 99 103 86 88 96 99 94 82 87 74 95 83 84 108 85 75 89 92 87 91 98 101 98 97 111 124 126 137 148 118 137 100 78 98 86 106 102 105 124 115 116 92 101 93 91 84 85 100 93 88 122 91 79 72 111 77 93 103 80 78 97 89 98 90 96 101 89 88 70 68 99 98 93 97 90 95 99 92 93 95 86 100 78 66 94 84 78 74 69 100 91 99 103 88 88 90 94 94 84 112 115 92 103 99 107 101 94 77 110 76 113 100 93 107 129 126 128 107 121 97 110 86 129 102 118 104 106 92 112 96 123 86 105 89 97 88 112 100 104 101 86 108 111 85 103 97 89 111 96 90 83 99 87 78 98 75 87 90 99 80 69 85 81 80 78 90 74 70 71 90 74 64 108 125 72 86 81 95 98 91 78 96 94 83 80 68 69 82 97 70 87 65 100 84 75 92 73 74 90 91 89 88 95 110 67 83 80 81 84 77 100 100 114 71 94 89 84 95 112 90 74 81 72 87 89 99 82 109 85 102 117 91 79 89 73 87 90 94 90 98 111 85 86 90 91 104 95 102 87 80 65 88 81 119 90 77 84 95 74 90 91 105 103 97 96 84 78 79 77 99 72 102 94 80 72 102 77 95 83 93 82 90 94 71 88 84 97 87 94 88 82 75 74 74 61 88 65 88 74 82 96 95 90 94 70 84 83 74 118 126 126 116 108 95 88 97 90 87 85 83 94 95 85 112 98 122 103 108 94 100 78 120 112 93 103 108 82 93 69 98 93 83 104 64 86 92 93 67 94 98 89 91 81 68 100 72 95 106 83 86 96 89 85 92 77 93 71 83 89 80 87 92 102 87 88 78 82 108 106 87 76 77 73 69 98 73 108 92 76 78 80 100 106 89 97 95 90 76 81 91 107 102 95 81 89 80 91 108 97 74 87 91 84 99 77 77 88 81 89 80 90 92 114 82 90 93 111 81 107 96 105 105 85 93 95 104 102 123 95 104 98 103 95 96 99 88 117 97 117 95 104 121 112 138 114 119 124 99 109 86 95 94 80 103 84 90 98 106 111 84 117 105 95 96 91 75 76 87 105 97 97 75 97 86 90 109 117 65 80 101 73 120 106 96 70 74 76 95 96 82 81 75 83 106 116 80 79 84 103 102 91 75 81 89 94 118 74 88 101 87 83 82 73 89 74 85 93 98 86 106 88 108 90 83 89 101 95 95 94 102 103 86 112 78 71 87 83 95 91 80 69 119 83 90 87 98 87 85 100 89 76 75 103 68 94 103 81 91 90 100 84 72 87 101 83 76 97 80</counts>
			</dataPoints>
		</scan>
	</xrdMeasurement>
</xrdMeasurements>