File: dataset/precursor_mixture/TiO2_Nb2O5_Li3PO4_Bi2O3-beta.12-min.xrdml
<?xml version="1.0"?>
<xrdMeasurements xmlns="http://www.xrdml.com/XRDMeasurement/2.2" xmlns:xsi="http://www.w3.org/2001/XMLSchema-instance" xsi:schemaLocation="http://www.xrdml.com/XRDMeasurement/2.2 http://www.xrdml.com/XRDMeasurement/2.2/XRDMeasurement.xsd" status="Completed" recordIdentifier="{B93BD6A6-2E9D-4625-AA0A-9A82474C5972}">
	<comment>
		<entry/>
	</comment>
	<sample type="To be analyzed">
		<id>dara-47-2</id>
		<name></name>
		<preparedBy></preparedBy>
	</sample>
	<xrdMeasurement measurementType="Scan" status="Completed" sampleMode="Reflection">
		<usedWavelength intended="K-Alpha 1">
			<kAlpha1 unit="Angstrom">1.5405980</kAlpha1>
			<kAlpha2 unit="Angstrom">1.5444260</kAlpha2>
			<kBeta unit="Angstrom">1.3922500</kBeta>
			<ratioKAlpha2KAlpha1>0.5000</ratioKAlpha2KAlpha1>
		</usedWavelength>
		<incidentBeamPath>
			<radius unit="mm">145.00</radius>
			<xRayTube id="1010048" name="Empyrean Cu LFF HR (9430 033 7310x) DK430614">
				<tension unit="kV">40.0</tension>
				<current unit="mA">15.0</current>
				<anodeMaterial>Cu</anodeMaterial>
				<focus type="Line">
					<length unit="mm">12.0</length>
					<width unit="mm">0.4</width>
					<takeOffAngle unit="deg">6.0</takeOffAngle>
				</focus>
			</xRayTube>
			<filter id="20010004" name="Beta-filter Nickel">
				<material>Ni</material>
				<thickness unit="mm">0.020</thickness>
			</filter>
			<sollerSlit id="21010002" name="Soller slits 0.04 rad.">
				<opening unit="rad">0.0400</opening>
			</sollerSlit>
			<mask id="22031000" name="Fixed mask 13 mm">
				<width unit="mm">9.00</width>
			</mask>
			<divergenceSlit id="22120001" name="Divergence slit 1°" xsi:type="fixedDivergenceSlitType">
				<distanceToSample unit="mm">50.00</distanceToSample>
				<height unit="mm">1.52</height>
			</divergenceSlit>
		</incidentBeamPath>
		<beamKnife id="29030100" name="Beam knife low"/>
		<sampleMovement xsi:type="spinningSampleMovementType">
			<spinnerRevolutionTime unit="seconds">1.0</spinnerRevolutionTime>
		</sampleMovement>
		<diffractedBeamPath>
			<radius unit="mm">145.00</radius>
			<antiScatterSlit id="22090040" name="AS slit 9 mm" xsi:type="fixedAntiScatterSlitType">
				<height unit="mm">9.00</height>
			</antiScatterSlit>
			<sollerSlit id="21020003" name="Large Soller slits 0.04 rad.">
				<opening unit="rad">0.0400</opening>
			</sollerSlit>
			<filter id="20030001" name="Large beta-filter Nickel">
				<material>Ni</material>
				<thickness unit="mm">0.020</thickness>
			</filter>
			<detector id="7010019" name="PIXcel1D-Medipix3 detector" xsi:type="rtmsDetectorType">
				<phd unit="keV">
					<lowerLevel>4.0</lowerLevel>
					<upperLevel>11.3</upperLevel>
				</phd>
				<mode>Scanning</mode>
				<activeLength unit="deg">5.020</activeLength>
			</detector>
		</diffractedBeamPath>
		<scan appendNumber="0" mode="Continuous" scanAxis="Gonio" status="Completed">
			<header>
				<startTimeStamp>2024-02-18T16:11:32-08:00</startTimeStamp>
				<endTimeStamp>2024-02-18T16:24:00-08:00</endTimeStamp>
				<author>
					<name>AutomatedUser</name>
				</author>
				<source>
					<applicationSoftware version="1.4b (28)">PANalytical Aeris Instrument Suite</applicationSoftware>
					<instrumentControlSoftware version="2.0.0 20210224">AERIS</instrumentControlSoftware>
					<instrumentID>950485</instrumentID>
				</source>
			</header>
			<dataPoints>
				<positions axis="2Theta" unit="deg">
					<startPosition>9.99043322</startPosition>
					<endPosition>100.09495370</endPosition>
				</positions>
				<positions axis="Omega" unit="deg">
					<startPosition>4.99521661</startPosition>
					<endPosition>50.04747685</endPosition>
				</positions>
				<commonCountingTime unit="seconds">18.249</commonCountingTime>
				<counts unit="counts">3772 3796 3672 3754 3720 3798 3582 3622 3568 3587 3705 3622 3706 3575 3661 3598 3684 3628 3641 3720 3701 3623 3659 3658 3608 3640 3681 3659 3658 3593 3582 3515 3634 3633 3577 3506 3690 3565 3579 3565 3451 3526 3578 3584 3551 3475 3612 3513 3508 3519 3512 3544 3603 3514 3434 3444 3594 3432 3516 3534 3547 3423 3407 3430 3435 3503 3410 3497 3510 3489 3328 3448 3504 3430 3466 3357 3459 3442 3405 3454 3416 3278 3382 3388 3452 3496 3255 3428 3452 3395 3471 3417 3315 3242 3387 3406 3280 3416 3398 3285 3306 3427 3285 3325 3282 3364 3218 3237 3447 3280 3307 3320 3293 3138 3304 3325 3315 3323 3270 3279 3284 3137 3156 3305 3235 3215 3266 3252 3167 3244 3257 3146 3207 3141 3189 3154 3122 3273 3167 3242 3191 3115 3300 3121 3176 3137 3231 3295 3115 3210 3184 3194 3184 3177 3066 3108 3259 3164 3197 3108 3128 3179 3075 3074 3187 3152 3161 3160 3150 3057 3186 3103 3177 3120 3067 3059 3139 3129 3135 3100 3185 3182 3118 3127 3051 3171 3010 3073 3106 3012 3009 3002 3139 3010 3047 3036 3121 3001 3023 3177 3097 3071 2997 2985 2964 2944 3104 2979 2970 2953 2998 2934 2973 3008 3044 2926 2938 3053 2927 3119 2919 2978 3077 3022 3059 3014 2877 3022 2927 2947 2921 2880 3006 2862 2866 2864 2948 2949 2968 2847 2876 2888 2898 2996 2892 2921 2863 2816 2982 2953 2871 2921 2871 2834 2996 2825 2894 2930 2988 2899 2882 2849 2896 2918 2854 2922 2884 2909 2945 2850 3034 2872 2858 2859 2906 2925 2743 2783 2764 2905 2858 2929 2790 2831 2836 2824 2841 2757 2851 2830 2755 2793 2860 2803 2770 2811 2728 2893 2761 2924 2728 2723 2789 2662 2694 2774 2742 2789 2711 2740 2745 2679 2751 2778 2727 2770 2705 2735 2708 2715 2762 2757 2628 2718 2686 2726 2724 2703 2767 2631 2682 2740 2666 2700 2710 2766 2681 2793 2682 2696 2718 2728 2741 2640 2721 2591 2587 2734 2505 2739 2603 2630 2636 2655 2714 2692 2670 2576 2560 2616 2667 2576 2601 2666 2643 2706 2669 2657 2707 2505 2574 2644 2613 2561 2585 2576 2647 2577 2578 2537 2631 2643 2606 2641 2594 2663 2615 2614 2561 2623 2569 2500 2559 2588 2519 2627 2653 2543 2559 2573 2533 2632 2537 2549 2567 2645 2586 2500 2664 2636 2535 2536 2618 2540 2595 2618 2608 2566 2583 2610 2563 2668 2618 2595 2459 2548 2613 2475 2672 2555 2586 2571 2517 2591 2506 2658 2525 2556 2600 2563 2514 2629 2533 2460 2547 2505 2410 2522 2520 2519 2635 2572 2514 2520 2425 2667 2548 2519 2502 2599 2555 2517 2594 2458 2547 2483 2578 2499 2479 2406 2499 2536 2414 2558 2422 2564 2464 2628 2457 2515 2438 2463 2489 2471 2530 2485 2457 2412 2450 2506 2522 2457 2430 2538 2511 2453 2406 2493 2534 2533 2422 2443 2406 2428 2468 2591 2495 2406 2471 2444 2455 2484 2382 2460 2466 2465 2389 2381 2429 2479 2415 2480 2462 2451 2478 2491 2438 2498 2451 2421 2465 2414 2440 2413 2401 2471 2410 2493 2447 2443 2422 2371 2378 2510 2379 2402 2441 2414 2472 2478 2536 2470 2441 2435 2435 2524 2517 2451 2416 2546 2474 2600 2453 2628 2575 2601 2581 2607 2634 2801 2696 2835 2708 2890 2755 2837 2807 2820 2783 2772 2657 2638 2535 2509 2472 2414 2319 2445 2432 2440 2347 2427 2255 2387 2417 2381 2352 2446 2417 2360 2355 2375 2297 2429 2391 2400 2409 2378 2416 2361 2435 2437 2445 2400 2422 2446 2410 2432 2421 2505 2579 2462 2552 2480 2589 2499 2600 2529 2547 2605 2540 2604 2638 2588 2730 2644 2649 2670 2789 2819 2709 2744 2820 2768 2836 2773 2718 2798 2793 2755 2773 2786 2823 2727 2745 2811 2689 2716 2795 2641 2492 2506 2468 2519 2509 2433 2417 2337 2449 2434 2378 2371 2309 2267 2295 2335 2313 2234 2318 2234 2317 2352 2298 2299 2318 2288 2266 2253 2216 2231 2284 2183 2255 2265 2238 2317 2311 2329 2248 2257 2285 2230 2266 2323 2318 2260 2281 2224 2249 2208 2147 2278 2285 2242 2318 2305 2242 2243 2223 2256 2252 2157 2221 2223 2143 2238 2391 2325 2241 2244 2270 2215 2158 2297 2265 2225 2160 2255 2274 2225 2157 2183 2184 2156 2109 2262 2152 2201 2224 2257 2298 2248 2201 2169 2230 2257 2240 2233 2239 2212 2176 2352 2160 2151 2267 2317 2208 2252 2228 2238 2255 2181 2204 2184 2166 2195 2201 2256 2205 2310 2226 2290 2167 2149 2136 2129 2086 2194 2101 2247 2193 2159 2211 2266 2097 2185 2028 2150 2092 2102 2185 2069 2137 2146 2057 2159 2041 2068 2089 2103 2121 2160 2202 2142 2147 2085 2127 2114 2129 2106 2131 2150 2167 2122 2102 2148 2095 2126 2149 2168 2167 2071 2155 2019 2096 2063 2100 2064 2139 2054 2182 2106 2108 2121 2172 2102 2032 2167 2132 2142 2096 2197 2136 2131 2090 2190 2042 2187 2057 2169 2109 2049 2001 2065 2118 2173 2086 2227 2069 2081 2087 2041 2067 2119 2127 2067 2083 2060 2038 2092 2065 2067 2162 2020 2062 2070 2087 2192 2055 2063 2108 2009 2012 2013 2067 1929 2019 1990 2034 2178 2144 2079 2111 2149 2010 2067 2017 2071 2099 2096 2025 2030 1996 2092 2079 2129 2028 1943 2085 2074 2052 2131 2046 2122 1917 2012 2014 1950 2043 1952 2118 2001 2039 2018 1934 2035 2034 2082 2027 2150 2114 1965 2023 2017 2019 1956 1994 2077 2028 2004 1999 2015 2057 2011 1982 2026 2007 2019 2038 2003 1974 2064 1972 1947 2052 2007 1937 1939 1949 1987 2044 2041 2016 2042 2019 1932 2010 1958 1984 1929 2039 1937 1935 1893 1937 1982 1934 1988 1913 2040 2036 2057 1945 1970 1955 1945 1980 1955 1997 1909 1961 1954 1956 1933 1935 1980 1916 1968 1965 1991 1923 1934 2015 1971 1900 1905 1949 1996 1972 1929 1947 1959 1943 1978 1951 1929 1976 1960 1943 1877 2038 1988 1858 1937 1908 2042 1904 1957 1932 1910 1932 1927 1988 1953 1968 1956 1961 1909 1936 2038 1863 1974 1937 1899 1920 1988 1904 1958 1949 1879 1969 1964 1868 1986 1944 1951 1929 1920 1985 1902 1951 1916 1860 1953 1844 1999 1908 1872 1987 1871 1903 1921 1922 1977 1981 1870 1915 1964 1956 2021 2059 1978 1992 2069 2022 1936 1869 2013 2049 1990 2111 2049 2069 2106 2133 2055 2081 2115 2172 2168 2102 2131 2138 2215 2172 2299 2324 2225 2333 2344 2405 2463 2511 2472 2690 2721 2750 2805 2837 2863 3014 3085 3118 3262 3288 3329 3536 3622 3741 3854 3862 3946 3945 3979 4007 4002 3957 4152 4243 4346 4597 4722 4994 5284 5592 5953 6412 6922 7576 7957 8793 9485 10120 10703 11269 11192 11398 11051 10604 9772 8959 8228 7125 6374 5537 4721 4184 3780 3418 3059 2853 2710 2580 2471 2399 2415 2350 2413 2318 2346 2309 2290 2320 2295 2290 2395 2366 2303 2338 2310 2325 2329 2325 2393 2224 2287 2443 2490 2480 2447 2477 2577 2625 2585 2690 2730 2804 2861 2821 2855 2827 2883 2844 2917 2850 2817 2809 2853 2779 2873 2853 2864 2891 2806 2756 2822 2810 2712 2709 2647 2626 2637 2513 2388 2416 2304 2265 2255 2164 2162 2145 2096 2111 2084 1986 1986 2054 2003 1966 2001 1981 2032 1859 2009 1927 2014 1995 1929 2014 1963 1914 2085 1988 1909 2044 1964 1985 1976 1976 2010 1994 1968 1879 1932 1989 2003 1950 1890 2000 2004 1942 2027 1936 1884 1904 1882 1881 1897 1965 1916 1812 1881 1920 1912 1828 1919 1843 1909 1878 1949 1865 1952 1899 1985 1910 1961 1905 2014 1909 1958 1871 1907 1953 1873 1867 1855 1841 1858 1902 1957 1986 1975 1955 1923 1893 1845 1946 1968 1933 1976 1965 1991 2025 2003 2053 2059 2086 2048 2073 2102 2144 2217 2160 2221 2170 2199 2250 2245 2301 2293 2405 2383 2350 2364 2441 2448 2485 2571 2643 2495 2668 2530 2634 2575 2593 2568 2614 2596 2700 2658 2626 2671 2729 2712 2758 2799 2859 2917 2847 2940 2975 3123 3227 3240 3349 3517 3702 3872 4092 4413 4726 5325 5674 6373 6914 7585 8214 9135 9982 11253 12155 12862 13894 14337 14598 14483 14140 13399 12398 11275 10169 9230 8133 6951 6117 5209 4693 4124 3606 3270 3231 3034 2840 2749 2814 2692 2734 2739 2676 2781 2801 2933 2847 2948 2858 2976 3120 3233 3237 3166 3309 3365 3309 3252 3048 2992 2856 2790 2623 2426 2392 2227 2153 2167 2025 2084 2053 2024 1999 1977 1977 2002 1952 1966 1925 1848 1896 1882 1906 1857 1876 1798 1924 1837 1863 1857 1786 1860 1813 1926 1851 1859 1919 1879 1777 1879 1891 1791 1848 1906 1898 1828 1866 1731 1760 1752 1904 1809 1795 1933 1787 1779 1834 1760 1831 1735 1842 1894 1753 1804 1718 1795 1794 1784 1848 1791 1785 1728 1885 1809 1790 1819 1857 1855 1754 1773 1769 1738 1756 1710 1778 1785 1860 1760 1770 1762 1789 1759 1762 1777 1799 1790 1836 1756 1824 1887 1791 1857 1910 1876 1809 1989 1782 1910 1874 1908 1909 1947 1922 1980 1989 2012 2060 1987 2031 1957 2045 2064 2039 2110 2057 2121 2130 1969 2044 2012 2151 2185 2152 2100 2161 2143 2191 2141 2122 2242 2285 2197 2265 2292 2292 2308 2287 2483 2309 2429 2431 2399 2562 2529 2607 2642 2551 2735 2701 2845 2680 2838 2860 2931 2897 3013 2993 3020 3062 3183 3158 3239 3491 3630 3769 3950 4070 4333 4632 4944 5265 5793 6435 7194 7925 8814 9804 11346 12705 15033 16649 19461 22104 25057 28647 32664 37281 41451 45849 50277 53197 55708 55786 54445 50705 46615 41647 37785 33859 29475 25726 21573 17699 14245 11709 9807 8536 7436 6829 6384 5963 6073 6074 6148 6347 6513 7100 7371 7939 8303 8952 9622 10268 10886 11561 12144 12309 12369 11985 11370 10583 10217 9543 8441 7818 7122 6497 5712 5051 4621 3955 3746 3374 3365 2937 3052 2814 2685 2775 2602 2661 2520 2501 2518 2491 2455 2453 2538 2513 2566 2485 2372 2557 2602 2723 2765 2882 2881 3000 3097 3284 3572 3703 3853 4065 4304 4495 4791 5087 5190 5524 5692 5770 5931 5826 5649 5499 5287 5045 4516 4197 4058 3972 3430 3351 3150 2891 2765 2876 2649 2566 2496 2560 2548 2500 2491 2450 2540 2390 2370 2367 2444 2302 2317 2180 2181 2126 2159 2045 2034 1995 2025 1959 2021 1946 1901 1969 1938 1979 2003 1942 1900 1832 1909 1869 1887 1923 1870 1869 1905 1821 1778 1794 1848 1782 1841 1829 1818 1845 1768 1808 1795 1851 1876 1873 1935 1772 1770 1818 1717 1786 1810 1817 1785 1813 1822 1791 1787 1841 1803 1776 1828 1770 1853 1745 1897 1858 1807 1793 1863 1866 1895 1833 1888 1832 1892 1927 1886 1909 1872 1974 1989 2047 2084 2163 2153 2336 2302 2368 2337 2546 2579 2803 2729 2913 2876 2944 2983 2819 2844 2654 2581 2544 2317 2369 2309 2198 2182 2028 1975 1938 2025 1961 1916 1830 1804 1841 1754 1760 1815 1842 1811 1764 1853 1751 1741 1820 1746 1800 1739 1740 1780 1708 1649 1681 1720 1743 1693 1722 1729 1687 1665 1742 1676 1695 1723 1721 1676 1725 1680 1646 1703 1640 1735 1642 1636 1644 1626 1575 1577 1667 1677 1603 1718 1666 1706 1617 1737 1580 1637 1722 1641 1676 1599 1688 1638 1655 1685 1624 1684 1737 1689 1688 1743 1655 1722 1629 1644 1633 1732 1757 1715 1718 1693 1756 1744 1693 1692 1854 1759 1762 1796 1788 1810 1802 1867 2010 1919 1964 1904 2072 2017 2118 2238 2274 2377 2557 2677 2819 3054 3276 3578 3936 4176 4754 5180 5819 6696 7179 7887 8639 9309 9507 9556 9259 9008 8018 7565 7000 6467 5950 5522 4857 4463 3816 3319 3006 2591 2490 2238 2183 2098 2168 2007 2060 1937 1936 1824 1879 1876 1816 1735 1884 1788 1785 1859 1801 1860 1748 1789 1721 1742 1724 1828 1809 1818 1773 1886 1815 1783 1923 1798 1888 1842 1870 1829 1813 1889 1876 1937 1950 1928 2027 2098 2233 2206 2312 2363 2567 2732 2865 3099 3370 3558 4071 4458 4850 5482 6263 7088 7964 9047 10201 11485 12826 14128 15074 15472 15607 15177 14535 13185 12245 11388 10624 9834 9246 8155 7173 6113 5151 4410 3821 3440 3062 2844 2716 2511 2410 2261 2206 2141 2166 2028 1962 1980 1986 1880 1776 1918 1796 1870 1743 1859 1777 1776 1732 1672 1721 1603 1678 1611 1613 1660 1747 1660 1579 1536 1624 1608 1552 1601 1537 1557 1621 1620 1511 1644 1592 1565 1575 1622 1519 1558 1549 1465 1517 1523 1459 1561 1572 1616 1582 1586 1615 1532 1614 1600 1476 1588 1583 1616 1539 1648 1605 1637 1606 1629 1685 1649 1763 1700 1686 1765 1754 1760 1784 1877 1932 1916 2042 1999 2090 2081 2277 2224 2282 2458 2510 2570 2636 2563 2669 2622 2519 2468 2348 2362 2322 2309 2223 2205 2097 2163 1980 1982 1982 2023 1956 1938 1987 2025 1951 2093 2060 2051 2040 2071 1967 2011 1993 1967 2006 1988 1921 1945 1859 1782 1813 1805 1761 1760 1647 1630 1648 1723 1667 1684 1738 1687 1708 1651 1575 1666 1619 1641 1652 1709 1641 1688 1598 1622 1561 1625 1493 1611 1521 1571 1552 1576 1489 1469 1519 1439 1438 1486 1430 1434 1426 1544 1529 1500 1435 1464 1517 1455 1382 1475 1401 1392 1424 1425 1437 1419 1460 1360 1383 1395 1559 1419 1431 1488 1430 1456 1329 1307 1398 1337 1350 1379 1434 1334 1418 1328 1373 1363 1413 1370 1405 1416 1409 1398 1492 1472 1378 1397 1513 1352 1390 1494 1380 1415 1358 1451 1498 1466 1441 1412 1461 1366 1387 1420 1367 1428 1365 1348 1393 1379 1343 1407 1438 1331 1450 1416 1437 1380 1384 1452 1388 1375 1430 1490 1351 1501 1463 1404 1400 1423 1455 1445 1503 1431 1437 1489 1510 1527 1463 1491 1512 1428 1545 1510 1476 1540 1482 1525 1335 1513 1466 1490 1444 1516 1471 1448 1405 1507 1447 1478 1493 1471 1475 1574 1413 1427 1454 1434 1470 1401 1481 1517 1451 1475 1460 1512 1539 1482 1488 1507 1544 1611 1551 1626 1619 1764 1808 1844 1924 2089 2144 2254 2449 2625 2811 3230 3286 3628 3987 4538 4676 5028 5250 5316 5389 5368 5206 5063 4733 4682 4458 4209 4043 4052 3674 3323 3041 2848 2654 2429 2304 2188 2177 2056 2082 1935 1946 1973 1876 2050 1980 2047 1972 2107 2085 2211 2435 2616 2624 2809 2913 3048 3160 3248 3375 3425 3542 3480 3666 3645 3577 3401 3306 3188 2880 2756 2656 2481 2392 2255 2221 2077 2020 1917 1790 1676 1700 1627 1489 1510 1470 1466 1437 1426 1325 1392 1422 1441 1468 1455 1394 1409 1410 1354 1401 1320 1333 1405 1319 1434 1396 1380 1379 1409 1340 1418 1346 1386 1471 1389 1521 1480 1574 1562 1591 1651 1820 1807 1893 2006 2017 2353 2487 2626 2914 3113 3234 3500 3527 3711 3761 3725 3580 3335 3160 2937 2861 2811 2609 2589 2411 2346 2083 1983 1786 1760 1627 1599 1557 1503 1476 1355 1367 1406 1343 1361 1340 1425 1327 1366 1350 1347 1397 1361 1331 1381 1391 1373 1370 1380 1349 1402 1365 1543 1418 1521 1414 1506 1623 1587 1513 1538 1583 1480 1542 1487 1567 1516 1628 1641 1625 1608 1661 1716 1796 1876 1866 2017 1981 1984 2128 2003 2068 2050 1897 1886 1785 1791 1778 1730 1652 1670 1552 1550 1483 1428 1475 1389 1411 1440 1425 1382 1311 1415 1345 1386 1387 1350 1283 1364 1384 1351 1420 1387 1328 1292 1317 1279 1300 1275 1334 1280 1244 1251 1254 1238 1236 1313 1301 1334 1303 1291 1293 1251 1252 1236 1256 1285 1296 1176 1304 1212 1159 1224 1139 1249 1193 1218 1244 1195 1244 1235 1166 1199 1247 1199 1190 1183 1173 1291 1189 1258 1179 1208 1209 1234 1234 1197 1234 1249 1258 1282 1233 1304 1211 1199 1166 1216 1165 1199 1242 1186 1238 1174 1186 1175 1196 1224 1239 1191 1137 1218 1179 1123 1080 1165 1153 1183 1173 1201 1135 1243 1141 1224 1235 1180 1197 1163 1239 1178 1153 1190 1227 1195 1185 1166 1224 1218 1246 1288 1215 1274 1333 1272 1365 1338 1334 1310 1291 1217 1273 1226 1193 1253 1183 1233 1214 1195 1203 1167 1191 1209 1207 1259 1213 1214 1204 1195 1183 1209 1267 1244 1175 1266 1181 1210 1165 1174 1155 1153 1109 1139 1215 1180 1188 1166 1193 1078 1157 1129 1106 1162 1173 1103 1143 1174 1192 1148 1211 1192 1235 1153 1160 1129 1181 1180 1192 1161 1245 1169 1231 1112 1134 1198 1191 1243 1102 1190 1127 1118 1115 1114 1169 1237 1214 1228 1128 1177 1118 1191 1239 1244 1197 1164 1182 1284 1213 1250 1295 1266 1248 1292 1300 1382 1501 1539 1693 1677 1811 1901 1990 2021 2056 2084 1910 1957 1747 1770 1656 1700 1685 1550 1643 1589 1448 1459 1404 1350 1342 1332 1275 1304 1252 1306 1207 1201 1257 1230 1256 1259 1240 1224 1151 1236 1221 1223 1228 1172 1193 1217 1217 1209 1218 1156 1122 1225 1160 1122 1183 1171 1236 1173 1206 1171 1262 1203 1181 1208 1216 1197 1194 1243 1209 1267 1214 1308 1292 1341 1354 1454 1399 1395 1357 1321 1374 1287 1316 1207 1316 1283 1329 1297 1296 1310 1265 1348 1217 1201 1178 1173 1300 1285 1213 1257 1159 1255 1231 1234 1223 1249 1206 1263 1222 1275 1213 1284 1257 1285 1246 1302 1354 1382 1343 1370 1349 1419 1354 1380 1456 1432 1458 1434 1516 1458 1390 1374 1376 1348 1360 1330 1426 1378 1330 1320 1291 1272 1238 1260 1241 1195 1165 1193 1177 1176 1126 1173 1159 1133 1145 1199 1175 1196 1147 1128 1136 1091 1181 1126 1191 1093 1139 1106 1072 1178 1113 1186 1151 1156 1154 1142 1133 1128 1131 1128 1126 1196 1167 1119 1147 1151 1150 1144 1170 1171 1154 1151 1173 1114 1172 1115 1140 1126 1157 1118 1125 1199 1160 1159 1174 1190 1167 1135 1043 1192 1100 1140 1107 1088 1124 1144 1103 1060 1179 1148 1156 1166 1200 1189 1123 1210 1146 1150 1066 1082 1090 1132 1145 1063 1198 1096 1159 1125 1149 1075 1150 1110 1150 1157 1110 1052 1104 1071 1110 1079 1085 1105 1119 1097 1177 1127 1158 1144 1092 1108 1113 1097 1112 1179 1110 1034 1156 1081 1149 1080 1083 1076 1149 1138 1168 1123 1150 1127 1152 1210 1139 1163 1159 1134 1154 1138 1117 1098 1143 1108 1180 1130 1174 1154 1170 1199 1230 1229 1209 1229 1189 1231 1293 1196 1249 1168 1186 1262 1253 1226 1267 1204 1217 1148 1232 1214 1230 1203 1231 1186 1120 1175 1163 1277 1214 1148 1197 1187 1249 1224 1235 1220 1241 1264 1263 1307 1284 1213 1325 1298 1267 1407 1352 1477 1390 1461 1482 1656 1602 1662 1723 1735 1777 1860 1855 1953 2028 1965 2112 2116 2079 2168 2170 2080 2093 2001 2002 1860 1788 1729 1676 1621 1630 1656 1583 1570 1477 1450 1400 1403 1331 1285 1245 1243 1243 1202 1241 1174 1295 1235 1219 1217 1227 1267 1261 1212 1234 1255 1282 1160 1275 1337 1247 1235 1265 1276 1346 1233 1260 1297 1322 1311 1307 1362 1318 1328 1412 1446 1413 1374 1404 1428 1456 1525 1442 1588 1567 1629 1617 1609 1701 1753 1702 1866 1877 1941 1973 2138 2117 2151 2324 2389 2618 2744 2994 3152 3506 3861 4437 4873 5591 6285 7016 7861 8816 9916 10882 12317 13708 14819 15255 15663 15103 13849 12178 10782 9852 9374 8965 8995 9002 9006 8780 8139 7423 6280 5410 4611 3732 3540 2878 2742 2426 2378 2247 2160 2037 1974 1877 1852 1858 1765 1699 1656 1667 1642 1667 1617 1765 1692 1595 1705 1721 1666 1740 1853 1789 1829 1969 1970 2093 2304 2534 2566 3007 3275 3704 4326 4827 5354 6080 6782 7236 7333 7095 6713 6188 5478 5087 4730 4573 4538 4463 4712 4600 4613 4180 3783 3312 2902 2625 2224 2007 1938 1803 1733 1613 1647 1585 1594 1498 1511 1492 1430 1387 1373 1331 1339 1357 1326 1319 1275 1327 1289 1304 1338 1271 1271 1243 1269 1244 1350 1305 1267 1331 1332 1281 1230 1205 1307 1238 1264 1282 1250 1277 1251 1296 1221 1231 1251 1214 1245 1237 1210 1234 1305 1256 1282 1266 1254 1345 1337 1362 1324 1301 1356 1432 1487 1378 1382 1565 1523 1578 1655 1608 1741 1765 1918 2055 2272 2524 2862 3266 3363 3940 4135 4535 4756 4621 4517 4239 3964 3588 3363 3136 3151 3116 3252 3184 3116 3121 2875 2651 2484 2268 2063 1904 1776 1637 1644 1494 1503 1586 1559 1489 1486 1474 1583 1594 1565 1688 1821 1768 1809 1828 1838 1830 1761 1691 1635 1575 1644 1622 1546 1564 1553 1558 1446 1517 1459 1455 1455 1367 1321 1328 1312 1250 1380 1422 1321 1336 1249 1268 1254 1311 1253 1244 1290 1232 1234 1269 1167 1265 1280 1318 1176 1224 1241 1256 1230 1198 1274 1334 1245 1272 1322 1312 1256 1233 1315 1226 1296 1309 1329 1260 1214 1329 1236 1351 1316 1414 1373 1384 1362 1407 1409 1388 1387 1448 1417 1435 1445 1481 1509 1509 1418 1511 1494 1479 1438 1392 1392 1421 1450 1448 1447 1379 1370 1415 1369 1310 1404 1321 1369 1339 1334 1291 1399 1342 1352 1341 1358 1394 1320 1526 1399 1510 1522 1621 1781 1814 2023 2010 2327 2284 2484 2423 2446 2370 2335 2340 2158 2153 2162 2048 2121 2071 2053 2104 2089 2012 1977 1850 1831 1775 1701 1668 1553 1563 1522 1442 1334 1376 1416 1370 1355 1321 1369 1283 1341 1277 1296 1199 1227 1239 1249 1278 1164 1291 1227 1235 1181 1159 1210 1196 1171 1248 1223 1193 1207 1268 1243 1210 1207 1175 1263 1266 1244 1246 1166 1273 1178 1312 1279 1284 1318 1308 1303 1312 1365 1280 1371 1386 1315 1446 1448 1492 1520 1484 1558 1535 1598 1550 1618 1686 1632 1689 1773 1806 1713 1907 1984 1942 2106 2156 2274 2341 2513 2520 2591 2745 2754 2847 2990 3018 2851 2822 2741 2621 2563 2549 2376 2342 2394 2395 2374 2336 2283 2261 2200 2037 2088 2020 2057 2054 2024 2115 2157 2268 2293 2355 2632 2573 2552 2435 2433 2254 2086 1993 1927 1970 1949 1998 1912 1920 1990 1898 1857 1752 1694 1603 1562 1454 1473 1434 1399 1379 1396 1312 1322 1264 1313 1339 1304 1295 1289 1280 1252 1273 1206 1277 1269 1254 1256 1271 1188 1215 1204 1207 1240 1212 1193 1167 1195 1154 1165 1246 1168 1190 1146 1181 1194 1147 1200 1171 1131 1184 1129 1209 1129 1219 1182 1166 1190 1217 1200 1185 1178 1199 1145 1167 1126 1188 1199 1209 1207 1195 1175 1175 1196 1212 1180 1159 1104 1241 1200 1222 1219 1273 1233 1257 1189 1246 1176 1202 1163 1151 1137 1197 1186 1232 1253 1176 1226 1228 1153 1258 1154 1205 1137 1138 1167 1223 1188 1164 1233 1182 1146 1237 1160 1115 1234 1193 1161 1106 1179 1208 1151 1163 1201 1246 1149 1171 1169 1198 1204 1261 1246 1216 1238 1231 1230 1221 1263 1193 1232 1152 1195 1283 1241 1189 1224 1154 1158 1248 1214 1186 1227 1118 1162 1190 1190 1098 1196 1194 1225 1162 1130 1131 1208 1220 1189 1174 1208 1186 1245 1190 1207 1202 1189 1164 1233 1182 1161 1236 1217 1146 1201 1181 1246 1290 1245 1189 1193 1318 1255 1216 1286 1182 1347 1238 1297 1338 1359 1352 1381 1382 1418 1474 1541 1629 1594 1647 1661 1588 1586 1611 1569 1557 1533 1550 1603 1688 1729 1859 1864 1999 2114 2301 2337 2538 2686 2938 3066 3186 3343 3394 3287 3295 3158 2877 2732 2702 2638 2618 2550 2557 2634 2648 2665 2712 2579 2617 2408 2374 2357 2168 2366 2247 2411 2549 2694 2961 3256 3644 4209 4756 5402 6077 6959 7682 8275 8342 7987 7327 6622 5730 5036 4690 4470 4476 4445 4741 4819 5071 4932 4912 4581 4185 3718 3160 2810 2506 2210 2039 1989 1815 1792 1740 1700 1689 1688 1608 1555 1519 1554 1620 1586 1515 1479 1491 1517 1448 1470 1508 1499 1502 1438 1481 1516 1534 1567 1575 1533 1627 1571 1651 1738 1795 1844 1986 2165 2219 2421 2589 2875 3150 3399 3639 4029 4226 4510 4634 4775 4718 4665 4350 4222 3906 3815 3636 3531 3536 3669 3612 3796 3831 3816 3850 3685 3614 3725 3718 3587 3481 3704 3712 3792 3920 4107 4319 4549 4928 5152 5922 6563 7408 8334 9324 10834 11887 13139 13897 13952 13117 12231 10734 9336 8331 7442 7123 7195 7175 7558 7765 8290 8243 8263 7487 7091 6018 5382 4596 4058 3536 3171 2828 2641 2517 2488 2279 2296 2132 2106 2059 1962 1895 1881 1874 1747 1712 1612 1638 1590 1481 1473 1482 1470 1480 1418 1483 1447 1356 1482 1383 1432 1339 1370 1375 1424 1340 1380 1407 1387 1393 1406 1431 1334 1419 1445 1354 1528 1426 1506 1564 1515 1629 1641 1750 1823 1809 1983 2001 2064 2112 2127 2223 2118 2064 2024 1921 1814 1786 1749 1814 1740 1798 1778 1704 1654 1620 1687 1633 1564 1504 1518 1440 1389 1396 1361 1372 1350 1372 1269 1236 1259 1265 1184 1271 1277 1188 1322 1202 1214 1192 1190 1163 1217 1189 1187 1198 1212 1225 1264 1256 1159 1230 1225 1313 1180 1238 1191 1199 1225 1218 1164 1224 1211 1253 1249 1236 1234 1172 1210 1184 1320 1223 1229 1248 1295 1243 1289 1270 1295 1254 1215 1244 1253 1276 1299 1323 1281 1374 1253 1267 1329 1313 1362 1314 1277 1338 1273 1294 1291 1251 1323 1290 1367 1388 1348 1382 1402 1388 1413 1363 1456 1528 1655 1695 1783 1918 1978 2148 2453 2667 3044 3466 3916 4572 5055 5541 6003 6141 5918 5431 4985 4217 3811 3384 3332 3132 3194 3294 3419 3500 3737 3809 3751 3587 3096 2865 2681 2310 2067 1831 1794 1623 1528 1562 1498 1434 1445 1375 1387 1322 1372 1293 1274 1319 1317 1299 1298 1314 1295 1268 1187 1261 1245 1217 1226 1248 1246 1353 1239 1303 1220 1265 1372 1260 1302 1251 1350 1262 1328 1326 1320 1363 1348 1340 1407 1482 1509 1470 1638 1597 1749 1703 1746 1813 1808 1818 1853 1797 1713 1723 1646 1610 1584 1634 1650 1614 1553 1527 1568 1507 1551 1442 1522 1441 1458 1464 1358 1377 1306 1326 1266 1262 1292 1275 1305 1279 1272 1361 1338 1363 1321 1351 1360 1423 1521 1577 1543 1612 1611 1723 1651 1642 1635 1514 1468 1484 1390 1367 1366 1343 1410 1331 1430 1408 1536 1343 1367 1331 1326 1295 1269 1277 1179 1166 1127 1121 1106 1204 1144 1161 1157 1104 1179 1113 1135 1131 1173 1120 1193 1094 1166 1205 1159 1190 1209 1218 1257 1235 1279 1339 1351 1451 1428 1482 1340 1363 1282 1295 1323 1312 1264 1237 1361 1286 1345 1291 1359 1287 1326 1382 1341 1391 1260 1243 1327 1285 1249 1333 1322 1254 1307 1312 1336 1323 1283 1342 1310 1258 1269 1179 1202 1237 1206 1176 1199 1235 1303 1183 1228 1191 1262 1168 1170 1154 1158 1149 1145 1101 1122 1111 1134 1089 1186 1101 1132 1142 1132 1150 1125 1174 1167 1215 1236 1184 1263 1145 1261 1239 1218 1212 1152 1221 1185 1168 1245 1179 1225 1216 1188 1220 1188 1200 1193 1174 1193 1168 1150 1217 1245 1247 1122 1110 1180 1231 1157 1168 1218 1176 1204 1209 1181 1192 1272 1267 1333 1298 1283 1278 1294 1321 1342 1408 1380 1399 1403 1422 1363 1391 1408 1417 1412 1403 1469 1404 1395 1434 1383 1391 1398 1405 1383 1320 1356 1257 1265 1262 1354 1236 1208 1193 1213 1171 1200 1221 1222 1185 1156 1195 1138 1129 1063 1117 1141 1115 1134 1076 1092 1054 1119 1068 1094 1144 1084 1138 1128 1141 1051 1088 1086 1115 1140 1087 1069 1040 1153 1103 1082 1065 1115 1122 1036 1100 1053 1133 1063 1085 1067 1120 1107 1107 1036 1057 1166 1128 1007 1060 1066 1105 1145 1065 1177 1101 1094 1175 1144 1119 1220 1245 1320 1296 1335 1306 1451 1538 1536 1688 1735 1776 1840 1757 1746 1645 1550 1519 1476 1452 1474 1458 1417 1583 1606 1577 1631 1616 1589 1529 1586 1460 1332 1315 1274 1325 1271 1228 1249 1184 1296 1236 1226 1236 1181 1213 1232 1139 1263 1228 1258 1277 1260 1348 1356 1467 1506 1594 1731 1873 2080 2143 2370 2504 2476 2538 2470 2345 2121 1970 1897 1718 1673 1710 1589 1668 1713 1800 1751 1852 1782 1842 1706 1665 1611 1639 1476 1342 1350 1327 1266 1187 1189 1191 1154 1165 1135 1124 1030 1115 1133 1142 1159 1134 1113 1086 1087 1137 1130 1150 1128 1070 1153 1151 1106 1135 1175 1119 1183 1146 1167 1171 1186 1155 1184 1169 1191 1150 1195 1254 1229 1165 1177 1205 1251 1237 1238 1234 1235 1279 1365 1426 1350 1472 1404 1592 1542 1530 1631 1621 1651 1603 1557 1567 1588 1484 1489 1507 1360 1434 1416 1470 1335 1403 1352 1444 1371 1480 1392 1362 1267 1289 1247 1204 1219 1190 1179 1110 1127 1034 1103 1092 1123 1151 1097 1082 1070 1126 1082 1114 1070 1139 1034 1083 1041 1018 1014 1050 984 1033 1033 1055 1032 1002 1062 1075 1017 1055 1046 1023 1007 1009 1025 1011 982 1032 1103 1091 1073 994 1071 1038 999 1052 1073 1074 1057 1099 1018 1009 1043 975 1007 1034 1046 1034 1066 1087 1032 1047 1035 1065 1086 1062 1102 1031 1078 1088 1076 1055 1051 1095 1111 1131 1088 1123 1119 1085 1149 1117 1069 1158 1136 1129 1156 1134 1192 1155 1095 1135 1158 1115 1196 1152 1119 1193 1171 1137 1133 1140 1214 1067 1185 1107 1063 1093 1062 1125 1081 1077 1070 1118 1103 1057 1104 1053 1093 1060 1075 1085 1031 1032 1081 963 961 1004 1011 1025 1008 1019 1063 1059 1108 1049 1050 962 1016 958 1009 1013 1030 1062 1033 1051 986 1054 1050 1037 1044 1037 1115 990 1027 998 1070 1018 1083 1028 1062 1054 1021 1014 1035 1063 1039 1060 1064 1069 1054 1105 1095 1078 997 1048 1128 1099 1116 1139 1091 1132 1120 1106 1099 1098 1105 1120 1061 1155 1105 1153 1221 1213 1217 1226 1207 1217 1224 1196 1187 1177 1208 1191 1195 1183 1213 1127 1205 1200 1189 1248 1205 1253 1265 1327 1378 1395 1502 1444 1545 1698 1696 1818 1918 1936 1853 1808 1685 1599 1441 1430 1312 1396 1248 1295 1339 1368 1405 1499 1437 1443 1514 1460 1388 1456 1336 1296 1213 1184 1166 1110 1121 1056 1089 1078 1077 1084 1089 1120 1042 1119 1040 1124 1141 1019 1053 1015 1031 1033 1080 1126 1054 1022 1108 1087 1084 1004 1066 1072 1082 1071 1059 1123 1086 1077 1025 1111 1080 1092 1073 1103 1137 1085 1090 1162 1107 1066 1130 1052 1043 1064 1061 1037 1113 1082 1008 1107 1158 1094 1034 1069 1058 1060 1131 1102 1067 1052 1065 1046 1081 1102 1064 1061 1080 1068 1089 1100 1074 1087 1026 1030 1003 1130 1079 1179 1091 1108 1114 1128 1112 1202 1160 1112 1094 1083 1050 1049 1026 1045 1036 981 1077 1061 1080 1093 1074 1144 1016 1129 1107 1038 1064 1107 1097 1102 1016 1044 1085 1095 1058 1157 1106 1111 1083 1115 1071 1121 1134 1079 1077 1084 1107 1061 1057 1110 1144 1113 1147 1100 1110 1097 1127 1090 1165 1124 1192 1056 1122 1083 1138 1111 1170 1161 1180 1167 1188 1241 1220 1313 1305 1338 1385 1511 1527 1732 1778 1976 2069 2182 2295 2317 2334 2230 2098 1925 1749 1704 1602 1556 1508 1570 1605 1661 1721 1710 1922 1965 1966 2041 2123 2167 2025 2055 1950 1983 1861 1744 1748 1685 1567 1492 1415 1466 1393 1336 1428 1313 1422 1379 1328 1388 1331 1393 1411 1454 1307 1321 1347 1257 1238 1242 1210 1108 1189 1223 1254 1195 1245 1187 1297 1357 1319 1416 1464 1401 1369 1363 1315 1252 1201 1213 1147 1118 1143 1151 1169 1111 1137 1153 1201 1216 1209 1204 1172 1179 1111 1070 1035 1092 1063 1095 1048 1013 1059 1025 995 1002 983 1009 988 962 992 1042 987 1009 1019 969 988 942 1026 945 976 963 953 959 1024 1042 994 940 1014 939 1066 963 976 993 947 1006 1002 998 997 998 988 940 1065 1041 1114 1022 1109 1042 1056 1022 1073 1060 1130 1077 1173 1185 1187 1275 1234 1320 1355 1375 1547 1366 1501 1489 1484 1725 1678 1701 1730 1881 1964 1896 1864 1900 1806 1797 1726 1626 1618 1605 1490 1521 1539 1447 1453 1567 1521 1558 1462 1452 1506 1380 1452 1375 1353 1308 1231 1243 1290 1188 1177 1148 1039 1122 1021 1185 1056 1096 1033 1037 1084 1099 1015 1084 1065 1090 1104 1139 1094 1050 1120 1122 1133 1195 1160 1176 1215 1216 1297 1332 1402 1373 1438 1428 1380 1383 1327 1262 1375 1370 1360 1338 1349 1445 1452 1446 1614 1614 1673 1689 1674 1740 1638 1621 1578 1593 1463 1439 1364 1331 1358 1378 1348 1321 1418 1356 1374 1327 1266 1264 1285 1270 1288 1236 1240 1225 1151 1171 1127 1172 1092 1084 1025 1034 967 1051 1005 1083 956 1032 980 1045 994 987 1005 1001 961 925 1068 970 1049 996 921 969 919 905 1032 959 970 898 947 973 951 974 978 984 887 970 918 977 957 1052 986 986 1056 1022 1117 1001 1078 1016 1107 1096 1051 1070 1013 1015 1002 1051 991 960 1026 954 1072 1018 982 988 1002 968 1049 1013 1034 1026 1006 1016 1050 1048 1032 1105 987 982 1010 1075 1077 1080 1051 1108 1057 1040 1104 1051 1079 1082 1077 1075 1062 1006 966 1019 1010 1052 1044 1069 973 1001 1112 1002 1115 1030 1078 1074 1062 1015 1060 1073 1049 1012 972 1007 1028 983 1079 1028 1029 1004 1073 1002 1006 1053 1004 996 1058 1009 1024 1051 1052 993 1057 1073 1063 1023 989 1007 994 1041 1063 1047 1087 1046 1024 1125 1114 1118 1050 1123 1170 1093 1057 1131 1147 1226 1123 1216 1086 1077 1136 1110 1150 1054 1138 1115 1101 1114 1062 1120 1154 1043 1073 1112 1061 1163 1150 1063 1085 1119 1110 1106 1103 1128 1071 1067 1074 1160 1034 1051 1073 1083 1115 1128 1048 1110 1054 1050 1027 1027 1062 1080 1091 1032 1115 1074 1047 999 1082 988 1067 1095 1109 981 1141 1012 1111 1090 1129 1165 1136 1148 1149 1188 1213 1222 1276 1248 1201 1271 1202 1217 1249 1242 1236 1185 1218 1284 1222 1292 1227 1247 1246 1251 1246 1302 1264 1205 1262 1268 1286 1297 1284 1386 1226 1330 1328 1337 1427 1416 1549 1461 1599 1631 1816 1785 2002 2214 2378 2665 2996 3434 3888 4192 4711 4870 4963 4755 4509 4108 3572 3274 2879 2626 2526 2241 2308 2224 2337 2285 2350 2508 2798 2855 3022 3155 3224 3155 2956 2631 2430 2232 2071 1831 1720 1658 1630 1527 1484 1474 1449 1393 1442 1383 1444 1441 1622 1545 1573 1666 1748 1809 1852 2009 2185 2043 2128 2115 2085 1821 1858 1723 1619 1573 1523 1512 1511 1490 1486 1588 1722 1528 1518 1606 1662 1710 1743 1711 1649 1451 1560 1497 1531 1387 1424 1447 1388 1449 1454 1487 1523 1585 1694 1698 1938 2084 2206 2461 2684 2719 2742 2609 2606 2358 2182 2039 1752 1787 1627 1610 1606 1651 1597 1608 1672 1683 1766 1811 1911 1983 2062 2028 2012 1890 1862 1712 1732 1586 1651 1649 1658 1775 1844 1999 2128 2314 2508 2794 2880 3189 3189 3071 2987 2795 2472 2350 2264 2093 1883 1822 1815 1740 1632 1715 1719 1816 1861 1889 2080 2030 2139 2083 2083 1986 1832 1706 1652 1502 1497 1408 1381 1367 1286 1270 1278 1205 1184 1129 1144 1093 1126 1091 1088 1121 1168 1123 1097 1145 1133 1131 1133 1057 1085 1127 1141 1103 1116 1068 1165 1153 1219 1229 1279 1224 1368 1371 1293 1416 1453 1310 1366 1269 1243 1249 1152 1170 1135 1130 1139 1171 1127 1068 1079 1121 1117 1200 1160 1170 1239 1176 1212 1174 1183 1165 1112 1109 1080 1063 1078 1148 1048 1047 1117 1081 1099 1091 1103 1099 1085 1084 1117 1005 1091 1112 1070 1087 1086 1059 1182 1129 1110 1191 1119 1237 1262 1254 1236 1268 1265 1387 1448 1603 1614 1694 1828 2051 2233 2404 2447 2624 2669 2464 2401 2233 2109 1918 1878 1783 1808 1665 1689 1693 1762 1721 1805 1932 1929 1977 2057 1978 2022 2030 2023 1944 1802 1758 1657 1655 1587 1658 1464 1559 1541 1531 1536 1587 1646 1687 1782 1778 1818 1963 2196 2169 2421 2464 2532 2524 2341 2172 1961 1790 1722 1510 1547 1488 1479 1465 1449 1510 1508 1413 1542 1636 1649 1658 1772 1712 1808 1682 1722 1576 1328 1357 1321 1323 1279 1201 1239 1145 1173 1117 1114 1085 1190 1151 1101 1098 1074 1039 1079 1107 982 1107 1049 1093 1023 1043 1065 1038 988 1022 1016 1026 986 993 988 1011 1062 983 994 1032 1078 1028 1033 1046 1052 1005 1010 1013 1054 1091 1107 1048 1100 1074 1084 1093 989 1076 1050 1136 1016 1055 1031 1053 1097 1071 1120 1088 1061 1075 1103 1164 1136 1209 1089 1103 1188 1126 1171 1113 1181 1095 1162 1106 1103 1066 1060 1092 1071 1074 1046 1047 1088 1074 1032 1057 1056 1068 1026 1037 1072 1053 1057 1011 1107 1056 1039 1006 995 995 962 1011 947 1013 995 974 1019 1043 1070 1021 1045 1014 1026 1006 1022 1013 1008 1016 989 990 954 1069 970 1027 1030 1002 974 901 966 1004 1038 1049 1008 1017 990 925 1013 978 1017 953 955 1038 973 998 1027 993 1057 1073 1054 1060 1093 1070 1101 1153 1173 1120 1119 1165 1126 1159 1100 1221 1124 1234 1244 1231 1202 1149 1270 1165 1173 1192 1099 1208 1164 1159 1288 1245 1232 1311 1249 1299 1224 1198 1206 1154 1144 1098 1105 1112 1093 1145 1065 1125 1070 1137 1052 1092 1174 1072 1127 1058 1049 1096 1083 1046 1061 1030 1023 1005 1047 1069 1037 1028 1076 1125 1003 1082 1068 1049 1061 1040 1047 1030 1036 1063 1034 1068 969 1026 1047 1035 1016 1031 994 1025 985 1048 1038 1062 968 1059 1027 1028 975 1003 1032 1010 977 1001 1003 942 1008 994 1036 1043 1011 1038 1054 1026 1130 1063 1085 1150 1098 1170 1148 1232 1185 1209 1254 1157 1202 1205 1164 1214 1142 1110 1125 1072 1055 1076 1074 1108 1025 1113 1100 1128 1146 1118 1097 1166 1116 1089 1131 1124 1055 1071 1135 1113 1077 1126 1067 1129 1131 1129 1090 1042 1172 1095 1165 1154 1115 1052 1050 1011 1084 1092 1075 1034 986 1008 1036 1018 1025 1050 1042 961 1036 1064 1061 1062 1046 1113 1055 1025 1054 1058 1049 1080 1064 1126 1106 1121 1031 1086 1132 1119 1104 1085 1065 1163 1135 1068 1090 1000 1073 1024 1053 1024 1054 1000 980 1045 1098 1118 1144 1072 1105 1135 1084 1058 1132 1074 1089 1092 1121 1072 1048 1143 1108 1121 1134 1095 1176 1179 1242 1187 1226 1291 1386 1373 1388 1364 1469 1512 1512 1402 1395 1378 1307 1352 1216 1153 1234 1141 1146 1180 1225 1193 1226 1171 1166 1215 1180 1225 1311 1303 1290 1287 1252 1263 1179 1282 1159 1144 1175 1140 1167 1133 1095 1123 1168 1173 1132 1164 1309 1248 1285 1255 1439 1332 1467 1427 1486 1447 1388 1415 1439 1366 1341 1322 1264 1214 1215 1210 1145 1134 1163 1201 1199 1116 1158 1219 1184 1200 1208 1245 1259 1169 1197 1148 1200 1125 1156 1129 1072 1027 1034 1007 1002 1028 1019 970 1028 967 1044 1096 1062 1070 1058 1074 1115 1064 1097 1028 1046 1059 908 1033 999 998 954 912 964 958 960 955 1013 965 1009 1021 1045 1014 1015 1051 1048 975 1038 963 1010 990 1013 953 987 968 922 1005 961 1055 988 974 1001 927 986 959 955 936 964 937 1064 1059 987 1017 952 934 933 1001 977 1001 967 965 988 1066 1051 952 1031 1047 1006 1029 1109 1038 1113 1080 1099 1084 1081 1110 1150 1135 1053 1126 1061 1070 1058 1066 1011 1087 1125 1059 1002 1062 1164 1104 1090 1106 1060 1077 1062 1158 1101 1121 1101 1148 1055 1166 1142 1101 1132 1108 1140 1075 1094 1108 1085 1139 1136 1107 1115 1233 1062 1201 1156 1151 1251 1257 1290 1377 1428 1640 1700 1809 1971 2126 2203 2171 2139 2054 1871 1817 1626 1583 1440 1349 1366 1289 1291 1196 1203 1258 1210 1244 1277 1258 1382 1410 1457 1520 1496 1573 1472 1570 1436 1356 1315 1190 1215 1126 1215 1151 1097 1071 1018 1062 1042 1052 1005 1027 980 1001 985 1001 957 1042 1003 1011 999 1016 1062 1058 1115 1051 1104 1182 1148 1168 1234 1278 1205 1289 1296 1321 1323 1298 1254 1254 1241 1215 1187 1134 1190 1136 1089 1072 1177 1123 1145 1152 1101 1106 1154 1154 1190 1127 1219 1186 1314 1290 1145 1179 1233 1139 1168 1183 1234 1243 1269 1223 1274 1302 1250 1233 1264 1213 1224 1224 1188 1189 1174 1126 1143 1161 1232 1153 1172 1231 1277 1258 1324 1392 1440 1543 1580 1739 1847 2001 2122 2210 2516 2735 2900 2956 2896 2794 2593 2425 2238 2000 1813 1720 1681 1631 1544 1443 1499 1397 1445 1441 1431 1553 1619 1750 1798 1752 1986 1923 1961 1964 1949 1844 1674 1592 1458 1387 1371 1307 1185 1238 1135 1168 1122 1116 1102 1058 1074 1118 1011 1035 1007 1009 1041 967 1007 1017 960 948 973 957 972 1065 1011 1014 951 1007 960 952 972 1018 943 964 979 985 972 990 1010 965 959 965 951 953 1025 1000 976 971 1016 981 990 957 859 949 958 992 970 954 1006 955 964 1036 998 1025 984 1056 994 1044 1016 1092 1046 1062 1015 1003 982 1004 1029 918 953 927 942 920 952 967 881 919 929 985 910 955 985 900 976 943 925 976 948 950 944 955 1016 987 971 892 933 950 880 929 918 914 933 885 933 920 919 943 897 933 877 920 971 928 1012 920 970 1005 915 968 940 919 946 972 917 926 943 945 931 894 950 903 950 889 984 945 900 1004 972 964 930 909 979 951 967 916 994 868 942 959 965 960 924 949 896 988 899 1000 928 946 940 910 887 890 895 925 927 950 911 890 925 880 929 943 939 933 921 985 908 927 902 950 896 893 876 957 942 931 960 894 876 876 919 954 907 946 855 922 946 937 909 947 855 908 882 899 890 896 960 929 917 862 887 935 960 970 933 923 938 931 952 893 968 904 871 943 948 910 927 919 932 965 889 881 951 929 921 857 918 927 889 914 930 938 971 905 922 905 934 924 922 905 986 928 937 875 1040 934 927 933 917 955 931 869 927 960 972 892 961 945 927 933 913 918 975 868 993 988 971 939 904 977 915 937 911 880 909 992 929 1048 1036 936 900 938 964 940 966 964 1039 1030 953 999 973 945 942 951 995 991 1046 1049 978 992 1024 1040 1035 1026 1029 1101 1056 1010 1059 1033 998 1082 1121 1024 1056 1077 1110 1045 1105 1115 1110 1195 1142 1315 1243 1284 1344 1471 1573 1669 1696 1813 1972 2038 2032 1983 1843 1759 1667 1524 1430 1340 1326 1292 1274 1201 1167 1154 1216 1219 1176 1169 1208 1244 1226 1254 1244 1362 1440 1507 1542 1510 1434 1298 1309 1252 1243 1236 1138 1100 1034 1050 1072 1027 985 940 1008 1088 970 991 936 977 963 956 920 979 970 933 1031 938 1033 918 967 925 960 971 952 975 984 923 964 935 1036 924 963 952 932 932 907 896 975 947 974 1003 924 1035 946 925 904 940 924 984 971 975 944 1009 962 978 902 944 902 966 936 1025 969 1009 994 1031 978 975 1024 996 994 1032 960 917 1003 1006 951 1006 975 950 1022 1052 933 956 1004 952 1007 978 1076 1028 1071 1107 1173 1166 1246 1183 1214 1109 1171 1116 1147 1135 1045 1078 1095 1050 1060 1012 1050 1007 984 1073 1034 1034 1010 1062 1037 1099 1137 1081 1139 1108 1066 1109 1122 1156 1120 1132 1158 1101 1186 1148 1251 1187 1275 1292 1348 1387 1417 1513 1620 1794 1859 1845 1771 1750 1686 1634 1394 1409 1329 1270 1299 1191 1246 1148 1119 1149 1151 1202 1267 1181 1230 1187 1246 1327 1292 1294 1386 1441 1445 1461 1430 1444 1404 1327 1257 1240 1192 1171 1192 1199 1137 1115 1078 1126 1090 1071 1067 1073 1105 1124 1039 1041 1059 1052 1030 1070 1159 1134 1149 1060 1064 1063 1081 1130 1101 1117 1055 1113 1191 1089 1055 1132 1159 1136 1150 1147 1210 1142 1232 1237 1331 1323 1404 1454 1494 1618 1832 1897 2037 2175 2362 2316 2432 2289 2190 2175 2026 1821 1769 1771 1616 1631 1487 1588 1565 1581 1581 1525 1497 1423 1471 1470 1415 1533 1491 1553 1573 1707 1837 1804 1848 1887 1858 1783 1739 1666 1647 1591 1516 1499 1444 1405 1291 1300 1281 1322 1210 1264 1246 1216 1178 1134 1154 1220 1160 1168 1178 1163 1062 1142 1142 1145 1117 1180 1183 1182 1129 1141 1122 1087 1110 1063 1061 1100 1032 1045 1021 1036 1033 1047 1027 1053 1031 1042 954 1002 988 1009 1013 1082 1038 1071 1014 1020 1052 1010 1039 980 1004 978 973 986 1049 1047 1026 1027 994 1067 1068 1027 1047 1015 1134 1059 1048 1117 1061 1122 1084 1118 1156 1175 1193 1233 1227 1255 1215 1200 1143 1185 1159 1171 1120 1060 1052 1113 1184 1116 1111 1176 1117 1157 1255 1186 1151 1142 1223 1181 1238 1173 1192 1164 1153 1155 1202 1126 1099 1040 1148 1033 1061 1043 983 1053 1011 1036 953 1002 998 1023 1056 1005 1021 979 1059 1006 1068 961 958 951 993 968 1012 959 993 959 918 951 981 970 950 987 915 989 902 942 907 919 956 957 927 972 966 989 915 912 930 938 911 977 868 909 916 935 936 919 928 931 927 955 962 951 1007 951 918 973 951 961 988 914 1007 980 901 896 947 984 918 943 958 966 943 920 935 998 938 958 953 951 970 993 1057 940 976 1004 965 956 996 905 953 953 899 938 922 888 923 916 887 921 906 933 944 937 994 961 963 959 973 1009 948 916 936 928 1041 997 898 954 970 929 995 968 938 954 979 954 958 886 881 899 967 889 947 951 938 924 958 920 948 914 892 967 929 964 880 905 866 940 916 923 999 928 1010 957 1040 947 962 965 999 956 1003 960 909 927 1004 940 953 1014 935 952 964 963 1000 968 950 951 944 1019 1000 967 950 1004 953 1017 1036 1031 1052 1036 1048 998 1064 1032 1034 1073 1095 1124 1087 1075 1034 988 1058 1026 989 1069 954 994 999 1010 978 995 1019 1068 1072 1059 1045 1031 1090 1104 1083 1076 1077 1039 1063 1047 1064 1037 996 1061 985 1059 1046 1064 1027 1072 1029 984 1009 1095 1028 1090 1039 1092 1026 1082 1070 1106 1058 1134 1140 1048 1154 1057 1155 1059 1151 1089 1072 1051 1068 1032 1071 1061 1058 1094 1129 1074 1175 1150 1128 1089 1163 1065 1067 1091 1060 1020 1101 1038 1053 1056 1060 1057 1077 1060 1061 1047 1091 1005 1064 1033 1034 1021 1052 1009 1017 1069 1033 1030 1104 1038 1063 1065 1048 987 1017 947 1026 968 990 989 966 986 1000 949 975 962 952 928 959 1002 1018 1005 956 1003 996 975 947 925 979 1058 1014 983 1041 974 952 947 973 985 974 948 1015 1037 980 892 998 1010 953 947 990 1014 941 896 987 924 935 975 982 907 937 957 926 966 944 913 1007 923 1011 1015 902 980 981 953 944 937 977 1006 1090 975 1061 1022 1068 1152 1036 1122 1070 1064 1074 1093 1043 1147 1008 1043 1063 1063 1088 1040 997 1102 1085 1071 1070 1039 1034 1091 1078 1069 1028 1025</counts>
			</dataPoints>
		</scan>
	</xrdMeasurement>
</xrdMeasurements>