File: dataset/precursor_mixture/TiO2_NaHCO3_V2O5.12-min.xrdml
<?xml version="1.0"?>
<xrdMeasurements xmlns="http://www.xrdml.com/XRDMeasurement/2.2" xmlns:xsi="http://www.w3.org/2001/XMLSchema-instance" xsi:schemaLocation="http://www.xrdml.com/XRDMeasurement/2.2 http://www.xrdml.com/XRDMeasurement/2.2/XRDMeasurement.xsd" status="Completed" recordIdentifier="{2580C333-24C7-45C4-9BA7-F74100F7EC62}">
	<comment>
		<entry/>
	</comment>
	<sample type="To be analyzed">
		<id></id>
		<name></name>
		<preparedBy></preparedBy>
	</sample>
	<xrdMeasurement measurementType="Scan" status="Completed" sampleMode="Reflection">
		<usedWavelength intended="K-Alpha 1">
			<kAlpha1 unit="Angstrom">1.5405980</kAlpha1>
			<kAlpha2 unit="Angstrom">1.5444260</kAlpha2>
			<kBeta unit="Angstrom">1.3922500</kBeta>
			<ratioKAlpha2KAlpha1>0.5000</ratioKAlpha2KAlpha1>
		</usedWavelength>
		<incidentBeamPath>
			<radius unit="mm">145.00</radius>
			<xRayTube id="1010048" name="Empyrean Cu LFF HR (9430 033 7310x) DK437873">
				<tension unit="kV">40.0</tension>
				<current unit="mA">15.0</current>
				<anodeMaterial>Cu</anodeMaterial>
				<focus type="Line">
					<length unit="mm">12.0</length>
					<width unit="mm">0.4</width>
					<takeOffAngle unit="deg">6.0</takeOffAngle>
				</focus>
			</xRayTube>
			<filter id="20010004" name="Beta-filter Nickel">
				<material>Ni</material>
				<thickness unit="mm">0.020</thickness>
			</filter>
			<sollerSlit id="21010002" name="Soller slits 0.04 rad.">
				<opening unit="rad">0.0400</opening>
			</sollerSlit>
			<mask id="22031000" name="Fixed mask 13 mm">
				<width unit="mm">9.00</width>
			</mask>
			<divergenceSlit id="22120001" name="Divergence slit 1°" xsi:type="fixedDivergenceSlitType">
				<distanceToSample unit="mm">50.00</distanceToSample>
				<height unit="mm">1.52</height>
			</divergenceSlit>
		</incidentBeamPath>
		<beamKnife id="29030100" name="Beam knife low"/>
		<sampleMovement xsi:type="spinningSampleMovementType">
			<spinnerRevolutionTime unit="seconds">1.0</spinnerRevolutionTime>
		</sampleMovement>
		<diffractedBeamPath>
			<radius unit="mm">145.00</radius>
			<antiScatterSlit id="22090040" name="AS slit 9 mm" xsi:type="fixedAntiScatterSlitType">
				<height unit="mm">9.00</height>
			</antiScatterSlit>
			<sollerSlit id="21020003" name="Large Soller slits 0.04 rad.">
				<opening unit="rad">0.0400</opening>
			</sollerSlit>
			<filter id="20030001" name="Large beta-filter Nickel">
				<material>Ni</material>
				<thickness unit="mm">0.020</thickness>
			</filter>
			<detector id="7010019" name="PIXcel1D-Medipix3 detector" xsi:type="rtmsDetectorType">
				<phd unit="keV">
					<lowerLevel>4.0</lowerLevel>
					<upperLevel>11.3</upperLevel>
				</phd>
				<mode>Scanning</mode>
				<activeLength unit="deg">5.020</activeLength>
			</detector>
		</diffractedBeamPath>
		<scan appendNumber="0" mode="Continuous" scanAxis="Gonio" status="Completed">
			<header>
				<startTimeStamp>2024-03-22T22:08:48-07:00</startTimeStamp>
				<endTimeStamp>2024-03-22T22:21:15-07:00</endTimeStamp>
				<author>
					<name>Instrument</name>
				</author>
				<source>
					<applicationSoftware version="1.6 (94)">PANalytical Aeris Instrument Suite</applicationSoftware>
					<instrumentControlSoftware version="3.0.0 20211014">AERIS</instrumentControlSoftware>
					<instrumentID>2879380</instrumentID>
				</source>
			</header>
			<dataPoints>
				<positions axis="2Theta" unit="deg">
					<startPosition>9.99043322</startPosition>
					<endPosition>100.09495370</endPosition>
				</positions>
				<positions axis="Omega" unit="deg">
					<startPosition>4.99521661</startPosition>
					<endPosition>50.04747685</endPosition>
				</positions>
				<commonCountingTime unit="seconds">18.249</commonCountingTime>
				<counts unit="counts">3914 4053 3901 3888 3906 3896 3903 3901 3928 3914 3902 3806 3935 3888 3819 3930 3906 3990 3911 3825 3868 3917 3962 3835 3857 3843 3854 3783 3869 3816 3819 3795 3815 3919 3902 3876 3818 3730 3820 3739 3806 3745 3700 3735 3714 3893 3805 3621 3739 3672 3805 3624 3631 3759 3607 3779 3657 3667 3669 3604 3661 3665 3778 3563 3583 3650 3623 3552 3541 3558 3534 3675 3622 3646 3556 3571 3492 3562 3522 3652 3633 3576 3523 3538 3520 3478 3473 3553 3435 3533 3368 3514 3507 3450 3422 3498 3488 3527 3512 3583 3487 3478 3520 3514 3592 3430 3430 3376 3457 3308 3404 3262 3391 3286 3381 3458 3390 3382 3425 3409 3432 3404 3357 3435 3375 3351 3381 3305 3326 3343 3321 3449 3289 3357 3401 3170 3255 3346 3245 3297 3127 3198 3320 3272 3124 3234 3316 3146 3045 3224 3203 3248 3245 3251 3307 3220 3222 3226 3283 3130 3281 3174 3170 3142 2955 3119 3192 3189 3027 3088 3159 3126 3114 3212 3171 3100 3150 3091 3027 3055 3096 3076 3012 3114 3214 2981 3028 3182 3097 3012 3018 3148 3047 3084 2988 3030 2928 3039 3007 2856 2988 2945 2955 2951 3015 3066 3007 3138 3047 2959 3001 3021 2854 2960 3076 2925 3120 3013 2901 2915 2953 2914 3004 3122 2915 2907 2942 2917 2880 2964 2846 2977 2994 2919 2856 2952 2839 2930 2904 2850 2845 2908 2754 2827 2894 2946 2923 2814 2927 2877 2868 2840 2814 2742 2795 2956 2795 2871 2835 2859 2784 2793 2726 2841 2776 2981 2764 2765 2766 2704 2728 2769 2732 2718 2790 2767 2755 2722 2753 2702 2764 2729 2756 2671 2663 2666 2759 2777 2670 2743 2639 2697 2711 2803 2754 2661 2689 2663 2683 2694 2690 2674 2711 2669 2685 2588 2742 2683 2553 2607 2742 2594 2593 2631 2674 2568 2665 2576 2578 2663 2629 2570 2656 2466 2640 2522 2591 2593 2506 2569 2543 2570 2511 2642 2655 2589 2508 2617 2594 2577 2536 2491 2567 2587 2552 2494 2525 2609 2537 2611 2601 2549 2552 2581 2520 2543 2506 2523 2452 2481 2557 2482 2476 2464 2478 2534 2569 2586 2555 2518 2528 2533 2500 2436 2459 2399 2445 2509 2472 2495 2542 2536 2527 2482 2503 2447 2404 2381 2373 2557 2452 2420 2440 2460 2487 2379 2382 2400 2372 2423 2492 2428 2353 2412 2377 2464 2466 2399 2432 2412 2417 2431 2379 2419 2369 2507 2412 2446 2489 2446 2441 2354 2473 2381 2363 2388 2294 2377 2331 2351 2399 2398 2362 2426 2447 2405 2501 2380 2375 2488 2323 2478 2368 2441 2372 2443 2468 2492 2376 2612 2496 2564 2730 2678 2723 2702 2757 2803 2911 2940 3063 3079 3189 3252 3178 3111 3009 3012 2902 2845 2783 2730 2700 2589 2584 2541 2582 2720 2663 2641 2734 2858 2829 2903 2915 2975 3082 3075 3291 3313 3368 3592 3640 3725 3761 3871 4075 4197 4312 4258 4285 4052 4064 3815 3640 3397 3201 3010 2833 2682 2686 2535 2420 2418 2413 2377 2304 2329 2298 2297 2285 2164 2237 2259 2291 2309 2312 2360 2281 2302 2230 2299 2274 2200 2207 2252 2290 2264 2223 2194 2251 2128 2311 2239 2200 2238 2148 2207 2142 2210 2202 2209 2244 2260 2124 2249 2282 2212 2139 2139 2190 2210 2200 2160 2161 2144 2174 2095 2246 2138 2193 2019 2242 2274 2217 2195 2144 2157 2114 2117 2120 2138 2213 2187 2112 2149 2083 2129 2121 2196 2109 2129 2168 2067 2159 2178 2128 2182 2194 2171 2093 2126 2121 2102 2090 2072 2130 2127 2078 2234 2039 2178 2087 2124 2108 2073 2082 2098 2134 2100 2113 2057 2092 2116 2126 2088 2091 2105 2141 2129 2133 2130 2085 2146 2072 2045 2031 2127 2082 2121 2093 2096 2087 2099 2119 2088 2115 2128 2023 2027 2037 2092 2039 2068 2079 2071 2019 2044 2075 2034 1958 2000 2039 2148 2071 1985 1963 2101 2119 2031 2149 1982 2133 2067 2023 1986 2111 2033 2064 2068 2112 2033 2024 2038 2050 2003 1977 2125 2012 2023 2005 2001 2068 2021 2044 1990 2001 1993 1985 1973 2071 2022 2009 1926 2047 2067 2036 2039 2037 2030 2129 2042 2078 2049 2014 2053 2030 2079 2052 2036 2079 2021 2031 2103 2016 2017 2033 2042 2048 2084 2078 2054 2010 2083 2168 2063 2107 2104 2078 1996 2083 2058 2176 2158 2033 2101 2232 2250 2225 2252 2228 2338 2312 2463 2573 2686 2909 3055 3354 3506 3835 4189 4678 5169 5710 6600 7698 8413 9790 10694 10659 9944 8940 8135 7276 6196 4970 3991 3450 2876 2738 2440 2255 2174 2072 2047 2026 2065 1972 1995 1963 2014 1977 2064 1891 2056 1988 1962 1988 2053 1991 1984 1994 2035 2009 1972 1976 1881 1963 1953 1926 1857 1989 2001 1904 1874 1849 1896 1838 1821 1863 1976 1863 1878 1860 1804 1940 1910 1875 1840 1738 1887 1843 1790 1924 1871 1891 1847 1852 1804 1884 1839 1836 1900 1828 1830 1912 1884 1889 1815 1751 1848 1826 1903 1811 1829 1863 1827 1822 1903 1830 1821 1876 1838 1845 1838 1862 1850 1816 1840 1763 1805 1915 1879 1862 1804 1775 1780 1894 1855 1883 1882 1863 1844 1872 1862 1879 1930 1862 1850 1924 1892 1921 1923 1949 1855 1944 1929 1967 1973 1887 1983 1925 2031 2001 1838 2003 1998 2038 1915 1995 1986 2089 1996 2054 2112 2057 2278 2250 2150 2331 2311 2424 2413 2548 2556 2772 2752 2947 2963 3173 3282 3518 3584 3847 4162 4446 4816 5216 5446 6132 6468 6921 7409 8008 8379 8969 9612 9926 10256 10222 10712 10489 10018 9426 8848 8159 7339 6560 5729 5097 4525 3942 3530 3256 2873 2865 2519 2453 2380 2211 2164 2170 2158 1976 2056 2080 2085 1970 1944 1911 1937 1865 1829 1900 1869 1922 1865 1846 1842 1783 1809 1803 1792 1808 1726 1721 1774 1790 1710 1807 1715 1717 1775 1674 1711 1698 1773 1726 1747 1688 1798 1781 1700 1770 1636 1682 1712 1730 1695 1694 1773 1719 1723 1693 1698 1707 1720 1740 1701 1701 1704 1700 1708 1612 1754 1808 1706 1791 1721 1733 1701 1706 1707 1755 1758 1736 1746 1688 1872 1753 1743 1847 1731 1761 1809 1865 1907 1942 1831 2004 1996 2032 2087 2023 2179 2260 2400 2387 2474 2561 2729 2814 2843 3068 3238 3320 3555 3579 3641 3867 3936 3934 3958 4028 3839 3711 3616 3244 3189 3065 2903 2675 2525 2451 2473 2291 2103 2114 1985 2024 1943 1878 1808 1751 1736 1728 1751 1669 1774 1674 1566 1613 1624 1622 1648 1566 1601 1603 1695 1605 1567 1656 1567 1613 1610 1548 1532 1560 1494 1651 1570 1562 1526 1550 1563 1532 1470 1508 1528 1546 1545 1519 1556 1587 1585 1515 1586 1568 1484 1541 1574 1590 1511 1475 1535 1435 1571 1481 1563 1538 1508 1534 1481 1520 1532 1530 1515 1576 1496 1567 1553 1555 1490 1523 1440 1550 1574 1501 1524 1579 1554 1539 1553 1513 1584 1544 1582 1489 1544 1541 1510 1490 1562 1546 1429 1500 1519 1525 1549 1573 1576 1516 1489 1609 1487 1560 1452 1493 1503 1462 1472 1445 1441 1449 1491 1560 1507 1483 1460 1477 1424 1518 1475 1510 1437 1457 1477 1488 1496 1474 1476 1500 1349 1452 1567 1426 1496 1440 1473 1530 1446 1490 1457 1457 1563 1468 1479 1442 1408 1531 1495 1500 1528 1520 1486 1540 1536 1605 1535 1670 1577 1702 1686 1747 1763 1926 1924 2141 2213 2505 2751 2763 3040 3343 3803 4101 4201 4178 4077 3875 3526 3311 3153 2739 2592 2301 2080 1912 1731 1751 1651 1585 1556 1552 1569 1512 1487 1524 1469 1499 1475 1400 1465 1419 1468 1376 1448 1455 1446 1513 1432 1462 1446 1436 1433 1407 1441 1455 1421 1482 1439 1448 1441 1509 1530 1478 1451 1515 1519 1590 1497 1512 1511 1525 1525 1516 1538 1525 1532 1539 1499 1536 1544 1550 1605 1561 1575 1538 1538 1527 1552 1521 1589 1592 1657 1568 1659 1673 1710 1681 1606 1711 1685 1707 1718 1786 1793 1811 1772 1790 1836 1871 1853 1930 1964 1932 2063 2038 2080 2155 2323 2276 2385 2466 2600 2693 2816 3013 3040 3256 3586 3954 4141 4603 5024 5588 6250 6973 7778 8957 9803 11224 12551 13957 15836 17636 19513 21462 23326 24835 25979 26933 26937 26293 24393 23015 20664 18518 16600 14227 12413 10687 9238 7908 7047 6367 5966 5723 5830 5869 6232 6314 6488 6772 6943 6893 6708 6412 6171 5681 5137 4909 4362 3965 3485 3234 2830 2590 2404 2317 2185 2002 1958 1928 1922 1886 1723 1784 1817 1653 1716 1796 1740 1705 1791 1793 1965 1882 1831 1896 1879 1956 2026 2152 2320 2361 2611 2663 2965 3151 3372 3645 4272 4469 4869 5238 5526 5910 6121 6412 6252 5836 5523 5287 4720 4464 4004 3528 3204 2835 2495 2168 1993 1855 1778 1733 1599 1556 1550 1620 1468 1534 1507 1458 1521 1558 1452 1422 1443 1457 1438 1401 1358 1416 1352 1441 1383 1358 1408 1365 1339 1382 1383 1347 1343 1343 1393 1330 1315 1325 1339 1315 1365 1377 1319 1304 1343 1360 1273 1352 1248 1288 1313 1291 1311 1302 1282 1338 1313 1344 1334 1274 1276 1306 1413 1308 1335 1286 1280 1310 1401 1293 1380 1364 1360 1316 1334 1303 1333 1326 1398 1381 1376 1321 1336 1388 1424 1418 1469 1483 1456 1480 1408 1418 1475 1386 1486 1474 1508 1426 1507 1490 1579 1558 1563 1587 1689 1665 1715 1626 1782 1593 1561 1519 1489 1481 1492 1412 1427 1407 1437 1480 1517 1454 1379 1473 1465 1434 1426 1356 1429 1373 1360 1335 1375 1353 1326 1292 1258 1256 1234 1287 1154 1271 1206 1222 1285 1280 1243 1269 1264 1237 1188 1246 1276 1287 1268 1213 1263 1286 1274 1231 1241 1235 1174 1223 1173 1172 1212 1157 1202 1189 1255 1214 1200 1263 1189 1189 1223 1236 1232 1179 1260 1242 1218 1212 1157 1197 1141 1155 1144 1195 1297 1171 1207 1179 1192 1188 1259 1164 1162 1172 1165 1198 1204 1160 1189 1179 1226 1167 1081 1220 1182 1258 1157 1225 1185 1245 1187 1179 1187 1256 1183 1262 1224 1207 1117 1227 1184 1251 1256 1247 1311 1329 1398 1380 1430 1548 1601 1699 1745 2012 2213 2438 2716 2793 3241 3274 3541 3361 3129 2996 2756 2735 2490 2361 2339 2114 1985 1883 1713 1708 1682 1720 1734 1691 1700 1654 1614 1639 1641 1595 1446 1435 1458 1478 1372 1348 1405 1233 1285 1221 1241 1207 1223 1181 1227 1226 1160 1134 1213 1200 1270 1204 1176 1156 1169 1151 1167 1199 1178 1166 1168 1185 1186 1174 1170 1145 1158 1243 1177 1165 1191 1152 1173 1251 1233 1208 1251 1241 1247 1254 1190 1232 1202 1227 1304 1331 1285 1324 1285 1250 1276 1384 1348 1347 1289 1423 1441 1466 1523 1562 1726 1750 1785 1993 2134 2354 2581 2826 3075 3606 4022 4789 5120 5853 6510 7195 7999 8798 9868 11112 12158 12676 12535 12302 11178 9909 9244 8601 8231 7742 7215 6618 5668 5181 4999 4689 4924 5055 5205 5456 5497 5479 5065 4928 4440 3993 3930 3665 3465 3064 2789 2424 2118 1933 1813 1722 1573 1498 1494 1453 1388 1382 1384 1484 1388 1385 1377 1381 1403 1431 1478 1462 1546 1493 1468 1591 1685 1820 1892 2022 2067 2237 2338 2655 2762 2921 3139 3357 3726 3783 4253 4247 4556 4813 4954 4936 4949 4907 4759 4595 4272 4080 3713 3451 3151 2963 2664 2487 2188 1990 1886 1747 1530 1484 1353 1358 1324 1269 1323 1335 1171 1267 1176 1193 1172 1217 1089 1185 1164 1111 1131 1109 1188 1140 1115 1126 1091 1093 1121 1142 1096 1034 1047 1036 1095 1039 1125 1093 1082 1051 1055 1037 1085 1126 1076 1086 1086 1097 1116 1064 1081 1053 1041 1037 1077 1024 1114 1055 1067 1085 1082 1033 1071 1095 1066 1077 1101 1087 1073 1089 1043 1093 1093 1166 1120 1130 1125 1086 1128 1049 1051 1100 1111 1096 1168 1169 1133 1162 1210 1151 1175 1195 1252 1336 1331 1383 1423 1422 1554 1649 1726 1713 1984 2099 2182 2403 2593 2637 2620 2694 2817 2702 2672 2613 2399 2403 2200 2176 1982 1852 1781 1647 1574 1462 1389 1251 1239 1212 1207 1158 1096 1074 1107 1096 1062 1099 1025 1079 1004 1061 991 1041 1039 1040 999 1001 1019 1019 1005 1028 1024 987 1041 1009 966 998 963 1025 978 1036 960 1045 943 1008 992 1015 944 1023 987 1073 1007 1008 1065 973 1082 982 988 972 1030 1073 1088 1155 1083 1145 1202 1172 1211 1245 1271 1293 1405 1529 1536 1592 1693 1783 1782 1857 1805 1714 1765 1686 1688 1624 1581 1457 1511 1363 1303 1218 1192 1158 1134 1076 1050 1045 1029 964 1022 983 964 921 967 996 1025 937 1036 937 966 947 933 943 1001 1006 936 957 957 937 930 995 936 973 983 983 958 988 944 961 929 949 966 1011 938 985 993 947 1003 980 1064 985 999 1024 1084 1068 1033 989 1067 1083 1043 1073 1128 1059 1200 1184 1246 1312 1402 1450 1586 1662 1899 2090 2118 2333 2559 2734 2912 3075 3054 3045 3049 3063 2985 2998 3175 3339 3338 3657 3772 3988 4166 4490 4562 4442 4394 4259 3866 3616 3330 3202 2953 2827 2767 2346 2067 1952 1712 1449 1381 1277 1173 1147 1140 1051 1051 1024 1064 962 1017 959 984 976 1072 938 932 931 979 920 921 903 917 878 874 880 980 853 870 884 872 923 850 904 870 900 841 881 853 895 871 909 847 815 842 829 839 871 873 843 921 838 855 890 867 811 839 875 822 872 885 835 881 813 959 826 834 900 888 885 866 809 879 837 866 923 845 867 840 873 818 854 891 884 842 872 857 846 832 809 863 831 841 933 857 888 842 829 884 840 899 875 829 886 879 858 842 885 823 843 853 881 877 931 883 939 928 943 944 953 1003 972 1033 1028 1020 1078 1124 1184 1173 1145 1178 1132 1141 1170 1103 1166 1112 1065 1062 995 1011 915 944 956 914 906 915 885 869 926 865 856 846 855 839 890 862 835 853 863 842 878 890 869 833 867 804 851 838 837 883 850 827 857 854 848 907 836 910 894 914 872 854 870 872 888 931 913 919 916 936 986 916 931 941 1010 1044 1059 1064 1098 1099 1155 1181 1268 1327 1446 1570 1699 1836 1914 2033 1999 2188 2203 2127 1994 1906 1863 1845 1627 1617 1640 1587 1464 1444 1302 1225 1288 1131 1103 1059 1057 1054 1167 1132 1117 1157 1207 1271 1336 1407 1463 1705 1724 1791 1796 1723 1715 1676 1622 1536 1548 1582 1603 1505 1479 1359 1271 1318 1188 1130 1127 1150 1166 1140 1120 1089 1135 1096 1145 1220 1305 1279 1344 1403 1521 1609 1737 1874 2050 2385 2564 2892 3211 3703 3929 4604 4860 5130 5431 5578 5480 5431 4987 4835 4498 4195 3945 3817 3482 3316 2923 2719 2445 2042 1881 1701 1565 1367 1330 1193 1166 1137 1078 1057 1048 1021 1038 961 1059 964 974 966 894 947 951 936 892 922 916 944 931 920 825 860 885 870 867 879 879 934 954 865 960 959 958 969 1007 1027 1087 1151 1203 1274 1373 1547 1675 1775 1931 2029 2167 2216 2230 2304 2282 2188 2019 1906 1780 1707 1746 1658 1609 1491 1428 1287 1220 1175 1058 982 932 941 950 872 853 881 865 864 847 870 866 841 918 936 870 925 923 1033 1011 1126 1150 1215 1284 1313 1387 1379 1417 1432 1481 1313 1285 1248 1237 1191 1184 1127 1061 1022 1048 965 975 898 897 838 818 881 912 832 739 856 797 797 769 812 743 784 778 787 763 818 743 785 755 793 827 800 719 784 770 774 724 786 753 812 761 739 820 764 793 781 771 787 825 735 839 757 791 784 811 760 788 757 781 804 800 815 790 743 726 786 728 732 840 738 755 786 762 793 723 825 801 808 790 768 784 791 808 753 800 796 700 827 776 788 786 844 785 815 818 822 868 841 850 779 831 844 831 817 814 799 845 831 816 869 860 838 879 861 855 816 857 840 828 824 874 832 871 918 926 962 905 939 930 957 1044 1142 1149 1138 1250 1376 1442 1530 1814 1917 2223 2891 3158 3745 4325 5057 5641 6391 6716 6958 6611 6209 5507 4870 4691 4427 4313 4281 4096 4033 3707 3324 2754 2292 1947 1680 1526 1404 1293 1200 1180 1109 1051 1122 1086 1030 1033 1060 1023 1098 1069 1085 1117 1144 1212 1213 1327 1359 1391 1447 1542 1649 1662 1739 1858 1886 1841 1795 1788 1758 1752 1677 1533 1548 1453 1495 1472 1324 1295 1189 1177 1075 1029 996 961 1007 838 847 898 839 837 829 829 821 770 855 811 771 805 768 812 783 804 743 808 753 802 813 813 818 748 783 802 782 791 773 842 744 829 822 842 778 825 829 801 891 923 960 950 959 979 1064 1108 1067 1133 1138 1193 1177 1192 1208 1099 1145 1102 1098 1112 988 1054 1005 971 967 947 913 842 883 864 796 834 794 743 770 721 782 784 809 750 723 718 712 768 728 714 740 757 716 740 732 736 713 661 721 676 715 762 687 763 705 737 731 703 701 665 683 679 664 726 707 718 687 726 712 697 674 688 685 675 732 649 680 693 647 715 669 696 683 707 679 646 674 664 704 668 694 627 668 720 734 719 658 709 672 663 700 650 716 686 701 710 667 680 690 707 633 694 681 709 676 661 727 672 674 735 670 735 730 739 724 684 708 691 713 709 786 722 748 741 787 740 745 706 711 698 698 704 726 688 670 716 769 731 708 681 685 665 704 683 660 692 656 659 680 684 651 693 692 708 675 701 642 674 655 693 657 671 717 670 718 689 680 689 672 659 701 695 685 680 718 727 727 687 703 774 709 733 682 698 721 703 754 725 750 710 735 745 722 718 744 746 762 759 753 790 809 725 796 765 781 796 809 800 799 873 884 945 884 1027 1076 1170 1208 1281 1362 1435 1470 1476 1623 1698 1738 1825 2056 2240 2451 2598 2560 2509 2285 2035 1754 1639 1490 1420 1530 1511 1573 1532 1410 1282 1189 1002 911 876 873 750 807 784 756 743 727 757 732 716 732 711 699 692 677 682 709 703 726 727 696 717 719 658 688 678 724 712 679 664 760 691 694 661 705 734 741 754 717 757 689 729 705 745 760 752 801 799 789 820 807 783 825 919 954 983 1020 1078 1174 1241 1312 1306 1371 1432 1452 1393 1286 1370 1356 1341 1241 1317 1206 1280 1321 1213 1280 1202 1164 1153 1114 1054 1031 946 972 890 893 880 885 845 897 844 841 881 754 808 799 822 824 801 888 826 836 928 941 1034 1088 1171 1328 1432 1610 1885 2057 2339 2587 2723 2824 2808 2598 2358 2217 2094 1994 1903 1940 2006 1908 1877 1739 1637 1609 1444 1303 1156 1114 973 946 904 864 854 822 754 747 798 773 788 708 740 775 773 732 761 764 687 718 783 675 708 783 710 737 650 679 684 733 742 779 726 677 673 726 691 707 702 742 743 753 692 735 693 713 691 707 746 750 698 769 783 826 853 926 938 980 1099 1062 1025 1081 1038 934 925 929 936 934 896 984 941 895 945 938 845 845 844 853 773 854 748 799 798 812 827 852 898 870 966 990 1031 1045 1164 1267 1339 1294 1525 1687 1752 1915 1922 2072 1950 1901 1829 1705 1578 1572 1532 1542 1490 1584 1578 1529 1488 1431 1376 1225 1143 1162 1108 1074 1063 1069 1079 1101 1078 1110 1194 1181 1261 1335 1332 1536 1628 1761 1849 1862 1885 1831 1848 1862 1831 1850 1966 2018 2162 2205 2201 2249 2209 2344 2382 2443 2511 2839 3017 3484 3879 4420 5052 5626 6369 6787 7375 7570 7487 7210 6625 5974 5389 4904 4680 4608 4554 4557 4501 4419 4298 3810 3363 3066 2520 2234 1866 1717 1566 1331 1351 1210 1142 1119 1104 1082 1004 995 999 1013 1037 1034 1040 1011 1107 1053 1082 1241 1247 1436 1493 1731 1711 1796 1647 1571 1341 1203 1157 1217 1184 1248 1409 1432 1544 1494 1450 1462 1521 1591 1624 1913 2043 2344 2459 2622 2753 2663 2618 2488 2363 2202 2049 1953 1956 2000 1854 1924 1889 1820 1767 1618 1547 1417 1243 1232 1087 1030 1026 932 876 923 892 878 847 785 784 785 788 697 740 723 760 715 702 721 711 716 724 682 718 738 652 737 699 748 750 740 765 694 741 754 760 738 753 799 770 743 771 761 835 827 871 802 779 801 802 777 793 746 784 772 761 722 751 814 731 702 720 751 755 726 764 767 744 749 721 713 706 660 713 698 705 705 680 693 704 671 640 675 703 689 680 644 715 657 732 649 681 675 630 705 666 662 632 686 647 653 692 640 664 662 655 682 651 665 654 652 660 622 663 630 632 666 651 626 631 641 621 647 660 628 658 640 640 619 609 638 642 645 641 623 625 615 632 619 621 649 616 632 641 627 629 620 646 669 607 637 598 688 631 638 635 627 704 594 614 682 630 646 610 689 674 673 657 658 640 699 672 642 666 658 640 678 683 658 649 663 719 756 701 716 750 749 783 797 885 847 885 939 984 1123 1191 1264 1341 1583 1671 1848 1868 1935 2075 1940 1896 1732 1614 1579 1514 1568 1457 1546 1541 1493 1636 1551 1445 1333 1277 1111 1055 1051 995 964 956 911 868 872 828 826 785 775 764 835 706 742 747 726 731 738 724 716 658 698 671 705 781 718 655 699 709 651 657 646 669 692 675 676 702 716 719 766 764 744 761 829 927 921 990 1021 1011 1100 1175 1168 1145 1200 1229 1119 1006 985 1002 948 924 979 938 1008 957 947 921 900 880 780 828 745 749 758 713 671 696 665 700 704 672 709 702 675 676 742 676 701 752 761 770 822 862 858 854 878 966 995 1077 1085 1060 1087 1087 1065 1052 1025 1065 1041 1098 1127 1161 1285 1345 1320 1365 1496 1505 1580 1479 1376 1337 1190 1127 1114 1059 971 980 1020 958 1019 1003 1011 976 904 895 803 801 730 744 719 670 701 677 618 623 660 679 628 679 647 653 683 659 623 640 652 682 617 666 600 652 643 672 675 658 689 734 711 708 646 623 718 667 679 649 628 640 646 663 681 717 716 684 712 719 666 676 745 687 683 715 740 746 804 759 744 785 744 807 815 765 819 900 825 840 875 923 973 950 1070 1143 1139 1294 1461 1589 1751 1898 2184 2424 2687 3093 3366 3763 4028 4274 4457 4508 4382 4189 3756 3411 3192 2949 2819 2714 2702 2786 2751 2817 2681 2676 2468 2202 2050 1736 1574 1434 1290 1205 1136 1119 1090 1003 964 966 925 891 980 962 974 1047 1054 1038 1011 1057 1019 1007 955 963 849 885 895 823 828 821 844 798 809 820 847 842 755 774 757 731 755 697 664 731 688 667 717 694 719 657 696 715 717 764 725 758 700 752 752 786 712 746 773 776 781 808 812 819 795 869 913 936 941 1088 1059 1113 1281 1350 1516 1675 1890 2221 2465 2779 3221 3644 4006 4348 4380 4296 4281 3997 3606 3228 2996 2798 2647 2735 2715 2850 2966 3077 3006 2927 2887 2733 2417 2329 1994 1810 1526 1456 1278 1236 1088 1188 1125 1142 1135 1075 1084 1031 970 999 903 925 822 816 852 869 867 876 856 861 936 928 1018 1032 1088 1128 1134 1188 1235 1115 1077 1169 1023 1055 1020 991 872 1011 953 952 919 981 991 939 869 859 837 808 786 733 769 728 770 659 685 700 668 724 722 736 719 720 721 747 713 765 723 707 729 747 720 673 747 737 725 715 711 782 748 787 829 821 846 798 833 812 823 858 801 783 794 721 792 772 763 746 762 729 790 747 711 729 762 707 717 701 704 717 758 731 762 681 782 756 675 779 737 793 783 766 819 767 835 759 824 844 837 809 853 874 875 865 868 934 925 890 897 868 928 897 1022 1088 1176 1369 1543 1862 2158 2775 3523 4673 6149 7868 9730 11710 12701 13012 11363 9577 6997 5362 3952 3388 3299 3426 3922 4562 5160 6080 6615 6871 6290 5368 4190 3145 2374 1820 1536 1324 1050 1048 1048 936 912 893 840 757 770 779 758 758 749 735 748 684 692 686 646 673 638 712 669 669 722 647 635 661 666 589 620 619 598 589 586 631 652 635 615 625 628 598 639 625 587 633 618 702 596 611 615 596 611 633 569 635 623 600 613 607 590 630 583 589 653 655 651 615 616 655 641 632 681 656 665 703 668 660 703 666 690 722 760 721 777 777 726 803 812 721 773 775 765 756 741 727 798 725 831 803 791 784 828 844 865 916 975 876 995 978 896 919 958 921 981 958 910 890 822 832 832 871 807 840 846 781 808 782 826 800 798 739 697 785 727 716 728 634 716 669 690 709 673 734 727 756 804 720 783 777 784 826 823 909 965 972 962 985 972 1000 975 973 941 945 879 843 851 822 838 837 874 770 818 830 831 850 827 779 747 791 689 718 716 728 710 702 642 639 641 651 621 623 625 637 668 606 580 662 646 575 609 583 606 611 627 636 562 595 618 571 529 604 628 539 571 552 576 557 582 609 556 600 587 599 563 581 582 546 552 597 552 608 515 607 636 611 554 608 640 603 624 625 662 673 681 727 729 741 799 761 753 832 818 826 884 846 862 844 798 795 811 799 704 672 786 739 698 783 748 797 771 636 734 701 647 632 637 641 609 579 609 619 610 614 607 667 607 604 687 679 649 671 622 702 732 711 811 872 846 948 939 893 855 850 791 824 761 706 748 736 788 812 822 850 884 881 919 916 906 897 927 926 872 946 958 1000 1027 1073 1116 1080 980 1002 1021 955 934 931 842 900 943 970 1067 1020 1018 1089 1130 1114 1245 1279 1355 1280 1317 1292 1316 1262 1283 1192 1090 1076 1020 995 1017 967 934 974 986 1009 988 960 957 927 909 855 858 794 757 729 750 687 699 629 628 629 632 623 591 608 617 633 611 584 614 626 567 624 590 599 561 575 588 585 576 647 558 570 579 598 641 614 638 606 636 623 611 586 636 633 618 637 645 660 689 627 619 626 718 669 687 711 752 757 782 796 848 920 942 1061 1090 1179 1256 1451 1602 1790 1858 1973 2004 2010 1930 1812 1646 1562 1472 1432 1339 1278 1237 1274 1313 1344 1434 1457 1449 1417 1331 1299 1144 1085 1055 1064 970 886 905 847 857 878 808 822 804 808 839 915 924 896 937 929 1058 1129 1205 1344 1480 1647 1849 2051 2266 2668 2928 3148 3543 3640 3649 3460 3295 3123 2610 2476 2206 2181 1923 1913 2033 2054 2172 2250 2366 2321 2264 2179 2144 1887 1802 1580 1409 1269 1219 1123 1101 979 1014 989 872 874 854 789 749 711 759 771 745 757 712 731 703 762 703 657 670 643 658 635 717 656 660 687 635 696 693 699 736 655 603 629 647 596 607 625 585 607 627 655 620 658 667 641 610 645 627 611 602 585 588 594 568 615 592 538 610 565 581 583 619 614 625 553 589 549 561 548 563 604 607 587 562 549 571 572 558 580 601 538 554 557 572 551 555 563 549 563 527 576 587 578 551 593 606 585 590 597 549 573 580 534 594 557 660 572 597 589 604 645 593 606 627 603 603 597 607 631 616 631 638 615 652 711 691 703 680 707 669 714 737 738 745 756 763 772 797 760 759 847 768 801 797 795 790 774 800 738 775 738 670 699 738 677 683 690 685 708 706 742 669 667 653 670 634 616 646 611 577 581 630 572 589 614 569 600 557 566 580 574 598 537 573 560 603 587 607 603 573 635 614 679 655 623 637 600 623 578 598 587 589 620 579 567 552 597 587 618 618 677 651 655 695 668 706 759 749 835 818 750 791 776 674 699 672 609 641 618 640 626 616 641 635 703 690 695 643 585 646 666 612 636 567 560 610 580 556 522 567 552 548 582 539 571 570 566 542 534 566 539 598 632 534 605 603 554 572 614 626 656 632 617 646 654 700 728 753 827 780 799 842 882 761 787 736 726 703 684 705 701 697 677 705 665 726 719 731 689 656 633 621 634 631 619 631 577 615 568 615 562 571 545 557 532 532 555 554 604 537 545 537 504 533 552 607 538 591 530 548 525 547 574 547 551 587 583 548 545 547 567 565 604 566 547 538 581 555 599 572 520 590 568 552 525 470 545 515 530 543 510 536 496 529 542 514 530 503 505 507 522 525 494 529 522 568 531 488 560 538 519 527 521 511 552 504 517 501 501 518 514 570 502 508 519 522 547 525 514 543 494 485 514 526 502 523 536 529 529 517 599 572 551 562 542 568 508 522 587 513 522 578 589 579 587 568 661 554 538 604 636 587 565 641 602 616 641 710 723 704 670 728 667 649 618 638 652 665 583 649 616 591 603 628 638 655 644 652 648 631 618 640 635 597 614 583 562 617 613 605 602 613 611 613 594 640 635 669 648 587 600 570 606 659 636 605 629 766 695 725 694 703 754 683 692 666 643 652 650 660 609 714 662 693 690 745 661 678 696 716 737 731 740 805 804 824 829 874 925 964 1030 1108 1173 1212 1291 1410 1600 1684 1805 1745 1737 1873 1738 1582 1585 1386 1439 1305 1289 1200 1190 1169 1220 1315 1330 1368 1321 1405 1479 1528 1384 1384 1295 1181 1092 1039 971 898 788 831 827 775 784 756 804 810 772 795 849 838 841 787 860 862 896 950 952 1092 1132 1200 1258 1331 1237 1259 1170 1096 1015 985 925 883 846 873 869 882 892 933 943 965 1016 1031 1019 1007 992 955 979 933 934 844 869 796 870 760 852 790 784 766 778 801 700 701 779 745 766 747 794 783 697 748 768 764 762 775 797 765 812 775 790 875 878 877 899 905 899 890 880 823 771 809 794 748 761 741 787 860 846 906 934 969 1048 1028 1128 1168 1210 1377 1429 1455 1593 1734 1870 2011 1999 1997 1921 1760 1779 1619 1517 1454 1307 1272 1260 1216 1266 1286 1381 1344 1415 1417 1389 1435 1454 1388 1321 1224 1095 993 1016 940 844 830 807 746 779 730 709 700 687 681 678 664 686 623 592 597 597 660 577 577 567 563 564 588 588 537 559 556 555 511 535 516 540 516 546 508 506 587 543 508 494 530 533 561 523 497 513 537 479 514 508 501 494 500 476 455 504 497 495 486 508 499 505 502 528 519 568 541 531 528 534 502 558 481 520 491 512 506 524 506 540 521 549 560 540 496 553 495 531 485 507 568 564 556 501 576 536 583 570 571 562 601 606 613 635 656 708 640 665 649 649 656 651 618 620 599 579 594 610 643 635 575 609 642 597 630 604 598 604 641 651 576 571 544 603 548 600 586 611 571 570 571 573 604 640 641 630 637 703 720 688 722 791 826 851 873 872 869 897 887 890 793 795 758 723 697 721 717 655 750 733 750 715 799 745 801 774 808 809 780 786 796 731 821 769 776 855 807 848 864 874 852 919 872 913 881 811 834 766 761 763 762 753 732 762 757 774 759 767 751 757 803 734 685 712 754 672 626 654 578 644 640 572 609 593 619 602 588 545 595 570 562 590 553 545 526 492 520 520 564 554 539 523 518 582 549 485 517 487 497 480 521 546 503 527 484 499 470 545 481 515 481 492 517 502 486 496 472 485 504 514 447 524 505 542 517 510 521 532 503 487 529 532 561 496 541 545 544 538 547 569 570 498 501 515 514 515 522 522 509 534 547 488 523 518 524 535 556 502 549 509 538 592 561 583 564 617 582 630 670 603 644 582 644 546 593 588 541 555 545 578 592 591 675 641 624 652 646 702 669 642 703 668 664 698 666 653 728 755 681 724 738 800 784 794 815 829 840 819 869 844 798 868 813 809 826 816 816 831 850 798 799 771 768 747 776 766 742 720 846 764 722 814 781 760 779 760 759 716 737 724 742 753 780 796 833 895 899 913 958 1088 1224 1344 1455 1616 1736 1920 2088 2358 2375 2376 2347 2251 2094 1871 1696 1635 1422 1291 1229 1148 1122 1236 1174 1235 1242 1354 1387 1450 1504 1529 1511 1434 1317 1210 1225 1061 1012 925 876 840 790 703 642 645 682 650 627 628 599 613 545 544 526 613 589 536 559 536 546 515 538 539 551 541 546 509 562 585 513 557 565 552 508 539 589 540 569 546 543 580 583 600 622 657 605 645 695 676 724 711 821 752 893 1038 1051 1039 1075 1190 1191 1189 1217 1156 1155 1069 1017 871 882 813 838 820 705 779 719 794 821 897 820 943 914 902 913 854 924 870 812 831 771 686 719 703 676 692 631 618 711 673 676 734 777 817 855 931 987 1025 1018 1150 1162 1177 1146 1082 1047 1055 946 939 867 853 792 768 814 739 758 768 766 799 847 844 905 875 845 835 816 797 754 735 676 663 662 662 610 591 559 625 591 603 541 561 531 533 551 520 545 517 543 508 500 480 519 538 527 483 524 508 538 535 524 594 579 498 646 584 533 564 587 565 569 544 634 622 583 649 585 580 581 592 567 536 501 551 586 578 567 537 528 520 588 583 551 542 553 583 535 512 528 549 517 542 523 520 572 550 541 535 516 543 535 528 558 496 542 501 512 550 505 514 551 509 522 530 498 515 533 550 535 553 489 552 530 497 568 560 587 546 519 488 552 599 581 549 530 568 588 670 653 679 672 685 663 669 715 717 704 761 737 775 729 737 743 721 647 701 686 712 637 615 601 582 672 646 618 642 633 631 619 657 653 603 663 591 580 615 539 584 547 558 539 511 501 497 537 509 540 488 479 531 503 478 578 522 507 513 495 464 491 494 528 513 525 524 501 528 537 541 539 584 585 557 600 641 673 722 777 852 1007 1087 1286 1331 1577 1571 1440 1291 1157 1106 949 905 733 693 648 719 589 621 630 701 702 677 799 865 941 961 969 1038 958 869 814 734 684 650 645 613 583 583 555 559 580 544 565 537 526 522 523 544 540 553 562 565 518 535 538 496 497 541 530 518 547 499 512 509 493 541 534 512 463 511 467 494 492 513 486 484 443 485 481 436 505 422 460 470 504 464 480 501 436 479 461 413 471 502 456 459 453 481 503 496 490 494 515 529 501 472 512 488 516 495 464 494 487 513 469 470 512 500 482 541 475 478 492 502 474 509 462 498 461 468 497 511 443 520 474 465 464 518 518 479 507 494 447 491 479 533 483 511 517 520 500 500 482 498 501 480 558 602 540 558 528 521 578 525 528 568 535 549 547 492 538 494 461 522 502 513 482 481 511 499 497 513 507 545 499 542 501 526 562 540 555 501 518 531 501 555 539 545 538 539 532 530 501 540 550 555 531 535 559 626 597 654 656 662 717 755 707 696 733 677 662 597 632 543 562 515 581 548 504 575 545 567 565 580 586 572 614 605 567 597 607 588 593 616 565 551 524 536 512 506 510 511 457 510 538 472 490 451 493 470 505 428 477 453 515 508 497 478 518 473 502 482 482 460 508 499 498 495 485 489 492 509 562 531 531 542 578 545 578 658 605 644 642 591 551 633 645 558 575 586 595 521 563 537 564 549 585 586 543 555 593 549 597 582 588 582 618 570 592 616 643 660 626 609 699 676 699 727 822 831 854 887 970 1053 1153 1271 1292 1411 1333 1368 1307 1353 1316 1241 1075 1085 988 882 863 894 872 853 881 848 884 884 907 871 913 967 972 990 1021 939 966 997 867 860 818 818 762 805 724 715 797 786 787 797 813 849 995 974 884 971 852 895 826 771 780 718 718 614 637 645 665 630 533 652 596 626 613 644 627 667 707 695 674 649 683 681 671 606 620 561 571 571 516 546 556 536 540 553 516 523 497 498 525 501 545 495 495 520 541 490 467 479 501 472 497 442 472 460 491 460 509 496 527 500 569 502 545 511 577 576 553 518 556 575 574 560 569 533 560 543 528 492 545 511 518 508 490 486 527 514 506 511 481 527 569 539 522 569 515 544 526 513 500 540 502 458 475 503 496 504 502 534 516 540 507 518 527 517 509 521 461 476 480 499 520 480 495 517 543 460 489 533 473 485 509 500 515 506 493 517 474 475 511 521 485 491 525 476 495 493 505 519 533 499 562 497 501 538 554 507 560 551 572 534 557 540 564 602 539 534 575 507 561 549 520 543 482 523 519 521 520 564 513 535 551 501 499 545 581 571 490 482 493 499 528 517 510 503 509 464 512 509 530 506 512 561 481 490 504 526 518 570 539 525 542 521 562 525 536 551 504 524 495 503 516 503 496 488 516 483 472 503 471 527 478 493 486 503 480 526 501 491 471 444 496 489 460 516 481 519 477 442 498 498 484 463 447 463 442 463 466 493 482 472 487 486 433 458 439 442 466 492 480 481 455 517 505 514 475 467 462 496 493 486 472 504 486 476 478 544 495 490 426 487 475 496 498 470 504 477 467 498 499 527 520 523 520 522 510 552 552 533 538 523 523 500 543 520 565 565 534 516 535 585 505 557 539 563 579 579 582 535 579 542 611 549 579 586 573 579 540 534 534 558 544 524 535 571 553 529 520 498 537 535 580 565 533 534 528 533 557 519 534 499 479 518 508 509 525 529 482 528 486 477 484 472 520 481 520 430 471 477 468 454 513 488 472 483 514 467 484 477 486 541 498 447 476 461 507 496 506 525 473 470 491 447 492 474 507 496 525 530 519 490 534 518 562 569 565 582 567 596 624 611 671 625 577 565 553 530 587 551 575 501 510 516 512 473 489 510 480 497 552 532 516 546 540 520 532 504 547 528 548 539 506 556 465 523 486 512 453 511 475 457 488 487 470 480 483 486 494 437 512 509 498 487 552 482 511 508 516 534 537 514 549 527 556 521 550 551 570 587 568 560 561 578 557 584 558 566 553 554 529 562 526 510 526 529 522 537 547 550 505 499 508 582 539 480 492 542 577 566 513 517 504 560 523 488 512 520 503 498 526 490 505 499 491 497 474 496 485 508 505 505 513 511 508 494 487 524 442 519 515 490 537 510 471 492 474 496 498 529 492 530 510 496 525 510 478 454 508 476 485 530 504 466 485 527 488 500 519 495 498 506 483 502 501 527 529 478 481 514 513 499 535 457 534 509 499 511 524 525 470 488 511 485 505 483 528 522 513 529 541 612 594 545 575 563 541 541 526 530 530 512 530 487 500 526 533 566 576 563 553 533 594 598 625 658 665 643 616 573 583 548 529 524 539 499 525 556 499 552 481 532 527 543 494 526 534 522 511 549 543 574 564 562 491 517 566 517 538 510 520 563 509 476 561 467 539 534 487 533 501 552 516 515 554 521 551 564 555 578 585 554 579 571 574 590 601 568 598 588 608 593 533 542 518 546 538 507 544 518 508 471 569 496 541 569 527 490 501 537 512 563 504 561 543 512 518 498 512 467 504 482 472 418 518 481 465 472 455 526 493 493 485 434 477 460 481 509 476 510 466 502 507 468 514 434 479 514 475 484 442 444 459 492 458 458 425 484 476 465 466 472 484 498 462 453 466 476 485 492 499 517 470 482 449 457 479 494 454 508 463 504 481 490 454 461 471 462 467 450 460 459 512 473 462 458 471 480 472 455 454 507 437 539 507 508 500 464 499 511 516 539 577 567 556 573 543 578 515 547 520 473 510 483 522 499 487 506 476 460 504 445 514 497 469 494 502 493 545 521 536 507 493 548 477 559 484 530 543 539 503 526 506 563 566 547 561 530 588 592 556 611 623 586 579 568 546 524 564 484 580 531 551 518 568 573 590 554 548 547 586 587 605 597 610 613 597 563 612 563 595 550 585 581 521 546 533 534 532 561 560 547 536 539 552 557 550 585 623 597 618 622 649 628 636 661 716 704 690 683 663 643 656 614 600 644 592 597 574 597 563 570 526 593 647 615 612 615 621 631 665 603 634 650 650 611 584 586 582 618 551 597 574 550 537 580 544 618 532 568 568 530 554 587 540 557 550 517 567 524 562 529 540 494 514 534 530 515 483 499 507 521 529 507 538 503 539 537 557 588 576 562 591 626 616 677 711 732 762 806 849 835 930 857 891 949 876 879 839 771 741 718 703 633 641 686 651 651 646 584 638 659 659 651 650 620 652 726 729 666 725 735 667 702 694 706 704 651 643 651 663 635 656 573 588 565 575 597 629 572 612 598 611 580 621 614 553 636 632 617 655 545 572 598 599 613 566 617 538 594 555 583 583 568 557 579 603 659 703 717 727 707 744 775 853 869 868 924 1055 1039 996 978 1051 1004 987 948 875 917 867 787 832 768 711 702 713 699 665 647 757 701 657 679 682 760 721 792 754 734 737 781 760 731 714 735 728 751 710 716 683 664 570 607 584 601 565 577 520 558 568 580 556 528 523 504 518 492 553 566 557 458 467 499 507 487 456 505 490 506 497 482 504 517 522 482 531 474 487 495 485 463 487 480 456 495 463 455 459 507 452 497 498 491 476 466 508 483 533 506 496 500 490 472 484 524 493 530 543 481 526 509 520 530 478 523 511 472 486 470 484 517 462 518 507 541 537 478 517 555 523 528 500 511 546 508 554 514 541 529 526 575 605 559 594 584 620 561 529 544 522 499 538 495 498 489 467 525 504 474 484 474 479 466 486 494 513 491 553 505 521 528 556 529 512 540 521 554 584 537 507 544 541 540 535 524 531 575 553 578 572 553 567 560 519 537 527 510 506 502 484 477 493 525 526 513 479 489 525 534 497 514 486 536 543 526 502 490 503 508 517 519 513 511 497 537 509 495 565 504 492 499 528 453 481 493 524 500 506 500 479 483 498 500 450 561 488 540 495 477 530 537 519 563 548 491 543 555 494 490 533 525 525 540 506 525 539 511 486 537 524 537 556 556 530 517 500 572 555 562 576 584 581 595 617 587 644 619 624 681 711 722 736 750 801 854 809 774 795 761 705 710 681 711 637 637 658 590 659 574 589 597 590 529 570 648 597 599 627 642 653 616 683 640 704 684 677 660 634 618 574 610 608 569 528 582 511 523 525 527 523 538 519 547 516 539 536 543 539 538 533 468 545 518 560 550 555 598 552 584 588 563 578 545 556 593 531 614 577 609 577 571 557 574 555 566 531 575 538 509 545 531 514 547 557 487 523 490 532 603 549 569 579 562 578 592 591 588 593 585 580 561 584 605 619 612 600 622 616 599 528 621 615 601 660 600 593 606 595 577 616 592 617 621 669 641 656 659 657 718 698 682 680 673 643 616 677 645 617 629 640 621 628 614 575 581 568 583 616 550 583 596 595 595 587 598 591 567</counts>
			</dataPoints>
		</scan>
	</xrdMeasurement>
</xrdMeasurements>