File: dataset/precursor_mixture/TiO2_NaHCO3_V2O5.2-min.xrdml
<?xml version="1.0"?>
<xrdMeasurements xmlns="http://www.xrdml.com/XRDMeasurement/2.2" xmlns:xsi="http://www.w3.org/2001/XMLSchema-instance" xsi:schemaLocation="http://www.xrdml.com/XRDMeasurement/2.2 http://www.xrdml.com/XRDMeasurement/2.2/XRDMeasurement.xsd" status="Completed" recordIdentifier="{B8F5F054-93AF-4707-9706-A99ADAB72310}">
	<comment>
		<entry/>
	</comment>
	<sample type="To be analyzed">
		<id></id>
		<name></name>
		<preparedBy></preparedBy>
	</sample>
	<xrdMeasurement measurementType="Scan" status="Completed" sampleMode="Reflection">
		<usedWavelength intended="K-Alpha 1">
			<kAlpha1 unit="Angstrom">1.5405980</kAlpha1>
			<kAlpha2 unit="Angstrom">1.5444260</kAlpha2>
			<kBeta unit="Angstrom">1.3922500</kBeta>
			<ratioKAlpha2KAlpha1>0.5000</ratioKAlpha2KAlpha1>
		</usedWavelength>
		<incidentBeamPath>
			<radius unit="mm">145.00</radius>
			<xRayTube id="1010048" name="Empyrean Cu LFF HR (9430 033 7310x) DK437873">
				<tension unit="kV">40.0</tension>
				<current unit="mA">15.0</current>
				<anodeMaterial>Cu</anodeMaterial>
				<focus type="Line">
					<length unit="mm">12.0</length>
					<width unit="mm">0.4</width>
					<takeOffAngle unit="deg">6.0</takeOffAngle>
				</focus>
			</xRayTube>
			<filter id="20010004" name="Beta-filter Nickel">
				<material>Ni</material>
				<thickness unit="mm">0.020</thickness>
			</filter>
			<sollerSlit id="21010002" name="Soller slits 0.04 rad.">
				<opening unit="rad">0.0400</opening>
			</sollerSlit>
			<mask id="22031000" name="Fixed mask 13 mm">
				<width unit="mm">9.00</width>
			</mask>
			<divergenceSlit id="22120001" name="Divergence slit 1°" xsi:type="fixedDivergenceSlitType">
				<distanceToSample unit="mm">50.00</distanceToSample>
				<height unit="mm">1.52</height>
			</divergenceSlit>
		</incidentBeamPath>
		<beamKnife id="29030100" name="Beam knife low"/>
		<sampleMovement xsi:type="spinningSampleMovementType">
			<spinnerRevolutionTime unit="seconds">1.0</spinnerRevolutionTime>
		</sampleMovement>
		<diffractedBeamPath>
			<radius unit="mm">145.00</radius>
			<antiScatterSlit id="22090040" name="AS slit 9 mm" xsi:type="fixedAntiScatterSlitType">
				<height unit="mm">9.00</height>
			</antiScatterSlit>
			<sollerSlit id="21020003" name="Large Soller slits 0.04 rad.">
				<opening unit="rad">0.0400</opening>
			</sollerSlit>
			<filter id="20030001" name="Large beta-filter Nickel">
				<material>Ni</material>
				<thickness unit="mm">0.020</thickness>
			</filter>
			<detector id="7010019" name="PIXcel1D-Medipix3 detector" xsi:type="rtmsDetectorType">
				<phd unit="keV">
					<lowerLevel>4.0</lowerLevel>
					<upperLevel>11.3</upperLevel>
				</phd>
				<mode>Scanning</mode>
				<activeLength unit="deg">1.021</activeLength>
			</detector>
		</diffractedBeamPath>
		<scan appendNumber="0" mode="Continuous" scanAxis="Gonio" status="Completed">
			<header>
				<startTimeStamp>2024-03-24T11:14:57-07:00</startTimeStamp>
				<endTimeStamp>2024-03-24T11:17:19-07:00</endTimeStamp>
				<author>
					<name>Instrument</name>
				</author>
				<source>
					<applicationSoftware version="1.6 (94)">PANalytical Aeris Instrument Suite</applicationSoftware>
					<instrumentControlSoftware version="3.0.0 20211014">AERIS</instrumentControlSoftware>
					<instrumentID>2879380</instrumentID>
				</source>
			</header>
			<dataPoints>
				<positions axis="2Theta" unit="deg">
					<startPosition>10.02173288</startPosition>
					<endPosition>139.98435528</endPosition>
				</positions>
				<positions axis="Omega" unit="deg">
					<startPosition>5.01086644</startPosition>
					<endPosition>69.99217764</endPosition>
				</positions>
				<commonCountingTime unit="seconds">1.551</commonCountingTime>
				<counts unit="counts">379 384 393 416 365 342 375 370 353 342 411 394 353 378 353 384 369 388 337 317 362 346 357 309 378 370 301 346 365 339 326 345 353 334 306 285 285 327 292 328 290 316 345 311 308 306 314 293 335 298 310 277 294 305 262 276 298 269 267 263 272 280 292 259 229 266 275 277 255 251 289 241 225 248 220 265 262 294 259 252 240 229 257 279 267 251 230 234 239 240 245 225 229 236 201 248 216 220 207 221 245 225 227 193 238 224 229 207 212 205 248 279 280 237 236 228 256 251 263 308 369 399 326 230 193 201 200 205 189 169 192 195 183 198 185 199 198 220 205 159 157 198 207 188 186 161 161 197 192 181 180 159 175 181 189 201 181 187 188 171 177 152 148 195 187 199 186 159 192 177 169 162 162 164 190 167 149 153 155 180 192 188 161 164 202 297 612 1193 839 282 168 157 180 176 179 181 168 158 169 184 155 163 157 161 157 160 179 152 146 142 156 158 169 156 147 180 177 189 138 186 165 160 188 176 187 227 245 268 343 460 723 926 878 628 323 261 174 162 135 169 162 136 138 130 142 133 144 141 142 142 138 139 176 142 143 159 161 141 162 177 216 205 248 328 343 279 207 195 164 131 135 130 147 143 101 127 134 121 139 124 127 131 101 121 106 122 128 115 153 123 129 135 102 139 132 130 121 118 92 113 102 111 124 106 136 119 124 146 137 180 258 430 347 215 157 139 117 103 117 100 110 123 125 146 130 110 154 143 163 136 132 148 139 138 149 147 191 188 225 299 390 597 967 1581 2510 2358 1440 686 461 568 613 496 339 203 198 150 166 143 156 173 208 265 360 567 498 356 210 149 127 148 117 109 121 115 112 111 95 113 108 113 95 99 130 108 116 143 110 118 122 147 119 140 122 133 146 123 119 125 142 111 113 115 111 113 97 103 91 109 105 109 84 136 124 86 118 102 91 106 111 85 104 85 106 116 121 148 281 311 226 175 137 134 120 109 105 93 91 90 89 117 109 107 108 96 118 103 107 102 113 142 164 191 295 514 877 1186 848 608 381 488 402 341 209 141 112 119 111 121 136 172 215 271 319 435 367 301 192 137 133 83 97 85 101 82 85 92 99 88 97 74 86 82 104 77 84 91 85 93 104 96 109 146 166 210 232 188 170 100 83 100 77 92 67 81 90 82 88 76 73 108 83 86 99 99 147 152 145 111 82 91 69 74 73 76 65 77 91 74 85 75 85 89 100 99 107 136 214 251 228 284 313 380 271 222 117 96 91 75 90 97 87 74 74 50 88 83 76 82 83 80 76 70 77 78 68 63 66 75 69 68 74 81 76 78 83 81 110 101 90 74 87 74 54 58 61 70 83 78 57 83 60 86 81 82 116 154 193 187 138 118 105 99 90 125 149 129 136 105 72 88 92 96 116 168 300 489 459 340 248 171 109 112 74 85 71 52 72 67 88 81 81 130 180 200 183 152 104 83 59 77 66 71 95 117 95 85 68 85 52 60 59 60 66 75 61 73 72 72 52 53 76 55 61 58 61 61 66 61 68 52 62 61 73 59 63 72 67 62 97 107 236 469 563 394 357 265 129 85 79 79 81 106 141 179 158 116 115 89 98 71 68 77 60 63 59 60 81 74 83 88 81 89 92 77 76 64 57 56 64 63 69 63 53 53 61 51 68 49 60 45 62 63 57 46 66 59 64 56 70 46 51 45 58 50 49 51 53 52 45 64 60 52 45 50 75 68 50 55 53 58 49 71 64 73 89 100 144 170 225 165 149 155 84 43 68 59 49 52 73 52 39 66 65 66 74 64 93 104 131 111 107 89 86 78 65 65 59 67 89 106 187 214 140 159 114 86 91 63 63 49 65 62 54 67 67 53 55 90 63 76 83 83 82 72 76 61 74 76 88 130 172 150 137 134 124 91 93 87 121 167 152 215 185 234 290 526 642 444 381 361 218 131 96 82 66 90 127 171 117 121 124 137 207 224 158 155 148 111 68 77 72 60 63 70 68 52 60 74 68 71 51 61 65 55 69 45 57 55 61 61 68 56 55 50 38 52 70 45 55 50 64 60 47 47 48 50 48 52 42 59 68 47 44 63 44 84 110 172 136 151 141 107 104 88 62 57 66 78 42 47 56 49 71 69 101 103 73 76 78 64 77 61 58 58 46 63 74 87 82 95 106 124 131 87 71 82 56 48 47 48 57 55 57 60 44 54 44 49 33 61 74 74 84 81 102 140 255 377 400 246 238 209 152 103 83 90 82 94 68 62 61 52 64 48 61 61 53 74 78 67 93 120 159 266 376 301 236 251 219 134 82 78 67 72 68 54 82 104 77 82 78 88 64 66 67 67 43 64 72 53 64 77 72 66 58 43 46 75 63 68 60 83 70 74 103 107 225 708 1291 458 300 604 464 173 90 78 75 59 54 56 41 61 53 61 52 47 49 62 48 43 42 51 44 63 65 67 54 61 70 78 92 75 75 70 75 68 52 39 73 49 75 76 80 62 72 77 68 67 53 63 52 41 47 58 47 49 44 62 49 43 44 43 58 47 44 53 69 78 68 61 70 55 41 50 54 65 47 66 60 81 67 86 90 65 72 78 63 67 99 107 110 90 88 88 68 55 68 56 53 58 53 49 46 56 45 39 56 47 69 47 83 130 145 143 115 122 132 89 76 63 53 72 79 110 191 292 291 182 180 177 194 112 87 71 58 51 55 54 53 56 50 39 46 37 46 39 77 22 49 53 36 44 50 51 43 62 47 61 59 52 50 59 62 73 62 66 59 76 68 50 56 55 59 40 47 32 45 57 57 62 64 46 48 58 59 53 67 58 58 61 59 48 45 51 56 58 42 48 60 65 55 71 56 55 59 56 61 52 52 53 50 41 52 56 50 43 53 38 54 29 39 40 33 43 43 50 49 23 49 46 54 39 33 36 55 55 59 51 61 50 66 47 48 34 47 38 49 48 49 61 48 69 58 55 51 46 70 64 61 70 69 129 165 145 115 97 115 114 113 66 75 73 76 63 96 115 80 81 80 91 90 80 84 71 55 57 79 64 68 74 80 53 78 74 85 112 156 169 115 101 123 116 103 77 56 44 57 49 45 56 47 43 46 50 37 42 39 43 37 55 35 23 37 39 42 40 40 38 49 50 55 52 53 44 42 56 45 38 46 50 58 88 90 69 69 67 64 63 56 69 88 64 60 66 66 68 49 56 47 41 44 41 35 32 31 32 30 43 38 39 50 44 37 41 32 36 30 41 45 59 40 52 55 43 42 47 56 44 50 52 52 97 60 71 67 61 65 54 71 58 68 90 119 180 180 131 80 98 114 116 96 72 43 43 42 35 45 52 33 43 58 43 43 58 79 121 78 94 68 79 82 73 62 59 43 50 60 105 75 75 59 44 66 71 56 54 38 38 36 44 63 34 54 63 45 46 50 50 43 37 44 53 30 45 40 40 35 45 41 43 32 46 55 62 52 41 69 65 43 38 54 58 51 46 42 36 53 43 40 39 48 46 62 119 121 66 60 43 84 87 76 51 41 30 65 33 46 47 33 40 42 48 36 35 36 44 35 45 34 34 39 36 41 44 54 41 54 35 30 44 42 50 47 47 32 44 28 31 41 32 35 47 41 49 33 40 58 33 46 43 51 47 39 31 51 40 45 37 44 36 48 39 46 46 61 41 44 40 58 54 43 55 38 73 105 119 116 77 85 70 82 89 78 72 78 76 68 79 53 48 53 57 47 38 43 35 39 45 39 43 39 40 46 52 51 44 43 47 47 29 36 39 35 48 46 36 39 36 45 26 37 34 40 40 42 39 37 44 43 37 38 40 53 47 42 34 37 39 41 52 47 31 42 48 39 39 40 23 26 26 29 39 28 31 37 32 38 44 39 48 30 49 37 44 45 44 46 47 52 50 43 45 44 49 33 45 46 40 45 44 37 42 43 32 45 46 24 33 41 44 51 40 43 55 43 32 52 50 38 30 54 44 44 48 32 43 52 44 39 54 44 51 36 52 44 31 36 43 43 50 34 38 39 39 49 52 36 35 32 48 37 39 33 51 42 39 48 61 38 50 43 50 60 61 41 54 38 30 49 43 46 44 43 41 28 59 49 45 46 55 46 57 57 34 52 43 32 39 27 46 42 39 42 27 41 37 43 37 32 44 34 33 44 40 32 50 37 38 38 36 46 27 44 38 40 45 48 43 33 51 47 48 43 44 41 48 41 52 48 40 46 48 48 64 58 42 36 52 45 55 57 39 45 44 35 42 49 58 32 47 38 31 41 69 70 75 60 55 43 55 50 53 67 56 58 47 47 67 43 48 56 51 63 44 60 95 89 60 70 67 51 66 56 60 45 49 47 33 31 32 33 46 28 31 43 47 47 25 37 41 54 41 39 33 46 26 42 31 38 50 42 54 44 36 54 39 50 37 48 44 44 45 68 34 36 34 37 45 52 51 48 41 24 38 39 38 47 37 35 48 53 43 40 40 40 46 54 73 58 69 59 52 42 53 60 44 45 47 44 32 49 38 43 43 43 47 46 33 44 43 47 39 39 46 44 39 53 49 36 61 39 63 50 52 45 42 43 50 62 33 76 45 34 33 50 30 45 31 44 44 30 24 51 42 40 38 33 35 19 39 44 36 46 50 33 53 45 36 39 48 45 46 40 37 32 36 44 44 36 34 42 24 39 29 44 42 33 26 34 46 48 30 37 44 38 42 37 43 33 47 48 39 34 41 36 34 62 35 36 40 47 45 54 57 45 34 39 45 36 42 52 42 39 40 38 43 35 49 41 41 47 38 44 35 53 40 40 35 31 33 28 35 45 41 24 53 35 38 53 28 50 37 39 38 39 36 32 38 44 39 38 60 38 41 38 43 45 34 40 49 52 37 49 51 43 49 50 44 45 39 42 34 46 43 36 42 39 38 44 31 28 34 36 40 46 40 29 47 37 41 54 74 69 76 83 72 66 60 37 51 56 45 85 51 51 54 36 36 40 40 41 31 44 47 36 37 48 29 35 38 40 40 41 33 45 57 65 61 48 66 48 42 40 54 43 59 57 62 44 55 43 38 39 29 43 42 41 49 39 40 69 40 41 43 51 45 32 53 51 55 48 49 36 66 37 48 41 50 36 39 44 53 55 46 49 38 39 42 61 53 67 84 61 48 53 60 62 43 59 56 59 59 44 51 52 42 42 55 42 55 60 76 46 53 42 30 34 44 37 59 46 57 43 46 37 48 37 45 43 38 39 35 52 40 33 39 51 47 37 52 46 45 43 32 51 63 101 69 89 64 58 49 65 51 46 70 71 70 66 51 49 46 48 45 38 43 46 42 50 50 51 62 83 59 51 48 37 50 58 64 46 60 56 53 48 37 62 18 42 38 46 37 30 37 46 47 40 40 49 64 41 43 38 28 41 42 34 37 50 41 37 46 42 48 36 48 48 43 48 42 38 49 32 36 49 45 41 41 44 44 44 42 49 44 34 49 37 44 47 44 42 47 52 37 48 57 60 87 96 94 100 134 101 84 67 69 64 55 72 76 76 75 81 70 58 59 57 41 39 32 48 51 45 39 42 40 44 44 41 56 53 50 46 33 40 36 65 59 64 60 59 48 46 54 40 31 35 41 55 47 47 54 47 62 34 47 43 40 41 41 41 47 47 42 36 45 48 65 49 45 61 41 50 49 53 48 59 63 38 50 51 53 44 52 58 68 67 84 75 78 67 52 43 52 40 45 42 38 65 67 67 63 70 62 53 59 69 58 47 50 47 49 54 70 45 55 56 42 47 60 52 60 43 60 48 61 46 57 42 43 49 47 41 42 44 41 50 36 40 38 47 35 47 42 36 47 60 68 43 20 40 28 56 50 48 52 49 41 38 51 31 29 36 39 44 58 34 40 63 33 46 43 39 48 47 31 48 38 39 50 44 25 41 35 39 51 55 56 45 49 42 42 37 49 53 31 58 62 37 50 39 45 40 35 52 43 47 37 48 41 43 43 54 52 48 47 35 42 55 36 34 57 44 39 39 54 37 39 46 43 53 44 52 41 45 44 41 43 50 48 50 44 39 40 47 68 34 64 39 48 48 54 56 59 51 40 45 36 46 32 36 43 57 51 24 44 48 51 48 52 61 38 58 42 46 50 56 55 64 55 74 65 70 86 91 82 72 66 49 60 54 44 52 60 67 81 77 70 77 74 55 64 51 46 57 53 55 78 35 50 41 67 58 51 65 46 47 56 49 59 48 50 37 40 38 53 53 35 40 48 45 42 47 36 56 38 35 45 39 52 50 34 67 44 41 37 51 52 34 44 45 45 41 60 41 60 47 46 46 54 42 33 53 57 44 40 49 47 49 42 46 58 48 46 50 38 47 49 56 44 40 50 32 51 48 47 43 47 32 64 64 55 68 45 66 44 69 56 57 51 60 73 64 61 54 46 60 63 55 74 57 57 75 52 50 62 68 57 72 55 81 71 74 74 89 102 80 80 94 64 55 75 58 52 68 51 45 50 48 57 65 69 57 65 63 68 41 74 53 46 45 68 57 54 54 54 61 58 47 54 56 62 43 63 49 44 42 45 32 49 53 32 50 52 52 69 56 49 54 43 56 47 62 67 52 59 62 42 48 45 42 55 63 71 42 45 46 32 37 45 53 47 48 48 65 45 44 46 53 47 55 63 36 49 47 43 38 47 60 56 54 43 40 36 50 49 48 42 46 39 47 49 40 49 46 41 48 44 49 50 44 42 47 41 51 62 49 53 43 33 48</counts>
			</dataPoints>
		</scan>
	</xrdMeasurement>
</xrdMeasurements>