File: dataset/precursor_mixture/TiO2_ZrO2_CaCO3_LiCoO2.12-min.xrdml
<?xml version="1.0"?>
<xrdMeasurements xmlns="http://www.xrdml.com/XRDMeasurement/2.2" xmlns:xsi="http://www.w3.org/2001/XMLSchema-instance" xsi:schemaLocation="http://www.xrdml.com/XRDMeasurement/2.2 http://www.xrdml.com/XRDMeasurement/2.2/XRDMeasurement.xsd" status="Completed" recordIdentifier="{C051AAD4-B8DE-49F2-B1CB-492736D4E3C2}">
	<comment>
		<entry/>
	</comment>
	<sample type="To be analyzed">
		<id>dara-38-2</id>
		<name></name>
		<preparedBy></preparedBy>
	</sample>
	<xrdMeasurement measurementType="Scan" status="Completed" sampleMode="Reflection">
		<usedWavelength intended="K-Alpha 1">
			<kAlpha1 unit="Angstrom">1.5405980</kAlpha1>
			<kAlpha2 unit="Angstrom">1.5444260</kAlpha2>
			<kBeta unit="Angstrom">1.3922500</kBeta>
			<ratioKAlpha2KAlpha1>0.5000</ratioKAlpha2KAlpha1>
		</usedWavelength>
		<incidentBeamPath>
			<radius unit="mm">145.00</radius>
			<xRayTube id="1010048" name="Empyrean Cu LFF HR (9430 033 7310x) DK430614">
				<tension unit="kV">40.0</tension>
				<current unit="mA">15.0</current>
				<anodeMaterial>Cu</anodeMaterial>
				<focus type="Line">
					<length unit="mm">12.0</length>
					<width unit="mm">0.4</width>
					<takeOffAngle unit="deg">6.0</takeOffAngle>
				</focus>
			</xRayTube>
			<filter id="20010004" name="Beta-filter Nickel">
				<material>Ni</material>
				<thickness unit="mm">0.020</thickness>
			</filter>
			<sollerSlit id="21010002" name="Soller slits 0.04 rad.">
				<opening unit="rad">0.0400</opening>
			</sollerSlit>
			<mask id="22031000" name="Fixed mask 13 mm">
				<width unit="mm">9.00</width>
			</mask>
			<divergenceSlit id="22120001" name="Divergence slit 1°" xsi:type="fixedDivergenceSlitType">
				<distanceToSample unit="mm">50.00</distanceToSample>
				<height unit="mm">1.52</height>
			</divergenceSlit>
		</incidentBeamPath>
		<beamKnife id="29030100" name="Beam knife low"/>
		<sampleMovement xsi:type="spinningSampleMovementType">
			<spinnerRevolutionTime unit="seconds">1.0</spinnerRevolutionTime>
		</sampleMovement>
		<diffractedBeamPath>
			<radius unit="mm">145.00</radius>
			<antiScatterSlit id="22090040" name="AS slit 9 mm" xsi:type="fixedAntiScatterSlitType">
				<height unit="mm">9.00</height>
			</antiScatterSlit>
			<sollerSlit id="21020003" name="Large Soller slits 0.04 rad.">
				<opening unit="rad">0.0400</opening>
			</sollerSlit>
			<filter id="20030001" name="Large beta-filter Nickel">
				<material>Ni</material>
				<thickness unit="mm">0.020</thickness>
			</filter>
			<detector id="7010019" name="PIXcel1D-Medipix3 detector" xsi:type="rtmsDetectorType">
				<phd unit="keV">
					<lowerLevel>4.0</lowerLevel>
					<upperLevel>11.3</upperLevel>
				</phd>
				<mode>Scanning</mode>
				<activeLength unit="deg">5.020</activeLength>
			</detector>
		</diffractedBeamPath>
		<scan appendNumber="0" mode="Continuous" scanAxis="Gonio" status="Completed">
			<header>
				<startTimeStamp>2024-02-18T12:32:00-08:00</startTimeStamp>
				<endTimeStamp>2024-02-18T12:44:27-08:00</endTimeStamp>
				<author>
					<name>AutomatedUser</name>
				</author>
				<source>
					<applicationSoftware version="1.4b (28)">PANalytical Aeris Instrument Suite</applicationSoftware>
					<instrumentControlSoftware version="2.0.0 20210224">AERIS</instrumentControlSoftware>
					<instrumentID>950485</instrumentID>
				</source>
			</header>
			<dataPoints>
				<positions axis="2Theta" unit="deg">
					<startPosition>9.99043322</startPosition>
					<endPosition>100.09495370</endPosition>
				</positions>
				<positions axis="Omega" unit="deg">
					<startPosition>4.99521661</startPosition>
					<endPosition>50.04747685</endPosition>
				</positions>
				<commonCountingTime unit="seconds">18.249</commonCountingTime>
				<counts unit="counts">5649 5579 5612 5679 5697 5641 5681 5727 5802 5629 5745 5529 5723 5566 5697 5559 5565 5583 5614 5668 5575 5640 5584 5575 5594 5608 5566 5573 5559 5671 5528 5660 5519 5553 5474 5532 5588 5512 5508 5489 5503 5653 5600 5544 5514 5503 5535 5551 5576 5497 5587 5433 5494 5676 5584 5491 5525 5553 5578 5504 5504 5556 5386 5528 5482 5505 5447 5357 5569 5516 5443 5488 5415 5503 5572 5572 5466 5576 5519 5480 5380 5540 5485 5445 5606 5369 5395 5414 5429 5515 5418 5606 5288 5472 5364 5523 5554 5350 5470 5528 5439 5437 5448 5453 5441 5395 5366 5325 5341 5358 5400 5514 5373 5448 5500 5358 5455 5479 5378 5340 5544 5529 5433 5328 5570 5445 5395 5541 5316 5498 5326 5427 5424 5367 5279 5468 5369 5365 5322 5330 5290 5236 5374 5457 5441 5354 5418 5537 5310 5405 5340 5293 5293 5282 5270 5186 5415 5339 5250 5323 5504 5264 5252 5353 5309 5357 5379 5335 5440 5195 5371 5330 5332 5301 5240 5489 5259 5276 5175 5345 5352 5416 5372 5324 5337 5288 5220 5273 5307 5330 5247 5329 5402 5261 5189 5272 5358 5227 5402 5249 5351 5285 5359 5330 5254 5227 5213 5227 5270 5399 5323 5437 5190 5223 5237 5308 5273 5289 5293 5228 5179 5277 5194 5332 5372 5208 5085 5335 5276 5118 5169 5264 5287 5299 5161 5130 5225 5283 5201 5252 5218 5321 5378 5439 5161 5199 5245 5305 5273 5335 5394 5305 5179 5141 5244 5213 5183 5290 5182 5190 5317 5193 5268 5352 5314 5327 5352 5138 5318 5244 5267 5214 5248 5227 5330 5169 5244 5173 5203 5124 5308 5164 5367 5323 5317 5226 5225 5263 5139 5255 5235 5223 5281 5258 5286 5153 5287 5220 5310 5305 5261 5240 5262 5238 5277 5258 5215 5362 5319 5257 5228 5336 5318 5129 5285 5328 5166 5221 5108 5154 5242 5255 5269 5181 5289 5302 5151 5317 5183 5211 5329 5178 5204 5330 5186 5349 5245 5194 5189 5249 5226 5129 5191 5144 5321 5186 5316 5140 5155 5233 5310 5226 5138 5214 5124 5240 5082 5269 5057 5182 5362 5148 5133 5416 5204 5377 5157 5224 5011 5258 5284 5181 5216 5185 5330 5198 5310 5109 5161 5197 5286 5215 5132 5262 5225 5158 5188 5193 5332 5124 5309 5108 5015 5257 5217 5171 5156 5295 5037 5088 5230 5092 5228 5165 5218 5220 5272 5228 5261 5120 5284 5233 5165 5160 5275 5167 5251 5309 5178 5279 5203 5265 5297 5148 5065 5188 5170 5149 5134 5196 5128 5178 5181 5064 5048 5163 5175 5062 5050 5168 5204 5290 5187 5147 5260 5251 4952 5258 5167 5176 5244 5251 5216 5175 5165 5117 5144 5200 5152 5229 5106 5110 5108 5217 5187 5180 5106 5146 5021 5228 5074 5342 5250 5196 5135 5189 5094 5159 5176 5079 5241 5260 5126 5193 5121 5157 5154 5132 5207 5201 5246 5392 5214 5212 5131 5088 5190 5304 5220 5329 5210 5198 5120 5193 5251 5213 5241 5212 5194 5119 5224 5176 5224 5174 5211 5178 5158 5184 5259 5146 5344 5173 5266 5192 5199 5179 5222 5320 5287 5140 5264 5243 5277 5308 5322 5123 5228 5280 5185 5249 5081 5285 5169 5297 5200 5249 5117 5094 5142 5114 5209 5230 5150 5175 5144 5228 5216 5148 5179 5156 5144 5198 5168 5034 5330 5369 5085 5192 5278 4972 5249 5316 5335 5315 5312 5241 5191 5296 5164 5137 5183 5074 5291 5194 5143 5156 5364 5190 5133 5112 5132 5350 5102 5302 5193 5140 5177 5182 5087 5259 5105 5177 5237 5080 5132 5217 5235 5391 5083 5089 5208 5227 5078 5283 5190 5220 5134 5234 5052 5181 5182 5208 5188 5112 5088 5021 5190 5144 5157 5305 5215 5186 5243 5286 5119 5246 5239 5099 5391 5283 5229 5218 5253 5303 5316 5323 5248 5252 5271 5280 5234 5152 5046 5327 5433 5322 5149 5371 5337 5223 5267 5328 5436 5521 5532 5682 5556 5570 5598 5566 5399 5206 5434 5154 5262 5374 5218 5365 5411 5424 5208 5388 5303 5353 5339 5496 5462 5570 5489 5523 5570 5478 5491 5460 5519 5448 5467 5573 5391 5639 5472 5417 5492 5307 5434 5498 5371 5432 5297 5279 5530 5333 5254 5220 5295 5274 5261 5292 5143 5122 5102 5015 5283 5149 5270 5178 5214 5140 5109 5105 5206 5238 5247 5152 5064 5154 5202 5076 5147 5128 5199 5210 5114 5184 5257 5162 5164 5271 5186 5162 5151 5044 5192 5156 5262 5370 5135 5213 5279 5239 5147 5218 5290 5294 5196 5294 5171 5321 5208 5364 5279 5345 5453 5571 5671 5678 5781 5693 5802 6058 5881 5965 5887 6051 5938 6051 6042 6166 6169 6223 6479 6354 6649 6451 6715 6625 6822 6792 6888 7012 6950 7000 6927 7163 7368 7512 7443 7722 7803 8257 8578 8819 9325 9797 10453 10883 12178 13018 14345 16015 18129 20073 22806 25712 29263 34056 39204 44965 51691 60576 69985 81553 95108 109495 125981 138033 143343 135462 118226 102495 88144 74743 58397 42686 30825 23142 18051 14488 12120 10613 9346 8587 8101 7620 7420 7242 7094 7139 7010 6897 6831 6719 6637 6637 6542 6732 6510 6588 6353 6317 6228 6117 6028 6121 5965 5888 5530 5610 5703 5587 5662 5504 5558 5525 5515 5372 5409 5549 5531 5568 5426 5525 5373 5467 5583 5360 5488 5334 5342 5490 5418 5437 5350 5532 5322 5460 5396 5424 5407 5445 5399 5635 5642 5562 5493 5579 5560 5710 5485 5620 5641 5441 5651 5655 5600 5632 5618 5678 5642 5637 5630 5734 5578 5614 5607 5686 5628 5586 5530 5468 5613 5582 5654 5568 5689 5678 5807 5574 5669 5532 5538 5660 5423 5592 5554 5541 5620 5606 5609 5635 5587 5493 5540 5523 5578 5510 5562 5502 5643 5693 5540 5649 5699 5643 5610 5700 5601 5597 5619 5434 5592 5562 5533 5521 5677 5587 5427 5615 5761 5447 5508 5539 5460 5698 5640 5514 5540 5684 5602 5512 5585 5594 5523 5446 5645 5456 5525 5586 5530 5710 5680 5734 5685 5541 5711 5570 5538 5543 5399 5476 5442 5409 5443 5461 5531 5498 5519 5361 5359 5485 5442 5422 5461 5454 5444 5540 5450 5353 5402 5416 5542 5343 5457 5302 5381 5354 5475 5315 5315 5480 5394 5378 5341 5327 5369 5369 5337 5377 5409 5282 5491 5249 5399 5361 5513 5387 5378 5323 5294 5405 5322 5463 5460 5348 5447 5184 5491 5341 5273 5338 5372 5405 5327 5160 5312 5238 5242 5276 5309 5315 5226 5378 5304 5370 5412 5315 5364 5207 5280 5365 5395 5285 5328 5253 5148 5284 5269 5354 5254 5363 5362 5327 5248 5294 5327 5278 5256 5197 5158 5339 5122 5169 5156 5028 5346 5274 5215 5341 5117 5310 5102 5069 5240 5139 5212 5167 5269 5328 5176 5071 5137 5270 5189 5305 5151 5235 5098 5243 5285 5263 5056 5204 5178 5280 5163 5317 5088 5137 5065 5250 5075 5265 5211 5172 5183 5145 5202 5174 5322 5232 5151 5102 5210 5228 5213 5143 5130 5127 5267 5222 5272 5270 5311 5258 5179 5151 5222 5162 5270 5283 5111 5119 5104 5260 5227 5244 5212 5023 5290 5229 5289 5164 5222 5125 5257 5261 5322 5199 5343 5422 5411 5255 5327 5407 5528 5386 5338 5369 5201 5222 5334 5230 5267 5212 5082 5139 5175 5288 5023 5191 5158 5148 5287 5066 5038 5131 5151 5146 5130 5121 5098 5089 5077 5069 5222 5187 5074 5054 5103 5119 5145 5126 5146 5167 5108 5285 5236 5212 5128 5319 5081 5123 5137 5114 5079 5123 5172 5223 5207 5220 5134 5110 5231 5078 5169 5191 5153 5194 5244 5232 5213 5158 5233 5339 5288 5330 5352 5357 5411 5732 5541 5481 5547 5517 5788 5768 5845 5943 5918 6013 6072 6274 6320 6324 6391 6357 6521 6447 6473 6209 6262 6329 6151 6073 5964 5826 5705 5784 5604 5714 5543 5598 5574 5659 5484 5555 5485 5622 5566 5515 5612 5535 5681 5663 5754 5689 5870 5952 5858 5931 5976 6000 5991 6139 5980 5763 6027 5770 5755 5832 5720 5640 5724 5606 5600 5435 5413 5312 5419 5206 5305 5271 5377 5345 5128 5179 5373 5138 5295 5206 5294 5349 5346 5204 5196 5218 5178 5069 5191 5285 5329 5319 5309 5219 5297 5382 5325 5520 5351 5323 5444 5461 5525 5579 5675 5815 5794 5933 6007 6161 6213 6352 6415 6774 7147 7465 7655 8001 8600 9233 10035 10488 11333 12156 12874 13707 14849 15892 16901 17614 18219 18202 18012 17497 16497 15484 14657 13270 12261 11278 10116 9076 8395 7686 7261 6683 6237 6104 5830 5864 5717 5637 5643 5428 5339 5374 5352 5248 5475 5400 5355 5256 5249 5139 5073 5236 5046 5127 5153 5055 5004 5104 5055 5233 5012 5075 4961 5058 5132 5132 4958 4988 5043 5213 5033 5110 5083 5147 5115 5176 5172 5197 5197 5210 5236 5124 5149 5064 5108 5078 5003 5021 4986 5076 4939 4896 4856 4922 5067 4956 4849 5020 5002 5062 4961 4963 4958 4990 4951 4974 5042 4839 4944 4891 4936 4814 5041 4920 4912 4975 4834 5036 4968 5043 4995 5096 5068 4955 5180 5074 5226 5135 5206 5154 5177 5089 5084 4949 4927 4837 4911 4984 5034 4945 4827 4943 5048 4954 4969 4940 4736 4998 4960 4854 4919 4929 5083 4929 4962 4964 4769 4874 4900 4944 4922 4818 4938 4929 4714 4848 4827 4868 4844 4733 4895 4797 4873 4884 4858 4902 4832 4907 4830 4937 4837 4855 4928 4839 4917 4914 4946 4835 4964 4891 4960 4971 4854 4883 4948 4820 4904 4962 4993 4767 4955 5041 4986 4884 5016 4914 5020 4770 4874 4980 4931 5063 5056 4981 4960 5020 5031 5055 5078 4985 5025 5021 5070 5157 5094 5045 5076 4938 5006 4998 5042 5106 5200 5176 5185 5163 5106 5203 5133 5230 5133 5242 5253 5361 5183 5363 5271 5301 5484 5367 5344 5617 5488 5718 5647 5663 5826 5856 5950 6003 6253 6475 6493 6569 6820 6991 7428 7619 7914 8296 8728 9002 9331 10122 10618 11085 11578 12041 12652 13197 13373 13697 13619 13647 13369 12764 12464 12107 11515 11158 10438 10010 9407 9009 8544 8157 7600 7551 7359 7174 6967 6632 6547 6500 6458 6313 6377 6121 6063 6100 5952 5911 5946 6028 5796 5713 5796 5807 5866 5670 5652 5490 5620 5557 5670 5590 5572 5582 5586 5568 5605 5541 5458 5580 5638 5553 5538 5698 5596 5711 5770 5774 5709 5694 5787 5603 5728 6048 5941 6100 6136 6137 5996 6111 6017 6263 6256 6312 6391 6304 6312 6256 6276 6368 6639 6643 6604 6750 6835 7112 7218 7492 7655 8089 8340 8906 9557 10094 10918 12368 13689 15453 17852 20569 24044 28735 34694 41861 51294 62144 76235 91236 107281 120076 127845 126538 113056 98273 86955 78992 76786 71166 63240 52022 40001 29387 22576 17354 14345 11937 10629 9757 8799 8362 8099 7822 7386 7312 7157 7072 7060 6914 6715 6797 6618 6529 6458 6271 6300 6019 6082 6020 5792 5743 5776 5758 5657 5479 5461 5425 5410 5537 5461 5467 5368 5330 5332 5271 5283 5232 5338 5166 5163 5178 5202 5129 5239 5077 5112 5177 5154 5181 5099 5168 5139 5244 5093 5207 5169 5213 5175 5142 5141 5129 5039 5144 5226 5206 5058 5066 5189 5191 5221 5064 5175 5091 4998 5066 4994 5102 5098 5074 5125 5206 5097 5122 5119 5121 5065 5154 5052 5011 5180 5140 5067 5100 5020 5021 5180 5125 5084 5058 5092 5098 5196 5242 5046 5083 5092 5077 5142 5043 5096 5235 5046 5123 5152 5206 5220 5202 5393 5147 5402 5155 5252 5354 5192 5136 5244 5134 5427 5223 5286 5243 5363 5378 5395 5359 5199 5384 5348 5477 5550 5527 5534 5681 5558 5739 5695 5886 5878 5817 6167 6075 6270 6272 6493 6440 6684 6849 7059 7309 7556 8042 8162 8308 8829 9157 9374 9670 10110 10575 10761 11039 11060 10795 10636 10666 10434 9884 9827 9295 9125 8645 8430 7958 7666 7327 6991 6758 6584 6327 6346 6035 6000 5897 5784 5905 5607 5568 5504 5649 5478 5441 5347 5293 5219 5203 5371 5184 5245 4990 5081 5091 5066 5052 5181 5031 5217 5081 5056 5106 4935 5025 4895 4874 5019 5010 5104 4969 5062 5050 5010 4997 5063 4877 5010 5047 4850 5043 5039 4928 5012 4857 4816 4871 4798 4843 4885 4983 4899 4715 4870 4900 4831 5022 4819 5051 4843 4808 4848 4775 4789 4726 4883 4902 4877 4813 4723 4821 4948 4763 4945 4954 4945 4777 4888 4831 4901 4876 4697 4800 4729 4859 4797 4858 4786 4813 4889 4854 4870 4860 4783 4869 4792 4784 4757 4756 4749 4820 4819 4762 4883 4826 4785 4781 4739 4693 4873 4773 4731 4868 4772 4801 4880 4697 4674 4824 4805 4832 4785 4775 4829 4767 4787 4826 4797 4721 4726 5012 4810 4846 4741 4888 4755 4856 4824 4732 4611 4846 4840 4857 4918 4752 4820 4766 4842 4713 4782 4727 4943 4715 4807 4808 4859 4835 4651 4879 4751 4705 4804 4768 4751 4820 4698 4676 4852 4791 4866 4838 4749 4794 4775 4768 4786 4708 4918 4869 4867 4768 4802 4766 4879 4829 4909 4854 4839 4904 4848 4817 4870 4818 4873 4999 4884 4913 5002 4998 5058 5018 5181 5200 5121 5134 5268 5399 5352 5332 5542 5327 5633 5591 5815 5810 6055 6058 6202 6235 6316 6455 6699 6533 6524 6539 6526 6507 6610 6430 6425 6236 6281 6195 6227 6184 6000 6042 6163 6130 5988 6022 6148 6074 5870 6042 6005 5906 5838 5870 5775 5748 5684 5577 5548 5501 5433 5499 5328 5320 5373 5254 5244 5068 5177 5004 5040 5173 5052 5092 4932 5023 5033 5047 4955 4817 4856 4934 4961 4907 4954 4772 4885 4905 5016 4826 4926 4858 4857 4893 4918 4855 4820 4871 4940 4684 5000 4822 4861 4886 4860 4825 4903 4844 4899 4979 4837 4971 5118 5111 4927 5031 5046 5234 5177 5297 5168 5384 5417 5403 5451 5491 5610 5597 5620 5869 5751 6002 5871 5882 5989 5822 5828 5750 5832 5653 5543 5505 5519 5414 5383 5265 5207 5106 4950 5100 4926 5061 4860 4932 4820 4930 4756 4895 4864 4746 4843 4716 4766 4865 4862 4772 4770 4761 4863 4892 4800 4855 4725 4862 4951 4846 4852 4804 4799 4870 4982 4898 4979 4933 4991 4973 5185 5181 5137 4977 5149 5236 5358 5240 5122 5254 5063 5047 5011 5091 5020 5106 4941 4983 5023 4833 4833 4881 4759 4817 4724 4771 4873 4708 4627 4771 4653 4680 4728 4607 4824 4717 4702 4793 4760 4729 4761 4625 4505 4666 4635 4661 4636 4573 4608 4600 4759 4575 4587 4610 4594 4554 4657 4735 4587 4610 4597 4642 4597 4758 4663 4677 4689 4683 4668 4728 4672 4756 4651 4711 4686 4811 4664 4838 4719 4722 4621 4753 4718 4747 4664 4805 4869 4897 4948 4763 4903 4954 5075 5043 5068 5269 5239 5419 5414 5417 5338 5162 5272 5220 5137 5149 5010 5091 5019 4878 5126 4874 5077 4716 4945 4750 4762 4948 4652 4715 4815 4768 4786 4874 4814 4998 4881 5021 5069 5097 5170 5208 5295 5367 5623 5803 5938 6044 6114 6383 6169 6221 6118 5766 5758 5635 5612 5706 5626 5468 5377 5285 5302 5161 4917 5132 4853 5084 4949 5097 5067 5147 5263 5093 5383 5474 5420 5651 5830 5913 6149 6302 6684 6818 7167 7177 7124 7214 7085 6878 6769 6492 6338 6382 6208 6242 6057 5913 5722 5507 5260 5191 5095 5191 5005 4913 4934 4960 4790 4963 4857 4899 4816 4826 4819 4803 4910 4778 4901 4919 4783 4856 5018 5005 4904 5011 4984 4930 5101 5210 5330 5426 5663 6032 6174 6650 7350 7920 8693 9692 10905 12160 13429 14086 13800 12345 10763 9624 8904 9013 9315 9704 10032 9950 9489 8253 7405 6954 6240 6219 6059 5961 5789 5686 5671 5486 5518 5579 5432 5238 5129 5162 5106 5010 4849 4985 4860 4896 4782 4827 4772 4718 4804 4821 4787 4859 4742 4916 4566 4713 4773 4980 4726 4877 4878 4880 4987 5028 5123 5077 5074 5144 5373 5323 5216 5272 5096 5042 5050 5015 5042 4958 5059 4916 5018 4945 4849 4792 4845 4751 4882 4791 4944 4775 4803 4867 4867 4856 5048 5207 5142 5189 5436 5380 5459 5427 5282 5213 5149 5190 5081 5035 5185 5011 5059 4881 5005 5004 4845 4849 4679 4646 4609 4800 4705 4612 4592 4623 4637 4628 4608 4579 4511 4687 4593 4728 4529 4613 4524 4711 4628 4679 4566 4715 4503 4703 4617 4662 4711 4726 4631 4577 4658 4529 4556 4616 4652 4643 4528 4639 4628 4610 4545 4556 4582 4710 4698 4682 4775 4585 4557 4670 4719 4515 4648 4569 4567 4661 4674 4639 4692 4714 4478 4600 4602 4653 4642 4766 4748 4671 4745 4749 4489 4790 4574 4692 4703 4738 4789 4745 4769 4734 4729 4717 4820 4786 4962 4807 5053 4863 4876 4982 4959 5034 5158 5081 5349 5029 5359 5205 5379 5381 5407 5455 5497 5629 5511 5576 5453 5607 5564 5384 5349 5231 5368 5239 5277 5058 5177 5211 5267 5054 4996 5142 5007 4962 4902 4973 4847 4816 4869 4807 4863 4921 5056 4943 5050 4915 4864 5009 5014 5040 5087 4994 4954 4997 5073 5105 5092 5008 4882 4993 5060 4974 5095 5041 5010 5011 5055 4975 5047 5090 4939 5019 5055 5060 5012 5024 5067 4989 5036 5012 4911 4897 4948 4790 4868 4823 4886 4822 4735 4646 4751 4653 4652 4712 4776 4670 4713 4763 4616 4640 4622 4689 4567 4709 4542 4556 4708 4579 4586 4602 4615 4532 4522 4564 4554 4622 4484 4532 4705 4633 4587 4576 4512 4590 4582 4523 4722 4544 4570 4412 4554 4550 4573 4629 4545 4593 4576 4451 4529 4530 4611 4463 4492 4611 4624 4524 4563 4666 4626 4615 4591 4553 4534 4553 4589 4564 4522 4609 4570 4460 4567 4659 4506 4500 4488 4527 4518 4469 4499 4518 4573 4601 4515 4449 4575 4393 4452 4522 4557 4540 4489 4505 4545 4518 4587 4522 4524 4604 4500 4455 4521 4556 4588 4660 4472 4589 4543 4532 4584 4610 4524 4496 4483 4533 4511 4572 4505 4657 4583 4474 4456 4492 4433 4517 4603 4558 4484 4470 4530 4518 4568 4558 4608 4609 4671 4671 4655 4714 4744 4866 5044 4888 5043 5213 5180 5239 5284 5465 5302 5379 5093 5238 5150 4964 5114 4988 5094 5037 4880 4841 4865 4776 4830 4715 4720 4695 4463 4515 4570 4516 4578 4620 4577 4589 4488 4549 4602 4558 4591 4479 4663 4630 4548 4587 4619 4682 4529 4424 4552 4666 4546 4577 4574 4604 4628 4508 4552 4624 4477 4561 4523 4441 4484 4441 4540 4620 4512 4657 4496 4580 4510 4466 4365 4523 4553 4654 4507 4584 4467 4548 4602 4602 4436 4582 4482 4509 4707 4539 4625 4616 4498 4617 4434 4394 4487 4457 4601 4690 4602 4633 4647 4451 4390 4642 4550 4422 4585 4644 4596 4515 4517 4544 4655 4708 4680 4495 4545 4545 4686 4573 4631 4632 4627 4498 4568 4639 4642 4535 4539 4654 4556 4733 4515 4606 4515 4621 4649 4777 4672 4711 4694 4758 4614 4682 4733 4795 4873 4739 4833 4797 4775 4791 4847 4955 4876 4979 5108 4984 5238 5009 5161 5070 5199 5088 4985 5121 5070 5154 5098 5037 4989 5031 5019 4918 5090 5024 4848 4972 5059 4898 4977 4969 4898 5113 5170 5186 5489 5375 5756 5698 6041 6504 6909 7195 7763 8087 8409 8728 8677 8800 8077 7684 7404 7134 6808 6705 6910 7032 6860 6968 6717 6344 6231 5701 5693 5491 5314 5195 5198 5130 5234 5198 5211 5150 5186 5269 5132 5092 4896 5052 4943 5016 4883 4929 4987 4933 4987 4772 4825 4847 4811 4715 4709 4789 4804 4811 4704 4678 4743 4858 4666 4740 4748 4694 4562 4645 4549 4507 4732 4533 4557 4535 4612 4506 4486 4680 4565 4562 4545 4391 4550 4472 4647 4489 4567 4614 4485 4589 4543 4472 4540 4553 4652 4587 4468 4568 4456 4657 4588 4726 4519 4532 4474 4511 4422 4549 4645 4697 4633 4541 4591 4515 4491 4514 4642 4585 4580 4535 4547 4481 4495 4537 4597 4440 4453 4429 4528 4573 4520 4630 4563 4628 4554 4447 4561 4451 4626 4559 4697 4501 4435 4584 4596 4546 4547 4538 4625 4502 4561 4561 4615 4619 4559 4614 4534 4623 4489 4579 4665 4495 4553 4672 4486 4458 4550 4477 4567 4503 4592 4648 4635 4619 4584 4649 4647 4666 4772 4615 4793 4788 4560 4820 4853 4908 4667 4758 4840 4674 4814 4640 4744 4653 4868 4666 4741 4737 4763 4617 4681 4865 4930 4692 4874 4739 4846 5010 5063 5209 5318 5500 5738 5994 6097 6402 6970 6959 7271 6836 6828 6587 6079 5956 5839 5827 5901 5957 5953 5880 6014 5821 5642 5389 5303 5120 5047 4977 4833 4842 4842 4823 5007 4831 4746 4788 4854 4906 4854 4896 4809 4902 4945 5004 5019 5161 5218 5228 5310 5611 5948 6109 6411 6866 7145 7553 7867 8093 8230 8029 7867 7647 7029 6983 6716 6605 6712 6541 6838 6752 6415 6525 6143 5881 5584 5504 5234 5303 5038 5087 4959 4984 4814 4921 4859 4922 4784 4960 4839 4875 4990 4896 5224 5275 5368 5399 5432 5602 5837 5900 5914 5906 5858 5554 5469 5429 5188 5296 5199 5215 5427 5359 5386 5290 5225 5145 5037 4788 4839 4678 4913 4704 4836 4833 4731 4650 4641 4923 4843 4719 4717 4785 4620 4833 4670 4815 4669 4816 4777 4776 4930 4850 5075 4780 4966 4885 4835 4919 4856 4891 4855 4781 4922 4975 5000 5105 4996 5165 5111 5127 5278 5199 5322 5555 5593 5719 5713 5874 5863 6063 5956 6133 5980 5967 5962 5873 5780 5940 5862 5996 6036 5851 6069 5847 6113 6095 5958 5872 5800 5785 5676 5506 5586 5425 5356 5277 5342 5320 5275 5229 5135 5160 5117 4967 4931 5044 5028 4842 4880 4928 4709 4992 4823 4789 4792 4847 4799 4875 4867 4793 4751 4861 4868 5014 4925 4932 5020 4972 4862 4908 4950 5023 4864 4954 4963 5114 5335 5272 5380 5559 5482 5594 5693 5825 6025 5946 6129 6233 6452 6486 6420 6613 6286 6211 6225 6066 5956 5993 6037 5992 6021 5827 5877 5730 5701 5414 5495 5431 5352 5480 5313 5269 5257 5118 5128 5118 5297 5245 5016 5229 5134 5157 5298 5248 5293 5355 5471 5426 5470 5541 5537 5532 5621 5673 5488 5545 5361 5442 5405 5397 5358 5445 5174 5370 5187 5206 5207 5059 4897 4877 4906 4979 4993 4841 4800 4838 4823 4836 4739 4744 4773 4709 4790 4702 4720 4751 4615 4605 4671 4749 4737 4616 4719 4756 4654 4716 4827 4787 4815 4848 4735 4945 4809 4801 4969 4919 5016 4890 4920 4989 5014 4913 4889 4848 4756 4873 4843 4787 4849 4852 4695 4732 4806 4766 4825 4673 4633 4784 4707 4716 4762 4673 4774 4588 4645 4594 4617 4721 4569 4479 4575 4645 4631 4640 4567 4584 4568 4362 4570 4613 4435 4630 4484 4533 4496 4629 4520 4530 4556 4770 4612 4525 4606 4539 4492 4562 4508 4632 4592 4575 4503 4542 4559 4507 4525 4605 4511 4560 4550 4585 4618 4525 4643 4529 4522 4407 4566 4528 4650 4517 4477 4426 4384 4552 4657 4505 4578 4473 4613 4556 4555 4503 4448 4427 4532 4501 4599 4451 4492 4571 4541 4596 4511 4480 4464 4538 4536 4499 4480 4579 4584 4504 4662 4679 4575 4376 4346 4492 4451 4572 4418 4717 4489 4577 4599 4525 4495 4537 4503 4490 4525 4488 4468 4488 4426 4388 4539 4456 4549 4674 4684 4501 4523 4483 4553 4569 4627 4572 4557 4559 4567 4570 4473 4505 4531 4408 4451 4542 4492 4477 4631 4568 4467 4516 4473 4631 4530 4502 4484 4549 4602 4496 4512 4540 4535 4528 4551 4567 4542 4482 4503 4579 4504 4555 4621 4574 4521 4627 4534 4470 4505 4452 4550 4421 4546 4526 4524 4540 4553 4614 4486 4552 4606 4604 4597 4641 4574 4640 4408 4729 4561 4609 4535 4617 4774 4583 4672 4669 4709 4697 4721 4606 4669 4675 4604 4802 4689 4655 4736 4797 4963 4969 4873 5116 5086 5231 5275 5303 5590 5770 5895 6126 6287 6575 6662 6692 6679 6685 6662 6618 6319 6262 6152 5914 6031 6263 5916 6205 6151 6161 6323 6114 6432 6076 6049 5859 5910 5824 5648 5695 5426 5648 5361 5505 5271 5327 5130 5325 5321 5211 5061 5144 5146 4983 5033 5042 5039 4947 4877 4956 4849 5006 4831 4804 4765 4837 4820 4874 4760 4669 4672 4767 4743 4715 4690 4775 4564 4638 4595 4724 4700 4710 4826 4633 4608 4647 4735 4594 4858 4612 4708 4721 4676 4754 4810 4684 4766 4716 4842 4740 4624 4729 4684 4884 4666 4935 4767 4943 4825 4860 4870 4881 5045 5020 5160 5287 5312 5696 5805 5980 6371 6594 6536 6674 6799 6728 6548 6407 6357 6151 6151 6012 5933 6021 6094 6137 6191 6218 6200 6138 5909 5899 5902 5759 5797 5662 5605 5547 5552 5529 5540 5571 5666 5355 5731 5520 5638 5444 5463 5538 5500 5362 5463 5384 5376 5468 5437 5292 5455 5450 5393 5565 5409 5297 5341 5258 5327 5274 5280 5339 5211 5153 5253 5043 5252 5240 5155 5200 5000 5000 5120 5217 5286 5155 5181 5151 5303 5183 5146 5331 5279 5137 5084 5072 5110 4947 5093 4918 5137 4988 5035 5113 5044 5105 5003 5033 4960 4930 4918 4902 4772 4932 4866 4933 4775 4831 4773 4746 4701 4846 4856 4622 4701 4710 4702 4734 4691 4575 4735 4572 4572 4601 4661 4619 4654 4565 4648 4643 4571 4599 4642 4512 4624 4532 4661 4599 4732 4733 4812 4711 4630 4657 4657 4746 4626 4819 4632 4736 4610 4724 4556 4642 4550 4648 4705 4558 4682 4628 4627 4701 4617 4615 4661 4549 4652 4525 4630 4585 4598 4678 4726 4610 4566 4683 4599 4654 4754 4691 4642 4636 4672 4589 4706 4879 4770 4675 4804 4782 4941 4808 4951 4785 4944 5024 5234 5077 5061 5099 4983 5275 5252 5072 4882 5014 5005 5152 5023 4979 4989 5001 4937 5026 4987 5068 4973 5068 5184 5079 5065 5088 5062 4925 5021 4983 4830 4753 4874 4842 4792 4868 4772 4860 4747 4907 4779 4719 4780 4685 4762 4774 4603 4634 4632 4703 4609 4619 4765 4654 4810 4723 4675 4687 4726 4685 4782 4723 4918 4792 4836 4834 4971 5050 5003 4983 4801 4983 4861 4880 4933 4864 4887 4828 4876 4912 4949 4899 4930 4986 5009 5111 4947 5073 4893 4904 4821 4706 4790 4810 4667 4776 4819 4865 4958 4747 4896 4809 4861 4976 4813 4921 4932 5047 4919 4771 4766 4737 4763 4726 4851 4786 4609 4677 4803 4693 4746 4683 4740 4592 4716 4614 4586 4741 4669 4571 4616 4555 4603 4484 4681 4742 4611 4596 4690 4657 4596 4569 4648 4657 4617 4674 4621 4426 4500 4607 4477 4759 4522 4613 4703 4637 4556 4660 4606 4547 4620 4648 4661 4618 4716 4677 4530 4632 4577 4662 4619 4682 4726 4775 4681 4882 5036 5129 5160 5396 5738 6075 6635 6875 7278 7653 7561 6862 6241 5691 5305 5181 5246 5164 5068 5249 5503 5635 5903 6131 6269 5908 5642 5545 5233 5038 4847 4818 4711 4725 4748 4785 4760 4858 4827 4864 4816 4892 5001 4914 5142 5109 5194 5202 5454 5452 5587 5735 5806 5784 5831 5653 5454 5386 5244 5285 5283 5353 5404 5331 5556 5655 5602 5604 5856 5678 5591 5610 5338 5377 5189 5213 5158 5179 5251 5213 5190 5245 5208 5327 5137 5224 5216 5159 5260 5160 5156 5118 5319 5214 5187 5091 5084 5049 5085 5042 4989 5042 5072 4987 4993 4935 4915 4884 4885 4937 4829 4888 4849 4703 4713 4835 4819 4800 4811 4880 4780 4794 4818 4686 4778 4642 4683 4618 4812 4771 4584 4508 4679 4708 4573 4592 4546 4605 4670 4720 4682 4816 4705 4774 4749 4903 4929 4964 5011 4996 5020 4882 4884 4748 4829 4709 4851 4808 4677 4791 4818 4775 4854 4869 4959 5078 4904 4863 4974 4950 4984 5125 5167 5355 5800 6066 6373 7029 7275 7925 7880 7685 7110 6631 6070 5743 5467 5258 5362 5400 5617 5575 5907 6199 6385 6317 6261 6002 5765 5530 5382 5264 5121 5006 4903 5075 5161 4931 5131 5050 5130 5248 5330 5213 5472 5235 5248 5185 5125 4967 5068 4940 5090 4996 5062 5013 4951 4903 5040 5068 5000 4941 4729 4938 4836 4850 4877 4797 4680 4690 4731 4723 4700 4606 4783 4721 4704 4797 4731 4720 4916 4831 4693 4845 4709 4782 4769 4882 4800 4811 4931 4874 4915 4823 4929 4851 4882 4829 4975 4986 5107 4990 5121 5062 4963 5051 5180 5070 5139 5196 5167 5115 5291 5241 5201 5267 5178 5097 4974 4935 5039 4899 4993 4985 4975 4902 5007 4856 4934 4838 4859 4792 4791 4632 4802 4780 4629 4826 4712 4845 4777 4842 4758 4705 4699 4803 4783 4647 4815 4770 4804 4828 4789 4943 5002 4989 5108 5227 5537 5525 5801 5913 5866 6095 6295 6392 6360 6249 6150 5986 5946 5740 5781 5649 5677 5727 5669 5749 5906 5966 5948 5984 5941 5836 5826 5580 5523 5508 5318 5281 5223 5133 5145 4996 5185 5162 5150 5073 5138 5123 5000 4909 4880 4844 4699 4794 4793 4854 4742 4669 4733 4680 4726 4682 4769 4633 4701 4602 4616 4604 4535 4491 4563 4514 4570 4710 4582 4529 4709 4639 4598 4632 4552 4473 4608 4693 4528 4577 4468 4540 4512 4438 4443 4458 4597 4586 4448 4429 4522 4659 4579 4668 4587 4559 4576 4397 4466 4563 4543 4613 4573 4556 4484 4649 4589 4524 4535 4669 4696 4572 4535 4611 4552 4529 4520 4556 4556 4613 4506 4630 4518 4593 4492 4577 4608 4540 4629 4524 4632 4685 4534 4526 4589 4611 4720 4680 4647 4630 4702 4788 4625 4590 4695 4680 4631 4608 4625 4743 4892 4799 4579 4780 4671 4915 4753 4795 4735 4688 4730 4761 4725 4590 4773 4750 4719 4706 4590 4703 4631 4711 4606 4695 4655 4735 4674 4657 4734 4599 4752 4695 4630 4753 4727 4685 4860 4734 4776 4700 4789 4711 4597 4625 4629 4728 4617 4586 4546 4620 4688 4683 4693 4757 4596 4723 4725 4527 4565 4574 4760 4634 4672 4599 4756 4569 4751 4630 4712 4679 4796 4652 4710 4699 4738 4632 4534 4568 4633 4563 4585 4767 4695 4751 4614 4702 4786 4721 4700 4756 4782 4718 4844 4849 4746 4756 4907 4891 4973 4889 4946 5002 5253 5352 5383 5534 5646 5760 5931 6134 6183 6201 5932 5800 5655 5513 5415 5439 5495 5641 5457 5732 5830 5986 6021 6180 6235 5939 5915 5927 5706 5671 5475 5389 5453 5418 5353 5285 5254 5326 5328 5399 5344 5279 5242 5068 5084 4990 4980 4938 4999 4835 4937 4822 4951 4865 4991 4862 5027 4822 4765 4748 4750 4732 4754 4751 4621 4765 4620 4583 4651 4650 4613 4622 4709 4634 4603 4734 4669 4613 4673 4691 4749 4701 4617 4700 4805 4870 4830 4965 5087 5054 5339 5220 5232 4982 5051 4946 4907 4914 4791 4771 4722 4746 4707 4733 4666 4775 4840 4831 4822 4817 4818 4716 4769 4770 4657 4599 4639 4577 4468 4390 4512 4586 4432 4588 4513 4540 4475 4552 4532 4468 4699 4718 4455 4547 4500 4528 4568 4562 4537 4691 4392 4456 4461 4473 4488 4418 4429 4469 4579 4453 4473 4377 4502 4460 4564 4626 4428 4494 4485 4565 4572 4614 4507 4541 4529 4507 4490 4550 4326 4466 4417 4362 4528 4540 4479 4449 4410 4517 4483 4542 4525 4425 4472 4449 4486 4487 4434 4545 4516 4546 4420 4518 4429 4428 4426 4346 4556 4499 4377 4366 4562 4581 4522 4575 4506 4481 4468 4541 4472 4524 4578 4449 4483 4522 4552 4469 4502 4514 4517 4452 4397 4577 4555 4404 4497 4484 4411 4295 4546 4480 4531 4425 4573 4526 4438 4469 4384 4512 4482 4361 4541 4342 4443 4441 4377 4543 4550 4532 4683 4414 4584 4440 4480 4467 4412 4335 4558 4535 4498 4690 4416 4464 4354 4429 4528 4422 4412 4526 4461 4379 4439 4336 4404 4395 4485 4477 4512 4330 4468 4402 4455 4607 4448 4451 4438 4475 4474 4525 4555 4475 4505 4641 4556 4505 4570 4575 4579 4616 4596 4543 4470 4661 4559 4725 4598 4662 4624 4963 4933 5033 5082 5103 5053 5111 5106 5193 4997 5055 4933 4849 4816 4853 4890 4927 4932 4819 4799 4914 4977 4918 5012 4995 4898 4984 5001 4922 4938 4746 4734 4659 4691 4725 4716 4700 4691 4630 4627 4538 4573 4741 4680 4778 4731 4616 4593 4588 4628 4613 4706 4554 4642 4514 4568 4560 4474 4680 4395 4523 4465 4617 4518 4611 4443 4592 4471 4597 4488 4474 4501 4634 4460 4618 4648 4611 4540 4645 4610 4618 4766 4629 4674 4706 4824 4784 4744 4871 5012 4905 4998 4957 4972 4933 4987 4812 4897 4737 4693 4694 4791 4810 4582 4712 4542 4760 4800 4806 4823 4878 4798 4653 4835 4684 4600 4580 4499 4465 4545 4589 4636 4712 4577 4480 4689 4450 4551 4656 4571 4606 4570 4670 4625 4696 4630 4764 4771 4854 5024 5060 5031 5088 5153 5383 5382 5449 5327 5171 5229 5209 5086 5017 4811 4810 4767 4784 4846 4868 4792 4958 4967 4916 4923 4971 4857 4851 4828 4782 4762 4808 4765 4733 4731 4678 4706 4542 4608 4567 4490 4542 4611 4431 4629 4600 4573 4488 4543 4517 4427 4451 4436 4647 4562 4523 4615 4608 4611 4747 4613 4580 4580 4593 4551 4619 4564 4521 4578 4557 4682 4692 4673 4675 4681 4611 4635 4667 4738 4637 4752 4710 4544 4690 4760 4743 4750 4676 4825 4688 4613 4686 4691 4851 4775 4754 4747 4638 4595 4925 4874 4759 4776 4632 4769 4543 4702 4619 4712 4762 4747 4604 4772 4818 4614 4717 4658 4686 4653 4697 4748 4624 4660 4732 4634 4547 4590 4588 4624 4674 4757 4488 4570 4541 4633 4672 4576 4480 4603 4610 4505 4530 4598 4499 4511 4659 4544 4560 4551 4623 4540 4548 4553 4570 4656 4587 4590 4596 4495 4578 4520 4540 4572 4537 4503 4562 4552 4480 4602 4674 4518 4559 4699 4682 4590 4625 4610 4605 4623 4665 4562 4570 4606 4539 4581 4481 4544 4787 4611 4452 4551 4585 4626 4547 4642 4457 4511 4507 4575 4595 4661 4553 4466 4607 4650 4639 4570 4469 4628 4617 4722 4543 4446 4543 4645 4563 4654 4566 4480 4547 4561 4649 4474 4677 4620 4646 4605 4514 4642 4687 4614 4602 4608 4495 4562 4448 4623 4499 4644 4542 4474 4670 4751 4694 4578 4706 4583 4639 4663 4690 4696 4696 4721 4626 4650 4518 4605 4577 4724 4677 4481 4636 4533 4650 4573 4632 4436 4547 4604 4596 4476 4520 4546 4459 4582 4468 4437 4541 4469 4520 4551 4660 4437 4606 4574 4397 4512 4473 4444 4538 4524 4504 4577 4537 4423 4483 4425 4558 4500 4560 4390 4525 4478 4545 4587 4571 4526 4573 4497 4612 4575 4507 4504 4566 4571 4601 4608 4585 4699 4576 4511 4519 4623 4393 4527 4491 4589 4548 4545 4553 4406 4430 4562 4631 4548 4577 4601 4517 4506 4482 4573 4604 4485 4466 4468 4531 4458 4593 4548 4528 4595 4511 4405 4527 4592 4610 4693 4472 4489 4463 4584 4478 4494 4455 4558 4575 4441 4629 4470 4443 4548 4457 4549 4426 4459 4423 4654 4596 4427 4567 4508 4589 4638 4427 4507 4523 4533 4607 4555 4427 4510 4527 4590 4417 4683 4551 4636 4502 4663 4557 4584 4481 4626 4531 4660 4604 4628 4588 4576 4712 4557 4622 4589 4597 4683 4637 4685 4646 4694 4799 4706 4597 4607 4694 4673 4724 4646 4636 4707 4749 4788 4892 4830 4755 4868 4916 5003 5090 5104 5143 5144 5303 5398 5534 5651 5716 5747 5751 5795 5546 5381 5407 5297 5225 5199 5008 5107 5076 5066 5082 5102 5149 5142 5187 5157 5081 5191 5197 5152 5162 5147 5056 4938 4868 4854 4923 4802 4719 4610 4576 4716 4712 4718 4614 4508 4502 4565 4605 4596 4490 4531 4400 4556 4497 4599 4490 4710 4451 4572 4532 4543 4689 4660 4683 4469 4553 4498 4552 4374 4533 4503 4547 4579 4626 4547 4490 4465 4507 4433 4697 4556 4647 4714 4490 4585 4536 4514 4583 4531 4612 4561 4651 4632 4747 4806 4952 4776 4807 4805 4784 4784 4671 4679 4665 4720 4776 4552 4548 4551 4612 4633 4689 4615 4664 4697 4749 4736 4795 4707 4803 4656 4584 4721 4599 4643 4457 4665 4502 4621 4671 4690 4622 4526 4645 4526 4513 4713 4659 4614 4650 4626 4535 4643 4677 4732 4527 4584 4539 4610 4610 4465 4573 4483 4593 4538 4607 4601 4653 4674 4513 4705 4574 4675 4503 4600 4489 4502 4699 4598 4547 4568 4722 4546 4439 4625 4542 4430 4582 4541 4568 4556 4457 4445 4509 4598 4644 4499 4630 4523 4630 4618 4751 4613 4578 4677 4763 4702 4858 4942 5007 4975 4836 4839 4761 4728 4667 4646 4565 4601 4751 4731 4668 4606 4793 4673 4709 4708 4686 4563 4702 4710 4752 4704 4736 4601 4655 4575 4625 4652 4763 4567 4639 4551 4504 4551 4519 4562 4653 4513 4522 4630 4512 4541 4525 4559 4491 4607 4483 4526 4536 4518 4394 4511 4392 4542 4481 4547 4452 4585 4566 4554 4540 4530 4501 4567 4535 4453 4601 4531 4585 4526 4538 4429 4458 4462 4592 4523 4482 4552 4534 4492 4429 4594 4432 4649 4528 4508 4562 4590 4603 4432 4630 4719 4551 4505 4531 4585 4522 4597 4553 4533 4454 4551 4595 4480 4634 4700 4560 4552 4505 4533 4637 4545 4563 4563 4606 4523 4579 4693 4636 4694 4787 4537 4674 4746 4724 4690 4745 4737 4677 4744 4539 4572 4470 4619 4632 4695 4562 4507 4642 4649 4693 4888 4719 4877 4887 4847 4797 4889 4874 4682 4755 4680 4744 4697 4639 4637 4704 4701 4644 4685 4545 4815 4671 4668 4561 4738 4662 4566 4585 4670 4671 4714 4673 4579 4614 4458 4542 4534 4542 4559 4540 4601 4645 4661 4490 4562 4593 4639 4496 4617 4553 4704 4553 4584 4591 4652 4702 4593 4582 4559 4662 4651 4674 4665 4690 4660 4687 4704 4552 4527 4596 4521 4453 4565 4415 4444 4603 4638 4444 4478 4665 4651 4614 4549 4466 4432 4573 4540 4417 4454 4570 4486 4487 4433 4536 4555 4635 4534 4606 4459 4544 4457 4459 4498 4577 4427 4453 4474 4601 4429 4447 4592 4466 4456 4585 4546 4583 4462 4472 4434 4390 4581 4530 4555 4487 4535 4422 4473 4541 4419 4525 4467 4602 4502 4479 4458 4468 4478 4434 4491 4589 4629 4414 4525 4552 4482 4572 4396 4474 4534 4398 4623 4488 4571 4479 4519 4589 4484 4506 4479 4459 4482 4537 4388 4489 4401 4521 4491 4617 4419 4478 4447 4442 4487 4385 4557 4497 4539 4385 4592 4503 4516 4582 4481 4424 4584 4489 4542 4555 4617 4536 4506 4568 4564 4610 4610 4540 4586 4553 4649 4585 4562 4496 4473 4552 4537 4463 4515 4461 4557 4625 4404 4541 4561 4444 4555 4532 4569 4451 4566 4424 4550 4555 4502 4599 4679 4682 4545 4537 4554 4543 4683 4567 4577 4520 4578 4505 4625 4564 4572 4535 4623 4418 4580 4603 4557 4590 4564 4539 4526 4745 4567 4675 4526 4714 4717 4791 4708 4783 4865 4756 4728 4774 4789 4639 4747 4638 4691 4723 4668 4743 4708 4674 4807 4670 4691 4511 4676 4813 4581 4675 4652 4694 4738 4689 4686 4612 4683 4538 4696 4579 4660 4736 4700 4581 4648 4734 4570 4602 4674 4606 4625 4635 4751 4675 4576 4685 4699 4583 4850 4838 4826 4846 4775 4875 4988 4869 4971 5029 5061 5060 5085 5286 5271 5538 5822 6050 6740 7085 7929 8352 8575 8081 7446 6644 6130 5841 5637 5352 5203 5025 5056 4970 5005 5132 5160 5083 5358 5398 5525 5738 6202 6393 6674 6555 6478 6153 5775 5586 5512 5339 5259 5192 5371 5208 5216 5296 5211 5171 5095 5125 5082 5010 4873 4970 4931 4888 4826 4739 4868 4924 4850 4813 4732 4848 4864 4846 4895 4869 4952 4801 4875 4896 4757 4867 4708 4835 4900 4850 4937 4848 4911 4828 4862 4860 4897 4881 4864 4869 4933 4923 4855 5053 4901 4863 4834 4913 4822 4700 4788 4691 4712 4754 4695 4641 4805 4766 4676 4695 4765 4764 4832 4833 4585 4731 4683 4662 4675 4664 4649 4630 4720 4738 4710 4594 4698 4601 4693 4542 4563 4718 4719 4610 4660 4585 4701 4658 4697 4710 4657 4628 4645 4765 4626 4922 4669 4851 4675 4713 4794 4749 4705 4743 4745 4778 4812 4903 4809 5012 4904 4908 4851 5126 5055 5163 4942 5074 4978 5033 4824 4933 4880 4629 4926 4715 4758 4781 4801 4803 4789 4687 4795 4955 4738 4867 4769 4818 4805 4845 4741 4874 4749 4762 4822 4691 4668 4606 4642 4585 4683 4626 4651 4630 4654 4550 4482 4774 4640 4585 4572 4716 4589 4564 4577 4632 4509 4605 4614 4513 4582 4477 4573 4642 4469 4536 4425 4540 4568 4641 4501 4621 4526 4690 4696 4773 4604 4701 4547 4724 4744 4727 4625 4611 4623 4790 4694 4632 4573 4617 4640 4690 4640 4551 4724 4592 4464 4575 4531 4629 4535 4680 4632 4576 4675 4667 4653 4643 4590 4627 4606 4706 4418 4543 4534 4570 4548 4483 4631 4505 4468 4476 4582 4513 4550 4551 4360 4514 4569 4500 4617 4560 4483 4523 4441 4597 4537 4500 4524 4404 4635 4514 4500 4631 4603 4458 4537 4469 4487 4600 4506 4565 4466 4568 4607 4587 4543 4549 4466 4473 4520 4360 4596 4655 4464 4584 4553 4571 4684 4676 4685 4766 4799 4933 4992 4885 4913 4880 4800 4764 4999 4765 4671 4620 4563 4584 4606 4566 4577 4676 4613 4640 4570 4700 4681 4767 4597 4777 4734 4848 4791 4730 4749 4677 4863 4635 4609 4775 4541 4687 4611 4628 4569 4660 4575 4562 4668 4589 4524 4681 4477 4594 4560 4561 4472 4463 4561 4498 4627 4523 4528 4556 4613 4599 4516 4538 4578 4460 4522 4598 4515 4534 4624 4542 4539 4712 4488 4603 4450 4515 4653 4533 4493 4503 4482 4563 4553 4544 4609 4444 4457 4492 4483 4577 4518 4548 4484 4615 4458 4498 4482 4498 4509 4534 4457 4544 4463 4517 4547 4454 4630 4541 4508 4603 4602 4572 4628 4640 4596 4479 4518 4501 4692 4691 4587 4610 4556 4616 4518 4448 4518 4713 4537 4596 4565 4631 4562 4603 4530 4630 4581 4646 4668 4618 4630 4650 4573 4599 4585 4575 4544 4594 4670 4567 4577 4607 4637 4676 4718 4628 4524 4612 4520 4672 4555 4580 4444 4630 4508 4510 4602 4581 4534 4665 4570 4688 4661 4695 4561 4594 4567 4532 4587 4499 4465 4475 4668 4570 4531 4585 4540 4623 4491 4747 4652 4570 4637 4679 4466 4626 4556 4567 4652 4648 4531 4521 4528 4651 4617 4571 4531 4582 4542 4606 4524 4590 4565 4643 4590 4645 4654 4615 4699 4755 4812 4606 4784 4656 4702 4552 4778 4690 4693 4670 4720 4546 4574 4630 4658 4794 4577 4548 4695 4592 4726 4546 4540 4654 4815 4628 4793 4694 4659 4725 4647 4708 4763 4694 4713 4614 4741 4605 4721 4676 4760 4762 4728 4681 4794 4518 4805 4609 4611 4544 4633 4605 4526 4571 4619 4685 4710 4530 4609 4602 4629 4581 4655 4549 4571 4651 4425 4687 4618 4579 4561 4582 4591 4590 4598 4656 4624 4609 4530 4573 4603 4476 4497 4499 4522 4504 4489 4635 4584 4445 4509 4660 4570 4644 4603 4534 4401 4674 4712 4574 4534 4610 4587 4673 4620 4560 4501 4662 4677 4677 4441 4666 4541 4563 4640 4449 4656 4604 4590 4568 4556 4556 4619 4599 4654 4690 4615 4663 4562 4571 4619 4638 4733 4554 4612 4573 4579 4638 4578 4546 4647 4659 4629 4599 4544 4588 4675 4607 4706 4727 4758 4709 4753 4643 4651 4720 4723 4662 4636 4584 4690 4637 4516 4675 4710 4668 4621 4558 4464 4687 4756 4657 4725 4555 4638 4563 4491 4572 4654 4591 4591 4486 4756 4569 4540 4527 4553 4518 4613 4555 4452 4530 4580 4564 4538 4529 4486 4568 4575 4529 4466 4409 4531 4571 4521 4540 4536 4650 4601 4602 4541 4558 4503 4579 4522 4520 4596 4499 4465 4487 4540 4656 4514 4544 4602 4519 4616 4541 4625 4580 4578 4526 4567 4567 4565 4559 4563 4539 4572 4541 4495 4425 4470 4530 4578 4514 4579 4466 4549 4514 4553 4496 4366 4588 4444 4433 4591 4443 4477 4487 4474 4458 4575 4464 4370 4470 4580 4539 4486 4526 4430 4482 4499 4466 4596 4519 4623 4539 4525 4453 4542 4571 4567 4498 4496 4472 4462 4455 4573 4525 4623 4573 4571 4714 4423 4515 4584 4534 4566 4547 4468 4535 4563 4517 4525 4414 4510 4451 4443 4521 4728 4453 4545 4538 4485 4632 4651 4572 4561 4573 4467 4462 4437 4581 4485 4403 4469 4516 4423 4394 4583 4520 4497 4539 4502 4553 4488 4457 4607 4601 4489 4285 4527 4422 4493 4423 4402 4441 4387 4604 4515 4490 4474 4672 4504 4543 4518 4555 4527 4530 4509 4548 4553 4569 4343 4451 4551 4459 4417 4472 4426 4268 4359 4518 4490 4576 4453 4498 4506 4559 4564 4624 4416 4525 4454 4532 4522 4532 4564 4523 4468 4396 4415 4445 4477 4481 4513 4549 4482 4339 4595 4490 4655 4520 4517 4473 4464 4491 4409 4488 4525 4506 4572 4552 4535 4447 4478 4610 4564 4534 4610 4474 4482 4526 4355 4480 4592 4485 4535 4480 4526 4539 4549 4488 4535 4667 4489 4574 4539 4619 4568 4667 4707 4725 4754 4619 4741 4774 4674 4653 4623 4565 4750 4503 4515 4352 4598 4626 4494 4547 4571 4529 4667 4617 4607 4537 4665 4721 4641 4652 4582 4598 4679 4582 4706 4610 4556 4593 4632 4726 4580 4674 4654 4623 4613 4612 4650 4562 4445 4533 4542 4634 4599 4520 4671 4545 4616 4469 4545 4577 4799 4591 4656 4549 4582 4439 4465 4577 4677 4540 4591 4690 4492 4680 4611 4607 4653 4632 4595 4618 4606 4480 4556 4637 4565 4548 4682 4543 4520 4673 4571 4606 4680 4672 4713 4538 4591 4608 4481 4617 4558 4526 4632 4521 4658 4637 4812 4649 4753 4728 4836 4751 4842 4757 4809 4804 4778 4781 4752 4737 4666 4611 4615 4555 4651 4598 4471 4710 4576 4702 4664 4540 4631 4619 4502 4552 4510 4760 4706 4629 4660 4770 4728 4566 4650 4624 4678 4724 4613 4704 4661 4581 4701 4608 4649 4594 4663 4746 4695 4744 4754 4803 4709 4731 4658 4668 4618 4798 4513 4710 4666 4737 4724 4714 4673 4759 4862 4795 4665 4812 4869 4901 5024 4996 4898 4943 4948 5043 5026 4767 4836 4844 5036 4809 4995 4765 4836 4917 4942 4997 4918 5023 4803 4831 4880 4996 5044 4990 4873 4966 4926 4832 4890 4934 4975 4858 4863 4904 4912 4832 4960 4732 4795 4920 4648 4851 4680 4634 4786 4739 4747 4852 4601 4762 4697 4784 4804 4780 4799 4686 4716 4699 4614 4693 4633 4612 4757 4757 4798 4557 4632 4581 4611 4658 4594 4572 4523 4657 4580 4663 4490 4606 4601 4627 4535 4557 4649 4660 4648 4676 4613 4628 4644 4508 4611 4602 4632 4691 4766 4635 4760 4591 4702 4527 4791 4698 4758 4769 4888 4881 4910 4761 4960 4834 4880 4910 4817 4805 4789 4903 4751 4786 4718 4814 4753 4591 4647 4691 4733 4692 4666 4694 4679 4772 4861 4771 4782 4834 4810 4820 4889 4861 4870 4700 4805 4745 4781 4846 4872 4842 4811 4756 4747 4775 4787 4692 4842 4778 4683 4792 4763 4612 4684 4601 4709 4748 4698 4751 4642 4763 4611 4668 4751 4635 4835 4614 4802 4664 4661 4783 4724 4757 4714 4591 4642 4762 4705 4778 4634 4659 4743 4690 4819 4728 4695 4741 4667 4654 4632 4721 4669 4681 4692 4677 4626 4533 4514 4633 4588 4575 4517 4620 4678 4525 4719 4774 4606 4545 4615 4545 4628 4664 4592 4436 4670 4667 4581 4637 4582 4545 4765 4606 4707 4581 4500 4570 4592 4582 4629 4539 4578 4599 4537 4648 4677 4680 4610 4641 4523 4546 4545 4761 4628 4582 4601 4672 4612 4728 4480 4603 4517 4627 4510 4588 4494 4588 4574 4707 4502 4606 4661 4602 4607 4668 4732 4682 4587 4635 4710 4810 4590 4681 4674 4561 4697 4619 4570 4564 4647 4606 4620 4707 4697 4696 4754 4469 4660 4544 4680 4546 4643 4638 4719 4608 4605 4770 4614 4757 4714 4709 4632 4714 4592 4726 4782 4788 4718 4700 4700 4796 4804 4629 4722 4731 4678 4661 4814 4606 4776 4794 4586 4598 4682 4577 4702 4616 4635 4719 4588 4664 4687 4791 4738 4681 4673 4497 4667 4688 4810 4745 4682 4743 4799 4776 4820 4590 4750 4683 4724 4720 4685 4805 4830 4711 4704 4655 4606 4722 4831 4654 4695 4701 4876 4838 4841 4881 4802 4815 4846 5000 4984 5118 5297 5457 5558 5752 6095 6047 6119 5992 5907 5650 5613 5471 5254 5183 5038 4946 4940 5012 4843 4886 4880 4908 4830 4841 5057 4857 4952 5010 4994 5081 5032 4937 5148 5323 5366 5302 5456 5505 5477 5271 5264 5247 4989 5028 4865 4981 4928 4877 4888 4805 4709 4673 4832 4916 4672 4709 4780 4713 4905 4708 4788 4851 4788 4775 4758 4732 4720 4766 4700 4648 4712 4628 4581 4732 4638 4605 4711 4625 4602 4661 4557 4647 4771 4706 4542 4629 4666</counts>
			</dataPoints>
		</scan>
	</xrdMeasurement>
</xrdMeasurements>