File: dataset/precursor_mixture/TiO2_V2O5_Nb2O5.12-min.xrdml
<?xml version="1.0"?>
<xrdMeasurements xmlns="http://www.xrdml.com/XRDMeasurement/2.2" xmlns:xsi="http://www.w3.org/2001/XMLSchema-instance" xsi:schemaLocation="http://www.xrdml.com/XRDMeasurement/2.2 http://www.xrdml.com/XRDMeasurement/2.2/XRDMeasurement.xsd" status="Completed" recordIdentifier="{AFDA371B-440C-4D64-B1F6-9E2A3298B087}">
	<comment>
		<entry/>
	</comment>
	<sample type="To be analyzed">
		<id></id>
		<name></name>
		<preparedBy></preparedBy>
	</sample>
	<xrdMeasurement measurementType="Scan" status="Completed" sampleMode="Reflection">
		<usedWavelength intended="K-Alpha 1">
			<kAlpha1 unit="Angstrom">1.5405980</kAlpha1>
			<kAlpha2 unit="Angstrom">1.5444260</kAlpha2>
			<kBeta unit="Angstrom">1.3922500</kBeta>
			<ratioKAlpha2KAlpha1>0.5000</ratioKAlpha2KAlpha1>
		</usedWavelength>
		<incidentBeamPath>
			<radius unit="mm">145.00</radius>
			<xRayTube id="1010048" name="Empyrean Cu LFF HR (9430 033 7310x) DK437873">
				<tension unit="kV">40.0</tension>
				<current unit="mA">15.0</current>
				<anodeMaterial>Cu</anodeMaterial>
				<focus type="Line">
					<length unit="mm">12.0</length>
					<width unit="mm">0.4</width>
					<takeOffAngle unit="deg">6.0</takeOffAngle>
				</focus>
			</xRayTube>
			<filter id="20010004" name="Beta-filter Nickel">
				<material>Ni</material>
				<thickness unit="mm">0.020</thickness>
			</filter>
			<sollerSlit id="21010002" name="Soller slits 0.04 rad.">
				<opening unit="rad">0.0400</opening>
			</sollerSlit>
			<mask id="22031000" name="Fixed mask 13 mm">
				<width unit="mm">9.00</width>
			</mask>
			<divergenceSlit id="22120001" name="Divergence slit 1°" xsi:type="fixedDivergenceSlitType">
				<distanceToSample unit="mm">50.00</distanceToSample>
				<height unit="mm">1.52</height>
			</divergenceSlit>
		</incidentBeamPath>
		<beamKnife id="29030100" name="Beam knife low"/>
		<sampleMovement xsi:type="spinningSampleMovementType">
			<spinnerRevolutionTime unit="seconds">1.0</spinnerRevolutionTime>
		</sampleMovement>
		<diffractedBeamPath>
			<radius unit="mm">145.00</radius>
			<antiScatterSlit id="22090040" name="AS slit 9 mm" xsi:type="fixedAntiScatterSlitType">
				<height unit="mm">9.00</height>
			</antiScatterSlit>
			<sollerSlit id="21020003" name="Large Soller slits 0.04 rad.">
				<opening unit="rad">0.0400</opening>
			</sollerSlit>
			<filter id="20030001" name="Large beta-filter Nickel">
				<material>Ni</material>
				<thickness unit="mm">0.020</thickness>
			</filter>
			<detector id="7010019" name="PIXcel1D-Medipix3 detector" xsi:type="rtmsDetectorType">
				<phd unit="keV">
					<lowerLevel>4.0</lowerLevel>
					<upperLevel>11.3</upperLevel>
				</phd>
				<mode>Scanning</mode>
				<activeLength unit="deg">5.020</activeLength>
			</detector>
		</diffractedBeamPath>
		<scan appendNumber="0" mode="Continuous" scanAxis="Gonio" status="Completed">
			<header>
				<startTimeStamp>2024-03-22T21:43:03-07:00</startTimeStamp>
				<endTimeStamp>2024-03-22T21:55:31-07:00</endTimeStamp>
				<author>
					<name>Instrument</name>
				</author>
				<source>
					<applicationSoftware version="1.6 (94)">PANalytical Aeris Instrument Suite</applicationSoftware>
					<instrumentControlSoftware version="3.0.0 20211014">AERIS</instrumentControlSoftware>
					<instrumentID>2879380</instrumentID>
				</source>
			</header>
			<dataPoints>
				<positions axis="2Theta" unit="deg">
					<startPosition>9.99043322</startPosition>
					<endPosition>100.09495370</endPosition>
				</positions>
				<positions axis="Omega" unit="deg">
					<startPosition>4.99521661</startPosition>
					<endPosition>50.04747685</endPosition>
				</positions>
				<commonCountingTime unit="seconds">18.249</commonCountingTime>
				<counts unit="counts">4109 4202 4080 4168 4190 4105 4182 4215 4205 4113 4308 4016 4295 4244 4190 4105 4196 4079 4138 4142 4107 4082 4032 4162 4124 4127 4152 4162 3990 4081 4090 4136 4169 3930 4186 4025 4107 3990 4051 3938 4023 4025 3947 4177 3948 3918 4051 4092 4075 3920 4013 3973 4036 4063 3965 3982 3918 4056 3977 3989 4057 3945 3915 4050 4041 3981 3809 3867 3971 3966 3713 3833 3879 3874 3963 3945 3855 3758 3966 3728 3883 3967 3779 3905 3793 3811 3795 3878 3743 3845 3923 3786 3820 3831 3911 3783 3849 3833 3714 3794 3870 3804 3718 3745 3838 3838 3791 3816 3757 3628 3660 3701 3709 3660 3702 3706 3687 3794 3661 3725 3741 3658 3721 3679 3586 3811 3613 3522 3754 3703 3703 3561 3692 3711 3578 3621 3670 3639 3559 3538 3674 3517 3539 3647 3698 3500 3616 3584 3675 3626 3514 3529 3490 3625 3581 3444 3478 3574 3508 3463 3616 3552 3432 3526 3471 3460 3534 3557 3502 3524 3502 3455 3446 3471 3388 3385 3463 3500 3558 3440 3318 3464 3430 3415 3529 3525 3382 3386 3424 3401 3440 3301 3419 3380 3502 3412 3485 3385 3349 3266 3429 3431 3280 3334 3366 3422 3453 3403 3424 3447 3398 3378 3384 3233 3300 3334 3294 3337 3237 3368 3357 3310 3316 3383 3248 3409 3302 3330 3278 3291 3239 3268 3228 3225 3421 3301 3402 3231 3331 3244 3232 3173 3196 3178 3304 3211 3317 3189 3143 3280 3107 3184 3199 3174 3273 3118 3154 3146 3238 3100 3123 3126 3046 3233 3231 3198 3259 3203 3189 3135 3123 3203 3228 3269 3100 3170 3183 3121 3115 3167 3182 3169 3272 3151 3065 2972 3041 3083 3051 3153 3067 3180 3063 3048 3027 3200 2973 3103 3107 3060 3042 3061 3118 3069 3214 3081 3122 2935 3110 3024 3038 3018 3019 2895 2923 3014 2978 3025 3015 2951 2917 2967 3084 3103 3051 3069 2950 3025 3012 2960 2981 3008 2925 2948 3008 2975 2940 2959 2929 3009 2901 2969 2997 2898 2991 2904 2935 2918 2840 3048 2936 2893 3019 2896 2911 2954 2972 2870 2887 2964 2901 2869 2871 2894 2908 3006 3035 2941 2929 2851 2957 2921 2911 2960 2981 2940 2808 2853 2880 2772 2941 2989 2874 2895 2959 2922 2885 2934 2857 2919 2880 2946 2817 2881 2805 2911 2922 2879 2825 2799 2767 2873 2836 2867 2810 2818 2908 2753 2814 2925 2884 2832 2878 2783 2690 2897 2897 2909 2907 2752 2810 2792 2700 2819 2788 2877 2841 2792 2753 2819 2707 2809 2724 2703 2825 2714 2821 2679 2905 2841 2820 2886 2816 2824 2774 2847 2759 2805 2811 2831 2792 2847 2793 2735 2909 2822 2860 2808 2811 2820 2715 2852 2860 2877 2853 2909 2879 2694 2877 2825 2744 2915 2917 2976 2969 2915 2870 2948 2975 3036 2937 3065 3060 3185 3327 3212 3396 3356 3510 3505 3673 3712 3666 3881 3917 3995 3947 4200 4116 4183 4004 4010 3832 3695 3549 3401 3173 3087 2987 2994 2902 2752 2775 2881 2781 2842 2808 2782 2785 2725 2856 2771 2759 2813 2751 2685 2793 2833 2675 2726 2786 2634 2711 2675 2733 2723 2686 2639 2686 2715 2664 2727 2700 2759 2790 2717 2651 2717 2653 2718 2693 2628 2711 2587 2657 2698 2631 2688 2615 2703 2522 2694 2697 2718 2631 2760 2719 2621 2603 2701 2781 2666 2611 2759 2606 2762 2651 2698 2597 2669 2568 2585 2591 2614 2737 2661 2660 2714 2746 2579 2662 2584 2641 2616 2634 2620 2586 2626 2708 2688 2557 2540 2597 2645 2664 2640 2681 2626 2659 2665 2545 2589 2523 2686 2570 2615 2612 2598 2629 2538 2519 2741 2602 2650 2621 2681 2673 2679 2580 2724 2612 2807 2647 2658 2646 2711 2866 2764 2680 2693 2791 2770 2755 2881 2945 2951 3009 2938 2788 3073 3004 3045 3093 3137 3082 2964 2831 2777 2921 2815 2691 2852 2708 2626 2708 2531 2648 2547 2592 2590 2578 2584 2472 2591 2525 2619 2513 2608 2535 2427 2447 2624 2510 2498 2492 2500 2544 2430 2637 2550 2632 2537 2552 2564 2484 2676 2488 2515 2495 2443 2452 2445 2442 2526 2524 2414 2432 2417 2499 2536 2458 2461 2429 2456 2565 2384 2463 2497 2499 2490 2439 2433 2527 2516 2527 2439 2491 2528 2544 2534 2411 2560 2442 2502 2567 2359 2499 2497 2448 2456 2540 2617 2464 2494 2497 2510 2591 2512 2554 2486 2483 2474 2469 2483 2468 2409 2508 2562 2454 2475 2500 2426 2536 2470 2504 2593 2482 2404 2521 2473 2587 2517 2521 2580 2434 2583 2447 2460 2447 2499 2630 2577 2518 2473 2454 2509 2417 2403 2476 2362 2349 2446 2390 2412 2461 2428 2482 2423 2362 2379 2346 2325 2461 2494 2527 2385 2358 2394 2340 2498 2366 2415 2349 2369 2360 2424 2380 2393 2470 2406 2381 2440 2444 2361 2437 2418 2310 2408 2387 2465 2333 2447 2443 2318 2271 2308 2376 2333 2363 2449 2369 2480 2355 2373 2365 2431 2494 2412 2372 2294 2363 2374 2387 2384 2418 2356 2343 2322 2376 2319 2422 2352 2387 2347 2365 2338 2368 2316 2260 2436 2230 2420 2362 2318 2363 2366 2338 2375 2379 2487 2364 2386 2469 2342 2442 2316 2462 2426 2427 2412 2524 2438 2399 2473 2396 2462 2472 2364 2485 2446 2486 2460 2503 2511 2461 2490 2446 2578 2516 2556 2619 2573 2595 2615 2644 2648 2757 2698 2766 2829 2727 2990 2831 2936 3060 3107 3203 3467 3420 3484 3662 3781 4072 4232 4432 4764 5091 5508 5601 5924 6553 6838 7414 7591 8319 8780 9311 9850 10165 10527 10525 10730 10242 9799 9214 8494 7861 6891 6245 5623 5043 4602 4128 3753 3577 3383 3152 3035 2916 2855 2852 2645 2666 2662 2542 2656 2562 2602 2600 2494 2438 2519 2495 2564 2439 2399 2454 2470 2447 2518 2496 2465 2369 2396 2426 2351 2389 2335 2277 2211 2265 2346 2275 2338 2257 2277 2230 2425 2353 2259 2421 2335 2333 2305 2295 2274 2306 2250 2258 2223 2328 2296 2272 2317 2271 2242 2258 2189 2218 2235 2260 2331 2383 2221 2302 2347 2279 2256 2212 2285 2243 2329 2307 2276 2283 2372 2357 2388 2398 2415 2325 2275 2413 2445 2313 2332 2513 2429 2495 2546 2490 2563 2542 2724 2754 2834 2784 2817 2944 3049 3114 3181 3303 3392 3575 3689 3808 3876 3941 4035 4186 4239 4171 4219 4195 3960 3961 3824 3684 3452 3232 3035 2890 2898 2634 2706 2558 2623 2488 2441 2481 2498 2431 2305 2392 2454 2367 2432 2429 2333 2402 2350 2345 2303 2365 2427 2318 2398 2336 2421 2410 2458 2516 2480 2402 2518 2528 2553 2603 2618 2567 2734 2615 2673 2845 2738 2864 2958 2991 3156 3306 3359 3587 3777 4017 4303 4682 5184 5350 5864 6531 7020 7743 8556 9225 10280 11276 12334 13347 14626 15325 16299 16834 16823 16614 15879 14785 13255 12041 10614 9123 7889 6877 5817 4960 4361 3945 3594 3217 3215 2937 2861 2777 2929 2648 2595 2502 2586 2502 2625 2454 2468 2543 2439 2370 2410 2367 2356 2401 2411 2421 2290 2322 2382 2333 2240 2317 2252 2214 2194 2291 2231 2225 2245 2237 2193 2195 2091 2195 2135 2222 2203 2192 2261 2173 2164 2164 2191 2102 2133 2078 2139 2109 2251 2259 2061 2176 2110 2185 2058 2166 2217 2144 2172 2120 2080 2243 2073 2118 2161 2103 2138 2204 2105 2090 2295 2212 2190 2175 2111 2161 2184 2168 2128 2090 2040 2158 2010 2086 2084 2148 2105 2068 2069 2202 2101 2100 2108 2108 2139 2101 2141 2056 2042 2029 2102 2132 2109 2014 2081 2060 2107 2137 2029 2114 2116 2113 2176 2169 2047 2122 2004 2215 2113 2072 2153 2033 2084 2066 2155 2103 2053 2044 2104 2012 2138 2030 2049 2084 2110 2128 2117 2199 2102 2082 2134 2097 2096 2131 2116 2131 2216 2082 2150 2151 2287 2168 2223 2079 2165 2131 2222 2168 2207 2220 2242 2171 2210 2176 2235 2223 2237 2203 2174 2245 2137 2280 2286 2285 2282 2232 2275 2261 2234 2325 2262 2366 2437 2354 2378 2314 2459 2543 2457 2613 2542 2560 2644 2488 2584 2655 2713 2707 2866 2929 3027 3052 3123 3237 3481 3694 4043 4128 4484 4608 5131 5715 6299 6854 7709 8588 9190 10456 11556 12859 14284 15491 17423 18802 19903 21119 21882 21977 21615 20553 18783 17270 15365 13579 12054 10318 8933 7663 6188 5538 4845 4484 4098 3801 3732 3474 3457 3426 3318 3310 3383 3386 3253 3182 3126 2943 2960 2867 2898 2749 2597 2691 2568 2473 2468 2514 2457 2335 2349 2359 2292 2382 2315 2229 2213 2291 2258 2294 2342 2283 2366 2388 2204 2443 2356 2363 2390 2537 2534 2705 2668 2797 2803 3140 3209 3425 3547 3799 4133 4225 4519 4741 5009 5133 5369 5167 5082 4866 4641 4415 4067 3784 3647 3424 3035 2852 2550 2614 2471 2362 2288 2177 2187 2211 2173 2176 2102 2101 2046 2126 2080 2101 2088 2081 2065 2121 2115 2048 1996 2111 2094 2125 2068 2048 2024 1979 2036 2078 1959 2022 1972 1959 2069 1984 2027 1924 2013 2002 1989 1926 1990 1913 1954 2083 2047 2066 2026 1924 1935 1953 2020 1955 1978 1946 2023 1993 1881 1954 1987 1970 2009 1952 1971 1944 2049 2049 2014 1975 1948 1974 1968 2027 1978 2102 1972 2056 1904 1987 2021 2001 1972 1951 1898 1951 1952 1945 2030 1997 2075 2016 1955 2066 1815 2198 1955 2033 2154 2106 2142 2216 2146 2211 2198 2185 2125 2074 2093 2164 2144 2101 2076 2077 2043 2141 2125 2054 2042 1989 2070 2059 2069 2019 2036 2190 2033 2121 2102 2071 2068 2113 2159 2152 2203 2246 2123 2128 2169 2194 2273 2261 2236 2242 2260 2369 2282 2284 2385 2416 2383 2351 2397 2414 2412 2565 2483 2588 2616 2523 2588 2666 2775 2804 2932 3083 3204 3412 3725 3852 4144 4340 4834 5191 5747 6318 7122 7843 8646 9746 10776 11862 13185 13989 15459 16217 16959 16851 16542 15925 14990 13956 12674 11704 10826 9609 8566 7445 6278 5604 4996 4314 3908 3569 3339 3214 3073 2906 2814 2761 2703 2650 2656 2615 2631 2588 2636 2528 2524 2473 2526 2560 2778 2717 2829 2828 3062 3195 3320 3438 3645 4007 4239 4515 4750 5007 5689 5848 6450 6799 6982 7410 7561 7650 7818 7456 7234 6830 6193 5754 5253 4938 4624 4203 3725 3452 3173 2954 2716 2623 2502 2621 2508 2551 2522 2537 2509 2482 2439 2376 2360 2251 2301 2219 2273 2237 2188 2185 2115 2035 1985 2057 1994 1977 1928 1921 1884 1848 1918 1904 1894 1904 1949 1879 1781 1880 1839 1884 1876 1767 1873 1948 1900 1888 1939 1741 1865 1808 1774 1741 1843 1940 1742 1916 1848 1811 1845 1773 1869 1845 1784 1794 1854 1855 1892 1854 1884 1882 1888 1771 1875 1922 1829 1839 1812 1820 1759 1898 1825 1823 1754 1780 1834 1791 1882 1726 1767 1823 1795 1826 1801 1795 1761 1842 1795 1851 1776 1799 1732 1837 1803 1898 1872 1764 1816 1784 1826 1944 1894 1939 1787 1862 1816 1813 1802 1850 1972 1874 1870 1824 1852 1808 1869 1800 1881 1773 1806 1788 1906 1887 1839 1804 1867 1838 1828 1877 1744 1826 1841 1790 1843 1851 1869 1840 1809 1860 1884 1929 2039 1990 2049 2071 1995 2107 2004 2158 2157 2279 2391 2490 2480 2650 2863 3041 3086 3170 3491 3547 3887 3958 4201 4403 4588 4504 4721 4690 4720 4610 4471 4344 3972 3796 3439 3359 3101 2943 2773 2688 2517 2335 2154 2139 2048 1931 2012 1924 1855 1890 1880 1827 1913 1752 1860 1803 1869 1788 1815 1782 1802 1850 1691 1896 1769 1775 1739 1729 1669 1772 1685 1698 1806 1719 1755 1703 1733 1721 1732 1755 1697 1711 1814 1760 1703 1674 1698 1638 1723 1675 1682 1785 1725 1669 1693 1595 1650 1681 1683 1646 1755 1665 1636 1729 1710 1750 1636 1690 1698 1682 1638 1721 1736 1723 1655 1638 1687 1705 1785 1708 1669 1701 1676 1704 1683 1742 1701 1771 1716 1772 1780 1833 1832 1762 1814 1840 1934 1901 1965 1994 1994 2176 2110 2236 2271 2406 2610 2664 2777 2911 2962 2998 2939 3049 2800 2783 2724 2443 2470 2475 2349 2237 2142 2022 2031 1977 1880 1787 1860 1791 1828 1840 1841 1806 1765 1787 1850 1775 1843 1875 1815 1868 1958 1916 1998 2020 1958 1978 1993 2007 2036 1994 1942 1916 1997 1865 1890 1801 1773 1691 1819 1768 1730 1706 1621 1666 1710 1632 1665 1632 1619 1671 1611 1664 1561 1723 1635 1643 1670 1694 1641 1639 1593 1725 1649 1720 1641 1728 1779 1813 1791 1773 1904 1833 1860 2003 1985 1970 2054 1949 2066 2028 1981 1909 1893 1884 1806 1756 1787 1744 1736 1738 1656 1726 1756 1679 1649 1599 1570 1681 1602 1626 1568 1623 1639 1605 1541 1553 1556 1554 1547 1577 1570 1592 1579 1525 1587 1456 1568 1593 1509 1567 1611 1584 1529 1558 1575 1500 1540 1578 1625 1535 1610 1603 1572 1549 1584 1677 1565 1584 1607 1528 1493 1673 1571 1587 1644 1566 1618 1700 1672 1661 1676 1607 1714 1726 1732 1812 1920 1986 1990 2133 2168 2306 2422 2594 2611 2674 2896 2881 2756 2669 2775 2502 2442 2448 2373 2420 2270 2281 2065 2145 2033 1923 2006 1898 1812 1838 1860 1806 1801 1738 1769 1830 1836 1684 1677 1617 1726 1667 1630 1650 1538 1616 1589 1654 1605 1558 1604 1473 1577 1583 1531 1545 1507 1491 1604 1477 1529 1474 1563 1517 1545 1532 1502 1484 1406 1468 1465 1465 1497 1462 1477 1493 1504 1405 1483 1466 1495 1484 1494 1498 1469 1590 1430 1456 1506 1456 1469 1562 1459 1524 1547 1565 1570 1540 1549 1542 1501 1529 1535 1517 1515 1564 1525 1484 1486 1510 1563 1516 1591 1545 1541 1586 1492 1513 1473 1584 1533 1511 1605 1494 1478 1541 1608 1577 1484 1498 1564 1545 1591 1549 1580 1470 1552 1537 1576 1542 1541 1521 1562 1497 1570 1562 1628 1573 1605 1614 1524 1572 1575 1545 1635 1582 1592 1600 1720 1719 1711 1661 1679 1728 1819 1734 1749 1786 1759 1835 1804 1669 1787 1771 1866 1724 1659 1691 1701 1737 1709 1645 1634 1620 1676 1644 1694 1630 1648 1740 1718 1762 1806 1784 1703 1912 1908 1923 1954 2020 2204 2415 2445 2553 2890 3066 3272 3674 4114 4585 4918 5366 5894 6291 6757 6970 7268 7025 6905 6466 6239 5943 5673 5516 5123 4978 4456 4200 3797 3547 3059 2930 2604 2537 2382 2277 2120 2217 2140 2112 2187 2215 2240 2234 2324 2307 2465 2616 2758 2879 3181 3343 3479 3681 3929 4042 4252 4281 4433 4324 4441 4449 4534 4351 4183 3848 3639 3398 3330 3140 2804 2809 2563 2533 2336 2220 1981 1934 1749 1834 1644 1725 1742 1726 1615 1643 1681 1727 1700 1635 1642 1727 1803 1742 1766 1655 1738 1629 1667 1642 1598 1641 1579 1729 1671 1675 1618 1696 1676 1661 1777 1840 1830 1679 1711 1875 1869 2084 2044 2393 2350 2519 2707 2901 3183 3541 3812 4155 4390 4774 4955 5169 5294 5148 4951 4465 4387 4166 3889 3750 3678 3548 3255 3054 2788 2516 2342 2122 1963 1843 1830 1755 1662 1675 1666 1633 1631 1620 1528 1667 1508 1493 1531 1537 1550 1500 1504 1555 1523 1502 1468 1488 1486 1422 1426 1511 1494 1516 1461 1505 1506 1460 1550 1487 1559 1481 1623 1548 1517 1603 1614 1736 1721 1784 1847 1987 2005 2104 2286 2227 2432 2597 2705 2576 2558 2471 2445 2330 2231 2149 2118 2105 2026 2006 1917 1740 1704 1638 1634 1621 1644 1578 1534 1474 1445 1503 1479 1470 1458 1421 1377 1468 1418 1317 1416 1345 1427 1386 1406 1361 1306 1382 1395 1462 1470 1423 1431 1373 1316 1441 1406 1379 1327 1393 1371 1369 1433 1450 1409 1413 1405 1328 1305 1352 1356 1384 1372 1344 1398 1389 1426 1413 1324 1405 1268 1381 1356 1401 1397 1316 1361 1378 1327 1333 1366 1345 1343 1375 1364 1356 1313 1400 1253 1249 1295 1339 1389 1320 1323 1318 1359 1334 1299 1328 1281 1383 1342 1367 1308 1334 1382 1370 1365 1444 1307 1347 1335 1304 1272 1362 1334 1411 1296 1338 1306 1359 1352 1340 1363 1402 1357 1381 1372 1446 1290 1401 1360 1370 1373 1425 1375 1352 1428 1344 1385 1417 1349 1383 1378 1412 1401 1411 1369 1431 1363 1387 1425 1354 1372 1432 1361 1402 1397 1375 1345 1397 1385 1390 1276 1282 1330 1348 1292 1340 1309 1394 1414 1328 1426 1351 1364 1401 1358 1323 1307 1332 1288 1306 1260 1420 1222 1319 1321 1333 1262 1346 1381 1266 1380 1390 1394 1371 1361 1342 1451 1308 1362 1278 1308 1298 1341 1406 1394 1399 1404 1348 1363 1375 1347 1357 1438 1388 1395 1374 1432 1514 1402 1379 1427 1427 1451 1429 1506 1413 1565 1522 1644 1580 1710 1690 1692 1862 1798 2021 2042 2011 2160 2154 2254 2309 2443 2415 2356 2341 2223 2199 2143 2014 2038 1881 1990 1981 1821 1839 1780 1699 1631 1676 1619 1524 1478 1495 1450 1487 1450 1410 1389 1359 1314 1325 1424 1405 1336 1402 1444 1394 1404 1337 1339 1351 1366 1428 1317 1394 1351 1384 1395 1415 1299 1426 1290 1359 1417 1381 1497 1367 1423 1451 1433 1439 1440 1513 1528 1482 1504 1579 1664 1731 1660 1674 1760 1733 1869 1835 1749 1689 1735 1718 1703 1620 1589 1556 1626 1634 1551 1539 1483 1515 1475 1419 1446 1414 1356 1401 1444 1351 1414 1443 1431 1415 1472 1509 1522 1474 1490 1447 1523 1526 1521 1530 1507 1468 1555 1570 1651 1497 1556 1630 1587 1674 1670 1662 1817 1805 1695 1887 1632 1764 1714 1663 1671 1505 1600 1617 1596 1615 1564 1593 1568 1489 1423 1439 1419 1348 1398 1373 1328 1353 1343 1274 1351 1327 1372 1220 1311 1284 1356 1348 1315 1272 1342 1334 1225 1337 1321 1316 1289 1256 1306 1278 1340 1208 1335 1272 1333 1292 1320 1353 1318 1221 1286 1290 1251 1288 1299 1311 1280 1250 1224 1235 1240 1242 1232 1261 1272 1285 1236 1360 1271 1291 1246 1342 1264 1272 1286 1227 1268 1242 1298 1262 1267 1370 1279 1315 1295 1277 1300 1269 1262 1244 1347 1284 1322 1293 1314 1242 1234 1328 1306 1286 1277 1289 1282 1341 1224 1270 1303 1265 1324 1311 1203 1309 1301 1227 1312 1286 1246 1301 1258 1303 1273 1225 1252 1329 1274 1343 1266 1304 1382 1295 1332 1341 1284 1337 1299 1330 1275 1362 1251 1327 1313 1241 1267 1360 1359 1310 1331 1318 1287 1332 1353 1404 1421 1477 1332 1424 1434 1408 1382 1394 1420 1405 1387 1414 1384 1438 1446 1498 1502 1487 1400 1422 1441 1425 1379 1360 1366 1377 1441 1526 1388 1358 1408 1303 1315 1394 1350 1387 1320 1385 1323 1362 1264 1391 1295 1388 1387 1328 1374 1355 1339 1387 1420 1443 1497 1427 1508 1627 1485 1597 1624 1730 1776 1731 1870 1946 1975 1984 2002 2081 2152 2101 2162 2071 2147 2102 2043 1887 1802 1907 1814 1711 1843 1712 1684 1742 1640 1555 1560 1581 1492 1444 1514 1538 1479 1541 1471 1510 1504 1479 1640 1658 1623 1723 1758 1764 1900 1803 1863 1816 1856 1845 1764 1768 1765 1689 1727 1669 1649 1644 1636 1558 1535 1580 1501 1502 1460 1474 1419 1482 1362 1328 1338 1365 1333 1455 1412 1397 1454 1432 1517 1475 1495 1465 1651 1545 1591 1554 1667 1692 1677 1691 1726 1779 1755 1822 1882 1919 2145 2129 2342 2515 2570 2976 3236 3464 3764 3930 4159 4171 4025 3909 3708 3449 3339 3309 3259 3174 3090 3162 3177 3062 2822 2638 2474 2292 2102 1984 1798 1758 1768 1706 1594 1576 1516 1483 1533 1487 1463 1389 1381 1347 1390 1411 1407 1307 1349 1348 1327 1382 1258 1328 1280 1323 1320 1251 1309 1248 1343 1322 1353 1266 1315 1341 1333 1313 1298 1277 1326 1322 1301 1351 1303 1280 1321 1226 1243 1279 1347 1312 1279 1287 1337 1223 1387 1307 1331 1289 1285 1314 1372 1342 1294 1327 1348 1383 1314 1326 1313 1335 1395 1365 1311 1371 1467 1376 1408 1397 1471 1582 1588 1646 1690 1777 1974 1997 2072 2127 2304 2184 2160 2176 2107 2023 2036 1908 1871 1917 1908 1937 1904 1840 1864 1739 1748 1731 1636 1630 1575 1505 1482 1563 1518 1514 1471 1535 1589 1535 1565 1571 1587 1527 1633 1582 1584 1752 1755 1765 1837 1926 1812 1938 2108 2068 2179 2158 2346 2333 2368 2453 2410 2530 2644 2771 3082 3335 3661 3867 4379 4958 5491 6125 6483 6717 6808 6679 6390 5776 5160 4926 4582 4404 4311 4358 4365 4395 4233 4049 3683 3382 3041 2583 2402 2149 2136 1988 1830 1782 1754 1675 1756 1652 1692 1596 1557 1637 1601 1614 1553 1614 1542 1546 1580 1536 1466 1581 1553 1603 1523 1507 1450 1521 1572 1522 1497 1532 1587 1508 1544 1514 1496 1568 1541 1570 1569 1580 1621 1626 1769 1663 1751 1736 1770 1879 1871 2003 2016 1954 1946 1946 1826 1835 1783 1708 1747 1820 1833 1724 1782 1746 1734 1718 1774 1669 1656 1610 1515 1582 1603 1589 1593 1599 1516 1503 1557 1532 1554 1586 1572 1593 1562 1525 1637 1660 1607 1636 1564 1640 1629 1686 1569 1629 1655 1735 1703 1704 1662 1587 1577 1758 1546 1581 1620 1573 1551 1662 1602 1593 1637 1625 1631 1581 1634 1673 1583 1565 1576 1684 1590 1629 1744 1748 1767 1843 1999 2069 2166 2437 2532 2719 2936 3129 3148 3153 3161 2970 2947 2757 2664 2551 2496 2427 2464 2503 2526 2429 2371 2346 2216 2125 2012 1878 1873 1706 1707 1682 1551 1504 1476 1537 1461 1463 1441 1436 1418 1441 1416 1348 1371 1392 1435 1400 1342 1366 1275 1339 1347 1343 1344 1341 1258 1333 1295 1345 1342 1372 1313 1391 1361 1409 1329 1387 1331 1324 1379 1340 1493 1396 1429 1383 1448 1362 1510 1443 1423 1501 1504 1592 1464 1580 1502 1611 1584 1671 1598 1635 1717 1675 1691 1864 1781 1871 1890 1903 2104 2028 2187 2296 2253 2456 2555 2683 2758 2909 3062 3237 3503 3658 3723 3674 3801 3686 3614 3533 3305 3216 3113 2943 2980 2817 2878 2821 2847 2732 2722 2588 2508 2434 2447 2399 2322 2427 2504 2459 2596 2551 2649 2629 2450 2420 2294 2165 2110 1988 2049 1944 2073 2054 2046 2089 2001 1897 1931 1731 1735 1652 1597 1536 1521 1562 1458 1492 1435 1521 1505 1534 1407 1446 1421 1401 1345 1407 1357 1394 1319 1360 1430 1368 1380 1333 1380 1322 1354 1242 1326 1383 1290 1276 1309 1317 1288 1275 1260 1292 1290 1330 1319 1343 1398 1410 1472 1474 1480 1567 1666 1567 1682 1717 1749 1765 1733 1621 1660 1541 1554 1517 1492 1602 1497 1484 1496 1508 1485 1548 1489 1460 1354 1465 1315 1377 1272 1336 1324 1299 1232 1314 1271 1244 1299 1295 1336 1324 1286 1334 1278 1386 1384 1364 1420 1305 1285 1372 1366 1381 1365 1348 1382 1467 1423 1341 1410 1389 1367 1363 1319 1341 1342 1344 1301 1377 1338 1337 1313 1373 1296 1293 1280 1322 1361 1258 1297 1290 1346 1322 1374 1391 1365 1403 1438 1373 1300 1249 1361 1260 1304 1255 1364 1299 1269 1265 1262 1287 1313 1350 1264 1309 1255 1321 1311 1324 1276 1325 1267 1239 1264 1271 1274 1338 1250 1345 1301 1328 1286 1278 1307 1266 1299 1338 1268 1237 1253 1270 1287 1292 1280 1299 1271 1282 1244 1396 1307 1347 1286 1278 1314 1298 1272 1298 1358 1381 1298 1378 1380 1397 1403 1376 1392 1408 1509 1440 1475 1442 1511 1433 1525 1590 1568 1747 1723 1844 2038 2093 2149 2396 2546 2728 3021 3264 3626 3867 4065 4374 4422 4429 4348 3994 3618 3279 3109 2924 2961 2914 2953 2993 3076 2988 2852 2788 2617 2463 2342 2103 1920 1872 1644 1615 1549 1648 1564 1556 1515 1531 1466 1442 1422 1461 1362 1404 1337 1420 1387 1466 1367 1421 1431 1419 1432 1347 1374 1313 1335 1343 1291 1305 1431 1353 1313 1355 1344 1329 1364 1348 1364 1393 1304 1373 1332 1349 1291 1308 1424 1355 1418 1438 1403 1401 1420 1343 1444 1427 1454 1449 1435 1480 1515 1584 1597 1676 1612 1656 1637 1634 1775 1822 1874 1997 2238 2295 2624 2808 2929 3326 3835 4335 4701 5179 5662 6039 6056 6166 6166 5893 5779 5312 5026 4787 4423 4456 4427 4493 4228 4557 4508 4422 4465 4422 4128 3948 3859 3871 3797 3694 3660 3530 3475 3499 3482 3385 3367 3444 3316 3313 3247 3199 3133 2955 2909 2901 2803 2812 2605 2519 2493 2509 2509 2385 2369 2168 2103 2174 2144 2164 2169 2041 2000 2004 1989 1879 1813 1800 1737 1667 1701 1617 1691 1609 1662 1605 1608 1663 1636 1546 1532 1536 1450 1482 1457 1505 1379 1403 1434 1405 1368 1395 1417 1332 1389 1401 1398 1440 1455 1476 1327 1413 1425 1518 1461 1421 1519 1462 1480 1459 1507 1540 1530 1719 1654 1701 1720 1770 1872 1915 1985 2034 2183 2138 2258 2314 2431 2558 2621 2746 2728 2729 2738 2616 2577 2270 2339 2226 2232 2116 2082 2194 2089 2089 2076 2005 1953 1830 1841 1697 1748 1638 1523 1581 1440 1485 1419 1358 1349 1306 1347 1308 1267 1270 1221 1300 1317 1276 1234 1266 1301 1238 1333 1238 1260 1242 1237 1214 1251 1241 1234 1230 1192 1273 1238 1196 1295 1164 1195 1142 1199 1188 1248 1225 1150 1307 1233 1258 1277 1286 1246 1292 1288 1243 1242 1247 1243 1180 1247 1247 1204 1194 1218 1268 1307 1259 1272 1298 1328 1244 1236 1238 1221 1271 1223 1204 1211 1186 1271 1247 1283 1218 1308 1162 1280 1213 1249 1184 1237 1184 1229 1223 1242 1244 1221 1208 1229 1235 1160 1178 1224 1197 1145 1224 1243 1233 1216 1184 1245 1190 1250 1203 1193 1213 1198 1186 1204 1248 1180 1200 1193 1181 1244 1281 1209 1247 1198 1190 1222 1230 1239 1270 1215 1217 1293 1226 1269 1278 1268 1305 1359 1242 1283 1205 1220 1236 1286 1261 1247 1354 1263 1311 1273 1314 1279 1338 1316 1334 1381 1307 1347 1379 1343 1367 1384 1449 1457 1542 1522 1585 1606 1717 1747 1832 1774 1939 1986 2073 2119 2155 2187 2250 2333 2345 2331 2231 2273 2201 2180 2173 2060 2154 2106 1934 2074 2015 1980 1977 1959 1999 1837 1743 1705 1731 1698 1592 1588 1601 1575 1603 1519 1528 1468 1569 1595 1449 1565 1666 1481 1614 1549 1621 1601 1613 1574 1496 1543 1485 1422 1438 1444 1464 1484 1491 1422 1418 1394 1407 1371 1416 1360 1360 1368 1370 1210 1269 1259 1310 1268 1331 1226 1212 1319 1331 1273 1258 1231 1207 1206 1174 1192 1228 1217 1229 1240 1189 1212 1252 1231 1230 1197 1250 1222 1207 1195 1271 1215 1247 1260 1235 1194 1238 1185 1241 1270 1282 1244 1315 1288 1284 1365 1328 1297 1347 1321 1303 1373 1356 1332 1411 1421 1399 1379 1454 1411 1498 1448 1484 1481 1576 1566 1687 1540 1651 1610 1588 1565 1549 1582 1552 1473 1468 1497 1462 1483 1440 1440 1426 1377 1455 1421 1385 1435 1359 1384 1329 1292 1367 1316 1319 1243 1270 1260 1207 1273 1257 1229 1081 1194 1192 1171 1212 1213 1188 1225 1191 1217 1204 1188 1219 1226 1165 1214 1179 1194 1190 1209 1171 1213 1223 1204 1161 1221 1225 1209 1302 1179 1202 1259 1221 1188 1179 1198 1163 1247 1260 1242 1209 1207 1282 1267 1249 1303 1338 1319 1301 1364 1402 1393 1413 1426 1374 1488 1510 1431 1464 1467 1526 1662 1587 1690 1742 1682 1725 1751 1755 1640 1652 1643 1556 1406 1492 1451 1451 1458 1550 1531 1457 1480 1442 1414 1403 1341 1429 1335 1367 1308 1329 1321 1252 1319 1234 1241 1230 1181 1200 1215 1277 1236 1280 1304 1249 1247 1262 1248 1275 1252 1282 1221 1226 1223 1255 1236 1211 1184 1300 1216 1214 1157 1256 1150 1256 1246 1246 1233 1261 1258 1264 1191 1331 1237 1308 1196 1284 1293 1280 1357 1300 1279 1247 1258 1342 1391 1412 1442 1436 1448 1561 1616 1687 1731 1800 1998 2080 2260 2290 2346 2284 2358 2202 2188 1953 1909 1885 1896 1860 1970 1939 1914 1955 1971 1957 1877 1907 1828 1771 1759 1633 1585 1475 1543 1505 1476 1482 1430 1448 1366 1401 1466 1364 1426 1362 1336 1498 1469 1499 1514 1604 1668 1689 1713 2009 1944 2247 2486 2686 2957 3086 3291 3421 3454 3265 3178 2847 2635 2567 2308 2108 2116 2104 2159 2144 2243 2296 2340 2452 2401 2259 2139 2084 1912 1786 1741 1595 1527 1472 1388 1427 1387 1338 1307 1284 1314 1269 1312 1258 1238 1276 1256 1292 1267 1314 1288 1210 1253 1253 1337 1360 1323 1290 1377 1311 1349 1350 1360 1314 1353 1442 1353 1356 1397 1347 1353 1365 1385 1372 1377 1395 1448 1337 1484 1451 1530 1518 1622 1576 1564 1661 1769 1712 1765 1863 1913 2003 2008 2083 2089 2054 1917 1906 1937 1879 1943 1734 1783 1660 1689 1707 1808 1806 1764 1749 1745 1625 1691 1640 1627 1536 1509 1531 1459 1424 1490 1412 1374 1327 1324 1317 1379 1274 1371 1248 1272 1225 1325 1239 1295 1257 1241 1273 1222 1270 1243 1305 1241 1329 1242 1245 1352 1257 1264 1229 1279 1264 1378 1309 1352 1315 1229 1342 1335 1316 1281 1282 1301 1285 1266 1315 1309 1291 1325 1312 1320 1242 1296 1347 1378 1333 1289 1387 1381 1439 1372 1475 1338 1371 1343 1316 1422 1269 1347 1309 1272 1214 1252 1269 1272 1296 1352 1267 1324 1290 1323 1266 1232 1279 1274 1324 1281 1291 1218 1292 1250 1291 1327 1359 1357 1341 1316 1330 1344 1315 1253 1325 1356 1323 1301 1310 1302 1315 1284 1354 1346 1250 1279 1336 1297 1205 1280 1243 1202 1204 1221 1181 1182 1208 1203 1191 1175 1171 1160 1187 1083 1200 1206 1159 1178 1151 1183 1165 1204 1146 1131 1135 1157 1204 1203 1153 1299 1101 1237 1231 1216 1192 1123 1184 1180 1128 1282 1123 1178 1143 1193 1172 1165 1205 1158 1237 1231 1202 1189 1172 1265 1221 1243 1265 1239 1284 1252 1272 1258 1259 1242 1299 1248 1123 1256 1273 1342 1298 1403 1305 1346 1330 1418 1347 1404 1450 1444 1418 1382 1458 1479 1409 1426 1456 1310 1239 1302 1399 1296 1282 1275 1346 1368 1337 1405 1322 1345 1338 1268 1320 1285 1207 1133 1234 1237 1188 1239 1188 1158 1153 1211 1163 1178 1098 1166 1156 1207 1223 1221 1181 1197 1206 1228 1187 1139 1161 1235 1206 1140 1220 1195 1124 1136 1175 1139 1199 1213 1199 1264 1163 1177 1233 1175 1250 1204 1240 1160 1186 1211 1209 1193 1112 1188 1247 1261 1226 1197 1197 1164 1232 1254 1185 1163 1235 1236 1255 1269 1206 1261 1169 1277 1173 1185 1266 1226 1187 1269 1186 1241 1264 1256 1254 1213 1173 1124 1247 1156 1217 1231 1134 1229 1224 1187 1255 1204 1205 1222 1227 1234 1136 1202 1179 1212 1202 1199 1192 1234 1218 1167 1228 1094 1231 1154 1212 1140 1179 1196 1227 1225 1170 1201 1281 1212 1260 1230 1142 1230 1228 1214 1266 1184 1253 1253 1319 1303 1336 1310 1330 1314 1253 1220 1173 1252 1299 1229 1269 1251 1231 1279 1195 1182 1260 1240 1206 1295 1296 1270 1213 1183 1177 1199 1184 1171 1222 1212 1204 1223 1196 1217 1235 1221 1180 1161 1209 1191 1220 1218 1223 1269 1197 1268 1261 1220 1269 1276 1313 1320 1227 1277 1244 1305 1185 1296 1256 1278 1249 1225 1272 1315 1318 1292 1225 1304 1266 1308 1275 1412 1284 1347 1332 1379 1340 1345 1389 1435 1480 1479 1583 1584 1656 1852 1804 1958 1967 2026 2098 2207 2255 2189 2133 2118 1937 1917 1811 1726 1782 1686 1708 1741 1742 1794 1799 1744 1719 1771 1828 1769 1675 1640 1560 1535 1522 1512 1447 1414 1361 1343 1339 1256 1244 1210 1304 1237 1275 1240 1273 1233 1262 1150 1210 1169 1130 1225 1095 1134 1226 1155 1176 1113 1205 1126 1248 1140 1153 1160 1163 1138 1109 1200 1105 1211 1209 1213 1193 1127 1216 1238 1192 1190 1242 1218 1212 1289 1295 1316 1262 1304 1260 1270 1305 1349 1268 1269 1246 1303 1265 1198 1248 1242 1221 1261 1212 1279 1347 1280 1326 1351 1277 1290 1271 1230 1285 1208 1267 1235 1231 1234 1207 1231 1289 1335 1384 1273 1291 1277 1334 1339 1384 1399 1430 1577 1648 1660 1695 1764 1809 1967 1915 2081 2148 2134 2189 2240 2297 2560 2536 2605 2561 2517 2427 2372 2350 2260 2139 2138 2118 2024 2031 1882 1930 1997 1939 1958 1967 2013 1919 1952 1921 1872 1720 1721 1620 1546 1552 1522 1431 1448 1433 1345 1293 1282 1246 1227 1292 1314 1233 1201 1244 1225 1200 1178 1189 1211 1247 1280 1257 1209 1143 1211 1250 1250 1176 1266 1213 1214 1271 1241 1343 1283 1334 1339 1345 1445 1398 1568 1434 1601 1620 1700 1750 1767 1825 1865 1989 2021 1956 1965 1878 1845 1766 1738 1759 1684 1622 1511 1578 1534 1581 1583 1623 1595 1613 1635 1612 1560 1540 1568 1511 1490 1489 1454 1410 1334 1314 1299 1340 1277 1237 1190 1171 1187 1180 1196 1177 1215 1145 1152 1145 1104 1175 1140 1207 1177 1208 1168 1196 1138 1151 1197 1206 1221 1238 1183 1252 1265 1270 1187 1232 1147 1259 1172 1153 1196 1231 1263 1210 1248 1228 1242 1260 1281 1301 1232 1376 1258 1286 1315 1265 1253 1292 1165 1236 1158 1232 1209 1150 1300 1228 1214 1271 1213 1245 1247 1217 1310 1252 1296 1333 1360 1355 1340 1462 1316 1354 1419 1325 1300 1355 1270 1313 1202 1214 1158 1254 1235 1266 1225 1243 1252 1303 1298 1348 1296 1274 1305 1238 1270 1297 1202 1339 1280 1299 1275 1322 1275 1339 1287 1303 1369 1364 1359 1222 1315 1287 1181 1267 1256 1217 1194 1276 1282 1182 1258 1228 1270 1200 1239 1252 1189 1196 1159 1225 1072 1192 1158 1180 1161 1121 1127 1106 1090 1111 1131 1049 1146 1104 1024 1042 1124 1057 1104 1068 1112 1117 1115 1047 1096 1114 1042 1091 1085 1085 1133 1038 1087 1053 1069 1012 1148 1053 1071 1010 1053 1031 1068 1034 1082 1073 1069 1060 1079 1048 1060 1112 1061 1051 1038 1130 1052 1029 1083 1041 958 1097 1061 1102 1091 1050 1097 1068 1062 1026 1056 1086 1058 1097 1054 1069 1049 1063 1070 1150 1048 1119 1055 1053 1088 1106 1065 1111 1122 1101 1091 1087 1099 1095 1102 1159 1080 1107 1104 1107 1100 1172 1167 1157 1083 1113 1136 1079 1056 1157 1123 1174 1124 1145 1146 1089 1131 1166 1164 1128 1187 1219 1145 1182 1216 1190 1177 1191 1186 1171 1213 1209 1236 1284 1207 1271 1285 1273 1275 1394 1377 1294 1371 1407 1404 1368 1293 1261 1311 1263 1205 1275 1255 1199 1278 1283 1288 1274 1286 1239 1355 1295 1355 1246 1303 1314 1241 1189 1293 1217 1307 1300 1245 1298 1218 1274 1328 1281 1338 1342 1419 1354 1456 1458 1613 1782 1843 1951 2025 2222 2367 2422 2525 2553 2568 2455 2340 2198 2046 1935 1738 1709 1622 1666 1575 1536 1621 1626 1709 1730 1778 1859 1821 1885 1865 1767 1747 1633 1584 1527 1378 1350 1324 1257 1305 1254 1168 1216 1154 1204 1204 1141 1167 1180 1125 1143 1123 1125 1120 1212 1192 1110 1124 1137 1028 1152 1084 1150 1079 1084 1131 1064 1129 1031 1113 1103 1088 1101 1061 1103 1087 1099 1087 1085 1093 1125 1123 1223 1148 1181 1129 1169 1235 1206 1284 1396 1374 1467 1346 1553 1528 1619 1580 1646 1635 1616 1558 1435 1351 1441 1321 1288 1296 1215 1215 1326 1309 1299 1335 1361 1387 1289 1321 1343 1375 1331 1329 1288 1291 1264 1256 1262 1201 1117 1221 1164 1091 1120 1109 1167 1102 1050 1174 1105 1164 1118 1047 1083 1073 1008 1170 1097 1102 1084 1165 1097 1110 1024 1127 1118 1108 1156 1084 1076 1067 1062 1068 1056 1112 1061 1110 1093 1048 1049 1078 1060 1087 1029 1088 1056 1102 1105 1068 1060 1072 1103 1051 1076 1028 1062 1033 1069 1042 1104 1127 1049 1035 1112 1026 1051 1073 1050 1042 1051 1016 1119 1075 1075 1139 1051 1068 1107 1103 1119 1126 1141 1135 1152 1179 1126 1174 1187 1202 1253 1151 1166 1153 1128 1141 1182 1216 1191 1207 1197 1212 1226 1208 1198 1251 1308 1315 1288 1298 1267 1423 1376 1420 1413 1490 1510 1528 1561 1557 1530 1532 1510 1418 1419 1402 1386 1380 1358 1344 1392 1366 1309 1304 1390 1368 1341 1406 1384 1362 1343 1343 1330 1274 1293 1303 1296 1247 1228 1184 1251 1252 1208 1259 1148 1197 1235 1210 1272 1287 1300 1236 1311 1235 1248 1287 1212 1235 1276 1301 1211 1282 1204 1299 1276 1218 1215 1168 1245 1213 1157 1222 1189 1198 1193 1147 1240 1074 1196 1160 1256 1188 1137 1123 1184 1100 1155 1189 1220 1124 1101 1110 1092 1153 1094 1157 1132 1159 1141 1171 1089 1108 1105 1074 1130 1167 1151 1124 1144 1143 1158 1115 1108 1182 1086 1163 1159 1247 1213 1246 1261 1244 1154 1136 1209 1266 1252 1228 1169 1195 1224 1210 1221 1190 1256 1223 1266 1250 1235 1322 1317 1316 1235 1240 1261 1332 1173 1281 1190 1193 1166 1254 1184 1120 1194 1136 1197 1216 1120 1143 1145 1177 1195 1256 1184 1156 1159 1217 1124 1149 1189 1200 1176 1156 1120 1068 1096 1045 1060 1124 1055 1063 1100 1127 1122 1090 1106 1055 1172 1138 1063 1152 1113 1104 1117 1109 1077 1157 1046 1050 1100 1079 1081 1117 1044 1031 1103 1106 1068 1099 1065 1122 1077 1104 1084 1032 1037 1083 1051 1061 1070 1072 1099 1095 1097 1124 1127 1166 1245 1132 1316 1238 1287 1286 1348 1179 1299 1271 1233 1233 1295 1170 1220 1222 1158 1191 1171 1149 1146 1208 1231 1207 1203 1169 1217 1198 1322 1271 1199 1225 1230 1150 1125 1174 1162 1112 1183 1183 1126 1140 1130 1138 1117 1086 1061 1039 1060 1081 1097 1101 1086 1161 1000 1076 1069 1135 1098 1110 1139 1136 1117 1110 1108 1174 1136 1113 1114 1121 1148 1138 1118 1061 1070 1071 1003 1082 1036 1044 1052 1099 1143 1089 1102 1135 1117 1108 1096 1129 1096 1053 1122 1128 1107 1036 1120 1114 1125 1082 1050 1002 1071 1065 1053 1132 1123 1115 1117 1095 1109 1126 1121 1059 1072 1150 1118 1143 1151 1114 1187 1126 1136 1170 1160 1132 1156 1103 1163 1049 1203 1080 1130 1150 1148 1136 1145 1159 1217 1180 1177 1187 1220 1246 1136 1133 1137 1113 1161 1152 1164 1122 1161 1138 1083 1091 1101 1146 1057 1139 1073 1059 1065 1159 1120 1015 1033 1096 1112 1127 1108 1037 1049 1092 1016 1102 1108 1070 1086 1070 1097 1082 1044 1100 1014 1085 1087 1080 1156 1063 1173 1118 1148 1190 1152 1209 1180 1197 1237 1164 1115 1109 1161 1150 1155 1161 1053 1149 1117 1142 1156 1150 1110 1189 1186 1187 1188 1173 1175 1224 1193 1191 1140 1238 1181 1195 1253 1210 1271 1241 1313 1262 1330 1269 1391 1334 1446 1478 1539 1637 1678 1754 1902 1841 1911 1877 1787 1684 1658 1649 1528 1477 1415 1454 1483 1349 1346 1381 1363 1289 1382 1468 1501 1476 1497 1425 1445 1525 1480 1420 1380 1371 1344 1408 1350 1352 1196 1260 1176 1287 1226 1293 1322 1338 1390 1271 1402 1384 1359 1394 1362 1273 1230 1263 1204 1218 1180 1160 1155 1175 1134 1153 1133 1175 1117 1209 1158 1215 1205 1170 1259 1196 1170 1167 1161 1126 1125 1185 1130 1113 1133 1096 1075 1074 1080 1060 1109 1152 1011 1106 1019 1001 1070 972 1003 1084 1065 1038 1010 1045 1074 1011 1027 998 1035 1005 994 1078 996 1059 1026 1053 1023 1048 975 1041 1081 997 1044 1060 1052 1085 1120 1016 1089 1099 1087 1160 1085 1067 1063 1042 1034 1086 1054 1010 1086 1014 1080 1030 1078 1095 1107 1068 1079 1014 1038 1048 1059 1062 1066 1039 1054 1051 1088 1030 1072 1105 1023 1121 1143 1135 1173 1164 1213 1228 1233 1193 1237 1236 1215 1217 1311 1234 1211 1311 1252 1265 1276 1180 1187 1160 1158 1198 1158 1154 1165 1153 1163 1173 1151 1173 1209 1171 1171 1253 1170 1215 1288 1201 1168 1139 1226 1157 1116 1123 1117 1099 1097 1098 1052 1164 1088 1133 1117 1082 1085 1102 1027 1100 1059 1061 1029 1051 1055 1100 1114 1042 1021 1042 1057 1071 1016 1081 981 1024 1065 974 1059 997 1030 1021 1049 1021 1014 1009 1011 992 1038 1028 1002 1014 1031 997 1035 1071 1032 1101 1016 1021 1066 1031 1068 1088 1055 1043 1029 1096 967 1071 989 1010 1056 987 1064 955 1054 986 969 1009 974 1006 1063 962 1020 1049 1020 999 1056 1021 1080 997 1101 1026 1026 1108 993 1028 1052 1063 1068 1067 1052 1044 1055 1055 1093 1037 1116 1071 1117 1106 1139 1051 1119 1077 1097 1086 1090 1085 1034 1064 1044 1047 1057 1129 1035 1018 1047 1131 1108 1053 1142 1068 1123 1129 1056 1113 1132 1084 1075 1092 1043 1073 1082 1029 1065 1063 1093 1114 1080 1063 1047 1090 1085 1060 1049 1056 1060 1096 1088 1116 1024 1149 1077 1028 1063 1061 1132 1079 1089 1113 1019 1117 1127 1131 1006 1102 1071 1107 1162 1100 1126 1050 1127 1087 1146 1114 1171 1178 1116 1132 1140 1071 1132 1179 1106 1140 1106 1092 1098 1065 1099 1053 1102 1105 1070 1100 1096 1074 1017 1074 991 1129 1025 1005 1019 951 1045 1044 1027 1101 1036 1069 1034 1121 1020 990 999 1004 954 1008 1070 1116 1033 1014 973 1012 975 1028 1020 964 1020 970 1008 1058 1032 1052 933 1021 1003 1021 1030 973 1009 1016 1029 1021 975 1031 983 1028 961 951 974 987 1030 1028 1009 977 1002 1037 1012 1031 939 1006 1027 1011 996 1008 969 933 1009 958 1057 1028 998 1020 1048 966 1064 955 997 949 984 969 1025 975 1034 1022 986 1026 955 979 998 992 1005 1062 981 999 1046 957 1040 1036 1020 1003 1043 1018 998 1006 976 1081 995 1049 1064 1105 1028 1063 993 1091 1056 1026 1071 1005 1084 1071 1080 1073 1152 1075 1109 1114 1178 1144 1132 1072 1011 1103 1081 1035 1071 994 1012 1011 1071 1058 1053 1036 1006 1002 1045 1068 1048 1069 989 1070 1079 1076 1122 1012 999 997 1025 1024 1009 998 999 1081 976 972 1041 1003 976 963 1041 978 1069 942 1012 945 1004 967 994 1038 1020 989 1027 937 1001 969 1003 1034 1001 994 1026 1044 1040 976 1011 997 1035 1005 1019 959 986 954 1036 1010 998 995 971 981 941 1024 948 1037 1039 1028 1029 984 1009 983 944 1027 1017 1037 1038 1020 972 979 1028 942 959 1006 980 951 984 1009 1043 977 1027 1077 1050 1052 1048 1039 1078 1067 986 1106 1058 1038 1046 1074 996 1065 1014 1055 1090 1103 1013 1055 1086 1064 1032 1055 1003 980 1071 1036 1070 1024 1037 1076 1069 1041 1105 995 1098 998 1061 1074 1066 1067 1030 1047 1019 997 1042 1054 1031 979 1097 1012 1085 1094 1078 1004 1011 1123 1002 1013 1065 1020 1024 972 998 1088 1109 1093 1118 1061 1050 998 1064 1077 1088 1008 1048 1035 1097 1095 1094 1080 1095 1072 1091 1114 1095 1143 1173 1048 1181 1150 1141 1108 1171 1229 1183 1124 1074 1086 1099 1078 1057 1068 1107 1081 1109 1006 1114 1094 1037 1071 1079 1001 1025 1077 983 1083 1115 1059 1026 1043 1034 999 1039 1062 1047 998 1055 1079 1083 1046 1047 974 1016 1015 967 1051 1052 1006 1022 972 949 1043 966 1027 1001 972 1052 914 968 971 995 1010 935 987 1058 969 975 979 1020 994 1028 1037 1047 973 1057 984 936 1002 1024 966 945 953 1030 955 993 958 991 963 1001 991 985 927 1061 982 995 974 992 926 945 941 998 926 951 946 956 921 924 964 1038 989 994 1009 976 972 976 949 922 975 1008 943 954 999 960 1005 924 1025 936 976 999 990 936 1002 955 961 947 967 1013 983 981 1007 995 973 980 943 984 1012 1047 981 1037 958 1015 977 986 1011 1048 1028 991 1016 981 1047 999 1001 1100 992 1031 1021 1029 1095 1141 1100 1058 1006 1084 1129 1122 1086 1064 1019 1081 1091 1080 1043 1020 989 1119 1032 1079 1035 1085 1031 1106 1146 1082 1100 1115 1081 1103 1101 1105 1061 1130 1118 1121 1142 1156 1161 1138 1102 1105 1047 1072 1034 1051 1044 1132 1076 1087 1113 1116 1163 1091 1062 1127 1142 1115 1118 1184 1111 1173 1196 1202 1168 1160 1162 1122 1210 1161 1171 1122 1096 1143 1165 1159 1170 1170 1128 1197 1173 1182 1185 1201 1156 1219 1177 1226 1227 1238 1169 1190 1197 1178 1146 1152 1178 1143 1184 1154 1106 1106 1090 1080 1053 1164 1134 1109 1123 1142 1162 1161 1146 1107 1110 1083 1077 1103 1119 1058 1089 1025 1071 1050 1064 1096 1100 1099 1087 985 1006 1001 1103 1046 1036 1101 1044 1094 1084 1051 1017 1077 1176 1135 1159 1241 1245 1200 1245 1327 1283 1329 1295 1351 1464 1417 1332 1398 1271 1349 1239 1208 1208 1227 1208 1217 1215 1189 1202 1124 1242 1226 1204 1244 1273 1222 1253 1337 1326 1316 1275 1272 1337 1257 1176 1313 1266 1211 1214 1198 1111 1107 1134 1126 1096 1172 1169 1101 1126 1148 1099 1117 1118 1087 1132 1114 1126 1059 1081 1061 1049 1131 1045 1116 1075 1093 1122 1102 1098 1133 1101 1118 1128 1159 1098 1167 1144 1102 1151 1209 1238 1212 1263 1234 1299 1301 1401 1414 1477 1432 1369 1452 1503 1372 1548 1442 1453 1378 1340 1219 1237 1228 1207 1237 1207 1215 1224 1168 1126 1201 1227 1162 1132 1193 1288 1224 1204 1278 1211 1307 1252 1241 1235 1257 1274 1216 1223 1149 1148 1215 1131 1125 1113 1143 1084 1089 1051 1031 1031 1073 1067 988 1037 1122 1026 1095 1065 1056 1118 1040 1048 993 1034 1023 1040 1023 1048 996 986 1063 1021 1028 965 1070 1031 987 1026 1003 1055 989 1022 1051 1031 1052 1047 977 1018 1055 1025 938 1046 1000 1055 1013 1070 1062 1023 1081 1058 1096 1059 1042 1016 1047 1051 1022 1016 1005 1071 949 999 1020 980 995 941 1025 993 991 1027 990 943 1022 974 1014 951 1022 1011 1035 1047 953 1046 1011 1024 1048 992 1033 998 1144 991 1012 1052 1014 999 1023 980 1009 978 1012 989 1041 976 1058 953 995 1010 978 1036 996 965 957 976 978 988 1016 983 982 1004 955 1098 988 1030 1070 1001 1067 1009 1030 1077 1066 1044 1042 959 947 1031 1030 1038 1025 987 1031 1022 1091 1068 960 1085 983 1025 1015 1027 1026 1097 1073 1064 1054 1049 990 1037 1002 958 1046 1085 1027 1074 1002 1029 1047 1047 1015 1063 1054 1022 1072 1018 1043 1051 1099 1066 1073 1105 1098 1112 1083 1078 1125 1103 1094 1064 1099 1143 1150 1088 1113 1141 1106 1175 1153 1151 1182 1157 1071 1125 1138 1181 1092 1144 1106 1104 1157 1106 1114 1083 1057 1053 1043 1075 1182 1113 1202 1147 1172 1139 1158 1115 1091 1172 1141 1167 1153 1150 1110 1117 1099 1121 1121 1121 1216 1208 1096 1151 1195 1248 1211 1261 1269 1230 1295 1313 1256 1241 1257 1190 1228 1217 1131 1135 1114 1146 1146 1101 1102 1036 1051 1161 1061 1112 1157 1081 1121 1050 1124 1130 1233 1107 1143 1107 1158 1102 1143 1146 1161 1209 1150 1145 1127 1102 1135 1158 1189 1112 1089 1104 1118 1118 1084 1105 1164 1087 1135 1134 1108 1127 1124 1055 1075 1070 1104 1110 1108 1104 1085 1134 1098 1118 1096 1070 1065 1091 1028 1078 1091 1174 1065 1101 1090 1088 1148 1144 1125 1124 1184 1183 1140 1166 1155 1157 1147 1097 1149 1141 1113 1029 1117 1120 1076 1119 1105 1077 990 1129 1100 1129 1132 1168 1132 1137 1069 1124 1108 1150 1119 1161 1147 1154 1202 1244 1189 1202 1205 1271 1252 1268 1187 1230 1162 1239 1306 1205 1254 1232 1270 1280 1229 1261 1223 1342 1300 1255 1230 1252 1286 1236 1226 1233 1235 1214 1179 1178 1208 1234 1219 1182 1208 1202 1253 1229 1228 1225 1246</counts>
			</dataPoints>
		</scan>
	</xrdMeasurement>
</xrdMeasurements>