File: dataset/precursor_mixture/TiO2_GeO2_LiCoO2_Bi2O3-alpha.12-min.xrdml
<?xml version="1.0"?>
<xrdMeasurements xmlns="http://www.xrdml.com/XRDMeasurement/2.2" xmlns:xsi="http://www.w3.org/2001/XMLSchema-instance" xsi:schemaLocation="http://www.xrdml.com/XRDMeasurement/2.2 http://www.xrdml.com/XRDMeasurement/2.2/XRDMeasurement.xsd" status="Completed" recordIdentifier="{E903538B-10CB-4D09-9ACD-FE8F786A171D}">
	<comment>
		<entry/>
	</comment>
	<sample type="To be analyzed">
		<id>dara-30-2</id>
		<name></name>
		<preparedBy></preparedBy>
	</sample>
	<xrdMeasurement measurementType="Scan" status="Completed" sampleMode="Reflection">
		<usedWavelength intended="K-Alpha 1">
			<kAlpha1 unit="Angstrom">1.5405980</kAlpha1>
			<kAlpha2 unit="Angstrom">1.5444260</kAlpha2>
			<kBeta unit="Angstrom">1.3922500</kBeta>
			<ratioKAlpha2KAlpha1>0.5000</ratioKAlpha2KAlpha1>
		</usedWavelength>
		<incidentBeamPath>
			<radius unit="mm">145.00</radius>
			<xRayTube id="1010048" name="Empyrean Cu LFF HR (9430 033 7310x) DK437873">
				<tension unit="kV">40.0</tension>
				<current unit="mA">15.0</current>
				<anodeMaterial>Cu</anodeMaterial>
				<focus type="Line">
					<length unit="mm">12.0</length>
					<width unit="mm">0.4</width>
					<takeOffAngle unit="deg">6.0</takeOffAngle>
				</focus>
			</xRayTube>
			<filter id="20010004" name="Beta-filter Nickel">
				<material>Ni</material>
				<thickness unit="mm">0.020</thickness>
			</filter>
			<sollerSlit id="21010002" name="Soller slits 0.04 rad.">
				<opening unit="rad">0.0400</opening>
			</sollerSlit>
			<mask id="22031000" name="Fixed mask 13 mm">
				<width unit="mm">9.00</width>
			</mask>
			<divergenceSlit id="22120001" name="Divergence slit 1°" xsi:type="fixedDivergenceSlitType">
				<distanceToSample unit="mm">50.00</distanceToSample>
				<height unit="mm">1.52</height>
			</divergenceSlit>
		</incidentBeamPath>
		<beamKnife id="29030100" name="Beam knife low"/>
		<sampleMovement xsi:type="spinningSampleMovementType">
			<spinnerRevolutionTime unit="seconds">1.0</spinnerRevolutionTime>
		</sampleMovement>
		<diffractedBeamPath>
			<radius unit="mm">145.00</radius>
			<antiScatterSlit id="22090040" name="AS slit 9 mm" xsi:type="fixedAntiScatterSlitType">
				<height unit="mm">9.00</height>
			</antiScatterSlit>
			<sollerSlit id="21020003" name="Large Soller slits 0.04 rad.">
				<opening unit="rad">0.0400</opening>
			</sollerSlit>
			<filter id="20030001" name="Large beta-filter Nickel">
				<material>Ni</material>
				<thickness unit="mm">0.020</thickness>
			</filter>
			<detector id="7010019" name="PIXcel1D-Medipix3 detector" xsi:type="rtmsDetectorType">
				<phd unit="keV">
					<lowerLevel>4.0</lowerLevel>
					<upperLevel>11.3</upperLevel>
				</phd>
				<mode>Scanning</mode>
				<activeLength unit="deg">5.020</activeLength>
			</detector>
		</diffractedBeamPath>
		<scan appendNumber="0" mode="Continuous" scanAxis="Gonio" status="Completed">
			<header>
				<startTimeStamp>2024-03-25T12:04:58-07:00</startTimeStamp>
				<endTimeStamp>2024-03-25T12:17:26-07:00</endTimeStamp>
				<author>
					<name>AutomatedUser</name>
				</author>
				<source>
					<applicationSoftware version="1.6 (94)">PANalytical Aeris Instrument Suite</applicationSoftware>
					<instrumentControlSoftware version="3.0.0 20211014">AERIS</instrumentControlSoftware>
					<instrumentID>2879380</instrumentID>
				</source>
			</header>
			<dataPoints>
				<positions axis="2Theta" unit="deg">
					<startPosition>9.99043322</startPosition>
					<endPosition>100.09495370</endPosition>
				</positions>
				<positions axis="Omega" unit="deg">
					<startPosition>4.99521661</startPosition>
					<endPosition>50.04747685</endPosition>
				</positions>
				<commonCountingTime unit="seconds">18.249</commonCountingTime>
				<counts unit="counts">5586 5623 5597 5625 5643 5781 5507 5474 5547 5660 5449 5595 5602 5614 5815 5556 5742 5524 5625 5543 5568 5617 5560 5492 5418 5485 5606 5821 5526 5559 5624 5557 5677 5682 5482 5620 5602 5637 5524 5502 5647 5528 5607 5636 5525 5555 5499 5520 5526 5496 5462 5490 5509 5576 5342 5561 5543 5494 5612 5445 5499 5461 5474 5558 5460 5423 5497 5316 5622 5448 5336 5518 5398 5517 5449 5382 5451 5335 5317 5375 5381 5459 5477 5454 5501 5304 5401 5387 5603 5436 5359 5331 5293 5391 5299 5332 5279 5405 5364 5383 5303 5461 5258 5429 5258 5304 5424 5219 5284 5457 5270 5412 5298 5315 5266 5307 5376 5332 5333 5232 5297 5350 5374 5211 5300 5290 5257 5424 5291 5299 5449 5383 5254 5264 5322 5358 5262 5449 5296 5371 5266 5311 5235 5335 5340 5265 5205 5372 5239 5342 5188 5314 5309 5267 5344 5291 5352 5228 5296 5054 5353 5190 5280 5271 5317 5345 5370 5271 5133 5198 5157 5187 5196 5157 5096 5189 5110 5179 5091 5205 5136 5183 5220 5259 5195 5241 5279 5273 5156 5142 5163 5194 5106 5142 5202 5078 5202 5203 5218 4986 5104 5100 5119 5161 4974 5025 5046 5190 5039 5251 5160 5141 5126 5093 5066 5052 5044 5139 5036 5230 5112 5093 5127 5006 5057 5183 5064 5094 5074 5022 5044 5027 5126 5068 5271 5277 4917 5049 5083 5100 5035 5117 5194 5029 5133 5025 4998 5077 5057 5092 4951 5106 5133 4955 5061 4987 5117 5007 5036 4988 4976 5147 5021 5186 4966 5030 5085 4983 5062 5093 4938 5077 5144 5216 5083 5026 4945 5037 4967 5055 5026 4983 4978 4831 4985 5137 5062 4897 5100 4965 5156 5028 4871 4991 5104 4928 4931 5010 5003 5105 4982 5076 5116 4979 4988 4991 5027 4965 4881 5087 4957 4935 4973 5018 5005 4877 4913 5018 5068 4957 4894 4782 4990 4990 5001 5025 4816 4865 4940 4915 4937 5009 5043 4813 4981 4943 4837 4974 4880 4929 4981 4966 4864 5011 4815 4940 4878 4859 4924 4848 4913 4946 4990 4835 4860 4945 4827 4881 5026 4871 4900 4885 4836 4932 5001 4988 5003 4950 4853 4843 4870 4988 5024 4793 4915 4934 4782 4764 4813 4890 4916 4788 4861 4854 4897 4854 4930 4924 4917 4793 4924 4916 4875 4838 4916 4895 4915 4791 4908 4965 5048 4923 4842 4838 4866 4834 4968 4942 4890 4823 4969 4897 4881 4808 4898 4907 4893 4860 4852 4766 4873 4867 4856 4901 4868 4812 4833 4763 4867 4898 4782 4957 4887 4873 4861 4879 4891 4940 4826 4829 4816 4859 4982 4899 4900 4757 4868 4778 4877 4902 4676 4955 4916 4744 4873 4852 4936 4895 4833 4889 4838 4814 4808 4779 4819 4838 4900 4747 4765 4840 4845 4874 4925 4745 4951 4913 4880 4775 4811 4942 4698 4858 4871 4936 4880 4938 4959 4907 4846 4880 4985 4816 4910 4963 4859 4930 4710 4910 4883 4935 4843 4818 4887 4803 4821 4866 4931 4915 4868 4826 4887 4961 4903 4943 4818 4929 4908 4806 4936 4962 4907 4828 4769 4764 4896 4751 4758 4889 4914 4852 4913 4962 4897 4904 4783 4885 4888 4885 4886 4866 4769 4875 4764 4883 4850 5029 4865 4753 4862 4887 4783 4950 4889 4872 4867 4948 4711 4943 4759 4884 4799 4942 4846 4911 4842 4944 4776 4894 4874 4779 4778 4944 4808 4804 4857 4861 4920 4856 4827 4908 4780 4769 4837 4886 4844 4957 4712 4940 4850 4846 4812 4869 4915 4993 4856 4797 4711 4835 4896 4953 4803 4842 4801 4977 4949 4962 4967 4929 5027 4760 5088 5059 4889 5041 4973 4806 4871 5015 5172 4960 5086 5115 4969 5120 5075 5069 5210 5135 5136 5433 5074 5046 5024 5026 5052 5048 4963 4925 4962 5025 4915 5042 4883 4940 5032 5072 5059 4983 5040 5158 5099 5225 5331 5337 5313 5407 5567 5837 5952 5747 5459 5437 5221 5163 5088 5005 5011 4975 4921 5020 4863 5066 4872 5000 4880 4789 5023 5018 4725 4854 4850 4886 5083 4874 4865 4865 4835 4857 4931 4981 4962 4831 4833 4743 4985 4866 4893 4967 4866 4862 4843 4887 4892 4828 4861 4811 5017 4910 4823 4813 4839 4886 5089 4923 4891 4866 4978 4853 4950 5018 4886 4931 4855 4962 4899 4869 4951 4990 4858 4836 4875 4868 4863 4742 4894 4909 5011 4946 5028 4989 5091 4920 4987 4896 4919 4953 5026 4853 4957 5051 5028 4936 5066 4907 4993 4934 5116 5095 5119 5215 5110 5157 5332 5292 5490 5582 5634 5880 5896 6039 6142 6141 6311 6339 6482 6253 6406 6370 6540 6659 6641 6804 7001 7139 7044 7165 7470 7401 7554 7881 7951 8086 8119 8230 8471 8386 8537 9096 9128 9485 9866 10189 10367 11118 11685 12880 13633 15083 16383 18514 21102 23772 27221 32000 37383 44126 52080 60863 71531 83832 97462 114054 133723 156477 182564 215626 251604 280442 276682 244499 211038 186029 161894 125025 88271 59880 41183 29063 20729 15380 12425 10840 10295 9545 9209 9030 8641 8633 8528 8598 8186 8078 7981 8116 7844 7904 7754 7669 7451 7515 7385 7323 7227 6919 6716 6602 6363 6311 6154 6094 6080 6017 5969 5821 5829 5814 5677 5661 5727 5763 5655 5576 5834 5655 5642 5660 5749 5797 5866 5917 5847 5758 6045 5964 6131 6192 6052 6255 6216 6364 6195 6122 6173 6199 6158 6149 6098 6148 5951 6014 6022 6016 5984 5709 5861 5935 5833 5997 6002 5908 5855 5968 5951 6040 5938 5996 5985 5849 5971 5883 6050 5933 6075 5987 5852 6024 5951 5980 5895 5921 5970 5833 5939 6036 5827 5936 6144 5925 5938 5934 6028 6069 5991 6146 6041 6124 6223 6169 6194 6208 6328 6404 6502 6479 6579 6686 6835 6703 6880 7168 7133 7197 7285 7178 7259 7178 7059 7015 6930 6852 6544 6499 6360 6050 6298 6140 6042 6008 5939 5966 5796 5862 5925 5898 5963 5861 5718 5772 5694 5928 5905 5967 5950 5718 5762 5715 5706 5722 5720 5792 5844 5662 5658 5735 5689 5815 5675 5656 5580 5582 5591 5402 5693 5566 5570 5506 5655 5585 5641 5506 5492 5570 5502 5656 5486 5409 5518 5559 5415 5523 5522 5514 5447 5480 5491 5379 5441 5379 5543 5455 5360 5537 5383 5546 5530 5496 5475 5411 5304 5402 5257 5332 5572 5534 5700 5407 5429 5508 5604 5555 5538 5652 5639 5712 5613 5879 5857 5826 5789 5933 6054 6131 6108 6201 6444 6422 6507 6141 6219 6093 5952 5794 5894 5785 5470 5420 5419 5364 5372 5366 5347 5301 5353 5367 5204 5463 5243 5187 5287 5356 5384 5228 5271 5240 5265 5251 5270 5318 5301 5301 5295 5202 5228 5384 5168 5174 5112 5304 5054 5175 5317 5296 5168 5297 5287 5138 5183 5254 5115 5177 5310 5124 5230 5267 5105 5324 5271 5287 5084 5176 5154 5233 5063 5133 5025 5099 5141 5198 5289 5115 5140 5086 5097 5131 5119 5160 4974 5187 5086 5056 5111 5181 5179 5114 5155 5115 5130 5265 5142 4998 5153 5255 5125 5226 5111 5007 5144 5225 4979 5021 5146 5130 5302 5101 5193 4988 5263 5169 5005 5051 5092 5022 5091 4989 5016 5104 4947 4976 5076 5114 4906 5092 5044 4977 5071 5075 5081 5014 5040 4911 5066 4991 5103 4998 5005 5047 4864 5085 4925 4948 5066 4885 5027 5003 4959 5076 4985 5023 4994 5003 5038 4855 4984 5037 4842 4975 4929 4975 5020 5032 4996 5112 5108 4975 5092 5021 4938 4917 5118 5031 5095 4864 4881 4972 5057 4943 4852 4886 5051 4834 4868 4988 4889 5001 4938 4926 4763 5006 5004 4933 4988 4917 4945 5001 4927 5068 5021 4990 4962 4957 5032 4873 4918 4918 4985 4887 4847 4959 4817 4857 4876 4940 4945 4984 4795 4946 4916 4988 4933 4858 4812 4831 4830 4952 4906 4901 4946 4930 4925 4757 4842 4893 4853 4973 4996 5022 5088 5137 5174 5294 5241 5274 5177 5419 5477 5511 5661 5857 5952 6139 6164 6180 6447 6577 6478 6317 6277 5970 5982 5750 5715 5428 5451 5332 5213 5139 5102 5070 4911 5145 5092 5072 4955 5025 5035 5023 5036 5157 5017 5055 5096 5197 5079 5160 5182 4996 5146 5108 5190 5174 5319 5234 5281 5352 5357 5583 5522 5734 5674 5720 5675 6035 6162 6414 6525 6674 6978 7357 7689 8120 8697 9179 10069 10686 11584 12327 13315 14566 15326 16392 17216 17941 18519 18357 17659 16986 16029 14789 13552 12413 11386 10051 9113 8423 7649 6979 6488 6459 6197 5940 5957 5897 5988 5821 5825 5964 6021 6160 6026 6096 6127 6570 6639 6952 7075 7401 7675 7961 8223 8944 9422 9893 10155 10694 10556 10657 10371 10210 10214 10528 10601 10858 11164 11571 11780 12762 13146 14005 14687 14939 15461 15334 15128 14787 13953 12808 12172 11236 10461 9647 8741 8272 7589 7089 6730 6445 6144 5997 5670 5859 5622 5528 5498 5363 5510 5350 5350 5319 5209 5209 5236 5277 5061 5073 5003 5024 5060 5179 5092 5277 4991 5145 5003 5077 5156 5042 5057 5180 5018 5024 5043 5015 5061 4948 5005 5011 5012 4981 5105 4969 5081 4915 4929 5060 4948 4994 5065 5219 5138 5203 5296 5285 5514 5434 5612 5848 5864 5982 6362 6590 6931 7319 7830 8038 8664 9519 9885 10471 11317 11872 11989 12032 11669 11073 10380 9511 8944 8421 7988 7355 6903 6497 6160 5710 5721 5561 5779 5649 5864 5910 5866 5907 6080 6333 6421 6598 6986 7355 7784 8436 9002 9857 10703 11854 13625 15056 16777 18518 20866 23231 25983 28589 30835 32941 33212 31991 28900 25949 23112 20898 19322 17331 15171 12761 10350 8589 7444 6684 6211 5977 5791 5651 5459 5491 5230 5447 5251 5266 5246 5225 5191 5225 5117 5133 5192 5172 5065 5133 5203 5027 5265 5140 5212 5276 5215 5392 5336 5365 5514 5975 6046 6113 6426 6710 7055 7471 7879 8469 8959 9261 9549 9284 9111 8532 7826 7376 7334 6882 6619 6271 5815 5533 5216 5172 5061 4790 4955 4681 4894 4809 4859 4606 4754 4871 4627 4786 4734 4694 4686 4569 4704 4736 4707 4642 4668 4705 4610 4607 4650 4698 4654 4636 4725 4632 4812 4661 4622 4635 4736 4625 4574 4645 4754 4589 4512 4753 4568 4522 4523 4603 4578 4455 4694 4622 4646 4560 4629 4599 4535 4493 4576 4705 4604 4549 4560 4637 4601 4727 4523 4663 4520 4547 4356 4565 4476 4521 4563 4556 4681 4582 4527 4634 4596 4608 4471 4648 4465 4571 4627 4635 4584 4565 4578 4572 4504 4532 4586 4615 4653 4579 4521 4523 4542 4625 4660 4539 4658 4500 4578 4607 4452 4430 4707 4524 4423 4498 4518 4427 4628 4564 4650 4421 4477 4494 4559 4473 4632 4583 4626 4600 4629 4608 4473 4478 4620 4572 4468 4506 4526 4611 4585 4487 4522 4542 4501 4647 4572 4533 4587 4500 4459 4619 4656 4542 4662 4441 4554 4547 4450 4479 4575 4537 4647 4559 4598 4555 4454 4432 4655 4593 4502 4658 4478 4426 4686 4471 4550 4342 4446 4561 4509 4481 4472 4412 4389 4498 4519 4647 4567 4466 4461 4505 4435 4556 4598 4612 4552 4510 4596 4516 4575 4500 4426 4497 4542 4474 4526 4552 4459 4448 4361 4526 4427 4618 4527 4487 4520 4590 4475 4413 4435 4533 4474 4438 4494 4461 4449 4481 4449 4532 4463 4446 4498 4426 4441 4452 4419 4441 4353 4468 4337 4592 4416 4479 4402 4410 4444 4617 4608 4320 4367 4439 4510 4376 4385 4459 4443 4435 4389 4460 4349 4455 4369 4390 4362 4489 4388 4500 4492 4360 4316 4376 4589 4542 4223 4324 4522 4432 4407 4349 4321 4443 4393 4345 4502 4428 4408 4342 4421 4420 4279 4316 4343 4276 4424 4327 4520 4351 4519 4556 4365 4419 4423 4391 4340 4397 4389 4389 4270 4436 4336 4320 4307 4408 4396 4444 4383 4358 4456 4410 4469 4468 4298 4424 4458 4321 4393 4393 4352 4320 4413 4267 4349 4353 4425 4491 4527 4513 4323 4374 4316 4429 4467 4457 4457 4418 4466 4296 4359 4293 4401 4436 4415 4387 4409 4517 4580 4373 4397 4416 4499 4344 4355 4397 4347 4399 4466 4477 4436 4398 4438 4461 4466 4405 4436 4351 4425 4339 4501 4499 4489 4481 4396 4392 4397 4402 4438 4507 4524 4673 4523 4641 4580 4632 4602 4774 4944 4874 4905 5036 5303 5321 5573 5418 5584 5588 5413 5218 5240 5037 5215 5152 4918 4861 4855 4724 4676 4765 4599 4628 4613 4605 4562 4604 4559 4695 4728 4698 4656 4639 4712 4689 4757 4830 4942 5070 5041 4955 5220 5238 5445 5555 5883 6031 6421 6964 7350 8063 8832 9322 10292 10972 12049 12205 12463 12311 11613 10939 10528 10239 10036 10132 10249 10285 10164 10380 10728 11099 12000 12502 13180 13488 13588 13479 12965 12263 11006 10462 9945 9454 9035 8430 7935 7132 6366 5873 5570 5137 5038 4931 4740 4780 4693 4783 4803 4649 4673 4475 4688 4492 4602 4453 4441 4488 4564 4446 4507 4370 4496 4575 4434 4381 4520 4557 4368 4464 4402 4429 4534 4435 4530 4462 4515 4630 4546 4661 4535 4701 4632 4731 4922 5092 4984 5203 5482 5461 5452 5467 5555 5337 5361 5025 4997 5068 4970 4990 4697 4766 4687 4570 4532 4519 4415 4382 4404 4386 4372 4538 4496 4498 4336 4313 4411 4354 4462 4416 4351 4467 4431 4337 4401 4329 4298 4375 4352 4297 4298 4380 4297 4361 4434 4284 4361 4456 4400 4262 4365 4289 4347 4504 4420 4367 4495 4384 4424 4471 4608 4449 4438 4388 4350 4439 4377 4423 4394 4349 4460 4237 4355 4434 4570 4396 4395 4399 4472 4416 4357 4477 4462 4488 4455 4505 4692 4637 4624 4752 4750 4866 5023 5464 5499 5596 5998 6207 6573 6866 7433 7307 7592 7379 7197 6871 6333 6239 6136 6137 6045 5791 5613 5422 5140 5015 4700 4724 4727 4716 4672 4606 4710 4599 4684 4752 4974 4977 5081 5239 5328 5597 5715 5937 6194 6322 6372 6082 5848 5652 5564 5440 5427 5530 5224 5250 5015 4978 4751 4672 4431 4480 4609 4376 4668 4528 4504 4575 4639 4441 4450 4364 4374 4428 4487 4597 4522 4708 4463 4649 4794 4737 4725 4957 4812 5182 5296 5325 5690 5879 6099 6210 6097 6223 6154 5989 5987 5984 6129 6001 5961 5992 5533 5390 5296 5218 5106 5116 5079 4857 4750 4865 4744 4666 4528 4533 4508 4507 4381 4581 4469 4473 4485 4417 4471 4339 4502 4334 4409 4376 4482 4383 4342 4349 4372 4487 4308 4323 4335 4449 4377 4335 4385 4341 4366 4331 4359 4440 4349 4365 4430 4431 4242 4269 4336 4554 4439 4468 4502 4422 4276 4432 4471 4449 4425 4376 4504 4409 4337 4405 4478 4455 4486 4495 4637 4526 4695 4690 4903 4855 4938 5146 5200 5435 5720 5891 6130 6181 6452 6378 6315 6088 5808 5666 5490 5365 5503 5358 5447 5391 5124 5025 4637 4630 4490 4510 4524 4597 4507 4605 4579 4702 4439 4513 4580 4639 4636 4648 4780 4774 4784 4940 5104 5269 5550 5686 5723 5910 6225 6169 6262 6004 5764 5774 5666 5752 5892 5924 5889 6058 6092 6166 6338 6576 6911 7019 7239 7209 7396 6895 6692 6412 6402 6331 6450 6415 6621 6637 6532 6560 6695 6785 6759 6838 7156 7118 7088 7069 6792 6669 6615 6505 6374 6353 6373 6332 6423 6293 6310 6196 6343 6555 6728 6907 6914 7073 7177 7015 6878 6810 6549 6408 6336 6198 6101 6079 5965 5735 5693 5399 5368 5167 5036 5079 4994 5035 5087 5124 5380 5279 5561 5647 5945 6424 6782 7733 8665 10021 11525 13767 16123 18924 22395 23554 21641 17035 13515 11324 10726 11002 12297 13480 13890 13062 11036 9056 7232 6289 5805 5645 5350 5325 5132 5137 5011 5130 5015 4943 4913 4809 4815 4763 4665 4597 4614 4583 4517 4410 4612 4576 4487 4527 4512 4488 4469 4522 4496 4528 4357 4492 4555 4444 4442 4516 4556 4561 4792 4674 4785 4679 4731 4871 5200 5056 5033 4944 4934 4754 4743 4730 4679 4775 4793 4547 4730 4606 4622 4472 4489 4513 4393 4572 4635 4556 4618 4597 4685 4757 4733 4794 4931 5097 5308 5171 5413 5511 5601 5551 5726 5636 5638 5441 5395 5510 5372 5218 5162 5262 5099 4906 5010 4916 4782 4655 4663 4638 4637 4425 4458 4402 4405 4330 4382 4444 4346 4383 4353 4395 4324 4383 4302 4407 4315 4364 4350 4341 4276 4424 4378 4355 4328 4415 4459 4313 4675 4476 4771 4755 4810 4767 5112 5358 5457 5364 5510 5288 5077 4874 4805 4731 4906 4775 4967 4839 4756 4634 4584 4409 4347 4514 4365 4473 4274 4219 4283 4407 4269 4273 4310 4273 4342 4420 4187 4238 4220 4227 4212 4269 4320 4403 4383 4215 4425 4353 4300 4351 4202 4306 4361 4206 4404 4282 4294 4265 4349 4399 4476 4455 4463 4419 4287 4379 4343 4322 4481 4439 4375 4441 4262 4402 4236 4338 4306 4283 4310 4255 4212 4297 4237 4325 4342 4241 4207 4249 4202 4208 4313 4293 4293 4272 4295 4220 4251 4376 4131 4239 4294 4239 4335 4312 4349 4219 4322 4396 4360 4379 4361 4239 4271 4270 4329 4376 4286 4355 4378 4408 4475 4357 4368 4458 4446 4408 4499 4537 4512 4546 4710 4711 4878 4957 5090 5214 5314 5297 5289 5242 4947 5111 4953 4828 4866 5043 4921 4986 4857 4801 4872 4866 4869 4853 4715 4958 5098 5107 5204 5432 5527 5943 5929 6164 6379 6387 6509 6384 6317 6259 6218 6058 6168 6327 6356 6245 6227 6100 5911 5876 5632 5384 5215 5292 4985 5071 4937 4810 4922 4834 4622 4521 4667 4549 4486 4435 4527 4312 4497 4448 4500 4336 4425 4503 4543 4374 4494 4506 4439 4564 4605 4602 4738 4950 5013 5140 5423 5433 5608 5622 5703 5670 5349 5267 4851 5017 4845 5083 4983 5004 5054 4859 4611 4747 4539 4427 4391 4249 4582 4352 4208 4356 4313 4304 4366 4315 4306 4329 4334 4293 4302 4285 4203 4275 4245 4298 4224 4258 4274 4268 4289 4213 4250 4237 4405 4293 4306 4347 4234 4238 4225 4206 4263 4166 4264 4232 4140 4331 4089 4168 4268 4314 4229 4145 4159 4238 4304 4194 4362 4217 4239 4215 4165 4258 4442 4369 4217 4295 4236 4129 4165 4236 4242 4279 4259 4222 4348 4360 4265 4232 4242 4199 4190 4160 4127 4185 4179 4411 4256 4358 4265 4221 4260 4190 4277 4138 4183 4181 4145 4206 4332 4284 4262 4186 4312 4334 4230 4123 4311 4112 4211 4240 4296 4222 4348 4256 4244 4099 4336 4210 4399 4240 4256 4233 4341 4279 4388 4325 4182 4267 4334 4200 4306 4081 4269 4182 4180 4234 4215 4354 4272 4161 4261 4222 4229 4126 4244 4234 4178 4123 4230 4309 4118 4124 4191 4226 4252 4243 4258 4260 4324 4279 4321 4364 4426 4388 4455 4427 4535 4704 4606 4545 4449 4472 4532 4430 4521 4401 4383 4418 4416 4328 4270 4316 4303 4433 4314 4205 4371 4252 4347 4212 4348 4265 4229 4335 4288 4276 4352 4196 4324 4367 4368 4372 4264 4309 4392 4324 4234 4329 4415 4277 4383 4353 4372 4420 4459 4446 4444 4550 4503 4395 4451 4493 4503 4584 4467 4608 4518 4491 4569 4690 4617 4684 4671 4747 4820 4909 5051 5132 5420 5580 5946 5951 6376 6438 6707 6741 6981 7452 7918 8429 9138 9266 9494 8917 8486 7722 7098 6628 6508 6453 6667 6820 6759 6676 6381 5976 5562 5177 4964 4796 4749 4557 4726 4490 4607 4520 4523 4548 4459 4422 4379 4317 4388 4346 4477 4398 4460 4181 4272 4296 4372 4238 4244 4230 4244 4217 4269 4258 4268 4342 4170 4411 4335 4360 4271 4363 4332 4189 4337 4218 4321 4371 4441 4306 4319 4411 4409 4137 4234 4236 4341 4271 4314 4408 4305 4248 4400 4494 4442 4433 4336 4458 4544 4493 4537 4574 4527 4577 4858 4827 4906 5026 5298 5678 5972 6394 6780 7562 8214 8843 9271 9571 9603 9274 8705 8056 7291 7082 6851 7008 6945 7230 7227 7041 6819 6361 5849 5737 5233 4988 4753 4711 4581 4477 4525 4575 4467 4447 4416 4446 4389 4312 4329 4276 4331 4360 4328 4450 4301 4297 4361 4201 4345 4349 4242 4276 4289 4294 4177 4207 4256 4309 4231 4151 4227 4391 4248 4313 4318 4245 4396 4286 4173 4212 4424 4274 4339 4325 4391 4340 4313 4203 4438 4331 4369 4248 4338 4299 4224 4466 4319 4211 4359 4239 4218 4404 4299 4295 4200 4240 4209 4268 4208 4246 4273 4325 4393 4328 4364 4498 4488 4577 4495 4586 4669 4676 4560 4559 4535 4623 4631 4739 4613 4663 4790 4867 5020 4999 5086 4985 4856 4885 4574 4681 4615 4692 4621 4591 4529 4575 4569 4557 4560 4526 4549 4513 4410 4471 4498 4404 4500 4466 4591 4557 4429 4538 4784 4701 4854 5071 5216 5371 5469 5688 6133 6382 6760 7151 7577 7623 7692 7410 7164 6917 6627 6446 6401 6279 6218 6253 6510 6366 6284 6265 5820 5838 5674 5404 5489 5322 5509 5450 5518 5345 5407 5265 5395 5483 5634 5800 5872 6055 6234 6161 6161 6074 5930 5495 5425 5258 5384 5562 5723 5954 6126 6400 6605 6843 7093 7445 7210 7079 6931 6582 6313 6505 6385 6459 6406 6286 6332 6426 6189 6050 5878 5688 5312 5324 5197 5146 5044 5007 4888 4710 4766 4766 4697 4537 4500 4534 4451 4388 4516 4461 4354 4419 4267 4354 4416 4380 4443 4324 4258 4524 4327 4339 4359 4333 4288 4294 4327 4305 4343 4317 4340 4329 4256 4388 4307 4321 4336 4521 4391 4293 4392 4347 4361 4444 4487 4453 4542 4651 4951 5005 5154 5305 5526 5849 5878 6038 5988 5719 5578 5256 5052 4985 4987 5063 5005 5077 5063 5086 5144 5107 5036 4782 4504 4511 4469 4471 4409 4337 4481 4167 4265 4288 4372 4329 4267 4279 4290 4216 4333 4453 4370 4394 4456 4305 4496 4607 4794 4798 4928 5166 5257 5308 5455 5327 5109 5012 4860 4844 4640 4587 4438 4653 4789 4796 4871 4798 4807 4492 4439 4373 4285 4313 4375 4152 4193 4276 4216 4239 4242 4310 4221 4212 4404 4331 4271 4311 4289 4276 4308 4314 4329 4431 4284 4413 4467 4361 4225 4157 4297 4238 4301 4343 4454 4343 4243 4241 4344 4244 4241 4404 4250 4309 4303 4287 4183 4237 4361 4188 4188 4203 4270 4271 4100 4144 4279 4230 4179 4250 4424 4416 4332 4333 4328 4227 4311 4334 4182 4119 4219 4216 4337 4332 4342 4193 4242 4252 4353 4134 4215 4112 4173 4361 4191 4201 4259 4225 4213 4184 4314 4205 4262 4326 4181 4207 4243 4253 4258 4202 4270 4435 4241 4407 4400 4344 4446 4469 4486 4504 4531 4643 4492 4330 4437 4378 4389 4381 4391 4399 4534 4364 4547 4419 4414 4454 4459 4324 4528 4212 4532 4418 4351 4567 4562 4719 4736 4898 5109 5226 5357 5321 5544 5628 5749 5754 5669 5453 5215 5064 4937 5003 5016 4967 5087 5074 5278 5276 5306 5218 5347 5407 5385 5658 5708 5809 5881 5779 5432 5489 5169 4981 4902 4907 5007 5057 5186 5212 5246 5317 5210 5089 4978 4912 4727 4638 4673 4545 4601 4500 4612 4494 4581 4508 4561 4532 4798 4809 5013 5094 5478 5801 6163 6714 6995 7440 7671 7506 7445 6719 6288 5674 5575 5411 5386 5369 5660 5773 5813 5983 5772 5774 5507 5129 4969 4768 4552 4488 4362 4513 4507 4385 4519 4410 4504 4437 4346 4452 4467 4338 4398 4463 4294 4415 4399 4374 4389 4469 4480 4383 4407 4451 4674 4756 4659 4870 4960 5211 5345 5712 6005 6367 6430 6678 6625 6634 6533 6327 5808 5594 5333 5337 5251 5357 5475 5653 5625 5623 5549 5361 5381 5094 5072 4811 4703 4784 4722 4687 4638 4691 4698 4789 4957 5026 4995 5094 5023 4991 4937 4803 4785 4707 4731 4735 4747 4676 4764 4753 4742 4746 4701 4749 4630 4578 4490 4520 4503 4447 4412 4507 4366 4466 4507 4525 4416 4349 4585 4386 4446 4531 4407 4448 4481 4507 4708 4614 4740 4969 4958 5067 5174 5545 5717 5870 6011 6214 6269 6023 6126 5723 5751 5565 5401 5370 5335 5313 5328 5337 5450 5338 5167 5220 5173 5022 4699 4850 4681 4709 4562 4657 4385 4535 4592 4503 4482 4449 4400 4293 4440 4369 4467 4226 4333 4322 4331 4318 4532 4330 4422 4359 4468 4261 4308 4366 4420 4343 4343 4458 4279 4270 4278 4368 4403 4266 4474 4400 4412 4451 4402 4392 4275 4380 4413 4293 4482 4493 4503 4606 4726 4885 4865 5153 5437 5843 6116 6476 7153 7320 7469 7421 6876 6374 5951 5543 5360 5286 5291 5418 5643 5777 6033 6274 6123 5997 5945 5782 5679 5510 5748 5809 5744 6085 6267 6160 6265 6175 6053 5866 5638 5385 5420 5256 5262 5427 5310 5288 5428 5248 5502 5264 5090 4948 4930 4906 4845 4764 4570 4538 4562 4515 4743 4590 4828 4833 5068 5149 5473 5723 5830 5900 6053 5883 5521 5454 5255 5343 5055 5149 4993 5016 5001 5239 5091 5055 4955 5036 4977 4813 4871 4697 4672 4501 4560 4447 4482 4271 4472 4536 4403 4282 4516 4480 4544 4738 4768 4919 5091 5325 5450 5564 5813 5786 5889 5606 5471 5103 4844 4699 4710 4713 4733 4794 4873 4909 5023 5099 4930 4920 4800 4711 4574 4444 4406 4405 4377 4255 4319 4271 4211 4390 4533 4331 4398 4373 4480 4543 4465 4424 4447 4414 4360 4289 4404 4563 4318 4421 4313 4407 4305 4485 4528 4458 4472 4458 4495 4628 4497 4515 4604 4438 4432 4372 4266 4292 4505 4349 4283 4372 4352 4393 4338 4347 4298 4292 4302 4277 4287 4202 4124 4212 4162 4239 4298 4191 4282 4212 4248 4171 4306 4266 4319 4287 4209 4318 4248 4132 4225 4338 4254 4265 4125 4236 4259 4188 4238 4249 4273 4282 4300 4355 4229 4131 4206 4197 4224 4246 4167 4213 4203 4239 4225 4116 4130 4173 4263 4148 4287 4207 4361 4206 4267 4230 4180 4374 4187 4286 4229 4365 4311 4201 4318 4159 4326 4292 4263 4362 4146 4381 4285 4326 4249 4283 4292 4264 4215 4207 4287 4270 4201 4357 4295 4318 4328 4462 4311 4425 4615 4580 4693 4747 5013 5070 5210 5292 5320 5227 5293 5095 5273 5305 5482 5545 5590 5463 5653 5385 5344 5268 5244 5107 5140 5118 5088 5027 4942 4842 5059 4969 4820 4734 4758 4637 4527 4526 4524 4549 4541 4479 4459 4482 4600 4595 4660 4724 4949 5074 5070 5487 5525 5679 5754 5442 5486 5303 5008 4998 4756 4753 4663 4820 4912 4850 4995 5159 5143 5109 4920 4860 4804 4705 4668 4750 4743 4841 4701 4907 4879 4892 4904 4836 4651 4707 4531 4755 4611 4636 4808 4943 4972 5059 5271 5165 5442 5602 5676 5856 5691 5867 5958 6052 6007 5900 5815 5624 5587 5549 5594 5476 5654 5745 5653 5932 5956 5980 6253 6324 6113 6331 6569 6476 6667 6602 6689 6790 6952 7413 8360 9615 10747 11126 10777 9088 7793 6821 6248 6052 5697 5639 5566 5905 5936 6384 6736 7205 7417 7020 6582 5615 5223 4870 4662 4632 4513 4464 4577 4447 4513 4453 4621 4485 4421 4293 4552 4536 4593 4822 4747 4828 4907 5015 5148 5230 5361 5230 5019 5006 4836 4844 4636 4648 4609 4616 4648 4655 4743 4798 4719 4756 4679 4715 4698 4577 4514 4516 4369 4420 4402 4309 4475 4480 4285 4342 4420 4345 4351 4321 4449 4357 4394 4321 4251 4302 4313 4303 4427 4309 4181 4244 4228 4245 4267 4120 4175 4203 4320 4373 4263 4158 4229 4274 4307 4126 4187 4245 4194 4100 4128 4251 4170 4280 4119 4103 4263 4187 4145 4287 4230 4309 4165 4183 4313 4294 4221 4177 4216 4277 4288 4427 4270 4194 4194 4320 4247 4281 4228 4271 4136 4247 4264 4172 4161 4308 4149 4175 4182 4172 4103 4217 4199 4221 4314 4283 4285 4155 4229 4285 4120 4168 4183 4236 4186 4081 4231 4291 4162 4147 4230 4119 4167 4228 4159 4360 4255 4148 4107 4169 4184 4089 4141 4181 4244 4345 4250 4193 4318 4182 4309 4289 4253 4220 4128 4310 4201 4167 4239 4163 4232 4245 4290 4201 4284 4373 4268 4393 4314 4337 4307 4556 4688 4602 4645 4819 5079 5155 5235 5259 5306 5298 5163 4962 4857 4737 4761 4611 4878 4866 5066 5096 5166 5163 5283 5291 5302 5155 4939 4879 4821 4857 4866 4912 4853 5139 5105 5252 5473 5336 5404 5284 5260 5092 4953 4910 4691 4684 4564 4391 4606 4570 4688 4661 4748 4911 4884 4822 4709 4781 4730 4713 4507 4752 4580 4684 4619 4631 4576 4444 4587 4631 4387 4451 4509 4441 4523 4483 4763 4771 4731 4956 4991 4867 5063 5034 4828 4831 4870 4740 4724 4661 4624 4928 5065 5047 5205 5262 5340 5282 5256 5217 5023 4977 4945 4808 4957 4926 4822 4907 5101 5070 5206 5208 5423 5608 5573 5785 5745 5868 5756 5712 5565 5425 5227 5128 4915 4842 4904 4838 4741 4873 4939 5031 5051 5022 4861 5026 4739 4756 4737 4605 4547 4414 4447 4385 4309 4329 4389 4362 4295 4388 4260 4418 4288 4246 4281 4324 4258 4262 4429 4285 4264 4198 4175 4290 4175 4042 4269 4156 4171 4153 4116 4255 4155 4286 4186 4221 4212 4195 4109 4230 4234 4236 4354 4267 4224 4434 4395 4407 4491 4365 4510 4654 4421 4490 4616 4811 4807 4809 4914 4881 4900 4687 4620 4411 4456 4458 4456 4500 4431 4581 4515 4519 4552 4612 4646 4461 4492 4351 4262 4344 4297 4537 4180 4326 4351 4192 4356 4211 4175 4203 4173 4234 4266 4280 4244 4100 4167 4285 4080 4342 4187 4285 4258 4206 4211 4200 4174 4135 4196 4232 4281 4190 4160 4066 4143 4143 4118 4160 4171 4285 4198 4120 4265 4229 4216 4058 4092 4195 4245 4223 4225 4239 4170 4138 4168 4102 4224 4236 4088 4191 4131 4082 4199 4258 4247 4224 4203 4295 4190 4211 4209 4243 4103 4120 4221 4264 4242 4253 4292 4357 4317 4212 4214 4237 4292 4180 4235 4162 4217 4295 4195 4084 4253 4273 4315 4298 4262 4264 4329 4158 4252 4205 4262 4390 4314 4224 4172 4157 4204 4109 4247 4358 4214 4228 4180 4281 4284 4229 4239 4316 4185 4248 4182 4378 4339 4332 4297 4259 4337 4227 4248 4268 4361 4367 4258 4510 4434 4475 4488 4488 4629 4798 4696 4814 5010 5025 5205 5471 5540 5611 5647 5670 5475 5227 5171 4972 4713 4780 4706 4777 4734 4803 4996 5061 4948 5173 5213 5330 5361 5415 5369 5272 5286 5477 5513 5354 5421 5409 5266 5142 5153 5042 4911 4937 4899 4822 4795 4881 4898 4832 5165 5086 4963 5134 5210 5222 5253 5226 5429 5458 5381 5383 5497 5569 5632 5468 5387 5318 5259 5256 5040 5117 5051 5007 4913 4985 4999 5026 5026 5269 5292 5189 5338 5349 5576 5346 5397 5324 5351 5181 5239 5196 5332 5226 5223 5197 5086 5040 4908 4784 4862 4770 4773 4774 4796 4790 4738 4690 4856 4771 4787 4788 4816 4716 4648 4613 4635 4608 4580 4496 4552 4499 4443 4427 4447 4297 4430 4522 4397 4490 4390 4592 4758 4710 4857 4869 5070 5053 4995 5077 4982 4966 5037 4934 5223 5229 5180 5228 5109 5278 5134 5263 5439 5521 5385 5334 5440 5306 5062 5145 5095 5188 5121 4966 5019 5021 4776 4856 4828 4840 4672 4752 4739 4608 4613 4475 4690 4569 4466 4384 4412 4312 4365 4382 4247 4396 4265 4294 4252 4329 4312 4301 4285 4361 4317 4328 4233 4361 4357 4235 4210 4243 4213 4321 4189 4200 4184 4186 4197 4380 4147 4238 4317 4255 4453 4280 4128 4300 4291 4229 4291 4332 4230 4372 4371 4341 4337 4324 4391 4399 4397 4458 4572 4638 4802 4821 4647 4690 4616 4584 4420 4372 4426 4402 4275 4319 4382 4356 4284 4526 4419 4547 4500 4647 4421 4472 4581 4401 4278 4367 4234 4283 4199 4191 4259 4260 4232 4188 4333 4371 4242 4165 4258 4163 4281 4210 4159 4266 4200 4287 4408 4291 4272 4326 4282 4243 4390 4371 4337 4496 4409 4361 4490 4601 4766 4912 4917 4970 4977 5057 4900 4837 4614 4776 4619 4518 4564 4622 4493 4715 4822 4842 4960 5128 5178 5266 5293 5333 5264 5173 4990 4928 4669 4786 4667 4757 4586 4691 4736 4646 4714 4687 4747 4914 4797 4688 4622 4592 4572 4461 4447 4377 4477 4293 4398 4238 4341 4383 4306 4312 4221 4391 4391 4281 4334 4165 4357 4247 4367 4357 4402 4206 4333 4299 4186 4462 4237 4421 4311 4367 4339 4180 4239 4169 4214 4158 4241 4194 4305 4457 4425 4263 4412 4339 4347 4428 4368 4413 4450 4435 4515 4462 4521 4632 4649 4724 4715 4832 5060 5083 5199 5035 4994 5115 4897 4898 4794 4707 4854 4803 4898 4882 5018 4891 4993 4867 4941 4800 4893 4843 4854 4886 4826 4814 4763 4986 4862 4928 5021 5139 5226 5058 5284 4946 4842 4937 4777 4669 4616 4534 4532 4566 4420 4534 4623 4581 4822 4800 4830 4741 4865 4895 4870 5034 5032 4917 5025 4993 5014 4989 4865 4800 4753 4516 4593 4519 4596 4505 4538 4442 4515 4757 4640 4726 4635 4624 4585 4492 4586 4522 4438 4495 4484 4442 4485 4403 4467 4331 4411 4399 4404 4278 4304 4285 4254 4306 4234 4388 4289 4194 4365 4250 4376 4468 4382 4472 4597 4324 4434 4546 4481 4508 4434 4521 4422 4311 4263 4323 4255 4299 4323 4276 4335 4339 4363 4348 4277 4456 4246 4397 4345 4397 4392 4352 4272 4318 4268 4274 4170 4464 4307 4385 4303 4344 4231 4420 4224 4365 4350 4442 4499 4432 4457 4631 4677 4934 5076 5211 5378 5426 5489 5343 5358 5164 5206 5124 5081 4857 4810 4796 4792 4655 4919 4731 4837 4883 4859 4796 4976 4968 4773 4680 4701 4591 4748 4635 4674 4516 4574 4504 4361 4305 4346 4287 4442 4346 4100 4254 4262 4210 4191 4342 4159 4202 4178 4297 4192 4281 4118 4234 4406 4378 4334 4471 4437 4540 4559 4437 4620 4395 4461 4338 4232 4266 4275 4226 4313 4221 4249 4368 4162 4410 4258 4378 4420 4387 4381 4471 4701 4573 4526 4557 4733 4616 4761 4842 4762 4664 4664 4525 4531 4487 4430 4301 4218 4302 4316 4496 4327 4365 4327 4351 4479 4319 4452 4443 4444 4441 4291 4259 4244 4365 4180 4254 4302 4192 4208 4224 4245 4132 4200 4172 4154 4180 4148 4139 4225 4156 4154 4293 4129 4164 4234 4278 4225 4261 4212 4065 4163 4205 4160 4084 4120 4210 4177 4215 4076 4119 4186 4221 4320 4198 4166 4197 4269 4102 4223 4235 4200 4052 4260 4231 4199 4168 4154 4237 4122 4125 4284 4256 4159 4205 4047 4217 4180 4282 4237 4235 4130 4179 4177 4176 4233 4231 4393 4261 4314 4311 4314 4258 4288 4194 4258 4289 4284 4095 4272 4285 4283 4086 4297 4206 4218 4288 4236 4425 4293 4471 4330 4468 4326 4506 4564 4471 4660 4586 4482 4605 4513 4761 4519 4541 4619 4598 4570 4505 4536 4504 4468 4439 4427 4458 4624 4508 4591 4513 4549 4784 4918 4903 4974 4787 4668 4792 4555 4576 4492 4461 4411 4360 4337 4296 4332 4406 4406 4433 4428 4431 4424 4505 4522 4381 4497 4477 4497 4452 4499 4433 4596 4569 4652 4540 4710 4704 4696 4760 4743 4666 4532 4560 4446 4452 4352 4477 4306 4323 4271 4304 4374 4336 4296 4388 4491 4540 4522 4417 4476 4559 4290 4371 4354 4353 4316 4249 4247 4264 4302 4215 4250 4337 4364 4125 4290 4376 4233 4340 4258 4399 4345 4417 4528 4428 4484 4681 4629 4595 4635 4577 4693 4650 4899 4901 5183 5016 5047 5170 5096 5117 4963 4885 4874 4661 4755 4649 4576 4603 4557 4531 4511 4627 4393 4605 4755 4734 4609 4536 4606 4510 4483 4492 4492 4343 4416 4287 4400 4289 4281 4213 4295 4210 4186 4241 4253 4358 4159 4288 4231 4144 4287 4300 4263 4167 4220 4234 4212 4226 4261 4270 4349 4242 4224 4220 4310 4100 4192 4150 4266 4239 4007 4152 4127 4137 4333 4174 4196 4350 4124 4200 4182 4116 4230 4101 4307 4067 4227 4248 4192 4363 4243 4309 4253 4385 4446 4381 4463 4514 4515 4370 4424 4398 4440 4323 4428 4321 4310 4334 4296 4244 4239 4354 4370 4468 4416 4312 4308 4380 4456 4569 4354 4363 4319 4285 4312 4393 4296 4306 4325 4254 4231 4277 4232 4230 4206 4348 4162 4266 4206 4247 4323 4140 4284 4190 4273 4171 4333 4150 4249 4228 4106 4233 4159 4174 4203 4067 4210 4225 4138 4157 4164 4219 4119 4198 4283 4216 4325 4102 4219 4214 4158 4105 4086 4277 4153 4204 4161 4171 4139 4173 4138 4329 4208 4175 4259 4264 4323 4305 4291 4211 4341 4366 4480 4401 4542 4529 4409 4545 4480 4539 4483 4521 4497 4444 4601 4528 4676 4443 4609 4599 4714 4652 4643 4629 4618 4621 4514 4505 4569 4467 4499 4525 4447 4444 4597 4545 4615 4519 4648 4530 4729 4753 4729 4863 4786 4698 4764 4834 4898 4821 4790 4745 4804 4678 4620 4589 4376 4591 4583 4488 4551 4484 4417 4468 4526 4466 4506 4479 4377 4429 4512 4462 4518 4391 4485 4448 4392 4418 4271 4270 4325 4259 4268 4233 4346 4168 4180 4143 4333 4110 4176 4158 4230 4385 4201 4156 4097 4340 4133 4199 4211 4281 4330 4133 4295 4298 4120 4308 4278 4287 4395 4105 4188 4345 4326 4208 4279 4305 4303 4278 4333 4357 4467 4338 4408 4500 4499 4340 4400 4531 4457 4560 4552 4494 4588 4680 4540 4534 4461 4512 4455 4507 4592 4463 4565 4673 4715 4722 4686 4821 4778 4767 4794 4780 4670 4732 4710 4551 4551 4493 4443 4496 4476 4448 4385 4462 4381 4292 4470 4331 4444 4515 4491 4462 4495 4544 4441 4370 4379 4445 4275 4234 4356 4322 4323 4357 4262 4275 4311 4306 4417 4293 4380 4390 4467 4529 4529 4484 4649 4729 4624 4762 4813 4698 4587 4750 4564 4636 4634 4606 4569 4617 4491 4567 4488 4542 4556 4511 4495 4489 4512 4557 4644 4503 4401 4489 4468 4552 4486 4434 4395 4413 4389 4370 4607 4379 4335 4339 4529 4620 4484 4670 4598 4805 4779 4879 4739 4807 4765 4780 4685 4608 4490 4392 4306 4418 4468 4514 4474 4433 4527 4566 4705 4526 4565 4701 4669 4797 4872 4783 4780 4712 4689 4766 4809 4622 4666 4684 4634 4483 4663 4540 4589 4595 4711 4674 4720 4655 4715 4959 4939 4929 4948 4928 4808 4789 4918 4677 4852 4702 4711 4638 4437 4515 4606 4570 4706 4668 4838 4789 4757 4733 4789 4619 4554 4649 4472 4519 4507 4422 4356 4395 4302 4291 4308 4115 4302 4356 4413 4439 4420 4399 4228 4359 4370 4309 4246 4368 4315 4186 4342 4136 4235 4259 4276 4249 4273 4223 4184 4180 4301 4224 4269 4248 4365 4240 4315 4172 4284 4255 4234 4283 4373 4143 4338 4218 4294 4162 4208 4202 4213 4225 4130 4285 4148 4107 4274 4335 4202 4355 4140 4264 4247 4295 4309 4338 4263 4337 4502 4374 4560 4463 4466 4409 4420 4349 4367 4269 4344 4203 4280 4265 4335 4390 4301 4220 4177 4290 4390 4415 4312 4476 4359 4396 4280 4442 4361 4310 4399 4256 4293 4215 4294 4193 4153 4247 4297 4178 4283 4181 4123 4267 4280 4326 4299 4354 4272 4377 4224 4325 4151 4331 4145 4231 4327 4378 4330 4397 4434 4282 4320 4283 4378 4262 4264 4387 4348 4486 4488 4538 4412 4567 4639 4636 4701 4992 5025 4926 5178 5357 5599 5664 5866 5887 6164 6491 6734 7234 7828 8721 9960 11576 12319 12184 10895 9386 7941 6668 6162 5764 5677 5408 5418 5238 5460 5280 5390 5395 5587 5601 5820 6267 6769 7345 7896 8315 8041 7452 6867 6223 5778 5356 5039 5034 5080 4943 4859 4856 4842 4878 4837 4769 4706 4631 4491 4571 4429 4563 4486 4516 4391 4388 4459 4405 4457 4401 4442 4425 4589 4599 4517 4661 4692 4534 4638 4559 4737 4555 4658 4548 4580 4572 4483 4509 4346 4285 4284 4297 4450 4444 4606 4369 4490 4371 4399 4368 4292 4420 4343 4490 4420 4495 4367 4391 4392 4384 4406 4216 4284 4353 4339 4445 4377 4337 4352 4238 4368 4378 4314 4282 4175 4303 4242 4213 4251 4384 4245 4318 4288 4257 4360 4274 4248 4151 4177 4251 4229 4126 4107 4238 4136 4328 4229 4216 4257 4313 4383 4351 4387 4302 4326 4355 4339 4270 4391 4350 4402 4249 4361 4389 4383 4493 4483 4475 4733 4506 4573 4527 4430 4380 4547 4311 4428 4324 4254 4291 4327 4263 4289 4336 4203 4361 4269 4427 4425 4447 4488 4584 4627 4630 4707 4785 4823 4937 4839 4928 4685 4625 4542 4472 4431 4286 4357 4269 4480 4254 4323 4301 4458 4199 4399 4323 4378 4281 4441 4420 4408 4516 4459 4479 4437 4335 4383 4368 4195 4196 4271 4179 4283 4253 4292 4223 4187 4125 4324 4293 4213 4139 4189 4233 4216 4308 4291 4315 4187 4289 4345 4227 4354 4391 4413 4264 4391 4403 4482 4417 4404 4413 4519 4434 4384 4476 4400 4375 4309 4285 4216 4196 4314 4295 4192 4247 4225 4279 4338 4259 4321 4334 4200 4281 4238 4396 4281 4313 4289 4335 4307 4219 4279 4365 4347 4234 4274 4296 4335 4255 4274 4257 4208 4185 4357 4314 4386 4255 4300 4301 4300 4229 4105 4174 4279 4313 4338 4290 4251 4218 4308 4380 4329 4347 4306 4360 4277 4290 4322 4289 4339 4359 4447 4383 4375 4341 4530 4450 4490 4525 4434 4420 4589 4451 4518 4355 4388 4338 4248 4330 4254 4227 4205 4289 4410 4229 4298 4300 4275 4297 4257 4387 4247 4467 4417 4414 4280 4310 4405 4188 4220 4272 4220 4198 4160 4219 4148 4226 4229 4245 4225 4286 4287 4197 4250 4265 4178 4293 4135 4154 4108 4207 4221 4249 4299 4311 4378 4348 4533 4347 4438 4573 4610 4765 4709 4786 4865 4686 4580 4544 4477 4527 4542 4653 4422 4405 4440 4435 4408 4432 4310 4319 4415 4391 4421 4509 4627 4607 4577 4537 4624 4687 4668 4593 4698 4615 4659 4752 4603 4642 4649 4559 4485 4428 4430 4321 4398 4292 4265 4394 4458 4277 4408 4324 4387 4299 4336 4322 4255 4304 4388 4353 4402 4319 4435 4380 4277 4385 4226 4324 4305 4263 4235 4302 4198 4171 4259 4198 4207 4226 4247 4296 4199 4173 4236 4307 4228 4220 4160 4146 4183 4177 4161 4188 4321 4218 4190 4169 4237 4119 4320 4302 4420 4498 4433 4532 4533 4586 4576 4591 4663 4464 4441 4410 4363 4366 4288 4330 4194 4405 4349 4352 4312 4447 4355 4450 4419 4313 4532 4344 4432 4265 4543 4517 4480 4492 4516 4447 4519 4367 4332 4329 4302 4336 4287 4263 4213 4319 4286 4228 4317 4418 4196 4232 4384 4227 4338 4272 4225 4364 4213 4322 4323 4348 4385 4348 4486 4455 4386 4601 4685 4569 4525 4620 4713 4445 4455 4528 4496 4372 4336 4344 4308 4481 4232 4267 4477 4291 4322 4394 4449 4572 4423 4488 4601 4507 4550 4588 4494 4628 4510 4471 4495 4450 4476 4465 4354 4358 4341 4382 4336 4371 4327 4388 4250 4308 4386 4337 4327 4403 4302 4331 4434 4385 4284 4297 4432 4331 4367 4499 4327 4375 4370 4438 4267 4265 4298 4371 4345 4279 4345 4333 4312 4282 4284 4197 4234 4327 4232 4305 4400 4231 4227 4192 4313 4312 4195 4260 4213 4145 4188 4294 4163 4205 4203 4128 4260 4247 4133 4231 4188 4130 4215 4379 4215 4227 4140 4216 4211 4235 4415 4200 4443 4305 4257 4303 4383 4402 4339 4412 4445 4436 4461 4315 4333 4395 4237 4420 4258 4399 4310 4335 4260 4277 4380 4135 4315 4357 4382 4274 4215 4313 4290 4237 4323 4298 4343 4269 4338 4467 4402 4509 4499 4476 4365 4430 4304 4259 4266 4376 4273 4311 4435 4277 4256 4263 4278 4151 4228 4329 4118 4305 4158 4242 4182 4205 4288 4243 4207 4351 4287 4263 4386 4377 4345 4374 4312 4223 4232 4214 4225 4300 4516 4429 4367 4331 4411 4426 4296 4405 4388 4423 4285 4259 4291 4404 4302 4241 4269 4194 4205 4256 4190 4239 4197 4273 4318 4134 4287 4217 4236 4324 4320 4333 4286 4322 4336 4311 4251 4304 4254 4234 4143 4238 4169 4063 4295 4187 4158 4098 4206 4267 4230 4214 4133 4226 4204 4321 4209 4180 4147 4215 4171 4213 4218 4221 4366 4113 4184 4225 4205 4250 4325 4336 4185 4120 4289 4333 4411 4456 4490 4531 4514 4473 4430 4485 4297 4432 4398 4449 4314 4389 4473 4297 4464 4336 4382 4324 4297 4268 4273 4274 4250 4406 4207 4288 4238 4345 4335 4419 4455 4245 4213 4242 4386 4275 4278 4310 4289 4310 4291 4329 4213 4238 4335 4329 4192 4306 4269 4215 4275 4145 4268 4316 4460 4525 4463 4408 4540 4479 4526 4622 4762 4523 4498 4500 4529 4353 4418 4384 4491 4489 4399 4433 4497 4354 4413 4410 4373 4416 4443 4433 4336 4339 4519 4539 4602 4469 4544 4539 4642 4572 4557 4630 4610 4453 4582 4606 4560 4468 4498 4445 4447 4465 4458 4471 4381 4370 4590 4375 4306 4364 4472 4412 4349 4375 4409 4471 4372 4405 4382 4388 4421 4220 4402 4325 4302 4286 4419 4315 4286 4253 4158 4410 4233 4269 4343 4323 4300 4305 4395 4422 4541 4382 4476 4345 4412 4284 4403 4427 4420 4374 4335 4430 4254 4293 4371 4350 4300 4296 4278 4393 4368 4275 4426 4472 4429 4481 4492 4501 4342 4403 4408 4372 4413 4339 4408 4363 4328 4430 4401 4398 4382 4300 4377 4457 4265 4405 4319 4377 4357 4325 4311 4337 4273 4418 4359 4385 4390 4375 4290 4359 4382 4366 4394 4460 4516 4472 4561 4563 4510 4676 4492 4576 4592 4444 4408 4585 4339 4409 4497 4415 4494 4423 4348 4326 4388 4376 4306 4412 4400 4344 4373 4375 4427 4305 4378 4287 4486 4344 4393 4386 4306 4417 4378 4356 4371 4433 4312 4371 4388 4310 4365 4258 4449 4377 4493 4485 4532 4431 4451 4383 4423 4371 4343 4433 4410 4280 4334 4384 4359 4424 4438 4400 4389 4388 4371 4540 4365 4441 4378 4335 4375 4259 4427 4344 4333 4311 4224 4221 4206 4315 4263 4290 4136 4233 4361 4261 4230 4256 4324 4356 4256 4257 4353 4232 4257 4241 4227 4281 4365 4342 4242 4210 4250 4257 4054 4154 4318 4447 4239 4260 4266 4279 4309 4146 4251 4190 4351 4358 4187 4294 4192 4196 4189 4363 4226 4196 4253 4256 4351 4330 4288 4227 4195 4247 4182 4266 4292 4345 4287 4217 4301 4217 4400 4433 4551 4353 4474 4405 4535 4438 4473 4540 4474 4473 4495 4469 4338 4491 4328 4485 4387 4392 4327 4396 4406 4305 4401 4360 4516 4398 4371 4386 4447 4496 4452 4357 4368 4550 4423 4481 4459 4401 4406 4417 4337 4353 4434 4435 4572 4419 4439 4572 4512 4608 4452 4573 4424 4598 4513 4625 4618 4614 4517 4593 4486 4586 4535 4528 4616 4495 4370 4475 4462 4446 4408 4399 4301 4449 4369 4373 4255 4430 4329 4360 4321 4278 4332 4479 4362 4405 4318 4341 4398 4325 4357 4284 4328 4298 4430 4383 4267 4365 4380 4449 4287 4346 4295 4407 4450 4292 4236 4274 4456 4306 4296 4271 4174 4205 4172 4126 4152 4119 4254 4176 4125 4264 4100 4323 4175 4263 4262 4211 4132 4284 4277 4389 4125 4253 4181 4100 4258 4170 4103 4239 4144 4182 4171 3988 4241 4150 4296 4229 4247 4194 4285 4182 4191 4343 4319 4230 4208 4299 4218 4383 4226 4396 4230 4311 4205 4240 4319 4272 4300 4335 4171 4171 4297 4186 4226 4108 4119 4277 4385 4298 4214 4221 4157 4286 4241 4332 4279 4278 4172 4214 4104 4123 4265 4306 4325 4229 4243 4228 4288 4243 4165 4135 4108 4226 4184 4218 4171 4104 4238 4058 4181 4213 4103 4186 4237 4168 4160 4094 4355 4134 4127 4097 4310 4116 4119 4198 4220 4093 4105 4151 4224 4096 4212 4192 4276 4277 4154 4300 4090 4265 4115 4281 4170 4241 4204 4277 4298 4203 4356 4275 4116 4174 4189 4220 4227 4269 4247 4331 4371 4475 4379 4539 4389 4270 4295 4355 4320 4252 4300 4461 4217 4229 4245 4261 4201 4343 4150 4283 4311 4317 4250 4296 4390 4279 4251 4244 4322 4264 4341 4390 4305 4331 4355 4417 4406 4382 4260 4173 4402 4306 4327 4336 4232 4244 4264 4340 4137 4304 4277 4320 4174 4227 4119 4325 4275 4238 4240 4279 4195 4273 4227 4255 4175 4141 4169 4222 4310 4191 4211 4309 4217 4232 4271 4315 4164 4336 4227 4125 4292 4162 4258 4315 4313 4109 4152 4264 4155 4234 4184 4146 4157 4237 4238 4209 4260 4292 4257 4217 4212 4154 4243 4206 4396 4265 4327 4321 4422 4305 4466 4428 4299 4403 4378 4493 4385 4523 4350 4434 4517 4389 4500 4487 4546 4589 4560 4432 4445 4499 4509 4549 4442 4457 4529 4486 4567 4348 4555 4303 4395 4480 4474 4411 4493 4438 4422 4460 4558 4581 4664 4562 4536 4549 4451 4630 4546 4503 4596 4611 4475 4535 4489 4573 4615 4726 4505 4351 4522 4623 4598 4618 4567 4752 4667 4492 4566 4517 4529 4379 4428 4464 4395 4406 4441 4411 4358 4306 4379 4438 4425 4493 4493 4361 4419 4473 4414 4533 4517 4603 4673</counts>
			</dataPoints>
		</scan>
	</xrdMeasurement>
</xrdMeasurements>