File: dataset/precursor_mixture/TiO2_GeO2_SnO2.2-min.xrdml
<?xml version="1.0"?>
<xrdMeasurements xmlns="http://www.xrdml.com/XRDMeasurement/2.2" xmlns:xsi="http://www.w3.org/2001/XMLSchema-instance" xsi:schemaLocation="http://www.xrdml.com/XRDMeasurement/2.2 http://www.xrdml.com/XRDMeasurement/2.2/XRDMeasurement.xsd" status="Completed" recordIdentifier="{8C90F4F7-B4CE-490F-BCAC-61BFBBAC616A}">
	<comment>
		<entry/>
	</comment>
	<sample type="To be analyzed">
		<id>dara-3-1</id>
		<name></name>
		<preparedBy></preparedBy>
	</sample>
	<xrdMeasurement measurementType="Scan" status="Completed" sampleMode="Reflection">
		<usedWavelength intended="K-Alpha 1">
			<kAlpha1 unit="Angstrom">1.5405980</kAlpha1>
			<kAlpha2 unit="Angstrom">1.5444260</kAlpha2>
			<kBeta unit="Angstrom">1.3922500</kBeta>
			<ratioKAlpha2KAlpha1>0.5000</ratioKAlpha2KAlpha1>
		</usedWavelength>
		<incidentBeamPath>
			<radius unit="mm">145.00</radius>
			<xRayTube id="1010048" name="Empyrean Cu LFF HR (9430 033 7310x) DK430614">
				<tension unit="kV">40.0</tension>
				<current unit="mA">15.0</current>
				<anodeMaterial>Cu</anodeMaterial>
				<focus type="Line">
					<length unit="mm">12.0</length>
					<width unit="mm">0.4</width>
					<takeOffAngle unit="deg">6.0</takeOffAngle>
				</focus>
			</xRayTube>
			<filter id="20010004" name="Beta-filter Nickel">
				<material>Ni</material>
				<thickness unit="mm">0.020</thickness>
			</filter>
			<sollerSlit id="21010002" name="Soller slits 0.04 rad.">
				<opening unit="rad">0.0400</opening>
			</sollerSlit>
			<mask id="22031000" name="Fixed mask 13 mm">
				<width unit="mm">9.00</width>
			</mask>
			<divergenceSlit id="22120001" name="Divergence slit 1°" xsi:type="fixedDivergenceSlitType">
				<distanceToSample unit="mm">50.00</distanceToSample>
				<height unit="mm">1.52</height>
			</divergenceSlit>
		</incidentBeamPath>
		<beamKnife id="29030100" name="Beam knife low"/>
		<sampleMovement xsi:type="spinningSampleMovementType">
			<spinnerRevolutionTime unit="seconds">1.0</spinnerRevolutionTime>
		</sampleMovement>
		<diffractedBeamPath>
			<radius unit="mm">145.00</radius>
			<antiScatterSlit id="22090040" name="AS slit 9 mm" xsi:type="fixedAntiScatterSlitType">
				<height unit="mm">9.00</height>
			</antiScatterSlit>
			<sollerSlit id="21020003" name="Large Soller slits 0.04 rad.">
				<opening unit="rad">0.0400</opening>
			</sollerSlit>
			<filter id="20030001" name="Large beta-filter Nickel">
				<material>Ni</material>
				<thickness unit="mm">0.020</thickness>
			</filter>
			<detector id="7010019" name="PIXcel1D-Medipix3 detector" xsi:type="rtmsDetectorType">
				<phd unit="keV">
					<lowerLevel>4.0</lowerLevel>
					<upperLevel>11.3</upperLevel>
				</phd>
				<mode>Scanning</mode>
				<activeLength unit="deg">1.021</activeLength>
			</detector>
		</diffractedBeamPath>
		<scan appendNumber="0" mode="Continuous" scanAxis="Gonio" status="Completed">
			<header>
				<startTimeStamp>2024-02-18T09:32:37-08:00</startTimeStamp>
				<endTimeStamp>2024-02-18T09:34:59-08:00</endTimeStamp>
				<author>
					<name>AutomatedUser</name>
				</author>
				<source>
					<applicationSoftware version="1.4b (28)">PANalytical Aeris Instrument Suite</applicationSoftware>
					<instrumentControlSoftware version="2.0.0 20210224">AERIS</instrumentControlSoftware>
					<instrumentID>950485</instrumentID>
				</source>
			</header>
			<dataPoints>
				<positions axis="2Theta" unit="deg">
					<startPosition>10.02173288</startPosition>
					<endPosition>139.98435528</endPosition>
				</positions>
				<positions axis="Omega" unit="deg">
					<startPosition>5.01086644</startPosition>
					<endPosition>69.99217764</endPosition>
				</positions>
				<commonCountingTime unit="seconds">1.551</commonCountingTime>
				<counts unit="counts">328 320 338 320 313 346 327 323 333 314 289 312 310 348 309 319 337 321 326 355 315 317 304 351 316 338 299 281 325 306 299 317 288 272 265 291 278 287 262 306 309 249 300 256 258 252 276 281 287 231 295 278 243 262 281 249 252 260 247 268 252 233 243 241 272 257 261 238 255 260 192 231 244 254 242 251 209 234 243 215 240 239 234 220 233 200 213 211 225 188 208 239 218 194 221 218 238 190 197 220 191 222 218 206 214 189 221 198 173 178 172 228 214 228 186 173 193 189 211 168 183 170 185 175 183 185 196 177 178 152 163 177 191 190 188 168 139 151 186 175 174 198 184 168 167 184 179 152 140 169 171 149 163 170 158 154 157 158 161 152 168 159 150 169 183 143 169 154 150 177 170 143 159 135 138 142 153 167 141 159 123 166 159 147 145 143 157 134 139 170 171 143 168 173 166 138 145 158 149 136 120 147 147 137 157 146 142 165 152 160 161 157 175 125 140 136 153 159 149 144 137 137 145 126 169 136 155 156 142 128 131 165 138 154 151 187 182 250 290 326 343 266 192 171 147 120 135 129 131 128 144 130 117 136 114 123 131 121 106 119 120 127 124 115 131 117 145 119 111 124 129 110 142 110 129 128 111 110 91 124 130 99 126 126 142 134 153 116 119 118 116 130 131 134 119 119 113 127 123 110 97 129 127 138 116 124 114 113 119 96 112 120 123 108 118 105 116 109 113 140 112 104 119 116 122 113 119 108 130 136 103 116 137 158 128 132 133 128 134 132 151 213 227 337 501 854 1246 1426 1165 738 373 235 206 232 248 271 303 336 553 795 1162 1476 1373 1003 584 414 284 264 283 319 399 449 599 896 1334 1871 2034 1793 1088 643 451 340 299 274 195 185 158 155 121 134 140 129 132 126 143 120 100 119 115 111 128 101 102 116 134 100 103 112 106 124 103 115 107 82 94 113 110 106 95 93 87 67 104 101 96 77 104 75 87 90 103 96 64 102 86 82 89 76 94 99 113 100 84 85 75 84 91 77 94 89 70 84 98 61 86 82 90 86 89 77 77 90 81 90 89 83 81 62 66 70 82 77 79 76 89 81 71 87 74 71 94 85 111 74 93 84 67 86 81 79 94 74 76 63 64 80 78 74 70 75 84 73 86 70 84 92 103 77 57 65 71 86 78 89 81 85 66 96 88 99 100 78 74 106 111 98 111 126 116 120 129 175 168 187 236 285 382 628 1016 1442 1626 1364 985 668 411 295 244 188 156 149 137 123 98 92 109 88 124 108 104 100 78 102 93 82 84 83 69 69 79 65 82 72 75 79 59 66 56 72 76 78 82 84 80 96 109 146 185 198 199 148 140 107 100 79 88 63 87 66 81 81 64 86 68 80 88 107 104 119 119 140 129 99 99 103 79 99 82 67 84 105 85 79 110 111 137 181 248 333 429 503 586 717 740 709 630 429 299 190 140 107 99 104 101 126 130 140 128 135 116 101 92 102 92 117 142 174 149 124 110 85 83 86 107 129 157 196 198 194 157 113 115 103 94 67 80 62 65 66 48 65 79 45 74 75 61 57 78 73 68 61 59 57 64 65 66 56 73 76 57 59 65 42 71 61 70 52 65 62 76 57 74 64 71 87 106 159 167 282 264 243 190 142 112 93 87 71 67 57 59 78 68 58 71 70 67 79 72 75 82 79 73 54 66 58 50 54 48 48 55 65 65 71 64 65 48 60 62 56 46 53 47 58 57 43 65 56 59 68 47 64 56 50 47 38 53 52 43 46 44 48 51 62 52 39 60 72 69 70 75 48 68 75 54 54 56 60 44 52 46 55 71 52 64 70 52 49 46 45 50 47 63 56 58 42 47 50 41 66 44 52 51 50 47 89 43 49 44 56 49 41 40 51 50 50 63 48 36 72 57 65 66 45 59 60 55 46 56 70 75 61 65 67 68 62 82 82 136 282 359 388 280 283 245 175 155 147 130 97 101 83 111 180 213 186 138 133 108 84 77 72 73 56 56 73 44 57 46 51 52 50 43 49 59 55 57 66 51 45 63 55 47 48 58 43 49 65 62 42 63 61 56 59 37 63 56 42 93 71 60 45 61 40 50 46 50 69 64 76 71 72 79 87 90 101 102 118 159 182 213 266 484 776 1133 1111 889 825 673 475 283 214 159 136 114 119 74 93 83 72 54 66 74 50 58 55 61 68 66 70 71 96 99 74 71 81 88 95 93 132 133 105 112 104 109 80 86 68 97 104 138 195 289 211 185 181 154 100 76 77 49 63 64 65 73 76 104 92 118 146 240 289 306 230 244 251 236 220 290 244 197 176 173 130 75 80 72 63 50 68 51 54 50 44 62 57 56 56 60 53 54 46 62 48 58 55 73 72 55 50 81 53 57 37 42 47 47 67 48 42 66 43 54 48 47 55 50 48 42 64 37 36 66 66 47 47 63 75 79 124 149 156 157 134 129 104 78 64 75 55 46 80 69 51 50 44 57 76 63 64 133 155 206 192 200 183 151 143 121 86 81 57 56 50 45 69 66 47 65 53 52 50 47 47 46 45 49 53 52 51 57 40 40 53 40 50 68 45 51 51 60 39 48 54 51 45 43 46 46 48 48 58 54 38 54 48 58 59 60 62 60 53 55 62 67 98 128 119 150 153 213 262 274 232 209 196 216 160 128 96 99 96 75 66 71 63 76 115 131 186 201 182 128 144 122 97 66 60 46 56 46 53 49 54 57 58 48 49 60 45 38 29 50 34 44 45 61 48 48 41 56 43 73 52 50 68 63 73 58 55 95 73 106 126 150 192 275 227 177 180 191 139 102 97 72 78 71 81 74 68 64 68 67 66 68 100 122 170 202 185 197 249 336 420 461 398 353 304 293 226 210 172 109 102 66 85 65 71 71 47 61 62 69 54 89 76 122 131 142 93 90 100 80 81 65 45 71 58 55 47 47 51 56 42 37 40 38 41 30 37 52 38 47 40 43 46 39 48 57 37 41 35 48 66 71 97 95 122 90 61 75 73 73 41 45 51 52 46 44 46 46 56 41 46 43 37 57 56 48 53 52 49 67 98 123 116 100 82 118 109 134 135 99 76 72 85 78 73 61 50 46 50 54 43 54 66 51 57 57 59 78 77 123 145 109 102 110 107 108 82 46 76 58 38 41 43 36 47 54 35 47 41 40 48 40 38 46 56 42 36 38 50 46 28 43 34 38 43 44 35 31 32 35 42 36 44 38 38 34 41 42 48 37 39 37 73 59 60 72 91 74 91 71 65 61 85 43 44 49 51 58 46 42 49 63 51 47 41 50 36 49 56 42 59 56 57 79 119 146 87 98 77 97 88 68 66 48 59 41 39 43 56 30 35 46 37 40 50 50 55 59 78 55 50 59 64 48 58 45 38 39 41 43 40 46 44 47 30 43 63 36 57 41 40 45 39 57 68 69 57 71 49 46 59 63 65 71 72 55 58 53 59 49 44 44 31 49 47 54 47 46 58 58 67 78 87 100 115 132 166 212 195 160 138 140 138 138 106 102 53 75 51 43 40 54 46 51 51 44 45 35 51 32 57 49 67 49 54 63 77 81 70 61 62 74 42 56 59 48 45 41 40 37 54 39 57 47 52 52 50 52 41 49 78 80 92 75 82 75 65 79 72 59 66 49 40 47 47 44 51 38 45 43 21 37 34 25 39 47 39 42 49 62 49 42 41 49 72 99 85 102 76 66 56 48 65 46 54 65 71 60 79 41 41 51 53 59 60 55 47 74 107 160 162 141 90 105 109 106 110 80 80 61 75 53 50 58 30 42 53 36 42 34 36 43 34 34 46 30 45 50 41 42 42 47 33 42 37 31 30 34 42 34 40 36 34 42 44 46 27 39 47 21 38 41 33 38 34 39 38 23 37 36 47 41 32 46 40 42 41 47 22 38 39 30 42 47 51 43 60 74 107 101 109 55 67 79 52 74 70 69 44 33 38 28 49 42 29 48 30 36 38 27 46 42 43 41 48 42 66 49 54 50 61 55 38 35 48 64 45 55 43 36 52 51 55 59 70 51 53 54 43 47 72 82 89 106 121 127 151 170 135 96 98 80 113 125 90 100 60 57 49 62 62 37 49 60 59 59 81 77 80 100 133 179 154 142 125 114 98 128 112 116 81 65 60 57 46 46 72 61 51 51 58 57 46 43 27 44 46 46 45 43 49 57 69 53 57 46 47 75 57 51 44 53 47 41 69 51 52 54 59 56 56 59 67 84 95 105 94 76 84 54 72 79 79 53 57 48 63 45 41 50 42 42 41 43 50 66 55 55 65 45 43 45 41 51 48 26 50 36 44 48 43 25 39 37 55 55 66 50 60 48 55 69 36 63 57 57 57 57 56 58 64 41 79 66 94 90 81 71 61 77 57 65 54 84 63 64 61 51 36 40 50 40 39 43 63 54 45 45 47 43 45 49 43 46 43 40 30 45 45 36 42 38 43 32 37 23 24 40 42 30 46 45 40 31 41 37 54 49 51 58 43 49 36 53 39 53 36 39 40 63 49 31 50 43 36 40 32 54 57 73 77 68 51 49 88 69 93 74 67 76 49 56 64 47 67 44 46 56 43 61 50 49 46 37 48 42 40 49 57 30 40 40 38 39 43 49 40 46 35 36 29 25 42 44 38 60 33 43 39 37 38 31 48 29 31 45 29 36 33 35 35 48 39 41 33 31 52 33 38 34 31 39 35 41 34 36 40 36 33 31 48 38 38 44 36 48 32 31 46 47 31 39 28 56 30 28 35 28 32 41 46 38 36 40 35 39 38 59 56 65 63 44 54 45 53 41 46 39 52 47 46 36 42 41 55 40 38 39 40 39 42 38 46 51 33 28 30 25 42 28 31 38 33 40 42 47 41 43 40 42 32 45 25 37 43 38 21 31 36 41 43 26 25 40 48 46 32 41 36 57 34 35 35 42 40 46 36 38 36 42 53 30 53 63 81 67 56 55 58 48 50 63 59 62 71 67 60 73 77 81 114 99 146 153 154 168 140 131 115 90 119 107 101 97 119 112 104 96 101 59 76 59 65 63 47 56 39 61 64 51 46 50 57 64 59 51 50 50 47 42 56 37 38 39 46 38 43 44 40 38 32 41 39 43 49 40 48 57 62 62 60 58 79 55 69 64 47 41 36 64 46 54 53 58 37 56 56 57 59 64 61 69 85 94 109 117 103 97 92 88 70 55 63 70 61 80 60 80 51 71 40 40 70 61 43 48 42 38 34 62 36 44 39 56 47 52 42 34 39 35 61 45 42 41 64 70 54 72 88 60 65 63 61 57 67 50 70 59 58 53 68 48 50 62 90 69 76 101 108 97 107 111 96 82 73 78 65 79 82 86 79 75 69 77 58 66 53 73 55 69 72 75 88 97 111 162 181 137 132 87 111 94 80 95 80 108 114 114 99 84 65 57 53 54 37 43 47 63 48 41 46 48 49 51 32 39 46 39 57 57 42 38 43 32 38 36 57 40 37 35 33 43 39 47 47 48 51 48 67 74 65 84 60 65 75 81 58 59 56 60 72 87 70 55 52 53 55 76 48 36 32 41 42 43 54 42 56 49 47 49 40 58 43 35 47 49 40 54 66 62 51 47 52 42 44 49 59 45 37 53 46 51 47 47 43 60 46 50 40 44 42 44 58 41 53 64 63 43 84 90 77 94 158 139 185 177 159 125 122 117 117 107 103 87 110 86 115 130 127 117 119 97 64 73 69 59 55 60 61 70 61 65 76 68 50 45 53 55 42 43 47 40 45 51 53 43 49 38 34 43 42 29 45 39 42 33 31 43 39 31 47 39 44 50 40 45 37 38 29 28 48 26 37 37 38 34 37 30 46 39 45 39 36 36 44 38 38 34 30 50 45 42 43 30 45 39 29 33 42 40 51 47 43 51 62 55 70 69 67 74 63 58 57 51 41 42 39 61 56 48 50 49 39 43 44 40 35 51 45 33 21 31 39 44 59 45 39 38 47 49 51 46 43 45 34 42 62 43 41 53 35 56 47 41 42 53 44 33 46 53 53 53 39 36 53 51 50 50 36 42 32 41 35 34 58 48 44 53 33 35 54 45 51 49 46 44 42 50 51 51 60 41 54 64 46 69 59 84 71 87 87 101 111 128 133 125 140 96 96 105 100 89 97 98 119 96 113 105 84 108 80 79 59 68 74 66 70 57 74 61 70 75 63 61 71 59 62 76 60 51 51 46 51 51 49 54 46 53 53 58 56 41 47 49 48 49 47 43 47 44 51 47 42 46 49 39 42 52 46 47 49 43 64 74 63 66 69 80 71 66 51 58 44 53 51 43 56 61 52 58 41 48 65 50 41 43 58 36 52 41 43 53 51 46 32 48 39 44 53 47 67 52 43 44 39 59 43 45 53 53 56 59 43 62 63 53 52 57 56 60 47 56 55 65 42 53 46 50 71 42 38 53 45 54 77 62 45 47 57 55 58 74 68 79 79 82 88 98 91 118 123 120 122 107 114 109 112 92 112 75 75 74 74 90 73 81 85 76 97 82 102 84 82 69 78 64 75 62 58 61 49 65 67 59 64 57 42 63 34 64 39 48 36 52 54 40 45 31 33 51 51 44 50 38 62 44 43 43 50 34 46 48 41 48 53 44 41 57 43 50 49 60 39 55 57 55 31 42 57 45 52 45 41 55 50 56 38 52 60 42 60 47 45 42 54 59 44 46 44 45 34 46 35 43 55 43 49 31 40 49 45 43 39 39 48 54 56 42 49 59</counts>
			</dataPoints>
		</scan>
	</xrdMeasurement>
</xrdMeasurements>