File: dataset/precursor_mixture/TiO2_Li2CO3_MnCO3_K2SO4.12-min.xrdml
<?xml version="1.0"?>
<xrdMeasurements xmlns="http://www.xrdml.com/XRDMeasurement/2.2" xmlns:xsi="http://www.w3.org/2001/XMLSchema-instance" xsi:schemaLocation="http://www.xrdml.com/XRDMeasurement/2.2 http://www.xrdml.com/XRDMeasurement/2.2/XRDMeasurement.xsd" status="Completed" recordIdentifier="{3262BABD-3B17-4451-A648-A2F09B0211DB}">
	<comment>
		<entry/>
	</comment>
	<sample type="To be analyzed">
		<id>dara-11-2</id>
		<name></name>
		<preparedBy></preparedBy>
	</sample>
	<xrdMeasurement measurementType="Scan" status="Completed" sampleMode="Reflection">
		<usedWavelength intended="K-Alpha 1">
			<kAlpha1 unit="Angstrom">1.5405980</kAlpha1>
			<kAlpha2 unit="Angstrom">1.5444260</kAlpha2>
			<kBeta unit="Angstrom">1.3922500</kBeta>
			<ratioKAlpha2KAlpha1>0.5000</ratioKAlpha2KAlpha1>
		</usedWavelength>
		<incidentBeamPath>
			<radius unit="mm">145.00</radius>
			<xRayTube id="1010048" name="Empyrean Cu LFF HR (9430 033 7310x) DK430614">
				<tension unit="kV">40.0</tension>
				<current unit="mA">15.0</current>
				<anodeMaterial>Cu</anodeMaterial>
				<focus type="Line">
					<length unit="mm">12.0</length>
					<width unit="mm">0.4</width>
					<takeOffAngle unit="deg">6.0</takeOffAngle>
				</focus>
			</xRayTube>
			<filter id="20010004" name="Beta-filter Nickel">
				<material>Ni</material>
				<thickness unit="mm">0.020</thickness>
			</filter>
			<sollerSlit id="21010002" name="Soller slits 0.04 rad.">
				<opening unit="rad">0.0400</opening>
			</sollerSlit>
			<mask id="22031000" name="Fixed mask 13 mm">
				<width unit="mm">9.00</width>
			</mask>
			<divergenceSlit id="22120001" name="Divergence slit 1°" xsi:type="fixedDivergenceSlitType">
				<distanceToSample unit="mm">50.00</distanceToSample>
				<height unit="mm">1.52</height>
			</divergenceSlit>
		</incidentBeamPath>
		<beamKnife id="29030100" name="Beam knife low"/>
		<sampleMovement xsi:type="spinningSampleMovementType">
			<spinnerRevolutionTime unit="seconds">1.0</spinnerRevolutionTime>
		</sampleMovement>
		<diffractedBeamPath>
			<radius unit="mm">145.00</radius>
			<antiScatterSlit id="22090040" name="AS slit 9 mm" xsi:type="fixedAntiScatterSlitType">
				<height unit="mm">9.00</height>
			</antiScatterSlit>
			<sollerSlit id="21020003" name="Large Soller slits 0.04 rad.">
				<opening unit="rad">0.0400</opening>
			</sollerSlit>
			<filter id="20030001" name="Large beta-filter Nickel">
				<material>Ni</material>
				<thickness unit="mm">0.020</thickness>
			</filter>
			<detector id="7010019" name="PIXcel1D-Medipix3 detector" xsi:type="rtmsDetectorType">
				<phd unit="keV">
					<lowerLevel>4.0</lowerLevel>
					<upperLevel>11.3</upperLevel>
				</phd>
				<mode>Scanning</mode>
				<activeLength unit="deg">5.020</activeLength>
			</detector>
		</diffractedBeamPath>
		<scan appendNumber="0" mode="Continuous" scanAxis="Gonio" status="Completed">
			<header>
				<startTimeStamp>2024-02-18T13:58:11-08:00</startTimeStamp>
				<endTimeStamp>2024-02-18T14:10:39-08:00</endTimeStamp>
				<author>
					<name>AutomatedUser</name>
				</author>
				<source>
					<applicationSoftware version="1.4b (28)">PANalytical Aeris Instrument Suite</applicationSoftware>
					<instrumentControlSoftware version="2.0.0 20210224">AERIS</instrumentControlSoftware>
					<instrumentID>950485</instrumentID>
				</source>
			</header>
			<dataPoints>
				<positions axis="2Theta" unit="deg">
					<startPosition>9.99043322</startPosition>
					<endPosition>100.09495370</endPosition>
				</positions>
				<positions axis="Omega" unit="deg">
					<startPosition>4.99521661</startPosition>
					<endPosition>50.04747685</endPosition>
				</positions>
				<commonCountingTime unit="seconds">18.249</commonCountingTime>
				<counts unit="counts">4214 4054 4169 4142 4257 4161 4048 4125 4196 4126 4217 4228 4015 4126 4067 4116 4170 4110 4098 4124 4107 4180 4037 4224 4025 4140 4220 4032 4156 4134 4163 4113 4034 4107 4047 4112 4044 4013 3960 4013 4016 4042 4087 4045 3982 4073 3958 3956 4105 4044 3859 3956 4033 3853 4008 3943 3939 3930 3851 3990 3896 3973 3871 3940 3965 4023 4051 3986 3912 3880 3938 4048 4010 3955 3783 3784 3904 3841 3962 3809 3957 3904 3881 3846 3934 3852 3906 3885 3781 3945 3776 3845 3749 3850 3874 3780 3825 3930 3814 3929 3874 3807 3781 3814 3855 3892 3776 3729 3755 3711 3716 3742 3799 3865 3778 3873 3821 3805 3684 3765 3734 3802 3834 3722 3691 3748 3714 3772 3753 3706 3659 3722 3675 3711 3609 3713 3750 3626 3652 3668 3743 3668 3699 3647 3584 3694 3597 3626 3615 3712 3588 3635 3626 3594 3595 3558 3597 3568 3577 3689 3744 3643 3645 3607 3683 3596 3671 3584 3644 3544 3490 3470 3665 3518 3570 3593 3540 3637 3476 3621 3671 3570 3522 3472 3549 3479 3711 3561 3486 3448 3527 3478 3533 3577 3507 3444 3491 3539 3402 3461 3630 3437 3382 3442 3411 3601 3528 3498 3433 3434 3531 3432 3341 3502 3453 3261 3322 3414 3518 3485 3486 3402 3327 3317 3281 3485 3392 3459 3427 3411 3260 3369 3463 3395 3483 3248 3395 3410 3334 3344 3363 3385 3305 3273 3406 3437 3365 3316 3326 3279 3279 3309 3260 3321 3280 3360 3391 3382 3402 3369 3326 3379 3394 3317 3275 3379 3320 3305 3485 3152 3321 3299 3221 3341 3218 3257 3085 3369 3312 3256 3253 3163 3232 3313 3190 3292 3218 3259 3294 3300 3184 3185 3178 3347 3174 3236 3107 3250 3164 3292 3240 3157 3225 3210 3149 3063 3311 3227 3234 3243 3229 3211 3182 3158 3232 3183 3137 3162 3114 3162 3192 3125 3215 3312 3124 3098 3203 3191 3152 3241 3190 3257 3229 3163 3246 3228 3142 3197 3073 3157 3169 3128 3098 3199 3099 3044 3149 3076 3095 3187 3159 3243 3112 3192 3101 3179 3152 3149 3195 3145 3010 3171 3077 3027 3109 3073 3107 3142 2999 3064 3054 3135 3018 3119 3096 2982 3064 3066 3121 3025 3132 3065 3113 3029 3089 3083 3051 3017 2994 2987 3093 3035 3150 3071 3049 3160 2971 3045 3066 3068 3024 2966 3051 3078 2959 2943 3054 2945 3070 2989 2933 2972 3034 3079 3050 3057 3008 2905 3051 2977 2936 3008 3132 3043 2981 3040 3038 2996 2985 3011 3052 3024 3030 2947 2944 3063 3026 2993 2943 2951 3106 3063 2909 3033 3050 3012 3072 3042 3028 2970 3002 3057 2966 3017 3023 2992 3035 2928 3032 2858 2950 2998 2988 2983 2955 2953 2962 2928 3028 2966 3009 2958 2924 3015 3032 2925 2958 2949 2853 2994 2998 2959 2941 2893 2961 2956 2993 2909 3013 2945 2912 2929 2867 3000 2950 2929 2969 2986 3040 3027 3009 2872 2890 2917 3042 2827 2968 2884 2981 2999 2912 2865 2981 2890 2927 2945 2919 2988 2859 2898 2938 2936 2875 2901 2966 2805 2928 2960 2922 2926 3013 2849 2863 2908 2860 2890 3022 2898 2860 2929 2813 2916 2828 2994 2878 2885 2933 2893 2904 2918 2813 2921 2931 3046 2811 2933 2788 2906 2868 2922 2873 2860 2909 2836 2921 2818 2920 2871 2902 2865 2801 2842 2818 2885 2858 2819 2884 2884 2826 2870 2865 2838 2833 2756 2972 2757 2856 2846 2981 2861 2818 2877 2852 2932 2844 2915 2781 2786 2862 2820 2834 2973 2795 2850 2737 2810 2941 2909 2888 2805 2773 2836 2789 2728 2808 2823 2787 2858 2828 2837 2840 2839 2901 2816 2743 2828 2735 2885 2780 2846 2852 2819 2758 2807 2783 2840 2789 2802 2751 2854 2824 2773 2834 2739 2814 2761 2865 2850 2757 2856 2828 2829 2816 2829 2749 2783 2744 2825 2683 2768 2746 2811 2778 2721 2719 2677 2660 2760 2751 2730 2729 2767 2792 2630 2690 2714 2643 2753 2745 2745 2737 2733 2817 2695 2711 2715 2778 2780 2716 2832 2690 2777 2768 2679 2759 2719 2706 2703 2813 2703 2780 2728 2817 2822 2896 2909 2899 2909 3011 2916 2955 2963 2987 2916 3000 3095 3231 3045 2990 3074 3052 3002 3064 3020 3017 3068 2890 2962 2922 2832 2940 2876 2725 2807 2801 2802 2613 2671 2768 2650 2635 2610 2637 2636 2696 2646 2647 2575 2654 2642 2704 2590 2660 2708 2718 2629 2662 2652 2624 2691 2689 2650 2658 2615 2610 2678 2583 2591 2644 2591 2589 2517 2664 2612 2541 2592 2618 2714 2696 2665 2595 2553 2585 2522 2600 2632 2588 2672 2622 2654 2670 2615 2500 2576 2605 2605 2664 2450 2562 2667 2519 2592 2593 2555 2686 2510 2588 2565 2587 2548 2569 2521 2492 2542 2546 2602 2556 2624 2605 2505 2566 2501 2653 2564 2669 2468 2476 2483 2548 2524 2573 2526 2497 2479 2511 2521 2522 2545 2536 2627 2570 2595 2517 2562 2568 2595 2560 2461 2562 2618 2569 2574 2501 2554 2533 2482 2444 2558 2613 2592 2506 2642 2499 2586 2560 2586 2422 2550 2452 2508 2546 2496 2513 2455 2499 2402 2447 2525 2423 2509 2434 2508 2448 2508 2490 2470 2466 2471 2582 2436 2464 2491 2486 2344 2475 2569 2548 2456 2496 2415 2578 2491 2384 2542 2522 2466 2380 2512 2421 2480 2520 2445 2502 2424 2463 2393 2420 2494 2408 2445 2465 2557 2496 2413 2422 2377 2402 2458 2542 2382 2403 2415 2405 2515 2457 2413 2459 2318 2457 2474 2358 2435 2380 2365 2411 2411 2461 2387 2407 2405 2361 2471 2382 2363 2545 2409 2491 2442 2315 2508 2485 2383 2428 2413 2444 2416 2311 2362 2418 2434 2387 2376 2426 2380 2337 2355 2431 2459 2343 2401 2434 2358 2407 2395 2461 2404 2407 2406 2391 2405 2340 2356 2402 2404 2439 2429 2452 2419 2432 2442 2366 2389 2392 2429 2539 2409 2404 2403 2453 2405 2333 2536 2457 2498 2375 2495 2330 2474 2441 2403 2387 2457 2596 2490 2523 2519 2392 2474 2495 2464 2626 2502 2535 2540 2637 2581 2628 2682 2781 2861 2933 2967 3011 3158 3415 3404 3656 3780 3885 4019 4257 4490 4875 4832 5014 5148 5313 5472 5507 5453 5492 5272 5021 4847 4522 4133 3922 3765 3441 3167 3057 2934 2750 2738 2521 2613 2483 2505 2419 2398 2419 2510 2358 2476 2406 2426 2308 2300 2324 2397 2353 2393 2230 2293 2314 2314 2368 2420 2315 2336 2274 2342 2329 2317 2350 2336 2294 2355 2365 2338 2308 2326 2325 2288 2276 2329 2319 2298 2240 2330 2265 2339 2230 2223 2248 2360 2367 2371 2287 2363 2249 2310 2300 2275 2357 2241 2308 2267 2293 2263 2263 2303 2258 2347 2305 2356 2205 2293 2264 2240 2339 2209 2264 2219 2243 2219 2226 2264 2295 2188 2232 2340 2246 2224 2240 2240 2217 2257 2240 2263 2223 2181 2272 2159 2152 2181 2212 2182 2302 2323 2225 2235 2273 2209 2269 2251 2303 2196 2253 2222 2122 2234 2322 2264 2260 2232 2282 2317 2313 2339 2277 2191 2261 2286 2196 2234 2227 2282 2240 2312 2188 2280 2258 2227 2241 2264 2182 2226 2176 2254 2255 2254 2219 2164 2170 2279 2190 2186 2272 2259 2244 2311 2252 2227 2366 2193 2270 2313 2242 2279 2275 2294 2373 2333 2296 2363 2363 2397 2407 2421 2299 2438 2398 2415 2459 2429 2357 2406 2454 2354 2359 2297 2434 2315 2407 2300 2393 2285 2310 2369 2517 2544 2564 2501 2580 2636 2721 2699 2830 2799 2895 3046 3213 3279 3468 3434 3388 3317 3269 3218 3192 3064 2967 2980 2770 2706 2696 2616 2576 2581 2561 2614 2610 2627 2644 2831 2891 2841 2867 2893 3084 3042 3321 3322 3398 3468 3752 3683 3782 3804 3939 4001 4147 4077 4160 4072 4062 3789 3810 3633 3519 3497 3416 3162 3070 3072 2990 2748 2725 2667 2689 2535 2455 2528 2475 2505 2474 2424 2365 2403 2396 2453 2345 2357 2350 2406 2292 2464 2283 2330 2303 2278 2277 2396 2411 2405 2209 2386 2339 2374 2329 2313 2351 2360 2283 2466 2333 2420 2486 2380 2315 2472 2492 2394 2498 2552 2490 2564 2533 2589 2572 2664 2610 2667 2707 2805 2817 3038 3058 3050 3281 3421 3522 3741 3942 4235 4460 4795 5037 5514 6132 6626 7444 8112 8850 9898 10820 11901 12994 14080 15281 16380 17343 18324 18972 19070 19226 18455 17700 16539 15343 14134 12865 11200 10175 8648 7822 6629 5931 5204 4690 4131 3779 3584 3281 3104 3045 2891 2863 2760 2665 2617 2635 2533 2583 2513 2481 2488 2392 2392 2380 2380 2308 2214 2208 2341 2310 2276 2217 2060 2237 2201 2175 2225 2226 2253 2158 2147 2162 2159 2153 2228 2179 2159 2101 2212 2261 2233 2090 2184 2092 2164 2113 2131 2177 2154 2084 2130 2181 2097 2060 2059 2184 2100 2130 2216 2191 2180 2168 2217 2261 2275 2368 2242 2221 2346 2360 2297 2333 2278 2314 2385 2227 2195 2211 2241 2139 2157 2101 2026 2097 2080 2009 2053 2113 2082 2109 2029 1986 2057 1984 2002 2053 2031 1961 2019 1934 2084 2076 1987 2050 2070 2114 2101 1984 2080 1994 1962 1978 1993 2076 1970 2007 1942 1985 2005 1988 2070 1949 2032 2018 1926 1963 1976 1988 1999 2073 1943 2011 1946 2039 1946 1941 1968 2020 2005 1939 2034 1896 1891 1976 2016 1964 1982 1993 2027 1913 1909 1927 2009 2024 2006 1905 1960 1917 1967 1996 1991 1981 2029 1982 1969 1972 2030 2017 1989 2003 2082 2048 1956 2069 2039 2000 2009 1998 2091 2066 1994 2006 1990 1931 1951 1917 2027 1896 1940 1908 1951 2064 1818 1957 1985 2025 1936 1959 1947 2020 1975 1969 1961 1878 2008 1950 1935 1979 1915 1871 1929 1908 1869 1966 1914 1917 1932 1935 1953 1914 1923 1953 1989 1927 1949 1920 1886 1875 1941 1931 1972 1887 1955 2001 1984 1909 1991 1955 1882 1971 1968 1906 1943 1935 1909 1983 1982 1967 1866 1916 1932 1936 1930 2024 2058 2020 2030 2031 1959 2047 2029 2053 2056 2106 1997 2106 2140 2075 2071 1996 1995 2066 2002 1985 1899 1968 1939 2026 1866 1921 1936 1896 1883 1788 1949 2018 1817 1860 1897 1914 1866 1822 1989 1823 1931 1917 1915 1933 1900 1942 1976 1895 1910 1928 1962 1956 1862 1965 1877 1993 1841 1960 1977 1932 1939 1942 2020 1973 1967 2013 2018 2029 2110 2094 2036 2220 2217 2221 2200 2110 2253 2161 2070 2119 2114 2096 2031 2107 1974 2106 2112 2034 2034 2001 2063 1988 2131 2119 2085 2087 2089 2186 2283 2275 2269 2337 2383 2325 2393 2297 2358 2331 2296 2292 2258 2212 2276 2334 2256 2308 2275 2273 2314 2389 2381 2447 2618 2781 2903 3098 3461 3560 3755 3863 4055 4326 4454 4445 4734 4710 4835 4763 4442 4264 3820 3707 3435 3394 3148 3014 2837 2634 2487 2349 2179 2216 2091 2047 1921 2073 1906 2067 1926 2012 1920 2031 1978 1969 1973 1995 1963 2009 1970 2018 1997 1936 2044 1949 2001 1931 2042 1954 2069 2079 2011 1987 1981 2063 2023 2092 2124 2123 2154 2191 2137 2280 2288 2310 2403 2398 2533 2611 2650 2752 2865 2926 3003 3093 3326 3511 3587 3586 3874 3967 4050 4095 4230 4363 4420 4585 4625 4970 5308 5485 6088 7104 7923 9113 9881 10562 11053 10488 10469 9801 10241 9302 9360 8579 8173 7358 6939 6275 6416 6016 5961 5691 5506 5438 5234 4969 4865 4669 4566 4608 4406 4100 4005 3861 3584 3630 3523 3474 3553 3603 3704 3707 3870 4040 4242 4675 4853 5164 5326 5857 6144 6538 6794 7265 7425 7675 7906 7921 8060 7850 7867 7635 7268 6959 6781 6173 5904 5681 5164 4915 4635 4220 4161 3891 3626 3451 3369 3247 3183 3111 3103 3117 3238 3153 3160 3314 3475 3594 3629 3708 3953 4056 4370 4624 4812 4984 4938 5043 5148 5255 5069 5015 4769 4603 4527 4404 4174 4017 3809 3559 3376 3283 3029 2944 2768 2578 2564 2423 2360 2361 2196 2242 2157 2207 2044 2058 2107 2072 2036 2015 1986 1971 1933 1965 1931 1972 1897 1889 1888 1926 1926 1896 1890 1962 2029 1946 1960 1975 1832 1888 1876 1935 1900 1838 1978 1859 1738 1891 1843 1940 1856 1805 1848 1865 1818 1836 1868 1839 1856 1795 1871 1850 1850 1810 1799 1789 1841 1729 1825 1803 1793 1849 1859 1753 1720 1788 1755 1738 1827 1775 1809 1740 1762 1738 1813 1780 1758 1808 1738 1803 1844 1722 1797 1783 1864 1817 1772 1749 1722 1856 1779 1815 1791 1870 1806 1851 1808 1734 1750 1791 1753 1671 1783 1702 1857 1766 1768 1733 1694 1774 1740 1752 1748 1728 1754 1763 1704 1710 1721 1684 1773 1791 1729 1694 1716 1771 1763 1666 1764 1688 1717 1687 1760 1702 1781 1770 1764 1805 1779 1762 1837 1784 1830 1855 1820 1841 1823 1882 1871 1823 1804 1829 1859 1874 1823 1798 1819 1865 1777 1769 1794 1815 1714 1718 1714 1723 1702 1711 1809 1667 1777 1777 1770 1794 1817 1725 1886 1838 1947 1842 1864 1994 1957 1976 2079 2026 2141 2261 2160 2350 2372 2204 2220 2383 2309 2291 2295 2206 2208 2132 2094 2098 1974 1980 1953 2008 1898 1868 1905 1903 1894 1816 1849 1843 1808 1721 1806 1796 1713 1805 1775 1810 1696 1731 1728 1759 1816 1792 1728 1744 1748 1710 1655 1758 1698 1753 1685 1729 1686 1847 1677 1716 1624 1649 1632 1635 1690 1616 1593 1714 1544 1756 1632 1644 1678 1663 1643 1548 1676 1706 1679 1704 1707 1606 1648 1661 1606 1647 1674 1684 1623 1618 1642 1671 1671 1692 1635 1682 1597 1735 1639 1663 1626 1683 1697 1715 1632 1675 1655 1578 1635 1687 1546 1698 1721 1646 1627 1584 1586 1748 1653 1701 1669 1659 1679 1700 1587 1669 1682 1724 1598 1670 1689 1661 1675 1662 1735 1785 1807 1724 1902 1968 1987 1996 2122 2167 2252 2411 2546 2679 2731 2823 2927 2871 2855 2745 2732 2579 2583 2745 2651 2509 2408 2470 2262 2166 2243 2179 2276 2357 2227 2342 2312 2287 2319 2517 2429 2457 2473 2580 2539 2472 2491 2473 2515 2577 2724 2756 2777 3034 3120 3266 3508 3711 3830 3798 3783 3610 3361 3164 2992 3031 2855 2797 2756 2555 2455 2293 2165 2041 1895 1824 1782 1767 1733 1759 1709 1692 1751 1697 1669 1665 1656 1685 1694 1670 1598 1726 1655 1592 1724 1622 1652 1703 1679 1634 1641 1698 1685 1728 1781 1736 1737 1694 1728 1634 1655 1783 1719 1753 1682 1739 1715 1765 1734 1865 1755 1891 1822 1867 1895 1942 2026 2090 2253 2207 2347 2519 2601 2714 2888 3024 3107 3208 3390 3463 3379 3560 3414 3498 3307 3262 3275 3378 3411 3457 3504 3497 3465 3434 3297 3239 3228 3112 3094 2922 2786 2760 2614 2532 2491 2525 2407 2424 2332 2224 2239 2346 2347 2396 2489 2532 2630 2749 2721 2851 2912 2835 2786 2864 2866 2812 2776 2797 2764 2762 2775 2728 2679 2557 2545 2629 2553 2569 2639 2745 2618 2717 2736 2725 2840 2979 3138 3310 3487 3639 3892 4266 4405 4685 4929 5135 5147 5434 5367 5363 5100 5004 4804 4447 4292 4116 3884 3745 3558 3260 3012 2789 2686 2464 2213 2215 2099 2007 1945 1899 1781 1812 1796 1768 1778 1781 1671 1695 1649 1748 1742 1698 1663 1687 1719 1640 1651 1681 1605 1647 1672 1587 1612 1683 1637 1625 1618 1615 1673 1709 1620 1727 1654 1709 1754 1810 1827 1852 1902 1939 2039 2098 2232 2243 2384 2524 2381 2562 2512 2555 2523 2412 2453 2397 2385 2230 2178 2182 2127 2070 1939 1865 1789 1806 1786 1689 1712 1587 1654 1600 1584 1596 1570 1621 1539 1566 1534 1548 1572 1642 1693 1525 1519 1594 1573 1486 1553 1523 1655 1536 1572 1592 1567 1509 1572 1560 1521 1664 1554 1536 1578 1524 1551 1508 1609 1532 1607 1505 1594 1548 1547 1589 1544 1439 1497 1576 1575 1502 1488 1625 1593 1545 1581 1521 1569 1592 1512 1599 1594 1674 1694 1734 1759 1767 1790 1820 1913 1944 2029 2002 1967 2052 1961 1952 1921 1974 1895 1859 1823 1807 1758 1835 1725 1672 1583 1673 1684 1597 1591 1583 1574 1585 1510 1628 1653 1662 1603 1764 1707 1743 1765 1724 1745 1764 1777 1732 1727 1698 1689 1746 1689 1717 1660 1678 1542 1613 1599 1516 1555 1635 1552 1601 1534 1447 1550 1563 1577 1522 1469 1544 1597 1587 1581 1556 1635 1625 1698 1654 1710 1781 1769 1836 1877 1927 2051 1934 2044 1940 1990 1913 2064 2046 2038 2022 2002 1950 1909 1783 1743 1737 1728 1686 1731 1678 1607 1647 1619 1627 1639 1512 1599 1529 1459 1517 1557 1583 1580 1519 1654 1634 1633 1789 1718 1875 1798 1863 1864 2014 2003 2112 2141 2124 2012 1930 1968 1899 1861 1846 1859 1963 1831 1829 1788 1804 1746 1733 1637 1711 1726 1666 1676 1742 1772 1688 1696 1859 1875 1861 1857 1994 1994 2094 2126 2320 2337 2314 2408 2589 2480 2643 2638 2728 2672 2720 2847 2666 2744 2658 2579 2560 2576 2389 2447 2333 2284 2219 2231 2063 2101 1932 1884 1873 1856 1787 1698 1705 1670 1695 1685 1650 1618 1564 1563 1612 1507 1550 1547 1546 1496 1521 1556 1555 1548 1565 1564 1470 1529 1501 1496 1503 1590 1468 1514 1477 1468 1476 1495 1558 1472 1516 1474 1500 1466 1482 1529 1497 1512 1379 1470 1532 1461 1518 1447 1425 1457 1461 1493 1492 1472 1426 1444 1420 1398 1486 1469 1498 1411 1581 1445 1503 1477 1476 1436 1392 1524 1427 1503 1477 1476 1395 1414 1453 1492 1441 1441 1421 1492 1425 1428 1420 1528 1467 1518 1491 1481 1418 1426 1533 1479 1563 1499 1434 1513 1441 1522 1559 1556 1584 1569 1566 1540 1529 1531 1521 1513 1520 1557 1527 1477 1542 1493 1544 1513 1588 1537 1524 1587 1595 1540 1606 1627 1619 1672 1656 1792 1708 1669 1812 1675 1830 1726 1675 1683 1645 1680 1714 1686 1587 1650 1768 1633 1785 1855 1918 1936 2010 2223 2316 2572 2555 2784 2634 2546 2420 2268 2244 2258 2352 2326 2539 2706 2857 2933 2967 3127 3015 3161 2948 2830 2608 2525 2321 2321 2187 2323 2236 2249 2227 2093 2031 1950 1889 1728 1615 1622 1505 1528 1531 1531 1502 1431 1475 1531 1581 1455 1476 1431 1460 1370 1464 1417 1490 1467 1442 1472 1472 1452 1378 1416 1407 1484 1454 1396 1420 1485 1414 1443 1451 1421 1466 1440 1485 1413 1454 1391 1460 1500 1419 1475 1469 1471 1438 1455 1467 1402 1454 1448 1502 1388 1407 1526 1399 1509 1429 1465 1544 1454 1354 1427 1457 1507 1556 1452 1457 1462 1477 1428 1510 1456 1465 1472 1459 1468 1443 1451 1539 1491 1508 1437 1472 1431 1441 1522 1493 1538 1462 1479 1468 1477 1496 1468 1516 1478 1440 1490 1526 1523 1503 1534 1542 1619 1538 1649 1562 1585 1618 1640 1685 1654 1733 1839 1804 1851 2031 1859 2088 2057 2197 2155 2294 2372 2383 2559 2520 2610 2708 2675 2703 2524 2586 2604 2505 2460 2506 2506 2351 2445 2402 2396 2464 2518 2286 2313 2206 2142 2001 1909 1971 2031 1839 1851 1816 1875 1782 1728 1619 1744 1714 1602 1558 1629 1586 1501 1475 1458 1502 1467 1428 1454 1479 1502 1480 1488 1468 1489 1493 1485 1387 1412 1400 1457 1439 1484 1424 1471 1404 1461 1439 1419 1445 1375 1402 1413 1455 1419 1460 1387 1406 1439 1420 1414 1353 1404 1380 1410 1456 1441 1455 1390 1357 1323 1419 1434 1487 1376 1458 1414 1462 1368 1448 1450 1453 1515 1490 1539 1476 1520 1520 1527 1458 1466 1501 1387 1491 1456 1412 1453 1471 1449 1464 1434 1466 1519 1417 1398 1414 1389 1425 1415 1381 1376 1351 1429 1423 1458 1453 1395 1444 1328 1436 1475 1546 1458 1526 1568 1541 1519 1630 1596 1568 1629 1664 1595 1620 1600 1489 1528 1483 1533 1480 1532 1582 1505 1522 1512 1474 1418 1405 1437 1493 1427 1369 1437 1412 1343 1405 1455 1442 1427 1430 1357 1392 1420 1328 1412 1419 1415 1404 1421 1430 1444 1380 1401 1377 1411 1361 1401 1449 1404 1424 1431 1349 1446 1438 1438 1394 1397 1424 1425 1388 1424 1426 1405 1464 1433 1415 1386 1392 1383 1382 1397 1442 1406 1442 1445 1390 1461 1449 1406 1490 1444 1436 1495 1463 1493 1402 1453 1505 1493 1454 1566 1499 1546 1490 1542 1558 1632 1531 1631 1499 1555 1679 1618 1560 1679 1611 1638 1624 1742 1678 1749 1701 1900 1952 1964 2073 2319 2390 2581 2899 3061 3485 3780 4241 4719 5222 5446 5833 6003 6192 5846 5977 5608 5329 5092 4929 4734 4655 4525 4355 4348 4139 3802 3655 3359 3197 2807 2614 2499 2210 2151 1990 2008 1850 1816 1720 1660 1686 1608 1628 1577 1616 1578 1513 1523 1584 1491 1529 1519 1572 1503 1530 1544 1585 1539 1617 1555 1572 1621 1560 1670 1787 1894 1893 2036 2104 2165 2147 2228 2126 2086 1970 1896 1886 1899 1933 2000 1905 1928 1913 2005 1848 1786 1780 1675 1737 1625 1615 1574 1558 1585 1571 1513 1566 1553 1615 1516 1516 1493 1470 1586 1483 1621 1540 1591 1592 1517 1548 1522 1448 1458 1560 1553 1497 1513 1430 1471 1511 1509 1500 1415 1475 1471 1579 1542 1434 1503 1465 1490 1531 1511 1490 1415 1487 1535 1504 1546 1592 1635 1580 1552 1675 1744 1726 1798 1787 1843 1870 1811 1831 1842 1837 1848 1821 1901 1816 1782 1815 1726 1791 1747 1756 1757 1731 1617 1626 1684 1644 1548 1562 1658 1551 1525 1467 1575 1499 1491 1501 1446 1421 1500 1513 1387 1460 1480 1483 1526 1415 1456 1383 1407 1427 1419 1451 1409 1492 1481 1412 1372 1415 1473 1422 1454 1490 1491 1404 1423 1412 1418 1460 1453 1403 1485 1433 1486 1436 1566 1468 1518 1484 1460 1458 1460 1421 1493 1458 1468 1460 1397 1547 1400 1427 1446 1467 1355 1455 1435 1426 1407 1458 1460 1416 1435 1456 1439 1397 1413 1401 1406 1428 1364 1407 1425 1452 1404 1474 1454 1340 1349 1375 1418 1410 1452 1367 1379 1468 1359 1394 1427 1445 1447 1417 1445 1442 1478 1424 1404 1404 1418 1453 1422 1427 1486 1460 1399 1432 1455 1474 1465 1475 1510 1477 1548 1463 1493 1496 1522 1556 1551 1561 1548 1703 1600 1594 1683 1716 1644 1715 1722 1837 1838 1907 1859 2079 2174 2157 2181 2318 2434 2515 2528 2695 2778 2826 2733 2917 2916 2854 2936 3053 3068 3029 3135 3143 3139 3301 3276 3260 3332 3245 3257 3216 3156 3012 2892 2848 2818 2663 2671 2739 2594 2521 2481 2429 2277 2255 2180 2158 2029 1946 1934 1938 1868 1778 1769 1672 1748 1746 1708 1611 1632 1615 1527 1587 1608 1550 1565 1592 1576 1498 1542 1501 1494 1559 1526 1529 1573 1535 1612 1548 1521 1523 1568 1505 1417 1527 1406 1537 1462 1408 1507 1433 1429 1499 1415 1450 1480 1478 1398 1396 1397 1443 1453 1377 1335 1453 1420 1363 1432 1416 1452 1375 1361 1404 1427 1340 1385 1431 1418 1379 1355 1278 1341 1407 1373 1323 1387 1362 1242 1321 1355 1403 1351 1416 1414 1354 1340 1280 1350 1378 1329 1325 1362 1325 1336 1381 1397 1388 1374 1367 1357 1343 1473 1352 1337 1331 1398 1321 1473 1390 1413 1365 1308 1361 1388 1408 1357 1448 1293 1432 1353 1416 1328 1476 1409 1367 1382 1395 1389 1352 1402 1325 1402 1387 1363 1438 1343 1381 1419 1388 1429 1382 1460 1323 1406 1466 1422 1503 1476 1441 1492 1525 1581 1571 1581 1543 1515 1482 1494 1502 1528 1485 1497 1623 1543 1607 1621 1611 1565 1691 1682 1738 1778 1820 1951 1951 2155 2301 2404 2653 2808 3197 3227 3541 3687 3958 4099 4093 3972 3891 3691 3401 3404 3259 3048 2979 2965 2975 3055 2952 3044 3007 2876 2673 2509 2376 2341 2198 2076 2070 1840 1739 1792 1729 1645 1676 1705 1671 1615 1597 1658 1673 1602 1583 1656 1608 1585 1515 1541 1629 1626 1535 1525 1530 1543 1435 1466 1455 1573 1495 1513 1506 1566 1487 1520 1510 1509 1519 1637 1549 1660 1765 1764 1743 1823 1632 1626 1678 1631 1537 1586 1580 1570 1649 1531 1718 1532 1705 1672 1669 1658 1493 1640 1613 1634 1703 1729 1770 1748 1989 1980 2222 2339 2440 2654 2779 2895 2995 3148 3336 3520 3767 3856 4149 4155 4276 4298 4080 3880 3627 3341 3119 3123 3042 3039 2934 2928 2858 2838 2735 2681 2495 2364 2184 2103 1974 1850 1758 1707 1658 1560 1476 1520 1465 1550 1506 1499 1381 1459 1430 1400 1367 1357 1374 1394 1363 1340 1321 1321 1395 1353 1384 1442 1341 1348 1288 1346 1397 1379 1348 1304 1297 1323 1333 1326 1332 1278 1356 1327 1308 1313 1266 1349 1337 1296 1341 1360 1358 1328 1275 1323 1324 1374 1262 1353 1335 1420 1378 1279 1361 1347 1346 1371 1331 1356 1393 1309 1267 1347 1337 1381 1294 1374 1340 1308 1325 1352 1337 1421 1393 1320 1449 1361 1385 1477 1432 1445 1425 1443 1443 1400 1439 1365 1418 1404 1382 1411 1433 1397 1422 1480 1468 1416 1420 1409 1395 1318 1341 1289 1330 1324 1344 1369 1335 1404 1352 1372 1339 1374 1313 1408 1308 1344 1418 1304 1409 1467 1509 1477 1615 1538 1547 1602 1583 1585 1510 1395 1429 1482 1428 1416 1400 1366 1431 1445 1439 1520 1532 1527 1435 1457 1439 1406 1524 1421 1458 1420 1494 1497 1418 1391 1356 1389 1429 1365 1317 1359 1362 1334 1378 1407 1383 1333 1365 1395 1364 1266 1294 1319 1276 1290 1321 1349 1327 1292 1281 1349 1281 1302 1301 1286 1352 1317 1317 1249 1297 1265 1305 1354 1250 1279 1344 1371 1330 1320 1310 1284 1371 1319 1358 1345 1401 1429 1395 1467 1501 1438 1495 1445 1481 1492 1546 1470 1425 1325 1402 1385 1409 1349 1444 1509 1425 1413 1438 1368 1402 1375 1409 1366 1381 1332 1330 1422 1277 1356 1386 1343 1315 1347 1354 1313 1367 1360 1361 1419 1319 1414 1375 1373 1359 1325 1354 1344 1400 1384 1320 1361 1376 1324 1360 1348 1364 1322 1424 1403 1429 1412 1356 1424 1382 1398 1344 1388 1371 1430 1396 1370 1425 1509 1493 1512 1517 1445 1421 1473 1423 1489 1471 1399 1546 1446 1544 1520 1514 1550 1606 1569 1628 1586 1506 1497 1537 1542 1515 1537 1539 1518 1610 1507 1604 1523 1529 1517 1615 1523 1572 1531 1571 1531 1560 1597 1595 1631 1611 1638 1596 1605 1602 1590 1599 1479 1590 1550 1493 1449 1554 1511 1490 1556 1465 1512 1469 1418 1439 1409 1449 1357 1424 1364 1415 1387 1399 1386 1353 1356 1383 1262 1344 1366 1368 1295 1350 1394 1272 1409 1319 1365 1325 1416 1377 1413 1354 1456 1439 1410 1431 1433 1556 1476 1474 1446 1488 1500 1500 1540 1501 1584 1515 1576 1654 1646 1568 1681 1605 1584 1650 1669 1638 1674 1724 1691 1686 1781 1727 1785 1732 1750 1782 1819 1883 1885 1873 1897 1954 1963 1964 1979 1922 1933 1890 1892 1791 1838 1873 1775 1785 1748 1790 1812 1748 1659 1687 1664 1706 1590 1649 1543 1539 1614 1563 1559 1581 1481 1490 1476 1509 1466 1454 1482 1492 1421 1485 1479 1538 1434 1317 1413 1408 1368 1371 1443 1398 1395 1389 1318 1320 1356 1318 1308 1412 1360 1357 1284 1300 1337 1284 1358 1329 1310 1322 1429 1250 1301 1283 1267 1362 1300 1304 1261 1331 1285 1266 1271 1324 1281 1312 1296 1338 1270 1289 1252 1366 1266 1315 1330 1327 1312 1328 1339 1318 1337 1368 1344 1318 1340 1332 1420 1296 1325 1341 1374 1387 1379 1301 1361 1364 1416 1436 1343 1321 1380 1374 1412 1405 1401 1371 1426 1366 1364 1389 1462 1345 1408 1418 1448 1357 1404 1422 1362 1381 1396 1302 1454 1357 1346 1335 1382 1334 1378 1372 1351 1296 1358 1399 1375 1346 1343 1324 1347 1342 1318 1302 1355 1355 1308 1325 1359 1273 1339 1296 1280 1275 1361 1323 1361 1348 1430 1405 1322 1420 1410 1350 1363 1429 1443 1388 1359 1358 1357 1410 1409 1369 1473 1504 1529 1526 1557 1654 1612 1660 1745 1807 1669 1707 1781 1720 1695 1592 1614 1604 1548 1509 1519 1505 1529 1549 1546 1586 1610 1561 1561 1558 1493 1473 1421 1475 1454 1437 1484 1441 1422 1393 1358 1436 1459 1418 1482 1447 1533 1540 1522 1544 1645 1644 1749 1810 1893 1985 2136 2353 2520 2699 2925 3112 3282 3328 3315 3253 3147 2944 2887 2641 2548 2412 2257 2324 2298 2273 2333 2389 2391 2520 2361 2259 2294 2184 2035 1897 1793 1688 1664 1627 1509 1512 1475 1529 1412 1460 1376 1364 1332 1331 1417 1418 1400 1357 1381 1453 1447 1369 1421 1478 1431 1380 1402 1349 1421 1432 1478 1389 1480 1460 1442 1487 1449 1468 1432 1476 1532 1461 1438 1425 1471 1490 1454 1387 1462 1515 1483 1427 1462 1530 1412 1555 1544 1548 1451 1545 1519 1560 1643 1578 1596 1631 1595 1601 1680 1672 1635 1647 1622 1679 1622 1693 1721 1663 1693 1660 1731 1696 1579 1669 1607 1651 1578 1627 1653 1556 1557 1585 1553 1580 1488 1573 1575 1554 1613 1598 1612 1757 1763 1882 2006 2187 2078 2058 1945 1987 1860 1830 1764 1703 1590 1578 1536 1531 1524 1528 1616 1653 1762 1724 1706 1618 1514 1579 1494 1473 1468 1434 1320 1371 1404 1373 1404 1388 1398 1430 1414 1493 1567 1558 1565 1596 1518 1545 1530 1508 1439 1474 1382 1401 1334 1425 1366 1434 1416 1418 1425 1405 1460 1429 1457 1400 1333 1390 1428 1326 1359 1323 1408 1276 1349 1336 1355 1345 1377 1324 1331 1399 1395 1384 1516 1540 1542 1536 1619 1749 1726 1745 1654 1636 1590 1529 1475 1478 1444 1376 1348 1385 1365 1478 1448 1464 1583 1561 1506 1545 1509 1431 1429 1483 1466 1361 1428 1417 1368 1371 1382 1474 1412 1438 1539 1526 1563 1547 1513 1573 1545 1532 1585 1529 1532 1490 1522 1546 1522 1406 1439 1478 1530 1564 1539 1520 1580 1496 1485 1532 1492 1529 1341 1481 1406 1381 1337 1430 1305 1341 1365 1374 1375 1289 1380 1404 1233 1311 1261 1344 1310 1293 1364 1310 1382 1339 1348 1333 1341 1358 1390 1328 1382 1421 1401 1400 1411 1386 1308 1429 1372 1391 1403 1352 1391 1316 1387 1409 1422 1327 1390 1364 1423 1400 1300 1415 1362 1368 1311 1333 1388 1407 1263 1371 1364 1412 1372 1374 1348 1361 1348 1420 1395 1363 1374 1257 1391 1396 1366 1320 1286 1373 1340 1376 1298 1314 1365 1291 1272 1402 1337 1272 1367 1281 1319 1278 1368 1255 1339 1293 1296 1202 1291 1274 1300 1283 1320 1351 1277 1311 1283 1409 1396 1303 1419 1426 1397 1553 1528 1647 1479 1584 1472 1415 1410 1402 1381 1333 1338 1381 1363 1403 1380 1460 1505 1440 1531 1556 1499 1551 1480 1432 1498 1428 1505 1476 1438 1458 1414 1406 1425 1384 1431 1448 1489 1449 1498 1458 1500 1515 1576 1536 1650 1647 1728 1626 1701 1653 1644 1676 1714 1616 1634 1670 1605 1616 1639 1552 1542 1561 1536 1591 1607 1605 1552 1532 1435 1509 1457 1482 1469 1518 1500 1451 1419 1356 1353 1362 1388 1357 1383 1442 1391 1269 1318 1349 1261 1313 1276 1267 1249 1326 1297 1284 1305 1310 1245 1330 1318 1285 1231 1250 1337 1341 1295 1392 1294 1252 1282 1272 1308 1227 1268 1259 1263 1256 1303 1270 1249 1269 1351 1308 1270 1319 1290 1298 1312 1286 1270 1278 1260 1309 1307 1321 1296 1334 1244 1287 1286 1295 1281 1295 1239 1341 1266 1365 1276 1342 1311 1380 1342 1460 1387 1463 1388 1456 1466 1516 1535 1723 1690 1870 1953 1963 2035 2041 2004 2035 1960 2054 1883 1838 1757 1738 1679 1615 1623 1550 1606 1614 1686 1657 1700 1696 1673 1694 1685 1667 1538 1534 1491 1433 1400 1326 1322 1311 1320 1326 1270 1295 1272 1261 1300 1315 1259 1337 1215 1278 1289 1273 1305 1306 1306 1347 1344 1281 1409 1380 1401 1434 1495 1494 1531 1487 1587 1421 1469 1376 1401 1369 1303 1291 1275 1341 1367 1346 1342 1323 1357 1315 1334 1421 1330 1285 1398 1336 1427 1292 1299 1251 1321 1286 1265 1315 1311 1246 1252 1244 1252 1216 1202 1287 1227 1260 1216 1240 1273 1313 1284 1322 1257 1286 1231 1286 1263 1204 1263 1301 1243 1267 1295 1320 1212 1273 1209 1268 1371 1307 1334 1424 1352 1337 1331 1406 1378 1447 1491 1529 1643 1750 1751 1891 1912 1944 2002 2129 2138 2116 2133 2163 1995 1905 1828 1754 1741 1619 1652 1570 1657 1674 1708 1658 1676 1735 1653 1686 1752 1653 1627 1653 1541 1485 1448 1471 1386 1359 1379 1296 1293 1290 1243 1377 1312 1264 1381 1349 1225 1236 1234 1258 1239 1257 1238 1277 1265 1163 1263 1344 1319 1213 1155 1244 1208 1191 1167 1179 1225 1180 1246 1218 1187 1186 1223 1220 1193 1271 1194 1207 1242 1209 1244 1265 1195 1259 1174 1131 1211 1177 1191 1265 1178 1230 1232 1156 1203 1200 1203 1255 1178 1183 1198 1169 1188 1178 1174 1152 1196 1163 1198 1199 1237 1189 1193 1194 1204 1171 1267 1197 1265 1163 1244 1209 1233 1225 1211 1244 1188 1266 1220 1189 1185 1258 1172 1199 1204 1253 1239 1211 1230 1194 1221 1278 1202 1232 1286 1251 1244 1304 1205 1201 1242 1220 1174 1253 1250 1268 1239 1281 1281 1283 1236 1309 1283 1227 1283 1291 1337 1250 1266 1290 1286 1270 1312 1282 1275 1369 1297 1348 1363 1346 1327 1356 1282 1338 1427 1360 1279 1346 1373 1358 1346 1289 1320 1333 1372 1437 1367 1367 1436 1307 1401 1385 1365 1449 1380 1412 1325 1358 1348 1349 1287 1301 1274 1299 1275 1297 1381 1283 1347 1300 1340 1362 1412 1359 1380 1343 1258 1276 1332 1263 1198 1248 1143 1276 1248 1207 1286 1259 1247 1255 1244 1260 1217 1200 1320 1202 1234 1230 1312 1245 1231 1228 1133 1217 1204 1248 1219 1204 1227 1194 1251 1224 1198 1148 1194 1143 1166 1178 1227 1201 1206 1238 1174 1194 1226 1231 1228 1205 1174 1199 1249 1229 1225 1246 1213 1240 1306 1216 1199 1264 1217 1237 1261 1259 1167 1267 1246 1279 1222 1267 1301 1264 1268 1291 1237 1324 1235 1236 1226 1250 1307 1298 1307 1331 1279 1295 1344 1319 1371 1326 1384 1391 1397 1306 1329 1356 1341 1319 1288 1291 1367 1291 1262 1307 1286 1265 1263 1369 1369 1327 1303 1426 1379 1371 1344 1436 1387 1374 1326 1389 1301 1303 1356 1332 1354 1330 1295 1286 1301 1349 1320 1296 1286 1331 1285 1338 1260 1234 1321 1297 1263 1261 1225 1195 1258 1262 1255 1272 1268 1232 1156 1291 1201 1277 1240 1225 1239 1196 1164 1202 1209 1220 1259 1228 1226 1197 1233 1265 1167 1207 1200 1224 1262 1295 1289 1288 1248 1239 1276 1270 1231 1324 1284 1296 1203 1319 1256 1277 1313 1258 1278 1217 1406 1329 1325 1359 1302 1421 1394 1434 1434 1492 1557 1597 1671 1760 1877 1892 2101 2238 2406 2330 2411 2508 2600 2617 2578 2444 2367 2101 2066 1996 1899 1780 1822 1801 1785 1707 1769 1838 1871 1908 1962 1978 2074 1890 1871 1850 1807 1773 1625 1556 1530 1539 1482 1483 1512 1517 1453 1401 1345 1377 1362 1370 1265 1255 1299 1306 1357 1319 1271 1284 1317 1298 1334 1263 1285 1317 1338 1355 1340 1298 1374 1345 1310 1345 1306 1299 1277 1297 1354 1350 1302 1287 1252 1332 1336 1355 1413 1373 1389 1425 1460 1392 1454 1460 1504 1502 1541 1609 1551 1614 1641 1717 1654 1678 1678 1604 1692 1585 1633 1534 1597 1519 1485 1494 1404 1452 1452 1403 1367 1465 1420 1443 1568 1494 1431 1545 1527 1446 1490 1455 1397 1448 1447 1411 1308 1347 1313 1305 1215 1311 1280 1274 1237 1292 1327 1232 1260 1194 1270 1289 1340 1289 1291 1176 1229 1261 1255 1192 1243 1248 1256 1162 1195 1202 1212 1172 1145 1176 1212 1215 1225 1244 1287 1188 1281 1255 1231 1289 1280 1215 1268 1213 1207 1173 1191 1237 1224 1209 1289 1200 1228 1213 1166 1251 1270 1212 1234 1255 1189 1247 1268 1259 1260 1231 1218 1297 1244 1207 1228 1216 1226 1247 1208 1165 1233 1243 1248 1263 1189 1201 1300 1243 1209 1283 1247 1252 1210 1259 1193 1230 1240 1271 1202 1227 1197 1197 1280 1238 1238 1230 1148 1257 1249 1221 1252 1237 1259 1249 1272 1234 1276 1192 1380 1302 1296 1260 1280 1296 1321 1318 1296 1439 1352 1388 1391 1337 1358 1354 1322 1322 1404 1360 1312 1332 1369 1319 1377 1296 1344 1389 1319 1267 1432 1274 1343 1339 1334 1252 1315 1279 1313 1266 1299 1237 1333 1258 1286 1266 1287 1300 1262 1355 1342 1254 1299 1229 1285 1196 1218 1187 1267 1256 1217 1219 1219 1256 1241 1256 1266 1245 1254 1209 1277 1243 1282 1302 1279 1204 1250 1228 1243 1233 1160 1234 1187 1215 1227 1130 1173 1212 1245 1203 1228 1271 1236 1264 1243 1210 1228 1224 1243 1171 1248 1275 1162 1257 1179 1235 1163 1198 1242 1208 1227 1180 1208 1157 1244 1185 1155 1195 1169 1184 1241 1140 1210 1246 1280 1202 1206 1247 1225 1149 1201 1213 1259 1235 1210 1300 1248 1187 1191 1134 1222 1168 1180 1223 1144 1264 1183 1147 1236 1225 1181 1303 1229 1166 1194 1110 1166 1147 1177 1180 1215 1225 1180 1172 1221 1186 1179 1178 1198 1182 1201 1261 1190 1229 1232 1212 1222 1136 1166 1182 1175 1221 1229 1195 1223 1248 1232 1204 1174 1206 1254 1253 1257 1188 1282 1214 1274 1279 1244 1288 1234 1226 1246 1255 1283 1279 1251 1273 1268 1195 1255 1271 1226 1224 1185 1256 1233 1219 1241 1219 1236 1201 1219 1292 1265 1173 1191 1226 1182 1192 1187 1214 1224 1169 1191 1260 1246 1262 1207 1216 1198 1149 1196 1172 1212 1100 1196 1128 1220 1212 1242 1177 1150 1145 1173 1179 1169 1220 1162 1148 1100 1187 1196 1169 1168 1197 1193 1226 1187 1233 1210 1178 1203 1216 1206 1225 1226 1215 1214 1242 1245 1181 1267 1253 1270 1252 1281 1263 1240 1292 1290 1284 1221 1278 1285 1210 1333 1267 1331 1270 1240 1208 1187 1281 1162 1253 1202 1245 1289 1320 1247 1247 1236 1178 1171 1228 1241 1265 1239 1250 1216 1240 1184 1297 1234 1282 1212 1211 1249 1178 1212 1237 1239 1220 1198 1219 1187 1165 1224 1202 1215 1194 1263 1155 1210 1205 1180 1252 1210 1162 1170 1208 1185 1170 1255 1129 1162 1282 1186 1182 1206 1164 1197 1242 1203 1179 1136 1239 1219 1201 1258 1194 1192 1175 1212 1190 1216 1183 1272 1244 1277 1265 1258 1287 1323 1337 1281 1276 1327 1359 1284 1287 1272 1249 1200 1324 1234 1253 1211 1287 1268 1257 1341 1264 1312 1323 1362 1335 1394 1417 1340 1358 1326 1379 1362 1360 1290 1337 1277 1344 1273 1355 1272 1297 1308 1263 1278 1297 1305 1277 1298 1278 1295 1297 1310 1295 1224 1334 1307 1279 1279 1297 1305 1301 1327 1303 1367 1318 1351 1367 1363 1358 1437 1454 1526 1485 1660 1689 1755 1771 1750 1815 1804 1790 1789 1782 1666 1575 1596 1528 1475 1503 1364 1403 1437 1464 1459 1426 1493 1422 1541 1488 1519 1490 1533 1530 1508 1428 1456 1433 1459 1442 1429 1347 1351 1365 1376 1394 1421 1343 1475 1438 1443 1480 1481 1487 1512 1469 1464 1446 1401 1359 1390 1294 1371 1315 1342 1283 1334 1315 1387 1306 1336 1400 1332 1375 1439 1302 1331 1381 1312 1289 1277 1298 1262 1254 1200 1295 1255 1260 1287 1224 1236 1204 1226 1239 1248 1236 1275 1265 1276 1323 1217 1302 1251 1366 1333 1408 1363 1412 1347 1382 1257 1206 1262 1308 1252 1288 1241 1319 1338 1338 1349 1244 1262 1205 1294 1189 1260 1289 1222 1259 1195 1332 1277 1172 1291 1274 1234 1262 1296 1289 1245 1226 1277 1305 1267 1256 1265 1232 1281 1300 1227 1221 1308 1265 1215 1191 1288 1206 1267 1228 1323 1201 1270 1283 1271 1211 1231 1251 1264 1327 1215 1259 1269 1281 1278 1281 1285 1237 1264 1343 1355 1292 1315 1237 1336 1307 1371 1382 1284 1366 1249 1250 1265 1297 1258 1285 1318 1240 1338 1339 1259 1311 1262 1285 1275 1304 1229 1347 1284 1259 1194 1261 1278 1296 1281 1277 1302 1302 1282 1294 1348 1295 1269 1285 1247 1297 1254 1199 1301 1258 1318 1237 1255 1240 1247 1238 1269 1278 1231 1272 1229 1322 1197 1208 1263 1288 1269 1258 1295 1210 1288 1213 1224 1256 1237 1198 1224 1153 1164 1196 1231 1215 1228 1191 1274 1149 1190 1252 1230 1190 1237 1158 1206 1267 1189 1235 1152 1193 1194 1158 1262 1145 1196 1241 1114 1201 1185 1189 1210 1220 1180 1114 1172 1225 1204 1237 1190 1190 1175 1140 1061 1157 1204 1153 1202 1169 1194 1160 1214 1193 1168 1147 1215 1207 1204 1205 1171 1208 1227 1250 1216 1247 1279 1189 1227 1243 1213 1320 1300 1310 1236 1227 1257 1279 1214 1323 1230 1238 1189 1217 1198 1235 1251 1270 1211 1215 1180 1218 1177 1261 1251 1285 1247 1265 1179 1213 1180 1244 1199 1178 1215 1215 1185 1211 1200 1195 1204 1200 1196 1168 1166 1165 1211 1197 1143 1247 1157 1244 1229 1191 1201 1160 1175 1166 1171 1127 1181 1164 1176 1218 1238 1170 1209 1157 1142 1215 1231 1194 1248 1175 1181 1173 1168 1210 1165 1225 1241 1220 1174 1233 1224 1135 1154 1143 1208 1176 1186 1156 1157 1201 1147 1146 1176 1182 1210 1179 1215 1167 1247 1138 1214 1206 1279 1167 1160 1161 1191 1147 1195 1248 1237 1162 1267 1163 1227 1243 1193 1231 1245 1156 1233 1181 1145 1181 1207 1253 1177 1239 1231 1238 1261 1192 1275 1219 1287 1272 1225 1263 1219 1243 1230 1182 1256 1307 1209 1230 1242 1283 1309 1315 1315 1225 1233 1291 1313 1225 1298 1277 1292 1244 1340 1304 1323 1266 1348 1336 1259 1320 1304 1326 1366 1330 1362 1294 1370 1351 1300 1327 1349 1342 1382 1390 1422 1395 1401 1358 1381 1381 1403 1409 1425 1377 1361 1380 1338 1416 1394 1313 1317 1333 1360 1273 1371 1326 1294 1293 1331 1360 1342 1348 1336 1291 1279 1252 1348 1364 1345 1254 1317 1295 1296 1280 1262 1292 1209 1218 1265 1253 1217 1193 1256 1225 1247 1250 1299 1234 1183 1235 1185 1228 1240 1222 1212 1222 1167 1192 1215 1174 1232 1259 1231 1189 1201 1258 1253 1253 1234 1210 1228 1170 1205 1187 1236 1236 1180 1183 1175 1208 1149 1244 1188 1202 1211 1193 1220 1210 1251 1224 1252 1328 1239 1283 1209 1254 1315 1235 1236 1188 1229 1215 1201 1219 1217 1169 1193 1181 1249 1241 1274 1261 1253 1326 1353 1329 1387 1359 1352 1323 1258 1258 1290 1261 1253 1269 1211 1233 1263 1290 1272 1306 1263 1253 1337 1386 1243 1260 1320 1379 1402 1449 1425 1382 1391 1315 1343 1302 1308 1289 1318 1276 1283 1305 1233 1297 1271 1223 1228 1247 1234 1279 1306 1276 1285 1266 1250 1266 1239 1209 1271 1257 1243 1208 1261 1290 1331 1211 1199 1238 1252 1235 1186 1246 1199 1243 1249 1163 1162 1225 1209 1225 1192 1188 1270 1167 1227 1212 1222 1164 1183 1154 1166 1240 1149 1147 1185 1187 1226 1182 1171 1142 1223 1181 1291 1171 1191 1175 1257 1170 1235 1155 1199 1231 1225 1206 1226 1261 1204 1271 1187 1202 1200 1182 1239 1171 1203 1297 1127 1172 1147 1192 1305 1228 1159 1231 1230 1260 1154 1234 1187 1224 1193 1179 1141 1155 1162 1206 1150 1127 1204 1146 1210 1189 1238 1206 1224 1167 1161 1208 1157 1158 1168 1159 1181 1211 1097 1178 1206 1211 1178 1127 1114 1140 1190 1197 1206 1203 1181 1160 1149 1187 1182 1140 1157 1146 1132 1132 1200 1170 1134 1209 1176 1107 1151 1158 1213 1171 1229 1138 1170 1127 1156 1190 1181 1169 1185 1107 1175 1129 1116 1154 1131 1133 1243 1152 1126 1182 1131 1139 1176 1201 1099 1229 1152 1131 1194 1150 1189 1189 1195 1163 1150 1155 1170 1171 1175 1220 1126 1143 1165 1123 1156 1143 1171 1171 1161 1176 1191 1151 1199 1159 1196 1215 1126 1137 1206 1153 1187 1224 1178 1142 1260 1203 1265 1196 1174 1285 1172 1219 1227 1200 1280 1273 1205 1192 1193 1164 1185 1198 1163 1193 1209 1212 1193 1168 1178 1186 1173 1179 1176 1211 1105 1190 1162 1174 1196 1208 1224 1141 1223 1246 1200 1204 1188 1131 1115 1151 1169 1194 1192 1186 1151 1173 1156 1206 1193 1141 1217 1160 1211 1202 1168 1151 1161 1266 1181 1122 1227 1200 1076 1134 1229 1166 1245 1195 1215 1154 1216 1179 1188 1165 1253 1200 1227 1321 1250 1173 1262 1232 1290 1270 1311 1294 1313 1237 1307 1292 1237 1281 1212 1188 1187 1265 1224 1225 1182 1134 1228 1179 1162 1233 1225 1223 1212 1283 1222 1298 1238 1230 1219 1221 1295 1214 1289 1217 1230 1252 1271 1171 1273 1193 1191 1255 1194 1183 1262 1187 1173 1245 1254 1275 1230 1258 1221 1280 1276 1314 1284 1307 1312 1272 1288 1248 1283 1262 1166 1249 1167 1226 1176 1224 1268 1187 1230 1207 1249 1224 1245 1305 1201 1238 1318 1384 1333 1347 1373 1426 1477 1510 1522 1495 1389 1488 1435 1474 1412 1377 1443 1342 1326 1345 1328 1361 1313 1252 1279 1302 1244 1256 1196 1255 1240 1309 1315 1329 1377 1364 1304 1322 1341 1280 1332 1369 1287 1260 1294 1255 1296 1238 1227 1241 1206 1251 1292 1199 1226 1201 1238 1168 1219 1227 1205 1205 1220 1244 1209 1267 1203 1298 1249 1208 1265 1258 1209 1292 1278 1243 1238 1347 1298 1335 1349 1359 1334 1305 1365 1366 1311 1332 1367 1346 1439 1389 1423 1485 1550 1552 1581 1603 1557 1528 1536 1484 1503 1428 1382 1365 1360 1373 1336 1362 1322 1329 1356 1359 1274 1329 1315 1351 1333 1339 1352 1376 1333 1344 1374 1377 1429 1416 1390 1365 1378 1354 1320 1250 1261 1303 1338 1284 1245 1291 1241 1213 1225 1216 1246 1259 1231 1194 1199 1259 1154 1167 1170 1168 1216 1216 1214 1189 1143 1226 1183 1239 1169 1156 1186 1221 1154 1147 1186 1129 1177 1172 1264 1193 1203 1215 1238 1215 1249 1227 1143 1146 1157 1144 1237 1152 1163 1176 1144 1185 1224 1217 1139 1222 1111 1182 1220 1232 1194 1168 1184 1270 1248 1191 1081 1170 1255 1134 1217 1219 1249 1184 1174 1197 1108 1125 1184 1205 1128 1127 1117 1171 1210 1089 1201 1167 1165 1213 1149 1272 1166 1183 1155 1148 1194 1145 1187 1219 1181 1193 1098 1177 1207 1211 1184 1190 1167 1211 1208 1177 1140 1147 1179 1244 1145 1176 1228 1197 1210 1138 1165 1198 1238 1233 1237 1243 1239 1214 1299 1188 1226 1146 1147 1174 1183 1180 1143 1181 1255 1169 1130 1185 1179 1162 1134 1192 1239 1149 1180 1231 1254 1112 1093 1215 1257 1208 1147 1284 1213 1182 1168 1202 1158 1141 1148 1214 1195 1206 1185 1166 1193 1149 1109 1119 1161 1165 1231 1136 1261 1195 1105 1098 1183 1117 1169 1164 1142 1156 1120 1239 1147 1187 1138 1198 1141 1146 1153 1223 1130 1185 1239 1232 1219 1197 1191 1200 1189 1113 1225 1200 1204 1175 1140 1168 1159 1211 1248 1191 1205 1211 1270 1124 1168 1197 1222 1215 1228 1139 1213 1230 1258 1233 1260 1205 1206 1261 1254 1281 1339 1334 1351 1344 1417 1333 1375 1415 1418 1381 1424 1409 1403 1429 1432 1347 1399 1330 1315 1354 1333 1284 1237 1258 1286 1186 1287 1201 1284 1286 1209 1322 1238 1252 1211 1233 1233 1263 1274 1286 1285 1252 1307 1232 1189 1318 1297 1372 1217 1278 1228 1234 1210 1218 1274 1194 1123 1204 1192 1255 1215 1164 1197 1179 1251 1284 1205 1195 1210 1177 1198 1264 1117 1212 1183 1179 1175 1167 1177 1202 1224 1188 1218 1215 1169 1207 1171 1183 1169 1205 1189 1255 1189 1160 1273 1212 1197 1207 1186 1212 1176 1200 1186 1242 1149 1218 1203 1163 1214 1213 1246 1251 1146 1242 1177 1250 1174 1174 1244 1229 1272 1216 1211 1164 1229 1263 1186 1211 1224 1207 1268 1250 1276 1286 1298 1298 1301 1277 1327 1404 1340 1298 1356 1364 1367 1380 1330 1366 1420 1360 1359 1345 1342 1397 1295 1279 1283 1266 1282 1315 1272 1324 1347 1299</counts>
			</dataPoints>
		</scan>
	</xrdMeasurement>
</xrdMeasurements>