File: dataset/precursor_mixture/TiO2_GeO2_SnO2.12-min.xrdml
<?xml version="1.0"?>
<xrdMeasurements xmlns="http://www.xrdml.com/XRDMeasurement/2.2" xmlns:xsi="http://www.w3.org/2001/XMLSchema-instance" xsi:schemaLocation="http://www.xrdml.com/XRDMeasurement/2.2 http://www.xrdml.com/XRDMeasurement/2.2/XRDMeasurement.xsd" status="Completed" recordIdentifier="{CDA22758-4F3A-4B18-9B83-C3A619BE7626}">
	<comment>
		<entry/>
	</comment>
	<sample type="To be analyzed">
		<id>dara-3-2</id>
		<name></name>
		<preparedBy></preparedBy>
	</sample>
	<xrdMeasurement measurementType="Scan" status="Completed" sampleMode="Reflection">
		<usedWavelength intended="K-Alpha 1">
			<kAlpha1 unit="Angstrom">1.5405980</kAlpha1>
			<kAlpha2 unit="Angstrom">1.5444260</kAlpha2>
			<kBeta unit="Angstrom">1.3922500</kBeta>
			<ratioKAlpha2KAlpha1>0.5000</ratioKAlpha2KAlpha1>
		</usedWavelength>
		<incidentBeamPath>
			<radius unit="mm">145.00</radius>
			<xRayTube id="1010048" name="Empyrean Cu LFF HR (9430 033 7310x) DK430614">
				<tension unit="kV">40.0</tension>
				<current unit="mA">15.0</current>
				<anodeMaterial>Cu</anodeMaterial>
				<focus type="Line">
					<length unit="mm">12.0</length>
					<width unit="mm">0.4</width>
					<takeOffAngle unit="deg">6.0</takeOffAngle>
				</focus>
			</xRayTube>
			<filter id="20010004" name="Beta-filter Nickel">
				<material>Ni</material>
				<thickness unit="mm">0.020</thickness>
			</filter>
			<sollerSlit id="21010002" name="Soller slits 0.04 rad.">
				<opening unit="rad">0.0400</opening>
			</sollerSlit>
			<mask id="22031000" name="Fixed mask 13 mm">
				<width unit="mm">9.00</width>
			</mask>
			<divergenceSlit id="22120001" name="Divergence slit 1°" xsi:type="fixedDivergenceSlitType">
				<distanceToSample unit="mm">50.00</distanceToSample>
				<height unit="mm">1.52</height>
			</divergenceSlit>
		</incidentBeamPath>
		<beamKnife id="29030100" name="Beam knife low"/>
		<sampleMovement xsi:type="spinningSampleMovementType">
			<spinnerRevolutionTime unit="seconds">1.0</spinnerRevolutionTime>
		</sampleMovement>
		<diffractedBeamPath>
			<radius unit="mm">145.00</radius>
			<antiScatterSlit id="22090040" name="AS slit 9 mm" xsi:type="fixedAntiScatterSlitType">
				<height unit="mm">9.00</height>
			</antiScatterSlit>
			<sollerSlit id="21020003" name="Large Soller slits 0.04 rad.">
				<opening unit="rad">0.0400</opening>
			</sollerSlit>
			<filter id="20030001" name="Large beta-filter Nickel">
				<material>Ni</material>
				<thickness unit="mm">0.020</thickness>
			</filter>
			<detector id="7010019" name="PIXcel1D-Medipix3 detector" xsi:type="rtmsDetectorType">
				<phd unit="keV">
					<lowerLevel>4.0</lowerLevel>
					<upperLevel>11.3</upperLevel>
				</phd>
				<mode>Scanning</mode>
				<activeLength unit="deg">5.020</activeLength>
			</detector>
		</diffractedBeamPath>
		<scan appendNumber="0" mode="Continuous" scanAxis="Gonio" status="Completed">
			<header>
				<startTimeStamp>2024-02-18T09:35:29-08:00</startTimeStamp>
				<endTimeStamp>2024-02-18T09:47:57-08:00</endTimeStamp>
				<author>
					<name>AutomatedUser</name>
				</author>
				<source>
					<applicationSoftware version="1.4b (28)">PANalytical Aeris Instrument Suite</applicationSoftware>
					<instrumentControlSoftware version="2.0.0 20210224">AERIS</instrumentControlSoftware>
					<instrumentID>950485</instrumentID>
				</source>
			</header>
			<dataPoints>
				<positions axis="2Theta" unit="deg">
					<startPosition>9.99043322</startPosition>
					<endPosition>100.09495370</endPosition>
				</positions>
				<positions axis="Omega" unit="deg">
					<startPosition>4.99521661</startPosition>
					<endPosition>50.04747685</endPosition>
				</positions>
				<commonCountingTime unit="seconds">18.249</commonCountingTime>
				<counts unit="counts">3539 3492 3438 3474 3395 3532 3539 3462 3510 3524 3533 3447 3398 3455 3456 3573 3431 3489 3391 3517 3508 3451 3388 3543 3400 3490 3513 3430 3488 3383 3416 3348 3324 3472 3340 3397 3340 3464 3363 3287 3247 3424 3304 3266 3318 3292 3317 3418 3240 3334 3367 3373 3352 3253 3382 3177 3313 3318 3273 3304 3304 3277 3318 3278 3280 3338 3276 3275 3243 3288 3246 3198 3094 3310 3189 3270 3241 3262 3144 3168 3167 3201 3238 3159 3115 3166 3219 3229 3162 3102 3154 3187 3207 3205 3253 3068 3225 3114 3103 3085 3165 2963 3082 3102 3051 3101 3051 3167 3029 3113 3101 3023 2995 3114 3029 2992 3035 3102 2970 3047 3023 3021 3054 3000 3079 3010 2944 3096 2964 3079 3070 2971 2990 2972 2926 2982 2898 2895 2960 2944 2984 2894 2912 3014 2926 2896 2923 2858 2942 2886 2831 3015 2976 2922 2937 2863 2896 2885 2862 2919 2868 2828 2865 2905 2918 2906 2862 2837 2799 2847 2746 2753 2776 2859 2863 2799 2730 2836 2745 2726 2766 2770 2709 2728 2693 2847 2851 2765 2776 2713 2816 2784 2852 2756 2646 2773 2731 2756 2760 2746 2682 2779 2578 2729 2752 2694 2828 2665 2712 2629 2728 2698 2699 2686 2621 2603 2661 2613 2675 2628 2635 2711 2672 2658 2743 2686 2647 2623 2613 2533 2625 2596 2701 2631 2659 2686 2707 2615 2710 2598 2514 2595 2524 2514 2644 2553 2550 2585 2532 2644 2519 2562 2498 2532 2590 2525 2507 2604 2592 2575 2586 2520 2585 2608 2483 2517 2590 2560 2615 2488 2494 2478 2490 2458 2478 2487 2519 2474 2521 2524 2517 2544 2510 2490 2421 2535 2488 2446 2479 2497 2459 2509 2427 2452 2555 2528 2456 2537 2466 2461 2437 2464 2402 2477 2561 2470 2386 2463 2450 2395 2404 2392 2370 2438 2456 2304 2463 2384 2380 2423 2410 2338 2338 2295 2441 2335 2420 2288 2393 2367 2409 2328 2431 2344 2328 2419 2393 2404 2359 2317 2488 2385 2348 2286 2408 2394 2392 2364 2351 2370 2382 2352 2303 2282 2288 2355 2335 2341 2316 2326 2438 2276 2287 2350 2264 2316 2211 2250 2300 2365 2293 2346 2330 2366 2334 2254 2247 2203 2281 2245 2248 2222 2242 2225 2360 2206 2203 2233 2323 2333 2272 2307 2285 2285 2220 2325 2303 2313 2198 2312 2207 2214 2193 2299 2225 2321 2266 2284 2181 2197 2244 2208 2261 2264 2257 2235 2251 2293 2150 2318 2233 2221 2194 2266 2266 2193 2190 2204 2093 2165 2220 2153 2149 2200 2163 2227 2207 2189 2269 2126 2193 2192 2145 2249 2233 2195 2250 2193 2186 2157 2166 2168 2150 2134 2180 2226 2114 2214 2189 2150 2245 2241 2218 2226 2118 2205 2132 2295 2196 2099 2175 2064 2184 2039 2110 2154 2030 2184 2147 2113 2167 2140 2108 2148 2103 2171 2125 2130 2156 2083 2064 2156 2135 2108 2056 2114 2187 2130 2166 2191 2048 2103 2074 2099 2107 2132 2085 2132 2033 2163 2025 2140 2135 2034 2137 2150 2150 2197 2119 2148 2090 2053 2085 2113 2115 2154 2004 2051 2162 2139 2060 2108 2136 2050 2053 2126 2192 1997 2033 2044 2136 2128 2037 2106 1990 2107 2083 2059 2071 2098 2089 2108 2086 2026 1938 2002 2055 2086 2061 2012 2076 2042 2067 2002 2004 1998 2147 1982 2046 2078 2012 2011 2033 2032 2035 2049 1997 2098 2003 2092 2057 1937 2101 1988 2019 1996 1972 1945 2007 2074 2009 1957 1968 2013 2037 2027 2040 1963 1928 1972 1968 1990 1958 1950 2005 2024 1916 2079 1962 1955 1991 1994 1973 1967 1902 1960 1974 1957 2012 1981 1910 1947 1942 1940 1980 1980 1874 1958 1950 2057 1872 1930 1983 1851 1936 1948 1951 1925 2011 1869 1917 1930 1950 1867 1926 2026 1990 1913 1919 1988 1936 1956 1871 1911 1907 1939 1934 1858 1857 1942 1885 1896 1951 1880 1880 1916 1968 1914 1957 1844 1893 1932 2026 1907 1884 1915 1919 1894 1831 1877 1812 1931 1965 1867 1944 1895 1935 1846 1977 1915 1879 1876 1842 1882 1851 1786 1875 1839 1863 1845 1909 1805 1830 1840 1915 1872 1794 1956 1784 1896 1773 1831 1809 1906 1852 1914 1842 1834 1877 1889 1809 1880 1876 1858 1763 1740 1786 1899 1789 1843 1724 1837 1800 1805 1812 1936 1788 1850 1958 1849 1783 1868 1791 1839 1800 1812 1762 1795 1864 1826 1888 1828 1835 1860 1853 1760 1825 1776 1825 1807 1842 1822 1839 1839 1826 1741 1829 1678 1820 1728 1780 1758 1807 1787 1703 1809 1792 1785 1770 1776 1795 1878 1799 1800 1742 1742 1824 1751 1781 1764 1784 1803 1763 1761 1729 1796 1769 1844 1825 1751 1754 1771 1732 1738 1790 1781 1805 1706 1789 1819 1728 1751 1730 1743 1755 1682 1802 1708 1661 1674 1745 1810 1758 1726 1758 1743 1641 1713 1678 1704 1700 1791 1732 1753 1686 1682 1619 1761 1704 1701 1716 1720 1684 1727 1788 1743 1686 1738 1703 1755 1733 1668 1754 1735 1653 1725 1708 1745 1698 1668 1685 1745 1667 1694 1653 1673 1792 1676 1644 1664 1700 1707 1702 1667 1728 1717 1684 1630 1736 1678 1644 1591 1694 1711 1710 1664 1733 1670 1608 1687 1646 1672 1678 1639 1694 1661 1664 1687 1637 1679 1693 1717 1649 1729 1729 1594 1668 1680 1618 1717 1738 1713 1687 1679 1633 1690 1602 1705 1627 1682 1600 1713 1565 1705 1569 1686 1592 1553 1760 1599 1689 1610 1665 1722 1664 1693 1730 1638 1649 1587 1656 1742 1695 1737 1718 1783 1714 1633 1724 1845 1799 1840 1785 1788 1839 1825 1799 1855 1826 1858 1991 2054 2016 1995 1999 2201 2228 2260 2351 2412 2521 2570 2653 2905 2817 3099 3143 3296 3368 3477 3659 3617 3695 3863 3827 3817 3784 3521 3390 3210 3044 2939 2717 2535 2450 2226 2087 1993 2039 1937 1885 1897 1789 1803 1812 1667 1749 1762 1695 1737 1560 1607 1677 1657 1633 1630 1699 1662 1568 1580 1609 1630 1598 1613 1641 1676 1597 1601 1618 1532 1609 1575 1627 1577 1534 1590 1566 1563 1603 1596 1580 1568 1524 1627 1509 1575 1490 1588 1479 1485 1545 1533 1588 1558 1514 1497 1510 1563 1526 1500 1494 1539 1499 1530 1515 1514 1483 1554 1529 1642 1454 1500 1499 1594 1517 1532 1489 1540 1452 1547 1549 1492 1470 1537 1468 1537 1492 1473 1430 1475 1465 1525 1525 1529 1472 1476 1507 1534 1457 1455 1488 1513 1510 1501 1429 1483 1401 1405 1403 1515 1519 1494 1414 1535 1505 1407 1458 1546 1511 1524 1482 1508 1463 1427 1415 1531 1454 1463 1499 1465 1518 1414 1402 1514 1431 1497 1438 1479 1404 1516 1484 1471 1398 1488 1423 1413 1521 1510 1460 1410 1447 1426 1368 1508 1467 1506 1476 1406 1422 1418 1435 1406 1440 1409 1450 1420 1392 1407 1328 1434 1398 1505 1491 1484 1415 1456 1368 1452 1477 1403 1376 1486 1433 1469 1438 1409 1471 1438 1476 1383 1507 1427 1451 1497 1467 1356 1457 1443 1442 1353 1429 1374 1338 1375 1381 1328 1406 1365 1424 1467 1445 1410 1386 1393 1404 1407 1431 1379 1436 1484 1339 1406 1443 1356 1405 1390 1391 1372 1361 1407 1319 1384 1336 1416 1393 1389 1390 1360 1437 1340 1380 1415 1424 1389 1398 1460 1431 1458 1408 1404 1427 1404 1295 1352 1370 1381 1445 1374 1451 1423 1392 1360 1413 1415 1396 1410 1342 1403 1334 1330 1352 1342 1390 1351 1425 1354 1348 1360 1407 1385 1348 1394 1367 1435 1376 1416 1371 1393 1352 1391 1350 1426 1372 1405 1471 1412 1399 1442 1279 1422 1430 1354 1454 1388 1386 1380 1318 1429 1364 1377 1421 1334 1325 1292 1335 1360 1394 1357 1417 1346 1344 1416 1286 1378 1355 1377 1389 1421 1367 1424 1324 1381 1360 1380 1366 1366 1362 1276 1357 1377 1371 1475 1493 1416 1437 1432 1421 1461 1483 1477 1484 1462 1494 1447 1468 1542 1516 1513 1433 1507 1516 1579 1457 1514 1478 1529 1528 1582 1593 1520 1572 1567 1474 1624 1603 1568 1651 1600 1659 1703 1660 1634 1682 1658 1745 1805 1800 1838 1815 1892 1916 1953 2013 1995 2012 2137 2286 2322 2240 2577 2723 2817 3033 3306 3526 3888 4206 4615 5061 5386 6061 6692 7451 8209 9161 10144 10919 12035 12993 13784 14677 15674 15970 15767 15362 14816 13904 12726 11624 10467 9349 8090 7138 6070 5088 4700 3934 3552 3362 3145 2900 2834 2812 2768 2639 2707 2543 2518 2687 2568 2652 2735 2695 2841 2873 3011 3133 3192 3322 3455 3676 3896 4144 4477 4915 5225 5599 6239 6695 7664 8230 9147 9813 10693 11864 12717 13537 14665 15379 16014 16236 16261 16059 15499 14927 13919 12825 11649 10557 9420 8512 7682 6800 5980 5438 4900 4561 4147 4098 3801 3700 3530 3522 3452 3464 3306 3487 3453 3537 3572 3596 3731 3845 3858 4112 4242 4341 4628 4943 5106 5484 5943 6298 6927 7263 8046 8689 9307 10464 11406 12281 13325 14666 15600 17167 18075 19295 20454 21315 22208 22298 22602 22323 21501 20059 19163 17871 16546 14955 13493 12181 10718 9553 8512 7625 6761 6122 5483 4973 4697 4258 4088 3830 3602 3383 3240 3105 3104 2935 2821 2665 2615 2521 2468 2374 2326 2258 2178 2153 2104 2041 1956 1942 1879 1928 1833 1737 1699 1750 1703 1723 1656 1619 1736 1635 1637 1673 1661 1610 1680 1619 1588 1684 1623 1582 1515 1600 1584 1506 1625 1493 1606 1511 1557 1569 1479 1583 1557 1500 1466 1535 1478 1486 1436 1429 1427 1439 1409 1455 1459 1352 1407 1347 1351 1402 1346 1383 1324 1367 1372 1364 1363 1350 1369 1306 1301 1297 1302 1287 1285 1314 1279 1228 1297 1231 1314 1284 1286 1274 1264 1337 1297 1319 1305 1299 1221 1360 1280 1278 1299 1240 1336 1276 1328 1289 1247 1299 1274 1258 1255 1253 1280 1279 1252 1277 1218 1329 1235 1247 1253 1205 1228 1220 1199 1254 1173 1260 1240 1243 1141 1156 1188 1201 1261 1183 1265 1195 1209 1235 1212 1183 1149 1210 1157 1173 1106 1189 1182 1242 1226 1148 1168 1139 1174 1169 1167 1213 1161 1188 1165 1155 1149 1112 1132 1147 1182 1150 1120 1202 1118 1159 1208 1188 1147 1154 1190 1172 1132 1139 1068 1168 1157 1158 1117 1106 1127 1132 1163 1198 1147 1149 1122 1156 1178 1163 1172 1160 1155 1122 1199 1117 1169 1161 1122 1142 1154 1141 1105 1109 1171 1179 1113 1070 1116 1094 1113 1109 1086 1111 1147 1163 1047 1030 1101 1111 1120 1129 1099 1120 1107 1104 1084 1038 1051 1085 1098 1124 1103 1132 1051 1085 1108 1084 1051 1097 1136 1072 1051 1053 1080 1023 1103 1041 1126 1101 1127 1130 1109 1108 1078 1068 1036 1022 1083 1085 1030 1128 1053 1034 1116 1063 1106 1016 1123 988 1124 1064 1131 1068 1022 1107 1010 1070 1041 1075 1020 1053 1035 1034 994 1049 1063 1082 1001 1064 1057 1022 1016 1018 1018 1066 1015 1056 987 1020 1094 1032 1074 1104 1078 973 1079 1046 1053 999 1011 1021 1042 1065 1038 1039 1035 1064 1090 1003 1014 1037 1014 1005 1024 1074 1016 1064 1013 1033 1063 1054 1063 1045 1031 1020 1069 1007 1072 1053 1063 1031 978 971 1021 978 979 1000 1003 976 1035 1011 971 1005 1031 987 1003 975 974 927 947 962 1031 1056 1058 1039 953 984 988 1033 985 1076 959 1006 1012 994 930 990 927 981 1027 964 915 980 999 994 981 1040 1023 987 996 1004 938 985 1001 934 1018 948 1061 1020 953 1034 973 979 1010 1048 990 962 1029 957 934 968 1035 942 972 957 959 966 976 969 998 992 895 1017 936 906 1003 954 962 937 960 990 989 913 1020 960 963 1008 917 958 984 996 998 932 1011 980 896 1022 966 912 980 941 960 941 995 978 1035 961 942 1024 951 990 1009 951 896 954 972 932 997 1000 986 1005 959 958 946 986 959 983 932 939 980 955 929 975 976 939 927 941 1018 925 998 961 972 946 978 923 926 965 985 977 981 935 1015 960 987 962 1030 931 1016 956 967 937 985 968 932 985 979 951 959 976 969 982 982 1025 977 1022 1024 992 1006 1077 984 1058 988 1149 1007 1049 988 1025 1067 1105 1112 1150 1088 1101 1072 1109 1019 1071 1084 1021 1066 1066 1087 1107 1031 1176 1091 1072 1124 1143 1162 1196 1116 1180 1157 1169 1065 1129 1208 1106 1172 1180 1222 1214 1222 1168 1210 1210 1337 1184 1285 1288 1177 1274 1359 1288 1334 1394 1396 1442 1495 1452 1510 1533 1554 1651 1608 1668 1709 1643 1673 1840 1812 1922 1938 1948 2186 2184 2324 2284 2498 2530 2752 3011 3206 3244 3515 3860 4245 4440 5020 5334 6074 6723 7440 8168 9177 10095 11120 12080 13075 14455 15392 16511 17124 17784 18060 18090 17419 16947 15994 15191 14394 13456 12410 11501 10363 9449 8515 7582 6618 5958 5266 4700 4263 3943 3578 3431 3046 2975 2704 2567 2468 2362 2215 2228 2057 2052 1894 1837 1824 1728 1676 1656 1529 1515 1483 1477 1469 1389 1312 1314 1293 1302 1265 1211 1274 1241 1188 1222 1200 1128 1180 1081 1143 1169 1062 1106 1124 1066 1065 1069 1102 1049 1093 1106 988 1085 1121 1085 1092 1051 1013 997 1010 1051 1043 1028 1061 965 1010 991 983 995 1024 1019 1070 984 981 1006 973 969 967 1004 892 994 942 1003 898 981 894 1033 917 952 883 960 913 924 884 989 920 940 997 971 913 919 901 897 936 973 994 952 894 871 918 993 858 982 925 962 944 926 922 902 943 914 929 983 929 923 856 861 857 887 954 903 906 988 950 1011 922 969 924 917 869 925 960 976 956 976 984 961 970 960 1028 947 940 986 1028 1076 1060 1141 1153 1099 1236 1311 1219 1442 1405 1518 1645 1733 1796 1936 1976 2202 2193 2435 2415 2427 2525 2458 2332 2247 2106 2038 2029 1937 1868 1711 1645 1488 1530 1320 1349 1203 1221 1188 1169 1043 1092 1026 1049 1039 995 986 966 971 939 970 937 841 971 985 922 951 968 1005 943 907 914 927 904 897 903 882 937 960 954 941 929 958 873 941 900 901 906 872 920 912 912 866 984 979 947 963 937 958 974 939 958 1028 991 963 964 1069 1086 1099 1110 1185 1238 1276 1281 1400 1530 1589 1563 1658 1754 1664 1700 1727 1555 1619 1430 1467 1397 1395 1308 1310 1310 1214 1166 1138 1044 1086 1035 1016 1026 999 1000 933 1057 907 940 1027 942 1012 944 1019 977 1005 988 996 1023 1043 1064 1085 1025 1064 1082 1110 1092 1097 1137 1123 1159 1148 1131 1189 1171 1163 1280 1303 1316 1376 1413 1464 1453 1487 1533 1647 1797 1897 2018 2140 2299 2662 2865 3050 3329 3684 4031 4309 4616 4793 5072 5202 5443 5506 5591 5637 5902 6043 6224 6444 6745 7274 7719 7946 8105 8412 8426 8612 8457 8697 8296 8088 7914 7561 7143 6630 6292 5927 5414 4947 4634 4167 3822 3519 3187 2923 2579 2356 2199 1976 1904 1778 1776 1636 1484 1472 1534 1470 1424 1376 1356 1328 1223 1277 1227 1329 1228 1256 1294 1312 1350 1318 1401 1366 1432 1481 1589 1630 1730 1803 1875 1883 1815 1880 1788 1672 1721 1639 1573 1539 1476 1462 1405 1379 1227 1247 1221 1144 1141 1154 1077 1163 1097 1162 1121 1154 1210 1186 1305 1284 1324 1346 1437 1500 1612 1625 1726 1832 1761 1794 1798 1790 1825 1710 1724 1629 1572 1610 1507 1582 1465 1377 1361 1253 1286 1184 1211 1150 1084 1042 1076 1047 1131 1083 1053 1089 1129 1166 1187 1218 1302 1439 1409 1564 1671 1721 1818 2030 2147 2296 2450 2629 2532 2635 2581 2534 2540 2400 2274 2314 2216 2039 1956 1842 1883 1613 1600 1447 1374 1270 1257 1240 1155 1051 998 1030 998 955 995 904 962 951 917 832 903 830 856 877 861 862 873 868 843 816 792 825 810 746 762 799 784 816 750 781 779 750 783 721 749 794 802 782 802 781 765 737 795 836 747 801 737 755 813 795 805 802 784 743 784 759 718 738 792 755 827 714 766 770 743 779 800 797 828 750 780 746 744 774 769 739 731 805 781 759 808 735 729 740 758 728 757 806 744 737 757 735 722 761 744 727 709 738 735 730 762 787 731 797 712 760 781 713 730 763 721 706 731 673 750 787 780 781 757 743 732 759 733 766 723 777 776 730 822 789 741 753 749 790 724 798 814 763 768 793 764 737 772 785 823 777 749 802 831 841 831 738 838 797 791 730 808 798 796 845 813 854 842 905 845 864 828 897 863 907 910 903 1003 1055 1025 1033 1103 1117 1193 1202 1301 1422 1565 1774 1816 2016 2205 2359 2632 2798 3013 3138 3218 3373 3211 3154 2978 2937 2818 2622 2609 2510 2465 2312 2145 2015 1936 1768 1590 1533 1415 1258 1237 1170 1118 1036 1081 963 1018 896 900 954 886 893 912 881 836 901 814 819 835 783 822 770 838 810 807 768 729 760 756 816 798 756 769 781 750 742 787 722 732 783 731 783 765 757 781 774 831 796 829 847 825 878 917 882 950 840 955 1001 964 981 936 1005 1011 915 1022 958 933 927 934 863 947 871 903 849 838 793 796 768 760 709 742 743 688 757 666 719 704 781 696 712 713 724 704 661 671 660 688 683 684 655 729 699 713 673 678 670 697 684 656 669 686 701 659 749 683 632 686 654 655 620 708 646 696 661 632 641 705 681 687 595 669 669 655 695 701 634 717 668 687 615 640 658 764 664 656 654 653 664 678 691 705 669 634 722 639 644 618 656 675 688 668 684 611 734 658 678 667 676 645 611 649 710 639 664 624 648 625 688 676 705 664 662 632 638 687 636 724 628 663 701 644 682 640 653 669 661 614 670 650 690 636 669 604 692 638 665 632 642 626 610 645 610 643 676 662 689 605 643 675 700 649 607 614 667 671 633 689 604 610 654 627 706 641 613 637 675 648 637 665 711 685 668 606 620 667 648 708 649 663 629 632 690 716 729 707 704 777 788 769 771 800 782 854 834 940 941 858 897 902 880 837 885 832 790 832 778 744 755 805 769 834 791 728 695 635 778 660 671 655 656 663 671 679 691 700 636 652 624 620 659 677 573 602 628 627 637 647 674 644 633 609 659 653 675 617 640 641 617 663 599 655 643 571 633 678 614 598 594 612 610 632 626 585 635 636 607 606 666 638 625 584 666 631 624 641 606 636 612 643 613 601 573 652 621 568 635 621 603 624 565 618 632 674 608 605 644 686 618 640 610 670 624 591 617 577 603 598 609 622 613 625 594 604 627 619 650 599 589 654 631 655 603 613 608 616 580 610 630 569 652 625 642 687 594 622 692 636 628 675 632 632 634 635 681 648 687 646 640 683 656 663 628 680 677 644 599 642 704 621 641 620 598 638 640 583 637 669 600 646 687 655 665 675 630 625 681 601 606 630 634 606 679 630 650 650 628 629 610 664 656 632 624 612 616 603 626 618 600 611 640 682 688 635 640 675 592 602 590 648 587 692 658 627 619 662 612 657 641 669 631 701 629 689 635 669 667 675 643 677 669 638 665 708 650 683 655 707 624 681 711 711 709 680 670 688 691 720 678 727 699 728 771 760 757 750 734 776 752 771 821 831 806 818 801 822 878 852 864 895 991 1002 1091 1110 1275 1363 1540 1579 1822 1946 2237 2653 3116 3421 3749 4182 4550 4599 4641 4754 4381 4144 3890 3513 3295 3218 3141 3138 3137 3176 3066 2977 2777 2736 2468 2336 2082 2100 1944 1870 1839 1816 1678 1567 1484 1397 1407 1307 1427 1413 1415 1317 1311 1215 1193 1196 1209 1121 1110 1127 1099 1124 1100 1230 1344 1441 1502 1701 1812 2003 2066 2225 2304 2387 2369 2424 2352 2217 2123 2044 1944 1856 1847 1824 1760 1702 1645 1642 1588 1429 1372 1208 1196 1090 1042 986 928 852 828 870 831 806 770 757 703 753 749 726 738 742 752 708 765 700 688 708 698 719 633 695 691 648 619 653 671 714 651 646 624 670 607 653 613 635 621 641 656 597 642 650 656 663 634 625 659 638 655 585 658 593 679 609 597 656 616 576 659 629 587 633 620 654 629 571 618 628 598 618 620 631 591 678 600 670 605 629 656 599 630 626 651 666 622 632 574 664 614 601 645 668 656 682 677 665 659 649 665 666 647 599 654 681 635 673 664 686 651 650 702 665 622 650 614 639 657 658 656 674 601 682 645 696 660 648 675 638 688 679 654 642 675 648 690 707 664 597 655 610 657 678 669 665 657 677 659 635 676 662 695 668 675 704 709 756 721 703 724 707 683 698 714 667 678 712 661 663 664 698 704 729 724 698 733 686 699 712 648 696 682 728 710 760 682 717 719 690 732 718 786 767 722 762 740 700 811 749 785 744 777 784 818 795 808 860 795 778 836 885 944 895 918 910 925 936 963 1013 993 1041 1092 1041 1088 1061 1180 1164 1168 1170 1270 1275 1338 1353 1372 1479 1485 1580 1709 1672 1759 1848 1938 1977 2280 2235 2487 2582 2773 2894 3278 3658 4032 4320 5045 5547 5997 7107 7804 8700 10005 10957 11738 12896 13377 13679 13862 13549 13045 12115 11352 10899 10185 9883 9579 9466 9350 9170 8826 8448 7830 7280 6548 5876 5236 4539 4160 3853 3361 3183 2846 2612 2498 2247 2217 2038 1849 1787 1810 1578 1475 1496 1372 1413 1335 1300 1233 1185 1176 1167 1087 1079 1070 1067 1042 999 959 964 972 913 911 864 852 870 902 889 875 838 793 855 803 803 773 844 833 804 782 787 763 809 812 758 785 777 727 807 797 832 748 752 762 737 765 820 755 773 753 766 735 752 778 773 838 811 821 820 865 850 851 896 930 957 1009 1019 1032 1025 1112 1132 1088 1110 1053 983 1053 985 984 1023 992 990 970 1016 962 970 1019 975 1007 976 966 976 1026 1033 1116 1084 1265 1283 1331 1525 1490 1478 1536 1564 1528 1471 1436 1379 1373 1367 1322 1341 1265 1283 1361 1304 1332 1280 1151 1175 1180 1070 1111 1039 997 1013 965 972 940 878 898 900 904 894 897 934 1016 1009 1060 1065 1130 1221 1340 1393 1468 1635 1794 2031 2162 2464 2548 2767 3061 3077 3024 3084 2854 2636 2514 2337 2014 2095 2021 2041 2035 2009 1975 2005 1832 1887 1735 1581 1402 1290 1204 1089 1006 1019 909 947 910 867 802 825 907 881 885 825 890 852 919 857 801 837 905 862 921 912 824 815 866 889 907 921 860 923 920 891 1000 1008 1038 972 1037 1127 1106 1146 1212 1270 1345 1462 1450 1611 1602 1731 1942 2084 2321 2453 2759 2965 3204 3295 3656 3807 3722 3757 3505 3385 3256 3085 2943 2816 2780 2772 2793 2727 2901 2784 2766 2699 2553 2600 2531 2489 2517 2660 2763 2854 2949 3260 3350 3263 3416 3265 3106 2872 2638 2436 2201 2067 2140 2051 2099 2068 2047 1996 2039 1875 1825 1682 1533 1316 1227 1172 1011 989 931 916 884 837 866 819 781 778 794 720 713 691 766 677 720 697 674 656 677 645 705 682 657 624 639 604 638 632 692 634 650 643 628 617 693 635 625 577 647 698 636 674 618 650 635 603 639 592 627 605 606 594 658 613 660 609 630 633 595 653 617 664 635 600 632 632 623 616 586 671 606 617 660 666 631 693 667 719 643 734 779 726 767 800 777 798 835 863 802 871 826 814 847 806 793 769 780 808 779 762 708 714 781 719 756 759 707 740 701 672 644 677 688 657 641 633 650 653 591 641 617 670 655 697 625 615 616 652 623 610 625 620 678 628 638 625 644 664 657 584 641 624 658 620 613 616 621 625 629 635 569 588 578 642 567 583 614 586 614 627 590 568 612 592 618 615 583 636 616 588 631 624 608 620 616 639 622 671 634 602 645 625 643 643 641 684 644 647 612 645 697 653 705 656 674 666 650 650 663 684 711 709 720 702 731 765 774 746 709 799 786 775 839 864 886 903 984 993 1072 1099 1165 1239 1347 1411 1463 1648 1695 1770 1841 1851 1867 1814 1808 1763 1669 1612 1640 1548 1573 1554 1459 1451 1527 1480 1478 1346 1339 1248 1223 1135 1124 1117 1011 969 947 883 834 841 876 811 777 796 755 763 708 757 792 680 747 734 698 703 750 747 736 682 650 721 638 748 702 630 682 660 691 713 702 703 679 696 720 665 717 758 719 781 789 783 743 857 834 808 890 875 946 903 938 1107 1066 1195 1236 1371 1533 1683 1816 2100 2140 2296 2351 2558 2621 2413 2496 2351 2342 2134 2030 2150 1969 1987 1943 1966 1927 1842 1875 1899 1759 1729 1637 1595 1477 1289 1272 1153 1106 1020 956 988 924 911 803 855 808 817 753 769 769 718 696 728 720 691 725 687 693 679 659 642 635 636 692 635 621 617 656 627 605 615 650 600 620 621 624 587 646 651 604 599 610 601 625 633 631 687 630 615 569 568 577 614 598 551 625 608 597 582 627 586 581 595 588 562 581 595 571 572 631 648 603 598 567 588 593 626 542 593 605 585 572 595 567 579 518 591 556 580 592 573 569 561 631 555 550 572 548 570 524 580 566 590 584 568 574 605 591 578 573 568 560 566 550 573 556 572 524 565 562 570 537 552 557 627 598 585 526 608 578 554 552 580 572 551 596 546 578 572 533 604 536 602 586 545 583 608 534 576 553 606 576 577 621 554 580 555 564 557 510 579 577 560 533 580 566 556 550 565 590 612 584 607 553 608 542 570 573 588 579 557 593 590 634 597 565 581 618 638 564 645 608 593 609 652 594 600 600 643 628 658 606 623 655 610 653 657 687 683 673 685 757 701 717 713 737 740 800 780 750 793 865 861 918 910 920 986 1130 1111 1171 1265 1369 1444 1451 1472 1534 1523 1498 1509 1462 1532 1561 1547 1606 1770 1847 1991 2110 2199 2434 2740 2694 2999 3080 3247 3495 3455 3275 3231 3083 2848 2812 2612 2531 2415 2226 2378 2320 2269 2420 2374 2408 2519 2478 2425 2242 2180 2057 1862 1751 1731 1579 1507 1412 1242 1260 1154 1167 1140 1122 1074 1039 1018 1100 982 1011 963 954 909 878 870 900 826 802 818 854 832 779 792 769 751 871 918 821 875 884 918 935 968 1092 1198 1237 1354 1505 1675 1898 1993 2252 2282 2448 2405 2336 2290 2069 1885 1864 1706 1522 1462 1459 1500 1470 1422 1553 1591 1555 1496 1493 1393 1331 1270 1169 1036 913 917 838 741 781 747 745 751 685 694 658 677 666 666 631 642 612 612 599 673 627 609 580 612 610 567 590 593 612 592 652 615 622 672 589 575 566 637 605 592 628 582 621 605 586 599 565 571 575 618 544 594 574 541 627 626 645 606 589 606 607 611 592 623 582 595 633 578 592 628 604 621 579 621 625 626 618 559 628 608 592 583 591 606 571 556 625 592 611 630 549 622 605 637 627 632 650 618 622 616 642 603 636 628 618 643 661 620 633 655 666 663 651 628 686 663 680 687 693 715 709 719 707 713 723 737 738 760 738 816 681 749 773 776 844 821 801 829 888 802 855 921 948 958 999 1023 1006 1088 1091 1235 1238 1303 1406 1458 1540 1654 1838 1966 2057 2200 2478 2579 2785 2942 3013 3074 3046 3046 2923 2759 2623 2525 2347 2299 2344 2284 2204 2200 2060 2229 2225 2186 2141 2021 1956 1965 1813 1626 1578 1526 1353 1350 1194 1164 1112 1030 1068 993 1041 968 984 870 898 891 941 864 809 856 813 850 794 876 793 785 725 820 773 777 824 802 780 750 781 772 831 818 847 868 767 833 815 866 915 903 850 944 898 910 979 970 1031 1108 1088 1223 1255 1347 1407 1543 1648 1716 1873 1964 2125 2194 2369 2387 2427 2339 2294 2268 2219 2213 2231 2254 2265 2390 2502 2574 2956 2953 3283 3427 3803 4053 4389 4700 4836 5139 5304 5222 5261 5138 5045 4895 4595 4339 3999 3971 3705 3695 3603 3459 3479 3415 3438 3488 3404 3399 3230 3174 2887 2810 2567 2383 2267 2014 1897 1725 1656 1521 1470 1372 1305 1234 1163 1148 1109 1019 970 978 953 929 932 922 858 840 892 915 845 804 782 781 772 783 809 744 747 795 772 750 781 716 723 796 730 749 760 695 740 749 784 707 768 785 750 849 751 759 824 808 864 910 979 929 1077 1108 1227 1213 1376 1395 1491 1469 1577 1579 1497 1537 1475 1401 1434 1329 1312 1199 1202 1194 1177 1236 1218 1226 1200 1127 1176 1189 1160 1124 1083 1005 981 948 907 900 883 827 747 811 778 747 703 712 729 688 675 703 687 652 682 625 626 630 616 617 633 617 622 580 627 590 595 583 571 556 580 567 604 537 588 557 559 562 516 569 561 596 545 530 533 572 563 561 564 539 496 583 549 568 534 542 559 590 568 539 585 552 537 542 520 562 559 530 595 536 555 521 528 554 581 556 561 520 587 568 537 507 497 513 538 523 558 575 530 561 553 590 544 567 493 510 568 550 619 544 558 533 528 529 523 566 554 584 587 592 566 576 611 615 615 612 630 610 646 614 667 672 649 692 713 756 832 840 855 989 1086 1055 1107 1228 1228 1283 1234 1195 1099 1151 1078 994 937 899 855 824 861 809 885 872 888 910 897 883 986 876 892 867 763 705 743 703 654 692 617 585 649 587 555 597 576 622 560 605 611 622 624 573 590 631 612 601 588 562 576 578 540 567 578 562 554 564 564 581 563 602 568 567 524 586 584 552 520 527 540 553 594 598 579 566 542 556 561 536 584 533 572 573 562 587 531 615 594 566 563 592 636 653 613 651 639 669 653 624 640 662 683 765 774 839 827 871 917 1036 1049 1209 1153 1258 1362 1398 1328 1359 1350 1332 1289 1182 1107 1065 987 981 1021 1111 1062 1130 1153 1135 1188 1220 1302 1377 1405 1462 1535 1505 1598 1558 1532 1470 1513 1349 1195 1210 1080 1025 984 942 864 956 937 983 932 992 1012 1030 946 997 962 946 872 871 818 801 771 697 694 660 625 610 652 580 664 623 599 569 569 521 582 627 631 595 590 616 529 608 600 585 594 586 613 606 630 606 612 613 573 632 591 612 608 618 609 676 661 676 703 794 708 708 776 752 794 812 891 881 905 949 1000 1083 1140 1234 1286 1393 1539 1578 1704 1771 1777 1803 1829 1770 1595 1607 1477 1366 1371 1222 1273 1224 1249 1224 1195 1254 1280 1237 1266 1251 1263 1248 1193 1161 1144 1034 983 921 852 837 811 813 701 742 718 700 686 640 641 620 627 668 644 628 584 597 638 571 591 613 544 584 565 565 512 581 545 581 535 525 512 574 580 548 538 524 520 562 567 507 500 540 505 566 534 511 505 491 498 501 486 475 512 511 504 496 478 511 478 491 476 536 491 511 484 495 501 510 507 502 496 534 520 495 470 549 477 497 487 516 469 498 508 503 539 520 524 508 497 518 446 504 534 531 517 514 501 537 480 474 539 479 486 510 564 511 495 500 489 449 506 485 537 486 511 504 474 517 470 505 467 472 513 497 523 495 509 493 530 527 499 450 530 484 562 473 494 500 511 484 533 493 509 509 521 519 465 517 529 493 526 478 507 500 517 510 500 508 518 518 519 473 578 524 523 473 527 534 507 508 502 543 538 578 506 509 511 539 514 558 597 560 608 606 581 631 594 609 659 649 664 768 746 797 861 830 964 963 996 997 1070 990 1071 1000 990 942 945 907 893 853 801 853 915 773 826 844 817 873 880 859 867 857 845 802 808 799 833 784 726 720 637 688 679 699 663 659 580 619 658 556 618 587 584 611 613 599 597 582 599 561 561 555 547 530 557 568 564 524 590 573 547 543 569 590 577 598 571 508 546 571 485 529 569 553 515 551 545 559 563 587 560 552 573 577 584 539 607 558 560 544 539 585 575 584 577 533 596 582 596 591 588 640 690 701 728 783 777 863 903 1011 1074 1137 1272 1346 1443 1559 1664 1696 1640 1609 1560 1408 1385 1263 1102 1061 1025 984 1005 897 986 961 968 1004 1078 1062 1036 1136 1155 1173 1057 1034 979 892 780 804 708 721 665 613 617 637 588 596 528 560 555 543 547 570 535 523 555 486 515 488 565 513 526 529 520 543 558 512 516 525 488 506 478 521 489 551 530 498 574 506 558 550 528 522 540 551 563 548 535 540 555 544 570 570 657 653 652 747 739 749 806 833 828 839 866 790 752 705 702 705 652 625 657 662 707 672 721 716 686 791 828 793 804 792 796 789 760 727 734 742 665 662 638 641 639 615 579 573 561 579 628 623 613 613 611 589 594 537 604 530 566 608 543 537 577 511 547 544 519 522 503 552 539 520 512 547 517 534 503 590 551 527 552 548 568 522 529 536 510 525 522 536 531 508 525 481 510 523 521 513 536 536 533 551 506 567 550 571 608 560 632 589 562 633 586 676 704 739 721 772 786 854 855 897 898 871 878 888 786 819 748 754 772 700 762 702 680 709 726 660 746 713 736 753 831 802 835 816 838 908 857 909 884 857 907 920 919 899 858 863 823 760 793 776 707 673 752 678 690 691 683 675 678 675 753 688 692 690 723 706 735 644 710 637 619 630 623 614 629 629 619 588 593 602 581 535 578 531 550 574 538 533 567 533 578 543 592 615 566 614 566 605 634 602 648 638 612 662 631 633 663 671 700 698 707 764 794 791 758 820 904 843 953 897 978 954 973 940 991 1011 1065 1021 1036 1164 1179 1240 1267 1348 1383 1460 1619 1754 1953 2041 2150 2449 2538 2420 2556 2583 2649 2456 2311 2144 1997 1888 1788 1695 1530 1496 1505 1470 1418 1490 1535 1542 1611 1688 1706 1717 1751 1654 1530 1510 1407 1273 1261 1174 1038 959 933 1001 852 835 787 781 781 747 757 716 749 696 663 687 650 629 670 624 579 601 592 624 606 544 593 612 610 605 573 533 562 571 573 573 562 519 582 578 523 535 549 535 548 550 515 542 497 512 562 547 537 582 591 553 572 548 542 556 509 550 503 567 559 562 551 574 621 567 620 573 608 596 625 662 668 678 662 698 744 775 799 797 894 934 940 952 922 905 936 909 898 900 872 878 866 824 795 784 773 754 755 757 758 820 783 767 771 844 775 797 800 789 778 713 746 724 694 710 625 648 627 611 619 597 618 625 606 549 562 511 572 529 537 550 550 554 548 558 596 547 533 553 523 594 568 530 552 556 511 586 591 614 550 567 598 633 607 616 590 554 566 594 621 634 603 587 607 538 615 586 570 618 653 596 593 667 643 653 670 730 689 729 790 805 828 844 936 908 1001 1027 1051 1072 1085 1036 1070 1040 1012 962 941 923 841 852 800 812 849 795 828 813 829 871 809 831 786 892 831 862 817 789 836 773 726 721 697 620 666 658 613 618 608 581 623 575 587 549 599 572 553 540 544 556 539 519 484 542 524 506 452 525 527 532 531 494 503 534 502 490 481 532 518 511 536 496 541 509 514 542 510 515 498 550 517 460 565 499 533 626 610 646 576 597 602 688 643 680 648 702 669 658 633 676 653 590 605 601 593 592 641 559 614 583 619 632 595 625 584 620 636 616 578 681 665 637 629 574 613 623 572 587 561 614 587 631 663 694 724 688 836 819 893 931 984 1016 1030 987 1099 1004 936 937 871 841 780 755 702 706 721 730 657 699 679 651 752 755 765 737 801 787 819 801 814 760 793 683 675 686 648 729 665 647 647 647 670 686 712 718 716 809 767 754 782 741 770 695 735 694 681 650 670 617 587 603 617 619 629 710 672 653 680 741 708 686 702 750 721 734 730 701 659 714 692 709 740 751 817 745 830 917 910 969 1052 1103 1174 1241 1376 1460 1595 1667 1803 1846 1928 1931 1810 1688 1597 1478 1462 1382 1235 1204 1170 1075 1060 1068 1108 1094 1071 1144 1144 1161 1187 1258 1264 1273 1218 1159 1168 1026 1102 1013 997 955 908 837 811 739 765 732 700 723 676 645 650 650 629 630 606 628 573 609 575 586 535 557 579 544 541 538 549 565 528 517 487 515 520 514 508 541 512 493 528 498 481 493 502 470 530 473 502 464 476 502 511 511 504 528 507 472 478 482 453 524 488 481 470 502 481 471 502 472 498 521 491 506 500 546 521 530 525 564 563 563 544 542 538 560 532 572 585 526 577 577 577 568 489 475 517 493 541 522 544 560 518 473 511 557 504 483 539 540 509 540 506 556 552 479 508 458 502 458 500 460 475 514 462 493 479 495 434 476 447 505 480 431 532 443 510 475 459 441 421 423 451 473 421 500 437 477 462 455 459 477 450 485 444 444 465 449 402 420 442 483 476 462 416 487 462 491 459 432 408 439 447 472 491 452 478 484 488 473 454 499 479 453 480 479 479 482 445 463 469 496 448 473 460 452 498 426 441 467 438 459 450 516 471 477 430 457 450 478 471 456 455 435 485 474 474 446 505 456 464 452 471 461 445 464 524 444 459 503 461 485 455 500 456 476 433 489 473 501 472 445 458 451 500 453 467 503 502 468 453 513 499 500 470 499 498 457 501 509 469 516 472 477 526 498 500 517 529 501 551 544 510 601 557 620 591 592 576 636 636 667 628 714 731 790 785 817 914 860 995 1017 1013 1045 1062 1110 987 1027 904 921 861 863 842 752 792 718 709 704 664 680 696 735 712 769 774 786 778 804 837 794 830 783 765 739 724 697 736 662 628 607 599 590 583 542 580 594 527 565 568 528 542 503 498 493 534 520 458 466 509 542 533 531 521 469 489 512 523 493 465 485 509 490 497 468 508 486 535 480 509 505 487 504 483 475 485 513 498 491 498 503 490 534 511 496 493 486 517 468 496 483 526 490 501 509 525 501 527 494 536 509 544 543 565 550 559 593 550 578 651 596 658 666 672 664 691 719 653 663 662 716 709 674 662 609 684 688 653 672 595 609 551 585 599 640 609 637 600 634 640 601 655 623 624 671 600 533 604 601 572 604 599 591 556 544 523 559 582 539 565 521 546 539 557 544 530 548 569 498 522 539 533 553 557 565 570 556 565 580 575 540 588 589 554 581 591 632 604 610 574 596 612 601 611 644 637 691 646 709 733 666 718 828 771 834 878 929 878 941 1009 967 1056 1088 1032 1047 1139 1124 1262 1234 1279 1335 1415 1542 1594 1710 1776 1861 1938 1974 2071 2053 2150 1991 1845 1841 1722 1584 1556 1493 1474 1371 1321 1283 1239 1186 1182 1244 1217 1237 1218 1242 1262 1403 1324 1399 1432 1372 1360 1301 1257 1193 1076 1024 1067 1041 961 934 887 793 784 796 788 763 732 774 731 688 729 704 670 648 692 739 660 689 654 694 660 664 655 627 664 641 642 649 667 654 693 643 635 672 729 688 696 725 771 729 726 784 774 779 780 777 847 862 891 837 905 970 1019 1101 1162 1252 1285 1367 1544 1641 1625 1796 1892 1923 1977 1999 2097 2082 1978 1911 1817 1699 1537 1504 1528 1401 1362 1299 1287 1258 1178 1176 1151 1127 1199 1220 1280 1321 1331 1323 1421 1411 1374 1428 1341 1282 1191 1227 1104 1038 1046 941 915 902 784 832 751 766 763 752 714 698 601 693 694 632 593 606 594 620 587 592 526 591 582 605 542 611 570 556 554 532 588 556 575 532 568 510 525 523 525 562 510 532 509 553 510 535 477 492 520 512 497 480 520 513 554 518 522 518 495 531 515 484 544 555 524 529 505 535 501 538 523 548 503 586 591 564 570 568 636 677 684 644 732 725 745 768 775 872 761 763 754 744 720 780 767 730 692 642 645 609 619 624 598 601 623 625 615 675 594 639 679 643 654 638 657 663 663 676 659 668 628 631 591 615 634 583 633 594 550 544 608 540 604 540 605 545 554 577 540 540 568 567 539 587 599 580 614 602 581 572 585 567 564 603 615 634 647 676 703 665 747 730 755 767 767 777 786 765 827 836 865 904 957 952 991 974 1022 1109 1164 1268 1270 1327 1359 1289 1282 1282 1202 1162 1140 1100 1100 991 1012 935 909 946 938 960 859 880 892 901 959 880 851 903 896 960 922 929 842 913 931 908 888 869 845 780 762 760 732 740 700 634 635 640 612 571 630 565 589 590 533 593 625 559 584 566 545 550 529 547 557 543 543 533 525 538 509 539 527 495 542 547 564 545 587 597 625 622 581 678 756 680 723 719 793 776 750 695 722 681 675 658 614 607 586 545 610 512 577 568 587 489 582 559 539 583 599 567 594 591 608 601 579 619 623 601 604 619 589 582 567 551 543 533 528 518 533 548 527 532 510 568 510 542 505 515 512 498 523 507 522 472 493 507 500 502 480 482 488 527 504 468 499 524 499 532 545 531 544 535 534 603 614 602 619 640 689 682 747 709 746 733 780 754 775 737 749 727 727 691 653 691 675 610 611 579 602 580 558 622 607 590 608 629 615 613 634 641 648 727 724 744 748 727 739 760 743 798 790 744 729 754 717 691 683 697 698 690 676 656 684 646 662 668 652 663 689 646 644 703 682 679 713 745 708 743 822 813 853 796 890 870 905 879 963 1047 1043 1082 1086 1022 1149 1092 1042 1087 990 1009 978 987 888 861 870 879 764 757 729 782 769 794 769 751 727 768 750 782 819 801 807 782 826 856 803 784 800 751 747 731 728 740 648 621 711 637 651 596 656 637 570 627 588 596 574 530 556 569 539 553 521 529 509 548 560 517 518 561 544 559 511 522 563 578 581 592 594 662 665 605 669 628 672 615 641 681 664 678 654 626 641 602 602 579 566 560 562 526 536 534 531 529 584 536 569 524 560 531 553 599 626 562 601 535 567 558 601 577 527 564 529 527 517 536 534 531 503 476 473 429 439 450 502 481 481 517 509 495 476 499 470 472 490 498 473 466 442 473 461 485 455 461 475 488 437 443 486 461 430 448 470 496 433 418 501 443 520 453 473 469 442 478 410 478 444 484 481 457 494 522 470 471 485 451 504 499 464 456 515 480 482 491 478 453 475 486 492 463 460 497 498 533 481 515 522 517 543 561 512 523 574 532 588 587 611 620 596 630 573 611 611 602 665 649 612 600 600 525 559 515 530 529 518 569 483 520 500 531 531 555 553 550 578 564 533 598 567 562 569 592 564 601 624 553 575 527 528 539 549 519 513 491 515 529 486 525 491 515 483 533 527 518 531 509 546 506 541 529 523 510 525 551 532 553 590 600 577 584 644 636 649 691 661 656 753 774 744 694 852 833 913 882 946 819 821 861 854 828 818 793 774 736 776 782 753 762 762 753 788 725 718 773 778 778 818 789 896 861 846 876 896 926 874 934 840 921 828 903 823 845 785 790 726 763 770 756 753 725 709 760 740 739 720 802 764 755 725 737 713 741 657 766 669 704 717 614 708 671 671 631 631 624 635</counts>
			</dataPoints>
		</scan>
	</xrdMeasurement>
</xrdMeasurements>