File: dataset/precursor_mixture/TiO2_Nb2O5_Li3PO4_Bi2O3-beta.2-min.xrdml
<?xml version="1.0"?>
<xrdMeasurements xmlns="http://www.xrdml.com/XRDMeasurement/2.2" xmlns:xsi="http://www.w3.org/2001/XMLSchema-instance" xsi:schemaLocation="http://www.xrdml.com/XRDMeasurement/2.2 http://www.xrdml.com/XRDMeasurement/2.2/XRDMeasurement.xsd" status="Completed" recordIdentifier="{5F5268F5-8408-4199-8B75-BB7FE8315BC8}">
	<comment>
		<entry/>
	</comment>
	<sample type="To be analyzed">
		<id>dara-47-1</id>
		<name></name>
		<preparedBy></preparedBy>
	</sample>
	<xrdMeasurement measurementType="Scan" status="Completed" sampleMode="Reflection">
		<usedWavelength intended="K-Alpha 1">
			<kAlpha1 unit="Angstrom">1.5405980</kAlpha1>
			<kAlpha2 unit="Angstrom">1.5444260</kAlpha2>
			<kBeta unit="Angstrom">1.3922500</kBeta>
			<ratioKAlpha2KAlpha1>0.5000</ratioKAlpha2KAlpha1>
		</usedWavelength>
		<incidentBeamPath>
			<radius unit="mm">145.00</radius>
			<xRayTube id="1010048" name="Empyrean Cu LFF HR (9430 033 7310x) DK430614">
				<tension unit="kV">40.0</tension>
				<current unit="mA">15.0</current>
				<anodeMaterial>Cu</anodeMaterial>
				<focus type="Line">
					<length unit="mm">12.0</length>
					<width unit="mm">0.4</width>
					<takeOffAngle unit="deg">6.0</takeOffAngle>
				</focus>
			</xRayTube>
			<filter id="20010004" name="Beta-filter Nickel">
				<material>Ni</material>
				<thickness unit="mm">0.020</thickness>
			</filter>
			<sollerSlit id="21010002" name="Soller slits 0.04 rad.">
				<opening unit="rad">0.0400</opening>
			</sollerSlit>
			<mask id="22031000" name="Fixed mask 13 mm">
				<width unit="mm">9.00</width>
			</mask>
			<divergenceSlit id="22120001" name="Divergence slit 1°" xsi:type="fixedDivergenceSlitType">
				<distanceToSample unit="mm">50.00</distanceToSample>
				<height unit="mm">1.52</height>
			</divergenceSlit>
		</incidentBeamPath>
		<beamKnife id="29030100" name="Beam knife low"/>
		<sampleMovement xsi:type="spinningSampleMovementType">
			<spinnerRevolutionTime unit="seconds">1.0</spinnerRevolutionTime>
		</sampleMovement>
		<diffractedBeamPath>
			<radius unit="mm">145.00</radius>
			<antiScatterSlit id="22090040" name="AS slit 9 mm" xsi:type="fixedAntiScatterSlitType">
				<height unit="mm">9.00</height>
			</antiScatterSlit>
			<sollerSlit id="21020003" name="Large Soller slits 0.04 rad.">
				<opening unit="rad">0.0400</opening>
			</sollerSlit>
			<filter id="20030001" name="Large beta-filter Nickel">
				<material>Ni</material>
				<thickness unit="mm">0.020</thickness>
			</filter>
			<detector id="7010019" name="PIXcel1D-Medipix3 detector" xsi:type="rtmsDetectorType">
				<phd unit="keV">
					<lowerLevel>4.0</lowerLevel>
					<upperLevel>11.3</upperLevel>
				</phd>
				<mode>Scanning</mode>
				<activeLength unit="deg">1.021</activeLength>
			</detector>
		</diffractedBeamPath>
		<scan appendNumber="0" mode="Continuous" scanAxis="Gonio" status="Completed">
			<header>
				<startTimeStamp>2024-02-18T16:08:37-08:00</startTimeStamp>
				<endTimeStamp>2024-02-18T16:10:59-08:00</endTimeStamp>
				<author>
					<name>AutomatedUser</name>
				</author>
				<source>
					<applicationSoftware version="1.4b (28)">PANalytical Aeris Instrument Suite</applicationSoftware>
					<instrumentControlSoftware version="2.0.0 20210224">AERIS</instrumentControlSoftware>
					<instrumentID>950485</instrumentID>
				</source>
			</header>
			<dataPoints>
				<positions axis="2Theta" unit="deg">
					<startPosition>10.02173288</startPosition>
					<endPosition>139.98435528</endPosition>
				</positions>
				<positions axis="Omega" unit="deg">
					<startPosition>5.01086644</startPosition>
					<endPosition>69.99217764</endPosition>
				</positions>
				<commonCountingTime unit="seconds">1.551</commonCountingTime>
				<counts unit="counts">355 380 392 349 335 377 322 311 337 353 314 347 375 322 347 389 357 321 341 321 310 301 324 324 340 337 348 305 343 296 357 324 304 323 301 323 339 285 327 318 298 300 307 289 322 305 277 307 316 284 301 313 308 277 291 294 281 301 283 265 270 285 272 291 287 290 269 225 300 257 289 254 240 237 296 254 280 266 257 242 249 284 275 261 232 251 224 257 232 254 254 254 235 250 230 240 262 232 237 229 234 256 205 238 240 210 260 284 222 237 237 209 225 238 217 205 238 224 241 225 195 221 230 203 224 198 215 242 214 206 216 205 224 205 181 208 232 203 223 275 227 235 206 192 238 176 184 194 185 225 209 210 197 204 266 253 238 256 248 224 227 217 207 165 195 204 214 209 207 196 191 190 185 192 191 204 179 187 201 184 181 192 198 218 180 158 202 179 205 186 178 200 222 193 197 173 174 160 174 168 183 191 169 175 184 215 198 170 171 184 193 188 199 192 160 164 206 162 165 192 179 175 145 179 174 165 184 173 174 143 149 161 169 195 185 165 185 184 174 174 175 190 167 155 146 163 160 175 163 183 159 168 169 159 140 162 150 166 158 174 175 145 148 186 188 163 158 177 186 189 163 197 175 195 198 239 266 310 324 370 353 379 592 858 1100 790 482 284 236 214 211 215 190 212 209 237 208 253 264 251 237 243 223 206 168 186 195 158 147 165 175 153 158 141 165 163 175 145 154 140 138 135 132 145 151 125 183 146 137 179 196 203 220 210 220 209 222 242 251 264 274 322 468 751 1142 1395 1071 607 312 239 208 225 277 332 292 227 206 184 167 165 146 149 159 136 143 170 168 148 148 140 140 153 155 159 150 160 142 133 149 133 169 157 166 176 181 169 185 198 165 176 186 185 217 217 234 220 231 293 311 424 603 965 1666 3149 4977 4423 2981 1391 679 515 525 682 947 1092 860 631 351 257 246 223 235 223 208 234 276 329 463 489 400 344 268 224 216 210 174 197 199 161 167 143 166 164 153 138 142 149 164 143 140 163 175 143 149 154 148 231 271 243 212 194 156 184 161 135 127 133 128 158 157 164 153 161 127 131 127 137 152 144 157 168 171 166 164 134 164 157 168 245 345 617 815 772 526 359 195 193 142 171 142 165 145 122 156 188 200 163 210 279 352 565 1091 1454 1104 816 491 217 239 163 174 135 147 135 141 146 126 127 138 133 152 161 130 122 142 147 141 119 160 181 234 177 200 195 177 158 154 187 157 157 158 153 158 147 131 153 140 140 122 113 133 126 109 112 137 131 117 123 136 140 104 109 109 142 132 137 101 118 119 110 133 104 120 147 138 117 135 135 116 112 139 98 138 133 130 131 149 183 331 404 475 423 358 256 191 150 159 178 214 291 309 331 249 174 171 115 133 112 91 99 104 97 136 108 128 163 213 259 331 261 218 199 141 145 120 114 119 124 127 137 106 135 135 191 152 154 178 130 120 143 108 122 105 112 134 120 112 110 95 95 92 90 101 103 95 99 79 82 111 112 91 92 95 99 103 101 108 75 86 117 103 98 111 93 107 108 113 90 109 72 117 95 109 88 98 97 92 97 92 77 117 77 107 104 99 107 145 165 152 116 153 113 104 102 86 72 118 105 89 95 111 86 110 136 118 111 118 127 116 98 108 130 119 98 129 141 103 95 91 102 96 112 104 107 97 102 107 90 90 109 86 106 87 104 89 90 102 105 82 91 88 81 83 92 109 87 86 95 92 116 86 95 78 111 99 90 134 119 107 108 106 101 98 88 79 78 118 109 109 115 137 170 168 182 143 136 135 96 125 106 85 102 115 108 107 116 113 112 122 143 144 150 207 199 303 498 743 1179 1265 851 802 570 292 171 176 148 130 134 145 169 201 310 537 658 472 395 371 230 152 136 111 102 126 78 84 116 100 104 107 130 81 111 111 86 122 138 168 266 345 358 270 308 198 152 134 135 133 168 133 140 125 146 147 130 134 135 111 85 122 116 106 119 105 118 100 118 128 118 113 113 110 89 95 117 107 130 186 209 178 179 180 164 116 123 147 97 84 87 110 103 117 103 116 105 130 110 101 116 140 151 143 187 216 262 261 187 213 210 173 154 204 232 175 180 172 123 116 127 108 111 114 102 90 91 91 97 93 118 103 105 96 95 100 103 101 108 74 79 92 86 96 94 99 94 88 93 94 105 116 87 115 102 86 86 105 121 110 104 111 114 122 140 111 145 138 154 119 145 175 246 280 254 226 200 224 210 232 307 523 684 475 363 392 319 181 146 125 125 121 115 130 135 141 171 216 295 391 351 287 302 325 285 321 434 579 879 1202 823 579 688 587 325 221 170 176 151 130 138 106 109 119 111 122 108 126 161 165 177 142 140 124 129 114 107 105 90 84 96 111 79 123 96 91 110 115 104 117 104 102 109 106 95 129 129 140 200 338 524 424 258 299 295 193 149 132 100 135 132 103 103 115 93 102 105 105 146 153 136 115 145 125 120 101 93 106 115 125 139 143 123 116 133 106 102 97 97 84 90 94 121 124 124 102 110 113 129 107 110 103 127 86 92 97 88 85 109 92 95 101 125 79 90 92 91 99 105 113 81 130 133 128 109 106 127 119 101 104 89 75 94 104 91 91 83 102 99 91 85 89 87 87 73 77 106 129 161 152 135 145 144 110 93 100 89 80 108 137 201 184 187 127 123 172 128 106 87 92 94 91 108 106 81 95 97 95 87 105 87 128 131 122 119 117 114 117 93 93 84 99 90 85 69 106 86 83 72 74 80 81 81 82 87 98 105 104 104 84 97 69 101 92 74 76 82 83 84 84 72 67 103 83 92 92 95 80 67 69 88 80 98 84 95 91 118 91 110 115 87 98 100 135 155 104 124 133 114 117 115 89 89 89 91 93 95 134 77 98 89 94 95 84 97 77 77 64 78 80 77 91 101 88 83 99 87 80 96 100 91 77 88 99 79 95 79 109 104 114 142 187 184 172 117 150 173 172 157 125 121 117 133 128 82 106 111 112 82 83 72 92 90 76 89 86 63 76 72 80 80 79 84 73 83 92 67 85 110 124 117 150 176 126 128 127 118 134 86 114 93 89 115 79 88 88 105 120 113 117 113 158 138 136 120 112 117 93 109 84 78 88 62 74 82 82 77 99 88 91 70 81 63 87 83 95 73 76 93 99 86 87 94 74 87 66 102 88 95 82 91 83 109 115 79 73 95 96 72 114 94 84 95 105 78 88 86 86 79 81 93 77 98 83 86 106 97 84 111 115 125 117 95 131 148 187 289 413 333 245 198 207 282 202 158 142 100 115 157 158 180 170 126 147 131 121 129 108 154 218 220 172 142 129 164 176 152 150 155 238 282 188 164 147 161 174 128 119 111 96 103 80 93 113 121 101 127 108 132 95 89 93 106 75 97 105 98 100 110 85 123 95 135 196 234 181 178 158 167 185 137 139 127 148 188 212 166 129 109 141 167 137 130 98 84 105 86 103 83 84 77 94 95 87 84 107 93 111 77 108 112 105 83 76 100 87 89 76 79 86 105 75 82 79 73 76 88 87 74 85 78 72 97 93 95 105 100 98 105 91 87 68 77 77 86 78 78 82 80 78 81 79 81 74 99 88 80 104 106 111 93 90 109 105 79 83 86 90 95 100 111 106 89 101 67 98 82 68 75 87 75 87 95 98 68 85 91 96 86 101 115 119 100 103 85 100 91 89 91 77 92 120 122 112 121 108 96 106 101 100 113 103 95 93 92 70 75 74 77 94 79 107 71 76 73 81 69 93 78 84 95 79 86 76 83 88 119 89 91 84 80 98 86 102 101 117 135 181 158 89 101 94 121 133 138 85 81 100 82 75 62 75 101 120 114 99 91 93 99 86 102 101 107 104 98 97 111 104 137 195 247 184 133 134 138 152 163 175 128 94 98 86 84 101 90 77 100 79 72 77 70 86 88 82 89 79 72 79 80 75 80 85 63 90 66 66 80 60 82 62 79 71 78 69 73 78 78 76 77 72 54 86 77 51 100 79 72 91 64 78 62 80 88 83 74 65 89 98 60 75 82 76 64 79 73 59 71 77 91 77 84 51 77 59 80 86 81 78 88 73 81 99 77 115 125 148 157 125 94 94 107 95 107 100 86 75 84 71 87 111 68 86 80 84 80 75 75 78 73 78 87 98 72 80 82 78 86 102 108 99 79 89 88 77 95 93 81 99 108 142 147 127 114 124 96 89 122 110 95 105 95 86 87 70 86 92 97 90 95 134 143 177 177 154 148 130 106 127 157 173 174 132 101 82 110 108 98 103 96 94 87 82 100 66 87 103 85 67 125 112 101 103 97 89 96 96 88 113 108 81 94 92 78 80 74 79 66 77 86 59 87 99 86 76 71 69 83 75 91 58 73 107 84 68 64 68 77 89 70 77 74 79 72 70 80 70 69 69 77 69 81 80 68 69 73 72 82 80 90 83 90 99 77 70 92 69 79 75 105 95 86 94 87 77 116 93 92 82 104 76 71 90 80 93 97 75 79 83 94 87 72 80 78 72 78 82 82 81 80 90 65 69 70 85 71 94 82 82 93 88 73 111 98 79 101 85 76 98 71 84 85 91 81 81 84 58 80 69 88 69 74 73 61 73 82 91 78 63 81 84 77 87 69 87 80 75 73 84 74 93 87 81 84 94 64 83 93 102 75 73 85 79 84 74 76 79 56 79 69 76 79 84 79 87 78 75 47 81 87 72 78 87 112 90 114 83 101 106 150 151 128 97 79 100 76 82 106 102 72 76 101 82 68 94 102 95 87 96 86 70 89 85 77 86 72 72 79 71 89 98 69 75 76 106 108 77 83 73 78 75 77 67 85 80 89 89 82 80 93 95 88 93 89 93 99 81 89 88 65 82 93 85 85 100 64 76 110 77 71 102 85 96 92 70 86 67 78 96 90 96 80 81 85 80 77 70 91 97 100 94 116 85 93 90 103 94 67 98 85 75 78 78 77 81 74 82 91 78 78 76 81 88 74 89 88 97 85 86 86 114 100 122 124 101 105 112 95 110 121 136 138 223 226 181 124 122 125 113 123 116 109 130 147 104 111 103 85 103 79 92 98 101 88 108 112 112 90 67 100 64 92 93 84 91 101 103 116 99 106 79 100 69 115 125 84 111 125 128 116 142 171 146 114 72 101 97 91 125 157 123 122 120 94 92 96 90 89 97 110 93 101 115 158 166 138 136 122 109 119 126 113 158 179 225 196 160 115 117 110 114 94 97 113 112 113 113 88 81 86 85 96 108 118 113 113 93 81 82 89 105 108 107 96 92 79 95 110 110 127 127 131 121 125 102 105 132 96 114 119 94 96 100 92 112 101 105 109 90 97 114 122 81 98 105 116 93 105 110 112 109 72 90 74 93 112 105 78 90 123 98 114 114 96 67 100 107 94 96 78 86 88 98 104 76 86 89 76 73 82 84 85 59 79 74 97 69 88 52 70 91 83 90 80 88 76 88 78 93 101 96 90 93 95 93 89 116 128 126 91 86 97 117 104 119 102 110 107 112 107 80 112 90 94 68 95 104 77 84 75 95 99 92 76 108 93 112 94 113 101 106 79 87 79 100 116 109 96 100 105 117 152 114 110 97 104 96 98 110 115 98 100 101 104 112 81 92 74 78 77 98 81 75 73 75 97 100 92 74 107 96 95 76 83 80 90 83 93 99 82 102 81 89 96 110 99 84 92 76 107 84 84 95 82 82 86 106 98 111 130 114 77 83 107 79 90 91 111 102 76 94 108 99 110 95 95 105 90 73 80 78 71 109 87 82 74 107 76 105 66 63 89 84 80 59 74 75 90 72 98 81 89 96 107 100 100 107 105 88 80 80 93 72 84 87 97 119 113 103 104 141 110 100 93 98 98 86 88 81 94 118 77 105 86 95 109 86 83 126 112 105 85 86 96 82 79 79 94 110 107 94 80 104 114 90 101 80 89 67 80 121 91 93 83 106 99 104 99 88 76 83 100 80 87 89 105 69 82 77 98 93 100 97 103 102 149 104 104 93 107 78 86 76 108 74 87 99 91 104 106 83 100 97 105 84 98 102 93 84 66 72 81 94 87 90 80 91 98 76 69 85 86 89 96 103 97 126 128 125 110 85 91 100 87 92 73 86 110 104 133 120 112 103 108 106 90 79 99 92 117 112 96 106 115 147 127 129 120 118 103 106 123 98 115 88 102 96 80 107 137 122 106 99 99 87 92 105 104 104 88 135 106 117 101 116 136 182 140 160 112 104 100 109 83 79 84 84 110 96 108 91 126 106 112 107 97 96 80 94 89 85 85 79 79 85 87 90 91 94 97 82 101 83 79 81 95 83 72 92 74 73 81 91 96 90 80 84 86 78 83 89 100 102 72 89 77 84 92 89 96 81 119 114 100 95 132 88 110 112 118 80 109 109 93 92 106 121 97 82 113 134 117 101 96 94 104 129 128 125 133 155 124 137 134 122 115 100 114 125 104 89 110 116 115 126 114 123 124 101 95 96 105 112 94 109 96 100 115 88 93 90 80 72 107 67 99 83 100 102 104 76 100 96 94 67 90 85 88 102 81 95 95 95 92 89 115 80 97 89 88 103 122 81 80 87 83 88 79 102 68 64 78 114 100 108 110 55 92 74 87 87 87 68 112 83 67 93 74 103 93 91 85 90 89 80 83 91 81 84 100 78 111 121 84 87 92 92 90 114 81 84 90 88 86 97 82 84 96 100 90 67 106 80 93 83 81 89</counts>
			</dataPoints>
		</scan>
	</xrdMeasurement>
</xrdMeasurements>