File: dataset/precursor_mixture/TiO2_Li2CO3_MnCO3_K2SO4.2-min.xrdml
<?xml version="1.0"?>
<xrdMeasurements xmlns="http://www.xrdml.com/XRDMeasurement/2.2" xmlns:xsi="http://www.w3.org/2001/XMLSchema-instance" xsi:schemaLocation="http://www.xrdml.com/XRDMeasurement/2.2 http://www.xrdml.com/XRDMeasurement/2.2/XRDMeasurement.xsd" status="Completed" recordIdentifier="{B6436A91-A52F-4925-8105-89493EDAEFDA}">
	<comment>
		<entry/>
	</comment>
	<sample type="To be analyzed">
		<id>dara-11-1</id>
		<name></name>
		<preparedBy></preparedBy>
	</sample>
	<xrdMeasurement measurementType="Scan" status="Completed" sampleMode="Reflection">
		<usedWavelength intended="K-Alpha 1">
			<kAlpha1 unit="Angstrom">1.5405980</kAlpha1>
			<kAlpha2 unit="Angstrom">1.5444260</kAlpha2>
			<kBeta unit="Angstrom">1.3922500</kBeta>
			<ratioKAlpha2KAlpha1>0.5000</ratioKAlpha2KAlpha1>
		</usedWavelength>
		<incidentBeamPath>
			<radius unit="mm">145.00</radius>
			<xRayTube id="1010048" name="Empyrean Cu LFF HR (9430 033 7310x) DK430614">
				<tension unit="kV">40.0</tension>
				<current unit="mA">15.0</current>
				<anodeMaterial>Cu</anodeMaterial>
				<focus type="Line">
					<length unit="mm">12.0</length>
					<width unit="mm">0.4</width>
					<takeOffAngle unit="deg">6.0</takeOffAngle>
				</focus>
			</xRayTube>
			<filter id="20010004" name="Beta-filter Nickel">
				<material>Ni</material>
				<thickness unit="mm">0.020</thickness>
			</filter>
			<sollerSlit id="21010002" name="Soller slits 0.04 rad.">
				<opening unit="rad">0.0400</opening>
			</sollerSlit>
			<mask id="22031000" name="Fixed mask 13 mm">
				<width unit="mm">9.00</width>
			</mask>
			<divergenceSlit id="22120001" name="Divergence slit 1°" xsi:type="fixedDivergenceSlitType">
				<distanceToSample unit="mm">50.00</distanceToSample>
				<height unit="mm">1.52</height>
			</divergenceSlit>
		</incidentBeamPath>
		<beamKnife id="29030100" name="Beam knife low"/>
		<sampleMovement xsi:type="spinningSampleMovementType">
			<spinnerRevolutionTime unit="seconds">1.0</spinnerRevolutionTime>
		</sampleMovement>
		<diffractedBeamPath>
			<radius unit="mm">145.00</radius>
			<antiScatterSlit id="22090040" name="AS slit 9 mm" xsi:type="fixedAntiScatterSlitType">
				<height unit="mm">9.00</height>
			</antiScatterSlit>
			<sollerSlit id="21020003" name="Large Soller slits 0.04 rad.">
				<opening unit="rad">0.0400</opening>
			</sollerSlit>
			<filter id="20030001" name="Large beta-filter Nickel">
				<material>Ni</material>
				<thickness unit="mm">0.020</thickness>
			</filter>
			<detector id="7010019" name="PIXcel1D-Medipix3 detector" xsi:type="rtmsDetectorType">
				<phd unit="keV">
					<lowerLevel>4.0</lowerLevel>
					<upperLevel>11.3</upperLevel>
				</phd>
				<mode>Scanning</mode>
				<activeLength unit="deg">1.021</activeLength>
			</detector>
		</diffractedBeamPath>
		<scan appendNumber="0" mode="Continuous" scanAxis="Gonio" status="Completed">
			<header>
				<startTimeStamp>2024-02-18T13:55:16-08:00</startTimeStamp>
				<endTimeStamp>2024-02-18T13:57:38-08:00</endTimeStamp>
				<author>
					<name>AutomatedUser</name>
				</author>
				<source>
					<applicationSoftware version="1.4b (28)">PANalytical Aeris Instrument Suite</applicationSoftware>
					<instrumentControlSoftware version="2.0.0 20210224">AERIS</instrumentControlSoftware>
					<instrumentID>950485</instrumentID>
				</source>
			</header>
			<dataPoints>
				<positions axis="2Theta" unit="deg">
					<startPosition>10.02173288</startPosition>
					<endPosition>139.98435528</endPosition>
				</positions>
				<positions axis="Omega" unit="deg">
					<startPosition>5.01086644</startPosition>
					<endPosition>69.99217764</endPosition>
				</positions>
				<commonCountingTime unit="seconds">1.551</commonCountingTime>
				<counts unit="counts">406 434 386 406 368 360 379 399 378 414 376 416 405 398 373 421 357 366 390 348 384 380 389 380 342 348 345 399 356 355 345 345 338 323 335 306 335 368 380 339 341 321 336 329 343 335 310 298 333 309 339 329 316 335 325 331 344 321 328 325 296 279 305 316 298 324 332 314 306 315 314 288 291 320 301 320 300 292 320 351 301 276 304 285 283 276 296 271 304 305 253 300 313 299 259 301 246 285 312 302 265 285 268 289 257 302 261 276 256 314 268 276 304 267 267 234 272 282 292 259 232 274 274 218 257 273 258 270 252 248 272 292 215 232 268 260 233 245 271 261 248 289 234 249 249 209 242 237 235 238 238 224 253 240 243 215 227 230 230 198 228 238 217 232 247 261 237 225 241 241 247 269 234 271 266 285 262 232 215 266 243 249 243 240 220 202 228 209 192 212 216 220 244 212 232 213 242 214 213 210 196 210 218 219 234 223 205 224 223 183 245 201 231 214 217 213 191 239 218 221 210 198 200 224 236 198 203 228 194 194 217 213 206 213 187 225 213 213 223 183 206 203 207 198 203 211 196 215 195 209 219 209 218 243 240 296 422 423 485 394 349 221 198 188 213 204 223 187 199 212 210 194 177 192 236 200 206 217 208 161 178 178 190 178 190 158 192 192 189 181 200 201 174 189 174 192 185 197 176 186 201 189 194 198 200 231 197 186 181 186 217 209 242 266 331 274 189 191 234 253 272 351 364 332 335 298 253 206 222 198 206 199 203 214 236 201 196 210 205 245 250 230 274 379 462 741 1244 1632 1793 1334 779 413 262 254 243 218 170 201 188 179 172 190 194 176 187 178 182 171 183 185 190 175 179 182 164 185 200 158 176 199 159 159 181 169 198 163 180 177 161 170 167 185 157 149 175 143 180 138 163 142 182 164 162 180 162 156 147 146 157 170 170 181 155 190 166 150 162 164 175 175 152 151 154 172 135 145 169 166 167 178 141 183 169 208 206 152 165 191 182 185 177 191 170 214 195 208 289 323 520 428 333 241 167 183 181 156 168 188 184 165 192 190 218 199 226 265 318 350 415 599 847 896 787 583 522 470 393 303 311 315 406 508 645 697 640 516 379 352 294 253 306 331 386 466 423 308 267 242 209 181 160 169 163 161 165 134 161 147 156 150 124 146 150 150 176 155 160 137 146 158 136 196 150 145 165 143 140 152 146 136 129 159 152 159 161 170 168 165 152 158 149 151 160 189 189 197 176 161 167 171 144 155 154 122 151 131 126 131 152 140 143 140 151 149 136 139 138 124 146 140 151 150 152 128 130 168 154 157 207 251 261 206 231 171 218 204 231 185 239 293 299 298 207 194 172 168 167 152 157 139 121 147 126 162 133 139 156 217 224 279 279 276 275 268 278 231 212 211 201 257 244 219 235 239 265 243 252 335 450 499 404 325 255 188 157 160 136 148 126 142 140 115 126 160 192 239 213 220 195 184 174 123 120 137 124 119 124 161 134 153 109 104 139 117 130 138 144 145 176 166 151 148 156 144 154 135 146 153 140 160 137 131 134 159 139 155 162 172 170 188 152 119 146 127 144 147 140 150 177 149 155 158 132 121 146 195 207 227 228 230 213 187 179 171 155 152 134 156 136 141 125 118 141 117 126 107 130 165 129 125 119 108 144 125 116 117 135 119 132 147 134 120 111 144 134 133 144 148 143 142 156 202 214 167 211 255 212 191 173 142 128 127 135 128 122 102 121 139 125 125 118 104 130 149 121 129 101 125 103 118 152 122 117 121 124 161 144 143 127 166 160 224 230 206 216 200 224 147 151 147 155 140 145 140 157 114 117 128 139 119 124 134 97 129 108 141 104 157 116 136 113 92 113 124 137 101 119 135 131 130 112 117 93 106 110 109 91 114 99 109 112 135 134 118 133 131 127 123 133 127 142 131 114 154 140 142 180 299 421 473 500 391 402 244 182 151 147 149 155 123 117 148 148 171 168 150 172 136 161 126 132 133 140 140 131 106 130 133 106 134 135 140 150 155 148 133 141 128 121 123 112 115 128 122 124 130 109 112 128 102 115 141 127 144 137 117 82 124 104 128 143 125 126 159 120 112 125 121 131 131 139 156 128 173 175 199 244 251 257 299 323 269 214 217 196 181 147 146 125 134 135 127 145 107 116 110 121 124 121 126 111 104 124 118 110 110 106 100 120 112 102 136 111 115 106 133 102 117 127 96 131 116 117 116 132 128 115 141 172 235 318 305 267 256 258 209 176 171 129 123 135 116 130 133 127 130 144 145 120 112 130 153 173 178 205 273 286 345 278 230 238 212 145 133 130 123 109 101 118 133 130 96 117 132 97 115 85 116 114 110 124 123 108 106 88 96 111 128 124 95 130 131 110 126 116 129 123 126 124 132 156 124 112 114 121 125 112 111 117 113 130 105 107 113 102 115 122 120 107 127 106 91 128 104 115 115 105 118 122 117 115 126 111 143 114 120 126 136 131 117 136 164 147 128 128 123 121 126 138 144 124 102 124 109 96 113 106 120 115 150 120 138 141 143 155 145 179 179 180 147 138 156 141 131 129 126 138 120 96 119 132 109 120 128 110 119 125 93 107 115 95 121 111 117 130 116 113 106 120 114 110 130 108 106 98 105 122 115 103 126 105 111 122 113 140 126 131 148 129 121 136 141 120 123 127 135 159 224 303 287 234 165 232 164 161 136 145 153 112 129 114 112 95 134 122 123 115 123 139 135 132 145 167 133 143 143 143 120 111 158 178 134 122 152 160 115 108 136 118 103 115 118 129 101 120 82 128 108 96 148 128 141 99 100 111 120 140 117 140 145 136 109 125 115 131 142 121 96 88 119 91 118 116 130 109 121 110 119 111 96 110 109 101 117 119 118 110 112 111 112 111 122 111 138 135 107 115 95 138 144 137 93 113 133 151 132 126 112 126 163 135 119 140 123 121 108 99 109 97 94 112 112 113 94 106 109 104 115 116 113 112 102 98 128 158 162 130 138 128 131 117 148 121 88 107 121 103 115 132 120 120 106 120 113 116 108 118 95 116 85 102 103 110 116 96 111 113 102 156 178 180 150 148 156 181 139 120 90 112 124 104 99 105 92 85 108 100 105 90 104 76 106 105 91 85 111 104 85 100 89 101 106 111 102 91 125 101 87 119 110 111 112 99 115 125 149 107 118 112 117 113 112 124 84 101 96 103 99 102 91 100 106 82 108 98 93 92 109 102 103 115 98 117 112 105 105 112 116 113 94 101 123 101 141 104 108 109 113 114 117 120 112 104 111 119 109 101 103 112 126 113 117 95 140 153 198 236 219 182 136 158 159 158 147 134 122 118 103 106 104 121 125 112 104 84 142 129 114 153 135 127 107 116 119 132 121 112 102 97 88 96 111 121 100 98 104 116 101 126 93 84 76 105 102 120 110 100 106 108 106 92 102 101 125 124 113 93 105 99 122 124 116 110 100 111 100 126 112 104 91 108 106 126 110 108 119 106 107 99 79 87 109 84 85 106 114 100 92 110 94 83 86 103 101 101 115 91 95 99 104 117 104 126 103 120 118 98 115 97 89 107 102 103 107 112 90 96 96 85 109 95 95 80 84 118 102 109 112 110 113 110 116 96 92 105 121 109 101 91 104 104 100 98 99 108 86 117 100 100 95 123 108 110 106 95 103 131 130 98 95 122 116 107 106 115 103 116 138 151 135 122 108 95 122 110 124 109 103 128 134 110 121 107 80 92 122 121 107 115 106 96 109 106 112 131 135 114 104 100 99 87 107 106 107 104 96 88 105 137 113 125 112 116 126 97 128 96 104 118 107 113 79 111 98 96 111 122 109 82 96 94 79 87 86 99 97 115 104 107 108 90 97 99 92 112 108 108 105 102 85 94 89 90 115 137 101 99 106 104 95 108 102 100 102 103 101 99 83 95 110 107 100 101 121 106 131 92 107 120 102 98 93 104 114 114 102 131 123 126 103 122 113 109 129 108 109 107 122 103 130 97 109 97 115 82 98 100 107 110 101 106 98 98 104 102 107 109 98 110 106 101 110 111 107 118 118 122 124 109 101 112 100 109 99 109 103 108 103 121 83 69 105 88 110 102 110 114 106 90 97 109 102 111 109 112 85 97 86 108 91 112 103 93 96 110 97 114 119 73 103 96 98 90 82 99 114 108 106 90 115 81 90 104 111 119 85 113 87 89 99 110 110 85 100 82 86 90 95 89 110 101 91 116 107 118 101 110 96 99 105 99 103 103 109 107 104 99 99 95 95 92 106 124 100 106 112 130 141 125 126 105 105 99 105 113 111 105 114 98 91 110 96 83 91 96 122 118 115 126 118 140 92 116 112 122 87 124 110 110 100 93 96 98 85 102 100 106 92 114 93 95 87 85 104 87 123 96 83 101 87 100 92 100 128 93 123 87 103 88 103 102 95 94 94 98 80 108 101 86 89 84 86 106 107 80 99 105 87 87 92 100 91 97 103 90 107 91 114 134 113 121 91 108 90 105 99 128 118 112 124 119 105 98 103 120 114 108 105 95 96 88 107 89 93 114 117 87 103 106 80 134 105 108 117 110 141 112 103 132 110 130 99 101 122 109 105 118 113 92 111 86 94 94 119 112 107 90 123 109 108 91 73 109 104 97 109 132 111 115 133 83 123 109 105 122 129 120 80 102 104 107 101 118 91 106 114 108 78 98 108 95 108 106 103 87 100 91 113 107 105 102 97 112 112 117 105 112 99 105 130 93 92 101 122 118 113 112 113 110 112 117 96 99 94 94 89 90 93 90 116 102 113 78 107 93 117 106 108 95 100 77 116 81 95 102 72 101 121 121 103 87 107 91 88 100 111 82 104 85 81 80 90 99 95 120 102 106 105 92 99 87 99 91 106 98 101 107 112 95 94 87 105 100 105 99 105 113 100 96 108 102 122 75 97 100 109 118 88 108 110 113 114 126 134 113 139 152 140 97 140 111 126 106 127 125 133 123 119 112 117 128 128 122 96 113 126 105 104 86 126 115 114 118 129 117 107 109 120 145 115 132 116 134 123 108 102 113 106 118 108 123 113 106 109 121 100 81 97 99 118 98 101 105 108 97 101 106 106 100 94 96 119 109 110 88 113 84 98 84 88 96 100 100 103 103 89 110 120 93 99 112 108 114 114 92 97 119 106 106 99 104 99 80 115 100 111 100 109 89 120 101 111 86 112 115 102 110 112 91 92 104 114 94 107 94 95 115 107 116 93 119 105 107 100 98 118 116 106 109 128 90 107 108 98 98 113 111 132 132 138 144 135 151 129 121 123 102 126 129 118 127 128 114 118 113 117 109 103 152 101 120 112 140 141 127 127 130 129 113 103 122 120 132 114 127 99 96 122 135 110 115 107 113 104 94 89 103 110 107 88 109 105 113 131 112 121 100 105 110 115 114 105 98 128 99 101 96 110 112 104 112 120 86 110 92 119 85 95 108 99 89 89 99 100 111 97 116 113 98 110 117 102 112 113 116 138 119 105 162 120 137 138 172 163 156 137 115 134 114 128 138 128 141 133 131 145 126 133 116 113 98 114 118 98 120 107 93 101 113 99 111 99 105 104 112 103 99 108 117 114 99 115 127 97 84 89 118 111 119 105 112 118 107 118 114 101 127 112 94 114 81 95 100 113 119 108 101 100 104 97 102 105 90 106 114 133 122 122 103 89 97 92 118 89 129 112 100 125 125 118 124 118 121 92 91 117 105 121 84 116 134 122 97 127 99 97 128 123 109 98 102 104 112 109 116 119 104 111 115 105 116 112 81 91 91 88 96 99 71 117 79 94 107 104 69 110 104 99 119 100 107 106 86 95 98 78 98 128 86 99 89 110 80 108 112 115 104 93 105 113 102 81 109 102 99 104 100 101 94 97 105 112 83 108 91 89 110 121 100 127 96 106 94 104 111 118 97 90 95 119 122 112 104 125 101 91 110 106 91 106 110 114 104 109 104 117 117 114 108 108 100 115 118 116 127 96 112 107 109 123 98 90 118 102 112 86 108 109 116 115 93 104 110 90 118 86 106 109 107 111 100 109 91 102 96 104 112 110 105 114 116 89 115 108 129 98 90 88 90 96 95 124 104 110 125 113 127 102 125 116 106 133 97 106 97 97 135 108 121 105 116 111 134 107 136 136 134 133 129 124 114 114 117 114 94 114 116 114 124 127 121 133 132 114 133 87 108 115 108 126 100 124 100 123 110 105 109 110 102 100 107 101 102 97 97 114 114 109 114 108 106 110 108 90 96 119 108 99 88 108 96 86 110 119 93 103 120 135 95 104 112 115 101 104 102 127 119 108 112 115 102 99 115 117 92 97 116 104 101 102 103 96 116 95 104 121 123 107 93 120 118 104 116 108 134 117 130 101 117 107 91 132 99 110 102 107 119 146 123 134 110 119 111 113 120 131 101 128 107 92 117 112 121 130 110 131 116 121 96 109 118 107 146 113 124 131 126 165 151 155 114 118 115 118 138 120 123 104 113 129 109 127 141 143 121 115 140 117 99 140 99 119 122 102 119 111 123 113 96 122 105 111 103 109 110 124 117 105 116 98 109 121 106 95 99 105 111 101 107 126 102 109 94 93 119 122 93 95 104 122 119 109 103 129 110 118 111 105 105 108 98 82 108 104 108 91 112 129 120 130 118 118 117 127 92 111 101 114 129 94 108 124 104 116 106 106 114 102 104 108 109 119 126 111 113 105 120 102 115 127 123 108 100 116 117 106 118 125 120 125 119</counts>
			</dataPoints>
		</scan>
	</xrdMeasurement>
</xrdMeasurements>