File: dataset/precursor_mixture/TiO2_0p4009-ZnO_0p6010--8min.xrdml
<?xml version="1.0"?>
<xrdMeasurements xmlns="http://www.xrdml.com/XRDMeasurement/2.3" xmlns:xsi="http://www.w3.org/2001/XMLSchema-instance" xsi:schemaLocation="http://www.xrdml.com/XRDMeasurement/2.3 http://www.xrdml.com/XRDMeasurement/2.3/XRDMeasurement.xsd" status="Completed" recordIdentifier="{F6BD0720-B997-480A-B9D3-99158DEF91A3}">
	<comment>
		<entry/>
	</comment>
	<sample type="To be analyzed">
		<id>TiO2_0p4009-ZnO_0p6010--8min</id>
		<name></name>
		<preparedBy></preparedBy>
	</sample>
	<xrdMeasurement measurementType="Scan" status="Completed" sampleMode="Reflection">
		<usedWavelength intended="K-Alpha 1">
			<kAlpha1 unit="Angstrom">1.5405980</kAlpha1>
			<kAlpha2 unit="Angstrom">1.5444260</kAlpha2>
			<kBeta unit="Angstrom">1.3922500</kBeta>
			<ratioKAlpha2KAlpha1>0.5000</ratioKAlpha2KAlpha1>
		</usedWavelength>
		<incidentBeamPath>
			<radius unit="mm">145.00</radius>
			<xRayTube id="1010048" name="Empyrean Cu LFF HR (9430 033 7310x)">
				<tension unit="kV">40.0</tension>
				<current unit="mA">15.0</current>
				<anodeMaterial>Cu</anodeMaterial>
				<focus type="Line">
					<length unit="mm">12.0</length>
					<width unit="mm">0.4</width>
					<takeOffAngle unit="deg">6.0</takeOffAngle>
				</focus>
			</xRayTube>
			<sollerSlit id="21010002" name="Soller slits 0.04 rad.">
				<opening unit="rad">0.0400</opening>
			</sollerSlit>
			<mask id="22031000" name="Fixed mask 13 mm">
				<width unit="mm">9.00</width>
			</mask>
			<divergenceSlit id="22120001" name="Divergence slit 1°" xsi:type="fixedDivergenceSlitType">
				<distanceToSample unit="mm">50.00</distanceToSample>
				<height unit="mm">1.52</height>
			</divergenceSlit>
		</incidentBeamPath>
		<sampleMovement xsi:type="spinningSampleMovementType">
			<spinnerRevolutionTime unit="seconds">1.0</spinnerRevolutionTime>
		</sampleMovement>
		<diffractedBeamPath>
			<radius unit="mm">145.00</radius>
			<antiScatterSlit id="22090040" name="AS slit 9 mm (PIXcel)" xsi:type="fixedAntiScatterSlitType">
				<height unit="mm">9.00</height>
			</antiScatterSlit>
			<sollerSlit id="21020003" name="Large Soller slits 0.04 rad.">
				<opening unit="rad">0.0400</opening>
			</sollerSlit>
			<filter id="20030001" name="Large beta-filter Nickel">
				<material>Ni</material>
				<thickness unit="mm">0.020</thickness>
			</filter>
			<detector id="7010019" name="PIXcel1D-Medipix3 detector" xsi:type="rtmsDetectorType">
				<phd unit="keV">
					<lowerLevel>4.02</lowerLevel>
					<upperLevel>11.27</upperLevel>
				</phd>
				<mode>Scanning</mode>
				<activeLength unit="deg">5.542</activeLength>
			</detector>
		</diffractedBeamPath>
		<scan appendNumber="0" mode="Continuous" scanAxis="Gonio" status="Completed">
			<header>
				<startTimeStamp>2024-11-14T12:53:32-08:00</startTimeStamp>
				<endTimeStamp>2024-11-14T13:01:39-08:00</endTimeStamp>
				<author>
					<name>AutomatedUser</name>
				</author>
				<source>
					<applicationSoftware version="1.7b (136)">PANalytical Aeris Instrument Suite</applicationSoftware>
					<instrumentControlSoftware version="3.2.00000000 20240306">AERIS</instrumentControlSoftware>
					<instrumentID>950485</instrumentID>
				</source>
			</header>
			<dataPoints>
				<positions axis="2Theta" unit="deg">
					<startPosition>10.00943322</startPosition>
					<endPosition>99.99442286</endPosition>
				</positions>
				<positions axis="Omega" unit="deg">
					<startPosition>5.00471661</startPosition>
					<endPosition>49.99721143</endPosition>
				</positions>
				<commonCountingTime unit="seconds">12.495</commonCountingTime>
				<counts unit="counts">2174 2225 2186 2280 2218 2242 2227 2204 2248 2243 2140 2233 2310 2227 2156 2211 2200 2162 2152 2190 2222 2224 2209 2127 2161 2139 2186 2076 2164 2125 2121 2167 2165 2119 2100 2138 2189 2141 2193 2074 2115 2143 2067 2117 2116 2090 2136 2060 2161 2134 2088 2021 2151 2156 2064 2073 2143 1991 2106 2017 2040 1989 1957 2022 2027 2041 1967 2046 1993 2022 2080 1979 2010 2024 2016 1994 1986 1998 2067 1904 2011 1859 2076 1996 1969 2056 2023 1949 1979 1985 1975 1950 1941 1940 2008 1939 1882 1984 1917 1926 1837 1975 1980 1937 1914 1898 1905 1878 1898 1868 1832 1859 1812 1884 1921 1905 1843 1987 1870 1769 1878 1948 1881 1854 1799 1803 1873 1827 1882 1790 1773 1711 1810 1768 1735 1809 1810 1792 1813 1787 1857 1778 1814 1777 1803 1768 1875 1739 1868 1769 1811 1757 1761 1769 1735 1783 1735 1691 1881 1777 1768 1821 1817 1663 1746 1686 1686 1728 1755 1774 1712 1765 1692 1680 1715 1709 1706 1695 1623 1691 1733 1690 1647 1640 1715 1700 1693 1686 1673 1709 1619 1703 1639 1737 1631 1628 1625 1644 1611 1624 1657 1667 1641 1605 1627 1668 1639 1651 1646 1593 1709 1624 1661 1627 1508 1589 1674 1506 1708 1577 1545 1643 1596 1560 1555 1584 1598 1522 1603 1584 1567 1621 1568 1521 1555 1653 1500 1499 1572 1520 1715 1592 1572 1540 1569 1509 1567 1563 1590 1511 1532 1510 1486 1512 1514 1542 1499 1579 1509 1524 1522 1585 1481 1535 1439 1448 1525 1486 1467 1496 1493 1453 1464 1470 1479 1422 1426 1528 1453 1502 1406 1448 1431 1576 1488 1502 1438 1484 1447 1503 1525 1454 1371 1488 1464 1464 1476 1480 1434 1438 1486 1500 1431 1481 1400 1377 1436 1428 1426 1395 1395 1385 1464 1404 1380 1395 1461 1379 1394 1363 1393 1430 1353 1349 1421 1373 1442 1450 1419 1459 1406 1379 1317 1370 1392 1349 1462 1407 1372 1448 1390 1373 1348 1373 1428 1385 1337 1387 1371 1356 1395 1295 1382 1362 1372 1282 1402 1323 1320 1357 1318 1361 1398 1373 1425 1370 1404 1319 1349 1339 1379 1349 1311 1367 1339 1370 1343 1347 1364 1331 1277 1322 1366 1327 1301 1271 1353 1372 1301 1311 1296 1325 1239 1324 1382 1317 1274 1238 1332 1317 1289 1332 1266 1312 1257 1254 1320 1269 1299 1290 1324 1281 1264 1279 1328 1276 1369 1240 1287 1262 1215 1250 1316 1285 1402 1261 1277 1279 1279 1335 1240 1278 1283 1201 1222 1237 1314 1305 1258 1279 1293 1324 1265 1244 1286 1206 1295 1260 1244 1227 1338 1248 1207 1246 1193 1349 1217 1248 1249 1267 1225 1237 1278 1256 1243 1193 1231 1270 1172 1210 1208 1156 1188 1145 1233 1270 1189 1103 1178 1250 1207 1227 1221 1202 1202 1217 1240 1303 1251 1235 1231 1242 1249 1181 1202 1246 1201 1306 1236 1215 1202 1193 1242 1177 1199 1237 1184 1177 1215 1191 1209 1191 1222 1161 1172 1229 1206 1142 1232 1206 1221 1201 1221 1181 1241 1176 1187 1194 1141 1161 1216 1253 1180 1195 1172 1244 1156 1199 1183 1197 1184 1220 1165 1140 1164 1110 1196 1147 1104 1127 1180 1133 1194 1214 1153 1126 1155 1128 1251 1155 1217 1101 1145 1162 1113 1184 1129 1159 1113 1184 1114 1140 1160 1143 1100 1162 1170 1169 1137 1132 1138 1202 1161 1093 1195 1104 1177 1185 1160 1090 1157 1105 1083 1184 1108 1121 1162 1157 1159 1199 1141 1146 1087 1152 1087 1223 1072 1131 1137 1092 1201 1158 1104 1168 1148 1099 1170 1076 1061 1139 1050 1125 1077 1133 1126 1070 1087 1125 1052 1133 1090 1153 1153 1103 1086 1103 1105 1109 1143 1105 1120 1117 1069 1099 1085 1153 1097 1103 1156 1075 1078 1104 1107 1091 1092 1066 1004 1055 1106 1114 1135 1167 1065 1053 1095 1104 1073 1124 1092 1074 1096 1074 1055 1098 1126 1092 1060 1047 1090 1085 1048 1081 1035 1093 1088 995 1048 1041 1126 1014 1017 1059 1074 1049 1118 1028 1118 1110 1028 1040 1062 1089 1109 1051 1030 1035 1017 1063 1025 1077 982 1089 998 1082 1075 1080 973 1006 1042 1037 1024 985 1098 1040 1048 1016 969 1057 1069 1016 1016 977 1032 1081 1047 967 1058 1010 969 1014 1064 1023 964 1011 1018 1072 1030 1022 1005 954 1012 1015 947 1022 1002 1011 1029 1010 968 1068 972 1035 1051 1052 1042 1047 1011 1010 1008 956 1016 988 987 1048 975 977 992 962 1025 980 989 1070 996 1016 1002 1017 1007 994 976 1011 979 1006 1009 976 969 956 980 1021 969 982 1072 968 959 954 944 1004 985 954 991 959 968 924 929 955 965 957 995 968 953 1020 951 914 987 884 990 934 919 946 941 926 918 941 982 956 982 950 923 960 944 941 934 935 971 1012 1021 939 912 932 966 916 971 916 970 948 912 897 921 936 940 954 920 896 957 960 974 1043 956 935 969 941 924 1016 957 913 908 944 936 919 964 882 969 932 965 891 906 915 907 931 912 929 923 923 921 917 919 907 940 935 921 923 903 952 908 943 914 910 897 879 898 924 844 826 911 883 858 851 924 930 865 812 895 870 925 875 926 833 876 865 873 934 925 845 918 893 872 874 871 888 920 893 908 882 869 918 878 929 858 900 860 898 906 874 900 879 892 824 867 846 896 820 921 876 831 856 906 862 826 951 810 863 880 828 870 837 868 826 828 865 838 871 812 874 893 851 860 790 772 901 851 894 781 876 829 862 854 843 840 837 874 815 812 836 834 863 866 851 860 851 869 860 848 857 847 845 865 895 843 857 812 817 868 853 814 828 829 830 870 808 867 854 794 830 857 784 824 800 786 834 794 865 772 844 869 833 835 803 833 808 828 857 797 843 771 836 803 785 784 855 822 873 807 808 816 857 775 803 759 857 838 803 825 816 814 868 801 791 839 781 802 832 797 864 810 842 792 814 774 792 855 813 788 769 814 812 804 836 794 826 834 814 807 799 791 791 808 806 769 787 791 751 763 810 724 815 743 791 785 834 789 786 835 771 837 813 800 838 794 758 766 827 729 766 756 783 741 774 822 796 766 809 790 795 810 799 793 802 757 765 754 754 764 773 786 812 738 740 762 742 752 789 773 763 741 774 774 804 719 764 792 799 787 785 784 818 770 800 830 814 764 812 794 715 750 764 753 764 785 800 794 738 770 817 797 781 744 761 718 735 749 770 810 783 763 731 751 756 761 765 771 715 734 785 721 770 769 788 767 692 752 740 753 764 697 745 711 750 740 778 722 797 750 738 710 753 764 745 700 740 733 697 679 706 767 754 700 730 772 749 679 761 758 689 678 735 695 733 721 727 733 744 751 723 705 737 671 723 773 775 728 695 745 717 701 686 732 737 735 726 705 712 782 712 732 815 710 765 734 730 735 731 709 760 689 723 769 714 742 731 710 706 730 806 715 715 703 686 734 781 702 715 708 734 746 754 706 794 752 722 733 743 735 732 713 705 740 755 765 728 726 775 763 761 781 776 782 756 732 749 769 796 761 852 803 799 759 749 742 846 805 811 779 859 792 782 809 779 791 827 856 878 886 908 812 849 848 899 896 874 906 965 951 961 998 972 995 1003 1027 1112 1053 1151 1208 1244 1323 1372 1436 1462 1623 1765 1798 2099 2051 2275 2409 2560 2849 3066 3312 3644 3840 4096 4271 4638 4867 5246 5523 5758 6034 6324 6559 6801 7162 7115 7468 7578 8026 8095 8376 8302 8009 7875 7645 7148 6710 6337 5621 5031 4487 4087 3567 3146 2740 2416 2099 1875 1706 1605 1450 1419 1324 1144 1222 1146 1153 1050 1054 1037 974 1033 911 914 925 932 871 971 912 887 810 796 849 815 851 774 793 819 750 770 757 775 792 738 773 764 725 727 726 720 761 727 753 701 744 665 740 712 711 723 702 726 706 694 698 713 674 765 667 707 705 677 687 677 624 717 707 745 716 702 677 726 699 708 651 695 635 698 703 662 687 664 686 622 688 713 663 680 685 643 633 658 695 721 619 668 646 634 693 660 665 632 697 680 619 673 702 696 621 639 631 646 664 689 668 718 627 698 673 655 644 656 675 625 677 621 630 644 640 690 651 651 664 650 643 650 676 689 642 643 683 625 627 671 618 655 674 621 645 659 705 703 670 632 639 657 652 708 664 669 655 684 655 596 653 657 620 692 682 728 702 690 671 684 714 684 683 695 684 688 699 674 662 672 742 648 665 631 655 645 674 659 651 661 593 616 626 636 603 635 650 646 616 656 671 640 627 637 618 658 660 673 649 603 639 668 609 658 578 590 590 584 648 602 610 590 636 648 640 650 626 591 649 645 653 612 640 623 636 607 662 619 642 595 578 619 590 707 613 614 623 586 625 630 662 634 606 581 589 624 634 584 673 605 636 619 584 676 603 634 587 616 636 613 645 609 600 630 590 621 616 614 593 622 581 614 672 611 631 645 579 659 635 588 592 608 617 656 645 650 600 631 590 624 573 623 609 603 631 595 585 619 610 604 591 622 568 616 642 566 606 581 576 589 623 646 581 631 608 617 545 618 591 577 554 599 657 561 540 567 615 587 596 590 558 593 573 581 547 592 610 575 585 588 556 609 588 611 626 567 557 568 577 565 622 590 576 573 552 593 620 572 616 597 576 564 616 612 592 597 576 561 593 573 597 532 510 587 591 594 574 607 556 591 609 527 598 558 582 547 600 604 578 575 572 568 585 591 644 601 597 611 573 580 616 572 586 582 570 573 609 617 569 592 592 551 574 585 605 594 585 590 587 595 603 594 596 559 549 634 584 596 618 616 612 587 540 600 622 600 662 645 653 609 618 586 532 614 567 629 626 539 636 655 634 644 613 581 621 661 615 614 656 627 602 660 647 635 671 621 628 639 674 654 704 696 708 658 665 661 710 680 683 708 691 666 730 683 679 736 754 748 726 748 716 747 747 737 741 780 754 741 755 809 785 767 801 779 853 835 837 956 843 893 880 962 884 957 947 947 1055 983 1044 1020 1023 1170 1204 1247 1263 1256 1374 1344 1534 1626 1636 1827 1890 2093 2100 2282 2396 2560 2899 2964 3196 3420 3708 4010 4254 4488 4735 4777 5206 5627 5745 6134 6391 6785 6847 7046 7328 7795 7810 7929 8086 8051 8251 8133 7762 7566 7285 6909 6436 5994 5693 5165 4789 4404 4122 3540 3354 2960 2760 2485 2299 2090 1953 1854 1721 1644 1529 1465 1343 1300 1259 1245 1174 1165 1137 1077 1109 1046 1002 967 912 925 919 849 852 835 877 823 804 772 772 769 808 753 711 716 734 733 721 758 716 693 689 694 706 716 696 694 684 690 653 651 682 666 707 660 693 655 632 635 712 650 628 624 702 629 642 698 706 659 648 667 656 635 638 663 604 582 604 637 593 566 599 617 631 550 594 567 615 646 616 578 571 623 528 627 609 643 599 612 582 611 609 571 579 572 591 615 582 628 592 567 608 600 592 587 651 616 595 655 630 642 578 594 663 566 595 595 598 567 599 611 627 633 633 603 578 612 631 589 597 647 629 598 607 684 655 616 582 675 565 660 611 595 616 615 609 669 670 678 638 651 690 659 642 632 650 698 676 682 689 661 706 698 718 751 722 767 784 777 760 812 799 822 855 816 812 976 928 972 917 1083 1052 1102 1170 1228 1357 1306 1456 1546 1692 1864 1922 2156 2354 2572 2675 2777 3093 3240 3384 3686 3925 4221 4352 4707 4918 5123 5348 5729 5917 6074 6140 6401 6570 6909 6539 6562 6520 6276 6097 5597 5285 5004 4541 4252 3851 3461 3084 2930 2574 2351 2062 1833 1673 1567 1463 1350 1253 1237 1189 1052 1068 974 1015 1026 950 914 924 886 922 851 881 811 793 824 805 826 795 748 764 788 734 794 743 747 759 776 758 770 710 716 737 767 736 748 703 721 752 709 725 714 734 683 726 755 692 704 705 737 710 729 694 741 734 742 723 753 767 712 746 719 766 726 738 764 768 745 771 793 795 763 816 805 858 867 800 818 858 846 853 922 949 940 903 926 920 970 1001 1070 1020 1107 1100 1186 1179 1165 1268 1276 1318 1307 1304 1439 1495 1512 1567 1646 1730 1782 1949 2029 2028 2253 2434 2585 2670 2870 3052 3380 3463 3830 4119 4498 4922 5098 5731 5873 6455 6980 7383 7765 8296 8833 9562 9786 10098 10633 11401 11797 12038 12586 13203 13146 13715 13985 14028 13985 13834 13644 12839 12455 11653 11144 10332 9699 9110 8283 7745 7004 6246 5639 5399 4616 4214 3931 3617 3202 3054 2780 2639 2525 2280 2124 2114 1964 1781 1840 1650 1674 1565 1506 1538 1413 1453 1385 1326 1295 1275 1336 1250 1218 1233 1163 1218 1191 1133 1246 1182 1209 1159 1212 1212 1177 1289 1224 1304 1296 1210 1247 1274 1195 1228 1201 1242 1269 1113 1104 1072 1004 924 909 976 890 866 892 829 800 795 705 740 747 675 703 683 687 634 704 702 646 668 655 642 662 644 652 659 614 689 686 706 667 692 689 703 699 760 743 780 810 774 805 789 897 873 992 1002 1067 1110 1172 1241 1355 1339 1433 1541 1550 1582 1745 1731 1827 2044 2027 2048 2183 2265 2299 2265 2430 2300 2445 2496 2327 2285 2208 1961 1929 1856 1718 1653 1613 1407 1386 1283 1145 1075 990 898 858 788 756 769 706 737 676 664 606 674 622 650 590 597 604 555 638 587 624 587 544 561 600 599 553 596 595 611 664 636 663 649 672 682 691 744 787 721 771 817 780 881 879 976 960 937 1040 1023 1029 1079 1035 1096 1108 1069 1085 1064 988 976 965 891 844 809 789 754 784 684 679 669 651 602 592 549 557 543 582 543 532 506 522 495 496 474 488 498 499 530 470 504 456 480 513 461 473 441 459 455 470 449 494 483 480 465 464 475 457 473 465 450 466 467 420 460 445 438 456 468 474 443 478 459 458 468 445 439 424 492 453 439 463 421 441 409 426 456 457 444 460 465 488 437 459 416 444 456 422 468 417 495 468 427 427 427 436 461 409 418 464 438 445 423 431 443 439 413 458 411 461 434 441 411 431 455 451 460 431 412 391 428 451 471 416 425 409 430 427 412 462 426 428 404 442 443 411 404 431 402 411 408 407 443 427 455 450 419 409 421 391 404 426 435 436 401 414 407 437 401 399 403 429 394 386 425 440 393 411 384 413 401 426 393 397 426 392 431 404 407 420 436 413 412 401 410 392 383 396 373 411 427 392 401 404 418 449 402 393 395 372 396 425 391 421 408 421 404 416 382 388 454 387 378 404 437 411 386 415 404 389 397 401 408 424 360 417 413 391 432 403 402 419 420 408 406 409 415 442 433 436 406 422 406 380 378 399 416 449 415 424 414 401 415 408 408 367 382 458 395 424 380 402 410 424 420 405 435 443 398 436 407 428 397 409 384 404 375 371 376 372 374 414 399 429 432 403 358 399 410 439 401 397 382 388 387 373 389 380 380 394 373 386 397 382 382 385 421 388 386 393 400 422 398 375 403 376 382 343 383 412 376 390 377 380 383 400 330 390 374 400 369 399 382 411 396 377 371 367 396 386 374 380 418 378 374 393 363 352 382 373 389 355 409 415 417 390 390 409 368 395 426 362 417 397 394 365 407 394 336 418 354 376 426 418 420 381 386 403 391 387 362 387 407 370 400 367 358 384 379 384 392 412 393 391 391 385 358 368 379 404 366 394 370 357 380 388 405 342 395 379 417 337 396 385 377 410 357 405 396 428 372 371 361 378 393 393 366 351 396 403 390 401 338 369 341 353 369 365 363 379 364 399 391 395 361 364 362 341 350 366 371 356 346 372 354 400 351 348 375 341 373 356 369 359 356 364 395 377 384 332 380 348 365 395 366 378 378 343 355 352 386 392 368 322 347 372 366 352 316 363 354 362 363 362 367 370 348 318 353 352 368 349 411 360 350 357 369 370 378 334 374 344 389 361 371 351 335 372 357 359 350 372 374 378 355 354 352 374 339 341 379 363 339 365 364 340 326 322 323 378 363 371 319 362 374 359 359 336 371 343 344 362 359 365 298 339 343 364 348 340 353 303 378 318 372 337 342 354 364 389 351 351 322 329 363 359 347 355 368 315 368 339 329 339 378 382 344 337 332 329 330 364 347 308 319 359 345 357 365 360 360 347 360 384 332 346 337 339 367 371 361 331 341 340 321 359 332 349 361 333 350 339 352 349 345 345 326 356 319 318 329 359 368 312 365 316 356 368 387 329 372 353 340 316 367 341 368 325 326 360 366 327 310 361 340 383 347 351 366 369 356 400 324 380 397 341 343 356 331 369 375 350 360 386 364 364 398 363 334 372 393 371 369 347 360 387 354 358 358 370 364 363 408 340 374 367 309 357 371 342 388 371 351 375 388 397 392 367 382 359 389 398 391 416 361 397 406 386 398 357 375 369 375 382 396 401 383 370 409 397 406 382 397 413 384 415 411 377 423 393 380 377 418 408 395 415 426 413 432 421 425 458 416 448 450 486 488 498 452 496 427 411 472 479 453 488 508 485 512 464 489 510 493 512 521 572 532 581 576 598 602 624 661 656 672 680 733 749 812 807 895 889 916 873 996 1032 1160 1199 1250 1283 1449 1536 1553 1755 1830 1882 2043 2075 2242 2270 2388 2492 2662 2820 2977 3017 3218 3304 3354 3537 3548 3547 3556 3519 3370 3251 3099 3006 2904 2797 2672 2603 2397 2395 2216 2140 2166 2006 1878 1782 1680 1708 1611 1607 1602 1592 1615 1650 1592 1693 1857 1892 1993 2092 2132 2189 2429 2464 2601 2735 2950 3056 3071 3187 3287 3434 3526 3411 3400 3211 3068 2945 2714 2608 2495 2275 2229 2079 2053 1943 1790 1681 1603 1385 1236 1147 961 935 851 775 728 724 665 630 601 551 587 535 539 573 529 525 484 475 443 471 493 490 443 447 417 427 479 425 444 432 422 429 390 400 383 373 394 379 371 405 352 412 365 323 370 410 405 416 367 357 377 363 382 383 376 375 361 316 361 396 370 329 390 352 373 364 371 319 381 338 372 358 326 347 359 368 364 327 346 341 331 357 320 321 351 319 326 359 354 350 376 338 349 334 353 371 325 368 311 386 351 356 340 345 305 356 365 318 330 322 346 339 359 364 314 309 335 319 331 361 343 316 353 337 305 340 333 396 305 310 331 333 328 369 362 333 330 350 348 327 316 302 314 363 330 337 340 357 308 304 333 333 349 312 359 304 330 315 354 336 315 349 320 307 351 353 330 364 320 325 358 348 332 351 328 332 346 310 352 297 335 329 298 292 334 319 333 337 346 316 326 341 333 352 349 331 321 308 363 319 321 343 314 368 337 326 325 303 311 308 325 324 329 310 322 353 327 304 324 317 313 339 318 314 353 315 332 347 325 297 325 346 345 327 337 312 322 294 362 280 312 336 311 307 319 313 322 346 297 308 310 313 282 332 352 328 324 307 291 334 344 327 315 325 306 353 329 334 347 300 324 316 341 300 291 327 342 326 308 287 325 310 320 307 305 306 335 317 331 321 316 333 301 328 312 343 332 341 324 356 313 315 332 348 309 317 346 300 354 305 315 342 311 334 322 319 345 340 359 307 335 312 316 263 334 326 327 339 299 313 328 308 329 326 351 324 344 332 297 314 292 319 331 308 284 336 321 331 313 325 329 328 311 341 333 329 302 366 313 295 298 334 340 322 320 350 331 322 320 335 287 318 315 328 305 327 351 312 334 310 341 315 342 349 316 365 317 346 311 340 325 321 308 321 295 318 361 319 298 316 324 325 306 322 335 320 327 328 337 302 343 324 330 309 298 324 316 362 307 282 350 348 300 289 359 363 352 332 335 360 324 361 304 326 319 330 345 312 302 320 321 340 317 347 330 370 330 330 321 368 354 319 341 334 368 364 338 347 369 353 343 370 340 370 367 396 378 406 387 348 377 383 346 360 396 418 404 409 431 450 391 425 447 467 428 454 482 482 498 507 572 499 542 578 587 605 644 715 811 828 789 910 967 1003 1034 1093 1183 1235 1324 1441 1511 1552 1737 1716 1898 1996 2028 2040 2176 2081 2049 2085 1970 1954 1779 1810 1645 1589 1435 1405 1456 1312 1372 1263 1180 1201 1072 1056 934 889 802 746 700 652 602 627 583 538 546 532 485 490 491 488 492 492 510 461 463 491 477 469 467 453 460 458 458 482 437 456 431 469 433 456 440 456 427 460 438 472 437 436 457 495 451 428 431 476 451 478 490 482 493 506 498 515 529 551 569 571 558 639 601 649 682 675 756 838 930 891 992 1020 1100 1090 1238 1295 1413 1496 1567 1653 1694 1841 1855 2060 2093 2075 2070 2165 2153 1972 1988 1932 1744 1746 1586 1444 1509 1384 1356 1353 1344 1238 1226 1160 1042 1026 898 867 775 692 669 668 615 595 594 579 551 542 473 474 490 476 479 481 467 450 438 454 454 499 442 435 474 453 443 448 452 438 465 409 441 445 451 507 514 439 457 474 462 459 430 462 470 419 465 467 438 439 497 467 464 490 574 498 531 523 518 569 494 549 568 551 584 583 557 581 642 611 652 616 683 697 674 709 724 706 765 771 750 817 826 868 853 872 905 960 1053 1057 1103 1133 1200 1245 1288 1400 1467 1662 1691 1817 1965 2003 2083 2314 2495 2606 2885 2930 3145 3390 3569 3760 3970 4260 4318 4567 4794 4924 5019 5160 5168 5042 5024 4831 4719 4529 4296 3964 3971 3670 3678 3542 3456 3334 3221 3069 2886 2855 2562 2342 2170 2051 1906 1790 1565 1442 1390 1244 1222 1144 1038 1048 1032 970 888 862 842 777 773 769 761 734 670 699 647 689 659 605 608 552 611 568 575 579 525 539 537 532 510 485 512 485 457 465 509 493 477 441 445 469 432 450 434 435 437 371 421 397 391 333 413 400 420 420 413 394 375 401 404 388 393 417 403 394 371 365 365 398 365 388 359 351 404 373 378 377 347 369 358 368 356 325 340 324 366 324 364 314 361 344 400 352 388 326 376 344 364 307 358 341 369 359 313 336 365 341 351 367 336 380 328 345 326 349 341 329 354 320 327 319 350 343 371 330 395 340 345 327 376 333 345 337 324 355 357 304 351 324 340 311 334 311 333 293 334 362 343 339 326 319 300 329 370 352 329 290 300 276 341 348 353 304 339 331 348 345 331 363 360 359 313 315 312 312 315 333 323 363 318 299 315 318 334 309 304 326 311 343 311 297 317 316 353 314 331 340 299 331 330 299 298 315 319 296 292 317 347 313 334 340 297 298 319 306 310 314 328 307 312 315 314 300 296 299 278 306 336 293 320 305 313 332 343 282 304 331 333 305 301 313 316 336 342 341 327 317 334 309 295 337 299 296 309 331 305 271 286 306 291 311 318 305 289 323 308 298 303 299 314 315 300 290 322 308 312 325 282 289 311 290 296 321 317 324 284 339 286 320 341 307 352 263 320 349 324 342 299 316 343 331 319 321 319 281 298 349 313 338 319 317 326 304 280 300 322 301 331 329 320 321 322 341 352 356 309 351 339 344 339 324 346 350 352 331 334 357 335 343 337 349 360 351 334 360 348 352 344 349 345 309 330 297 326 353 336 343 309 334 310 368 338 327 340 316 354 367 374 377 331 342 328 314 330 298 322 323 372 388 354 328 317 384 348 355 337 340 348 363 361 347 332 359 332 360 339 359 365 349 356 335 379 349 371 401 374 380 356 355 356 358 335 355 318 363 376 353 349 359 361 353 348 398 386 361 369 381 357 387 356 389 365 365 357 413 433 403 395 423 374 402 388 386 384 397 411 383 432 451 441 413 426 433 465 470 449 489 475 529 473 477 479 543 554 524 497 563 550 604 642 633 648 682 687 761 715 704 775 802 773 789 768 757 777 724 787 682 766 739 751 762 814 757 779 831 784 735 742 814 746 811 821 788 863 878 894 883 1013 974 973 1042 1092 1231 1270 1335 1390 1404 1488 1613 1760 1856 2006 2025 2220 2280 2533 2730 2878 2992 3186 3381 3523 3626 3667 3839 3764 3868 3982 4142 4209 4355 4500 4869 4872 4856 5054 5088 5140 5102 5078 4836 4397 4383 3971 3849 3558 3454 3317 3235 3136 3080 3013 2872 2772 2853 2601 2487 2277 2067 1940 1730 1705 1509 1432 1408 1202 1217 1150 1060 994 909 959 878 897 809 801 799 749 748 679 685 689 615 597 614 572 601 551 571 564 551 552 493 532 572 524 479 508 518 477 502 447 485 434 483 441 448 423 443 401 434 420 437 444 420 432 406 394 439 358 417 407 391 395 418 351 413 366 402 351 369 385 334 379 366 383 357 394 347 387 362 391 364 376 378 380 358 342 364 363 377 349 350 358 349 379 363 343 330 364 345 335 320 334 316 344 354 311 354 348 345 348 347 318 327 354 325 364 336 331 330 331 354 346 356 328 321 351 322 360 324 323 326 338 357 294 314 322 358 330 350 310 297 334 346 311 363 333 319 309 337 290 326 338 332 340 296 346 324 315 324 305 314 304 311 327 304 306 319 322 284 301 297 334 332 345 313 323 328 325 341 289 337 310 344 285 319 331 306 304 308 362 308 331 291 333 343 323 329 363 349 328 329 320 326 330 340 304 310 326 312 343 328 350 341 379 325 358 347 331 384 374 301 355 348 338 370 344 342 331 346 327 334 335 368 340 348 383 378 344 370 379 376 376 355 371 372 373 379 351 369 371 356 378 385 386 397 393 415 414 399 405 410 366 383 415 395 410 420 389 420 430 477 472 487 466 470 488 524 568 517 523 605 566 594 604 645 673 731 684 751 728 773 792 833 874 930 926 941 925 1020 993 990 988 955 899 838 845 844 793 780 793 730 736 738 745 787 747 734 707 645 697 666 629 600 588 528 544 570 522 499 435 465 485 462 481 456 451 447 461 438 442 443 456 447 426 421 437 438 433 387 464 420 405 437 431 412 426 491 424 428 417 416 424 360 441 424 461 405 422 458 443 442 487 451 471 461 497 457 478 473 463 482 492 493 482 452 505 570 531 530 552 567 541 573 557 575 599 622 625 637 656 602 628 636 687 698 729 719 723 809 770 874 855 805 891 978 963 1000 1076 1129 1196 1255 1240 1347 1468 1531 1556 1664 1819 1829 2077 2162 2215 2396 2566 2672 2845 2886 3120 3382 3326 3490 3569 3647 3682 3535 3413 3432 3231 3137 3179 2989 2836 2662 2594 2633 2391 2395 2558 2460 2386 2324 2342 2232 2200 2038 1956 1796 1665 1539 1531 1360 1247 1220 1123 1059 994 1004 993 989 891 863 847 786 864 832 838 741 787 787 765 760 753 707 760 801 785 690 722 760 739 827 799 853 893 850 912 925 942 921 967 1032 1030 1024 1085 1173 1169 1217 1221 1257 1259 1251 1260 1265 1209 1141 1202 1207 1195 1325 1360 1324 1354 1436 1489 1587 1549 1620 1718 1750 1819 1868 1878 2007 1902 2013 1951 2018 2007 2135 2012 1995 1932 1842 1728 1641 1573 1581 1493 1453 1423 1438 1444 1414 1321 1336 1369 1347 1281 1232 1202 1146 1057 977 945 885 826 798 759 708 744 642 625 592 602 545 596 528 511 522 553 531 517 520 493 476 439 469 452 429 424 447 454 433 391 406 477 464 461 370 439 459 434 421 424 405 399 426 439 407 411 385 417 403 416 410 432 407 382 383 417 435 418 399 412 446 441 479 486 489 488 502 533 538 578 575 580 668 632 738 707 742 766 804 830 856 893 972 939 880 995 886 901 820 747 762 747 703 692 673 697 620 638 638 669 626 642 633 624 602 591 524 528 524 518 467 398 429 400 402 380 387 352 373 350 362 298 357 332 306 304 310 291 302 292 282 331 318 321 316 316 328 307 284 334 314 300 302 324 283 248 322 296 323 327 294 307 288 296 310 314 292 288 293 306 289 314 305 286 323 295 285 285 277 261 279 283 308 238 311 299 307 282 262 284 299 280 284 297 298 278 280 284 283 294 280 308 271 277 267 290 278 318 280 281 264 272 270 266 301 285 308 284 274 295 298 272 273 256 271 276 290 272 277 267 260 275 294 269 280 247 309 281 264 251 277 280 277 294 287 258 279 273 329 293 276 281 290 270 299 296 299 268 271 288 293 292 272 303 299 313 278 321 324 324 292 287 306 297 320 319 293 336 309 317 328 382 335 334 351 376 350 389 379 389 440 408 429 441 442 431 465 487 491 517 516 568 568 590 558 558 561 568 495 504 501 474 435 499 418 415 452 420 429 480 425 440 426 446 436 431 414 424 392 358 333 353 340 316 325 329 316 344 325 299 318 307 283 318 269 288 309 280 286 279 275 245 313 290 267 306 265 286 260 265 272 284 289 292 305 299 305 287 275 297 261 292 283 269 298 279 287 283 280 291 263 272 280 283 284 285 272 302 273 249 257 226 273 259 256 283 246 260 276 260 278 291 283 267 299 265 283 292 277 265 258 249 239 269 265 297 279 290 279 273 282 278 298 307 295 312 261 293 298 298 295 305 299 276 284 330 302 307 344 339 340 314 314 337 335 324 323 335 312 293 314 312 318 309 280 321 372 307 331 279 327 316 310 307 288 296 286 278 292 306 281 319 282 311 284 266 274 295 302 302 321 273 308 311 321 319 280 388 294 325 328 321 349 306 308 324 321 324 342 352 364 372 359 380 374 377 340 377 398 473 418 474 518 500 514 526 568 614 635 682 717 760 845 827 895 932 1041 1041 1125 1088 1152 1113 1181 1247 1152 1112 1033 1000 900 887 842 863 799 762 796 751 772 784 801 786 731 811 810 741 732 675 580 636 572 583 489 507 475 440 396 430 371 338 388 343 350 341 354 314 334 306 307 315 324 350 306 320 324 294 315 321 300 294 292 360 329 294 293 316 319 326 335 311 314 312 347 363 318 327 328 354 345 342 345 367 410 409 368 447 457 466 436 476 461 541 502 526 508 534 529 531 507 477 483 476 478 423 444 399 416 407 410 374 371 410 460 441 404 398 417 425 402 419 407 365 351 316 339 329 348 329 322 332 273 300 345 304 348 335 323 333 352 330 322 345 365 364 359 349 336 354 354 365 367 377 375 363 361 379 415 412 443 439 424 461 477 461 447 517 505 552 587 571 577 602 650 623 667 665 724 669 777 758 769 715 710 712 665 717 647 608 610 565 551 571 589 572 618 540 516 548 514 596 551 506 520 538 500 502 484 435 489 417 369 351 401 353 380 333 405 363 324 340 303 320 287 347 303 298 312 308 296 315 312 284 278 322 299 292 291 313 273 289 294 268 316 287 281 279 291 286 273 284 277 283 245 273 241 287 261 320 266 273 268 241 264 262 293 265 257 276 270 222 269 263 258 230 278 257 257 233 249 264 240 261 273 263 290 243 278 267 265 302 276 240 230 260 235 239 258 269 266 263 247 268 274 222 229 232 245 214 277 262 251 262 223 257 246 243 229 257 260 290 244 229 266 218 256 245 257 204 256 230 259 249 222 246 243 271 219 213 234 243 227 236 242 268 251 238 232 288 256 264 222 239 216 249 239 219 251 273 251 260 257 238 225 258 269 247 251 301 267 222 210 225 238 285 265 240 245 259 257 276 230 243 241 236 232 249 289 234 232 233 229 239 218 245 242 216 261 219 251 223 264 262 256 263 243 260 242 258 263 271 247 246 263 263 232 245 230 242 262 238 246 233 234 244 232 229 240 259 244 276 244 232 249 239 229 240 241 282 274 208 245 205 243 242 256 267 214 262 239 244 237 258 275 236 236 222 218 247 223 196 224 275 246 240 269 228 241 221 260 244 277 259 218 241 256 261 261 239 276 224 256 256 242 300 236 261 271 248 244 239 221 260 258 247 256 244 234 212 268 256 262 239 235 233 266 247 268 262 297 283 297 274 301 260 278 285 289 238 289 256 288 262 316 297 291 319 292 275 274 297 288 279 286 296 302 317 299 317 264 324 284 278 308 297 266 307 266 258 288 294 278 295 301 280 306 314 280 291 300 315 309 310 306 331 310 317 296 334 319 332 340 344 343 396 369 387 373 420 408 444 451 446 475 462 444 505 477 548 481 468 474 442 449 392 436 417 388 435 417 409 366 394 405 388 402 387 397 362 391 366 393 394 369 356 357 351 377 329 355 313 314 321 346 309 284 289 307 285 259 300 318 291 281 289 266 290 363 317 284 320 298 314 296 309 288 299 277 305 307 299 329 331 340 352 344 313 310 366 340 340 339 331 327 348 272 321 332 315 310 309 336 316 291 323 315 362 336 314 345 321 351 343 342 370 373 360 370 393 459 427 424 443 437 461 486 542 544 573 623 608 684 640 685 647 696 708 720 692 645 603 605 619 543 503 507 480 497 488 472 474 549 494 537 485 463 548 511 548 548 505 539 522 458 471 478 460 435 468 449 449 451 453 421 423 499 466 464 495 493 529 453 469 468 445 425 399 411 390 394 365 356 370 340 353 349 345 349 344 387 356 358 393 355 331 365 358 332 346 310 327 293 309 294 286 272 285 276 234 244 302 277 289 247 275 267 285 265 237 261 241 256 231 271 281 258 235 261 236 273 261 209 236 246 235 242 218 248 236 249 249 275 283 218 220 246 250 243 240 256 257 218 246 240 243 217 239 240 236 225 244 220 216 235 233 232 247 195 222 284 226 226 205 228 222 233 238 256 235 228 220 261 237 230 249 227 277 224 225 247 258 216 271 244 222 217 235 246 234 240 238 219 262 213 239 243 232 266 224 237 266 244 224 238 217 238 263 256 244 210 200 264 272 241 235 242 200 238 236 219 229 220 235 259 220 279 193 258 220 234 262 232 247 235 232 227 239 258 239 249 217 257 220 236 231 264 235 227 264 239 264 243 250 215 205 216 237 230 257 206 240 232 262 265 230 202 250 241 263 271 233 229 234 260 234 234 219 238 243 225 269 250 229 223 249 225 244 225 228 182 236 226 228 207 240 239 226 224 237 265 250 223 214 261 260 241 232 213 258 234 243 232 229 235 245 217 240 207 229 209 233 216 234 225 242 209 222 239 236 234 236 244 239 210 246 202 231 232 238 235 235 227 219 227 267 236 289 245 216 230 211 277 245 224 223 220 220 228 239 226 230 222 235 236 244 221 247 267 228 242 204 235 219 242 219 202 269 213 244 239 199 224 227 244 241 231 246 241 226 245 236 249 226 233 223 221 226 225 221 214 215 213 262 240 226 243 236 221 215 224 222 234 264 258 210 259 241 235 229 228 261 262 225 220 214 243 232 215 265 241 205 231 209 248 265 225 234 226 227 212 231 234 214 228 226 235 200 212 257 221 246 190 234 244 232 244 251 257 248 244 233 221 236 227 210 214 221 246 226 270 248 244 215 246 225 230 217 244 231 268 231 223 213 277 222 233 224 245 240 227 221 245 213 261 246 224 239 242 265 266 222 234 262 240 265 231 241 229 256 261 247 286 276 238 217 230 227 212 217 240 234 223 270 222 209 225 260 249 265 273 259 242 258 233 265 286 236 232 233 237 231 219 246 247 258 245 263 245 260 275 247 217 258 275 280 219 282 258 249 280 232 288 241 266 269 290 274 257 299 257 236 249 265 256 289 316 271 307 267 276 281 265 263 261 250 284 289 265 282 304 299 287 264 306 318 330 307 318 302 297 384 313 325 322 293 323 352 345 320 366 348 371 429 361 395 416 397 376 370 407 402 439 406 411 426 480 477 453 475 466 501 531 531 554 564 593 668 679 701 704 733 759 867 881 895 961 1014 1023 1106 1145 1142 1120 1268 1168 1217 1194 1221 1141 1095 1126 1087 976 970 931 888 918 890 837 821 797 794 812 820 870 830 859 840 831 849 861 802 817 795 764 715 701 661 639 630 602 554 550 508 512 516 470 419 416 429 450 457 410 426 398 426 374 395 351 356 344 350 314 350 358 397 346 326 319 300 308 309 320 306 332 315 307 297 315 314 315 310 300 284 292 309 290 308 274 286 268 276 291 264 271 269 300 249 272 283 301 286 282 276 315 283 292 308 300 291 269 266 281 300 264 265 273 250 273 232 266 268 250 268 278 242 245 265 234 236 264 238 272 226 266 247 287 268 250 261 239 264 263 239 230 266 299 278 238 291 274 265 264 232 277 237 258 265 263 234 251 256 273 245 234 247 267 260 224 279 267 256 241 262 273 277 277 233 281 240 262 240 259 233 271 264 227 243 276 233 262 287 262 274 249 259 249 259 279 257 244 256 263 284 247 266 238 229 220 287 264 259 247 259 265 242 267 246 258 230 223 238 236 260 285 298 246 262 277 266 270 237 241 261 276 246 265 295 291 259 275 259 272 270 282 267 245 267 297 282 285 294 267 301 279 276 310 285 323 287 305 324 304 296 290 282 296 304 332 323 311 342 318 301 356 356 357 345 386 388 373 423 433 437 400 459 460 470 457 504 500 540 510 516 599 565 591 612 575 593 563 573 560 542 492 473 485 521 500 452 461 437 482 460 428 447 429 468 443 444 489 437 439 455 466 445 512 499 455 445 491 443 428 417 377 398 421 401 402 405 405 408 351 368 370 329 357 368 317 370 356 330 304 333 341 317 335 331 299 295 323 326 312 311 344 308 323 341 328 302 328 315 318 320 290 285 294 320 280 300 298 261 309 288 303 312 321 291 288 294 298 281 311 288 283 272 334 272 301 310 280 305 318 311 316 309 309 314 322 329 349 353 345 344 398 397 410 359 428 399 418 437 437 468 485 489 520 451 530 467 461 488 498 478 434 456 408 396 413 414 397 357 367 391 398 398 397 380 413 448 414 413 448 405 406 446 407 436 460 476 421 405 391 395 408 415 387 374 388 377 373 385 377 397 378 381 395 395 368 401 359 402 433 403 432 420 391 430 448 439 456 438 471 477 496 482 517 485 521 542 537 587 600 639 681 668 750 732 727 831 841 897 903 931 1015 1024 1032 1123 1090 1132 1201 1199 1266 1246 1261 1248 1417 1336 1333 1400 1310 1327 1228 1186 1210 1121 1083 1026 1075 1025 941 990 873 1002 956 928 999 891 898 850 884 881 910 939 891 923 891 900 893 862 846 833 757 751 707 651 600 603 626 588 508 525 516 478 484 458 459 460 434 466 441 433 421 364 385 408 367 361 390 366 413 358 402 351 362 338 331 361 343 345 310 357 315 303 346 327 324 346 304 308 306 288 301 361 298 310 304 332 335 311 298 324 281 296 333 292 315 317 312 300 268 311 274 296 282 298 279 291 313 320 297 246 245 287 288 247 256 269 269 259 288 286 251 310 261 288 279 269 270 265 299 265 267 282 284 288 299 266 267 274 297 245 283 301 292 277 276 246 261 270 273 233 274 239 247 274 235 285 239 281 265 272 277 239 266 282 265 277 247 288 256 277 247 242 271 286 297 295 269 293 293 248 268 287 264 290 263 265 251 285 264 308 257 280 267 276 259 300 233 334 303 249 270 265 288 261 265 265 271 267 241 243 232 302 270 278 300 268 298 265 279 264 286 307 283 300 298 277 292 275 295 280 291 279 324 320 319 306 321 307 314 320 312 327 333 295 326 355 324 341 330 340 336 342 318 332 357 320 349 374 411 395 356 375 425 417 429 416 472 455 489 468 463 529 486 517 509 503 523 515 537 543 531 559 557 562 575 621 561 588 654 644 634 719 688 743 693 764 812 795 860 888 797 832 873 775 797 855 726 737 737 706 625 630 635 595 542 588 588 575 567 502 559 568 534 560 539 589 572 602 568 596 558 563 630 578 601 551 528 539 459 442 467 448 419 415 419 383 391 346 343 342 381 370 361 337 322 345 341 325 334 327 322 286 325 288 326 332 326 289 281 314 316 316 311 315 333 310 297 310 322 299 311 275 271 289 294 311 331 292 331 279 343 326 309 331 304 307 330 321 312 320 292 356 319 322 356 330 342 356 335 388 377 369 406 392 391 371 376 346 348 335 348 327 348</counts>
			</dataPoints>
		</scan>
	</xrdMeasurement>
</xrdMeasurements>