File: dataset/precursor_mixture/TiO2_0p4009-ZnO_0p6010--2min.xrdml
<?xml version="1.0"?>
<xrdMeasurements xmlns="http://www.xrdml.com/XRDMeasurement/2.3" xmlns:xsi="http://www.w3.org/2001/XMLSchema-instance" xsi:schemaLocation="http://www.xrdml.com/XRDMeasurement/2.3 http://www.xrdml.com/XRDMeasurement/2.3/XRDMeasurement.xsd" status="Completed" recordIdentifier="{F8AFCEB4-1E7C-4A20-9849-EE7E7EFD7C78}">
	<comment>
		<entry/>
	</comment>
	<sample type="To be analyzed">
		<id>TiO2_0p4009-ZnO_0p6010--2min</id>
		<name></name>
		<preparedBy></preparedBy>
	</sample>
	<xrdMeasurement measurementType="Scan" status="Completed" sampleMode="Reflection">
		<usedWavelength intended="K-Alpha 1">
			<kAlpha1 unit="Angstrom">1.5405980</kAlpha1>
			<kAlpha2 unit="Angstrom">1.5444260</kAlpha2>
			<kBeta unit="Angstrom">1.3922500</kBeta>
			<ratioKAlpha2KAlpha1>0.5000</ratioKAlpha2KAlpha1>
		</usedWavelength>
		<incidentBeamPath>
			<radius unit="mm">145.00</radius>
			<xRayTube id="1010048" name="Empyrean Cu LFF HR (9430 033 7310x)">
				<tension unit="kV">40.0</tension>
				<current unit="mA">15.0</current>
				<anodeMaterial>Cu</anodeMaterial>
				<focus type="Line">
					<length unit="mm">12.0</length>
					<width unit="mm">0.4</width>
					<takeOffAngle unit="deg">6.0</takeOffAngle>
				</focus>
			</xRayTube>
			<sollerSlit id="21010002" name="Soller slits 0.04 rad.">
				<opening unit="rad">0.0400</opening>
			</sollerSlit>
			<mask id="22031000" name="Fixed mask 13 mm">
				<width unit="mm">9.00</width>
			</mask>
			<divergenceSlit id="22120001" name="Divergence slit 1°" xsi:type="fixedDivergenceSlitType">
				<distanceToSample unit="mm">50.00</distanceToSample>
				<height unit="mm">1.52</height>
			</divergenceSlit>
		</incidentBeamPath>
		<sampleMovement xsi:type="spinningSampleMovementType">
			<spinnerRevolutionTime unit="seconds">1.0</spinnerRevolutionTime>
		</sampleMovement>
		<diffractedBeamPath>
			<radius unit="mm">145.00</radius>
			<antiScatterSlit id="22090040" name="AS slit 9 mm (PIXcel)" xsi:type="fixedAntiScatterSlitType">
				<height unit="mm">9.00</height>
			</antiScatterSlit>
			<sollerSlit id="21020003" name="Large Soller slits 0.04 rad.">
				<opening unit="rad">0.0400</opening>
			</sollerSlit>
			<filter id="20030001" name="Large beta-filter Nickel">
				<material>Ni</material>
				<thickness unit="mm">0.020</thickness>
			</filter>
			<detector id="7010019" name="PIXcel1D-Medipix3 detector" xsi:type="rtmsDetectorType">
				<phd unit="keV">
					<lowerLevel>4.02</lowerLevel>
					<upperLevel>11.27</upperLevel>
				</phd>
				<mode>Scanning</mode>
				<activeLength unit="deg">5.542</activeLength>
			</detector>
		</diffractedBeamPath>
		<scan appendNumber="0" mode="Continuous" scanAxis="Gonio" status="Completed">
			<header>
				<startTimeStamp>2024-11-14T13:02:13-08:00</startTimeStamp>
				<endTimeStamp>2024-11-14T13:04:18-08:00</endTimeStamp>
				<author>
					<name>AutomatedUser</name>
				</author>
				<source>
					<applicationSoftware version="1.7b (136)">PANalytical Aeris Instrument Suite</applicationSoftware>
					<instrumentControlSoftware version="3.2.00000000 20240306">AERIS</instrumentControlSoftware>
					<instrumentID>950485</instrumentID>
				</source>
			</header>
			<dataPoints>
				<positions axis="2Theta" unit="deg">
					<startPosition>10.02173288</startPosition>
					<endPosition>99.99585608</endPosition>
				</positions>
				<positions axis="Omega" unit="deg">
					<startPosition>5.01086644</startPosition>
					<endPosition>49.99792804</endPosition>
				</positions>
				<commonCountingTime unit="seconds">10.965</commonCountingTime>
				<counts unit="counts">1946 1927 1893 1900 1926 1850 1866 1824 1935 1826 1887 1770 1796 1767 1744 1696 1754 1738 1623 1656 1642 1691 1672 1609 1588 1739 1622 1599 1589 1624 1597 1579 1631 1512 1575 1533 1537 1571 1490 1478 1585 1536 1572 1512 1457 1438 1467 1417 1474 1364 1394 1432 1327 1400 1394 1334 1382 1425 1383 1389 1316 1301 1302 1364 1332 1304 1354 1324 1350 1344 1309 1325 1268 1278 1274 1258 1267 1303 1210 1207 1236 1224 1235 1229 1144 1259 1222 1150 1250 1250 1141 1149 1228 1158 1220 1145 1172 1172 1113 1097 1165 1182 1183 1097 1107 1026 1148 1149 1098 1096 1091 1121 1070 1185 1163 1124 1026 1068 1051 1073 999 1029 1080 1079 1061 1049 1078 1093 1050 1019 1032 1048 1019 961 941 1055 1059 981 951 1035 1005 1023 963 1043 974 1035 976 1020 1068 949 1101 1023 977 954 991 983 929 1035 974 935 953 975 947 998 976 936 1003 1016 910 921 885 919 926 904 936 903 906 932 882 950 929 948 923 853 860 915 828 900 976 882 871 872 875 830 826 841 882 826 857 844 828 813 884 812 837 858 839 790 787 894 840 827 813 844 796 796 862 803 850 803 874 806 709 812 826 798 761 728 768 725 768 775 799 771 758 757 744 775 773 757 751 739 818 767 732 782 732 762 715 752 713 721 778 732 770 763 733 699 760 707 722 767 717 728 725 755 676 719 694 694 694 692 686 678 733 687 682 717 677 701 652 666 731 670 678 725 681 650 702 682 694 672 678 686 633 682 670 680 722 618 672 643 662 647 658 633 676 678 691 603 677 594 664 663 586 644 657 656 639 620 592 619 605 649 634 663 667 659 629 628 618 643 635 669 661 701 679 707 660 688 726 768 819 935 992 1105 1303 1706 2245 3145 4202 5221 6242 6788 7302 6148 4239 2580 1671 1288 1005 920 807 824 720 658 630 671 646 667 636 635 656 643 659 598 663 663 647 573 667 611 524 551 600 623 600 609 563 601 550 551 613 571 574 535 564 554 574 632 586 619 601 590 584 559 539 638 570 528 509 532 541 613 501 599 515 463 525 607 546 585 549 506 490 552 560 571 569 510 545 506 546 559 536 536 552 573 518 538 556 535 530 515 534 489 482 481 478 512 503 506 548 464 515 515 539 554 519 477 485 574 518 550 521 468 554 505 551 506 504 540 529 556 492 511 581 584 589 559 605 593 625 627 569 649 685 651 694 726 790 835 909 1072 1154 1477 1944 2693 3458 4311 5435 6216 7011 6904 5862 4363 3039 2046 1509 1240 1015 900 806 741 679 715 654 605 604 626 608 600 599 543 587 566 549 475 533 550 497 546 492 522 507 542 532 508 528 558 550 556 537 526 537 545 563 572 587 625 583 673 699 710 808 858 1081 1397 1869 2568 3332 4165 4937 5651 5638 4623 3517 2257 1446 1139 1007 886 744 734 674 642 594 617 636 631 630 657 671 605 586 661 655 669 706 787 782 813 912 961 1074 1239 1475 1731 2057 2859 3877 5221 7049 8818 10378 11849 11932 10123 7954 5762 3894 2690 2071 1683 1375 1177 1058 1061 1040 1026 1058 1050 1110 1003 886 740 630 670 638 621 577 613 628 617 689 782 912 1201 1371 1579 1922 2012 1971 1628 1180 941 699 602 556 515 475 505 499 558 587 632 729 839 904 874 838 741 650 491 437 413 432 451 414 350 419 422 390 379 388 341 403 364 379 367 375 376 375 402 354 380 405 362 361 355 367 345 374 338 334 358 382 321 325 342 338 346 343 323 358 352 308 323 316 299 350 354 342 344 361 324 353 343 323 341 357 336 321 334 343 326 352 346 370 328 320 361 317 351 347 343 389 341 333 305 309 339 355 314 333 337 305 319 346 349 346 339 329 324 357 344 358 315 323 305 300 342 315 352 337 301 324 326 294 297 310 282 331 327 323 314 304 291 299 307 276 325 330 261 336 284 304 318 311 285 288 291 291 277 297 306 307 288 308 298 306 276 302 295 278 280 287 275 271 295 309 303 270 320 288 306 319 279 322 284 264 284 292 276 296 326 331 305 286 287 304 277 293 328 291 290 286 316 320 315 364 323 308 333 317 328 359 360 360 370 351 415 425 440 443 503 587 662 794 894 1182 1426 1836 2225 2645 2936 2855 2489 2103 1726 1514 1388 1470 1679 2054 2342 2848 2791 2342 1961 1539 1123 757 555 505 433 367 369 365 340 325 319 307 326 314 306 311 287 296 299 289 291 283 299 287 282 319 299 307 309 281 275 320 273 318 267 280 280 293 265 271 259 267 270 273 273 282 270 281 277 276 282 288 274 289 245 282 269 259 273 293 251 276 276 254 260 263 269 287 237 278 267 277 266 278 271 263 267 259 296 313 261 239 280 261 255 249 288 292 264 292 278 271 277 278 281 275 275 282 265 275 247 304 270 240 273 285 262 303 312 294 274 281 273 284 284 292 292 316 345 338 342 361 376 402 514 629 821 1047 1309 1486 1760 1714 1366 1213 1058 791 583 544 407 409 459 381 376 375 357 379 340 370 409 396 491 560 692 845 1107 1275 1649 1860 1700 1357 1235 1015 845 604 497 413 421 365 396 387 354 350 391 368 412 385 427 434 442 504 540 582 639 684 796 946 1075 1448 1852 2381 3001 3745 4338 4143 3568 3111 2706 2181 1620 1210 895 773 602 595 566 450 440 413 382 390 367 342 344 313 321 323 335 296 300 302 296 312 280 278 280 312 285 309 292 298 302 285 315 282 292 292 277 285 256 238 269 268 276 265 262 264 287 259 277 283 240 280 275 248 240 282 279 281 277 253 258 284 256 262 240 239 241 266 269 280 276 241 270 277 261 250 292 237 280 282 230 272 264 285 285 320 291 278 296 257 283 296 293 297 305 306 300 288 300 330 291 278 308 292 329 294 297 290 297 299 365 345 348 396 400 415 492 536 584 672 632 621 587 645 663 684 726 840 1084 1218 1586 2097 2680 3148 3383 3811 4111 4110 3413 2800 2646 2206 1642 1166 946 767 692 612 544 499 414 420 398 367 360 322 344 365 325 306 312 325 303 280 299 332 305 263 276 301 308 258 271 270 275 299 272 259 282 272 259 275 281 266 292 262 260 270 279 264 269 273 264 281 284 277 252 288 297 297 297 271 301 266 329 295 329 354 317 346 352 366 477 489 562 637 751 830 788 746 636 631 604 583 433 403 381 408 389 347 358 353 347 339 338 372 372 383 372 432 487 451 490 541 595 682 772 930 1023 1353 1691 2084 2528 2950 2890 2651 2267 2058 1868 1630 1193 944 868 721 679 623 619 615 688 752 809 967 1043 1062 1029 1113 1257 1400 1532 1758 1729 1568 1302 1131 1138 964 771 668 561 459 403 410 386 377 364 346 358 340 360 339 355 330 390 468 508 629 704 785 755 608 561 488 538 446 423 303 268 290 219 274 256 270 266 264 251 247 262 275 223 251 239 249 243 228 248 218 256 247 247 238 226 243 208 196 203 263 237 225 222 260 252 254 258 273 265 319 332 397 408 450 502 413 377 386 343 354 293 290 275 229 251 224 252 240 256 230 228 220 242 222 257 231 222 264 243 224 242 206 234 234 260 230 238 291 285 243 262 281 244 249 237 246 248 224 259 263 263 245 277 307 319 351 424 536 640 811 911 956 829 710 703 611 635 529 380 334 279 305 275 248 274 279 259 281 257 313 344 364 443 438 439 353 342 357 328 372 304 272 304 267 266 282 278 284 315 363 363 424 484 602 644 644 579 495 475 466 444 418 370 316 270 278 275 233 242 235 208 249 218 252 236 225 200 232 224 227 216 228 231 191 217 217 223 219 202 235 216 209 227 174 205 180 234 205 216 232 222 196 191 230 207 190 211 218 198 199 201 219 204 189 189 220 233 230 231 201 204 177 205 231 194 176 216 212 222 205 210 218 212 218 239 222 217 220 215 237 273 243 252 235 260 270 222 238 263 249 263 278 328 318 321 362 432 394 362 365 335 331 383 279 276 247 250 247 257 271 241 246 250 294 278 259 265 288 263 269 285 359 365 424 513 604 587 506 408 393 403 449 440 416 370 335 402 381 383 327 297 326 296 315 272 252 229 230 190 221 220 215 229 222 186 209 217 208 248 169 207 211 193 219 190 220 198 183 206 214 171 196 216 221 188 187 191 176 200 184 195 212 205 183 183 193 185 204 216 198 200 195 191 218 202 211 229 235 193 187 188 206 178 192 200 167 195 213 226 205 215 212 187 190 199 212 206 222 204 198 194 193 200 210 226 198 187 192 235 201 205 197 222 201 210 209 208 209 221 197 214 219 204 198 203 192 185 193 195 203 186 213 204 208 229 213 195 189 214 202 237 228 226 223 213 229 216 223 243 228 266 260 267 276 273 290 335 374 346 415 458 533 665 778 913 965 953 879 752 670 692 714 742 652 544 437 397 340 338 292 271 294 286 232 267 248 251 247 208 247 228 214 230 225 187 233 208 232 223 215 223 224 198 201 243 212 227 214 214 218 195 217 214 220 206 241 186 242 213 215 224 203 216 226 227 252 236 277 258 268 234 259 256 274 296 383 373 505 488 482 399 395 421 387 378 418 399 371 346 309 314 291 252 316 249 266 302 287 298 240 288 244 265 251 261 301 283 266 308 334 406 389 418 341 349 314 312 338 342 349 344 332 346 302 289 317 352 357 421 426 538 664 779 885 962 1086 1168 1174 998 849 817 761 798 733 766 594 545 471 347 357 350 335 316 275 255 289 281 253 277 261 253 258 242 237 261 245 234 235 255 209 269 228 250 210 259 221 224 219 219 209 231 228 207 244 243 232 221 220 243 234 216 238 244 236 234 228 260 247 263 260 277 293 288 322 369 407 423 409 553 508 594 640 704 712 680 572 520 451 465 491 509 470 413 321 321 300 295 270 270 259 265 270 248 304 247 254 289 246 282 299 305 296 288 236</counts>
			</dataPoints>
		</scan>
	</xrdMeasurement>
</xrdMeasurements>