File: dataset/precursor_mixture/TiO2_GeO2_LiCoO2_Bi2O3-alpha.2-min.xrdml
<?xml version="1.0"?>
<xrdMeasurements xmlns="http://www.xrdml.com/XRDMeasurement/2.2" xmlns:xsi="http://www.w3.org/2001/XMLSchema-instance" xsi:schemaLocation="http://www.xrdml.com/XRDMeasurement/2.2 http://www.xrdml.com/XRDMeasurement/2.2/XRDMeasurement.xsd" status="Completed" recordIdentifier="{7BDAC9B5-81A4-40D4-BD1D-D620E2D87156}">
	<comment>
		<entry/>
	</comment>
	<sample type="To be analyzed">
		<id>dara-30-1</id>
		<name></name>
		<preparedBy></preparedBy>
	</sample>
	<xrdMeasurement measurementType="Scan" status="Completed" sampleMode="Reflection">
		<usedWavelength intended="K-Alpha 1">
			<kAlpha1 unit="Angstrom">1.5405980</kAlpha1>
			<kAlpha2 unit="Angstrom">1.5444260</kAlpha2>
			<kBeta unit="Angstrom">1.3922500</kBeta>
			<ratioKAlpha2KAlpha1>0.5000</ratioKAlpha2KAlpha1>
		</usedWavelength>
		<incidentBeamPath>
			<radius unit="mm">145.00</radius>
			<xRayTube id="1010048" name="Empyrean Cu LFF HR (9430 033 7310x) DK437873">
				<tension unit="kV">40.0</tension>
				<current unit="mA">15.0</current>
				<anodeMaterial>Cu</anodeMaterial>
				<focus type="Line">
					<length unit="mm">12.0</length>
					<width unit="mm">0.4</width>
					<takeOffAngle unit="deg">6.0</takeOffAngle>
				</focus>
			</xRayTube>
			<filter id="20010004" name="Beta-filter Nickel">
				<material>Ni</material>
				<thickness unit="mm">0.020</thickness>
			</filter>
			<sollerSlit id="21010002" name="Soller slits 0.04 rad.">
				<opening unit="rad">0.0400</opening>
			</sollerSlit>
			<mask id="22031000" name="Fixed mask 13 mm">
				<width unit="mm">9.00</width>
			</mask>
			<divergenceSlit id="22120001" name="Divergence slit 1°" xsi:type="fixedDivergenceSlitType">
				<distanceToSample unit="mm">50.00</distanceToSample>
				<height unit="mm">1.52</height>
			</divergenceSlit>
		</incidentBeamPath>
		<beamKnife id="29030100" name="Beam knife low"/>
		<sampleMovement xsi:type="spinningSampleMovementType">
			<spinnerRevolutionTime unit="seconds">1.0</spinnerRevolutionTime>
		</sampleMovement>
		<diffractedBeamPath>
			<radius unit="mm">145.00</radius>
			<antiScatterSlit id="22090040" name="AS slit 9 mm" xsi:type="fixedAntiScatterSlitType">
				<height unit="mm">9.00</height>
			</antiScatterSlit>
			<sollerSlit id="21020003" name="Large Soller slits 0.04 rad.">
				<opening unit="rad">0.0400</opening>
			</sollerSlit>
			<filter id="20030001" name="Large beta-filter Nickel">
				<material>Ni</material>
				<thickness unit="mm">0.020</thickness>
			</filter>
			<detector id="7010019" name="PIXcel1D-Medipix3 detector" xsi:type="rtmsDetectorType">
				<phd unit="keV">
					<lowerLevel>4.0</lowerLevel>
					<upperLevel>11.3</upperLevel>
				</phd>
				<mode>Scanning</mode>
				<activeLength unit="deg">1.021</activeLength>
			</detector>
		</diffractedBeamPath>
		<scan appendNumber="0" mode="Continuous" scanAxis="Gonio" status="Completed">
			<header>
				<startTimeStamp>2024-03-25T12:02:08-07:00</startTimeStamp>
				<endTimeStamp>2024-03-25T12:04:30-07:00</endTimeStamp>
				<author>
					<name>AutomatedUser</name>
				</author>
				<source>
					<applicationSoftware version="1.6 (94)">PANalytical Aeris Instrument Suite</applicationSoftware>
					<instrumentControlSoftware version="3.0.0 20211014">AERIS</instrumentControlSoftware>
					<instrumentID>2879380</instrumentID>
				</source>
			</header>
			<dataPoints>
				<positions axis="2Theta" unit="deg">
					<startPosition>10.02173288</startPosition>
					<endPosition>139.98435528</endPosition>
				</positions>
				<positions axis="Omega" unit="deg">
					<startPosition>5.01086644</startPosition>
					<endPosition>69.99217764</endPosition>
				</positions>
				<commonCountingTime unit="seconds">1.551</commonCountingTime>
				<counts unit="counts">579 553 516 540 538 505 564 561 504 552 527 517 496 508 549 507 555 525 535 485 508 531 522 525 574 526 446 489 527 504 479 498 557 539 562 505 503 507 504 486 515 499 515 508 497 493 510 476 512 445 452 493 503 442 462 480 482 456 451 483 490 473 396 450 477 451 438 462 451 487 507 457 433 495 444 454 465 453 469 432 452 514 452 434 459 479 419 467 470 443 435 468 459 452 420 460 488 453 413 410 451 428 425 414 470 451 458 466 446 461 406 416 433 420 441 433 461 469 445 423 432 414 404 431 421 437 426 427 415 454 400 469 428 443 428 412 447 405 401 429 439 424 414 421 413 374 409 437 433 391 424 440 445 460 428 420 439 488 462 481 573 426 413 441 420 428 452 394 424 438 390 410 428 445 424 481 403 411 453 418 463 413 414 437 443 444 477 539 569 550 613 642 645 721 738 841 1064 1405 2200 4365 12007 29625 20971 6632 1132 873 776 686 663 677 589 562 477 490 476 497 460 545 535 541 507 532 549 518 505 562 496 456 503 573 486 573 514 560 573 563 591 651 602 610 515 519 546 518 537 483 493 503 460 517 500 438 460 502 503 493 471 430 471 480 520 474 507 510 597 584 481 503 484 493 467 429 463 467 452 435 449 398 463 470 440 417 437 470 468 465 439 481 448 430 424 452 399 433 454 399 458 455 442 410 435 426 431 439 411 408 448 369 410 414 419 437 452 448 415 404 412 434 415 400 427 450 437 433 436 450 461 582 545 530 498 419 422 407 415 449 431 440 540 463 537 685 817 1183 1678 1541 1114 744 606 530 521 557 578 661 855 899 927 1016 1304 1399 1107 755 546 502 514 440 473 454 461 427 434 421 429 425 465 451 468 499 545 766 1024 1061 790 586 470 503 475 592 726 1118 1896 3161 2288 1589 664 467 480 424 435 465 442 436 467 522 667 866 755 561 452 441 398 376 398 405 434 425 399 362 372 404 401 408 424 362 431 388 405 372 392 386 363 371 388 359 380 376 396 427 388 383 373 370 406 385 400 388 402 364 387 384 374 383 391 363 381 369 388 383 422 384 394 395 390 374 383 381 379 390 363 408 384 351 406 370 367 383 407 364 389 351 370 376 366 393 399 370 378 343 391 389 368 364 344 359 352 397 408 367 364 413 365 360 378 395 396 470 501 469 418 422 400 407 417 413 478 468 486 748 1080 963 813 808 1075 1254 890 761 466 381 375 395 385 387 349 375 360 401 391 415 456 446 430 386 426 413 360 407 355 333 387 352 372 408 431 414 401 345 343 381 387 366 372 415 476 597 595 510 500 394 405 380 411 545 489 531 465 385 389 376 439 368 380 411 465 532 506 494 460 458 433 369 404 388 382 410 336 378 392 383 395 361 419 449 381 420 400 438 548 544 472 428 399 383 384 395 405 431 562 503 528 549 586 602 586 574 548 618 584 575 539 558 622 566 590 495 490 473 485 495 761 1890 1714 1043 1243 534 432 428 420 400 370 402 398 401 414 401 431 384 446 396 347 395 401 423 468 553 519 452 417 380 388 372 365 363 359 365 371 397 535 456 431 411 357 365 366 359 351 341 343 357 352 349 372 390 369 349 350 341 361 357 349 379 386 361 375 377 367 404 399 415 470 402 434 452 383 447 477 581 540 554 555 453 381 365 388 334 367 391 379 425 502 458 403 411 373 366 334 357 388 356 385 353 377 347 377 379 370 333 371 340 374 370 353 345 406 380 411 319 349 351 345 377 364 377 365 340 330 346 346 374 368 359 376 382 403 365 402 381 382 374 382 364 393 331 368 360 350 378 438 420 416 391 541 591 685 848 579 561 548 401 390 383 367 383 325 383 338 367 402 351 384 390 359 378 434 373 396 508 532 848 696 585 604 492 385 385 367 393 384 398 328 347 403 351 364 381 360 363 323 340 360 349 382 385 401 397 406 422 411 380 394 380 375 415 383 437 479 606 650 565 590 530 519 437 465 476 553 502 451 524 654 598 569 546 486 471 397 394 384 375 356 376 381 366 353 379 428 363 433 501 523 410 407 430 383 360 354 371 407 394 401 461 448 389 420 391 381 384 359 367 367 389 364 370 381 353 363 365 350 415 371 363 382 354 346 372 373 376 329 396 358 419 386 389 360 381 343 377 431 464 543 463 396 439 451 475 511 416 460 424 429 368 383 399 466 653 582 484 494 492 413 401 359 381 351 380 361 399 431 535 540 484 515 455 409 370 453 393 415 402 395 405 406 368 372 383 360 399 420 525 515 471 457 490 394 357 418 358 377 368 376 366 380 375 354 356 373 398 442 571 638 432 445 559 457 516 562 541 493 481 435 415 380 437 469 490 424 399 454 399 399 365 381 399 435 519 413 390 412 382 359 368 365 354 387 341 366 413 382 392 374 409 396 373 362 343 341 371 350 341 394 401 326 354 356 379 372 382 362 345 326 365 376 381 367 415 404 465 436 468 443 416 418 396 378 388 376 420 461 454 394 429 445 369 380 413 387 378 394 497 544 507 519 482 539 571 592 803 980 586 464 641 524 429 383 407 395 418 435 440 398 385 417 403 376 395 373 401 340 353 360 372 349 373 383 305 358 381 358 369 346 341 350 348 358 386 377 358 401 314 383 368 357 307 359 351 373 352 402 373 416 455 442 402 450 446 371 456 441 414 399 407 421 414 418 442 374 391 421 470 414 426 470 464 439 426 442 473 500 443 367 388 454 388 386 418 382 377 365 342 351 368 391 353 369 378 381 427 452 417 394 389 384 355 369 381 382 352 353 359 326 379 366 386 345 344 344 330 369 363 378 349 400 321 379 373 348 350 343 347 344 392 364 373 390 352 401 414 470 493 455 439 423 403 516 488 444 438 372 448 429 453 424 482 447 418 420 478 465 477 411 423 414 380 384 368 399 390 417 423 426 416 437 457 451 471 455 444 409 360 418 357 377 344 372 361 346 372 363 328 382 345 364 357 373 428 396 352 383 381 366 343 360 405 365 367 378 363 373 419 419 402 367 405 446 466 402 395 383 386 415 381 386 397 358 385 351 369 385 347 338 365 411 365 414 398 421 405 460 426 391 383 443 444 400 395 406 432 399 452 399 376 385 393 387 418 386 384 380 369 342 393 399 363 341 334 352 332 321 390 366 347 391 388 424 399 390 407 405 410 394 334 355 352 326 351 350 386 390 379 388 348 359 390 380 389 421 373 386 359 405 368 349 334 335 384 323 363 404 398 336 347 376 373 360 363 364 344 385 397 363 381 401 362 368 373 380 350 393 356 391 368 410 394 383 393 354 365 402 383 391 366 419 374 377 361 404 376 360 349 360 340 352 407 406 429 435 402 415 391 413 413 364 397 338 353 326 358 350 340 352 337 373 365 337 334 371 382 389 353 379 405 375 397 371 362 398 342 368 346 362 372 358 327 342 339 354 333 359 365 383 336 424 369 393 426 395 414 364 377 402 391 417 439 443 402 353 345 386 349 353 364 357 359 354 360 362 353 380 406 373 345 376 422 372 420 395 430 415 363 380 414 384 377 365 357 354 353 422 426 388 387 413 346 370 370 398 409 368 390 414 451 402 370 398 385 426 433 363 434 429 418 411 420 425 391 367 413 412 359 391 375 395 378 354 350 357 353 396 337 345 397 388 358 344 385 374 370 370 356 393 408 389 380 363 365 356 343 363 374 381 379 361 387 395 455 511 579 1003 948 542 453 465 535 685 605 463 437 383 362 369 372 371 349 418 403 367 391 380 359 367 375 410 349 349 354 396 363 344 354 366 412 379 343 359 379 417 407 405 392 387 361 388 430 373 393 330 352 400 365 384 348 356 398 367 344 393 373 379 390 334 367 344 334 322 403 405 373 363 355 373 370 359 357 366 381 379 389 389 395 336 389 353 386 365 359 388 379 347 358 372 367 366 405 406 367 351 340 339 383 393 377 385 368 356 363 350 360 408 369 395 393 404 345 359 359 343 369 369 397 369 368 370 362 395 354 401 378 374 384 386 332 393 374 425 428 368 365 375 399 358 372 396 392 411 407 387 386 353 331 369 368 364 318 386 351 370 361 366 380 358 372 349 360 342 359 362 339 364 401 405 378 376 357 350 343 356 344 358 331 334 365 377 365 384 389 355 339 355 392 341 368 360 360 377 347 399 379 351 320 356 389 384 387 367 349 333 356 357 327 388 357 385 377 377 388 390 389 377 378 402 410 402 423 383 358 352 338 350 380 370 360 389 362 368 403 436 416 364 391 365 377 383 386 410 375 407 375 350 353 366 394 408 400 383 363 368 384 392 379 399 338 421 366 391 373 346 390 330 330 370 376 374 348 387 370 372 347 365 331 337 374 384 381 337 345 370 378 387 405 426 366 402 360 386 378 418 396 425 373 376 386 417 385 360 378 407 352 395 425 395 387 394 390 388 371 379 353 337 364 379 377 327 395 350 378 423 348 358 358 358 370 375 363 369 355 353 347 365 354 352 358 341 333 333 344 368 366 325 335 356 366 355 342 355 359 364 386 361 356 401 380 370 362 348 419 382 369 343 354 364 345 341 361 348 376 343 360 355 389 402 411 400 386 425 390 388 369 394 376 378 370 431 411 349 401 376 362 395 387 395 386 403 393 425 390 408 402 391 382 403 423 405 392 381 399 368 394 394 373 398 412 374 366 411 411 394 381 351 384 341 354 359 354 346 333 390 331 363 357 375 384 346 370 342 387 349 351 344 373 370 369 391 351 337 342 373 373 356 326 380 367 371 332 370 361 369 377 381 393 346 407 391 379 429 444 394 414 370 395 381 367 357 368 353 397 416 428 427 383 399 352 395 400 381 392 341 345 361 373 380 381 366 388 348 379 395 343 388 394 382 383 382 377 322 373 396 363 430 358 340 355 395 353 362 399 397 361 358 395 367 356 331 356 346 354 395 380 354 335 347 379 317 387 342 355 347 350 333 372 352 353 368 384 348 364 370 385 375 364 373 337 361 373 388 404 390 395 423 415 392 382 356 386 406 391 368 376 376 389 375 378 361 378 361 347 392 375 370 377 356 382 396 387 351 381 363 390 334 362 343 355 391 387 378 363 360 322 384 395 384 361 359 363 376 389 400 388 331 396 395 390 379 400 383 416 369 356 380 398 417 401 371 402 425 496 590 634 477 449 415 429 383 404 424 435 491 461 432 379 405 367 382 361 389 412 361 378 370 381 359 400 399 380 412 420 406 403 381 388 398 398 386 330 370 339 387 384 378 385 402 369 378 375 331 360 410 364 378 374 372 369 383 358 373 387 356 411 360 354 357 401 373 381 388 374 383 377 387 401 394 389 426 392 338 368 377 400 360 385 373 390 356 365 352 374 366 387 385 385 349 364 409 411 364 405 375 374 357 364 414 401 355 407 379 369 402 348 395 401 349 375 347 388 348 389 342 344 393 352 386 348 359 352 363 332 360 343 323 375 402 353 369 378 368 370 387 391 385 362 358 379 344 375 369 403 392 360 372 346 377 328 387 414 421 380 352 365 423 387 365 417 350 353 404 388 354 369 381 431 427 398 407 426 409 423 380 341 373 416 367 400 444 464 375 413 361 367 362 365 350 368 375 359 378 372 382 402 437 390 333 357 407 359 371 363 386 383 419 366 400 355 356 405 390 374 368 384 390 355 401 392 371 418 356 393 370 372 343 409 412 376 391 363 387 351 373 406 383 383 356 398 377 408 370 452 391 397 405 410 376 393 418 401 364 372 383 404 377 416 398 416 393 372 361 440 417 364 377 436 373 382 370 397 337 372 397 412 396 365 371 406 339 360 344 376 368 408 371 409 361 392 360 372 372 348 365 347 317 400 337 359 309 362 349 353 357 370 364 373 365 336 358 377 389 353 369 334 340 372 359 359 392 390 341 344 342 337 380 373 377 373 378 348 367 379 380 393 370 393 398 337 359 403 359 416 423 376 397 394 374 373 400 336 371 375 407 371 382 374 383 400 356 355 380 337 366 394 398 333 319 365 321 416 403 343 378 350 395 383 368 357 366 385 372 377 383 390 384 402 389 366 394 358 351 404 359 358 340 382 417 387 396 372 349 383 383 376 391 375 382 414 396 383 427 386 405 399 390 418 379 418 381 379 393 376 399 386 380 390 400 380 353 379 331 339 373 364 397 367 409 383 365 373 378 387 390 354 372 402 359 351 393 395 415 415 392 361 375 424 374 379 404 376 383 422 360 394 409 365 388 383 390 384 393 387 361 419 373 389 397 461 372 383 400 409 367 398 384 364 390 386 405 402 371 362 372 414 383 377 389 402 403 371 396 364 367 397 367 372 362 364 381 362 383 351 398 373 376 405 339 411 378 379 368 384 359 351 357 347 377 396 380 401 395 385 382 392 376 390 397 415 399 365 387 378 395 380 341 368 391 383 385 346 387 363 345 389 427 340 360 357 371 401 379 435 375 393 357 374 385 391 375 397 376 396 404 364 356 395 408 400 410 388 355 361 389 375 398 405 396 421 405 377 405 397 374 381 398 385 349 395 398 395 378 416 376 410 370 387 360 397 407 399 396 406 377 420 376 413 369 396 373 359 415 406 367 384 403 350 408 372 409 392 351 393 406 387 359 400 344 344 365 418 409 386 367 360 386 416 397 364 379 361 384 376 388 366 375 403 417 367 348 364 396 390 359 372 357 436 424 364 387 417 323 345 337 367 389 380 370 373 379 397 399 375 356 370 366 394 392 378 384 340 358 367 364 391 361 366 376 371 355 413 416 391 383 384 433 395 422 378 388 378 393 385 393 363 383 384 379 394 397</counts>
			</dataPoints>
		</scan>
	</xrdMeasurement>
</xrdMeasurements>