File: dataset/precursor_mixture/TiO2_ZrO2_CaCO3_LiCoO2.2-min.xrdml
<?xml version="1.0"?>
<xrdMeasurements xmlns="http://www.xrdml.com/XRDMeasurement/2.2" xmlns:xsi="http://www.w3.org/2001/XMLSchema-instance" xsi:schemaLocation="http://www.xrdml.com/XRDMeasurement/2.2 http://www.xrdml.com/XRDMeasurement/2.2/XRDMeasurement.xsd" status="Completed" recordIdentifier="{DB406323-0236-4A66-8317-C75A5D5EBBB5}">
	<comment>
		<entry/>
	</comment>
	<sample type="To be analyzed">
		<id>dara-38-1</id>
		<name></name>
		<preparedBy></preparedBy>
	</sample>
	<xrdMeasurement measurementType="Scan" status="Completed" sampleMode="Reflection">
		<usedWavelength intended="K-Alpha 1">
			<kAlpha1 unit="Angstrom">1.5405980</kAlpha1>
			<kAlpha2 unit="Angstrom">1.5444260</kAlpha2>
			<kBeta unit="Angstrom">1.3922500</kBeta>
			<ratioKAlpha2KAlpha1>0.5000</ratioKAlpha2KAlpha1>
		</usedWavelength>
		<incidentBeamPath>
			<radius unit="mm">145.00</radius>
			<xRayTube id="1010048" name="Empyrean Cu LFF HR (9430 033 7310x) DK430614">
				<tension unit="kV">40.0</tension>
				<current unit="mA">15.0</current>
				<anodeMaterial>Cu</anodeMaterial>
				<focus type="Line">
					<length unit="mm">12.0</length>
					<width unit="mm">0.4</width>
					<takeOffAngle unit="deg">6.0</takeOffAngle>
				</focus>
			</xRayTube>
			<filter id="20010004" name="Beta-filter Nickel">
				<material>Ni</material>
				<thickness unit="mm">0.020</thickness>
			</filter>
			<sollerSlit id="21010002" name="Soller slits 0.04 rad.">
				<opening unit="rad">0.0400</opening>
			</sollerSlit>
			<mask id="22031000" name="Fixed mask 13 mm">
				<width unit="mm">9.00</width>
			</mask>
			<divergenceSlit id="22120001" name="Divergence slit 1°" xsi:type="fixedDivergenceSlitType">
				<distanceToSample unit="mm">50.00</distanceToSample>
				<height unit="mm">1.52</height>
			</divergenceSlit>
		</incidentBeamPath>
		<beamKnife id="29030100" name="Beam knife low"/>
		<sampleMovement xsi:type="spinningSampleMovementType">
			<spinnerRevolutionTime unit="seconds">1.0</spinnerRevolutionTime>
		</sampleMovement>
		<diffractedBeamPath>
			<radius unit="mm">145.00</radius>
			<antiScatterSlit id="22090040" name="AS slit 9 mm" xsi:type="fixedAntiScatterSlitType">
				<height unit="mm">9.00</height>
			</antiScatterSlit>
			<sollerSlit id="21020003" name="Large Soller slits 0.04 rad.">
				<opening unit="rad">0.0400</opening>
			</sollerSlit>
			<filter id="20030001" name="Large beta-filter Nickel">
				<material>Ni</material>
				<thickness unit="mm">0.020</thickness>
			</filter>
			<detector id="7010019" name="PIXcel1D-Medipix3 detector" xsi:type="rtmsDetectorType">
				<phd unit="keV">
					<lowerLevel>4.0</lowerLevel>
					<upperLevel>11.3</upperLevel>
				</phd>
				<mode>Scanning</mode>
				<activeLength unit="deg">1.021</activeLength>
			</detector>
		</diffractedBeamPath>
		<scan appendNumber="0" mode="Continuous" scanAxis="Gonio" status="Completed">
			<header>
				<startTimeStamp>2024-02-18T12:29:07-08:00</startTimeStamp>
				<endTimeStamp>2024-02-18T12:31:28-08:00</endTimeStamp>
				<author>
					<name>AutomatedUser</name>
				</author>
				<source>
					<applicationSoftware version="1.4b (28)">PANalytical Aeris Instrument Suite</applicationSoftware>
					<instrumentControlSoftware version="2.0.0 20210224">AERIS</instrumentControlSoftware>
					<instrumentID>950485</instrumentID>
				</source>
			</header>
			<dataPoints>
				<positions axis="2Theta" unit="deg">
					<startPosition>10.02173288</startPosition>
					<endPosition>139.98435528</endPosition>
				</positions>
				<positions axis="Omega" unit="deg">
					<startPosition>5.01086644</startPosition>
					<endPosition>69.99217764</endPosition>
				</positions>
				<commonCountingTime unit="seconds">1.551</commonCountingTime>
				<counts unit="counts">584 525 541 574 552 543 552 541 537 475 534 541 573 530 517 529 518 540 573 523 531 520 540 507 510 540 515 499 503 549 475 503 531 527 498 516 465 463 448 530 507 498 469 488 512 492 473 470 490 472 466 438 488 473 447 484 519 513 498 488 544 519 486 495 496 480 517 484 487 478 463 433 549 485 486 460 483 500 501 412 429 481 459 487 481 471 511 469 530 499 449 460 529 486 452 434 466 489 484 503 468 438 452 471 411 471 479 471 473 495 473 501 467 461 511 436 490 448 450 470 460 468 433 458 430 499 478 480 465 450 518 431 457 405 452 409 439 475 492 437 500 421 495 463 475 454 465 479 430 415 428 482 457 404 489 457 419 421 441 435 472 473 474 521 464 493 455 474 491 506 505 530 474 478 424 453 438 475 455 449 468 453 452 454 451 450 459 466 484 454 505 514 563 556 562 617 641 719 852 1102 1527 3200 6847 13340 11914 4768 1176 699 641 626 590 600 560 481 500 495 466 454 460 465 507 466 484 492 521 528 526 516 468 495 480 530 518 495 493 494 510 486 477 464 446 475 501 510 486 460 499 426 467 434 478 470 495 454 485 446 477 466 464 443 470 452 462 436 434 491 487 478 500 478 438 497 422 419 455 426 432 437 452 443 466 426 459 436 464 498 467 440 425 451 466 439 524 474 477 454 462 451 475 466 442 444 465 466 457 433 427 455 420 429 435 479 439 481 451 482 516 543 500 541 555 521 499 473 474 519 472 474 534 468 473 478 476 438 415 438 470 495 486 420 422 481 552 652 895 1215 1565 1576 1198 826 563 482 499 447 440 435 404 424 420 432 446 416 460 378 409 411 427 423 438 450 430 426 404 440 437 464 402 440 437 415 413 434 449 410 427 410 471 417 418 410 398 409 435 414 404 426 484 436 473 471 441 437 445 469 479 506 519 539 671 829 1065 1191 1187 985 800 630 539 575 538 513 484 508 460 536 500 460 478 536 521 535 559 575 602 633 756 967 1504 3445 9154 12514 7877 4674 1305 783 658 658 567 539 510 451 441 436 480 413 428 458 443 463 426 438 479 440 385 421 431 408 469 421 421 445 421 449 440 473 432 502 467 475 458 516 509 584 681 783 870 943 934 800 709 573 510 481 464 470 408 426 422 399 416 438 432 472 447 415 401 443 398 442 416 415 385 443 396 394 384 428 425 413 470 411 392 403 420 429 428 408 402 394 427 425 421 408 425 391 402 453 380 424 384 428 451 461 462 501 531 573 649 590 591 555 541 545 502 497 492 453 459 409 436 458 455 471 474 447 413 451 426 432 430 471 504 491 516 474 450 463 400 428 422 424 420 411 448 427 470 452 435 443 430 400 434 439 403 425 411 383 404 427 434 391 407 386 402 428 433 425 434 419 488 496 427 458 412 420 443 398 435 460 509 549 521 491 423 431 439 440 504 606 639 534 544 472 436 416 394 420 404 446 470 459 620 1077 1174 853 906 610 542 512 419 418 427 406 427 412 464 426 466 460 415 399 386 413 422 453 490 434 417 398 411 418 392 396 401 395 419 394 376 375 453 403 381 389 433 384 381 415 366 428 402 393 408 439 456 478 471 485 457 475 454 456 440 403 386 410 428 447 434 403 460 412 399 422 406 438 419 385 421 378 420 398 397 384 357 428 383 400 382 391 422 371 382 373 406 390 363 381 405 392 388 381 391 407 425 422 389 403 447 419 505 481 415 432 383 426 360 417 385 393 377 413 370 408 405 441 424 367 387 380 354 388 424 395 377 403 408 371 407 424 355 435 413 358 423 362 454 448 481 493 431 459 392 414 467 544 655 724 614 633 551 476 417 412 424 379 431 415 407 455 399 397 394 367 394 438 360 421 356 426 385 393 390 369 347 430 388 362 403 405 398 363 405 363 412 427 412 382 397 394 421 404 432 417 426 437 442 557 702 527 511 500 454 432 432 429 430 462 509 622 698 631 536 588 485 433 426 406 441 493 539 495 493 461 426 402 419 379 436 428 405 428 399 426 433 486 471 515 520 524 548 502 501 443 461 464 455 420 437 445 420 418 458 404 485 540 542 570 471 528 522 494 469 412 412 468 463 438 458 505 424 450 411 402 416 407 421 421 409 392 434 419 459 441 444 389 417 418 391 389 411 414 432 399 353 365 449 424 376 381 383 403 404 410 352 373 395 392 387 406 365 409 395 391 391 380 353 362 377 383 376 365 338 386 409 372 361 404 393 414 378 410 391 378 374 379 411 408 411 425 428 576 575 544 542 580 510 484 506 441 440 446 421 368 423 380 393 404 401 378 407 388 404 404 413 427 429 491 632 560 514 527 549 503 475 483 502 497 489 468 433 462 439 448 475 411 437 435 466 463 425 407 418 371 401 416 437 392 425 428 417 401 408 439 365 432 414 391 460 395 397 392 431 428 454 413 414 426 444 427 422 427 430 414 420 447 407 374 422 407 418 431 428 424 395 443 409 422 370 426 439 412 443 409 369 410 415 422 404 401 443 441 395 398 391 431 412 396 448 566 645 442 460 533 504 420 390 405 438 443 484 469 468 494 458 463 442 431 443 442 428 449 407 443 404 398 406 383 408 412 404 386 426 449 454 444 376 433 424 400 489 656 637 522 433 574 515 449 403 452 461 450 434 447 425 439 398 420 368 408 437 461 456 436 454 395 427 392 438 393 423 365 386 429 402 424 390 445 458 518 544 530 486 490 528 509 441 410 422 396 448 464 456 385 385 409 399 369 359 381 370 381 382 391 404 399 413 409 404 366 405 402 353 406 370 397 377 400 406 428 391 401 413 410 377 418 400 384 392 449 353 397 437 436 432 384 394 414 439 423 498 524 505 504 496 538 500 416 486 456 436 433 429 400 417 353 370 383 411 369 426 446 421 433 415 444 380 408 394 366 346 351 408 399 410 372 399 360 400 378 376 353 390 377 397 364 394 377 361 402 377 403 411 358 382 384 427 367 387 375 373 404 407 359 399 391 378 394 369 406 372 418 398 416 397 422 424 414 399 425 432 414 408 392 418 393 368 433 405 382 413 379 387 383 395 414 466 446 415 409 414 379 400 401 368 378 394 380 405 398 435 480 459 376 449 413 403 385 404 363 368 383 400 394 438 377 408 413 420 450 412 423 400 418 433 422 390 386 439 409 384 379 390 395 411 354 402 401 371 383 401 402 430 363 402 425 426 397 394 387 380 411 412 357 376 380 388 377 397 382 418 398 377 387 426 385 387 373 397 416 397 374 413 400 401 392 413 394 382 372 411 407 376 404 388 381 350 404 401 358 364 406 383 374 386 380 414 373 393 356 380 410 390 435 411 460 473 495 485 444 467 424 464 446 452 415 392 404 404 420 416 414 425 384 361 409 429 381 385 387 403 394 428 407 388 408 376 411 388 385 391 389 408 419 386 439 382 400 426 342 390 403 404 421 402 402 369 419 381 432 422 393 433 422 392 425 393 406 332 372 415 368 415 395 378 390 393 409 396 377 387 392 365 368 358 483 393 418 429 385 446 384 390 398 393 430 401 378 394 384 352 383 380 391 412 372 352 392 406 412 364 344 391 356 372 367 394 443 363 363 365 347 374 419 426 372 372 411 398 400 392 429 374 387 437 383 396 397 363 376 409 381 391 377 378 398 393 419 396 372 372 378 367 389 402 382 421 404 386 435 398 405 406 363 403 405 445 461 417 533 737 691 462 441 475 511 571 498 443 450 409 420 391 447 438 440 406 439 417 438 419 442 372 395 441 422 391 413 381 446 424 392 414 397 399 423 434 422 492 432 417 439 433 414 423 424 410 412 429 411 412 430 379 419 406 418 361 363 404 383 378 405 391 426 419 391 399 388 410 373 430 400 405 381 380 417 424 424 443 399 422 403 387 428 409 423 410 404 442 387 389 417 398 396 391 361 361 359 351 425 380 377 426 390 371 363 400 370 367 370 370 374 408 402 409 387 415 404 384 389 393 388 388 411 394 376 409 407 373 394 381 446 441 398 407 393 380 397 417 401 403 431 387 393 401 389 401 431 414 415 434 361 410 406 391 368 361 387 430 406 416 394 388 397 361 374 423 386 417 403 391 420 405 418 405 383 402 412 409 398 390 407 388 387 370 382 354 397 440 380 404 360 398 450 397 366 424 384 361 439 380 396 398 399 393 403 345 392 389 349 375 378 395 371 388 401 394 420 401 374 408 409 324 430 419 397 393 362 364 355 372 322 385 377 394 392 365 414 406 389 406 350 387 365 411 367 424 396 399 419 361 394 405 383 407 388 373 391 400 395 411 375 417 402 357 392 414 399 411 383 406 410 406 370 414 436 397 383 407 397 410 386 414 401 397 424 401 413 410 460 457 436 415 398 423 413 412 427 397 429 411 431 421 419 400 372 391 426 373 404 360 426 412 416 398 418 402 395 412 386 399 357 393 410 432 399 428 402 373 398 398 381 372 411 391 397 397 379 369 410 374 360 408 425 380 388 411 390 383 424 378 403 389 414 382 432 386 396 379 416 406 380 401 403 369 401 417 436 404 408 429 409 383 388 412 452 443 430 443 548 507 443 419 455 406 393 470 476 466 378 430 403 384 400 414 399 449 384 394 382 370 451 385 388 443 390 373 403 393 396 419 453 405 388 395 394 409 388 423 432 402 372 403 393 363 397 424 410 457 419 394 398 372 463 395 413 375 397 373 422 413 390 378 418 392 353 414 408 401 359 431 411 401 404 386 456 393 358 389 392 381 396 408 397 411 398 400 417 424 417 367 420 425 400 401 412 395 407 392 422 367 397 414 378 401 401 396 425 429 371 397 365 399 403 390 379 388 401 389 378 381 365 406 385 374 404 388 407 353 396 374 357 409 376 396 398 394 405 375 363 386 347 414 378 365 381 407 417 391 442 427 382 357 406 379 415 383 409 392 398 414 393 396 365 390 378 395 406 434 392 411 461 407 389 384 403 368 410 359 401 416 434 394 400 394 408 427 437 445 423 398 372 404 415 407 444 414 398 443 390 419 363 409 408 411 389 439 432 365 440 412 386 373 436 352 392 388 424 392 410 431 411 450 418 408 387 362 431 415 394 378 399 409 403 400 391 377 416 400 395 405 418 419 389 399 379 413 375 423 393 427 361 431 381 414 401 420 470 550 521 407 436 397 404 420 421 402 434 427 451 447 416 356 404 426 371 351 395 384 370 407 416 393 429 426 386 419 414 437 396 379 430 401 419 392 427 355 395 387 420 406 390 415 389 410 411 386 411 333 357 386 410 367 390 356 420 378 381 378 389 404 379 422 408 383 406 378 388 433 408 414 444 428 428 347 383 420 377 425 430 417 427 400 388 397 395 450 374 432 383 401 393 431 433 443 369 388 452 401 393 420 403 406 404 411 410 460 403 404 434 407 394 423 401 361 388 415 402 416 371 364 381 406 416 401 374 406 447 407 387 382 432 405 346 437 413 378 382 420 367 389 382 413 344 359 426 391 383 376 382 421 392 426 381 389 383 420 423 419 433 425 401 434 438 391 385 434 415 444 393 383 436 404 443 433 425 426 407 402 390 397 395 402 443 441 417 392 401 423 426 406 432 413 429 385 442 402 389 442 447 369 397 420 400 389 416 406 395 373 385 385 440 412 392 390 395 424 451 412 425 412 393 412 422 391 449 442 442 397 433 398 438 434 405 395 395 392 377 402 416 456 436 402 446 414 393 390 384 374 399 382 388 436 435 395 383 407 422 451 397 395 454 456 438 425 418 390 415 382 412 396 409 414 408 425 424 439 378 396 405 413 369 376 416 434 386 421 368 378 410 407 409 450 378 393 374 355 392 380 396 373 408 418 400 389 377 411 402 414 387 385 395 386 372 452 427 429 417 415 419 413 440 398 438 395 403 397 405 431 406 373 406 436 422 362 384 399 401 408 382 385 390 399 395 385 383 365 430 340 420 400 408 368 381 399 365 390 378 393 380 416 422 406 438 405 406 425 358 403 396 452 403 391 419 357 393 420 417 399 357 393 358 379 396 399 398 392 412 393 394 418 399 413 411 415 416 410 413 401 431 417 370 416 392 378 372 387 392 387 399 397 385 389 395 427 403 410 375 375 381 423 442 380 399 392 415 407 406 412 370 400 375 403 407 402 392 394 403 383 430 428 408 389 402 387 406 402 394 406 415 445 439 425 396 374 435 395 439 467 433 414 433 450 431 424 381 397 420 420 378 422 379 402 433 430 429 390 420 391 428 415 397 397 367 403 388 424 430 399 382 401 416 421 379 412 380 338 403 387 383 374 386 401 428 455 387 407 403 428 379 404 412 382 368 375 416 408 422 411 407 441 430 435 417 428 373 409 425 353 410 418 404 384 417 368 418 420 381 423 384 390 391 415 409 397 378 414 384 395 366 400 405 421 391 437 403 401 363 360 393 426 361 373 407 435 435 373 434 381 395 404 438 416 381 392 399 384 388 403 413 387 438 409 434 426 413 392 419 419 384 430 430 430 410 411 399 423 462 446 431 425 430 384 400 440 450 419 410 424 427 397 429 417 449 394 403 431 412 451 385 386 449 416 425 386 436 373 421 412 428 406 446 421 423 396 420 424 413 436 388 387 426 405 388 373 401 420 409 435 401 408 429 418 393 392 400 424 438 435 414 404 410 390 425 389 399 390 405 438 413 448 362 387 415 371 386 401 392 425 397 379 429 453 367 414 406 403 405 415 374 410 414 394 438 394 420 400 415 397 405 375 386 427 401 403 442 386 406 417 438 412 393 401 409 407 399 394 400 366 367 336 447 393</counts>
			</dataPoints>
		</scan>
	</xrdMeasurement>
</xrdMeasurements>