File: dataset/precursor_mixture/V2O5_0p3015-TiO2_0p6998--2min.xrdml
<?xml version="1.0"?>
<xrdMeasurements xmlns="http://www.xrdml.com/XRDMeasurement/2.3" xmlns:xsi="http://www.w3.org/2001/XMLSchema-instance" xsi:schemaLocation="http://www.xrdml.com/XRDMeasurement/2.3 http://www.xrdml.com/XRDMeasurement/2.3/XRDMeasurement.xsd" status="Completed" recordIdentifier="{A57B405B-BF46-4304-8B38-5A84E2F8D1FA}">
	<comment>
		<entry/>
	</comment>
	<sample type="To be analyzed">
		<id>V2O5_0p3015-TiO2_0p6998--2min</id>
		<name></name>
		<preparedBy></preparedBy>
	</sample>
	<xrdMeasurement measurementType="Scan" status="Completed" sampleMode="Reflection">
		<usedWavelength intended="K-Alpha 1">
			<kAlpha1 unit="Angstrom">1.5405980</kAlpha1>
			<kAlpha2 unit="Angstrom">1.5444260</kAlpha2>
			<kBeta unit="Angstrom">1.3922500</kBeta>
			<ratioKAlpha2KAlpha1>0.5000</ratioKAlpha2KAlpha1>
		</usedWavelength>
		<incidentBeamPath>
			<radius unit="mm">145.00</radius>
			<xRayTube id="1010048" name="Empyrean Cu LFF HR (9430 033 7310x)">
				<tension unit="kV">40.0</tension>
				<current unit="mA">15.0</current>
				<anodeMaterial>Cu</anodeMaterial>
				<focus type="Line">
					<length unit="mm">12.0</length>
					<width unit="mm">0.4</width>
					<takeOffAngle unit="deg">6.0</takeOffAngle>
				</focus>
			</xRayTube>
			<sollerSlit id="21010002" name="Soller slits 0.04 rad.">
				<opening unit="rad">0.0400</opening>
			</sollerSlit>
			<mask id="22031000" name="Fixed mask 13 mm">
				<width unit="mm">9.00</width>
			</mask>
			<divergenceSlit id="22120001" name="Divergence slit 1°" xsi:type="fixedDivergenceSlitType">
				<distanceToSample unit="mm">50.00</distanceToSample>
				<height unit="mm">1.52</height>
			</divergenceSlit>
		</incidentBeamPath>
		<sampleMovement xsi:type="spinningSampleMovementType">
			<spinnerRevolutionTime unit="seconds">1.0</spinnerRevolutionTime>
		</sampleMovement>
		<diffractedBeamPath>
			<radius unit="mm">145.00</radius>
			<antiScatterSlit id="22090040" name="AS slit 9 mm (PIXcel)" xsi:type="fixedAntiScatterSlitType">
				<height unit="mm">9.00</height>
			</antiScatterSlit>
			<sollerSlit id="21020003" name="Large Soller slits 0.04 rad.">
				<opening unit="rad">0.0400</opening>
			</sollerSlit>
			<filter id="20030001" name="Large beta-filter Nickel">
				<material>Ni</material>
				<thickness unit="mm">0.020</thickness>
			</filter>
			<detector id="7010019" name="PIXcel1D-Medipix3 detector" xsi:type="rtmsDetectorType">
				<phd unit="keV">
					<lowerLevel>4.02</lowerLevel>
					<upperLevel>11.27</upperLevel>
				</phd>
				<mode>Scanning</mode>
				<activeLength unit="deg">5.542</activeLength>
			</detector>
		</diffractedBeamPath>
		<scan appendNumber="0" mode="Continuous" scanAxis="Gonio" status="Completed">
			<header>
				<startTimeStamp>2024-11-14T15:57:47-08:00</startTimeStamp>
				<endTimeStamp>2024-11-14T15:59:51-08:00</endTimeStamp>
				<author>
					<name>AutomatedUser</name>
				</author>
				<source>
					<applicationSoftware version="1.7b (136)">PANalytical Aeris Instrument Suite</applicationSoftware>
					<instrumentControlSoftware version="3.2.00000000 20240306">AERIS</instrumentControlSoftware>
					<instrumentID>950485</instrumentID>
				</source>
			</header>
			<dataPoints>
				<positions axis="2Theta" unit="deg">
					<startPosition>10.02173288</startPosition>
					<endPosition>99.99585608</endPosition>
				</positions>
				<positions axis="Omega" unit="deg">
					<startPosition>5.01086644</startPosition>
					<endPosition>49.99792804</endPosition>
				</positions>
				<commonCountingTime unit="seconds">10.965</commonCountingTime>
				<counts unit="counts">2123 2162 2105 2094 2196 2048 2049 2034 2119 2056 2107 2043 1935 2011 1901 1965 1937 1970 1888 1909 1931 1925 1902 1910 1954 1844 1867 1923 1852 1865 1807 1814 1825 1785 1812 1809 1765 1717 1735 1691 1765 1768 1751 1720 1661 1670 1617 1660 1633 1649 1665 1645 1613 1676 1577 1600 1602 1546 1585 1533 1551 1610 1524 1540 1507 1530 1462 1438 1452 1507 1549 1478 1458 1475 1473 1398 1412 1455 1325 1432 1483 1374 1358 1375 1429 1395 1413 1441 1361 1430 1382 1336 1363 1261 1375 1366 1356 1379 1340 1357 1366 1298 1325 1313 1390 1292 1246 1253 1277 1280 1268 1303 1282 1344 1342 1368 1336 1416 1363 1494 1556 1655 1717 1961 1891 1688 1557 1273 1327 1268 1276 1288 1312 1263 1218 1264 1155 1223 1248 1232 1179 1208 1232 1177 1164 1255 1183 1148 1176 1242 1194 1174 1133 1114 1190 1164 1123 1150 1125 1116 1117 1147 1094 1171 1087 1112 1122 1146 1059 1128 1119 1054 1120 1106 1116 1058 1138 1138 1117 1034 1062 1090 1065 1109 1027 1061 1017 1038 1024 1090 1139 1074 1090 1041 1037 1007 1083 1012 1027 1007 1057 1047 1004 1007 974 952 1028 1017 1005 1021 965 980 984 1006 1057 988 977 1042 968 1025 1009 1006 1043 1117 1078 1053 1158 1218 1319 1391 1587 1915 2448 3044 4045 5108 6127 6468 5659 4118 2570 1682 1343 1197 1176 1097 1069 1057 1032 1027 946 976 954 932 975 984 958 1008 933 952 983 1014 1037 1048 1160 1305 1477 1621 1916 2088 2183 1959 1538 1242 1041 983 956 920 894 903 856 937 899 904 869 808 920 841 820 863 790 890 843 932 900 920 883 821 815 811 832 833 800 824 829 847 810 836 819 791 834 753 810 741 788 747 730 780 818 775 828 829 780 769 791 793 860 808 806 761 819 794 851 874 827 890 922 970 956 952 1011 1072 1124 1219 1378 1783 2159 3307 4771 7189 10280 13537 15909 14728 10001 5740 2980 1767 1551 1329 1186 1139 961 918 947 995 1035 1084 1246 1477 1740 2011 2102 1736 1344 1040 812 803 808 798 824 774 757 742 714 730 716 727 717 706 719 678 689 688 658 704 709 687 719 786 793 674 826 740 729 657 666 691 708 659 689 702 650 687 681 651 667 616 613 672 620 637 612 666 654 617 644 623 612 690 610 564 592 636 634 616 621 622 590 548 626 603 631 579 596 579 579 589 560 640 548 592 597 529 591 607 609 577 569 569 537 587 597 585 572 551 555 604 571 566 536 629 636 560 593 616 660 678 761 904 1136 1363 1758 1904 2130 1833 1368 1060 799 655 605 642 578 571 560 540 526 502 574 537 547 516 549 563 555 545 538 538 538 576 585 718 813 871 1059 1169 1138 977 774 650 592 554 573 541 497 481 448 486 463 481 495 487 541 566 532 619 648 708 677 564 507 524 516 542 504 470 472 465 505 468 481 512 545 500 470 561 618 677 889 1038 1030 867 735 603 488 507 483 491 457 448 446 430 471 429 418 414 468 460 422 479 407 419 434 423 433 465 421 425 464 461 436 395 435 419 432 406 467 480 486 535 547 541 497 412 453 420 421 488 431 481 459 436 501 449 474 544 620 750 931 1119 1292 1313 1061 778 610 513 553 520 582 564 602 567 574 582 716 884 1261 1807 2508 3346 3615 2850 2255 1465 924 652 554 545 564 461 474 531 478 627 662 912 1089 1333 1474 1166 949 712 489 454 445 413 433 407 400 403 418 416 413 366 413 357 398 400 368 417 370 406 420 363 394 398 384 419 407 358 384 377 360 384 385 371 385 400 381 410 420 388 355 412 368 430 390 354 362 389 409 433 420 393 414 513 639 744 904 1058 1167 962 816 698 567 475 421 438 394 397 421 411 420 433 471 526 622 685 644 619 624 507 452 419 382 388 355 362 387 372 328 327 388 324 330 369 324 360 371 355 332 357 332 394 348 338 302 356 341 356 345 338 346 296 353 379 361 352 335 304 343 320 384 332 325 300 312 325 336 366 371 321 316 308 366 336 345 334 335 324 339 359 322 302 318 343 305 380 348 332 350 377 366 462 473 557 599 594 502 468 464 392 362 328 343 332 300 340 319 288 321 313 324 321 321 333 329 330 345 327 346 343 312 359 361 340 317 326 311 363 339 348 352 370 376 440 489 604 725 808 779 753 610 615 478 507 534 528 595 784 979 1275 1727 2502 3760 4827 4541 3394 2925 2388 1320 802 603 503 518 471 442 441 436 418 429 546 607 646 673 600 557 476 433 414 346 340 358 338 343 362 364 377 403 409 401 366 344 379 335 305 299 319 305 336 329 320 325 322 312 312 323 297 307 337 305 317 313 305 322 312 317 285 305 334 349 258 339 320 322 339 490 593 713 663 542 538 480 403 408 365 353 351 327 338 326 343 312 339 433 451 537 569 463 448 375 391 341 338 338 321 310 349 324 338 329 365 332 347 295 313 293 310 332 284 299 312 350 318 346 334 338 333 324 353 378 362 435 430 516 642 808 1163 1871 2620 3074 2488 1996 1803 1357 932 657 498 440 435 444 416 373 369 392 354 368 393 366 408 403 500 594 714 1087 1698 2493 2916 2343 1946 1815 1518 908 614 474 446 393 412 407 448 508 486 403 440 416 368 331 327 296 306 304 354 331 319 302 306 335 286 335 316 340 285 256 288 283 257 307 308 260 253 274 324 297 321 299 286 310 272 280 294 278 296 240 263 251 289 249 261 270 271 249 300 278 293 282 300 295 306 308 285 337 283 317 345 297 357 397 334 336 337 360 305 304 327 321 372 410 471 466 431 396 385 387 297 306 295 303 262 302 279 261 283 308 289 272 278 252 308 278 320 336 317 340 288 363 275 304 286 278 289 279 284 315 286 273 294 295 261 294 270 275 322 339 385 443 465 462 478 427 384 357 351 289 296 293 285 282 281 282 275 316 288 323 319 332 387 486 680 928 1011 876 738 763 690 638 478 451 517 542 797 1128 1677 2278 1957 1433 1266 1308 1086 748 521 406 367 327 344 285 316 297 284 285 290 287 277 285 283 261 265 260 267 287 262 236 252 266 290 281 273 291 279 318 306 346 325 331 392 354 355 388 342 348 315 316 306 275 264 295 295 277 267 272 300 298 289 256 252 260 243 244 246 236 256 283 261 288 246 247 263 268 274 302 342 391 320 330 298 321 293 263 276 259 270 254 284 239 220 250 262 226 253 275 235 276 255 253 252 312 250 248 256 250 247 264 252 266 265 259 278 287 272 316 300 344 291 305 288 286 339 295 285 246 300 303 298 326 342 351 364 376 402 409 566 798 1029 1157 998 893 819 824 742 564 458 397 348 317 311 290 304 324 308 317 318 317 318 352 411 365 356 372 354 348 379 353 408 350 443 542 744 1076 1261 1115 868 782 768 808 605 484 416 316 328 291 241 276 242 260 262 249 267 249 239 229 234 252 245 237 273 267 255 267 238 285 264 362 327 305 288 287 299 307 301 269 311 284 326 332 373 323 310 329 354 373 355 354 394 365 369 332 309 324 324 295 294 255 238 266 253 241 259 242 271 257 238 232 249 284 238 266 241 243 245 232 249 277 260 321 317 306 296 283 307 302 337 334 343 366 402 409 444 360 401 405 359 401 445 424 556 744 1107 1554 1605 1116 845 790 1014 905 704 491 422 326 297 280 286 291 265 251 307 290 314 352 499 540 660 657 519 438 421 482 454 361 315 286 280 254 268 249 263 262 228 235 223 225 248 227 206 245 238 244 257 251 263 235 295 253 244 239 236 289 241 265 266 273 249 215 247 239 255 242 253 291 259 328 306 309 295 310 261 273 308 251 280 255 235 245 241 240 239 233 216 224 232 202 215 227 235 215 240 215 246 237 234 219 236 228 246 251 236 215 248 225 230 216 209 250 231 219 217 220 231 232 246 227 227 234 235 198 256 273 257 247 298 275 252 282 242 254 246 215 204 244 234 206 235 227 276 247 230 227 250 262 250 237 249 231 200 254 222 226 239 258 271 264 299 309 306 285 249 267 331 295 340 362 439 605 775 898 843 582 488 513 629 633 533 401 497 552 524 461 364 355 337 370 371 313 272 258 245 227 216 235 223 237 239 224 241 259 271 232 228 241 243 257 223 240 256 252 244 268 211 242 220 226 209 240 216 238 228 222 229 227 219 248 189 210 244 224 210 234 244 225 238 251 259 229 219 229 240 247 224 232 248 236 232 233 253 214 218 236 226 201 245 254 217 220 255 252 224 234 260 273 290 260 238 232 243 202 266 215 227 249 217 244 234 208 214 237 216 211 234 215 203 210 214 224 195 219 227 208 204 209 191 212 213 244 229 233 257 240 223 254 269 246 237 229 234 235 265 244 227 234 212 232 233 220 224 194 213 195 215 207 226 241 209 211 231 234 240 244 241 227 234 249 256 235 230 249 230 236 221 239 246 238 210 240 234 248 266 236 272 254 261 259 299 251 223 249 251 242 247 251 216 227 211 223 246 221 236 177 213 204 235 210 205 227 250 192 205 220 222 222 203 210 200 215 215 208 212 220 223 204 191 223 241 219 230 223 240 230 244 249 264 289 266 233 244 252 268 302 324 328 292 239 267 257 299 279 293 276 241 248 302 279 246 232 218 270 287 343 371 459 571 481 413 349 351 345 371 416 359 370 306 270 284 278 258 254 269 271 298 331 397 574 568 582 441 362 366 388 408 371 412 379 308 286 257 255 257 210 219 225 238 215 242 240 246 185 241 208 215 212 215 210 194 224 213 207 235 209 237 230 225 234 236 206 202 213 233 224 194 214 238 217 231 233 231 228 217 259 247 205 211 225 252 250 253 252 221 254 259 275 264 259 337 360 429 458 401 358 322 302 332 286 356 320 256 288 252 245 237 245 221 249 223 219 220 209 249 251 243 219 234 264 264 310 293 303 317 369 378 383 404 344 294 280</counts>
			</dataPoints>
		</scan>
	</xrdMeasurement>
</xrdMeasurements>