File: dataset/precursor_mixture/V2O5_0p6008-ZnO_0p4010--8min.xrdml
<?xml version="1.0"?>
<xrdMeasurements xmlns="http://www.xrdml.com/XRDMeasurement/2.3" xmlns:xsi="http://www.w3.org/2001/XMLSchema-instance" xsi:schemaLocation="http://www.xrdml.com/XRDMeasurement/2.3 http://www.xrdml.com/XRDMeasurement/2.3/XRDMeasurement.xsd" status="Completed" recordIdentifier="{81D7F4AB-6226-4FD6-B1E4-526028116A7E}">
	<comment>
		<entry/>
	</comment>
	<sample type="To be analyzed">
		<id>V2O5_0p6008-ZnO_0p4010--8min</id>
		<name></name>
		<preparedBy></preparedBy>
	</sample>
	<xrdMeasurement measurementType="Scan" status="Completed" sampleMode="Reflection">
		<usedWavelength intended="K-Alpha 1">
			<kAlpha1 unit="Angstrom">1.5405980</kAlpha1>
			<kAlpha2 unit="Angstrom">1.5444260</kAlpha2>
			<kBeta unit="Angstrom">1.3922500</kBeta>
			<ratioKAlpha2KAlpha1>0.5000</ratioKAlpha2KAlpha1>
		</usedWavelength>
		<incidentBeamPath>
			<radius unit="mm">145.00</radius>
			<xRayTube id="1010048" name="Empyrean Cu LFF HR (9430 033 7310x)">
				<tension unit="kV">40.0</tension>
				<current unit="mA">15.0</current>
				<anodeMaterial>Cu</anodeMaterial>
				<focus type="Line">
					<length unit="mm">12.0</length>
					<width unit="mm">0.4</width>
					<takeOffAngle unit="deg">6.0</takeOffAngle>
				</focus>
			</xRayTube>
			<sollerSlit id="21010002" name="Soller slits 0.04 rad.">
				<opening unit="rad">0.0400</opening>
			</sollerSlit>
			<mask id="22031000" name="Fixed mask 13 mm">
				<width unit="mm">9.00</width>
			</mask>
			<divergenceSlit id="22120001" name="Divergence slit 1°" xsi:type="fixedDivergenceSlitType">
				<distanceToSample unit="mm">50.00</distanceToSample>
				<height unit="mm">1.52</height>
			</divergenceSlit>
		</incidentBeamPath>
		<sampleMovement xsi:type="spinningSampleMovementType">
			<spinnerRevolutionTime unit="seconds">1.0</spinnerRevolutionTime>
		</sampleMovement>
		<diffractedBeamPath>
			<radius unit="mm">145.00</radius>
			<antiScatterSlit id="22090040" name="AS slit 9 mm (PIXcel)" xsi:type="fixedAntiScatterSlitType">
				<height unit="mm">9.00</height>
			</antiScatterSlit>
			<sollerSlit id="21020003" name="Large Soller slits 0.04 rad.">
				<opening unit="rad">0.0400</opening>
			</sollerSlit>
			<filter id="20030001" name="Large beta-filter Nickel">
				<material>Ni</material>
				<thickness unit="mm">0.020</thickness>
			</filter>
			<detector id="7010019" name="PIXcel1D-Medipix3 detector" xsi:type="rtmsDetectorType">
				<phd unit="keV">
					<lowerLevel>4.02</lowerLevel>
					<upperLevel>11.27</upperLevel>
				</phd>
				<mode>Scanning</mode>
				<activeLength unit="deg">5.542</activeLength>
			</detector>
		</diffractedBeamPath>
		<scan appendNumber="0" mode="Continuous" scanAxis="Gonio" status="Completed">
			<header>
				<startTimeStamp>2024-11-14T13:05:50-08:00</startTimeStamp>
				<endTimeStamp>2024-11-14T13:13:57-08:00</endTimeStamp>
				<author>
					<name>AutomatedUser</name>
				</author>
				<source>
					<applicationSoftware version="1.7b (136)">PANalytical Aeris Instrument Suite</applicationSoftware>
					<instrumentControlSoftware version="3.2.00000000 20240306">AERIS</instrumentControlSoftware>
					<instrumentID>950485</instrumentID>
				</source>
			</header>
			<dataPoints>
				<positions axis="2Theta" unit="deg">
					<startPosition>10.00943322</startPosition>
					<endPosition>99.99442286</endPosition>
				</positions>
				<positions axis="Omega" unit="deg">
					<startPosition>5.00471661</startPosition>
					<endPosition>49.99721143</endPosition>
				</positions>
				<commonCountingTime unit="seconds">12.495</commonCountingTime>
				<counts unit="counts">2303 2211 2264 2189 2277 2284 2272 2251 2175 2285 2219 2157 2217 2169 2190 2229 2224 2160 2228 2229 2209 2196 2240 2122 2237 2123 2147 2082 2121 2298 2139 2187 2158 2050 2113 2118 2094 2110 2024 2120 2137 2085 2037 2081 2158 2113 2010 2013 2100 2126 2098 2033 2110 2111 2117 2066 2155 2078 2138 2134 2030 1925 2018 2113 2117 1994 2019 2075 1993 2074 2062 2050 1977 1949 2061 2091 1967 2006 1982 1965 2025 1965 1978 1988 2011 2011 1927 1942 2022 2056 2025 2001 1955 1940 2043 1936 1957 1841 1945 1877 1877 1972 1896 1977 1984 1978 1925 1878 1845 1838 1968 2038 1880 1949 1898 1904 1942 1845 1857 1874 1920 1899 1830 1885 1854 1929 1865 1913 1817 1740 1851 1832 1857 1907 1823 1901 1830 1827 1842 1824 1873 1820 1848 1842 1780 1806 1836 1844 1791 1773 1870 1815 1852 1848 1830 1770 1774 1746 1682 1767 1838 1809 1754 1753 1794 1749 1711 1724 1704 1753 1686 1774 1741 1786 1742 1812 1756 1787 1712 1830 1727 1743 1643 1698 1688 1713 1705 1731 1797 1700 1750 1745 1731 1647 1660 1690 1697 1778 1684 1736 1675 1697 1723 1641 1627 1653 1657 1725 1659 1645 1653 1768 1616 1686 1627 1644 1592 1739 1617 1599 1683 1625 1637 1648 1548 1625 1572 1658 1602 1652 1647 1679 1595 1641 1636 1627 1701 1613 1622 1608 1629 1629 1610 1542 1592 1603 1590 1593 1599 1622 1577 1603 1561 1568 1618 1608 1589 1575 1552 1490 1557 1645 1649 1592 1571 1580 1505 1581 1504 1539 1504 1556 1569 1614 1546 1563 1548 1552 1490 1528 1489 1558 1513 1501 1465 1548 1543 1485 1497 1537 1496 1593 1462 1467 1432 1476 1438 1428 1405 1506 1508 1538 1528 1513 1506 1471 1461 1488 1473 1459 1516 1524 1526 1508 1482 1439 1453 1483 1523 1553 1482 1487 1521 1433 1474 1455 1393 1479 1425 1509 1415 1515 1451 1504 1429 1462 1494 1445 1393 1439 1543 1386 1402 1448 1497 1469 1419 1349 1500 1442 1393 1355 1392 1413 1382 1398 1405 1447 1501 1418 1487 1399 1483 1404 1388 1470 1446 1455 1422 1361 1467 1307 1408 1394 1413 1451 1380 1395 1406 1372 1405 1442 1294 1372 1414 1386 1466 1396 1403 1426 1384 1337 1383 1360 1434 1370 1430 1384 1451 1426 1367 1437 1374 1436 1423 1360 1375 1389 1475 1353 1410 1381 1317 1403 1360 1347 1320 1422 1422 1298 1431 1277 1387 1368 1396 1331 1339 1323 1427 1407 1380 1283 1323 1324 1359 1287 1353 1310 1405 1347 1416 1357 1390 1324 1331 1431 1399 1389 1371 1348 1375 1324 1330 1421 1379 1391 1348 1397 1310 1363 1398 1345 1325 1369 1409 1415 1424 1460 1447 1466 1450 1489 1389 1381 1491 1418 1461 1477 1512 1479 1587 1518 1575 1550 1533 1604 1621 1611 1678 1766 1698 1757 1696 1717 1792 1858 1873 1921 1954 2026 1897 2049 2037 1979 2055 2048 2048 2073 2024 2035 2003 2085 2024 2034 2025 1953 2091 1995 2031 1893 1775 1870 1831 1742 1708 1588 1449 1465 1470 1358 1411 1388 1412 1400 1380 1392 1322 1285 1290 1275 1369 1346 1345 1267 1358 1315 1279 1325 1314 1299 1268 1297 1226 1336 1292 1265 1254 1296 1324 1331 1282 1287 1317 1281 1261 1257 1314 1306 1301 1327 1258 1261 1271 1279 1272 1184 1357 1214 1218 1225 1321 1261 1186 1232 1251 1244 1202 1245 1204 1251 1254 1343 1249 1245 1269 1193 1165 1265 1222 1334 1215 1172 1246 1273 1256 1250 1259 1305 1284 1220 1250 1239 1157 1247 1240 1209 1164 1227 1215 1298 1249 1309 1184 1221 1218 1221 1221 1250 1232 1195 1189 1195 1190 1269 1134 1211 1234 1213 1212 1228 1236 1225 1208 1192 1171 1257 1193 1241 1192 1151 1197 1254 1281 1211 1214 1174 1208 1186 1193 1201 1188 1230 1264 1175 1204 1125 1220 1164 1185 1199 1162 1176 1258 1180 1194 1245 1232 1162 1206 1193 1234 1138 1220 1244 1166 1140 1095 1179 1168 1196 1159 1247 1175 1207 1188 1107 1118 1140 1037 1167 1172 1164 1206 1108 1166 1154 1150 1192 1195 1148 1144 1171 1139 1151 1177 1134 1176 1089 1182 1188 1180 1156 1148 1185 1142 1083 1105 1114 1136 1150 1177 1112 1150 1140 1098 1184 1091 1147 1171 1203 1220 1120 1155 1110 1125 1106 1158 1094 1131 1117 1224 1188 1161 1130 1195 1127 1069 1063 1079 1120 1075 1121 1160 1144 1146 1178 1101 1154 1150 1160 1030 1070 1091 1132 1154 1195 1121 1071 1084 1154 1107 1155 1119 1106 1135 1090 1146 1085 1138 1174 1162 1064 1242 1107 1148 1122 1176 1118 1138 1127 1101 1111 1181 1144 1075 1140 1095 1072 1118 1102 1105 1065 1114 1109 1135 1109 1110 1131 1019 1127 1107 1109 1110 1084 1106 1095 1149 1031 1082 1059 1118 1101 1039 1173 1060 1121 1098 1121 1132 1068 1050 1089 1111 1167 1107 1096 1027 1076 1103 1132 1107 1076 1098 1112 1141 1104 1109 1182 1155 1099 1082 1107 1127 1061 1114 1053 1058 1126 1114 1165 1087 1115 1077 1083 1040 1135 1087 1113 1140 1176 1167 1144 1005 1132 1089 1185 1150 1107 1188 1173 1135 1138 1151 1122 1104 1177 1155 1154 1164 1192 1230 1187 1208 1196 1232 1128 1269 1191 1187 1267 1279 1325 1299 1310 1332 1389 1363 1365 1393 1442 1492 1449 1469 1482 1595 1616 1687 1711 1633 1801 1864 1931 1943 2037 2127 2043 2086 2336 2400 2508 2531 2610 2697 2845 2788 3000 3056 3116 3300 3361 3474 3532 3632 3580 3750 3789 3825 3902 3879 3927 4024 4044 4017 3977 3913 3875 3818 3744 3647 3645 3349 3248 3243 2880 2941 2659 2561 2435 2100 2077 1992 1887 1779 1721 1638 1496 1522 1458 1419 1443 1365 1354 1309 1303 1251 1327 1271 1331 1213 1200 1228 1205 1226 1178 1204 1134 1178 1122 1158 1132 1168 1119 1128 1171 1128 1063 1166 1145 1113 1104 1116 1044 1158 1120 1042 1095 1046 1097 1121 1092 1120 1081 1061 1059 1086 1105 1089 1060 1106 1105 1135 1055 1040 1092 1128 1143 1172 1156 1106 1121 1114 1162 1126 1165 1156 1114 1168 1209 1177 1219 1187 1207 1237 1233 1324 1259 1294 1342 1403 1352 1365 1421 1392 1472 1473 1549 1541 1622 1555 1615 1680 1776 1798 1806 1760 1851 1787 1865 1851 1887 1856 1905 1835 1969 1959 1917 1926 1825 1889 1804 1770 1715 1794 1678 1687 1666 1567 1462 1427 1368 1403 1286 1278 1189 1150 1231 1210 1156 1145 1106 1058 1078 1086 1116 1041 1079 1056 1083 1048 1033 1046 1050 1000 1050 1001 1002 1042 961 1040 978 965 1001 1015 955 978 987 967 1005 991 965 975 1010 925 974 997 1000 1012 970 974 925 959 980 1030 949 951 935 889 913 939 882 963 945 901 946 944 963 923 945 924 940 939 942 932 955 892 966 906 970 1025 918 927 941 976 923 925 919 901 929 918 916 898 905 958 858 916 929 857 876 900 938 914 884 931 888 897 988 934 953 894 906 907 886 866 925 882 852 930 897 941 874 915 928 895 898 920 892 896 882 851 848 886 914 853 913 898 952 905 839 899 931 889 943 864 931 914 894 856 892 861 933 938 888 840 869 921 883 914 899 865 897 908 876 853 923 849 874 900 819 852 835 893 865 891 904 871 858 917 874 886 831 883 880 915 852 881 867 949 850 875 887 861 815 855 910 854 895 923 864 903 861 839 873 874 871 886 815 897 899 814 829 857 862 898 915 861 846 860 813 820 853 896 846 923 818 879 847 876 850 838 902 809 827 835 862 887 772 862 851 881 870 869 835 847 845 847 853 873 881 854 878 823 843 885 908 853 863 828 836 909 833 825 812 812 825 842 861 925 812 820 851 847 844 869 801 867 864 812 844 917 841 887 895 826 822 904 815 845 780 877 901 818 860 833 855 863 849 832 876 888 899 853 941 937 890 867 883 873 857 873 923 904 870 893 964 863 903 928 884 938 956 1024 927 1023 992 952 957 989 978 984 1002 1027 1030 988 1010 1061 1084 1039 1058 1018 1056 1076 1127 1086 1091 1090 1095 1059 1146 1070 1072 1028 1062 1112 1103 1084 1143 1228 1149 1240 1198 1297 1331 1314 1418 1525 1456 1563 1601 1710 1676 1842 1909 2028 2115 2197 2237 2301 2486 2597 2608 2725 2842 2797 2982 3084 3152 3189 3194 3251 3303 3486 3443 3400 3314 3342 3461 3236 3264 3187 3076 2962 2794 2664 2472 2254 2100 1967 1845 1719 1589 1556 1417 1337 1259 1253 1128 1190 1029 1109 1061 1038 1041 1038 1006 964 939 956 929 930 932 992 945 904 877 855 911 915 872 837 895 823 890 830 859 918 886 887 831 815 820 886 841 848 811 822 856 819 757 830 806 784 780 773 837 843 799 810 801 808 757 813 804 807 816 803 861 794 797 835 835 792 801 861 821 768 799 819 825 773 827 818 785 810 781 851 747 795 758 764 811 793 764 775 761 775 745 763 829 746 871 771 801 788 754 778 791 742 735 765 804 805 816 801 775 767 802 795 772 808 755 771 790 790 780 819 784 714 760 809 760 763 787 771 813 772 714 749 787 745 758 761 800 760 771 826 812 774 788 802 758 768 787 798 809 869 755 775 786 781 791 780 797 701 768 749 775 728 771 784 808 741 746 740 757 818 770 767 767 796 776 722 774 767 734 777 797 750 774 700 738 778 782 755 764 753 791 743 755 744 738 806 723 747 704 704 739 717 721 738 743 752 791 780 738 764 773 795 732 799 774 784 717 774 737 804 815 759 708 739 726 743 718 728 726 777 753 671 785 669 694 766 779 742 768 722 722 749 741 750 732 724 718 768 703 728 769 687 754 715 676 704 731 732 757 732 710 744 721 732 730 715 690 703 738 734 695 760 721 724 725 697 735 720 735 662 748 707 731 782 792 744 708 742 766 720 754 767 707 748 768 734 703 755 761 767 692 752 728 739 739 716 744 749 723 755 792 767 687 719 727 761 727 762 748 736 710 767 664 753 750 757 717 752 755 776 733 693 749 759 754 689 804 770 808 743 780 747 773 804 744 786 774 781 772 814 785 797 767 738 783 789 749 819 794 799 829 774 811 865 849 806 773 835 796 844 844 803 825 814 907 878 894 866 854 909 877 923 949 979 988 939 1059 1025 1017 1039 1091 1099 1129 1155 1179 1339 1324 1356 1395 1403 1513 1603 1592 1745 1807 1785 1874 1963 2073 2214 2209 2323 2436 2542 2569 2643 2648 2809 2951 2937 2997 3030 3092 3180 3035 3188 3154 3145 3057 3021 3039 3048 2919 2934 2723 2607 2547 2290 2238 2102 1933 1976 1811 1670 1600 1608 1473 1439 1394 1352 1373 1280 1268 1287 1179 1272 1354 1316 1317 1425 1259 1459 1494 1485 1484 1609 1621 1727 1835 1952 2074 2110 2265 2315 2536 2634 2614 2809 2965 3228 3439 3648 3748 3892 4092 4283 4433 4431 4586 4741 4804 4985 5149 5017 5336 5114 5284 5214 5194 5080 4935 4731 4650 4324 4130 3790 3487 3234 3060 2757 2657 2401 2123 1976 1821 1840 1673 1601 1590 1445 1492 1347 1354 1343 1364 1358 1336 1374 1425 1383 1331 1456 1475 1417 1460 1495 1497 1500 1563 1543 1623 1629 1643 1568 1719 1752 1724 1802 1781 1718 1828 1703 1782 1798 1721 1638 1639 1658 1607 1525 1486 1402 1368 1342 1269 1290 1210 1164 1104 1120 1093 1008 915 968 955 965 940 932 862 838 873 835 858 832 854 812 815 817 793 743 831 786 792 770 863 778 811 789 786 827 736 780 780 767 773 769 804 805 772 779 831 803 825 843 847 820 881 885 839 921 920 875 906 964 912 907 937 939 986 1012 1016 1018 1041 979 1067 1007 998 1032 1102 1048 1066 1054 1032 935 996 1032 1044 957 954 893 899 928 890 856 867 813 874 782 786 803 846 780 804 819 789 804 812 748 812 773 749 751 820 767 789 771 783 783 796 786 763 772 819 790 826 853 864 809 845 831 854 880 878 953 915 982 932 1012 990 1032 1123 1136 1207 1191 1286 1324 1362 1416 1460 1657 1662 1832 1855 1921 2090 2255 2437 2506 2655 2798 3053 3080 3261 3403 3582 3644 3911 3882 4152 4398 4491 4532 4659 4685 4746 4771 4763 4977 4750 4876 4736 4684 4526 4576 4276 4124 3966 3695 3374 3057 2820 2684 2453 2266 2101 1878 1621 1510 1412 1261 1210 1117 1070 1031 1005 1031 950 911 904 858 851 837 889 802 820 784 822 785 811 736 759 765 790 779 797 831 712 743 727 762 713 704 705 783 735 684 806 784 734 731 698 734 750 761 678 744 784 731 707 718 733 728 763 733 735 704 715 785 770 810 767 778 728 719 691 723 727 741 740 728 747 810 783 823 773 726 753 785 729 766 787 783 786 781 813 797 781 811 848 827 844 836 891 887 884 920 897 912 958 988 1001 1026 1019 1045 1118 1096 1155 1235 1241 1260 1342 1339 1459 1603 1585 1703 1758 1904 2076 2165 2247 2427 2514 2818 2886 3225 3412 3651 3874 4027 4273 4736 4913 5332 5596 5737 6211 6529 6824 6887 7162 7646 7766 7913 8075 8390 8484 8654 8622 8805 8761 8591 8440 8139 7913 7360 6938 6433 5941 5733 5062 4655 4294 3999 3626 3203 2830 2607 2365 2166 1952 1811 1588 1583 1394 1413 1279 1278 1170 1159 1118 1066 1049 1004 994 919 910 948 935 913 899 838 792 789 835 772 734 796 807 751 803 760 782 728 717 753 784 725 662 685 752 708 694 694 681 702 748 725 672 720 678 729 654 727 657 700 661 669 673 720 668 643 673 682 686 670 741 695 697 715 709 718 697 709 721 741 685 710 734 737 676 712 738 736 711 694 668 692 674 702 713 691 662 721 673 682 603 658 646 636 617 698 656 667 652 604 622 577 594 612 661 562 615 567 620 593 639 565 640 577 607 586 643 599 598 551 593 565 633 599 600 574 575 603 590 593 585 597 602 547 594 586 582 570 573 591 588 630 593 592 550 589 568 607 599 585 599 589 556 566 544 551 574 588 557 560 535 599 579 544 598 588 606 545 589 547 577 587 568 562 546 589 567 565 575 530 534 529 568 559 554 548 584 593 600 544 559 572 577 523 549 555 573 558 628 566 512 545 496 519 542 538 559 532 530 595 567 564 557 544 553 554 524 561 568 600 540 549 605 566 578 518 549 535 556 529 548 522 561 543 558 571 510 523 522 540 570 613 524 587 555 522 526 559 538 574 567 575 565 555 556 573 550 548 535 489 575 583 565 576 552 534 536 544 561 552 582 546 541 560 557 548 520 514 555 530 598 561 536 558 569 597 549 540 553 515 554 588 577 565 575 533 537 540 557 562 535 517 530 534 556 560 563 537 542 541 517 536 540 593 566 530 545 562 599 580 557 576 557 562 568 578 614 571 587 572 598 563 611 547 571 583 569 625 555 549 572 560 570 535 616 583 542 529 547 599 563 547 552 583 521 529 548 588 540 567 522 593 527 547 576 570 554 584 556 556 563 532 586 557 573 578 573 578 593 591 592 555 574 560 585 591 609 577 596 632 616 632 596 612 615 599 642 632 650 656 699 668 657 668 705 688 721 815 740 792 797 768 842 802 863 848 845 900 862 894 900 883 1002 998 1058 1033 988 996 1027 1052 1028 1068 1009 1079 1076 1051 1088 1043 1040 959 991 943 966 836 918 940 893 788 834 785 783 718 760 721 762 691 669 644 674 679 649 693 662 692 660 639 611 710 627 694 644 608 652 646 641 612 683 620 616 688 675 697 694 622 696 666 657 702 692 692 751 748 716 693 754 828 711 724 713 787 833 797 808 787 796 780 751 761 816 747 706 712 722 721 650 688 703 632 626 613 636 627 630 611 602 620 574 574 562 568 558 527 591 571 573 613 495 541 536 556 506 544 541 508 528 531 564 528 522 559 549 580 511 536 514 550 520 568 530 535 470 551 522 521 515 531 552 495 532 516 518 502 516 527 537 481 501 513 527 481 542 484 547 478 503 494 501 560 522 498 490 507 488 491 511 477 492 519 491 465 471 495 515 491 530 491 494 517 507 476 539 507 477 491 513 496 524 477 489 539 499 529 471 466 509 463 451 446 482 525 493 458 487 465 477 510 477 532 501 503 492 497 493 458 523 450 498 495 493 468 476 505 492 465 492 516 524 517 470 500 516 495 479 500 485 479 496 490 475 467 485 500 522 460 530 499 510 537 482 505 522 495 505 514 479 501 501 524 487 523 501 514 488 515 524 524 542 532 521 501 490 492 498 519 524 541 511 511 516 497 539 500 534 496 453 532 527 507 515 540 474 501 495 530 502 472 503 503 496 480 456 484 504 511 502 468 480 503 502 509 494 479 520 471 482 485 526 541 472 509 514 534 504 480 527 506 515 544 508 469 504 506 507 520 492 454 474 522 494 543 485 557 461 482 554 484 540 517 527 541 604 590 537 564 585 543 559 577 614 633 607 634 606 627 618 615 647 653 667 708 727 739 707 784 761 760 881 828 829 878 817 896 876 966 952 900 951 1016 1010 1018 1012 985 952 1016 1012 934 989 931 964 902 883 796 830 842 778 731 778 707 714 722 648 700 646 621 591 637 573 632 598 591 602 583 572 610 600 578 525 607 540 524 515 517 572 517 536 566 528 546 500 519 576 519 511 526 526 542 509 552 528 512 515 524 510 547 499 549 494 530 511 537 508 533 499 522 509 469 496 496 531 461 538 551 520 462 513 554 514 523 479 494 504 504 521 545 525 519 529 541 507 527 524 509 543 572 529 550 557 516 532 509 528 546 561 539 546 542 579 565 569 577 582 607 554 570 568 594 588 583 588 564 624 635 681 656 627 612 634 650 685 685 793 712 745 677 734 805 794 828 835 852 867 864 965 937 1055 986 1092 1125 1225 1250 1268 1376 1364 1426 1539 1595 1666 1689 1848 1877 1921 1992 2116 2134 2261 2299 2398 2415 2440 2484 2546 2492 2666 2655 2617 2629 2736 2722 2865 2922 2830 2934 2704 2816 2763 2583 2646 2477 2405 2359 2170 2155 1961 1960 1894 1766 1721 1711 1613 1552 1554 1461 1411 1398 1324 1276 1274 1252 1160 1190 1163 1132 1119 1075 1003 1069 1014 1009 983 907 944 919 854 827 793 798 717 766 771 723 741 708 688 706 690 666 686 619 620 590 646 602 631 613 634 613 620 625 609 633 613 615 613 595 624 586 649 607 627 592 612 616 572 586 633 589 652 626 619 630 566 642 651 678 692 628 682 681 696 728 736 702 701 737 771 800 779 782 823 813 875 824 851 860 891 880 924 928 924 913 880 899 920 874 858 856 824 852 804 794 786 797 756 741 778 761 733 677 736 650 650 606 648 694 640 622 576 621 599 584 590 555 565 587 561 598 594 661 594 586 575 579 586 587 596 594 619 580 585 591 612 592 617 581 628 607 664 605 622 615 640 593 600 569 598 587 581 576 619 590 561 585 561 555 551 561 541 569 538 509 513 515 532 536 519 518 542 474 528 505 510 516 518 503 497 515 505 491 478 498 569 520 479 461 502 474 512 500 544 545 471 491 493 489 491 514 474 498 510 518 471 512 514 521 508 501 490 459 511 514 526 513 514 449 523 487 506 491 479 467 495 486 524 482 452 524 481 502 481 493 498 523 430 522 474 467 451 505 497 537 467 499 483 507 484 527 529 519 533 528 531 559 556 520 539 548 515 519 595 571 609 555 562 591 588 584 571 607 617 625 622 625 686 691 707 701 737 789 803 840 799 883 879 977 955 962 1041 1025 1112 1142 1220 1263 1214 1288 1253 1291 1355 1372 1416 1444 1372 1453 1514 1442 1349 1322 1333 1245 1192 1146 1151 1092 1099 1074 984 1015 968 936 847 852 810 774 806 731 750 720 735 758 729 722 704 658 648 639 686 620 629 623 649 609 640 629 607 621 619 604 582 606 626 625 657 633 691 668 690 648 709 713 746 703 740 766 774 799 765 802 798 779 907 868 856 834 842 853 900 866 849 815 859 805 721 700 776 747 724 689 726 681 682 669 662 630 579 614 598 547 555 593 555 592 548 539 568 551 517 521 526 540 559 515 536 529 537 540 533 537 516 568 568 540 526 495 532 497 512 524 521 482 498 498 501 512 495 519 528 520 499 473 492 495 431 499 489 479 465 492 489 454 460 480 463 465 484 458 491 503 468 515 470 480 470 480 443 479 530 475 456 463 439 478 475 459 474 430 453 458 467 462 456 444 447 450 488 470 476 448 447 463 436 442 475 474 462 475 430 481 480 440 479 456 446 457 501 511 484 479 437 462 477 499 513 482 464 445 477 460 486 471 521 487 517 503 463 490 487 492 509 523 524 537 538 529 533 516 548 548 557 547 560 573 526 501 521 536 510 513 502 504 510 504 494 476 511 474 509 507 535 475 531 481 491 494 455 459 457 441 422 442 465 477 442 409 475 472 456 450 479 461 493 436 440 427 453 430 463 498 410 467 452 477 433 474 469 420 483 489 454 473 486 432 471 420 449 476 454 487 493 486 464 437 473 467 490 521 469 450 463 468 457 433 464 462 489 482 481 462 480 461 466 426 447 516 453 461 497 483 461 461 476 498 473 479 487 482 505 419 500 511 494 462 498 456 507 511 519 498 482 499 488 517 483 500 495 488 490 512 529 478 542 492 544 500 552 493 532 548 515 576 585 600 606 586 598 559 605 620 643 606 653 652 682 725 708 697 687 754 740 772 815 734 770 824 791 810 915 833 853 833 812 868 844 794 817 800 764 781 733 784 742 777 745 713 719 690 705 671 688 671 664 657 673 679 663 683 631 651 667 636 641 624 599 654 659 667 642 668 675 713 716 691 709 754 741 718 749 755 842 837 835 901 853 944 944 962 975 1013 1132 1139 1148 1218 1287 1330 1325 1344 1584 1577 1724 1818 1774 1897 2043 2172 2239 2451 2638 2604 2789 2849 3039 3133 3211 3275 3304 3542 3467 3554 3526 3502 3252 3202 3114 2961 2824 2603 2572 2334 2356 2264 2241 2116 1970 1979 1836 1703 1541 1505 1392 1315 1170 1138 1073 933 951 851 808 840 810 743 752 710 727 710 730 634 625 578 621 552 601 619 564 542 561 519 563 555 539 568 531 536 511 546 514 566 508 517 532 492 484 523 448 512 536 500 482 484 487 462 480 535 510 493 524 427 557 498 480 503 463 521 424 459 414 506 499 491 514 463 505 483 457 512 507 494 490 485 475 443 450 491 502 456 440 477 493 470 466 489 470 470 461 522 474 504 507 481 507 457 474 529 499 521 490 485 480 547 538 533 494 528 486 524 514 509 532 545 571 527 509 513 542 498 533 500 553 550 551 540 554 553 554 549 603 587 609 573 586 577 566 603 585 628 625 626 664 638 647 665 637 664 671 675 634 680 678 673 673 657 657 646 641 643 715 635 662 684 637 606 636 666 652 720 638 678 655 661 703 664 682 668 696 729 698 632 725 693 696 728 764 718 709 747 714 749 807 784 800 763 767 790 720 779 733 709 681 667 683 696 671 682 633 617 669 581 615 626 592 538 606 576 557 573 596 538 565 560 571 502 541 515 505 527 522 508 529 481 507 518 494 492 491 479 443 498 471 473 457 505 472 478 487 493 462 463 520 494 510 502 521 466 513 493 481 498 487 521 499 525 482 532 499 489 547 492 534 544 509 530 548 574 531 566 559 571 570 580 560 623 597 604 607 585 599 590 643 588 523 542 573 584 582 554 572 572 570 568 526 549 569 549 524 556 533 544 551 526 514 513 515 496 517 479 474 490 503 496 522 484 479 523 497 497 510 509 543 529 532 497 486 505 517 505 541 503 497 530 501 510 545 506 528 521 556 527 569 591 563 537 567 568 615 650 580 627 613 683 585 681 669 711 678 708 756 737 776 820 791 852 861 873 863 893 899 979 938 939 949 961 932 921 989 968 945 929 861 898 855 832 871 807 816 788 793 805 751 773 720 747 691 669 684 642 644 623 601 609 581 572 607 614 594 546 595 565 564 590 566 561 530 531 550 541 534 529 548 526 523 538 554 592 539 580 501 573 557 541 558 593 591 602 593 546 597 607 678 588 620 618 651 677 704 709 758 707 782 743 776 748 771 856 911 951 996 899 996 988 1027 936 988 1028 1013 1033 1016 1036 1033 1030 1015 997 993 973 936 960 922 889 903 857 904 880 877 849 824 759 782 825 759 812 750 731 791 758 766 791 756 730 783 815 796 813 832 843 879 879 974 961 1005 1024 1115 1085 1193 1199 1276 1401 1463 1584 1679 1681 1741 1833 1960 2108 2199 2279 2476 2497 2653 2823 2759 2819 2966 2928 2969 2980 2936 2805 2611 2638 2539 2376 2351 2238 2193 2028 2018 1969 1913 1900 1942 1825 1701 1637 1504 1411 1331 1238 1142 1118 998 1028 870 893 821 785 751 699 725 668 657 634 662 655 602 560 599 584 590 564 570 558 522 570 503 531 510 567 540 538 553 510 488 511 480 501 536 536 529 481 510 503 471 483 456 482 508 498 466 511 521 492 474 527 511 536 453 512 504 498 485 503 476 461 509 431 492 485 452 487 533 503 523 506 499 543 504 498 513 513 467 475 500 489 490 513 535 466 532 520 538 517 475 511 532 530 549 484 540 527 533 521 528 529 553 527 561 547 567 594 582 567 561 594 587 553 574 586 623 623 564 618 599 625 625 662 638 632 607 592 643 594 628 565 630 574 567 636 560 590 585 536 504 612 505 543 573 570 568 540 585 567 537 513 522 540 549 504 526 501 492 449 497 507 529 501 533 500 517 480 540 513 511 526 546 520 516 507 510 511 546 533 528 521 525 488 506 498 502 466 508 519 463 508 452 528 451 501 477 472 462 466 489 479 484 465 460 488 454 473 497 466 455 472 446 468 450 490 459 446 460 509 462 432 504 480 471 505 460 498 503 489 466 508 476 510 486 507 484 463 488 507 553 502 502 514 505 529 529 567 566 578 554 557 592 585 601 626 655 645 688 677 652 703 668 707 640 707 729 709 689 655 692 710 743 654 726 677 748 738 722 704 767 710 793 825 784 810 796 855 841 893 839 895 850 894 890 844 908 920 887 936 843 780 807 770 763 745 734 710 725 704 655 716 687 674 685 722 663 666 657 582 630 599 559 569 582 530 567 531 504 505 450 537 499 501 507 476 509 463 495 468 500 512 461 493 483 485 449 477 484 491 482 492 483 469 455 456 438 494 467 474 452 486 456 492 470 480 483 465 506 511 490 518 507 499 524 503 494 539 502 526 520 533 516 522 514 563 525 554 573 584 542 528 581 576 617 604 576 625 623 653 646 668 716 738 691 790 741 782 753 789 867 863 868 892 961 938 1013 1050 1085 1272 1221 1255 1351 1420 1481 1590 1697 1740 1888 1907 1966 2091 2246 2272 2270 2400 2596 2602 2619 2608 2670 2528 2533 2615 2329 2306 2215 2184 2107 2030 1917 1879 1801 1865 1781 1856 1704 1774 1688 1628 1526 1524 1494 1349 1255 1235 1123 1120 1028 1000 969 990 930 842 860 769 831 843 732 788 799 677 720 761 737 668 686 708 650 655 677 684 664 690 623 682 662 670 683 659 667 681 659 670 640 687 724 668 683 722 696 685 762 713 785 733 803 798 802 853 878 843 896 920 943 904 1012 955 1040 1069 1090 1125 1154 1200 1255 1305 1392 1389 1361 1436 1402 1550 1515 1591 1667 1594 1543 1513 1503 1554 1422 1407 1340 1232 1220 1237 1171 1163 1191 1194 1165 1057 1133 1078 1100 1065 1038 1004 928 891 914 821 805 747 776 743 727 668 715 686 655 693 661 663 644 692 639 672 671 617 660 659 610 616 623 610 652 687 622 631 609 606 629 591 624 664 606 583 612 601 610 589 549 620 580 565 569 609 560 557 599 530 551 518 510 532 523 548 531 579 553 550 548 589 549 529 557 580 557 544 535 571 580 572 559 531 593 572 596 566 594 604 558 593 607 579 587 610 547 587 568 616 573 614 572 599 542 621 589 518 591 526 545 531 554 589 528 573 547 559 546 517 533 516 567 520 460 479 483 469 439 478 492 485 509 469 459 495 509 512 425 462 474 483 439 433 408 464 460 422 452 473 486 446 438 457 433 463 446 430 440 415 432 448 451 420 426 421 416 458 447 407 464 434 437 459 429 462 428 410 448 456 453 487 475 463 427 444 513 459 446 412 460 400 464 431 496 492 493 439 457 506 445 444 443 493 481 474 458 491 537 451 500 466 539 496 526 527 542 535 540 532 526 602 550 545 586 544 585 580 564 546 535 590 567 581 552 515 537 563 562 561 562 598 547 566 568 538 564 580 546 566 573 558 566 577 547 573 585 611 582 566 564 585 593 633 637 660 682 665 703 693 695 749 700 708 744 762 780 755 794 803 782 790 795 788 729 728 770 784 778 839 805 790 812 812 865 849 873 830 862 880 906 873 878 877 862 860 887 818 883 826 795 778 757 777 795 827 778 756 673 758 706 715 717 740 734 673 666 692 684 690 640 623 600 566 600 583 583 524 537 528 536 497 548 516 478 517 472 492 469 500 463 461 473 522 466 485 465 437 414 467 452 482 452 461 458 443 482 471 415 438 400 453 439 444 473 404 444 413 417 420 409 400 409 475 414 435 416 404 445 426 422 454 423 452 439 440 447 433 447 418 442 450 420 440 437 419 428 426 443 443 424 405 467 441 425 440 418 422 426 440 435 496 434 475 451 413 408 450 428 438 419 467 462 465 464 436 459 453 435 487 460 464 471 467 494 442 460 497 476 478 499 503 499 529 500 502 535 540 545 490 523 483 598 522 550 548 535 583 594 567 572 564 554 581 535 599 648 592 609 621 612 619 596 572 573 572 584 584 566 547 585 583 511 573 542 554 546 543 540 539 569 515 511 498 481 552 487 479 482 492 475 505 463 459 515 462 464 432 451 451 468 444 474 437 432 435 441 470 435 452 417 414 448 440 438 440 416 421 456 390 414 417 414 407 381 423 413 400 387 412 407 429 421 408 389 407 400 437 427 429 443 368 387 434 410 402 422 417 434 434 384 464 402 434 449 417 475 467 403 431 465 470 418 465 428 417 443 465 451 453 439 437 446 441 462 444 479 469 501 449 514 440 509 485 512 544 463 524 548 542 520 537 573 541 546 581 564 596 534 599 543 548 549 557 510 486 582 535 499 563 500 503 516 523 492 524 497 525 552 502 472 470 462 456 483 473 487 495 475 491 456 437 489 438 483 480 443 435 458 461 454 428 457 463 439 481 445 440 481 475 419 509 459 464 478 464 472 477 509 447 479 477 496 518 498 493 519 532 553 549 562 578 543 634 595 601 618 650 634 646 658 698 724 710 739 738 726 688 745 752 688 709 679 636 697 663 650 633 614 647 625 579 633 585 613 676 622 621 616 619 646 608 613 598 554 568 552 544 569 533 553 508 538 515 493 523 552 459 474 502 462 496 442 499 457 495 500 493 444 496 507 478 475 469 479 435 456 484 406 500 530 486 440 487 462 448 478 430 469 435 437 424 435 469 448 470 417 472 479 445 488 453 416 459 496 445 471 478 478 431 429 446 480 461 432 491 484 465 480 499 525 525 466 488 507 529 536 535 483 508 521 498 488 498 456 473 463 482 501 465 483 477 455 532 491 494 487 449 470 445 449 439 491 431 456 419 414 420 425 421 419 411 438 425 456 444 436 425 430 366 409 392 406 420 366 384 418 429 421 396 384 382 443 384 408 359 385 402 392 393 392 408 386 378 388 382 414 388 421 362 411 407 374 369 375 399 383 421 394 439 380 390 414 427 443 396 410 377 404 410 382 381 397 396 394 387 370 383 422 393 420 360 449 384 379 401 374 388 388 382 413 358 414 396 434 394 380 364 392 408 391 381 402 369 389 371 366 367 388 386 379 376 386 391 393 379 370 426 389 404 373 382 395 375 406 375 379 373 356 381 387 402 364 402 365 352 341 387 388 405 358 385 408 396 366 375 380 384 416 411 349 362 354 430 404 377 390 380 400 349 389 353 373 374 391 368 378 375 401 390 368 362 390 358 376 409 377 400 387 375 344 373 367 386 368 394 367 396 354 362 418 403 410 403 367 378 427 378 380 403 360 376 435 394 397 369 391 426 403 420 385 403 390 424 366 394 396 376 423 398 399 380 409 356 403 421 392 409 425 401 402 399 399 396 375 411 439 404 423 396 399 403 423 456 429 437 441 446 461 441 450 429 459 484 448 507 477 482 495 474 560 468 536 550 528 543 584 514 577 562 564 607 571 594 546 608 535 528 538 558 520 506 542 497 558 530 467 537 508 503 485 496 473 482 450 506 467 551 446 471 504 469 480 441 438 409 432 402 416 465 422 419 416 414 404 406 456 380 422 382 424 401 411 399 386 395 400 382 379 370 417 401 438 349 359 381 398 412 378 371 386 362 373 410 413 394 389 398 366 387 380 395 409 403 384 384 411 395 414 411 388 374 382 391 387 426 390 408 382 398 356 460 384 400 420 448 411 409 432 426 450 409 438 450 393 423 440 412 431 405 412 405 467 424 478 409 433 462 403 434 454 457 433 430 440 418 400 445 452 427 460 424 426 443 455 428 427 448 420 434 423 442 391 449 425 386 431 394 409 412 398 462 409 399 408 371 385 426 398 374 370 386 407 389 418 394 378 426 372 393 433 398 381 426 357 389 400 387 410 417 434 379 402 398 369 332 410 403 389 402 415 384 407 365 425 417 407 410 366 462 404 409 399 389 390 355 436 387 377 405 418 375 360 402 394 402 417 411 418 440 428 375 436 405 397 404 440 428 432 453 427 427 432 420 439 453 439 430 445 399 469 426 463 425 428 414 420 418 402 382 411 426 404 422 473 433 390 432 388 443 445 435 416 456 418 420 452 381 405 408 406 405 400 416 414 424 412 421 415 411 407 407 396 399 414 413 392 391 402 443 400 434 391 438 399 431 423 425 386 429 387 419 362 394 444 383 407 450 430 403 440 404 430 446 405 437 400 412 440 422 440 467 397 435 454 436 409 377 429 409 414 416 445 421 427 416 430 434 402 439 394 404 412 429 403 424 409 418 399 396 428 419 383 432 469 437 371 410 431 428 427 450 447 449 417 455 454 489 461 465 418 458 457 506 441 436 413 443 425 376 387 418 438 418 425 421 423 418 406 406 432 423 429 456 381 419 450 418 423 399 425 406 404 422 370 406 360 416 415 376 381 433 423 405 373 432 402 362 415 372 392 345 389 399 405 387 400 372 428 393 396 401 421 367 405 410 426 347 401 421 387 382 435 408 413 457 431 435 423 403 401 418 435 404 415 443 398 416 445 436 417 498 480 427 423 418 400 440 428 432 443 458 448 453 438 456 456 498 479 489 469 463 464 445 446 475 464 457 459 454 462 464 455 441 450 482 474 455 438 504 452 445 445 467 432 441 447 450 457 410 453 445 396 432 437 392 399 440 380 403 463 447 448 407 472 454 413 418 444 405 406 375 409 402 406 393 372 401 400 422 403 415 372 441 392 423 390 355 386 441 411 454 385 395 351 430 397 429 421 429 375 380 395 414 391 422 429 394 401 396 370 389 417 408 401 411 367 399 379 385 407 400 368 392 417 394 381 388 405 401 348 403 397 391 412 380 399 419 387 401 398 422 409 398 368 407 408 386 411 393 412 428 379 424 421 407 399 401 421 406 431 421 429 430 427 432 403 398 435 452 416 447 425 431 419 470 443 415 487 448 406 442 424 438 478 449 507 453 464 458 447 456 476 447 529 482 434 483 462 451 466 458 506 494 441 460 433 436 450 461 447 466 467 449 484 453 443 462 434 468 460 475 461 426 442 463 454 497 448 454 475 460 417 427 455 443 430 423 442 490 458 439 446 443 528 441 459 458 465 504 490 469 520 485 491 516 538 505 521 471 512 546 542 524 546 568 592 604 656 619 667 665 705 743 749 742 782 818 819 828 867 924 1001 933 981 1006 1078 1002 1091 1045 1075 991 1055 932 931 862 866 907 878 797 829 785 846 792 787 769 782 763 836 836 845 788 750 753 827 854 782 787 807 675 699 653 672 679 614 592 673 593 555 549 604 529 511 560 492 490 517 502 518 473 509 503 513 482 470 471 493 464 463 439 474 451 426 433 449 467 445 460 447 437 449 482 435 475 436 482 468 426 465 436 421 457 450 456 480 458 444 466 464 472 462 474 483 462 490 452 460 491 528 515 505 520 468 478 493 486 494 461 476 503 463 437 471 466 432 463 493 486 443 470 433 450 452 462 450 473 419 455 451 415 476 478 443 441 424 429 422 391 478 430 413 459 376 418 417 451 403 389 414 417 424 392 455 412 423 417 446 405 409 410 416 374 407 392 340 415 400 393 377 400 382 411 413 369 403 342 392 412 396 419 389 406 385 412 401 409 399 388 348 392 400 379 388 395 405 399 380 371 380 381 385 372 419 390 407 342 373 379 362 410 388 385 420 431 385 406 367 404 391 393 407 372 403 406 459 409 469 423 423 394 446 385 412 404 418 379 405 407 402 391 408 395 423 413 423 406 377 385 406 427 413 432 420 437 444 396 454 436 472 474 429 447 460 477 479 435 463 451 472 504 494 489 505 533 520 568 554 587 558 574 598 614 622 638 624 647 627 674 661 617 661 686 650 696 656 736 666 645 693 627 596 633 596 594 553 583 616 549 580 592 610 578 595 569 557 588 582 563 566 568 583 585 538 570 578 574 554 563 542 509 530 538 493 499 512 485 501 481 476 506 527 484 479 496 515 494 498 498 477 468 490 489 477 480 503 518 472 472 488 469 442 499 502 441 411 454 459 456 439 479 452 441 438 466 473 489 451 458 484 467 447 453 448 451 464 419 420 430 464 430 514 449 430 448 443 450 460 470 410 466 438 444 447 426 455 445 468 444 430 441 407 416 454 455 436 437 438 434 421 413 426 453 426 423 454 452 429 477 395 435 417 485 424 422 459 420 440 414 444 431 420 425 437 390 472 479 444 419 422 463 426 421 440 424 455 453 435 453 424 455 460 481 465 462 454 442 471 421 453 466 498 439 442 473 438 468 440 466 440 506 468 541 453 494 513 501 477 504 547 513 540 532 610 554 579 594 605 564 527 561 640 708 681 719 690 668 669 765 761 849 829 866 854 908 950 940 1062 1079 1028 1042 1110 1075 1111 1169 1142 1080 1005 968 964 913 922 840 844 870 812 814 831 850 766 824 776 769 758 779 804 837 791 836 887 841 784 792 780 773 728 713 679 688 622 648 617 632 651 586 557 550 529 526 516 547 500 493 457 508 496 464 466 454 454 448 486 443 424 421 467 411 452 420 457 442 420 442 455 451 425 381 432 400 421 458 410 419 418 411 406 401 398 403 425 384 401 382 408 439 415 412 384 441 395 423 366 395 392 413 384 402 413 397 388 352 391 400 402 393 405 370 389 421 381 401 421 367 378 374 418 405 407 385 401 403 365 409 412 382 387 383 400 377 410 390 424 403 378 377 390 378 380 405 361 380 399 413 388 372 397 388 396 423 411 395 408 393 403 388 426 381 409 394 359 387 361 370 385 423 389 394 429 390 393 421 425 408 388 413 384 351 415 381 403 392 366 368 375 376 384 402 397 375 409 394 395 385 378 416 385 388 402 428 426 407 451 388 424 398 388 364 404 432 405 429 436 400 394 414 402 437 426 417 431 384 435 381 392 418 423 440 394 423 417 438 410 434 404 405 405 446 379 420 429 426 426 437 422 428 443 427 455 419 484 427 455 411 421 440 465 430 479 424 424 447 453 421 438 427 417 459 463 452 478 474 431 476 520 490 535 496 514 521 556 580 545 551 581 594 570 625 601 630 685 690 696 714 761 759 735 769 748 734 793 746 688 687 605 668 598 648 580 607 522 558 628 645 608 540 594 536 574 580 553 580 569 555 585 638 602 631 583 603 592 591 589 583 574 532 551 488 496 490 493 488 482 472 491 504 448 454 449 468 487 473 459 459 429 469 443 443 496 464 464 530 486 485 453 423 451 454 423 456 435 463 460 446 438 472 448 430 431 460 457 473 446 463 470 509 429 456 454 464 472 462 490 453 422 483 475 479 464 447 450 473 477 472 482 445 466 464 437 433 472 448 462</counts>
			</dataPoints>
		</scan>
	</xrdMeasurement>
</xrdMeasurements>