File: dataset/precursor_mixture/V2O5_La(OH)3_Y2O3_Li3PO4.12-min.xrdml
<?xml version="1.0"?>
<xrdMeasurements xmlns="http://www.xrdml.com/XRDMeasurement/2.2" xmlns:xsi="http://www.w3.org/2001/XMLSchema-instance" xsi:schemaLocation="http://www.xrdml.com/XRDMeasurement/2.2 http://www.xrdml.com/XRDMeasurement/2.2/XRDMeasurement.xsd" status="Completed" recordIdentifier="{FC94D147-5E53-4DE9-9314-5546A19C43B1}">
	<comment>
		<entry/>
	</comment>
	<sample type="To be analyzed">
		<id>dara-35-2</id>
		<name></name>
		<preparedBy></preparedBy>
	</sample>
	<xrdMeasurement measurementType="Scan" status="Completed" sampleMode="Reflection">
		<usedWavelength intended="K-Alpha 1">
			<kAlpha1 unit="Angstrom">1.5405980</kAlpha1>
			<kAlpha2 unit="Angstrom">1.5444260</kAlpha2>
			<kBeta unit="Angstrom">1.3922500</kBeta>
			<ratioKAlpha2KAlpha1>0.5000</ratioKAlpha2KAlpha1>
		</usedWavelength>
		<incidentBeamPath>
			<radius unit="mm">145.00</radius>
			<xRayTube id="1010048" name="Empyrean Cu LFF HR (9430 033 7310x) DK430614">
				<tension unit="kV">40.0</tension>
				<current unit="mA">15.0</current>
				<anodeMaterial>Cu</anodeMaterial>
				<focus type="Line">
					<length unit="mm">12.0</length>
					<width unit="mm">0.4</width>
					<takeOffAngle unit="deg">6.0</takeOffAngle>
				</focus>
			</xRayTube>
			<filter id="20010004" name="Beta-filter Nickel">
				<material>Ni</material>
				<thickness unit="mm">0.020</thickness>
			</filter>
			<sollerSlit id="21010002" name="Soller slits 0.04 rad.">
				<opening unit="rad">0.0400</opening>
			</sollerSlit>
			<mask id="22031000" name="Fixed mask 13 mm">
				<width unit="mm">9.00</width>
			</mask>
			<divergenceSlit id="22120001" name="Divergence slit 1°" xsi:type="fixedDivergenceSlitType">
				<distanceToSample unit="mm">50.00</distanceToSample>
				<height unit="mm">1.52</height>
			</divergenceSlit>
		</incidentBeamPath>
		<beamKnife id="29030100" name="Beam knife low"/>
		<sampleMovement xsi:type="spinningSampleMovementType">
			<spinnerRevolutionTime unit="seconds">1.0</spinnerRevolutionTime>
		</sampleMovement>
		<diffractedBeamPath>
			<radius unit="mm">145.00</radius>
			<antiScatterSlit id="22090040" name="AS slit 9 mm" xsi:type="fixedAntiScatterSlitType">
				<height unit="mm">9.00</height>
			</antiScatterSlit>
			<sollerSlit id="21020003" name="Large Soller slits 0.04 rad.">
				<opening unit="rad">0.0400</opening>
			</sollerSlit>
			<filter id="20030001" name="Large beta-filter Nickel">
				<material>Ni</material>
				<thickness unit="mm">0.020</thickness>
			</filter>
			<detector id="7010019" name="PIXcel1D-Medipix3 detector" xsi:type="rtmsDetectorType">
				<phd unit="keV">
					<lowerLevel>4.0</lowerLevel>
					<upperLevel>11.3</upperLevel>
				</phd>
				<mode>Scanning</mode>
				<activeLength unit="deg">5.020</activeLength>
			</detector>
		</diffractedBeamPath>
		<scan appendNumber="0" mode="Continuous" scanAxis="Gonio" status="Completed">
			<header>
				<startTimeStamp>2024-02-18T13:42:17-08:00</startTimeStamp>
				<endTimeStamp>2024-02-18T13:54:45-08:00</endTimeStamp>
				<author>
					<name>AutomatedUser</name>
				</author>
				<source>
					<applicationSoftware version="1.4b (28)">PANalytical Aeris Instrument Suite</applicationSoftware>
					<instrumentControlSoftware version="2.0.0 20210224">AERIS</instrumentControlSoftware>
					<instrumentID>950485</instrumentID>
				</source>
			</header>
			<dataPoints>
				<positions axis="2Theta" unit="deg">
					<startPosition>9.99043322</startPosition>
					<endPosition>100.09495370</endPosition>
				</positions>
				<positions axis="Omega" unit="deg">
					<startPosition>4.99521661</startPosition>
					<endPosition>50.04747685</endPosition>
				</positions>
				<commonCountingTime unit="seconds">18.249</commonCountingTime>
				<counts unit="counts">3965 3996 3889 3940 3856 3969 3915 3962 3975 3857 3930 3906 3925 3814 3993 3973 3860 3934 3923 3767 3793 3828 3861 3837 3853 3853 3815 3771 3896 3862 3784 3772 3612 3833 3656 3877 3815 3841 3773 3859 3775 3793 3730 3732 3769 3827 3722 3792 3812 3711 3716 3652 3722 3709 3771 3723 3710 3737 3566 3669 3668 3693 3701 3760 3634 3616 3724 3549 3661 3782 3720 3735 3650 3690 3589 3635 3607 3576 3615 3578 3640 3547 3573 3572 3542 3550 3563 3531 3540 3655 3633 3558 3656 3529 3491 3552 3557 3514 3588 3450 3523 3499 3511 3443 3587 3477 3469 3482 3546 3497 3507 3471 3429 3551 3512 3503 3427 3475 3442 3342 3568 3457 3523 3376 3481 3408 3377 3405 3406 3383 3314 3403 3415 3393 3433 3397 3377 3390 3280 3361 3354 3309 3315 3295 3415 3316 3355 3329 3392 3319 3369 3342 3233 3296 3365 3314 3358 3253 3335 3406 3301 3321 3447 3249 3253 3194 3294 3249 3256 3296 3197 3269 3227 3302 3251 3164 3186 3185 3265 3219 3213 3164 3260 3198 3103 3214 3160 3217 3234 3257 3208 3083 3079 3201 3179 3167 3054 3109 3056 3171 3111 3235 3014 3162 3203 3197 3138 3221 3158 3141 3100 3191 3118 3089 3090 3245 3093 3109 3218 3190 3032 3023 3133 3020 3162 3013 3030 3017 2960 3152 2989 3103 3176 3163 3057 3083 3182 3087 3123 2967 2932 2933 3154 3039 2957 3060 2974 3133 2949 3008 2889 2942 2983 3081 3023 2942 2909 2962 2966 3010 2977 3038 3098 3073 2927 2997 2884 2853 3010 3015 3064 2943 2944 2916 2980 2869 3060 2816 2960 3039 3007 2916 2892 3025 2918 2911 2885 2981 2983 3044 2897 2943 2971 2926 2922 2858 2881 2924 2864 2845 2885 2826 2873 2873 3005 2993 2852 2873 2984 2855 2875 2923 2951 2790 2974 2956 2977 2881 2900 2902 2874 2973 2856 2853 2873 2842 2929 2817 2879 2830 2884 2893 2838 2858 2851 2886 2888 2835 2837 2894 2893 2814 2839 2803 2868 2827 2881 2905 2899 2810 2821 2926 2909 2836 2955 2837 2911 2923 2856 2825 2819 2833 2923 2867 2824 2848 2810 2874 2809 2892 2810 2768 2948 2792 2843 2797 2785 2766 2782 2826 2924 2794 2818 2862 2771 2901 2799 2685 2816 2841 2842 2802 2717 2753 2765 2780 2846 2777 2893 2786 2697 2849 2795 2787 2785 2681 2875 2761 2795 2762 2752 2862 2766 2798 2605 2647 2818 2773 2735 2776 2750 2869 2663 2704 2719 2786 2735 2775 2706 2776 2811 2758 2761 2757 2854 2718 2861 2807 2827 2794 2834 2836 2734 2828 2761 2912 2834 2791 2925 2781 2785 2885 2833 2936 2770 2835 2937 2850 2922 2934 2870 2964 2903 2914 3046 2950 2996 3064 3068 3080 3103 3275 3083 3077 3272 3259 3228 3348 3505 3382 3578 3703 3605 3753 3806 3953 4024 4149 4271 4392 4554 4572 4810 4825 5142 5170 5470 5748 5723 5859 6139 6155 6459 6519 6626 6605 6842 7197 7465 7894 8378 8576 8985 9302 9652 10221 10574 10663 11219 11204 11532 11423 11488 11403 11012 10927 10420 9913 9319 8647 8178 7556 7062 6671 6196 5865 5330 5089 4962 4694 4423 4195 4087 3848 3778 3900 3674 3626 3459 3494 3369 3246 3300 3207 3131 3200 3009 3072 3050 3042 3077 3087 2960 2911 2971 2992 2869 2837 2809 2847 2868 2815 2906 2821 2828 2844 2891 2729 2766 2707 2948 2732 2774 2618 2818 2629 2732 2793 2730 2810 2801 2853 2674 2694 2683 2714 2747 2681 2669 2668 2698 2703 2599 2744 2667 2713 2780 2749 2774 2616 2690 2687 2773 2695 2656 2713 2728 2888 2864 2774 2727 2773 2725 2850 2756 2708 2749 2779 2801 2847 2846 2866 2795 2856 2898 2994 2834 3041 2936 2878 2911 2857 2901 2783 2841 2866 2733 2716 2762 2640 2654 2700 2614 2634 2475 2707 2622 2603 2604 2642 2517 2544 2567 2543 2547 2507 2498 2585 2542 2562 2510 2504 2562 2465 2406 2559 2500 2504 2525 2489 2564 2539 2521 2585 2550 2456 2473 2373 2621 2368 2478 2474 2445 2515 2438 2510 2476 2523 2538 2483 2435 2467 2450 2495 2410 2424 2359 2410 2458 2537 2400 2548 2477 2464 2334 2416 2431 2347 2451 2525 2338 2408 2440 2496 2405 2446 2447 2428 2470 2426 2372 2400 2306 2459 2430 2371 2312 2456 2459 2388 2363 2305 2353 2391 2324 2393 2365 2334 2351 2346 2424 2380 2486 2425 2396 2472 2394 2409 2428 2457 2375 2369 2241 2443 2391 2379 2390 2364 2380 2345 2437 2432 2422 2376 2387 2441 2391 2319 2342 2349 2442 2394 2287 2353 2397 2309 2339 2359 2398 2435 2316 2291 2342 2351 2324 2327 2258 2365 2413 2321 2378 2301 2328 2305 2337 2373 2376 2315 2371 2294 2298 2284 2250 2304 2387 2249 2248 2285 2391 2273 2232 2255 2382 2287 2302 2258 2300 2364 2292 2307 2314 2297 2258 2190 2273 2268 2406 2262 2240 2255 2262 2284 2436 2321 2214 2350 2307 2326 2252 2282 2246 2236 2213 2222 2310 2242 2260 2299 2306 2295 2170 2176 2316 2274 2275 2319 2302 2237 2275 2204 2347 2332 2280 2138 2317 2226 2253 2226 2286 2172 2276 2268 2268 2239 2320 2292 2289 2238 2176 2284 2272 2388 2270 2337 2289 2362 2285 2339 2346 2289 2383 2322 2259 2366 2390 2425 2373 2360 2434 2373 2398 2381 2410 2406 2419 2471 2453 2439 2535 2548 2653 2589 2548 2696 2634 2694 2886 2917 2931 3089 3064 3228 3212 3333 3617 3861 3856 4162 4391 4550 4836 5162 5351 5642 6182 6421 6742 6896 7137 7398 7385 7389 7493 7141 6730 6551 6150 5818 5520 5346 5168 4914 4761 4782 4784 4790 4930 4949 5016 4825 4736 4570 4477 4230 4059 3842 3688 3444 3220 3075 3066 2830 2707 2584 2602 2559 2434 2383 2504 2297 2452 2344 2428 2284 2258 2298 2210 2279 2258 2275 2314 2340 2218 2223 2243 2197 2205 2141 2134 2230 2201 2228 2193 2032 2229 2179 2080 2181 2217 2170 2132 2198 2166 2149 2135 2162 2128 2109 2139 2111 2065 2133 2127 2175 2093 2142 2059 2119 2068 2219 2161 2141 2154 2181 2086 2154 2070 2187 2095 2172 2124 2204 2204 2214 2153 2329 2175 2286 2211 2270 2281 2255 2300 2355 2352 2310 2352 2436 2447 2605 2547 2601 2716 2821 2791 3048 3026 3116 3324 3173 3392 3299 3397 3232 3332 3217 3141 2995 2838 2874 2768 2715 2508 2352 2409 2445 2295 2391 2280 2256 2289 2286 2283 2282 2169 2150 2224 2266 2251 2352 2389 2274 2347 2268 2293 2351 2384 2451 2477 2530 2521 2532 2560 2671 2656 2886 2827 2924 2968 2988 3100 3107 3272 3246 3340 3384 3370 3464 3551 3468 3460 3294 3221 3228 2952 3024 2904 2806 2716 2624 2584 2383 2467 2391 2396 2359 2349 2296 2284 2276 2308 2189 2231 2255 2252 2245 2147 2179 2124 2119 2201 2163 2160 2112 2150 2132 2212 2141 2154 2161 2137 2111 2127 2173 2143 2163 2146 2177 2079 2192 2137 2174 2202 2229 2120 2162 2143 2243 2213 2339 2271 2348 2271 2388 2422 2493 2467 2504 2526 2634 2600 2620 2734 2715 2773 2833 2837 2949 2981 2858 2936 2847 2886 2913 2837 2936 2838 2946 2848 2879 2811 2930 2779 2850 2790 2902 2892 2846 2637 2627 2636 2508 2482 2465 2430 2268 2293 2206 2168 2119 2073 2061 2166 2034 2072 2113 2155 2155 2086 2026 2030 2075 2007 1947 1969 2057 2023 1899 2042 2017 1950 1938 1941 1978 1974 1959 1878 2019 1957 1902 1937 1909 1967 2002 1931 2023 1933 2007 1978 1866 1935 1982 1913 1865 1878 1939 1936 1935 1897 1996 2006 1990 1976 1949 1851 1853 1954 1919 1968 1966 1906 1952 1888 1996 1974 2011 1999 1989 1935 1946 1936 2006 1997 1886 1932 1975 1972 2020 2082 1980 1964 1961 1986 1923 1981 2033 1943 2031 1969 1959 2062 2047 2079 2052 2008 1966 2005 2039 2059 2059 2124 2078 2119 2123 2059 2286 2208 2237 2255 2273 2346 2382 2257 2338 2366 2463 2371 2396 2310 2404 2431 2400 2357 2318 2341 2424 2405 2198 2382 2358 2374 2439 2275 2364 2430 2283 2359 2250 2274 2232 2146 2187 2009 2161 2067 2053 1937 2056 1947 2012 1931 1954 2000 1938 2005 1928 1980 1934 1883 1976 2022 1875 1931 1944 1954 1951 1872 1987 1992 1918 1879 1958 1910 1854 1848 1938 1872 2008 1873 1973 2059 2014 2035 2002 2005 2072 2000 2074 1986 2042 2031 1890 1903 1986 1883 1968 1869 1919 1867 1910 1853 1902 1879 1819 1934 1842 1974 1836 1932 1852 1829 1847 1916 1891 1857 1892 1859 1898 1987 1952 1998 1965 2070 2056 2108 2133 2204 2319 2404 2558 2619 2731 2947 3031 3080 3310 3489 3778 3799 3884 3897 3737 3498 3452 3275 3170 2961 2811 2683 2445 2401 2164 2194 2118 2072 1979 2084 2007 2031 1942 1928 1980 1901 1955 1898 1913 1909 1935 2018 1915 1956 1915 1977 1947 2004 1874 2024 1929 1988 1901 2060 1948 2009 1933 1949 1993 2025 1963 1956 2018 2075 2066 1955 2054 2106 2089 2154 2098 2284 2142 2204 2189 2295 2220 2239 2275 2399 2417 2375 2439 2450 2518 2657 2625 2782 2867 2909 2916 3031 3226 3316 3444 3565 3772 3877 4160 4467 4702 4887 5150 5436 5918 6112 6544 6905 7209 7459 7734 8096 8198 8464 8672 8587 8506 8304 8270 8003 7847 7650 7241 6792 6608 6286 5638 5430 5256 5012 4628 4375 4217 4047 3740 3729 3539 3526 3418 3396 3286 3248 3105 3201 3107 3092 3088 3229 3132 3227 3103 3208 3241 3426 3447 3504 3712 3843 3976 4109 4521 4501 4847 5104 5390 5659 5988 6428 6797 7391 7931 8510 8860 9407 9685 10093 10614 10798 11204 11065 11325 11235 10850 10468 10108 9646 9096 8548 8192 7644 6867 6564 6054 5726 5419 5000 4677 4388 4182 3922 3822 3535 3481 3378 3144 3141 3082 2798 2948 2753 2849 2671 2649 2562 2541 2556 2503 2469 2393 2382 2433 2485 2342 2439 2275 2254 2242 2258 2280 2297 2296 2282 2281 2307 2251 2255 2219 2233 2224 2317 2346 2363 2361 2300 2390 2539 2476 2428 2394 2442 2433 2567 2613 2621 2737 2699 2767 2842 2897 2873 2999 3182 3281 3348 3554 3600 3872 4111 4500 4794 5183 5562 5960 6645 7127 8016 8650 9901 10770 12375 13966 15098 16729 18441 19879 21314 22820 23643 24135 23669 22759 21471 19916 18337 17002 15366 14041 12297 10575 9373 8058 6916 6000 5335 4794 4313 3999 3667 3504 3349 3174 3041 2923 2864 2698 2640 2593 2563 2529 2531 2354 2359 2208 2341 2151 2202 2209 2064 2145 2045 2067 2018 2067 1965 1980 1970 1908 1989 1935 1917 1925 1935 1956 1847 1848 1875 1807 1872 1856 1813 1902 1824 1861 1799 1817 1813 1821 1765 1844 1777 1748 1783 1821 1772 1828 1753 1779 1764 1731 1727 1803 1688 1749 1699 1744 1665 1728 1660 1751 1740 1780 1721 1706 1687 1715 1682 1683 1705 1712 1745 1707 1680 1619 1752 1737 1796 1684 1705 1708 1764 1708 1755 1707 1682 1732 1725 1728 1819 1734 1646 1707 1784 1760 1766 1673 1709 1723 1742 1727 1733 1682 1722 1658 1833 1683 1724 1709 1741 1723 1756 1797 1759 1705 1718 1720 1785 1821 1854 1780 1802 1813 1848 1926 1998 2117 2031 2152 2247 2256 2359 2416 2679 2730 2801 3103 3175 3261 3380 3475 3452 3563 3702 3527 3376 3480 3324 3060 2906 2826 2695 2588 2524 2405 2252 2182 2025 2039 1902 1920 1896 1763 1913 1867 1898 1891 1888 1857 1926 1961 1967 1945 2004 2012 2106 2111 2196 2209 2272 2367 2277 2459 2483 2528 2697 2683 2860 2932 2999 3108 3164 3089 3142 3198 3331 3284 3196 3136 3073 3000 2987 2802 2826 2639 2555 2546 2426 2309 2316 2218 2144 2126 2068 2038 2057 2003 1900 1901 1859 1889 1758 1766 1787 1836 1760 1622 1747 1724 1698 1666 1755 1701 1724 1689 1595 1681 1661 1606 1667 1558 1683 1625 1611 1624 1680 1596 1630 1626 1622 1689 1664 1723 1704 1751 1688 1841 1867 1895 1939 2029 2060 2094 2281 2275 2237 2372 2331 2343 2397 2279 2282 2206 2164 2076 2102 1925 1938 1883 1800 1774 1693 1646 1586 1542 1600 1633 1540 1548 1633 1493 1553 1499 1624 1647 1528 1632 1533 1575 1592 1576 1542 1528 1519 1565 1547 1614 1551 1503 1611 1566 1492 1497 1520 1467 1577 1542 1579 1560 1586 1490 1515 1485 1534 1481 1531 1495 1505 1562 1547 1505 1553 1508 1561 1562 1523 1552 1541 1658 1587 1539 1620 1675 1721 1601 1670 1659 1745 1751 1897 1848 1844 1809 1925 1888 1947 1942 1953 1812 1932 1821 1848 1857 1846 1799 1810 1865 1788 1769 1837 1908 1824 1887 1866 2020 2015 1976 2188 2174 2220 2289 2557 2678 2839 2995 3104 3405 3596 3940 4341 4694 5193 5665 5960 6372 6546 6546 6886 6626 6436 6175 5960 5808 5568 5373 5135 4777 4646 4365 4123 3752 3487 3445 3141 3141 2871 2838 2706 2631 2582 2512 2431 2365 2386 2413 2226 2286 2276 2156 2272 2240 2290 2249 2336 2316 2352 2429 2533 2497 2584 2673 2570 2584 2635 2795 2642 2757 2566 2556 2449 2306 2206 2094 2046 1934 1954 1850 1885 1766 1708 1674 1729 1689 1640 1621 1640 1574 1527 1577 1586 1563 1534 1589 1529 1574 1593 1522 1595 1596 1490 1524 1514 1468 1550 1487 1547 1462 1529 1473 1461 1542 1484 1469 1559 1500 1478 1438 1489 1495 1538 1465 1506 1436 1455 1503 1432 1532 1438 1552 1535 1410 1494 1517 1410 1453 1506 1530 1456 1508 1513 1419 1375 1459 1449 1500 1447 1470 1483 1445 1454 1481 1425 1491 1449 1457 1441 1365 1488 1454 1442 1550 1481 1505 1464 1403 1536 1451 1547 1479 1544 1519 1488 1474 1519 1533 1497 1538 1509 1579 1493 1561 1543 1538 1541 1471 1495 1553 1500 1541 1538 1687 1572 1533 1684 1628 1758 1682 1697 1801 1898 1782 1972 2100 2073 2233 2320 2433 2449 2686 2766 2748 2783 2814 2800 2759 2729 2659 2823 2720 2700 2670 2587 2494 2487 2400 2339 2221 2147 2057 1977 2039 2043 1819 1822 1768 1758 1635 1756 1635 1629 1658 1588 1640 1540 1611 1532 1542 1552 1517 1526 1544 1493 1613 1487 1528 1591 1610 1604 1673 1655 1653 1666 1729 1702 1799 1868 1819 1795 1818 1840 1791 1874 1774 1746 1819 1722 1782 1807 1860 1730 1684 1619 1556 1674 1606 1673 1558 1576 1570 1586 1465 1562 1511 1635 1602 1583 1641 1522 1558 1578 1603 1550 1553 1521 1517 1615 1574 1540 1575 1659 1611 1621 1655 1678 1598 1695 1733 1637 1610 1634 1563 1628 1584 1524 1497 1506 1482 1474 1517 1500 1511 1450 1490 1437 1409 1387 1440 1398 1366 1464 1357 1381 1453 1505 1416 1422 1412 1520 1431 1487 1431 1440 1325 1319 1406 1381 1388 1396 1423 1438 1338 1436 1388 1368 1330 1258 1359 1421 1327 1341 1383 1284 1350 1311 1332 1306 1358 1347 1330 1310 1363 1405 1365 1351 1404 1360 1377 1403 1417 1418 1479 1486 1494 1556 1478 1505 1522 1564 1475 1564 1561 1536 1590 1500 1496 1498 1398 1426 1447 1382 1304 1420 1447 1431 1350 1328 1381 1305 1320 1386 1344 1389 1313 1331 1352 1332 1252 1411 1345 1341 1336 1429 1394 1324 1373 1327 1358 1288 1413 1317 1301 1387 1405 1390 1392 1361 1410 1345 1341 1299 1512 1338 1429 1424 1412 1388 1417 1390 1413 1417 1473 1475 1412 1454 1517 1448 1440 1395 1561 1453 1432 1573 1538 1594 1592 1507 1564 1589 1620 1583 1601 1589 1668 1599 1622 1625 1625 1598 1702 1573 1706 1635 1721 1725 1676 1774 1703 1769 1696 1766 1861 1863 1926 1865 1994 1978 1978 2070 2031 2085 2059 2248 2273 2373 2455 2509 2602 2733 2830 2998 3074 3189 3432 3706 3952 4001 4204 4498 4676 5051 5419 5510 5881 6137 6427 6499 6695 6963 7007 6981 7051 7037 7104 6788 6769 6541 6178 6184 5906 5679 5568 5182 5110 4740 4555 4291 4005 3809 3633 3603 3395 3363 3175 3178 3134 3060 3032 3058 3147 3153 3209 3208 3199 3209 3127 3113 2962 2836 2866 2552 2599 2523 2457 2460 2345 2286 2053 1941 1825 1863 1739 1712 1702 1687 1656 1663 1532 1560 1468 1475 1582 1468 1488 1500 1533 1392 1500 1440 1435 1365 1413 1521 1429 1477 1404 1404 1387 1422 1355 1436 1416 1333 1285 1316 1330 1396 1389 1413 1344 1336 1330 1297 1239 1371 1342 1369 1386 1284 1360 1309 1295 1316 1356 1257 1292 1315 1354 1320 1288 1295 1330 1214 1285 1292 1303 1277 1330 1240 1304 1242 1248 1295 1264 1215 1295 1277 1252 1215 1319 1272 1276 1322 1238 1336 1303 1297 1374 1338 1349 1292 1391 1294 1289 1389 1401 1410 1368 1383 1469 1407 1430 1447 1386 1401 1594 1547 1569 1654 1633 1649 1739 1802 1845 1758 1898 1901 1884 1891 1872 1816 1745 1722 1641 1688 1645 1622 1649 1558 1531 1506 1490 1388 1378 1408 1414 1386 1355 1351 1393 1395 1313 1321 1351 1371 1429 1373 1383 1461 1436 1527 1398 1434 1481 1493 1535 1535 1532 1510 1437 1476 1551 1509 1491 1464 1505 1500 1503 1505 1442 1500 1536 1519 1522 1492 1590 1669 1553 1628 1645 1726 1698 1785 1780 1943 1962 1966 1922 2030 2028 2075 2007 2100 2052 2172 2154 2281 2249 2333 2291 2319 2291 2231 2351 2284 2271 2278 2258 2270 2174 2231 2084 2016 2059 1954 1985 1925 1775 1833 1819 1850 1745 1705 1675 1604 1531 1548 1542 1425 1492 1459 1455 1455 1382 1372 1379 1363 1373 1356 1415 1313 1311 1270 1274 1353 1377 1376 1275 1256 1292 1225 1242 1293 1298 1204 1211 1314 1294 1221 1256 1289 1301 1307 1321 1197 1292 1177 1306 1282 1278 1300 1287 1276 1329 1272 1241 1276 1253 1219 1238 1215 1211 1291 1273 1281 1297 1293 1245 1343 1268 1284 1358 1274 1252 1346 1289 1344 1419 1380 1388 1322 1439 1367 1515 1512 1488 1478 1569 1636 1765 1881 1902 2117 2134 2343 2478 2562 2766 2745 2792 2917 2788 2753 2661 2415 2432 2423 2403 2319 2237 2184 2129 2031 1912 1836 1736 1591 1620 1477 1522 1459 1436 1450 1346 1347 1347 1305 1322 1273 1245 1252 1305 1280 1282 1300 1198 1238 1282 1218 1239 1191 1269 1278 1139 1236 1178 1202 1251 1242 1215 1141 1185 1085 1170 1180 1219 1215 1242 1226 1234 1180 1171 1237 1220 1174 1181 1154 1218 1219 1189 1286 1177 1270 1222 1174 1133 1180 1207 1181 1206 1165 1215 1170 1202 1226 1179 1205 1177 1179 1190 1112 1161 1113 1192 1106 1179 1135 1234 1228 1097 1228 1141 1136 1183 1130 1165 1212 1138 1192 1219 1155 1161 1119 1211 1200 1111 1108 1174 1187 1206 1243 1214 1194 1095 1177 1133 1163 1251 1113 1219 1169 1167 1193 1154 1199 1114 1139 1114 1161 1156 1153 1228 1174 1183 1206 1118 1173 1175 1234 1279 1182 1213 1245 1168 1228 1227 1190 1184 1179 1190 1218 1303 1160 1155 1195 1208 1289 1161 1218 1270 1271 1216 1318 1329 1364 1354 1381 1375 1426 1479 1455 1473 1518 1514 1463 1476 1497 1551 1374 1406 1408 1405 1341 1352 1359 1415 1307 1299 1296 1325 1294 1182 1220 1257 1210 1179 1222 1136 1190 1206 1135 1150 1180 1157 1232 1217 1250 1161 1244 1173 1191 1131 1106 1121 1121 1108 1163 1155 1157 1126 1148 1208 1241 1189 1199 1212 1191 1131 1144 1090 1124 1172 1167 1214 1219 1173 1150 1220 1150 1179 1204 1197 1136 1136 1104 1150 1165 1184 1163 1154 1131 1193 1146 1229 1133 1214 1137 1149 1086 1153 1206 1208 1212 1238 1135 1200 1203 1157 1216 1196 1201 1248 1287 1304 1184 1235 1308 1251 1241 1292 1320 1185 1287 1289 1359 1293 1363 1360 1365 1382 1361 1373 1442 1496 1550 1594 1644 1595 1804 1842 1813 1894 2004 1987 2090 1979 2058 2033 2105 1999 2143 2134 2124 2184 2250 2268 2304 2330 2291 2330 2325 2291 2326 2307 2247 2219 2167 2213 2182 2088 2128 2148 2126 2102 2052 2043 2101 2146 2143 2042 2101 2162 2211 2275 2189 2312 2158 2089 2005 1972 1855 1896 1801 1813 1786 1822 1698 1781 1684 1681 1618 1693 1618 1525 1548 1536 1516 1506 1491 1497 1493 1387 1566 1507 1482 1531 1548 1619 1560 1636 1670 1637 1656 1708 1790 1810 1843 1850 1988 1954 1979 2128 2106 2030 2185 2061 2175 2093 2158 2274 2174 2260 2195 2220 2384 2414 2485 2461 2566 2571 2700 2755 2716 2795 2981 3016 3200 3286 3463 3371 3609 3568 3717 3673 3843 3926 3852 3991 3975 3974 4055 4089 4184 4190 4263 4311 4441 4408 4603 4660 5005 5118 5442 5918 6107 6997 7518 8260 9052 9821 10600 11624 12255 12606 12473 12688 11986 11793 11267 10958 10715 10523 10705 10575 10653 10414 10209 9775 9308 8902 8084 7543 7174 6697 6373 6057 5679 5505 5354 4957 5012 4556 4500 4180 3986 3916 3798 3545 3412 3296 3116 2970 2852 2789 2628 2543 2393 2420 2333 2316 2177 2156 2090 1988 1868 1882 1903 1832 1808 1775 1654 1695 1703 1625 1640 1635 1639 1540 1504 1555 1462 1536 1489 1453 1391 1400 1528 1442 1472 1424 1471 1412 1455 1459 1465 1448 1413 1527 1448 1545 1463 1491 1502 1472 1552 1484 1443 1463 1424 1449 1421 1478 1467 1427 1415 1426 1407 1480 1411 1475 1505 1464 1522 1478 1446 1437 1440 1528 1545 1516 1643 1713 1619 1583 1649 1668 1738 1731 1819 1820 1830 1783 1800 1743 1873 1859 1880 1871 1902 1905 1821 1902 1850 1848 1933 1736 1869 1951 1921 1919 1888 1866 1827 1695 1704 1678 1599 1663 1522 1598 1588 1507 1557 1493 1451 1444 1484 1482 1350 1396 1304 1297 1327 1262 1274 1271 1203 1194 1210 1217 1198 1239 1250 1231 1248 1178 1190 1260 1176 1213 1257 1245 1241 1291 1209 1202 1217 1217 1275 1272 1273 1245 1223 1235 1292 1275 1331 1306 1242 1299 1242 1270 1318 1218 1318 1268 1303 1194 1227 1292 1291 1303 1270 1266 1291 1278 1211 1255 1268 1294 1320 1281 1197 1268 1329 1310 1343 1322 1371 1340 1315 1365 1404 1487 1394 1561 1577 1722 1797 1805 1784 1756 1878 1809 1767 1645 1501 1545 1573 1513 1502 1559 1521 1511 1513 1549 1485 1402 1498 1362 1359 1250 1288 1284 1296 1310 1246 1345 1348 1280 1289 1278 1346 1269 1301 1308 1425 1356 1373 1318 1298 1281 1313 1360 1335 1235 1306 1255 1272 1251 1220 1217 1270 1245 1190 1227 1201 1225 1229 1190 1150 1166 1201 1294 1189 1241 1258 1245 1342 1268 1330 1345 1417 1345 1400 1487 1395 1351 1309 1217 1280 1204 1227 1273 1296 1227 1319 1275 1251 1230 1155 1206 1174 1165 1121 1188 1102 1109 1131 1113 1098 1130 1105 1109 1138 1116 1112 1126 1143 1202 1080 1070 1142 1162 1163 1176 1087 1173 1125 1192 1118 1138 1111 1152 1133 1109 1143 1094 1078 1128 1113 1096 1183 1085 1177 1123 1104 1126 1101 1051 1103 1088 1157 1100 1138 1136 1097 1151 1075 1089 1112 1070 1171 1170 1093 1086 1169 1107 1080 1172 1086 1156 1209 1181 1152 1139 1145 1192 1151 1247 1242 1204 1307 1379 1388 1470 1443 1527 1592 1763 1705 1912 1846 2020 2051 1963 1920 1899 1743 1748 1707 1615 1561 1533 1546 1604 1666 1572 1520 1510 1462 1437 1367 1313 1283 1264 1220 1212 1146 1235 1130 1109 1139 1149 1137 1130 1125 1120 1077 1128 1081 1072 1157 1122 1070 1118 1095 1128 1079 1067 1078 1039 1032 1100 1131 1125 1187 1127 1164 1141 1184 1089 1078 1108 1147 1101 1089 1131 1062 1051 1146 1118 1116 1103 1131 1064 1083 1070 1115 1100 1042 1075 1070 1010 1072 1025 1055 1037 1086 1063 1098 1022 1114 1042 1134 1070 1056 1091 1162 1121 1084 1085 1146 1089 1113 1078 1121 1096 1088 1149 1015 1162 1001 1140 1100 1031 1084 1095 1126 1104 1148 1116 1118 1128 1109 1214 1135 1170 1199 1152 1245 1183 1260 1185 1234 1246 1263 1319 1330 1355 1298 1346 1273 1320 1337 1381 1283 1306 1237 1313 1298 1328 1344 1262 1316 1297 1320 1332 1347 1375 1295 1265 1267 1265 1331 1396 1270 1256 1381 1347 1392 1397 1436 1527 1550 1478 1570 1611 1651 1631 1794 1709 1738 1772 1834 1905 1978 2038 2076 2178 2241 2126 2292 2194 2231 2275 2268 2350 2320 2206 2228 2189 2172 2160 2161 2129 2049 2054 1897 2014 1952 1885 1845 1748 1850 1723 1734 1677 1618 1530 1594 1603 1602 1569 1552 1668 1661 1635 1607 1583 1587 1479 1554 1508 1465 1464 1415 1402 1477 1386 1434 1425 1405 1451 1456 1372 1372 1410 1277 1327 1310 1425 1315 1296 1363 1358 1336 1366 1382 1363 1433 1439 1513 1509 1502 1537 1640 1618 1739 1724 1798 2025 1963 2107 2163 2242 2238 2307 2337 2394 2317 2289 2218 2178 2212 2256 2250 2101 2145 2254 2185 2119 2101 2025 1988 1900 1960 1888 1849 1835 1784 1666 1657 1647 1599 1550 1426 1565 1462 1416 1440 1412 1346 1359 1291 1264 1296 1308 1267 1248 1229 1301 1251 1272 1205 1239 1192 1235 1205 1144 1173 1194 1172 1223 1165 1150 1154 1156 1163 1179 1192 1136 1150 1088 1119 1160 1160 1181 1133 1104 1165 1213 1151 1196 1130 1197 1188 1193 1201 1235 1165 1214 1266 1293 1228 1222 1218 1218 1309 1280 1278 1309 1325 1334 1299 1323 1322 1252 1298 1451 1380 1385 1451 1393 1440 1442 1464 1519 1419 1588 1614 1565 1711 1768 1851 1997 2114 2264 2345 2581 2882 3109 3602 3865 4265 4902 5129 5775 6077 6280 6171 5830 5589 5205 4832 4422 4280 4013 4061 4059 4153 4167 4229 4299 4180 4108 3770 3486 3167 2886 2759 2584 2287 2103 2146 1993 1984 1835 1868 1798 1683 1671 1617 1592 1529 1513 1401 1419 1438 1400 1447 1313 1351 1425 1285 1299 1318 1374 1325 1344 1293 1250 1278 1246 1280 1187 1253 1279 1279 1235 1194 1206 1185 1281 1276 1145 1228 1228 1252 1214 1199 1260 1164 1198 1258 1203 1222 1295 1297 1270 1331 1254 1292 1316 1399 1380 1335 1341 1361 1341 1386 1363 1354 1309 1381 1410 1416 1520 1437 1486 1462 1558 1488 1505 1508 1458 1458 1583 1503 1483 1516 1521 1556 1504 1665 1627 1673 1651 1706 1701 1792 1843 2005 1974 2077 2134 2323 2436 2523 2472 2476 2437 2392 2337 2247 2171 2029 1838 1956 1827 1943 1911 1877 1917 1905 1803 1825 1758 1650 1543 1568 1398 1417 1320 1309 1277 1277 1227 1184 1175 1147 1122 1125 1134 1145 1121 1081 1112 1142 1038 1072 1113 1011 1040 1076 1028 1085 1097 1127 1099 1116 1065 1057 1092 1043 1028 1000 1077 991 1002 1080 1055 1008 1106 1070 1040 985 1112 1027 1015 1028 1044 1031 1082 1099 1054 1102 1015 1089 1032 1080 1065 1087 1061 1111 1070 1040 1125 1091 1137 1146 1094 1134 1202 1125 1084 1174 1152 1154 1109 1148 1135 1099 1091 1115 1161 1146 1124 1162 1129 1195 1240 1167 1226 1156 1238 1212 1205 1270 1408 1326 1439 1428 1641 1686 1843 1778 1857 2005 1974 1968 1940 1820 1805 1705 1738 1730 1593 1683 1549 1582 1666 1639 1625 1658 1628 1529 1514 1542 1457 1340 1336 1291 1369 1272 1247 1265 1216 1158 1174 1131 1193 1173 1127 1156 1155 1149 1179 1253 1132 1166 1217 1175 1216 1240 1188 1279 1237 1264 1329 1304 1335 1418 1337 1383 1484 1449 1609 1576 1498 1625 1647 1602 1613 1552 1566 1434 1424 1379 1450 1390 1369 1387 1343 1362 1324 1347 1275 1297 1314 1188 1161 1190 1165 1180 1127 1129 1124 1123 1120 1100 1042 1027 1045 1009 1100 1048 1058 1138 1019 1055 1018 1038 1055 1036 1061 1076 1035 1033 1146 1096 1110 1126 1105 1072 1142 1122 1089 1145 1207 1224 1280 1336 1316 1341 1320 1392 1461 1373 1275 1294 1295 1216 1282 1171 1205 1214 1240 1257 1308 1296 1281 1302 1255 1266 1274 1314 1331 1355 1482 1461 1460 1512 1473 1475 1396 1346 1311 1295 1225 1211 1161 1255 1169 1244 1243 1216 1267 1270 1230 1179 1145 1144 1124 1105 1087 1047 1094 1052 1101 1037 1081 1050 1036 1043 1024 1016 1008 1026 996 990 1046 1016 996 1072 991 981 969 1060 1028 993 953 975 962 1022 973 1009 1017 1036 982 1034 1039 1003 978 1022 999 991 956 971 958 1087 1010 1046 979 1041 986 1065 1057 1020 1081 993 1089 979 1015 1016 1038 1017 1070 994 1000 1062 1052 1039 1082 1092 1134 1155 1162 1188 1164 1252 1199 1249 1197 1215 1154 1155 1124 1081 1106 1151 1143 1131 1134 1086 1183 1179 1207 1170 1210 1138 1139 1060 1133 1099 1086 1111 1057 1084 1144 1145 1140 1153 1056 1148 1143 1164 1142 1164 1153 1163 1205 1184 1167 1209 1214 1221 1200 1289 1281 1306 1306 1383 1348 1297 1366 1417 1434 1510 1519 1491 1585 1572 1571 1667 1587 1718 1724 1782 1807 1705 1859 1865 1864 1824 1942 1935 1943 1895 1884 1971 1988 1920 1887 1908 1830 1842 1857 1802 1808 1804 1757 1792 1789 1705 1713 1735 1653 1611 1591 1602 1629 1485 1510 1568 1519 1465 1584 1456 1542 1482 1515 1468 1473 1549 1514 1540 1458 1524 1543 1596 1704 1693 1737 1863 1830 1876 1803 1772 1732 1605 1636 1592 1538 1485 1446 1451 1478 1516 1510 1593 1499 1459 1489 1459 1465 1414 1418 1330 1347 1399 1234 1257 1275 1248 1273 1218 1228 1211 1244 1220 1347 1300 1302 1322 1267 1320 1305 1313 1314 1315 1319 1354 1339 1352 1405 1416 1433 1395 1372 1342 1393 1361 1430 1384 1330 1318 1296 1403 1268 1308 1289 1253 1226 1298 1231 1324 1229 1212 1269 1209 1262 1193 1168 1183 1180 1105 1120 1150 1077 1138 1094 1066 1097 1131 1105 1137 1075 1119 1135 1055 1094 1146 1025 1086 1072 1098 1066 1047 1116 1015 1069 1155 1125 1081 1133 1127 1172 1122 1185 1153 1138 1194 1200 1251 1331 1335 1362 1335 1357 1294 1298 1287 1266 1205 1264 1255 1232 1288 1258 1408 1238 1338 1324 1441 1338 1340 1309 1291 1406 1319 1328 1296 1263 1211 1143 1112 1143 1170 1212 1172 1111 1120 1156 1144 1097 1120 1099 1143 1120 1099 1032 1033 1096 977 1103 991 1050 1080 1077 1003 1015 1035 994 998 983 988 1035 1040 938 1051 974 1042 1005 1000 940 1041 917 974 921 986 1022 974 983 986 993 963 940 927 920 958 967 956 1004 959 905 946 928 968 955 1002 905 970 935 926 981 933 1032 955 999 972 902 959 973 909 985 916 934 956 982 919 959 940 983 926 915 950 950 931 915 904 936 856 943 922 918 1017 962 946 965 918 931 942 995 1044 931 994 981 983 967 998 1013 918 977 938 922 991 968 933 985 970 943 1003 945 966 992 1000 968 938 948 1026 989 1016 1047 1053 970 1026 926 1008 981 933 1049 1001 996 1018 1051 1020 1083 964 1048 941 1059 1023 1095 1046 1060 1035 1042 1078 1035 987 1037 981 1063 1053 1052 1075 1054 1014 1097 1089 1058 1115 1076 978 1111 972 1037 1004 1051 1042 1065 1000 1034 1047 1047 1056 996 1019 1086 1072 1078 1041 998 1058 1017 1025 1109 969 1008 1004 987 1027 985 1035 989 1005 1018 991 1105 997 1033 973 1041 1006 1030 1010 1031 1098 1014 1008 1041 1018 1010 1056 975 958 1002 973 995 1005 1047 1020 1004 1049 1031 1018 1037 1064 1054 1079 1085 1073 1073 1146 1124 1115 1142 1114 1083 1127 1062 1105 1119 1040 1041 1006 1078 1040 1055 1080 1052 1068 1071 1018 1100 1059 1034 1025 1000 1071 1019 1047 1072 1054 1112 1061 1104 1064 1095 1065 1068 1076 1132 1149 1131 1056 1157 1170 1216 1217 1186 1195 1184 1239 1261 1174 1254 1288 1291 1367 1345 1368 1423 1477 1456 1564 1528 1544 1540 1606 1700 1630 1772 1770 1817 1856 1847 1782 1882 1851 1926 1945 1999 1887 2040 1993 2051 2039 2005 1949 1931 2005 1881 1907 1804 1803 1792 1711 1814 1657 1688 1624 1655 1635 1598 1579 1506 1549 1504 1419 1358 1387 1404 1312 1294 1264 1205 1220 1190 1222 1248 1185 1233 1160 1234 1201 1106 1121 1143 1121 1143 1173 1180 1052 1140 1096 1176 1219 1126 1173 1183 1193 1146 1162 1154 1128 1103 1146 1194 1118 1144 1094 1133 1059 1106 1101 1163 1086 1140 1127 1111 1100 1080 1045 1184 1090 1122 1104 1101 1124 1142 1173 1124 1151 1149 1166 1152 1185 1109 1169 1201 1230 1159 1237 1242 1257 1221 1377 1342 1280 1320 1383 1392 1302 1390 1391 1441 1506 1476 1496 1686 1665 1701 1805 1765 1886 1809 1825 1742 1758 1644 1498 1533 1425 1339 1419 1397 1440 1409 1419 1399 1451 1401 1483 1470 1447 1369 1402 1339 1247 1246 1144 1195 1093 1169 1101 1142 1121 1082 1122 1037 1105 1040 1031 1033 972 1012 1005 983 1017 977 1006 1048 1094 1016 928 962 1009 970 1032 936 1023 1031 1053 1043 1001 1073 1097 1083 1076 1046 1036 1071 1022 1099 1067 1027 959 1074 1023 1064 1094 1004 1077 1017 998 1047 1011 1040 957 969 1058 1065 1006 1081 1104 1030 1066 967 1063 1052 1022 1003 1067 1035 995 1091 1107 1124 1119 1088 1205 1221 1253 1331 1341 1398 1403 1527 1551 1570 1632 1604 1669 1645 1623 1614 1427 1447 1419 1292 1364 1284 1324 1274 1361 1348 1341 1436 1441 1453 1520 1396 1389 1464 1395 1312 1327 1361 1318 1293 1264 1334 1215 1307 1242 1258 1286 1277 1317 1256 1216 1232 1192 1240 1207 1199 1269 1165 1204 1099 1156 1135 1206 1142 1122 1165 1126 1141 1185 1101 1164 1145 1107 1154 1081 1109 1005 1128 1065 1143 1109 1116 1108 1052 1056 1111 1094 1053 1095 998 1063 1066 1029 1045 1070 1041 1077 1085 987 1076 1052 1101 1073 1052 1002 1123 1112 1046 998 1023 1030 1048 1041 1070 1051 1049 1126 1077 1110 1141 1090 1137 1163 1244 1230 1212 1288 1295 1323 1282 1299 1219 1140 1179 1131 1217 1121 1140 1133 1093 1099 1177 1197 1091 1131 1053 1191 1174 1151 1171 1093 1125 1159 1129 1057 1098 1042 1039 1044 1043 1060 1120 1026 1031 1010 953 1047 1015 1034 989 1005 1095 979 959 1022 934 1072 1049 963 1056 986 1001 1031 966 1009 1036 1037 981 1015 1062 960 1030 994 1044 955 1040 1045 1018 1069 1089 993 1042 1151 1025 1157 1109 1157 1139 1109 1171 1191 1155 1136 1116 1132 1076 1071 1054 1097 1067 1125 1075 1049 1030 1056 1070 1053 1121 1082 1131 1085 1144 1114 1136 1158 1078 1197 1194 1151 1195 1288 1291 1338 1259 1299 1264 1253 1241 1190 1158 1158 1077 1123 1166 1042 1131 1139 1063 1112 1155 1083 1137 1159 1151 1182 1177 1119 1149 1067 1097 1087 1051 1090 981 1014 1061 1002 1031 1010 1051 1027 1016 1022 1015 989 1005 1057 992 1003 926 943 990 1014 995 1006 1016 1049 973 955 993 1077 1082 1046 1025 1035 1015 1074 1066 987 1042 1062 1073 1092 1179 1116 1068 1145 1173 1155 1170 1164 1228 1163 1271 1177 1228 1261 1282 1286 1290 1264 1301 1305 1353 1361 1308 1361 1307 1344 1280 1352 1318 1378 1371 1443 1379 1407 1355 1512 1478 1418 1466 1395 1430 1484 1392 1563 1533 1473 1446 1515 1451 1480 1429 1465 1456 1398 1348 1515 1398 1450 1505 1523 1486 1502 1522 1478 1487 1525 1527 1506 1477 1470 1486 1448 1413 1402 1466 1378 1390 1352 1350 1330 1323 1380 1267 1379 1255 1311 1307 1292 1289 1221 1235 1277 1292 1276 1301 1228 1257 1238 1177 1223 1292 1188 1277 1247 1225 1242 1181 1234 1292 1241 1253 1193 1209 1206 1186 1303 1264 1206 1290 1308 1266 1298 1330 1312 1305 1300 1380 1359 1356 1348 1373 1384 1531 1426 1520 1464 1449 1549 1526 1553 1535 1580 1596 1578 1673 1702 1660 1658 1742 1753 1906 1792 1947 1911 2005 2124 2175 2121 2175 2201 2264 2201 2195 2319 2071 2147 2142 2057 2078 2081 2064 1978 2083 2062 2107 1992 2140 2080 2117 2089 2127 2199 2073 2029 1913 1889 1816 1812 1817 1843 1749 1748 1754 1654 1669 1678 1558 1634 1595 1563 1625 1547 1489 1463 1424 1462 1439 1369 1378 1372 1273 1334 1287 1359 1332 1332 1252 1268 1328 1258 1228 1259 1193 1217 1197 1291 1293 1237 1187 1233 1241 1204 1244 1226 1316 1265 1229 1238 1265 1259 1229 1191 1183 1288 1171 1306 1158 1136 1255 1187 1277 1247 1250 1256 1289 1314 1262 1306 1286 1377 1417 1476 1422 1570 1605 1678 1683 1750 1931 1901 2062 2235 2215 2266 2227 2281 2131 2061 1926 1881 1722 1693 1637 1572 1502 1555 1488 1543 1539 1559 1513 1592 1604 1693 1652 1544 1653 1602 1577 1461 1451 1373 1349 1388 1273 1235 1185 1130 1131 1087 1179 1080 1035 1081 1007 1013 964 1081 1019 994 965 972 1043 954 1025 951 1021 975 940 899 884 974 963 927 989 933 968 942 1007 889 902 927 972 888 935 835 924 929 940 915 942 878 894 919 917 950 910 875 918 951 944 874 926 900 878 865 846 879 946 915 999 952 913 935 931 976 868 945 925 929 919 884 912 906 910 908 976 902 881 893 893 913 902 920 948 908 863 909 901 918 900 944 978 945 925 937 889 888 949 887 903 882 992 933 940 982 907 897 975 903 981 949 951 966 922 980 901 876 913 900 944 915 938 919 985 890 962 887 882 862 908 927 921 889 890 929 969 944 924 881 883 908 958 921 955 975 958 944 976 958 939 947 943 1018 978 987 929 957 959 998 946 989 971 978 1017 999 985 954 1033 968 989 963 1033 1029 975 985 1166 1090 1110 1191 1148 1174 1301 1345 1321 1511 1465 1617 1696 1575 1591 1650 1553 1528 1537 1372 1351 1261 1200 1266 1183 1178 1185 1145 1193 1202 1226 1233 1281 1224 1333 1308 1330 1284 1296 1237 1274 1186 1148 1144 1074 1108 1041 1098 1015 995 1022 1026 992 941 963 949 977 968 975 940 952 883 930 973 899 969 948 948 905 878 917 940 920 909 942 902 961 934 893 947 968 947 973 979 975 954 1028 908 998 1005 923 966 945 1004 1023 990 1013 943 994 1008 940 990 936 1044 1031 1029 1018 983 1065 1060 1023 1089 1093 1092 1092 1102 1063 1160 1151 1118 1253 1161 1249 1263 1233 1258 1305 1273 1260 1302 1278 1273 1340 1238 1176 1231 1239 1192 1235 1206 1243 1206 1237 1227 1185 1230 1221 1244 1218 1186 1262 1132 1153 1152 1170 1112 1128 1169 1124 1129 1094 1152 1093 1011 1029 1045 1094 1108 1099 1119 1032 1036 1035 1016 1008 1018 1047 1041 1039 1068 945 983 961 974 910 950 1058 950 954 945 964 971 913 944 1024 893 954 907 978 883 944 846 936 938 912 859 889 888 949 951 897 963 961 973 914 926 903 962 904 949 927 880 998 942 903 920 898 949 934 951 952 1036 954 968 992 1062 1091 1052 1059 1011 1036 941 979 916 1000 928 979 953 953 945 926 901 934 925 933 977 961 961 897 984 914 938 979 931 1013 979 916 908 937 883 938 953 869 946 896 965 905 876 953 808 964 919 921 913 977 952 935 904 966 932 939 891 913 894 901 870 882 952 875 942 932 923 848 947 886 926 928 937 857 980 922 953 934 967 859 918 918 928 863 936 911 1008 891 927 935 903 925 882 896 907 1014 894 973 953 969 948 936 958 1004 1007 1048 1052 1055 1039 1101 1149 1150 1228 1155 1245 1293 1196 1242 1210 1145 1173 1143 1089 1101 1058 1074 1091 1079 1037 1078 1088 1027 1085 1067 1177 1083 1195 1123 1159 1154 1156 1182 1140 1087 1090 1047 1004 999 1041 1060 1013 1035 1068 1007 1040 1003 1040 962 994 977 997 1006 1044 942 975 959 952 887 978 993 987 928 896 983 911 946 962 941 919 910 978 928 915 950 938 925 929 995 935 1011 915 925 976 973 999 966 910 908 935 910 896 954 917 961 942 897 925 905 918 912 940 926 975 918 961 1018 942 956 929 976 962 985 945 876 947 913 846 869 985 941 988 960 945 892 930 898 911 913 923 901 895 886 865 893 891 901 926 875 901 920 951 900 912 903 873 939 980 925 957 874 943 911 889 834 853 912 826 923 895 885 939 893 836 921 893 924 889 900 896 923 854 929 880 933 853 897 970 903 856 876 960 905 905 934 920 968 908 939 888 917 995 929 935 941 894 954 938 935 955 896 943 906 888 971 932 930 926 999 932 1042 1041 1022 966 1015 995 1037 963 960 987 997 1026 1034 1231 1066 1111 1141 1152 1190 1221 1217 1131 1148 1155 1104 1135 1094 1003 1046 966 986 982 952 1024 964 1044 979 974 1043 943 1003 999 1025 1108 1085 1079 1137 1035 1015 1012 1036 944 973 944 894 972 911 952 924 910 960 926 890 948 901 893 847 844 861 906 930 882 886 870 892 906 861 899 887 880 813 980 847 909 849 869 914 876 902 891 909 898 828 899 892 940 884 915 890 906 888 891 948 897 920 950 949 860 922 855 905 935 998 938 889 961 882 970 923 1003 897 990 929 934 924 918 943 965 997 1006 1006 959 945 952 944 1054 1052 1050 1082 1045 982 1084 1061 1160 1157 1076 1082 1133 1172 1131 1178 1323 1214 1279 1253 1267 1277 1184 1217 1221 1211 1272 1270 1208 1313 1309 1286 1286 1277 1315 1310 1233 1303 1294 1274 1259 1282 1384 1208 1241 1240 1250 1251 1201 1263 1250 1195 1224 1158 1162 1155 1170 1217 1140 1201 1155 1114 1133 1245 1114 1083 1121 1107 1096 1120 1048 1110 1087 1055 1058 1070 1021 1041 1064 997 993 995 1036 971 994 1022 1042 1009 1026 1058 1031 1038 1029 1056 1054 1014 1084 1030 1110 1085 1241 1068 1227 1212 1181 1251 1232 1306 1172 1298 1252 1243 1232 1186 1147 1124 1099 1100 1162 1066 1060 1104 1122 1091 1114 1128 1106 1159 1187 1099 1164 1226 1174 1263 1206 1209 1200 1194 1170 1103 1141 1075 1165 1071 1103 1107 1082 1115 1078 1141 1055 1109 1114 1106 1060 1099 1118 1178 1097 1127 1124 1139 1081 1138 1137 1132 1179 1186 1228 1090 1177 1150 1171 1124 1078 1201 1126 1251 1201 1185 1202 1158 1187 1152 1112 1120 1161 1120 1154 1131 1141 1135 1244 1142 1070 1189 1092 1151 1150 1224 1155 1193 1208 1234 1206 1287 1289 1333 1409 1404 1482 1484 1640 1630 1729 1725 1721 1756 1764 1747 1750 1732 1658 1595 1459 1472 1435 1395 1327 1301 1332 1296 1290 1249 1235 1249 1331 1257 1280 1292 1292 1349 1409 1347 1350 1413 1363 1387 1327 1316 1312 1193 1178 1094 1161 1178 1094 1037 1139 1049 1044 1053 1070 1068 1088 1067 960 1002 978 1059 1047 1015 1011 1000 1007 966 1062 1006 1044 1015 1079 1001 1068 1030 1029 985 976 1002 1014 987 981 976 992 957 1007 951 948 945 985 943 990 991 971 980 954 1019 919 1000 961 1007 915 911 943 994 1001 974 996 958 1055 1048 1088 1128 1124 1122 1130 1213 1194 1267 1171 1263 1234 1190 1208 1135 1144 1103 1085 1046 1116 1057 1019 1120 1026 966 1051 1002 1010 1062 1081 1124 1079 1019 1007 992 1026 1068 1088 1025 1101 1103 1000 1083 1048 1012 1050 924 963 993 967 941 959 931 904 985 940 919 912 920 924 940 892 853 945 910 900 962 912 901 922 927 989 991 956 915 897 853 920 891 892 912 895 907 816 934 882 906 887 929 967 943 915 960 934 889 937 877 872 959 905 921 899 947 922 868 916 889 996 1004 889 925 903 1011 963 1072 985 983 1032 994 1046 1020 1118 1086 1042 1109 1026 1052 1030 964 991 969 953 923 928 943 928 933 975 975 975 923 889 1017 957 962 969 949 950 1021 1013 1042 956 993 973 979 929 983 988 942 916 928 887 863 862 880 863 872 846 917 878 949 887 903 870 899 846 903 860 957 876 881 880 906 910 928 903 902 846 883 871 879 871 828 862 888 858 898 865 932 895 899 906 876 949 850 863 847 876 876 850 888 881 840 889 926 926 920 846 923 849 914 892 904 868 886 985 996 962 964 929 949 958 1008 1035 972 990 966 898 976 919 909 923 958 913 924 912 929 909 977 867 906 895 940 915 916 944 857 910 950 917 912 904 948 988 965 946 946 939 933 959 949 973 874 938 912 872 968 877 867 931 944 950 917 881 958 938 988 982 1046 973 974 997 940 932 986 1030 996 971 994 1048 999 975 1040 1094 1017 1028 1076 1043 1060 1108 1053 1085 1135 1089 1070 1107 1099 1117 1117 1064 1113 1106 1196 1163 1158 1246 1268 1223 1255 1172 1258 1306 1294 1323 1437 1420 1528 1475 1474 1499 1559 1562 1601 1621 1667 1611 1704 1577 1628 1486 1645 1544 1544 1427 1521 1419 1392 1422 1360 1332 1354 1295 1305 1343 1311 1380 1324 1339 1341 1399 1372 1346 1377 1380 1353 1395 1295 1347 1289 1290 1201 1254 1271 1282 1227 1218 1188 1134 1101 1085 1120 1147 1103 1181 1042 1108 1094 1090 1037 1057 1051 983 1060 954 1106 1075 1076 1058 1065 952 1024 1022 1031 1032 1026 1043 1073 1022 1051 992 1058 1059 1000 1063 1007 1029 1060 1139 1064 1144 1070 1069 1025 1111 1008 1116 1127 1105 1123 1080 1134 1155 1182 1098 1210 1140 1165 1171 1167 1219 1241 1243 1173 1254 1171 1232 1264 1244 1210 1214 1135 1233 1133 1226 1301 1185 1223 1215 1177 1190 1151 1152 1121 1170 1161 1134 1067 1123 1083 1115 1060 1086 1058 1169 1131 1076 1085 1104 1138 1123 1083 1081 1090 1083 1045 1060 1009 1057 1019 1030 988 962 1058 1011 993 1020 995 935 962 1031 988 961 1006 946 933 964 956 1023 952 945 973 1030 897 974 888 944 995 937 994 971 900 973 963 934 1000 895 992 981 1006 934 969 918 971 943 973 964 1026 1001 973 1027 952 979 1091 1061 1084 1083 1097 1090 1141 1155 1187 1329 1325 1323 1351 1419 1457 1446 1418 1462 1412 1440 1423 1362 1307 1323 1293 1210 1189 1169 1161 1123 1144 1105 1097 1082 1123 1120 1087 1139 1118 1119 1114 1114 1092 1149 1206 1177 1220 1222 1200 1281 1193 1154 1131 1109 1068 1064 977 1017 974 979 1020 970 1034 926 959 985 929 919 909 952 895 985 917 894 949 849 887 899 911 952 942 916 924 958 945 936 938 942 963 882 885 966 945 895 910 888 910 853 876 907 903 925 897 922 940 895 905 879 959 962 931 980 966 895 906 973 1013 1000 1030 993 1004 1088 1042 1110 1236 1173 1141 1257 1211 1271 1229 1267 1233 1207 1273 1163 1138 1108 1030 1054 1039 970 1007 1020 1019 1002 963 961 946 1029 973 1049 1050 1061 1047 1074 1064 1081 1086 1150 1100 1149 1124 1131 1100 1040 1028 997 1035 987 985 961 1008 942 977 945 949 960 950 941 878 981 925 912 916 917 851 915 868 921 946 908 854 930 924 893 944 901 888 905 890 885 969 902 881 897 910 905</counts>
			</dataPoints>
		</scan>
	</xrdMeasurement>
</xrdMeasurements>