File: dataset/precursor_mixture/V2O5_0p2013-La(OH)3_0p5000-ZrO2_0p3001--2min.xrdml
<?xml version="1.0"?>
<xrdMeasurements xmlns="http://www.xrdml.com/XRDMeasurement/2.3" xmlns:xsi="http://www.w3.org/2001/XMLSchema-instance" xsi:schemaLocation="http://www.xrdml.com/XRDMeasurement/2.3 http://www.xrdml.com/XRDMeasurement/2.3/XRDMeasurement.xsd" status="Completed" recordIdentifier="{23CDB7F2-E0CB-40DA-BB40-CA317BFA2056}">
	<comment>
		<entry/>
	</comment>
	<sample type="To be analyzed">
		<id>V2O5_0p2013-La(OH)3_0p5000-ZrO2_0p3001--2min</id>
		<name></name>
		<preparedBy></preparedBy>
	</sample>
	<xrdMeasurement measurementType="Scan" status="Completed" sampleMode="Reflection">
		<usedWavelength intended="K-Alpha 1">
			<kAlpha1 unit="Angstrom">1.5405980</kAlpha1>
			<kAlpha2 unit="Angstrom">1.5444260</kAlpha2>
			<kBeta unit="Angstrom">1.3922500</kBeta>
			<ratioKAlpha2KAlpha1>0.5000</ratioKAlpha2KAlpha1>
		</usedWavelength>
		<incidentBeamPath>
			<radius unit="mm">145.00</radius>
			<xRayTube id="1010048" name="Empyrean Cu LFF HR (9430 033 7310x)">
				<tension unit="kV">40.0</tension>
				<current unit="mA">15.0</current>
				<anodeMaterial>Cu</anodeMaterial>
				<focus type="Line">
					<length unit="mm">12.0</length>
					<width unit="mm">0.4</width>
					<takeOffAngle unit="deg">6.0</takeOffAngle>
				</focus>
			</xRayTube>
			<sollerSlit id="21010002" name="Soller slits 0.04 rad.">
				<opening unit="rad">0.0400</opening>
			</sollerSlit>
			<mask id="22031000" name="Fixed mask 13 mm">
				<width unit="mm">9.00</width>
			</mask>
			<divergenceSlit id="22120001" name="Divergence slit 1°" xsi:type="fixedDivergenceSlitType">
				<distanceToSample unit="mm">50.00</distanceToSample>
				<height unit="mm">1.52</height>
			</divergenceSlit>
		</incidentBeamPath>
		<sampleMovement xsi:type="spinningSampleMovementType">
			<spinnerRevolutionTime unit="seconds">1.0</spinnerRevolutionTime>
		</sampleMovement>
		<diffractedBeamPath>
			<radius unit="mm">145.00</radius>
			<antiScatterSlit id="22090040" name="AS slit 9 mm (PIXcel)" xsi:type="fixedAntiScatterSlitType">
				<height unit="mm">9.00</height>
			</antiScatterSlit>
			<sollerSlit id="21020003" name="Large Soller slits 0.04 rad.">
				<opening unit="rad">0.0400</opening>
			</sollerSlit>
			<filter id="20030001" name="Large beta-filter Nickel">
				<material>Ni</material>
				<thickness unit="mm">0.020</thickness>
			</filter>
			<detector id="7010019" name="PIXcel1D-Medipix3 detector" xsi:type="rtmsDetectorType">
				<phd unit="keV">
					<lowerLevel>4.02</lowerLevel>
					<upperLevel>11.27</upperLevel>
				</phd>
				<mode>Scanning</mode>
				<activeLength unit="deg">5.542</activeLength>
			</detector>
		</diffractedBeamPath>
		<scan appendNumber="0" mode="Continuous" scanAxis="Gonio" status="Completed">
			<header>
				<startTimeStamp>2024-11-14T16:22:49-08:00</startTimeStamp>
				<endTimeStamp>2024-11-14T16:24:54-08:00</endTimeStamp>
				<author>
					<name>AutomatedUser</name>
				</author>
				<source>
					<applicationSoftware version="1.7b (136)">PANalytical Aeris Instrument Suite</applicationSoftware>
					<instrumentControlSoftware version="3.2.00000000 20240306">AERIS</instrumentControlSoftware>
					<instrumentID>950485</instrumentID>
				</source>
			</header>
			<dataPoints>
				<positions axis="2Theta" unit="deg">
					<startPosition>10.02173288</startPosition>
					<endPosition>99.99585608</endPosition>
				</positions>
				<positions axis="Omega" unit="deg">
					<startPosition>5.01086644</startPosition>
					<endPosition>49.99792804</endPosition>
				</positions>
				<commonCountingTime unit="seconds">10.965</commonCountingTime>
				<counts unit="counts">2027 1945 1871 1966 1977 1944 1935 1885 1912 1901 1881 1931 1869 1892 1856 1844 1857 1930 1857 1799 1758 1749 1765 1749 1831 1758 1713 1722 1752 1788 1667 1690 1677 1679 1617 1625 1648 1662 1589 1663 1564 1639 1616 1609 1601 1604 1578 1541 1595 1478 1559 1603 1535 1547 1523 1534 1523 1502 1415 1496 1432 1470 1494 1511 1437 1480 1514 1417 1453 1384 1464 1451 1512 1366 1511 1431 1426 1419 1413 1389 1427 1361 1373 1392 1427 1303 1383 1373 1298 1357 1423 1341 1397 1405 1420 1407 1305 1349 1423 1348 1327 1367 1371 1393 1271 1272 1349 1322 1335 1292 1334 1368 1355 1310 1402 1310 1357 1397 1351 1452 1535 1482 1674 1791 1844 2122 2267 2484 2800 3038 3307 3378 3405 3528 3555 3410 3162 2802 2502 1940 1817 1658 1557 1373 1288 1399 1334 1260 1322 1326 1257 1219 1255 1202 1204 1226 1306 1254 1220 1239 1250 1292 1259 1211 1219 1255 1183 1207 1219 1166 1270 1252 1204 1195 1240 1253 1209 1240 1250 1263 1204 1233 1133 1112 1149 1188 1123 1235 1170 1138 1118 1126 1250 1252 1161 1097 1157 1120 1150 1064 1184 1199 1127 1120 1110 1149 1127 1060 1134 1122 1123 1073 1117 1166 1099 1091 1096 1140 1119 1107 1024 1044 1069 1124 1092 1064 1079 1135 1074 1114 1108 1200 1222 1344 1436 1380 1566 1725 1785 1751 1870 1860 1898 1832 1600 1363 1282 1138 1054 1051 981 1022 1030 1097 1048 1021 1034 1007 1023 983 1005 1121 1086 1040 1086 1078 1059 1038 1111 1132 1228 1231 1193 1267 1280 1164 1193 1153 1086 1065 1023 991 981 965 939 1032 997 993 1004 1031 899 970 1002 982 956 978 995 937 1050 994 879 995 936 913 976 994 956 966 1015 977 1018 1000 952 961 1011 935 1015 952 1059 1070 1105 1100 1148 1146 1228 1226 1240 1190 1240 1273 1229 1195 1207 1138 1121 1188 1096 1165 1248 1101 1021 1011 966 955 969 980 937 792 918 977 908 888 952 958 916 877 913 909 869 972 1035 956 967 950 1004 1021 946 1022 1014 1042 1104 1034 1144 1147 1247 1223 1209 1277 1168 1130 1019 1065 1037 972 1053 975 1057 1039 1058 1118 1232 1425 1575 1835 1969 2120 2695 2863 3124 3425 3538 3630 3650 3421 3254 2868 2537 2458 2342 2440 2648 2944 3315 3696 4190 4679 5046 5490 5469 5540 5227 4614 4249 3709 3454 2976 2394 1982 1616 1385 1328 1185 1190 1127 991 987 1049 1039 1003 1007 913 967 978 886 898 874 944 900 931 936 828 911 897 949 921 906 855 918 838 879 937 864 867 899 918 847 926 887 898 912 887 905 896 842 918 888 881 975 1003 1030 998 1047 1056 1218 1204 1173 1303 1364 1555 1542 1552 1771 1850 1983 2097 2240 2335 2579 2587 2643 2635 2418 2057 1862 1642 1354 1238 1120 1013 951 930 972 894 883 868 919 950 956 979 922 967 948 914 855 755 831 806 820 794 730 777 762 758 793 713 785 793 791 831 822 876 823 755 788 863 779 817 810 785 810 842 816 856 957 1002 1009 1156 1177 1289 1326 1300 1393 1381 1350 1319 1273 1157 1123 1025 929 909 827 821 749 770 774 834 756 831 845 894 893 924 987 948 1012 1020 1027 1021 978 894 888 898 933 847 889 928 899 955 1013 1002 1002 984 1027 984 916 898 828 747 759 696 742 710 685 728 709 705 725 710 647 652 654 712 728 735 713 682 667 687 692 711 702 686 752 712 679 652 749 656 703 703 610 681 713 635 701 666 689 677 650 693 711 707 750 674 756 716 731 837 825 870 866 843 871 841 940 817 888 860 919 956 1148 1240 1374 1545 1873 2019 2374 2658 2870 3079 3207 3441 3249 3087 2677 2370 1969 1622 1431 1271 1081 1024 947 917 812 894 825 824 821 805 764 717 767 810 861 837 865 965 911 963 951 962 986 979 878 868 890 902 984 979 982 1046 994 926 1044 942 899 865 781 788 759 791 789 748 804 861 847 915 911 1085 1122 1150 1207 1183 1231 1155 1189 1019 1029 997 892 837 759 741 751 683 709 669 719 648 730 634 599 618 698 640 665 629 661 639 610 637 672 672 641 637 629 623 652 682 661 618 670 638 662 624 640 631 684 658 627 608 681 698 672 664 706 737 650 691 720 769 739 774 804 769 766 718 719 753 730 717 727 764 747 772 760 761 858 863 854 836 823 761 828 698 700 734 695 672 681 643 678 654 639 648 662 720 648 671 637 673 658 669 716 670 723 721 713 799 844 916 957 1015 1014 1125 1204 1197 1185 1138 1108 1041 965 961 930 894 893 880 857 856 947 964 1095 1110 1242 1297 1433 1548 1567 1763 1869 2150 2157 2314 2361 2517 2594 2748 2764 2940 3014 3067 3163 2986 2881 2721 2407 2131 1849 1734 1600 1494 1319 1353 1301 1166 1312 1216 1188 1107 1092 1099 970 985 960 921 961 1009 1084 1133 1213 1294 1364 1389 1366 1443 1416 1411 1186 1266 1082 1050 1005 961 962 1001 943 1015 960 927 851 750 742 717 782 726 786 834 853 777 845 845 855 840 821 741 748 717 709 594 617 672 664 582 645 615 698 672 654 698 674 638 712 630 567 622 590 589 566 584 597 635 657 608 592 595 620 602 594 601 619 623 592 565 565 612 619 621 573 626 616 638 579 626 635 618 667 586 629 669 693 694 763 774 683 812 780 812 890 795 786 730 765 702 653 706 688 691 673 701 657 659 712 697 743 777 855 970 1019 1052 1073 1201 1308 1445 1435 1546 1545 1553 1456 1380 1261 1243 1201 1095 1040 1008 1049 1010 1049 1056 1003 995 994 971 1044 1046 1096 989 1044 972 959 962 838 730 829 756 733 743 691 734 666 705 658 763 734 699 829 731 769 787 825 783 716 677 727 716 742 743 750 843 791 781 850 864 869 867 878 836 776 745 769 762 737 758 752 738 725 719 721 719 764 812 773 781 817 824 848 797 834 820 737 755 696 713 710 703 648 673 618 672 636 661 672 692 687 732 765 786 804 841 817 820 839 794 818 787 792 775 670 684 610 591 611 594 629 602 580 585 626 586 636 604 632 616 604 630 695 672 709 674 641 658 664 679 717 664 733 716 712 653 677 639 645 710 638 680 717 719 746 770 747 823 737 732 713 671 710 717 624 620 618 606 665 709 727 730 723 785 722 748 813 770 788 702 707 673 674 652 636 616 639 660 617 661 646 747 722 792 855 851 991 1104 1073 1082 1131 1189 1278 1067 1076 1100 1068 1022 972 895 885 863 795 763 726 731 755 674 686 698 683 789 789 788 740 808 790 813 771 793 736 686 804 800 753 785 812 835 752 780 769 806 749 847 783 744 739 719 731 695 691 690 661 667 661 546 566 584 530 528 538 539 582 580 561 555 556 504 549 566 561 497 554 576 493 555 562 533 574 565 513 524 523 576 560 564 534 550 517 560 577 595 526 580 543 562 551 553 514 627 567 580 579 520 578 581 532 616 626 616 562 588 657 670 656 732 641 622 634 659 584 691 702 656 729 749 814 888 994 1033 1028 1008 1092 1028 1011 974 863 830 794 736 667 762 702 692 690 631 658 608 664 678 639 652 649 652 666 745 701 748 740 769 778 742 746 790 742 718 743 634 729 703 718 681 613 609 649 630 592 635 610 591 566 583 585 619 589 617 605 659 648 616 646 622 729 657 668 640 703 679 729 724 643 623 769 614 636 631 666 672 621 635 565 631 577 521 523 578 540 490 545 523 570 489 526 568 559 508 583 559 522 545 552 575 505 497 550 590 579 561 552 597 563 601 576 639 613 607 640 579 630 624 641 627 674 647 623 608 678 620 661 620 577 620 621 640 595 563 645 695 708 701 710 756 752 717 756 798 858 849 799 846 813 859 887 813 862 876 903 881 795 804 817 795 842 837 793 753 756 821 816 870 932 910 1039 993 1059 1089 1138 1075 1182 1225 1155 1232 1197 1168 1059 1078 964 1006 921 878 882 767 797 759 788 759 732 703 735 734 737 701 711 690 694 738 719 689 711 689 677 684 698 652 613 611 657 628 605 541 588 483 580 556 574 557 517 508 569 551 568 489 585 530 544 532 479 517 567 524 503 532 549 562 477 507 533 499 523 552 566 483 585 543 499 506 483 506 479 521 508 591 491 526 509 539 499 540 520 515 538 570 544 563 591 596 616 623 620 583 550 553 626 595 612 642 602 648 628 704 740 751 696 768 720 790 751 704 712 689 709 580 659 634 585 636 602 592 620 644 647 663 586 608 616 599 609 569 586 555 542 563 594 573 531 599 602 594 542 587 560 588 601 594 622 546 592 546 575 575 557 541 556 571 561 548 608 623 591 591 655 594 597 603 622 559 600 591 606 562 598 544 514 578 573 575 576 560 568 581 531 536 559 554 554 611 557 564 624 577 541 566 583 572 557 517 544 552 533 573 533 565 509 532 585 546 548 555 529 529 518 539 571 568 521 556 564 544 545 567 542 548 569 602 571 515 547 551 540 544 569 559 569 607 618 618 595 650 708 681 731 696 708 749 779 793 812 796 872 840 799 853 743 821 779 745 756 649 659 665 623 606 599 606 641 632 594 660 644 657 705 665 688 646 642 656 787 745 662 752 703 725 748 676 759 729 711 749 671 679 700 743 694 690 623 697 681 638 621 616 617 648 614 646 591 634 647 660 628 649 597 577 604 624 650 534 583 551 570 551 546 546 568 570 536 558 555 542 554 579 543 557 563 544 537 539 531 518 502 545 552 525 497 546 588 582 531 556 504 504 545 549 512 525 529 540 532 531 494 457 511 496 588 542 551 605 603 545 574 561 544 538 517 569 539 510 558 495 597 529 541 543 550 599 559 576 514 594 614 587 609 629 614 650 624 670 689 654 736 697 785 809 728 775 836 844 861 795 741 774 826 806 774 766 772 739 751 672 729 709 731 737 827 707 786 728 696 780 772 793 741 705 796 809 813 705 786 788 692 776 786 774 724 686 662 670 633 607 593 633 625 596 549 595 591 593 566 563 599 559 582 621 589 539 597 626 598 571 616 629 547 590 574 624 590 604 601 633 613 605 561 609 575 590 559 540 615 599 571 610 583 587 579 616 653 592 590 556 612 628 628 607 594 668 611 580</counts>
			</dataPoints>
		</scan>
	</xrdMeasurement>
</xrdMeasurements>