File: dataset/precursor_mixture/V2O5_0p8011-ZrO2_0p2012--8min.xrdml
<?xml version="1.0"?>
<xrdMeasurements xmlns="http://www.xrdml.com/XRDMeasurement/2.3" xmlns:xsi="http://www.w3.org/2001/XMLSchema-instance" xsi:schemaLocation="http://www.xrdml.com/XRDMeasurement/2.3 http://www.xrdml.com/XRDMeasurement/2.3/XRDMeasurement.xsd" status="Completed" recordIdentifier="{EF9B5883-8528-407E-B0F4-FAEECC284801}">
	<comment>
		<entry/>
	</comment>
	<sample type="To be analyzed">
		<id>V2O5_0p8011-ZrO2_0p2012--8min</id>
		<name></name>
		<preparedBy></preparedBy>
	</sample>
	<xrdMeasurement measurementType="Scan" status="Completed" sampleMode="Reflection">
		<usedWavelength intended="K-Alpha 1">
			<kAlpha1 unit="Angstrom">1.5405980</kAlpha1>
			<kAlpha2 unit="Angstrom">1.5444260</kAlpha2>
			<kBeta unit="Angstrom">1.3922500</kBeta>
			<ratioKAlpha2KAlpha1>0.5000</ratioKAlpha2KAlpha1>
		</usedWavelength>
		<incidentBeamPath>
			<radius unit="mm">145.00</radius>
			<xRayTube id="1010048" name="Empyrean Cu LFF HR (9430 033 7310x)">
				<tension unit="kV">40.0</tension>
				<current unit="mA">15.0</current>
				<anodeMaterial>Cu</anodeMaterial>
				<focus type="Line">
					<length unit="mm">12.0</length>
					<width unit="mm">0.4</width>
					<takeOffAngle unit="deg">6.0</takeOffAngle>
				</focus>
			</xRayTube>
			<sollerSlit id="21010002" name="Soller slits 0.04 rad.">
				<opening unit="rad">0.0400</opening>
			</sollerSlit>
			<mask id="22031000" name="Fixed mask 13 mm">
				<width unit="mm">9.00</width>
			</mask>
			<divergenceSlit id="22120001" name="Divergence slit 1°" xsi:type="fixedDivergenceSlitType">
				<distanceToSample unit="mm">50.00</distanceToSample>
				<height unit="mm">1.52</height>
			</divergenceSlit>
		</incidentBeamPath>
		<sampleMovement xsi:type="spinningSampleMovementType">
			<spinnerRevolutionTime unit="seconds">1.0</spinnerRevolutionTime>
		</sampleMovement>
		<diffractedBeamPath>
			<radius unit="mm">145.00</radius>
			<antiScatterSlit id="22090040" name="AS slit 9 mm (PIXcel)" xsi:type="fixedAntiScatterSlitType">
				<height unit="mm">9.00</height>
			</antiScatterSlit>
			<sollerSlit id="21020003" name="Large Soller slits 0.04 rad.">
				<opening unit="rad">0.0400</opening>
			</sollerSlit>
			<filter id="20030001" name="Large beta-filter Nickel">
				<material>Ni</material>
				<thickness unit="mm">0.020</thickness>
			</filter>
			<detector id="7010019" name="PIXcel1D-Medipix3 detector" xsi:type="rtmsDetectorType">
				<phd unit="keV">
					<lowerLevel>4.02</lowerLevel>
					<upperLevel>11.27</upperLevel>
				</phd>
				<mode>Scanning</mode>
				<activeLength unit="deg">5.542</activeLength>
			</detector>
		</diffractedBeamPath>
		<scan appendNumber="0" mode="Continuous" scanAxis="Gonio" status="Completed">
			<header>
				<startTimeStamp>2024-11-14T13:56:02-08:00</startTimeStamp>
				<endTimeStamp>2024-11-14T14:04:09-08:00</endTimeStamp>
				<author>
					<name>AutomatedUser</name>
				</author>
				<source>
					<applicationSoftware version="1.7b (136)">PANalytical Aeris Instrument Suite</applicationSoftware>
					<instrumentControlSoftware version="3.2.00000000 20240306">AERIS</instrumentControlSoftware>
					<instrumentID>950485</instrumentID>
				</source>
			</header>
			<dataPoints>
				<positions axis="2Theta" unit="deg">
					<startPosition>10.00943322</startPosition>
					<endPosition>99.99442286</endPosition>
				</positions>
				<positions axis="Omega" unit="deg">
					<startPosition>5.00471661</startPosition>
					<endPosition>49.99721143</endPosition>
				</positions>
				<commonCountingTime unit="seconds">12.495</commonCountingTime>
				<counts unit="counts">2276 2345 2231 2326 2359 2283 2202 2229 2270 2294 2226 2295 2192 2182 2224 2252 2264 2259 2211 2245 2233 2191 2252 2252 2151 2202 2216 2256 2284 2291 2204 2137 2160 2216 2199 2148 2186 2181 2111 2195 2203 2120 2104 2210 2214 2102 2160 2118 2123 2218 2124 2170 2146 2132 2160 2176 2084 2092 2101 2187 2074 2059 2128 2051 2057 2060 2114 2106 2113 2105 2059 2044 2068 2009 2074 1999 2013 2137 2050 2048 2026 1980 1968 2051 2047 1963 2085 1985 2057 2002 1938 1967 2114 2025 1915 2014 2037 2006 1972 2006 2036 1933 2050 2025 1973 1943 1972 1951 2015 1863 1985 1991 1946 1947 1957 2008 1977 2009 1907 1936 1929 1941 1934 1915 2036 1909 1840 1951 1873 1862 1931 1898 1941 1869 1878 1906 1975 1945 1959 1881 1833 1909 1920 1900 1814 1878 1898 1883 1853 1836 1885 1922 1881 1866 1855 1855 1818 1849 1815 1878 1770 1811 1846 1868 1811 1878 1829 1831 1833 1780 1809 1768 1795 1779 1882 1823 1756 1776 1819 1799 1822 1807 1805 1785 1778 1860 1762 1754 1832 1796 1798 1777 1748 1795 1686 1749 1686 1787 1708 1731 1737 1783 1802 1729 1784 1742 1723 1746 1678 1658 1700 1747 1668 1736 1682 1754 1664 1669 1640 1661 1672 1721 1585 1666 1742 1667 1607 1696 1712 1678 1702 1679 1683 1675 1670 1671 1686 1703 1756 1658 1684 1543 1591 1726 1639 1671 1633 1702 1697 1732 1705 1664 1651 1695 1617 1645 1613 1640 1653 1630 1614 1635 1654 1656 1584 1545 1550 1669 1649 1635 1536 1618 1613 1571 1584 1596 1607 1573 1610 1601 1670 1628 1603 1509 1541 1585 1546 1523 1638 1639 1577 1576 1561 1606 1612 1474 1572 1582 1593 1517 1632 1558 1633 1534 1527 1601 1583 1570 1534 1487 1571 1589 1497 1511 1550 1598 1506 1575 1569 1586 1509 1525 1627 1486 1550 1499 1599 1574 1516 1622 1531 1570 1514 1552 1466 1596 1404 1522 1521 1514 1510 1551 1407 1532 1518 1523 1550 1490 1493 1593 1541 1571 1518 1569 1529 1470 1486 1484 1488 1481 1499 1587 1500 1490 1536 1510 1479 1492 1464 1441 1482 1571 1453 1435 1466 1523 1482 1519 1411 1503 1463 1462 1499 1473 1532 1508 1437 1505 1402 1610 1432 1501 1435 1510 1493 1439 1471 1518 1551 1425 1501 1416 1509 1423 1541 1461 1516 1449 1460 1460 1559 1446 1446 1482 1435 1463 1471 1479 1373 1374 1481 1440 1432 1436 1490 1430 1427 1410 1466 1445 1487 1417 1433 1470 1458 1415 1461 1433 1430 1479 1417 1500 1401 1448 1408 1457 1509 1435 1460 1396 1439 1430 1463 1463 1422 1452 1423 1453 1436 1388 1372 1415 1442 1510 1521 1517 1521 1505 1489 1516 1491 1425 1588 1531 1591 1521 1578 1575 1583 1641 1658 1671 1684 1622 1758 1771 1831 1714 1860 1800 1950 1848 1879 1951 1918 1999 1996 1969 2088 2115 1991 2052 2038 2078 2067 2083 2076 1966 2003 1920 1954 1977 1889 1881 1842 1749 1765 1758 1696 1746 1677 1725 1699 1620 1572 1579 1587 1615 1609 1481 1537 1479 1531 1586 1589 1550 1534 1592 1447 1456 1490 1472 1390 1413 1380 1397 1404 1380 1387 1448 1425 1454 1353 1398 1336 1456 1365 1382 1427 1329 1433 1377 1395 1452 1354 1384 1396 1457 1413 1456 1417 1335 1391 1375 1395 1326 1464 1406 1417 1360 1388 1425 1358 1452 1342 1323 1369 1312 1364 1350 1448 1362 1380 1287 1305 1381 1338 1342 1373 1307 1357 1344 1379 1327 1354 1297 1408 1340 1439 1323 1334 1395 1390 1368 1338 1404 1311 1404 1381 1346 1392 1333 1367 1331 1314 1379 1380 1295 1356 1382 1348 1333 1350 1357 1374 1305 1291 1376 1285 1390 1369 1396 1338 1408 1333 1419 1352 1362 1346 1372 1400 1376 1335 1330 1305 1291 1300 1273 1351 1344 1330 1381 1340 1369 1433 1357 1292 1316 1379 1348 1356 1350 1352 1390 1296 1445 1324 1343 1385 1318 1289 1403 1322 1307 1367 1355 1374 1384 1402 1377 1349 1392 1379 1444 1307 1439 1376 1369 1306 1402 1342 1392 1334 1351 1372 1357 1343 1360 1352 1356 1372 1399 1299 1421 1342 1301 1299 1382 1349 1280 1334 1366 1307 1279 1381 1327 1276 1339 1334 1288 1373 1280 1286 1349 1339 1253 1347 1347 1292 1376 1290 1310 1355 1271 1258 1377 1344 1300 1347 1231 1235 1279 1271 1333 1291 1312 1307 1303 1223 1279 1320 1296 1287 1301 1289 1276 1227 1293 1299 1267 1329 1398 1257 1271 1266 1317 1301 1258 1302 1293 1241 1358 1314 1299 1319 1314 1245 1250 1309 1307 1288 1275 1192 1270 1269 1255 1274 1271 1318 1332 1269 1297 1256 1260 1277 1307 1272 1279 1225 1261 1328 1241 1252 1250 1323 1301 1283 1307 1235 1317 1219 1250 1231 1202 1228 1260 1259 1221 1214 1281 1278 1340 1300 1255 1256 1275 1251 1234 1283 1243 1168 1259 1214 1257 1245 1321 1269 1276 1236 1264 1277 1312 1261 1305 1307 1295 1241 1259 1230 1244 1237 1271 1249 1254 1276 1312 1281 1293 1235 1296 1286 1188 1206 1298 1325 1224 1273 1190 1247 1319 1236 1272 1250 1267 1323 1310 1306 1331 1281 1303 1350 1366 1370 1273 1304 1461 1367 1409 1403 1409 1318 1454 1404 1448 1430 1497 1455 1533 1562 1528 1507 1561 1549 1562 1601 1603 1712 1780 1734 1805 1845 1910 1966 1991 2179 2186 2206 2362 2445 2532 2702 2842 2983 3115 3332 3470 3695 3773 4069 4155 4482 4633 4872 5187 5563 5810 6165 6270 6618 6884 7224 7392 7747 8056 8207 8658 8905 8689 8850 8877 8840 8935 8835 8554 8371 8102 7634 7473 7206 6838 6573 6224 5879 5496 5383 4925 4929 4705 4586 4468 4310 4181 3996 3867 3886 3719 3479 3622 3286 3191 3087 2961 2735 2582 2354 2437 2094 1961 1862 1740 1758 1717 1569 1570 1560 1457 1461 1417 1451 1473 1445 1424 1367 1337 1425 1418 1358 1328 1386 1388 1364 1373 1340 1382 1355 1268 1354 1312 1366 1332 1300 1347 1298 1305 1318 1272 1315 1325 1351 1404 1397 1311 1394 1334 1338 1304 1355 1331 1335 1343 1391 1403 1435 1427 1424 1381 1518 1442 1571 1584 1628 1620 1683 1660 1707 1851 1803 1860 1900 1951 2044 2091 2079 2181 2242 2401 2297 2474 2517 2486 2688 2714 2880 2921 2945 3040 3147 3172 3206 3307 3174 3215 3255 3201 3116 3129 3034 2971 2896 2939 2762 2678 2626 2574 2450 2446 2317 2314 2154 2188 2182 2095 2012 2077 1952 1987 1896 1848 1789 1792 1740 1668 1773 1640 1569 1659 1525 1512 1462 1436 1403 1388 1309 1291 1312 1298 1338 1255 1281 1272 1273 1263 1168 1267 1271 1277 1187 1137 1251 1269 1247 1254 1180 1192 1176 1201 1231 1124 1162 1248 1166 1190 1190 1171 1213 1166 1229 1208 1115 1234 1168 1259 1178 1162 1223 1140 1195 1154 1180 1174 1117 1169 1214 1115 1188 1202 1142 1151 1202 1188 1212 1153 1141 1132 1225 1195 1128 1158 1192 1182 1165 1161 1112 1151 1195 1164 1179 1158 1193 1037 1141 1144 1180 1211 1152 1180 1116 1195 1126 1170 1164 1153 1203 1126 1141 1140 1206 1189 1130 1184 1059 1135 1073 1127 1116 1149 1133 1177 1163 1144 1191 1107 1094 1090 1150 1138 1155 1107 1113 1223 1165 1136 1088 1146 1154 1202 1135 1203 1146 1152 1111 1122 1105 1185 1136 1128 1215 1145 1191 1163 1166 1142 1174 1188 1094 1152 1195 1250 1150 1286 1219 1241 1245 1261 1276 1217 1245 1260 1264 1262 1322 1291 1302 1265 1357 1334 1418 1376 1419 1363 1456 1380 1416 1462 1460 1472 1415 1409 1408 1429 1368 1488 1410 1408 1450 1405 1426 1372 1399 1398 1391 1372 1350 1403 1303 1368 1346 1387 1365 1383 1345 1428 1386 1380 1431 1395 1365 1367 1419 1363 1300 1402 1373 1358 1392 1323 1255 1312 1332 1301 1287 1284 1279 1334 1255 1244 1278 1242 1262 1240 1192 1243 1230 1225 1201 1201 1211 1221 1128 1198 1187 1209 1185 1197 1135 1149 1185 1181 1112 1187 1097 1060 1128 1137 1133 1028 1107 1054 1165 1153 1162 1144 1150 1039 1120 1180 1081 1168 1087 1125 1115 1129 1043 1078 1097 1124 1089 1114 1078 1075 1061 1095 1079 1100 1129 1137 1100 1154 1127 1138 1106 1112 1159 1167 1143 1170 1102 1214 1218 1280 1186 1228 1220 1217 1351 1329 1229 1281 1328 1364 1380 1292 1355 1356 1248 1419 1338 1363 1455 1337 1309 1311 1328 1330 1345 1282 1265 1305 1259 1306 1349 1273 1264 1343 1371 1380 1412 1372 1398 1429 1547 1486 1510 1503 1535 1671 1576 1697 1736 1799 1921 1902 2025 2070 2173 2155 2251 2339 2458 2537 2506 2648 2728 2816 2934 2930 2928 2933 2853 2827 2821 2816 2673 2705 2663 2610 2561 2362 2429 2352 2247 2038 2160 2084 2081 1952 1895 1884 1889 1793 1749 1801 1698 1761 1692 1629 1600 1559 1506 1550 1460 1438 1363 1274 1186 1154 1189 1149 1139 1111 1088 1052 1060 1136 1104 1085 1100 1074 1088 1084 1046 1005 1121 1010 1120 1044 1100 1053 1088 1028 1077 1036 1048 960 1034 1056 1013 1035 1050 1008 1062 1116 1076 1039 1048 938 1014 1039 974 1055 1060 1094 1102 1089 1017 1015 1026 1051 1004 1096 1037 1124 1083 1071 1035 1051 1086 1032 991 1136 1047 1040 1051 1071 1066 1095 1038 1081 1010 1076 1035 1046 1054 1050 1086 1070 1060 1095 1045 1091 1052 1068 1116 1070 1093 1157 1077 1129 1096 1108 1160 1121 1078 1162 1055 1151 1023 1101 1127 1119 1160 1103 1158 1225 1170 1214 1192 1276 1222 1246 1254 1251 1309 1373 1370 1352 1405 1431 1379 1477 1531 1548 1567 1654 1679 1768 1765 1826 1989 2066 2045 2124 2226 2321 2455 2469 2647 2600 2739 2836 2929 2964 2937 2993 3013 3045 3200 3143 3221 3097 3049 2988 2915 2865 2871 2776 2672 2703 2540 2571 2499 2422 2434 2358 2281 2264 2140 2163 2085 2177 1962 1952 1783 1751 1764 1794 1689 1735 1676 1600 1525 1510 1385 1486 1405 1354 1342 1302 1221 1251 1213 1183 1149 1114 1115 1207 1155 1122 1066 1161 1154 1155 1121 1073 1129 1053 1077 1026 1074 1130 1048 1020 1115 1107 1062 1038 1039 1077 1095 1037 1069 1042 1034 1031 1057 1000 1029 1056 1077 1013 987 1022 1060 1042 1087 1007 998 998 1021 1032 1032 991 972 1010 1018 995 1021 1051 982 1097 961 1100 1005 998 957 1070 986 1026 994 983 1005 1003 1036 1021 1009 1036 1060 961 1087 1057 1000 1035 1009 995 979 1019 967 1021 1049 937 1039 1044 969 1059 993 1005 980 1007 1004 1004 1045 1056 963 968 994 917 1046 929 1082 965 1003 988 997 1004 980 991 1055 1037 1001 1036 979 1025 1023 1014 1003 1040 1052 1018 1037 1037 1027 977 1029 978 1019 1068 1047 1033 1036 1101 1028 1116 1011 1071 1043 1025 1035 1075 1017 1035 1043 1046 1031 1058 1103 1069 1055 1062 1081 1086 986 1051 1111 1033 1054 1098 1134 1096 1061 1110 1082 1135 1090 1148 1137 1161 1148 1290 1110 1221 1173 1298 1278 1268 1227 1299 1279 1327 1356 1424 1526 1544 1615 1598 1731 1727 1816 1853 2052 2046 2242 2286 2429 2564 2704 2713 2835 3095 3177 3352 3546 3488 3662 3665 3815 3852 3813 3824 3938 3860 3826 3885 3743 3782 3519 3675 3377 3417 3326 3317 3125 3151 3141 3009 3003 3048 2895 2791 2837 2912 2747 2708 2773 2793 2758 2685 2748 2715 2743 2642 2676 2677 2577 2633 2722 2685 2714 2785 2604 2638 2684 2503 2590 2550 2621 2436 2449 2441 2360 2411 2364 2277 2216 2121 2168 2077 2094 2051 1928 1921 1872 1874 1752 1748 1742 1766 1717 1556 1548 1542 1492 1454 1356 1462 1322 1239 1259 1277 1238 1289 1169 1188 1158 1167 1167 1207 1186 1151 1082 1076 1142 1163 1162 1150 1129 1097 1177 1183 1242 1201 1194 1284 1294 1333 1331 1427 1370 1403 1474 1520 1599 1718 1630 1748 1851 1790 1947 1907 2077 2037 2052 2106 2122 2076 2201 2039 2119 1997 2085 1887 2045 2036 1954 1889 1880 1749 1746 1775 1687 1574 1700 1619 1503 1525 1513 1525 1386 1432 1375 1388 1308 1294 1327 1295 1190 1180 1230 1150 1148 1074 1062 1088 1031 1083 1052 1024 987 984 998 917 1016 1011 970 995 983 968 1024 1006 999 1042 947 965 1021 1034 1053 1023 988 982 1063 1052 1027 1066 1078 1114 1080 1107 1123 1143 1147 1144 1182 1224 1170 1320 1311 1320 1293 1273 1316 1291 1318 1222 1280 1310 1275 1234 1273 1262 1303 1253 1255 1237 1162 1181 1192 1183 1221 1147 1250 1155 1087 1206 1152 1091 1068 1106 1109 1099 1078 1003 1066 1046 1004 1024 1049 1058 1031 1033 1026 1018 971 1047 1037 963 1035 1065 1035 1005 1135 1037 1098 1052 1065 1139 1031 1040 1135 1210 1172 1210 1217 1254 1234 1288 1357 1328 1375 1474 1428 1476 1536 1547 1630 1666 1759 1704 1762 1930 1948 1959 1973 2005 2107 2169 2247 2247 2163 2280 2301 2339 2369 2312 2318 2391 2322 2400 2328 2229 2213 2138 2179 2129 2054 2102 1998 2004 1929 1875 1795 1734 1701 1778 1704 1646 1673 1517 1529 1493 1470 1366 1400 1324 1332 1230 1248 1225 1197 1173 1170 1129 1006 1034 1047 1003 1006 1024 1065 1024 1116 1026 1007 1030 979 1018 977 996 1010 968 990 968 964 983 1041 1003 995 997 961 1006 1006 1032 1057 999 1053 1069 1089 1015 1104 1059 1119 1108 1070 1178 1148 1122 1172 1166 1287 1185 1188 1219 1213 1183 1237 1166 1312 1253 1173 1380 1188 1245 1227 1204 1163 1203 1148 1140 1106 1191 1149 1117 1177 1136 1138 1114 1066 1097 1055 1078 1073 1059 972 1054 1048 968 1050 913 995 1024 989 1020 915 964 972 1019 950 948 966 974 1030 971 978 940 1002 902 1008 959 1056 1037 1034 1001 1025 1053 1052 1008 1034 1068 1057 1056 1008 1076 1092 1034 1064 1040 1091 984 1053 1011 1008 1003 1006 922 948 974 996 943 952 987 980 953 913 969 979 976 928 963 911 925 882 956 852 909 906 862 835 944 898 895 885 861 896 910 850 836 842 876 837 834 807 874 864 959 870 880 826 827 859 841 863 852 858 920 817 833 875 844 890 869 882 858 834 878 853 894 820 894 893 865 873 797 868 827 833 829 848 857 839 865 872 863 815 903 900 873 885 862 890 881 860 855 849 902 871 847 870 846 862 876 916 898 948 994 960 955 941 946 951 929 937 949 988 958 914 1017 1004 945 983 989 1012 908 919 961 903 975 913 967 912 904 849 899 934 881 869 927 891 871 890 906 885 887 929 822 914 904 856 848 867 844 941 847 860 847 811 875 792 852 829 801 784 804 836 842 886 828 824 809 818 863 798 824 808 809 850 861 846 841 814 832 858 872 860 821 876 854 839 889 821 842 781 834 818 838 843 884 775 800 854 821 910 787 923 855 875 928 888 863 893 940 893 886 919 862 898 931 898 911 1001 945 905 901 917 947 892 928 959 994 951 932 957 999 952 916 915 921 967 936 896 899 874 948 886 969 919 978 913 872 880 881 895 878 887 878 831 824 868 868 867 866 853 847 844 813 848 820 857 829 899 796 835 782 831 801 785 848 839 899 823 835 841 830 777 835 786 878 809 854 805 867 837 916 779 871 837 895 783 861 821 823 827 877 869 831 832 825 824 785 817 881 871 830 827 875 856 866 831 865 845 867 880 837 840 831 819 772 826 814 823 868 893 847 833 867 809 855 836 878 889 847 916 783 849 796 882 818 863 798 887 853 836 861 833 872 844 876 855 851 814 824 855 843 825 877 836 844 913 864 895 929 961 872 893 898 894 860 904 882 839 863 852 912 848 846 877 891 887 837 912 848 935 875 804 960 819 844 885 949 839 907 918 961 892 952 940 920 935 962 985 939 1032 1015 1078 1036 1085 1063 1034 1034 1071 1056 1068 1168 1078 1150 1202 1143 1101 1185 1139 1188 1157 1166 1143 1200 1152 1147 1178 1140 1193 1219 1199 1202 1205 1202 1178 1219 1176 1257 1272 1278 1308 1372 1292 1357 1397 1490 1458 1478 1502 1506 1693 1756 1724 1902 1925 2037 2055 2136 2163 2197 2263 2384 2397 2340 2522 2412 2423 2535 2430 2500 2534 2424 2446 2476 2257 2300 2304 2210 2084 2153 2132 2094 1990 1917 2015 1867 1860 1772 1751 1659 1639 1529 1512 1466 1403 1427 1380 1296 1300 1225 1181 1167 1137 1064 1127 1044 1077 1057 1084 1064 1017 1023 1061 1038 1011 1002 1055 1103 1010 1177 1139 1168 1168 1143 1337 1199 1299 1345 1345 1395 1346 1441 1395 1460 1465 1470 1446 1490 1525 1543 1490 1500 1473 1439 1388 1388 1443 1393 1319 1357 1314 1275 1268 1211 1274 1249 1195 1207 1232 1234 1197 1112 1108 1095 1106 1088 1046 984 1048 954 949 933 854 914 875 889 888 845 887 780 882 833 846 883 861 810 868 813 840 828 867 846 798 805 872 780 775 837 817 833 804 810 833 804 736 773 796 858 793 767 833 820 816 789 808 771 839 765 806 812 750 796 819 840 784 763 802 791 812 795 817 805 821 780 726 807 832 809 746 759 749 786 786 756 839 759 794 815 764 770 783 802 803 797 754 820 778 737 817 808 805 798 777 753 752 807 821 806 784 730 779 749 792 789 787 794 765 805 843 854 758 789 753 786 828 782 803 754 807 777 819 808 809 790 804 827 780 832 896 792 788 783 806 757 827 755 730 761 799 717 778 768 801 766 787 846 755 844 813 755 795 807 868 793 832 841 803 845 829 844 786 839 796 799 869 832 834 813 840 822 811 873 822 935 893 888 893 909 885 847 870 838 846 872 841 831 899 885 806 900 832 873 897 882 847 867 851 862 885 875 876 846 857 879 884 882 890 930 962 880 869 888 960 905 937 884 922 921 905 982 953 909 962 913 961 915 989 989 973 960 966 904 997 963 952 978 971 965 924 956 972 928 921 999 937 958 904 969 986 890 932 937 937 989 940 913 886 930 932 948 951 940 975 1053 1051 1032 1018 1072 1180 1123 1192 1170 1219 1231 1301 1244 1311 1356 1354 1367 1461 1361 1436 1401 1406 1446 1426 1433 1453 1450 1356 1457 1385 1446 1387 1354 1458 1314 1341 1273 1321 1265 1249 1247 1275 1153 1178 1173 1129 1098 1005 982 1004 999 912 958 924 959 922 903 873 920 904 930 864 851 847 847 859 831 810 907 865 849 772 836 843 770 833 756 836 771 790 824 801 855 768 776 833 788 855 765 801 801 806 803 776 822 817 765 788 804 805 821 743 858 772 777 773 804 768 771 813 803 771 795 817 754 790 764 763 796 709 782 794 813 820 774 829 764 793 765 792 795 813 782 820 766 784 757 804 736 814 795 764 842 792 790 793 804 821 845 839 792 829 880 833 760 855 849 877 788 924 818 899 867 865 879 929 948 890 963 929 950 916 950 1007 1098 1097 1058 1116 1154 1182 1256 1335 1308 1386 1458 1354 1339 1449 1538 1451 1630 1519 1555 1607 1581 1602 1577 1624 1653 1572 1497 1543 1594 1487 1501 1447 1447 1450 1462 1411 1428 1485 1459 1341 1361 1320 1277 1231 1253 1308 1272 1235 1307 1309 1377 1359 1398 1437 1422 1402 1413 1497 1451 1506 1539 1543 1541 1610 1619 1577 1620 1656 1611 1586 1571 1572 1581 1605 1585 1617 1541 1619 1557 1513 1504 1513 1364 1319 1394 1204 1266 1265 1236 1210 1244 1143 1131 1133 1066 1027 1063 1069 978 975 996 909 905 915 917 937 887 876 883 845 892 912 875 819 887 852 876 810 854 864 826 839 852 886 907 933 916 940 945 917 968 946 937 959 997 1008 1022 1034 1084 1102 1132 1076 1235 1196 1329 1286 1292 1358 1358 1361 1446 1530 1466 1492 1510 1520 1511 1595 1554 1571 1659 1634 1627 1535 1537 1575 1591 1583 1520 1539 1451 1546 1414 1498 1438 1442 1453 1365 1394 1414 1469 1430 1351 1429 1378 1396 1386 1382 1410 1429 1338 1422 1346 1363 1378 1315 1329 1360 1358 1359 1420 1299 1388 1326 1324 1379 1364 1344 1320 1355 1341 1412 1339 1359 1264 1271 1257 1274 1321 1301 1300 1214 1200 1239 1189 1214 1142 1191 1198 1140 1135 1085 1105 1170 1023 1057 1051 1048 1007 1001 1052 977 1109 1047 995 983 981 998 985 1033 988 1014 1063 1018 1088 1038 1018 1083 1096 1106 1187 1143 1209 1191 1207 1268 1249 1280 1307 1386 1282 1358 1333 1369 1389 1416 1382 1368 1365 1354 1453 1381 1364 1375 1355 1396 1353 1360 1280 1342 1356 1302 1305 1223 1236 1280 1284 1177 1271 1229 1177 1179 1202 1233 1149 1222 1189 1116 1144 1187 1181 1147 1193 1194 1063 1242 1158 1125 1196 1118 1138 1167 1204 1181 1149 1138 1151 1090 1148 1097 1053 1138 1084 1069 1078 1048 1013 1040 1042 991 1024 1022 986 978 1004 1059 1019 1009 1033 991 946 1027 1039 1023 1081 1019 1037 1157 1102 1156 1174 1135 1209 1241 1319 1280 1360 1340 1424 1444 1417 1417 1467 1527 1581 1608 1567 1633 1559 1558 1547 1557 1525 1584 1576 1525 1581 1538 1523 1469 1524 1496 1468 1424 1522 1385 1340 1307 1243 1161 1193 1160 1281 1124 1142 1080 1078 1044 1144 1058 1062 1056 1025 1000 988 957 959 928 921 928 914 972 943 937 918 948 878 908 991 970 893 958 981 944 1027 1022 1076 1023 1004 1104 1058 1044 1119 1148 1166 1150 1211 1235 1192 1187 1103 1173 1206 1167 1196 1226 1131 1182 1149 1190 1179 1182 1128 1163 1130 1039 1028 1037 1062 1084 1033 968 969 1002 973 909 917 945 904 853 907 861 902 811 909 831 865 902 863 930 837 884 801 852 819 864 816 788 874 893 868 897 872 880 840 905 851 831 815 864 888 841 921 821 798 853 781 838 777 777 773 800 746 746 778 831 772 799 807 795 734 771 795 758 807 784 764 731 746 765 767 766 770 791 778 741 737 755 754 763 762 786 784 754 809 772 773 736 773 795 792 762 839 751 756 800 782 729 791 750 775 773 776 760 785 800 769 812 796 799 773 791 792 745 744 815 801 803 794 807 773 810 759 804 787 854 830 808 844 809 832 829 820 800 891 904 923 912 871 863 856 846 873 893 897 909 888 922 944 927 859 880 978 907 939 950 918 1023 1019 1012 1032 984 1063 1057 1124 1020 1044 1045 1101 1024 1076 1045 1051 1068 1067 1066 1116 1013 1029 1064 1061 1016 1046 1025 1053 1016 1056 984 1040 963 931 927 954 922 943 906 878 938 896 839 912 897 873 822 857 782 821 794 790 795 864 796 845 838 838 811 742 801 767 785 765 781 815 824 760 874 808 854 798 816 831 802 803 825 797 792 814 789 842 807 788 754 811 778 785 791 793 805 893 839 840 811 783 880 845 870 836 849 868 847 849 884 844 894 905 944 896 880 900 944 963 902 957 938 982 987 939 1070 1009 999 1078 1089 1088 1108 1151 1154 1045 1161 1095 1163 1161 1223 1138 1226 1203 1202 1202 1274 1289 1241 1269 1306 1341 1422 1405 1408 1400 1396 1417 1408 1454 1473 1440 1390 1351 1409 1424 1405 1397 1412 1399 1325 1452 1319 1406 1422 1403 1404 1313 1228 1410 1264 1298 1249 1207 1225 1190 1189 1175 1123 1154 1190 1094 1123 1135 1050 1094 1130 1058 1065 1072 1045 997 984 1012 1017 1019 1051 1011 961 903 969 981 939 962 943 1002 974 979 1001 944 936 956 937 974 912 914 926 899 882 895 946 822 898 921 870 876 847 819 842 889 869 860 795 768 856 868 795 805 791 857 839 831 812 810 841 865 844 852 710 786 785 774 767 783 795 754 776 783 763 756 835 816 814 839 803 852 745 786 832 871 870 840 764 832 847 841 895 810 798 843 829 857 867 917 887 859 882 944 966 872 980 939 943 965 975 941 937 948 1021 957 881 876 918 973 840 909 961 885 891 922 894 915 893 873 852 836 836 903 851 882 847 886 837 829 809 868 873 838 827 811 829 724 804 829 830 821 821 866 828 839 808 839 858 837 848 908 835 890 793 867 845 871 811 882 874 932 848 886 854 883 894 934 891 955 882 928 915 910 901 945 905 927 937 885 928 906 902 915 892 894 1006 870 914 944 996 891 909 955 942 839 950 934 1032 887 978 938 956 936 938 938 976 958 939 1007 990 1022 990 934 1055 1051 1021 1003 1021 1024 1064 1032 995 1022 1047 1046 998 969 933 1002 996 1008 1002 976 974 952 966 1002 1048 1046 1002 930 939 1049 1017 981 958 981 958 1025 1018 1064 1013 987 996 1079 1087 1053 1086 1068 1089 1082 1126 1121 1122 1147 1193 1180 1171 1197 1215 1153 1233 1199 1207 1271 1132 1211 1173 1162 1219 1191 1141 1174 1102 1092 1029 1117 1076 1030 1045 977 1021 938 994 945 973 926 947 901 950 950 806 905 910 911 897 884 854 863 861 865 898 840 862 850 876 873 895 879 904 883 831 907 921 902 909 915 919 937 937 971 968 995 996 1010 983 1053 996 1054 985 1064 1018 1106 1052 995 1063 1060 1122 1092 1114 1105 1210 1043 1158 1119 1151 1167 1191 1190 1116 1112 1075 1132 1166 1149 1162 1166 1190 1122 1117 1135 1144 1058 1056 1070 1092 1055 1128 1055 1066 999 1014 961 944 1003 983 963 994 918 926 966 927 927 950 865 886 821 859 829 797 840 815 898 783 814 828 813 836 841 856 802 837 814 814 829 825 830 800 790 813 805 818 824 828 821 812 796 799 822 789 848 823 872 832 862 888 874 841 914 878 895 933 904 949 922 939 1010 1008 1012 1087 1096 1075 1179 1146 1180 1138 1128 1153 1209 1188 1221 1197 1186 1233 1241 1246 1253 1224 1263 1259 1243 1311 1237 1212 1244 1160 1190 1174 1145 1122 1106 1102 1101 1078 1096 1087 1088 1073 1060 1086 1011 1020 1012 1022 981 977 969 1064 991 982 921 925 885 961 964 920 897 861 907 927 858 887 938 907 880 1004 859 886 902 918 882 942 930 907 936 893 914 924 996 998 1050 1000 1012 972 1079 1100 1166 1187 1144 1129 1244 1236 1245 1248 1293 1269 1275 1303 1335 1345 1374 1421 1363 1359 1430 1408 1426 1423 1386 1334 1428 1408 1423 1403 1333 1365 1275 1270 1253 1233 1239 1136 1181 1186 1055 1059 1146 1068 1037 1050 1008 991 985 993 902 999 908 884 900 928 924 864 887 871 844 894 906 860 920 934 843 877 910 844 861 919 925 877 977 926 919 930 1016 949 941 945 974 996 994 993 992 947 976 987 972 999 1000 914 1022 964 968 963 982 949 934 955 959 867 952 902 982 921 940 876 934 837 821 860 840 917 922 860 798 800 824 772 868 778 754 770 792 820 804 781 808 757 775 771 765 733 789 713 764 722 776 750 772 755 739 771 743 738 710 768 728 760 746 806 696 708 755 774 735 746 742 752 827 715 777 725 805 714 746 763 794 816 799 786 744 760 817 781 748 776 803 764 821 796 774 859 766 828 768 851 808 803 794 789 815 816 838 873 809 848 880 816 874 886 853 873 892 833 871 894 846 855 943 914 888 949 907 994 920 972 1016 997 1027 1036 1043 1003 1023 1022 1078 1064 1040 1153 1113 1147 1094 1094 1135 1104 1102 1123 1086 1098 1082 1154 1074 1150 1090 1171 1078 1071 1040 1083 1032 1077 984 1016 995 988 987 1007 957 936 967 951 940 974 952 884 875 886 875 871 867 922 835 839 881 867 875 838 813 837 878 897 786 773 799 802 809 814 866 831 865 801 883 797 853 875 888 837 784 886 853 836 786 811 870 811 858 906 841 842 853 872 836 892 880 838 871 835 829 848 856 916 903 879 833 895 861 888 878 903 896 886 859 874 866 911 920 860 865 963 870 853 885 910 970 869 915 966 888 963 957 975 965 926 960 946 892 899 962 932 954 965 929 952 989 969 991 1037 985 1010 965 990 981 1012 956 1034 981 1008 1036 1079 985 1051 968 959 980 1051 1003 1037 1025 980 1000 1057 966 1026 982 954 936 934 906 935 918 916 884 876 842 849 882 858 804 790 809 786 801 796 798 816 770 825 751 761 737 766 750 756 728 763 730 735 675 734 718 725 774 692 745 780 680 728 751 703 719 754 775 651 739 728 743 750 717 661 821 722 761 718 747 659 718 720 696 709 704 728 703 728 761 728 743 730 730 753 768 754 719 736 727 753 697 672 709 722 733 763 770 664 728 713 720 722 723 718 700 721 771 710 754 727 691 761 687 713 736 713 760 753 738 740 788 737 802 766 756 754 779 709 805 731 751 765 739 750 789 804 753 813 830 807 810 795 774 831 838 787 847 856 856 828 874 897 838 842 838 859 879 883 873 832 851 853 924 839 871 870 825 890 828 918 819 871 882 890 802 856 789 896 815 876 824 799 809 836 828 763 777 840 802 860 804 825 814 817 867 837 794 866 847 784 792 845 806 834 793 832 850 860 820 815 855 834 863 857 921 866 844 864 858 893 870 897 822 845 839 907 948 882 908 897 930 885 989 873 916 882 962 921 974 981 947 965 970 1055 1007 1007 1003 1083 1040 1093 1026 1080 1070 1136 1074 1102 1152 1116 1179 1113 1140 1111 1072 1121 1054 1126 1060 1060 1056 1028 1019 1067 960 992 967 1036 1008 956 943 974 889 937 910 891 968 959 915 874 925 889 875 900 840 937 887 844 899 867 871 850 799 909 854 934 853 873 869 951 911 907 844 967 901 965 921 985 976 986 1047 984 996 987 1004 1041 1062 1063 1046 1051 1039 1083 1115 1077 1059 1055 1081 1050 1033 1016 1032 1047 1049 1024 985 953 1002 954 1021 940 1012 932 973 950 925 1011 894 933 886 967 882 880 903 911 961 909 928 896 892 853 951 915 955 895 956 892 896 933 928 898 949 917 927 959 1017 958 959 1012 999 976 1003 972 988 980 993 975 974 1012 961 973 961 949 995 1060 987 951 875 890 915 899 931 848 947 887 875 832 916 857 891 824 842 871 838 799 816 818 803 761 871 780 801 795 854 790 778 760 779 817 789 792 746 793 772 791 787 748 777 800 797 796 795 772 794 841 844 866 814 814 804 791 797 803 835 851 860 882 832 856 862 858 882 828 808 874 868 905 841 951 883 905 842 807 861 854 857 832 850 791 940 907 888 854 892 856 867 878 855 839 850 893 829 856 833 839 868 829 864 828 903 881 856 962 905 897 869 914 930 980 953 897 946 942 917 928 951 985 916 908 921 930 908 952 982 990 946 989 979 916 918 939 931 897 985 885 952 861 883 954 951 934 932 860 914 949 958 940 955 950 999 959 998 960 1045 967 1065 993 1073 992 1010 1036 1069 999 1089 1051 1026 1030 1033 1025 1109 1059 1067 1072 1078 1039 1069 1081 1077 1009 1046 1108 1112 1098 1113 1104 1081 1095 1068 1174 1108 1126 1151 1092 1187 1155 1152 1131 1172 1096 1100 1109 1078 1102 1102 1057 1066 1061 1109 1105 1056 1026 1018 979 951 1056 986 962 1005 980 974 900 936 912 919 899 901 914 917 879 860 825 878 843 856 813 796 780 751 850 784 824 815 783 737 743 760 729 724 742 747 736 797 785 762 707 764 706 769 709 832 724 738 709 736 812 743 763 779 716 782 770 739 737 740 741 740 738 731 777 759 746 682 736 729 758 758 773 782 758 743 706 709 762 745 774 695 741 704 725 732 625 683 747 734 727 706 731 750 719 790 774 750 724 772 754 754 662 784 760 815 760 751 738 775 768 806 737 738 754 742 822 745 818 820 827 830 776 847 826 931 823 894 877 867 890 911 883 942 958 908 951 971 1014 1043 1002 996 1064 1085 1088 1082 1097 1178 1050 1156 1141 1095 1088 1211 1143 1158 1100 1149 1111 1144 1090 1105 1112 1100 1149 1127 1128 1138 1115 1032 1029 1035 984 991 1034 1063 1002 962 978 940 938 957 986 942 994 920 912 881 875 906 884 855 950 842 923 837 871 872 812 875 891 849 787 861 835 837 848 813 913 783 834 907 851 864 815 808 834 854 803 842 806 769 839 849 791 834 828 749 767 773 800 807 834 827 740 837 812 740 757 743 764 778 776 802 796 746 746 729 778 798 730 777 748 708 753 699 707 782 771 720 742 747 744 746 755 808 751 812 780 770 767 800 788 740 848 789 790 770 817 895 810 835 866 812 869 882 863 834 892 858 824 848 822 878 820 888 872 910 804 876 887 867 833 859 802 819 748 809 839 824 851 789 843 865 784 875 814 873 801 862 795 874 790 782 840 801 841 844 758 758 810 753 850 774 830 812 798 755 785 802 825 801 765 813 800 826 730 807 735 816 749 760 796 730 762 761 804 728 765 801 779 714 707 726 736 806 772 697 741 715 792 717 776 686 790 729 748 688 677 739 738 737 746 741 707 742 755 707 788 736 751 759 783 759 759 771 783 801 823 792 827 816 841 838 803 818 858 838 822 857 866 894 884 794 861 860 861 802 838 794 835 849 859 813 840 810 791 825 794 813 778 836 858 817 786 790 808 792 764 816 838 825 796 821 810 839 785 799 805 786 777 779 770 790 806 763 793 758 809 836 834 776 778 848 747 819 761 819 837 843 802 846 830 851 869 910 809 905 875 844 915 952 916 930 991 952 943 933 949 973 978 956 958 911 908 1002 975 957 1024 941 936 925 965 911 988 890 882 899 951 915 876 903 869 913 849 958 882 902 845 842 823 845 837 831 803 797 781 821 802 779 770 839 769 785 794 801 794 711 776 785 820 777 781 745 825 783 812 768 810 769 826 811 739 725 775 750 801 767 801 765 775 764 829 761 804 753 729 798 828 730 760 771 754 748 757 740 718 769 747 760 762 759 777 706 743 759 758 729 705 767 743 725 766 720 711 738 734 643 681 693 649 705 713 679 719 802 704 743 708 710 670 713 764 720 732 736 740 656 711 696 690 705 691 707 718 710 694 708 720 711 709 692 695 732 687 748 706 722 694 714 743 744 719 723 745 729 709 729 702 718 699 669 694 699 717 702 723 675 684 704 712 738 737 678 659 721 694 681 707 729 694 694 678 725 662 665 718 675 718 741 684 701 667 695 706 688 728 684 698 692 754 661 757 715 733 685 732 722 673 702 745 680 731 706 690 722 752 715 696 696 740 663 745 703 662 678 698 698 714 682 710 722 729 710 705 713 692 717 696 667 710 691 762 641 766 671 660 674 748 725 707 705 727 734 693 666 656 704 667 726 703 677 738 699 762 744 696 702 681 709 748 689 713 782 679 732 735 769 703 745 707 715 777 791 745 716 758 782 783 807 784 765 757 854 780 787 869 753 784 806 756 793 845 733 849 795 741 809 759 751 770 766 758 777 783 818 742 791 765 791 807 732 825 747 746 747 782 772 726 754 684 752 731 740 701 756 739 750 769 716 732 682 782 796 687 731 754 743 774 698 715 737 767 757 668 705 760 776 678 697 722 693 757 737 683 713 686 742 702 724 803 726 681 740 781 709 738 794 736 772 751 731 699 724 708 759 761 718 757 771 780 781 783 759 726 734 719 749 788 792 838 695 805 824 766 866 790 795 810 750 769 824 816 902 828 845 803 791 837 823 788 825 788 816 763 850 784 806 798 895 811 863 796 825 852 889 815 832 842 817 825 818 815 817 751 819 790 842 844 797 814 823 810 827 839 809 770 790 807 812 801 817 822 841 781 811 761 811 863 794 742 808 753 799 776 783 833 786 800 719 784 793 754 809 736 796 756 774 758 785 784 719 794 693 696 753 751 818 754 769 766 773 786 734 787 716 807 762 792 775 770 785 778 785 761 814 773 811 791 771 818 830 837 808 848 837 795 835 848 793 819 812 760 834 822 854 856 818 842 842 769 844 821 805 846 817 814 817 806 769 814 780 839 776 845 771 776 770 854 771 731 830 828 834 825 821 773 777 827 747 810 764 790 787 732 838 796 810 804 814 808 771 772 729 795 788 754 755 776 721 727 734 705 784 718 756 753 766 797 756 788 764 752 807 765 798 771 763 760 736 795 756 800 703 799 765 752 730 725 769 764 729 720 797 778 764 771 755 769 779 742 777 767 780 754 799 813 742 744 782 765 783 840 730 775 753 701 706 782 709 771 793 736 778 765 791 788 754 727 743 781 735 735 763 743 769 751 777 747 780 792 745 790 727 759 749 749 767 773 767 774 798 750 745 743 731 781 782 774 756 752 703 696 696 755 739 728 737 695 760 752 702 750 722 717 699 703 690 730 778 749 703 696 699 774 719 723 759 750 745 765 781 812 753 737 773 732 735 734 737 765 733 729 728 732 761 732 707 790 737 774 743 750 781 743 709 722 699 739 750 756 748 690 784 708 714 790 724 713 754 788 776 761 817 779 793 751 826 773 753 827 732 833 787 845 796 845 870 791 843 829 801 849 840 801 826 823 812 823 803 810 930 801 840 827 785 848 844 822 856 830 864 826 797 813 810 813 751 866 813 763 858 772 791 826 830 803 756 808 787 796 759 821 750 818 770 787 806 767 788 688 794 692 794 771 805 768 784 743 738 749 739 825 786 819 729 794 792 769 790 822 820 764 815 735 797 762 772 807 768 791 753 798 805 736 747 779 800 792 754 773 805 809 812 790 730 741 811 775 789 760 734 725 765 777 735 763 758 751 797 810 777 763 747 709 766 694 686 727 755 762 740 799 757 736 780 773 842 775 780 701 772 821 803 791 790 750 837 825 840 801 823 802 813 850 809 803 845 831 862 834 860 823 800 901 789 829 878 887 859 892 897 878 899 865 893 951 894 910 881 897 948 885 928 933 945 915 952 876 970 878 903 888 857 868 860 864 853 905 903 808 838 811 857 858 841 868 838 770 860 830 814 846 855 821 834 762 730 787 817 784 787 798 763 786 788 786 797 771 760 752 718 786 793 747 797 735 831 719 750 782 765 719 737 730 719 778 778 746 774 766 787 786 744 768 755 755 799 770 755 757 815 759 793 778 781 826 763 755 766 768 805 762 776 771 765 770 715 771 864 835 731 782 866 752 874 823 845 818 818 882 837 886 888 854 846 809 808 857 871 898 904 878 868 927 937 871 942 863 863 848 835 897 845 870 815 861 830 878 821 900 819 796 805 850 851 852 816 796 818 848 853 806 826 787 764 822 850 827 841 792 766 810 757 801 818 771 749 772 726 807 721 754 772 790 787 802 804 745 725 756 808 771 794 866 835 751 738 783 798 812 795 805 833 846 821 854 873 878 857 860 772 867 863 845 808 830 835 905 850 814 859 791 903 839 922 826 814 831 818 822 898 845 849 784 865 769 758 774 821 838 798 817 786 762 751 845 792 813 762 833 808 747 758 768 781 773 777 769 738 671 735 739 746 712 736 691 730 746 726 701 728 715 687 690 702 813 696 730 715 768 736 780 724 759 685 719 781 704 762 740 715 700 749 705 674 715 717 688 711 702 712 653 715 729 713 695 743 704 736 712 691 681 755 737 736 703 678 689 734 690 677 687 723 685 731 691 671 696 713 692 664 644 718 690 703 701 716 771 704 703 744 698 698 714 685 702 712 707 691 723 720 720 686 689 705 721 723 675 721 824 679 711 692 696 686 698 734 742 729 728 761 688 746 723 741 751 748 751 659 713 700 736 772 741 769 777 739 724 743 756 775 776 824 739 751 738 742 775 834 791 748 788 773 760 825 778 790 835 692 735 750 766 821 759 773 812 768 707 777 801 782 787 801 774 752 842 744 767 745 768 714 842 738 707 755 833 760 768 753 813 757 794 737 773 763 784 739 807 803 749 755 781 821 800 824 810 881 821 811 761 865 790 831 797 816 837 796 814 897 807 834 842 764 871 779 825 822 826 871 813 822 822 790 827 845 819 851 833 789 826 809 787 858 790 801 822 810 771 809 776 825 773 808 813 706 895 730 772 814 765 767 804 804 824 777 784 757 769 779 747 737 777 740 736 791 736 795 751 750 795 733 751 767 810 798 791 775 745 807 728 770 778 773 756 735 787 815 828 745 815 773 810 714 850 752 763 789 771 807 799 720 835 740 745 789 763 818 744 781 728 752 771 782 767 803 713 744 732 729 792 741 805 783 767 777 777 809 740 791 757 788 743 807 808 801 772 824 725 750 817 784 744 807 791 854 823 886 837 825 791 880 852 805 901 804 827 798 860 814 831 850 862 879 847 832 851 854 827 891 816 839 868 886 812 883 854 800 790 841 832 815 833 852 894 829 794 847 809 783 850 825 815 839 868 808 859 745 769 833 766 786 776 787 784 809 776 832 761 800 821 820 777 790 822 763 817 767 788 771 832 743 759 797 804 766 825 777 748 740 815 728 781 760 742 698 779 770 794 753 757 773 805 805 784 782 803 744 801 814 755 822 806 813 809 802 801 808 824 776 856 784 795 767 799 814 784 804 793 776 789 831 796 784 794 762 771 855 850 770 811 789 735 857 817 787 817 838 902 878 838 806 807 797 797 824 819 758 807 826 839 827 787 777 778 776 781 834 781 820 809 802 774 803 791 827 803 795 787 820 802 836 796 756 795 767 746 799 792 804 805 830 868 803 784 773 785 791 767 778 797 817 747 723 785 736 797 770 770 808 753 785 783 810 741 748 832 759 847 747 824 804 753 740 774 754 770 807 841 783 751 762 791 744 791 738 748 774 750 729 752 823 763 792 783 762 704 742 757 733 733 729 745 808 748 788 825 730 776 748 811 734 823 763 803 779 837 820 823 846 780 832 803 805 789 817 772 796 748 803 838 805 836 798 832 824 769 771 782 726 781 725 784 818 770 812 753 790 750 746 765 758 753 755 752 766 747 762 706 752 773 774 779 787 797 772 755 763 695 744 726 721 800 708 728 760 771 805 719 724 764 740 757 788 759 790 781 800 745 767 754 767 762 763 784 740 796 753 799 783 775 789 762 763 798 794 795 779 770 789 803 783 763 742 762 766 756 729 832 790 755 763 857 725 792 757 766 803 841 780 813 737 774 769 810 814 828 743 784 809 882 829 827 860 843 805 907 843 814 827 839 875 866 862 875 813 873 871 875 872 893 872 881 871 916 903 915 936 871 944 927 934 998 931 906 922 945 944 969 948 973 967 953 989 974 930 894 914 978 921 977 946 944 935 887 888 933 880</counts>
			</dataPoints>
		</scan>
	</xrdMeasurement>
</xrdMeasurements>