File: dataset/precursor_mixture/V2O5_0p2013-La(OH)3_0p5000-ZrO2_0p3001--8min.xrdml
<?xml version="1.0"?>
<xrdMeasurements xmlns="http://www.xrdml.com/XRDMeasurement/2.3" xmlns:xsi="http://www.w3.org/2001/XMLSchema-instance" xsi:schemaLocation="http://www.xrdml.com/XRDMeasurement/2.3 http://www.xrdml.com/XRDMeasurement/2.3/XRDMeasurement.xsd" status="Completed" recordIdentifier="{7782842D-4AB1-4A2E-A286-19A586E45BE6}">
	<comment>
		<entry/>
	</comment>
	<sample type="To be analyzed">
		<id>V2O5_0p2013-La(OH)3_0p5000-ZrO2_0p3001--8min</id>
		<name></name>
		<preparedBy></preparedBy>
	</sample>
	<xrdMeasurement measurementType="Scan" status="Completed" sampleMode="Reflection">
		<usedWavelength intended="K-Alpha 1">
			<kAlpha1 unit="Angstrom">1.5405980</kAlpha1>
			<kAlpha2 unit="Angstrom">1.5444260</kAlpha2>
			<kBeta unit="Angstrom">1.3922500</kBeta>
			<ratioKAlpha2KAlpha1>0.5000</ratioKAlpha2KAlpha1>
		</usedWavelength>
		<incidentBeamPath>
			<radius unit="mm">145.00</radius>
			<xRayTube id="1010048" name="Empyrean Cu LFF HR (9430 033 7310x)">
				<tension unit="kV">40.0</tension>
				<current unit="mA">15.0</current>
				<anodeMaterial>Cu</anodeMaterial>
				<focus type="Line">
					<length unit="mm">12.0</length>
					<width unit="mm">0.4</width>
					<takeOffAngle unit="deg">6.0</takeOffAngle>
				</focus>
			</xRayTube>
			<sollerSlit id="21010002" name="Soller slits 0.04 rad.">
				<opening unit="rad">0.0400</opening>
			</sollerSlit>
			<mask id="22031000" name="Fixed mask 13 mm">
				<width unit="mm">9.00</width>
			</mask>
			<divergenceSlit id="22120001" name="Divergence slit 1°" xsi:type="fixedDivergenceSlitType">
				<distanceToSample unit="mm">50.00</distanceToSample>
				<height unit="mm">1.52</height>
			</divergenceSlit>
		</incidentBeamPath>
		<sampleMovement xsi:type="spinningSampleMovementType">
			<spinnerRevolutionTime unit="seconds">1.0</spinnerRevolutionTime>
		</sampleMovement>
		<diffractedBeamPath>
			<radius unit="mm">145.00</radius>
			<antiScatterSlit id="22090040" name="AS slit 9 mm (PIXcel)" xsi:type="fixedAntiScatterSlitType">
				<height unit="mm">9.00</height>
			</antiScatterSlit>
			<sollerSlit id="21020003" name="Large Soller slits 0.04 rad.">
				<opening unit="rad">0.0400</opening>
			</sollerSlit>
			<filter id="20030001" name="Large beta-filter Nickel">
				<material>Ni</material>
				<thickness unit="mm">0.020</thickness>
			</filter>
			<detector id="7010019" name="PIXcel1D-Medipix3 detector" xsi:type="rtmsDetectorType">
				<phd unit="keV">
					<lowerLevel>4.02</lowerLevel>
					<upperLevel>11.27</upperLevel>
				</phd>
				<mode>Scanning</mode>
				<activeLength unit="deg">5.542</activeLength>
			</detector>
		</diffractedBeamPath>
		<scan appendNumber="0" mode="Continuous" scanAxis="Gonio" status="Completed">
			<header>
				<startTimeStamp>2024-11-14T16:14:08-08:00</startTimeStamp>
				<endTimeStamp>2024-11-14T16:22:15-08:00</endTimeStamp>
				<author>
					<name>AutomatedUser</name>
				</author>
				<source>
					<applicationSoftware version="1.7b (136)">PANalytical Aeris Instrument Suite</applicationSoftware>
					<instrumentControlSoftware version="3.2.00000000 20240306">AERIS</instrumentControlSoftware>
					<instrumentID>950485</instrumentID>
				</source>
			</header>
			<dataPoints>
				<positions axis="2Theta" unit="deg">
					<startPosition>10.00943322</startPosition>
					<endPosition>99.99442286</endPosition>
				</positions>
				<positions axis="Omega" unit="deg">
					<startPosition>5.00471661</startPosition>
					<endPosition>49.99721143</endPosition>
				</positions>
				<commonCountingTime unit="seconds">12.495</commonCountingTime>
				<counts unit="counts">2248 2304 2398 2320 2267 2246 2319 2268 2220 2302 2252 2304 2213 2280 2332 2289 2320 2278 2233 2264 2221 2300 2227 2246 2231 2217 2229 2285 2200 2201 2240 2191 2225 2176 2190 2253 2184 2257 2143 2172 2211 2078 2065 2168 2135 2179 2201 2206 2108 2124 2136 2111 2231 2141 2084 2141 2153 2110 2113 2132 2141 2160 2006 2134 2139 2027 2084 2195 2106 2120 2120 2065 2008 2102 2083 2091 1967 2021 1980 2046 2069 2005 2079 2030 1982 2045 2003 2058 2006 2035 1981 1964 2009 2038 2017 2043 2047 2042 2068 2020 1955 1977 1942 2020 1923 1987 1996 1981 1906 2011 2067 2005 1999 1952 1974 2005 2081 1977 1961 1925 2022 1913 1996 1943 1951 1890 1934 1943 1895 1868 1922 1937 1896 1948 1881 1841 1876 1913 1903 1960 1885 1958 1807 1892 1848 1837 1839 1924 1833 1927 1823 1867 1798 1906 1911 1850 1871 1806 1854 1834 1898 1830 1862 1885 1853 1870 1888 1871 1886 1780 1777 1852 1799 1773 1793 1784 1830 1848 1798 1841 1750 1846 1743 1842 1833 1844 1784 1817 1819 1804 1758 1808 1777 1704 1791 1778 1715 1812 1798 1818 1720 1777 1796 1733 1752 1760 1753 1760 1679 1770 1751 1730 1774 1747 1777 1764 1729 1676 1692 1843 1757 1759 1760 1777 1776 1750 1662 1721 1662 1705 1746 1694 1728 1678 1703 1677 1719 1700 1679 1718 1669 1707 1692 1649 1653 1655 1675 1776 1668 1710 1717 1680 1732 1687 1679 1648 1719 1656 1651 1683 1648 1656 1686 1632 1644 1657 1716 1704 1681 1644 1605 1678 1608 1659 1780 1653 1640 1524 1687 1680 1720 1727 1672 1586 1650 1584 1635 1729 1680 1675 1673 1607 1590 1590 1607 1684 1614 1637 1631 1593 1579 1602 1573 1624 1653 1617 1568 1671 1702 1598 1596 1595 1628 1620 1584 1542 1595 1627 1559 1563 1627 1568 1545 1566 1574 1611 1602 1536 1583 1595 1629 1589 1556 1497 1545 1567 1616 1602 1563 1631 1539 1567 1563 1582 1543 1536 1628 1556 1488 1505 1574 1512 1551 1549 1545 1563 1544 1611 1493 1568 1597 1529 1551 1556 1506 1570 1506 1564 1537 1569 1500 1522 1517 1558 1608 1559 1507 1561 1528 1536 1626 1537 1516 1568 1532 1540 1569 1470 1568 1506 1437 1525 1486 1438 1576 1474 1541 1554 1521 1517 1535 1508 1516 1521 1390 1550 1587 1512 1492 1502 1509 1476 1533 1488 1570 1484 1493 1489 1631 1572 1477 1497 1498 1540 1567 1515 1502 1529 1583 1480 1586 1442 1509 1549 1556 1462 1580 1476 1536 1411 1585 1473 1538 1481 1483 1587 1505 1528 1536 1553 1530 1530 1537 1517 1519 1506 1517 1534 1535 1590 1444 1543 1539 1576 1551 1561 1558 1541 1537 1538 1601 1615 1677 1587 1661 1659 1664 1705 1691 1747 1626 1739 1792 1689 1745 1705 1865 1822 1849 1913 1853 1918 1994 1962 2051 2123 2154 2044 2240 2267 2318 2417 2393 2594 2582 2522 2723 2770 2832 2859 2860 3017 2974 3131 3159 3342 3293 3333 3424 3483 3619 3525 3548 3726 3789 3816 3920 3890 3955 3871 3963 3928 3982 3974 3912 4034 4021 3883 3934 3887 3980 3857 3802 3801 3687 3725 3598 3399 3359 3248 3033 3012 2803 2733 2560 2494 2439 2328 2265 2189 2112 2022 1981 1891 1865 1905 1802 1792 1755 1778 1652 1717 1624 1707 1611 1641 1614 1612 1650 1596 1623 1572 1584 1528 1513 1511 1527 1525 1512 1519 1444 1521 1459 1473 1539 1507 1437 1545 1475 1491 1491 1406 1587 1452 1472 1449 1495 1457 1489 1454 1456 1429 1459 1402 1413 1457 1401 1406 1421 1484 1476 1410 1445 1412 1417 1399 1394 1425 1397 1406 1464 1403 1414 1442 1366 1405 1353 1373 1322 1418 1432 1386 1347 1426 1384 1375 1418 1363 1376 1366 1340 1431 1412 1422 1361 1415 1380 1371 1370 1448 1412 1383 1395 1359 1375 1321 1436 1431 1472 1421 1415 1414 1454 1424 1421 1433 1472 1434 1355 1432 1445 1387 1411 1441 1424 1417 1354 1343 1425 1409 1477 1463 1491 1398 1456 1386 1435 1347 1466 1352 1437 1403 1511 1378 1361 1379 1410 1408 1439 1337 1452 1258 1329 1366 1384 1401 1314 1331 1357 1385 1384 1350 1414 1314 1329 1371 1337 1332 1349 1308 1360 1354 1342 1308 1357 1351 1332 1397 1247 1347 1366 1330 1306 1275 1306 1355 1315 1428 1303 1380 1341 1292 1317 1244 1364 1260 1330 1324 1284 1366 1294 1298 1252 1282 1309 1353 1325 1291 1259 1305 1285 1214 1313 1331 1353 1380 1288 1331 1305 1320 1351 1308 1298 1299 1303 1264 1272 1257 1270 1279 1243 1298 1233 1214 1318 1252 1300 1243 1295 1294 1245 1207 1283 1260 1313 1287 1230 1282 1301 1301 1303 1311 1295 1287 1282 1307 1275 1260 1253 1315 1280 1205 1244 1329 1276 1287 1252 1291 1289 1242 1293 1235 1239 1178 1305 1186 1259 1291 1273 1192 1216 1284 1239 1289 1252 1224 1201 1214 1254 1247 1239 1249 1254 1253 1259 1236 1264 1258 1269 1244 1205 1239 1235 1243 1244 1257 1225 1244 1278 1225 1281 1255 1267 1186 1157 1209 1239 1247 1267 1265 1213 1186 1310 1260 1298 1235 1239 1249 1219 1227 1164 1168 1241 1173 1268 1218 1230 1296 1191 1158 1245 1192 1209 1249 1215 1233 1158 1250 1241 1201 1249 1265 1290 1277 1290 1285 1209 1261 1257 1322 1272 1337 1320 1298 1244 1381 1471 1394 1396 1455 1376 1481 1467 1499 1422 1485 1516 1574 1540 1559 1618 1720 1640 1715 1771 1758 1763 1765 1928 1862 1932 1900 2002 1931 1985 1945 2044 1966 2061 2018 2013 2059 2078 2064 2108 2103 2027 2116 2029 2069 2032 2008 1950 1981 1943 1925 1916 1897 1757 1712 1638 1667 1481 1476 1460 1448 1426 1269 1308 1262 1281 1271 1229 1212 1220 1208 1247 1273 1268 1240 1177 1229 1170 1217 1176 1165 1231 1114 1169 1174 1184 1165 1238 1211 1194 1151 1170 1178 1197 1169 1262 1147 1204 1237 1120 1150 1254 1171 1162 1260 1121 1125 1163 1114 1163 1158 1161 1154 1235 1253 1165 1152 1125 1201 1217 1237 1212 1187 1248 1157 1215 1211 1178 1186 1161 1177 1122 1251 1206 1161 1191 1201 1244 1195 1232 1217 1305 1259 1297 1222 1297 1264 1310 1289 1345 1262 1319 1269 1332 1349 1404 1363 1353 1400 1315 1365 1362 1433 1402 1333 1344 1428 1411 1332 1393 1364 1440 1426 1434 1394 1366 1414 1424 1369 1437 1350 1330 1339 1326 1285 1301 1217 1267 1269 1232 1275 1219 1238 1186 1272 1168 1213 1180 1121 1100 1149 1095 1140 1126 1136 1136 1115 1142 1212 1122 1149 1142 1064 1182 1172 1148 1192 1165 1125 1171 1146 1124 1152 1117 1104 1079 1158 1156 1129 1241 1154 1141 1140 1083 1126 1095 1025 1127 1088 1125 1136 1119 1060 1108 1081 1062 1132 1128 1192 1144 1060 1096 1120 1101 1120 1132 1113 1190 1097 1091 1128 1149 1156 1088 1118 1085 1088 1083 1082 1125 1084 1090 1095 1080 1118 1104 1108 1011 1053 1077 1092 1118 1095 1117 1044 1082 1123 1053 1108 1130 1130 1156 1067 1029 1145 1103 1133 1083 1059 1026 1146 1091 1105 1125 1054 1098 1022 1080 1126 1130 1078 1085 1077 1114 1091 1095 1059 1105 1118 1102 1170 1058 1023 1044 1082 1131 1085 1087 1090 1095 1091 1196 1117 1109 1093 1104 1166 1157 1132 1104 1089 1105 1142 1127 1153 1149 1151 1152 1171 1124 1079 1151 1085 1131 1145 1192 1248 1186 1201 1234 1208 1231 1233 1255 1243 1246 1255 1223 1209 1335 1211 1275 1296 1316 1343 1316 1346 1330 1329 1394 1371 1392 1389 1395 1409 1418 1336 1357 1361 1341 1447 1408 1409 1398 1424 1438 1349 1356 1356 1338 1325 1319 1242 1312 1289 1311 1223 1357 1327 1325 1288 1299 1370 1316 1273 1297 1333 1287 1314 1251 1231 1208 1309 1310 1281 1230 1246 1244 1322 1246 1251 1187 1195 1166 1187 1179 1180 1197 1194 1146 1145 1194 1123 1145 1125 1058 1141 1111 1095 1062 1124 1129 1078 1097 1047 1046 1112 1040 1084 1081 1067 1089 1050 1037 1061 1084 1056 1031 1032 1062 1051 1064 1032 1032 1035 1090 1044 1051 1057 1083 1028 1112 1008 1127 1059 1003 1081 991 1059 1048 1111 1053 1119 1117 1097 1067 1034 1098 1052 1085 1060 1062 1140 1093 999 1080 1008 1055 1084 1098 1017 1080 1042 1057 955 1061 1034 1046 1044 1103 1067 1097 1091 1065 1109 1066 1077 1112 1108 1105 1081 1137 1151 1113 1067 1122 1096 1138 1093 1084 1107 1057 1120 1083 1175 1110 1147 1096 1105 1194 1186 1136 1156 1319 1190 1175 1141 1226 1257 1201 1262 1249 1298 1288 1250 1322 1299 1371 1389 1282 1337 1334 1360 1294 1382 1408 1412 1408 1376 1355 1415 1325 1423 1422 1372 1382 1339 1396 1312 1330 1317 1255 1260 1340 1221 1257 1181 1228 1174 1206 1169 1121 1182 1177 1181 1100 1134 1093 1138 1136 1139 1118 1116 1139 1149 1113 1140 1173 1182 1098 1170 1282 1276 1310 1197 1205 1262 1238 1267 1262 1227 1310 1335 1388 1389 1440 1404 1539 1545 1522 1484 1592 1609 1693 1782 1858 1832 1895 1921 2048 2072 2115 2300 2269 2310 2460 2546 2659 2842 2783 2922 2903 3029 3070 3111 3186 3218 3484 3466 3619 3488 3484 3700 3743 3683 3776 3797 3937 3950 4007 4011 4014 4081 4006 4034 4197 3901 3936 3830 3776 3891 3697 3676 3595 3439 3469 3309 3301 3059 3031 2889 2941 2843 2735 2687 2683 2639 2700 2620 2718 2643 2665 2695 2777 2716 2839 2925 3030 3121 3191 3437 3403 3518 3602 3760 3775 3854 3924 4127 4310 4361 4478 4649 4697 4924 5077 5076 5252 5219 5274 5566 5566 5832 5731 5753 5893 5967 6111 6086 6107 6220 6015 6109 6085 5990 6001 5920 5762 5631 5477 5249 5145 5005 5001 4960 4650 4656 4503 4342 4252 4107 4034 3821 3707 3573 3481 3254 3292 3145 2916 2728 2644 2511 2401 2244 2085 2097 1955 1845 1776 1745 1649 1670 1618 1504 1536 1486 1510 1374 1329 1366 1332 1269 1314 1236 1346 1273 1268 1279 1316 1241 1153 1168 1251 1182 1139 1168 1136 1084 1213 1124 1112 1166 1138 1108 1208 1097 1110 1084 1082 1078 1077 1066 1110 1098 1022 1045 1070 1060 1071 1117 1071 1030 1040 1050 978 1038 1021 1046 1069 1032 1065 1027 1073 1011 1014 1022 1028 1042 1014 1025 1025 1077 989 1042 1018 1021 998 991 970 1059 988 1043 1022 1064 999 976 972 1015 1055 1037 1014 1055 1038 1067 1034 1049 965 970 948 973 1044 990 1023 994 961 1004 959 1008 1054 964 1053 1003 1002 986 941 1036 1025 1030 1037 993 1005 1011 995 964 1034 1043 1000 995 974 1025 1015 1055 994 922 980 966 982 1003 1015 969 1022 956 1053 975 1027 1025 1003 1050 967 986 944 944 980 950 933 1003 1029 1011 948 995 1002 991 1016 936 963 970 906 1018 959 1030 1004 930 984 983 1029 985 1024 947 1053 1002 972 1065 1053 1070 1001 1019 1006 1042 1038 999 1041 1030 994 1074 994 1044 1081 1118 1090 1046 1055 1126 1082 1100 1137 1186 1136 1133 1145 1153 1228 1279 1273 1257 1288 1268 1237 1292 1402 1336 1393 1386 1396 1386 1439 1464 1470 1491 1469 1496 1544 1606 1602 1556 1637 1540 1658 1616 1704 1705 1731 1758 1805 1849 1849 1791 1837 1923 1903 1841 1901 2064 2033 2073 2112 2175 2168 2222 2206 2205 2315 2357 2365 2394 2531 2592 2538 2600 2659 2684 2716 2848 2853 2973 2841 2867 2975 3009 3013 3006 3022 3063 3064 3002 2947 2875 2892 2953 2959 2750 2728 2664 2487 2527 2393 2318 2201 2122 2049 1993 1886 1829 1752 1735 1667 1622 1587 1473 1418 1367 1462 1357 1398 1205 1296 1194 1278 1173 1176 1190 1089 1140 1104 1129 1081 1093 1072 1069 1065 1059 1026 1088 1074 1032 1102 1011 1020 1056 1056 1076 1051 989 1008 1030 1063 1046 1035 1084 1058 986 997 1069 1013 1043 1070 1142 1031 1063 1103 1094 1119 1104 1070 1040 1147 1054 1090 1063 1068 1022 1019 1068 989 1039 982 1002 969 956 928 946 982 940 917 932 922 877 889 917 909 893 898 879 907 916 884 930 884 885 868 876 932 927 916 885 820 833 841 813 885 900 872 909 904 859 911 867 907 893 873 892 839 847 860 865 875 899 884 886 929 902 929 900 894 928 882 878 831 946 975 953 910 883 912 891 895 910 956 913 970 890 907 919 1002 941 950 941 928 968 880 879 966 881 903 882 920 943 845 936 848 883 882 917 838 912 814 926 865 982 873 942 901 955 953 991 907 921 883 921 983 992 975 1010 983 1026 1042 1079 1069 1086 1076 996 1096 1066 1145 1152 1201 1183 1211 1250 1210 1259 1291 1283 1273 1321 1342 1394 1312 1387 1345 1404 1452 1515 1477 1463 1594 1539 1494 1568 1549 1578 1539 1576 1580 1479 1595 1508 1584 1493 1532 1471 1533 1486 1490 1473 1450 1413 1383 1326 1343 1375 1323 1262 1240 1341 1219 1207 1193 1114 1114 1083 1132 1064 1084 1102 1090 1002 1044 1006 994 971 938 907 947 902 977 871 948 902 884 915 907 896 883 910 866 917 914 912 883 893 848 851 920 866 924 945 999 915 941 933 986 913 994 940 980 999 1064 1020 1043 925 1004 1062 1014 1097 1066 1042 1123 1136 1043 1180 1113 1133 1105 1124 1179 1159 1149 1152 1167 1110 1194 1170 1164 1236 1148 1093 1103 1167 1142 1130 1160 1063 1058 1048 1129 1088 1117 1030 1038 1025 993 994 994 913 989 936 988 948 972 896 915 960 960 932 989 1020 1059 975 991 1016 1069 951 1048 1075 1051 1085 1070 1108 1083 1070 1152 1064 1151 1172 1146 1100 1155 1096 1233 1187 1177 1208 1148 1175 1212 1134 1148 1201 1155 1100 1038 1126 1133 1105 1120 1123 1010 1055 1010 1047 1075 985 1049 994 989 935 851 929 871 936 891 850 868 837 863 839 837 859 811 800 818 812 804 838 793 813 846 758 806 736 819 826 759 869 743 788 809 783 808 772 797 846 813 823 818 774 808 847 846 782 733 790 747 804 768 788 753 798 789 815 762 736 779 822 757 782 764 780 784 776 808 749 829 724 747 782 778 759 798 765 780 740 734 815 739 760 798 808 811 872 775 810 758 762 765 743 800 804 764 858 873 757 857 790 779 768 783 785 773 788 766 844 781 780 849 832 785 783 761 775 750 818 836 711 764 772 824 801 823 750 820 707 832 747 770 816 760 741 742 789 784 727 706 771 753 815 835 806 725 836 794 798 813 795 753 790 760 754 804 761 772 844 826 746 795 749 759 770 783 783 782 772 799 785 732 760 816 816 787 797 803 824 739 817 808 811 843 857 857 758 817 872 843 889 903 845 920 902 841 891 867 870 861 829 898 924 871 905 858 960 910 969 849 985 906 995 996 903 925 952 991 965 948 960 1009 951 964 1059 985 1016 969 989 1007 934 934 954 1000 1011 981 1006 926 994 1006 962 970 1013 1004 987 1054 1041 1069 1122 1158 1061 1090 1145 1184 1128 1237 1259 1280 1208 1386 1368 1392 1444 1451 1513 1569 1659 1722 1767 1835 1905 2069 2024 2161 2216 2350 2359 2388 2549 2608 2711 2777 2867 2890 3019 3129 3157 3300 3312 3409 3430 3445 3541 3584 3579 3527 3703 3788 3773 3804 3748 3822 3818 3697 3709 3707 3627 3682 3576 3415 3257 3288 3212 3231 2961 2847 2791 2591 2514 2439 2382 2150 2192 2069 1928 1917 1770 1740 1608 1569 1554 1438 1386 1384 1338 1259 1301 1270 1220 1211 1108 1163 1111 1157 1098 1040 1055 1002 993 970 974 988 930 958 956 1006 992 925 963 926 887 884 907 922 909 915 915 913 907 847 851 897 851 874 896 890 895 881 887 874 865 876 910 885 902 894 920 894 967 948 906 960 959 928 941 926 920 951 959 1069 985 985 979 988 959 1027 1036 1024 1063 996 1084 1077 1057 1049 1110 1099 1089 1119 1112 1146 1060 1096 1102 1126 1094 1103 1078 1096 1063 1063 1101 1082 1030 997 1043 1089 1052 1053 1030 1012 1032 986 1051 1018 1049 1001 1085 968 1066 1094 1109 1065 1035 994 1137 1096 1107 1104 1087 1061 1050 1155 1137 1118 1150 1181 1118 1174 1154 1170 1158 1179 1120 1125 1187 1112 1090 1047 1091 1047 966 1049 1012 1019 1013 960 1000 980 940 916 962 904 909 926 932 891 864 888 930 881 795 883 855 866 918 825 865 903 876 860 947 866 945 921 911 968 913 956 950 994 918 1000 965 1044 1020 1011 1049 1085 1146 1113 1177 1124 1195 1086 1235 1160 1232 1240 1230 1246 1280 1285 1318 1412 1381 1406 1288 1372 1323 1387 1375 1312 1355 1342 1376 1333 1320 1308 1337 1364 1317 1276 1371 1279 1256 1236 1209 1203 1195 1163 1130 1050 1152 1067 995 1005 964 993 943 989 969 895 937 891 895 870 817 875 850 827 846 827 871 835 824 842 824 833 773 790 836 788 790 763 737 774 715 738 776 760 750 779 750 749 795 755 778 769 771 763 779 751 733 720 795 823 834 767 722 804 780 771 687 739 790 767 762 732 721 697 710 735 684 758 699 715 766 717 735 696 741 749 777 803 743 724 693 756 726 708 752 717 758 779 739 764 777 763 710 779 708 753 779 733 744 702 706 721 730 733 757 740 712 701 687 729 746 808 716 720 741 729 697 719 743 727 717 713 704 723 737 734 764 701 708 724 737 694 717 706 762 672 710 711 757 742 762 736 772 753 729 702 788 724 660 777 764 754 738 728 728 748 710 743 759 776 772 710 765 727 754 756 701 724 757 714 786 756 770 755 760 696 750 746 784 741 707 761 782 714 794 771 766 754 755 741 744 716 828 685 792 819 878 781 851 830 883 855 794 834 785 876 819 866 815 842 885 909 883 867 863 836 913 851 894 846 936 920 911 886 810 879 860 867 859 916 834 820 818 855 834 820 831 777 789 802 796 814 813 812 829 788 804 789 858 865 834 829 827 830 796 831 821 857 853 847 817 857 861 865 858 914 931 895 913 912 889 947 905 890 958 891 919 994 919 922 962 955 968 1039 1049 886 982 942 978 940 992 933 894 886 899 909 910 875 817 826 796 819 801 812 822 756 825 775 796 774 800 790 746 739 760 796 785 742 744 764 755 762 817 737 770 690 664 690 704 713 748 732 738 706 770 703 754 735 747 753 723 763 714 773 767 764 777 733 692 721 715 750 694 775 731 755 752 760 763 777 740 743 775 729 744 739 757 778 775 777 705 743 802 790 810 805 717 737 783 760 833 838 849 799 789 853 823 769 842 853 862 861 885 888 813 864 906 955 931 937 984 954 1027 1025 1007 1091 995 1093 1079 1074 1147 1180 1162 1132 1179 1215 1166 1194 1221 1281 1307 1298 1216 1275 1238 1322 1277 1322 1351 1332 1328 1360 1377 1325 1334 1258 1241 1289 1188 1252 1163 1244 1251 1175 1171 1149 1171 1142 1215 1173 1110 1118 1053 1161 1102 1065 1077 1000 1025 1013 1057 1006 960 1068 943 1035 1014 974 944 957 1037 908 1001 1047 1060 962 998 1020 1003 1020 983 1078 1074 1151 1072 1091 1097 1155 1225 1182 1231 1278 1291 1244 1308 1343 1394 1344 1410 1401 1573 1532 1616 1493 1544 1665 1598 1742 1783 1696 1800 1887 1933 1894 1928 1999 1975 2035 2053 2203 2161 2218 2239 2279 2267 2313 2389 2346 2390 2318 2527 2544 2489 2621 2592 2627 2766 2758 2699 2813 2753 2824 2961 2777 2930 2820 2979 2918 3137 3097 3057 3264 3108 3244 3257 3329 3340 3287 3295 3398 3437 3463 3503 3500 3569 3579 3587 3579 3626 3622 3598 3652 3554 3580 3436 3364 3372 3221 3207 3178 3130 3045 2996 2865 2789 2657 2647 2566 2431 2420 2288 2192 2203 2090 2052 2050 2001 1814 1881 1845 1690 1704 1732 1710 1667 1672 1591 1563 1571 1511 1454 1452 1477 1545 1477 1414 1393 1350 1338 1404 1324 1392 1418 1435 1433 1451 1378 1453 1393 1396 1461 1387 1311 1397 1386 1327 1336 1314 1259 1339 1296 1242 1205 1169 1203 1225 1165 1197 1123 1126 1106 1141 1142 1079 1114 1125 1064 1079 1073 1131 1102 1065 1165 1080 1147 1185 1148 1096 1203 1189 1156 1207 1131 1196 1278 1256 1334 1257 1289 1298 1328 1344 1451 1373 1470 1455 1472 1485 1522 1537 1469 1541 1520 1640 1556 1575 1555 1557 1555 1575 1540 1586 1597 1598 1581 1562 1617 1565 1555 1523 1448 1518 1478 1440 1419 1428 1366 1324 1333 1325 1262 1280 1262 1200 1214 1235 1126 1197 1105 1174 1129 1155 1108 1117 1128 1054 1074 1148 1084 1117 1101 1122 1110 1130 1054 1066 1054 1102 1041 1108 1125 1042 1097 1019 1053 996 957 1026 1064 968 998 917 966 957 899 908 876 942 932 829 868 825 814 915 843 868 831 867 844 892 845 844 866 850 878 861 942 863 846 905 931 889 936 886 964 917 960 962 969 972 918 965 939 960 971 948 981 941 997 954 972 933 986 962 971 962 877 918 893 888 854 843 788 808 829 807 769 803 825 795 768 783 728 726 740 750 754 730 799 746 786 752 697 804 744 763 742 781 728 798 752 789 639 702 697 728 713 760 751 767 685 737 704 750 693 777 736 697 709 739 750 732 773 741 743 757 720 749 764 732 734 709 730 755 784 735 768 774 811 725 781 682 780 770 725 712 664 650 715 676 691 730 674 703 647 709 641 726 677 725 708 667 728 687 716 681 713 708 699 650 706 707 717 720 712 676 673 708 670 721 679 713 670 674 754 678 693 690 706 665 707 706 662 717 708 715 699 729 693 725 625 669 659 670 738 685 648 661 621 702 662 693 685 627 720 645 690 678 665 664 629 712 630 694 691 644 696 689 637 669 686 653 650 686 673 674 722 715 709 671 667 724 663 684 625 719 716 684 685 698 681 640 663 680 710 662 678 687 699 699 738 728 658 684 661 701 670 680 682 701 698 690 717 712 759 702 792 712 709 709 706 718 741 747 760 764 749 762 775 778 812 763 810 787 791 812 860 832 781 812 809 856 867 861 949 887 865 910 928 890 922 982 940 978 972 996 971 1014 983 937 985 939 968 1020 1034 1032 997 923 917 963 959 983 971 896 897 865 867 856 823 961 877 813 865 776 800 830 830 825 746 743 762 765 801 789 786 753 799 777 782 765 717 778 769 722 740 761 745 761 762 779 799 732 767 862 744 801 798 755 826 791 877 853 829 819 850 859 869 894 960 895 939 917 949 958 925 945 1009 979 969 1040 1050 1147 1092 1201 1176 1160 1237 1215 1251 1256 1253 1383 1282 1383 1382 1402 1492 1519 1577 1568 1543 1657 1627 1628 1695 1671 1721 1737 1723 1744 1797 1767 1682 1750 1764 1743 1758 1765 1781 1751 1742 1723 1668 1689 1620 1593 1580 1606 1576 1538 1527 1524 1493 1416 1406 1432 1359 1322 1382 1411 1339 1376 1269 1307 1292 1208 1291 1276 1197 1143 1203 1176 1185 1204 1142 1117 1140 1102 1153 1114 1144 1128 1194 1092 1126 1099 1201 1118 1224 1138 1121 1187 1134 1092 1159 1111 1088 1131 1192 1126 1127 1176 1170 1194 1119 1170 1134 1138 1104 1260 1148 1133 1216 1166 1232 1195 1199 1157 1202 1185 1223 1155 1180 1130 1155 1110 1110 1140 1092 1091 1084 1062 1025 1054 1044 1021 1057 1040 934 973 992 925 954 967 901 913 923 941 854 843 885 867 813 902 802 821 800 845 831 813 862 787 804 795 770 773 799 818 805 747 773 741 777 803 748 719 806 831 800 818 776 794 802 769 782 742 836 757 838 887 853 817 836 854 827 840 839 894 853 856 878 865 898 932 893 871 813 912 883 967 850 905 842 924 814 859 824 867 809 866 875 831 840 833 874 777 849 767 813 794 781 816 809 901 846 775 868 803 820 845 912 865 911 900 829 897 879 891 913 912 906 946 926 949 962 961 935 947 993 1003 1001 960 963 955 988 1007 1068 999 1018 1044 1030 1013 1039 947 1028 989 967 949 1008 988 934 931 905 900 944 850 859 874 899 923 873 844 876 867 857 870 848 837 893 822 910 837 889 813 847 892 843 835 868 870 882 872 864 819 784 916 832 853 924 793 837 917 889 884 888 808 865 860 847 923 926 923 876 898 932 935 962 917 926 942 897 905 869 917 967 937 989 942 933 913 911 884 938 973 923 922 966 941 892 853 896 871 868 928 893 824 910 862 945 859 910 895 830 854 822 809 844 827 778 843 812 789 790 807 818 765 769 755 764 702 739 764 778 742 756 728 714 736 719 778 739 760 729 733 714 689 740 694 729 769 732 742 781 738 711 764 699 734 757 791 781 765 733 769 797 790 852 801 830 851 819 876 861 847 805 915 910 855 849 919 919 932 874 900 987 973 955 938 920 980 896 966 968 980 947 921 956 964 971 983 915 904 912 951 962 907 914 891 903 839 895 910 896 899 919 896 881 818 917 904 843 790 841 801 837 821 783 772 800 762 758 779 706 794 723 749 687 723 652 699 714 720 659 656 676 713 708 668 680 633 661 664 707 718 669 687 675 709 632 702 670 720 652 711 643 655 757 636 677 639 645 666 656 670 612 700 680 678 730 682 740 706 713 762 751 677 722 705 641 709 743 705 668 697 762 775 750 747 765 836 728 791 722 793 788 775 831 806 802 758 798 815 792 775 831 855 777 793 800 743 838 781 794 809 822 814 757 882 802 854 812 818 843 817 780 816 829 826 834 836 783 816 808 837 803 797 743 680 766 800 741 741 762 762 761 792 722 775 737 731 758 740 764 746 796 794 756 706 781 771 771 828 808 783 825 887 841 832 827 783 846 857 844 837 875 871 884 908 966 846 880 933 898 921 848 884 886 859 860 831 837 858 819 777 795 818 818 805 803 823 789 743 793 776 801 765 784 799 784 741 747 789 732 737 682 716 785 716 744 691 683 724 656 727 742 762 708 741 775 752 756 767 779 725 783 719 750 806 775 758 839 929 817 813 816 878 869 815 852 862 828 859 877 931 889 939 891 872 870 906 927 874 908 936 819 856 786 831 938 771 836 806 813 791 823 834 796 727 756 782 811 738 741 796 745 700 697 704 767 658 699 701 744 701 718 728 686 739 759 709 697 723 735 689 685 752 712 721 744 760 790 764 837 776 794 771 744 753 748 794 840 830 833 910 780 872 922 831 891 946 923 909 994 1014 974 988 952 1006 1056 1129 1108 1109 1172 1170 1173 1196 1161 1258 1211 1201 1267 1255 1217 1319 1315 1318 1354 1351 1384 1313 1333 1360 1398 1413 1450 1377 1340 1379 1415 1396 1329 1280 1255 1280 1254 1329 1231 1202 1229 1164 1258 1201 1193 1227 1238 1141 1060 1022 1053 1093 1018 1109 1035 1000 1076 1000 993 1001 945 967 919 960 895 919 946 974 856 823 896 863 841 825 849 829 767 810 805 837 867 812 820 787 822 800 744 847 792 813 818 843 883 891 828 793 837 810 851 851 895 884 868 881 911 839 924 854 906 944 957 907 877 927 917 950 900 983 927 974 903 960 920 931 962 871 941 929 933 928 880 913 895 932 914 934 930 872 882 877 952 877 889 896 799 882 932 867 826 834 821 825 796 826 906 812 877 848 858 848 847 843 804 827 860 872 881 847 825 887 905 890 883 888 903 884 810 900 892 879 944 960 875 962 941 950 876 990 873 878 881 915 959 893 906 822 844 843 908 827 864 881 828 850 822 843 873 844 837 792 853 798 813 815 839 845 854 815 733 800 791 777 772 743 788 765 756 747 725 766 710 685 699 723 706 716 646 730 696 688 666 700 680 672 649 662 631 653 628 637 671 633 649 658 638 630 645 675 659 680 625 654 642 606 622 635 614 620 623 569 679 623 629 665 603 601 591 626 625 584 589 628 595 623 620 586 576 581 615 624 651 617 662 648 643 579 581 606 602 670 585 628 568 610 626 615 582 654 596 665 590 662 597 608 651 553 600 622 671 638 560 626 661 620 603 567 594 607 668 568 659 593 642 618 598 618 553 636 641 630 629 624 597 601 584 664 709 610 658 625 628 582 601 627 597 646 610 611 598 621 656 641 632 628 650 642 637 646 594 666 634 630 625 644 616 638 638 601 639 605 623 594 677 551 632 600 600 661 670 691 631 571 613 646 638 626 601 619 638 622 609 608 667 608 689 633 608 646 645 624 633 614 594 627 658 612 616 610 654 637 658 682 630 603 611 598 724 630 638 607 673 641 689 642 651 625 682 661 599 639 646 655 653 627 629 633 650 671 708 673 691 658 637 714 667 711 708 742 677 741 672 727 729 686 753 735 733 747 776 691 738 703 725 716 723 711 759 716 789 732 782 734 744 721 741 755 757 738 807 752 713 777 764 749 809 747 773 803 758 720 787 766 770 773 793 799 749 806 792 833 823 772 871 940 843 870 818 839 872 905 881 934 922 1001 940 999 972 1074 1108 1084 1032 1070 1062 1074 1102 1126 1116 1139 1156 1164 1109 1167 1190 1135 1135 1184 1132 1155 1183 1212 1181 1165 1136 1195 1172 1058 1098 1090 1150 1078 1110 1010 1062 969 972 974 1013 1015 994 966 972 953 912 894 934 905 890 875 887 826 811 845 837 820 782 753 758 836 795 815 783 798 740 770 793 843 753 768 755 766 741 767 734 707 732 713 771 732 748 759 761 783 731 756 767 770 760 702 699 729 727 725 732 757 733 780 707 710 699 768 711 770 757 701 786 797 761 780 796 734 748 746 798 809 761 800 835 805 789 826 829 832 799 848 832 841 920 913 892 811 861 877 831 862 831 874 813 796 861 861 860 850 871 861 836 874 796 881 811 884 816 851 845 835 882 771 839 845 825 820 794 828 808 813 812 856 805 804 800 739 801 704 770 792 747 729 751 670 706 732 817 693 749 704 727 664 682 703 679 692 741 682 705 670 665 680 683 735 705 718 695 659 673 704 691 680 689 674 688 686 686 757 739 709 765 698 712 671 666 675 676 688 652 709 719 695 701 666 743 697 707 730 718 713 698 729 648 709 706 752 741 664 774 713 696 721 708 687 745 740 625 703 739 729 745 767 744 738 732 688 728 755 741 709 732 738 736 737 769 739 730 731 773 726 721 713 807 744 744 768 765 717 746 811 768 756 874 763 787 764 818 830 717 782 782 848 788 792 752 772 730 791 714 720 753 749 764 815 773 767 764 783 720 681 681 726 659 740 740 691 710 630 722 670 651 712 667 632 653 667 666 562 693 656 648 661 684 625 649 653 645 649 657 617 666 638 652 636 652 624 703 622 634 628 627 667 639 675 628 646 617 629 674 628 654 633 620 592 615 644 595 578 618 599 581 595 620 596 604 629 639 671 653 623 574 595 603 633 590 584 661 637 596 629 613 592 654 597 595 617 617 604 654 638 601 592 590 595 668 567 634 584 641 581 614 614 638 613 638 620 568 627 604 587 620 656 604 666 669 635 619 605 625 670 706 646 629 663 622 624 673 650 624 653 697 663 654 599 693 697 703 713 688 673 727 659 725 655 681 636 743 677 723 758 754 698 722 701 673 694 689 679 720 737 701 743 713 713 680 683 705 726 726 706 741 731 689 754 725 759 711 720 717 695 787 678 714 773 734 723 763 755 749 743 752 782 742 733 732 697 753 738 768 780 759 733 780 698 738 751 757 669 722 689 725 695 717 722 737 708 768 736 717 680 685 728 725 732 710 715 720 713 763 755 764 771 711 739 688 753 763 731 728 761 710 762 771 754 798 782 776 797 763 840 856 842 838 878 800 825 867 848 852 903 913 849 919 906 821 861 905 853 922 994 890 944 962 914 914 935 895 914 923 966 917 968 894 973 952 957 949 951 898 916 932 930 911 933 953 949 961 933 943 925 973 1019 964 998 982 939 980 952 987 1017 1021 973 1023 1052 1015 1050 1049 965 970 886 936 1040 981 991 1000 992 1003 970 934 951 950 940 955 925 921 941 937 888 954 941 898 967 885 886 917 858 871 938 929 926 905 905 912 847 915 869 916 911 947 903 919 929 859 931 936 970 944 943 1006 1002 989 992 1020 1032 1058 1050 1086 1015 1108 1070 1080 1144 1151 1070 1100 1195 1132 1135 1211 1199 1187 1215 1186 1246 1217 1130 1277 1296 1281 1308 1361 1325 1325 1362 1371 1330 1366 1354 1327 1356 1371 1379 1384 1331 1417 1367 1377 1392 1344 1343 1319 1350 1289 1336 1374 1373 1335 1265 1280 1243 1257 1230 1305 1248 1238 1240 1166 1225 1191 1145 1172 1121 1103 1079 1102 1141 1138 996 1014 967 1070 1023 1041 972 962 908 940 908 932 925 950 899 946 887 897 889 846 875 864 880 747 875 862 889 861 911 831 883 848 781 823 854 836 813 811 859 846 823 885 794 848 796 886 844 827 883 835 826 844 832 816 865 819 828 840 865 784 828 808 850 867 855 819 786 856 817 788 812 738 805 807 813 797 830 815 782 824 789 765 752 831 804 831 740 742 766 768 735 754 715 712 737 800 729 760 739 701 705 730 772 760 748 741 726 747 742 708 711 685 752 652 730 697 698 649 719 732 635 728 660 673 704 657 667 693 639 681 681 670 658 625 611 730 682 626 654 645 578 593 626 626 619 638 576 617 618 587 683 657 645 652 553 572 593 575 601 615 621 622 597 659 615 635 623 592 593 630 570 647 638 580 575 613 609 588 634 625 625 553 625 589 610 592 566 588 612 629 625 558 621 610 604 631 601 578 605 562 615 627 657 586 604 616 573 717 621 609 593 590 624 626 619 577 640 669 595 607 590 551 665 646 690 621 591 620 544 645 603 577 585 662 637 589 672 619 598 648 599 588 625 613 604 616 609 582 612 614 580 587 639 670 613 623 634 637 598 640 581 590 538 604 598 592 574 611 635 581 586 633 572 601 619 609 601 567 615 614 625 656 587 597 587 595 575 596 576 593 605 604 623 626 571 588 628 605 637 611 607 608 577 589 579 596 633 623 611 617 635 552 631 622 597 654 591 622 610 586 612 656 666 632 648 609 667 655 658 672 617 637 679 710 674 648 663 607 668 652 624 638 691 651 589 665 651 715 660 655 632 676 679 683 635 678 674 659 688 648 632 637 636 720 643 664 646 705 663 639 680 629 667 687 664 636 703 677 701 690 667 726 681 650 681 664 719 678 705 731 735 769 792 704 733 760 741 721 747 710 777 793 823 741 792 734 821 859 803 825 808 824 787 855 847 798 864 834 836 855 826 832 850 800 794 774 833 802 803 849 817 784 795 832 793 844 760 804 745 763 761 773 742 807 804 749 831 761 795 777 818 780 782 689 776 745 684 696 694 750 701 734 696 708 740 724 718 685 698 709 698 752 700 758 747 704 710 651 673 690 682 751 683 699 688 720 695 682 738 706 651 715 721 711 706 694 694 662 687 693 690 665 703 662 681 695 698 644 694 652 656 696 666 647 681 691 662 659 663 665 666 658 626 599 594 636 680 640 663 641 685 574 625 636 611 649 675 600 634 667 622 621 650 657 698 699 657 604 663 664 656 614 669 679 670 674 665 662 719 669 682 702 655 667 673 661 670 722 652 663 641 705 672 696 689 724 703 693 706 673 689 679 704 680 649 694 677 698 686 615 685 674 646 636 714 615 596 640 616 636 672 636 618 654 632 622 601 588 658 639 640 661 642 636 676 656 647 606 642 688 667 669 672 645 667 664 662 650 639 629 717 641 663 688 728 714 619 669 713 665 685 696 732 648 670 694 711 728 712 689 733 642 688 762 760 730 765 708 725 723 692 726 666 739 681 683 711 685 673 690 723 740 712 709 691 655 665 698 692 687 677 701 663 677 679 672 717 701 707 637 632 660 669 665 639 652 699 634 667 630 618 665 611 715 636 636 617 642 652 613 681 633 663 632 668 655 654 635 685 652 609 642 642 642 658 607 661 649 616 650 599 606 644 623 624 594 600 613 658 687 680 665 626 655 647 687 617 636 628 656 689 677 611 629 606 598 660 608 643 661 624 661 663 643 634 633 661 647 677 627 651 653 670 607 623 657 651 619 634 664 637 619 665 618 681 665 587 588 580 580 639 616 625 615 572 624 609 636 575 614 663 601 618 625 644 636 670 652 615 583 616 659 589 623 607 681 586 559 623 573 630 587 637 649 615 633 597 587 619 589 589 615 629 658 582 636 601 576 615 623 665 601 606 594 632 569 658 595 646 623 628 641 630 601 571 588 541 592 689 623 644 575 634 618 623 675 652 613 622 624 603 599 632 638 619 655 663 635 661 640 654 687 627 679 663 635 633 683 702 660 660 663 673 637 684 660 608 653 604 679 601 648 648 675 611 634 672 692 621 694 625 728 673 641 636 628 693 650 695 635 663 627 679 656 625 686 602 621 611 631 640 631 640 635 632 688 696 628 750 667 677 677 627 736 706 690 734 672 736 760 713 705 713 744 736 724 754 742 770 771 739 725 785 766 781 818 829 830 801 791 788 797 797 826 877 843 854 854 920 885 885 855 905 920 871 951 900 935 950 915 939 954 948 958 989 974 954 908 953 944 1021 935 953 907 894 995 965 1026 932 946 965 914 965 943 874 920 940 894 964 872 838 851 807 868 847 921 812 833 867 769 808 793 772 786 826 768 792 753 774 798 736 747 782 732 791 694 756 705 736 776 722 737 744 696 738 710 714 731 727 745 709 714 735 695 745 726 689 774 708 670 675 738 757 706 718 685 726 726 674 698 674 697 717 692 806 748 726 724 770 761 722 718 755 772 794 700 774 833 757 750 742 756 745 821 789 821 794 813 780 713 765 799 793 824 833 842 833 850 760 851 747 870 784 797 782 806 805 811 842 819 875 865 860 842 777 829 839 841 840 827 826 843 844 848 805 779 761 809 788 787 838 912 803 808 787 808 847 758 850 848 789 793 826 808 766 766 756 784 762 737 779 787 777 827 757 746 770 759 774 704 741 757 777 755 759 716 773 772 749 723 763 711 718 743 716 752 708 778 757 749 694 671 683 728 684 697 686 726 695 683 675 703 691 683 688 668 676 731 682 670 648 716 663 695 713 690 710 722 676 703 695 725 743 682 760 709 688 699 692 692 741 750 669 677 734 722 721 779 736 754 687 661 699 705 640 680 695 687 689 677 677 671 762 745 661 728 746 674 655 711 661 673 654 672 666 676 649 679 647 609 641 678 656 629 646 710 648 647 682 636 668 633 639 626 673 635 623 578 692 648 670 604 611 610 577 635 638 626 623 639 657 660 634 651 626 604 634 602 602 650 648 582 626 592 640 631 592 594 568 633 604 655 666 646 578 645 628 584 590 562 603 595 624 594 595 595 534 593 623 619 638 587 638 627 624 607 606 618 566 583 615 619 676 660 605 594 622 608 624 639 623 622 603 622 615 605 609 607 604 626 616 657 582 647 587 620 605 641 585 647 606 585 617 617 630 587 590 685 585 614 587 643 617 634 617 595 589 581 638 599 635 622 607 615 622 566 666 586 585 573 591 586 583 629 626 617 643 632 595 619 588 630 596 585 584 628 569 625 671 610 585 629 603 632 628 628 580 605 648 596 627 664 608 586 639 624 631 612 617 687 659 612 648 684 641 660 628 655 632 624 648 641 682 701 677 696 660 586 676 667 610 625 623 597 745 655 656 640 600 662 647 627 643 616 659 647 677 652 606 626 638 659 642 589 629 588 551 588 644 620 647 627 646 648 629 646 599 651 680 580 610 601 620 614 622 590 639 555 612 603 609 657 633 655 598 603 624 609 623 634 594 625 649 607 657 648 639 656 658 672 649 691 657 727 686 665 685 636 652 681 654 679 696 664 651 697 660 698 666 658 686 667 702 667 720 716 752 709 719 715 702 752 694 735 758 736 765 773 774 769 728 745 787 778 734 799 759 816 755 768 845 800 795 768 816 807 819 863 827 853 868 838 892 810 853 842 885 946 900 870 870 880 842 893 1003 852 943 859 881 937 902 885 885 891 893 958 895 921 934 910 922 962 922 864 931 912 913 944 922 926 956 949 880 861 902 862 856 798 838 879 871 873 826 873 863 898 839 835 841 825 881 842 853 826 879 827 826 796 802 830 816 875 792 853 836 828 830 802 805 836 797 808 820 836 793 823 809 876 811 850 832 818 837 832 817 854 813 874 845 880 824 830 849 857 923 804 871 876 878 836 876 883 864 844 942 905 867 886 960 934 900 880 914 866 938 944 948 896 932 943 923 968 919 932 965 890 900 937 874 903 892 919 916 906 891 886 888 859 848 846 863 845 856 896 915 819 847 912 820 850 842 747 810 836 814 766 768 804 835 788 798 849 785 827 752 749 767 790 721 769 776 714 707 759 746 757 699 723 685 713 772 717 636 709 710 717 701 732 715 672 719 677 679 716 660 653 693 665 643 694 666 685 719 668 632 681 683 658 673 663 646 659 676 629 658 621 675 702 669 706 653 660 681 658 657 663 662 692 656 696 662 618 661 700 671 698 658 632 623 684 683 649 675 649 671 704 641 675 645 628 668 681 629 683 692 687 656 655 652 651 697 659 699 623 617 673 654 676 671 672 660 644 704 630 719 662 609 684 625 662 614 598 680 641 681 635 671 677 668 633 711 683 715 671 613 674 699 711 653 636 694 674 663 663 706 703 652 679 699 684 666 661 683 655 670 659 664 672 654 648 687 646 669 614 681 661 730 683 697 713 655 672 656 652 674 663 646 613 627 691 666 622 647 626 709 608 724 607 713 657 703 713 662 655 673 703 651 650 700 691 703 683 684 674 691 673 716 754 775 689 743 725 717 652 715 722 760 677 681 749 675 643 697 700 734 676 682 739 691 710 690 669 672 690 672 670 675 689 692 728 663 718 676 664 635 649 674 603</counts>
			</dataPoints>
		</scan>
	</xrdMeasurement>
</xrdMeasurements>