File: dataset/precursor_mixture/V2O5_Cr2O3_Y2O3_LiCoO2.12-min.xrdml
<?xml version="1.0"?>
<xrdMeasurements xmlns="http://www.xrdml.com/XRDMeasurement/2.2" xmlns:xsi="http://www.w3.org/2001/XMLSchema-instance" xsi:schemaLocation="http://www.xrdml.com/XRDMeasurement/2.2 http://www.xrdml.com/XRDMeasurement/2.2/XRDMeasurement.xsd" status="Completed" recordIdentifier="{0E6EE77B-E7B1-4D11-A10B-45F0E944E4C5}">
	<comment>
		<entry/>
	</comment>
	<sample type="To be analyzed">
		<id>dara-26-2</id>
		<name></name>
		<preparedBy></preparedBy>
	</sample>
	<xrdMeasurement measurementType="Scan" status="Completed" sampleMode="Reflection">
		<usedWavelength intended="K-Alpha 1">
			<kAlpha1 unit="Angstrom">1.5405980</kAlpha1>
			<kAlpha2 unit="Angstrom">1.5444260</kAlpha2>
			<kBeta unit="Angstrom">1.3922500</kBeta>
			<ratioKAlpha2KAlpha1>0.5000</ratioKAlpha2KAlpha1>
		</usedWavelength>
		<incidentBeamPath>
			<radius unit="mm">145.00</radius>
			<xRayTube id="1010048" name="Empyrean Cu LFF HR (9430 033 7310x) DK430614">
				<tension unit="kV">40.0</tension>
				<current unit="mA">15.0</current>
				<anodeMaterial>Cu</anodeMaterial>
				<focus type="Line">
					<length unit="mm">12.0</length>
					<width unit="mm">0.4</width>
					<takeOffAngle unit="deg">6.0</takeOffAngle>
				</focus>
			</xRayTube>
			<filter id="20010004" name="Beta-filter Nickel">
				<material>Ni</material>
				<thickness unit="mm">0.020</thickness>
			</filter>
			<sollerSlit id="21010002" name="Soller slits 0.04 rad.">
				<opening unit="rad">0.0400</opening>
			</sollerSlit>
			<mask id="22031000" name="Fixed mask 13 mm">
				<width unit="mm">9.00</width>
			</mask>
			<divergenceSlit id="22120001" name="Divergence slit 1°" xsi:type="fixedDivergenceSlitType">
				<distanceToSample unit="mm">50.00</distanceToSample>
				<height unit="mm">1.52</height>
			</divergenceSlit>
		</incidentBeamPath>
		<beamKnife id="29030100" name="Beam knife low"/>
		<sampleMovement xsi:type="spinningSampleMovementType">
			<spinnerRevolutionTime unit="seconds">1.0</spinnerRevolutionTime>
		</sampleMovement>
		<diffractedBeamPath>
			<radius unit="mm">145.00</radius>
			<antiScatterSlit id="22090040" name="AS slit 9 mm" xsi:type="fixedAntiScatterSlitType">
				<height unit="mm">9.00</height>
			</antiScatterSlit>
			<sollerSlit id="21020003" name="Large Soller slits 0.04 rad.">
				<opening unit="rad">0.0400</opening>
			</sollerSlit>
			<filter id="20030001" name="Large beta-filter Nickel">
				<material>Ni</material>
				<thickness unit="mm">0.020</thickness>
			</filter>
			<detector id="7010019" name="PIXcel1D-Medipix3 detector" xsi:type="rtmsDetectorType">
				<phd unit="keV">
					<lowerLevel>4.0</lowerLevel>
					<upperLevel>11.3</upperLevel>
				</phd>
				<mode>Scanning</mode>
				<activeLength unit="deg">5.020</activeLength>
			</detector>
		</diffractedBeamPath>
		<scan appendNumber="0" mode="Continuous" scanAxis="Gonio" status="Completed">
			<header>
				<startTimeStamp>2024-02-18T13:10:38-08:00</startTimeStamp>
				<endTimeStamp>2024-02-18T13:23:06-08:00</endTimeStamp>
				<author>
					<name>AutomatedUser</name>
				</author>
				<source>
					<applicationSoftware version="1.4b (28)">PANalytical Aeris Instrument Suite</applicationSoftware>
					<instrumentControlSoftware version="2.0.0 20210224">AERIS</instrumentControlSoftware>
					<instrumentID>950485</instrumentID>
				</source>
			</header>
			<dataPoints>
				<positions axis="2Theta" unit="deg">
					<startPosition>9.99043322</startPosition>
					<endPosition>100.09495370</endPosition>
				</positions>
				<positions axis="Omega" unit="deg">
					<startPosition>4.99521661</startPosition>
					<endPosition>50.04747685</endPosition>
				</positions>
				<commonCountingTime unit="seconds">18.249</commonCountingTime>
				<counts unit="counts">6134 6331 6037 6183 6185 6234 6358 6306 6230 6049 6254 6394 6094 6267 6123 6234 6142 6140 6096 6280 6169 6314 6192 6092 6096 6224 6075 6021 6196 6084 6266 6117 6073 6094 6002 6096 6258 5955 6163 5998 6129 6221 6095 6122 5950 6149 6048 6062 6007 6156 6053 6133 6080 6185 6166 6041 6071 6123 6199 6086 6141 6110 6113 6140 6121 6149 6079 6097 6139 6053 6097 6090 6079 6097 6049 5966 6174 5999 6114 6034 6121 5981 6055 6009 6088 6063 6109 5921 6148 5908 5922 5873 6093 5880 5987 6021 6039 5906 5938 6061 6122 6033 5931 5962 6089 5981 5788 5875 6048 6059 6082 6008 5947 5935 6041 5944 5928 5968 5995 5851 5912 5879 6095 5650 5908 5901 6170 5941 5860 5893 5814 5975 5952 5896 6072 6009 6017 6047 5881 5943 5962 5770 5926 5902 5905 5919 5970 5930 5749 5802 5798 5819 5903 5821 5998 5940 5846 5824 5915 5944 5990 5947 5901 6001 5801 5913 5932 5723 5913 5914 5897 5796 5863 5726 5808 5913 5843 5865 5893 5890 5906 5850 5764 5951 5805 5761 5887 5927 5896 5762 5836 5852 5848 5913 5831 5942 5819 5786 5738 5769 5780 5909 5893 5843 5673 5887 5781 5822 5812 5827 5821 5869 5842 5880 5695 5908 5712 5729 5748 5859 5737 5733 5780 5778 5872 5670 5795 5679 5871 5944 5824 5958 5797 5858 5767 5819 5977 5975 5796 5751 5768 5768 5785 5821 5746 5797 5853 5691 5809 5859 5795 5843 5829 5729 5892 5818 5802 6015 5790 5755 5738 5798 5796 5871 5902 5995 5795 5826 5756 5856 5789 5826 5738 5828 5664 5871 5672 5746 5745 5756 5925 5791 5893 5686 5835 5776 5822 5832 5858 5731 5728 5802 5851 5787 5984 5751 5647 5807 5705 5658 5827 5812 5966 5741 5783 5741 5766 5812 5772 5713 5798 5751 5758 5739 5624 5867 5627 5717 5850 5658 5689 5760 5872 5929 5786 5789 5866 5617 5703 5810 5974 5716 5855 5718 5866 5867 5804 5675 5867 5845 5725 5848 5769 5818 5724 5787 5870 5743 5880 5711 5788 5891 5828 5840 5770 5829 5902 5747 5845 5779 5810 5873 5862 5701 5854 5772 5762 5809 5798 5783 5740 5766 5635 5505 5785 5796 5928 5881 5783 5809 5778 5802 5638 5848 5778 5833 5915 5857 5714 5880 5667 5746 5778 5861 5826 5889 5848 5765 5824 5769 5777 5767 5774 5708 5789 5769 5908 5955 5887 5950 5902 5868 5852 5916 5778 5770 5905 5731 5874 5788 5734 5819 5959 5657 5860 5832 5933 5921 5790 5965 5897 5930 5764 6003 5839 5895 5839 5917 5897 5907 5876 5726 5971 5822 5910 5875 5755 5965 5916 5789 5916 5854 5932 5706 5968 5809 5868 5753 5969 5994 5900 6050 6058 6031 6053 5818 5866 5968 6019 5882 5938 5909 5764 6028 5823 5934 6013 5938 5952 6084 6004 6068 6201 6105 6197 6102 6152 6275 6265 6381 6468 6417 6426 6584 6560 6541 6730 6770 6669 6882 6708 6620 6819 6562 6498 6358 6390 6216 6220 6142 6178 6044 6041 5863 6078 5904 5906 5991 5908 5953 5944 5884 6006 5917 5994 5958 6046 5985 5972 5817 6134 6028 5911 5897 5972 5897 5849 5870 5965 5845 5951 6114 5927 5991 6004 5825 5919 5939 6026 5815 5860 6000 6082 5971 6035 6052 5998 5972 6102 5905 5958 5870 5936 5943 5904 6075 6064 5994 5984 5910 6019 6064 5940 6117 5910 5852 5912 5817 6016 6164 5987 5962 6061 5922 5976 5943 6026 5894 5924 5902 5838 5920 5965 5989 5985 6014 5999 6006 5882 5990 6001 5860 6005 5949 6084 5949 6012 5982 6062 5923 5995 6013 6054 6061 6078 5960 5917 6033 6018 6097 6017 6010 6029 5952 6147 6135 6037 6026 6032 6017 6004 5987 5964 6038 5981 5975 6139 6024 6024 5997 6064 5995 6061 5972 6056 6097 6073 5973 6130 6087 6207 6195 6204 6144 6184 6273 6175 6282 6148 6269 6286 6269 6165 6079 5928 5968 6028 6194 5959 5943 5991 5970 6052 6062 5997 5973 5981 5999 5967 6095 5963 6039 5902 6040 6122 6015 5947 6004 6111 5943 5857 5920 6005 6003 6060 6057 5953 5996 6080 5921 6080 6110 6051 5938 6097 5854 6050 5927 5906 5963 5966 5975 6037 5899 5900 6103 5959 6145 5967 5989 5971 6048 6013 5959 5938 5997 5932 6022 5910 6063 6102 5979 5927 6097 6151 5930 6040 5954 5976 6136 6035 6087 5945 6046 5838 5976 5934 6226 5995 6020 5934 6019 5934 5955 6142 6061 6196 6303 6240 6059 6125 6196 6325 6213 6289 6379 6400 6274 6509 6543 6583 6721 6746 6651 6793 6721 6644 6916 6927 6919 6957 7071 7026 7114 7159 7344 7313 7318 7466 7386 7396 7505 7494 7755 7663 7887 8219 8143 8393 8577 8926 9086 9503 9912 10152 10654 11584 12285 12996 14329 15484 17014 18562 20864 23531 26421 30009 34033 38424 43640 49740 56385 63432 71928 80752 90113 99481 105854 104324 96712 83834 73428 62414 51116 39351 28829 21124 16118 12785 10680 9418 8623 8189 8126 7618 7614 7376 7592 7428 7246 7233 7418 7252 7232 7141 7138 7028 7171 7043 6929 6966 6818 6734 6600 6694 6725 6596 6627 6396 6434 6471 6335 6288 6306 6303 6235 6242 6423 6363 6249 6229 6294 6296 6356 6445 6334 6209 6233 6313 6168 6325 6138 6302 6227 6240 6460 6400 6346 6302 6312 6215 6466 6421 6435 6638 6558 6354 6630 6552 6652 6630 6692 6562 6671 6662 6771 6594 6673 6556 6742 6915 6767 6744 6879 6864 6892 6957 6803 7145 6960 7095 7253 7281 7290 7327 7591 7658 7879 7937 8097 8389 8640 8746 8910 9370 9633 9686 9878 10104 10348 10207 10516 10717 10339 10403 10281 10366 9592 9669 9165 9174 8992 8816 8953 9013 8832 8904 9062 8823 9041 9196 8940 8855 8911 8549 8234 8126 7906 7653 7456 7434 7275 7115 6930 6929 6692 6860 6799 6746 6626 6661 6631 6505 6614 6469 6613 6383 6399 6483 6467 6518 6446 6517 6426 6335 6463 6338 6431 6482 6442 6435 6262 6392 6400 6299 6291 6275 6308 6396 6304 6393 6199 6435 6259 6253 6276 6167 6216 6234 6301 6297 6273 6174 6344 6375 6332 6236 6361 6269 6271 6237 6344 6331 6341 6287 6247 6159 6220 6250 6303 6192 6295 6215 6254 6162 6339 6207 6373 6160 6303 6227 6360 6318 6375 6293 6390 6325 6364 6359 6542 6656 6472 6762 6550 6779 6794 6855 6901 6918 7100 7004 7081 7086 7155 7308 7089 6916 6910 6891 6710 6784 6629 6590 6410 6406 6400 6246 6228 6287 6230 6199 6238 6085 6187 6134 6376 6285 6073 6207 6145 6111 6099 6128 6242 6238 6102 6116 6172 5967 6230 6166 6221 6156 6017 6053 5998 6203 6116 6002 6100 6145 6058 5969 6035 6064 6112 6178 6005 6193 6135 5956 6006 6085 6119 6116 5982 6164 6038 5977 5827 5990 5907 6068 6047 6128 5882 6062 6084 5977 5957 6089 6018 6085 6006 5954 5992 5956 5860 6107 5774 5904 5942 5980 5968 6125 5896 6048 5991 6003 5946 6035 5954 5990 6123 6006 5936 5808 5948 6019 5970 5965 5959 6036 5988 6059 6073 6017 5994 5880 5937 5963 5983 5978 5850 5961 5825 5899 6025 5942 5842 6035 5898 5912 5898 5906 5865 5948 5934 6053 5961 5928 5930 5963 5936 5951 5837 5866 5838 6027 5820 5977 5860 5786 5841 5835 5967 5994 5842 5992 6053 5880 5989 6038 5980 5947 5896 5885 5983 5983 6025 6003 6030 6019 5837 5918 5919 5962 5848 5829 5901 5864 5894 5838 5797 5892 5920 5837 5764 5872 5898 5948 6008 5787 5836 5838 5846 5856 5839 5910 5901 5804 5941 5999 5884 5911 5863 6027 5812 5861 5921 5948 6063 5958 5776 5987 5804 5774 5817 6080 5945 5859 5799 5860 5841 5822 5836 5900 5927 5921 5858 5900 5897 5887 5928 5956 6061 5966 6065 6031 6087 6177 6327 6390 6264 6508 6459 6619 6933 7047 7126 7199 7617 7987 8030 8373 8518 8731 8885 9168 9145 8839 8734 8450 8092 8006 7766 7409 7069 6930 6560 6488 6396 5993 6186 6009 6067 5995 5946 5929 5648 5769 5768 5783 5909 5734 5840 5758 5745 5722 5837 5828 5734 5680 5879 5731 5648 5793 5789 5782 5923 5687 5697 5851 5899 5690 5749 5745 5654 5775 5562 5721 5761 5583 5598 5664 5729 5852 5775 5608 5675 5663 5588 5738 5719 5680 5707 5834 5686 5711 5793 5863 5764 5692 5680 5654 5661 5712 5665 5746 5680 5771 5893 5783 5842 5763 5985 5651 5755 5787 5935 5910 5816 5847 5749 5882 5961 5871 5771 5990 5798 5910 5870 5603 5799 5843 5694 5779 5753 5757 5844 5681 5753 5818 5748 5806 5671 5705 5848 5860 5718 5661 5823 5822 5854 5782 5881 5781 5917 5916 5954 6058 6018 6194 6086 6090 6252 6025 6211 6076 6187 6167 6416 6475 6527 6790 6731 7020 7001 7255 7443 7489 7421 7454 7407 7080 7003 6959 6773 6656 6376 6276 6211 5925 6130 5742 5872 5830 5788 5723 5792 5720 5692 5623 5720 5492 5943 5737 5563 5674 5688 5618 5733 5620 5713 5701 5662 5649 5738 5695 5733 5619 5588 5649 5673 5456 5540 5478 5580 5539 5378 5635 5602 5577 5628 5515 5564 5647 5506 5682 5781 5622 5606 5694 5609 5551 5590 5584 5475 5509 5634 5700 5496 5521 5462 5575 5588 5696 5630 5646 5590 5689 5574 5528 5554 5656 5576 5630 5555 5553 5567 5645 5562 5747 5690 5609 5540 5623 5652 5684 5464 5656 5659 5528 5543 5529 5712 5551 5475 5531 5560 5659 5518 5564 5576 5466 5602 5530 5697 5653 5688 5648 5605 5552 5788 5518 5627 5438 5672 5525 5497 5606 5541 5715 5542 5569 5463 5582 5472 5527 5454 5538 5565 5549 5655 5759 5591 5618 5581 5629 5626 5528 5603 5644 5559 5576 5407 5533 5514 5652 5644 5682 5662 5621 5568 5454 5617 5562 5562 5640 5605 5657 5575 5641 5646 5542 5599 5691 5730 5632 5721 5537 5485 5630 5729 5792 5576 5581 5711 5650 5833 5754 5629 5802 5613 5585 5808 5746 5599 5785 5652 5815 5654 5752 5680 5718 5737 5655 5734 5729 5727 5694 5722 5765 5641 5757 5753 5597 5833 5743 5822 5826 5845 5676 6042 5779 6024 5886 5841 5935 5855 6092 6088 6017 6019 6024 6079 5983 5977 6098 6110 6223 6278 6200 6312 6282 6418 6458 6369 6535 6689 6795 6843 7049 7131 7355 7526 7800 7989 8398 8769 9076 9789 10372 11099 11727 12821 14060 14951 16434 17964 19316 20937 22581 24131 25266 26678 26979 26822 26345 25642 23732 22364 21088 19649 18051 16415 15043 13352 12323 11094 9850 9328 8814 8305 7757 7582 7523 7111 6925 6949 6722 6698 6665 6602 6479 6249 6380 6241 6238 6067 6066 6174 6067 5929 5965 5993 5944 5815 5746 5899 5764 5793 5821 5753 5732 5824 5763 5717 5784 5618 5706 5833 5743 5787 5745 5544 5766 5811 5716 5709 5638 5642 5515 5686 5644 5555 5650 5565 5605 5682 5662 5569 5708 5562 5574 5490 5734 5615 5588 5650 5546 5577 5535 5591 5662 5589 5539 5542 5625 5496 5485 5556 5477 5638 5505 5681 5569 5458 5500 5590 5451 5587 5617 5675 5557 5496 5693 5521 5606 5509 5499 5543 5583 5439 5537 5508 5553 5563 5546 5620 5540 5586 5562 5618 5586 5623 5513 5435 5729 5454 5552 5504 5457 5641 5630 5622 5631 5587 5671 5557 5576 5688 5722 5716 5607 5630 5634 5625 5682 5860 5643 5749 5787 5814 5861 6053 6041 6214 6314 6311 6478 6501 6520 6696 6792 6943 6921 7148 7064 6977 7191 7111 7054 6790 6837 6621 6365 6310 6363 6126 6120 5829 5941 5832 5706 5605 5544 5598 5507 5598 5552 5686 5525 5537 5550 5471 5573 5555 5597 5625 5501 5481 5562 5634 5453 5544 5463 5553 5390 5575 5505 5486 5556 5706 5476 5601 5559 5592 5451 5574 5646 5517 5361 5481 5477 5420 5421 5302 5425 5512 5417 5507 5509 5419 5605 5502 5480 5487 5560 5486 5427 5590 5466 5494 5446 5476 5705 5512 5506 5328 5373 5446 5532 5393 5460 5329 5497 5369 5352 5337 5546 5531 5446 5446 5378 5569 5379 5473 5516 5419 5513 5472 5442 5424 5538 5467 5483 5440 5540 5581 5499 5513 5494 5756 5795 5842 5954 5785 5766 6043 5940 6148 6124 6097 6057 6017 6162 6048 5941 5837 6015 5884 5729 5778 5724 5706 5468 5626 5481 5492 5600 5426 5575 5484 5487 5523 5370 5521 5449 5442 5290 5446 5296 5390 5383 5498 5413 5548 5439 5427 5516 5290 5381 5494 5457 5498 5394 5371 5491 5491 5353 5491 5419 5448 5527 5455 5513 5515 5486 5552 5468 5359 5385 5528 5399 5471 5457 5499 5583 5378 5516 5438 5618 5493 5414 5479 5541 5553 5569 5554 5527 5589 5788 5744 5696 5790 5703 5806 5824 5912 5777 5796 5888 5837 5983 6025 6124 6001 6174 6127 6217 6209 6428 6532 6508 6825 7136 7508 7698 7987 8437 8944 9065 9751 10219 10414 10887 10604 10688 10345 10232 10103 10131 10162 10126 10247 10059 10144 10236 10247 10491 10496 10454 10547 10486 10122 9744 9402 8999 8839 8517 8252 7905 7602 7284 7166 6688 6648 6456 6307 6061 5896 5961 5822 5876 5866 5908 5595 5687 5603 5707 5612 5605 5510 5502 5615 5559 5683 5697 5531 5482 5607 5650 5750 5685 5817 5865 5803 5967 5934 6099 6290 6140 5894 6041 6015 6017 5781 5725 5845 5854 5644 5555 5561 5459 5628 5380 5379 5508 5431 5410 5456 5533 5524 5336 5384 5401 5443 5403 5373 5351 5326 5425 5307 5232 5244 5335 5368 5230 5318 5351 5253 5441 5419 5313 5405 5271 5291 5380 5382 5212 5381 5280 5325 5268 5338 5195 5269 5215 5329 5317 5243 5316 5320 5344 5515 5338 5267 5305 5328 5415 5222 5314 5233 5278 5356 5293 5353 5335 5333 5373 5230 5208 5309 5382 5339 5325 5375 5252 5330 5405 5334 5383 5411 5292 5458 5320 5362 5230 5304 5310 5160 5333 5404 5319 5250 5256 5382 5379 5386 5180 5259 5308 5377 5355 5364 5398 5406 5356 5329 5310 5426 5520 5400 5273 5560 5455 5458 5452 5451 5529 5389 5412 5499 5478 5527 5690 5698 5794 5797 5967 6007 6074 6275 6227 6269 6363 6417 6301 6355 6431 6280 6228 6262 6286 6335 6290 6213 6290 6237 6268 6168 6436 6349 6382 6819 6762 7030 7479 7695 7984 8125 8565 8952 9192 9289 9337 9232 8745 8531 8062 8082 7802 7724 7460 7328 6845 6657 6499 6160 6006 5793 5843 5742 5552 5572 5519 5560 5508 5348 5426 5438 5335 5290 5321 5420 5432 5388 5247 5238 5365 5237 5247 5277 5458 5456 5288 5344 5387 5303 5254 5362 5199 5251 5121 5400 5220 5167 5311 5109 5307 5270 5271 5414 5295 5348 5221 5237 5415 5243 5241 5419 5389 5235 5420 5197 5322 5372 5200 5383 5238 5310 5378 5310 5275 5204 5302 5231 5280 5368 5386 5320 5280 5344 5399 5359 5483 5382 5428 5278 5366 5442 5356 5431 5387 5536 5569 5721 5976 5911 6259 6258 6512 6583 6811 6820 6880 6836 6680 6486 5994 6118 6203 6032 6039 6198 5916 5885 5680 5651 5475 5450 5379 5359 5396 5283 5367 5229 5279 5174 5263 5289 5182 5335 5399 5373 5170 5275 5285 5199 5496 5383 5387 5523 5176 5266 5394 5280 5369 5484 5331 5492 5417 5489 5485 5454 5528 5416 5424 5399 5481 5492 5426 5380 5280 5306 5349 5348 5443 5237 5344 5370 5327 5308 5306 5232 5332 5236 5283 5310 5420 5344 5497 5403 5489 5474 5749 5733 5848 5983 6318 6554 6981 7522 8165 8640 9519 10223 11007 11524 11106 10268 9011 8244 7696 7743 7780 8023 8248 8115 7585 6752 6390 5753 5597 5459 5328 5376 5200 5281 5383 5258 5314 5427 5399 5273 5310 5261 5197 5294 5218 5219 5293 5307 5312 5288 5101 5195 5269 5374 5230 5268 5275 5245 5285 5264 5295 5227 5244 5149 5452 5334 5299 5501 5392 5724 5596 5616 5823 5798 5999 5816 5572 5467 5497 5532 5587 5495 5487 5583 5624 5532 5237 5299 5238 5215 5132 5213 5280 5359 5195 5219 5206 5313 5234 5198 5197 5224 5239 5172 5248 5225 5249 5216 5362 5239 5258 5189 5202 5238 5216 5297 5286 5124 5323 5228 5199 5302 5268 5420 5366 5357 5421 5479 5427 5467 5648 5575 5655 5772 5813 5706 5914 6017 6134 6303 6184 6477 6476 6546 6532 6495 6346 6251 6278 6133 6191 5925 6027 5909 5969 5839 5735 5585 5670 5636 5489 5277 5468 5340 5376 5388 5320 5251 5225 5341 5242 5339 5239 5301 5207 5263 5228 5187 5188 5239 5170 5199 5306 5137 5345 5232 5398 5196 5181 5171 5203 5150 5272 5151 5220 5199 5169 5275 5060 5212 5228 5104 5248 5193 5188 5206 5133 5098 5299 5177 5145 5070 5262 5207 5264 5184 5138 5224 5245 5291 5246 5217 5207 5051 5216 5186 5222 5113 5257 5273 5277 5134 5118 5278 5161 5153 5162 5240 5104 5107 5253 5017 5176 5286 5157 5274 5215 5335 5197 5276 5217 5183 5288 5337 5217 5189 5340 5128 5373 5147 5296 5109 5465 5303 5367 5443 5480 5442 5199 5511 5588 5699 5627 5657 5662 5555 5886 5647 5517 5762 5592 5839 5817 5640 5811 5931 5895 5878 6010 6048 6171 6357 6329 6640 6645 6500 6604 6548 6443 6356 6305 6231 6253 6083 6122 6053 6008 5857 5706 5679 5639 5556 5583 5517 5381 5482 5499 5493 5249 5389 5389 5432 5415 5341 5357 5379 5426 5362 5207 5211 5213 5221 5285 5257 5311 5257 5272 5332 5283 5341 5447 5258 5289 5289 5381 5287 5447 5601 5352 5435 5420 5342 5258 5279 5330 5233 5187 5425 5288 5219 5228 5202 5231 5206 5243 5134 5218 5130 5281 5211 5098 5139 5146 5181 5207 4956 5121 5103 5261 5131 5216 5211 5098 5077 5194 5178 5093 5203 5150 5037 5208 5342 5153 5149 5127 5255 5094 5074 4952 5182 5203 5295 5106 5178 5233 5117 5104 5097 5196 5072 5039 5319 5039 5255 5152 5057 5037 5110 5152 5060 5057 5044 5087 5123 5108 5183 5061 5202 5188 5212 4945 5127 5148 5046 5108 5104 5085 5185 5158 5118 5167 5228 5156 5101 5092 5095 5135 5255 5141 5297 5070 5181 5231 5263 5014 5161 5249 5107 5324 5206 5376 5282 5331 5272 5381 5359 5403 5568 5590 5559 5693 5819 5993 6122 6275 6446 6620 6714 6508 6735 6760 6504 6362 6396 6342 6245 6249 6128 6109 5832 6091 6017 5702 5654 5590 5593 5401 5257 5364 5361 5305 5282 5196 5197 5142 5254 5104 5109 5030 5222 5062 5259 5198 5171 5367 5024 5125 5111 5167 5236 5156 5159 5218 5157 5197 5114 5126 5305 5097 5119 5146 5174 5216 5138 5141 5300 5149 5214 5153 5305 5242 5266 5183 5248 5342 5341 5321 5319 5255 5347 5358 5088 5128 5341 5211 5209 5321 5213 5063 5248 5198 5186 5139 5293 5082 5149 5114 5200 5127 5097 5101 5100 5232 5200 4991 5112 5075 5124 5239 5073 5064 5085 5163 5073 5197 5055 5181 5082 5125 5021 5294 5175 5080 5051 5127 5182 5202 5198 5027 5033 5196 5134 5071 5185 5236 5251 5142 5213 5147 5263 5062 5268 5245 5317 5161 5170 5259 5235 5300 5240 5331 5393 5327 5368 5505 5471 5330 5542 5681 5646 5867 5899 6357 6517 6957 7252 7769 7973 8674 8732 8875 8920 8410 7971 7341 7120 6959 7197 7101 7255 7308 7301 7164 6884 6555 6210 5860 5895 5809 5625 5654 5544 5552 5624 5456 5414 5541 5445 5482 5373 5454 5339 5423 5250 5358 5218 5276 5383 5237 5260 5215 5148 5214 5214 5110 5125 4970 5053 5143 5208 5170 5187 5026 5095 4934 5105 5108 5089 5031 5168 5020 5184 4918 5073 5095 5141 5106 5038 5195 5093 5285 5139 5066 5145 5035 5054 4973 5077 5059 5093 5006 5084 5005 5188 4939 4934 5181 4919 5170 5135 5025 4999 5149 5084 5170 5065 5174 5120 5028 5127 5026 5028 4937 5062 5059 5061 4894 5155 5212 5189 5042 5080 5014 5010 5200 5054 5184 5097 5141 5226 5117 4992 5029 4951 5102 5135 5120 5055 4998 5053 5177 5156 5055 5110 5177 5094 5122 5219 5141 5197 5340 5196 5204 5177 5353 5362 5310 5397 5578 5509 5606 5501 5617 5692 5624 5474 5606 5515 5434 5435 5416 5319 5263 5411 5325 5419 5466 5337 5237 5164 5236 5418 5258 5204 5141 5213 5214 5212 5200 5162 5166 5074 5130 5125 5269 5457 5225 5386 5318 5391 5464 5533 5543 5550 5685 5719 5715 5615 5554 5362 5343 5445 5408 5402 5403 5600 5321 5345 5234 5321 5338 5306 5241 5237 5176 5224 5128 5162 5080 5132 5136 5273 5277 5209 5245 5189 5137 5235 5139 5312 5268 5342 5301 5235 5331 5507 5282 5471 5546 5458 5571 5432 5613 5472 5426 5453 5361 5303 5351 5337 5506 5436 5484 5338 5270 5293 5448 5340 5517 5400 5301 5314 5460 5291 5341 5289 5417 5254 5315 5422 5360 5447 5433 5386 5390 5478 5366 5556 5455 5604 5625 5560 5700 5860 5794 5813 6026 6162 6285 6554 6647 6939 7164 7519 8020 8253 8962 9537 10150 11082 11872 12413 12723 12715 12528 12308 11622 10988 10704 10400 10082 9977 9776 9783 9715 9577 9314 8809 8404 7839 7398 7052 6832 6575 6438 6270 6124 6170 5964 5943 5955 5987 5840 5742 5745 5625 5701 5517 5496 5554 5481 5416 5373 5490 5382 5518 5289 5347 5408 5162 5442 5275 5248 5204 5180 5262 5107 5210 5184 5231 5066 5211 5118 5292 5145 5169 5159 5168 5231 5253 5148 5272 5282 5165 5259 5323 5243 5163 5146 5306 5305 5411 5427 5516 5559 5549 5723 6012 5705 5705 5668 5668 5481 5476 5343 5492 5511 5465 5405 5494 5585 5453 5432 5489 5351 5203 5171 5209 5195 5245 5106 5169 5041 5235 5148 5085 5086 4984 5105 5024 5244 5052 5113 5017 5190 5095 5194 5035 5182 5124 5283 5190 5204 5106 5245 5222 5327 5202 5184 5195 5229 5265 5390 5300 5555 5573 5672 5613 5802 5831 5981 6112 6126 6251 6348 6528 6691 6964 6975 6761 6779 6722 6421 6490 6296 6177 6206 6058 6068 6071 5951 5901 5849 5999 5755 5769 5527 5577 5290 5259 5174 5172 5313 5132 5132 5188 5283 5129 5177 4910 5069 5127 5179 5065 5105 5097 5170 5107 4951 5069 5063 4969 5030 4928 4985 5168 5213 4989 5022 5049 4994 4940 5123 5003 5051 5224 5088 5113 5014 5020 5095 5198 5171 4986 5146 4913 4988 5097 5083 5026 5039 5025 5095 5087 5072 5148 5231 5057 5141 5063 5079 5173 5212 5260 5302 5282 5307 5351 5550 5627 5554 5651 5485 5540 5446 5387 5425 5336 5278 5427 5374 5319 5487 5365 5502 5338 5201 5279 5207 5158 5119 5061 5220 5096 5095 5143 5162 5160 5108 5088 5156 5187 5081 5206 5109 5043 5081 5109 5152 5073 5057 5120 5117 5110 5100 5225 5145 5135 5015 5104 5200 5040 5262 5130 5150 5085 5133 5029 5205 5060 5054 5123 5011 4969 5076 5111 5189 5211 5068 5293 5277 5330 5199 5247 5241 5341 5316 5202 5220 5052 5255 5171 5160 5144 5158 5249 5282 5169 5232 5104 5248 5138 5123 5089 5231 4995 5003 4969 5103 4921 4995 4991 4991 5083 5014 5008 4958 4997 5019 5013 4986 5114 5073 4946 5016 4936 5050 5102 4995 5068 5068 4995 5031 5053 4984 5075 5092 4967 5007 5030 4963 4916 5077 4867 4936 5058 4991 5058 4951 4902 4893 5132 5041 4957 5030 5022 5018 5018 4923 4984 5068 5011 5002 5046 5061 5217 5201 5026 5163 4932 5095 5027 5069 5163 5034 5070 5139 5151 5104 5120 5255 5233 5202 5288 5318 5343 5538 5331 5637 5533 5631 5793 5897 5872 5845 5829 5795 5624 5578 5457 5612 5480 5393 5521 5412 5621 5560 5586 5495 5352 5376 5230 5206 5215 5118 5189 5149 5102 5084 5055 4854 5074 5134 5096 5093 5155 4955 4998 4998 5074 5031 4920 4959 4938 5117 5078 5015 5176 5023 5019 4976 5133 4977 5024 5047 4990 5060 5039 5100 5139 5107 5090 5094 5030 5034 5112 4939 4989 4950 5001 5098 5009 5108 5100 4970 4992 4944 4989 4929 5006 5013 5092 5023 5022 5039 5036 5035 4958 5096 4964 4981 4950 4893 4931 4833 4855 4938 5175 5139 4996 5051 5133 5103 5118 4988 4984 4954 4929 5052 4973 5079 5102 5102 5004 5088 5088 5006 5019 4973 5111 5015 5262 5145 5108 5123 5059 5117 5200 5130 5172 5219 5270 5367 5312 5321 5321 5428 5421 5494 5684 5721 5756 5738 5924 6127 6217 6525 6786 7005 7234 7767 8010 8383 8511 8627 8821 8550 8260 8119 7781 7416 7270 6987 7292 7009 6918 7190 7138 7174 7059 6727 6754 6363 6192 5922 5803 5794 5525 5536 5422 5378 5301 5354 5189 5286 5202 5166 5085 5142 5222 5164 5096 5113 5114 5196 5004 5177 5111 4978 4949 5067 5119 4947 5103 5017 5034 5122 4965 4890 4939 5103 5076 4978 4957 5007 4960 5039 4985 5054 5136 5081 4938 4969 5200 5136 5195 5312 5371 5212 5275 5241 5208 5183 5167 5299 5271 5083 5073 5266 5124 5060 5202 5139 5092 5255 5111 5131 5226 5004 5074 5181 5135 5104 4963 5040 5205 5093 5002 5107 4968 5094 5096 5204 5157 5176 5282 5302 5263 5269 5232 5541 5533 5503 5491 5618 5625 5754 5656 5647 5624 5440 5568 5350 5454 5321 5473 5556 5369 5353 5497 5378 5386 5328 5251 5314 5219 5329 5181 5235 5096 5082 5176 5096 5067 4996 5074 5069 5187 5050 5055 5040 4948 5019 5047 4935 5079 4966 5048 5085 4905 4966 5173 5030 5007 4954 5131 4833 4993 5156 5068 4975 4910 4986 4953 4896 4941 5129 4897 5139 5075 4948 4997 5068 5045 5075 4943 5055 4965 4985 4968 4969 5019 5142 4968 5082 5006 4985 5142 5066 4969 5229 5158 5070 5109 4984 5014 4911 5100 5009 5160 5323 5170 5210 5119 4969 5070 5235 5070 5299 5159 5252 5264 5215 5278 5286 5336 5231 5362 5465 5495 5508 5492 5609 5595 5692 5812 5775 6019 6311 6435 6795 7053 7418 7800 8229 8641 9051 9442 9539 9700 9844 9302 8903 8480 8104 7874 7652 7526 7571 7513 7633 7668 7767 7534 7556 7289 7199 6809 6675 6486 6132 6073 5871 5628 5762 5678 5420 5484 5441 5366 5314 5278 5154 5317 5089 5141 5150 5271 5174 5033 5059 5017 5263 5142 4975 5110 5021 5072 4987 5041 4955 5116 5056 5053 4892 5123 5030 5076 5096 5112 5183 4977 5115 5137 5261 5091 5145 5222 5255 5303 5131 5222 5349 5303 5191 5245 5252 5320 5338 5297 5266 5281 5325 5166 5336 5238 5399 5168 5211 5176 5242 5166 5197 5171 5146 5020 5148 5260 5134 5096 5171 5149 5059 5129 5001 5136 5053 5214 5140 5112 5175 5222 5178 5200 5346 5283 5456 5356 5253 5446 5492 5536 5545 5639 5775 5929 5912 6058 6237 6310 6381 6363 6336 6460 6384 6626 6744 6929 7489 7641 7448 7506 7052 6588 6109 5977 5915 5790 5744 5798 5690 5894 5925 5943 6044 6132 6011 5653 5488 5273 5284 5331 5104 5151 5167 5172 5171 5188 5181 5103 5209 5154 5175 5267 5375 5229 5428 5371 5642 5652 5642 5991 5982 6053 5975 5809 5643 5574 5511 5472 5362 5301 5338 5360 5385 5427 5600 5478 5504 5501 5399 5413 5143 5105 5104 5134 4938 5059 5126 4940 5067 5010 5138 5108 5102 4928 5067 5134 5167 4938 5082 5136 5052 5058 5023 5047 5002 5163 5000 5135 4969 5068 5075 5104 4950 5040 5082 5070 5062 5030 5084 4984 4927 5079 5113 5101 5109 5070 5163 5257 5078 5321 5384 5614 5558 5716 5658 5701 5715 5717 5729 5628 5563 5593 5404 5365 5432 5311 5386 5363 5375 5508 5449 5449 5314 5517 5280 5309 5083 5098 5284 5104 5260 5058 5054 5137 5133 5011 4930 5067 4964 5047 5031 5166 5043 5021 5032 4750 4917 4861 4992 4938 4916 5016 4853 4967 5054 5090 5040 4946 5161 4922 5098 5037 5113 5129 5142 5200 5369 5254 5225 5358 5246 5275 5060 5030 5149 5112 5209 5063 5067 5136 5142 5090 5252 4936 5145 5186 4999 5006 5015 4941 4961 4942 5081 4865 4928 4943 5033 4846 5092 4959 4933 5087 5033 4976 4896 5017 5009 4895 4903 5025 4990 4990 4931 5030 4862 5049 4895 4920 4929 5067 5002 4994 5043 5012 5040 5134 5031 5147 4987 5278 5256 5171 5320 5288 5248 5256 5215 5165 5127 5205 4914 5261 5044 5059 5106 4932 5087 5195 5071 5141 5237 5301 5291 5187 5245 5137 5167 5345 5324 5315 5360 5251 5145 5161 5271 5184 5096 5192 5139 4982 5144 5066 5095 5143 5028 5162 5032 5014 5071 5118 5128 5153 4990 4981 5027 4938 5113 4944 4871 4836 4931 4986 4907 5014 4884 4885 5003 5090 5013 4909 5002 4984 5038 5037 4910 4924 4970 4893 4899 4825 4830 4882 4918 4891 4982 4956 4986 4944 4924 4912 4916 4849 5007 5003 4894 4912 4961 5051 4830 4899 4939 4974 4859 4863 4871 4893 4922 5027 4995 4933 4924 4901 4949 4897 5081 4996 4913 5035 4941 4942 4981 5077 5076 4967 5090 5067 5145 5134 5068 5096 5220 5114 5015 5057 4986 5028 5142 5251 5173 5192 5093 5144 5237 5331 5172 5281 5534 5471 5532 5675 5756 5814 5768 6075 6049 6026 5991 5989 5805 5736 5721 5547 5564 5520 5503 5421 5496 5474 5535 5513 5523 5569 5588 5394 5456 5510 5409 5274 5082 5213 5053 5019 5009 5175 5029 5213 4803 4999 5122 4919 4944 4900 5024 4988 4904 4930 5014 4912 4845 4937 4870 4882 4896 4914 4964 5020 4961 5090 5094 4905 4848 4874 4903 4931 4894 4998 4858 5021 4865 5003 4849 5008 5001 4850 4971 4922 4993 5015 5025 5017 4943 5113 4882 4966 5019 5035 5119 5009 5093 5153 5010 4990 5136 5235 5221 5195 5203 5344 5445 5322 5431 5364 5471 5563 5577 5526 5370 5485 5428 5293 5208 5276 5307 5393 5129 5158 5093 5269 5269 5268 5298 5363 5086 5251 5217 5134 5126 5041 5058 5216 5162 5160 4990 5133 5082 5041 5105 5039 5103 5086 5023 5275 5172 5237 5232 5317 5309 5558 5538 5627 5757 5734 5844 5950 6202 6227 6278 6299 6343 6292 6165 5950 5920 5929 5657 5867 5573 5828 5776 5792 5758 5702 5861 5841 5906 5831 5733 5776 5778 5788 5662 5958 5924 5929 6077 6264 6320 6301 6401 6070 5903 5758 5634 5567 5387 5286 5333 5172 5427 5426 5484 5415 5611 5622 5682 5576 5621 5511 5297 5290 5115 5092 5039 5139 4954 5012 5193 5076 5209 5077 5145 5199 5136 5254 5108 5133 5165 5202 5095 5099 5043 5113 5044 5056 5118 5073 5036 5133 5063 5149 5176 5157 5141 5092 5264 5096 5122 5122 5066 5017 4950 5037 5088 4984 5101 4968 4985 5093 4978 5029 4989 5015 5163 5102 5020 5219 5289 5377 5323 5484 5583 5641 5445 5264 5315 5253 5144 5049 5011 5088 5110 5122 5026 5005 5133 5059 5224 5154 5207 5113 5183 5036 5027 4961 4980 4979 5006 4820 4960 4928 4893 5059 5031 4926 4773 4800 4923 4948 4795 4941 4867 4813 4788 4814 4900 4776 4880 4846 4816 4858 4966 4910 4860 4883 4875 4786 4830 4815 4757 4998 4948 4914 4936 4866 4832 4778 5068 4830 4899 4766 4937 4807 4775 4866 4912 4973 4733 4886 4906 4839 4880 4888 4846 4961 4842 4904 4915 4924 4835 4759 5000 4952 4822 4908 4800 4707 4898 4720 4951 4865 4947 4848 4846 4912 4787 4823 4881 4772 4898 5007 4951 4894 4804 4787 4864 4941 4898 4898 4834 4796 5076 4912 4976 5011 4927 4911 4938 4889 4994 4807 4924 4967 4920 5001 4927 4993 4937 4979 4925 4879 4830 4799 4921 4905 4948 4788 4984 4875 4844 4816 4922 4798 4983 4986 4823 4763 4779 4962 4873 4916 4856 4876 4739 4884 4834 4899 4970 4809 4954 4783 4819 4862 4878 4888 4743 4857 4950 4891 4849 4878 4879 4834 4956 4952 4815 4764 4919 4837 4877 4867 4968 4846 4870 4992 4835 4880 4891 4705 4963 4799 4840 4883 4895 4928 4910 4956 4770 4904 4972 4897 4833 4782 4777 4945 4921 4972 4916 4865 4885 4914 4997 4825 4958 4831 4869 4982 4943 4932 4796 4847 4878 5004 4967 4897 4952 4937 4979 4927 5068 4946 5062 4965 4978 4924 4932 4825 4817 5010 4876 4944 4931 4844 4931 4880 4903 4896 4918 4839 4940 4800 4972 4866 4849 4940 5025 4953 4963 4868 4939 4869 4861 4944 4866 4917 4864 4844 4878 4866 4941 4695 4959 4878 4937 4809 4916 4947 4907 4836 5020 5002 4833 4881 4925 5057 4919 4981 4973 5054 5056 5101 5137 5053 5174 5266 5273 5453 5273 5597 5554 5511 5473 5529 5445 5365 5277 5423 5440 5254 5369 5341 5212 5309 5190 5242 5246 5191 5328 5267 5309 5246 5286 5082 5144 5176 5007 5076 5030 4951 4899 4924 4865 5055 5008 4989 4855 5060 4906 4907 4991 4977 4747 4903 4940 4904 4873 4805 5049 4845 4994 4823 4861 4837 4998 4863 4892 4887 4910 5192 4880 4890 4833 5104 4850 4845 4938 5012 4948 4856 4847 4979 4978 4789 5014 4793 4978 4913 4934 4912 4885 4872 4747 4951 4841 4983 4857 4829 4928 4962 4809 4849 4980 5011 4853 5017 4838 4851 4812 5046 4879 5007 4915 5013 4900 4931 4953 4784 4880 4915 5054 4917 4928 4996 4870 4926 5042 5000 5091 5165 5123 5332 5226 5447 5350 5357 5439 5537 5375 5245 5233 5244 5282 5226 5196 5154 5198 5145 5115 5024 5128 5136 5232 5176 5306 5212 5200 5148 5202 4988 5080 5012 5005 5032 4939 4923 4874 4846 4877 4999 4943 5013 4955 4955 4894 4966 4868 4789 4845 5011 4812 4873 4933 4962 4776 4917 4866 4821 5114 4871 4755 4861 4849 4958 4833 4981 4743 4884 4945 4992 4969 4934 5110 4834 4762 4949 4976 4955 4970 4845 4937 4913 4829 4727 4934 4930 4947 4833 4885 4852 4974 4836 5033 4854 5003 5047 4903 4931 4880 4879 4831 4828 4936 4824 4858 4883 4971 4910 4823 5031 5054 4948 5128 5058 5030 5038 5115 5457 5351 5354 5479 5483 5441 5494 5489 5627 5280 5368 5336 5262 5288 5253 5212 5269 5338 5198 5258 5149 5339 5212 5262 5186 5391 5252 5213 5113 5164 4994 5148 5142 5089 5060 5136 5112 5147 5084 4980 5146 5090 5082 5061 5147 5031 5026 5009 5045 5006 5117 5165 5214 5157 5241 5279 5246 5287 5371 5503 5569 5486 5367 5319 5234 5413 5221 5298 5260 5225 5193 5231 5077 5137 5056 5107 5088 5105 5180 5130 5123 5181 5119 5102 5019 5192 5140 4980 5046 5001 4916 4955 4980 5047 5093 4963 4938 5032 4985 4998 5045 4942 4934 5115 4914 4865 4924 5001 4889 4984 4865 5080 4904 5055 5026 5006 4941 5064 5157 5205 5077 5150 5119 5152 5174 5168 5145 5053 4875 5013 4904 5005 4889 4814 5004 4849 4929 4987 4972 5007 4847 4930 4902 4994 5014 5059 5040 4958 4859 4820 4908 4950 4816 4756 4822 4958 4770 4793 4893 4868 4887 4830 4823 4811 4907 4884 4778 4855 4873 4806 4849 4892 4788 4790 4904 4858 4925 4754 4743 4895 4815 5008 4879 5043 4870 4920 4853 4863 4796 4904 4844 4882 4943 4917 4847 4895 4835 4868 5075 4982 4942 5024 4968 5001 5026 5036 4925 5012 5038 5044 4898 4872 4903 4909 4970 4889 4914 4911 4890 4952 4763 4984 4936 5136 4858 4980 4860 4997 4854 4904 5004 4960 4914 5019 5126 5071 5122 5148 5207 5133 5215 5144 5049 4993 5019 4950 4945 4827 4872 4890 4995 4977 4966 5042 4900 4994 5069 4946 4818 4960 4989 4939 4879 4933 4906 4963 4751 4824 4879 4740 4713 4900 4827 4852 4866 4738 4937 4755 4901 4797 4859 4844 4894 4772 4950 4834 4989 4789 4825 4760 4935 4825 4702 4873 4846 4841 4664 4882 4846 4817 4897 4762 4947 4659 4860 4895 4749 4895 4791 4873 4724 4858 4769 4853 4917 4830 4749 4860 4852 4866 4809 4768 4854 4767 4809 4884 4770 4823 4789 4941 4899 4966 4819 4900 4736 4928 4887 4954 4901 4962 4931 4859 4929 4932 4872 4944 4954 5022 4871 4972 4998 4887 4883 5114 4931 5093 4862 4954 4959 4798 4995 4983 4928 5007 5043 4888 4914 4998 4859 4927 4859 4945 4888 4902 4893 5039 4928 4910 5058 4989 4919 4887 4991 4842 4809 4939 4787 4912 4956 4844 4902 5010 4744 4835 4697 4918 4886 4877 4765 4899 4829 4891 4808 4858 4860 4828 4789 4884 4792 5071 4974 5006 4957 4951 4973 5025 4967 4946 5136 5120 5078 5137 5098 5126 4979 5019 4843 5090 4876 4980 5023 4930 4959 5000 4898 4858 4922 5016 4902 5072 4943 4930 5069 4968 4955 4873 4912 5011 4823 4924 4973 4986 4974 4935 5002 5130 4970 4966 5171 5114 5135 5052 5112 5181 5303 5194 5211 5377 5314 5302 5240 5290 5145 5150 5100 4888 5266 5082 4926 5082 4980 5111 5073 5066 5044 5111 5168 5116 5125 4954 5154 5017 5077 4996 4990 4884 5009 4974 4815 4857 4924 4786 4944 4901 4986 4906 4922 4860 4835 4888 4874 4776 4820 4918 4791 4835 4752 4863 4754 4851 4725 4800 5030 4737 4979 4882 4904 4881 4805 4926 4869 4880 4852 4870 4845 4954 4978 4944 5014 4876 5009 4992 4948 4969 4967 4999 5011 4846 5049 4761 5005 4895 5055 4948 4892 4958 4961 4914 4994 4962 5075 4923 5105 5110 5017 5190 5169 5194 5220 5296 5283 5344 5490 5639 5582 5480 5713 5785 5899 5916 5789 5939 5937 5883 5821 5742 5596 5567 5614 5531 5382 5419 5333 5488 5314 5444 5464 5487 5493 5428 5317 5657 5383 5569 5357 5548 5381 5146 5161 5201 5272 5068 5226 5167 5023 5113 5057 5183 4986 4948 5129 5102 5247 5110 4977 5079 5141 5224 5251 4867 5122 4865 4926 5038 5003 4950 4914 4828 5036 4797 5081 5032 4783 5024 4966 5003 5074 5187 4898 5128 5024 5132 5075 4965 5040 4945 4953 4981 4866 4912 4866 4801 4876 4913 4879 4848 4798 4860 4801 4956 4761 4853 5009 4886 4970 4908 4949 4853 4803 4924 4812 4783 4830 4853 4858 4833 4901 4889 4948 4843 4944 4867 5040 4981 4769 4867 4806 4920 4891 4882 4878 4846 4789 4929 4858 4831 4717 4842 4817 4820 4931 4720 4793 4894 4800 4804 4688 4764 4829 4834 4764 4980 4720 4849 4731 4872 4856 4867 4788 4777 4900 4704 4712 4860 4660 4806 4839 4877 4864 4899 4668 4822 4869 4760 4832 4839 4774 4898 4852 4929 4835 4741 4797 4801 4765 4860 4828 4875 4874 4790 4767 4789 4896 4757 4854 4821 4710 4787 4921 4822 4858 4788 4888 4839 4911 4874 4909 4695 4932 4796 4857 4760 4977 4824 4862 4882 4863 4789 4833 4916 4771 4945 4873 4948 5101 4986 5077 5015 4982 4906 5236 5073 5197 5343 5307 5322 5455 5331 5444 5371 5398 5274 5255 5167 5225 5121 5140 4983 4986 5137 5062 4945 5037 5031 5124 5071 5255 5011 5052 5243 5253 5164 5110 5007 5054 5069 5062 5068 4941 4981 4923 4980 4909 4770 4897 4960 4914 4811 4735 4990 4921 4832 4824 4769 4886 4702 4897 4783 4771 4778 4946 4710 4861 4944 4838 4806 4664 4807 4772 4820 4837 4743 4776 4803 4803 4775 4888 4805 4708 4734 4818 4826 4783 4871 4926 4903 4911 4810 4785 4899 4978 4839 4953 4871 4901 4943 4862 5023 4885 4927 4836 5045 4954 5091 5046 4975 5029 5097 5071 5076 4981 5281 5141 5385 5394 5535 5529 5712 5948 6339 6685 7184 7436 7528 6906 6510 6151 5666 5505 5339 5267 5214 5121 5131 5075 5083 5163 5055 5286 5424 5404 5462 5653 5795 5989 5828 6047 5880 5653 5408 5184 5331 5103 4975 4991 4853 5042 4867 4909 4848 5032 4797 4969 4881 4941 4834 4893 4910 4745 4803 4874 4723 4820 4836 4862 4857 4950 4816 4835 4850 4772 4790 4767 4967 4906 4883 4704 4791 4913 4749 4732 4800 4924 4829 4941 4808 4788 4839 4881 4768 4842 4803 4723 4834 4693 4900 4790 4887 4829 4781 4717 4853 4794 4820 4883 4767 4802 4843 4667 4888 4765 4772 4793 4784 4855 4901 4924 4831 4947 4836 5078 4924 4995 4811 4784 4750 4770 4909 4889 4846 4801 5077 4884 4894 4894 4864 4864 4831 4706 4801 4811 5017 4862 4945 4944 4946 4851 4959 4769 4865 4885 4966 4746 4906 4785 4928 4964 5005 4777 4924 5114 4976 5224 4972 5079 5115 5131 5213 4941 4976 4891 4892 4882 5007 4806 5026 4974 4811 5032 4892 4957 5032 4996 4963 5128 4992 5281 5169 5233 5194 5086 5264 5112 5110 5108 5175 4988 4916 4998 4853 5032 5071 4990 4773 4920 4835 4968 4940 5010 4910 4980 4908 4761 5038 5052 4955 5008 4777 4924 5063 4998 5022 4942 4952 4940 4888 4978 5018 5056 5067 5035 5004 5151 5126 5245 5120 4911 5104 5004 5080 4978 4944 4976 4784 4936 4847 4794 4892 4907 4858 4907 4843 4981 5024 4926 5020 5030 4993 4892 4947 4925 5139 4986 4882 4854 4890 4763 4836 4859 4901 4768 4818 4799 4896 4824 4805 4756 4920 4795 4659 4691 4867 4752 4751 4778 4800 4756 4841 4674 4797 4779 4834 4589 4702 4821 4748 4761 4694 4882 4684 4832 4784 4728 4761 4889 4868 4748 4923 4892 4848 4858 4810 4965 4943 4769 4949 4718 4877 4869 4686 4877 4841 4850 4863 4851 4942 4961 4927 5082 5050 4954 4988 5206 5205 5241 5273 5219 5097 5224 5289 5058 5065 5037 4998 5013 4871 4929 5047 4810 4967 4895 4943 4943 4905 4982 4941 4996 4969 4871 4992 4988 5027 5055 4924 5000 4879 4903 4911 4930 5050 4735 4899 4892 4791 4996 4877 4809 4793 4822 4780 4811 4776 4831 4974 4797 4882 4831 4775 4888 4907 4817 4845 4861 4996 4945 5105 4914 4914 4975 5116 4871 5004 5068 4881 5088 5097 4998 4896 4994 5038 4969 4930 5064 4828 4954 4918 4931 4782 4971 4866 4920 4948 4927 4904 4985 4895 4895 4947 4977 5077 4955 5018 4893 4958 4940 4775 4874 4835 4841 4850 4885 5005 4889 4931 4923 5002 4944 4934 4937 5027 5090 5137 5037 5262 5084 5161 5158 5169 5126 5116 5017 5144 4948 5018 4975 5016 4945 4937 4890 4962 4947 4886 4946 4907 5129 4970 4980 4937 4935 4961 4797 4844 5016 4916 4849 4914 4881 4968 4881 4876 4877 4823 4857 4954 4888 4759 4728 4803 4728 4607 4969 4791 4886 4851 4897 4835 4736 4908 4595 4845 4690 4742 4860 4795 4860 4753 4750 4707 4656 4680 4744 4741 4695 4645 4733 4760 4804 4707 4814 4760 4705 4732 4851 4804 4791 4757 4731 4812 4810 4719 4788 4713 4739 4863 4619 4760 4873 4694 4729 4839 4862 4669 4821 4748 4825 4848 4678 4871 4645 4728 4740 4798 4866 4813 4857 4808 4730 4812 4787 4716 4673 4769 4762 4758 4770 4816 4633 4881 4846 4791 4702 4852 4733 4821 4760 4827 4754 4826 4847 4838 4802 4945 4889 4811 4722 4789 4930 4823 4771 4709 4724 4759 4718 4739 4766 4794 4743 4724 4751 4985 4878 4866 4773 4772 4791 4830 4746 4697 4804 4770 4771 4694 4830 4812 4755 4688 4756 4766 4675 4812 4862 4968 4782 4814 4721 4771 4782 4855 4689 4899 4813 4794 4694 4881 4850 4715 4649 4713 4725 4825 4703 4766 4748 4788 4825 4748 4808 4821 4729 4681 4764 4803 4845 4816 4848 4880 4897 4792 4777 4826 4849 5090 4877 5130 5000 5030 4970 5060 5073 5160 4987 5118 5120 4924 4984 5012 4937 4984 4990 4951 4810 4949 4978 5065 4948 4853 4927 4949 4911 4847 4817 4876 5031 4898 5093 4932 5039 5031 4905 4915 5081 4976 4980 5045 4995 4906 4960 4800 4938 4709 4978 4908 5027 4987 4924 4911 4895 4956 5025 4941 5051 5031 5054 5056 5112 5151 5266 5225 5323 5324 5262 5232 5225 5219 5228 5151 5174 5019 4985 5054 4915 5063 4980 4843 4909 4919 5015 4998 5054 5022 5174 4913 5051 5010 5170 5027 5180 5124 5127 5121 5009 5043 4863 4957 5100 5111 5061 5075 5234 5081 5089 5128 5248 5342 5367 5297 5398 5304 5374 5497 5577 5313 5532 5307 5439 5370 5326 5204 5217 5235 5174 5031 5110 5146 5161 5023 4948 4997 4951 5028 5154 4971 5074 5109 5079 5135 5048 5167 5167 5125 5176 5057 5020 5036 5015 5106 5017 4889 4865 4943 4922 4740 4966 4819 4723 4847 4872 4862 4696 4907 4820 4779 4692 4835 4745 4871 4802 4852 4812 4908 4703 4912 4904 4686 4793 4848 4732 4712 4709 4843 4817 4733 4839 4727 4883 4805 4669 4748 4790 4855 4818 4821 4846 4834 4867 4827 4639 4735 4767 4924 4806 4765 4681 4845 4746 4882 4804 4845 4939 4790 4834 4775 4915 4778 4926 4934 5076 4964 5065 5097 5032 5073 5004 5061 4939 5017 5058 4811 4970 4962 5015 4861 4962 4826 4894 4957 4776 4980 4744 4830 4759 4836 4841 4870 4831 4900 5014 4913 4867 4909 4909 4876 4873 4809 4869 4768 4858 4975 4781 4798 4790 4675 4801 4870 4792 4714 4867 4834 4788 4715 4790 4665 4729 4659 4694 4799 4753 4828 4728 4677 4842 4901 4751 4776 4800 4693 4959 4818 4693 4728 4728 4785 4861 4775 4793 4740 4844 4778 4891 4747 4677 4856 4710 4855 4784 4772 4778 4859 4767 4913 4992 4831 4862 4814 4778 4829 4855 4702 4827 4788 4909 4779 4843 4741 4910 4857 4926 4992 4824 4867 4851 5117 4936 4950 4928 5015 5112 5058 4982 4913 4836 4851 4952 4917 4851 4882 4900 4772 4885 4868 4976 4864 4930 4902 4900 4849 4826 4911 4881 4955 4955 5014 4938 4903 4943 4987 4859 4892 4838 4742 4955 4792 4699 4930 4859 4784 4892 4840 4712 4928 4781 4895 4847 4833 4783 4740 4702 4702 4818 4717 4779 4806 4744 4916 4735 4903 4753 4859 4659 4750 4773 4741 4861 4779 4633 4805 4742 4728 4662 4800 4660 4722 4793 4754 4715 4706 4747 4790 4775 4776 4882 4887 4744 4727 4759 4579 4821 4866 4860 4764 4765 4915 4677 4843 4819 4784 4853 4585 4761 4812 4718 4755 4950 4711 4851 4807 4938 4909 4882 4838 4819 4744 4841 4821 4854 4862 4792 4941 4842 4712 4764 4784 4763 4716 4811 4844 4835 4815 4821 4850 4809 4776 4866 4856 4905 4894 4871 4963 4826 4761 4810 4898 4940 4860 4761 4826 4832 4760 4852 4956 4868 4857 4717 4878 4894 4856 4835 4890 4804 4855 4921 4907 4935 4853 4770 4784 4953 5045 4851 4907 5009 4828 4896 4822 4950 4888 4883 4942 5007 5030 5085 5130 5060 5022 5048 5251 5192 5275 5426 5402 5344 5257 5337 5183 5067 5216 5146 5093 5220 5100 5124 5095 5012 4950 5172 5137 5201 5090 5198 5238 5101 5343 5324 5228 5296 5251 5455 5317 5467 5296 5398 5253 5323 5369 5315 5077 5139 5059 5085 5109 4928 5051 5094 4975 4870 5049 4979 4969 5014 5054 5038 4911 5000 4982 5036 4858 5061 5102 4912 4898 4783 4985 4847 4995 4681 4865 4825 4790 4859 4832 4821 4819 4697 4898 4724 4840 4650 4789 4767 4836 4815 4850 4882 4719 4933 4804 4780 4708 4644 4635 4671 4851 4717 4738 4715 4630 4818 4794 4832 4790 4756 4639 4778 4713 4791 4710 4849 4832 4693 4905 4750 4750 4715 4750 4694 4788 4795 4829 4766 4773 4717 4661 4768 4863 4873 4771 4828 4866 4796 4759 4705 4825 4825 4848 4795 4857 5025 4947 4931 4815 4949 4843 4918 4868 4807 4789 4801 4745 4812 4785 4839 4761 4853 4786 4703 4880 4716 4777 4645 4797 4824 4895 4807 4781 4704 4838 4863 4674 4839 4918 4689 4963 4786 4835 4869 4771 4757 4818 4833 4849 4788 4725 4805 4810 4723 4800 4742 4723 4629 4805 4644 4862 4767 4847 4555 4854 4732 4846 4835 4819 4800 4853 4749 4749 4749 4893 4721 4867 4856 4818 4949 4862 4876 4785 4889 4748 4788 4831 4927 4773 4881 4891 4874 4784 4872 4820 4916 4743 4830 4953 4881 4943 4799 4902 4806 4946 4923 4950 5068 4962 5010 5041 4979 5207 4991 5211 5188 5232 5375 5286 5286 5302 5379 5314 5100 5083 5306 5120 5053 5019 5147 4979 4901 4948 4996 5052 4981 4893 5072 4898 4919 4858 4862 4837 4965 4954 5068 5013 4957 5038 5079 5083 5022 5044 5006 4931 4852 4893 4896 4901 4825 4873 5004 4856 4964 4814 4753 4927 4773 4680 4839 4936 4673 4768 4762 4750 4771 4749 4618 4723 4915 4729 4739 4772 4645 4761 4875 4798 4702 4875 4716 4834 4760 4759 4612 4789 4653 4762 4750 4692 4913 4822 4906 4702 4838 4825 4689 4787 4757 4791 4803 4778 4838 4827 4763 4785 4782 4984 4873 4754 4804 4783 4812 4971 4900 4790 4889 4971 5050 5045 5003 5010 5070 5092 5137 5113 4976 5089 5028 4899 4981 4868 4894 4937 4871 4930 5036 5056 4861 4886 4843 4833 4916 4785 4990 5016 4881 4853 4804 4829 4933 5020 4967 5030 5090 4900 4981 4992 5017 4990 4939 4929 4864 4894 4895 4881 4927 4937 4832 4852 4894 4640 4739 4762 4848 4736 4810 4650 4731 4761 4796 4858 4740 4831 4862 4574 4732 4811 4742 4637 4666 4791 4780 4871 4703 4859 4718 4766 4994 4954</counts>
			</dataPoints>
		</scan>
	</xrdMeasurement>
</xrdMeasurements>