File: dataset/precursor_mixture/V2O5_0p3015-TiO2_0p6998--8min.xrdml
<?xml version="1.0"?>
<xrdMeasurements xmlns="http://www.xrdml.com/XRDMeasurement/2.3" xmlns:xsi="http://www.w3.org/2001/XMLSchema-instance" xsi:schemaLocation="http://www.xrdml.com/XRDMeasurement/2.3 http://www.xrdml.com/XRDMeasurement/2.3/XRDMeasurement.xsd" status="Completed" recordIdentifier="{912C50A6-F175-43C7-A494-E06D9F346D84}">
	<comment>
		<entry/>
	</comment>
	<sample type="To be analyzed">
		<id>V2O5_0p3015-TiO2_0p6998--8min</id>
		<name></name>
		<preparedBy></preparedBy>
	</sample>
	<xrdMeasurement measurementType="Scan" status="Completed" sampleMode="Reflection">
		<usedWavelength intended="K-Alpha 1">
			<kAlpha1 unit="Angstrom">1.5405980</kAlpha1>
			<kAlpha2 unit="Angstrom">1.5444260</kAlpha2>
			<kBeta unit="Angstrom">1.3922500</kBeta>
			<ratioKAlpha2KAlpha1>0.5000</ratioKAlpha2KAlpha1>
		</usedWavelength>
		<incidentBeamPath>
			<radius unit="mm">145.00</radius>
			<xRayTube id="1010048" name="Empyrean Cu LFF HR (9430 033 7310x)">
				<tension unit="kV">40.0</tension>
				<current unit="mA">15.0</current>
				<anodeMaterial>Cu</anodeMaterial>
				<focus type="Line">
					<length unit="mm">12.0</length>
					<width unit="mm">0.4</width>
					<takeOffAngle unit="deg">6.0</takeOffAngle>
				</focus>
			</xRayTube>
			<sollerSlit id="21010002" name="Soller slits 0.04 rad.">
				<opening unit="rad">0.0400</opening>
			</sollerSlit>
			<mask id="22031000" name="Fixed mask 13 mm">
				<width unit="mm">9.00</width>
			</mask>
			<divergenceSlit id="22120001" name="Divergence slit 1°" xsi:type="fixedDivergenceSlitType">
				<distanceToSample unit="mm">50.00</distanceToSample>
				<height unit="mm">1.52</height>
			</divergenceSlit>
		</incidentBeamPath>
		<sampleMovement xsi:type="spinningSampleMovementType">
			<spinnerRevolutionTime unit="seconds">1.0</spinnerRevolutionTime>
		</sampleMovement>
		<diffractedBeamPath>
			<radius unit="mm">145.00</radius>
			<antiScatterSlit id="22090040" name="AS slit 9 mm (PIXcel)" xsi:type="fixedAntiScatterSlitType">
				<height unit="mm">9.00</height>
			</antiScatterSlit>
			<sollerSlit id="21020003" name="Large Soller slits 0.04 rad.">
				<opening unit="rad">0.0400</opening>
			</sollerSlit>
			<filter id="20030001" name="Large beta-filter Nickel">
				<material>Ni</material>
				<thickness unit="mm">0.020</thickness>
			</filter>
			<detector id="7010019" name="PIXcel1D-Medipix3 detector" xsi:type="rtmsDetectorType">
				<phd unit="keV">
					<lowerLevel>4.02</lowerLevel>
					<upperLevel>11.27</upperLevel>
				</phd>
				<mode>Scanning</mode>
				<activeLength unit="deg">5.542</activeLength>
			</detector>
		</diffractedBeamPath>
		<scan appendNumber="0" mode="Continuous" scanAxis="Gonio" status="Completed">
			<header>
				<startTimeStamp>2024-11-14T15:49:02-08:00</startTimeStamp>
				<endTimeStamp>2024-11-14T15:57:09-08:00</endTimeStamp>
				<author>
					<name>AutomatedUser</name>
				</author>
				<source>
					<applicationSoftware version="1.7b (136)">PANalytical Aeris Instrument Suite</applicationSoftware>
					<instrumentControlSoftware version="3.2.00000000 20240306">AERIS</instrumentControlSoftware>
					<instrumentID>950485</instrumentID>
				</source>
			</header>
			<dataPoints>
				<positions axis="2Theta" unit="deg">
					<startPosition>10.00943322</startPosition>
					<endPosition>99.99442286</endPosition>
				</positions>
				<positions axis="Omega" unit="deg">
					<startPosition>5.00471661</startPosition>
					<endPosition>49.99721143</endPosition>
				</positions>
				<commonCountingTime unit="seconds">12.495</commonCountingTime>
				<counts unit="counts">2556 2510 2419 2413 2389 2451 2558 2503 2517 2422 2504 2384 2436 2403 2457 2400 2403 2388 2416 2397 2444 2358 2430 2334 2304 2333 2328 2368 2366 2412 2378 2428 2266 2297 2427 2392 2230 2396 2399 2369 2291 2352 2319 2322 2354 2377 2244 2356 2241 2390 2319 2379 2290 2309 2303 2340 2248 2272 2255 2240 2252 2213 2241 2229 2353 2199 2219 2221 2256 2221 2243 2293 2161 2228 2273 2265 2318 2227 2182 2158 2190 2194 2248 2194 2144 2187 2201 2132 2126 2202 2226 2227 2266 2138 2211 2187 2210 2169 2136 2093 2156 2194 2105 2168 2105 2137 2144 2087 2174 2135 2050 2070 2163 2076 2165 2182 2097 1994 2052 2065 2140 2101 2116 2038 2108 2068 2072 2028 2141 2004 2051 2028 2076 2150 2057 2009 2090 2033 2068 2076 2049 2018 2020 2013 2016 1979 2022 2065 2024 1915 2033 1965 1938 1955 2081 1919 1898 2013 1880 2066 2019 2049 2004 2006 1944 2038 1897 1910 1982 2034 1988 1953 1868 1971 1873 1982 1924 1985 1977 1920 1889 1897 1915 1944 1935 1920 1903 1950 1888 1933 1952 1872 1910 1845 1882 1861 1785 1845 1919 1856 1850 1934 1787 1864 1868 1789 1898 1910 1860 1833 1910 1900 1815 1737 1805 1799 1785 1849 1833 1797 1898 1850 1817 1851 1846 1854 1859 1805 1813 1802 1724 1858 1758 1812 1744 1815 1798 1716 1740 1753 1769 1751 1805 1766 1713 1662 1807 1779 1757 1875 1813 1762 1763 1709 1752 1765 1742 1758 1688 1726 1681 1700 1675 1767 1795 1704 1700 1664 1739 1713 1732 1756 1704 1735 1715 1688 1683 1658 1685 1783 1685 1673 1697 1689 1745 1699 1665 1743 1601 1737 1699 1725 1668 1632 1700 1675 1679 1725 1733 1640 1680 1654 1667 1646 1673 1643 1639 1610 1592 1656 1687 1589 1681 1682 1607 1691 1615 1616 1573 1627 1711 1605 1642 1621 1534 1683 1519 1594 1663 1641 1543 1655 1553 1633 1565 1634 1623 1581 1624 1509 1596 1564 1643 1613 1534 1580 1622 1586 1608 1637 1639 1590 1593 1531 1542 1639 1605 1585 1547 1566 1540 1536 1580 1602 1569 1518 1577 1596 1577 1652 1548 1586 1538 1594 1538 1636 1507 1636 1577 1534 1553 1553 1534 1515 1525 1537 1569 1508 1553 1467 1520 1463 1515 1514 1527 1497 1513 1519 1498 1462 1535 1512 1572 1544 1448 1461 1461 1466 1528 1549 1521 1533 1460 1497 1606 1502 1487 1469 1483 1481 1501 1524 1530 1501 1433 1551 1440 1444 1461 1493 1526 1535 1480 1499 1460 1531 1443 1467 1501 1600 1495 1522 1482 1516 1531 1436 1523 1480 1507 1517 1514 1438 1503 1530 1503 1514 1541 1505 1492 1538 1586 1507 1559 1542 1531 1541 1518 1467 1499 1598 1555 1591 1574 1573 1516 1591 1640 1667 1673 1771 1737 1783 1818 1852 1862 1895 1977 2020 2053 2063 2129 2063 2182 2183 2209 2141 2175 2192 2207 2165 2085 1933 2055 1954 1806 1774 1583 1566 1556 1511 1518 1451 1508 1468 1450 1478 1408 1409 1383 1478 1394 1364 1451 1369 1432 1386 1408 1390 1345 1402 1488 1444 1399 1453 1442 1382 1339 1401 1389 1380 1365 1433 1364 1412 1410 1428 1344 1309 1352 1413 1384 1450 1402 1425 1386 1374 1368 1402 1467 1347 1320 1336 1391 1355 1327 1418 1338 1330 1371 1313 1295 1377 1312 1299 1334 1319 1327 1348 1432 1303 1321 1342 1370 1379 1313 1300 1353 1264 1338 1343 1348 1397 1363 1260 1354 1339 1304 1374 1424 1332 1423 1362 1409 1261 1325 1350 1330 1332 1292 1378 1268 1350 1332 1296 1264 1350 1288 1320 1333 1363 1364 1406 1287 1338 1304 1210 1276 1335 1353 1218 1349 1289 1321 1314 1281 1307 1317 1264 1324 1331 1270 1316 1259 1284 1277 1334 1266 1330 1336 1306 1276 1238 1261 1341 1291 1305 1360 1343 1259 1246 1335 1356 1262 1249 1345 1295 1339 1296 1347 1231 1341 1233 1330 1271 1285 1314 1300 1349 1284 1297 1294 1308 1257 1269 1303 1241 1315 1312 1309 1300 1258 1313 1307 1209 1261 1256 1326 1307 1251 1206 1290 1316 1321 1256 1274 1254 1224 1248 1222 1225 1226 1269 1311 1229 1279 1280 1284 1282 1205 1203 1222 1283 1185 1204 1252 1300 1242 1254 1239 1265 1210 1193 1226 1225 1239 1193 1255 1223 1178 1168 1298 1214 1260 1239 1229 1192 1275 1235 1246 1215 1245 1235 1169 1229 1184 1218 1221 1259 1198 1235 1260 1230 1228 1192 1264 1278 1246 1187 1166 1211 1226 1243 1223 1173 1216 1252 1225 1171 1253 1171 1224 1148 1214 1252 1222 1161 1213 1115 1231 1172 1215 1195 1194 1185 1166 1236 1132 1157 1169 1179 1178 1144 1194 1230 1145 1166 1172 1294 1161 1166 1147 1124 1123 1147 1202 1173 1094 1103 1156 1189 1196 1150 1147 1156 1166 1156 1155 1102 1208 1127 1138 1110 1127 1104 1147 1195 1086 1130 1096 1113 1115 1166 1168 1121 1137 1193 1146 1130 1151 1151 1135 1173 1165 1111 1148 1107 1176 1111 1118 1127 1169 1171 1137 1156 1183 1212 1203 1148 1157 1172 1202 1131 1227 1181 1121 1204 1157 1224 1189 1173 1149 1146 1134 1077 1196 1174 1249 1093 1188 1191 1209 1216 1256 1220 1256 1247 1224 1198 1207 1256 1290 1275 1333 1253 1311 1284 1241 1283 1271 1421 1362 1361 1427 1432 1511 1497 1473 1556 1600 1600 1722 1789 1807 1885 2003 2078 2157 2275 2495 2635 2737 3068 3100 3511 3615 3856 4083 4488 4752 5098 5388 5604 5986 6389 6670 7020 7226 7359 7804 7715 7718 7523 7229 6916 6660 6087 5486 4783 4305 3752 3471 2942 2516 2332 2176 1927 1862 1746 1541 1593 1434 1476 1400 1417 1362 1370 1345 1291 1316 1286 1254 1217 1248 1212 1230 1198 1212 1169 1156 1182 1134 1141 1154 1180 1136 1108 1133 1087 1142 1076 1087 1115 1098 1105 1084 1060 1131 1100 1072 1134 1079 1163 1130 1071 1089 1082 1139 1125 1135 1116 1065 1097 1138 1086 1058 1126 1053 1084 1080 1065 1065 1074 1132 1172 1145 1017 1153 1049 1094 1106 1167 1125 1182 1149 1111 1133 1149 1155 1195 1189 1128 1130 1240 1227 1211 1250 1277 1261 1342 1358 1416 1433 1476 1548 1545 1760 1722 1763 1777 1821 2008 1952 1999 2178 2223 2408 2328 2449 2532 2597 2511 2594 2615 2561 2480 2366 2214 2191 1975 1865 1792 1641 1538 1505 1435 1295 1311 1283 1201 1125 1157 1119 1113 1030 1082 1030 1120 1147 1042 1137 1026 1065 1010 1017 1073 1072 1030 1040 1042 1060 1063 956 1028 969 1035 938 984 976 986 1024 942 972 986 1044 1037 948 1039 1062 1060 1007 966 996 975 1008 1001 979 1014 997 1006 945 975 944 1009 943 1016 964 983 978 930 978 993 968 1018 1045 991 1033 990 987 969 998 948 1028 967 967 975 962 987 1013 970 951 982 1011 994 1011 959 940 968 1019 952 988 945 915 931 962 946 984 1034 954 947 911 942 977 958 902 975 958 943 934 967 899 949 901 927 909 958 923 888 983 898 939 933 939 969 921 933 907 913 903 912 927 901 896 961 927 932 934 922 888 955 918 1003 949 949 958 903 926 891 911 932 956 911 878 912 920 948 951 915 926 869 944 926 912 960 844 887 945 972 910 834 937 935 928 945 905 906 913 869 931 899 884 850 901 947 898 854 948 932 901 893 922 909 875 836 868 882 937 851 895 913 885 887 899 888 907 897 867 891 914 866 904 899 847 919 928 917 897 876 859 916 983 929 930 958 987 979 977 932 929 951 1000 967 993 1010 1013 972 1021 1028 956 1004 1037 1023 1071 1083 1075 1023 1071 1036 1000 1081 1073 1060 1096 1089 1078 1080 1147 1072 1137 1143 1159 1244 1236 1154 1285 1233 1231 1245 1274 1267 1311 1375 1332 1358 1437 1454 1490 1448 1607 1720 1738 1792 1922 1930 2033 2224 2397 2583 2782 3105 3381 3589 4009 4552 4948 5594 6101 6636 7520 8102 8885 10235 10883 11806 13188 14015 15118 16175 17087 17937 18692 18791 18971 18714 17569 16713 15291 14057 12366 10921 9326 8055 6789 5769 4780 4053 3342 3028 2670 2398 2261 1988 1994 1892 1781 1748 1674 1613 1606 1534 1534 1557 1492 1328 1354 1264 1323 1279 1240 1200 1159 1190 1152 1133 1054 1079 1171 1053 1057 1043 1029 1037 1116 1148 1056 1114 1102 1126 1141 1177 1154 1217 1268 1392 1262 1428 1474 1530 1521 1759 1776 1816 2008 2039 2065 2228 2332 2374 2404 2414 2473 2421 2335 2223 2095 1873 1792 1638 1507 1384 1293 1200 1132 1100 1037 1006 986 945 965 898 994 933 909 860 893 921 852 888 879 872 878 870 894 860 824 837 873 853 876 832 908 842 866 843 849 820 800 851 835 871 834 874 837 824 835 817 815 802 819 810 864 829 796 844 815 823 817 836 810 806 832 784 817 868 779 826 791 794 823 791 831 789 752 806 847 835 800 764 794 786 843 828 863 774 817 843 838 851 849 789 829 851 836 797 783 833 820 839 877 862 854 851 900 867 897 905 891 902 884 908 1004 867 892 841 822 825 844 757 846 774 843 744 740 807 821 750 750 727 764 709 742 715 747 795 761 756 774 730 742 714 745 780 759 766 822 765 774 748 740 773 806 737 689 726 740 782 793 779 753 770 737 733 722 744 718 724 736 735 777 726 779 755 768 727 755 737 747 724 765 759 711 801 734 759 719 725 659 788 743 748 703 759 686 704 709 786 741 758 694 705 695 653 753 746 693 749 665 779 693 743 714 748 744 706 723 724 705 737 749 720 701 709 736 662 744 700 680 682 723 671 694 715 710 712 720 721 672 706 720 722 686 715 716 731 721 664 679 692 661 696 686 694 674 678 643 678 697 714 703 671 691 678 689 681 669 677 737 717 697 680 699 691 687 674 691 686 702 692 669 629 678 719 660 680 677 690 629 690 657 661 664 713 699 671 683 698 618 694 695 650 688 675 632 649 635 678 659 639 667 666 671 679 696 651 608 663 648 690 642 657 673 633 634 597 675 692 673 665 694 705 663 604 709 623 635 689 674 667 675 678 713 680 670 642 675 647 669 624 727 687 609 662 683 684 665 656 650 743 688 698 648 678 670 638 720 630 706 656 707 673 656 697 700 682 634 608 621 706 607 657 683 726 667 739 720 643 660 637 693 659 673 624 700 700 722 674 660 710 654 694 751 716 727 672 737 769 727 759 753 739 796 837 896 826 822 951 865 915 1007 1083 1106 1104 1246 1263 1389 1418 1486 1601 1672 1796 1901 2076 2146 2149 2290 2394 2456 2434 2448 2484 2272 2294 2156 2076 1959 1804 1584 1611 1342 1269 1209 1144 1043 918 930 885 810 802 751 734 739 707 733 696 735 662 704 722 706 679 694 624 652 687 611 680 651 651 637 664 628 638 657 623 627 650 571 622 627 626 567 607 587 612 651 639 592 683 623 663 601 596 624 600 611 606 600 626 697 575 593 650 622 615 625 652 603 543 622 629 650 606 634 607 649 622 589 587 641 652 643 634 664 611 613 674 645 684 677 679 665 675 728 720 718 789 760 706 815 853 823 908 935 958 987 1064 1138 1157 1184 1250 1285 1301 1356 1279 1299 1286 1305 1266 1181 1097 1062 1036 957 929 857 869 780 770 775 714 712 674 639 678 637 612 640 630 579 599 600 589 596 565 600 605 560 594 623 644 608 625 597 585 561 552 635 577 587 539 575 571 596 551 608 597 599 562 597 632 587 612 561 570 577 603 634 607 618 580 581 589 652 619 591 624 637 613 684 704 701 675 764 686 751 768 735 811 860 766 779 838 798 758 823 805 738 719 683 643 715 661 633 591 609 650 599 557 594 544 559 583 586 560 596 588 579 549 537 534 538 548 521 539 559 560 589 549 567 534 543 551 600 567 559 563 565 592 547 544 550 557 596 552 553 569 548 588 594 582 566 583 591 597 546 580 536 604 560 583 592 608 609 630 652 669 641 707 719 777 777 806 889 945 946 1025 1067 1126 1138 1176 1257 1141 1177 1118 1110 1088 1037 936 938 866 833 791 800 699 677 693 680 599 596 573 571 536 580 542 617 563 556 549 568 557 548 574 581 542 537 535 526 565 543 538 592 529 559 504 607 533 549 537 483 540 524 547 526 537 484 512 498 490 523 495 507 514 528 503 555 538 554 519 550 539 517 525 508 490 535 516 531 517 509 523 560 527 542 514 503 516 500 471 527 501 492 506 489 552 480 514 476 514 511 490 513 497 510 481 474 494 522 487 512 498 509 492 513 531 545 489 529 536 532 561 488 489 499 518 501 490 525 470 520 495 540 506 523 469 515 527 551 510 523 507 532 545 522 536 531 520 527 583 551 541 536 565 543 582 583 595 605 603 626 615 597 592 644 691 632 623 563 551 594 586 597 560 534 540 564 566 515 529 530 481 549 507 483 540 505 524 497 510 510 505 493 504 519 508 515 518 512 496 490 503 572 514 465 490 533 509 525 474 545 479 523 522 499 557 554 525 563 560 568 532 551 558 616 603 557 627 638 693 684 705 833 810 874 931 933 1045 1060 1190 1238 1278 1377 1466 1468 1538 1547 1486 1471 1351 1364 1198 1236 1173 1052 1031 985 951 875 790 775 709 659 651 588 640 636 582 547 617 584 588 595 612 609 618 625 641 650 602 666 652 637 699 666 678 625 717 707 679 617 642 626 727 689 684 732 695 713 810 822 784 831 884 944 1028 1078 1173 1320 1435 1609 1698 1878 2035 2343 2636 2867 3152 3316 3575 3869 4006 4207 4237 4221 4023 3927 3685 3506 3199 3027 2827 2561 2390 2221 2022 1741 1526 1335 1131 1005 982 849 843 811 762 706 698 616 656 675 630 674 638 623 650 570 577 588 554 600 557 629 586 571 566 535 557 523 583 571 572 601 606 628 618 681 660 714 680 759 787 820 856 969 1036 1065 1174 1304 1369 1474 1465 1526 1544 1682 1643 1624 1522 1448 1438 1368 1260 1235 1119 1088 1019 960 896 837 737 731 629 657 587 519 517 533 497 543 508 518 502 511 481 499 506 466 522 492 474 500 449 498 455 465 455 494 502 487 484 461 479 477 471 496 449 492 460 499 498 461 523 505 467 461 426 476 467 458 440 483 476 468 480 476 404 454 432 438 418 427 454 441 433 463 424 469 454 490 449 473 473 425 435 465 440 427 483 444 457 422 412 416 458 416 420 462 456 494 419 435 405 457 432 463 420 447 439 428 449 492 417 451 427 430 450 413 477 428 429 407 461 476 451 431 390 455 413 453 432 447 436 497 402 438 463 465 450 443 449 447 440 442 454 481 472 436 451 446 462 413 493 421 423 433 443 456 433 426 429 480 449 433 443 405 441 425 419 419 441 464 417 401 432 434 480 433 468 404 469 431 473 420 486 424 409 452 472 461 465 409 437 412 439 425 473 439 453 459 479 435 454 504 423 432 441 463 458 444 459 488 457 465 445 468 455 485 480 494 569 530 516 535 488 570 605 595 682 639 675 720 801 777 813 945 1010 1006 1096 1088 1202 1170 1241 1303 1309 1288 1284 1159 1199 1168 1084 1040 1018 1039 936 867 827 802 762 731 706 680 568 638 582 574 534 518 517 488 470 501 457 478 476 485 472 451 456 469 495 507 469 412 474 480 448 445 460 453 445 470 492 491 493 476 517 505 510 507 489 497 535 585 592 606 633 630 706 695 726 673 755 750 766 795 769 780 764 770 757 731 706 709 639 616 654 574 615 548 578 518 526 476 448 538 447 449 444 463 463 450 425 416 435 432 409 462 462 432 449 398 393 414 409 387 406 415 453 439 393 388 426 401 424 423 413 421 419 440 433 424 414 420 445 396 361 395 418 394 426 397 397 391 419 406 419 420 405 408 374 414 386 382 403 389 429 416 413 391 444 391 395 363 369 432 346 420 418 406 381 391 414 410 445 428 396 444 390 420 401 402 425 386 451 391 430 398 404 358 401 393 419 405 399 416 402 396 378 376 393 384 390 406 381 379 406 424 401 394 355 377 375 408 402 418 425 402 402 402 390 385 392 395 403 378 406 397 421 376 389 376 399 420 410 393 421 370 387 374 421 405 399 429 398 400 387 384 411 370 400 398 397 413 405 384 369 388 395 370 406 405 402 386 427 420 382 394 410 379 429 385 423 442 432 443 429 422 402 424 473 396 444 438 430 411 397 399 388 449 447 404 429 405 371 414 412 437 435 395 404 389 408 389 433 375 361 393 410 396 362 390 351 431 364 382 368 402 399 347 393 388 410 407 388 371 390 389 386 401 368 398 411 390 396 353 344 351 420 384 378 358 388 380 421 408 370 418 403 376 421 381 393 409 375 369 373 377 394 427 381 402 371 423 379 381 403 412 426 404 439 458 411 437 428 450 494 492 485 527 526 518 543 574 572 599 629 685 660 689 694 722 694 683 665 662 634 620 598 577 567 576 574 565 548 507 470 489 451 456 434 410 430 431 399 424 393 432 372 388 371 417 359 392 388 429 385 380 380 379 377 399 358 388 365 396 381 376 364 394 363 380 363 403 374 394 352 364 352 380 370 352 307 335 369 396 371 392 379 361 370 355 375 376 398 377 422 360 387 380 410 392 398 384 381 391 415 394 391 358 422 381 418 396 405 371 392 344 416 411 363 367 420 411 411 392 419 374 393 405 369 376 375 415 397 416 399 415 438 416 397 407 363 399 399 393 392 418 396 425 450 435 429 422 426 411 392 419 403 388 477 411 387 434 444 424 476 452 463 450 445 473 433 444 447 482 511 492 508 508 557 544 619 673 687 728 785 821 853 829 913 935 940 867 873 918 890 870 828 756 811 719 677 795 757 724 770 675 668 608 572 623 573 565 557 581 592 545 610 596 586 615 608 666 678 687 767 752 694 772 821 886 1011 1014 1027 1149 1181 1232 1286 1340 1524 1642 1699 1832 1946 2256 2401 2620 3006 3324 3848 4117 4493 5023 5252 5627 5727 5724 5477 5324 5069 4720 4342 3893 3823 3622 3633 3328 3368 3234 3077 2639 2483 2056 1856 1493 1363 1159 972 907 863 801 735 711 653 661 680 577 622 541 595 543 550 543 530 520 529 505 489 451 473 440 474 447 470 454 479 482 471 442 466 469 477 481 474 515 531 497 513 543 531 634 655 713 628 674 782 781 733 792 765 779 730 742 705 744 714 693 682 667 632 614 595 597 568 614 565 524 502 501 538 490 484 476 437 441 454 406 430 445 409 400 457 372 410 415 442 405 442 432 406 413 393 433 391 409 424 423 446 420 404 459 480 447 455 445 428 439 499 488 520 488 430 486 464 465 474 466 441 455 444 437 443 449 414 472 441 438 398 389 386 390 420 375 397 390 348 396 376 389 382 373 391 392 354 424 374 350 365 324 369 341 377 348 351 347 375 374 373 400 365 384 353 368 379 391 365 407 341 361 345 375 349 376 339 357 391 339 405 384 373 375 354 362 344 364 352 340 356 383 349 361 375 383 378 396 355 360 364 359 370 364 373 397 349 348 343 361 351 351 345 386 397 361 361 363 333 339 346 349 400 374 320 378 313 352 362 358 340 374 399 314 393 385 385 304 351 395 388 359 412 372 416 395 348 372 383 367 398 365 398 401 376 401 435 464 461 506 519 490 567 591 642 662 644 751 750 779 816 814 763 801 749 702 694 704 646 618 637 600 598 624 562 570 553 548 548 488 472 483 424 445 444 414 422 455 385 423 414 413 424 411 406 425 388 393 376 397 389 426 425 377 387 366 370 369 385 401 378 401 394 361 386 363 367 411 432 435 413 449 476 498 422 459 492 531 536 557 530 627 589 628 620 589 610 562 549 521 548 510 468 531 520 504 455 477 482 495 474 421 428 430 409 406 400 397 370 343 375 365 374 384 377 356 391 366 386 403 373 374 379 436 383 381 400 394 411 375 388 433 397 443 436 436 370 441 364 436 400 346 368 370 399 418 396 367 375 356 347 376 363 363 390 356 365 355 363 375 388 364 365 333 387 351 373 403 355 370 331 372 386 357 369 368 395 364 365 370 357 376 347 371 326 385 358 354 376 363 355 351 365 383 369 386 377 343 376 391 419 370 398 404 406 376 418 396 429 430 377 410 404 408 422 424 406 419 423 435 410 438 486 442 440 462 477 485 482 502 553 516 559 544 598 608 597 621 708 774 818 839 994 1062 1123 1321 1489 1618 1817 2025 2280 2636 2805 3024 3228 3305 3353 3480 3394 3296 3097 2874 2751 2494 2314 2270 2156 2150 2160 2183 1978 1931 1873 1732 1514 1381 1173 1000 961 816 741 713 623 652 556 520 597 537 544 503 547 496 541 510 483 523 498 495 491 496 483 450 430 458 429 466 429 448 445 425 445 373 448 433 423 473 428 437 440 416 420 429 441 469 472 484 411 488 452 418 448 423 438 479 442 510 467 469 496 599 513 550 514 558 580 605 661 632 695 756 792 924 1064 1161 1309 1486 1535 1843 2075 2286 2609 2824 3126 3296 3412 3440 3406 3122 3013 2781 2541 2445 2217 2075 2041 1948 2098 2026 2107 1975 1816 1741 1615 1461 1244 1079 992 835 757 754 677 615 550 521 553 518 525 491 526 489 460 433 417 482 439 454 455 476 489 490 485 461 477 526 569 563 553 571 522 545 577 534 543 502 481 481 485 508 437 488 466 442 494 471 461 452 418 378 409 381 374 373 381 416 365 354 355 355 350 382 394 384 362 341 363 337 320 370 397 381 371 380 344 374 347 366 430 370 404 383 350 393 394 359 390 394 428 404 437 385 382 417 411 375 400 363 377 348 382 360 394 374 394 344 361 331 364 377 381 347 320 323 339 319 336 359 363 356 380 319 357 366 332 329 353 348 325 354 294 378 315 335 365 333 316 364 319 329 327 355 340 320 340 324 342 309 339 333 323 335 328 337 348 305 355 330 341 326 329 304 317 322 335 322 331 335 336 332 311 325 326 312 325 312 308 307 340 291 329 325 327 286 331 313 327 334 327 322 366 353 327 308 301 341 327 285 322 340 350 324 303 310 320 322 339 319 318 338 341 307 337 302 337 348 315 335 329 305 334 331 325 358 320 283 284 285 321 320 315 315 284 332 332 339 312 333 329 327 306 312 322 296 325 324 328 328 334 339 312 339 329 347 355 327 370 323 350 332 303 332 308 343 341 344 325 385 333 321 344 348 322 333 340 312 347 331 318 346 378 335 349 361 367 358 362 371 388 402 428 403 426 422 472 423 434 394 414 390 368 427 380 406 391 401 401 397 406 405 435 397 371 394 376 357 394 367 341 400 327 331 407 398 412 391 426 408 411 413 415 459 473 459 493 505 489 529 568 525 553 543 516 494 499 519 491 487 465 448 479 445 476 438 468 428 447 426 443 383 383 392 363 338 362 362 329 369 365 372 327 351 358 344 352 342 302 333 322 293 339 322 326 317 324 303 336 326 335 329 316 340 316 287 313 311 323 378 305 311 298 335 305 309 290 317 342 328 374 328 309 329 347 356 321 323 343 302 366 326 346 324 354 326 315 342 362 347 370 346 377 396 383 398 399 435 398 415 393 374 353 385 387 382 365 401 341 378 355 376 344 370 375 335 342 317 349 313 326 315 337 356 322 316 319 331 334 333 325 322 356 364 317 346 322 353 346 334 331 301 347 327 336 345 333 342 325 314 348 300 329 373 288 296 347 291 321 316 320 331 313 304 357 312 333 340 334 338 350 371 294 326 348 348 357 354 373 361 374 374 419 388 423 456 449 448 498 503 546 570 575 567 558 548 546 549 460 514 458 483 494 437 460 472 466 500 474 458 441 404 483 440 436 400 411 406 420 362 373 363 329 372 337 316 375 316 330 366 330 356 320 337 345 348 340 316 309 356 333 335 302 343 335 349 330 310 323 357 303 376 338 356 338 367 353 341 357 350 356 418 330 388 395 388 383 368 405 400 403 467 454 493 502 540 536 622 680 724 785 845 944 1016 1012 1134 1185 1112 1162 1081 1085 988 920 862 852 841 822 803 775 854 808 834 812 806 776 839 716 695 680 650 597 591 536 606 512 543 546 520 517 594 572 549 548 627 642 707 794 855 991 980 1144 1206 1452 1520 1743 1902 2149 2363 2407 2624 2542 2624 2469 2301 2154 1914 1757 1651 1552 1518 1381 1542 1415 1538 1533 1597 1613 1466 1410 1316 1241 1109 922 930 765 720 647 585 544 506 479 472 443 458 416 408 438 381 408 416 383 366 423 339 385 358 376 357 329 353 340 329 352 320 345 350 343 332 310 335 344 338 335 325 311 358 339 329 334 319 301 327 326 325 304 326 272 294 347 320 341 306 303 309 320 308 288 312 313 333 320 327 315 320 356 333 314 303 330 311 306 321 308 318 305 334 331 326 302 318 334 331 303 335 341 286 321 316 332 301 345 313 323 336 328 349 319 352 332 294 327 333 340 363 353 330 308 347 317 356 375 323 332 353 366 364 382 402 413 393 410 395 385 375 398 421 375 430 394 432 395 433 400 406 444 442 429 459 420 426 419 430 434 419 445 490 419 428 397 392 435 387 384 378 401 392 343 388 382 365 336 352 361 356 352 340 324 284 344 317 308 318 302 338 332 319 327 328 295 309 305 338 309 284 317 366 314 336 320 354 322 321 329 361 333 330 345 349 316 277 352 342 321 362 298 336 318 333 320 318 294 331 327 285 316 285 336 308 318 307 278 299 312 341 298 299 302 323 294 290 262 317 288 291 300 319 299 306 325 285 302 288 325 292 317 315 324 312 308 289 307 300 309 290 324 301 302 322 306 326 322 303 299 308 313 291 296 365 325 327 308 347 405 356 370 353 372 389 413 440 433 402 421 411 390 389 387 375 386 393 394 370 329 329 351 359 355 341 360 340 355 330 352 366 345 343 334 308 292 316 277 339 340 306 334 298 322 320 310 306 301 288 280 285 312 289 295 269 317 295 305 302 318 320 323 321 287 312 315 311 318 287 303 266 324 298 289 313 327 305 303 289 270 307 287 317 308 309 306 321 317 300 299 295 293 295 326 302 308 315 281 299 289 249 281 284 271 317 304 302 286 280 318 285 296 301 302 271 293 334 276 309 295 341 274 261 301 284 313 304 321 309 285 277 332 313 287 299 288 294 307 311 298 305 298 286 293 284 289 295 318 303 301 300 307 359 351 310 341 343 313 355 357 364 371 372 382 384 378 389 390 371 357 341 357 346 351 363 355 361 361 337 334 347 356 333 359 351 353 334 341 330 334 346 323 334 350 349 318 326 337 300 328 349 316 338 317 329 324 345 353 360 339 345 346 330 355 396 374 415 405 390 329 374 365 384 393 375 436 407 399 407 398 421 398 413 406 407 458 452 455 476 481 511 508 574 635 625 679 748 780 881 921 1023 1085 1167 1225 1206 1306 1335 1330 1303 1240 1101 1096 993 917 1028 952 943 920 889 954 920 890 933 907 947 903 821 797 768 774 677 643 608 615 539 555 481 507 457 443 425 437 393 351 415 354 396 366 387 341 328 342 339 339 335 360 356 339 348 342 324 357 380 345 351 344 336 333 322 378 334 311 339 332 374 351 416 353 389 367 395 427 395 402 430 416 456 434 463 465 447 432 411 446 410 437 441 397 408 404 425 445 417 428 408 402 426 388 448 393 379 387 410 420 425 415 366 413 381 379 422 361 404 421 387 419 441 407 439 475 455 490 495 603 633 635 674 788 851 944 973 1160 1166 1253 1363 1403 1484 1512 1332 1345 1249 1210 1113 1059 913 931 811 889 842 881 845 865 863 953 907 903 915 926 875 745 729 654 609 588 531 534 469 450 418 448 421 398 361 367 355 336 357 339 350 340 352 349 310 329 294 293 337 310 324 340 287 319 299 308 294 309 285 275 297 294 284 322 294 279 324 298 287 269 295 286 301 276 304 305 282 299 273 260 279 304 295 262 298 326 284 296 293 328 318 310 315 309 293 307 294 294 260 290 297 288 276 295 295 258 303 298 295 281 291 275 340 296 299 258 304 287 300 335 321 327 332 302 325 319 359 343 342 368 375 396 389 363 339 409 364 388 380 345 340 373 304 379 330 360 362 350 369 363 329 364 299 322 343 312 364 296 320 304 343 329 361 323 321 344 360 305 337 347 355 343 349 370 359 375 359 392 396 363 459 441 460 472 436 406 396 405 407 374 358 407 365 396 412 369 365 349 366 333 390 388 420 414 434 409 422 426 409 428 407 413 419 388 470 444 460 432 469 454 470 473 407 406 412 395 413 392 386 401 408 358 381 389 379 398 376 365 354 351 364 365 370 352 335 368 336 314 334 314 331 290 315 324 285 319 283 305 290 299 289 283 279 289 303 297 272 280 284 266 298 273 315 282 285 299 316 270 279 282 258 275 332 294 289 328 299 296 279 272 274 312 277 269 261 304 321 300 250 274 281 296 294 299 311 279 325 264 296 282 289 282 304 313 271 293 297 280 289 305 279 277 262 289 287 294 317 291 304 310 333 313 278 339 331 364 337 325 318 346 357 373 348 381 384 350 381 378 358 380 374 370 343 364 359 376 367 367 330 325 359 379 354 387 405 381 439 361 393 377 369 379 373 415 439 401 418 419 398 415 452 437 454 460 492 444 487 478 502 508 496 446 508 447 488 415 449 449 446 461 472 444 441 456 483 430 496 444 483 483 467 478 421 446 464 457 465 520 496 584 524 601 606 660 709 744 841 972 975 1189 1266 1316 1540 1648 1742 1808 1800 1756 1770 1688 1499 1494 1288 1176 1017 1041 920 908 911 932 973 1007 1014 1027 1094 1078 1154 1069 1030 992 976 855 778 757 682 619 553 518 468 447 453 392 405 414 396 364 343 340 340 323 353 349 311 365 346 324 340 313 313 336 325 304 285 319 310 329 338 320 326 323 293 319 345 354 306 346 315 369 364 365 350 400 377 376 399 476 480 506 540 564 603 631 662 735 773 774 785 779 746 727 709 654 631 610 565 545 490 515 456 473 477 497 553 461 497 566 552 585 520 548 502 500 429 451 428 405 374 347 382 343 350 339 317 358 346 375 280 299 309 304 282 263 320 319 306 319 314 326 279 288 259 299 311 281 277 286 264 303 294 282 305 309 295 280 281 258 293 260 312 273 279 279 294 306 272 270 289 286 293 277 281 280 292 300 294 270 258 234 305 262 296 230 281 265 283 270 290 258 285 248 260 299 267 289 333 290 308 282 301 324 336 322 319 321 335 305 352 352 316 305 320 293 287 292 267 305 290 296 308 329 289 291 264 298 277 328 311 323 284 277 309 284 293 289 308 280 307 280 301 267 277 270 303 322 285 273 290 271 268 257 283 288 269 268 279 262 299 304 280 289 306 278 311 270 288 300 315 293 268 299 294 294 303 346 309 308 341 379 314 361 376 375 396 393 354 363 348 351 378 347 345 359 385 375 321 332 340 355 336 326 316 327 342 324 321 322 342 339 319 318 319 340 302 296 304 290 289 298 311 313 293 285 285 289 258 276 298 300 282 268 285 241 293 250 267 243 276 248 262 265 267 266 277 258 262 264 283 257 277 237 261 248 256 279 265 244 282 239 263 248 237 277 284 282 231 305 216 294 275 239 259 244 274 286 235 288 279 269 261 243 270 257 285 237 263 291 274 248 239 266 220 294 280 273 279 287 272 271 247 246 274 301 272 259 250 263 258 249 268 278 294 278 284 280 241 256 289 268 270 256 258 268 261 287 274 268 278 265 277 275 304 241 258 284 240 262 273 277 263 268 244 245 227 265 239 283 273 265 262 260 242 272 270 261 235 265 239 245 260 257 245 239 223 256 245 271 267 267 263 249 264 247 258 270 263 240 289 248 238 294 265 296 275 271 282 278 250 264 268 248 264 270 244 275 251 261 272 240 248 242 271 305 294 286 267 294 285 329 272 299 297 248 281 304 323 326 303 342 374 338 301 301 318 336 295 332 295 312 308 298 310 273 282 299 299 271 290 294 284 288 302 319 341 300 322 283 302 307 293 305 267 305 269 257 279 281 278 288 259 283 272 321 250 310 285 274 241 281 263 286 267 298 247 291 272 301 290 323 258 313 284 283 297 277 296 260 258 259 272 277 287 296 275 287 277 283 311 274 294 281 286 283 284 279 260 273 243 258 233 277 280 297 278 282 267 228 270 234 263 265 294 274 268 275 225 272 307 299 279 266 268 322 249 298 291 274 271 268 296 326 298 284 331 351 342 340 385 335 385 390 420 371 386 366 327 362 354 318 333 343 346 347 317 316 321 317 312 345 359 355 375 313 385 415 379 363 394 398 390 367 444 385 444 419 462 487 532 500 573 626 655 724 738 842 984 985 1048 976 1048 1042 1008 949 929 844 729 748 659 621 639 625 597 543 545 563 586 637 607 654 672 723 684 723 726 718 643 660 563 583 560 569 550 528 486 521 554 543 517 570 575 611 651 659 635 613 606 564 569 566 517 446 426 444 391 411 435 396 400 357 389 409 395 393 408 433 446 437 438 439 406 400 404 410 346 341 326 305 311 293 303 305 298 299 292 296 235 300 291 276 279 299 275 247 289 276 260 284 272 281 260 239 251 271 241 280 263 242 283 264 277 270 280 302 283 243 290 264 328 317 288 270 290 297 268 274 268 283 294 295 278 269 259 275 242 241 311 269 245 282 261 264 268 297 281 249 272 287 284 283 271 247 265 263 286 291 298 285 288 274 279 291 288 259 314 259 268 262 280 277 262 259 258 295 293 271 243 257 247 276 265 271 247 268 239 268 280 267 239 240 257 195 267 267 264 257 267 233 246 295 286 269 263 245 271 243 231 315 272 237 283 278 278 260 247 298 272 265 267 257 277 264 265 265 287 257 304 265 277 278 274 245 298 239 272 265 243 273 266 265 261 265 217 270 284 246 246 245 257 257 287 256 295 260 294 271 277 300 305 273 311 309 297 265 283 283 259 273 237 263 270 265 242 260 236 223 243 219 250 267 251 267 260 281 264 265 280 275 304 256 241 261 269 259 237 233 226 230 263 219 248 235 245 281 297 235 265 257 280 242 276 248 256 263 262 257 237 263 226 266 278 237 248 250 232 261 278 268 259 267 240 251 236 258 269 261 242 275 262 285 273 292 243 293 261 256 258 259 275 263 271 256 293 271 264 265 267 302 258 279 286 260 294 287 276 316 297 314 301 297 294 284 282 317 295 304 329 309 312 327 316 302 307 285 281 278 290 330 322 271 291 302 271 275 268 302 301 283 278 288 279 257 275 282 286 276 304 296 286 273 267 260 266 268 274 264 269 256 237 243 263 237 257 233 237 240 221 242 257 265 265 262 281 283 275 267 275 258 234 267 266 262 244 280 248 306 257 275 257 242 257 270 272 235 258 262 261 259 231 264 241 267 260 267 245 246 237 260 243 256 278 248 281 238 278 260 242 258 256 228 251 260 233 275 237 266 244 234 249 225 285 286 271 269 248 240 248 296 257 249 262 237 226 259 257 269 291 270 259 273 261 229 267 236 257 285 287 261 280 267 259 227 245 300 266 276 275 292 307 259 294 301 296 312 295 297 321 298 291 308 311 296 309 343 283 283 292 302 281 294 282 248 292 284 290 264 286 287 302 259 303 279 298 294 272 290 300 277 269 290 295 299 276 271 283 275 271 278 263 263 275 276 247 288 256 303 234 265 286 234 236 258 260 264 223 243 259 282 234 263 269 244 231 278 278 272 248 273 242 256 240 290 261 259 277 249 273 267 277 250 256 249 259 257 288 265 248 221 279 273 249 267 275 281 259 297 272 271 262 272 279 273 238 267 261 256 265 260 296 295 261 278 293 293 259 291 297 292 294 280 293 306 304 273 279 279 278 303 302 277 320 265 275 277 274 282 287 267 289 268 290 276 290 264 291 270 271 247 273 300 260 289 273 273 260 262 248 274 270 235 263 290 273 246 244 278 285 276 273 285 265 261 275 270 267 262 238 267 275 258 267 272 294 239 275 273 280 245 292 304 318 286 296 300 320 280 295 289 327 325 303 299 271 336 316 298 294 308 294 287 285 310 278 282 285 274 310 280 262 296 294 297 272 308 279 299 322 319 301 246 281 277 277 310 289 295 248 262 268 248 241 249 247 258 221 277 231 250 277 248 251 245 278 292 236 233 273 233 270 230 198 211 260 266 273 236 267 249 261 273 241 273 263 256 261 220 232 217 259 272 242 242 229 237 290 268 261 233 248 229 230 270 217 261 226 261 280 250 266 209 294 248 241 247 238 209 237 275 242 259 256 260 275 259 223 256 242 266 243 246 263 242 288 237 245 238 229 280 263 304 259 258 262 238 249 257 296 240 267 243 262 246 270 248 241 273 225 231 246 221 260 277 259 275 262 238 247 285 229 248 259 275 235 270 269 263 296 247 274 260 276 275 317 274 232 268 274 246 257 262 257 281 299 257 259 275 267 245 247 267 259 282 243 303 295 296 321 294 281 256 298 310 301 293 285 301 264 306 297 285 271 279 300 266 293 310 276 303 304 286 271 293 305 329 306 342 375 354 371 325 340 348 379 345 358 367 342 353 351 359 306 305 326 339 326 363 349 309 335 357 355 291 325 338 329 361 332 326 340 321 329 326 347 328 312 337 315 294 312 343 334 279 304 301 282 277 308 289 282 313 301 302 295 307 297 274 288 295 297 293 293 289 309 239 310 289 275 305 305 308 294 297 333 317 341 343 378 350 358 336 414 423 400 477 519 528 538 604 573 560 658 638 652 612 557 568 527 503 469 450 443 428 425 382 386 377 364 362 382 375 382 410 433 437 429 434 439 444 475 502 486 466 445 416 422 385 405 417 322 382 355 339 332 353 339 324 290 310 292 296 321 289 310 332 299 312 286 269 306 272 282 317 294 295 334 319 277 316 307 327 304 312 349 350 403 383 408 380 443 423 448 523 535 607 618 656 626 708 686 701 714 700 612 610 587 575 530 522 488 455 435 465 389 411 395 393 425 442 441 452 444 445 456 477 468 483 485 474 516 500 485 509 449 447 411 395 378 354 344 355 344 322 309 331 335 293 296 287 291 302 300 330 305 301 264 293 292 267 295 304 265 263 266 270 291 261 289 290 275 267 262 241 244 269 273 280 272 284 239 269 285 267 261 264 248 238 268 244 271 267 257 277 235 257 275 267 263 272 244 266 216 280 235 276 233 213 249 245 235 261 245 280 249 256 276 249 257 235 242 226 244 236 243 302 248 259 244 240 233 277 263 276 245 231 256 259 273 286 264 227 222 238 258 219 262 247 235 259 209 290 267 269 248 220 224 273 234 269 244 267 265 238 224 237 256 265 282 276 227 262 226 221 263 272 240 264 282 247 250 257 238 250 238 293 266 236 239 262 271 247 296 285 267 278 246 279 261 249 272 269 243 235 244 279 263 278 262 276 270 257 283 278 270 268 274 264 248 263 262 271 263 270 270 284 267 276 285 261 289 270 258 281 280 273 260 234 274 277 272 314 281 283 282 304 246 264 305 315 271 283 295 296 308 313 275 275 302 257 259 287 288 278 295 297 275 291 330 324 283 329 320 315 307 305 318 351 329 396 365 365 391 425 398 447 454 413 479 504 478 493 505 532 527 479 505 435 468 427 396 383 352 356 385 339 379 356 347 346 403 342 360 365 360 379 391 386 321 360 426 403 387 393 386 386 364 411 352 342 314 340 332 324 312 302 324 275 303 297 281 302 269 288 286 267 251 266 294 266 258 284 273 257 284 245 269 271 244 270 264 260 277 270 277 260 290 282 287 308 309 267 274 282 265 235 285 263 289 296 296 290 289 320 276 289 310 274 279 283 287 303 284 307 279 285 298 296 295 342 299 325 331 324 307 330 324 351 336 347 338 352 358 351 391 399 375 391 384 369 370 357 457 431 412 397 410 411 433 427 458 421 451 414 437 405 372 350 388 352 368 401 355 327 361</counts>
			</dataPoints>
		</scan>
	</xrdMeasurement>
</xrdMeasurements>