File: dataset/precursor_mixture/V2O5_0p7006-MnCO3_0p3001--2min.xrdml
<?xml version="1.0"?>
<xrdMeasurements xmlns="http://www.xrdml.com/XRDMeasurement/2.3" xmlns:xsi="http://www.w3.org/2001/XMLSchema-instance" xsi:schemaLocation="http://www.xrdml.com/XRDMeasurement/2.3 http://www.xrdml.com/XRDMeasurement/2.3/XRDMeasurement.xsd" status="Completed" recordIdentifier="{62D52D71-D3D5-400F-9985-14667E2C6981}">
	<comment>
		<entry/>
	</comment>
	<sample type="To be analyzed">
		<id>V2O5_0p7006-MnCO3_0p3001--2min</id>
		<name></name>
		<preparedBy></preparedBy>
	</sample>
	<xrdMeasurement measurementType="Scan" status="Completed" sampleMode="Reflection">
		<usedWavelength intended="K-Alpha 1">
			<kAlpha1 unit="Angstrom">1.5405980</kAlpha1>
			<kAlpha2 unit="Angstrom">1.5444260</kAlpha2>
			<kBeta unit="Angstrom">1.3922500</kBeta>
			<ratioKAlpha2KAlpha1>0.5000</ratioKAlpha2KAlpha1>
		</usedWavelength>
		<incidentBeamPath>
			<radius unit="mm">145.00</radius>
			<xRayTube id="1010048" name="Empyrean Cu LFF HR (9430 033 7310x)">
				<tension unit="kV">40.0</tension>
				<current unit="mA">15.0</current>
				<anodeMaterial>Cu</anodeMaterial>
				<focus type="Line">
					<length unit="mm">12.0</length>
					<width unit="mm">0.4</width>
					<takeOffAngle unit="deg">6.0</takeOffAngle>
				</focus>
			</xRayTube>
			<sollerSlit id="21010002" name="Soller slits 0.04 rad.">
				<opening unit="rad">0.0400</opening>
			</sollerSlit>
			<mask id="22031000" name="Fixed mask 13 mm">
				<width unit="mm">9.00</width>
			</mask>
			<divergenceSlit id="22120001" name="Divergence slit 1°" xsi:type="fixedDivergenceSlitType">
				<distanceToSample unit="mm">50.00</distanceToSample>
				<height unit="mm">1.52</height>
			</divergenceSlit>
		</incidentBeamPath>
		<sampleMovement xsi:type="spinningSampleMovementType">
			<spinnerRevolutionTime unit="seconds">1.0</spinnerRevolutionTime>
		</sampleMovement>
		<diffractedBeamPath>
			<radius unit="mm">145.00</radius>
			<antiScatterSlit id="22090040" name="AS slit 9 mm (PIXcel)" xsi:type="fixedAntiScatterSlitType">
				<height unit="mm">9.00</height>
			</antiScatterSlit>
			<sollerSlit id="21020003" name="Large Soller slits 0.04 rad.">
				<opening unit="rad">0.0400</opening>
			</sollerSlit>
			<filter id="20030001" name="Large beta-filter Nickel">
				<material>Ni</material>
				<thickness unit="mm">0.020</thickness>
			</filter>
			<detector id="7010019" name="PIXcel1D-Medipix3 detector" xsi:type="rtmsDetectorType">
				<phd unit="keV">
					<lowerLevel>4.02</lowerLevel>
					<upperLevel>11.27</upperLevel>
				</phd>
				<mode>Scanning</mode>
				<activeLength unit="deg">5.542</activeLength>
			</detector>
		</diffractedBeamPath>
		<scan appendNumber="0" mode="Continuous" scanAxis="Gonio" status="Completed">
			<header>
				<startTimeStamp>2024-11-14T14:17:16-08:00</startTimeStamp>
				<endTimeStamp>2024-11-14T14:19:21-08:00</endTimeStamp>
				<author>
					<name>AutomatedUser</name>
				</author>
				<source>
					<applicationSoftware version="1.7b (136)">PANalytical Aeris Instrument Suite</applicationSoftware>
					<instrumentControlSoftware version="3.2.00000000 20240306">AERIS</instrumentControlSoftware>
					<instrumentID>950485</instrumentID>
				</source>
			</header>
			<dataPoints>
				<positions axis="2Theta" unit="deg">
					<startPosition>10.02173288</startPosition>
					<endPosition>99.99585608</endPosition>
				</positions>
				<positions axis="Omega" unit="deg">
					<startPosition>5.01086644</startPosition>
					<endPosition>49.99792804</endPosition>
				</positions>
				<commonCountingTime unit="seconds">10.965</commonCountingTime>
				<counts unit="counts">2129 2151 2187 2223 2076 2187 2185 2145 2188 2157 2151 2125 2061 2045 2083 2120 2039 2002 2046 2045 2061 2033 1993 1882 1932 1929 1901 1879 1942 1934 2018 1867 1885 1934 1872 1864 1844 1790 1830 1842 1845 1778 1831 1881 1777 1836 1778 1705 1763 1743 1821 1637 1695 1733 1802 1671 1713 1712 1687 1731 1728 1706 1708 1615 1640 1694 1757 1689 1663 1625 1663 1679 1576 1552 1579 1682 1529 1612 1638 1586 1552 1621 1630 1658 1635 1581 1587 1558 1549 1525 1583 1575 1511 1486 1570 1580 1574 1600 1542 1514 1461 1477 1489 1526 1470 1476 1515 1490 1496 1492 1569 1505 1577 1539 1614 1626 1630 1645 1771 1969 2042 2262 2278 2423 2298 2161 2091 1972 1745 1661 1649 1546 1496 1490 1409 1435 1504 1476 1501 1431 1405 1467 1424 1529 1399 1476 1465 1455 1455 1435 1381 1460 1411 1418 1461 1415 1369 1398 1463 1438 1498 1398 1416 1438 1356 1405 1357 1400 1393 1333 1358 1389 1412 1313 1369 1412 1363 1425 1447 1398 1413 1429 1357 1425 1363 1362 1319 1343 1364 1401 1364 1374 1343 1375 1335 1378 1368 1432 1363 1355 1350 1315 1318 1345 1354 1289 1355 1328 1359 1338 1295 1274 1328 1392 1348 1361 1311 1337 1310 1409 1440 1484 1430 1432 1560 1577 1517 1578 1803 2046 2480 3088 3961 5167 6441 7318 7947 7564 6852 5513 4686 3729 2741 2074 1718 1600 1522 1520 1436 1448 1385 1320 1436 1400 1317 1387 1392 1338 1352 1378 1377 1345 1502 1547 1828 2020 2375 2624 2915 3021 2888 2749 2367 2164 1924 1645 1426 1357 1404 1320 1259 1298 1253 1182 1300 1264 1245 1249 1238 1269 1174 1203 1201 1298 1229 1220 1191 1200 1187 1130 1192 1164 1210 1210 1183 1178 1179 1185 1203 1194 1219 1224 1162 1198 1229 1171 1187 1208 1210 1232 1312 1232 1444 1396 1586 1621 1651 1607 1593 1530 1445 1294 1340 1266 1175 1147 1213 1075 1134 1142 1136 1128 1168 1134 1137 1117 1113 1158 1065 1091 1153 1162 1127 1182 1226 1257 1375 1366 1401 1369 1263 1271 1314 1234 1255 1329 1581 1844 2118 2551 2988 3148 3029 2874 2531 2206 1844 1559 1286 1176 1175 1158 1148 1139 1081 1063 1058 1083 1059 1091 1049 1065 1027 1029 1056 1105 1041 1004 1071 1033 1068 1061 1085 1071 1091 1088 1011 1027 1055 1032 1058 995 1046 1009 1062 1104 1032 1034 1043 1014 1026 1042 1019 1042 1025 965 1073 961 1014 996 1062 969 1076 1023 1022 1046 1035 1047 1029 1019 990 975 999 995 981 1009 1001 1025 1049 1018 985 1035 1003 992 1038 1041 1046 1004 1046 1022 1031 1019 1063 1020 1020 1027 1024 1030 1107 1064 1064 1093 1065 1051 1128 1152 1257 1404 1548 1939 2292 2699 3303 3673 3837 3683 3699 3518 3277 3274 3146 2967 2914 2633 2326 1959 1760 1416 1298 1188 1201 1090 1146 1107 1144 1097 1028 1100 1151 1136 1261 1360 1556 1792 2057 2199 2063 2006 1771 1550 1353 1265 1078 1080 1034 993 1023 998 1035 997 1013 999 1032 1096 1143 1301 1405 1354 1298 1289 1164 1186 1109 1007 997 1018 949 986 976 958 971 1024 997 975 1076 1193 1358 1558 1693 1878 1827 1762 1693 1451 1319 1160 1070 1014 965 973 955 887 963 904 907 910 899 971 947 885 876 912 910 947 891 955 957 928 885 873 888 876 888 865 873 936 1027 1070 1004 1030 993 1043 1043 987 982 935 931 895 892 876 888 916 874 852 880 903 870 872 880 902 926 970 927 886 1009 998 1027 1065 1199 1214 1335 1295 1303 1272 1214 1135 1007 1013 946 929 891 923 903 879 879 875 864 884 884 865 881 897 856 835 887 893 883 850 844 868 806 861 829 838 883 884 856 894 871 885 883 878 805 848 830 846 831 805 856 853 899 864 849 826 890 856 877 847 830 862 855 817 921 849 879 887 890 894 896 899 876 887 857 925 902 828 893 929 908 898 915 963 983 1022 1115 1229 1455 1678 1965 2184 2343 2381 2195 2107 1735 1561 1316 1168 1011 1021 1020 987 1005 1045 1052 1195 1278 1370 1373 1333 1257 1201 1069 1059 927 923 939 907 867 831 853 842 836 831 818 837 896 808 803 814 800 899 814 821 797 816 819 852 880 855 868 846 803 841 843 789 840 858 887 792 830 833 821 855 821 826 858 906 857 851 900 886 852 862 859 866 848 877 876 864 852 966 888 974 1090 1146 1150 1317 1256 1307 1261 1138 1141 1162 1231 1293 1355 1338 1390 1364 1217 1125 1005 879 910 914 865 797 834 791 826 850 824 800 834 834 834 775 875 872 777 839 795 836 847 786 866 868 788 833 793 898 901 857 891 1005 1097 1160 1421 1540 1568 1599 1526 1320 1258 1208 1150 1093 1164 1281 1344 1504 1482 1483 1470 1245 1169 1062 966 906 954 922 897 898 887 926 918 891 957 979 1075 1182 1217 1306 1463 1448 1429 1342 1220 1097 1055 991 953 926 948 968 990 994 1025 1078 1107 1152 1173 1103 1067 1017 967 938 894 880 909 837 812 803 855 838 823 846 857 825 873 783 859 813 838 863 839 851 813 886 851 888 866 940 989 995 1247 1434 1533 1588 1699 1761 1657 1620 1629 1703 1657 1680 1708 1611 1581 1504 1351 1254 1335 1269 1295 1250 1293 1262 1136 1100 973 1002 905 897 865 864 881 853 878 848 858 836 855 796 853 825 806 822 796 817 890 810 792 782 786 833 801 849 818 797 734 864 788 852 846 853 879 875 856 895 869 844 835 795 796 820 753 781 769 740 806 814 785 795 740 748 764 809 790 787 830 756 772 791 825 741 786 808 789 755 806 832 829 837 892 874 914 1073 1117 1049 1103 1071 1082 996 934 888 825 814 859 828 875 901 936 907 905 905 864 888 843 802 899 825 776 788 758 751 767 737 751 750 767 795 810 764 794 775 763 782 833 803 763 743 805 740 803 806 853 741 739 755 797 883 761 776 739 816 790 786 830 851 865 970 857 926 999 984 997 1005 945 964 933 921 1021 1026 1128 1121 1258 1162 1190 1176 1086 987 900 924 915 790 866 857 874 854 821 786 862 843 871 952 1003 1050 1110 1121 1109 1051 1131 1027 1012 1003 887 902 888 889 798 823 790 776 800 734 764 806 823 832 893 962 1030 1110 1247 1192 1171 1170 1077 1045 941 985 838 835 800 793 785 761 780 822 808 913 848 865 915 1064 1143 1258 1246 1235 1231 1103 1093 999 993 834 811 816 800 713 801 785 792 819 839 777 771 777 822 809 806 800 797 821 828 780 817 830 856 870 839 865 875 907 933 928 972 979 942 942 894 874 838 831 824 879 905 920 901 917 989 952 967 1008 1007 1020 911 960 977 900 905 835 870 887 830 797 817 841 866 861 845 862 790 812 859 870 816 799 776 790 796 828 823 831 815 825 862 951 972 1027 954 957 950 929 916 862 888 864 844 833 846 808 833 770 765 787 777 782 771 746 788 800 792 794 746 813 837 791 858 892 914 926 953 952 951 937 925 969 999 911 965 892 894 859 902 816 815 870 866 855 881 956 939 890 840 887 830 832 833 871 910 951 990 967 980 898 959 902 921 863 848 841 803 811 862 805 845 895 887 968 938 974 1043 998 968 925 886 893 907 866 873 820 882 870 919 884 943 952 897 993 960 880 878 899 838 812 835 798 776 752 782 730 754 744 710 761 760 788 796 726 747 796 813 823 859 809 839 786 858 923 891 915 860 940 854 847 828 922 927 960 957 1072 1049 1039 1043 964 964 977 1068 1030 1061 1068 1022 1031 994 970 922 946 825 840 795 791 752 802 807 750 764 775 728 716 715 797 768 755 742 764 766 820 760 753 745 787 769 819 770 791 855 799 889 921 988 1019 1040 1038 1064 1037 930 971 920 905 863 870 801 816 851 740 793 740 724 775 772 798 760 742 766 759 727 718 755 749 759 787 789 871 862 925 938 925 932 902 867 842 820 897 780 841 800 841 815 832 769 783 765 800 740 779 764 761 753 752 736 823 788 787 790 808 816 837 839 850 820 882 846 802 870 804 795 895 857 873 847 889 866 838 882 963 945 939 908 899 838 864 841 865 847 801 797 783 789 735 771 766 716 792 759 758 711 773 756 750 744 729 752 810 727 711 739 731 750 760 735 751 685 766 738 796 822 747 735 759 693 757 769 692 745 767 790 752 689 742 720 769 770 720 721 741 771 744 758 719 746 740 739 740 807 722 807 775 788 764 819 790 759 778 774 838 751 731 753 730 752 750 763 724 724 711 753 778 689 735 752 696 692 746 694 758 732 762 786 730 788 709 837 815 847 849 772 786 761 759 763 791 741 746 760 751 767 674 759 699 715 745 739 723 710 757 775 760 754 833 768 826 830 809 794 835 773 864 819 808 773 828 809 758 774 774 726 746 789 775 767 860 750 786 784 820 762 788 789 762 770 782 813 797 792 764 792 808 853 735 786 757 754 773 760 730 736 777 737 756 789 759 743 778 754 713 789 797 754 776 800 777 879 880 841 837 833 818 836 796 851 777 833 740 771 732 752 786 734 780 708 730 758 752 786 843 805 764 788 841 828 786 781 827 853 823 845 849 832 908 862 863 876 885 861 895 857 876 819 819 861 845 847 759 785 790 802 796 777 783 752 731 735 775 745 816 752 761 768 768 781 785 823 844 872 858 837 839 861 815 851 815 829 816 801 746 759 788 813 762 765 752 816 840 818 886 896 887 862 829 836 823 828 870 836 830 771 763 723 760 738 740 681 729 739 704 714 654 747 760 717 748 710 762 683 696 730 757 722 674 710 675 781 758 767 748 776 772 763 797 778 809 723 847 755 782 826 780 829 771 803 758 772 798 796 834 820 796 807 825 812 816 779 732 820 817 746 820 804 770 750 770 735 748 821 780 665 765 751 767 786 791 725 778 757 777 797 769 775 829 743 756 767 765 764 816 836 838 819 742 828 735 796 817 785 837 779 780 760 728 733 772 713 718 720 784 738 754 732 722 720 750 737 701 771 785 715 725 677 685 710 730 729 771 763 710 736 843 739 726 731 685 754 747 712 757 736 725 713 731 731 708 755 755 810 783 791 704 680 790 784 765 770 714 770 766 767 736 756 747 755 788 751 755 732 750 778 726 765 770 730 756 754 695 738 757 756 710 788 740 733 792 822 751 776 785 825 835 830 818 905 885 875 827 808 776 789 821 874</counts>
			</dataPoints>
		</scan>
	</xrdMeasurement>
</xrdMeasurements>