File: dataset/precursor_mixture/V2O5_0p3005-NiO_0p4020-TiO2_0p3020--2min.xrdml
<?xml version="1.0"?>
<xrdMeasurements xmlns="http://www.xrdml.com/XRDMeasurement/2.3" xmlns:xsi="http://www.w3.org/2001/XMLSchema-instance" xsi:schemaLocation="http://www.xrdml.com/XRDMeasurement/2.3 http://www.xrdml.com/XRDMeasurement/2.3/XRDMeasurement.xsd" status="Completed" recordIdentifier="{6819EB9F-9C60-48EC-B49C-472B9B401544}">
	<comment>
		<entry/>
	</comment>
	<sample type="To be analyzed">
		<id>V2O5_0p3005-NiO_0p4020-TiO2_0p3020--2min</id>
		<name></name>
		<preparedBy></preparedBy>
	</sample>
	<xrdMeasurement measurementType="Scan" status="Completed" sampleMode="Reflection">
		<usedWavelength intended="K-Alpha 1">
			<kAlpha1 unit="Angstrom">1.5405980</kAlpha1>
			<kAlpha2 unit="Angstrom">1.5444260</kAlpha2>
			<kBeta unit="Angstrom">1.3922500</kBeta>
			<ratioKAlpha2KAlpha1>0.5000</ratioKAlpha2KAlpha1>
		</usedWavelength>
		<incidentBeamPath>
			<radius unit="mm">145.00</radius>
			<xRayTube id="1010048" name="Empyrean Cu LFF HR (9430 033 7310x)">
				<tension unit="kV">40.0</tension>
				<current unit="mA">15.0</current>
				<anodeMaterial>Cu</anodeMaterial>
				<focus type="Line">
					<length unit="mm">12.0</length>
					<width unit="mm">0.4</width>
					<takeOffAngle unit="deg">6.0</takeOffAngle>
				</focus>
			</xRayTube>
			<sollerSlit id="21010002" name="Soller slits 0.04 rad.">
				<opening unit="rad">0.0400</opening>
			</sollerSlit>
			<mask id="22031000" name="Fixed mask 13 mm">
				<width unit="mm">9.00</width>
			</mask>
			<divergenceSlit id="22120001" name="Divergence slit 1°" xsi:type="fixedDivergenceSlitType">
				<distanceToSample unit="mm">50.00</distanceToSample>
				<height unit="mm">1.52</height>
			</divergenceSlit>
		</incidentBeamPath>
		<sampleMovement xsi:type="spinningSampleMovementType">
			<spinnerRevolutionTime unit="seconds">1.0</spinnerRevolutionTime>
		</sampleMovement>
		<diffractedBeamPath>
			<radius unit="mm">145.00</radius>
			<antiScatterSlit id="22090040" name="AS slit 9 mm (PIXcel)" xsi:type="fixedAntiScatterSlitType">
				<height unit="mm">9.00</height>
			</antiScatterSlit>
			<sollerSlit id="21020003" name="Large Soller slits 0.04 rad.">
				<opening unit="rad">0.0400</opening>
			</sollerSlit>
			<filter id="20030001" name="Large beta-filter Nickel">
				<material>Ni</material>
				<thickness unit="mm">0.020</thickness>
			</filter>
			<detector id="7010019" name="PIXcel1D-Medipix3 detector" xsi:type="rtmsDetectorType">
				<phd unit="keV">
					<lowerLevel>4.02</lowerLevel>
					<upperLevel>11.27</upperLevel>
				</phd>
				<mode>Scanning</mode>
				<activeLength unit="deg">5.542</activeLength>
			</detector>
		</diffractedBeamPath>
		<scan appendNumber="0" mode="Continuous" scanAxis="Gonio" status="Completed">
			<header>
				<startTimeStamp>2024-11-14T15:32:36-08:00</startTimeStamp>
				<endTimeStamp>2024-11-14T15:34:40-08:00</endTimeStamp>
				<author>
					<name>AutomatedUser</name>
				</author>
				<source>
					<applicationSoftware version="1.7b (136)">PANalytical Aeris Instrument Suite</applicationSoftware>
					<instrumentControlSoftware version="3.2.00000000 20240306">AERIS</instrumentControlSoftware>
					<instrumentID>950485</instrumentID>
				</source>
			</header>
			<dataPoints>
				<positions axis="2Theta" unit="deg">
					<startPosition>10.02173288</startPosition>
					<endPosition>99.99585608</endPosition>
				</positions>
				<positions axis="Omega" unit="deg">
					<startPosition>5.01086644</startPosition>
					<endPosition>49.99792804</endPosition>
				</positions>
				<commonCountingTime unit="seconds">10.965</commonCountingTime>
				<counts unit="counts">2267 2342 2273 2343 2290 2175 2295 2248 2277 2277 2215 2189 2213 2260 2203 2236 2244 2183 2135 2153 2124 2096 2135 2234 2118 2108 2151 2085 2019 2155 2030 2160 2142 2065 2046 2007 2052 2001 2013 2080 2047 2001 2107 2025 1970 2001 1931 1957 1946 1917 2000 1973 1922 1978 1964 1917 1829 1877 1930 1995 1918 1924 1811 1923 1871 1868 1898 1817 1935 1846 1875 1939 1807 1909 1839 1885 1831 1945 1824 1841 1855 1870 1925 1863 1884 1852 1906 1903 1821 1808 1851 1852 1852 1871 1845 1842 1874 1795 1830 1764 1861 1894 1822 1824 1841 1847 1849 1877 1845 1871 1817 1867 1819 1905 1869 1878 1910 2015 1937 1953 2064 2221 2196 2259 2330 2358 2287 2157 2019 2022 1909 1889 1816 1908 1892 1755 1890 1788 1868 1825 1819 1891 1904 1824 1892 1963 1884 1913 1854 1841 1924 1880 1847 1861 1908 1831 1804 1908 1806 1848 1911 1844 1858 1847 1798 1865 1874 1857 1903 1815 1809 1850 1908 1877 1828 1773 1887 1861 1797 1849 1899 1875 1917 1893 1872 1896 1879 1910 1842 1782 1868 1696 1771 1760 1781 1910 1910 1797 1910 1841 1901 1888 1819 1851 1854 1849 1845 1885 1864 1964 1876 1809 1909 1852 1896 2005 1888 1848 1939 1842 1886 1862 1985 1904 1924 1967 2094 2067 2112 2226 2300 2511 2751 3211 3903 4550 4874 4873 4731 4337 3862 3360 2729 2404 2176 1961 2055 1948 1941 1929 1818 1896 1923 1904 1819 1897 1868 1839 2038 1934 2033 1870 1896 2005 2078 2141 2305 2434 2579 2689 2656 2654 2584 2473 2361 2183 1973 1939 1869 1845 1881 1972 1969 1903 1871 1807 1940 1925 1815 1825 1928 1852 1915 1856 1844 1925 1883 1872 1895 1867 1738 1848 1861 1838 1782 1840 1839 1866 1918 1856 1883 1797 1879 1903 1853 1868 1870 1866 1845 1846 1846 1803 1842 1918 1880 1823 1855 1821 1768 1820 1926 1939 1923 1954 1898 1858 1959 1965 1954 1957 1989 2016 1967 2121 2171 2430 2500 2934 3735 4926 6290 6854 7118 6910 6612 5864 4914 3791 2955 2543 2308 2151 2189 2089 2087 1987 2140 2327 2447 2788 3007 3115 3236 3132 2929 2720 2490 2196 1953 1925 1998 1904 1950 1971 1870 1991 1870 1963 1795 1809 1898 1804 1825 1900 1885 1898 1833 1930 1828 1900 1895 1803 1920 1925 1928 1862 1776 1895 1833 1976 1808 1798 1879 1749 1764 1850 1834 1804 1821 1827 1839 1758 1805 1828 1863 1737 1890 1887 1815 1803 1784 1838 1861 1864 1818 1767 1796 1840 1852 1864 1891 1873 1783 1741 1807 1773 1770 1845 1801 1796 1822 1844 1899 1882 1795 1868 1803 1906 1822 1821 1856 1788 1808 1855 1784 1791 1838 1873 1851 1755 1834 1933 1856 1840 1877 2052 1969 1994 2031 2252 2460 2900 3064 3337 3218 3183 3112 2859 2558 2346 2071 1956 1863 1896 1849 1807 1879 1791 1841 1807 1794 1801 1802 1846 1754 1819 1841 1771 1881 1875 1966 2015 2145 2205 2429 2374 2408 2411 2263 2157 2031 1934 1901 1821 1896 1824 1816 1850 1781 1839 1786 1771 1869 1850 1900 2022 1928 1999 1897 1966 2002 1901 1878 1852 1863 1755 1820 1890 1824 1810 1838 1800 1841 1839 1836 1857 2060 2165 2423 2358 2396 2373 2214 2171 1999 1879 1840 1808 1857 1787 1778 1682 1796 1922 1804 1802 1711 1795 1768 1789 1795 1773 1709 1784 1789 1792 1764 1887 1798 1739 1821 1805 1796 1754 1739 1823 1878 1885 1831 1820 1968 1928 1830 1832 1877 1810 1791 1791 1865 1859 1863 1812 1804 1835 1947 2040 2041 2006 2163 2351 2485 2762 3004 3713 4452 5430 6086 6401 6646 6432 5825 5028 4161 3420 2879 2565 2628 2893 2943 3006 3095 3104 2934 2744 2438 2168 2076 1935 1869 1835 1858 1888 1833 1901 1921 2041 2034 2195 2190 2105 2146 2069 2008 1912 1857 1812 1768 1785 1786 1804 1802 1700 1846 1778 1759 1759 1803 1794 1783 1781 1856 1868 1775 1874 1699 1745 1858 1721 1750 1734 1789 1718 1830 1777 1778 1811 1803 1748 1821 1719 1796 1761 1740 1690 1774 1784 1817 1879 1751 1789 1764 1834 1813 1738 1924 1990 2032 2220 2108 2208 2311 2241 2251 2225 2121 1955 1913 1799 1862 1883 1810 1967 1878 1916 1969 1935 1976 2045 2038 2136 2119 1950 1972 1911 1791 1865 1845 1911 1880 1834 1825 1939 1917 1920 1907 1957 2177 2197 2231 2480 2663 3196 4454 6040 7560 8729 9835 10355 10105 8891 7380 5820 4494 3318 2712 2368 2315 2012 1924 1942 1853 1898 1876 1872 1798 1888 1836 1794 1841 1855 1869 1846 1844 1831 1872 1715 1791 1791 1846 1845 1715 1763 1768 1720 1851 1800 1789 1858 1886 1757 1804 1788 1960 1934 1947 2041 1982 2022 2122 2190 1874 1970 1904 1804 1735 1850 1809 1853 1740 1776 1804 1762 1801 1762 1880 1820 1770 1772 1819 1840 1812 1799 1738 1823 1767 1781 1842 1819 1782 1808 1810 1824 1825 1780 1839 1909 1907 2086 2188 2249 2232 2232 2259 2188 2131 2002 1909 2029 2009 2142 2204 2521 2854 3005 3364 3593 3727 3721 3674 3219 2690 2527 2121 2043 1874 1851 1809 1830 1962 1890 1942 1888 2001 2123 2067 2046 2104 2078 2067 1974 1988 1878 1807 1879 1782 1782 1850 1869 1810 1859 1871 1886 1833 1795 1800 1751 1702 1720 1662 1766 1762 1689 1739 1802 1765 1774 1796 1786 1766 1762 1788 1723 1793 1742 1846 1892 1741 1784 1739 1652 1780 1748 1742 1864 1846 1833 1988 1973 2108 2168 2165 2256 2115 2036 2016 1966 1901 1770 1831 1827 1819 1789 1795 1845 1938 1853 1881 2051 1947 1939 2018 1894 1881 1854 1807 1762 1689 1817 1807 1839 1778 1784 1791 1700 1746 1842 1795 1721 1754 1769 1794 1720 1739 1781 1786 1766 1765 1697 1800 1742 1764 1810 1812 1862 1860 1934 2041 2315 2524 2583 2843 2823 2956 2698 2474 2306 2185 2020 1911 1884 1838 1847 1798 1805 1877 1784 1747 1797 1814 1801 1869 1979 1924 2033 2267 2439 2586 2733 2856 2842 2700 2506 2308 2103 2079 1959 1910 1864 1894 1816 1969 1990 2026 1938 1910 1893 1792 1857 1777 1760 1805 1774 1807 1760 1798 1820 1841 1814 1808 1793 1842 1776 1760 1810 1734 1674 1820 1783 1767 1720 1753 1738 1782 1808 1741 1746 1762 1712 1809 1763 1792 1708 1740 1789 1762 1702 1683 1738 1760 1785 1763 1723 1798 1859 1708 1812 1807 1759 1804 1742 1737 1757 1807 1795 1816 1776 1934 1827 1838 1872 1843 1892 1843 1763 1860 1815 1871 1833 1914 1996 2032 1973 1876 1843 1827 1834 1792 1893 1832 1772 1753 1786 1715 1794 1773 1751 1743 1809 1675 1805 1810 1827 1756 1890 1797 1807 1815 1763 1726 1702 1715 1786 1768 1764 1754 1848 1718 1753 1816 1786 1766 1768 1839 1847 1932 2020 2058 2073 1988 1981 1963 1893 1994 1851 1751 1840 1813 1871 1765 1852 1732 1855 1843 1795 1889 1913 2010 2167 2152 2259 2315 2405 2293 2115 2118 2236 2299 2181 2211 2450 2681 3045 3327 4017 4516 4857 5233 5426 5475 5580 5001 4552 3913 3485 3141 2788 2529 2267 2141 1972 2064 1876 1869 1865 1820 1883 1822 1883 1843 1792 1894 1874 1822 1831 1843 1812 1783 1827 1826 1824 1804 1897 1835 1875 1828 1838 1967 2043 1864 1949 1790 1807 1756 1807 1820 1805 1705 1791 1802 1775 1794 1822 1717 1723 1769 1739 1740 1809 1801 1735 1786 1783 1783 1757 1798 1759 1789 1834 1876 1729 1864 1900 1809 1937 1735 1913 1826 1881 1787 1753 1779 1701 1703 1806 1770 1729 1762 1755 1739 1746 1733 1805 1753 1810 1769 1714 1745 1744 1744 1781 1754 1754 1731 1776 1789 1747 1786 1784 1786 1811 1868 1779 1792 1878 1766 1826 1791 1834 1913 1762 1763 1789 1822 1812 1886 1782 1788 1790 1986 2028 1990 2095 2188 2085 2224 2265 2190 2107 1976 1979 1912 1833 1870 1795 1800 1780 1769 1791 1779 1871 1806 1923 1893 1936 1880 1882 1850 1841 1887 1864 1810 1809 1864 1906 1931 2028 2033 2126 2171 2319 2191 2094 2118 2039 2085 1981 1902 1824 1774 1752 1829 1794 1772 1801 1770 1872 1754 1701 1816 1730 1715 1739 1782 1765 1743 1783 1775 1836 1826 1799 1835 1895 1848 1882 1804 1785 1762 1803 1866 1756 1819 1806 1910 1877 1848 1892 1902 1939 1837 1839 1918 1908 1949 1954 1915 1851 1890 1860 1850 1890 1902 1790 1777 1731 1751 1801 1816 1716 1771 1767 1760 1779 1685 1828 1747 1749 1732 1714 1760 1807 1815 1756 1806 1744 1842 1835 1771 1854 1826 1875 1901 1849 1833 1930 1907 1975 1964 1969 1906 1958 1991 1961 1963 2008 2079 2169 2367 2431 2567 2497 2524 2554 2689 2845 2934 3084 3060 3014 2886 2781 2823 2538 2422 2356 2212 2033 2009 2111 2027 2093 2061 2013 2107 2030 1889 1838 1868 1905 1759 1826 1755 1869 1827 1794 1662 1743 1716 1869 1791 1788 1725 1749 1723 1768 1749 1777 1802 1717 1849 1724 1862 1715 1817 1801 1694 1796 1738 1802 1753 1751 1735 1803 1791 1772 1828 1831 1746 1776 1869 1868 1858 1872 1772 1782 1740 1875 1812 1790 1818 1770 1718 1809 1760 1811 1840 1817 1878 1897 1924 1877 1949 1925 2031 2077 2238 2322 2409 2552 2525 2510 2333 2430 2339 2338 2205 2151 2061 2033 1968 1953 1863 1876 1808 1767 1775 1749 1836 1813 1855 1757 1730 1759 1663 1821 1787 1754 1734 1749 1766 1847 1773 1748 1796 1745 1774 1656 1736 1841 1737 1719 1749 1789 1807 1756 1774 1832 1769 1739 1782 1809 1687 1765 1721 1717 1683 1764 1808 1734 1808 1777 1800 1750 1755 1817 1846 1787 1719 1832 1796 1822 1930 1971 2078 1987 2112 2002 1997 1935 1947 2115 1927 1878 1817 1886 1930 1875 1841 1873 1812 1818 1804 1848 1780 1834 1724 1827 1684 1737 1797 1778 1786 1714 1685 1870 1751 1728 1720 1819 1671 1756 1827 1743 1775 1816 1729 1687 1746 1663 1720 1671 1755 1656 1731 1806 1725 1756 1777 1748 1825 1835 1769 1779 1803 1677 1754 1783 1822 1761 1799 1713 1783 1746 1722 1828 1724 1749 1751 1752 1744 1723 1719 1755 1751 1695 1776 1730 1750 1761 1775 1821 1869 1861 1744 1799 1818 1782 1785 1849 1830 1831 1766 1736 1734 1773 1781 1826 1784 1763 1754 1704 1766 1759 1727 1826 1719 1715 1752 1712 1730 1812 1649 1704 1774 1726 1722 1792 1790 1674 1716 1697 1763 1716 1658 1840 1779 1801 1816 1891 1722 1771 1756 1750 1703 1655 1833 1762 1798 1726 1750 1726 1703 1822 1750 1763 1702 1845 1739 1774 1725 1752 1749 1821 1777 1723 1783 1819 1744 1838 1790 1764 1735 1776 1841 1797 1738 1789 1732 1764 1724 1773 1781 1756 1736 1812 1698 1745 1792 1807 1829 1728 1810 1794 1799 1767 1785 1729 1750 1788 1749 1718 1763 1838 1686 1764 1723 1740 1736 1714 1754 1742 1793 1718 1690 1776 1813 1800 1783 1820 1808 1746 1700 1810 1844 1828 1793 1793 1701 1793 1661 1808 1788 1770 1752 1692 1768 1704 1809 1833 1776 1842 1767 1705 1803 1722 1761 1847 1791 1833 1888 1811 1801 1791 1891 1861 1869 1749 1836 1873 1819 1769 1831 1784 1821 1788 1742 1836 1819 1936 1924 1928 1875 1908 1903 1819 1805 1957 1810 1824 1860 1824 1821 1869 1860 1906 2061 2048 2072 2213 2237 2294 2291 2199 2251 2046 2103 2051 1992 2021 1989 1939 1860 1834 1817 1893 1799 1796 1800 1877 1707 1811 1813 1791 1739 1746 1749 1694 1739 1746 1829 1816 1738 1752 1725 1738 1685 1741 1742 1764 1726 1767 1791 1691 1666 1722 1726 1632 1776 1711 1689 1767 1781 1709 1768 1768 1802 1807 1761 1706 1731 1846 1752 1779 1802 1774 1829 1758 1773 1858 1882 1767 1778 1858 1819 1891 1837 1870 1813 1750 1753 1860 1847 1794 1829 1759 1842 1740 1693 1701 1831 1750 1735 1756 1831 1759 1718 1655 1741 1706 1832 1839 1803 1920 1743 1883 1868 1823 1900 1850 1793 1847 1878</counts>
			</dataPoints>
		</scan>
	</xrdMeasurement>
</xrdMeasurements>