File: dataset/precursor_mixture/V2O5_0p2012-La(OH)3_0p5004-MnCO3_0p3013--8min.xrdml
<?xml version="1.0"?>
<xrdMeasurements xmlns="http://www.xrdml.com/XRDMeasurement/2.3" xmlns:xsi="http://www.w3.org/2001/XMLSchema-instance" xsi:schemaLocation="http://www.xrdml.com/XRDMeasurement/2.3 http://www.xrdml.com/XRDMeasurement/2.3/XRDMeasurement.xsd" status="Completed" recordIdentifier="{AD347354-D6EE-49C0-BDFF-DF25805AE8BB}">
	<comment>
		<entry/>
	</comment>
	<sample type="To be analyzed">
		<id>Dara_redo_4-8min_manual</id>
		<name></name>
		<preparedBy></preparedBy>
	</sample>
	<xrdMeasurement measurementType="Scan" status="Completed" sampleMode="Reflection">
		<usedWavelength intended="K-Alpha 1">
			<kAlpha1 unit="Angstrom">1.5405980</kAlpha1>
			<kAlpha2 unit="Angstrom">1.5444260</kAlpha2>
			<kBeta unit="Angstrom">1.3922500</kBeta>
			<ratioKAlpha2KAlpha1>0.5000</ratioKAlpha2KAlpha1>
		</usedWavelength>
		<incidentBeamPath>
			<radius unit="mm">145.00</radius>
			<xRayTube id="1010048" name="Empyrean Cu LFF HR (9430 033 7310x)">
				<tension unit="kV">40.0</tension>
				<current unit="mA">15.0</current>
				<anodeMaterial>Cu</anodeMaterial>
				<focus type="Line">
					<length unit="mm">12.0</length>
					<width unit="mm">0.4</width>
					<takeOffAngle unit="deg">6.0</takeOffAngle>
				</focus>
			</xRayTube>
			<sollerSlit id="21010002" name="Soller slits 0.04 rad.">
				<opening unit="rad">0.0400</opening>
			</sollerSlit>
			<mask id="22031000" name="Fixed mask 13 mm">
				<width unit="mm">9.00</width>
			</mask>
			<divergenceSlit id="22120001" name="Divergence slit 1°" xsi:type="fixedDivergenceSlitType">
				<distanceToSample unit="mm">50.00</distanceToSample>
				<height unit="mm">1.52</height>
			</divergenceSlit>
		</incidentBeamPath>
		<sampleMovement xsi:type="spinningSampleMovementType">
			<spinnerRevolutionTime unit="seconds">1.0</spinnerRevolutionTime>
		</sampleMovement>
		<diffractedBeamPath>
			<radius unit="mm">145.00</radius>
			<antiScatterSlit id="22090040" name="AS slit 9 mm (PIXcel)" xsi:type="fixedAntiScatterSlitType">
				<height unit="mm">9.00</height>
			</antiScatterSlit>
			<sollerSlit id="21020003" name="Large Soller slits 0.04 rad.">
				<opening unit="rad">0.0400</opening>
			</sollerSlit>
			<filter id="20030001" name="Large beta-filter Nickel">
				<material>Ni</material>
				<thickness unit="mm">0.020</thickness>
			</filter>
			<detector id="7010019" name="PIXcel1D-Medipix3 detector" xsi:type="rtmsDetectorType">
				<phd unit="keV">
					<lowerLevel>4.02</lowerLevel>
					<upperLevel>11.27</upperLevel>
				</phd>
				<mode>Scanning</mode>
				<activeLength unit="deg">5.542</activeLength>
			</detector>
		</diffractedBeamPath>
		<scan appendNumber="0" mode="Continuous" scanAxis="Gonio" status="Completed">
			<header>
				<startTimeStamp>2024-11-29T08:03:42-08:00</startTimeStamp>
				<endTimeStamp>2024-11-29T08:11:49-08:00</endTimeStamp>
				<author>
					<name>AutomatedUser</name>
				</author>
				<source>
					<applicationSoftware version="1.7b (136)">PANalytical Aeris Instrument Suite</applicationSoftware>
					<instrumentControlSoftware version="3.2.00000000 20240306">AERIS</instrumentControlSoftware>
					<instrumentID>950485</instrumentID>
				</source>
			</header>
			<dataPoints>
				<positions axis="2Theta" unit="deg">
					<startPosition>10.00943322</startPosition>
					<endPosition>99.99442286</endPosition>
				</positions>
				<positions axis="Omega" unit="deg">
					<startPosition>5.00471661</startPosition>
					<endPosition>49.99721143</endPosition>
				</positions>
				<commonCountingTime unit="seconds">12.495</commonCountingTime>
				<counts unit="counts">2419 2422 2388 2498 2451 2438 2423 2383 2412 2465 2286 2378 2332 2351 2356 2356 2360 2340 2215 2345 2304 2347 2355 2265 2319 2337 2345 2365 2348 2338 2396 2363 2256 2235 2380 2264 2298 2392 2279 2320 2366 2328 2212 2324 2254 2380 2349 2267 2289 2291 2244 2264 2240 2289 2175 2174 2168 2327 2223 2231 2251 2223 2247 2231 2236 2240 2201 2256 2148 2219 2339 2215 2177 2240 2219 2161 2283 2123 2204 2231 2183 2201 2132 2207 2196 2194 2161 2152 2174 2129 2148 2233 2129 2204 2234 2162 2168 2160 2104 2073 2112 2117 2127 2173 2124 2051 2105 2130 2153 2145 2218 2007 2107 2099 2093 2116 2116 2047 2092 2032 2088 2121 2109 2062 2041 2116 2112 2001 2059 2041 2074 2148 2018 2037 2049 2012 2090 2006 2092 2044 2091 2055 1981 1950 1959 2058 2009 1978 2002 1976 2072 1927 2008 1971 1925 2052 1966 1989 1972 1962 2002 2070 2017 2006 1997 2015 1983 2000 1932 1998 1942 1938 1968 1891 1902 1896 1975 1909 1998 1934 1894 1997 1909 1988 1904 1893 1861 1816 1935 1920 1933 1938 1934 1897 1918 1914 1941 1925 1930 1862 1928 1863 1918 1870 1912 1818 1945 1891 1950 1869 1899 1850 1938 1835 1899 1870 1846 1906 1941 1925 1952 1848 1885 1806 1805 1888 1828 1849 1827 1841 1883 1888 1843 1983 1861 1912 1837 1733 1779 1885 1837 1843 1881 1884 1858 1954 1778 1857 1876 1862 1903 1814 1755 1772 1743 1812 1873 1764 1779 1881 1797 1821 1797 1735 1803 1774 1868 1776 1840 1785 1822 1749 1753 1847 1791 1810 1781 1736 1765 1804 1833 1794 1801 1705 1812 1718 1685 1769 1738 1725 1723 1744 1777 1704 1720 1883 1686 1715 1739 1709 1767 1761 1801 1778 1746 1741 1736 1815 1761 1714 1735 1713 1716 1740 1627 1689 1699 1787 1643 1778 1740 1718 1701 1732 1744 1738 1751 1742 1695 1796 1710 1629 1712 1691 1772 1747 1742 1741 1685 1614 1702 1655 1770 1768 1722 1731 1760 1704 1664 1735 1634 1742 1652 1701 1662 1685 1760 1774 1604 1677 1666 1752 1680 1664 1696 1684 1760 1658 1719 1676 1664 1701 1655 1654 1715 1696 1653 1701 1748 1724 1659 1705 1673 1739 1645 1690 1619 1691 1688 1743 1714 1732 1691 1665 1652 1619 1673 1582 1597 1690 1655 1676 1626 1700 1599 1631 1643 1598 1687 1668 1644 1638 1626 1743 1632 1638 1676 1571 1650 1626 1648 1658 1706 1666 1619 1654 1644 1655 1676 1695 1689 1736 1609 1579 1535 1665 1631 1589 1695 1624 1680 1614 1710 1670 1620 1686 1650 1677 1639 1690 1587 1626 1616 1645 1669 1660 1706 1661 1721 1679 1731 1712 1684 1702 1792 1743 1744 1796 1727 1757 1775 1788 1760 1865 1825 1773 1793 1842 1911 1831 1910 1932 1995 2060 1975 2059 2083 2177 2199 2250 2160 2267 2430 2421 2486 2542 2609 2655 2626 2702 2833 2897 3049 3157 3405 3445 3487 3641 3819 3953 4133 4235 4390 4566 4649 4977 5184 5250 5300 5541 5527 5874 5868 6193 6002 6165 6169 6129 6010 6043 5769 5617 5467 5209 4769 4680 4275 4121 3873 3498 3378 3199 2856 2885 2676 2549 2491 2411 2335 2238 2081 2128 2073 2033 2012 1933 2010 1939 1928 1895 1867 1787 1838 1837 1892 1759 1689 1700 1683 1684 1657 1715 1698 1660 1609 1690 1714 1663 1640 1732 1610 1608 1630 1566 1608 1617 1575 1595 1596 1634 1646 1613 1570 1587 1518 1574 1621 1587 1547 1530 1624 1552 1565 1580 1545 1509 1596 1534 1539 1594 1612 1605 1550 1666 1568 1508 1543 1578 1538 1516 1502 1509 1581 1538 1590 1586 1568 1491 1523 1516 1504 1501 1525 1631 1566 1583 1509 1551 1484 1588 1462 1535 1565 1544 1554 1481 1558 1449 1512 1459 1466 1467 1490 1554 1510 1475 1466 1553 1549 1492 1481 1447 1465 1467 1592 1447 1469 1520 1515 1504 1539 1484 1435 1562 1497 1468 1453 1521 1435 1529 1516 1511 1504 1492 1501 1452 1514 1452 1556 1389 1576 1451 1402 1477 1527 1497 1518 1510 1457 1417 1419 1526 1405 1477 1454 1499 1410 1530 1441 1467 1448 1503 1424 1447 1499 1408 1416 1401 1423 1437 1436 1427 1440 1483 1402 1434 1457 1537 1395 1409 1435 1363 1368 1385 1479 1380 1514 1414 1468 1423 1377 1384 1445 1450 1468 1397 1499 1397 1494 1421 1451 1356 1490 1436 1393 1373 1438 1382 1369 1495 1430 1401 1407 1391 1386 1434 1463 1423 1464 1442 1438 1366 1438 1459 1545 1383 1376 1375 1391 1397 1419 1459 1423 1418 1392 1382 1363 1406 1372 1382 1315 1434 1457 1378 1367 1417 1403 1342 1423 1306 1352 1410 1260 1377 1329 1309 1260 1335 1357 1393 1367 1383 1388 1312 1394 1329 1390 1360 1262 1381 1333 1299 1371 1342 1472 1330 1390 1350 1342 1264 1353 1287 1367 1373 1396 1432 1419 1341 1353 1333 1436 1378 1335 1375 1310 1331 1385 1291 1323 1331 1407 1370 1359 1433 1433 1368 1372 1360 1300 1416 1408 1335 1333 1361 1288 1277 1304 1401 1357 1345 1354 1303 1429 1322 1362 1271 1359 1332 1294 1372 1333 1298 1317 1335 1309 1244 1385 1323 1311 1362 1343 1309 1364 1395 1341 1332 1350 1342 1331 1341 1302 1340 1304 1261 1320 1360 1383 1299 1388 1357 1333 1342 1364 1270 1321 1339 1373 1373 1367 1320 1281 1290 1332 1432 1400 1441 1385 1433 1365 1396 1449 1446 1523 1470 1472 1556 1444 1517 1622 1589 1685 1703 1653 1722 1758 1765 1826 1860 1897 1937 1949 1954 2078 2053 2207 2110 2048 1973 2002 1912 1922 1925 1783 1794 1625 1603 1555 1504 1507 1478 1346 1440 1366 1362 1341 1358 1351 1300 1254 1258 1336 1246 1308 1213 1270 1215 1291 1296 1208 1292 1292 1348 1278 1244 1258 1286 1317 1286 1277 1212 1247 1217 1228 1301 1277 1227 1255 1257 1227 1203 1285 1252 1236 1227 1255 1278 1277 1264 1257 1296 1253 1303 1219 1214 1218 1270 1220 1200 1207 1190 1169 1228 1277 1250 1263 1149 1239 1238 1262 1269 1265 1244 1256 1245 1291 1185 1244 1283 1237 1151 1224 1310 1177 1193 1222 1264 1181 1286 1298 1268 1301 1294 1237 1252 1262 1269 1211 1287 1232 1293 1383 1260 1344 1294 1323 1339 1384 1349 1462 1412 1392 1420 1375 1431 1435 1352 1391 1489 1453 1309 1418 1434 1359 1390 1335 1384 1341 1322 1336 1285 1203 1257 1225 1216 1208 1233 1252 1213 1183 1231 1224 1210 1193 1202 1174 1209 1256 1190 1236 1220 1220 1201 1160 1122 1166 1160 1188 1214 1163 1162 1221 1164 1123 1211 1191 1174 1158 1188 1193 1194 1178 1125 1174 1172 1164 1214 1310 1194 1224 1157 1153 1196 1204 1089 1165 1200 1125 1243 1224 1173 1182 1149 1186 1203 1162 1189 1214 1223 1202 1208 1196 1173 1197 1199 1146 1139 1117 1137 1172 1153 1221 1144 1099 1168 1124 1155 1159 1132 1137 1104 1173 1141 1175 1133 1123 1119 1107 1148 1150 1129 1125 1160 1241 1174 1165 1141 1097 1128 1162 1173 1199 1176 1165 1162 1120 1133 1127 1176 1184 1174 1197 1096 1220 1141 1152 1157 1133 1166 1097 1136 1196 1082 1125 1110 1173 1207 1175 1135 1184 1174 1187 1168 1119 1151 1174 1173 1081 1108 1129 1170 1110 1233 1140 1097 1135 1122 1167 1122 1190 1079 1142 1152 1056 1091 1205 1111 1182 1164 1205 1145 1166 1101 1231 1110 1220 1176 1212 1219 1157 1211 1205 1153 1189 1212 1235 1228 1194 1217 1154 1255 1230 1245 1208 1286 1249 1296 1276 1299 1402 1351 1399 1321 1415 1472 1436 1453 1564 1477 1589 1532 1558 1557 1691 1600 1601 1686 1608 1533 1592 1601 1499 1484 1449 1405 1353 1414 1316 1263 1277 1280 1284 1257 1182 1256 1252 1236 1179 1207 1182 1137 1157 1157 1196 1193 1152 1144 1161 1082 1167 1126 1145 1093 1142 1093 1066 1068 1073 1045 1132 1078 1122 1120 1113 1102 1119 1095 1111 1080 1046 1106 1099 1072 1165 1023 1082 1021 1119 1148 1095 1115 1110 1060 1047 1124 1110 1102 1075 1082 1046 1122 1093 1098 1121 1093 1067 1116 1040 1066 1108 1105 1121 1152 1055 1064 1140 1079 1101 1094 1125 1107 1090 1023 1067 1044 1137 1113 1071 1027 1051 1064 1128 1058 1057 1110 1129 1135 1044 1074 1062 1096 1117 1103 1063 1086 1017 1011 1097 1041 1060 1092 1088 1157 1045 1106 1084 1027 1068 1070 1037 1065 993 1088 1080 1111 1105 1041 1071 1062 1051 1027 1065 1035 1059 1052 1020 1101 1051 1109 1125 1049 1104 1139 1034 1133 1070 1071 1141 1119 1142 1222 1198 1211 1096 1241 1209 1302 1269 1309 1358 1379 1368 1364 1460 1493 1403 1409 1415 1404 1515 1433 1360 1361 1268 1294 1194 1197 1192 1150 1239 1154 1153 1088 1179 1135 1165 1119 1133 1168 1065 1101 1080 1076 1099 1096 1081 1128 1157 1130 1148 1179 1162 1094 1150 1204 1160 1198 1158 1197 1150 1220 1222 1218 1156 1216 1271 1301 1254 1230 1278 1266 1284 1385 1235 1321 1346 1362 1425 1504 1476 1524 1562 1487 1619 1611 1678 1696 1805 1850 1900 2000 2067 2133 2143 2370 2433 2530 2672 2807 2980 3106 3188 3396 3510 3770 3947 4074 4165 4603 4650 4864 5004 5126 5183 5369 5407 5475 5572 5613 5568 5404 5332 5246 5122 5159 4707 4541 4405 4056 4010 3816 3435 3280 3106 2980 2808 2705 2584 2570 2444 2327 2290 2258 2170 2154 2091 2140 2105 2081 2125 2241 2090 2268 2288 2344 2396 2504 2610 2791 2824 2871 3114 3255 3371 3615 3767 3921 4199 4378 4550 4836 5040 5218 5385 5864 6082 6295 6466 6586 6760 6801 6746 6904 6888 6893 6730 6509 6321 6216 5956 5618 5309 4973 4697 4337 4130 3732 3626 3265 3030 2715 2686 2500 2411 2227 2132 2046 1949 1760 1776 1725 1741 1589 1551 1555 1538 1465 1428 1396 1357 1354 1330 1338 1241 1247 1289 1232 1260 1286 1229 1202 1232 1188 1191 1180 1155 1099 1131 1136 1150 1067 1098 1065 1089 1133 1061 1053 1095 1050 1107 1042 1089 1081 1055 1025 1022 1032 1056 1087 1056 1069 1076 1051 1039 1058 1045 1057 1070 991 1036 991 947 1072 1024 1035 1024 985 1035 1031 1032 985 1049 1026 1001 1000 975 1048 1000 1005 978 1023 1055 974 1021 1079 956 1079 1026 995 1005 1079 990 997 1006 1015 1004 962 951 992 972 956 1038 984 954 973 988 899 931 1015 1020 1052 1034 973 978 959 965 962 1044 898 929 972 1028 1019 977 967 970 935 964 959 950 916 974 1004 981 1005 1017 961 974 1022 982 946 1034 904 1010 905 960 947 963 925 997 1030 934 1009 999 952 1024 966 921 992 928 968 1000 1000 957 1002 914 955 940 928 974 997 924 946 1009 942 981 930 994 979 995 982 969 966 924 1053 980 961 931 966 963 922 973 978 952 969 1004 943 934 1012 937 1012 1037 990 999 960 998 1032 980 1015 1014 956 1028 1013 975 1035 1009 1011 953 1040 1008 1011 1023 1022 1060 1097 1119 1033 1059 1052 1048 1088 1088 1077 1134 1085 1114 1126 1236 1254 1223 1259 1286 1271 1388 1297 1431 1408 1523 1507 1502 1560 1537 1551 1589 1630 1694 1754 1679 1791 1764 1745 1745 1791 1739 1912 1872 1981 2003 2015 2105 2122 2263 2357 2516 2509 2628 2680 2827 2908 2940 3145 3095 3231 3088 3237 3084 2861 2948 2873 2728 2698 2673 2569 2558 2402 2476 2383 2354 2351 2331 2320 2351 2388 2339 2269 2260 2150 2371 2151 2180 2172 2025 1932 1908 1955 1857 1765 1864 1596 1621 1554 1470 1447 1388 1328 1269 1264 1287 1235 1243 1219 1153 1151 1146 1124 1052 1089 1046 1046 940 1096 1018 1112 982 1012 988 996 1009 980 1002 978 944 1000 1004 945 1017 936 956 947 990 977 1022 1018 1015 1051 989 986 1034 992 1067 1001 1012 1042 1039 1069 1014 1034 1105 1091 1129 1058 1027 1069 1094 1041 994 1057 1030 1007 978 966 936 936 911 914 955 920 926 941 922 872 845 861 931 880 845 933 879 896 875 855 884 864 878 846 873 848 821 917 862 858 873 908 904 854 870 838 843 848 908 896 851 919 866 895 822 835 870 850 850 852 820 869 855 853 863 839 839 860 865 834 877 873 904 867 827 907 870 907 958 866 865 888 906 927 906 920 890 882 879 890 904 889 861 862 835 843 842 853 889 861 847 850 873 880 847 841 869 840 891 821 816 751 884 855 866 796 840 813 861 868 835 854 841 811 814 888 827 858 820 882 868 904 798 858 853 794 854 818 798 842 841 812 857 886 837 814 842 864 866 792 894 872 853 843 866 857 829 829 841 839 919 851 846 970 845 914 906 917 930 932 1008 1041 988 1012 984 1015 1076 1013 1011 999 907 945 989 935 986 881 849 864 905 830 894 813 867 823 810 853 821 829 819 832 811 784 811 770 796 833 803 830 849 801 854 808 769 816 785 817 804 751 770 744 823 771 768 837 890 831 767 837 805 775 821 827 847 799 825 817 750 815 816 840 800 818 797 807 845 803 802 778 796 850 841 802 776 780 797 781 853 832 853 838 794 811 818 813 818 767 799 845 813 832 856 830 827 825 788 798 776 835 868 813 848 798 840 824 833 834 853 809 827 796 835 854 829 838 838 841 836 844 834 855 877 877 888 862 905 899 974 963 872 892 925 902 964 999 1011 1023 1114 1055 1103 1079 1100 1165 1124 1164 1204 1215 1246 1221 1291 1224 1247 1201 1267 1255 1236 1258 1212 1158 1179 1174 1155 1112 1104 1104 1080 1043 985 1008 958 953 939 917 987 955 821 903 919 895 854 841 854 890 896 821 892 853 809 821 771 882 781 764 830 814 789 767 827 820 811 789 840 791 824 794 814 831 769 828 771 802 768 814 760 774 788 802 779 809 780 770 819 790 750 787 788 779 760 769 754 774 788 775 781 776 787 784 783 767 751 825 841 770 825 825 790 769 774 769 823 806 819 823 833 857 836 837 824 826 836 850 888 828 867 880 966 912 877 958 947 922 966 984 1050 1055 1005 1135 1049 1102 1100 1157 1147 1083 1163 1144 1167 1120 1104 1026 1055 1020 995 1051 1019 959 944 884 910 855 875 888 858 862 851 833 791 794 865 776 846 753 780 829 773 782 849 762 817 837 774 819 761 759 815 836 754 830 832 826 793 813 790 804 850 780 808 838 794 812 804 799 788 770 786 825 768 770 772 772 835 792 802 804 778 780 820 780 826 790 779 841 863 821 753 793 733 842 795 774 745 807 836 794 753 790 857 790 821 822 845 821 868 837 833 781 840 835 844 846 820 770 864 824 805 815 866 839 853 822 880 825 868 841 796 853 818 862 876 908 901 957 894 932 928 906 956 950 942 975 967 921 981 998 975 1041 1080 1058 1070 1085 1117 1129 1130 1206 1277 1257 1266 1304 1393 1396 1460 1503 1551 1532 1574 1680 1813 1787 1871 2143 2191 2281 2379 2509 2639 2767 3001 3017 3295 3433 3572 3839 3924 4069 4300 4472 4593 4662 4871 4872 5007 4931 5093 5021 4971 4897 4870 4802 4481 4360 4289 4063 3855 3750 3609 3302 3243 3017 2836 2609 2488 2305 2255 2157 1986 1964 1860 1676 1567 1561 1511 1480 1445 1376 1323 1252 1298 1285 1243 1194 1200 1114 1083 1118 1065 1036 971 1027 978 1016 977 938 997 889 928 898 981 903 872 860 904 873 888 943 835 842 830 816 905 856 864 832 811 851 836 825 830 735 817 797 767 827 773 829 806 803 777 809 786 781 836 769 828 803 773 776 777 820 796 779 749 754 790 780 782 807 781 804 816 805 773 760 762 767 832 782 767 805 789 801 755 770 742 770 791 760 827 792 844 812 798 768 795 766 805 805 747 791 845 784 856 806 760 820 866 783 833 854 815 898 876 831 881 863 898 903 985 943 967 1042 1041 995 1082 1117 1162 1221 1234 1227 1272 1309 1234 1248 1253 1338 1281 1234 1243 1234 1156 1227 1186 1184 1157 1108 1083 1070 1053 1039 1010 950 899 1001 880 872 884 827 839 837 877 830 807 778 820 843 904 823 797 890 845 837 827 793 824 812 853 848 861 863 847 878 874 897 905 913 901 919 903 1013 993 989 1010 1051 1019 1041 1115 1066 1125 1158 1198 1247 1252 1304 1273 1246 1330 1355 1433 1380 1445 1484 1487 1452 1473 1516 1508 1573 1593 1489 1479 1476 1480 1499 1370 1396 1346 1365 1266 1309 1243 1276 1221 1136 1187 1124 980 1073 1026 954 996 987 927 911 931 938 915 803 868 802 845 791 874 811 828 813 819 795 798 815 771 771 764 771 751 777 765 764 719 774 752 774 755 705 691 739 731 785 742 721 763 691 773 747 760 743 704 742 737 759 782 724 757 756 727 734 795 721 727 691 746 746 744 721 703 750 732 734 752 684 703 771 650 716 732 727 747 701 719 701 710 728 734 730 753 722 733 685 711 700 717 705 774 731 720 659 652 690 738 723 728 708 714 734 716 702 719 776 697 725 761 708 710 724 613 735 739 725 704 745 669 702 735 693 695 709 742 704 689 695 698 700 691 724 730 712 720 695 691 690 668 672 692 717 694 734 683 655 701 683 726 744 699 697 689 733 648 693 679 732 684 718 714 710 718 727 701 726 763 718 693 728 680 706 714 750 707 662 712 748 696 699 693 706 704 706 722 704 704 707 694 707 657 712 724 675 705 732 706 693 724 722 706 707 693 776 757 725 681 666 762 731 740 759 743 778 737 784 739 778 811 792 818 846 849 853 868 906 993 885 958 948 1003 1024 1003 1034 1067 1091 1052 1105 1090 996 1035 1030 1065 1034 1003 982 1002 954 974 936 923 978 894 821 896 846 830 832 846 822 810 842 898 785 798 820 784 788 781 812 799 785 798 817 867 834 777 780 841 814 749 787 801 806 755 744 807 719 700 737 746 757 734 695 703 741 695 730 675 704 708 699 699 700 678 699 698 707 741 706 707 698 690 692 708 729 681 658 648 687 681 682 715 686 710 680 684 716 651 730 690 671 731 696 694 657 717 693 702 763 698 671 683 717 700 723 653 682 689 690 698 724 703 714 705 721 681 711 715 755 742 735 713 707 709 727 713 729 729 677 777 690 711 742 724 707 698 709 742 689 732 787 707 725 751 760 779 798 720 808 755 813 872 807 810 832 808 811 833 873 865 819 981 952 970 1001 1044 1015 1058 1092 1130 1158 1188 1277 1239 1280 1295 1357 1314 1447 1366 1387 1440 1438 1412 1381 1380 1353 1419 1366 1311 1371 1308 1309 1307 1298 1193 1233 1193 1139 1186 1188 1131 1145 1168 1123 1139 1091 1126 1011 1017 1006 1019 1014 937 937 916 976 982 936 906 935 903 881 887 940 842 894 913 814 908 857 935 917 866 922 908 933 895 927 895 1019 924 1003 976 1062 1048 1020 1156 1069 1113 1054 1120 1169 1135 1240 1228 1306 1249 1258 1295 1324 1399 1458 1401 1485 1453 1512 1618 1670 1674 1792 1913 1872 1924 1993 2046 2215 2232 2262 2336 2351 2293 2533 2334 2632 2703 2648 2607 2632 2652 2538 2615 2613 2646 2700 2668 2644 2606 2562 2589 2619 2629 2812 2705 2713 2728 2843 2848 2984 3079 3152 3240 3359 3332 3563 3510 3741 3786 3834 4050 4156 4109 4151 4232 4164 4252 4269 4032 4186 4002 3972 3967 3821 3703 3658 3467 3373 3251 3170 3066 2855 2761 2772 2642 2456 2329 2310 2145 2039 1987 1971 1791 1790 1707 1694 1599 1576 1444 1442 1340 1321 1272 1313 1227 1165 1188 1153 1104 1059 1031 1020 1020 1074 972 958 988 935 1008 880 942 906 920 918 903 917 905 947 851 886 914 878 886 900 898 916 898 858 916 791 918 862 904 940 929 957 974 983 1010 924 998 976 998 976 958 1032 1032 983 998 978 1045 1051 1021 1000 1015 1026 1017 1040 1044 1102 1024 1043 1152 1129 1116 1144 1129 1152 1116 1173 1217 1132 1221 1237 1156 1144 1203 1201 1189 1195 1171 1139 1123 1092 1095 1098 1068 1090 1026 1037 1006 961 949 931 850 926 898 879 870 859 831 787 797 839 804 778 828 775 757 818 778 800 720 794 747 717 751 734 711 681 727 711 698 709 802 669 757 720 767 688 736 705 724 675 691 681 703 731 721 703 677 693 666 729 656 690 661 740 719 649 740 709 730 732 713 691 768 698 705 706 727 686 723 757 668 710 727 707 712 733 707 745 689 733 752 736 735 733 750 753 793 728 784 808 776 801 871 847 866 888 908 890 924 917 973 951 938 917 946 890 994 955 912 954 972 1075 968 1030 1062 1049 1102 1089 1083 1148 1152 1192 1170 1241 1209 1176 1248 1195 1273 1240 1305 1272 1259 1282 1265 1311 1374 1324 1310 1340 1276 1261 1274 1196 1177 1100 1156 1105 1146 1071 1022 1032 953 974 895 940 913 892 887 847 921 847 864 840 848 761 815 827 768 817 804 764 795 787 775 782 747 753 730 746 785 690 760 750 726 733 719 716 730 721 685 725 679 732 719 616 654 659 683 654 673 692 756 714 741 688 668 640 663 708 727 723 662 672 659 676 709 724 698 635 661 668 670 674 641 668 647 654 673 677 664 655 690 665 640 652 623 645 650 693 679 674 680 658 654 655 689 684 658 654 644 673 665 650 600 643 696 688 626 626 643 655 597 629 647 658 651 681 669 640 683 665 667 663 637 589 627 637 674 615 658 656 661 637 676 655 666 634 721 624 673 622 642 649 671 606 606 683 619 644 645 678 646 633 667 657 684 661 630 616 659 649 642 613 632 600 644 686 644 660 626 622 673 686 687 695 653 607 650 636 679 632 662 631 652 632 721 659 673 657 631 647 598 650 647 648 645 663 670 639 645 671 663 636 660 624 662 642 687 672 673 668 675 628 682 613 594 677 657 622 652 666 620 676 647 634 623 632 691 612 666 659 641 674 669 649 689 688 669 617 666 683 631 624 662 655 641 690 684 648 666 658 676 693 648 656 650 685 708 638 670 637 637 641 618 656 678 688 666 673 677 682 666 722 648 699 671 741 684 684 732 779 730 710 794 715 737 807 794 855 828 856 807 862 888 879 838 883 939 917 1034 951 964 939 1054 1023 1109 1167 1195 1219 1273 1273 1336 1440 1414 1396 1451 1417 1523 1577 1514 1537 1655 1568 1560 1574 1514 1393 1496 1502 1491 1373 1400 1394 1348 1322 1274 1243 1281 1225 1246 1181 1136 1071 1108 1040 1062 1031 1042 946 979 1009 959 885 922 896 912 901 877 917 804 888 837 799 770 852 796 816 766 833 756 852 810 821 815 818 818 746 773 808 831 820 843 811 732 790 842 839 862 860 832 865 855 895 903 930 893 967 926 931 948 979 957 1042 1077 1054 1108 1138 1149 1078 1111 1159 1118 1197 1209 1169 1091 1108 1173 1087 1111 1089 1126 1145 1138 1056 989 1003 1029 1044 982 937 930 961 919 944 878 846 867 861 879 824 840 782 783 796 791 716 757 670 764 759 770 668 722 690 678 681 687 661 696 689 716 663 644 657 634 641 641 663 648 630 645 665 684 638 672 628 715 622 635 664 601 634 668 638 640 672 627 641 648 605 644 662 621 649 636 666 628 645 662 665 658 642 679 644 664 663 654 609 644 633 667 632 655 622 648 712 710 706 674 672 633 668 669 645 723 664 669 671 690 656 669 678 681 727 748 759 803 732 728 775 742 795 763 833 786 856 799 841 867 852 833 860 876 840 853 828 901 890 856 865 839 886 801 822 829 799 824 835 849 816 786 840 751 773 773 736 736 807 780 740 735 688 733 707 703 694 691 690 688 749 642 644 643 751 692 661 669 682 685 716 693 674 741 681 637 712 712 682 658 711 698 702 705 738 745 706 745 737 796 803 729 785 800 845 788 813 819 829 874 851 848 877 851 880 828 849 929 921 909 924 965 871 892 955 908 887 843 909 985 967 920 903 920 906 901 916 895 917 853 859 883 956 900 891 930 900 863 831 827 823 794 788 798 754 769 734 735 725 668 686 745 761 738 657 726 684 723 673 681 684 610 675 662 682 648 660 642 665 622 658 665 628 612 597 632 645 635 622 634 663 620 635 636 618 630 641 620 669 619 651 653 685 615 644 684 699 653 662 665 667 666 716 667 626 668 702 673 743 741 706 761 710 680 730 803 772 794 810 800 787 837 794 767 867 839 824 781 816 798 809 810 796 803 773 759 745 744 727 766 708 667 685 726 716 694 645 716 746 671 682 677 690 627 665 680 648 668 637 625 623 627 626 667 644 624 645 617 629 620 621 594 613 574 621 573 641 617 642 582 636 589 582 622 613 612 613 598 611 553 589 599 562 539 585 602 610 583 617 623 618 621 612 612 653 597 624 603 632 594 640 581 610 655 683 601 633 598 658 620 673 654 696 729 709 676 699 704 711 656 660 673 641 667 682 616 636 605 641 676 694 647 642 658 649 599 663 644 622 653 614 639 631 590 591 620 615 581 569 614 617 657 635 594 642 605 629 607 583 566 621 569 601 591 614 613 608 595 566 599 623 551 630 598 569 617 601 589 647 548 607 630 629 562 585 602 570 614 611 581 617 619 614 648 643 597 647 653 615 651 705 715 640 700 664 695 698 696 694 683 709 701 682 672 710 690 699 694 708 687 643 616 677 690 669 659 644 674 674 618 696 628 651 647 598 629 596 588 612 603 613 606 631 569 632 586 587 560 575 624 610 594 653 647 623 633 617 621 605 560 657 604 612 630 627 615 606 585 630 633 623 612 589 595 643 587 644 651 645 649 610 565 632 594 599 616 584 561 639 656 630 659 655 602 669 669 648 626 611 622 608 615 636 637 661 629 648 630 665 658 680 648 712 665 668 672 642 653 706 689 643 713 656 675 664 722 693 705 715 649 704 698 730 743 756 733 784 758 764 691 755 775 787 775 793 776 828 810 883 879 831 847 966 959 923 987 956 1067 985 1045 1046 1059 1099 1073 1163 1167 1136 1224 1216 1265 1277 1231 1305 1364 1320 1364 1339 1459 1370 1341 1434 1390 1426 1459 1474 1476 1380 1386 1374 1392 1391 1340 1391 1361 1269 1310 1276 1280 1311 1168 1243 1135 1165 1176 1170 1095 1122 1076 1071 1006 1018 985 1007 939 917 925 918 905 892 869 913 798 858 877 853 842 793 776 788 824 766 781 779 813 749 768 811 763 810 719 754 738 744 763 723 736 742 684 740 749 743 696 799 699 755 798 735 753 771 767 783 775 826 756 789 756 739 840 853 841 786 814 840 831 854 868 862 895 868 871 874 965 867 924 856 913 913 887 913 897 873 929 915 862 885 893 852 872 805 807 844 831 860 781 834 783 799 765 823 749 807 781 759 786 751 731 739 725 735 684 744 693 694 724 727 698 700 642 647 668 698 669 689 674 651 680 657 677 653 720 654 636 682 674 705 670 672 675 689 715 641 681 708 698 673 743 717 743 693 780 712 814 730 728 708 763 736 777 784 777 762 750 737 783 771 791 784 769 747 722 750 759 725 709 768 711 742 741 731 764 680 758 697 658 667 715 713 685 640 705 639 617 689 620 654 662 711 664 634 689 637 617 638 619 611 652 661 679 626 630 584 666 606 585 642 630 604 610 627 616 634 588 622 589 624 638 592 595 595 606 603 611 597 572 594 597 644 614 624 640 587 609 651 629 595 558 619 581 611 621 599 619 622 593 610 593 648 619 641 613 591 598 640 611 612 577 639 646 580 593 587 632 667 642 626 623 613 674 651 640 591 615 679 680 640 680 684 681 711 744 666 714 720 712 724 655 691 735 739 782 718 752 715 704 679 699 678 688 716 670 722 673 653 748 655 719 649 655 673 679 627 755 641 688 651 660 648 650 620 627 666 641 642 620 627 634 584 677 611 602 605 605 596 668 581 676 624 600 650 602 597 633 572 601 602 560 639 645 601 589 608 597 600 590 603 632 656 615 622 656 572 596 609 608 637 622 616 584 561 593 625 620 639 631 603 585 598 642 582 564 616 539 567 632 618 613 609 626 623 599 601 583 592 586 640 613 669 632 605 636 612 605 625 638 625 677 625 679 617 628 628 638 692 617 635 609 646 650 679 670 659 627 635 679 682 659 660 676 729 686 668 677 640 601 650 655 606 670 625 654 703 690 711 668 684 694 655 715 754 755 692 699 716 721 702 688 776 749 800 808 810 874 831 788 847 835 900 939 924 965 980 958 1012 1068 1083 1091 1133 1119 1172 1185 1165 1153 1184 1213 1274 1199 1165 1170 1186 1200 1169 1197 1160 1145 1136 1147 1117 1055 1161 1123 1099 1094 1006 961 1015 1019 943 1011 939 924 960 894 954 930 843 860 859 846 857 845 791 787 773 760 752 772 740 725 714 750 705 698 744 711 721 753 720 697 739 744 662 737 759 645 711 688 720 664 665 679 669 694 682 689 678 689 657 668 661 650 657 657 659 656 651 728 694 740 638 693 732 702 702 699 730 720 758 689 722 716 749 752 734 757 736 716 744 754 750 777 744 725 757 779 759 804 780 803 845 751 771 818 832 797 796 826 756 817 773 762 810 743 779 832 736 729 732 737 741 700 698 748 721 714 692 666 714 695 713 627 640 680 630 651 661 675 653 670 644 613 596 639 639 641 599 588 600 605 590 608 604 585 635 610 590 613 613 594 624 618 553 613 624 603 618 638 625 604 582 689 603 606 638 595 645 619 621 622 612 647 665 650 650 626 627 606 560 615 631 582 648 626 651 578 619 639 554 617 623 618 678 553 633 605 614 636 600 648 561 623 612 575 649 632 680 706 634 675 652 700 653 669 638 669 654 723 694 678 706 704 701 639 692 664 700 634 631 656 662 682 657 655 663 632 692 751 655 643 713 691 696 683 686 694 694 622 709 706 661 720 700 733 668 746 738 759 762 709 735 657 708 739 709 710 709 742 734 717 688 680 687 718 708 736 740 694 722 640 683 694 690 666 686 654 672 678 657 643 627 620 640 574 643 632 607 611 666 614 655 651 590 617 602 609 606 627 585 611 635 642 574 634 583 632 595 603 570 543 594 569 616 611 583 603 600 545 588 619 607 577 612 571 592 624 590 556 558 606 555 532 576 582 594 574 601 569 634 566 592 564 553 582 616 561 546 547 555 592 604 592 560 542 583 617 575 604 604 589 596 589 582 555 586 566 585 597 564 545 563 607 602 545 584 609 599 581 559 601 565 612 547 576 568 578 583 574 580 608 623 546 604 582 600 621 563 591 626 627 606 594 607 606 630 623 635 631 658 591 591 595 600 610 618 641 653 610 622 674 586 638 616 636 590 661 628 615 562 615 647 593 615 623 643 604 636 602 593 605 584 604 640 590 601 602 608 598 604 627 581 589 593 611 594 613 650 564 595 584 590 620 616 569 572 618 555 573 654 579 641 590 602 627 567 620 606 575 639 603 595 585 600 578 609 644 609 637 609 599 602 606 629 594 607 652 630 660 664 689 643 644 638 656 634 695 690 703 684 693 662 656 734 748 731 750 742 770 757 790 792 766 846 785 790 798 854 825 844 847 884 884 891 880 915 925 917 864 917 892 959 898 929 881 914 939 919 914 874 939 905 881 885 933 894 896 960 902 914 890 884 931 926 860 991 894 988 913 954 894 952 956 903 936 966 933 966 920 924 937 944 1019 944 966 939 959 984 914 894 895 897 924 903 970 884 876 869 890 856 903 838 858 785 881 844 902 821 861 822 847 863 810 820 871 879 817 803 819 822 865 816 813 839 836 837 843 823 778 797 824 896 821 844 835 886 872 903 918 961 951 953 928 973 1002 984 976 1057 1039 996 1035 1016 1060 1021 1131 1044 1129 1122 1147 1163 1173 1133 1205 1193 1243 1269 1292 1204 1248 1243 1313 1283 1261 1350 1292 1295 1377 1366 1395 1369 1369 1314 1340 1306 1383 1371 1354 1354 1408 1364 1396 1331 1362 1333 1292 1371 1312 1313 1307 1248 1304 1220 1317 1255 1212 1215 1161 1229 1198 1180 1178 1199 1119 1149 1170 1106 1134 1088 1048 1024 1015 955 1035 984 974 931 975 883 921 974 863 867 920 842 858 860 875 866 853 871 855 855 827 790 822 786 824 831 787 832 766 780 826 828 753 816 784 729 764 790 778 768 750 740 718 768 753 761 800 749 775 762 734 760 779 747 781 865 727 788 746 791 803 793 789 759 755 747 768 740 752 738 669 721 728 775 698 725 754 658 717 739 712 695 695 677 718 667 663 691 674 690 680 669 639 662 674 684 643 655 659 671 648 606 631 654 605 625 661 565 654 626 570 575 624 567 591 607 609 607 606 605 636 573 610 562 619 564 612 611 597 623 607 567 547 621 578 590 577 595 592 578 588 565 547 570 572 583 566 581 582 580 622 582 615 614 567 541 562 593 579 587 599 628 583 598 591 571 589 587 555 579 571 584 578 636 549 561 616 611 586 622 595 605 579 596 563 594 584 621 607 614 609 589 590 601 609 599 594 549 577 542 635 666 561 571 587 581 594 605 602 582 575 527 573 563 571 535 551 586 593 583 600 573 597 573 550 604 600 606 566 583 602 623 534 586 593 583 570 619 574 537 559 504 609 525 553 582 594 578 609 584 583 548 603 553 555 544 579 548 569 571 600 559 579 594 552 505 553 535 513 538 558 577 580 568 543 591 591 578 533 585 561 590 573 550 537 555 592 595 531 571 563 536 593 561 578 576 551 540 563 592 562 554 531 545 564 528 614 549 587 598 558 562 557 540 549 562 592 544 599 574 605 586 584 573 574 580 583 554 594 559 562 589 533 540 540 572 603 512 545 628 558 573 587 605 581 596 556 589 556 559 649 587 579 533 583 611 563 589 575 647 586 630 553 586 578 634 570 599 608 557 591 596 658 617 608 618 580 668 634 629 622 619 625 679 634 707 614 688 666 752 698 699 714 765 702 701 710 724 717 715 713 771 739 771 790 759 730 716 761 748 776 807 784 749 752 776 813 743 791 762 774 769 744 726 756 742 753 722 733 742 738 762 729 710 674 707 665 670 666 631 691 630 681 641 638 678 641 667 680 639 641 665 654 613 690 626 642 606 603 577 672 600 594 618 618 607 625 564 556 602 624 591 579 573 584 575 568 569 508 604 551 612 583 593 557 564 616 585 584 614 611 557 591 591 536 611 569 553 566 598 544 561 547 534 572 533 590 557 596 528 606 550 550 545 548 540 563 577 556 559 543 602 551 596 533 568 560 588 555 550 564 562 612 592 568 567 576 579 565 557 579 564 587 600 530 595 556 515 605 562 570 601 564 553 577 580 577 538 603 578 595 577 595 550 561 577 611 594 548 558 592 562 564 610 582 607 539 558 531 637 639 618 605 544 605 537 608 573 566 598 592 564 628 591 605 610 644 632 564 585 579 618 584 613 561 588 628 619 592 627 631 625 615 628 555 610 575 559 591 622 578 577 618 606 602 595 621 598 601 597 633 624 627 637 603 571 645 637 652 649 643 600 683 623 681 626 631 651 666 681 670 629 642 665 652 654 661 700 693 616 662 632 660 592 626 659 643 623 703 624 614 619 630 623 652 616 612 604 600 625 612 624 608 676 679 595 568 612 566 616 575 581 559 573 621 607 600 628 638 575 610 661 619 594 575 595 552 629 541 574 592 588 574 624 578 615 669 603 637 566 646 589 604 609 611 590 572 601 584 616 611 605 565 586 617 613 665 587 557 624 603 564 562 569 542 580 530 596 545 597 586 590 607 588 617 604 595 595 582 594 653 588 582 571 571 607 602 596 605 572 553 546 586 588 546 571 529 600 568 558 578 555 544 554 557 561 567 558 578 558 543 554 575 585 531 554 526 536 561 566 566 548 561 539 595 554 570 593 594 564 551 538 584 568 585 582 612 580 621 535 551 561 630 546 587 572 592 568 553 534 560 594 497 597 572 552 556 515 578 570 574 577 609 566 554 584 544 582 569 548 596 535 613 552 590 539 572 585 557 543 583 547 592 586 574 620 558 540 521 582 598 612 591 544 532 555 528 552 555 559 569 580 572 592 562 560 596 586 560 600 523 591 558 578 624 576 609 614 599 560 614 608 588 635 645 630 610 569 645 584 612 604 623 566 619 634 621 601 604 621 638 628 609 617 617 636 672 632 635 669 643 637 646 611 597 624 641 640 627 659 696 668 645 679 657 641 699 668 681 652 666 724 695 694 666 710 669 711 710 768 679 687 716 693 687 726 745 753 773 797 763 762 746 799 777 825 763 826 788 785 824 816 868 828 838 867 833 868 854 880 861 858 894 880 912 888 953 895 918 891 903 867 873 882 862 880 887 857 861 817 908 826 854 832 829 789 901 843 755 818 841 842 751 823 786 853 743 734 779 758 772 719 731 742 697 694 694 692 647 707 676 673 695 671 635 657 692 685 656 647 689 655 664 664 647 642 647 668 617 646 659 643 628 666 627 646 644 628 630 665 623 672 626 678 578 634 662 671 629 703 631 657 616 679 620 654 710 677 633 707 688 661 642 744 672 742 725 710 706 668 684 768 684 683 697 671 693 720 714 698 731 742 726 735 759 759 798 706 739 759 772 772 767 698 717 738 771 790 754 743 749 719 811 776 730 756 777 782 778 751 779 779 806 799 769 786 727 756 759 743 790 756 772 757 738 739 793 756 750 772 773 774 717 794 689 770 779 787 704 726 672 685 790 690 743 726 697 658 723 747 758 674 731 743 731 675 718 693 741 605 633 675 688 685 668 650 654 655 654 676 630 644 718 644 623 697 678 686 655 622 658 655 672 668 666 647 656 664 657 702 656 664 668 639 635 663 666 630 681 643 620 638 666 677 670 672 661 706 678 682 679 617 638 661 660 659 636 663 619 666 681 673 676 631 653 616 616 590 625 639 631 667 606 631 566 579 642 656 639 624 620 627 621 593 601 629 598 637 569 606 607 637 585 585 660 581 634 593 653 587 605 598 631 627 634 613 589 579 586 617 573 581 554 622 552 635 622 598 568 619 588 608 615 611 575 604 633 622 583 585 592 583 556 600 578 580 603 564 585 658 575 576 574 594 560 605 607 600 578 564 562 603 553 613 614 624 630 600 586 548 578 584 592 591 578 599 561 575 550 552 556 543 534 605 559 588 557 543 586 622 595 608 577 617 596 568 573 597 561 572 541 591 577 566 553 549 606 540 568 566 512 571 547 618 566 606 553 563 549 608 567 585 519 532 528 557 631 566 606 527 596 592 574 554 532 570 615 657 555 597 564 558 545 561 602 529 547 576 560 555 590 587 606 564 595 579 596 580 538 580 598 553 591 572 551 607 557 545 583 554 556 600 578 591 587 602 539 601 589 559 584 602 567 584 546 584 624 541 563 617 564 550 562 586 565 525 577 578 579 569 538 550 534 558 548 580 583 592 535 585 553 545 551 546 563 562 575 597 570 535 572 547 590 514 576 560 628 592 545 584 549 571 568 544 538 549 540 536 520 567 559 570 546 575 549 570 603 559 570 605 610 639 603 594 606 589 617 569 605 582 591 596 582 533 540 593 529 586 566 554 599 612 600 609 563 629 594 618 584 617 643 605 589 597 609 582 595 623 575 576 612 626 615 620 628 648 627 658 635 681 684 700 660 676 626 635 673 672 707 644 667 670 692 699 714 722 713 669 719 741 734 755 737 745 699 773 765 714 812 724 788 793 843 774 793 814 827 812 836 880 840 898 902 871 865 876 904 884 865 958 858 876 849 885 881 883 884 866 837 876 898 843 838 849 893 849 879 851 893 833 831 824 833 810 889 781 766 843 833 812 784 815 776 755 790 717 801 746 735 754 775 755 711 721 738 725 742 757 735 715 701 689 725 735 725 747 707 685 726 684 672 739 681 701 678 700 734 725 714 738 705 739 733 709 733 692 736 717 724 754 717 743 712 678 716 758 726 741 817 742 737 755 791 798 780 768 774 768 818 748 754 769 772 774 796 764 801 785 800 735 811 790 859 747 786 797 768 831 822 758 798 680 754 794 763 841 765 797 772 759 741 781 720 743 713 790 717 695 731 707 695 706 732 716 705 736 692 722 663 600 679 670 706 704 630 656 662 581 661 653 639 632 592 636 640 621 693 606 579 647 646 663 614 584 594 622 615 615 614 622 624 601 581 585 598 603 579 604 601 558 574 579 612 580 641 592 582 610 602 620 599 604 566 574 571 591 619 607 607 536 589 634 588 573 573 615 580 578 573 588 606 564 596 591 633 601 573 564 598 611 592 610 571 547 606 564 609 569 632 605 603 606 575 554 574 614 602 589 589 606 595 627 613 591 562 562 614 581 565 573 572 581 558 572 542 576 591 490 583 566 579 549 617 596 583 576 575 604 583 574 618 571 600 573 605 634 549 602 551 591 637 617 600 585 571 558 576 584 595 585 607 568 576 618 608 564 565 600 562 595 541 627 583 571 586 537 578 585 589 596 572 581 576 607 565 523 592 584 593 567 561 542 553 597 544 557 571 617 565 556 566 581 574 545 579 627 571 601 569 587 592 591 581 589 609 583 556 567 564 605 611 591 589 608 586 583 592 599 584 571 597 615 572 628 568 620 598 607 602 596 587 569 570 589 611 633 562 557 567 606 569 587 599 663 583 562 575 591 604 544</counts>
			</dataPoints>
		</scan>
	</xrdMeasurement>
</xrdMeasurements>