File: dataset/precursor_mixture/V2O5_Cr2O3_Y2O3_LiCoO2.2-min.xrdml
<?xml version="1.0"?>
<xrdMeasurements xmlns="http://www.xrdml.com/XRDMeasurement/2.2" xmlns:xsi="http://www.w3.org/2001/XMLSchema-instance" xsi:schemaLocation="http://www.xrdml.com/XRDMeasurement/2.2 http://www.xrdml.com/XRDMeasurement/2.2/XRDMeasurement.xsd" status="Completed" recordIdentifier="{9BA5DDB9-5525-47A7-BBD5-0B25F8C7D71E}">
	<comment>
		<entry/>
	</comment>
	<sample type="To be analyzed">
		<id>dara-26-1</id>
		<name></name>
		<preparedBy></preparedBy>
	</sample>
	<xrdMeasurement measurementType="Scan" status="Completed" sampleMode="Reflection">
		<usedWavelength intended="K-Alpha 1">
			<kAlpha1 unit="Angstrom">1.5405980</kAlpha1>
			<kAlpha2 unit="Angstrom">1.5444260</kAlpha2>
			<kBeta unit="Angstrom">1.3922500</kBeta>
			<ratioKAlpha2KAlpha1>0.5000</ratioKAlpha2KAlpha1>
		</usedWavelength>
		<incidentBeamPath>
			<radius unit="mm">145.00</radius>
			<xRayTube id="1010048" name="Empyrean Cu LFF HR (9430 033 7310x) DK430614">
				<tension unit="kV">40.0</tension>
				<current unit="mA">15.0</current>
				<anodeMaterial>Cu</anodeMaterial>
				<focus type="Line">
					<length unit="mm">12.0</length>
					<width unit="mm">0.4</width>
					<takeOffAngle unit="deg">6.0</takeOffAngle>
				</focus>
			</xRayTube>
			<filter id="20010004" name="Beta-filter Nickel">
				<material>Ni</material>
				<thickness unit="mm">0.020</thickness>
			</filter>
			<sollerSlit id="21010002" name="Soller slits 0.04 rad.">
				<opening unit="rad">0.0400</opening>
			</sollerSlit>
			<mask id="22031000" name="Fixed mask 13 mm">
				<width unit="mm">9.00</width>
			</mask>
			<divergenceSlit id="22120001" name="Divergence slit 1°" xsi:type="fixedDivergenceSlitType">
				<distanceToSample unit="mm">50.00</distanceToSample>
				<height unit="mm">1.52</height>
			</divergenceSlit>
		</incidentBeamPath>
		<beamKnife id="29030100" name="Beam knife low"/>
		<sampleMovement xsi:type="spinningSampleMovementType">
			<spinnerRevolutionTime unit="seconds">1.0</spinnerRevolutionTime>
		</sampleMovement>
		<diffractedBeamPath>
			<radius unit="mm">145.00</radius>
			<antiScatterSlit id="22090040" name="AS slit 9 mm" xsi:type="fixedAntiScatterSlitType">
				<height unit="mm">9.00</height>
			</antiScatterSlit>
			<sollerSlit id="21020003" name="Large Soller slits 0.04 rad.">
				<opening unit="rad">0.0400</opening>
			</sollerSlit>
			<filter id="20030001" name="Large beta-filter Nickel">
				<material>Ni</material>
				<thickness unit="mm">0.020</thickness>
			</filter>
			<detector id="7010019" name="PIXcel1D-Medipix3 detector" xsi:type="rtmsDetectorType">
				<phd unit="keV">
					<lowerLevel>4.0</lowerLevel>
					<upperLevel>11.3</upperLevel>
				</phd>
				<mode>Scanning</mode>
				<activeLength unit="deg">1.021</activeLength>
			</detector>
		</diffractedBeamPath>
		<scan appendNumber="0" mode="Continuous" scanAxis="Gonio" status="Completed">
			<header>
				<startTimeStamp>2024-02-18T13:07:47-08:00</startTimeStamp>
				<endTimeStamp>2024-02-18T13:10:09-08:00</endTimeStamp>
				<author>
					<name>AutomatedUser</name>
				</author>
				<source>
					<applicationSoftware version="1.4b (28)">PANalytical Aeris Instrument Suite</applicationSoftware>
					<instrumentControlSoftware version="2.0.0 20210224">AERIS</instrumentControlSoftware>
					<instrumentID>950485</instrumentID>
				</source>
			</header>
			<dataPoints>
				<positions axis="2Theta" unit="deg">
					<startPosition>10.02173288</startPosition>
					<endPosition>139.98435528</endPosition>
				</positions>
				<positions axis="Omega" unit="deg">
					<startPosition>5.01086644</startPosition>
					<endPosition>69.99217764</endPosition>
				</positions>
				<commonCountingTime unit="seconds">1.551</commonCountingTime>
				<counts unit="counts">624 601 635 556 586 606 590 567 611 561 582 607 576 576 519 579 578 548 501 534 586 570 558 573 570 591 555 558 557 584 591 569 510 520 564 567 591 566 540 564 589 495 558 540 513 507 476 553 534 547 522 545 499 550 532 538 540 545 489 521 518 541 504 518 528 563 504 565 497 523 491 562 558 520 554 530 537 561 525 532 563 550 544 538 527 508 535 566 536 494 548 526 531 525 504 556 570 582 561 529 582 544 525 509 479 517 548 524 566 545 530 477 528 520 506 527 549 530 602 575 612 633 629 543 523 519 576 489 589 496 456 523 510 499 556 531 517 508 487 530 566 463 516 522 508 505 487 504 507 491 552 552 519 501 544 508 492 498 570 555 522 526 548 525 507 539 538 497 501 501 548 497 569 526 539 516 566 513 528 484 545 512 547 529 558 579 523 575 575 574 642 593 642 705 697 798 885 1143 1637 2628 5467 10399 8172 2989 892 690 738 646 628 589 592 591 554 519 560 575 551 556 525 528 579 556 587 574 552 568 605 626 622 717 764 898 922 775 745 773 788 745 659 642 584 607 595 606 569 570 590 532 581 552 562 532 514 525 570 539 520 525 584 524 548 550 597 620 597 546 592 562 547 570 585 516 508 504 546 510 564 525 456 492 509 550 519 546 537 517 493 485 523 498 548 521 501 509 525 531 544 566 491 502 473 543 469 523 525 556 544 518 523 486 469 496 513 487 495 506 517 523 493 553 533 535 574 571 624 701 803 766 654 563 519 508 546 484 558 500 505 501 566 483 506 492 513 487 525 506 509 524 475 504 483 516 520 465 485 544 505 514 504 550 512 540 636 627 684 651 506 551 509 495 468 463 459 465 523 484 511 536 498 494 478 520 464 502 527 439 489 523 509 474 440 443 484 504 512 481 457 477 487 459 504 522 533 497 477 486 512 474 484 461 464 479 471 483 505 481 515 490 467 439 548 556 509 552 541 589 664 754 1005 1372 1956 2488 2028 1545 985 753 582 563 536 515 554 538 495 463 498 492 518 488 477 480 532 512 441 429 513 487 465 500 499 471 464 434 445 476 439 483 482 474 520 513 521 518 565 604 598 598 521 499 479 445 485 480 494 474 496 495 442 439 439 495 435 463 499 493 539 442 463 444 500 468 454 485 491 557 519 522 492 484 496 488 487 471 432 451 464 474 463 463 501 442 499 463 495 426 515 505 559 544 531 619 821 903 959 922 870 932 832 768 621 550 490 503 525 514 492 502 542 512 503 516 557 484 491 424 450 432 439 445 485 444 492 517 473 432 443 477 505 475 451 421 417 459 471 432 437 437 468 447 439 468 458 550 523 585 555 508 547 564 621 753 824 717 691 560 496 489 473 522 429 444 453 473 410 463 455 444 463 457 439 436 481 482 481 454 520 548 548 607 516 513 476 493 486 474 462 441 498 462 482 471 457 494 407 472 442 438 462 497 649 932 955 714 713 509 445 470 430 457 465 489 425 438 431 468 490 450 523 444 477 482 472 433 447 427 470 447 452 430 483 549 509 593 585 506 522 504 464 431 454 429 420 453 430 429 438 459 462 474 433 428 437 424 452 437 490 414 435 430 450 441 449 454 484 497 482 516 524 555 540 540 540 510 480 502 489 437 431 467 445 458 443 439 460 423 470 434 450 440 457 446 413 420 454 461 422 420 423 454 422 441 406 463 462 421 439 426 471 428 429 416 414 470 525 553 580 560 577 464 441 448 457 475 418 429 443 506 482 490 453 460 455 439 434 435 461 458 429 439 450 423 414 447 452 429 426 423 435 426 449 490 506 508 718 777 634 619 573 513 470 467 451 478 447 458 462 415 442 442 449 458 433 444 426 422 432 382 396 417 445 456 471 401 457 398 436 415 427 447 425 463 493 454 469 490 425 411 418 430 431 466 529 481 471 419 444 446 440 437 490 457 449 475 449 518 488 494 433 465 428 439 472 485 486 548 601 677 1000 1130 932 859 843 660 569 495 553 503 490 515 426 453 430 458 465 455 439 465 448 468 489 496 450 426 478 421 482 426 492 442 415 452 488 447 470 485 549 608 570 513 548 499 425 448 464 450 438 410 430 433 488 431 459 421 417 418 454 468 455 447 510 432 458 480 461 430 456 411 411 448 454 433 463 426 448 439 409 421 466 439 445 437 427 436 439 415 443 433 467 432 435 429 408 466 438 448 424 404 466 452 419 489 451 466 522 495 475 487 462 496 413 397 479 398 435 440 453 411 421 463 448 449 408 405 463 428 399 435 458 402 419 418 443 438 416 458 465 503 493 509 606 789 686 593 607 592 486 459 520 463 482 490 424 444 424 459 420 445 453 466 427 465 426 402 423 433 449 477 423 477 472 475 507 491 467 484 462 417 411 411 446 417 416 445 428 432 428 435 425 430 449 437 461 445 435 416 410 445 465 444 477 553 656 870 812 669 668 685 590 509 471 460 437 400 476 459 480 458 417 451 453 430 474 422 438 447 476 446 439 407 440 442 475 456 502 564 573 548 699 534 472 515 529 419 423 459 446 470 464 488 457 445 509 455 436 411 421 437 425 449 440 409 377 436 451 422 474 538 462 468 484 474 461 437 440 478 421 412 407 441 435 448 457 410 415 425 426 445 442 442 423 417 446 420 411 395 492 440 492 458 436 408 462 464 446 475 397 430 406 406 434 419 455 388 418 389 474 408 405 425 412 399 393 450 436 453 419 404 459 466 455 439 447 494 515 507 508 469 445 497 456 432 444 450 445 380 407 389 405 454 446 408 461 432 405 441 426 433 460 520 520 469 451 440 459 423 428 418 432 464 500 490 529 564 527 510 475 464 506 534 525 472 499 490 475 503 416 388 454 455 415 466 478 461 457 408 435 426 436 469 474 470 451 425 447 425 408 429 433 418 425 408 411 429 418 458 430 440 434 399 441 446 431 415 395 412 393 444 432 423 392 454 383 401 407 451 447 455 436 417 407 420 400 444 420 400 394 446 440 386 407 413 425 433 425 404 399 414 424 443 408 386 434 441 452 442 382 440 404 410 390 436 396 422 457 473 493 478 453 446 462 457 437 389 445 417 448 439 446 409 442 414 392 393 420 419 469 432 362 402 422 448 454 424 429 454 472 441 412 435 434 468 433 401 406 439 455 420 432 412 404 427 407 444 436 430 449 404 378 468 453 428 425 464 445 462 475 443 432 461 467 465 474 418 459 435 454 417 471 451 427 460 423 443 416 474 443 459 417 427 437 407 432 464 415 409 394 435 415 390 418 421 395 411 436 394 410 422 409 433 424 407 407 452 366 418 411 437 448 407 408 414 439 467 414 436 421 437 446 398 420 382 442 385 391 392 428 391 429 399 412 412 450 399 391 431 397 442 447 428 399 403 461 394 413 410 398 471 414 411 411 427 410 442 436 429 433 449 431 425 436 438 449 415 422 442 456 435 429 416 433 461 444 437 457 450 384 438 405 407 453 392 394 408 441 445 417 424 427 406 445 429 449 473 438 497 556 461 460 436 481 468 438 446 406 433 423 435 446 401 420 436 424 422 464 459 408 434 402 417 445 425 416 403 388 415 421 391 462 384 379 427 431 422 445 432 396 409 402 411 403 362 419 431 418 410 423 471 417 428 467 477 419 458 395 424 422 447 450 450 391 396 439 416 446 455 425 441 397 423 418 420 430 444 428 496 450 449 544 690 545 416 390 479 523 483 456 422 420 430 391 439 427 425 397 403 437 400 384 433 412 389 384 398 418 425 415 388 383 419 380 422 396 409 378 393 479 452 400 432 452 391 456 434 474 421 393 428 446 407 429 438 452 433 446 426 424 428 412 436 415 439 375 457 418 392 420 407 435 397 436 399 400 408 377 441 420 449 443 465 422 420 444 434 446 488 449 406 431 442 399 415 436 452 459 402 418 458 451 410 395 392 408 406 373 420 410 443 468 455 378 428 377 401 400 409 397 416 388 392 343 430 405 429 421 387 395 419 401 407 410 396 387 423 407 395 377 405 424 403 409 396 412 399 411 404 384 411 415 398 381 464 450 409 442 449 405 441 428 377 451 437 426 447 431 419 382 426 419 393 427 408 434 426 439 461 431 436 382 439 427 452 411 457 437 437 441 427 487 451 439 433 405 442 422 451 431 454 428 427 416 441 405 467 430 419 374 394 458 420 435 404 402 417 388 415 453 418 435 414 441 413 395 422 417 430 457 418 415 431 385 411 376 454 432 381 416 420 395 409 413 409 416 416 472 432 406 428 433 429 424 450 473 392 414 419 388 424 390 398 389 408 431 409 405 401 442 373 413 417 436 424 420 427 379 408 418 414 440 426 423 413 429 441 419 413 374 417 431 427 455 472 451 441 426 423 469 431 461 446 466 446 423 427 428 436 425 459 408 388 430 458 450 387 371 408 370 392 417 426 385 449 415 364 402 416 483 434 426 389 431 454 394 413 415 428 423 382 410 392 434 389 389 409 420 424 431 403 364 433 452 453 439 393 475 414 443 421 426 465 472 443 432 411 420 418 446 387 393 408 430 414 382 427 411 371 432 469 413 478 413 458 458 411 400 393 431 405 418 424 449 436 419 450 409 411 422 390 387 410 411 401 417 409 420 422 402 398 434 436 396 406 381 409 409 420 404 402 437 393 419 422 408 392 364 400 415 432 439 411 437 417 409 448 396 463 400 420 402 424 388 411 409 413 386 443 437 385 411 403 375 469 423 424 401 407 391 436 378 398 424 414 454 400 407 437 410 450 364 389 430 415 397 452 412 397 381 435 374 391 392 436 375 408 430 436 416 415 424 440 399 450 384 461 410 401 391 407 395 423 419 461 428 436 414 388 412 401 417 409 476 387 460 389 444 411 435 385 403 436 442 436 370 401 389 405 410 392 403 421 467 401 363 399 427 375 444 411 410 427 378 407 418 418 385 448 442 415 448 454 409 422 362 433 392 446 429 442 388 382 389 418 408 413 426 407 399 398 403 384 396 410 418 407 401 397 395 415 426 403 379 451 399 442 394 389 433 404 399 412 444 402 418 387 396 420 432 415 420 455 421 433 417 420 467 422 452 457 431 423 395 398 419 454 434 413 406 406 421 423 389 433 417 402 425 404 423 445 411 413 390 450 416 401 417 455 424 494 468 415 387 415 421 454 366 445 442 436 454 443 432 370 431 386 385 407 423 383 398 420 397 432 396 430 382 409 383 431 404 423 390 380 452 426 420 397 397 454 381 422 404 389 396 407 409 414 398 388 431 385 386 424 476 396 382 413 409 427 427 413 405 456 414 416 419 458 433 418 452 395 428 404 415 384 400 416 403 423 430 430 457 460 435 416 378 398 441 408 420 378 390 447 409 414 403 382 418 405 416 461 426 427 410 384 405 406 444 393 429 426 395 435 434 427 423 389 419 423 423 443 414 402 415 390 389 410 414 425 365 413 413 375 411 409 425 392 385 371 392 401 407 364 390 430 424 403 398 474 400 402 427 419 399 461 404 453 399 403 410 434 429 424 438 399 393 433 419 431 444 424 393 423 432 476 447 449 434 413 433 421 410 395 450 450 411 441 421 440 455 436 427 384 420 391 434 421 401 425 425 414 457 441 382 410 413 427 384 411 431 438 423 451 404 398 398 397 445 390 406 421 424 421 409 423 392 387 418 425 408 432 370 463 423 443 413 408 429 434 377 463 424 382 403 419 420 433 408 428 406 427 421 436 409 424 411 433 410 460 418 437 410 426 420 440 421 422 430 427 424 440 440 435 448 404 445 399 426 404 406 423 415 412 411 415 408 391 413 399 422 449 391 412 385 405 412 390 414 422 423 448 420 435 369 446 421 425 411 413 398 440 398 402 435 436 411 390 387 394 396 429 412 405 418 401 428 399 419 410 444 441 422 442 423 481 419 446 419 473 450 428 463 404 400 407 440 438 438 427 451 419 405 434 397 413 417 399 416 414 442 388 424 409 416 388 423 417 422 435 429 433 404 423 415 410 479 353 426 388 431 413 430 432 382 383 404 379 402 404 429 435 421 422 377 438 403 398 418 340 446 432 410 438 391 458 389 427 414 431 421 380 380 404 439 422 406 415 409 370 450 409 412 395 407 422 418 428 392 380 404 410 383 426 401 397 421 433 441 440 403 378 388 373 393 392 418 430 403 408 431 426 421 423 387 392 446 401 405 410 408 422 418 390 436 352 377 398 387 427 428 373 447 410 419 449 455 412 426 398 441 447 417 416 420 422 400 454 432 403 438 419 449 451 401 432 403 399 429 426 409 434 423 399 415 403 375 424 431 424 384 432 401 436 447 421 413 383 430 429 425 398 430 388 435 416 414 415 393 425 471 433 405 403 403 394 436 420 393 439 395 436 418 419 454 445 418 472 438 436 452 409 413 412 406 447 444 412 385 394 381 406 389 421 466 461 427 447 407 424 393 458 422 462 453 436 404 411 427 402 440 430 444 421 450 431 450 425 462 432 472 422 473 452 401 454 453 429 403 418 438 466 401 410 455 447 452 461 468 424 421 439 427 407 418 390 418 419 449 372 402 406 463 452 461 417 459 393 439 416 418 412 441 394 420 381 373 452 454 398 405 439 418 408 371 372 440 422 417 385 380 399 435 434 405 433 347 399 368 458 435 427 423 397 418 395 425 386 471 412 396 420 436 405 422 403 431 425 448 409 413 392 419 419 447 463 431 398 394 429 416 446 441 453 459 439 425 406 477 377 420 387 406 413 460 448 466 395 414 411 389 401 397 435 473 457 403 433 414 386 443 421 396 436 446</counts>
			</dataPoints>
		</scan>
	</xrdMeasurement>
</xrdMeasurements>