File: dataset/precursor_mixture/V2O5_0p4013-In2O3_0p4021-La(OH)3_0p2014--2min.xrdml
<?xml version="1.0"?>
<xrdMeasurements xmlns="http://www.xrdml.com/XRDMeasurement/2.3" xmlns:xsi="http://www.w3.org/2001/XMLSchema-instance" xsi:schemaLocation="http://www.xrdml.com/XRDMeasurement/2.3 http://www.xrdml.com/XRDMeasurement/2.3/XRDMeasurement.xsd" status="Completed" recordIdentifier="{E95B2788-E451-4A83-B0DD-F5EC15BF7FD6}">
	<comment>
		<entry/>
	</comment>
	<sample type="To be analyzed">
		<id>V2O5_0p4013-In2O3_0p4021-La(OH)3_0p2014--2min</id>
		<name></name>
		<preparedBy></preparedBy>
	</sample>
	<xrdMeasurement measurementType="Scan" status="Completed" sampleMode="Reflection">
		<usedWavelength intended="K-Alpha 1">
			<kAlpha1 unit="Angstrom">1.5405980</kAlpha1>
			<kAlpha2 unit="Angstrom">1.5444260</kAlpha2>
			<kBeta unit="Angstrom">1.3922500</kBeta>
			<ratioKAlpha2KAlpha1>0.5000</ratioKAlpha2KAlpha1>
		</usedWavelength>
		<incidentBeamPath>
			<radius unit="mm">145.00</radius>
			<xRayTube id="1010048" name="Empyrean Cu LFF HR (9430 033 7310x)">
				<tension unit="kV">40.0</tension>
				<current unit="mA">15.0</current>
				<anodeMaterial>Cu</anodeMaterial>
				<focus type="Line">
					<length unit="mm">12.0</length>
					<width unit="mm">0.4</width>
					<takeOffAngle unit="deg">6.0</takeOffAngle>
				</focus>
			</xRayTube>
			<sollerSlit id="21010002" name="Soller slits 0.04 rad.">
				<opening unit="rad">0.0400</opening>
			</sollerSlit>
			<mask id="22031000" name="Fixed mask 13 mm">
				<width unit="mm">9.00</width>
			</mask>
			<divergenceSlit id="22120001" name="Divergence slit 1°" xsi:type="fixedDivergenceSlitType">
				<distanceToSample unit="mm">50.00</distanceToSample>
				<height unit="mm">1.52</height>
			</divergenceSlit>
		</incidentBeamPath>
		<sampleMovement xsi:type="spinningSampleMovementType">
			<spinnerRevolutionTime unit="seconds">1.0</spinnerRevolutionTime>
		</sampleMovement>
		<diffractedBeamPath>
			<radius unit="mm">145.00</radius>
			<antiScatterSlit id="22090040" name="AS slit 9 mm (PIXcel)" xsi:type="fixedAntiScatterSlitType">
				<height unit="mm">9.00</height>
			</antiScatterSlit>
			<sollerSlit id="21020003" name="Large Soller slits 0.04 rad.">
				<opening unit="rad">0.0400</opening>
			</sollerSlit>
			<filter id="20030001" name="Large beta-filter Nickel">
				<material>Ni</material>
				<thickness unit="mm">0.020</thickness>
			</filter>
			<detector id="7010019" name="PIXcel1D-Medipix3 detector" xsi:type="rtmsDetectorType">
				<phd unit="keV">
					<lowerLevel>4.02</lowerLevel>
					<upperLevel>11.27</upperLevel>
				</phd>
				<mode>Scanning</mode>
				<activeLength unit="deg">5.542</activeLength>
			</detector>
		</diffractedBeamPath>
		<scan appendNumber="0" mode="Continuous" scanAxis="Gonio" status="Completed">
			<header>
				<startTimeStamp>2024-11-14T15:20:02-08:00</startTimeStamp>
				<endTimeStamp>2024-11-14T15:22:07-08:00</endTimeStamp>
				<author>
					<name>AutomatedUser</name>
				</author>
				<source>
					<applicationSoftware version="1.7b (136)">PANalytical Aeris Instrument Suite</applicationSoftware>
					<instrumentControlSoftware version="3.2.00000000 20240306">AERIS</instrumentControlSoftware>
					<instrumentID>950485</instrumentID>
				</source>
			</header>
			<dataPoints>
				<positions axis="2Theta" unit="deg">
					<startPosition>10.02173288</startPosition>
					<endPosition>99.99585608</endPosition>
				</positions>
				<positions axis="Omega" unit="deg">
					<startPosition>5.01086644</startPosition>
					<endPosition>49.99792804</endPosition>
				</positions>
				<commonCountingTime unit="seconds">10.965</commonCountingTime>
				<counts unit="counts">2045 2086 2060 2150 2017 1994 2002 1965 1947 1977 1977 1910 1946 1934 2035 1908 1926 1898 1950 1959 1922 1874 1866 1896 1873 1841 1759 1833 1853 1754 1824 1675 1773 1674 1706 1678 1677 1655 1695 1717 1718 1675 1634 1622 1645 1582 1616 1589 1550 1500 1549 1526 1588 1511 1605 1519 1576 1550 1540 1522 1527 1547 1527 1466 1490 1505 1458 1468 1354 1439 1506 1485 1462 1379 1485 1455 1451 1448 1434 1420 1501 1336 1467 1426 1338 1433 1397 1383 1406 1335 1380 1301 1277 1366 1335 1372 1406 1272 1396 1363 1327 1281 1360 1355 1351 1321 1372 1277 1291 1330 1287 1339 1316 1321 1400 1323 1408 1347 1331 1480 1567 1727 1768 1845 2064 2053 2079 2167 2230 2328 2306 2165 1845 1690 1585 1421 1348 1316 1276 1234 1252 1208 1253 1233 1155 1195 1135 1183 1173 1214 1183 1129 1137 1170 1170 1154 1164 1115 1156 1156 1226 1208 1111 1144 1122 1132 1177 1120 1188 1061 1070 1133 1125 1083 1097 1083 1125 1062 1127 1115 1087 1133 1075 1061 1095 1104 1062 1007 1060 1049 1075 1075 1103 1013 1105 1101 1025 1054 1061 1018 1072 1081 1036 1037 1012 1047 1033 1100 1048 1087 1020 1025 1069 1062 994 976 1018 1101 973 990 955 999 1082 1084 1063 1013 1081 1093 1011 1096 1204 1318 1491 1744 2045 2397 2416 2553 2312 1794 1456 1192 1135 1076 1024 974 1024 975 972 967 900 1014 951 934 984 1028 1003 1015 1023 1149 1201 1380 1528 1672 1893 1921 1713 1514 1472 1444 1388 1324 1237 1039 972 944 924 950 901 956 980 901 915 1024 925 898 849 919 866 938 855 924 896 869 922 845 851 899 831 858 835 807 850 834 807 787 830 836 819 783 879 793 852 829 852 846 792 773 843 825 777 789 792 729 837 774 822 796 825 792 789 799 780 786 787 822 763 815 770 778 777 798 746 718 740 760 760 792 794 737 782 806 801 799 807 813 850 847 820 822 874 841 827 794 841 835 942 1080 1193 1486 1648 1754 1885 1565 1263 992 796 828 788 769 720 765 763 782 803 782 822 802 879 892 978 1057 1143 1329 1458 1624 1835 1888 1744 1704 1561 1300 1172 1121 1057 1000 1085 1238 1308 1528 1847 2055 2243 2361 2238 2120 1794 1438 1233 1012 951 852 790 779 732 740 767 746 716 737 657 660 748 670 672 660 678 673 681 720 665 678 653 628 681 697 684 682 709 670 656 756 703 729 805 747 790 741 758 822 787 931 935 953 1083 1157 1326 1599 2172 3113 4583 6364 8401 10126 10114 7796 5318 3220 2052 1690 1725 1717 1773 1917 1905 1682 1288 1185 920 880 807 876 875 861 864 949 950 913 903 900 818 748 715 704 706 658 655 685 667 746 742 818 908 967 1038 1075 971 823 827 707 681 611 565 626 664 591 586 700 618 676 694 703 739 687 725 758 748 769 763 645 627 570 530 607 629 551 571 579 595 539 578 564 566 581 624 731 778 859 948 1038 979 846 773 704 565 613 587 601 580 603 559 574 582 664 598 661 643 758 717 773 899 1167 1530 2065 2749 3309 3396 2934 2075 1498 1093 903 752 774 735 738 744 733 747 729 671 628 596 601 608 581 552 465 488 544 514 503 488 498 481 548 542 565 494 490 520 507 512 518 503 546 558 497 576 550 590 630 602 677 765 808 928 987 960 816 689 608 548 485 555 543 459 505 513 479 423 485 500 447 500 451 524 502 465 493 499 541 485 499 510 530 594 589 583 611 709 748 816 999 1128 1346 1523 1647 1655 1643 1447 1242 1094 953 837 844 758 734 637 547 590 548 470 484 494 472 452 494 477 470 499 473 464 453 414 452 434 438 514 479 567 472 455 489 511 542 567 622 742 744 795 723 645 570 613 495 448 520 614 677 794 860 1011 1029 956 915 875 820 815 764 702 713 650 629 678 576 580 461 484 494 457 426 429 446 430 451 394 450 431 410 372 395 398 434 437 404 428 419 402 444 416 409 447 437 409 475 487 535 508 448 505 482 426 459 398 399 378 443 450 440 410 411 392 390 425 351 407 401 390 391 423 408 359 422 375 412 421 418 483 452 458 460 443 571 635 666 778 842 978 1134 1282 1368 1275 1047 942 724 550 509 449 482 460 428 388 390 346 410 421 425 423 452 415 420 452 414 404 404 473 439 515 488 571 598 619 691 706 675 693 810 840 821 735 742 652 578 553 499 557 540 611 687 724 718 739 718 801 728 857 873 917 923 1002 1001 937 1006 1040 1104 1239 1374 1436 1525 1510 1402 1347 1216 1138 936 852 723 666 635 616 654 662 764 705 680 601 640 592 552 501 534 519 539 518 476 550 546 588 566 557 554 522 476 483 492 446 473 471 437 476 485 492 538 568 617 668 697 819 1103 1456 2242 3162 3844 4043 3553 2942 2593 2093 1441 1096 914 787 699 596 549 582 500 479 493 469 437 386 437 496 532 529 596 530 497 493 498 418 405 399 424 429 409 437 411 528 560 627 552 537 532 513 452 416 403 362 392 366 390 346 358 356 334 333 386 391 365 318 362 351 397 397 393 386 390 381 376 359 330 330 367 390 367 385 422 424 377 423 363 407 395 388 327 369 343 374 378 370 401 416 439 417 511 549 592 595 675 679 649 616 593 591 596 616 654 572 509 586 555 541 701 770 928 904 818 749 737 718 613 576 617 606 547 537 471 440 432 409 380 360 380 369 399 373 387 372 351 340 368 314 366 376 337 354 349 380 387 392 471 506 478 507 460 441 450 412 431 452 390 395 416 430 355 358 392 389 380 391 410 450 438 428 463 451 510 502 463 502 496 535 535 603 679 707 842 837 798 722 667 627 498 438 413 397 369 371 379 421 320 364 388 379 418 379 419 409 434 458 466 426 501 508 608 542 593 699 837 1138 1701 2388 2904 2774 2138 1930 1754 1539 1075 762 755 689 690 670 604 534 547 509 435 404 398 402 385 396 347 352 344 378 400 386 378 413 477 500 724 867 1036 1053 956 900 769 689 638 457 435 376 357 333 354 321 320 377 346 338 335 366 354 315 336 335 357 329 387 364 413 376 399 453 554 621 745 905 817 713 783 787 739 725 684 616 550 560 595 534 541 458 499 464 460 424 465 462 448 484 391 412 418 411 396 386 406 470 441 527 629 659 604 542 473 534 466 444 353 366 350 364 356 330 341 337 351 366 341 335 370 429 414 413 413 381 331 377 381 366 318 350 358 412 385 431 357 365 375 373 340 320 344 312 313 331 288 324 323 319 314 335 299 322 317 316 290 330 311 317 388 415 358 418 429 456 556 600 526 554 485 449 496 458 441 418 385 348 371 347 376 299 316 340 338 380 400 407 383 355 370 375 394 387 381 342 370 405 472 506 482 545 573 587 612 628 617 567 509 514 513 480 412 428 384 361 363 387 404 384 389 395 357 391 382 356 355 335 347 354 339 379 368 335 384 365 338 340 311 328 305 311 321 324 299 320 337 262 276 298 330 341 319 332 359 334 365 341 359 325 329 323 336 364 374 393 378 378 365 366 397 378 365 425 432 406 457 382 405 401 353 372 353 336 316 300 321 289 336 281 293 294 343 332 378 372 518 467 504 432 379 373 409 378 363 323 326 344 311 308 300 340 337 342 368 391 396 421 406 380 381 417 371 391 365 367 404 514 586 613 554 494 448 498 453 427 402 376 330 336 365 332 354 388 369 377 353 357 421 457 474 460 483 437 435 499 510 534 587 662 714 705 618 514 508 565 569 440 444 424 383 360 398 386 423 463 407 490 457 520 536 555 559 604 569 604 538 536 592 593 574 666 616 626 475 521 519 502 449 410 397 373 392 427 405 396 374 396 377 336 337 338 376 369 335 319 325 302 331 368 359 426 446 487 504 389 366 397 445 390 342 298 307 273 290 291 292 298 258 280 313 254 277 281 308 292 304 302 292 272 311 336 346 385 433 379 357 327 353 335 347 325 272 295 275 308 290 300 272 288 311 286 303 291 306 320 330 282 277 314 366 363 418 464 612 595 566 430 404 406 419 453 425 372 380 365 366 386 389 349 404 346 360 340 363 358 354 370 352 374 389 414 441 577 676 865 878 683 583 575 555 613 601 531 429 367 347 324 323 287 295 328 337 334 285 331 313 270 281 281 324 282 294 336 281 308 297 291 311 307 327 288 303 337 300 311 342 343 311 314 332 336 288 327 312 323 302 310 358 346 381 349 348 408 424 517 649 728 694 542 513 439 504 536 504 412 361 352 298 315 302 262 329 331 273 314 312 306 292 312 371 320 319 292 326 297 295 374 353 341 322 316 328 326 292 308 267 298 283 273 291 260 342 289 302 275 315 317 292 307 290 311 295 298 360 364 370 444 462 474 438 443 424 489 448 444 434 399 357 363 357 329 322 323 324 337 348 333 342 322 303 301 320 290 327 331 376 430 518 502 477 437 443 426 482 445 407 406 352 357 350 370 381 334 344 305 367 360 333 330 365 373 311 368 344 289 343 349 309 319 304 358 295 288 341 283 303 296 262 313 311 319 291 256 302 294 288 258 297 314 280 286 302 307 300 329 330 347 419 499 461 449 391 328 351 336 397 415 388 342 369 341 322 325 306 306 274 284 290 302 317 307 319 295 298 309 285 280 295 271 276 260 278 263 242 302 265 276 320 300 292 315 286 279 297 300 282 310 303 309 292 304 306 291 267 327 304 344 384 412 475 540 532 505 373 413 409 404 527 503 473 419 427 424 434 396 413 375 405 388 379 387 342 377 362 374 371 382 415 472 570 646 735 609 536 446 476 452 558 546 557 458 467 397 390 352 377 390 335 339 312 299 316 303 319 331 329 307 311 330 362 449 477 477 458 366 339 296 346 386 396 387 359 362 347 271 321 301 325 306 289 284 282 276 256 284 280 293 281 307 303 336 384 390 464 394 336 367 338 325 328 352 367 360 312 362 357 344 316 288 269 294 277 316</counts>
			</dataPoints>
		</scan>
	</xrdMeasurement>
</xrdMeasurements>