File: dataset/precursor_mixture/V2O5_Fe3O4_Y2O3_CuO.12-min.xrdml
<?xml version="1.0"?>
<xrdMeasurements xmlns="http://www.xrdml.com/XRDMeasurement/2.2" xmlns:xsi="http://www.w3.org/2001/XMLSchema-instance" xsi:schemaLocation="http://www.xrdml.com/XRDMeasurement/2.2 http://www.xrdml.com/XRDMeasurement/2.2/XRDMeasurement.xsd" status="Completed" recordIdentifier="{7D4B38F0-8BD5-4E6A-84A2-28F3507F79C8}">
	<comment>
		<entry/>
	</comment>
	<sample type="To be analyzed">
		<id>dara-20-2</id>
		<name></name>
		<preparedBy></preparedBy>
	</sample>
	<xrdMeasurement measurementType="Scan" status="Completed" sampleMode="Reflection">
		<usedWavelength intended="K-Alpha 1">
			<kAlpha1 unit="Angstrom">1.5405980</kAlpha1>
			<kAlpha2 unit="Angstrom">1.5444260</kAlpha2>
			<kBeta unit="Angstrom">1.3922500</kBeta>
			<ratioKAlpha2KAlpha1>0.5000</ratioKAlpha2KAlpha1>
		</usedWavelength>
		<incidentBeamPath>
			<radius unit="mm">145.00</radius>
			<xRayTube id="1010048" name="Empyrean Cu LFF HR (9430 033 7310x) DK437873">
				<tension unit="kV">40.0</tension>
				<current unit="mA">15.0</current>
				<anodeMaterial>Cu</anodeMaterial>
				<focus type="Line">
					<length unit="mm">12.0</length>
					<width unit="mm">0.4</width>
					<takeOffAngle unit="deg">6.0</takeOffAngle>
				</focus>
			</xRayTube>
			<filter id="20010004" name="Beta-filter Nickel">
				<material>Ni</material>
				<thickness unit="mm">0.020</thickness>
			</filter>
			<sollerSlit id="21010002" name="Soller slits 0.04 rad.">
				<opening unit="rad">0.0400</opening>
			</sollerSlit>
			<mask id="22031000" name="Fixed mask 13 mm">
				<width unit="mm">9.00</width>
			</mask>
			<divergenceSlit id="22120001" name="Divergence slit 1°" xsi:type="fixedDivergenceSlitType">
				<distanceToSample unit="mm">50.00</distanceToSample>
				<height unit="mm">1.52</height>
			</divergenceSlit>
		</incidentBeamPath>
		<beamKnife id="29030100" name="Beam knife low"/>
		<sampleMovement xsi:type="spinningSampleMovementType">
			<spinnerRevolutionTime unit="seconds">1.0</spinnerRevolutionTime>
		</sampleMovement>
		<diffractedBeamPath>
			<radius unit="mm">145.00</radius>
			<antiScatterSlit id="22090040" name="AS slit 9 mm" xsi:type="fixedAntiScatterSlitType">
				<height unit="mm">9.00</height>
			</antiScatterSlit>
			<sollerSlit id="21020003" name="Large Soller slits 0.04 rad.">
				<opening unit="rad">0.0400</opening>
			</sollerSlit>
			<filter id="20030001" name="Large beta-filter Nickel">
				<material>Ni</material>
				<thickness unit="mm">0.020</thickness>
			</filter>
			<detector id="7010019" name="PIXcel1D-Medipix3 detector" xsi:type="rtmsDetectorType">
				<phd unit="keV">
					<lowerLevel>4.0</lowerLevel>
					<upperLevel>11.3</upperLevel>
				</phd>
				<mode>Scanning</mode>
				<activeLength unit="deg">5.020</activeLength>
			</detector>
		</diffractedBeamPath>
		<scan appendNumber="0" mode="Continuous" scanAxis="Gonio" status="Completed">
			<header>
				<startTimeStamp>2024-03-24T16:26:20-07:00</startTimeStamp>
				<endTimeStamp>2024-03-24T16:38:47-07:00</endTimeStamp>
				<author>
					<name>AutomatedUser</name>
				</author>
				<source>
					<applicationSoftware version="1.6 (94)">PANalytical Aeris Instrument Suite</applicationSoftware>
					<instrumentControlSoftware version="3.0.0 20211014">AERIS</instrumentControlSoftware>
					<instrumentID>2879380</instrumentID>
				</source>
			</header>
			<dataPoints>
				<positions axis="2Theta" unit="deg">
					<startPosition>9.99043322</startPosition>
					<endPosition>100.09495370</endPosition>
				</positions>
				<positions axis="Omega" unit="deg">
					<startPosition>4.99521661</startPosition>
					<endPosition>50.04747685</endPosition>
				</positions>
				<commonCountingTime unit="seconds">18.249</commonCountingTime>
				<counts unit="counts">5776 5772 5913 5870 5872 5719 5732 5643 5797 5836 5823 5736 5691 5849 5640 5694 5643 5783 5764 5812 5844 5801 5673 5701 5718 5838 5706 5680 5774 5828 5808 5579 5838 5638 5796 5838 5796 5716 5650 5598 5693 5796 5847 5556 5742 5584 5554 5672 5547 5648 5561 5544 5715 5607 5535 5646 5580 5808 5646 5590 5685 5647 5657 5667 5556 5474 5591 5701 5560 5637 5617 5628 5606 5618 5652 5571 5581 5632 5646 5563 5560 5608 5584 5615 5523 5595 5393 5540 5583 5612 5545 5589 5627 5444 5526 5584 5564 5437 5538 5547 5601 5417 5516 5507 5523 5484 5410 5551 5540 5361 5492 5541 5549 5502 5609 5462 5527 5411 5436 5377 5534 5591 5532 5520 5531 5566 5513 5556 5494 5510 5535 5425 5359 5502 5512 5500 5437 5460 5352 5302 5414 5394 5429 5314 5520 5502 5357 5446 5446 5450 5407 5354 5424 5331 5576 5377 5543 5509 5373 5473 5242 5424 5560 5401 5340 5493 5410 5385 5361 5499 5357 5293 5387 5231 5453 5316 5361 5251 5317 5422 5239 5321 5286 5370 5431 5341 5430 5358 5408 5324 5603 5243 5259 5384 5371 5335 5372 5499 5308 5469 5351 5338 5340 5441 5394 5315 5443 5197 5238 5363 5278 5244 5293 5252 5284 5359 5376 5349 5372 5258 5283 5449 5452 5346 5265 5401 5292 5310 5273 5208 5293 5355 5182 5163 5372 5298 5234 5259 5250 5313 5246 5212 5269 5370 5333 5291 5220 5271 5351 5195 5367 5218 5378 5277 5337 5284 5241 5186 5263 5060 5198 5228 5367 5324 5213 5305 5295 5197 5288 5281 5140 5246 5300 5295 5149 5268 5233 5289 5269 5233 5247 5306 5241 5208 5072 5257 5135 5288 5197 5297 5181 5286 5214 5090 5257 5151 5163 5252 5202 5138 5196 5170 5171 5152 5293 5243 5025 5159 5104 5193 5222 5232 5249 5232 5141 5375 5089 5094 5191 5165 5226 5249 5221 5277 5102 5217 5227 5152 5218 5233 5162 5195 5159 5299 5069 5172 5186 5069 5173 5295 5163 5142 5208 5245 5273 5140 5273 5065 5234 5302 5111 5368 5077 5313 5138 5261 5179 5161 5054 5239 5145 5226 5154 5039 5323 5224 5238 5275 5174 5272 5230 5131 5155 5078 5192 5200 5132 5254 5278 5204 5237 5116 5157 5219 5266 5272 5304 5321 5085 5146 5302 5199 5195 5269 5287 5145 5171 5206 5200 5250 5296 5204 5062 5135 5155 5156 5287 5255 5106 5206 5208 5195 5145 5207 5266 5142 5136 5193 5090 5234 5162 5342 5218 5220 5131 5160 5272 5280 5321 5244 5227 5153 5363 5055 5259 5260 5229 5194 5314 5216 5150 5167 5036 5230 5428 5099 5158 5148 5166 5282 5194 5180 5270 5320 5311 5326 5361 5211 5177 5370 5241 5312 5233 5193 5336 5206 5442 5159 5243 5299 5280 5235 5226 5253 5323 5353 5338 5346 5390 5499 5433 5309 5346 5569 5381 5420 5486 5509 5427 5506 5783 5739 5660 5819 5739 5902 5918 5874 5994 5987 6240 6267 6236 6238 6142 6155 6090 5878 5837 5892 5550 5540 5349 5412 5332 5421 5258 5375 5209 5362 5292 5280 5215 5287 5251 5281 5316 5302 5267 5150 5226 5185 5232 5372 5323 5331 5283 5091 5132 5349 5238 5175 5227 5157 5260 5341 5193 5168 5281 5313 5265 5233 5204 5228 5345 5263 5233 5209 5178 5276 5271 5341 5256 5251 5360 5160 5280 5332 5252 5276 5318 5237 5176 5266 5079 5388 5249 5236 5214 5269 5143 5313 5322 5280 5386 5213 5148 5170 5293 5326 5261 5168 5273 5212 5161 5268 5305 5180 5213 5287 5277 5327 5277 5265 5334 5313 5291 5334 5167 5335 5291 5406 5393 5396 5280 5149 5370 5265 5301 5429 5299 5287 5389 5353 5267 5266 5202 5284 5281 5275 5287 5356 5362 5243 5319 5158 5304 5165 5278 5299 5165 5209 5176 5289 5481 5260 5202 5201 5287 5225 5287 5257 5051 5327 5374 5252 5280 5182 5412 5191 5295 5350 5330 5291 5258 5319 5274 5334 5139 5367 5258 5190 5306 5353 5251 5203 5202 5295 5260 5346 5302 5257 5420 5295 5267 5419 5276 5259 5456 5269 5278 5108 5156 5121 5194 5170 5174 5202 5212 5195 5340 5253 5377 5237 5327 5411 5339 5282 5383 5327 5264 5200 5169 5157 5274 5296 5267 5364 5351 5254 5361 5368 5361 5378 5267 5355 5344 5230 5335 5303 5415 5260 5337 5269 5241 5433 5282 5344 5387 5410 5208 5393 5370 5306 5392 5427 5413 5523 5356 5533 5433 5581 5614 5552 5388 5521 5534 5602 5781 5613 5629 5725 5718 5721 5940 5862 5934 5821 5918 6124 5986 6085 6067 5922 5864 5799 5697 5872 5541 5574 5638 5564 5392 5304 5343 5432 5414 5445 5411 5276 5416 5214 5321 5282 5257 5482 5451 5288 5368 5354 5385 5274 5287 5275 5232 5292 5309 5284 5287 4983 5267 5195 5384 5324 5438 5329 5263 5246 5272 5355 5183 5387 5188 5302 5197 5275 5350 5271 5253 5222 5280 5326 5344 5319 5332 5184 5267 5198 5228 5224 5283 5283 5289 5283 5203 5223 5153 5438 5399 5365 5256 5255 5318 5393 5323 5200 5253 5302 5244 5301 5291 5219 5179 5304 5364 5211 5221 5350 5335 5215 5334 5135 5292 5374 5253 5444 5359 5306 5358 5392 5208 5209 5364 5311 5229 5317 5248 5363 5388 5248 5233 5350 5355 5332 5336 5325 5413 5294 5304 5306 5371 5260 5329 5353 5370 5435 5385 5386 5411 5353 5472 5418 5403 5411 5323 5422 5472 5462 5452 5591 5508 5610 5738 5724 5663 5645 5681 5753 5712 5906 5919 5928 6011 6184 6255 6392 6461 6506 6540 6992 7198 7445 7560 8052 8238 8615 8836 9168 9598 9897 10271 10751 11093 11138 11456 11455 11474 11467 11142 10618 10250 9791 9407 9256 8640 8473 8288 8119 8056 8033 8133 8194 8107 8016 8072 7947 7827 7621 7371 6989 6892 6676 6596 6282 6176 6015 5755 5907 5692 5601 5534 5528 5571 5390 5417 5652 5478 5392 5501 5451 5430 5384 5269 5344 5364 5327 5303 5288 5377 5281 5289 5365 5362 5301 5331 5339 5318 5323 5195 5317 5275 5296 5400 5304 5317 5310 5246 5301 5299 5237 5228 5134 5212 5297 5143 5333 5239 5387 5358 5305 5375 5248 5209 5322 5210 5365 5288 5346 5359 5198 5239 5276 5331 5312 5270 5264 5337 5346 5411 5493 5428 5267 5390 5388 5313 5440 5550 5444 5641 5485 5581 5562 5572 5663 5803 5929 6066 5955 6150 6219 6162 6341 6434 6468 6492 6485 6679 6651 6402 6511 6301 6175 6135 6033 5836 5853 5658 5607 5552 5487 5467 5313 5379 5234 5366 5251 5347 5232 5210 5314 5308 5320 5186 5387 5231 5270 5164 5266 5153 5201 5153 5170 5200 5109 5270 5250 5073 5208 5310 5173 5249 5168 5257 5445 5162 5088 5008 5143 5173 5154 5106 5026 5144 5159 5054 5124 5189 5117 5115 5055 5211 5178 5114 5237 5132 5229 5116 5011 5085 5081 5136 5155 5194 5162 5071 5139 5140 5102 5193 5093 5001 5272 5201 5223 5216 5067 5104 5103 5112 5145 5292 5157 5174 4999 5154 5145 5102 5014 5292 5017 5052 5107 5172 5139 4960 5154 5145 5181 5186 5170 5215 5097 5094 5160 5032 5204 5041 5187 5178 5205 4965 5132 4994 5116 5124 5118 5212 5067 5108 5158 5083 5087 5083 5134 5104 5007 5034 5132 5168 5009 5100 5109 5118 5092 5127 5175 5169 4997 5144 5169 5068 5064 5085 5111 4950 4968 4950 5001 5107 5141 5126 5186 5076 5063 5047 4999 5045 5035 5153 5227 5050 5236 5091 5018 5025 4989 5022 4994 5147 5175 5157 5224 4924 5146 5145 5129 4947 5022 5076 5002 5129 5064 5035 5117 5041 5029 4962 4959 5049 5089 5091 5214 5118 5003 5050 5142 5015 5126 5032 5110 5029 5030 4981 5085 4943 5170 5122 5031 5063 5076 5017 5209 5110 5080 5116 5199 5002 5045 4969 5065 5145 4988 5032 4987 5192 5091 5009 4985 5043 5028 4973 5028 4956 5111 4973 4905 5155 5004 5077 4967 5207 5155 4996 5078 5093 5088 5131 5035 4913 5114 4938 5053 4961 5008 4969 4934 5043 4974 4966 4904 4967 5086 4919 4980 5051 5085 5016 4984 5063 4942 5000 4925 4992 4929 4901 5142 5101 4903 5031 5106 5055 5052 5042 5038 5030 5160 4971 4926 5049 4904 5103 5001 5043 5050 4891 5015 5101 5035 5057 5094 4836 5108 5057 5136 5100 5048 4991 4960 5005 5072 5144 5130 4971 4978 4981 4983 5103 4881 4971 4906 5148 5075 5004 5012 5041 5091 5007 5097 5002 5024 5009 5064 5098 5217 5141 5122 5024 5180 5164 5162 5145 5278 5117 5102 5127 5189 5063 5100 5027 5203 5078 5071 4963 4872 5117 5092 5163 5076 4967 4991 5029 5143 5120 5070 5103 5130 5047 5090 5216 5057 5054 5062 5270 5138 5359 5236 5351 5290 5262 5543 5523 5572 5619 5711 5987 5914 6195 6265 6418 6709 6867 6912 7128 7327 7316 7252 7174 6880 6960 6700 6254 6279 6005 5841 5542 5529 5600 5266 5170 5032 5236 5233 5040 5115 5083 5154 5097 5006 5070 5024 4940 5062 5066 5064 4990 4982 4925 4945 4832 4968 4979 4927 5193 5111 4909 4961 4918 5005 4993 4961 4988 5126 5000 4913 5015 5066 4803 4940 4952 4983 4943 4978 4918 4981 5110 5053 4893 4778 4906 4924 4948 4933 4997 4883 4884 5057 4922 4765 4971 4977 4946 5083 4908 4968 4943 4941 4930 4961 5097 4993 4942 4982 4970 4963 4927 4822 4757 4955 4911 4953 4901 4979 4835 4830 4943 4935 4971 5013 4914 4891 4868 4861 4963 4717 4822 4837 4945 4856 4927 4960 4877 4935 4940 4993 4903 5064 4816 4898 4847 4861 4901 4868 5019 4873 4872 5036 5073 4987 4833 5095 4950 4728 4975 4903 4869 4943 4961 4851 4891 4891 4906 4792 4928 4891 4992 4948 4971 4893 4928 5037 4880 4964 5007 5032 4988 4922 4917 5003 4989 4921 4973 4997 4997 5029 4994 4861 4947 5033 4897 5129 5059 5013 4889 4856 4965 4895 4969 5031 4954 5043 5006 5051 5047 4995 4952 5090 4955 5165 5096 4926 5087 5089 5145 5077 5078 4936 5122 5122 4879 5184 5280 5125 5106 5091 5132 4960 5146 5077 5113 5227 5206 5225 5129 5298 5155 5133 5344 5221 5225 5241 5331 5410 5340 5165 5421 5496 5344 5349 5494 5394 5631 5561 5579 5538 5626 5580 5670 5698 5960 5823 5967 6070 6205 6231 6564 6486 6854 6920 7245 7509 7836 8080 8606 9206 9548 10311 11082 12058 13108 13978 15633 16765 18288 20105 21592 22900 24701 25890 27061 27279 27574 27189 25920 24693 23312 21660 20337 18376 17043 15225 13828 12451 11183 10112 9267 8532 8023 7503 7311 7060 6673 6631 6350 6191 6083 5922 5768 5901 5888 5762 5708 5595 5662 5519 5488 5515 5331 5440 5490 5262 5367 5403 5195 5267 5243 5106 5183 5119 5299 5337 5237 5152 5191 5178 5141 5142 5215 5284 5144 5070 5211 5243 5372 5323 5249 5335 5420 5351 5474 5474 5479 5546 5799 5912 6005 6082 6310 6435 6854 6857 7282 7516 7570 7615 7786 8002 7855 7846 7728 7703 7458 7320 7123 6904 6867 6569 6276 6068 6151 5853 5548 5721 5544 5283 5533 5239 5225 5152 5196 5162 5123 5171 5094 5178 5164 5187 5132 5057 5024 5079 4922 4998 5034 4989 5112 4875 5034 5053 5031 4984 5005 4846 5078 4939 5046 5067 4942 4986 4978 5002 4947 5020 5143 5065 5045 5069 4990 5067 5024 5174 5185 5165 5342 5192 5342 5562 5343 5384 5532 5650 5677 5902 6050 6156 6360 6273 6548 6645 6715 6928 7094 7122 6966 7225 7205 7056 6835 6608 6521 6411 6065 5974 5849 5786 5681 5359 5296 5212 5118 5040 5107 5044 5028 5040 4907 5122 5066 4957 4954 4730 5063 4889 4929 5012 4907 4857 4913 5014 4896 4878 4921 4769 4838 4812 4920 4911 4911 4833 4915 4968 4980 4835 4842 4942 4815 5019 4849 4897 4839 4881 4905 5073 4971 4824 4986 4717 4846 4793 4893 4825 4823 4843 4828 4850 4979 4890 4972 4867 4890 4970 5010 4872 4989 4790 4933 5010 4949 4910 4926 4848 4932 4901 4823 4793 4950 4935 4913 4779 4932 4796 4897 4972 4844 4909 5003 4985 5060 5019 4980 4956 4906 4967 5219 5173 5202 5192 5201 5338 5291 5333 5600 5599 5659 5705 5747 5835 5754 6096 5881 6069 5874 5925 5849 5695 5704 5793 5760 5688 5530 5498 5442 5332 5369 5436 5435 5281 5266 5085 5237 5087 5068 5025 4945 5126 4924 4926 4967 4852 4991 4968 4905 4850 4970 4902 4853 4788 4896 4945 4878 4947 4896 4806 4934 4904 4899 4762 4898 4847 4885 4892 4839 4836 4928 4935 4844 4787 4828 4902 4732 4863 4831 4758 4855 4991 4884 5090 4931 4830 4878 4902 5009 4923 4915 4921 4965 5025 5092 5172 5157 5082 5071 5135 5151 5103 5169 5264 5149 5106 5211 5129 5048 5198 5009 5183 5148 5108 5202 4970 5125 5105 5151 5216 5162 5244 5272 5260 5382 5444 5435 5579 5455 5718 6046 6201 6312 6575 6926 7197 7348 7766 8147 8643 9170 9190 9533 9782 9788 9654 9571 9385 9034 8631 8387 8071 7764 7579 7132 6969 6552 6176 6143 5816 5802 5632 5458 5301 5311 5192 5249 5005 5216 5025 5100 5014 5113 5002 5194 5209 5081 5158 5106 5169 5226 5326 5210 5220 5299 5338 5444 5631 5554 5855 5840 5844 5725 5679 5844 5655 5673 5686 5503 5485 5363 5347 5316 5273 5199 5119 5059 5063 4937 4966 4886 4893 4963 4984 4871 4911 4990 4978 4858 4952 4877 4913 4881 4977 4920 4747 4853 5047 4790 5045 5037 4906 4878 4879 4918 4948 4873 5035 4871 4969 4890 5109 5033 5038 4947 4992 4983 5112 4905 5104 5033 4930 5006 5009 4994 5302 4950 5119 5298 5125 5184 5203 5085 5234 5340 5355 5290 5228 5399 5529 5598 5567 5902 5848 5872 5987 6179 6376 6636 6920 7119 7447 7976 8535 9131 9696 10781 11444 12461 13310 14623 15470 16478 16847 17689 17990 18390 18476 18437 18430 18348 17683 17449 16886 16435 15874 15446 14629 13920 13453 12459 12000 11163 10802 10168 9458 9064 8866 8453 8130 7653 7452 7157 6881 6830 6635 6587 6302 6441 6393 6357 6274 6294 6344 6190 6385 6326 6153 6328 6256 6236 6177 6061 6003 5936 5794 5876 5767 5632 5642 5523 5387 5484 5306 5226 5256 5119 5013 5135 5086 5017 5093 5040 4900 5144 4971 5091 4945 4910 4896 4907 4819 4855 4801 4755 4838 4955 4780 4699 4691 4862 4802 4976 4674 4713 4844 4835 4744 4755 4899 4824 4920 4699 4979 4785 4834 4834 4682 4768 4846 4769 4821 4720 4742 4773 4709 4716 4848 4763 4784 4720 4744 4872 4683 4709 4767 4847 4735 4763 4604 4776 4754 4758 4811 4676 4708 4775 4771 4824 4804 4742 4880 4876 4885 4879 4949 5039 4924 4933 4886 5036 5130 5120 5217 5154 5257 5309 4998 5169 5289 5055 5147 5189 5142 5055 5081 5079 4757 4934 4746 4818 4851 4778 4937 4848 4776 4919 4806 4852 4822 4880 4909 4813 4800 4882 4811 4830 4755 4713 4722 4873 4796 4793 4802 4768 4720 4787 4784 4820 4822 4665 4765 4786 4631 4747 4954 4929 4718 4762 4701 4720 4741 4829 4883 4658 4865 4868 4739 4743 4822 4737 4769 4792 4820 4970 4771 4821 4734 4881 4974 4876 5048 4963 4917 4889 4985 4951 4949 5006 4893 4810 4872 4821 5092 4902 4877 4997 4930 4936 4989 4719 4929 4812 4968 5024 4846 4880 4865 4880 4853 4854 4799 4964 5006 4951 4862 4994 4952 4914 5115 5064 5113 5122 5208 5494 5213 5183 5398 5501 5532 5343 5465 5555 5590 5864 5825 5994 6028 6148 6193 6392 6600 6784 6819 7014 7302 7386 7680 8021 8057 8401 8358 8890 8718 9036 9094 9146 9396 9315 9340 9177 9089 9038 8892 8824 8457 8299 8278 8025 8048 7759 7492 7402 7294 7299 7049 6970 6854 6682 6511 6462 6421 6308 6223 6091 6299 5871 6004 5941 5866 5756 5539 5469 5239 5332 5343 5259 5146 5164 5143 5142 5095 4963 5058 4997 5015 4806 4885 4860 4878 4783 4855 4808 4759 4752 4763 4840 4740 4850 4775 4745 4744 4663 4704 4735 4697 4590 4746 4718 4689 4659 4654 4660 4714 4725 4711 4791 4633 4697 4673 4808 4799 4710 4815 4670 4934 4819 4881 5002 4990 5069 5054 5151 5310 5483 5442 5724 5782 5700 5768 5794 5792 5878 5866 5850 5662 5593 5631 5426 5489 5311 5270 5359 5181 5228 5190 5055 4874 4870 4811 4795 4676 4731 4709 4742 4756 4654 4478 4657 4689 4700 4652 4708 4646 4683 4658 4634 4518 4590 4626 4554 4669 4728 4796 4624 4652 4779 4610 4614 4612 4701 4661 4559 4726 4685 4597 4687 4639 4690 4624 4563 4564 4503 4570 4667 4633 4595 4438 4453 4582 4703 4658 4525 4649 4649 4572 4686 4646 4588 4625 4626 4498 4496 4601 4642 4661 4594 4610 4647 4754 4546 4671 4605 4572 4548 4640 4593 4585 4678 4581 4607 4504 4683 4750 4648 4642 4751 4607 4691 4575 4640 4682 4605 4621 4617 4786 4666 4641 4835 4804 4887 4878 4966 4987 5035 5056 5030 5145 5137 5312 5277 5182 5322 5302 5404 5181 5183 5192 5240 5191 5099 5135 5020 5015 4816 4995 4797 4776 4871 4826 4754 4534 4840 4661 4728 4690 4653 4663 4883 4702 4789 4609 4761 4730 4705 4689 4674 4808 4803 4874 4707 4821 4718 4664 4923 4764 4846 4763 4855 4753 4857 4775 4651 4640 4660 4839 4609 4691 4569 4764 4755 4643 4780 4755 4733 4772 4760 4769 4790 4874 4979 4850 4792 4845 4814 4901 4699 4950 4833 4817 4860 4760 4708 4785 4634 4767 4816 4717 4648 4571 4708 4675 4669 4657 4663 4606 4756 4457 4731 4612 4565 4442 4598 4608 4632 4609 4430 4576 4589 4576 4488 4515 4485 4690 4457 4583 4379 4576 4506 4721 4658 4575 4679 4575 4484 4565 4673 4584 4625 4533 4636 4579 4549 4594 4531 4513 4577 4481 4607 4662 4579 4589 4684 4633 4761 4719 4550 4698 4619 4663 4835 4782 4941 4907 4977 5167 5120 5333 5410 5578 5791 5923 6092 6243 6332 6389 6265 6437 6401 6601 6555 6469 6342 6383 6434 6156 6229 5940 5821 5875 5721 5586 5571 5464 5348 5274 5159 5125 5149 5234 5123 5078 5199 5139 5182 5175 5212 5355 5470 5669 5826 5801 6055 6168 6265 6373 6310 6359 6258 6119 5957 5964 5745 5710 5625 5619 5566 5459 5507 5240 5190 5120 5055 5020 4894 5003 4849 4731 4782 4636 4750 4645 4681 4758 4682 4702 4643 4638 4652 4515 4633 4435 4599 4645 4640 4646 4607 4564 4503 4537 4657 4560 4453 4509 4523 4550 4599 4557 4557 4568 4589 4452 4633 4625 4556 4611 4442 4629 4614 4637 4651 4505 4599 4525 4558 4558 4581 4577 4537 4597 4542 4592 4661 4525 4523 4534 4497 4486 4591 4576 4660 4421 4604 4524 4601 4571 4552 4386 4545 4596 4572 4463 4589 4593 4501 4417 4485 4455 4422 4507 4478 4492 4385 4462 4452 4526 4451 4443 4504 4549 4581 4447 4563 4374 4466 4519 4468 4475 4453 4543 4526 4584 4504 4607 4666 4470 4429 4561 4543 4575 4462 4492 4420 4434 4542 4477 4393 4496 4565 4340 4603 4458 4581 4451 4596 4473 4443 4355 4514 4471 4413 4565 4419 4633 4631 4455 4583 4537 4460 4581 4488 4615 4504 4499 4481 4577 4739 4608 4698 4578 4801 4626 4880 4671 4856 4768 4976 4899 4854 4887 4835 4934 4898 4664 4669 4744 4830 4820 4698 4805 4660 4829 4686 4694 4647 4659 4697 4562 4650 4699 4596 4643 4556 4466 4596 4582 4554 4532 4448 4543 4601 4531 4433 4488 4512 4521 4529 4457 4480 4455 4502 4584 4534 4490 4557 4339 4412 4520 4423 4497 4488 4465 4499 4519 4429 4536 4501 4529 4567 4435 4675 4470 4655 4627 4617 4610 4554 4732 4501 4545 4552 4598 4676 4565 4544 4585 4492 4614 4556 4560 4661 4563 4594 4534 4621 4460 4599 4560 4464 4487 4358 4539 4462 4411 4547 4580 4515 4655 4456 4423 4582 4548 4560 4546 4599 4502 4547 4755 4508 4574 4510 4516 4544 4599 4569 4575 4559 4542 4692 4502 4644 4655 4701 4919 4752 4934 4869 5008 5034 5097 4965 4924 5038 4969 4902 4864 4937 4913 4800 4782 4835 4884 4843 4803 4708 4715 4667 4742 4602 4807 4638 4764 4600 4752 4711 4564 4688 4654 4632 4771 4794 4796 4788 4714 4954 4938 4970 5026 5151 5335 5176 5363 5199 5244 5053 5109 4981 5001 5044 5010 5057 5051 5043 4886 4992 4922 4879 4734 4910 4819 4665 4751 4647 4622 4673 4651 4619 4733 4603 4578 4638 4656 4576 4607 4694 4628 4798 4853 4732 4772 4875 4924 4908 4969 5099 4966 4943 5099 5130 5001 5116 4954 4938 4911 4889 4865 4948 4983 4937 4990 4910 4911 4920 4730 4869 4804 4822 4955 4774 4837 4835 4817 4947 4752 4903 4956 4887 4822 4871 4771 4944 5017 5027 5095 5085 5090 5042 5185 5326 5279 5335 5394 5632 5592 5799 5932 6095 6379 6727 7311 7553 8171 8615 9404 9906 10888 11357 12330 12738 13105 13098 13029 12716 12216 11799 11280 11007 10720 10326 10293 10252 10315 10108 9745 9506 8918 8668 8378 7876 7530 7399 7154 7067 6847 6777 6728 6808 6719 6564 6573 6350 6299 6323 6047 6136 6179 5907 5911 5631 5728 5636 5619 5517 5359 5298 5377 5257 5197 5080 4958 5123 5118 4791 4896 4850 4926 4881 4849 4815 4870 4724 4715 4743 4680 4748 4787 4713 4702 4710 4714 4615 4603 4563 4540 4688 4537 4655 4623 4685 4631 4612 4644 4567 4592 4596 4677 4664 4581 4723 4673 4659 4577 4682 4657 4538 4634 4699 4497 4643 4411 4599 4445 4522 4611 4531 4572 4546 4594 4523 4609 4589 4465 4490 4535 4768 4447 4640 4712 4430 4537 4525 4443 4618 4554 4364 4598 4552 4588 4516 4561 4481 4495 4526 4693 4599 4541 4653 4640 4712 4644 4660 4653 4735 4815 4912 4968 5022 4735 4902 4827 4835 4717 4722 4776 4847 4728 4702 4620 4819 4610 4731 4722 4604 4560 4494 4537 4590 4684 4465 4581 4516 4439 4446 4499 4394 4530 4535 4420 4501 4388 4499 4445 4511 4432 4331 4447 4449 4339 4394 4449 4386 4415 4394 4432 4564 4418 4468 4467 4465 4444 4526 4380 4496 4441 4375 4588 4488 4460 4561 4566 4394 4390 4453 4408 4423 4524 4439 4472 4488 4336 4519 4503 4420 4509 4478 4531 4508 4524 4433 4546 4493 4521 4592 4534 4528 4517 4699 4573 4745 4847 4765 4872 5048 4920 5130 4996 5113 5216 5229 5117 5207 5038 5036 4930 4971 4970 5032 4818 4789 5015 5009 4999 4994 4809 4785 4758 4562 4686 4615 4848 4743 4525 4649 4619 4642 4573 4636 4497 4644 4630 4560 4553 4588 4578 4553 4604 4653 4717 4464 4681 4652 4647 4619 4529 4662 4750 4568 4576 4578 4378 4495 4455 4554 4478 4493 4586 4582 4753 4550 4536 4576 4541 4616 4628 4754 4793 4685 4740 4830 4878 4864 4798 4790 4823 4659 4654 4626 4676 4428 4616 4763 4592 4629 4527 4641 4524 4697 4555 4553 4462 4545 4481 4543 4607 4387 4581 4487 4488 4442 4318 4363 4456 4400 4458 4440 4352 4365 4504 4380 4379 4417 4516 4466 4544 4586 4456 4514 4479 4576 4547 4496 4522 4489 4578 4439 4498 4404 4573 4498 4520 4634 4536 4508 4560 4494 4434 4545 4476 4372 4487 4428 4638 4514 4612 4604 4365 4592 4334 4448 4481 4556 4717 4604 4562 4608 4482 4530 4553 4600 4571 4570 4564 4708 4633 4629 4682 4706 4818 4717 4908 4853 4762 5041 5134 5213 5192 5293 5348 5628 5629 5578 5752 5581 5508 5500 5591 5426 5432 5529 5473 5606 5459 5705 5605 5724 5653 5651 5671 5742 5738 5665 5667 5521 5766 5447 5610 5651 5591 5459 5496 5465 5387 5369 5241 5300 5246 5192 5175 4990 5130 4981 5064 4937 4981 4906 4877 4787 4722 4696 4866 4752 4803 4700 4791 4681 4619 4682 4613 4533 4552 4747 4626 4656 4639 4525 4528 4387 4577 4530 4705 4458 4405 4438 4434 4463 4515 4582 4517 4419 4490 4371 4374 4464 4336 4544 4492 4548 4552 4462 4530 4505 4529 4392 4429 4481 4436 4403 4508 4530 4557 4413 4421 4403 4451 4394 4406 4461 4345 4393 4429 4437 4504 4473 4503 4491 4569 4418 4479 4421 4320 4481 4533 4462 4494 4576 4573 4521 4401 4445 4538 4550 4627 4479 4582 4646 4609 4609 4470 4564 4654 4600 4561 4559 4605 4533 4639 4561 4478 4566 4568 4539 4560 4573 4560 4474 4605 4544 4553 4585 4515 4553 4490 4347 4423 4470 4545 4538 4357 4511 4432 4463 4513 4514 4488 4391 4375 4433 4506 4461 4401 4448 4570 4497 4464 4403 4570 4427 4392 4590 4480 4451 4449 4384 4425 4547 4539 4539 4474 4547 4484 4433 4469 4479 4368 4347 4450 4487 4557 4593 4459 4478 4513 4481 4426 4515 4529 4547 4635 4546 4558 4565 4644 4734 4908 4737 4673 4842 4796 4766 4664 4542 4694 4689 4824 4598 4691 4600 4600 4635 4662 4720 4629 4771 4693 4639 4545 4569 4677 4677 4559 4504 4531 4638 4542 4738 4568 4523 4682 4716 4659 4645 4677 4808 4686 4808 4843 5004 4919 5069 4995 5081 5235 5130 5197 5209 5185 5262 5073 5273 5120 5072 4964 5114 4865 4991 4915 4985 4973 4991 4819 4963 4872 4693 4830 4670 4667 4753 4637 4599 4606 4593 4574 4634 4554 4674 4702 4679 4500 4596 4709 4541 4723 4586 4643 4607 4680 4567 4655 4716 4627 4721 4741 4819 4771 4815 4678 4903 4779 4987 5058 5013 5123 5250 5484 5567 5725 5789 5834 5950 6184 6275 6278 6408 6407 6428 6609 6490 6590 6475 6516 6397 6472 6399 6397 6207 6380 6314 6194 6209 6050 5976 5766 5715 5696 5583 5590 5616 5431 5473 5428 5246 5297 5119 5325 5122 5002 4967 5060 5074 4968 5135 5059 4926 4969 5138 5108 5102 5229 5247 5296 5278 5625 5633 5857 5883 6244 6394 6713 7108 7560 7941 8431 8868 9196 9591 9694 9770 9359 9358 8946 8332 7868 7772 7668 7608 7488 7353 7617 7646 7661 7394 7450 7228 6962 6655 6343 5981 5691 5647 5547 5462 5324 5135 5182 5081 4997 4978 4956 4972 4784 4857 4944 4926 4996 4891 5031 4728 4872 4830 4873 4842 4891 4904 4899 4854 4874 4951 4854 4861 4886 5063 4944 4985 4973 4941 4936 5103 5049 4940 4989 5115 5140 5120 4973 5041 4802 5005 4970 4897 4967 4854 4996 4824 4929 4742 4901 4900 4884 4835 4950 4967 4769 4880 4775 4754 4743 4682 4628 4786 4623 4772 4630 4725 4668 4771 4689 4748 4829 4568 4696 4615 4732 4560 4682 4548 4622 4588 4660 4713 4740 4702 4713 4765 4767 4857 4892 4946 5056 5142 5119 5412 5521 5493 5753 5798 5817 5750 5680 5723 5531 5516 5413 5254 5334 5203 5333 5379 5262 5308 5207 5158 5169 5175 5160 5049 4938 5096 4780 4777 4701 4671 4847 4671 4719 4558 4577 4592 4455 4499 4561 4446 4402 4623 4438 4498 4493 4555 4396 4450 4475 4497 4494 4361 4496 4541 4563 4381 4467 4554 4485 4533 4422 4379 4427 4569 4384 4279 4510 4487 4445 4373 4326 4384 4456 4539 4510 4429 4547 4425 4413 4405 4456 4409 4513 4488 4597 4540 4516 4420 4467 4413 4433 4566 4577 4509 4480 4552 4510 4568 4772 4622 4537 4509 4502 4512 4469 4588 4499 4551 4523 4481 4409 4603 4493 4641 4450 4613 4636 4619 4595 4502 4751 4749 4726 4692 4873 4793 4951 4996 4940 5008 5165 5194 5166 5290 5396 5402 5195 5214 5160 5028 4974 4965 4976 4931 4954 4924 4869 4955 4929 4899 4931 4885 4896 4899 4819 4664 4748 4640 4439 4584 4608 4549 4591 4608 4515 4438 4551 4623 4520 4550 4483 4577 4535 4683 4430 4519 4513 4613 4529 4543 4536 4520 4476 4579 4468 4539 4599 4654 4783 4792 4762 4788 4792 4969 4787 4890 4909 4927 4931 4872 4769 4680 4738 4656 4817 4709 4860 4735 4747 4856 4752 4747 4764 4759 4850 4786 4754 4882 4816 4789 4798 4712 4731 4753 4907 4871 4898 4930 5044 4998 5077 5177 5131 5169 5138 5244 5359 5325 5248 5116 5189 5345 5288 5266 5246 5188 5125 5167 5200 5125 5043 5096 5109 4982 5002 5139 5080 5216 5171 5234 5019 5157 5127 4951 5096 5039 4952 4937 4925 4841 4907 4863 4923 4799 4848 4860 4898 4789 4799 5012 5059 4903 4930 4848 4948 4972 4991 4888 4991 5101 4962 5019 4976 4861 5054 4863 4775 4905 4789 4813 4749 4916 4954 4931 5066 4943 5012 5113 4963 5140 4975 5230 5281 5378 5476 5679 5847 5986 6022 6171 6504 6446 6598 6579 6855 6974 6872 6928 6917 7039 6965 7045 7007 6964 7065 6957 7004 6795 6798 6666 6675 6549 6372 6397 6373 6229 6151 5963 5936 5771 5827 5454 5511 5446 5453 5282 5169 5281 5087 5155 5083 4985 4866 4813 4800 4929 4823 4763 4755 4959 4778 4617 4735 4621 4709 4653 4682 4635 4606 4543 4595 4746 4707 4767 4605 4737 4675 4710 4659 4686 4546 4473 4585 4571 4556 4461 4519 4549 4593 4741 4537 4639 4500 4594 4666 4564 4412 4569 4553 4583 4419 4425 4499 4422 4485 4491 4475 4395 4449 4445 4445 4457 4425 4387 4384 4414 4572 4595 4442 4563 4461 4507 4372 4530 4482 4488 4556 4312 4284 4291 4446 4420 4417 4390 4380 4515 4495 4437 4534 4507 4370 4521 4432 4426 4425 4375 4406 4449 4527 4475 4420 4416 4378 4343 4604 4440 4447 4481 4429 4456 4410 4529 4374 4530 4381 4377 4625 4479 4459 4511 4567 4442 4481 4526 4471 4336 4381 4540 4560 4514 4519 4607 4560 4595 4424 4583 4608 4702 4609 4737 4729 4801 4737 4859 4848 4965 4997 5053 5118 5037 5051 5115 5151 5039 4932 4885 5072 4736 4930 4861 4700 4909 4807 4907 4757 4805 4786 4860 4791 4939 4756 4735 4604 4601 4625 4517 4739 4585 4461 4610 4460 4471 4378 4338 4576 4600 4436 4423 4500 4446 4441 4438 4539 4506 4474 4454 4512 4440 4451 4510 4554 4412 4516 4438 4469 4451 4553 4483 4657 4622 4459 4492 4436 4516 4421 4477 4528 4507 4412 4547 4447 4457 4568 4628 4430 4436 4427 4552 4576 4668 4474 4584 4467 4600 4482 4512 4491 4534 4617 4588 4629 4644 4532 4631 4673 4698 4596 4756 4666 4780 4833 4673 4794 4760 4779 4663 4745 4793 4870 4895 4808 5032 4999 5000 5009 5034 4987 5065 5078 5224 5140 5130 5144 5160 5284 5152 5193 5183 5101 5010 5090 4969 5095 5013 5049 5121 4989 5082 5253 5208 5119 5010 5087 5128 5043 4982 5147 5169 5240 4973 5100 5081 5090 4986 5056 5006 5099 5091 5055 5090 5068 5101 5127 5116 5034 5109 5102 5036 4958 5079 5140 4942 4954 4988 4960 4961 4979 4994 4749 4913 4909 4822 4751 4719 4762 4678 4736 4630 4685 4549 4531 4652 4583 4623 4436 4570 4599 4523 4563 4557 4539 4546 4399 4558 4508 4557 4512 4647 4570 4337 4442 4421 4532 4448 4515 4347 4506 4315 4355 4506 4527 4416 4396 4424 4428 4419 4390 4448 4432 4419 4455 4355 4429 4388 4495 4397 4270 4403 4472 4321 4441 4416 4354 4555 4533 4403 4416 4426 4425 4530 4389 4343 4275 4450 4482 4468 4446 4367 4380 4410 4371 4526 4482 4468 4416 4443 4449 4422 4505 4512 4434 4434 4399 4544 4385 4559 4539 4601 4403 4535 4525 4570 4641 4452 4526 4675 4639 4520 4686 4548 4660 4649 4642 4662 4844 4651 4622 4710 4752 4750 4590 4748 4747 4872 4974 4867 4731 4778 4854 4931 5024 4834 4986 5045 5058 4920 5049 4893 5140 5037 4921 5026 5028 5005 5070 5115 5150 5034 4894 5027 5048 5282 4911 4949 4959 4975 4989 4997 5001 4912 4880 4851 4826 4951 4887 4941 4952 4787 4825 4861 4842 4724 4802 4647 4769 4737 4781 4588 4638 4532 4689 4629 4662 4588 4483 4508 4520 4504 4572 4533 4462 4554 4498 4429 4457 4521 4334 4553 4469 4476 4611 4547 4488 4316 4418 4516 4457 4525 4490 4469 4559 4542 4597 4540 4476 4558 4593 4601 4505 4510 4612 4465 4489 4468 4392 4511 4434 4447 4501 4529 4563 4550 4431 4547 4529 4418 4496 4443 4526 4400 4444 4447 4468 4425 4625 4491 4418 4399 4429 4467 4400 4508 4493 4364 4410 4417 4350 4344 4444 4391 4472 4384 4510 4441 4331 4406 4416 4410 4458 4596 4389 4532 4445 4444 4422 4344 4408 4442 4440 4503 4408 4495 4472 4508 4501 4584 4300 4433 4644 4657 4629 4621 4602 4734 4641 4696 4705 4740 4729 4788 4726 4686 4905 4762 4772 4670 4701 4696 4826 4756 4711 4691 4793 4613 4646 4614 4620 4453 4536 4562 4551 4576 4574 4618 4588 4544 4606 4544 4454 4613 4484 4493 4448 4509 4506 4506 4367 4379 4450 4380 4507 4521 4506 4429 4412 4521 4468 4502 4440 4497 4482 4559 4405 4446 4419 4510 4448 4464 4524 4454 4460 4366 4585 4454 4551 4431 4619 4440 4360 4443 4473 4354 4420 4455 4546 4396 4391 4471 4412 4541 4447 4476 4458 4514 4434 4440 4452 4443 4450 4474 4421 4441 4402 4538 4538 4513 4512 4449 4545 4495 4671 4673 4583 4627 4502 4601 4616 4593 4802 4705 4692 4746 4818 4879 4884 5142 4940 5158 5021 5143 5180 5213 5155 5330 5326 5091 4917 4936 4802 4798 4689 4789 4840 4721 4821 4779 4725 4815 4763 4732 4805 4824 4819 4719 4822 4731 4704 4600 4518 4571 4588 4535 4586 4582 4533 4476 4375 4511 4582 4534 4679 4384 4439 4448 4350 4523 4495 4502 4495 4411 4523 4433 4411 4336 4418 4323 4558 4366 4347 4546 4544 4364 4610 4381 4495 4590 4470 4543 4440 4508 4573 4482 4405 4599 4553 4419 4602 4505 4551 4458 4493 4453 4469 4520 4556 4488 4499 4458 4592 4618 4479 4564 4658 4444 4619 4442 4582 4474 4498 4580 4525 4591 4617 4577 4624 4649 4639 4726 4704 4782 4868 5003 5096 5114 5194 5123 5403 5328 5267 5310 5283 5203 5147 5264 5132 5070 4989 5036 5024 5024 5001 4901 4973 4983 5121 5077 5044 5026 5043 4925 4998 4915 4964 4829 4897 4777 4808 4919 4777 4819 4856 4814 4693 4697 4577 4781 4771 4559 4681 4599 4523 4414 4655 4513 4626 4535 4518 4496 4555 4506 4526 4437 4505 4469 4363 4476 4491 4441 4468 4369 4525 4534 4466 4403 4428 4495 4415 4346 4443 4410 4285 4372 4351 4418 4352 4328 4523 4395 4434 4430 4373 4426 4408 4382 4276 4343 4312 4348 4305 4451 4300 4326 4360 4442 4424 4353 4281 4311 4523 4529 4486 4236 4474 4473 4517 4512 4491 4547 4608 4491 4480 4667 4624 4520 4680 4763 4586 4661 4656 4610 4624 4514 4561 4560 4497 4571 4537 4535 4615 4556 4607 4659 4548 4587 4693 4753 4839 4862 4758 4864 4797 4668 4718 4800 4649 4717 4657 4743 4671 4793 4773 4756 4941 4813 4763 4795 4819 4789 4945 4791 4807 4867 4871 4788 4762 4699 4740 4726 4559 4805 4714 4682 4772 4645 4583 4652 4554 4728 4569 4659 4571 4687 4675 4686 4657 4589 4596 4536 4553 4507 4541 4494 4656 4645 4717 4637 4549 4717 4587 4687 4574 4553 4661 4513 4473 4528 4574 4486 4522 4483 4644 4596 4431 4600 4447 4596 4564 4430 4669 4657 4694 4718 4761 4758 4842 4761 4843 4844 4819 4924 4984 4940 5002 4996 4926 5003 5006 4962 5113 4971 5023 4936 5062 5038 4971 4951 5101 5063 4929 4942 4921 4995 4783 4928 4926 4823 4804 4891 4912 4839 4970 4853 4943 4914 4769 4901 4763 4799 4718 4693 4802 4743 4666 4668 4702 4633 4792 4650 4573 4596 4754 4523 4528 4509 4507 4587 4504 4537 4556 4592 4591 4583 4465 4468 4444 4404 4376 4424 4386 4495 4436 4443 4463 4331 4481 4423 4399 4545 4480 4343 4488 4522 4526 4581 4312 4355 4426 4319 4380 4466 4524 4407 4400 4463 4525 4506 4385 4331 4387 4410 4416 4563 4500 4611 4564 4546 4544 4588 4543 4736 4608 4626 4522 4474 4532 4515 4581 4551 4574 4480 4519 4536 4565 4601 4511 4481 4303 4412 4602 4556 4615 4507 4444 4543 4397 4565 4403 4584 4536 4506 4406 4545 4370 4434 4439 4311 4319 4410 4419 4326 4411 4392 4331 4443 4319 4300 4402 4263 4402 4365 4423 4399 4349 4429 4389 4391 4346 4290 4342 4243 4369 4300 4379 4321 4269 4353 4434 4325 4317 4363 4348 4546 4310 4386 4280 4290 4283 4364 4371 4360 4366 4206 4476 4390 4374 4358 4360 4356 4424 4431 4406 4182 4446 4259 4377 4475 4326 4380 4434 4457 4441 4405 4448 4434 4474 4377 4583 4461 4506 4420 4601 4568 4610 4682 4794 4783 4890 4626 4883 4898 4995 4951 4991 4858 4763 4712 4793 4590 4625 4659 4587 4569 4621 4535 4551 4426 4543 4794 4644 4645 4535 4592 4809 4632 4689 4570 4599 4598 4480 4415 4461 4577 4383 4490 4528 4381 4326 4483 4429 4282 4504 4415 4448 4387 4324 4442 4300 4322 4316 4320 4363 4326 4386 4408 4424 4317 4441 4382 4506 4398 4424 4580 4388 4348 4395 4322 4373 4439 4371 4422 4335 4545 4450 4429 4547 4360 4479 4475 4426 4522 4498 4486 4529 4580 4443 4499 4404 4558 4519 4542 4528 4366 4500 4519 4560 4592 4596 4531 4671 4739 4649 4664 4804 4795 4760 4972 4992 5095 5137 5277 5361 5417 5619 5426 5587 5652 5518 5212 5226 5199 4902 4867 4852 4925 4831 4947 4888 4981 4860 4968 5044 5041 5091 4970 5015 5167 5110 4955 4891 4921 4818 4698 4773 4655 4708 4514 4602 4506 4609 4658 4562 4498 4652 4586 4589 4559 4459 4427 4434 4604 4522 4409 4396 4508 4350 4396 4548 4329 4246 4405 4374 4370 4440 4414 4424 4393 4411 4381 4406 4344 4433 4459 4455 4263 4434 4195 4451 4400 4314 4337 4391 4389 4464 4393 4370 4340 4480 4364 4457 4349 4353 4327 4380 4527 4414 4349 4353 4306 4345 4364 4372 4284 4390 4407 4313 4387 4362 4278 4259 4236 4333 4319 4390 4408 4414 4428 4332 4318 4339 4445 4351 4482 4358 4295 4302 4323 4288 4425 4300 4359 4341 4349 4293 4381 4403 4367 4275 4402 4321 4218 4296 4299 4321 4405 4479 4417 4312 4500 4461 4445 4343 4338 4410 4386 4419 4252 4451 4429 4302 4382 4368 4418 4381 4265 4465 4273 4388 4369 4428 4292 4418 4328 4379 4430 4403 4294 4193 4343 4344 4420 4434 4450 4347 4366 4280 4500 4301 4395 4355 4316 4384 4419 4347 4392 4323 4366 4445 4398 4390 4365 4445 4360 4371 4303 4465 4370 4428 4453 4564 4321 4429 4526 4476 4566 4422 4500 4520 4488 4517 4587 4602 4746 4642 4867 5024 4871 5180 5131 5020 5185 5037 5065 5181 4997 4930 4854 4717 4733 4757 4581 4573 4530 4674 4707 4530 4677 4742 4770 4735 4712 4690 4822 4701 4762 4716 4600 4644 4675 4769 4589 4585 4544 4526 4556 4439 4512 4306 4426 4480 4333 4441 4328 4427 4413 4362 4407 4432 4362 4433 4419 4315 4365 4357 4354 4407 4324 4356 4557 4424 4373 4329 4368 4346 4336 4441 4438 4357 4338 4312 4313 4292 4211 4355 4415 4299 4336 4361 4375 4380 4370 4427 4465 4351 4374 4375 4392 4511 4399 4488 4375 4188 4429 4347 4407 4393 4302 4412 4413 4440 4502 4475 4450 4464 4558 4490 4495 4526 4531 4527 4583 4666 4548 4553 4668 4441 4561 4532 4570 4551 4435 4605 4582 4645 4449 4402 4518 4564 4550 4456 4435 4535 4524 4616 4566 4461 4547 4465 4498 4573 4526 4527 4528 4638 4514 4495 4485 4430 4590 4582 4583 4507 4534 4474 4618 4455 4577 4519 4522 4434 4470 4513 4605 4613 4509 4499 4580 4489 4488 4570 4564 4546 4426 4377 4546 4434 4380 4453 4541 4602 4496 4408 4439 4461 4623 4464 4482 4523 4591 4561 4606 4542 4562 4580 4411 4476 4442 4542 4444 4331 4485 4537 4311 4571 4398 4477 4575 4531 4423 4376 4609 4547 4529 4348 4388 4362 4528 4512 4478 4493 4501 4599 4570 4613 4526 4563 4528 4633 4653 4471 4473 4555 4587 4597 4490 4410 4622 4526 4609 4405 4647 4516 4354 4549 4578 4363 4616 4602 4617 4385 4401 4441 4518 4601 4540 4474 4544 4468 4512 4535 4399 4420 4362 4435 4413 4520 4433 4480 4532 4385 4368 4489 4482 4489 4552 4304 4514 4470 4324 4345 4366 4386 4360 4253 4429 4355 4401 4508 4314 4338 4420 4329 4335 4329 4310 4498 4324 4437 4357 4516 4332 4408 4491 4417 4320 4421 4370 4439 4450 4455 4461 4355 4307 4463 4469 4425 4473 4341 4396 4337 4327 4423 4402 4401 4437 4530 4375 4526 4653 4518 4583 4608 4690 4566 4708 4593 4670 4698 4694 4694 4626 4618 4382 4495 4587 4349 4561 4514 4521 4538 4420 4483 4546 4537 4504 4381 4411 4522 4447 4565 4571 4448 4609 4506 4500 4497 4490 4417 4367 4391 4491 4352 4437 4421 4469 4474 4295 4319 4322 4355 4345 4387 4483 4345 4332 4356 4438 4318 4414 4381 4172 4433 4432 4445 4383 4279 4399 4350 4411 4355 4337 4356 4377 4351 4280 4338 4433 4450 4325 4312 4344 4335 4297 4414 4473 4252 4331 4286 4391 4223 4330 4312 4364 4363 4397 4447 4441 4422 4351 4499 4345 4224 4272 4168 4344 4325 4391 4443 4327 4328 4354 4364 4488 4266 4342 4284 4234 4472 4449 4271 4323 4347 4343 4347 4250 4258 4299 4420 4352 4362 4398 4363 4291 4400 4262 4284 4390 4291 4341 4409 4338 4385 4285 4352 4264 4390 4346 4428 4383 4386 4349 4340 4373 4380 4419 4349 4402 4246 4377 4347 4204 4420 4366 4418 4410 4257 4457 4318 4499 4335 4367 4426 4359 4531 4435 4333 4524 4286 4556 4428 4531 4562 4498 4566 4505 4578 4563 4581 4526 4528 4615 4543 4563 4669 4522 4511 4564 4511 4558 4630 4547 4594 4503 4488 4523 4444 4572 4630 4779 4681 4582 4364 4624 4626 4494 4621 4586 4686 4508 4589 4598 4641 4655 4753 4715 4811 4786 4630 4780 4844 4826 4856 4792 4785 4683 4662 4607 4545 4477 4447 4453 4386 4450 4500 4363 4518 4346 4490 4442 4527 4661 4551 4429 4562 4545 4572 4596 4465 4453 4540 4566 4554 4357 4386 4378 4526 4445 4331 4400 4378 4374 4440 4343 4460 4267 4326 4344 4366 4476 4351 4317 4277 4290 4347 4343 4231 4378 4359 4244 4294 4481 4224 4260 4318 4127 4475 4381 4420 4247 4339 4382 4398 4254 4290 4325 4322 4348 4308 4332 4372 4299 4270 4405 4272 4392 4388 4314 4201 4345 4445 4343 4423 4308 4442 4404 4443 4251 4419 4354 4301 4422 4352 4360 4339 4423 4237 4391 4382 4361 4387 4371 4315 4310 4310 4348 4308 4350 4373 4452 4358 4405 4401 4417 4354 4485 4330 4421 4471 4446 4403 4388 4418 4494 4447 4461 4472 4417 4421 4315 4406 4383 4306 4425 4257 4436 4425 4373 4402 4390 4340 4354 4603 4485 4398 4342 4428 4405 4326 4393 4393 4346 4363 4466 4238 4372 4392 4391 4339 4410 4414 4364 4408 4293 4376 4435 4369 4315 4518 4375 4326 4446 4385 4471 4502 4349 4458 4367 4373 4434 4398 4418 4380 4415 4600 4435 4535 4467 4494 4440 4656 4355 4470 4552 4546 4684 4663 4556 4573 4644 4695 4829 4696 4846 4762 4912 4989 4995 5141 5052 5112 5199 5080 5189 5217 5052 5266 5110 5189 5226 5255 5196 5120 5088 5086 5152 4996 4981 5265 5063 5119 5193 5127 5106 5111 5204 5253 5285 5174 5132 4953 5036 5096 5078 5204 4966 4980 4941 4919 4805 4893 4848 4749 4775 4867 4773 4771 4793 4807 4593 4690 4757 4646 4701 4803 4625 4683 4699 4671 4519 4572 4540 4487 4514 4455 4458 4609 4488 4535 4490 4575 4417 4489 4581 4344 4538 4406 4419 4587 4306 4564 4420 4315 4528 4512 4338 4440 4506 4481 4450 4389 4472 4448 4385 4543 4598 4645 4574 4548 4532 4633 4544 4781 4677 4670 4783 4778 4900 4791 4990 4902 5068 5067 5128 5254 5331 5127 5131 5061 5047 5014 4905 4763 4869 4580 4692 4744 4615 4495 4630 4554 4782 4621 4567 4784 4779 4833 4757 4826 4872 4756 4852 4783 4678 4844 4738 4733 4710 4469 4553 4615 4551 4553 4453 4535 4500 4343 4397 4417 4512 4484 4357 4555 4449 4346 4442 4395 4340 4364 4420 4469 4505 4483 4336 4454 4334 4354 4574 4388 4305 4414 4334 4500 4325 4389 4296 4507 4514 4451 4404 4479 4336 4383 4382 4436 4532 4452 4385 4386 4414 4371 4416 4450 4394 4510 4415 4517 4470 4359 4404 4366 4559 4535 4433 4396 4456 4530 4514 4465 4670 4607 4580 4557 4619 4797 4626 4643 4620 4669 4623 4597 4545 4603 4575 4528 4523 4397 4497 4501 4371 4489 4406 4433 4500 4490 4523 4532 4604 4508 4483 4510 4504 4481 4536 4541 4527 4370 4387 4413 4463 4482 4504 4316 4552 4357 4423 4327 4314 4372 4494 4331 4501 4370 4432 4426 4324 4362 4384 4387 4423 4324 4447 4251 4304 4353 4470 4324 4355 4350 4470 4381 4355 4348 4427 4303 4314 4372 4367 4441 4272 4360 4287 4356 4386 4318 4346 4342 4308 4335 4492 4405 4264 4421 4451 4383 4298 4486 4408 4348 4418 4399 4423 4582 4393 4440 4455 4334 4555 4390 4399 4410 4525 4521 4570 4513 4469 4622 4622 4532 4553 4472 4569 4520 4566 4528 4502 4517 4508 4480 4400 4401 4415 4348 4374 4546 4404 4461 4485 4428 4504 4447 4484 4455 4531 4485 4561 4600 4469 4513 4445 4475 4497 4411 4496 4379 4411 4348 4405 4350 4316 4402 4384 4445 4304 4343 4399 4452 4297 4406 4352 4483 4322 4354 4196 4271 4370 4367 4238 4452 4320 4389 4285 4392 4273 4431 4314 4317 4313 4293 4350 4279 4342 4349 4445 4245 4523 4261 4534 4322 4420 4362 4284 4267 4328 4475 4388 4332 4364 4429 4302 4562 4421 4331 4482 4489 4431 4404 4549 4514 4349 4601 4614 4561 4640 4570 4552 4511 4549 4667 4745 4666 4524 4551 4565 4472 4550 4471 4540 4510 4505 4509 4499 4595 4442 4549 4548 4516 4580 4616 4596 4580 4578 4579 4643 4616 4553 4439 4564 4706 4625 4433 4477 4519 4543 4521 4439 4516 4445 4492 4417 4593 4486 4420 4321 4546 4419 4355 4441 4382 4511 4479 4434 4317 4434 4483 4453 4401 4412 4251 4393 4486 4430 4393 4394 4482 4382 4489 4473 4397 4313 4455 4446 4510 4431 4439 4539 4579 4505 4435 4476 4457 4545 4484 4361 4425 4426 4541 4507 4409 4483 4439 4564 4565 4434 4552 4426 4451 4636 4530 4637 4603 4708 4498 4677 4722 4812 4771 4811 4873 4828 4789 4780 4863 4708 4781 4715 4748 4605 4629 4613 4629 4535 4622 4504 4529 4482 4410 4494 4526 4536 4400 4496 4534 4450 4486 4589 4636 4611 4525 4510 4587 4531 4556 4531 4509 4367 4340 4424 4446 4407 4326 4510 4444 4317 4424 4340 4489 4547 4364 4397 4484 4297 4379 4334 4343 4426 4372 4212 4317 4463 4415 4477 4320 4334 4493 4327 4396 4254 4240 4287 4202 4283 4343 4412 4448 4212 4330 4378 4318 4442 4304 4197 4358 4254 4377 4412 4357 4328 4293 4281 4354 4258 4370 4351 4337 4470 4256 4344 4204 4309 4401 4430 4437 4305 4439 4368 4479 4355 4346 4358 4576 4416 4373 4328 4344 4442 4374 4376 4374 4373 4439 4401 4425 4373 4379 4318 4268 4477 4433 4378 4376 4355 4382 4486 4307 4355 4325 4409 4489 4392 4542 4388 4418 4282 4402 4298 4365 4330 4353 4441 4286 4276 4212 4423 4280 4304 4445 4220 4287 4366 4338 4416 4367 4294 4461 4309 4366 4295 4399 4328 4257 4294 4359 4302 4362 4379 4311 4363 4422 4312 4415 4310 4312 4288 4422 4343 4349 4417 4424 4339 4393 4295 4379 4419 4267 4365 4514 4263 4441 4393 4343 4456 4469 4417 4422 4474 4401 4446 4470 4540 4513 4508 4540 4651 4650 4657 4675 4667 4764 4653 4864 4838 4800 4896 4936 4994 4984 4830 4861 4749 4733 4806 4601 4731 4691 4622 4618 4601 4433 4631 4694 4631 4686 4583 4548 4723 4520 4599 4619 4602 4698 4655 4704 4786 4594 4673 4650 4659 4554 4640 4484 4521 4517 4581 4603 4593 4520 4586 4503 4380 4437 4523 4397 4258 4391 4417 4464 4371 4490 4314 4381 4477 4386 4306 4459 4430 4425 4323 4504 4324 4448 4321 4361 4380 4342 4485 4414 4429 4409 4421 4383 4485 4456 4312 4310 4348 4415 4395 4391 4320 4254 4306 4387 4431 4434 4475 4416 4395 4422 4498 4411 4381 4447 4540 4548 4472 4471 4576 4615 4675 4578 4727 4685 4778 4745 4885 4796 4810 4673 4639 4711 4657 4630 4626 4744 4547 4687 4612 4606 4519 4572 4487 4430 4441 4573 4587 4627 4495 4639 4541 4485 4674 4679 4547 4789 4590 4742 4593 4731 4703 4563 4626 4621 4621 4692 4660 4604 4543 4468 4642 4536 4486 4414 4491 4447 4574 4502 4466 4684 4387 4532 4480 4517 4362 4496 4322 4497 4439 4356 4334 4472 4424 4395 4356 4503 4394 4481 4437 4386 4460 4491 4427</counts>
			</dataPoints>
		</scan>
	</xrdMeasurement>
</xrdMeasurements>