File: dataset/precursor_mixture/V2O5_0p1012-In2O3_0p2008-TiO2_0p7001--2min.xrdml
<?xml version="1.0"?>
<xrdMeasurements xmlns="http://www.xrdml.com/XRDMeasurement/2.3" xmlns:xsi="http://www.w3.org/2001/XMLSchema-instance" xsi:schemaLocation="http://www.xrdml.com/XRDMeasurement/2.3 http://www.xrdml.com/XRDMeasurement/2.3/XRDMeasurement.xsd" status="Completed" recordIdentifier="{080C5580-290B-4923-A09B-AB5F1C4A7BBC}">
	<comment>
		<entry/>
	</comment>
	<sample type="To be analyzed">
		<id>V2O5_0p1012-In2O3_0p2008-TiO2_0p7001--2min</id>
		<name></name>
		<preparedBy></preparedBy>
	</sample>
	<xrdMeasurement measurementType="Scan" status="Completed" sampleMode="Reflection">
		<usedWavelength intended="K-Alpha 1">
			<kAlpha1 unit="Angstrom">1.5405980</kAlpha1>
			<kAlpha2 unit="Angstrom">1.5444260</kAlpha2>
			<kBeta unit="Angstrom">1.3922500</kBeta>
			<ratioKAlpha2KAlpha1>0.5000</ratioKAlpha2KAlpha1>
		</usedWavelength>
		<incidentBeamPath>
			<radius unit="mm">145.00</radius>
			<xRayTube id="1010048" name="Empyrean Cu LFF HR (9430 033 7310x)">
				<tension unit="kV">40.0</tension>
				<current unit="mA">15.0</current>
				<anodeMaterial>Cu</anodeMaterial>
				<focus type="Line">
					<length unit="mm">12.0</length>
					<width unit="mm">0.4</width>
					<takeOffAngle unit="deg">6.0</takeOffAngle>
				</focus>
			</xRayTube>
			<sollerSlit id="21010002" name="Soller slits 0.04 rad.">
				<opening unit="rad">0.0400</opening>
			</sollerSlit>
			<mask id="22031000" name="Fixed mask 13 mm">
				<width unit="mm">9.00</width>
			</mask>
			<divergenceSlit id="22120001" name="Divergence slit 1°" xsi:type="fixedDivergenceSlitType">
				<distanceToSample unit="mm">50.00</distanceToSample>
				<height unit="mm">1.52</height>
			</divergenceSlit>
		</incidentBeamPath>
		<sampleMovement xsi:type="spinningSampleMovementType">
			<spinnerRevolutionTime unit="seconds">1.0</spinnerRevolutionTime>
		</sampleMovement>
		<diffractedBeamPath>
			<radius unit="mm">145.00</radius>
			<antiScatterSlit id="22090040" name="AS slit 9 mm (PIXcel)" xsi:type="fixedAntiScatterSlitType">
				<height unit="mm">9.00</height>
			</antiScatterSlit>
			<sollerSlit id="21020003" name="Large Soller slits 0.04 rad.">
				<opening unit="rad">0.0400</opening>
			</sollerSlit>
			<filter id="20030001" name="Large beta-filter Nickel">
				<material>Ni</material>
				<thickness unit="mm">0.020</thickness>
			</filter>
			<detector id="7010019" name="PIXcel1D-Medipix3 detector" xsi:type="rtmsDetectorType">
				<phd unit="keV">
					<lowerLevel>4.02</lowerLevel>
					<upperLevel>11.27</upperLevel>
				</phd>
				<mode>Scanning</mode>
				<activeLength unit="deg">5.542</activeLength>
			</detector>
		</diffractedBeamPath>
		<scan appendNumber="0" mode="Continuous" scanAxis="Gonio" status="Completed">
			<header>
				<startTimeStamp>2024-11-14T15:07:29-08:00</startTimeStamp>
				<endTimeStamp>2024-11-14T15:09:34-08:00</endTimeStamp>
				<author>
					<name>AutomatedUser</name>
				</author>
				<source>
					<applicationSoftware version="1.7b (136)">PANalytical Aeris Instrument Suite</applicationSoftware>
					<instrumentControlSoftware version="3.2.00000000 20240306">AERIS</instrumentControlSoftware>
					<instrumentID>950485</instrumentID>
				</source>
			</header>
			<dataPoints>
				<positions axis="2Theta" unit="deg">
					<startPosition>10.02173288</startPosition>
					<endPosition>99.99585608</endPosition>
				</positions>
				<positions axis="Omega" unit="deg">
					<startPosition>5.01086644</startPosition>
					<endPosition>49.99792804</endPosition>
				</positions>
				<commonCountingTime unit="seconds">10.965</commonCountingTime>
				<counts unit="counts">2034 1962 2046 1960 1967 1924 2009 1833 1878 1984 1870 1900 1790 1866 1820 1944 1888 1841 1893 1815 1803 1735 1805 1807 1699 1779 1773 1767 1675 1634 1712 1657 1647 1666 1639 1575 1551 1560 1576 1591 1584 1603 1565 1637 1597 1653 1562 1587 1493 1491 1422 1541 1492 1517 1569 1468 1577 1435 1462 1469 1439 1496 1381 1416 1394 1456 1394 1354 1351 1381 1383 1354 1288 1303 1340 1427 1390 1242 1377 1314 1325 1315 1304 1276 1279 1256 1223 1314 1215 1319 1262 1265 1257 1204 1278 1250 1241 1253 1212 1268 1156 1267 1300 1217 1223 1186 1179 1222 1183 1178 1223 1136 1283 1209 1172 1129 1155 1189 1127 1103 1213 1201 1192 1195 1227 1239 1264 1229 1183 1253 1125 1128 1103 1082 1125 1115 1071 1075 1108 1083 1111 1076 1179 1084 1126 1062 1065 1087 1087 1084 1096 1085 1059 992 1074 1118 1069 1037 1061 1072 1048 1086 1042 1055 1062 1045 1103 1049 973 1075 1099 1038 1067 1045 1081 1074 985 1012 1022 1033 1066 1027 1003 1025 984 1040 1019 937 993 990 1048 966 930 970 907 989 961 981 945 1018 949 940 974 957 898 993 937 946 949 918 964 929 900 894 918 921 965 945 884 872 873 922 933 965 866 825 879 892 868 936 904 917 940 1011 1088 1116 1196 1310 1308 1434 1481 1240 1148 1021 961 923 895 903 834 814 875 912 844 905 847 833 852 884 861 785 915 939 978 1028 1117 1202 1336 1359 1406 1298 1140 1087 1025 1011 959 857 857 858 862 812 773 769 830 751 787 834 805 818 804 809 827 764 805 833 791 802 812 784 756 805 774 785 783 764 763 770 715 720 706 745 769 708 727 822 766 751 768 718 766 772 723 727 684 721 678 708 779 747 699 739 743 703 736 743 768 767 723 847 817 749 866 866 835 845 982 1016 1158 1274 1666 2288 3058 4087 5233 6677 7984 8655 8005 5942 4015 2474 1710 1334 1175 909 899 834 853 820 826 811 793 853 890 956 1003 1013 885 885 801 754 645 672 702 686 682 658 648 687 706 692 684 621 659 628 635 674 673 614 677 672 641 674 739 711 729 668 711 633 672 598 666 622 675 639 580 635 623 626 652 585 586 599 611 574 606 586 631 629 642 572 597 593 664 610 583 568 567 596 585 554 570 546 559 626 593 547 545 588 604 582 591 661 608 583 665 629 580 603 605 652 672 680 663 641 707 703 733 817 922 1004 1244 1596 2235 2981 4189 5384 6430 6125 4995 3719 2372 1656 1210 1062 961 1021 1024 945 899 842 687 683 629 578 576 606 598 571 582 587 551 582 523 480 575 547 588 529 521 479 518 552 527 517 549 626 613 656 675 652 651 597 506 504 519 550 508 492 549 503 561 534 575 576 584 614 557 542 587 580 510 469 561 495 472 481 467 491 445 460 457 481 465 493 506 480 497 471 532 543 552 601 647 590 630 592 536 527 470 476 462 480 472 546 511 500 471 511 510 552 564 589 696 694 855 1159 1454 1851 2119 2240 1974 1599 1168 850 652 586 558 469 488 533 490 482 476 549 531 503 458 419 403 443 445 461 490 460 488 438 489 467 535 591 653 861 892 1008 917 840 749 655 549 555 461 473 523 563 565 612 739 880 1158 1494 1914 2393 2552 2508 2254 1682 1332 906 701 582 521 508 469 506 508 483 555 651 814 962 1038 1069 920 725 589 535 457 396 364 410 390 416 413 387 439 422 368 381 383 386 393 401 377 380 417 445 401 482 458 484 427 448 438 394 380 379 404 376 358 347 371 374 384 380 369 357 393 354 365 348 374 361 384 369 364 378 356 389 385 436 409 469 498 476 469 464 410 392 389 382 417 410 477 586 602 660 677 671 600 528 486 432 422 388 396 346 385 364 366 354 349 357 339 332 355 320 333 354 350 344 317 343 373 374 343 373 336 349 319 329 332 360 361 336 311 338 338 344 380 358 370 386 362 376 380 331 357 328 374 379 363 350 367 289 345 347 365 332 344 347 317 325 333 363 331 342 359 310 316 325 330 372 340 377 341 389 376 431 443 488 526 611 729 897 899 859 789 676 561 456 390 368 327 348 336 341 327 351 291 356 355 336 335 336 283 336 359 325 340 344 337 304 348 362 307 328 324 308 357 375 397 408 476 423 419 411 443 406 424 407 535 507 622 772 1022 1468 2188 2882 3309 3115 2628 2203 1603 1138 702 600 399 416 421 418 364 367 372 362 366 371 432 404 414 377 334 348 411 394 412 479 493 568 482 433 455 393 382 331 353 350 353 334 327 309 333 310 338 329 361 333 322 315 357 302 357 333 341 372 361 372 412 395 427 400 552 631 748 1016 1426 2083 2582 2524 2309 2008 1757 1233 946 692 595 471 420 383 368 377 383 376 365 327 339 327 340 363 360 356 345 317 325 374 330 309 322 339 395 317 366 338 338 371 431 427 427 452 384 393 394 342 290 313 339 363 299 333 344 332 329 344 374 338 346 449 436 552 645 839 1244 1715 2067 2105 1982 1688 1362 1096 809 581 456 454 465 409 429 381 368 381 390 376 359 410 397 456 492 601 783 1119 1525 1991 2032 1862 1632 1472 1094 824 556 491 417 415 394 380 380 395 392 402 347 403 468 608 603 645 522 564 463 466 385 367 347 329 332 301 252 286 293 326 311 308 280 284 314 284 261 278 269 321 304 272 280 262 309 316 287 314 334 344 338 368 347 310 333 305 339 300 296 274 304 252 282 272 287 279 252 279 304 271 282 323 284 311 315 304 307 311 305 308 316 314 319 366 367 479 583 568 502 493 424 395 380 359 335 371 300 300 298 293 292 276 261 312 306 283 294 286 333 319 316 331 335 366 410 374 414 487 576 735 1189 1685 1958 1796 1497 1364 1242 1024 805 579 539 464 377 393 414 322 335 345 328 328 293 271 312 312 314 295 298 299 319 330 340 401 407 561 725 841 982 957 894 782 786 653 621 614 546 588 820 1095 1505 1709 1470 1253 1184 1046 908 608 482 424 371 334 321 275 313 292 280 272 317 300 369 450 492 581 552 474 469 458 407 380 320 274 281 298 301 271 302 281 291 271 274 273 281 326 259 290 307 280 295 235 294 286 283 267 270 305 389 403 372 302 333 341 317 334 252 233 253 258 248 246 274 242 253 257 238 290 286 279 281 281 276 283 277 267 246 295 278 270 291 283 343 305 308 291 335 309 298 266 303 262 261 265 258 246 283 252 252 248 243 252 257 270 271 258 255 248 259 285 273 299 283 363 359 417 389 395 335 370 385 367 351 324 316 302 341 387 387 485 552 740 806 817 773 651 593 658 567 441 379 322 310 284 296 278 305 337 389 353 313 345 323 340 346 331 292 296 298 292 287 332 351 344 423 484 663 916 949 813 681 609 625 580 487 388 308 306 256 247 264 264 241 253 239 254 255 231 259 230 257 256 261 231 244 243 222 255 257 244 242 228 286 229 258 227 236 256 253 244 248 259 281 275 303 268 242 240 238 276 270 261 282 246 243 272 293 236 248 236 236 227 225 227 238 232 225 240 261 239 267 264 277 320 366 362 339 296 279 313 304 310 301 307 328 313 291 269 276 306 292 282 272 304 272 285 309 302 329 319 361 397 429 532 609 988 1267 1386 1289 1035 880 945 936 829 592 495 337 315 302 310 254 238 293 312 281 260 309 356 458 612 530 461 418 386 470 460 484 511 452 409 387 347 350 352 368 288 236 263 277 226 255 242 254 207 232 225 231 221 243 213 240 271 252 249 262 247 286 279 328 371 296 303 273 298 297 286 268 271 268 282 207 225 248 252 254 244 250 222 229 234 238 228 222 230 223 242 229 260 285 312 368 331 335 300 286 293 294 274 267 243 195 233 219 221 221 226 212 256 241 220 226 220 229 212 234 228 232 251 231 269 261 305 311 307 262 295 282 295 297 279 260 245 248 241 231 248 232 243 228 267 267 257 230 228 241 229 252 258 251 282 283 373 426 459 377 341 303 358 376 385 383 312 360 288 323 305 298 322 335 403 502 656 687 695 620 507 507 563 579 588 563 618 740 837 775 659 550 475 524 560 535 403 332 255 242 261 251 261 242 220 236 212 232 241 253 215 227 218 227 243 230 232 229 240 244 238 230 244 230 232 211 249 232 222 200 205 220 237 227 230 215 232 245 243 232 242 272 230 273 277 292 297 328 393 530 493 439 348 360 334 385 393 349 280 255 292 240 226 246 247 238 229 224 216 234 207 205 237 249 230 237 232 240 240 273 260 264 243 241 246 253 232 261 225 223 196 232 209 219 222 203 225 243 231 196 212 203 208 210 185 215 240 203 216 254 251 275 252 243 247 230 236 218 239 265 234 224 213 227 232 215 203 206 209 200 203 215 210 199 219 246 234 198 235 283 304 363 364 279 280 259 236 253 281 287 245 231 244 235 222 215 222 210 197 223 211 219 217 240 249 219 260 234 257 230 255 228 235 237 201 238 195 224 208 235 208 219 199 228 211 214 206 217 220 236 219 204 188 251 208 257 225 221 225 263 268 275 369 317 306 276 261 290 301 270 314 254 213 220 276 249 242 245 269 266 288 280 280 221 246 216 268 234 243 237 231 234 254 210 240 228 213 238 282 316 351 421 449 434 391 347 304 299 321 367 335 333 275 241 247 267 234 295 243 279 323 409 430 551 637 604 446 434 369 392 392 443 391 347 352 288 278 264 222 219 247 239 255 248 242 249 240 249 214 276 269 273 383 413 446 429 345 344 283 283 331 362 317 281 279 268 205 256 207 218 211 228 222 208 220 250 243 245 217 247 242 268 267 280 327 358 360 322 296 257 269 302 313 345 333 379 360 382 368 340 288 283 294 271 291 317 321 248 244 243 231 259 241 247 292 318 325 304 267 234 261 283 253 275 274 290 258 249 265 290 312 339 311 274</counts>
			</dataPoints>
		</scan>
	</xrdMeasurement>
</xrdMeasurements>