File: dataset/precursor_mixture/V2O5_0p7006-MnCO3_0p3001--8min.xrdml
<?xml version="1.0"?>
<xrdMeasurements xmlns="http://www.xrdml.com/XRDMeasurement/2.3" xmlns:xsi="http://www.w3.org/2001/XMLSchema-instance" xsi:schemaLocation="http://www.xrdml.com/XRDMeasurement/2.3 http://www.xrdml.com/XRDMeasurement/2.3/XRDMeasurement.xsd" status="Completed" recordIdentifier="{59D0FE89-675A-4157-813A-E47FDB756484}">
	<comment>
		<entry/>
	</comment>
	<sample type="To be analyzed">
		<id>V2O5_0p7006-MnCO3_0p3001--8min</id>
		<name></name>
		<preparedBy></preparedBy>
	</sample>
	<xrdMeasurement measurementType="Scan" status="Completed" sampleMode="Reflection">
		<usedWavelength intended="K-Alpha 1">
			<kAlpha1 unit="Angstrom">1.5405980</kAlpha1>
			<kAlpha2 unit="Angstrom">1.5444260</kAlpha2>
			<kBeta unit="Angstrom">1.3922500</kBeta>
			<ratioKAlpha2KAlpha1>0.5000</ratioKAlpha2KAlpha1>
		</usedWavelength>
		<incidentBeamPath>
			<radius unit="mm">145.00</radius>
			<xRayTube id="1010048" name="Empyrean Cu LFF HR (9430 033 7310x)">
				<tension unit="kV">40.0</tension>
				<current unit="mA">15.0</current>
				<anodeMaterial>Cu</anodeMaterial>
				<focus type="Line">
					<length unit="mm">12.0</length>
					<width unit="mm">0.4</width>
					<takeOffAngle unit="deg">6.0</takeOffAngle>
				</focus>
			</xRayTube>
			<sollerSlit id="21010002" name="Soller slits 0.04 rad.">
				<opening unit="rad">0.0400</opening>
			</sollerSlit>
			<mask id="22031000" name="Fixed mask 13 mm">
				<width unit="mm">9.00</width>
			</mask>
			<divergenceSlit id="22120001" name="Divergence slit 1°" xsi:type="fixedDivergenceSlitType">
				<distanceToSample unit="mm">50.00</distanceToSample>
				<height unit="mm">1.52</height>
			</divergenceSlit>
		</incidentBeamPath>
		<sampleMovement xsi:type="spinningSampleMovementType">
			<spinnerRevolutionTime unit="seconds">1.0</spinnerRevolutionTime>
		</sampleMovement>
		<diffractedBeamPath>
			<radius unit="mm">145.00</radius>
			<antiScatterSlit id="22090040" name="AS slit 9 mm (PIXcel)" xsi:type="fixedAntiScatterSlitType">
				<height unit="mm">9.00</height>
			</antiScatterSlit>
			<sollerSlit id="21020003" name="Large Soller slits 0.04 rad.">
				<opening unit="rad">0.0400</opening>
			</sollerSlit>
			<filter id="20030001" name="Large beta-filter Nickel">
				<material>Ni</material>
				<thickness unit="mm">0.020</thickness>
			</filter>
			<detector id="7010019" name="PIXcel1D-Medipix3 detector" xsi:type="rtmsDetectorType">
				<phd unit="keV">
					<lowerLevel>4.02</lowerLevel>
					<upperLevel>11.27</upperLevel>
				</phd>
				<mode>Scanning</mode>
				<activeLength unit="deg">5.542</activeLength>
			</detector>
		</diffractedBeamPath>
		<scan appendNumber="0" mode="Continuous" scanAxis="Gonio" status="Completed">
			<header>
				<startTimeStamp>2024-11-14T14:08:36-08:00</startTimeStamp>
				<endTimeStamp>2024-11-14T14:16:43-08:00</endTimeStamp>
				<author>
					<name>AutomatedUser</name>
				</author>
				<source>
					<applicationSoftware version="1.7b (136)">PANalytical Aeris Instrument Suite</applicationSoftware>
					<instrumentControlSoftware version="3.2.00000000 20240306">AERIS</instrumentControlSoftware>
					<instrumentID>950485</instrumentID>
				</source>
			</header>
			<dataPoints>
				<positions axis="2Theta" unit="deg">
					<startPosition>10.00943322</startPosition>
					<endPosition>99.99442286</endPosition>
				</positions>
				<positions axis="Omega" unit="deg">
					<startPosition>5.00471661</startPosition>
					<endPosition>49.99721143</endPosition>
				</positions>
				<commonCountingTime unit="seconds">12.495</commonCountingTime>
				<counts unit="counts">2523 2535 2509 2463 2386 2505 2509 2493 2542 2442 2519 2493 2474 2508 2399 2402 2471 2528 2474 2436 2577 2514 2502 2455 2471 2356 2394 2518 2329 2451 2335 2348 2489 2383 2435 2462 2424 2402 2349 2364 2373 2361 2320 2474 2255 2375 2350 2403 2365 2407 2402 2389 2395 2328 2339 2260 2410 2373 2352 2368 2345 2243 2346 2343 2325 2385 2253 2253 2340 2450 2254 2292 2205 2376 2297 2288 2298 2321 2378 2361 2350 2211 2263 2254 2238 2261 2176 2299 2250 2287 2205 2253 2258 2258 2202 2294 2184 2293 2253 2239 2216 2295 2222 2195 2279 2263 2246 2170 2197 2148 2178 2111 2199 2182 2087 2199 2105 2225 2154 2126 2157 2176 2177 2267 2197 2248 2172 2136 2241 2147 2130 2168 2148 2194 2122 2179 2179 2158 2134 2197 2092 2162 2133 2176 2077 2059 2161 2149 2131 2193 2176 2106 2055 2025 2079 2124 2118 1990 2148 2023 2076 2064 2188 2102 2054 2085 2070 2053 2067 2124 2149 2087 2117 2107 2047 2065 2046 2062 2104 2102 2048 1994 2119 2004 1998 2028 2028 2053 2045 1964 2012 2063 1985 1966 1964 1967 2037 1989 2109 1990 1931 1995 1959 2009 1973 1897 1973 1975 2016 2081 1938 1982 1911 2011 1993 1944 1942 1940 1921 1946 1999 1904 2002 1941 1955 1949 1957 1994 1993 1951 1992 2008 1965 1889 1920 1969 1915 1958 1935 1911 1895 1827 1877 1937 2024 1889 1879 1889 1975 1887 1987 1923 1913 1930 1926 1863 1796 1873 1866 1941 1808 1909 1952 1871 1895 1849 1983 1859 1905 1883 1904 1827 1840 1905 1854 1912 1837 1906 1834 1791 1824 1868 1854 1853 1864 1871 1887 1806 1859 1829 1806 1829 1835 1803 1832 1851 1857 1838 1824 1859 1865 1831 1793 1848 1883 1865 1783 1799 1851 1852 1796 1883 1835 1746 1829 1793 1778 1787 1818 1803 1841 1809 1773 1764 1788 1717 1875 1701 1824 1827 1794 1757 1805 1777 1822 1775 1827 1855 1727 1788 1724 1777 1732 1732 1749 1820 1725 1844 1762 1787 1781 1718 1832 1797 1701 1754 1819 1773 1704 1762 1816 1823 1695 1804 1797 1709 1717 1720 1853 1723 1812 1723 1738 1745 1832 1802 1742 1772 1747 1748 1741 1753 1809 1776 1735 1726 1687 1818 1694 1778 1715 1792 1793 1717 1711 1743 1691 1731 1754 1708 1797 1770 1718 1690 1731 1789 1727 1746 1684 1781 1673 1782 1727 1733 1771 1663 1719 1728 1854 1842 1757 1720 1721 1764 1731 1694 1758 1600 1730 1646 1853 1683 1707 1636 1643 1666 1768 1706 1745 1732 1720 1840 1676 1753 1770 1762 1699 1799 1706 1749 1770 1787 1792 1799 1802 1769 1776 1801 1776 1727 1734 1749 1788 1762 1825 1803 1842 1797 1812 1900 1967 1956 1975 2033 2006 2042 2088 2150 2136 2168 2280 2359 2331 2358 2465 2456 2506 2617 2591 2635 2641 2587 2648 2708 2666 2548 2547 2576 2550 2442 2500 2482 2429 2396 2355 2291 2326 2326 2265 2134 2290 2232 2146 2017 1982 1908 1903 1914 1881 1783 1831 1768 1657 1773 1764 1709 1709 1719 1729 1700 1706 1723 1629 1645 1735 1710 1654 1656 1736 1549 1678 1680 1693 1719 1705 1725 1704 1591 1647 1733 1695 1641 1612 1704 1671 1635 1672 1626 1665 1592 1655 1700 1618 1630 1595 1663 1691 1638 1588 1651 1727 1593 1687 1677 1575 1597 1626 1613 1677 1722 1662 1602 1680 1618 1648 1713 1570 1629 1636 1599 1606 1706 1556 1643 1619 1644 1677 1562 1592 1652 1574 1604 1566 1551 1617 1602 1636 1544 1582 1569 1605 1601 1688 1543 1552 1593 1658 1612 1662 1584 1561 1609 1627 1622 1653 1523 1586 1600 1589 1603 1618 1626 1516 1579 1606 1599 1646 1633 1559 1655 1687 1568 1654 1665 1552 1638 1543 1576 1618 1659 1603 1613 1588 1590 1636 1514 1579 1549 1523 1612 1542 1612 1508 1595 1532 1597 1664 1623 1658 1633 1590 1541 1599 1564 1574 1509 1612 1571 1559 1548 1584 1585 1561 1559 1492 1563 1603 1602 1636 1532 1572 1586 1558 1600 1497 1597 1534 1495 1600 1533 1612 1578 1611 1568 1655 1558 1648 1570 1643 1568 1625 1524 1535 1514 1556 1561 1505 1527 1534 1534 1514 1574 1594 1515 1526 1429 1593 1506 1556 1540 1486 1560 1494 1498 1511 1484 1547 1530 1595 1511 1553 1528 1563 1563 1527 1504 1558 1490 1549 1569 1605 1666 1612 1572 1622 1596 1508 1512 1553 1619 1506 1520 1498 1564 1524 1569 1517 1553 1583 1590 1560 1503 1521 1602 1503 1569 1543 1580 1481 1421 1512 1502 1516 1497 1467 1499 1564 1551 1588 1447 1568 1550 1480 1530 1583 1507 1552 1445 1516 1502 1633 1515 1549 1530 1553 1546 1474 1548 1483 1482 1509 1477 1500 1568 1504 1510 1496 1556 1546 1560 1492 1566 1428 1504 1408 1554 1501 1479 1499 1511 1573 1450 1432 1513 1487 1514 1552 1480 1469 1487 1543 1463 1464 1502 1423 1538 1503 1507 1462 1528 1496 1470 1450 1494 1488 1490 1497 1536 1558 1556 1513 1539 1527 1489 1476 1515 1547 1492 1504 1485 1453 1456 1503 1547 1502 1497 1536 1546 1596 1565 1491 1595 1589 1596 1617 1546 1669 1587 1621 1559 1569 1582 1592 1636 1700 1654 1637 1659 1652 1666 1664 1633 1751 1683 1716 1753 1851 1892 1881 1889 1866 1876 1949 2040 2052 2157 2173 2245 2309 2417 2456 2636 2854 3018 3052 3227 3529 3621 3826 4139 4439 4650 4991 5181 5831 6115 6343 6610 6988 7167 7519 7793 8121 8452 8512 8517 8703 8516 8429 8514 8231 7850 7739 7237 7343 7025 6683 6287 6145 5918 5685 5384 5218 4849 4608 4352 4021 3637 3363 3181 2871 2710 2472 2445 2257 2138 2050 1990 1921 1889 1861 1779 1800 1766 1743 1690 1721 1703 1634 1587 1647 1648 1621 1617 1599 1575 1533 1595 1613 1554 1544 1534 1593 1580 1591 1545 1460 1499 1533 1575 1457 1552 1547 1469 1485 1521 1480 1503 1505 1489 1594 1573 1404 1531 1523 1506 1468 1570 1498 1563 1507 1509 1392 1552 1468 1497 1573 1543 1575 1543 1576 1562 1517 1551 1581 1563 1660 1685 1610 1676 1696 1673 1696 1682 1798 1831 1929 1963 1994 2025 2118 2126 2293 2302 2500 2527 2633 2637 2805 2896 2972 2961 3136 3164 3209 3410 3224 3442 3417 3253 3339 3327 3200 3219 3105 3083 2948 2883 2797 2762 2762 2604 2574 2486 2382 2401 2282 2223 2115 1993 1856 1872 1908 1792 1693 1689 1580 1622 1599 1521 1576 1507 1534 1571 1556 1526 1545 1408 1468 1505 1444 1497 1445 1497 1439 1464 1398 1505 1425 1419 1446 1460 1465 1354 1384 1427 1368 1403 1338 1398 1383 1408 1356 1388 1366 1408 1383 1371 1353 1374 1389 1418 1452 1468 1349 1333 1346 1331 1319 1360 1369 1343 1329 1410 1338 1348 1289 1410 1296 1417 1456 1326 1369 1363 1350 1332 1371 1412 1341 1350 1423 1339 1387 1308 1281 1361 1329 1288 1343 1331 1331 1408 1305 1288 1279 1282 1315 1395 1364 1397 1325 1305 1271 1382 1347 1285 1375 1391 1339 1322 1341 1354 1263 1339 1350 1364 1316 1302 1342 1368 1336 1325 1291 1310 1302 1412 1302 1352 1409 1348 1398 1313 1357 1272 1296 1233 1320 1414 1338 1336 1295 1320 1330 1353 1327 1342 1380 1344 1334 1351 1362 1367 1361 1396 1367 1344 1371 1319 1263 1292 1332 1310 1332 1356 1356 1355 1384 1346 1379 1370 1433 1397 1376 1349 1332 1442 1428 1321 1328 1318 1479 1454 1446 1438 1445 1572 1443 1513 1518 1489 1614 1525 1627 1646 1604 1646 1670 1765 1714 1791 1797 1810 1845 1926 1850 1921 1839 1865 1839 1790 1818 1837 1770 1787 1808 1775 1820 1672 1741 1732 1723 1638 1600 1699 1554 1562 1487 1536 1475 1467 1380 1447 1365 1386 1401 1387 1326 1421 1367 1334 1378 1317 1384 1328 1273 1310 1312 1293 1341 1329 1346 1334 1293 1338 1286 1309 1293 1339 1281 1311 1257 1232 1281 1227 1265 1206 1241 1341 1310 1338 1299 1312 1211 1220 1193 1254 1271 1223 1238 1296 1239 1258 1240 1296 1287 1258 1305 1266 1278 1259 1239 1290 1271 1264 1315 1237 1244 1320 1257 1235 1320 1228 1282 1307 1291 1337 1321 1224 1368 1370 1339 1297 1359 1262 1344 1346 1388 1371 1296 1420 1457 1412 1449 1459 1473 1456 1491 1440 1508 1490 1533 1537 1538 1530 1507 1480 1481 1496 1499 1519 1493 1581 1538 1397 1417 1465 1434 1415 1369 1380 1442 1370 1417 1440 1394 1380 1428 1451 1432 1434 1514 1568 1571 1627 1630 1746 1756 1823 1881 1951 2081 2098 2179 2328 2408 2505 2679 2812 2949 2969 3172 3324 3301 3536 3471 3460 3553 3624 3542 3437 3415 3406 3375 3205 3138 3088 2911 2842 2865 2640 2681 2579 2510 2435 2204 2130 2007 1881 1709 1757 1651 1608 1533 1419 1468 1396 1458 1354 1329 1344 1291 1263 1296 1284 1308 1245 1264 1326 1294 1256 1243 1331 1203 1257 1250 1201 1185 1278 1216 1217 1204 1200 1224 1243 1196 1220 1171 1161 1222 1201 1245 1147 1159 1144 1222 1227 1243 1205 1189 1243 1192 1165 1145 1219 1203 1154 1167 1260 1215 1238 1134 1250 1165 1178 1220 1177 1256 1120 1233 1184 1227 1152 1134 1179 1219 1171 1228 1188 1132 1135 1192 1131 1178 1146 1193 1203 1156 1243 1171 1209 1250 1217 1111 1177 1147 1169 1170 1165 1118 1145 1149 1234 1145 1238 1120 1229 1136 1188 1175 1179 1114 1136 1206 1124 1193 1125 1226 1158 1115 1200 1132 1130 1144 1125 1222 1210 1138 1165 1175 1151 1126 1140 1147 1182 1195 1124 1201 1191 1151 1193 1163 1124 1126 1177 1132 1208 1170 1158 1170 1156 1185 1169 1204 1183 1186 1121 1122 1135 1160 1126 1167 1147 1163 1180 1177 1186 1131 1157 1148 1182 1074 1109 1183 1134 1195 1150 1177 1188 1176 1191 1176 1136 1157 1150 1173 1154 1178 1155 1242 1133 1138 1139 1174 1149 1129 1204 1161 1179 1113 1141 1169 1056 1225 1123 1131 1128 1151 1133 1182 1142 1200 1109 1166 1175 1201 1100 1135 1138 1130 1118 1137 1099 1132 1203 1149 1165 1176 1122 1133 1186 1183 1145 1092 1150 1142 1151 1214 1137 1162 1142 1122 1155 1173 1094 1152 1133 1090 1160 1176 1081 1140 1166 1066 1175 1116 1200 1089 1087 1185 1149 1169 1144 1190 1205 1107 1155 1145 1160 1119 1109 1068 1161 1103 1106 1143 1161 1158 1199 1144 1112 1120 1130 1077 1137 1098 1181 1150 1136 1130 1075 1117 1188 1075 1157 1158 1164 1106 1095 1157 1126 1176 1101 1132 1189 1203 1143 1106 1200 1130 1081 1068 1106 1110 1118 1119 1157 1138 1109 1162 1099 1129 1144 1110 1170 1114 1147 1199 1124 1184 1112 1120 1186 1161 1140 1112 1171 1179 1133 1085 1109 1108 1154 1239 1211 1115 1149 1198 1162 1089 1148 1166 1172 1196 1176 1220 1198 1167 1217 1187 1244 1191 1203 1251 1177 1188 1171 1214 1200 1215 1199 1237 1180 1170 1236 1205 1184 1172 1227 1259 1189 1296 1208 1235 1261 1260 1289 1303 1231 1320 1295 1344 1322 1322 1365 1391 1446 1452 1461 1543 1599 1602 1614 1607 1774 1808 1742 1941 2053 2151 2243 2380 2499 2602 2730 2874 3143 3261 3376 3465 3631 3647 3843 3972 4087 4099 4198 4242 4225 4276 4274 4244 4198 4346 4114 4158 4071 4026 3951 3854 3871 3982 3881 3780 3704 3800 3536 3644 3749 3634 3714 3667 3643 3706 3531 3439 3526 3364 3445 3287 3205 3257 3093 3037 2890 2803 2827 2760 2617 2545 2370 2323 2347 2166 2011 1911 1938 1785 1732 1701 1650 1546 1615 1543 1431 1476 1372 1433 1368 1406 1331 1416 1267 1267 1296 1317 1277 1246 1224 1186 1348 1250 1214 1228 1240 1216 1162 1126 1299 1150 1228 1196 1236 1248 1152 1261 1202 1222 1174 1238 1230 1294 1259 1266 1251 1284 1281 1343 1360 1321 1320 1290 1351 1432 1531 1416 1476 1554 1639 1666 1803 1744 1905 1992 1975 2073 2143 2174 2227 2307 2239 2338 2422 2369 2384 2404 2418 2333 2211 2233 2224 2146 2084 2114 1965 2005 1879 1875 1767 1722 1692 1602 1524 1535 1422 1392 1386 1379 1282 1299 1268 1258 1175 1245 1257 1268 1180 1173 1182 1158 1192 1166 1199 1137 1112 1109 1098 1138 1140 1177 1121 1080 1144 1147 1157 1149 1153 1083 1091 1108 1061 1093 1125 1127 1089 1134 1179 1152 1161 1173 1164 1180 1166 1232 1213 1211 1223 1275 1289 1328 1296 1283 1368 1347 1478 1399 1442 1487 1476 1471 1447 1458 1444 1383 1452 1380 1420 1394 1442 1441 1365 1399 1293 1327 1359 1274 1270 1233 1234 1209 1209 1138 1177 1166 1147 1120 1095 1141 1087 1075 1133 1089 1112 1104 1123 1127 1089 1052 1123 1108 1059 1130 1133 1043 1085 1072 1086 1070 1093 1057 1113 1105 1033 1169 1161 1090 1047 1077 1124 1114 1051 1078 1060 1157 1133 1094 1226 1205 1168 1258 1232 1278 1240 1263 1313 1371 1467 1531 1554 1550 1672 1673 1761 1843 1817 1874 1962 2002 2066 2039 2032 2118 2036 2050 2056 2056 1964 1874 1908 1841 1911 1791 1768 1780 1654 1606 1579 1571 1557 1415 1398 1303 1296 1295 1241 1146 1191 1144 1113 1053 1111 1109 1059 1109 1099 1073 1035 1039 1065 1111 1036 1051 1093 1089 1057 1035 1011 1014 1050 1043 1018 1067 1034 1039 1047 1028 1051 1033 976 1028 1043 1090 1027 1025 1013 1002 1050 988 1071 1046 1018 1049 1036 980 1003 1006 1008 1050 992 1114 1069 975 1022 998 1029 1010 985 1045 1002 1015 1023 1023 988 1068 990 1024 1081 1049 984 1065 1003 1001 1037 1034 1061 1030 1017 1064 1014 1045 1008 1044 997 1020 1022 1036 963 1018 1051 1040 1037 1038 983 987 1055 961 1058 993 1043 980 1003 1046 991 1026 1049 1012 1060 1027 1036 1054 1020 1064 1056 1152 1042 1127 1067 1105 1099 1122 1101 1118 1186 1075 1209 1145 1145 1137 1171 1168 1157 1140 1123 1141 1224 1167 1170 1086 1192 1159 1093 1167 1046 1129 1084 1109 1053 1122 1046 1084 1064 1080 1073 1057 1036 993 1102 1019 1017 1057 1028 1007 987 1040 978 1029 1001 1042 1038 1013 1007 966 1028 1014 939 1055 969 980 965 1000 971 1017 1002 1006 1016 984 1001 1002 1011 1018 1037 948 1022 962 1004 1009 989 970 1003 984 958 1035 1054 1032 981 1028 993 990 1032 1020 1034 973 1027 1012 1029 1044 1019 1109 1041 1068 1074 1030 1054 1008 1063 1006 1089 1022 1066 1042 1056 1128 1061 1118 1121 1088 1158 1170 1175 1167 1199 1217 1268 1310 1329 1319 1386 1375 1381 1429 1499 1420 1495 1504 1501 1554 1461 1516 1495 1544 1598 1598 1524 1409 1439 1518 1462 1423 1334 1342 1295 1270 1305 1217 1290 1180 1238 1201 1198 1131 1127 1084 1091 1054 1117 1084 1054 1082 1000 1015 1020 960 999 1014 955 998 1005 1026 998 1022 996 994 1008 1025 946 1030 1009 970 963 968 984 1000 1008 969 1009 938 952 1007 970 985 936 1034 987 911 1008 989 1010 970 954 947 999 990 931 925 995 1013 1003 919 964 962 946 953 938 965 979 924 933 983 950 944 961 993 979 937 950 970 954 930 947 998 1048 919 1034 1040 966 991 960 942 984 937 991 961 935 947 946 908 948 978 953 900 939 976 948 979 1035 912 961 950 919 981 939 1031 969 960 950 957 991 963 966 1025 1046 947 977 938 990 956 975 959 985 909 943 950 968 967 994 985 991 896 950 964 1008 962 965 886 961 988 901 898 958 935 968 972 913 960 982 965 970 925 922 1017 924 949 908 966 1025 921 973 965 977 944 995 940 888 923 939 896 965 911 923 979 949 923 932 954 974 952 910 971 964 839 1014 942 951 992 993 956 960 976 1008 952 1000 925 991 966 924 966 998 950 1036 961 961 982 963 969 957 967 994 1044 985 1005 1004 997 966 953 1042 1004 1033 1005 1052 1082 1001 970 977 1011 1005 1060 992 978 986 1015 999 1009 1027 940 1009 999 1026 996 998 984 973 972 993 987 966 999 1046 1011 972 954 978 1003 1028 984 960 945 970 969 1000 931 980 949 1016 941 990 1003 1023 1001 1034 1028 934 991 1027 994 1031 1033 1011 1012 1054 1016 1019 1020 1044 1030 1060 1069 1052 1031 1015 1049 1071 1102 1072 1105 1155 1164 1168 1152 1165 1187 1215 1280 1347 1437 1456 1538 1507 1513 1651 1620 1804 1878 2001 1952 2190 2253 2281 2427 2308 2422 2382 2493 2629 2593 2561 2600 2633 2597 2638 2561 2569 2531 2482 2396 2402 2251 2280 2065 2031 1921 1835 1786 1722 1693 1642 1598 1497 1494 1395 1369 1274 1170 1244 1266 1177 1210 1141 1180 1194 1172 1102 1161 1140 1152 1099 1152 1049 1120 1102 1153 1077 1070 1049 1122 1143 1156 1134 1197 1233 1198 1241 1242 1357 1306 1353 1387 1406 1487 1483 1501 1509 1527 1564 1499 1494 1488 1549 1433 1554 1460 1431 1410 1405 1447 1408 1374 1352 1301 1344 1221 1216 1247 1189 1202 1144 1138 1089 1102 1029 1062 1036 996 996 986 1034 993 988 983 945 931 991 970 1018 975 975 994 989 943 988 963 1011 952 993 993 974 958 904 916 994 952 974 920 986 1021 933 916 967 982 959 918 881 965 958 969 912 974 981 1036 962 952 911 923 927 925 947 959 939 941 955 931 963 958 933 970 913 909 956 977 949 902 927 890 915 886 961 899 930 932 947 926 984 952 910 918 878 962 950 930 937 928 931 970 984 920 923 1005 910 938 908 925 964 948 962 911 949 885 941 969 902 969 916 927 949 928 960 982 883 881 955 942 925 888 921 968 920 960 940 953 867 903 990 944 916 972 865 933 899 904 939 897 907 907 969 909 937 924 962 891 888 903 923 996 968 927 957 940 959 886 967 944 940 955 919 922 947 989 953 947 962 956 919 998 966 1019 981 1060 1028 986 992 1030 990 968 999 1009 1008 907 975 933 1026 1004 1042 989 990 943 976 923 997 990 988 976 962 950 1014 1002 1000 958 1008 927 976 975 999 1004 906 932 1006 940 992 949 938 934 1003 1004 1030 960 997 937 1007 1068 1051 1085 1009 1042 1024 1023 1135 1087 1135 1162 1194 1210 1272 1326 1334 1315 1285 1350 1384 1339 1375 1431 1443 1374 1401 1457 1371 1519 1412 1432 1432 1478 1410 1432 1295 1294 1309 1330 1376 1327 1312 1346 1296 1370 1324 1318 1351 1304 1339 1326 1449 1439 1481 1437 1437 1490 1476 1581 1596 1491 1538 1593 1526 1513 1456 1543 1533 1507 1545 1490 1376 1468 1422 1342 1388 1318 1271 1230 1225 1177 1231 1176 1190 1134 1117 1054 1101 1043 1008 1001 1064 1029 987 1012 983 1023 977 1022 970 921 990 965 982 973 937 958 919 929 935 979 907 944 863 931 918 917 1035 985 982 956 930 931 942 902 920 873 999 954 930 973 975 951 931 914 939 926 912 960 969 919 929 920 915 871 952 925 924 903 993 932 942 872 972 913 915 923 891 956 932 923 899 937 951 986 950 963 966 944 930 933 992 909 936 935 935 938 949 954 937 923 923 978 924 958 936 993 974 963 984 961 931 935 950 958 964 956 1016 943 965 977 995 998 945 1044 1001 1101 1000 1041 1040 1036 1079 1025 1095 1062 1123 1147 1125 1173 1211 1226 1263 1295 1431 1426 1523 1552 1562 1616 1723 1672 1670 1767 1671 1747 1772 1727 1767 1816 1797 1887 1795 1758 1733 1702 1679 1601 1585 1508 1479 1410 1379 1321 1354 1340 1312 1312 1251 1317 1237 1271 1203 1220 1215 1238 1315 1314 1260 1317 1355 1386 1395 1460 1533 1635 1559 1594 1623 1718 1666 1635 1749 1715 1654 1733 1684 1715 1696 1650 1661 1692 1633 1631 1477 1444 1472 1421 1329 1353 1335 1308 1250 1252 1249 1198 1133 1211 1134 1072 1088 1017 1064 1004 992 1039 1007 986 935 1005 1044 965 1003 954 961 1021 986 1002 1040 967 1034 1005 980 966 956 1014 982 988 985 1013 984 972 998 1001 1031 1019 1025 1057 1062 1018 1043 1092 1053 1088 1102 1132 1203 1175 1203 1205 1274 1260 1322 1382 1433 1438 1485 1510 1530 1554 1567 1508 1552 1601 1516 1572 1583 1622 1643 1603 1578 1540 1545 1552 1533 1506 1383 1320 1278 1330 1298 1238 1239 1291 1255 1132 1166 1172 1100 1127 1046 1055 1130 1014 1066 1045 1038 1002 980 1023 1025 1055 989 1041 1044 1021 1045 1101 1057 1063 1059 1058 1095 1074 1088 1136 1198 1179 1221 1215 1178 1206 1277 1252 1269 1272 1254 1251 1293 1243 1274 1290 1372 1285 1336 1301 1312 1201 1226 1200 1238 1212 1232 1172 1191 1120 1150 1130 1110 1124 1096 1099 1095 1019 1070 1053 1065 1037 1030 1032 960 981 949 902 999 962 952 955 951 965 958 969 1032 944 961 941 983 940 961 944 941 962 968 953 896 1004 953 941 948 883 879 933 978 948 964 970 893 936 950 947 954 932 923 929 897 929 997 924 944 941 1000 928 899 974 957 1008 926 953 934 967 948 889 970 881 967 987 968 881 1047 968 977 963 988 913 959 947 969 952 929 983 982 937 1010 960 996 963 965 991 932 1040 1026 1005 965 1087 992 1026 965 1030 1061 1015 1070 1090 1116 1057 1131 1171 1139 1221 1314 1268 1362 1425 1454 1546 1539 1582 1653 1673 1668 1750 1740 1711 1799 1833 1851 1875 1902 1976 1904 2042 1920 1960 1959 1880 2029 1818 1810 1853 1859 1848 1832 1846 1831 1836 1816 1841 1894 1923 1857 1898 1985 1955 1935 1993 1921 1970 1883 1915 1878 1896 1895 1835 1825 1808 1792 1822 1786 1725 1739 1692 1684 1640 1592 1540 1527 1527 1503 1537 1490 1426 1440 1493 1365 1400 1414 1460 1403 1548 1422 1511 1436 1492 1473 1443 1459 1398 1416 1444 1459 1440 1428 1438 1468 1394 1360 1376 1297 1348 1271 1240 1241 1276 1214 1152 1154 1141 1104 1055 1064 1121 1044 1022 990 1057 1004 1012 970 985 950 1000 1011 1011 983 976 1037 951 998 984 952 1032 970 1004 917 1019 966 1014 1095 1019 1005 986 1006 1041 1023 972 961 950 967 955 933 962 977 929 965 898 939 928 913 898 934 933 963 943 921 944 942 869 891 940 933 911 910 863 894 928 857 893 916 889 842 897 927 947 922 959 935 901 957 878 857 895 921 908 902 923 938 924 890 873 894 922 887 905 920 918 903 950 903 922 879 871 884 889 940 869 905 913 926 907 914 910 891 866 875 887 919 872 933 858 878 906 950 892 958 940 906 927 900 942 914 976 923 950 950 940 998 954 938 982 1024 953 928 957 956 944 1026 969 961 948 978 975 947 941 977 1020 974 937 980 941 796 910 914 917 966 937 900 869 897 896 922 862 848 871 914 861 898 884 913 870 914 917 863 942 918 887 919 853 912 816 872 889 832 846 871 858 866 823 933 900 895 946 848 842 907 958 918 869 891 884 880 861 898 896 853 923 840 839 886 847 837 944 900 826 938 852 899 933 841 911 898 886 943 797 873 864 896 902 903 854 891 888 887 895 905 889 901 946 842 903 881 927 872 890 891 837 902 920 893 890 893 893 827 907 886 873 935 888 871 895 916 878 892 924 931 904 846 923 909 897 965 916 955 883 920 904 966 927 872 952 910 952 940 940 921 1007 976 983 996 1027 1044 1032 1073 1113 1171 1156 1139 1126 1174 1159 1216 1239 1291 1286 1225 1295 1203 1227 1250 1261 1145 1232 1210 1174 1163 1091 1134 1147 1074 1018 1053 1076 975 1070 1067 953 982 1021 988 961 918 992 876 978 946 920 923 951 922 908 899 951 931 939 915 949 948 968 979 969 965 973 960 974 936 948 985 984 1035 1021 986 1013 997 973 1019 1014 1001 1026 1013 1060 966 952 982 953 999 988 966 948 947 918 960 912 944 910 896 935 883 905 926 923 874 926 888 843 921 874 959 871 894 880 855 920 857 852 921 975 927 834 844 876 842 876 883 900 844 867 839 919 865 860 896 872 894 860 912 898 870 892 845 822 903 833 888 838 834 873 813 868 820 906 832 900 838 896 860 869 890 903 896 858 896 868 862 865 869 892 894 904 884 880 891 921 837 935 870 852 909 941 890 891 849 867 902 877 856 844 828 843 845 890 842 930 820 913 851 867 832 902 887 869 893 899 895 853 877 924 857 888 914 816 807 927 852 876 825 866 889 837 873 864 881 858 894 929 849 871 881 929 887 922 931 920 904 957 901 909 913 951 854 906 921 920 917 944 927 908 880 905 874 845 934 931 934 1005 928 944 948 967 966 938 946 922 986 962 982 1019 1004 1036 1043 1047 1043 1076 1068 1073 1101 1102 1122 1094 1058 1186 1120 1024 1142 1117 1136 1121 1091 1099 1125 1089 1078 1050 1021 1102 1007 1031 1028 1053 1013 1022 1075 1099 1064 1036 1107 1127 1082 1128 1116 1173 1140 1249 1212 1289 1200 1262 1316 1305 1252 1284 1357 1321 1348 1348 1336 1346 1321 1327 1324 1351 1317 1298 1361 1290 1215 1224 1223 1237 1178 1175 1165 1140 1193 1044 1011 1126 1050 1019 1017 951 1009 1002 945 948 986 976 914 997 891 991 930 964 973 970 953 878 965 918 935 1001 889 918 907 940 935 934 919 911 958 921 924 959 927 930 940 976 996 973 1014 972 992 1093 960 1066 998 1052 1029 1022 1084 1102 1162 1119 1156 1166 1121 1159 1187 1210 1230 1256 1280 1259 1273 1296 1240 1227 1279 1273 1277 1233 1243 1269 1293 1222 1229 1203 1200 1206 1153 1185 1148 1113 1192 1114 1115 960 1100 1067 1036 997 994 991 999 1044 992 961 983 1011 929 969 951 921 967 924 907 930 902 887 904 911 892 910 950 915 943 857 916 876 869 959 897 891 860 928 927 922 924 973 947 872 918 903 916 903 912 955 941 907 905 862 947 987 999 970 986 1015 967 988 1037 1035 1076 1109 1146 1132 1176 1191 1287 1192 1281 1359 1314 1347 1325 1348 1362 1287 1376 1311 1352 1339 1348 1365 1307 1314 1252 1242 1352 1189 1231 1229 1237 1117 1165 1083 1092 1073 1051 1077 1055 1029 968 987 998 970 919 969 977 900 927 938 913 887 916 952 952 864 885 938 888 917 937 956 842 945 878 896 876 891 900 922 970 983 911 914 865 883 918 869 902 904 941 911 925 936 950 971 993 986 941 1033 1065 1056 1063 1075 1143 1174 1223 1196 1268 1308 1367 1375 1470 1360 1332 1337 1359 1392 1410 1433 1442 1415 1440 1460 1402 1343 1386 1387 1334 1299 1253 1215 1226 1225 1158 1186 1159 1124 1142 1108 1103 1100 1022 1005 993 966 996 868 987 929 951 974 950 921 940 895 919 921 898 914 905 917 884 929 858 895 885 876 880 888 885 871 874 868 875 952 843 867 863 889 848 845 878 838 968 851 876 901 878 841 943 879 849 873 895 861 922 884 902 945 938 898 927 880 848 882 876 889 825 868 887 859 960 956 932 895 942 927 970 876 971 923 971 914 882 955 950 953 934 913 914 923 883 927 934 914 936 981 963 957 939 1017 961 973 950 945 950 988 1010 1008 965 1033 977 1042 980 962 1049 1018 1067 1049 1051 1079 1048 1055 1096 1073 1094 1116 1085 1065 1044 1066 1110 1064 1081 1050 1065 1026 1044 1062 1074 1023 1071 1034 1053 997 1012 979 981 929 1005 983 971 939 933 966 955 993 937 967 914 996 980 973 960 922 999 883 988 973 959 996 1032 986 996 1029 997 1076 971 1047 999 991 1107 1101 1017 1029 1022 1085 1122 1081 1155 1143 1112 1071 1128 1112 1217 1143 1159 1157 1148 1168 1101 1166 1178 1054 1094 1151 1152 1163 1093 1067 1096 1099 1059 1035 1053 1035 1102 1042 1020 1042 1012 976 1045 974 976 992 1009 1013 991 954 956 941 958 938 967 972 915 923 919 894 962 938 965 1005 895 950 887 953 952 964 909 932 960 1030 968 978 1044 971 956 970 927 969 966 956 1002 977 957 949 1042 967 971 969 965 977 915 981 926 927 950 908 1001 920 934 930 911 958 930 940 887 871 902 874 924 854 897 971 900 922 929 886 897 911 920 899 949 860 930 928 894 903 894 903 850 902 934 915 917 932 948 940 927 910 924 962 994 977 1001 1015 1034 1055 1030 1047 1077 1118 1084 1057 1114 1104 1111 1067 1120 1069 1069 1142 1064 1127 1146 1111 1106 1048 1106 1064 1069 1048 1079 1032 1048 1017 1008 1016 1080 1025 1027 1018 939 1002 961 1036 956 981 945 910 968 931 900 899 909 921 904 943 886 885 945 944 907 891 896 899 894 889 898 873 901 885 901 905 912 930 910 896 862 858 916 890 866 897 838 882 859 907 882 896 908 940 877 915 935 867 860 886 918 923 880 908 894 912 837 892 885 912 857 864 900 926 865 898 905 942 935 902 912 901 873 905 906 887 896 964 975 946 907 906 927 996 968 989 995 991 995 961 966 969 1058 988 1084 1011 1065 1012 1084 993 1043 1079 1046 1018 1108 1104 1068 1042 1136 1089 1081 1063 1086 1153 1052 1110 1100 1138 1093 1096 1098 1088 1170 1161 1081 1106 1067 1098 1074 1106 1115 1021 1068 1037 1046 1063 1082 1044 1007 1069 1072 1031 982 1032 967 1040 998 972 971 1029 927 923 968 887 887 974 951 946 925 954 897 869 961 924 929 974 946 953 952 967 921 930 984 976 976 999 920 974 969 1028 971 1031 949 1063 1022 1038 975 1030 989 1032 926 958 935 993 1008 979 959 977 991 963 996 960 979 1038 937 977 967 989 979 965 1035 1013 962 969 1017 1028 1006 1043 1080 1017 1121 1129 1111 1061 1195 1130 1182 1097 1194 1152 1111 1134 1176 1123 1144 1122 1072 1095 1132 1139 1060 1076 1069 1033 1093 1035 1092 1022 978 1038 996 1039 1053 940 969 943 1013 947 932 952 973 888 936 932 920 901 944 977 957 927 958 913 932 942 903 970 930 958 951 943 964 961 947 914 1004 986 1050 1078 1045 1061 1056 1033 1131 1042 1099 1132 1100 1140 1121 1178 1204 1064 1179 1102 1046 1117 1111 1072 1046 1071 1111 1144 1012 1080 1079 981 1064 1125 1048 1105 1031 1031 994 1068 972 1017 1007 994 968 1001 1028 942 1005 896 1028 959 962 938 973 986 959 1011 994 1018 989 996 1034 1021 1047 1024 1019 1082 1005 1023 1081 1013 1030 1040 1060 1079 1105 1082 1090 1044 1124 1106 1056 1038 1076 1020 1123 1073 982 1029 1087 1004 1011 1014 1027 1003 1014 1035 999 1004 1010 952 962 972 981 950 984 949 986 895 950 932 939 874 920 893 875 854 898 908 899 891 816 944 890 883 891 889 839 860 914 919 891 887 888 826 873 898 867 866 869 851 857 891 886 831 873 855 890 852 875 884 906 914 872 895 879 824 876 884 912 884 871 865 842 880 874 862 882 872 857 886 856 894 889 906 884 937 829 895 861 915 874 904 872 901 851 839 968 877 920 948 881 869 934 971 964 974 969 944 1009 952 1012 1022 984 1023 981 1016 996 1030 1013 1040 1029 976 1062 1052 1106 1070 1049 969 1006 1031 1066 1036 1051 1067 1034 1047 937 1010 1017 1027 996 993 1037 1116 1053 962 1064 1083 1013 1087 1065 1024 1030 1031 1028 1046 1092 1109 1128 1176 1182 1162 1197 1185 1150 1179 1216 1140 1162 1215 1134 1159 1190 1238 1186 1190 1129 1180 1098 1155 1109 1083 1217 1143 1091 1129 1086 1132 1116 1258 1169 1205 1168 1196 1176 1223 1255 1112 1250 1250 1223 1220 1233 1153 1224 1218 1154 1221 1230 1139 1205 1171 1138 1093 1071 1186 1111 1087 1071 1066 1024 1016 1035 1081 1062 1087 1047 980 997 988 959 970 1010 963 959 886 974 918 936 925 909 883 926 942 908 937 896 869 914 870 846 903 854 891 873 853 877 850 835 884 883 901 849 835 874 821 886 836 856 875 823 891 882 862 854 900 873 885 884 867 880 888 840 859 932 905 848 855 843 824 882 889 877 862 930 918 880 891 854 871 814 918 906 859 916 871 873 833 848 874 866 893 863 858 890 863 877 883 909 844 897 895 921 895 872 873 881 878 830 898 904 864 892 884 884 866 886 960 919 921 948 934 919 933 970 938 922 955 993 962 963 1056 947 987 1024 1017 1028 1046 1048 1088 1110 1090 1144 1227 1132 1167 1218 1257 1223 1194 1148 1138 1129 1158 1166 1150 1193 1142 1143 1161 1153 1084 1132 1127 1210 1145 1051 1053 1137 1078 1035 1024 1033 1019 1069 1035 1012 998 962 997 929 959 939 908 956 929 881 897 913 862 885 877 876 863 825 848 836 891 879 817 868 850 871 857 800 893 856 863 874 841 842 870 862 889 858 816 857 833 854 800 930 917 932 909 829 894 835 862 893 851 871 883 858 855 880 864 843 896 872 826 846 875 864 892 853 850 861 857 873 883 821 892 850 855 815 836 888 858 879 872 906 876 851 898 917 908 919 860 926 927 874 945 948 909 949 962 992 975 987 958 1010 1056 1059 968 1044 1083 1053 1003 1002 1073 1040 1057 1005 1031 1031 1015 962 993 971 933 956 987 960 962 978 989 981 938 952 945 1018 921 921 930 987 924 934 896 874 887 927 913 852 898 845 870 875 904 915 876 916 867 864 857 854 909 867 842 863 857 881 887 897 854 859 857 811 829 842 831 879 895 926 876 830 825 845 875 841 866 814 819 864 873 862 844 894 827 836 876 850 845 896 851 849 856 795 840 842 879 873 871 898 877 835 877 877 861 916 894 904 872 848 887 846 910 868 898 899 897 951 885 910 992 954 942 905 923 885 963 934 972 976 966 989 967 944 932 989 951 930 954 921 949 866 941 926 945 972 933 905 950 957 900 928 930 977 950 936 923 922 955 996 1002 907 942 992 999 957 957 947 936 996 972 936 987 962 1024 952 980 913 972 961 994 1001 954 1005 949 944 1017 1011 1014 1018 922 998 1011 1056 1024 1010 1073 993 1034 1096 985 1077 1103 1062 1110 1065 1065 1122 1024 1043 1069 1149 1086 1064 1026 1076 1065 1002 998 1025 989 981 974 977 1027 968 937 992 939 926 982 987 1074 955 975 925 946 972 894 906 935 874 876 884 890 857 838 879 859 843 870 914 874 859 880 926 890 820 895 854 851 921 896 825 852 835 875 813 855 782 899 828 829 823 807 879 836 873 842 878 856 839 848 837 812 828 836 865 871 814 863 878 852 842 861 842 843 843 893 860 881 909 856 845 828 860 854 882 885 865 879 839 817 813 864 893 861 840 853 839 827 841 886 847 860 804 812 872 797 865 856 852 886 833 913 808 877 870 908 872 832 885 856 885 846 828 878 877 905 914 866 909 843 849 859 814 849 888 863 832 854 907 918 867 867 885 851 863 869 880 896 820 865 826 838 821 893 829 814 807 855 841 838 890 807 815 854 905 894 837 913 806 820 795 850 849 810 796 902 810 883 864 796 853 886 839 846 858 822 876 815 854 806 845 871 833 791 815 797 843 794 854 840 846 823 800 809 821 796 824 824 829 866 854 820 831 877 846 856 776 820 870 829 768 802 823 829 801 756 812 842 818 821 857 808 794 815 822 788 838 830 856 792 837 847 844 837 829 817 815 837 824 841 865 798 900 839 857 773 863 859 851 856 830 776 891 841 855 890 871 906 892 940 869 927 891 916 838 899 915 950 825 876 856 892 900 936 816 864 956 902 822 861 896 893 858 830 939 820 861 837 877 855 860 852 835 827 828 893 823 862 854 820 880 879 856 807 813 824 853 882 847 862 821 850 823 827 772 818 798 809 828 849 800 829 792 810 855 861 880 830 832 901 836 835 832 809 873 874 819 862 877 832 787 851 863 813 861 804 859 804 867 845 805 821 844 849 796 840 812 876 832 824 786 823 848 791 821 830 870 818 813 812 846 823 878 868 784 896 851 826 884 834 908 873 912 837 914 832 895 863 928 852 949 883 865 950 904 891 927 918 873 895 889 883 915 900 843 893 865 876 837 790 866 947 843 836 906 880 812 923 885 872 841 862 862 857 899 843 853 858 839 874 855 885 881 886 840 842 828 858 932 834 858 836 821 842 855 831 797 868 806 853 857 879 841 845 873 804 843 768 836 859 831 861 851 800 847 856 863 828 879 820 867 843 804 868 867 863 819 855 846 905 861 842 845 860 827 846 902 833 843 835 853 818 802 830 841 848 913 845 845 875 892 862 925 894 911 906 894 922 951 837 861 906 896 877 869 912 862 932 919 869 925 885 964 917 878 925 963 903 926 949 886 909 954 858 932 931 970 835 864 878 977 933 895 910 914 942 930 867 936 888 892 853 979 956 925 906 877 909 877 891 898 936 867 914 898 856 893 943 859 865 877 876 867 914 897 837 893 870 932 858 894 861 838 838 839 841 891 816 906 833 947 921 892 903 898 909 929 870 921 915 895 892 859 891 908 821 913 929 865 870 898 863 915 889 874 856 867 849 896 877 864 855 902 838 892 842 876 890 906 854 919 888 830 883 868 869 868 882 928 906 916 890 863 796 945 901 891 890 881 844 861 828 895 860 895 880 883 855 899 906 943 943 852 830 869 858 931 864 833 867 854 928 856 871 852 860 864 837 908 829 867 884 851 874 794 866 861 859 863 820 854 806 853 826 853 817 865 828 869 886 848 791 870 790 887 826 862 826 847 830 853 835 855 866 831 875 862 873 872 835 832 881 883 861 883 882 875 843 839 844 855 886 901 899 889 878 897 887 893 873 897 895 875 912 912 894 898 965 973 856 906 968 932 970 970 1003 959 933 946 990 1017 935 973 926 909 989 944 925 950 943 924 973 942 954 887 976 922 916 926 921 989 881 894 971 929 929 877 894 943 912 910 878 946 912 868 905 909 894 891 880 862 864 831 855 866 876 864 896 859 886 861 875 887 901 838 870 872 857 859 882 838 850 829 892 855 914 897 863 914 867 850 823 884 886 937 832 883 869 918 885 857 908 894 858 874 877 884 854 887 955 903 937 921 866 877 933 959 987 910 918 827 867 878 904 882 907 917 847 922 928 1002 913 962 926 966 950 934 901 865 958 941 937 928 958 926 957 940 944 920 969 978 916 944 936 979 1018 929 1003 951 1010 977 969 956 982 988 961 969 1048 947 1018 973 958 1000 1023 956 1039 1014 1010 961 1017 984 1093 1022 1015 1012 933 983 1043 1007 973 984 995 1041 958 1008 944 933 945 959 945 933 939 906 869 920 902 912 936 966 984 951 956 915 918 955 906 917 910 899 890 924 904 945 868 854 883 900 860 837 929 854 876 865 848 885 852 859 867 880 873 848 862 850 905 805 855 851 843 845 945 926 854 804 870 876 930 838 826 862 859 810 828 896 894 844 937 893 888 897 822 880 907 849 862 867 878 919 827 906 915 962 857 834 947 845 939 940 899 892 872 940 949 937 939 948 955 956 949 947 909 1001 944 983 948 979 997 950 999 1020 967 1009 954 937 990 958 982 924 934 928 986 904 912 926 929 960 968 894 998 963 913 959 941 905 946 893 948 937 976 952 882 918 877 936 918 890 884 923 876 857 873 936 885 883 890 858 886 867 877 943 904 891 890 895 846 838 907 873 961 837 869 903 960 907 915 869 961 959 973 916 954 933 946 975 1017 965 975 943 1016 994 968 927 957 964 973 973 972 961 977 929 889 975 945 931 880 965 980 872 876 934 920 894 906 960 883 951 953 882 900 851 938 869 892 856 888 883 894 898 849 924 922 836 803 862 858 807 908 871 843 854 820 817 891 852 838 858 882 834 860 846 898 854 821 940 852 891 845 864 871 834 836 844 830 834 845 849 845 805 855 841 868 782 833 853 839 843 818 844 845 818 867 773 810 822 892 811 794 843 871 878 863 890 807 900 789 865 806 851 839 908 838 835 843 854 820 823 798 863 847 829 840 806 809 837 803 880 827 848 811 835 913 863 886 823 861 887 825 807 882 794 812 859 804 857 861 828 831 836 889 892 790 905 827 883 858 792 855 870 894 827 815 921 843 835 861 899 886 863 849 889 867 875 882 841 844 893 840 881 879 862 891 906 885 903 858 933 869 861 913 945 871 901 935 924 910 888 934 973 937 947 892 971 882 904 916 908 900 911 892 875 847 877 896 886 878 866 901 835 848 892 885 877 840 892 934 910 870 870 921 865 866 841 917 926 835 921 928 904 899 942 921 902 931 982 968 898 977 907 942 937 965 899 923 979 943 936 866 916 892 926 886 947 858 902 871 934 885 896 856 875 971 925 942 926 916 924 928 889 886 906 894 937 882 883 881 873 926 872 913 898 837 907 881 835 848 895 868 855 855 763 875 798 854 870 855 891 826 848 830 869 864 848 824 882 922 855 892 913 861 925 885 897 885 860 860 901 919 849 912 919 896 838 883 928 865 911 910 866 861 813 893 860 890 881 881 943 841 863 857 865 833 884 866 838 830 873 870 897 859 829 895 855 836 862 887 861 874 888 820 890 832 891 878 884 848 899 851 895 885 840 845 879 866 867 871 917 864 857 928 862 912 899 924 902 882 890 907 899 910 906 952 891 880 847 991 968 911 900 951 941 948 952 936 935 859 926 879 949 880 875 924 886 852 955 869 869 906 910 925 885 924 890 929 870 830 899 929 909 870 900 927 860 905 886 895 908 887 896 848 858 876 860 776 900 798 865 821 890 806 837 902 866 865 878 853 852 887 868 875 806 834 854 843 881 875 860 871 806 877 850 864 857 830 871 818 856 834 827 874 844 830 789 867 812 853 858 827 833 816 841 770 822 793 803 836 815 799 847 832 814 776 816 801 860 828 877 809 794 757 842 779 839 821 829 834 818 832 782 792 791 850 853 856 841 847 820 850 824 801 877 815 850 810 796 811 918 831 880 824 861 853 812 800 864 826 862 841 788 781 901 848 882 857 796 835 846 870 788 843 802 832 839 870 849 848 873 844 883 831 883 908 812 767 840 839 827 794 895 871 861 893 906 889 879 895 868 837 870 855 918 847 832 892 841 868 917 827 872 825 830 896 864 850 818 898 859 854 827 874 866 873 834 804 841 827 825 827 878 863 852 871 837 835 811 864 880 861 841 844 852 856 837 867 871 914 804 870 867 852 855 805 836 872 854 883 883 934 899 845 831 929 805 850 873 832 791 861 867 846 859 907 819 829 855 866 829 846 884 896 810 926 860 867 895 883 893 848 847 861 871 851 899 861 832 864 859 882 862 886 824 891 866 828 871 867 845 862 869 894 821 797 833 851 825 917 834 821 807 858 819 851 859 825 862 867 827 825 818 791 897 871 839 775 873 854 785 865 863 820 874 831 838 837 832 794 865 826 848 845 812 821 825 827 838 791 849 848 852 874 840 792 870 846 812 869 853 856 874 846 815 819 895 878 870 829 862 890 865 850 879 919 930 869 901 871 918 894 876 915 819 921 864 886 894 924 868 877 919 950 924 893 905 967 902 972 917 862 957 960 919 948 957 964 1018 958 984 990 953 982 975 1024 956 1019 989 975 981 973 961 933 958 1005 969 996 990 912 972 942 928 936 1002 955 939 1011 939 929 951</counts>
			</dataPoints>
		</scan>
	</xrdMeasurement>
</xrdMeasurements>