File: dataset/precursor_mixture/V2O5_0p4005-NiO_0p6016--8min.xrdml
<?xml version="1.0"?>
<xrdMeasurements xmlns="http://www.xrdml.com/XRDMeasurement/2.3" xmlns:xsi="http://www.w3.org/2001/XMLSchema-instance" xsi:schemaLocation="http://www.xrdml.com/XRDMeasurement/2.3 http://www.xrdml.com/XRDMeasurement/2.3/XRDMeasurement.xsd" status="Completed" recordIdentifier="{E0A35D33-2F57-4927-A5D9-2E1667E0FC6D}">
	<comment>
		<entry/>
	</comment>
	<sample type="To be analyzed">
		<id>V2O5_0p4005-NiO_0p6016--8min</id>
		<name></name>
		<preparedBy></preparedBy>
	</sample>
	<xrdMeasurement measurementType="Scan" status="Completed" sampleMode="Reflection">
		<usedWavelength intended="K-Alpha 1">
			<kAlpha1 unit="Angstrom">1.5405980</kAlpha1>
			<kAlpha2 unit="Angstrom">1.5444260</kAlpha2>
			<kBeta unit="Angstrom">1.3922500</kBeta>
			<ratioKAlpha2KAlpha1>0.5000</ratioKAlpha2KAlpha1>
		</usedWavelength>
		<incidentBeamPath>
			<radius unit="mm">145.00</radius>
			<xRayTube id="1010048" name="Empyrean Cu LFF HR (9430 033 7310x)">
				<tension unit="kV">40.0</tension>
				<current unit="mA">15.0</current>
				<anodeMaterial>Cu</anodeMaterial>
				<focus type="Line">
					<length unit="mm">12.0</length>
					<width unit="mm">0.4</width>
					<takeOffAngle unit="deg">6.0</takeOffAngle>
				</focus>
			</xRayTube>
			<sollerSlit id="21010002" name="Soller slits 0.04 rad.">
				<opening unit="rad">0.0400</opening>
			</sollerSlit>
			<mask id="22031000" name="Fixed mask 13 mm">
				<width unit="mm">9.00</width>
			</mask>
			<divergenceSlit id="22120001" name="Divergence slit 1°" xsi:type="fixedDivergenceSlitType">
				<distanceToSample unit="mm">50.00</distanceToSample>
				<height unit="mm">1.52</height>
			</divergenceSlit>
		</incidentBeamPath>
		<sampleMovement xsi:type="spinningSampleMovementType">
			<spinnerRevolutionTime unit="seconds">1.0</spinnerRevolutionTime>
		</sampleMovement>
		<diffractedBeamPath>
			<radius unit="mm">145.00</radius>
			<antiScatterSlit id="22090040" name="AS slit 9 mm (PIXcel)" xsi:type="fixedAntiScatterSlitType">
				<height unit="mm">9.00</height>
			</antiScatterSlit>
			<sollerSlit id="21020003" name="Large Soller slits 0.04 rad.">
				<opening unit="rad">0.0400</opening>
			</sollerSlit>
			<filter id="20030001" name="Large beta-filter Nickel">
				<material>Ni</material>
				<thickness unit="mm">0.020</thickness>
			</filter>
			<detector id="7010019" name="PIXcel1D-Medipix3 detector" xsi:type="rtmsDetectorType">
				<phd unit="keV">
					<lowerLevel>4.02</lowerLevel>
					<upperLevel>11.27</upperLevel>
				</phd>
				<mode>Scanning</mode>
				<activeLength unit="deg">5.542</activeLength>
			</detector>
		</diffractedBeamPath>
		<scan appendNumber="0" mode="Continuous" scanAxis="Gonio" status="Completed">
			<header>
				<startTimeStamp>2024-11-14T15:36:28-08:00</startTimeStamp>
				<endTimeStamp>2024-11-14T15:44:35-08:00</endTimeStamp>
				<author>
					<name>AutomatedUser</name>
				</author>
				<source>
					<applicationSoftware version="1.7b (136)">PANalytical Aeris Instrument Suite</applicationSoftware>
					<instrumentControlSoftware version="3.2.00000000 20240306">AERIS</instrumentControlSoftware>
					<instrumentID>950485</instrumentID>
				</source>
			</header>
			<dataPoints>
				<positions axis="2Theta" unit="deg">
					<startPosition>10.00943322</startPosition>
					<endPosition>99.99442286</endPosition>
				</positions>
				<positions axis="Omega" unit="deg">
					<startPosition>5.00471661</startPosition>
					<endPosition>49.99721143</endPosition>
				</positions>
				<commonCountingTime unit="seconds">12.495</commonCountingTime>
				<counts unit="counts">2856 2862 2765 2858 2795 2826 2843 2822 2826 2710 2857 2749 2785 2861 2752 2910 2691 2856 2797 2743 2771 2625 2782 2767 2697 2815 2728 2814 2705 2867 2645 2726 2744 2740 2713 2819 2720 2703 2781 2745 2690 2792 2692 2793 2777 2747 2754 2736 2703 2777 2646 2689 2706 2707 2731 2727 2656 2693 2705 2749 2716 2664 2663 2738 2609 2745 2657 2757 2617 2599 2652 2679 2715 2697 2680 2646 2635 2691 2628 2692 2640 2700 2550 2684 2704 2616 2619 2651 2657 2529 2637 2639 2667 2552 2621 2516 2654 2691 2615 2636 2600 2537 2631 2607 2582 2547 2613 2651 2515 2561 2588 2584 2704 2627 2621 2605 2540 2629 2602 2578 2542 2627 2506 2512 2650 2617 2533 2674 2545 2546 2625 2564 2576 2634 2546 2486 2475 2523 2630 2537 2528 2515 2559 2503 2673 2531 2536 2582 2546 2622 2473 2634 2499 2563 2502 2505 2552 2572 2456 2476 2540 2548 2573 2542 2493 2538 2522 2604 2460 2618 2534 2492 2503 2576 2521 2519 2490 2530 2520 2531 2523 2520 2435 2529 2476 2606 2389 2454 2519 2437 2510 2496 2550 2413 2517 2416 2484 2540 2479 2549 2437 2422 2413 2401 2510 2432 2401 2439 2475 2539 2497 2412 2570 2502 2450 2481 2412 2484 2542 2501 2421 2496 2437 2523 2431 2501 2377 2474 2498 2504 2541 2535 2390 2473 2398 2374 2510 2422 2522 2460 2463 2413 2459 2419 2512 2403 2496 2425 2537 2455 2449 2463 2451 2418 2352 2337 2421 2449 2429 2398 2413 2491 2472 2431 2398 2365 2414 2401 2420 2496 2411 2539 2464 2483 2416 2418 2335 2463 2460 2437 2375 2481 2343 2436 2441 2389 2317 2435 2325 2445 2386 2398 2364 2446 2480 2473 2367 2513 2422 2437 2432 2383 2472 2380 2401 2406 2478 2484 2411 2463 2382 2457 2502 2436 2462 2400 2441 2438 2415 2473 2434 2501 2432 2474 2393 2381 2416 2396 2353 2474 2427 2439 2371 2392 2373 2389 2417 2440 2408 2425 2379 2444 2394 2333 2271 2533 2422 2337 2475 2397 2353 2423 2368 2363 2340 2397 2452 2319 2400 2442 2344 2380 2360 2379 2403 2440 2372 2325 2418 2386 2386 2398 2414 2400 2402 2448 2368 2456 2402 2431 2364 2462 2331 2421 2401 2425 2340 2367 2330 2410 2445 2458 2413 2319 2380 2359 2423 2411 2460 2465 2363 2416 2450 2417 2390 2382 2466 2443 2473 2373 2432 2388 2369 2479 2457 2432 2431 2449 2390 2449 2358 2385 2396 2499 2420 2332 2411 2407 2444 2357 2491 2356 2428 2463 2519 2323 2431 2394 2489 2378 2464 2442 2446 2549 2409 2431 2349 2472 2502 2447 2337 2402 2411 2527 2420 2451 2430 2430 2430 2521 2460 2484 2491 2552 2427 2497 2476 2345 2481 2501 2489 2513 2568 2563 2584 2616 2561 2534 2670 2662 2643 2719 2726 2733 2748 2766 2808 2986 2944 2849 2981 2962 3039 3104 3131 3238 3195 3166 3239 3262 3305 3300 3181 3327 3260 3208 3189 3126 3068 3097 2861 2730 2785 2704 2629 2671 2579 2456 2540 2521 2415 2483 2487 2507 2444 2533 2345 2531 2491 2513 2469 2543 2545 2492 2494 2472 2412 2498 2404 2441 2480 2404 2427 2454 2473 2429 2613 2499 2481 2422 2444 2413 2531 2497 2458 2402 2472 2537 2497 2548 2466 2415 2417 2540 2377 2387 2518 2489 2515 2507 2539 2611 2491 2501 2458 2536 2548 2466 2486 2464 2437 2561 2458 2498 2441 2491 2494 2469 2445 2472 2427 2511 2504 2408 2540 2483 2540 2500 2569 2538 2464 2482 2458 2477 2436 2431 2552 2506 2425 2489 2460 2481 2471 2473 2520 2452 2551 2527 2609 2400 2495 2520 2572 2398 2515 2580 2552 2514 2520 2544 2409 2553 2429 2496 2555 2490 2508 2483 2452 2503 2477 2470 2507 2484 2629 2514 2446 2586 2580 2538 2489 2506 2562 2519 2592 2637 2525 2524 2573 2459 2522 2585 2531 2577 2489 2496 2543 2463 2590 2538 2549 2512 2556 2600 2492 2463 2555 2472 2499 2487 2464 2591 2533 2531 2502 2504 2514 2591 2588 2456 2500 2513 2430 2522 2510 2509 2433 2482 2522 2539 2491 2513 2641 2531 2425 2594 2395 2583 2539 2564 2460 2599 2448 2605 2511 2580 2627 2607 2478 2526 2532 2586 2580 2561 2422 2530 2554 2529 2569 2571 2582 2550 2589 2580 2529 2620 2518 2565 2614 2489 2510 2542 2574 2449 2500 2481 2610 2555 2537 2552 2544 2576 2463 2523 2463 2519 2537 2525 2507 2653 2590 2581 2579 2486 2561 2516 2661 2512 2523 2533 2581 2558 2537 2604 2552 2480 2573 2495 2488 2578 2544 2597 2601 2415 2577 2573 2602 2570 2582 2508 2602 2645 2578 2531 2596 2607 2521 2591 2513 2590 2511 2528 2600 2565 2575 2647 2480 2499 2594 2571 2596 2575 2512 2563 2573 2607 2675 2627 2575 2516 2559 2601 2614 2498 2602 2611 2542 2559 2591 2569 2604 2474 2466 2658 2565 2584 2509 2646 2583 2556 2662 2626 2569 2624 2548 2575 2596 2611 2598 2592 2661 2582 2677 2616 2560 2624 2631 2659 2604 2552 2563 2589 2663 2675 2611 2624 2533 2624 2646 2583 2577 2568 2539 2584 2585 2638 2547 2571 2583 2596 2639 2586 2565 2644 2568 2688 2637 2581 2615 2579 2658 2644 2713 2650 2665 2590 2598 2705 2692 2662 2714 2670 2643 2680 2712 2766 2739 2683 2782 2745 2805 2851 2766 2795 2690 2779 2769 2885 2858 2908 2985 3010 3028 2996 2970 3112 3230 3307 3315 3403 3504 3580 3625 3735 4002 3978 4186 4377 4471 4445 4730 4969 5018 5278 5528 5468 5888 5972 6054 6314 6201 6414 6542 6531 6593 6534 6389 6282 6240 5906 5772 5493 5289 5017 4644 4455 4200 3920 3833 3534 3435 3273 3158 3078 3081 3109 2972 2886 2888 2810 2972 2883 2781 2850 2774 2890 2899 2802 2748 2749 2805 2809 2774 2702 2710 2727 2840 2751 2693 2762 2762 2737 2670 2625 2639 2758 2766 2683 2696 2727 2772 2750 2707 2653 2782 2638 2653 2655 2737 2686 2621 2707 2705 2715 2721 2704 2679 2730 2751 2665 2766 2661 2759 2701 2665 2611 2733 2683 2711 2755 2751 2583 2699 2733 2727 2644 2738 2750 2726 2732 2789 2829 2802 2749 2785 2858 2870 2821 2869 2911 2884 2947 2908 2950 2958 3008 3168 3114 3131 3235 3123 3323 3420 3376 3438 3469 3438 3648 3650 3818 3741 3739 3751 3956 3874 3886 3770 3803 3827 3837 3771 3722 3546 3503 3475 3314 3347 3280 3153 3018 3086 2923 3060 2897 2909 2901 2790 2811 2872 2895 2800 2844 2793 2762 2858 2942 2847 2746 2777 2628 2785 2806 2828 2772 2796 2683 2740 2721 2760 2690 2646 2777 2666 2744 2809 2756 2770 2788 2708 2713 2707 2779 2752 2748 2749 2767 2775 2742 2772 2801 2726 2656 2719 2707 2710 2847 2782 2793 2852 2690 2659 2840 2712 2726 2753 2771 2717 2638 2659 2678 2632 2661 2812 2745 2663 2702 2754 2740 2706 2675 2760 2742 2722 2714 2684 2768 2712 2795 2604 2708 2722 2726 2738 2748 2733 2777 2819 2712 2677 2675 2694 2739 2724 2729 2770 2726 2703 2752 2735 2817 2751 2765 2670 2739 2726 2711 2740 2713 2725 2676 2812 2793 2768 2685 2779 2670 2746 2803 2716 2651 2656 2755 2645 2759 2817 2706 2737 2749 2748 2719 2746 2769 2715 2788 2810 2777 2741 2796 2718 2751 2605 2700 2797 2756 2800 2720 2767 2856 2699 2820 2850 2734 2738 2705 2703 2762 2780 2752 2695 2794 2709 2838 2775 2756 2853 2705 2742 2717 2788 2635 2755 2723 2718 2720 2728 2737 2727 2697 2885 2782 2737 2767 2800 2799 2785 2784 2792 2704 2669 2776 2666 2690 2785 2792 2723 2747 2798 2762 2782 2735 2763 2815 2863 2672 2683 2837 2708 2773 2723 2703 2757 2844 2741 2682 2702 2717 2701 2676 2855 2763 2717 2776 2809 2725 2737 2692 2724 2772 2758 2807 2782 2747 2799 2813 2747 2780 2714 2902 2792 2824 2776 2736 2692 2850 2755 2781 2675 2748 2870 2817 2754 2695 2745 2727 2847 2716 2818 2846 2811 2786 2774 2772 2821 2862 2749 2796 2703 2768 2733 2764 2773 2833 2827 2834 2905 2797 2733 2808 2774 2765 2672 2792 2871 2811 2905 2880 2792 2876 2820 2739 2830 2689 2754 2846 2732 2850 2894 2781 2889 2849 2906 2924 2935 2865 2858 2886 2851 2877 2871 2862 2812 2916 2859 2912 2939 2778 2881 2922 2985 2823 3014 2938 2878 3083 2878 2973 3051 3026 3002 3007 2999 3018 3001 2897 3007 3023 2978 3000 3041 2936 2933 2840 2975 2954 3028 2857 2892 2896 3038 2952 2964 2995 2920 2871 3006 3010 3096 2973 3206 3166 3176 3297 3288 3350 3539 3595 3629 3754 3838 3889 4150 4275 4400 4420 4517 4751 4816 4960 5073 5312 5152 5216 5378 5307 5265 5317 5164 5074 4982 4866 4640 4365 4211 3954 3810 3809 3574 3483 3361 3265 3143 3188 3110 3048 3074 3015 2970 3037 2952 2922 2840 3005 2873 2987 2943 2880 2962 2858 2878 2998 2820 2909 2889 2866 2830 2941 2920 2874 2822 2890 3039 2978 2836 2831 2766 2886 2901 2741 3003 2924 2983 2921 2832 2924 2787 2851 2758 2852 2839 2917 2791 2816 2902 2782 2860 2805 2821 2821 2968 2990 2812 2858 2709 2857 2848 2837 2810 2882 2886 2844 2836 2843 2876 2870 2841 2895 2877 2759 2906 2881 2904 2955 2929 2880 2886 2843 2914 2898 2866 2849 2797 2907 2895 2920 2876 2953 2881 2904 2862 2879 2913 2923 2828 2982 2806 2803 2854 2851 2897 2978 2840 2814 2939 2910 2818 2874 2872 2858 2883 2932 2918 2890 2873 2856 2827 2915 2800 2885 2864 2850 2801 2968 2923 2893 2927 2954 2875 2805 2915 2799 2817 2892 2891 2911 2899 2895 2814 2883 2907 2968 2918 2934 2826 2825 2797 2973 2906 3058 2787 2981 2908 2862 2866 2948 2871 2903 2823 2883 2893 2875 2861 2846 2822 2898 2894 2788 2961 2927 2885 2796 2854 2985 2885 2915 2924 2936 2830 2943 3013 2867 2882 2826 2962 2935 2946 2935 2931 2891 2871 2910 2811 2917 2953 2933 2890 3011 2874 2958 2810 2931 2936 2900 2852 2880 2920 2908 2983 2867 2791 2872 2844 2952 2879 2867 2989 2938 2944 2848 2919 2895 2854 2863 2962 2929 2931 2959 2787 2952 2841 2923 2831 2823 2909 2948 2947 2960 2943 2797 2966 2930 2987 2801 2952 2881 2960 3016 2995 2850 2869 2940 2851 2912 2904 2897 2928 2862 2939 2986 2945 2909 2939 2856 2966 2879 2944 2885 2956 2916 2825 2867 2854 2918 2971 2973 2977 2955 2978 2872 2940 2874 2931 3046 2943 2980 2927 2963 3011 3051 2879 2949 2974 2916 2923 2888 2911 2893 2863 2962 2931 2838 2954 2779 2961 2871 2844 2936 2971 2911 2858 2937 2944 2938 2930 2910 2957 2994 2832 2955 2818 2875 2948 2929 2983 2888 2951 2875 2985 3062 2934 2957 2946 2902 2924 2943 2876 2958 2891 3001 2930 2935 2957 2903 2954 2919 2917 3004 3046 2950 2888 3081 3049 3034 3015 2887 2980 3029 2901 2948 2967 2894 3001 2960 2962 2949 2960 3040 2938 3005 2955 2991 2989 2999 3077 2965 3012 2955 2923 3041 3049 2948 3015 2983 3096 2999 3069 3089 3068 3147 3098 3119 3065 3134 3191 3195 3278 3234 3382 3318 3453 3342 3410 3604 3734 3731 3831 3924 4033 4194 4120 4418 4453 4602 4660 4971 5039 5169 5278 5316 5395 5427 5422 5586 5524 5346 5427 5331 5314 4963 5098 4735 4640 4690 4399 3981 4065 3983 3761 3631 3687 3513 3354 3348 3289 3129 3260 3202 3213 3149 3091 3152 3073 3105 3081 3065 3073 3072 3120 3057 2981 2954 3056 3001 3068 3026 3007 3115 3078 3068 3030 3086 3011 3026 3012 2970 2919 2947 2982 2997 2887 3060 3048 3004 3025 3091 2939 2907 3000 2989 3019 2918 3010 3084 3019 3033 3042 2999 3018 3047 3192 3110 3037 2974 3036 2961 3049 3014 2969 3035 3002 2998 3111 3018 3118 3142 3039 3126 3105 3045 3075 3121 3057 3026 3183 3092 3252 3166 3219 3251 3192 3379 3351 3420 3374 3445 3619 3666 3688 3823 3815 3884 3927 4024 3957 4035 4026 4051 4142 4033 4136 4187 4036 4027 3918 3925 3905 3782 3667 3616 3608 3563 3383 3354 3278 3206 3164 3200 3069 3126 3090 3126 3062 3145 3143 3100 3024 3024 3062 2971 2991 2977 3130 2974 3102 2995 3094 3055 3002 3038 3035 2946 3022 3089 3006 3078 2826 3054 3009 3031 3099 2970 3093 3011 3125 3055 3011 3045 3020 3046 2986 3147 3069 3062 3055 3174 3013 3215 3136 3104 3171 3156 3192 3121 3152 3263 3197 3205 3298 3266 3314 3391 3400 3455 3360 3329 3273 3305 3378 3307 3312 3314 3392 3380 3229 3310 3265 3369 3145 3158 3197 3134 3077 3059 3067 3126 2984 3146 3079 2941 3033 2938 3015 3024 3060 3072 3099 3040 3020 2966 3108 3029 2891 2995 3070 3113 2949 3054 3044 3032 3072 3036 3030 3027 3061 3021 3011 3023 2903 3075 3072 2974 3047 3035 3158 2968 3102 3194 3051 3104 3142 3210 3090 3056 3192 3229 3260 3316 3343 3265 3290 3346 3434 3510 3548 3568 3828 3693 3764 3857 3870 4015 3990 4040 4094 4060 4103 4078 4063 4064 4109 4073 3883 3842 3810 3660 3619 3539 3531 3311 3327 3326 3223 3209 3170 3135 3172 3131 3127 3164 3248 3212 3145 3040 3129 3160 3092 3122 3018 2977 3121 2989 2952 3003 3054 3008 3002 3019 2939 2965 3077 3070 3087 2913 2968 3189 3135 3031 2979 3105 2967 3044 3000 2944 2913 3045 3106 2940 3032 3057 3119 3010 3062 2951 3005 2979 2901 3000 3066 3008 3034 2980 2996 3051 3030 2979 3038 3016 3054 3087 2993 2914 3029 3047 3110 3041 2996 3048 3039 3015 2973 2966 2973 3039 2986 3143 2977 3007 3101 3008 3040 3114 3129 3096 2981 3033 3003 3092 3021 2916 3061 2944 2964 3035 2949 3090 3016 2945 2998 3036 3028 2989 3150 3112 3027 3102 3007 3083 2972 3072 3107 3135 3037 3044 3076 3044 3154 3141 3073 3104 3081 3200 3176 3109 3013 3186 3130 3234 3108 3148 3164 3240 3238 3238 3300 3218 3235 3177 3185 3283 3260 3236 3318 3049 3193 3200 3105 3204 3167 3189 3059 3104 3133 3135 3112 3164 3245 3108 3219 3088 3162 3130 3124 3088 3196 3194 3136 3162 3121 3058 3119 3212 3269 3073 3072 3283 3120 3046 3034 3096 3192 3223 3299 3123 3270 3237 3213 3289 3346 3250 3202 3242 3237 3246 3350 3308 3307 3244 3341 3441 3463 3383 3467 3500 3487 3442 3608 3517 3723 3616 3537 3759 3691 3995 3943 3988 4058 4219 4249 4415 4664 4739 4890 5165 5289 5731 6043 6167 6536 6977 7497 7914 8405 9222 9624 10324 10682 11460 12047 12825 13245 14268 14448 14712 15264 15454 15769 15999 15903 15801 15658 15305 14711 14354 13698 13027 12327 11840 11234 10594 9897 9289 8656 8157 7615 7082 6673 6476 6168 5813 5468 5440 5063 4913 4758 4533 4534 4328 4274 4111 3993 4032 3941 3780 3706 3705 3699 3545 3552 3557 3449 3446 3533 3482 3452 3342 3327 3285 3305 3322 3321 3300 3400 3220 3196 3254 3189 3220 3264 3233 3150 3238 3208 3306 3305 3183 3220 3131 3159 3138 3215 3148 3128 3206 3125 3123 3127 3120 3167 3102 3100 3172 3142 3175 3187 3174 3201 3211 3054 3194 3058 3179 3155 3205 3160 3075 3143 3178 3126 3031 3072 3192 3164 3185 3124 3084 3108 3092 3192 3108 3247 3086 3057 3101 3169 3158 3148 3124 3111 3174 3180 3120 3158 3149 3058 3053 3151 3111 3069 3118 3149 3156 3069 3114 3166 3148 3159 3063 3160 3071 3057 3129 3107 3160 3145 3074 3161 3079 3232 3110 3110 3095 3064 3099 3091 3095 3105 3125 3167 3167 3100 3075 3134 3108 3187 3098 2959 3143 3077 3020 3150 3041 3004 3146 3049 3074 3113 3047 3167 2974 3083 3189 3147 3137 3083 3157 3073 3152 3080 3064 3034 3134 3111 3107 3037 3122 3082 3076 3067 3038 3010 3197 3131 3161 3025 3055 3126 3145 3081 3161 3092 3029 3142 3002 3024 3159 3164 3019 3127 3128 3172 3064 3084 3166 3172 3177 3152 3123 3082 3149 3117 3084 3082 3117 3131 3077 3234 3053 3159 3218 3041 3021 3252 3112 3156 3134 3111 3185 3079 3195 3146 3151 3170 3192 3142 3130 3066 3130 3206 3123 3107 3159 3169 3154 3111 3191 3154 3089 3116 3240 3172 3125 3155 3115 3120 3137 3140 3084 3188 3060 3160 3148 3209 3078 3131 3133 3124 3085 3102 3091 3082 3149 3170 3104 3127 3230 3072 3051 3061 3207 3204 3129 3046 3033 3170 3080 3084 3209 3077 3195 3121 3184 3072 3119 3109 3249 3172 3164 3235 3156 3240 3251 3178 3264 3176 3179 3069 3173 3182 3240 3150 3072 3163 3210 3182 3230 3178 3129 3277 3131 3269 3199 3235 3214 3306 3162 3289 3288 3335 3370 3363 3411 3523 3483 3485 3540 3534 3641 3667 3655 3651 3779 3795 3863 3972 3890 3856 3959 3820 3965 3874 3745 3925 3798 3685 3629 3722 3697 3717 3681 3491 3500 3509 3486 3387 3272 3317 3240 3287 3336 3202 3287 3223 3171 3234 3240 3255 3181 3224 3218 3115 3225 3266 3214 3193 3267 3195 3293 3198 3255 3196 3343 3401 3236 3395 3274 3250 3321 3368 3360 3286 3390 3360 3306 3338 3506 3311 3396 3399 3515 3501 3525 3522 3572 3512 3619 3598 3628 3537 3569 3681 3572 3589 3430 3525 3528 3575 3577 3632 3479 3477 3416 3344 3411 3380 3350 3402 3342 3324 3349 3315 3332 3349 3294 3275 3269 3335 3273 3337 3312 3272 3259 3275 3350 3262 3340 3377 3293 3425 3355 3336 3347 3437 3325 3341 3412 3440 3398 3337 3415 3335 3274 3474 3490 3494 3553 3428 3584 3530 3488 3661 3575 3705 3674 3710 3689 3794 3704 3765 3742 3795 3796 3885 3946 3948 4010 4129 4195 4350 4390 4459 4463 4675 4781 4941 5119 5416 5429 5725 5967 6472 6947 7180 7868 8168 9043 9630 10656 11696 12679 13647 14858 15954 17047 18522 19801 20921 22279 23169 24171 25087 26237 26196 26612 26672 26411 25741 25289 24133 23291 21980 20621 19014 18087 17071 15843 15026 14116 13160 12034 10972 9956 9216 8394 7708 7313 6700 6413 6164 5762 5700 5557 5302 5166 4834 4800 4735 4686 4435 4310 4118 4118 4275 4235 4042 3979 3820 3757 3809 3643 3679 3659 3697 3502 3607 3595 3632 3549 3487 3422 3425 3445 3508 3380 3407 3326 3470 3338 3425 3463 3330 3303 3406 3286 3286 3323 3366 3284 3375 3339 3325 3403 3341 3308 3400 3264 3191 3354 3343 3286 3339 3330 3406 3205 3291 3345 3346 3317 3280 3385 3295 3254 3361 3350 3346 3309 3431 3324 3281 3381 3233 3276 3331 3257 3240 3143 3271 3384 3247 3281 3164 3373 3348 3175 3217 3339 3176 3224 3112 3209 3131 3245 3128 3222 3188 3261 3229 3145 3178 3256 3257 3196 3200 3256 3167 3266 3174 3207 3178 3223 3184 3206 3138 3237 3170 3193 3136 3155 3248 3318 3206 3180 3158 3274 3242 3273 3237 3234 3288 3243 3302 3272 3204 3207 3329 3221 3198 3320 3206 3354 3146 3151 3309 3368 3295 3430 3336 3370 3310 3316 3377 3351 3313 3524 3575 3526 3689 3581 3660 3686 3628 3720 3737 3738 3804 3795 3684 3742 3777 3690 3671 3704 3694 3667 3543 3596 3415 3423 3291 3496 3369 3503 3543 3259 3351 3320 3269 3331 3267 3273 3354 3211 3298 3242 3209 3177 3138 3249 3238 3266 3223 3134 3287 3254 3206 3144 3252 3188 3230 3292 3167 3138 3212 3192 3100 3242 3262 3217 3162 3311 3245 3182 3148 3104 3250 3246 3249 3128 3160 3290 3139 3132 3079 3185 3153 3180 3127 3166 3107 3313 3263 3147 3199 3236 3245 3193 3335 3150 3247 3176 3193 3119 3103 3208 3201 3225 3187 3193 3115 3100 3213 3204 3209 3265 3141 3142 3153 3107 3255 3188 3080 3213 3169 3169 3202 3251 3153 3213 3185 3203 3160 3286 3147 3233 3287 3221 3193 3165 3246 3164 3189 3140 3262 3214 3243 3230 3267 3204 3239 3214 3107 3272 3305 3351 3204 3354 3347 3236 3332 3215 3185 3210 3301 3292 3340 3313 3317 3407 3396 3437 3539 3464 3468 3593 3551 3697 3723 3696 3766 3878 3812 3956 3972 4119 3982 4115 4197 4140 4134 4082 4116 4121 3870 3935 3776 3752 3692 3751 3819 3703 3631 3667 3556 3431 3499 3401 3423 3523 3367 3440 3459 3361 3344 3321 3395 3301 3492 3283 3440 3560 3430 3598 3574 3669 3518 3670 3559 3742 3722 3710 3643 3735 3684 3698 3750 3725 3752 3760 3696 3761 3731 3589 3714 3578 3651 3475 3540 3484 3495 3566 3485 3372 3360 3426 3249 3297 3219 3270 3270 3299 3279 3318 3210 3250 3248 3223 3201 3215 3216 3302 3197 3231 3174 3152 3248 3278 3136 3227 3195 3233 3301 3270 3211 3204 3308 3192 3247 3287 3321 3214 3206 3229 3353 3245 3251 3222 3225 3234 3379 3252 3320 3257 3246 3217 3328 3354 3347 3386 3465 3362 3354 3456 3435 3452 3506 3628 3587 3499 3648 3690 3565 3670 3671 3598 3633 3691 3720 3663 3727 3688 3714 3618 3704 3592 3539 3486 3591 3497 3448 3472 3489 3454 3405 3489 3372 3385 3341 3293 3315 3290 3250 3188 3214 3184 3261 3284 3252 3286 3171 3246 3273 3273 3144 3183 3216 3220 3186 3199 3203 3187 3241 3229 3227 3265 3261 3244 3250 3358 3272 3339 3294 3376 3318 3416 3304 3286 3412 3371 3350 3404 3404 3370 3362 3279 3336 3268 3391 3367 3239 3344 3298 3262 3239 3246 3248 3267 3349 3226 3256 3247 3263 3146 3309 3086 3251 3260 3217 3157 3166 3296 3195 3192 3135 3128 3206 3292 3126 3121 3259 3200 3213 3253 3192 3199 3169 3279 3163 3237 3270 3243 3210 3216 3262 3212 3276 3259 3236 3037 3180 3152 3239 3212 3195 3222 3270 3152 3207 3141 3206 3051 3201 3186 3212 3256 3180 3230 3133 3224 3180 3220 3169 3170 3167 3258 3196 3212 3192 3103 3157 3244 3243 3127 3041 3203 3180 3186 3173 3170 3183 3222 3130 3202 3087 3151 3263 3288 3138 3259 3242 3174 3241 3219 3174 3273 3192 3273 3283 3263 3257 3193 3166 3203 3017 3266 3212 3308 3258 3167 3347 3315 3266 3225 3273 3289 3328 3314 3397 3474 3565 3351 3410 3487 3584 3656 3716 3841 3704 3758 3962 4052 4077 4055 4074 4015 4079 4011 3981 3966 3960 3911 4009 3699 3829 3597 3807 3697 3636 3692 3608 3597 3567 3530 3448 3386 3472 3416 3394 3455 3406 3296 3327 3322 3402 3261 3311 3336 3267 3253 3200 3250 3330 3176 3234 3365 3259 3298 3278 3292 3188 3175 3289 3225 3388 3282 3288 3224 3377 3228 3252 3279 3314 3276 3188 3417 3449 3465 3506 3472 3574 3533 3569 3515 3579 3488 3470 3654 3478 3652 3660 3612 3646 3592 3738 3431 3500 3416 3566 3307 3370 3418 3448 3278 3359 3430 3326 3325 3385 3352 3294 3230 3252 3226 3261 3249 3354 3259 3237 3211 3220 3241 3227 3300 3194 3155 3173 3222 3202 3216 3240 3315 3327 3333 3297 3310 3275 3142 3366 3254 3248 3235 3192 3277 3171 3257 3224 3151 3153 3287 3218 3207 3322 3203 3137 3293 3244 3179 3177 3260 3214 3207 3240 3209 3076 3229 3130 3187 3293 3190 3184 3201 3229 3192 3159 3163 3307 3178 3233 3149 3195 3122 3096 3183 3252 3154 3172 3228 3147 3299 3137 3156 3155 3246 3189 3206 3190 3218 3234 3199 3152 3226 3214 3094 3174 3149 3269 3263 3185 3160 3247 3164 3210 3209 3204 3254 3315 3207 3174 3238 3177 3166 3202 3181 3230 3174 3136 3239 3230 3198 3242 3172 3250 3255 3191 3330 3212 3251 3149 3143 3267 3174 3158 3223 3200 3270 3309 3195 3259 3279 3242 3230 3232 3259 3233 3259 3229 3271 3179 3270 3281 3261 3322 3207 3227 3202 3186 3324 3250 3208 3185 3105 3190 3312 3231 3137 3273 3272 3158 3251 3237 3174 3145 3087 3108 3207 3236 3183 3219 3129 3170 3214 3179 3237 3226 3152 3295 3152 3147 3249 3179 3226 3135 3142 3213 3266 3238 3117 3141 3193 3160 3253 3263 3265 3119 3314 3189 3096 3116 3234 3220 3177 3257 3197 3296 3248 3244 3186 3137 3232 3211 3159 3252 3155 3255 3135 3290 3177 3163 3211 3195 3158 3182 3110 3121 3128 3274 3211 3216 3263 3235 3196 3238 3273 3201 3183 3252 3186 3116 3303 3101 3302 3263 3171 3187 3148 3279 3209 3286 3364 3231 3201 3264 3282 3167 3130 3194 3220 3213 3246 3193 3225 3208 3226 3197 3356 3098 3078 3178 3247 3235 3264 3309 3047 3268 3203 3306 3167 3327 3138 3343 3247 3286 3275 3337 3327 3168 3306 3278 3320 3315 3418 3375 3399 3410 3559 3428 3465 3492 3473 3606 3598 3587 3685 3558 3484 3575 3478 3502 3580 3523 3444 3446 3419 3369 3432 3357 3361 3265 3381 3302 3327 3320 3337 3338 3301 3156 3355 3358 3285 3174 3314 3296 3317 3214 3201 3221 3316 3255 3329 3178 3219 3199 3155 3356 3250 3278 3323 3281 3302 3303 3282 3214 3387 3279 3235 3241 3342 3353 3176 3293 3397 3334 3246 3307 3314 3379 3334 3408 3263 3346 3291 3280 3235 3183 3222 3219 3256 3250 3268 3230 3195 3309 3267 3259 3306 3177 3159 3234 3247 3219 3352 3320 3237 3200 3202 3305 3257 3171 3222 3130 3211 3319 3112 3217 3249 3167 3173 3286 3194 3223 3224 3146 3213 3192 3224 3183 3203 3216 3137 3243 3156 3218 3150 3205 3226 3226 3154 3243 3211 3270 3240 3130 3214 3219 3243 3133 3218 3303 3067 3262 3172 3130 3153 3139 3268 3276 3279 3162 3246 3272 3102 3254 3285 3119 3239 3192 3185 3221 3223 3114 3218 3180 3205 3161 3193 3276 3206 3199 3151 3145 3295 3323 3192 3155 3227 3230 3152 3177 3247 3220 3261 3289 3231 3323 3192 3175 3200 3076 3255 3193 3190 3152 3292 3294 3245 3183 3131 3184 3168 3236 3212 3222 3108 3233 3177 3218 3239 3245 3155 3175 3240 3272 3264 3275 3146 3248 3171 3237 3272 3273 3219 3220 3158 3295 3289 3261 3216 3307 3217 3300 3272 3340 3362 3226 3201 3308 3301 3311 3199 3196 3249 3299 3280 3206 3312 3207 3286 3201 3298 3313 3305 3240 3284 3331 3372 3339 3345 3337 3314 3299 3477 3354 3339 3341 3338 3600 3431 3311 3334 3268 3336 3402 3445 3356 3355 3384 3462 3344 3331 3316 3360 3349 3286 3375 3393 3395 3321 3289 3238 3314 3264 3294 3314 3345 3339 3309 3292 3358 3424 3440 3468 3485 3479 3521 3536 3448 3599 3600 3546 3475 3616 3579 3634 3467 3557 3609 3497 3393 3517 3490 3462 3485 3480 3428 3448 3473 3423 3432 3418 3374 3305 3438 3412 3287 3388 3271 3291 3347 3237 3259 3308 3318 3290 3203 3270 3262 3194 3270 3240 3284 3330 3327 3307 3292 3224 3242 3345 3159 3242 3186 3223 3188 3255 3295 3242 3219 3301 3217 3299 3308 3258 3219 3215 3262 3283 3177 3247 3224 3238 3243 3174 3255 3268 3265 3335 3281 3275 3185 3102 3276 3269 3207 3345 3225 3271 3226 3305 3371 3290 3333 3353 3333 3333 3378 3419 3394 3396 3308 3322 3355 3235 3302 3386 3332 3470 3397 3235 3218 3349 3418 3234 3296 3304 3361 3243 3213 3282 3350 3286 3170 3301 3418 3359 3329 3222 3346 3354 3201 3251 3329 3192 3232 3260 3189 3313 3146 3208 3258 3247 3225 3254 3211 3167 3240 3300 3275 3243 3260 3257 3212 3339 3303 3354 3340 3298 3262 3272 3327 3312 3238 3229 3359 3352 3343 3267 3252 3279 3261 3403 3282 3369 3464 3328 3300 3407 3374 3373 3322 3521 3517 3393 3421 3644 3435 3643 3703 3719 3637 3648 3665 3726 3697 3731 3776 3719 3786 3791 3820 3741 3667 3635 3756 3593 3659 3615 3703 3597 3499 3538 3579 3542 3529 3492 3527 3461 3505 3380 3419 3318 3355 3323 3348 3393 3345 3201 3273 3332 3201 3304 3315 3252 3391 3344 3539 3261 3369 3253 3314 3421 3325 3329 3347 3384 3306 3324 3485 3371 3355 3371 3358 3302 3383 3379 3546 3326 3453 3375 3404 3351 3480 3439 3393 3316 3412 3361 3338 3380 3324 3394 3484 3643 3634 3616 3573 3573 3585 3636 3844 3724 3845 3811 3935 3923 4017 3977 4011 4091 3928 4110 3952 3981 3945 3885 3878 3961 3851 3816 3827 3816 3865 3971 3962 3929 3929 3824 3944 3841 3923 3907 3939 3847 3902 3848 3890 3968 3871 3906 4100 4138 4063 4210 4266 4378 4333 4435 4474 4569 4682 4768 4766 5123 5010 5286 5472 5556 5719 6023 6332 6516 6762 7172 7287 7615 8019 8191 8633 9092 9534 9779 10399 10625 10822 11238 11461 11486 11639 11807 11946 11931 12035 11783 11724 11588 11232 11102 11063 10852 10572 10341 10203 9690 9613 9308 9097 8754 8504 8390 7995 7910 7306 7294 6975 6744 6466 6101 5967 5865 5597 5337 5257 5114 4855 4951 4757 4685 4446 4394 4421 4316 4171 4097 3997 3963 4123 4023 3860 3889 3842 3792 3783 3736 3770 3691 3662 3779 3584 3716 3645 3533 3594 3453 3561 3465 3513 3513 3603 3424 3490 3398 3460 3413 3457 3495 3515 3514 3487 3459 3350 3372 3465 3414 3471 3361 3429 3430 3402 3334 3490 3342 3411 3361 3369 3396 3284 3418 3356 3427 3224 3404 3346 3348 3350 3356 3288 3324 3347 3377 3265 3332 3308 3385 3419 3254 3399 3411 3452 3429 3392 3415 3303 3467 3364 3285 3400 3452 3361 3440 3444 3478 3388 3414 3518 3476 3426 3377 3483 3457 3389 3440 3467 3557 3511 3513 3493 3519 3471 3458 3371 3530 3399 3427 3439 3455 3541 3381 3521 3521 3480 3516 3385 3298 3403 3385 3390 3242 3341 3420 3356 3467 3473 3367 3464 3406 3408 3247 3227 3324 3373 3392 3306 3276 3382 3372 3328 3398 3339 3297 3292 3392 3330 3356 3308 3308 3362 3215 3381 3340 3385 3265 3294 3351 3307 3205 3330 3343 3299 3416 3254 3236 3294 3229 3267 3318 3320 3251 3269 3359 3208 3224 3318 3340 3366 3228 3339 3330 3281 3338 3390 3331 3249 3232 3252 3334 3284 3259 3305 3259 3266 3188 3318 3224 3265 3206 3279 3335 3217 3328 3218 3248 3240 3189 3165 3212 3231 3165 3200 3267 3412 3189 3307 3295 3398 3356 3379 3324 3218 3356 3345 3303 3336 3390 3291 3354 3280 3374 3284 3361 3334 3432 3343 3345 3440 3418 3415 3548 3482 3477 3466 3523 3561 3495 3457 3482 3448 3429 3430 3483 3567 3469 3503 3414 3412 3387 3375 3334 3456 3316 3345 3412 3515 3382 3434 3379 3201 3365 3288 3246 3240 3370 3311 3431 3266 3214 3277 3205 3295 3393 3301 3185 3375 3213 3244 3161 3321 3281 3239 3314 3313 3317 3254 3274 3287 3225 3242 3242 3256 3384 3220 3286 3400 3249 3342 3250 3211 3287 3345 3226 3316 3225 3317 3229 3238 3187 3265 3334 3322 3272 3234 3213 3347 3309 3215 3245 3224 3212 3290 3276 3283 3293 3317 3342 3165 3226 3278 3200 3164 3416 3235 3303 3309 3201 3370 3253 3327 3253 3303 3243 3347 3259 3339 3249 3310 3191 3272 3243 3254 3268 3277 3264 3294 3308 3330 3373 3240 3225 3238 3339 3311 3200 3234 3233 3259 3293 3229 3287 3381 3280 3301 3268 3217 3257 3359 3300 3330 3367 3305 3362 3429 3354 3270 3478 3365 3494 3396 3407 3428 3277 3335 3407 3427 3461 3269 3473 3455 3450 3375 3369 3326 3332 3449 3342 3380 3401 3439 3365 3357 3436 3338 3359 3274 3326 3304 3304 3317 3368 3277 3330 3353 3230 3403 3346 3344 3322 3379 3367 3347 3353 3381 3373 3363 3383 3419 3246 3330 3324 3458 3367 3320 3379 3332 3304 3376 3391 3417 3384 3361 3267 3374 3296 3326 3335 3381 3306 3314 3328 3308 3416 3406 3417 3363 3444 3340 3376 3381 3350 3355 3334 3316 3394 3383 3382 3429 3323 3378 3416 3426 3447 3383 3363 3497 3343 3522 3406 3464 3520 3450 3504 3440 3531 3506 3533 3431 3525 3575 3546 3428 3470 3368 3522 3569 3499 3364 3490 3380 3457 3453 3474 3436 3359 3436 3474 3409 3389 3438 3407 3286 3296 3379 3218 3422 3341 3251 3432 3378 3226 3350 3363 3327 3321 3335 3351 3195 3301 3261 3333 3351 3302 3304 3460 3247 3397 3301 3388 3315 3336 3324 3311 3422 3451 3315 3403 3368 3509 3569 3466 3510 3498 3477 3559 3477 3455 3481 3459 3426 3494 3508 3341 3409 3397 3423 3438 3438 3473 3364 3484 3396 3431 3370 3376 3569 3423 3415 3368 3399 3337 3409 3419 3392 3326 3281 3380 3237 3362 3370 3316 3288 3464 3302 3457 3298 3351 3348 3412 3320 3368 3364 3351 3354 3435 3371 3393 3362 3434 3335 3373 3380 3475 3495 3343 3485 3491 3379 3377 3508 3480 3490 3505 3579 3502 3459 3458 3502 3497 3486 3401 3400 3461 3343 3329 3460 3464 3498 3335 3255 3378 3471 3336 3442 3298 3425 3341 3350 3370 3428 3428 3278 3411 3289 3340 3360 3198 3409 3289 3339 3144 3309 3322 3289 3348 3322 3163 3228 3315 3204 3281 3251 3194 3294 3189 3308 3295 3314 3276 3243 3368 3182 3285 3103 3272 3398 3258 3270 3137 3294 3257 3323 3318 3260 3244 3318 3302 3190 3288 3252 3314 3374 3278 3320 3270 3465 3267 3254 3242 3320 3305 3312 3291 3314 3205 3365 3284 3291 3307 3253 3257 3270 3343 3163 3274 3256 3211 3390 3361 3307 3339 3291 3356 3317 3395 3386 3351 3316 3405 3285 3388 3495 3299 3465 3411 3329 3374 3346 3362 3340 3311 3416 3413 3367 3320 3414 3467 3431 3478 3400 3373 3353 3402 3325 3326 3424 3382 3526 3347 3381 3377 3343 3331 3330 3417 3355 3491 3275 3369 3368 3448 3459 3294 3409 3386 3400 3404 3366 3400 3441 3372 3514 3507 3544 3550 3557 3625 3539 3650 3543 3623 3604 3588 3501 3526 3495 3564 3550 3523 3460 3373 3425 3496 3555 3450 3491 3545 3468 3545 3520 3534 3559 3484 3432 3485 3438 3611 3542 3582 3454 3526 3525 3593 3677 3560 3677 3571 3648 3469 3591 3594 3567 3534 3550 3495 3527 3485 3446 3419 3505 3453 3497 3432 3452 3473 3395 3366 3557 3388 3388 3350 3400 3424 3407 3376 3354 3351 3338 3258 3280 3350 3399 3351 3318 3391 3271 3357 3280 3276 3351 3295 3275 3330 3308 3299 3376 3282 3275 3360 3227 3381 3235 3333 3300 3264 3302 3307 3237 3271 3348 3319 3282 3319 3208 3378 3340 3427 3359 3225 3300 3337 3297 3383 3186 3231 3279 3287 3339 3172 3248 3192 3271 3235 3317 3388 3317 3270 3336 3351 3301 3255 3432 3357 3280 3303 3404 3273 3251 3283 3361 3270 3261 3280 3307 3377 3317 3241 3321 3328 3343 3346 3294 3424 3324 3242 3445 3469 3229 3358 3401 3392 3340 3345 3413 3355 3334 3305 3384 3293 3282 3210 3377 3275 3342 3305 3371 3456 3484 3348 3432 3365 3380 3394 3436 3541 3458 3484 3532 3442 3502 3478 3552 3585 3585 3633 3466 3465 3654 3584 3585 3584 3619 3575 3701 3685 3685 3723 3561 3474 3560 3525 3557 3533 3544 3551 3407 3517 3496 3554 3556 3540 3495 3583 3472 3570 3610 3564 3530 3527 3467 3456 3546 3554 3533 3449 3542 3545 3603 3577 3507 3493 3604 3546 3728 3642 3691 3586 3676 3597 3678 3667 3745 3822 3682 3795 3723 3842 3835 3849 3950 3854 4044 4093 4058 4116 4362 4391 4393 4533 4624 4760 4969 5108 5046 5255 5399 5581 5648 5860 6035 6112 6009 6178 6190 6220 6216 6350 6424 6275 6231 6100 5871 5886 5913 5919 5806 5692 5599 5663 5560 5568 5478 5501 5554 5391 5378 5267 5235 5128 5012 4855 4886 4892 4707 4672 4501 4401 4380 4328 4354 4262 4171 4105 4053 4040 3957 3868 3832 3865 3772 3905 3823 3946 3814 3785 3861 3745 3680 3637 3738 3614 3647 3792 3726 3630 3642 3593 3581 3633 3593 3548 3473 3481 3509 3502 3446 3456 3428 3545 3579 3516 3575 3402 3471 3505 3431 3470 3421 3432 3464 3403 3478 3295 3388 3486 3297 3417 3466 3426 3285 3403 3353 3406 3451 3432 3368 3262 3445 3327 3376 3342 3344 3333 3386 3345 3311 3417 3381 3392 3458 3322 3353 3298 3352 3469 3425 3266 3310 3330 3285 3365 3362 3248 3317 3337 3332 3332 3289 3337 3328 3329 3273 3374 3372 3384 3352 3324 3441 3337 3236 3284 3323 3299 3293 3328 3284 3386 3392 3346 3277 3292 3382 3420 3408 3436 3464 3427 3378 3313 3391 3352 3325 3479 3336 3410 3380 3465 3443 3496 3527 3479 3536 3337 3305 3397 3376 3389 3438 3352 3319 3393 3417 3419 3451 3404 3343 3352 3383 3250 3302 3280 3417 3327 3402 3385 3357 3425 3404 3397 3294 3391 3383 3342 3293 3275 3345 3315 3272 3496 3429 3327 3447 3348 3352 3299 3352 3361 3432 3288 3315 3461 3253 3291 3398 3274 3410 3411 3388 3328 3270 3346 3478 3341 3350 3320 3334 3403 3446 3275 3335 3394 3452 3472 3536 3349 3441 3463 3516 3553 3658 3548 3511 3515 3414 3488 3509 3512 3513 3449 3456 3535 3486 3352 3564 3377 3465 3525 3390 3406 3446 3397 3365 3460 3375 3559 3430 3387 3338 3429 3426 3465 3494 3501 3466 3444 3487 3435 3431 3429 3346 3455 3368 3377 3358 3336 3501 3282 3519 3525 3398 3438 3510 3494 3392 3511 3362 3351 3558 3457 3413 3479 3420 3464 3424 3456 3557 3408 3475 3501 3538 3426 3507 3576 3531 3558 3533 3645 3555 3616 3691 3747 3707 3723 3872 3838 3849 3854 3872 3988 4043 3992 3981 4166 4103 4235 4252 4378 4574 4479 4556 4752 4757 4841 4903 5065 5151 5233 5157 5083 5255 5266 5088 5207 5240 5118 5117 5127 5099 4947 4922 5095 5089 5040 5074 5064 4939 5061 4978 4938 5021 4843 4817 4768 4731 4705 4599 4557 4530 4470 4468 4301 4211 4308 4103 4163 4062 4050 4045 3981 4029 3962 3909 3855 3928 3905 3800 3765 3701 3606 3707 3739 3647 3632 3565 3567 3490 3613 3565 3543 3460 3454 3527 3359 3548 3467 3494 3451 3483 3444 3393 3445 3476 3428 3443 3363 3365 3440 3510 3465 3354 3416 3260 3553 3438 3313 3338 3343 3336 3390 3388 3353 3370 3491 3406 3408 3392 3313 3327 3401 3440 3379 3300 3363 3274 3293 3362 3301 3276 3227 3364 3339 3389 3293 3275 3477 3316 3290 3330 3347 3377 3377 3450 3311 3371 3250 3319 3305 3257 3315 3344 3338 3320 3330 3298 3345 3366 3260 3296 3331 3354 3347 3287 3221 3196 3285 3326 3241 3338 3327 3359 3263 3229 3252 3330 3252 3317 3224 3287 3429 3327 3267 3399 3299 3302 3348 3507 3239 3264 3257 3319 3414 3325 3321 3327 3255 3431 3352 3367 3280 3298 3395 3453 3341 3279 3319 3488 3450 3261 3362 3369 3309 3200 3372 3443 3386 3376 3292 3363 3322 3327 3301 3373 3300 3312 3349 3339 3200 3330 3494 3334 3407 3257 3292 3223 3310 3297 3253 3244 3399 3248 3371 3362 3235 3328 3312 3255 3269 3373 3254 3280 3429 3307 3184 3347 3178 3327 3385 3212 3216 3303 3250 3269 3299 3318 3298 3272 3227 3180 3286 3321 3267 3326 3297 3279 3311 3332 3358 3341 3252 3235 3274 3281 3403 3287 3294 3221 3429 3306 3366 3321 3305 3214 3318 3389 3418 3263 3329 3221 3212 3205 3360 3324 3391 3229 3420 3332 3351 3289 3377 3409 3356 3344 3351 3304 3399 3369 3393 3260 3294 3321 3261 3294 3285 3430 3252 3354 3453 3351 3482 3211 3371 3385 3390 3432 3394 3389 3373 3269 3394 3377 3260 3420 3350 3331 3437 3421 3393 3418 3326 3327 3352 3389 3355 3412 3255 3361 3364 3402 3394 3327 3323 3275 3346 3360 3338 3369 3251 3307 3312 3306 3429 3364 3336 3417 3312 3316 3307 3283 3241 3316 3402 3210 3242 3193 3267 3402 3301 3303 3314 3332 3295 3289 3342 3270 3222 3217 3372 3359 3301 3357 3339 3288 3307 3295 3353 3404 3289 3320 3319 3258 3271 3228 3305 3232 3306 3301 3379 3228 3318 3386 3288 3286 3349 3330 3310 3397 3333 3241 3390 3357 3297 3292 3268 3394 3261 3355 3319 3372 3449 3265 3294 3465 3450 3450 3358 3331 3302 3343 3335 3395 3329 3300 3409 3269 3319 3394 3289 3301 3280 3332 3379 3327 3335 3400 3486 3281 3294 3303 3408 3397 3411 3385 3419 3387 3308 3414 3354 3432 3334 3401 3255 3250 3281 3190 3264 3278 3319 3305 3335 3322 3314 3409 3398 3246 3301 3325 3298 3273 3380 3303 3215 3461 3357 3389 3348 3358 3392 3215 3254 3347 3356 3416 3319 3316 3240 3385 3293 3272 3282 3402 3221 3274 3264 3325 3354 3299 3366 3384 3377 3351 3312 3370 3364 3417 3304 3376 3298 3400 3325 3340 3359 3347 3260 3387 3302 3299 3404 3288 3324 3284 3353 3316 3283 3322 3340 3220 3430 3343 3335 3323 3280 3280 3285 3221 3338 3346 3295 3281 3313 3440 3367 3359 3384 3416 3264 3417 3378 3410 3401 3355 3364 3313 3492 3366 3406 3432 3459 3354 3348 3253 3312 3300 3334 3295 3311 3316 3417 3334 3243 3321 3349 3395 3418 3387 3443 3426 3405 3439 3368 3397 3307 3425 3217 3212 3282 3222 3351 3260 3347 3332 3272 3352 3322 3189 3221 3253 3279 3302 3408 3345 3305 3349 3314 3273 3328 3275 3330 3258 3342 3261 3330 3315 3391 3332 3325 3356 3319 3248 3168 3292 3402 3336 3302 3303 3338 3259 3340 3293 3394 3278 3412 3265 3311 3311 3248 3347 3326 3328 3351 3345 3366 3403 3436 3278 3376 3336 3386 3391 3393 3433 3377 3419 3326 3314 3373 3313 3438 3368 3366 3497 3398 3576 3340 3353 3392 3433 3397 3501 3420 3342 3403 3336 3395 3331 3399 3294 3357 3426 3363 3439 3445 3469 3429 3377 3273 3404 3330 3357 3415 3410 3432 3365 3290 3283 3407 3431 3272 3499 3277 3335 3356 3422 3401 3314 3336 3338 3358 3333 3301 3295 3294 3288 3332 3317 3351 3332 3364 3367 3358 3289 3402 3356 3402 3387 3296 3260 3353 3400 3330 3329 3330 3314 3337 3418 3352 3231 3322 3260 3315 3327 3264 3307 3341 3312 3414 3421 3211 3222 3327 3392 3332 3325 3193 3344 3203 3378 3329 3377 3259 3367 3327 3397 3306 3305 3338 3256 3363 3255 3287 3319 3277 3312 3277 3381 3255 3362 3442 3376 3299 3346 3351 3377 3292 3381 3327 3276 3354 3256 3299 3370 3450 3351 3239 3316 3245 3355 3266 3295 3374 3376 3318 3361 3321 3330 3480 3302 3304 3246 3350 3398 3313 3304 3378 3364 3343 3265 3339 3394 3374 3413 3449 3403 3435 3316 3365 3490 3431 3402 3472 3347 3362 3368 3351 3328 3288 3335 3459 3442 3447 3437 3340 3379 3439 3363 3311 3391 3351 3379 3416 3335 3407 3454 3387 3438 3313 3414 3335 3488 3401 3272 3369 3306 3315 3374 3326 3426 3440 3325 3292 3281 3443 3311 3501 3375 3413 3318 3365 3311 3271 3285 3300 3316 3353 3352 3326 3311 3310 3354 3413 3347 3214 3347 3202 3302 3373 3419 3370 3229 3333 3299 3311 3264 3282 3333 3290 3366 3374 3361 3392 3305 3329 3291 3289 3268 3334 3330 3284 3400 3300 3342 3351 3252 3353 3411 3395 3303 3208 3304 3225 3284 3400 3315 3399 3347 3275 3372 3397 3407 3327 3314 3275 3415 3244 3396 3299 3472 3497 3408 3448 3374 3423 3427 3377 3419 3373 3400 3480 3405 3384 3335 3332 3342 3424 3372 3344 3419 3335 3348 3322 3306 3244 3401 3331 3316 3360 3336 3440 3232 3358 3378 3393 3336 3321 3297 3343 3284 3330 3390 3339 3412 3356 3311 3300 3421 3370 3368 3387 3504 3274 3236 3277 3309 3432 3408 3329 3392 3346 3273 3357 3414 3351 3312 3259 3401 3343 3374 3356 3415 3329 3478 3475 3351 3370 3410 3385 3380 3434 3414 3462 3438 3465 3465 3465 3402 3507 3483 3467 3430 3379 3399 3359 3519 3432 3449 3461 3411 3419 3285 3308 3427 3316 3423 3391 3329 3294 3358 3340 3426 3375 3384 3339 3401 3328 3437 3420 3402 3304 3264 3400 3345 3408 3335 3307 3288 3337 3356 3354 3316 3313 3428 3302 3379 3334 3266 3363 3290 3198 3310 3402 3390 3305 3408 3416 3296 3357 3389 3352 3262 3367 3232 3391 3386 3293 3291 3346 3269 3411 3308 3320 3281 3226 3295 3470 3359 3315 3263 3352 3273 3305 3406 3241 3290 3337 3314 3389 3387 3286 3278 3380 3355 3313 3440 3404 3339 3282 3351 3334 3401 3217 3402 3404 3366 3289 3296 3308 3365 3351 3429 3386 3321 3271 3263 3353 3356 3302 3262 3363 3284 3302 3320 3396 3385 3316 3326 3226 3406 3307 3338 3317 3299 3306 3257 3322 3280 3325 3210 3405 3386 3355 3360 3295 3274 3253 3286 3257 3337 3353 3289 3413 3359 3304 3446 3309 3418 3315 3325 3379 3308 3455 3424 3399 3359 3323 3325 3414 3220 3411 3398 3478 3277 3325 3446 3265 3394 3296 3388 3499 3355 3348 3391 3373 3344 3344 3359 3300 3405 3386 3390 3351 3347 3493 3448 3402 3518 3465 3368 3381 3430 3343 3476 3382 3434 3436 3419 3341 3419 3455 3311 3301 3346 3376 3306 3399 3277 3346 3301 3430 3292 3378 3405 3366 3378 3373 3308 3393 3432 3299 3322 3397 3526 3331 3446 3401 3280 3281 3434 3397 3403 3349 3528 3414 3443 3438 3454 3395 3402 3393 3556 3471 3455 3461 3453 3443 3439 3384 3440 3352 3396 3442 3386 3397 3368 3280 3410 3392 3392 3396 3460 3376 3307 3468 3395 3353 3456 3421 3434 3429 3409 3426 3363 3378 3346 3411 3353 3370 3322 3364 3454 3329 3359 3341 3414 3422 3350 3339 3420 3288 3475 3348 3417 3300 3284 3356 3348 3344 3432 3321 3334 3316 3379 3313 3346 3341 3307 3433 3372 3472 3443 3399 3384 3501 3433 3380 3334 3407 3479 3320 3372 3464 3395 3452 3372 3321 3379 3416 3342 3435 3411 3397 3392 3360 3357 3407 3410 3384 3455 3473 3448 3538 3539 3562 3593 3476 3421 3479 3601 3499 3509 3441 3513 3419 3450 3524 3649 3544 3524 3493 3561 3468 3666 3799 3656 3600 3693 3699 3657 3685 3809 3825 3872 3957 3981 3969 3950 4045 4161 4086 4261 4245 4338 4408 4335 4384 4339 4344 4304 4246 4331 4195 4238 4175 4106 4014 4037 4029 4078 4026 3993 3986 3909 3879 3929 3853 3999 3795 3832 3904 4084 4012 3976 3943 3844 3897 3940 3943 3944 3884 3908 3770 3680 3751 3731 3694 3617 3723 3626 3700 3713 3523 3587 3517 3572 3508 3593 3514 3491 3419 3389 3378 3383 3492 3375 3455 3490 3343 3453 3379 3499 3404 3505 3375 3429 3437 3423 3271 3467 3411 3448 3423 3272 3338 3430 3437 3319 3301 3446 3284 3339 3427 3459 3383 3384 3355 3331 3392 3365 3292 3391 3409 3426 3388 3327 3413 3451 3358 3358 3527 3455 3414 3410 3286 3416 3253 3369 3307 3319 3422 3294 3281 3310 3280 3310 3355 3305 3243 3287 3389 3385 3312 3397 3326 3312 3370 3356 3231 3326 3488 3337 3324 3530 3347 3292 3402 3268 3367 3376 3345 3366 3241 3413 3256 3292 3290 3461 3281 3389 3326 3372 3375 3409 3318 3306 3341 3481 3339 3392 3362 3303 3272 3316 3210 3279 3473 3269 3394 3369 3544 3406 3512 3236 3364 3365 3317 3250 3186 3350 3292 3373 3422 3306 3268 3375 3297 3327 3355 3327 3301 3359 3255 3427 3346 3294 3356 3363 3374 3393 3430 3384 3347 3362 3395 3395 3413 3367 3347 3382 3256 3325 3437 3455 3289 3388 3345 3411 3320 3383 3329 3216 3460 3367 3222 3419 3392 3342 3343 3437 3308 3357 3363 3231 3389 3265 3334 3307 3330 3356 3328 3372 3316 3349 3298 3410 3357 3317 3359 3414 3360 3347 3308 3436 3330 3361 3368 3442 3444 3379 3321 3442 3357 3303 3355 3409 3384 3322 3347 3380 3361 3427 3364 3323 3258 3331 3470 3417 3331 3393 3279 3316 3372 3306 3439 3249 3329 3254 3336 3320 3391 3312 3387 3358 3359 3362 3355 3454 3392 3339 3229 3329 3374 3403 3393 3400 3360 3285 3378 3354 3313 3389 3349 3329 3313 3418 3372 3390 3427 3442 3271 3361 3405 3456 3383 3336 3293 3307 3405 3384 3333 3350 3176 3233 3334 3424 3413 3354 3330 3317 3263 3361 3438 3440 3323 3273 3297 3230 3347 3398 3384 3441 3366 3406 3414 3333 3321 3213 3255 3333 3430 3374 3360 3335 3335 3504 3365 3270 3384 3420 3365 3345 3380 3348 3369 3463 3379 3436 3342 3351 3314 3471 3387 3411 3417 3309 3320 3310 3293 3433 3446 3389 3369 3321 3391 3360 3406 3331 3380 3452 3301 3308 3389 3367 3438 3427 3371 3451 3412 3393 3377 3331 3527 3486 3392 3349 3403 3437 3353 3404 3461 3422 3466 3438 3447 3522 3464 3568 3402 3420 3383 3396 3413 3364 3408 3326 3496 3428 3356 3439 3425 3393 3356 3368 3435</counts>
			</dataPoints>
		</scan>
	</xrdMeasurement>
</xrdMeasurements>