File: dataset/precursor_mixture/V2O5_0p6008-ZnO_0p4010--2min.xrdml
<?xml version="1.0"?>
<xrdMeasurements xmlns="http://www.xrdml.com/XRDMeasurement/2.3" xmlns:xsi="http://www.w3.org/2001/XMLSchema-instance" xsi:schemaLocation="http://www.xrdml.com/XRDMeasurement/2.3 http://www.xrdml.com/XRDMeasurement/2.3/XRDMeasurement.xsd" status="Completed" recordIdentifier="{81C23852-8AB5-4EFC-A816-5007F2A31AC2}">
	<comment>
		<entry/>
	</comment>
	<sample type="To be analyzed">
		<id>V2O5_0p6008-ZnO_0p4010--2min</id>
		<name></name>
		<preparedBy></preparedBy>
	</sample>
	<xrdMeasurement measurementType="Scan" status="Completed" sampleMode="Reflection">
		<usedWavelength intended="K-Alpha 1">
			<kAlpha1 unit="Angstrom">1.5405980</kAlpha1>
			<kAlpha2 unit="Angstrom">1.5444260</kAlpha2>
			<kBeta unit="Angstrom">1.3922500</kBeta>
			<ratioKAlpha2KAlpha1>0.5000</ratioKAlpha2KAlpha1>
		</usedWavelength>
		<incidentBeamPath>
			<radius unit="mm">145.00</radius>
			<xRayTube id="1010048" name="Empyrean Cu LFF HR (9430 033 7310x)">
				<tension unit="kV">40.0</tension>
				<current unit="mA">15.0</current>
				<anodeMaterial>Cu</anodeMaterial>
				<focus type="Line">
					<length unit="mm">12.0</length>
					<width unit="mm">0.4</width>
					<takeOffAngle unit="deg">6.0</takeOffAngle>
				</focus>
			</xRayTube>
			<sollerSlit id="21010002" name="Soller slits 0.04 rad.">
				<opening unit="rad">0.0400</opening>
			</sollerSlit>
			<mask id="22031000" name="Fixed mask 13 mm">
				<width unit="mm">9.00</width>
			</mask>
			<divergenceSlit id="22120001" name="Divergence slit 1°" xsi:type="fixedDivergenceSlitType">
				<distanceToSample unit="mm">50.00</distanceToSample>
				<height unit="mm">1.52</height>
			</divergenceSlit>
		</incidentBeamPath>
		<sampleMovement xsi:type="spinningSampleMovementType">
			<spinnerRevolutionTime unit="seconds">1.0</spinnerRevolutionTime>
		</sampleMovement>
		<diffractedBeamPath>
			<radius unit="mm">145.00</radius>
			<antiScatterSlit id="22090040" name="AS slit 9 mm (PIXcel)" xsi:type="fixedAntiScatterSlitType">
				<height unit="mm">9.00</height>
			</antiScatterSlit>
			<sollerSlit id="21020003" name="Large Soller slits 0.04 rad.">
				<opening unit="rad">0.0400</opening>
			</sollerSlit>
			<filter id="20030001" name="Large beta-filter Nickel">
				<material>Ni</material>
				<thickness unit="mm">0.020</thickness>
			</filter>
			<detector id="7010019" name="PIXcel1D-Medipix3 detector" xsi:type="rtmsDetectorType">
				<phd unit="keV">
					<lowerLevel>4.02</lowerLevel>
					<upperLevel>11.27</upperLevel>
				</phd>
				<mode>Scanning</mode>
				<activeLength unit="deg">5.542</activeLength>
			</detector>
		</diffractedBeamPath>
		<scan appendNumber="0" mode="Continuous" scanAxis="Gonio" status="Completed">
			<header>
				<startTimeStamp>2024-11-14T13:14:31-08:00</startTimeStamp>
				<endTimeStamp>2024-11-14T13:16:35-08:00</endTimeStamp>
				<author>
					<name>AutomatedUser</name>
				</author>
				<source>
					<applicationSoftware version="1.7b (136)">PANalytical Aeris Instrument Suite</applicationSoftware>
					<instrumentControlSoftware version="3.2.00000000 20240306">AERIS</instrumentControlSoftware>
					<instrumentID>950485</instrumentID>
				</source>
			</header>
			<dataPoints>
				<positions axis="2Theta" unit="deg">
					<startPosition>10.02173288</startPosition>
					<endPosition>99.99585608</endPosition>
				</positions>
				<positions axis="Omega" unit="deg">
					<startPosition>5.01086644</startPosition>
					<endPosition>49.99792804</endPosition>
				</positions>
				<commonCountingTime unit="seconds">10.965</commonCountingTime>
				<counts unit="counts">1948 1904 1895 1866 1966 2022 1914 1890 1858 1893 1822 1839 1854 1818 1829 1823 1739 1809 1786 1795 1818 1740 1678 1603 1633 1623 1689 1696 1642 1600 1606 1572 1613 1630 1567 1578 1553 1520 1566 1570 1596 1627 1549 1572 1542 1468 1540 1423 1476 1326 1452 1439 1401 1481 1508 1460 1394 1353 1452 1433 1349 1424 1373 1339 1412 1354 1342 1371 1331 1283 1348 1372 1288 1236 1301 1294 1293 1250 1317 1325 1314 1270 1239 1218 1233 1240 1254 1248 1238 1279 1275 1229 1234 1174 1213 1241 1205 1183 1269 1160 1254 1242 1181 1198 1208 1141 1182 1172 1110 1198 1146 1167 1165 1230 1208 1167 1209 1312 1219 1246 1361 1417 1473 1502 1551 1631 1702 1620 1753 1580 1449 1372 1200 1225 1169 1116 1063 1138 1094 1101 1067 1085 1064 1040 1060 1031 1092 1071 1051 1110 1012 1057 1049 1042 1040 1010 1015 1051 1059 1059 1018 1103 1047 1050 1045 1063 1070 1011 1000 1011 1003 1001 1023 1060 1023 1028 970 1047 1003 1031 936 948 1000 996 953 1010 964 981 939 935 975 1005 963 1042 999 962 920 1012 940 993 974 951 944 940 945 965 989 956 912 935 943 1052 975 1012 935 911 991 880 991 957 958 951 977 948 1001 974 1025 1052 1099 1203 1333 1350 1527 1633 1926 2107 2364 2691 2797 2982 2952 2874 2711 2329 1773 1472 1307 1188 1153 963 1063 1000 949 940 905 973 938 966 894 900 976 951 939 986 1052 1092 1025 1108 1290 1367 1363 1478 1476 1417 1368 1497 1299 1167 1050 983 881 849 892 884 836 828 851 832 786 814 881 775 794 783 755 785 801 760 779 799 795 784 750 740 763 720 737 824 790 794 744 751 744 803 717 717 728 765 722 818 705 774 761 731 760 709 663 732 746 708 699 749 716 674 735 685 664 755 721 714 667 694 730 697 703 726 704 711 665 722 778 719 710 770 756 754 776 804 823 863 838 870 897 909 887 937 1029 1074 1124 1310 1564 1818 2101 2244 2404 2484 2478 2371 2024 1572 1189 988 828 835 816 707 703 724 728 717 698 677 735 732 699 737 676 634 685 686 692 664 661 736 707 622 649 717 676 676 648 656 636 632 648 645 680 647 655 660 636 630 607 652 643 654 591 620 643 662 646 598 655 626 628 642 673 615 552 632 628 634 664 614 622 662 643 621 569 570 618 644 607 603 646 604 635 587 616 610 606 599 565 584 590 639 609 656 657 670 717 669 704 703 709 691 760 797 847 942 1062 1296 1403 1581 1842 2073 2215 2403 2396 2196 1920 1548 1312 1054 1046 1045 1110 1291 1534 1843 2171 2745 3149 3404 3836 3887 3601 3052 2408 1802 1348 1155 1117 1161 1123 1172 1314 1310 1436 1383 1246 1226 1008 944 817 736 706 677 644 619 652 634 618 651 719 746 709 795 893 778 828 823 786 701 766 647 642 655 686 603 621 665 667 736 748 848 907 1037 1183 1523 1918 2248 2706 3051 3486 3539 3590 3267 2590 1913 1368 963 810 710 716 704 672 619 619 585 581 600 647 593 570 583 603 587 605 621 631 681 660 711 727 745 823 911 1030 1213 1537 1881 2479 3058 3927 4684 5353 6007 6332 6252 5190 4047 2803 1866 1365 1050 885 794 691 662 602 635 608 602 542 558 567 567 580 604 589 567 609 609 552 550 544 533 489 508 541 458 476 487 479 472 484 457 473 463 471 476 471 459 463 464 478 469 434 439 449 477 399 460 468 465 436 434 406 465 435 427 445 467 451 449 426 461 442 420 435 488 449 448 406 434 442 405 432 426 453 415 415 473 484 454 434 462 447 448 434 438 461 461 403 431 443 450 445 458 461 441 507 493 563 557 629 664 644 690 757 781 750 835 833 736 664 675 607 596 576 534 479 491 475 600 548 604 597 609 621 621 579 603 510 510 459 482 460 500 417 421 470 454 392 386 417 416 416 394 399 398 411 445 415 386 421 397 370 412 367 441 381 380 415 377 424 407 438 438 418 383 412 405 402 385 410 362 399 397 421 436 411 428 407 419 482 416 415 362 413 435 412 439 375 381 440 448 422 452 431 435 524 466 550 601 653 689 716 792 743 722 732 657 615 567 519 449 433 460 442 446 416 414 407 427 440 457 397 447 429 374 409 393 448 396 435 433 406 457 443 463 472 518 564 538 647 678 772 926 1084 1297 1434 1655 1801 1969 2059 2053 2141 1985 1754 1493 1245 1120 990 944 860 784 701 605 612 528 508 509 505 525 505 526 547 556 480 523 574 652 668 696 681 699 731 681 593 571 524 465 495 475 397 471 465 476 445 537 491 464 440 474 469 465 385 419 408 424 431 448 401 415 428 366 398 360 366 398 409 380 346 426 408 389 408 414 446 458 432 474 479 537 586 653 759 823 908 1019 1096 1093 1000 834 784 725 666 580 552 491 514 505 495 511 570 617 673 670 686 674 649 628 526 499 467 427 472 421 433 469 449 420 441 421 405 379 403 387 420 408 407 386 357 394 382 391 387 374 356 386 404 370 329 356 375 385 413 409 451 451 421 400 436 394 391 407 360 370 359 391 374 370 334 344 357 334 335 383 393 367 350 403 365 371 418 410 390 390 375 383 437 424 420 407 457 449 529 483 486 623 631 622 661 702 645 556 546 543 483 499 491 564 570 547 654 722 788 903 1101 1286 1510 1775 2157 2453 2640 2510 2059 1769 1509 1230 1002 705 600 515 534 444 436 466 426 409 393 401 402 381 414 416 373 378 403 405 411 361 383 411 388 367 390 426 416 420 444 454 479 467 443 465 511 551 560 558 537 571 506 555 493 517 601 542 631 602 562 583 567 528 476 458 426 448 432 420 387 383 382 372 411 388 417 398 434 437 442 476 472 529 469 435 442 443 393 410 477 406 381 408 456 386 399 365 399 444 471 525 550 566 599 679 722 763 761 711 691 627 556 563 519 484 490 417 438 470 448 474 448 507 490 578 622 681 698 798 831 823 791 787 711 763 647 607 644 627 728 835 979 1152 1403 1633 1880 2208 2268 2104 1793 1550 1365 1231 876 734 606 549 497 454 434 406 446 414 426 382 410 346 398 405 366 401 404 374 364 379 438 432 401 452 417 480 432 456 457 472 490 474 484 477 490 444 395 403 470 392 412 418 422 407 398 411 402 377 433 368 392 370 405 374 396 401 410 388 400 434 458 464 436 479 560 558 543 610 556 658 651 662 718 736 666 592 562 563 483 458 467 423 407 406 393 376 408 379 363 393 377 434 408 419 409 446 450 502 507 494 585 690 782 891 1061 1216 1510 1743 1838 2045 1830 1692 1399 1326 1267 1055 806 773 620 581 575 575 611 490 530 544 591 625 674 687 803 877 1026 1128 1196 1241 1174 1065 1004 905 869 755 626 556 518 566 555 528 511 496 522 499 448 453 403 437 452 473 414 445 524 439 447 504 467 460 472 438 460 433 405 406 416 340 402 364 325 387 348 342 382 377 372 367 355 362 386 352 415 380 370 430 408 409 432 482 440 450 449 465 421 447 420 498 492 583 587 602 603 621 629 694 633 679 719 719 719 696 615 584 575 538 500 487 463 416 417 389 364 381 379 380 350 351 353 339 384 331 345 351 346 286 334 336 340 365 374 374 359 374 379 413 398 431 436 423 482 453 461 479 478 481 405 447 448 384 363 352 355 377 358 353 386 379 377 337 320 340 338 345 313 362 350 363 342 353 366 366 369 393 437 413 452 451 466 396 424 420 422 403 426 413 353 377 424 425 370 373 397 373 395 394 488 488 557 533 599 590 563 499 515 485 514 502 439 412 398 377 401 378 355 401 366 363 382 396 378 369 367 395 400 406 418 400 372 411 426 402 376 372 377 309 346 341 349 335 325 322 322 339 358 332 301 316 328 334 345 320 298 274 340 335 305 291 316 304 322 312 336 297 303 324 381 305 289 283 328 293 264 330 310 298 313 322 291 333 315 295 298 334 344 320 304 316 332 296 326 317 310 297 361 372 358 384 350 417 436 472 444 424 388 448 419 381 411 329 374 353 349 325 325 335 314 332 348 328 325 295 287 300 352 310 345 349 345 335 359 376 358 390 375 389 370 390 344 360 346 372 334 333 315 325 360 271 319 302 313 350 322 308 304 335 318 361 335 347 326 340 341 339 339 347 352 354 336 358 361 330 390 333 340 343 359 338 352 321 339 357 358 354 336 346 350 349 319 364 326 365 340 363 379 336 370 362 356 326 375 374 324 356 343 324 317 315 336 297 334 319 306 296 336 343 382 361 350 374 369 333 361 412 379 394 343 368 377 364 358 379 318 366 335 347 339 346 320 329 308 349 327 314 318 333 331 340 327 315 314 339 323 314 352 355 333 337 347 335 361 361 348 378 371 399 380 359 322 370 361 354 337 369 343 330 342 351 388 368 349 409 440 415 431 466 551 635 673 796 837 848 773 711 669 689 621 622 598 537 483 466 414 395 348 358 337 375 377 400 407 352 357 376 384 396 338 388 402 392 380 346 312 391 354 371 331 309 359 360 323 347 319 287 323 310 349 360 306 349 339 306 343 358 314 314 318 336 356 327 333 362 355 363 353 344 366 402 411 442 448 459 521 513 534 520 495 505 508 497 471 455 440 402 424 376 430 414 417 355 393 400 345 381 379 363 360 366 342 318 337 352 349 377 362 333 316 363 389 355 351 357 371 339 366 336 358 344 382 356 347 389 439 435 460 484 561 629 685 711 818 819 887 804 749 638 609 659 693 625 558 500 455 403 404 378 383 347 354 344 358 332 368 332 294 342 340 308 350 347 316 279 307 333 359 314 313 308 318 317 311 335 351 360 336 308 332 331 300 303 354 319 338 325 325 331 330 345 326 336 355 323 318 352 352 319 351 350 360 381 376 401 416 440 514 554 532 640 578 547 515 455 495 475 485 458 449 453 391 397 366 377 419 356 371 331 344 402 380 359 361 384 376 357 384 360 350</counts>
			</dataPoints>
		</scan>
	</xrdMeasurement>
</xrdMeasurements>