File: dataset/precursor_mixture/V2O5_La(OH)3_Y2O3_Li3PO4.2-min.xrdml
<?xml version="1.0"?>
<xrdMeasurements xmlns="http://www.xrdml.com/XRDMeasurement/2.2" xmlns:xsi="http://www.w3.org/2001/XMLSchema-instance" xsi:schemaLocation="http://www.xrdml.com/XRDMeasurement/2.2 http://www.xrdml.com/XRDMeasurement/2.2/XRDMeasurement.xsd" status="Completed" recordIdentifier="{6E6B6C96-D534-4D95-AB95-64D379ABE0B8}">
	<comment>
		<entry/>
	</comment>
	<sample type="To be analyzed">
		<id>dara-35-1</id>
		<name></name>
		<preparedBy></preparedBy>
	</sample>
	<xrdMeasurement measurementType="Scan" status="Completed" sampleMode="Reflection">
		<usedWavelength intended="K-Alpha 1">
			<kAlpha1 unit="Angstrom">1.5405980</kAlpha1>
			<kAlpha2 unit="Angstrom">1.5444260</kAlpha2>
			<kBeta unit="Angstrom">1.3922500</kBeta>
			<ratioKAlpha2KAlpha1>0.5000</ratioKAlpha2KAlpha1>
		</usedWavelength>
		<incidentBeamPath>
			<radius unit="mm">145.00</radius>
			<xRayTube id="1010048" name="Empyrean Cu LFF HR (9430 033 7310x) DK430614">
				<tension unit="kV">40.0</tension>
				<current unit="mA">15.0</current>
				<anodeMaterial>Cu</anodeMaterial>
				<focus type="Line">
					<length unit="mm">12.0</length>
					<width unit="mm">0.4</width>
					<takeOffAngle unit="deg">6.0</takeOffAngle>
				</focus>
			</xRayTube>
			<filter id="20010004" name="Beta-filter Nickel">
				<material>Ni</material>
				<thickness unit="mm">0.020</thickness>
			</filter>
			<sollerSlit id="21010002" name="Soller slits 0.04 rad.">
				<opening unit="rad">0.0400</opening>
			</sollerSlit>
			<mask id="22031000" name="Fixed mask 13 mm">
				<width unit="mm">9.00</width>
			</mask>
			<divergenceSlit id="22120001" name="Divergence slit 1°" xsi:type="fixedDivergenceSlitType">
				<distanceToSample unit="mm">50.00</distanceToSample>
				<height unit="mm">1.52</height>
			</divergenceSlit>
		</incidentBeamPath>
		<beamKnife id="29030100" name="Beam knife low"/>
		<sampleMovement xsi:type="spinningSampleMovementType">
			<spinnerRevolutionTime unit="seconds">1.0</spinnerRevolutionTime>
		</sampleMovement>
		<diffractedBeamPath>
			<radius unit="mm">145.00</radius>
			<antiScatterSlit id="22090040" name="AS slit 9 mm" xsi:type="fixedAntiScatterSlitType">
				<height unit="mm">9.00</height>
			</antiScatterSlit>
			<sollerSlit id="21020003" name="Large Soller slits 0.04 rad.">
				<opening unit="rad">0.0400</opening>
			</sollerSlit>
			<filter id="20030001" name="Large beta-filter Nickel">
				<material>Ni</material>
				<thickness unit="mm">0.020</thickness>
			</filter>
			<detector id="7010019" name="PIXcel1D-Medipix3 detector" xsi:type="rtmsDetectorType">
				<phd unit="keV">
					<lowerLevel>4.0</lowerLevel>
					<upperLevel>11.3</upperLevel>
				</phd>
				<mode>Scanning</mode>
				<activeLength unit="deg">1.021</activeLength>
			</detector>
		</diffractedBeamPath>
		<scan appendNumber="0" mode="Continuous" scanAxis="Gonio" status="Completed">
			<header>
				<startTimeStamp>2024-02-18T13:39:24-08:00</startTimeStamp>
				<endTimeStamp>2024-02-18T13:41:46-08:00</endTimeStamp>
				<author>
					<name>AutomatedUser</name>
				</author>
				<source>
					<applicationSoftware version="1.4b (28)">PANalytical Aeris Instrument Suite</applicationSoftware>
					<instrumentControlSoftware version="2.0.0 20210224">AERIS</instrumentControlSoftware>
					<instrumentID>950485</instrumentID>
				</source>
			</header>
			<dataPoints>
				<positions axis="2Theta" unit="deg">
					<startPosition>10.02173288</startPosition>
					<endPosition>139.98435528</endPosition>
				</positions>
				<positions axis="Omega" unit="deg">
					<startPosition>5.01086644</startPosition>
					<endPosition>69.99217764</endPosition>
				</positions>
				<commonCountingTime unit="seconds">1.551</commonCountingTime>
				<counts unit="counts">405 367 403 370 371 395 379 364 371 360 403 346 382 350 377 334 396 376 337 349 277 335 321 350 325 332 335 316 357 341 334 325 346 321 325 307 302 299 291 290 285 303 307 307 311 297 324 308 310 331 292 251 283 265 288 293 280 311 266 274 304 271 288 282 296 270 301 255 294 251 267 245 303 298 279 264 273 256 289 270 279 270 249 266 266 263 266 266 272 287 258 282 246 267 240 270 258 253 270 282 221 240 243 233 274 269 241 256 255 268 240 282 297 275 272 306 306 349 364 426 461 566 548 611 756 912 1082 1049 879 602 434 383 334 312 263 259 280 282 206 247 265 272 260 245 230 245 239 250 240 218 225 246 270 246 227 259 251 246 234 210 192 224 210 188 220 190 189 208 201 219 221 230 202 208 184 200 180 242 200 184 190 211 200 220 196 247 191 200 212 206 187 206 216 189 224 226 207 201 205 200 179 202 210 200 218 157 205 206 174 172 183 172 183 184 183 198 203 185 206 192 181 213 194 211 217 219 247 258 285 395 541 677 668 474 441 415 453 339 247 221 212 193 190 191 202 184 191 188 187 198 197 174 173 175 194 192 157 154 207 188 186 237 220 300 323 254 206 193 197 189 170 200 214 238 207 251 289 299 283 284 193 197 212 163 164 213 161 155 179 181 192 192 189 195 192 221 247 267 228 223 242 240 229 191 140 171 170 189 184 142 174 202 157 163 175 135 166 176 177 166 148 162 149 142 159 176 185 154 155 167 187 193 209 199 199 206 201 222 198 186 204 162 134 138 146 150 161 150 180 149 142 152 172 160 184 149 175 171 191 128 190 209 262 366 303 209 185 187 150 153 140 178 144 139 137 157 152 183 172 188 197 238 245 315 305 397 531 654 719 730 664 490 375 350 310 270 249 276 299 368 388 494 692 912 975 914 735 564 431 335 282 244 225 208 204 178 207 201 210 213 211 186 234 267 245 278 398 527 804 1289 1862 2044 1587 985 497 372 292 228 195 212 177 177 158 155 134 168 150 133 158 165 144 163 158 136 148 134 135 136 142 158 130 146 148 127 147 161 136 146 149 156 199 237 313 324 291 249 203 166 166 176 173 141 231 232 246 267 278 253 240 203 175 172 161 136 166 144 156 138 141 154 160 140 168 207 179 169 174 166 121 159 138 140 123 116 126 148 109 123 112 143 146 106 135 154 177 158 157 148 149 149 159 194 214 361 520 628 540 460 326 278 219 201 165 209 200 212 226 225 215 153 146 133 135 130 121 117 119 124 111 115 106 125 123 131 113 140 106 134 119 125 124 119 105 124 117 77 116 122 161 130 159 190 232 263 247 213 185 162 158 168 143 129 138 120 141 145 137 145 163 161 149 145 138 143 126 135 121 143 148 124 132 135 134 123 111 110 122 112 107 106 124 109 111 123 97 109 106 144 113 128 127 113 110 95 141 116 109 128 131 130 122 130 88 123 124 117 125 125 136 136 133 141 145 148 165 184 177 237 234 319 411 502 554 613 594 511 442 331 307 282 250 279 231 215 246 137 140 139 114 132 131 121 117 94 105 132 102 112 110 104 97 112 92 108 126 114 110 102 123 106 103 134 166 192 178 133 129 124 102 102 100 112 121 105 109 124 123 127 123 152 182 155 195 187 171 207 194 193 158 155 118 135 99 114 112 102 114 94 103 109 93 84 111 85 123 97 118 123 133 135 125 141 197 250 208 185 167 168 104 113 109 106 119 110 119 101 110 126 94 115 122 100 113 85 81 112 94 114 98 95 76 96 107 94 90 106 92 82 81 102 99 83 98 93 108 105 94 116 120 120 119 113 116 71 86 110 106 110 107 87 89 87 100 108 91 105 100 101 93 97 95 105 122 105 103 94 103 117 113 129 172 184 164 195 189 212 173 213 136 176 185 134 161 164 150 125 110 123 145 134 154 165 191 187 200 229 220 230 288 296 325 339 355 357 465 657 923 1133 945 954 836 676 511 430 342 280 247 200 197 211 161 135 150 133 130 132 128 141 117 141 130 127 117 131 129 134 128 136 159 179 142 168 171 149 131 148 119 122 129 118 117 97 102 120 104 106 110 98 110 103 92 88 109 85 117 96 135 150 144 139 118 136 95 105 124 104 123 138 77 90 117 95 87 96 102 116 97 94 98 94 93 83 103 117 96 94 112 89 68 72 115 99 87 96 80 119 81 115 89 98 106 155 183 154 159 132 136 102 109 101 75 108 75 77 87 108 84 98 86 71 101 83 74 81 100 78 90 70 89 90 94 68 99 100 107 127 120 97 124 115 92 119 122 124 138 144 164 170 190 170 209 172 178 156 168 135 141 156 137 107 118 101 126 115 117 107 122 168 169 212 178 194 179 151 167 142 118 106 99 126 116 101 92 89 76 94 92 79 105 86 96 85 115 117 110 112 107 160 181 274 372 518 487 320 332 351 248 183 199 176 138 120 112 101 107 80 99 96 137 87 73 116 101 116 105 124 109 121 122 145 145 149 177 226 202 142 162 147 89 98 92 101 109 92 89 84 93 93 81 74 99 91 65 80 64 107 77 96 89 79 82 94 110 131 169 161 147 129 123 131 93 101 77 99 90 92 101 101 142 149 154 98 116 124 112 103 72 87 78 83 76 83 85 86 90 105 95 99 115 96 110 114 101 102 73 114 89 96 81 66 83 76 85 96 71 101 79 64 83 85 100 64 95 89 99 97 86 115 92 98 83 93 94 82 71 102 83 97 97 102 109 132 139 151 149 179 148 163 154 140 159 150 137 121 105 151 153 151 142 171 117 126 111 120 102 99 114 101 114 102 104 117 95 84 83 80 65 68 76 103 92 85 111 88 91 108 96 108 114 102 121 108 123 114 118 108 85 69 82 72 66 75 85 74 86 87 84 69 99 83 110 84 67 91 93 66 84 78 65 97 72 82 69 84 93 73 90 83 83 82 97 103 90 76 60 79 80 79 68 63 87 78 67 87 84 68 79 85 80 91 100 100 79 72 110 69 77 81 84 80 59 74 61 92 104 94 98 103 122 138 120 159 166 174 157 165 149 146 144 149 106 108 84 97 88 101 87 79 101 94 73 73 99 87 98 97 97 107 128 98 106 141 130 145 165 133 112 129 127 129 89 107 106 69 85 70 99 74 84 92 97 78 105 87 78 98 103 96 74 107 85 125 133 148 103 111 129 110 113 96 96 105 100 97 104 106 120 85 107 109 83 85 75 92 84 77 102 73 77 104 88 114 96 74 113 118 102 95 89 82 82 93 82 76 80 87 91 87 95 99 72 76 89 85 104 104 88 105 107 95 99 71 97 85 97 87 78 85 77 83 91 83 75 99 92 77 91 122 108 106 88 106 115 102 99 121 94 124 114 111 135 94 121 133 132 114 119 99 117 95 102 112 109 124 136 107 112 128 115 118 133 119 162 156 198 194 184 147 161 226 174 189 133 135 153 125 119 108 100 104 95 100 112 105 91 114 97 100 111 133 124 144 178 206 179 138 135 129 132 151 118 89 88 122 81 90 86 95 77 76 80 74 77 65 70 72 83 91 88 72 69 51 75 79 72 77 89 102 82 82 76 85 99 92 70 84 82 95 64 69 98 95 91 68 92 98 120 125 125 147 124 106 99 108 109 100 97 83 65 79 76 67 70 60 82 86 83 98 79 71 80 98 85 85 100 122 90 122 84 98 84 108 69 89 92 81 100 82 79 78 78 88 91 95 77 76 75 78 68 73 71 64 97 81 95 78 70 71 60 86 82 78 77 75 77 70 80 71 77 82 77 69 73 79 94 68 70 86 95 85 114 106 112 81 76 75 102 90 74 83 90 90 68 85 71 70 72 79 73 67 65 58 82 99 68 85 86 79 65 78 68 96 79 76 77 76 72 50 76 64 62 64 66 78 72 89 81 71 76 79 78 102 87 98 105 103 97 102 94 89 87 84 74 65 81 92 70 78 73 78 65 71 69 69 51 67 73 92 64 86 88 62 61 72 92 92 100 111 80 96 100 97 79 107 109 98 97 119 95 78 68 96 89 88 93 73 75 86 79 118 89 83 106 84 84 111 78 81 96 90 76 82 91 104 80 109 100 83 92 92 110 95 73 92 113 104 134 178 125 93 91 114 117 103 114 110 78 74 67 105 94 99 77 72 78 82 92 67 90 78 91 62 101 130 121 93 106 93 89 85 105 97 82 91 75 78 62 84 64 55 77 76 64 64 54 76 82 77 71 105 106 113 102 85 79 92 66 85 103 91 71 77 105 95 84 73 69 78 82 71 65 79 68 68 72 86 78 86 105 75 83 64 91 75 86 102 80 73 68 76 69 82 72 73 79 84 79 84 95 93 77 94 95 121 103 145 155 140 138 109 115 108 123 93 94 98 99 74 77 68 84 72 65 96 70 99 101 76 103 120 90 95 86 85 106 105 106 104 78 96 79 82 88 76 91 64 78 93 70 72 63 75 97 73 80 86 83 71 92 101 115 124 111 107 101 97 102 86 101 87 85 70 69 79 87 66 76 90 98 81 71 92 81 79 75 91 85 79 117 112 69 77 94 74 88 81 82 82 77 70 66 97 85 76 77 69 72 85 80 73 65 60 64 89 70 80 91 74 55 74 53 75 70 64 82 62 80 80 80 84 69 72 73 81 94 85 83 86 101 111 83 95 96 112 124 98 108 86 108 80 103 99 102 98 89 68 62 68 74 71 68 62 68 77 74 67 67 65 96 79 106 111 133 113 118 109 109 78 90 105 115 113 85 91 75 102 84 80 109 85 100 75 86 73 96 94 78 86 105 90 99 91 94 97 77 78 73 90 80 93 94 81 69 98 91 64 69 76 60 66 73 49 67 70 95 78 78 98 107 76 85 65 86 78 91 109 86 67 73 77 85 85 86 74 59 74 71 75 77 70 58 81 86 73 54 86 79 76 74 86 69 84 80 71 92 85 92 79 82 84 71 52 68 69 86 75 62 76 68 78 87 78 90 74 91 71 81 77 79 88 84 71 70 80 64 86 88 86 104 59 98 109 92 81 86 67 63 86 84 82 81 105 107 103 108 98 74 71 93 77 98 81 86 105 81 58 83 76 66 93 78 63 98 88 78 71 76 78 86 77 94 83 97 90 94 67 77 100 78 77 103 71 67 80 71 88 79 62 68 63 78 69 64 62 70 65 58 83 96 86 70 89 83 72 72 66 77 81 81 77 93 84 77 66 78 68 53 92 89 83 87 74 80 74 67 79 76 94 82 95 80 92 97 80 72 74 73 82 87 63 71 82 66 67 62 82 73 67 74 75 71 58 83 80 74 76 80 71 91 85 102 99 113 112 94 96 100 83 82 90 99 103 77 97 108 98 90 116 91 99 67 88 107 84 94 83 83 112 97 77 86 104 79 85 85 90 98 91 79 86 97 87 102 101 82 93 96 85 66 84 109 83 88 93 90 89 82 84 90 109 87 109 93 102 76 88 94 89 95 75 93 73 94 101 86 71 67 78 84 67 104 62 61 73 79 80 72 85 72 104 81 107 92 101 90 75 90 79 82 79 94 76 81 90 101 80 80 73 53 81 78 79 80 80 74 68 67 83 62 77 77 79 69 83 75 83 75 77 85 72 65 84 85 79 73 77 41 83 70 62 62 77 81 81 51 64 63 75 80 84 76 96 91 92 92 69 96 89 78 77 74 83 77 73 71 98 68 74 90 78 85 89 77 76 72 60 82 70 83 87 81 83 101 84 90 98 94 108 119 88 94 92 77 66 80 85 96 114 84 94 92 74 90 70 67 76 69 110 95 64 71 81 84 64 81 95 81 103 79 83 97 71 73 69 66 87 78 77 70 92 75 97 88 85 86 64 65 73 86 55 84 73 88 73 60 76 72 96 87 84 88 107 82 75 91 80 79 69 67 61 88 74 76 76 65 80 72 84 93 88 70 80 80 106 80 67 86 61 70 56 83 92 75 76 91 75 98 96 93 95 100 89 101 84 72 93 84 110 124 83 96 75 93 97 91 87 87 79 84 76 82 80 66 73 84 85 78 95 93 100 88 109 79 84 85 99 77 82 91 81 81 90 81 61 63 90 90 69 94 77 94 89 86 89 81 83 63 91 70 93 96 80 97 75 67 95 99 69 88 100 85 87 86 110 87 86 62 73 117 77 81 92 96 81 81 91 76 86 82 67 72 82 108 76 95 75 93 87 75 80 111 96 85 117 102 92 100 105 100 83 92 86 102 92 81 101 101 100 92 94 81 91 83 82 91 92 89 101 103 82 86 104 98 81 86 95 96 81 99 90 109 119 92 85 94 86 83 72 82 112 113 73 86 95 100 79 86 90 76 89 84 96 75 73 77 89 82 68 78 105 86 102 86 79 90 78 116 109 85 83 71 82 76 100 78 67 82 91 82 83 92 89 93 92 96 92 92 88 76 85 105 93 100 84 73 82 91 127 76 72 94 73 95 105 106 116 108 108 118 113 116 120 101 133 112 106 101 93 89 109 86 93 85 109 91 87 101 84 83 72 103 88 101 120 72 85 101 91 86 105 97 108 115 97 101 102 103 109 112 123 118 129 112 86 104 78 90 100 107 105 117 100 111 101 144 121 111 94 119 95 107 110 91 91 107 100 107 119 115 96 119 114 91 103 97 108 100 138 115 104 102 126 110 136 86 95 91 108 114 113 118 122 119 95 109 109 111 127 102 141 115 112 100 112 125 107 99 108 103 105 117 91 86 109 126 101 119 93 118 104 96 98 136 119 120 104 117 112 91 104 104</counts>
			</dataPoints>
		</scan>
	</xrdMeasurement>
</xrdMeasurements>