File: dataset/precursor_mixture/V2O5_0p4005-NiO_0p6016--2min.xrdml
<?xml version="1.0"?>
<xrdMeasurements xmlns="http://www.xrdml.com/XRDMeasurement/2.3" xmlns:xsi="http://www.w3.org/2001/XMLSchema-instance" xsi:schemaLocation="http://www.xrdml.com/XRDMeasurement/2.3 http://www.xrdml.com/XRDMeasurement/2.3/XRDMeasurement.xsd" status="Completed" recordIdentifier="{37AEF64D-0F58-41BF-9149-5260BF56CC25}">
	<comment>
		<entry/>
	</comment>
	<sample type="To be analyzed">
		<id>V2O5_0p4005-NiO_0p6016--2min</id>
		<name></name>
		<preparedBy></preparedBy>
	</sample>
	<xrdMeasurement measurementType="Scan" status="Completed" sampleMode="Reflection">
		<usedWavelength intended="K-Alpha 1">
			<kAlpha1 unit="Angstrom">1.5405980</kAlpha1>
			<kAlpha2 unit="Angstrom">1.5444260</kAlpha2>
			<kBeta unit="Angstrom">1.3922500</kBeta>
			<ratioKAlpha2KAlpha1>0.5000</ratioKAlpha2KAlpha1>
		</usedWavelength>
		<incidentBeamPath>
			<radius unit="mm">145.00</radius>
			<xRayTube id="1010048" name="Empyrean Cu LFF HR (9430 033 7310x)">
				<tension unit="kV">40.0</tension>
				<current unit="mA">15.0</current>
				<anodeMaterial>Cu</anodeMaterial>
				<focus type="Line">
					<length unit="mm">12.0</length>
					<width unit="mm">0.4</width>
					<takeOffAngle unit="deg">6.0</takeOffAngle>
				</focus>
			</xRayTube>
			<sollerSlit id="21010002" name="Soller slits 0.04 rad.">
				<opening unit="rad">0.0400</opening>
			</sollerSlit>
			<mask id="22031000" name="Fixed mask 13 mm">
				<width unit="mm">9.00</width>
			</mask>
			<divergenceSlit id="22120001" name="Divergence slit 1°" xsi:type="fixedDivergenceSlitType">
				<distanceToSample unit="mm">50.00</distanceToSample>
				<height unit="mm">1.52</height>
			</divergenceSlit>
		</incidentBeamPath>
		<sampleMovement xsi:type="spinningSampleMovementType">
			<spinnerRevolutionTime unit="seconds">1.0</spinnerRevolutionTime>
		</sampleMovement>
		<diffractedBeamPath>
			<radius unit="mm">145.00</radius>
			<antiScatterSlit id="22090040" name="AS slit 9 mm (PIXcel)" xsi:type="fixedAntiScatterSlitType">
				<height unit="mm">9.00</height>
			</antiScatterSlit>
			<sollerSlit id="21020003" name="Large Soller slits 0.04 rad.">
				<opening unit="rad">0.0400</opening>
			</sollerSlit>
			<filter id="20030001" name="Large beta-filter Nickel">
				<material>Ni</material>
				<thickness unit="mm">0.020</thickness>
			</filter>
			<detector id="7010019" name="PIXcel1D-Medipix3 detector" xsi:type="rtmsDetectorType">
				<phd unit="keV">
					<lowerLevel>4.02</lowerLevel>
					<upperLevel>11.27</upperLevel>
				</phd>
				<mode>Scanning</mode>
				<activeLength unit="deg">5.542</activeLength>
			</detector>
		</diffractedBeamPath>
		<scan appendNumber="0" mode="Continuous" scanAxis="Gonio" status="Completed">
			<header>
				<startTimeStamp>2024-11-14T15:45:09-08:00</startTimeStamp>
				<endTimeStamp>2024-11-14T15:47:14-08:00</endTimeStamp>
				<author>
					<name>AutomatedUser</name>
				</author>
				<source>
					<applicationSoftware version="1.7b (136)">PANalytical Aeris Instrument Suite</applicationSoftware>
					<instrumentControlSoftware version="3.2.00000000 20240306">AERIS</instrumentControlSoftware>
					<instrumentID>950485</instrumentID>
				</source>
			</header>
			<dataPoints>
				<positions axis="2Theta" unit="deg">
					<startPosition>10.02173288</startPosition>
					<endPosition>99.99585608</endPosition>
				</positions>
				<positions axis="Omega" unit="deg">
					<startPosition>5.01086644</startPosition>
					<endPosition>49.99792804</endPosition>
				</positions>
				<commonCountingTime unit="seconds">10.965</commonCountingTime>
				<counts unit="counts">2476 2558 2567 2551 2445 2452 2429 2383 2506 2431 2362 2443 2323 2386 2389 2337 2433 2405 2363 2384 2304 2423 2297 2308 2297 2302 2297 2279 2255 2330 2362 2264 2219 2260 2279 2268 2172 2274 2349 2324 2229 2212 2194 2292 2175 2346 2264 2155 2267 2227 2193 2204 2177 2221 2236 2088 2232 2184 2171 2143 2099 2182 2066 2133 2108 2032 2190 2127 2091 2190 2200 2107 2073 2221 2213 2101 2178 2083 2118 2075 2120 2100 2131 2128 2204 2165 2151 2097 2084 2186 2200 2203 2035 2109 2137 2143 2143 2108 2124 2164 2097 2137 2173 2102 2086 2160 2090 2089 2150 2154 2216 2267 2090 2195 2225 2155 2144 2213 2241 2291 2404 2422 2628 2730 2804 2751 2659 2690 2426 2236 2191 2231 2190 2149 2168 2136 2203 2173 2185 2241 2257 2169 2284 2137 2139 2137 2168 2253 2164 2218 2258 2218 2189 2209 2311 2210 2131 2184 2124 2202 2228 2231 2220 2223 2315 2173 2179 2276 2250 2142 2322 2223 2249 2339 2200 2244 2312 2248 2233 2204 2203 2192 2157 2176 2254 2260 2215 2197 2142 2257 2317 2285 2272 2242 2335 2233 2199 2194 2215 2326 2249 2182 2232 2322 2225 2283 2203 2240 2167 2320 2304 2261 2214 2338 2227 2223 2296 2252 2301 2328 2283 2302 2296 2406 2427 2331 2384 2414 2450 2541 2685 2898 3120 3460 4019 4451 4997 5358 5473 5233 4563 3768 3062 2630 2617 2490 2607 2443 2368 2423 2409 2375 2356 2286 2356 2273 2357 2298 2307 2447 2258 2302 2490 2456 2482 2642 2748 2814 2887 3145 3186 3340 3290 3064 2766 2503 2450 2427 2409 2390 2408 2335 2429 2287 2366 2356 2521 2227 2247 2418 2329 2239 2284 2328 2389 2392 2303 2369 2363 2241 2279 2361 2360 2301 2312 2283 2346 2412 2300 2256 2340 2445 2343 2244 2405 2296 2322 2350 2363 2385 2359 2300 2331 2285 2356 2316 2300 2370 2272 2318 2411 2342 2372 2302 2437 2308 2357 2398 2395 2297 2415 2343 2312 2429 2281 2289 2327 2356 2304 2361 2347 2333 2478 2366 2321 2452 2428 2458 2500 2490 2491 2509 2336 2498 2504 2474 2586 2704 2870 3194 3590 3857 4066 4176 4039 3699 3130 2761 2451 2564 2548 2360 2475 2430 2381 2260 2398 2389 2286 2343 2323 2373 2324 2248 2312 2405 2330 2422 2356 2350 2445 2359 2333 2268 2263 2360 2321 2334 2363 2341 2303 2431 2356 2409 2279 2380 2306 2339 2356 2355 2226 2347 2402 2382 2374 2344 2441 2409 2298 2354 2371 2294 2317 2400 2315 2278 2279 2353 2389 2290 2349 2412 2310 2358 2283 2201 2361 2351 2463 2415 2448 2409 2348 2395 2394 2376 2446 2341 2466 2383 2303 2405 2458 2283 2455 2419 2302 2346 2445 2397 2410 2395 2447 2376 2381 2372 2516 2549 2622 2729 2838 3117 3609 3844 4151 4221 4101 3725 3383 2956 2709 2482 2491 2416 2473 2434 2433 2422 2317 2392 2484 2419 2352 2400 2344 2454 2339 2436 2434 2387 2444 2487 2542 2751 2882 3047 3173 3205 3065 2824 2683 2530 2405 2404 2392 2479 2357 2269 2457 2442 2429 2324 2453 2523 2406 2471 2515 2622 2573 2642 2540 2585 2552 2356 2386 2371 2399 2357 2298 2480 2391 2351 2394 2493 2416 2446 2584 2693 2795 2982 3187 3001 3112 2935 2606 2550 2339 2399 2409 2449 2396 2334 2349 2293 2354 2326 2314 2346 2433 2363 2341 2437 2358 2417 2408 2366 2318 2378 2333 2428 2383 2413 2322 2308 2457 2315 2377 2341 2537 2380 2471 2482 2443 2462 2486 2418 2463 2442 2368 2461 2441 2369 2449 2537 2590 2575 2645 2701 2753 2814 3107 3290 3898 4767 5741 7174 8823 10596 11663 11825 10864 8945 7171 5523 4397 3681 3308 3027 2837 2741 2613 2609 2607 2579 2537 2430 2495 2540 2466 2430 2452 2548 2467 2413 2415 2363 2413 2376 2427 2443 2374 2436 2399 2386 2416 2421 2407 2443 2439 2418 2395 2362 2395 2353 2446 2387 2415 2351 2483 2383 2383 2488 2383 2350 2328 2389 2336 2452 2378 2419 2334 2389 2365 2434 2362 2373 2473 2412 2452 2388 2363 2455 2499 2373 2339 2444 2493 2427 2468 2540 2482 2422 2416 2402 2423 2527 2650 2688 2828 2915 2875 3045 2927 2802 2677 2666 2568 2494 2449 2481 2467 2492 2538 2558 2655 2605 2658 2668 2675 2786 2656 2737 2717 2534 2594 2517 2573 2580 2551 2552 2534 2618 2499 2687 2729 2849 2856 2990 3093 3371 3850 4401 5550 7457 10183 13232 16871 19396 20103 17366 13593 10716 7623 5335 4339 3812 3479 3163 3011 2874 2754 2666 2647 2587 2474 2570 2602 2544 2533 2509 2556 2463 2512 2494 2515 2485 2532 2495 2422 2343 2514 2542 2437 2453 2451 2530 2469 2428 2485 2443 2469 2472 2489 2586 2703 2685 2759 2823 2735 2849 2693 2672 2554 2608 2489 2486 2504 2477 2430 2440 2501 2465 2513 2513 2451 2455 2381 2545 2427 2428 2410 2443 2497 2406 2355 2525 2502 2506 2497 2471 2575 2392 2528 2526 2551 2534 2600 2707 2818 2900 2991 3100 3004 2940 2775 2762 2576 2657 2628 2630 2773 2850 2910 2900 2794 2779 2649 2621 2491 2550 2571 2433 2361 2458 2506 2413 2538 2512 2384 2607 2586 2620 2504 2763 2715 2767 2884 2747 2788 2572 2582 2450 2523 2527 2472 2498 2474 2514 2474 2539 2549 2512 2681 2514 2519 2442 2563 2447 2431 2489 2456 2417 2464 2428 2444 2365 2438 2344 2418 2408 2504 2422 2521 2461 2434 2413 2427 2473 2412 2337 2449 2410 2445 2459 2496 2574 2629 2747 2922 2898 3042 3020 2923 2739 2836 2725 2560 2497 2485 2515 2600 2526 2579 2435 2486 2671 2720 2739 2739 2744 2666 2578 2618 2449 2458 2440 2457 2469 2484 2431 2545 2475 2480 2425 2506 2450 2448 2437 2466 2458 2408 2445 2556 2370 2486 2372 2426 2493 2414 2399 2397 2390 2400 2393 2434 2478 2480 2454 2523 2544 2436 2505 2500 2341 2408 2508 2358 2535 2346 2455 2405 2455 2478 2411 2526 2454 2563 2414 2544 2401 2530 2503 2531 2413 2385 2378 2384 2455 2375 2455 2477 2408 2422 2501 2404 2473 2512 2562 2556 2610 2616 2686 2768 2659 2629 2745 2546 2577 2516 2460 2520 2405 2521 2463 2487 2608 2624 2565 2614 2522 2528 2450 2640 2490 2489 2524 2501 2411 2443 2465 2450 2523 2447 2442 2487 2449 2537 2457 2428 2501 2555 2492 2438 2471 2476 2468 2492 2478 2461 2499 2493 2420 2438 2393 2451 2469 2507 2513 2416 2483 2479 2531 2486 2489 2491 2535 2572 2514 2677 2560 2576 2592 2534 2577 2511 2595 2667 2655 2647 2668 2648 2747 2711 2641 2601 2592 2571 2487 2471 2510 2455 2591 2499 2427 2470 2480 2416 2476 2658 2549 2577 2592 2614 2539 2574 2554 2569 2468 2480 2487 2535 2529 2481 2427 2576 2520 2574 2512 2463 2551 2475 2630 2580 2527 2690 2811 2729 2779 2915 2785 2726 2636 2617 2598 2503 2615 2497 2549 2546 2555 2515 2596 2646 2632 2563 2666 2671 2774 2838 2920 3025 3074 2906 2998 2927 2894 2958 3101 3113 3268 3526 3673 4259 4804 5657 6643 7696 8514 9148 8865 8343 7899 6958 6080 5354 4544 3949 3739 3348 3111 2961 2932 2875 2835 2755 2652 2679 2594 2625 2634 2611 2582 2556 2480 2569 2617 2588 2536 2571 2532 2679 2674 2701 2576 2643 2783 2618 2637 2710 2626 2580 2480 2613 2574 2500 2481 2536 2568 2511 2572 2576 2612 2493 2473 2577 2546 2558 2456 2518 2502 2488 2605 2427 2567 2469 2545 2500 2539 2555 2650 2679 2662 2706 2632 2651 2727 2561 2635 2562 2588 2516 2492 2483 2515 2463 2513 2509 2473 2486 2462 2461 2551 2497 2559 2567 2616 2495 2462 2581 2581 2495 2502 2588 2498 2497 2527 2427 2586 2727 2578 2681 2613 2657 2535 2580 2544 2660 2516 2584 2509 2606 2581 2591 2591 2521 2540 2562 2528 2576 2582 2623 2700 2600 2668 2651 2647 2772 2677 2662 2704 2556 2567 2559 2590 2542 2532 2535 2523 2453 2604 2563 2635 2595 2618 2694 2704 2664 2511 2675 2576 2716 2628 2574 2532 2552 2623 2713 2697 2655 2661 2654 2658 2708 2674 2600 2572 2597 2581 2552 2670 2558 2501 2548 2462 2489 2581 2539 2535 2579 2554 2487 2498 2598 2530 2518 2559 2583 2543 2582 2657 2671 2627 2663 2639 2635 2535 2565 2617 2603 2535 2631 2548 2607 2813 2697 2800 2808 2727 2692 2687 2807 2729 2757 2818 2690 2742 2676 2749 2643 2589 2606 2604 2653 2612 2557 2570 2583 2425 2637 2575 2612 2539 2491 2409 2527 2619 2483 2632 2584 2599 2565 2447 2505 2480 2538 2515 2644 2608 2532 2567 2613 2641 2795 2649 2739 2801 2818 2674 2786 2745 2722 2684 2767 2732 2729 2725 2928 2826 2938 3032 3020 3282 3595 3927 4430 4652 4874 4739 4579 4457 4316 4110 3966 3569 3387 3295 3156 3023 2959 2864 2856 2726 2696 2716 2714 2661 2695 2691 2718 2625 2701 2565 2538 2565 2569 2555 2570 2704 2530 2541 2536 2462 2643 2597 2552 2497 2600 2571 2608 2637 2649 2598 2646 2503 2581 2671 2570 2575 2585 2598 2591 2523 2560 2614 2595 2599 2617 2596 2619 2699 2696 2690 2719 2614 2645 2601 2622 2690 2578 2664 2629 2762 2700 2664 2641 2657 2744 2755 2726 2705 2834 2983 3108 3305 3574 3656 3742 3975 3985 3767 3945 3843 3806 3646 3433 3271 3181 3013 2943 2984 2757 2725 2729 2664 2725 2789 2686 2565 2571 2672 2634 2485 2554 2600 2631 2510 2487 2627 2614 2590 2566 2558 2658 2481 2579 2538 2621 2626 2531 2601 2596 2562 2561 2593 2531 2578 2623 2533 2605 2479 2602 2583 2491 2511 2600 2553 2526 2630 2514 2489 2503 2556 2507 2506 2458 2650 2576 2517 2478 2527 2593 2539 2528 2707 2660 2631 2570 2657 2561 2616 2529 2633 2524 2653 2611 2570 2535 2568 2580 2570 2549 2542 2603 2524 2556 2563 2541 2494 2538 2630 2539 2620 2672 2513 2616 2492 2575 2594 2500 2561 2568 2558 2640 2623 2673 2655 2596 2552 2582 2640 2567 2514 2619 2583 2516 2519 2522 2550 2635 2621 2559 2654 2569 2645 2591 2532 2652 2632 2569 2664 2553 2521 2494 2604 2532 2551 2612 2572 2539 2579 2609 2561 2553 2638 2573 2530 2675 2581 2471 2560 2599 2553 2647 2555 2568 2712 2553 2590 2568 2649 2617 2664 2685 2614 2588 2616 2648 2539 2631 2608 2521 2552 2551 2647 2618 2545 2544 2640 2483 2593 2624 2645 2627 2603 2515 2471 2491 2631 2667 2647 2600 2486 2448 2651 2604 2645 2584 2700 2594 2613 2527 2589 2572 2635 2521 2608 2584 2599 2595 2627 2537 2519 2605 2579 2484 2693 2593 2645 2521 2542 2477 2575 2554 2563 2589 2639 2657 2463 2689 2639 2554 2577 2573 2732 2628 2628 2586 2610 2492 2579 2554 2644 2522 2669 2525 2577 2647 2642 2700 2673 2698 2643 2572 2567 2583 2608 2626 2649 2618 2486 2487 2697 2593 2586 2478 2536 2574 2528 2572 2655 2445 2537 2598 2621 2590 2548 2564 2655 2616 2564 2531 2451 2591 2552 2579 2482 2567 2583 2583 2537 2499 2579 2636 2588 2582 2609 2700 2665 2688 2635 2567 2495 2701 2646 2597 2609 2514 2679 2611 2670 2593 2694 2766 2595 2591 2747 2639 2617 2627 2648 2644 2527 2712 2576 2613 2675 2569 2695 2744 2660 2589 2626 2679 2631 2637 2567 2569 2646 2650 2675 2726 2645 2787 2863 2963 3021 3297 3371 3309 3291 3158 3047 3024 3069 3069 2939 2985 2981 2799 2826 2837 2636 2796 2669 2711 2649 2662 2578 2678 2543 2655 2658 2585 2633 2591 2574 2548 2513 2565 2594 2623 2661 2715 2678 2634 2535 2726 2560 2541 2575 2602 2594 2522 2625 2512 2589 2647 2561 2561 2514 2584 2577 2627 2603 2624 2607 2703 2568 2611 2578 2654 2730 2622 2664 2696 2632 2674 2657 2704 2674 2635 2480 2573 2546 2586 2576 2525 2692 2539 2674 2575 2632 2600 2528 2512 2610 2624 2551 2669 2638 2609 2579 2683 2649 2621 2569 2713 2701 2579 2708 2661 2672 2614 2685 2597 2687 2586 2710 2584 2632 2648</counts>
			</dataPoints>
		</scan>
	</xrdMeasurement>
</xrdMeasurements>