File: dataset/precursor_mixture/V2O5_0p8011-ZrO2_0p2012--2min.xrdml
<?xml version="1.0"?>
<xrdMeasurements xmlns="http://www.xrdml.com/XRDMeasurement/2.3" xmlns:xsi="http://www.w3.org/2001/XMLSchema-instance" xsi:schemaLocation="http://www.xrdml.com/XRDMeasurement/2.3 http://www.xrdml.com/XRDMeasurement/2.3/XRDMeasurement.xsd" status="Completed" recordIdentifier="{9F48EC13-6B08-4530-B209-53FB0C30776D}">
	<comment>
		<entry/>
	</comment>
	<sample type="To be analyzed">
		<id>V2O5_0p8011-ZrO2_0p2012--2min</id>
		<name></name>
		<preparedBy></preparedBy>
	</sample>
	<xrdMeasurement measurementType="Scan" status="Completed" sampleMode="Reflection">
		<usedWavelength intended="K-Alpha 1">
			<kAlpha1 unit="Angstrom">1.5405980</kAlpha1>
			<kAlpha2 unit="Angstrom">1.5444260</kAlpha2>
			<kBeta unit="Angstrom">1.3922500</kBeta>
			<ratioKAlpha2KAlpha1>0.5000</ratioKAlpha2KAlpha1>
		</usedWavelength>
		<incidentBeamPath>
			<radius unit="mm">145.00</radius>
			<xRayTube id="1010048" name="Empyrean Cu LFF HR (9430 033 7310x)">
				<tension unit="kV">40.0</tension>
				<current unit="mA">15.0</current>
				<anodeMaterial>Cu</anodeMaterial>
				<focus type="Line">
					<length unit="mm">12.0</length>
					<width unit="mm">0.4</width>
					<takeOffAngle unit="deg">6.0</takeOffAngle>
				</focus>
			</xRayTube>
			<sollerSlit id="21010002" name="Soller slits 0.04 rad.">
				<opening unit="rad">0.0400</opening>
			</sollerSlit>
			<mask id="22031000" name="Fixed mask 13 mm">
				<width unit="mm">9.00</width>
			</mask>
			<divergenceSlit id="22120001" name="Divergence slit 1°" xsi:type="fixedDivergenceSlitType">
				<distanceToSample unit="mm">50.00</distanceToSample>
				<height unit="mm">1.52</height>
			</divergenceSlit>
		</incidentBeamPath>
		<sampleMovement xsi:type="spinningSampleMovementType">
			<spinnerRevolutionTime unit="seconds">1.0</spinnerRevolutionTime>
		</sampleMovement>
		<diffractedBeamPath>
			<radius unit="mm">145.00</radius>
			<antiScatterSlit id="22090040" name="AS slit 9 mm (PIXcel)" xsi:type="fixedAntiScatterSlitType">
				<height unit="mm">9.00</height>
			</antiScatterSlit>
			<sollerSlit id="21020003" name="Large Soller slits 0.04 rad.">
				<opening unit="rad">0.0400</opening>
			</sollerSlit>
			<filter id="20030001" name="Large beta-filter Nickel">
				<material>Ni</material>
				<thickness unit="mm">0.020</thickness>
			</filter>
			<detector id="7010019" name="PIXcel1D-Medipix3 detector" xsi:type="rtmsDetectorType">
				<phd unit="keV">
					<lowerLevel>4.02</lowerLevel>
					<upperLevel>11.27</upperLevel>
				</phd>
				<mode>Scanning</mode>
				<activeLength unit="deg">5.542</activeLength>
			</detector>
		</diffractedBeamPath>
		<scan appendNumber="0" mode="Continuous" scanAxis="Gonio" status="Completed">
			<header>
				<startTimeStamp>2024-11-14T14:04:43-08:00</startTimeStamp>
				<endTimeStamp>2024-11-14T14:06:48-08:00</endTimeStamp>
				<author>
					<name>AutomatedUser</name>
				</author>
				<source>
					<applicationSoftware version="1.7b (136)">PANalytical Aeris Instrument Suite</applicationSoftware>
					<instrumentControlSoftware version="3.2.00000000 20240306">AERIS</instrumentControlSoftware>
					<instrumentID>950485</instrumentID>
				</source>
			</header>
			<dataPoints>
				<positions axis="2Theta" unit="deg">
					<startPosition>10.02173288</startPosition>
					<endPosition>99.99585608</endPosition>
				</positions>
				<positions axis="Omega" unit="deg">
					<startPosition>5.01086644</startPosition>
					<endPosition>49.99792804</endPosition>
				</positions>
				<commonCountingTime unit="seconds">10.965</commonCountingTime>
				<counts unit="counts">1947 1935 1933 1955 1958 1962 1894 1921 1941 1931 1908 1814 1853 1825 1835 1789 1779 1812 1761 1735 1767 1801 1667 1773 1736 1790 1701 1676 1694 1764 1577 1695 1610 1689 1610 1659 1649 1620 1676 1554 1588 1520 1599 1522 1559 1551 1521 1527 1480 1482 1530 1504 1546 1598 1542 1565 1417 1395 1514 1425 1478 1479 1411 1445 1411 1362 1400 1366 1440 1361 1401 1409 1401 1303 1387 1431 1398 1341 1255 1364 1319 1371 1277 1354 1378 1207 1344 1319 1314 1302 1267 1259 1311 1283 1238 1288 1327 1304 1307 1319 1250 1336 1286 1289 1312 1320 1201 1257 1250 1251 1217 1274 1284 1337 1298 1283 1234 1283 1354 1412 1439 1526 1562 1663 1712 1777 1694 1647 1594 1524 1451 1441 1340 1328 1333 1214 1177 1217 1219 1174 1205 1198 1216 1176 1153 1174 1165 1164 1109 1183 1188 1189 1188 1154 1140 1154 1198 1133 1191 1155 1174 1096 1207 1211 1196 1156 1230 1176 1192 1216 1124 1114 1197 1120 1232 1190 1192 1222 1121 1224 1138 1152 1111 1080 1124 1127 1102 1146 1119 1033 1088 1098 1053 1129 1087 1109 1123 1159 1114 1030 1085 1036 1041 1142 1040 1084 1083 1123 1027 1131 1120 1098 1025 991 1095 1092 1119 1127 1066 1107 1055 1056 1163 1203 1125 1210 1185 1254 1427 1484 1680 1932 2319 2872 3350 4024 4733 5502 6391 6922 6947 6207 5474 4484 3990 3455 3314 2694 2144 1618 1353 1288 1274 1148 1109 1141 1174 1093 1107 1082 1158 1181 1170 1274 1389 1382 1557 1742 1858 2062 2218 2498 2577 2599 2409 2201 2008 1802 1680 1596 1455 1316 1224 1060 1096 1087 1018 973 1015 1001 1004 913 943 1029 944 1007 997 1002 943 1008 967 988 992 997 962 936 968 900 956 979 989 994 956 970 934 986 959 1042 1029 1020 1053 1048 1125 1091 1139 1175 1247 1143 1256 1243 1155 1204 1110 1128 1147 1154 1158 1097 1126 1040 989 1019 950 939 973 945 891 930 936 932 983 890 946 967 973 982 1005 1005 1033 1155 1129 1119 1166 1193 1087 1139 1165 1242 1490 1633 1668 1876 2045 2069 2174 2154 2017 2000 1685 1602 1559 1379 1244 1058 1039 927 908 928 935 850 896 819 877 878 897 770 797 833 841 883 872 871 893 942 928 860 907 887 954 971 1017 987 1103 1127 1190 1354 1523 1701 1913 2109 2282 2373 2343 2325 2096 1997 1890 1627 1557 1398 1221 1094 1025 960 976 979 972 879 845 857 886 930 899 852 871 835 839 866 845 846 785 725 783 866 867 808 866 800 872 814 827 794 826 885 874 898 841 905 818 866 950 868 938 885 963 925 926 960 1122 1218 1368 1689 1782 2047 2362 2659 2845 2946 2810 2840 2634 2495 2405 2230 2258 2227 2086 2114 2059 1918 1788 1635 1558 1478 1266 1190 1153 1055 970 990 1055 1037 1119 1146 1273 1409 1462 1548 1617 1629 1449 1452 1311 1291 1244 1121 1012 969 855 799 864 859 808 865 863 900 896 1006 1015 1021 1088 1062 1009 982 980 970 936 950 858 849 890 881 899 945 973 1051 1183 1299 1365 1532 1688 1783 1758 1824 1789 1672 1620 1428 1317 1216 1121 1038 911 878 883 860 858 808 882 806 880 892 906 936 929 1029 1004 995 937 942 902 881 888 839 845 814 835 869 814 851 844 865 881 858 877 814 789 775 775 780 743 806 751 779 718 691 698 733 706 698 704 683 732 701 731 733 745 714 673 683 768 755 790 828 809 810 804 814 727 744 735 653 716 744 693 694 658 728 702 732 659 684 712 722 724 767 783 760 713 785 729 754 763 742 753 718 740 702 781 702 673 706 725 676 682 710 670 695 730 705 767 678 731 752 735 766 695 701 644 676 731 695 694 717 723 717 751 723 730 726 762 725 787 735 777 783 846 825 885 978 928 940 954 940 1012 1052 1051 1179 1268 1355 1479 1706 1862 1852 1865 1918 1752 1731 1504 1373 1223 1094 1022 1002 853 930 945 986 1006 1043 1146 1121 1183 1182 1129 1011 989 899 833 747 832 761 720 651 660 632 683 692 677 683 633 644 629 694 662 679 637 678 618 611 667 729 644 627 720 628 631 656 724 658 654 647 657 665 677 685 708 715 665 719 734 677 698 726 737 745 703 725 726 663 704 743 769 759 799 770 853 800 785 732 799 834 786 773 859 887 927 1029 1062 1063 1153 1084 1134 1131 1096 1013 967 908 834 764 729 673 676 702 606 649 642 671 635 654 683 692 697 609 659 632 665 638 647 697 652 616 664 682 713 752 841 776 852 972 1095 1152 1216 1275 1218 1308 1258 1223 1205 1185 1155 1149 1111 1179 1215 1268 1350 1205 1252 1133 1189 1050 900 855 770 764 733 748 726 725 798 835 912 917 995 1083 1188 1229 1213 1223 1307 1306 1256 1172 1106 1139 1146 1164 1180 1209 1094 1094 1076 1110 980 966 955 865 846 890 924 834 924 923 1075 1128 1174 1175 1141 1094 1094 1134 1093 1037 975 961 991 946 956 957 972 925 876 844 892 843 900 916 1057 1014 1136 1150 1245 1282 1265 1229 1215 1190 1039 989 996 875 848 765 775 802 802 835 873 898 992 937 944 946 971 926 828 786 813 769 722 755 726 688 732 643 716 641 685 634 668 624 662 692 632 592 595 645 652 673 645 672 659 694 679 646 618 742 702 754 751 773 754 749 822 791 873 916 839 868 898 838 833 875 745 752 738 730 669 752 664 699 665 665 741 624 667 658 668 693 667 762 733 796 830 817 880 985 980 1011 1036 1070 1299 1155 1167 1189 1192 1072 1066 1053 1009 976 938 922 870 797 791 797 807 811 759 745 757 757 732 719 716 698 700 648 700 672 619 708 738 749 723 748 733 707 746 715 774 845 770 727 739 765 725 699 668 696 709 699 736 738 744 733 699 733 753 754 731 811 832 798 762 813 780 782 862 839 792 850 827 830 750 865 874 921 900 966 963 956 974 969 902 860 842 778 752 718 738 704 746 732 838 816 762 772 884 914 911 975 995 885 981 913 956 899 940 832 780 768 760 740 716 671 689 661 691 682 674 716 800 775 851 877 953 970 972 1038 1004 1052 1007 939 942 915 850 767 735 757 736 741 824 772 809 834 853 969 1034 1105 1171 1156 1193 1086 1134 1139 983 884 872 856 825 799 788 746 761 846 792 767 767 845 804 836 771 760 750 694 692 696 646 631 670 643 595 600 595 636 648 677 636 702 685 692 698 651 689 648 697 719 744 821 806 837 859 897 905 917 947 899 907 855 845 847 834 727 712 715 708 771 701 647 693 700 729 748 695 670 724 711 724 720 808 737 705 792 805 844 787 755 838 858 867 844 830 865 842 836 733 793 753 623 664 652 678 622 629 586 587 630 620 618 608 593 620 606 606 605 643 585 597 647 620 578 630 589 612 654 609 643 649 657 672 669 756 696 746 701 718 714 691 686 695 724 686 706 742 715 738 776 764 750 797 789 780 801 822 882 924 901 920 929 900 846 839 776 863 737 715 719 759 738 762 746 831 863 910 846 924 891 851 798 786 795 850 826 743 752 773 774 799 861 836 840 838 864 830 786 764 746 704 730 674 674 684 690 674 648 692 670 737 692 712 702 741 722 707 783 698 717 767 679 763 819 723 761 832 839 809 781 820 809 812 789 865 740 855 855 851 923 872 901 907 875 945 912 877 959 904 899 861 879 761 772 718 716 689 646 701 642 626 662 606 619 626 635 588 612 577 625 591 681 669 601 596 702 626 671 626 625 651 656 709 713 782 830 835 915 896 901 948 947 938 835 875 796 807 740 751 773 760 719 754 672 731 676 667 599 674 672 622 619 584 607 603 622 613 650 648 692 652 731 694 737 740 741 743 720 746 677 675 657 649 729 768 697 650 680 646 665 627 593 654 683 629 634 635 681 634 677 680 682 687 683 680 727 655 642 713 693 691 690 715 651 657 686 729 718 700 765 734 762 735 803 782 824 764 717 703 758 670 740 659 647 637 639 650 668 614 655 616 664 616 630 590 563 673 612 597 631 580 596 589 616 623 586 559 615 593 585 568 626 586 560 626 589 573 599 653 601 615 617 587 647 608 619 564 608 575 596 569 571 619 547 605 576 568 605 596 607 540 578 613 626 669 640 667 654 676 651 693 652 663 642 587 658 641 589 650 628 582 648 618 668 673 609 594 570 639 633 656 664 676 714 673 665 681 648 631 689 746 711 712 662 717 701 665 677 693 665 680 639 658 662 599 626 661 639 639 645 607 705 637 688 657 664 731 696 747 682 673 716 745 647 674 677 674 692 642 656 665 694 599 646 656 634 637 672 632 639 672 604 611 674 636 684 614 620 657 618 605 596 682 595 613 601 588 626 599 590 562 636 587 626 669 639 623 651 635 627 652 668 666 650 659 716 675 702 705 685 686 750 748 673 711 723 687 678 671 581 607 602 634 636 672 680 633 649 624 647 671 665 669 641 595 661 625 637 644 672 617 623 680 701 692 817 711 780 750 775 851 760 766 800 799 729 740 742 667 696 651 713 661 636 640 622 657 631 655 688 644 606 695 655 715 709 704 699 738 790 749 755 687 701 686 730 679 720 625 691 684 669 619 690 662 642 668 697 723 694 726 692 704 752 725 741 684 698 771 643 695 672 653 675 597 599 652 604 560 637 558 609 616 589 621 630 618 597 603 640 602 566 646 601 627 595 583 608 597 597 616 611 620 653 627 633 638 530 662 622 655 665 676 735 679 695 655 681 627 698 653 647 694 633 686 699 667 640 659 660 666 682 659 731 656 660 613 649 650 651 621 658 620 641 687 653 632 637 706 631 684 672 607 639 628 666 661 656 697 664 724 723 699 716 710 735 727 713 729 679 672 675 709 654 586 651 634 643 634 667 642 680 623 640 647 612 672 624 678 644 647 666 697 687 662 685 634 635 667 678 665 710 682 672 674 666 638 667 653 658 683 659 705 648 649 612 611 664 631 658 662 676 651 659 628 666 653 632 638 731 644 702 656 672 642 632 611 585 667 662 618 694 671 598 648 643 654 672 655 700 675 707 680 673 658 638 705 702 695 774 748 741 721 794 776 798 815 780 851 785 737</counts>
			</dataPoints>
		</scan>
	</xrdMeasurement>
</xrdMeasurements>