File: dataset/precursor_mixture/V2O5_0p3005-NiO_0p4020-TiO2_0p3020--8min.xrdml
<?xml version="1.0"?>
<xrdMeasurements xmlns="http://www.xrdml.com/XRDMeasurement/2.3" xmlns:xsi="http://www.w3.org/2001/XMLSchema-instance" xsi:schemaLocation="http://www.xrdml.com/XRDMeasurement/2.3 http://www.xrdml.com/XRDMeasurement/2.3/XRDMeasurement.xsd" status="Completed" recordIdentifier="{9C5DA32C-6FDE-4767-95F7-62A029571D97}">
	<comment>
		<entry/>
	</comment>
	<sample type="To be analyzed">
		<id>V2O5_0p3005-NiO_0p4020-TiO2_0p3020--8min</id>
		<name></name>
		<preparedBy></preparedBy>
	</sample>
	<xrdMeasurement measurementType="Scan" status="Completed" sampleMode="Reflection">
		<usedWavelength intended="K-Alpha 1">
			<kAlpha1 unit="Angstrom">1.5405980</kAlpha1>
			<kAlpha2 unit="Angstrom">1.5444260</kAlpha2>
			<kBeta unit="Angstrom">1.3922500</kBeta>
			<ratioKAlpha2KAlpha1>0.5000</ratioKAlpha2KAlpha1>
		</usedWavelength>
		<incidentBeamPath>
			<radius unit="mm">145.00</radius>
			<xRayTube id="1010048" name="Empyrean Cu LFF HR (9430 033 7310x)">
				<tension unit="kV">40.0</tension>
				<current unit="mA">15.0</current>
				<anodeMaterial>Cu</anodeMaterial>
				<focus type="Line">
					<length unit="mm">12.0</length>
					<width unit="mm">0.4</width>
					<takeOffAngle unit="deg">6.0</takeOffAngle>
				</focus>
			</xRayTube>
			<sollerSlit id="21010002" name="Soller slits 0.04 rad.">
				<opening unit="rad">0.0400</opening>
			</sollerSlit>
			<mask id="22031000" name="Fixed mask 13 mm">
				<width unit="mm">9.00</width>
			</mask>
			<divergenceSlit id="22120001" name="Divergence slit 1°" xsi:type="fixedDivergenceSlitType">
				<distanceToSample unit="mm">50.00</distanceToSample>
				<height unit="mm">1.52</height>
			</divergenceSlit>
		</incidentBeamPath>
		<sampleMovement xsi:type="spinningSampleMovementType">
			<spinnerRevolutionTime unit="seconds">1.0</spinnerRevolutionTime>
		</sampleMovement>
		<diffractedBeamPath>
			<radius unit="mm">145.00</radius>
			<antiScatterSlit id="22090040" name="AS slit 9 mm (PIXcel)" xsi:type="fixedAntiScatterSlitType">
				<height unit="mm">9.00</height>
			</antiScatterSlit>
			<sollerSlit id="21020003" name="Large Soller slits 0.04 rad.">
				<opening unit="rad">0.0400</opening>
			</sollerSlit>
			<filter id="20030001" name="Large beta-filter Nickel">
				<material>Ni</material>
				<thickness unit="mm">0.020</thickness>
			</filter>
			<detector id="7010019" name="PIXcel1D-Medipix3 detector" xsi:type="rtmsDetectorType">
				<phd unit="keV">
					<lowerLevel>4.02</lowerLevel>
					<upperLevel>11.27</upperLevel>
				</phd>
				<mode>Scanning</mode>
				<activeLength unit="deg">5.542</activeLength>
			</detector>
		</diffractedBeamPath>
		<scan appendNumber="0" mode="Continuous" scanAxis="Gonio" status="Completed">
			<header>
				<startTimeStamp>2024-11-14T15:23:55-08:00</startTimeStamp>
				<endTimeStamp>2024-11-14T15:32:02-08:00</endTimeStamp>
				<author>
					<name>AutomatedUser</name>
				</author>
				<source>
					<applicationSoftware version="1.7b (136)">PANalytical Aeris Instrument Suite</applicationSoftware>
					<instrumentControlSoftware version="3.2.00000000 20240306">AERIS</instrumentControlSoftware>
					<instrumentID>950485</instrumentID>
				</source>
			</header>
			<dataPoints>
				<positions axis="2Theta" unit="deg">
					<startPosition>10.00943322</startPosition>
					<endPosition>99.99442286</endPosition>
				</positions>
				<positions axis="Omega" unit="deg">
					<startPosition>5.00471661</startPosition>
					<endPosition>49.99721143</endPosition>
				</positions>
				<commonCountingTime unit="seconds">12.495</commonCountingTime>
				<counts unit="counts">2667 2675 2717 2675 2662 2597 2705 2720 2609 2688 2693 2642 2604 2660 2668 2664 2640 2623 2658 2664 2654 2635 2584 2535 2583 2589 2551 2687 2538 2614 2523 2665 2622 2629 2584 2566 2539 2630 2578 2552 2492 2522 2524 2660 2532 2641 2641 2521 2604 2541 2565 2580 2444 2490 2524 2550 2465 2484 2546 2513 2485 2515 2493 2622 2599 2492 2614 2531 2513 2509 2507 2611 2470 2496 2535 2488 2516 2479 2489 2527 2499 2455 2445 2430 2457 2466 2533 2471 2484 2375 2470 2480 2495 2432 2421 2401 2447 2410 2463 2596 2484 2516 2479 2421 2425 2519 2447 2379 2504 2445 2410 2369 2466 2303 2492 2298 2400 2308 2370 2369 2298 2409 2308 2372 2426 2361 2356 2333 2411 2391 2418 2380 2372 2316 2279 2489 2442 2379 2379 2382 2435 2311 2388 2401 2361 2291 2373 2351 2301 2317 2363 2328 2381 2218 2317 2436 2391 2406 2316 2304 2329 2342 2247 2325 2321 2268 2366 2377 2263 2359 2277 2320 2297 2343 2353 2297 2305 2292 2321 2313 2340 2232 2255 2340 2302 2359 2341 2283 2260 2257 2328 2294 2281 2289 2299 2257 2251 2353 2185 2275 2336 2275 2256 2213 2251 2145 2270 2269 2300 2244 2320 2270 2216 2297 2205 2324 2313 2229 2209 2303 2187 2234 2137 2318 2206 2288 2194 2246 2244 2240 2215 2186 2203 2298 2131 2223 2180 2238 2218 2279 2215 2296 2218 2232 2300 2307 2192 2216 2193 2262 2249 2176 2242 2235 2144 2224 2234 2258 2115 2134 2173 2165 2256 2261 2178 2211 2189 2247 2198 2217 2268 2155 2233 2207 2261 2126 2133 2219 2216 2200 2192 2185 2278 2167 2211 2207 2226 2134 2240 2180 2235 2115 2182 2223 2238 2236 2109 2160 2120 2187 2173 2151 2205 2159 2251 2190 2114 2185 2144 2172 2153 2164 2168 2127 2145 2219 2162 2245 2210 2100 2154 2150 2198 2193 2153 2147 2082 2153 2097 2149 2132 2219 2162 2141 2138 2165 2179 2145 2167 2185 2117 2179 2228 2143 2132 2078 2185 2178 2190 2225 2126 2276 2120 2119 2172 2139 2155 2197 2197 2140 2154 2161 2121 2171 2120 2106 2137 2167 2149 2063 2171 2100 2187 2179 2104 2173 2122 2153 2179 2191 2174 2135 2170 2171 2211 2192 2212 2072 2171 2170 2207 2118 2135 2089 2085 2236 2210 2138 2155 2176 2145 2090 2112 2206 2131 2139 2121 2106 2090 2169 2128 2157 2169 2189 2190 2116 2197 2236 2171 2159 2156 2133 2204 2173 2060 2077 2102 2150 2080 2161 2140 2191 2119 2181 2164 2167 2123 2190 2082 2178 2122 2169 2130 2198 2134 2149 2161 2112 2139 2247 2229 2199 2177 2132 2140 2170 2151 2227 2132 2165 2166 2231 2219 2147 2197 2132 2185 2177 2166 2236 2247 2295 2252 2259 2177 2321 2258 2321 2272 2368 2354 2384 2494 2405 2496 2539 2619 2599 2654 2622 2629 2598 2652 2733 2742 2706 2754 2723 2782 2692 2781 2709 2819 2669 2708 2599 2691 2659 2548 2562 2530 2469 2459 2358 2354 2333 2372 2275 2162 2254 2241 2194 2228 2232 2214 2113 2261 2259 2249 2154 2179 2213 2081 2162 2201 2152 2219 2161 2241 2232 2233 2215 2194 2229 2148 2202 2100 2124 2128 2058 2098 2163 2117 2162 2102 2082 2186 2180 2219 2133 2199 2089 2108 2140 2190 2143 2151 2154 2221 2125 2251 2196 2170 2127 2178 2210 2193 2159 2149 2251 2162 2145 2174 2213 2182 2169 2150 2205 2063 2171 2216 2159 2239 2255 2181 2205 2162 2224 2166 2243 2171 2166 2177 2079 2267 2097 2158 2087 2140 2165 2156 2145 2127 2065 2119 2189 2126 2137 2200 2241 2239 2146 2209 2168 2062 2174 2160 2160 2083 2154 2181 2189 2170 2170 2168 2158 2197 2138 2210 2134 2178 2186 2140 2127 2202 2159 2059 2124 2214 2183 2164 2248 2140 2201 2241 2128 2111 2192 2235 2154 2166 2215 2086 2183 2253 2138 2052 2148 2153 2135 2210 2182 2163 2204 2182 2170 2113 2228 2192 2127 2198 2282 2128 2126 2143 2223 2123 2098 2252 2176 2146 2089 2188 2091 2175 2139 2132 2174 2201 2178 2215 2139 2269 2228 2241 2123 2125 2145 2154 2186 2199 2240 2195 2189 1991 2259 2064 2077 2193 2138 2198 2145 2186 2185 2112 2127 2159 2229 2227 2207 2142 2145 2225 2125 2254 2200 2210 2226 2113 2172 2135 2195 2113 2173 2131 2177 2068 2232 2168 2175 2095 2159 2213 2139 2144 2163 2141 2186 2179 2137 2184 2198 2142 2164 2218 2123 2199 2047 2211 2202 2116 2173 2178 2197 2168 2166 2229 2258 2144 2198 2183 2234 2219 2237 2169 2159 2180 2230 2179 2163 2173 2285 2240 2162 2127 2133 2178 2213 2159 2164 2102 2246 2173 2174 2191 2301 2137 2180 2205 2184 2187 2220 2177 2211 2262 2118 2125 2310 2155 2185 2213 2152 2125 2106 2121 2113 2226 2250 2178 2125 2137 2101 2167 2127 2225 2186 2133 2185 2162 2174 2169 2127 2181 2210 2156 2216 2192 2216 2202 2156 2168 2186 2225 2130 2242 2106 2122 2189 2223 2183 2061 2135 2187 2209 2147 2178 2162 2246 2255 2086 2251 2177 2191 2140 2177 2260 2187 2200 2179 2167 2218 2146 2221 2153 2196 2190 2235 2292 2250 2324 2175 2241 2220 2261 2213 2254 2304 2248 2243 2308 2333 2284 2196 2266 2278 2261 2259 2379 2347 2362 2409 2416 2454 2344 2479 2422 2490 2489 2596 2508 2544 2623 2693 2680 2778 2842 2961 2990 3028 3163 3323 3245 3339 3663 3800 4045 4151 4257 4498 4815 4989 5077 5284 5322 5393 5598 5692 5716 5707 5857 5958 5793 5885 5715 5749 5448 5566 5393 5289 5014 5021 4851 4686 4360 4276 3933 3809 3623 3421 3303 3192 3019 2898 2846 2630 2664 2525 2496 2475 2416 2554 2467 2442 2420 2330 2349 2356 2379 2251 2359 2268 2259 2302 2339 2285 2295 2380 2260 2242 2278 2183 2251 2277 2302 2272 2197 2222 2269 2278 2221 2255 2248 2129 2170 2181 2300 2188 2259 2306 2296 2253 2230 2147 2254 2251 2197 2281 2182 2212 2210 2191 2272 2220 2258 2232 2178 2195 2227 2310 2255 2235 2107 2292 2302 2352 2251 2304 2312 2249 2468 2323 2316 2266 2359 2269 2387 2358 2326 2392 2460 2470 2514 2533 2514 2684 2629 2648 2793 2733 2905 2893 2902 2949 3140 3127 3112 3164 3181 3224 3250 3239 3305 3246 3299 3192 3219 3222 3196 3076 3093 3055 2941 3031 2943 2816 2798 2858 2798 2737 2565 2570 2406 2466 2451 2415 2407 2391 2335 2318 2275 2215 2316 2355 2406 2292 2261 2230 2186 2242 2276 2307 2302 2202 2216 2198 2192 2240 2280 2177 2244 2259 2257 2261 2176 2195 2198 2266 2235 2245 2223 2297 2241 2212 2271 2174 2205 2309 2186 2221 2274 2195 2219 2209 2267 2265 2274 2243 2209 2141 2209 2294 2169 2245 2189 2243 2223 2221 2187 2297 2251 2146 2143 2271 2123 2184 2225 2236 2217 2286 2207 2204 2178 2226 2240 2269 2263 2233 2212 2183 2220 2225 2233 2144 2226 2219 2241 2148 2204 2205 2231 2243 2257 2167 2209 2210 2193 2169 2237 2287 2217 2245 2266 2291 2286 2192 2196 2192 2308 2252 2187 2127 2204 2177 2201 2255 2253 2322 2108 2136 2197 2159 2212 2210 2128 2118 2217 2193 2262 2182 2190 2126 2340 2137 2242 2139 2232 2225 2250 2226 2240 2141 2143 2158 2152 2240 2098 2235 2231 2254 2138 2272 2238 2221 2145 2165 2188 2156 2182 2213 2310 2253 2187 2209 2125 2170 2155 2201 2120 2269 2085 2249 2161 2276 2196 2228 2290 2272 2190 2134 2233 2127 2296 2243 2182 2319 2221 2190 2184 2179 2180 2264 2233 2220 2226 2221 2198 2125 2282 2180 2183 2182 2174 2215 2251 2217 2182 2184 2298 2165 2200 2216 2272 2311 2253 2291 2280 2221 2272 2205 2263 2224 2262 2185 2308 2372 2329 2220 2273 2249 2230 2228 2272 2304 2372 2260 2331 2269 2353 2241 2282 2201 2233 2271 2297 2215 2307 2259 2241 2317 2339 2281 2331 2402 2357 2351 2353 2400 2345 2450 2428 2361 2405 2387 2473 2464 2537 2626 2613 2677 2599 2785 2716 2707 2879 2864 2961 3095 3096 3297 3333 3608 3751 3949 4284 4412 4804 4905 5396 5823 6095 6505 6965 7448 7644 8123 8231 8525 8654 8996 9116 9154 9148 9211 9062 8960 8910 8681 8495 8325 7918 7676 7380 6979 6664 6231 5989 5409 5220 4800 4362 4307 3962 3672 3489 3375 3232 3112 2929 2864 2863 2825 2801 2659 2772 2677 2592 2624 2484 2582 2545 2487 2602 2496 2455 2391 2414 2525 2450 2391 2386 2442 2438 2438 2501 2512 2525 2524 2534 2560 2730 2692 2778 2943 2924 2997 3124 3333 3367 3205 3438 3592 3560 3766 3755 3887 3906 4076 3952 4060 4027 3961 4030 3743 3921 3895 3872 3736 3668 3407 3526 3453 3321 3187 3027 3006 2953 2694 2644 2653 2524 2447 2422 2430 2375 2361 2321 2344 2299 2281 2265 2400 2316 2265 2276 2271 2278 2264 2202 2304 2195 2295 2222 2183 2269 2284 2318 2317 2171 2183 2205 2208 2308 2191 2297 2266 2214 2217 2319 2293 2311 2234 2198 2267 2233 2184 2255 2182 2177 2208 2179 2165 2261 2218 2245 2230 2247 2243 2247 2214 2252 2164 2238 2292 2161 2187 2229 2190 2148 2231 2236 2211 2140 2188 2185 2181 2190 2282 2141 2253 2223 2148 2225 2222 2237 2336 2300 2233 2238 2237 2251 2162 2265 2312 2270 2320 2209 2259 2225 2210 2325 2241 2213 2359 2289 2135 2250 2218 2226 2272 2196 2208 2285 2218 2163 2120 2199 2202 2169 2236 2183 2163 2189 2249 2217 2174 2234 2265 2261 2221 2235 2225 2212 2202 2315 2272 2242 2199 2176 2171 2177 2187 2248 2245 2245 2235 2243 2206 2122 2175 2190 2145 2157 2180 2142 2198 2205 2177 2285 2187 2241 2168 2262 2255 2166 2172 2222 2195 2192 2270 2291 2174 2245 2230 2213 2224 2210 2114 2166 2213 2095 2230 2166 2263 2200 2187 2192 2210 2181 2161 2219 2231 2216 2198 2247 2219 2201 2246 2116 2159 2203 2212 2100 2112 2203 2175 2232 2183 2248 2170 2084 2221 2231 2276 2320 2241 2250 2173 2139 2115 2145 2174 2183 2215 2225 2150 2229 2197 2200 2146 2169 2194 2213 2186 2264 2265 2172 2212 2158 2225 2140 2217 2150 2204 2211 2211 2154 2188 2145 2127 2157 2122 2127 2177 2156 2245 2200 2212 2264 2206 2107 2245 2207 2201 2141 2141 2217 2200 2209 2162 2258 2217 2207 2231 2195 2216 2149 2104 2207 2165 2119 2190 2230 2170 2165 2084 2204 2186 2118 2147 2227 2130 2286 2243 2206 2164 2132 2209 2149 2231 2152 2111 2185 2200 2123 2214 2160 2164 2197 2110 2213 2153 2182 2172 2131 2211 2162 2265 2201 2229 2128 2170 2197 2194 2217 2184 2208 2124 2240 2156 2120 2243 2180 2241 2155 2182 2214 2139 2162 2225 2233 2247 2186 2137 2125 2180 2179 2131 2180 2313 2190 2127 2174 2116 2298 2232 2190 2252 2191 2216 2186 2217 2183 2226 2214 2167 2266 2210 2280 2310 2231 2246 2298 2163 2271 2262 2197 2278 2270 2164 2164 2284 2171 2234 2299 2242 2304 2220 2275 2359 2265 2253 2244 2257 2279 2300 2263 2338 2285 2441 2349 2288 2452 2553 2617 2451 2572 2567 2616 2813 2691 2870 2928 3020 2934 3133 3109 3386 3505 3579 3612 3737 3838 3879 3947 3898 4142 4073 4119 4187 4067 4032 4053 3928 3941 3891 3867 3784 3585 3581 3492 3437 3312 3183 3028 2965 2767 2864 2664 2615 2540 2490 2445 2426 2377 2375 2305 2245 2299 2390 2310 2262 2079 2200 2303 2334 2234 2249 2232 2228 2142 2202 2251 2253 2207 2240 2170 2274 2104 2160 2055 2202 2164 2154 2139 2076 2202 2174 2211 2104 2198 2189 2239 2237 2235 2107 2189 2191 2296 2157 2160 2150 2161 2212 2142 2210 2223 2175 2229 2109 2211 2119 2170 2243 2159 2186 2180 2210 2177 2275 2145 2280 2180 2182 2191 2229 2182 2158 2319 2167 2279 2170 2299 2205 2342 2371 2315 2404 2442 2485 2543 2516 2661 2642 2664 2701 2871 2827 2768 2864 2938 2912 2955 2987 2999 2989 2940 2995 2997 2869 2877 2881 2932 2681 2729 2728 2701 2635 2579 2448 2534 2429 2416 2393 2379 2364 2328 2318 2233 2270 2184 2247 2246 2225 2175 2179 2273 2096 2266 2137 2154 2228 2285 2256 2176 2185 2248 2143 2090 2243 2187 2154 2124 2223 2212 2205 2190 2194 2193 2194 2156 2185 2164 2174 2211 2191 2180 2149 2169 2187 2172 2246 2163 2230 2234 2214 2230 2220 2315 2242 2317 2279 2370 2401 2360 2394 2305 2325 2317 2503 2411 2300 2372 2371 2370 2388 2328 2356 2401 2332 2337 2355 2327 2317 2278 2253 2228 2201 2193 2231 2218 2220 2193 2205 2131 2174 2172 2296 2111 2199 2238 2221 2172 2182 2106 2173 2113 2112 2121 2228 2104 2164 2150 2215 2159 2081 2162 2090 2008 2079 2158 2166 2132 2132 2211 2061 2113 2140 2189 2166 2220 2174 2250 2182 2119 2204 2171 2227 2273 2175 2254 2297 2339 2359 2314 2329 2381 2469 2405 2561 2627 2520 2708 2793 2699 2791 2687 2745 2820 2788 2886 2793 2836 2817 2832 2870 2876 2852 2740 2756 2742 2765 2756 2684 2572 2541 2506 2460 2429 2484 2278 2332 2280 2276 2199 2268 2209 2180 2186 2135 2181 2055 2244 2158 2231 2175 2136 2072 2107 2116 2159 2184 2153 2087 2150 2140 2143 2193 2071 2106 2109 2007 2079 2092 2242 2109 2117 2185 2036 2116 2133 2219 2044 2120 2196 2099 2072 2067 2139 2119 2100 2101 2096 2074 2193 2119 2103 2204 2232 2099 2139 2138 2177 2068 2092 2111 2227 2079 2171 2087 2211 2084 2098 2089 2085 2115 2134 2136 2186 2078 2194 2131 2196 2281 2073 2158 2137 2171 2187 2147 2107 2081 2133 2046 2109 2135 2100 2154 2105 2067 2116 2153 2213 2150 2168 2127 2096 2143 2209 2112 2229 2094 2192 2194 2191 2035 2171 2202 2174 2112 2172 2182 2209 2150 2137 2183 2203 2223 2148 2210 2243 2163 2280 2166 2147 2283 2244 2163 2231 2242 2282 2269 2292 2275 2210 2300 2222 2237 2249 2266 2176 2296 2228 2335 2201 2201 2181 2355 2248 2211 2137 2221 2182 2198 2198 2198 2200 2124 2204 2275 2144 2068 2225 2039 2079 2222 2091 2379 2220 2186 2263 2258 2175 2231 2215 2247 2170 2227 2278 2144 2161 2205 2311 2329 2183 2269 2300 2293 2294 2319 2286 2383 2390 2409 2376 2428 2305 2380 2345 2478 2500 2446 2556 2636 2596 2606 2700 2734 2777 2807 2939 3003 3039 3172 3156 3229 3231 3334 3411 3472 3603 3736 3843 4043 4164 4265 4532 4869 4880 5270 5409 5551 5931 6266 6489 6856 7013 7175 7398 7651 7770 7989 8183 8214 8108 8261 8082 8167 7931 7763 7723 7532 7341 6887 6750 6446 6170 5861 5565 5236 5092 4720 4503 4184 4033 3957 3628 3561 3430 3280 3273 3130 3138 3034 3113 3050 3130 3012 3194 3077 3254 3283 3284 3470 3446 3540 3470 3704 3555 3864 3807 3771 3752 3875 3787 3858 3748 3896 3646 3777 3586 3567 3403 3452 3172 3279 3154 2967 2951 2885 2860 2741 2643 2620 2526 2507 2453 2440 2364 2374 2280 2300 2266 2175 2273 2298 2260 2278 2232 2182 2269 2161 2216 2205 2112 2220 2204 2165 2203 2223 2297 2238 2158 2230 2132 2310 2188 2345 2345 2295 2401 2324 2460 2403 2450 2479 2435 2572 2538 2415 2576 2655 2614 2542 2638 2688 2647 2615 2565 2671 2645 2570 2556 2487 2559 2476 2472 2350 2361 2390 2367 2318 2330 2249 2280 2220 2251 2244 2237 2196 2210 2221 2235 2177 2142 2105 2087 2218 2180 2153 2176 2127 2201 2159 2186 2063 2174 2127 2107 2056 2099 2106 2138 2268 2167 2130 2080 2136 2137 2091 2155 2104 2179 2146 2133 2103 2121 2103 2108 2170 2163 2125 2157 2139 2106 2123 2093 2144 2140 2208 2022 2078 2106 2060 2091 2154 2199 2103 2152 2117 2027 2160 1984 2080 2117 2084 2048 2142 2099 2114 2163 2091 2145 2147 2208 2082 2108 2041 2109 2163 2116 2083 2097 2089 2178 2147 2244 2096 2101 2139 2101 2103 2163 2153 2116 2103 2121 2102 2068 2128 2144 2152 2199 2118 2087 2106 2113 2097 2093 2097 2166 2181 2122 2105 2104 2110 2083 2174 2184 2128 2137 2159 2075 2084 2116 2211 2076 2144 2157 2029 2129 2129 2094 2130 2210 2042 2159 2129 2112 2122 2054 1987 2093 2087 2086 2104 2122 2078 2180 2167 2096 2035 2234 2148 2116 2113 2091 2025 2171 2104 2139 2185 2087 2175 2129 2125 2105 2131 2190 2140 2203 2204 2180 2053 2018 2125 2088 2123 2063 2142 2116 2149 2091 2068 2090 2130 2153 2155 2217 2074 2111 2169 2234 2174 2124 2172 2240 2191 2221 2165 2292 2176 2289 2183 2379 2316 2406 2415 2297 2487 2336 2456 2420 2495 2571 2489 2597 2689 2742 2724 2655 2724 2737 2772 2814 2848 2752 2657 2769 2763 2713 2627 2657 2637 2634 2507 2554 2560 2402 2479 2454 2464 2358 2384 2364 2186 2214 2177 2248 2284 2142 2119 2168 2199 2171 2181 2089 2176 2166 2112 2200 2250 2206 2121 2146 2171 2098 2224 2109 2257 2155 2225 2173 2187 2218 2135 2183 2194 2205 2317 2279 2258 2293 2304 2429 2356 2365 2422 2401 2408 2407 2386 2398 2429 2490 2514 2412 2405 2402 2447 2487 2466 2495 2355 2421 2459 2417 2361 2413 2274 2317 2432 2212 2229 2157 2263 2190 2265 2227 2330 2307 2308 2184 2273 2170 2191 2154 2198 2237 2193 2140 2193 2228 2167 2149 2222 2257 2096 2236 2175 2112 2270 2120 2243 2132 2202 2178 2267 2278 2245 2280 2266 2298 2276 2332 2295 2247 2273 2290 2372 2297 2397 2324 2337 2425 2458 2411 2415 2445 2470 2560 2525 2606 2525 2593 2695 2597 2670 2829 2704 2903 2848 3054 3121 3186 3399 3644 3839 3913 4181 4531 4899 5421 5737 6406 6567 7191 7729 8408 8890 9227 9714 10067 10542 11172 11494 11978 12102 12464 12683 12933 12812 12906 12635 12578 12407 11908 11704 11306 10642 10124 9711 8968 8431 7840 7143 6863 6389 5900 5444 5234 4921 4570 4108 3944 3601 3559 3335 3210 2981 2971 2898 2758 2753 2678 2726 2583 2536 2592 2421 2499 2497 2469 2366 2482 2380 2415 2379 2229 2307 2330 2293 2252 2352 2206 2276 2231 2228 2319 2232 2203 2214 2193 2247 2262 2185 2219 2268 2222 2239 2275 2216 2193 2169 2191 2256 2185 2258 2161 2162 2210 2216 2271 2092 2183 2252 2239 2179 2125 2168 2076 2098 2102 2194 2201 2214 2241 2105 2086 2166 2146 2218 2264 2188 2181 2127 2226 2127 2124 2126 2118 2122 2135 2125 2193 2124 2104 2100 2019 2169 2186 2072 2066 2149 2258 2132 2198 2100 2183 2170 2136 2165 2108 2096 2123 2154 2218 2107 2158 2119 2145 2090 2146 2084 2106 2069 2101 2083 2112 2129 2093 2110 2071 2070 2092 2189 2126 2087 2093 2174 2135 2187 2079 2130 2159 2196 2143 2124 2178 2037 2052 2195 2098 2232 2147 2145 2116 2213 2134 2197 2222 2156 2271 2239 2223 2311 2242 2274 2308 2241 2322 2326 2346 2413 2515 2288 2436 2394 2436 2420 2481 2470 2527 2518 2384 2604 2468 2379 2353 2366 2395 2443 2424 2393 2340 2337 2281 2289 2259 2200 2221 2209 2207 2225 2157 2230 2100 2203 2184 2126 2135 2193 2087 2079 2155 2126 2166 2155 2153 2210 2004 2090 2152 2058 2177 2027 2084 2050 2145 2142 2116 2106 2085 2102 2142 2126 2198 2046 2088 2088 2126 2104 2127 2123 2060 2144 2081 2113 2154 2079 2167 2141 2085 1988 2211 2102 2123 2032 2066 2183 2154 2167 2109 2164 2151 2133 2084 2041 2162 2081 2213 2074 1982 2129 2106 2051 2082 2116 2087 2062 2123 2155 2114 2174 2168 2023 2044 2020 2104 2065 2199 2093 2182 2142 2077 2117 2089 2054 2170 2164 2147 2080 2109 2080 2065 2084 2062 2069 2096 2107 2122 2104 2200 2125 2088 2192 2196 2146 2124 2195 2131 2232 2239 2226 2161 2084 2159 2248 2239 2189 2194 2209 2166 2290 2299 2292 2326 2475 2366 2411 2462 2458 2454 2523 2524 2564 2533 2682 2670 2621 2636 2710 2752 2707 2685 2806 2701 2659 2736 2662 2690 2648 2570 2568 2590 2491 2486 2547 2427 2498 2475 2405 2351 2351 2354 2348 2373 2348 2447 2401 2392 2372 2362 2417 2417 2400 2435 2471 2517 2585 2590 2619 2563 2724 2775 2799 2757 2976 2967 3056 3213 3238 3400 3513 3671 3661 3775 3826 3954 4007 4228 4164 4285 4288 4394 4530 4547 4594 4555 4537 4559 4566 4376 4329 4341 4110 4085 3890 3801 3786 3482 3458 3300 3196 3071 3061 2902 2797 2752 2710 2615 2496 2445 2523 2442 2314 2371 2312 2274 2275 2258 2261 2233 2262 2190 2212 2179 2135 2183 2213 2168 2271 2218 2169 2194 2187 2163 2227 2228 2265 2251 2257 2261 2196 2204 2259 2305 2240 2356 2334 2334 2413 2466 2404 2418 2533 2416 2536 2543 2394 2477 2555 2482 2509 2417 2428 2489 2413 2472 2440 2476 2366 2479 2394 2338 2307 2284 2242 2238 2205 2196 2105 2192 2176 2116 2171 2172 2195 2082 2071 2109 2191 2209 2026 2142 2076 2079 2016 2154 2138 2158 2224 2122 2163 2160 2146 2195 2172 2167 2081 2129 2133 2169 2070 2156 2169 2129 2213 2155 2256 2157 2235 2171 2222 2184 2078 2168 2201 2168 2190 2182 2191 2165 2165 2127 2127 2176 2138 2173 2169 2105 2179 2113 2119 2094 2112 2028 2157 2184 1981 2153 2117 2084 2062 2108 2054 2060 2094 2108 2153 2061 2036 2064 2214 2140 2070 2025 2094 2153 2081 2132 2057 2139 2133 2082 2043 2052 2132 2155 2104 2147 2073 2139 2134 2144 2101 2020 2075 2084 2026 2032 2036 2185 2118 2078 2085 2025 2084 2090 2037 2161 2064 2056 2022 2089 1990 2044 2047 2040 2053 2038 2062 2022 2086 1985 2063 2045 2108 2156 2135 2130 2137 2143 2108 2163 2000 2122 2115 2027 2116 2125 2007 2073 2129 2053 2011 2051 2096 2078 2138 2127 2112 1997 2113 2097 2105 2130 2108 2039 2089 2101 2127 2073 2140 2088 2140 2104 2110 2134 2191 2164 2122 2159 2251 2234 2295 2263 2264 2286 2373 2445 2381 2521 2463 2471 2534 2429 2563 2562 2514 2677 2651 2684 2675 2723 2677 2622 2642 2601 2602 2560 2470 2509 2472 2397 2420 2371 2259 2385 2304 2226 2274 2251 2250 2265 2340 2177 2265 2141 2166 2104 2221 2237 2150 2115 2122 2175 2143 2090 2165 2180 2165 2177 2110 2059 2096 2086 2114 2207 2208 2202 2071 2174 2166 2173 2167 2108 2133 2263 2323 2342 2326 2278 2189 2233 2248 2378 2308 2319 2411 2324 2394 2377 2304 2358 2423 2373 2331 2358 2353 2325 2306 2342 2254 2261 2235 2265 2173 2260 2179 2111 2274 2135 2171 2215 2085 2149 2119 2113 2069 2090 2092 2098 2100 2203 2198 2091 2177 2067 2069 2118 2219 2107 2132 2151 2093 2085 2117 2121 2143 2157 2093 2118 2158 2150 2126 2168 2042 2110 2170 2125 2146 2085 2143 2137 2206 2123 2126 2157 2082 2106 2089 2132 2142 1988 2098 2131 2190 2143 2061 2096 2084 2128 2093 2049 2084 2062 2114 2062 2079 2050 2073 2107 2123 2085 2045 2057 2070 2170 2068 2058 2080 2122 2128 2065 2064 2071 2121 2059 2038 2161 2067 2076 2150 2076 2152 2187 2112 2151 1985 1988 2040 2096 2137 2083 1998 2135 2087 2084 2164 2062 2104 2028 2089 2126 2123 2177 2025 2171 2192 2175 2106 2109 2118 2125 2198 2212 2179 2166 2267 2300 2204 2248 2268 2276 2373 2270 2488 2481 2478 2584 2705 2714 2807 2854 2892 3023 3131 3258 3142 3250 3314 3404 3363 3444 3410 3469 3518 3515 3486 3514 3447 3404 3427 3335 3239 3142 3071 2896 2980 2815 2740 2775 2771 2709 2604 2553 2522 2477 2402 2402 2407 2250 2342 2265 2294 2228 2173 2149 2233 2240 2165 2114 2112 2103 2145 2148 2132 2107 2152 2085 2148 2116 2161 2111 2146 2142 2155 2121 2195 2040 2117 1990 2163 2139 2109 2146 2142 2058 2149 2099 2195 2164 2162 2120 2112 2147 2090 2087 2186 2209 2056 2202 2101 2086 2158 2220 2249 2237 2217 2214 2230 2240 2241 2398 2376 2264 2431 2553 2610 2631 2772 2741 2868 2899 2928 2918 3042 3054 3185 3240 3271 3337 3411 3399 3413 3519 3452 3473 3291 3416 3326 3149 3091 3116 3117 3010 2938 2931 2813 2809 2672 2661 2597 2504 2552 2484 2434 2407 2369 2307 2307 2325 2279 2227 2145 2144 2256 2146 2183 2221 2109 2181 2124 2290 2222 2153 2204 2296 2248 2239 2232 2344 2287 2292 2287 2264 2312 2314 2391 2403 2380 2313 2294 2288 2320 2277 2301 2314 2309 2292 2204 2174 2135 2230 2129 2102 2089 2107 2091 2132 2037 2138 2075 2073 2133 2152 2070 2097 2070 2154 2096 2115 2167 2069 2025 2088 2071 2056 2157 2113 2108 2028 2148 2082 2121 2135 2117 2070 2083 2239 2166 2106 2158 2135 2147 2060 2134 2235 2223 2161 2085 2109 2065 2169 2159 2069 2059 2117 2060 2141 2112 2037 2141 2103 2088 2097 2029 2087 2130 2033 2094 2009 2164 2046 1974 1996 1974 2039 2045 1994 2078 2079 2061 2055 2043 2035 2064 2135 2031 2117 2111 2068 2131 2101 2067 2090 2032 2045 2117 2057 2042 2064 1996 2113 2112 2132 2095 1992 2057 2027 2051 2024 2178 2085 2036 2018 2090 1988 2071 2062 2087 1946 1972 2042 2038 2154 2060 2029 2085 2100 2123 2077 2020 2063 2026 2088 2073 2078 2124 2082 2088 2120 2089 1981 1995 2104 2122 2063 2063 2102 2013 2064 2090 2087 2077 2081 2024 2035 2114 1986 2035 2104 1998 2059 2070 2016 2113 2126 2012 2080 2022 2051 2055 2086 2067 2017 2080 2078 2079 1997 2080 2039 2106 2073 2038 2008 2123 2100 2067 2030 2065 2072 2050 2018 2001 1975 2080 2079 2055 2086 2066 2052 2085 2032 2033 2073 1978 2107 2059 2006 1998 2075 2058 2047 2072 2010 2106 2100 2144 2044 2148 2051 2040 2073 2032 2047 2068 2172 2038 2110 2107 2171 2096 2184 2097 2153 2177 2130 2098 1998 2142 2164 2084 2149 2132 2238 2153 2031 2224 2229 2151 2188 2184 2144 2171 2170 2292 2172 2164 2253 2229 2135 2181 2235 2090 2139 2061 2160 2190 2166 2143 2192 2104 2123 2204 2049 2187 2141 2161 2102 2171 2117 2247 2133 2173 2216 2150 2293 2260 2257 2210 2289 2262 2263 2220 2323 2273 2296 2337 2334 2332 2253 2201 2246 2304 2268 2291 2247 2231 2202 2151 2215 2270 2236 2138 2187 2161 2202 2149 2049 2127 2154 2067 2127 2131 2137 2054 2114 2116 2115 2117 2099 2068 2148 2060 2073 2057 2041 2082 2027 2077 2135 2073 2073 2058 1963 2088 2162 2043 2033 1977 1987 2120 2056 2069 2063 2050 2101 2126 2015 2043 2149 2063 2045 2064 2011 2104 2104 2052 2121 2137 1988 2092 2138 2188 2064 2012 1988 2162 2166 2147 2086 2091 2085 2066 2093 2161 2163 2128 2161 2159 2098 2165 2090 2174 2220 2218 2219 2248 2122 2155 2233 2109 2180 2088 2103 2076 2106 2077 2167 2096 2120 2163 2090 2126 2108 2040 2055 2093 2036 2066 2037 2096 2028 2020 2126 2151 2076 2114 2065 1998 2090 2062 2090 2083 2062 2074 2051 2124 2016 2082 2145 2094 2159 2090 2083 2089 2099 2142 2142 2096 2118 2161 2094 2085 2097 2137 2064 1997 2110 2122 2074 2107 2139 2172 2157 2153 2135 2095 2158 2148 2131 2150 2241 2216 2307 2229 2240 2253 2338 2381 2330 2377 2292 2311 2322 2393 2378 2341 2381 2354 2431 2388 2429 2397 2363 2357 2336 2376 2369 2342 2336 2248 2321 2189 2285 2184 2152 2176 2188 2173 2207 2219 2171 2281 2133 2149 2182 2236 2064 2056 2072 2122 2111 2103 2101 2068 2059 2169 2072 2121 2179 2156 2041 2100 2147 2096 2127 2151 2018 2078 2024 2153 2060 2110 2097 2101 2092 2054 2125 2110 2143 2127 2125 2123 2184 2108 2189 2235 2236 2262 2134 2252 2243 2318 2356 2297 2424 2382 2435 2502 2487 2624 2596 2541 2530 2564 2642 2717 2760 2566 2661 2651 2780 2674 2711 2771 2660 2822 2645 2676 2601 2636 2669 2515 2621 2641 2600 2529 2599 2575 2670 2479 2469 2594 2603 2536 2537 2479 2538 2414 2507 2556 2570 2677 2758 2689 2800 2812 2944 3008 3143 3114 3287 3352 3393 3533 3709 3819 3938 4178 4174 4397 4450 4526 4708 4961 5108 5371 5520 5539 5841 5911 5882 6142 6112 6179 6488 6400 6501 6699 6610 6626 6787 6646 6576 6343 6494 6413 6061 5993 5958 5854 5591 5495 5375 5137 4936 4840 4844 4611 4501 4421 4197 4057 4024 3746 3617 3585 3379 3373 3242 3134 2967 2962 2899 2848 2718 2708 2648 2476 2574 2591 2448 2564 2528 2438 2472 2376 2376 2272 2336 2337 2335 2319 2200 2155 2226 2183 2244 2124 2194 2242 2149 2198 2235 2217 2094 2154 2184 2127 2114 2234 2132 2139 2179 2134 2089 2235 2156 2125 2116 2120 2103 2135 2156 2158 2135 2114 2154 2103 2041 2117 2158 2189 2150 2163 2112 2128 2183 2057 2068 2078 2142 2031 2121 2086 2043 2090 2059 2125 2046 2184 2109 2214 2061 2137 2075 2174 2078 2154 2124 2165 2097 2128 2163 2137 2194 2221 2099 2097 2101 2185 2080 2253 2073 2206 2188 2138 2145 2148 2181 2223 2238 2217 2193 2272 2171 2198 2259 2280 2184 2247 2161 2282 2185 2229 2198 2207 2345 2177 2093 2112 2196 2241 2235 2228 2195 2131 2152 2123 2099 2161 2101 2173 2124 2115 2157 2066 2128 2088 2144 2169 2175 2170 2146 2117 2065 2125 2100 2122 2169 2049 2032 2044 2048 2079 2079 2096 2139 2092 2190 2110 2084 2096 2041 2088 2093 2065 2100 2123 2147 2080 2077 2013 1998 2014 2056 2016 2086 2049 2108 2131 2116 2068 2021 2044 1998 2102 2018 2034 2068 2133 2012 2043 2013 2008 2090 2069 1998 2043 2021 2122 2024 2031 2039 2064 2061 2068 2039 2131 2005 2107 2113 2126 2156 2049 2120 2154 2010 2053 2077 1992 2058 2037 2118 2088 2094 2068 1997 2114 2124 1984 2027 2088 2125 2089 2120 2152 2001 2077 2108 2037 2131 2154 2173 2140 2135 2132 2201 2132 2255 2154 2136 2269 2204 2323 2201 2153 2067 2191 2180 2209 2156 2127 2247 2127 2211 2142 2096 2198 2101 2097 2139 2261 2114 2126 2112 2150 2070 2055 2140 2174 1997 2112 2050 2059 2138 2105 2071 2074 2052 2081 2061 2014 2028 2063 1995 2124 2041 2111 2092 2025 2094 1993 2013 2090 2037 2025 2036 2094 2025 2106 2030 2084 2053 2050 2023 2051 2120 2059 2098 1965 2083 2023 2063 2098 2071 2022 2044 2045 1978 2031 2051 2075 2074 2120 2012 2012 2157 2004 2120 2053 2097 2099 2157 2092 2070 2127 2065 1971 2105 2045 2083 2069 1992 2032 2037 2059 1959 2019 2049 2062 2090 1964 2026 2040 2021 2126 2085 2069 2053 2033 2087 2081 2039 2058 1976 2109 2110 2108 2153 2028 2124 2036 2047 2048 2098 2067 2085 2031 2044 2105 2138 2108 2062 2056 2092 2193 2106 2044 2135 2049 2141 2067 2115 2101 2147 2103 2158 2139 2127 2144 2161 2162 2205 2119 2171 2045 2195 2076 2115 2124 2190 2124 2129 2157 2057 2096 2108 2151 2102 2085 2058 2140 2131 2085 2071 2154 2056 2135 2171 2146 2066 2170 2060 2048 2209 2122 2134 2079 2160 2198 2102 2114 2120 2162 2140 2110 2150 2086 2174 2147 2113 2138 2211 2078 2162 2220 2224 2191 2110 2242 2187 2184 2130 2149 2177 2222 2196 2155 2270 2138 2189 2219 2194 2301 2240 2242 2243 2318 2278 2392 2419 2412 2473 2415 2450 2490 2495 2576 2494 2612 2548 2565 2493 2546 2648 2600 2594 2629 2558 2608 2582 2604 2514 2477 2498 2519 2380 2395 2392 2428 2301 2375 2412 2364 2381 2264 2328 2351 2324 2252 2256 2209 2283 2153 2175 2217 2106 2124 2130 2152 2056 2140 2191 2039 2106 2090 2075 2168 2114 2136 2146 2197 2120 2205 2119 2080 2167 2113 2220 2038 2099 2067 2032 2087 2028 2182 2052 2173 2142 2141 2131 2215 2275 2215 2242 2157 2171 2220 2105 2134 2316 2197 2129 2176 2097 2247 2275 2207 2182 2222 2152 2173 2250 2269 2161 2271 2223 2135 2102 2179 2161 2179 2159 2192 2248 2207 2165 2130 2221 2112 2028 2087 2156 2143 2101 2129 2152 2158 2158 2175 2220 2215 2237 2231 2275 2290 2329 2345 2419 2373 2497 2428 2365 2476 2620 2488 2548 2550 2602 2510 2580 2530 2612 2636 2545 2604 2587 2705 2682 2624 2603 2518 2510 2446 2521 2567 2455 2463 2386 2505 2469 2363 2358 2322 2365 2315 2371 2263 2258 2189 2234 2167 2104 2241 2196 2147 2105 2109 2115 2158 2071 2079 2052 2105 2107 2048 1992 2038 2132 2095 2011 2060 2076 1981 2086 2032 2048 2097 2048 1999 2028 2038 2054 2052 1997 2017 1945 2123 2102 2039 2049 2069 1988 2046 1971 1960 2103 1985 2049 2022 2100 2014 2039 2022 2053 2109 2058 2108 2028 2032 2021 2083 2026 2044 2077 2078 2158 2090 2060 2058 2032 2091 2052 2051 1963 2063 2072 2187 2012 1977 2067 2142 2058 2011 2054 1935 2075 2109 2068 2121 2065 2084 2062 2031 2109 2118 2087 2139 2158 2169 2197 2106 2197 2167 2153 2122 2180 2194 2134 2229 2138 2136 2085 2137 2062 2167 2201 2100 2234 2111 2140 2048 2149 2136 2159 2114 2046 2167 2125 2126 2153 2193 2124 2199 1999 2101 2098 2108 2151 2213 2171 2151 2119 2213 2098 2152 2197 2261 2206 2175 2159 2177 2198 2152 2197 2242 2225 2216 2429 2215 2265 2246 2237 2274 2221 2243 2172 2192 2175 2240 2209 2153 2240 2252 2150 2212 2269 2224 2229 2254 2244 2220 2169 2254 2259 2239 2216 2200 2291 2255 2225 2295 2136 2302 2211 2238 2247 2245 2237 2295 2213 2219 2171 2240 2058 2086 2167 2142 2105 2141 2203 2128 2200 2178 2199 2194 2144 2161 2144 2236 2105 2132 2053 2151 2126 2172 2105 1975 2038 2013 2039 2072 2001 2098 2056 2056 2100 2009 2074 2065 1990 2107 2014 1970 2092 2050 2026 2119 2042 2035 2088 2099 2131 2163 2102 2010 2102 2042 2055 2104 2116 2079 2126 2063 2080 2051 2073 2036 2024 2049 1997 2033 2079 2126 2208 2071 2104 1957 2106 2043 1987 2126 2133 2042 2113 2070 2036 2008 2017 2065 1988 2040 2034 2001 1990 2046 2113 2081 2117 2143 2093 2062 2087 2076 2052 2110 2113 2098 2115 2085 2073 2138 2142 2219 2115 2104 2224 2093 2201 2135 2091 2087 2040 2030 2097 2069 2135 2168 2021 2172 2132 2144 2088 2155 2114 2167 2131 2174 2147 2118 2162 2199 2120 2107 2181 2268 2210 2214 2262 2134 2165 2228 2137 2197 2234 2303 2229 2266 2257 2235 2300 2272 2226 2300 2221 2243 2380 2366 2218 2340 2276 2317 2258 2186 2284 2294 2293 2239 2238 2266 2340 2245 2305 2234 2285 2272 2353 2223 2319 2327 2373 2360 2406 2463 2524 2619 2522 2628 2608 2577 2766 2795 2779 2760 2874 2788 2898 2970 2954 3007 2974 3011 2915 2978 2930 2889 2937 2933 3060 2975 2967 2948 2959 2923 3118 3091 3133 3254 3215 3166 3461 3435 3419 3561 3570 3527 3642 3554 3643 3690 3663 3658 3727 3577 3584 3605 3500 3471 3458 3473 3405 3368 3283 3357 3198 3294 3158 3141 3048 3126 2963 3123 2986 3020 2908 2956 2852 2819 2753 2802 2773 2759 2622 2509 2466 2506 2549 2471 2462 2410 2470 2397 2336 2344 2311 2413 2451 2478 2395 2428 2401 2361 2470 2430 2434 2465 2398 2411 2427 2434 2411 2539 2401 2377 2434 2428 2413 2372 2307 2254 2318 2285 2377 2207 2312 2325 2237 2201 2307 2281 2217 2231 2304 2213 2177 2179 2151 2221 2267 2129 2169 2116 2114 2064 2109 2165 2054 2137 2232 2004 2038 2097 2125 2088 2060 2216 2093 2131 2089 2003 2031 2149 2059 2163 2107 1973 1991 2171 2056 2004 2119 2144 2053 2111 2065 2084 2019 2016 2043 2081 2093 2002 2116 2007 2022 2012 2126 2092 2072 2030 2041 2054 2029 2065 2061 1956 1996 2011 2042 2074 2047 2009 2051 2093 2069 2057 2079 2073 2037 2094 2078 2029 2079 2053 2106 2042 2045 2104 2058 2054 2022 2041 2129 2107 2111 2061 2021 2109 2169 2160 2094 2100 2180 2110 2189 2156 2109 2029 2119 2000 2139 2153 2179 2059 2066 2024 2097 2076 2192 2135 2051 2071 2194 2067 2114 2066 2076 2084 2084 2074 2087 2074 2082 2061 2024 2105 2073 2023 2084 2091 2053 2099 2042 2083 2035 2120 2041 2038 2064 2085 2095 2097 2040 2067 2073 2089 2067 2070 2076 2053 2084 2008 2096 2092 2116 2039 2157 1948 2038 2157 2095 2203 2081 2208 2089 2159 2254 2050 2136 2160 2117 2134 2204 2137 2012 2160 2157 2144 2067 2125 2069 2089 2117 2100 2110 2129 2095 2129 2172 2172 2181 2192 2067 2054 2141 2147 2142 2112 2029 2093 2134 2166 2134 2132 2139 2031 2202 2076 2051 2093 2009 2145 2098 1992 2093 2064 2089 2080 2024 2099 2110 2103 2045 2022 2012 2125 1964 2003 2134 2021 2167 2141 2177 2131 2118 2186 2170 2209 2148 2181 2173 2165 2221 2141 2141 2258 2151 2244 2230 2140 2244 2227 2307 2243 2357 2306 2320 2339 2432 2359 2487 2464 2479 2507 2611 2651 2600 2684 2725 2830 2602 2910 2902 2911 2870 2842 2937 2903 2888 2941 3047 2920 2975 2918 2891 2890 2851 2815 2839 2840 2779 2871 2927 2772 2709 2775 2768 2751 2773 2731 2662 2710 2686 2587 2658 2600 2511 2560 2474 2349 2373 2423 2362 2269 2340 2401 2272 2307 2337 2245 2223 2422 2162 2177 2263 2244 2239 2185 2235 2166 2190 2068 2039 2145 2125 2117 2086 2228 2166 2148 2188 2110 2033 2072 2196 2108 2109 2026 2018 2159 2096 2074 2079 2016 2135 2149 2003 2129 1973 2076 2093 2031 2035 2124 2042 2088 2054 2206 1998 1996 2012 2054 2066 1989 2080 2137 2030 2056 2078 2070 2089 2022 2068 2100 2008 2044 2045 2069 2067 1991 2058 2172 2047 2015 2076 2055 2155 2089 2009 2012 2035 2058 2028 2153 2138 2004 2137 2094 2069 2063 2087 2055 2069 2162 1985 2025 2157 1966 2043 2051 2035 2084 2046 2007 1998 2057 2048 2066 2032 2077 1996 2015 2093 2025 2048 2054 2056 2050 2097 1995 2061 2034 1967 2040 2045 2050 2087 2016 2098 2010 1996 2021 2098 2147 2119 2206 2038 2062 2048 2129 2069 2111 2052 2122 2094 2057 2087 2051 2055 2074 2061 1976 2029 2022 2023 2019 2127 1995 2045 2077 2033 2104 2072 2029 2033 2033 2064 2048 2029 2017 2066 2138 2161 2066 2046 2105 2032 1981 2053 1957 2033 2019 2053 2043 1977 1955 1965 2013 2001 2144 2042 2042 2031 2110 2032 2023 2038 2046 2098 2104 2042 2081 2049 1987 1973 2073 2098 2196 2050 2140 2053 2109 1993 2215 2068 2141 2047 2091 2059 2099 2066 2089 2106 2144 1987 2076 2091 2080 2084 2070 2108 2101 2053 2037 2062 1967 2055 2123 2106 2175 2126 2167 2154 2168 2219 2203 2141 2204 2278 2219 2312 2316 2327 2341 2410 2433 2366 2424 2430 2436 2424 2393 2409 2477 2326 2514 2375 2323 2340 2454 2249 2235 2272 2286 2276 2224 2231 2324 2263 2240 2212 2301 2318 2257 2316 2325 2300 2192 2218 2277 2301 2329 2224 2257 2187 2278 2226 2182 2200 2241 2223 2223 2172 2247 2222 2217 2243 2184 2222 2238 2171 2097 2030 2207 2171 2201 2142 2205 2151 2071 2079 2046 2044 2149 1997 2142 2147 2158 2074 2077 2183 2185 2114 2067 2143 2014 2129 2178 2019 2072 1973 2084 2027 2103 2129 2031 2016 2076 2099 2057 2050 2049 2035 2039 2010 1985 2022 2059 2103 1996 2032 2160 2045 2028 2034 2000 2093 2107 2032 2086 2065 2091 2111 2011 2035 2067 2085 2077 2121 2045 2018 1983 2110 2143 1961 2069 2094 2113 1994 2035 2130 2022 2024 2093 2141 2066 1983 2050 2084 1975 2069 1986 2052 2070 2006 2060 1968 2120 2053 2018 2077 2142 2091 2138 2067 2044 2082 2102 2039 2160 2061 2099 2008 2088 2044 2019 2068 2046 2119 1968 1992 2023 2070 2030 2030 2092 2016 2146 1995 2000 1994 2033 2030 2008 2026 2092 2035 2110 2030 2060 2095 2064 1960 1964 2046 1949 2047 2072 1993 2014 2061 2128 2111 2029 2061 2092 2133 2104 2079 2013 2019 2006 2003 2023 2065 2076 2011 1937 2001 2064 2057 2043 1940 1977 2165 2028 2004 2012 2092 2068 2029 1988 2086 2002 2032 2054 1967 2116 2016 1985 1983 2084 2093 2130 2032 2049 2029 2122 1995 2037 2088 2090 2050 2003 2066 2014 2025 2032 2100 1979 2138 2099 2115 2107 2066 2045 2087 2040 2037 1963 1997 2100 2065 2029 1996 2036 2077 2039 2032 2055 2035 1967 1954 2058 1981 2041 2031 2032 2105 2157 2060 2048 2011 2036 2020 1986 1973 2074 2022 2057 2001 2141 1964 2115 2030 2071 2052 2044 1985 2002 2091 2044 2056 2040 2098 2035 2073 1975 2044 1981 2025 2035 1984 2123 2067 2014 1998 1992 2027 1989 2023 1984 2109 2045 2058 2053 2142 2077 2019 2002 2103 2098 2073 2047 2026 2086 1995 2024 2068 2067 2064 2103 2058 2130 2062 2093 2083 2021 2070 2147 2153 2079 2118 2062 2174 2117 1967 2092 2049 2025 2058 2146 2110 2071 2031 2104 2069 2186 2064 2158 2152 2085 2117 2114 2036 2126 2108 2142 2055 1998 2123 2164 2125 1999 2058 2080 2104 2011 2121 2093 2060 2094 2111 2014 2130 1990 2045 2059 2043 2067 2079 2098 2090 2043 2043 2012 2026 1962 2080 1980 2010 1974 2055 2034 2042 2061 2032 2046 1978 2039 2026 2006 2050 2109 2045 1976 2017 2026 2096 2025 2100 2076 1997 2059 2015 2020 2003 1957 2041 2066 2004 2071 2016 2036 2020 2073 2008 2028 2063 2073 2047 2034 2021 1954 2064 1964 2047 1997 2064 2062 2031 1997 2076 2074 2184 1992 2021 2029 2018 1981 2064 1999 2033 2107 2012 2033 2046 2079 2075 2077 1984 2011 2068 2009 2067 2021 2129 2049 2026 2120 2037 2021 2136 2068 2066 2059 1923 2024 2101 2082 2070 2043 2091 2091 2018 2093 2029 2020 2043 2089 2005 2079 2021 2063 2123 2080 2109 2108 2002 2072 2110 2093 2065 2096 2190 2024 2140 2157 2116 2102 2114 2054 2053 2035 2165 2127 2098 2141 2086 2086 2068 2004 2060 2146 2029 2107 2169 2067 2055 2064 2104 2069 2040 2140 2058 2098 2061 2121 2083 1990 2091 2054 2050 1920 1969 2026 2082 2032 2105 2071 2118 2051 2008 2020 2052 2002 2093 2099 2034 2041 2063 2085 2057 1996 2064 2095 1992 2000 1967 2017 2060 1994 1996 1983 2071 1983 2044 2050 2047 2084 2061 2119 2104 2073 2074 1972 2084 2007 2080 2045 1978 2058 2018 2079 2037 2003 2013 2045 1995 2026 2020 2061 2095 2002 2027 2095 1987 2037 1979 2033 2081 2060 2126 2117 2035 2087 1996 2040 2056 1992 2067 2184 2040 2121 2110 2123 2083 2062 2048 2130 2059 2069 2100 2042 2099 2100 2115 2123 2060 2194 2111 2064 1988 2159 2056 2104 2009 2132 2098 2026 2122 2096 1977 2065 2013 2035 2037 2056 2106 2085 2119 2051 2056 2115 2104 2052 2112 2160 2130 2057 2091 2054 1996 2055 2048 2041 2082 2062 1997 2055 2043 2122 2057 2052 1946 2102 2056 2014 2104 2012 2085 2119 2002 2010 1966 2052 2124 2109 2058 2057 2131 2139 1973 2128 1979 2112 2114 2096 2097 2112 2100 2057 2129 2132 2136 2129 2002 2080 2136 2178 2184 2106 2046 2071 1971 2105 2055 2106 2096 2041 2060 2124 2025 2051 2107 2136 2089 2115 2108 2109 2042 2143 2071 2055 2039 2098 2042 2063 1992 2069 2003 2116 2013 1944 2039 2072 1973 2013 2023 2095 2070 2016 2070 2023 2029 2059 2021 2107 2037 2046 1950 2024 2069 1979 2178 2139 1949 2078 2076 2031 2008 2034 2061 2047 1970 2019 2071 2029 2064 2076 2023 2077 1977 2008 1977 1978 2087 2129 2101 2000 1975 2091 1976 2112 1977 2030 2009 2000 2092 2093 2038 1996 2018 2100 2024 2068 2058 2077 2091 2069 1934 2062 2046 2118 1994 2061 2163 2054 1959 2048 2044 1956 2106 2075 2107 2081 2083 2035 2109 2035 2089 2097 2026 2021 1894 2037 2079 2167 1976 2036 1981 2062 2053 2042 1963 2059 2074 2017 2055 2014 1945 2031 1994 2033 2059 2004 2082 1989 2038 2019 2020 2091 2052 2080 2094 2057 2060 2030 2009 2040 2089 2081 2109 2060 2110 1977 1990 2131 2039 2138 2071 2080 2041 2111 2044 2137 2013 2121 2054 2043 2046 2130 2043 2058 2073 2093 2112 2154 2092 2039 2149 2076 2075 2130 2061 2057 2120 2033 2146 2106 2197 2062 2170 2082 2028 2032 2049 2110 2057 2088 2141 2084 2134 2147 2072 2127 2075 2170 2099 2131 2064 2133 2167 2171 2088 2226 2070 2084 2070 2098 2102 2159 2199 2135 2110 2072 2105 2138 2149 2204 2147 2108 2095 2131 2093 2147 2105 2191 2198 2178 2069 2160 2185 2069 2104 2090 2172 2112 2072 2114 2122 2092 2077 2170 2090 2064 2130 2146 2108 2101 2019 2113 2087 2073 2072 2140 2018 2177 2022 2100 2101 2079 2064 2047 1932 2159 1997 2049 1988 2152 2085 2114 2133 2041 2072 2180 2122 2150 2147 2085 2247 2232 2163 2184 2205 2211 2193 2263 2204 2224 2248 2217 2226 2170 2256 2254 2162 2219 2224 2207 2204 2153 2212 2162 2203 2172 2186 2140 2158 2220 2179 2076 2125 2145 2099 2224 2214 2239 2179 2198 2198 2246 2254 2228 2149 2102 2173 2193 2179 2137 2083 2133 2166 2117 2199 2185 2117 2063 2157 2184 2123 2111 2152 2195 2099 2168 2177 2152 2110 2311 2251 2153 2280 2251 2216 2330 2347 2353 2440 2421 2451 2488 2605 2552 2511 2624 2544 2698 2783 2691 2556 2769 2673 2665 2700 2726 2708 2652 2552 2573 2623 2613 2620 2473 2550 2527 2386 2426 2625 2474 2459 2397 2373 2431 2405 2404 2477 2359 2483 2523 2449 2435 2411 2475 2416 2426 2362 2322 2298 2392 2361 2312 2303 2283 2264 2214 2236 2194 2161 2153 2209 2123 2240 2132 2169 2063 2113 2069 2055 2122 2079 2031 2031 2101 2026 2084 2074 2106 2144 2044 2003 2036 2144 2113 2036 2042 2017 1996 2028 2051 2144 2026 1998 2035 2074 2113 1997 2124 2064 2170 2147 2043 2036 2094 2110 2043 2038 2041 2090 2041 2133 2010 2058 2098 1990 2126 2009 2005 2006 2123 1958 2080 1986 2007 2072 1992 2034 2111 2079 2104 1925 2119 1975 2016 1955 1988 2098 2114 2022 2043 2152 1970 2066 1964 2015 2026 1944 2006 2071 2134 2062 2070 2059 1991 2090 2033 2056 2054 2077 1980 2033 2023 2062 2002 2042 1952 2103 1951 2089 1984 2094 2044 1966 1981 2023 2136 2072 2081 2013 2019 1991 2120 2047 1950 2001 1937 2068 1983 2022 2063 2077 1996 2046 2032 2083 2042 2066 2073 2066 2069 2032 1952 2108 2048 2075 2046 2024 2024 2089 2062 2003 2029 2016 1976 1969 2011 2061 2063 2010 2029 2078 2036 1948 2032 2064 2024 2010 2049 2075 2058 1968 2101 2047 2115 2137 2065 2012 2100 2006 2083 2096 1996 2048 2048 2057 2020 2021 2046 2108 2051 2036 2000 2040 2099 2053 2087 2093 2101 2119 2037 2083 2049 2060 2008 1940 2084 2163 2031 2022 2063 2092 2028 2059 2042 2054 2069 2104 2123 2035 1980 2106 2128 2057 2083 1940 2022 2000 2119 2071 2107 2104 2153 2042 2054 2064 2126 2086 2105 2126 2127 2148 2119 2093 2139 2146 2165 2174 2212 2167 2208 2220 2075 2121 2121 2185 2156 2187 2229 2179 2229 2129 2207 2147 2120 2130 2114 2135 2098 2089 2068 2177 2084 2094 2117 2132 2110 2047 2004 2048 2144 2076 2125 2069 2150 2100 2134 2086 2107 2096 2165 2143 2035 2034 1975 1946 2077 2016 1990 2109 2007 2044 2034 2021 2111 2007 2044 2068 1921 2049 2036 2071 2032 1973 2062 2052 2041 2014 2045 2086 2041 2061 2023 2028 2093 2074 2098 2066 2060 2142 2033 1996 2018 2097 2046 2015 2061 2043 2047 2056 2073 2109 2162 2021 2025 2076 2112 1992 2040 2009 2001 2127 2059 2097 2039 2171 2112 2077 2133 2117 2074 2192 2068 2212 2204 2178 2105 2177 2149 2190 2190 2158 2128 2264 2139 2132 2125 2089 2110 2173 2188 2067 2065 2087 2131 2124 2187 2169 2138 2164 2189 2201 2147 2204 2141 2189 2058 2100 2102 2146</counts>
			</dataPoints>
		</scan>
	</xrdMeasurement>
</xrdMeasurements>