File: dataset/precursor_mixture/V2O5_0p2012-La(OH)3_0p5004-MnCO3_0p3013--2min.xrdml
<?xml version="1.0"?>
<xrdMeasurements xmlns="http://www.xrdml.com/XRDMeasurement/2.3" xmlns:xsi="http://www.w3.org/2001/XMLSchema-instance" xsi:schemaLocation="http://www.xrdml.com/XRDMeasurement/2.3 http://www.xrdml.com/XRDMeasurement/2.3/XRDMeasurement.xsd" status="Completed" recordIdentifier="{7571A2F1-39C7-4B12-A06C-810CBB5747CE}">
	<comment>
		<entry/>
	</comment>
	<sample type="To be analyzed">
		<id>Dara_redo_4-2min_manual</id>
		<name></name>
		<preparedBy></preparedBy>
	</sample>
	<xrdMeasurement measurementType="Scan" status="Completed" sampleMode="Reflection">
		<usedWavelength intended="K-Alpha 1">
			<kAlpha1 unit="Angstrom">1.5405980</kAlpha1>
			<kAlpha2 unit="Angstrom">1.5444260</kAlpha2>
			<kBeta unit="Angstrom">1.3922500</kBeta>
			<ratioKAlpha2KAlpha1>0.5000</ratioKAlpha2KAlpha1>
		</usedWavelength>
		<incidentBeamPath>
			<radius unit="mm">145.00</radius>
			<xRayTube id="1010048" name="Empyrean Cu LFF HR (9430 033 7310x)">
				<tension unit="kV">40.0</tension>
				<current unit="mA">15.0</current>
				<anodeMaterial>Cu</anodeMaterial>
				<focus type="Line">
					<length unit="mm">12.0</length>
					<width unit="mm">0.4</width>
					<takeOffAngle unit="deg">6.0</takeOffAngle>
				</focus>
			</xRayTube>
			<sollerSlit id="21010002" name="Soller slits 0.04 rad.">
				<opening unit="rad">0.0400</opening>
			</sollerSlit>
			<mask id="22031000" name="Fixed mask 13 mm">
				<width unit="mm">9.00</width>
			</mask>
			<divergenceSlit id="22120001" name="Divergence slit 1°" xsi:type="fixedDivergenceSlitType">
				<distanceToSample unit="mm">50.00</distanceToSample>
				<height unit="mm">1.52</height>
			</divergenceSlit>
		</incidentBeamPath>
		<sampleMovement xsi:type="spinningSampleMovementType">
			<spinnerRevolutionTime unit="seconds">1.0</spinnerRevolutionTime>
		</sampleMovement>
		<diffractedBeamPath>
			<radius unit="mm">145.00</radius>
			<antiScatterSlit id="22090040" name="AS slit 9 mm (PIXcel)" xsi:type="fixedAntiScatterSlitType">
				<height unit="mm">9.00</height>
			</antiScatterSlit>
			<sollerSlit id="21020003" name="Large Soller slits 0.04 rad.">
				<opening unit="rad">0.0400</opening>
			</sollerSlit>
			<filter id="20030001" name="Large beta-filter Nickel">
				<material>Ni</material>
				<thickness unit="mm">0.020</thickness>
			</filter>
			<detector id="7010019" name="PIXcel1D-Medipix3 detector" xsi:type="rtmsDetectorType">
				<phd unit="keV">
					<lowerLevel>4.02</lowerLevel>
					<upperLevel>11.27</upperLevel>
				</phd>
				<mode>Scanning</mode>
				<activeLength unit="deg">5.542</activeLength>
			</detector>
		</diffractedBeamPath>
		<scan appendNumber="0" mode="Continuous" scanAxis="Gonio" status="Completed">
			<header>
				<startTimeStamp>2024-11-29T08:12:41-08:00</startTimeStamp>
				<endTimeStamp>2024-11-29T08:14:45-08:00</endTimeStamp>
				<author>
					<name>AutomatedUser</name>
				</author>
				<source>
					<applicationSoftware version="1.7b (136)">PANalytical Aeris Instrument Suite</applicationSoftware>
					<instrumentControlSoftware version="3.2.00000000 20240306">AERIS</instrumentControlSoftware>
					<instrumentID>950485</instrumentID>
				</source>
			</header>
			<dataPoints>
				<positions axis="2Theta" unit="deg">
					<startPosition>10.02173288</startPosition>
					<endPosition>99.99585608</endPosition>
				</positions>
				<positions axis="Omega" unit="deg">
					<startPosition>5.01086644</startPosition>
					<endPosition>49.99792804</endPosition>
				</positions>
				<commonCountingTime unit="seconds">10.965</commonCountingTime>
				<counts unit="counts">2153 2120 2106 2097 2025 2066 1924 1971 2048 2075 1996 1978 1946 2074 1886 1944 1977 1890 1846 1930 1876 1948 1864 1955 1913 1839 1829 1853 1807 1824 1759 1775 1830 1780 1733 1756 1741 1801 1778 1784 1840 1763 1695 1689 1691 1761 1758 1735 1683 1637 1592 1694 1610 1577 1688 1666 1718 1618 1682 1598 1634 1595 1645 1589 1576 1515 1570 1503 1552 1524 1595 1543 1633 1557 1618 1633 1595 1519 1535 1515 1564 1461 1570 1493 1510 1443 1502 1479 1486 1489 1486 1513 1494 1543 1414 1492 1532 1491 1503 1413 1448 1430 1424 1505 1415 1424 1456 1467 1531 1521 1460 1426 1516 1499 1442 1543 1512 1583 1544 1668 1689 1776 1911 2107 2369 2559 2904 3436 3951 4556 5168 5455 5276 4457 3523 2709 2166 1909 1770 1626 1552 1492 1513 1433 1417 1454 1417 1391 1423 1437 1409 1347 1367 1424 1362 1336 1420 1385 1286 1341 1327 1315 1322 1248 1333 1276 1277 1331 1285 1277 1290 1290 1307 1249 1256 1293 1248 1275 1215 1272 1311 1309 1307 1289 1229 1221 1305 1253 1271 1252 1290 1274 1233 1240 1230 1213 1243 1189 1233 1207 1172 1189 1219 1207 1175 1189 1220 1240 1187 1221 1143 1213 1143 1211 1235 1161 1252 1234 1145 1105 1145 1166 1206 1101 1194 1173 1118 1178 1192 1203 1149 1213 1193 1302 1330 1490 1607 1705 1830 1730 1662 1447 1232 1146 1110 1135 1129 1107 1108 1122 1034 1156 1128 1154 1035 1133 1063 1019 1056 1103 1150 1106 1071 1054 1118 1121 1101 1178 1146 1240 1207 1277 1176 1161 1132 1133 1064 1050 1132 1043 1112 1014 1049 1029 1081 1051 980 1041 1048 1050 1012 978 1006 1046 1056 1050 1026 981 1039 1007 962 989 975 1006 977 1013 989 973 1034 994 1070 1003 1025 999 1035 1042 991 967 991 981 1019 1020 1016 1096 1106 1203 1405 1376 1425 1433 1320 1215 1105 1032 1065 1012 1019 1001 989 960 972 947 923 997 998 921 930 945 928 970 1052 932 907 970 913 927 988 955 928 962 941 1016 932 924 909 916 928 946 942 997 1004 1108 1210 1254 1290 1150 1065 978 932 1024 974 1037 1035 1004 965 1114 1100 1171 1213 1269 1311 1491 1630 1968 2358 2835 3524 4219 4814 4932 4819 3843 3276 2545 2180 1931 1866 1864 1980 2214 2753 3340 4218 5052 5920 6222 5811 5072 3859 2835 2260 1876 1554 1411 1235 1147 1131 1009 1006 1068 1022 934 949 1028 881 919 915 1007 908 896 936 850 924 866 879 883 875 839 836 866 844 849 828 874 858 854 839 839 869 824 796 829 843 856 853 851 814 858 814 889 815 909 861 885 905 877 933 851 871 908 890 1034 1073 1206 1250 1434 1437 1511 1592 1811 2049 2343 2686 2657 2554 2299 2102 2007 2052 1936 1698 1551 1290 1151 1144 953 963 923 881 885 829 820 785 853 880 907 908 936 909 832 816 799 748 781 786 784 780 761 811 785 783 766 755 767 784 776 780 793 730 707 814 735 730 713 736 745 704 743 759 723 715 736 727 782 712 736 748 744 718 808 835 874 895 789 743 746 770 688 709 724 690 747 682 692 707 700 690 692 744 699 692 708 675 711 719 745 696 720 673 720 704 725 754 803 844 817 797 966 1006 1061 1090 1084 1009 967 855 801 733 729 780 709 714 736 726 710 679 725 692 696 662 642 710 737 703 709 726 730 728 692 770 774 880 930 934 1025 993 814 767 814 741 727 692 726 734 700 677 684 684 630 703 668 688 737 691 646 679 728 716 667 705 699 732 735 773 724 734 798 828 853 819 913 964 1097 1226 1434 1667 2095 2538 3252 3912 4313 4512 4196 3593 2877 2383 1938 1546 1333 1194 1012 949 889 886 805 722 737 745 731 745 746 730 682 665 717 661 683 697 667 699 669 675 645 702 721 687 728 715 757 804 876 948 1104 1164 1089 1054 974 857 852 777 815 682 677 730 714 719 809 771 869 944 1072 1112 1252 1267 1344 1273 1214 1138 964 927 830 787 753 685 640 643 659 684 626 653 594 655 646 630 623 693 647 673 589 586 686 595 592 613 532 591 622 632 629 628 653 596 588 629 616 630 606 594 629 614 599 584 594 606 638 621 595 679 595 592 657 594 682 625 635 668 730 810 900 903 916 932 762 782 691 733 647 673 699 676 665 709 659 655 653 620 620 599 631 642 612 586 607 622 565 635 640 581 581 601 579 651 624 641 584 682 621 631 738 729 753 832 842 1013 1066 1203 1244 1226 1173 1101 1046 976 1010 909 855 817 722 759 732 795 810 856 906 989 1004 1138 1184 1371 1563 1671 1935 2080 2206 2197 2202 2310 2334 2466 2646 2997 3406 3654 3667 3543 3160 2768 2405 1927 1638 1391 1303 1121 1022 913 854 785 828 829 743 743 849 802 887 904 857 902 874 948 917 932 1008 1094 1066 987 946 863 778 820 722 658 617 678 622 587 642 613 627 669 621 641 649 635 630 634 579 620 663 668 644 691 813 783 716 813 845 956 941 967 1141 1147 1159 1128 1035 952 881 774 763 692 738 690 717 658 628 679 619 608 609 546 585 538 605 560 606 540 583 591 560 543 561 548 552 532 578 565 540 543 555 594 557 573 565 543 566 611 530 559 534 545 565 587 551 567 533 583 576 596 548 619 573 510 581 582 540 559 540 576 570 587 573 574 624 604 593 666 633 699 644 722 770 805 884 1055 1155 1269 1283 1442 1275 1217 1105 1028 891 858 835 778 702 695 680 708 680 673 686 687 718 817 839 868 997 992 947 976 916 853 789 741 707 695 625 643 593 555 560 545 573 565 566 564 520 549 563 558 560 571 563 606 546 620 598 650 618 652 699 706 774 741 755 723 709 681 661 663 604 598 595 597 579 555 654 598 658 676 673 729 712 760 725 789 748 815 798 801 719 723 715 661 588 663 627 590 587 578 556 548 560 593 567 563 577 525 563 622 683 727 667 673 711 682 668 599 608 610 547 528 508 524 505 532 492 536 548 498 512 520 522 573 547 525 562 564 585 640 593 570 530 560 543 529 519 514 498 533 544 470 528 473 448 493 523 511 591 565 637 647 627 596 536 563 578 567 552 515 515 545 504 527 483 501 485 532 577 544 529 563 546 467 573 513 559 537 634 600 611 617 668 614 742 704 712 772 886 894 1000 1057 1109 1176 1226 1159 1185 1182 1116 1124 975 951 832 728 817 680 695 659 708 629 637 634 653 680 676 732 671 709 766 768 842 847 751 724 783 732 694 609 679 657 643 571 540 556 617 603 606 589 645 637 647 630 646 684 648 665 616 596 598 561 540 556 545 569 552 529 523 563 518 508 476 518 557 514 502 513 496 479 485 483 519 595 580 631 623 646 661 579 638 627 583 557 575 569 548 525 506 529 521 554 538 537 486 552 505 552 545 522 489 534 560 525 513 536 547 501 562 561 581 527 562 560 561 562 664 571 591 595 652 678 782 769 861 919 965 974 1060 1010 971 911 889 866 825 734 709 655 631 626 648 643 629 621 621 627 586 564 591 630 570 645 608 698 691 682 635 671 636 653 647 656 634 606 572 556 537 475 476 510 503 538 552 512 465 485 555 528 528 593 553 564 517 521 547 547 545 544 612 583 551 568 562 543 610 596 572 639 628 552 603 615 615 609 576 553 539 533 514 533 550 514 509 499 516 479 500 502 562 503 522 534 500 493 520 509 546 512 520 531 505 506 473 470 486 539 510 514 597 568 537 539 523 539 493 552 511 567 510 533 484 525 544 510 517 532 491 560 533 520 532 574 576 595 629 652 674 714 780 754 778 823 749 804 789 747 754 758 789 782 776 795 774 778 798 742 740 720 718 743 706 655 772 733 754 809 841 880 944 1026 967 1035 1071 1119 1163 1204 1178 1197 1156 1118 1071 1137 1026 1025 953 901 881 829 773 731 654 691 701 711 677 654 665 670 690 709 686 708 659 658 667 631 603 627 637 561 564 566 549 502 555 544 506 549 504 560 435 564 506 503 523 487 479 522 457 504 516 498 532 512 523 495 518 514 485 506 521 504 508 555 464 499 495 462 479 543 487 523 456 434 467 495 460 522 428 472 501 491 506 513 492 493 518 552 517 509 434 472 499 465 468 509 495 465 532 498 558 588 559 563 627 615 623 690 633 656 675 620 608 633 599 622 612 574 558 541 544 489 493 496 483 479 530 516 475 547 491 462 513 474 478 464 538 498 450 496 462 485 466 442 485 509 527 497 478 521 542 487 522 555 540 520 493 538 528 504 499 496 478 546 550 554 570 581 555 569 512 576 571 561 602 539 505 560 540 515 576 512 478 552 507 567 508 510 540 507 537 536 504 523 511 534 490 469 485 499 468 515 445 445 509 445 449 485 488 518 491 457 475 487 449 481 472 503 461 452 477 480 481 505 507 471 474 531 429 496 521 531 509 534 543 532 563 527 569 545 528 587 595 566 618 561 623 572 651 668 691 698 720 793 791 776 711 754 733 718 657 725 698 586 663 634 616 581 587 579 544 586 535 581 515 542 541 575 592 601 588 620 666 655 619 610 665 671 679 694 683 701 674 715 639 659 618 636 641 661 638 595 675 585 593 620 577 575 604 587 586 543 605 569 548 567 539 553 587 558 558 533 545 556 507 527 517 554 527 507 524 545 544 511 542 519 542 459 505 521 493 515 490 490 551 474 518 494 513 469 458 488 559 529 475 473 508 504 524 437 515 450 511 525 475 489 494 484 454 466 470 449 519 492 465 480 520 520 486 491 482 475 492 509 491 516 507 503 504 467 496 490 481 548 503 521 494 556 487 515 541 576 541 592 620 615 623 632 630 737 699 715 745 797 710 746 684 741 740 760 739 705 703 686 576 623 637 650 598 671 588 661 592 602 618 651 613 693 695 709 682 673 689 670 695 718 702 654 588 641 647 596 557 562 588 520 576 515 510 581 523 472 517 486 480 515 478 507 492 471 515 517 461 454 462 486 519 505 512 524 527 550 510 491 525 509 496 465 494 571 520 466 506 538 480 470 507 459 536 480 475 530 524 464 482 490 513 525 515 531 472 522 475 548</counts>
			</dataPoints>
		</scan>
	</xrdMeasurement>
</xrdMeasurements>