File: dataset/precursor_mixture/V2O5_0p1012-In2O3_0p2008-TiO2_0p7001--8min.xrdml
<?xml version="1.0"?>
<xrdMeasurements xmlns="http://www.xrdml.com/XRDMeasurement/2.3" xmlns:xsi="http://www.w3.org/2001/XMLSchema-instance" xsi:schemaLocation="http://www.xrdml.com/XRDMeasurement/2.3 http://www.xrdml.com/XRDMeasurement/2.3/XRDMeasurement.xsd" status="Completed" recordIdentifier="{9277140A-FCC7-49AE-A7CC-FB7B8499A44C}">
	<comment>
		<entry/>
	</comment>
	<sample type="To be analyzed">
		<id>V2O5_0p1012-In2O3_0p2008-TiO2_0p7001--8min</id>
		<name></name>
		<preparedBy></preparedBy>
	</sample>
	<xrdMeasurement measurementType="Scan" status="Completed" sampleMode="Reflection">
		<usedWavelength intended="K-Alpha 1">
			<kAlpha1 unit="Angstrom">1.5405980</kAlpha1>
			<kAlpha2 unit="Angstrom">1.5444260</kAlpha2>
			<kBeta unit="Angstrom">1.3922500</kBeta>
			<ratioKAlpha2KAlpha1>0.5000</ratioKAlpha2KAlpha1>
		</usedWavelength>
		<incidentBeamPath>
			<radius unit="mm">145.00</radius>
			<xRayTube id="1010048" name="Empyrean Cu LFF HR (9430 033 7310x)">
				<tension unit="kV">40.0</tension>
				<current unit="mA">15.0</current>
				<anodeMaterial>Cu</anodeMaterial>
				<focus type="Line">
					<length unit="mm">12.0</length>
					<width unit="mm">0.4</width>
					<takeOffAngle unit="deg">6.0</takeOffAngle>
				</focus>
			</xRayTube>
			<sollerSlit id="21010002" name="Soller slits 0.04 rad.">
				<opening unit="rad">0.0400</opening>
			</sollerSlit>
			<mask id="22031000" name="Fixed mask 13 mm">
				<width unit="mm">9.00</width>
			</mask>
			<divergenceSlit id="22120001" name="Divergence slit 1°" xsi:type="fixedDivergenceSlitType">
				<distanceToSample unit="mm">50.00</distanceToSample>
				<height unit="mm">1.52</height>
			</divergenceSlit>
		</incidentBeamPath>
		<sampleMovement xsi:type="spinningSampleMovementType">
			<spinnerRevolutionTime unit="seconds">1.0</spinnerRevolutionTime>
		</sampleMovement>
		<diffractedBeamPath>
			<radius unit="mm">145.00</radius>
			<antiScatterSlit id="22090040" name="AS slit 9 mm (PIXcel)" xsi:type="fixedAntiScatterSlitType">
				<height unit="mm">9.00</height>
			</antiScatterSlit>
			<sollerSlit id="21020003" name="Large Soller slits 0.04 rad.">
				<opening unit="rad">0.0400</opening>
			</sollerSlit>
			<filter id="20030001" name="Large beta-filter Nickel">
				<material>Ni</material>
				<thickness unit="mm">0.020</thickness>
			</filter>
			<detector id="7010019" name="PIXcel1D-Medipix3 detector" xsi:type="rtmsDetectorType">
				<phd unit="keV">
					<lowerLevel>4.02</lowerLevel>
					<upperLevel>11.27</upperLevel>
				</phd>
				<mode>Scanning</mode>
				<activeLength unit="deg">5.542</activeLength>
			</detector>
		</diffractedBeamPath>
		<scan appendNumber="0" mode="Continuous" scanAxis="Gonio" status="Completed">
			<header>
				<startTimeStamp>2024-11-14T14:58:48-08:00</startTimeStamp>
				<endTimeStamp>2024-11-14T15:06:55-08:00</endTimeStamp>
				<author>
					<name>AutomatedUser</name>
				</author>
				<source>
					<applicationSoftware version="1.7b (136)">PANalytical Aeris Instrument Suite</applicationSoftware>
					<instrumentControlSoftware version="3.2.00000000 20240306">AERIS</instrumentControlSoftware>
					<instrumentID>950485</instrumentID>
				</source>
			</header>
			<dataPoints>
				<positions axis="2Theta" unit="deg">
					<startPosition>10.00943322</startPosition>
					<endPosition>99.99442286</endPosition>
				</positions>
				<positions axis="Omega" unit="deg">
					<startPosition>5.00471661</startPosition>
					<endPosition>49.99721143</endPosition>
				</positions>
				<commonCountingTime unit="seconds">12.495</commonCountingTime>
				<counts unit="counts">2252 2367 2270 2304 2291 2286 2195 2243 2301 2226 2250 2292 2333 2311 2241 2206 2300 2274 2232 2212 2222 2296 2267 2240 2243 2159 2239 2234 2213 2209 2215 2191 2182 2209 2172 2154 2166 2154 2154 2185 2187 2154 2146 2145 2179 2176 2159 2150 2208 2219 2134 2185 2206 2113 2119 2177 2090 2203 2175 2222 2207 2080 2165 1992 2046 2057 2132 2051 2132 1988 2043 2084 2120 2043 2118 2103 2098 2021 2116 1993 2060 2061 2048 2082 2073 1998 2001 1992 2040 2089 2012 2027 2053 1987 2016 2111 1987 1973 2006 2017 2059 2018 1923 1997 2002 1934 1939 1997 1964 2069 1956 2006 1950 1912 2013 1999 1880 2033 1929 1958 1869 1966 1912 1917 1963 1912 1960 1940 1955 1953 1895 1942 1901 1900 1972 1877 1947 1844 1788 1864 1907 1873 1877 1908 1866 1886 1872 1873 1914 1967 1860 1816 1838 1826 1874 1822 1832 1852 1773 1873 1834 1845 1849 1986 1800 1863 1840 1856 1879 1819 1850 1754 1760 1800 1779 1830 1851 1679 1726 1791 1772 1819 1828 1872 1752 1802 1754 1774 1712 1766 1709 1741 1795 1724 1770 1720 1740 1723 1665 1712 1738 1790 1722 1722 1760 1689 1643 1768 1639 1748 1719 1713 1680 1700 1775 1687 1726 1812 1664 1670 1747 1612 1695 1614 1695 1685 1622 1642 1755 1647 1668 1683 1666 1680 1661 1746 1715 1688 1663 1617 1684 1705 1686 1704 1699 1712 1625 1640 1581 1592 1648 1616 1622 1565 1647 1611 1559 1638 1620 1567 1611 1610 1567 1622 1587 1640 1568 1612 1615 1535 1612 1559 1592 1526 1600 1532 1624 1544 1547 1603 1554 1561 1516 1559 1529 1594 1543 1556 1555 1482 1579 1563 1590 1610 1469 1551 1601 1480 1597 1556 1580 1569 1486 1586 1545 1573 1558 1547 1507 1537 1517 1502 1565 1494 1518 1539 1530 1446 1578 1511 1537 1457 1445 1524 1514 1443 1460 1546 1547 1539 1505 1496 1542 1411 1458 1448 1499 1508 1465 1403 1494 1479 1467 1502 1512 1502 1468 1525 1528 1444 1443 1506 1526 1448 1450 1427 1450 1497 1473 1424 1519 1447 1511 1471 1439 1421 1376 1433 1488 1389 1465 1385 1437 1427 1397 1472 1386 1467 1417 1438 1436 1390 1352 1438 1384 1417 1331 1457 1406 1451 1348 1419 1379 1418 1447 1396 1405 1448 1409 1437 1487 1378 1342 1388 1417 1402 1403 1284 1452 1406 1390 1392 1373 1443 1383 1425 1428 1412 1381 1420 1450 1425 1379 1365 1410 1412 1412 1382 1350 1356 1360 1424 1400 1367 1357 1375 1347 1412 1415 1352 1425 1426 1331 1457 1330 1346 1371 1336 1415 1378 1360 1370 1406 1398 1340 1325 1402 1423 1411 1406 1255 1314 1404 1373 1382 1354 1331 1386 1334 1266 1387 1358 1349 1320 1405 1397 1378 1297 1420 1391 1410 1433 1404 1442 1371 1374 1444 1380 1383 1333 1436 1379 1372 1343 1414 1380 1462 1449 1408 1373 1467 1436 1445 1407 1466 1403 1432 1351 1437 1463 1505 1417 1400 1417 1350 1342 1303 1297 1391 1359 1417 1310 1351 1391 1366 1361 1360 1351 1338 1346 1264 1271 1275 1241 1320 1271 1355 1240 1351 1316 1331 1312 1289 1304 1307 1252 1303 1319 1340 1289 1309 1318 1334 1365 1332 1224 1249 1273 1298 1272 1275 1263 1345 1242 1315 1329 1253 1348 1249 1275 1266 1305 1220 1316 1212 1276 1297 1317 1256 1296 1233 1324 1227 1242 1237 1332 1319 1261 1315 1257 1228 1309 1194 1276 1249 1267 1240 1262 1301 1299 1263 1165 1194 1278 1258 1234 1264 1237 1274 1279 1248 1274 1196 1252 1203 1261 1300 1281 1240 1196 1239 1283 1244 1271 1208 1251 1245 1188 1205 1252 1258 1269 1216 1236 1250 1194 1240 1178 1165 1224 1179 1254 1261 1199 1208 1173 1243 1195 1235 1232 1189 1225 1240 1245 1200 1232 1207 1221 1223 1162 1187 1215 1203 1179 1200 1135 1143 1159 1174 1188 1183 1193 1204 1280 1198 1266 1256 1201 1220 1264 1221 1188 1148 1285 1209 1291 1236 1227 1173 1216 1279 1223 1188 1207 1224 1193 1164 1199 1181 1202 1149 1202 1190 1167 1159 1212 1214 1177 1220 1189 1223 1244 1187 1155 1168 1206 1210 1173 1152 1180 1188 1160 1126 1175 1198 1149 1165 1133 1170 1221 1181 1186 1186 1195 1174 1202 1174 1196 1143 1174 1168 1133 1135 1169 1118 1140 1088 1146 1150 1121 1138 1154 1078 1085 1198 1149 1128 1139 1159 1143 1181 1141 1173 1079 1128 1123 1144 1151 1133 1102 1176 1146 1067 1140 1091 1122 1091 1191 1192 1127 1132 1155 1072 1133 1188 1153 1078 1117 1087 1103 1158 1075 1126 1122 1113 1102 1159 1138 1111 1093 1115 1035 1148 1132 1098 1154 1018 1081 1138 1068 1165 1126 1093 1114 1121 1143 1108 1097 1096 1094 1130 1163 1072 1109 1083 1107 1010 1154 1050 1092 1087 1154 1090 1112 1149 995 1113 1109 1080 989 1059 1101 1079 1052 1103 1099 1080 1092 1087 1075 1117 1052 1025 1064 1114 1061 1073 1064 1121 1063 1035 1085 1097 1043 1110 1062 1095 1056 1121 1069 1029 1044 1083 1066 1033 1032 1033 1040 1066 1030 1063 1064 1039 981 1036 1107 1076 1072 1047 988 1034 1054 1041 1049 1103 1088 1084 1027 1058 1032 1008 1051 1055 1043 1023 1060 971 1010 1090 1011 1121 1062 999 1013 1021 1057 1055 1054 1048 1038 1132 1047 1119 1087 1115 1076 1153 1100 1076 1143 1204 1142 1125 1169 1174 1227 1228 1235 1258 1320 1274 1327 1349 1357 1406 1415 1444 1478 1542 1525 1559 1611 1692 1665 1682 1725 1816 1730 1724 1629 1641 1634 1594 1631 1597 1580 1438 1507 1440 1400 1311 1287 1285 1174 1154 1186 1093 1052 1100 1104 1086 1027 1042 1028 1016 1040 1013 1061 1067 1029 1012 1041 983 1028 979 1094 998 1077 1006 984 973 976 991 1042 991 984 1135 1061 1043 1025 1034 1016 1017 962 1023 990 1018 948 995 1012 981 1007 1013 1019 982 984 1050 1062 979 1004 1030 1035 1042 1062 1035 988 1081 1022 1090 1105 1067 1088 1096 1048 1133 1108 1126 1195 1133 1161 1191 1263 1283 1269 1251 1351 1361 1363 1397 1395 1407 1535 1506 1567 1522 1554 1599 1609 1663 1592 1716 1635 1691 1557 1552 1476 1527 1473 1421 1373 1354 1259 1276 1332 1232 1240 1270 1238 1198 1262 1185 1183 1142 1174 1131 1135 1050 1161 1095 1108 1075 1092 1043 989 1022 1041 951 1005 979 1006 1024 963 1010 943 942 947 946 953 932 953 957 905 953 999 923 966 938 987 931 908 904 950 963 936 930 970 961 935 898 983 1003 993 938 904 915 1000 874 944 869 979 903 888 948 943 914 968 916 929 904 955 927 909 881 878 972 930 997 839 885 912 918 840 896 882 956 903 883 866 921 881 946 928 875 890 953 944 937 931 918 953 959 947 881 890 917 901 958 883 938 878 902 927 895 901 938 897 968 903 853 953 845 909 896 930 899 841 863 905 903 944 882 921 851 929 862 905 900 940 872 938 860 942 902 874 904 877 914 881 880 893 842 849 824 878 851 847 865 836 875 876 832 901 907 839 876 848 862 850 889 862 912 869 885 821 856 853 884 898 862 857 806 874 849 862 900 854 892 914 827 845 857 874 880 860 850 906 949 842 839 835 866 811 857 831 861 869 864 825 836 878 859 888 907 878 839 810 877 859 861 862 796 809 813 863 842 871 900 911 882 844 838 943 826 904 814 852 851 910 912 909 852 866 890 956 935 904 914 905 939 926 908 932 840 897 909 893 934 982 978 956 996 1002 927 1012 979 908 975 871 983 952 960 974 954 973 1063 978 1061 1007 1063 978 1081 1010 1107 1108 1044 1117 1141 1105 1208 1139 1214 1253 1234 1308 1366 1392 1501 1608 1647 1736 1715 1868 1972 2177 2305 2523 2688 2815 3103 3317 3746 4008 4437 4782 5045 5599 6036 6481 6843 7282 7802 8420 8791 9258 9560 9989 10100 10683 10643 10683 10725 10541 10417 10237 9594 9250 8411 7746 7248 6621 5949 5433 4743 4218 3830 3447 3030 2663 2512 2243 1891 1850 1659 1566 1534 1452 1392 1387 1301 1238 1179 1192 1099 1129 1097 1139 1082 1067 1056 1039 931 1038 980 972 995 970 1023 947 1000 951 946 947 902 875 953 1031 933 1018 957 962 996 968 1022 1033 1088 1089 1067 1079 1118 1027 1084 1182 1128 1151 1100 1173 1213 1138 1205 1237 1138 1157 1113 1120 1094 1045 1066 1024 1060 1017 963 949 918 915 849 895 892 870 816 807 899 803 811 801 847 761 830 781 808 803 816 823 838 767 762 803 799 804 817 738 802 833 782 778 749 773 756 803 815 773 822 781 775 792 741 777 823 790 761 760 745 764 828 710 770 804 809 779 752 799 825 805 717 815 716 769 779 770 756 777 745 695 727 779 764 727 738 801 708 759 798 748 761 752 805 777 779 752 756 748 769 742 792 774 782 844 802 822 810 827 853 829 827 817 793 842 811 828 794 872 839 838 861 813 785 762 783 824 788 791 778 761 801 742 786 809 764 757 783 739 688 765 726 693 696 775 729 778 754 725 748 685 738 731 721 728 763 727 719 718 779 738 709 736 750 694 719 772 697 678 730 724 726 732 738 769 710 702 705 693 677 678 703 809 752 727 704 671 726 708 717 713 743 736 712 748 705 699 722 704 704 748 694 722 701 713 727 732 719 696 680 698 728 717 686 709 735 675 710 684 732 749 700 688 713 688 723 680 665 687 719 688 634 657 700 727 656 693 673 682 724 750 674 730 714 696 619 708 680 723 668 643 679 690 675 707 691 644 697 622 675 654 717 730 720 662 709 698 731 701 695 690 711 702 672 688 653 683 677 704 668 679 637 669 723 685 678 688 652 698 674 687 707 693 721 684 692 689 702 707 651 706 661 675 713 701 687 735 628 702 715 738 737 690 701 691 653 733 746 720 701 756 777 735 712 751 713 701 708 768 715 734 738 746 716 744 779 719 706 781 711 774 790 752 806 728 819 847 786 770 778 779 793 815 819 864 751 870 787 830 903 884 827 847 897 874 937 984 969 1021 987 1036 1053 1102 1165 1268 1191 1226 1323 1476 1526 1677 1673 1871 2054 2191 2379 2613 2877 3142 3452 3698 3990 4394 4553 5048 5473 5829 6061 6428 6777 7084 7362 7536 7745 8073 8039 8001 7704 7328 7113 6492 5883 5653 5369 4866 4404 3904 3505 3099 2884 2538 2333 2069 1924 1701 1624 1481 1456 1376 1295 1379 1327 1239 1306 1230 1221 1279 1237 1230 1215 1159 1243 1223 1269 1268 1182 1224 1149 1111 1159 1080 1010 1068 1023 997 998 946 932 906 878 854 770 801 750 842 707 780 730 784 699 682 720 757 665 667 667 667 662 674 718 701 665 675 671 625 676 676 663 688 656 693 627 682 653 646 654 651 636 668 674 670 678 629 682 673 648 677 681 674 688 668 637 631 621 676 626 616 629 701 621 677 627 671 628 645 668 631 669 645 697 662 612 646 626 665 632 636 603 688 637 663 649 634 630 626 607 636 695 665 646 666 691 694 683 691 743 669 706 700 696 690 727 743 733 747 773 753 755 746 786 822 782 803 781 744 832 771 753 696 731 698 694 699 678 663 635 632 619 660 617 638 617 659 634 619 570 573 611 617 611 571 580 626 609 633 580 606 566 613 610 584 660 596 577 606 589 565 622 579 639 603 648 619 659 655 673 661 643 661 625 663 678 685 687 666 663 711 677 665 646 676 654 649 659 693 680 652 650 658 695 670 631 701 646 629 673 642 644 661 609 652 626 624 622 599 621 589 628 645 563 613 578 610 606 592 599 586 612 602 558 626 582 573 542 586 579 550 576 577 554 564 615 595 538 577 595 585 632 578 577 556 597 567 592 549 576 584 586 588 536 551 558 585 529 631 525 574 612 584 565 568 605 574 564 568 559 610 563 617 553 591 627 580 641 615 644 672 640 679 686 693 675 686 741 709 684 739 723 742 666 720 683 686 722 674 715 666 651 646 682 624 653 611 556 602 586 584 607 600 589 566 627 597 576 554 580 563 547 593 575 557 612 529 556 557 582 538 587 573 545 568 562 548 588 580 598 569 597 596 575 573 578 549 627 576 658 567 615 582 572 620 611 546 583 621 600 590 641 599 667 638 688 631 678 726 690 712 756 773 753 803 872 937 958 1026 1086 1132 1206 1295 1338 1494 1582 1777 1825 1894 2122 2239 2271 2355 2503 2592 2609 2804 2680 2850 2754 2691 2532 2461 2318 2271 2219 2024 1899 1807 1670 1536 1323 1231 1161 1050 1054 993 865 850 855 719 723 680 676 665 649 650 631 642 672 653 597 650 617 599 582 610 585 557 548 571 608 563 615 558 568 610 586 576 587 521 617 589 594 605 555 564 566 552 555 566 571 574 562 563 521 565 551 557 574 563 562 585 530 571 511 522 527 570 520 521 531 499 509 535 552 494 526 516 523 534 562 532 571 530 566 568 507 546 567 565 560 587 556 587 557 614 588 579 608 541 597 605 614 692 672 657 690 677 746 717 744 773 904 880 932 974 990 1050 1019 1145 1116 1188 1174 1241 1230 1184 1232 1147 1081 1136 1104 979 1005 903 957 911 861 847 779 729 736 693 707 683 657 664 617 617 650 603 581 606 598 587 649 580 598 576 611 629 627 650 599 661 661 663 678 615 698 684 725 753 796 816 825 859 866 957 964 1058 1095 1176 1286 1285 1425 1542 1613 1754 1923 2003 2210 2254 2399 2559 2709 2784 2962 2998 3143 3088 3265 3224 3212 3124 3181 3011 2834 2788 2577 2408 2319 2129 1986 1900 1694 1545 1443 1314 1229 1048 1006 885 906 850 827 774 732 709 690 704 635 621 626 594 616 637 646 571 605 625 566 589 559 598 573 616 546 600 589 576 637 586 645 663 668 700 688 692 761 749 825 850 879 954 938 1034 1085 1152 1147 1228 1268 1249 1268 1317 1297 1295 1138 1239 1196 1148 1036 1057 959 926 962 850 846 833 763 665 727 669 636 630 586 560 567 561 528 527 553 547 487 504 482 505 518 511 522 502 507 494 490 512 468 482 457 482 520 496 460 505 502 493 528 521 482 473 500 450 475 448 469 457 444 435 487 466 493 436 479 421 466 480 471 474 490 490 472 508 438 469 479 458 504 450 451 454 508 517 482 491 460 447 503 463 496 486 506 480 508 426 486 500 489 462 514 506 523 516 497 573 560 509 559 557 538 596 551 571 558 548 540 535 535 515 520 502 493 511 516 509 443 503 497 459 426 503 413 484 447 436 439 481 440 476 445 436 506 467 429 470 488 452 457 502 448 491 438 446 464 485 449 445 430 466 447 426 455 453 434 428 478 472 426 466 430 454 445 405 434 424 431 477 454 484 454 471 433 479 466 480 423 452 474 423 487 450 407 443 505 433 436 459 425 433 426 468 471 454 455 414 490 454 444 456 424 408 497 447 497 460 483 459 464 486 496 503 473 461 468 459 459 463 518 501 489 493 525 544 481 575 561 522 569 530 574 594 621 557 557 574 613 593 588 616 564 590 565 561 563 546 520 563 517 567 524 479 469 478 512 499 513 515 492 470 494 488 469 451 448 475 452 506 473 501 491 500 564 513 588 560 590 625 649 686 680 683 746 775 759 757 802 872 830 875 805 789 813 730 728 778 733 686 697 701 663 637 656 629 603 613 554 564 521 574 525 543 482 496 519 477 495 492 503 469 467 488 500 492 475 439 462 484 430 449 440 439 414 442 431 448 375 441 426 446 424 442 421 417 466 403 454 410 433 449 423 412 443 444 400 421 406 417 437 417 421 401 407 405 405 391 439 405 413 411 397 414 407 409 427 410 400 408 398 410 401 384 450 371 434 411 447 413 443 423 436 392 449 400 403 407 416 357 430 433 416 415 428 369 410 436 429 442 439 422 418 453 448 394 386 392 416 393 434 390 414 417 393 450 433 410 412 349 414 419 412 412 437 422 442 403 445 410 404 399 449 438 397 429 409 439 463 436 402 460 407 426 370 415 442 420 450 420 475 447 447 443 461 474 442 461 495 492 476 511 524 470 492 451 475 402 446 473 492 471 449 473 458 380 455 433 485 394 426 385 448 425 384 407 426 410 416 445 377 403 433 435 396 427 421 402 386 414 422 405 406 411 397 424 442 425 413 388 383 400 405 392 422 436 407 415 406 372 399 376 382 379 414 428 406 367 406 391 393 387 372 379 383 386 393 421 419 412 437 400 420 380 408 399 399 433 410 366 385 395 410 411 416 374 393 371 398 395 354 383 379 424 367 403 391 413 356 404 416 370 429 386 416 404 399 432 416 398 418 432 441 412 394 421 421 466 394 452 449 417 458 446 431 440 476 424 442 452 425 471 443 482 485 509 473 521 526 543 599 572 538 564 609 568 574 616 714 694 677 721 800 785 796 873 851 919 1013 1049 1037 1086 1059 1096 1120 1080 1062 1046 998 925 929 913 795 849 806 796 809 687 700 638 645 613 574 511 535 518 503 474 462 478 470 443 436 447 435 442 460 457 413 379 360 436 400 420 363 412 396 424 417 390 406 406 392 373 435 394 377 410 384 393 412 408 399 422 433 374 435 389 371 442 368 397 416 411 386 411 387 399 448 406 417 400 413 393 425 415 390 443 383 420 415 429 382 388 371 382 410 373 386 378 423 431 419 371 442 434 394 422 376 414 402 438 423 405 397 429 420 402 439 428 436 394 393 383 368 421 413 373 414 375 393 438 392 417 433 461 407 436 448 389 420 428 422 433 467 486 408 503 487 532 486 517 545 530 545 513 590 522 578 565 557 547 553 513 566 524 533 510 500 520 514 524 497 515 504 436 471 486 495 520 556 572 513 548 482 573 564 576 538 575 606 619 628 667 691 735 728 799 807 884 913 991 1110 1131 1279 1390 1546 1650 1920 1966 2229 2495 2677 2948 3133 3315 3453 3760 3966 4100 4146 4099 4141 4020 3749 3652 3447 3402 3254 3086 2946 2813 2641 2500 2272 2018 1843 1658 1433 1369 1245 1135 1014 944 839 802 665 678 629 647 601 556 578 483 529 560 529 502 467 509 466 500 488 467 466 457 435 483 468 427 459 436 424 421 465 454 428 441 410 441 435 433 464 438 496 464 483 514 455 447 438 444 479 506 486 490 493 472 469 461 459 459 483 436 472 464 437 467 456 421 419 468 456 432 407 413 412 435 444 479 429 446 476 502 517 469 522 521 511 587 539 623 543 680 613 597 622 595 600 574 562 544 557 534 565 473 529 537 506 531 507 490 453 452 481 437 454 396 458 447 440 416 417 402 471 396 410 403 398 413 409 448 402 411 386 455 374 429 397 357 416 403 414 391 388 376 443 378 399 390 379 405 417 391 394 393 379 391 392 423 397 390 391 413 331 380 406 406 420 390 422 385 380 391 365 418 406 406 394 416 443 431 410 409 391 446 375 415 394 389 394 438 390 395 418 473 406 405 407 433 434 447 404 441 417 419 465 421 492 448 448 506 455 490 424 460 466 479 497 514 514 470 499 503 574 558 566 598 615 654 724 709 741 733 800 811 868 929 1093 1150 1206 1286 1517 1572 1814 1914 2167 2328 2520 2716 2900 3066 3269 3343 3338 3319 3288 3133 3033 2784 2621 2678 2586 2439 2496 2340 2197 2182 2022 1938 1814 1638 1549 1306 1238 1126 1044 945 871 838 825 754 670 665 664 704 608 599 566 549 571 531 554 492 496 500 467 558 509 467 402 413 465 472 456 423 442 449 477 376 450 399 436 418 415 361 377 419 416 399 394 402 396 397 409 366 401 417 414 399 438 413 412 445 418 426 422 437 433 426 422 417 446 432 438 446 506 452 458 445 455 461 454 443 432 436 403 383 408 464 411 455 412 429 387 436 419 435 380 384 414 366 374 389 395 398 389 369 369 393 387 380 381 391 411 434 455 434 381 440 381 425 373 413 420 447 444 443 472 454 479 461 520 462 522 537 554 535 512 574 554 565 517 539 487 509 521 493 468 502 491 463 502 484 424 431 442 391 410 452 426 407 381 395 366 405 418 404 406 383 395 380 384 375 398 365 377 370 382 381 383 416 378 417 343 398 356 405 361 415 434 418 398 410 415 397 389 414 396 404 412 385 462 431 431 416 426 420 426 392 436 418 457 473 462 477 476 521 481 535 493 508 528 533 536 621 590 679 668 705 784 895 865 1060 1095 1113 1259 1412 1469 1644 1724 1900 2032 2209 2307 2457 2544 2667 2686 2668 2688 2640 2493 2274 2218 2088 2000 2006 1994 1941 1903 1747 1664 1620 1492 1316 1305 1174 1050 996 906 819 823 728 750 686 656 564 577 573 545 542 523 551 516 544 575 552 551 527 502 513 531 522 496 484 502 496 483 467 448 455 409 475 450 449 436 484 432 454 427 440 428 446 457 444 434 459 441 468 480 454 501 435 456 450 475 508 462 481 550 558 587 587 670 618 641 662 702 810 783 843 993 1057 1124 1273 1431 1519 1625 1873 1955 2128 2242 2308 2484 2479 2552 2539 2475 2478 2336 2289 2234 2078 2035 1942 1896 1871 1794 1758 1550 1542 1462 1385 1232 1209 1096 1001 856 859 768 701 674 660 580 539 535 541 502 555 461 489 452 456 482 434 488 414 445 420 464 467 471 484 468 463 479 432 460 482 512 466 445 481 458 436 484 466 437 456 466 444 505 488 472 506 500 524 561 560 552 580 633 629 684 698 700 678 748 752 742 789 738 768 754 684 654 637 669 631 621 580 617 596 581 571 553 508 540 445 513 441 455 424 462 458 420 389 390 430 411 382 411 380 364 398 384 411 369 397 372 377 366 375 396 350 388 373 334 313 370 368 345 377 371 368 363 363 360 325 383 347 324 375 351 361 349 317 332 360 365 328 347 304 340 335 398 351 345 355 343 368 374 321 377 335 324 329 305 349 335 331 356 332 342 358 347 362 335 373 365 344 312 372 329 339 339 362 368 377 339 350 373 346 324 332 325 347 346 322 333 336 335 331 345 349 323 346 326 341 357 374 382 388 380 376 404 380 404 386 418 442 448 417 405 415 443 411 422 438 402 448 398 369 387 376 385 386 418 399 377 389 392 365 405 387 361 385 363 354 366 354 318 348 331 342 337 345 329 352 343 361 326 370 325 345 351 304 359 344 350 330 325 339 366 379 351 348 365 352 331 356 321 369 377 343 334 360 358 321 323 321 334 364 365 365 341 341 353 339 370 334 350 374 392 384 356 356 373 412 371 403 343 353 361 421 380 351 349 381 383 348 380 391 342 370 332 376 364 388 390 362 398 363 382 369 360 367 373 399 347 396 416 430 377 380 407 385 437 392 396 405 456 464 461 474 445 487 471 582 585 571 612 595 603 639 654 663 710 683 701 675 716 715 662 625 569 599 601 603 534 577 560 533 484 516 525 550 509 477 437 444 405 408 420 381 416 373 333 369 376 358 403 353 376 371 341 337 343 378 362 374 320 328 392 358 356 382 355 385 373 348 359 367 354 358 339 375 366 336 348 341 387 337 352 317 356 358 369 359 371 361 360 326 356 363 374 359 361 372 370 372 394 402 407 391 412 359 398 395 377 380 380 395 394 420 382 424 469 463 377 448 425 438 473 455 450 473 427 484 437 499 466 526 493 493 513 512 543 567 606 710 651 733 756 783 853 927 985 1059 1196 1318 1449 1543 1768 1835 2045 2114 2312 2373 2479 2404 2350 2263 2165 2011 1955 1816 1800 1660 1606 1671 1612 1601 1543 1584 1503 1495 1375 1322 1242 1121 987 935 900 768 769 735 649 614 585 580 551 581 512 525 557 506 484 520 486 477 465 437 481 484 492 467 456 399 459 452 433 414 392 373 405 396 407 448 408 407 414 415 339 410 381 406 399 355 396 385 356 392 382 341 370 386 369 362 344 382 344 390 368 384 379 390 368 344 402 355 416 386 412 354 354 366 398 361 398 382 360 394 395 397 399 364 391 428 430 426 407 428 429 492 468 476 482 490 519 555 560 638 649 719 737 809 820 899 910 973 1016 1097 1101 1164 1139 1135 1148 1133 1183 1129 1139 1003 1111 996 998 904 913 932 974 883 901 925 841 837 783 786 689 713 713 662 652 634 621 637 607 639 636 681 631 705 759 773 889 951 1011 1066 1230 1364 1436 1547 1625 1833 1876 1900 2019 1988 2113 1961 1952 1755 1755 1702 1546 1499 1434 1449 1391 1367 1273 1339 1323 1333 1344 1262 1137 1025 992 945 854 743 731 637 614 608 503 554 465 478 454 442 407 398 401 422 417 419 391 395 393 368 356 385 367 335 322 392 349 381 375 388 330 372 379 371 368 398 333 371 357 355 416 365 372 365 401 399 393 388 377 417 415 450 428 442 504 512 542 584 602 585 617 617 621 689 691 714 658 658 693 687 659 633 584 610 583 574 570 547 556 536 554 551 516 499 503 493 428 467 415 445 373 410 390 367 363 376 329 345 368 325 345 332 329 338 345 378 315 361 343 325 344 319 337 328 344 348 311 376 341 359 316 329 329 343 359 342 336 339 359 386 346 361 319 311 332 346 364 386 322 322 358 354 297 359 306 378 348 346 353 304 346 329 343 349 346 328 335 333 344 381 314 327 316 306 310 349 316 333 340 300 316 323 349 312 318 304 311 310 360 353 299 338 338 346 357 353 361 326 425 398 383 377 381 410 395 398 460 469 480 453 473 514 501 392 456 420 422 452 386 416 415 419 401 404 387 414 382 391 390 413 401 330 355 376 331 355 363 364 341 355 340 353 307 325 327 309 301 305 323 323 336 294 363 307 291 275 343 313 319 324 321 318 323 290 315 339 337 306 303 321 332 291 321 311 341 291 287 325 280 310 312 309 335 303 326 340 327 299 334 318 286 346 314 323 340 306 376 345 338 351 317 323 352 323 312 337 303 352 326 346 341 342 324 312 306 299 311 284 327 344 337 318 334 339 324 300 367 328 319 327 330 324 316 348 324 383 369 367 391 345 389 407 414 399 377 405 390 372 404 367 375 366 381 353 377 383 351 367 347 381 340 362 379 360 328 326 342 343 307 334 308 331 334 331 318 341 299 317 293 340 321 301 340 264 284 303 290 286 320 296 321 298 281 312 306 287 316 304 291 308 302 284 300 259 299 286 297 322 294 299 324 297 316 286 322 258 339 314 305 305 291 323 319 307 308 307 304 302 285 318 347 323 302 296 310 358 314 311 327 318 307 318 320 350 320 320 326 306 329 338 326 335 340 358 339 351 325 327 335 316 360 353 341 400 397 412 436 448 439 422 426 480 508 522 499 498 513 562 526 522 541 470 464 504 430 495 444 422 440 444 407 440 432 442 435 485 459 427 411 420 412 370 410 374 389 361 394 362 343 360 353 343 354 416 393 399 363 392 395 388 391 396 435 413 430 445 441 438 508 507 561 582 571 600 639 694 776 834 859 919 983 1018 1050 1053 1041 999 935 934 925 958 844 871 861 739 759 708 725 745 727 690 711 767 687 752 661 689 609 555 574 554 511 501 436 479 402 425 408 403 427 348 361 373 365 346 364 353 359 333 340 331 323 321 340 332 364 368 345 372 393 387 381 380 418 380 457 422 438 422 481 437 402 450 407 441 393 400 400 429 417 377 393 369 432 389 423 393 387 372 405 371 365 405 358 355 346 355 370 358 361 369 332 360 356 365 354 337 335 325 405 353 344 383 376 336 430 356 388 359 402 392 358 366 353 389 408 407 420 432 421 485 488 519 596 613 655 603 745 864 866 928 1010 1018 1095 1152 1155 1118 1118 1103 1023 967 909 915 870 819 802 775 777 752 755 781 754 721 783 757 746 776 699 631 603 573 570 492 494 435 452 423 393 379 391 368 356 315 325 316 327 369 333 320 291 339 324 304 318 294 332 309 315 306 292 307 320 304 320 309 308 308 286 282 266 281 296 303 294 289 303 332 281 301 273 290 272 245 282 297 274 285 301 290 284 298 281 249 307 306 297 283 267 272 300 275 281 273 285 302 293 318 297 322 258 290 280 302 279 267 242 268 257 279 286 296 287 266 297 273 308 279 283 276 278 325 289 324 300 325 311 338 309 295 295 278 314 292 328 307 313 308 333 304 302 285 293 307 343 313 312 283 289 323 305 300 301 304 294 297 282 286 307 305 328 305 273 302 294 298 347 273 313 284 291 307 306 317 283 268 334 303 329 309 359 321 315 306 337 357 302 312 281 322 313 290 336 297 307 294 317 317 309 342 334 336 321 323 305 326 302 328 300 325 318 308 305 322 350 336 346 304 344 280 326 312 334 325 301 308 302 328 298 329 300 306 316 308 314 324 279 270 329 275 314 290 272 328 299 265 295 296 267 289 270 296 277 281 295 261 282 285 289 306 272 268 268 276 251 258 307 303 304 302 277 302 291 294 304 293 316 324 309 296 305 292 315 291 281 312 295 283 325 315 339 313 302 319 344 357 324 367 402 377 386 408 426 412 474 456 465 497 421 423 457 420 421 391 401 368 346 358 385 360 362 396 391 370 355 373 394 368 392 358 372 366 409 386 351 357 358 346 372 336 381 388 364 362 357 369 341 362 355 346 352 360 354 342 314 346 336 334 322 292 354 361 356 337 343 373 310 310 293 363 297 316 343 372 317 348 332 363 360 369 332 324 404 396 361 418 352 345 383 361 429 359 416 380 363 359 379 397 394 377 388 381 398 399 402 436 408 425 456 403 468 464 439 429 474 502 538 559 521 616 706 848 840 882 950 1044 1129 1280 1386 1513 1612 1675 1677 1798 1729 1831 1582 1611 1455 1336 1334 1217 1204 1115 1037 1053 981 1016 975 1081 1014 1131 1079 1036 1126 1138 1055 963 899 853 818 745 691 601 583 501 490 484 520 415 422 411 421 373 389 379 362 366 361 340 325 344 311 321 347 311 294 325 317 342 327 329 298 312 333 335 335 348 313 335 334 345 352 336 352 348 369 352 385 395 381 419 407 457 398 449 544 511 548 570 554 631 640 692 707 664 669 590 597 595 597 547 558 480 493 465 491 459 481 499 522 481 525 523 527 491 551 578 511 583 578 528 564 555 554 576 596 613 568 582 560 548 466 508 488 458 441 426 424 403 425 379 443 385 453 414 441 440 444 429 410 383 405 416 354 412 344 343 351 326 341 328 287 353 315 297 316 300 324 311 282 287 291 317 325 290 314 273 275 299 276 280 294 288 280 290 287 280 281 285 289 285 274 281 294 303 267 280 289 301 294 281 310 265 291 289 249 285 277 291 302 276 274 291 269 283 310 281 304 302 274 294 271 290 273 289 300 266 307 299 290 325 283 290 328 285 313 313 309 300 296 301 304 337 342 368 382 374 360 374 388 400 424 407 421 415 425 423 385 370 393 387 365 368 337 330 362 320 331 354 341 363 344 359 353 366 342 387 345 385 332 322 336 353 323 337 291 339 348 300 311 309 287 303 298 295 309 287 292 282 293 312 300 283 300 328 291 297 296 301 291 287 289 286 275 300 298 305 266 292 309 290 279 275 314 247 272 304 265 267 268 308 285 299 262 277 263 243 286 247 272 285 282 284 271 263 248 293 276 273 284 302 280 265 278 275 304 292 309 304 282 285 288 270 281 314 310 336 317 327 373 335 372 382 384 387 378 396 399 402 401 393 390 396 370 372 359 316 356 323 324 342 355 351 317 354 332 356 356 362 380 352 362 329 316 343 308 309 311 293 276 320 302 296 298 322 283 298 284 301 283 266 272 263 250 277 265 244 280 273 258 269 248 265 300 259 289 324 275 266 276 278 274 275 303 296 280 279 299 276 293 300 266 264 296 276 267 271 290 261 309 270 289 269 309 273 277 298 298 272 238 258 264 295 297 288 278 275 315 272 281 318 289 312 277 262 262 295 258 286 283 305 338 323 320 348 350 340 377 358 361 334 352 410 375 366 331 367 342 376 314 347 353 325 347 360 350 342 324 396 367 397 356 388 312 387 333 401 353 365 367 327 314 370 283 308 330 312 330 320 319 329 313 315 300 269 304 298 295 312 274 345 315 313 297 276 288 312 257 291 257 256 269 295 264 256 299 288 292 295 266 309 289 284 313 274 259 309 270 298 240 271 316 267 296 270 268 309 320 296 290 309 284 299 274 278 278 324 274 302 300 317 264 273 309 286 338 292 337 305 345 314 332 378 331 413 397 422 390 407 406 461 417 466 500 480 495 494 517 451 476 468 430 426 373 429 366 366 388 382 375 408 390 394 422 425 458 391 466 443 422 433 491 461 445 458 439 451 414 421 395 387 427 367 427 365 372 384 360 370 339 371 338 361 344 332 373 365 323 329 341 332 398 409 390 391 399 406 417 442 476 481 486 489 500 524 608 658 676 739 803 769 859 864 919 928 924 910 853 853 790 816 688 715 680 614 594 618 578 586 585 647 592 656 607 646 654 695 684 680 725 711 678 728 621 725 701 654 712 696 683 762 824 851 853 887 943 1083 1033 1086 1028 998 944 924 818 779 712 720 691 691 633 607 625 636 590 621 710 580 648 681 636 672 639 631 659 606 600 568 566 480 503 492 486 379 401 372 359 354 383 355 327 308 319 294 325 262 272 269 311 339 284 303 308 275 287 293 309 295 304 286 295 284 314 281 266 291 287 274 269 273 298 288 294 248 319 247 274 241 280 283 278 262 271 270 261 277 299 239 281 269 275 285 269 274 269 264 283 297 284 265 278 256 263 282 274 250 279 263 272 256 276 284 285 289 240 275 276 244 240 296 282 280 286 296 297 260 263 277 259 285 230 272 274 304 276 281 277 293 258 280 238 260 246 257 261 259 293 274 284 293 274 243 299 269 262 272 268 258 248 260 264 244 278 297 266 238 260 268 231 270 275 288 290 239 302 303 279 263 269 288 256 272 238 238 270 261 265 236 278 260 260 275 281 294 248 270 260 257 293 265 262 275 287 284 272 278 257 280 259 309 287 333 313 300 293 280 297 247 309 297 293 289 341 304 301 330 325 315 307 354 395 387 380 364 418 400 471 448 497 576 526 569 578 576 650 593 632 566 554 506 468 436 476 425 411 415 402 367 438 426 360 383 414 467 426 450 422 441 414 457 478 433 437 392 381 355 375 327 341 326 301 325 328 319 268 299 247 335 271 282 306 315 281 234 265 270 268 271 241 300 264 276 239 287 298 281 265 234 283 245 292 235 303 266 263 296 282 289 279 282 286 248 260 284 264 288 272 282 286 277 249 297 274 305 281 277 282 263 289 264 269 279 265 271 240 261 299 247 305 266 276 272 266 287 295 299 250 299 304 333 290 324 308 368 302 361 304 331 323 311 317 319 323 303 315 289 283 268 262 283 293 286 260 288 269 263 283 290 269 312 270 290 275 297 302 297 265 284 282 244 260 261 285 222 267 269 267 231 246 298 249 262 238 276 269 284 264 291 245 245 272 243 273 280 286 265 242 225 250 260 270 265 238 242 262 271 264 259 223 283 262 256 249 266 268 260 261 265 250 275 249 262 248 269 257 246 293 273 259 278 246 272 273 266 274 284 247 272 288 267 247 259 223 264 277 292 274 306 279 304 287 283 326 341 294 347 332 337 315 348 351 351 348 336 327 381 315 300 287 287 267 307 321 287 281 320 298 289 300 279 297 290 305 311 275 311 293 297 297 280 291 271 305 283 260 263 277 246 291 274 265 275 234 285 268 278 299 256 266 273 274 267 265 258 272 274 256 239 250 283 246 273 245 244 285 247 247 266 237 246 245 295 277 230 277 260 244 244 282 267 278 258 242 261 261 282 243 269 280 276 293 266 259 243 272 265 281 266 277 266 287 269 304 304 281 282 317 306 329 324 303 326 313 379 297 403 352 397 403 436 384 438 440 412 386 378 397 378 358 347 316 327 362 316 346 317 326 316 326 345 337 350 330 370 319 364 349 345 356 335 366 340 327 326 297 267 290 297 270 245 281 283 300 237 264 283 294 304 247 235 263 226 250 268 269 246 280 263 275 256 256 272 270 268 273 235 277 261 249 273 247 268 276 247 277 273 284 271 265 267 246 259 273 245 267 224 295 268 260 276 265 279 273 239 280 307 239 212 262 290 274 284 263 249 238 263 287 270 271 277 263 287 266 291 256 289 264 261 290 267 269 233 295 259 290 276 267 266 260 238 247 281 241 268 219 264 248 244 293 232 285 281 278 230 266 247 263 264 258 273 265 258 245 281 234 268 233 249 256 233 268 271 272 240 243 261 264 244 237 257 258 211 262 277 230 249 274 238 260 230 258 236 241 230 256 249 270 269 262 247 234 249 269 271 279 273 245 239 257 257 266 270 264 247 301 273 279 227 285 260 263 278 280 273 249 260 301 270 263 259 276 264 267 290 315 295 266 272 273 270 269 310 311 302 329 321 356 339 377 343 385 406 357 432 403 406 374 403 460 359 382 362 359 350 332 347 320 353 276 321 309 313 329 285 331 314 360 343 341 324 361 370 336 342 355 330 347 357 341 315 302 310 309 319 298 292 293 299 290 275 288 269 307 262 298 284 277 247 287 314 301 264 276 275 292 279 278 291 284 276 299 310 339 285 330 336 347 351 348 334 333 305 331 327 306 310 359 312 308 286 315 290 283 272 300 321 297 315 322 307 328 313 303 312 276 296 320 287 283 318 291 295 250 314 301 311 278 275 286 275 310 282 281 288 340 301 305 287 280 278 282 283 265 296 274 261 268 313 271 292 269 304 286 295 283 319 270 351 283 335 322 332 374 359 345 404 411 439 408 487 478 520 522 546 589 538 560 541 503 504 463 451 458 422 406 431 436 363 394 393 347 366 397 347 365 365 388 384 425 389 423 424 436 435 386 427 405 396 385 372 368 364 341 386 312 346 332 327 343 312 290 313 312 272 308 296 299 281 287 287 322 329 337 303 317 296 334 320 317 324 338 321 350 346 363 337 370 401 422 392 430 484 489 466 545 569 592 599 653 719 737 764 715 725 711 721 668 661 636 626 574 537 509 474 504 464 443 406 441 406 475 424 445 446 492 453 505 490 483 510 499 495 528 507 531 455 485 448 402 443 392 394 359 343 338 320 315 316 339 291 306 297 282 288 306 299 276 284 278 248 314 280 296 302 282 299 290 261 283 299 259 249 269 249 284 293 283 276 275 302 265 248 304 302 303 294 247 302 270 264 283 297 286 314 282 313 277 286 300 269 300 310 333 312 298 311 325 307 316 360 375 352 396 411 413 456 435 488 497 515 524 553 579 544 540 514 526 548 503 486 425 421 372 414 377 392 345 420 349 365 336 365 327 349 356 368 365 388 374 421 365 418 395 374 388 402 353 369 365 362 354 371 318 328 292 318 297 337 299 307 290 291 269 276 289 310 288 271 242 230 300 267 285 287 267 289 272 247 258 266 264 294 309 282 297 241 287 293 271 272 243 262 270 227 237 267 260 257 267 256 279 259 248 281 301 286 299 277 264 246 229 288 291 277 272 280 282 279 285 309 309 309 338 315 283 310 332 358 384 330 418 341 409 414 456 438 442 406 436 392 407 345 385 354 366 344 337 363 312 338 313 321 332 341 334 335 326 352 354 339 349 325 332 343 373 352 368 426 419 384 370 430 398 418 391 462 405 405 419 453 448 467 478 442 480 424 472 490 426 429 443 368 406 418 405 352 388 340 396 309 351 379 372 336 382 324 340 308 332 325 333 385 333 373 367 327 355 378 353 341 333 335 317 346 350 365 319 260 295 293 282 271 304 277 288 296 283 287 298 240 240 289 225 273 247 274 302 287 344 318 308 316 350 317 361 343 360 346 376 364 387 346 347 377 326 371 332 333 347 315 337 350 325 299 323 289 269 321 258 288 303 277 323 328 320 344 336 339 336 312 336 303 303 309 326 335 312 303 355 338 318 284 314 331 315 319 329 293 323 347 341 351 369 368 358 396 363 410 456 366 381 364 443 374 404 383 366 344 366 330</counts>
			</dataPoints>
		</scan>
	</xrdMeasurement>
</xrdMeasurements>