File: dataset/precursor_mixture/V2O5_Fe3O4_Y2O3_CuO.2-min.xrdml
<?xml version="1.0"?>
<xrdMeasurements xmlns="http://www.xrdml.com/XRDMeasurement/2.2" xmlns:xsi="http://www.w3.org/2001/XMLSchema-instance" xsi:schemaLocation="http://www.xrdml.com/XRDMeasurement/2.2 http://www.xrdml.com/XRDMeasurement/2.2/XRDMeasurement.xsd" status="Completed" recordIdentifier="{937AF655-C21E-4714-9E11-3552CC997965}">
	<comment>
		<entry/>
	</comment>
	<sample type="To be analyzed">
		<id>dara-20-1</id>
		<name></name>
		<preparedBy></preparedBy>
	</sample>
	<xrdMeasurement measurementType="Scan" status="Completed" sampleMode="Reflection">
		<usedWavelength intended="K-Alpha 1">
			<kAlpha1 unit="Angstrom">1.5405980</kAlpha1>
			<kAlpha2 unit="Angstrom">1.5444260</kAlpha2>
			<kBeta unit="Angstrom">1.3922500</kBeta>
			<ratioKAlpha2KAlpha1>0.5000</ratioKAlpha2KAlpha1>
		</usedWavelength>
		<incidentBeamPath>
			<radius unit="mm">145.00</radius>
			<xRayTube id="1010048" name="Empyrean Cu LFF HR (9430 033 7310x) DK437873">
				<tension unit="kV">40.0</tension>
				<current unit="mA">15.0</current>
				<anodeMaterial>Cu</anodeMaterial>
				<focus type="Line">
					<length unit="mm">12.0</length>
					<width unit="mm">0.4</width>
					<takeOffAngle unit="deg">6.0</takeOffAngle>
				</focus>
			</xRayTube>
			<filter id="20010004" name="Beta-filter Nickel">
				<material>Ni</material>
				<thickness unit="mm">0.020</thickness>
			</filter>
			<sollerSlit id="21010002" name="Soller slits 0.04 rad.">
				<opening unit="rad">0.0400</opening>
			</sollerSlit>
			<mask id="22031000" name="Fixed mask 13 mm">
				<width unit="mm">9.00</width>
			</mask>
			<divergenceSlit id="22120001" name="Divergence slit 1°" xsi:type="fixedDivergenceSlitType">
				<distanceToSample unit="mm">50.00</distanceToSample>
				<height unit="mm">1.52</height>
			</divergenceSlit>
		</incidentBeamPath>
		<beamKnife id="29030100" name="Beam knife low"/>
		<sampleMovement xsi:type="spinningSampleMovementType">
			<spinnerRevolutionTime unit="seconds">1.0</spinnerRevolutionTime>
		</sampleMovement>
		<diffractedBeamPath>
			<radius unit="mm">145.00</radius>
			<antiScatterSlit id="22090040" name="AS slit 9 mm" xsi:type="fixedAntiScatterSlitType">
				<height unit="mm">9.00</height>
			</antiScatterSlit>
			<sollerSlit id="21020003" name="Large Soller slits 0.04 rad.">
				<opening unit="rad">0.0400</opening>
			</sollerSlit>
			<filter id="20030001" name="Large beta-filter Nickel">
				<material>Ni</material>
				<thickness unit="mm">0.020</thickness>
			</filter>
			<detector id="7010019" name="PIXcel1D-Medipix3 detector" xsi:type="rtmsDetectorType">
				<phd unit="keV">
					<lowerLevel>4.0</lowerLevel>
					<upperLevel>11.3</upperLevel>
				</phd>
				<mode>Scanning</mode>
				<activeLength unit="deg">1.021</activeLength>
			</detector>
		</diffractedBeamPath>
		<scan appendNumber="0" mode="Continuous" scanAxis="Gonio" status="Completed">
			<header>
				<startTimeStamp>2024-03-24T16:23:33-07:00</startTimeStamp>
				<endTimeStamp>2024-03-24T16:25:55-07:00</endTimeStamp>
				<author>
					<name>AutomatedUser</name>
				</author>
				<source>
					<applicationSoftware version="1.6 (94)">PANalytical Aeris Instrument Suite</applicationSoftware>
					<instrumentControlSoftware version="3.0.0 20211014">AERIS</instrumentControlSoftware>
					<instrumentID>2879380</instrumentID>
				</source>
			</header>
			<dataPoints>
				<positions axis="2Theta" unit="deg">
					<startPosition>10.02173288</startPosition>
					<endPosition>139.98435528</endPosition>
				</positions>
				<positions axis="Omega" unit="deg">
					<startPosition>5.01086644</startPosition>
					<endPosition>69.99217764</endPosition>
				</positions>
				<commonCountingTime unit="seconds">1.551</commonCountingTime>
				<counts unit="counts">497 561 553 599 538 526 543 526 559 567 506 583 561 528 585 562 555 519 549 542 491 520 512 498 532 560 539 497 502 483 530 513 518 509 503 503 531 505 486 561 542 515 508 516 485 530 488 529 548 503 488 504 467 452 464 444 468 496 515 503 476 509 495 505 520 469 472 468 455 510 493 502 485 425 477 476 443 453 480 465 432 504 526 436 467 461 499 470 481 480 502 469 476 494 466 461 446 452 466 435 411 497 508 491 416 426 441 441 430 518 442 459 438 459 441 453 453 491 455 480 527 555 580 541 479 466 457 415 473 425 455 515 456 451 458 471 422 450 415 453 423 430 450 491 443 475 400 475 463 470 447 448 470 479 467 447 447 428 433 422 460 469 458 489 466 454 452 475 457 430 459 427 442 454 428 463 450 455 483 467 417 447 478 513 522 504 532 508 557 445 465 437 440 473 491 453 480 450 469 452 423 440 465 404 441 462 495 440 469 468 432 439 487 443 463 500 466 392 444 475 464 452 505 459 479 470 478 569 521 628 665 837 1062 984 897 738 723 736 662 539 489 499 445 455 449 509 416 475 452 465 487 464 440 421 456 471 390 426 446 440 542 476 500 563 577 594 550 488 443 460 453 457 429 447 488 457 421 495 423 418 425 454 406 434 420 499 444 401 455 400 421 407 432 425 435 471 409 425 452 448 470 382 410 410 454 446 394 437 416 434 465 399 416 408 430 434 456 474 472 397 470 427 442 434 423 460 409 425 437 473 425 383 411 411 422 434 438 455 449 441 412 466 391 425 409 445 393 421 411 427 444 443 446 475 405 418 421 384 408 426 434 494 465 585 663 615 547 442 444 415 432 444 445 418 428 381 421 416 440 417 400 403 454 428 405 410 418 416 421 429 420 456 387 416 425 419 477 443 366 420 413 434 402 444 424 390 414 429 398 438 423 419 425 417 411 415 392 421 461 419 446 480 481 470 461 539 538 647 747 1101 1678 2224 2457 1904 1427 904 630 589 548 501 477 467 428 433 452 446 437 462 506 430 494 565 675 642 722 582 497 430 467 444 420 404 434 431 435 399 479 428 465 418 418 496 515 591 639 583 493 448 458 422 488 433 442 458 411 420 424 438 397 433 439 442 415 438 425 435 392 393 420 389 408 419 467 459 491 477 511 479 491 441 447 416 428 444 387 406 438 401 395 392 429 399 391 446 442 444 417 438 449 458 452 410 513 510 627 727 827 761 672 535 475 480 446 410 412 456 425 460 493 431 454 427 414 408 409 402 426 447 434 459 447 432 438 468 406 436 448 522 504 572 702 887 1384 1617 1602 1438 1284 1047 840 682 631 560 515 570 565 484 504 469 479 417 432 444 410 396 403 433 391 382 423 406 421 425 410 405 447 420 405 421 432 466 460 424 418 394 442 447 367 392 373 450 431 364 431 374 423 408 388 395 428 393 419 387 390 390 410 413 384 403 447 473 453 439 576 574 612 714 818 787 798 700 617 652 585 506 535 471 452 447 446 416 435 428 385 400 416 407 403 385 400 438 439 464 476 510 462 466 410 370 423 407 378 380 401 372 397 367 414 382 389 399 389 360 350 354 373 370 361 363 423 398 381 418 438 426 428 467 446 417 371 380 429 394 404 389 410 356 402 400 429 382 391 389 407 406 393 405 405 386 385 362 383 353 395 387 403 414 443 370 432 418 434 437 474 437 533 543 556 519 482 452 441 433 448 534 562 492 508 481 451 439 408 374 383 390 426 377 389 365 378 411 382 397 413 416 385 381 398 402 403 370 392 361 378 373 379 408 386 368 404 397 363 374 380 393 386 377 400 389 366 435 396 435 399 392 410 383 381 381 369 412 403 364 386 381 392 387 363 390 412 429 380 387 356 391 341 359 392 397 397 402 407 436 440 447 397 385 366 393 396 401 451 436 412 397 408 437 403 430 436 444 390 451 452 426 438 412 418 419 388 411 450 429 460 453 487 577 771 1001 1131 916 878 855 662 638 598 582 522 519 461 452 410 449 397 371 378 400 412 400 430 419 423 414 389 389 394 386 401 369 384 364 387 392 414 433 392 391 416 378 414 380 419 376 332 390 392 402 407 355 380 381 394 371 407 364 360 401 399 423 455 449 458 431 455 387 417 405 385 396 384 399 379 397 414 398 441 421 439 390 394 386 392 419 398 400 374 414 383 380 348 371 343 383 391 386 366 382 368 412 423 426 428 441 456 426 461 466 505 514 510 443 496 456 394 389 399 443 367 397 391 410 382 382 398 396 343 397 378 380 359 390 384 382 371 357 397 392 389 387 382 417 392 408 360 389 397 376 368 386 364 389 371 434 340 375 383 398 393 370 389 408 432 383 388 378 393 371 365 410 410 484 457 435 472 469 437 412 414 370 377 390 361 402 425 397 442 503 536 543 606 577 511 517 473 452 397 422 425 457 467 497 581 754 824 778 653 625 637 502 434 445 423 420 407 415 427 440 391 420 459 460 449 446 401 441 401 393 383 406 414 375 416 406 465 490 502 458 434 450 427 454 395 418 432 415 404 344 390 380 365 372 411 342 372 342 358 427 382 429 385 403 394 421 404 441 401 412 447 438 421 448 384 414 365 433 398 369 396 367 398 424 418 364 408 396 418 344 405 434 424 415 435 404 425 447 392 404 440 433 450 417 425 397 436 441 403 423 413 408 490 469 500 516 565 596 597 610 559 597 500 504 468 451 428 400 400 395 423 389 415 367 394 375 402 368 415 348 430 390 368 367 382 370 372 395 338 356 378 423 389 382 369 394 401 380 392 396 435 410 411 459 407 412 398 422 368 356 389 375 369 357 417 395 364 382 428 378 364 356 373 359 437 392 447 383 419 419 411 455 456 431 392 426 429 410 402 374 440 400 446 451 418 415 419 432 406 392 398 384 363 376 408 415 356 335 356 368 398 390 380 367 369 389 363 372 403 372 378 441 388 387 401 379 417 405 431 436 420 449 448 436 472 398 432 432 381 363 381 394 399 379 372 395 372 375 391 413 373 396 387 386 374 387 400 413 362 380 385 381 419 392 391 320 374 375 378 411 401 356 398 411 389 373 370 372 363 383 391 406 391 398 389 357 413 416 396 397 410 383 362 377 440 364 397 440 430 401 413 430 389 431 415 403 378 402 390 347 343 409 400 367 342 336 357 390 418 423 402 361 397 419 433 403 415 455 435 435 425 427 455 429 419 407 380 414 432 370 390 342 374 360 370 360 389 371 313 406 379 371 352 366 400 417 412 407 412 404 419 371 394 401 422 397 367 439 432 414 338 409 365 369 391 362 395 364 366 375 397 432 423 441 414 446 467 483 430 441 433 399 424 422 400 371 416 409 426 356 387 394 377 382 397 358 337 399 371 361 398 381 352 388 391 381 409 389 359 355 346 416 374 351 334 396 376 361 399 396 343 362 394 366 381 375 408 369 418 416 381 391 385 380 375 397 407 383 362 385 343 356 364 397 336 403 375 369 380 354 391 337 365 384 405 435 444 509 458 445 427 424 403 406 390 405 419 382 414 388 377 361 381 355 400 432 345 399 380 372 372 324 317 378 363 355 407 377 334 385 365 382 375 398 366 346 397 373 396 338 382 355 354 407 364 353 371 391 383 381 401 378 414 469 442 414 407 402 378 375 384 416 381 414 348 406 393 366 369 372 357 358 411 359 387 427 377 390 383 397 396 396 404 373 373 390 401 414 403 367 357 412 418 399 372 350 381 358 359 390 391 378 329 378 369 392 433 371 387 369 386 433 397 387 396 407 415 338 375 407 419 371 383 380 374 396 348 417 381 349 341 381 367 381 411 433 427 385 432 422 385 367 352 357 362 379 376 383 380 351 382 355 326 367 411 392 387 338 394 396 357 380 382 350 364 350 377 362 366 376 381 379 368 343 326 402 378 371 368 380 379 378 421 367 376 403 378 395 350 395 399 420 409 412 388 398 401 377 389 383 338 386 371 406 356 363 378 373 348 367 397 380 377 390 383 384 359 352 345 398 356 353 407 403 395 398 389 390 360 354 359 392 376 381 361 352 375 413 371 374 400 397 432 449 433 415 449 473 444 421 446 437 420 464 391 423 381 404 383 423 382 376 398 356 414 378 413 390 425 464 413 448 426 415 402 389 389 405 450 438 375 364 421 342 361 392 344 369 362 426 392 360 369 399 404 393 363 387 405 384 421 390 380 388 379 381 387 367 358 375 359 354 378 370 398 349 340 399 396 380 379 364 388 376 380 396 384 376 366 413 372 378 390 390 427 421 363 410 376 387 388 390 361 346 369 379 364 364 352 399 379 390 384 438 389 383 397 358 359 388 358 396 398 327 396 395 376 380 370 382 375 399 368 383 406 370 406 376 390 394 423 407 394 427 375 396 372 378 408 357 405 382 422 368 366 372 373 383 394 374 335 353 340 365 369 357 348 395 345 418 417 360 401 361 362 391 320 353 351 395 364 366 385 397 369 359 385 365 373 409 392 371 384 377 402 439 413 404 427 400 433 387 403 432 384 394 382 385 379 419 383 373 379 387 323 342 394 377 426 398 384 394 371 390 413 408 402 365 349 388 385 375 413 425 384 371 359 372 371 391 359 381 380 386 375 320 377 373 376 377 354 363 381 352 379 370 390 383 370 373 381 340 359 387 328 405 368 359 353 367 378 369 386 361 391 375 375 420 387 352 380 375 349 399 388 402 405 384 379 357 360 370 360 358 391 345 352 380 386 360 392 365 348 389 365 392 395 413 400 403 405 393 383 403 385 395 385 384 375 399 405 379 393 365 380 352 366 387 381 396 420 403 371 380 393 387 374 377 361 396 366 383 370 370 398 374 397 380 404 377 370 347 397 361 407 356 383 403 484 392 411 413 415 376 425 394 387 407 427 398 375 392 370 361 413 409 403 412 387 388 386 392 378 388 380 399 385 323 386 391 380 387 384 370 369 404 360 379 378 371 391 391 385 386 382 349 365 386 378 365 348 358 382 386 377 403 381 391 379 370 395 368 353 387 332 365 354 352 395 353 387 407 392 396 384 388 373 356 375 390 402 367 372 351 351 350 420 382 400 419 378 401 402 374 369 382 367 425 379 403 399 406 420 387 395 403 372 431 387 402 408 369 385 401 377 401 374 411 398 396 372 356 390 390 387 415 379 379 400 375 375 353 385 368 350 368 372 406 370 375 407 390 390 371 374 373 382 375 359 393 381 384 378 347 368 394 384 372 379 369 406 352 385 405 373 345 371 381 344 373 358 398 389 400 386 393 406 363 425 355 368 374 365 379 382 371 372 367 360 430 377 422 367 370 367 389 344 391 387 431 378 395 333 384 380 382 397 351 385 335 340 411 377 417 412 404 358 377 353 412 383 380 384 375 375 400 384 364 375 330 356 379 418 403 357 361 377 380 348 375 387 345 362 388 376 371 361 350 322 387 359 394 333 350 348 375 373 370 366 358 370 373 393 365 408 369 398 378 399 396 380 365 386 341 370 368 358 347 384 384 324 404 409 372 397 394 383 375 334 386 386 394 345 388 416 379 395 375 389 428 415 380 374 414 418 401 395 397 347 390 406 353 382 383 373 357 385 349 378 340 376 391 401 371 385 361 395 411 385 378 352 392 376 415 374 369 377 437 386 382 369 395 381 405 371 357 381 419 385 382 374 408 409 370 397 374 362 403 417 369 393 423 353 354 381 354 371 395 404 385 392 396 407 415 408 388 339 394 382 399 361 372 389 454 423 411 382 394 389 404 417 394 399 408 389 371 400 400 388 384 407 344 378 395 375 367 390 366 402 401 381 384 384 370 406 365 356 355 342 372 365 352 414 394 385 380 389 392 378 391 377 334 394 433 362 377 410 381 366 394 391 369 411 399 371 397 404 380 369 374 406 371 388 372 420 384 374 385 398 364 380 399 368 382 385 372 395 367 398 382 413 419 371 347 347 381 392 427 359 415 376 373 354 362 426 387 362 412 393 398 400 392 410 409 377 392 426 390 416 413 414 382 437 414 397 397 407 430 433 411 421 401 398 437 408 430 419 449 402 446 401 402 413 408 400 414 449 398 411 448 422 356 403 395 424 396 375 411 380 394 366 353 405 392 392 398 359 378 352 389 360 368 385 389 412 379 362 361 378 386 402 398 381 372 384 313 344 371 330 387 390 379 419 369 372 400 364 417 393 420 423 389 393 361 405 393 429 364 375 382 363 409 362 445 410 369 380 405 429 402 414 377 440 382 349 374 421 388 396 370 415 375 382 383 399 387 366 389 352 371 392 323 395 400 395 364 349 330 427 387 350 442 389 369 405 426 403 382 409 391 358 384 391 372 363 357 406 390 403 389 410 374 402 400 382 373 416 345 388 402 351 414 394 370 367 405 413 404 382 407 377 345 355 375 369 386 416 369 364 376 421 371 378 376 429 383 406 359 405 368 367 368 408 407 388 388 379 370 365 422 387 356 357 359 378 381 380 416 402 402 423 411 411 385 431 389 413 410 378 410 391 404 381 406 373 403 433 430 401 395 355 405 374 375 423 401 427 364 384 374 364 353 389 381 389 371 399 368 368 387 415 403 366 388 417 377 382 365 389 376 386 375 368 420 402 414 378 381 362 377 361 404 425 364 409 392 385 359 368 397 434 379 382 368 396 385 381 391 398 389 400 385 381 409 373 435 369 398 402 391 404 387 388 419 384 381 422 407 404 407 414 406 376 385 441 387 374 362 400 390 377 380 394 380 429 354 401 388 386 397 357 381 403 373 371 429 410 367 354 377 394 385 374 421 380</counts>
			</dataPoints>
		</scan>
	</xrdMeasurement>
</xrdMeasurements>