File: dataset/precursor_mixture/V2O5_0p4013-In2O3_0p4021-La(OH)3_0p2014--8min.xrdml
<?xml version="1.0"?>
<xrdMeasurements xmlns="http://www.xrdml.com/XRDMeasurement/2.3" xmlns:xsi="http://www.w3.org/2001/XMLSchema-instance" xsi:schemaLocation="http://www.xrdml.com/XRDMeasurement/2.3 http://www.xrdml.com/XRDMeasurement/2.3/XRDMeasurement.xsd" status="Completed" recordIdentifier="{ECCCBB4B-5060-4FBB-AFBC-276BCD316890}">
	<comment>
		<entry/>
	</comment>
	<sample type="To be analyzed">
		<id>V2O5_0p4013-In2O3_0p4021-La(OH)3_0p2014--8min</id>
		<name></name>
		<preparedBy></preparedBy>
	</sample>
	<xrdMeasurement measurementType="Scan" status="Completed" sampleMode="Reflection">
		<usedWavelength intended="K-Alpha 1">
			<kAlpha1 unit="Angstrom">1.5405980</kAlpha1>
			<kAlpha2 unit="Angstrom">1.5444260</kAlpha2>
			<kBeta unit="Angstrom">1.3922500</kBeta>
			<ratioKAlpha2KAlpha1>0.5000</ratioKAlpha2KAlpha1>
		</usedWavelength>
		<incidentBeamPath>
			<radius unit="mm">145.00</radius>
			<xRayTube id="1010048" name="Empyrean Cu LFF HR (9430 033 7310x)">
				<tension unit="kV">40.0</tension>
				<current unit="mA">15.0</current>
				<anodeMaterial>Cu</anodeMaterial>
				<focus type="Line">
					<length unit="mm">12.0</length>
					<width unit="mm">0.4</width>
					<takeOffAngle unit="deg">6.0</takeOffAngle>
				</focus>
			</xRayTube>
			<sollerSlit id="21010002" name="Soller slits 0.04 rad.">
				<opening unit="rad">0.0400</opening>
			</sollerSlit>
			<mask id="22031000" name="Fixed mask 13 mm">
				<width unit="mm">9.00</width>
			</mask>
			<divergenceSlit id="22120001" name="Divergence slit 1°" xsi:type="fixedDivergenceSlitType">
				<distanceToSample unit="mm">50.00</distanceToSample>
				<height unit="mm">1.52</height>
			</divergenceSlit>
		</incidentBeamPath>
		<sampleMovement xsi:type="spinningSampleMovementType">
			<spinnerRevolutionTime unit="seconds">1.0</spinnerRevolutionTime>
		</sampleMovement>
		<diffractedBeamPath>
			<radius unit="mm">145.00</radius>
			<antiScatterSlit id="22090040" name="AS slit 9 mm (PIXcel)" xsi:type="fixedAntiScatterSlitType">
				<height unit="mm">9.00</height>
			</antiScatterSlit>
			<sollerSlit id="21020003" name="Large Soller slits 0.04 rad.">
				<opening unit="rad">0.0400</opening>
			</sollerSlit>
			<filter id="20030001" name="Large beta-filter Nickel">
				<material>Ni</material>
				<thickness unit="mm">0.020</thickness>
			</filter>
			<detector id="7010019" name="PIXcel1D-Medipix3 detector" xsi:type="rtmsDetectorType">
				<phd unit="keV">
					<lowerLevel>4.02</lowerLevel>
					<upperLevel>11.27</upperLevel>
				</phd>
				<mode>Scanning</mode>
				<activeLength unit="deg">5.542</activeLength>
			</detector>
		</diffractedBeamPath>
		<scan appendNumber="0" mode="Continuous" scanAxis="Gonio" status="Completed">
			<header>
				<startTimeStamp>2024-11-14T15:11:22-08:00</startTimeStamp>
				<endTimeStamp>2024-11-14T15:19:29-08:00</endTimeStamp>
				<author>
					<name>AutomatedUser</name>
				</author>
				<source>
					<applicationSoftware version="1.7b (136)">PANalytical Aeris Instrument Suite</applicationSoftware>
					<instrumentControlSoftware version="3.2.00000000 20240306">AERIS</instrumentControlSoftware>
					<instrumentID>950485</instrumentID>
				</source>
			</header>
			<dataPoints>
				<positions axis="2Theta" unit="deg">
					<startPosition>10.00943322</startPosition>
					<endPosition>99.99442286</endPosition>
				</positions>
				<positions axis="Omega" unit="deg">
					<startPosition>5.00471661</startPosition>
					<endPosition>49.99721143</endPosition>
				</positions>
				<commonCountingTime unit="seconds">12.495</commonCountingTime>
				<counts unit="counts">2471 2340 2477 2438 2374 2417 2332 2313 2369 2264 2378 2325 2380 2424 2348 2361 2258 2254 2369 2295 2359 2321 2309 2340 2325 2390 2272 2355 2322 2298 2275 2373 2302 2268 2195 2222 2284 2293 2257 2313 2362 2321 2210 2263 2196 2163 2209 2269 2229 2265 2254 2222 2231 2240 2342 2253 2220 2328 2155 2210 2160 2109 2253 2187 2245 2218 2192 2134 2166 2269 2161 2209 2126 2141 2095 2167 2109 2186 2075 2073 2053 2140 2197 2134 2129 2139 2148 2152 2099 2093 2115 2074 2082 2109 2034 2141 2121 2045 2102 2183 2150 2172 2021 2052 2085 2108 2032 2125 2085 2048 2134 2126 2058 2062 2023 2135 2116 1966 2067 2048 1984 2050 2049 1967 2018 1991 2016 2103 1985 2033 1990 1966 2072 2007 1984 2033 2053 1965 1989 2028 2053 1971 2008 1993 2003 2017 1997 1921 1954 1996 2057 1962 1959 1966 1905 1893 1906 1942 1914 2009 2016 1910 1870 1859 1929 1894 1908 1978 1951 2028 1910 1905 1929 1903 1965 1883 1955 1897 1948 1863 1823 1794 1878 1838 1954 1813 1875 1888 1900 1863 1911 1905 1829 1839 1812 1782 1855 1810 1833 1859 1811 1892 1795 1825 1915 1821 1776 1705 1811 1768 1734 1880 1833 1794 1824 1802 1673 1873 1817 1850 1806 1790 1763 1798 1823 1843 1811 1789 1760 1826 1782 1723 1850 1728 1799 1837 1863 1798 1735 1668 1768 1777 1812 1755 1738 1741 1767 1690 1712 1761 1752 1702 1719 1678 1656 1708 1727 1686 1697 1635 1714 1792 1626 1650 1705 1771 1681 1726 1771 1657 1685 1649 1673 1602 1695 1744 1711 1748 1682 1697 1689 1622 1622 1659 1704 1617 1647 1596 1685 1621 1664 1671 1613 1625 1622 1631 1656 1582 1651 1623 1625 1601 1620 1695 1649 1642 1627 1647 1623 1595 1638 1594 1625 1595 1520 1585 1613 1647 1636 1636 1635 1597 1614 1616 1638 1668 1620 1604 1600 1514 1504 1633 1580 1607 1608 1629 1583 1590 1525 1519 1568 1561 1625 1549 1543 1520 1583 1561 1570 1564 1576 1599 1614 1514 1558 1584 1570 1498 1535 1549 1501 1579 1558 1584 1590 1513 1560 1542 1546 1554 1563 1576 1572 1579 1570 1536 1584 1607 1553 1629 1560 1554 1516 1518 1548 1539 1489 1427 1546 1566 1538 1593 1553 1514 1510 1481 1487 1537 1536 1619 1479 1490 1518 1492 1567 1446 1477 1505 1563 1492 1510 1545 1481 1485 1477 1466 1499 1533 1452 1545 1442 1536 1489 1450 1558 1476 1576 1500 1515 1478 1501 1521 1580 1496 1499 1512 1461 1447 1462 1547 1500 1488 1498 1505 1445 1499 1471 1522 1415 1533 1463 1526 1399 1547 1437 1506 1467 1541 1512 1518 1481 1511 1490 1516 1555 1594 1545 1586 1602 1548 1626 1630 1605 1659 1688 1725 1720 1630 1725 1735 1793 1809 1898 1734 1891 1905 1945 1939 2020 2015 2022 2055 2061 2142 2176 2208 2302 2359 2352 2427 2327 2302 2360 2401 2405 2377 2437 2371 2389 2437 2470 2568 2508 2500 2552 2634 2676 2649 2619 2728 2701 2689 2668 2508 2608 2565 2521 2492 2363 2259 2203 2139 2053 1982 1978 1806 1847 1750 1754 1821 1709 1692 1647 1622 1598 1610 1515 1490 1534 1527 1551 1507 1524 1492 1570 1518 1441 1469 1412 1511 1448 1473 1427 1455 1496 1445 1349 1397 1431 1381 1354 1385 1388 1445 1386 1380 1422 1409 1404 1406 1445 1423 1403 1442 1382 1378 1301 1401 1381 1322 1332 1344 1384 1429 1399 1345 1352 1341 1360 1475 1393 1353 1407 1382 1416 1363 1416 1331 1346 1389 1348 1345 1346 1332 1320 1417 1383 1384 1408 1366 1344 1355 1296 1321 1372 1371 1388 1303 1320 1351 1313 1325 1278 1358 1330 1284 1295 1418 1342 1309 1290 1336 1316 1279 1270 1374 1310 1335 1386 1337 1359 1334 1248 1309 1355 1362 1372 1331 1281 1368 1275 1312 1315 1264 1282 1234 1281 1263 1268 1310 1265 1247 1319 1349 1286 1360 1328 1333 1307 1353 1278 1290 1287 1249 1407 1322 1285 1313 1277 1380 1348 1338 1276 1334 1223 1339 1225 1368 1207 1291 1346 1346 1274 1213 1329 1241 1308 1241 1321 1298 1230 1210 1282 1253 1269 1307 1252 1292 1250 1325 1319 1298 1213 1258 1236 1284 1272 1300 1346 1230 1278 1302 1267 1283 1214 1302 1322 1265 1325 1265 1301 1226 1269 1225 1218 1226 1315 1204 1310 1259 1181 1231 1228 1167 1208 1241 1190 1302 1278 1230 1262 1257 1277 1204 1227 1188 1232 1228 1280 1205 1279 1233 1187 1270 1177 1199 1228 1268 1218 1254 1289 1247 1195 1206 1208 1212 1242 1240 1172 1222 1126 1195 1218 1213 1191 1168 1209 1185 1257 1195 1157 1233 1121 1129 1174 1172 1107 1186 1210 1222 1171 1197 1187 1147 1165 1193 1132 1239 1245 1197 1228 1201 1169 1190 1174 1193 1255 1198 1243 1199 1208 1193 1225 1174 1259 1233 1262 1091 1190 1164 1157 1178 1202 1201 1168 1193 1159 1159 1114 1179 1123 1144 1175 1149 1204 1170 1137 1193 1145 1170 1215 1182 1191 1167 1144 1205 1216 1151 1229 1194 1168 1243 1173 1104 1179 1154 1206 1123 1185 1210 1191 1155 1117 1199 1202 1216 1190 1194 1188 1178 1139 1187 1158 1167 1168 1167 1171 1198 1277 1184 1092 1197 1216 1159 1233 1191 1210 1250 1250 1152 1281 1233 1226 1265 1268 1221 1366 1273 1284 1269 1312 1347 1314 1519 1397 1478 1566 1600 1561 1658 1710 1835 1761 1847 2003 2069 2084 2210 2388 2447 2525 2576 2650 2757 2893 2895 2853 2979 2961 3012 2989 2805 2806 2771 2610 2465 2307 2190 2045 1907 1773 1662 1568 1487 1421 1389 1300 1357 1301 1210 1199 1244 1235 1178 1240 1190 1227 1117 1138 1080 1161 1156 1170 1134 1225 1113 1170 1151 1114 1138 1133 1129 1051 1075 1100 1080 1188 1140 1139 1070 1186 1114 1086 1139 1146 1092 1106 1148 1209 1146 1154 1115 1141 1087 1158 1102 1125 1113 1160 1119 1151 1096 1180 1156 1173 1160 1160 1150 1141 1164 1232 1167 1190 1190 1217 1214 1255 1275 1330 1386 1369 1421 1490 1504 1503 1472 1598 1636 1701 1782 1826 1856 1933 1996 2008 2025 2090 2004 2222 2152 2185 2217 2207 2107 2014 1987 1944 1940 1822 1874 1712 1790 1737 1725 1639 1673 1612 1745 1725 1639 1633 1662 1643 1605 1649 1648 1596 1481 1363 1398 1376 1310 1255 1223 1248 1151 1152 1179 1106 1128 1126 1121 1076 1095 1088 1096 1060 1065 1069 1033 1028 1078 994 1074 1067 1056 1087 1071 1059 1053 1088 1063 1025 1021 1010 1033 1044 1034 1022 942 982 1018 1021 985 972 1029 977 1058 968 1000 990 987 1021 1064 985 1011 955 949 986 952 1032 1045 974 983 969 953 1019 1011 967 991 1003 983 975 962 999 1045 1041 1023 983 992 1007 1033 1028 1004 1005 1012 989 1035 1006 943 1004 1034 999 1037 1027 1058 953 1043 957 1042 1018 952 974 1015 1015 1043 992 958 992 978 1007 985 947 977 998 987 1029 967 1008 978 1031 998 979 997 957 989 1062 1038 911 906 955 938 954 909 924 979 1016 988 966 955 968 987 949 998 925 926 943 933 901 956 948 942 944 992 1007 1006 988 995 970 937 966 954 949 958 931 967 922 888 1003 934 909 919 938 923 958 967 999 926 966 977 994 962 889 958 998 970 934 996 956 907 939 873 933 905 918 900 925 943 907 949 942 921 930 937 903 907 980 937 875 947 855 954 872 907 890 926 933 903 903 905 897 899 936 937 907 930 886 944 877 911 875 878 922 895 916 927 915 932 891 907 978 940 956 901 871 898 865 898 954 915 929 947 877 909 881 869 941 943 947 904 940 898 916 917 847 916 865 892 919 869 867 882 898 922 860 932 922 865 896 852 854 851 895 925 902 863 942 856 960 944 924 940 854 814 937 929 892 884 880 843 858 912 949 868 883 956 890 925 854 915 842 904 914 871 925 939 948 893 846 926 850 887 925 927 858 921 948 903 878 931 929 944 932 989 981 944 918 918 941 953 925 921 1040 980 1001 958 1015 976 1004 1001 944 946 999 940 905 953 879 964 921 904 906 918 927 817 931 933 925 915 949 906 955 962 969 1018 1018 1082 1041 1073 1084 1076 1173 1248 1214 1310 1296 1437 1482 1557 1601 1814 1797 1881 1899 2124 2132 2155 2241 2237 2198 2182 2187 2072 2035 1864 1854 1763 1546 1494 1432 1334 1274 1146 1159 1079 1084 958 985 944 1005 925 919 958 919 903 906 944 882 912 953 901 893 881 855 910 867 899 905 871 902 873 885 913 893 837 908 880 862 949 937 895 919 905 910 980 936 910 916 972 1011 927 965 996 1028 891 1038 1028 1009 997 1031 1050 1046 1104 1061 1063 1097 1197 1187 1193 1224 1265 1271 1338 1395 1482 1499 1553 1650 1695 1675 1794 1849 1911 1997 2081 2029 2192 2151 2105 2140 2280 2328 2241 2160 2203 2164 2158 2125 1985 1934 1875 1861 1725 1766 1645 1584 1500 1486 1438 1461 1399 1358 1361 1270 1275 1298 1236 1315 1180 1198 1172 1210 1248 1251 1235 1289 1244 1226 1232 1305 1316 1351 1422 1468 1530 1559 1537 1572 1719 1781 1798 1866 1898 2016 2055 2243 2309 2344 2497 2530 2592 2673 2780 2808 2870 2883 2891 2830 2875 2796 2737 2598 2549 2444 2413 2232 2208 2046 1997 1852 1748 1698 1568 1532 1437 1378 1387 1332 1250 1241 1154 1117 1136 1105 1040 1030 1016 1016 1027 1025 1018 915 956 905 929 959 916 853 848 859 860 891 861 898 839 887 864 871 902 835 903 902 912 828 858 806 865 821 853 846 836 824 826 769 828 795 839 792 759 802 821 793 781 757 749 791 767 811 768 818 750 793 812 798 751 821 768 834 777 795 718 857 795 817 757 765 766 757 802 770 763 758 778 736 805 789 797 805 789 824 772 785 802 773 828 759 804 777 759 747 807 817 785 765 761 773 798 832 786 831 776 777 844 802 839 836 826 789 797 840 797 861 855 844 807 826 779 850 773 851 815 849 836 867 876 873 922 802 868 835 823 885 864 895 905 801 905 837 928 863 874 875 926 853 909 869 950 924 906 941 921 934 963 995 997 998 1006 1041 973 1049 1010 1032 1049 1065 1147 1099 1145 1166 1242 1244 1304 1213 1301 1316 1404 1373 1440 1579 1607 1667 1739 1748 1994 2076 2398 2383 2583 2775 3130 3337 3764 4125 4471 5098 5478 6099 6673 7224 8086 8627 9435 10054 10675 11161 11560 12106 12185 12540 12433 11972 11762 11248 10199 9387 8414 7529 6750 6123 5416 4884 4164 3685 3075 2807 2532 2378 2166 2080 2014 1971 1930 1944 1892 1850 1841 1852 1931 1870 1963 2069 2065 2111 2220 2212 2240 2325 2204 2264 2290 2226 2124 2148 2031 1900 1830 1739 1688 1553 1580 1478 1385 1253 1282 1211 1149 1069 989 1055 1029 1023 993 957 960 960 941 927 944 1010 954 949 922 975 971 976 959 1030 993 1031 1024 1069 1059 1104 1108 1051 1146 1108 1158 1163 1123 1165 1147 1066 1051 1147 1056 1109 975 1002 1032 970 957 970 1039 938 945 921 942 882 889 829 906 817 870 856 878 815 809 821 790 846 807 836 772 847 779 761 817 798 758 775 736 749 777 765 810 801 800 823 834 819 817 763 857 792 847 816 843 929 926 987 966 1028 1004 1044 1093 1173 1153 1111 1199 1281 1263 1202 1219 1304 1241 1201 1194 1187 1162 1148 1050 1040 1053 932 957 851 851 822 843 849 779 775 777 799 756 819 777 774 709 742 698 745 712 717 685 720 709 739 760 722 767 733 718 711 656 717 743 681 695 727 814 705 749 723 760 809 749 786 725 758 765 802 805 807 774 889 834 902 800 889 862 836 856 840 864 874 851 792 848 840 855 897 820 852 863 845 824 860 862 799 878 896 857 868 884 804 801 828 766 805 726 758 750 735 734 714 764 713 677 662 681 658 698 622 674 670 599 642 654 680 629 701 675 649 691 722 668 694 659 661 679 668 712 655 705 688 693 656 674 718 685 675 681 666 687 674 640 685 666 655 667 690 657 639 678 668 737 699 723 668 722 771 702 786 750 789 842 872 934 849 916 1070 1043 1036 1094 1199 1065 1258 1206 1213 1193 1183 1281 1194 1186 1116 1118 1065 1015 979 918 924 846 850 870 750 735 820 703 699 688 700 704 666 655 644 652 657 724 679 693 721 649 652 614 686 715 684 674 677 704 725 679 649 720 633 636 700 663 667 722 733 725 695 671 735 699 733 743 706 767 703 734 735 763 732 712 727 803 748 784 786 825 780 780 820 820 894 852 899 940 951 972 1027 1097 1142 1188 1320 1371 1388 1636 1614 1785 2041 2161 2407 2472 2665 2942 3137 3359 3598 3684 4106 4114 4154 4250 4080 4003 3935 3773 3409 3142 2895 2727 2591 2383 2182 1971 1761 1558 1420 1312 1221 1084 1043 990 995 942 982 871 913 892 841 893 845 834 831 807 848 803 842 773 832 824 844 874 840 817 798 871 824 873 893 849 881 886 888 861 819 884 859 836 809 769 775 755 864 696 731 749 712 706 687 689 629 757 650 640 670 644 655 674 643 641 638 609 627 652 609 634 617 632 630 612 618 594 593 566 563 604 581 555 575 571 613 588 612 584 624 607 565 618 588 563 643 573 618 574 604 583 600 611 607 573 581 588 578 610 584 595 585 555 576 499 615 603 597 560 562 578 589 595 616 575 588 573 595 609 594 611 565 628 621 588 586 571 560 566 602 586 552 587 584 622 607 592 604 596 637 611 625 602 646 592 622 638 638 653 635 641 630 634 648 646 698 673 611 677 656 628 723 673 747 729 780 712 773 782 836 843 927 934 983 1018 1053 1081 1135 1154 1165 1214 1285 1281 1231 1206 1193 1115 1054 977 980 955 945 820 812 789 711 771 681 642 725 604 629 642 609 636 659 631 611 585 601 574 589 609 541 519 613 584 589 531 619 575 546 576 631 594 557 592 613 577 613 573 629 568 574 572 611 602 589 548 549 565 579 586 580 573 581 529 621 574 545 557 576 552 534 546 570 604 614 536 603 544 575 575 597 556 574 575 575 567 526 548 553 615 605 637 577 585 648 608 606 583 613 580 584 683 620 591 624 559 577 621 628 656 664 614 669 621 659 645 623 634 654 677 684 692 713 711 657 713 697 759 745 768 718 818 802 776 876 891 916 1013 976 1026 1019 1095 1132 1207 1180 1167 1307 1413 1411 1460 1514 1551 1581 1693 1829 1789 1836 1980 1960 1903 2006 2043 2022 1922 1973 1977 1889 1848 1789 1833 1681 1671 1618 1586 1550 1477 1431 1348 1341 1294 1262 1122 1176 1120 1069 1074 975 962 1073 899 945 933 923 898 863 856 909 861 847 753 820 802 731 774 741 717 721 730 651 654 640 639 683 602 627 620 628 623 615 605 606 561 641 563 621 560 572 558 556 573 579 547 537 579 565 581 609 550 559 564 492 558 508 531 587 561 553 592 574 582 538 555 552 580 540 502 563 561 568 516 552 555 547 556 531 524 519 500 499 480 507 505 526 512 559 512 580 557 550 577 541 541 549 535 509 563 527 534 551 519 551 577 542 502 510 570 564 567 536 535 538 516 576 564 539 604 554 571 595 629 655 653 633 632 675 676 708 660 776 708 770 786 808 864 892 918 844 898 898 869 861 887 847 837 842 814 813 775 758 774 724 711 683 651 683 605 648 620 637 610 594 638 600 590 610 577 588 574 608 629 618 685 615 650 691 707 670 733 778 797 794 879 882 950 942 990 1107 1085 1104 1088 1182 1151 1234 1303 1163 1064 1042 1070 1041 1054 1002 1058 1045 966 929 1021 903 922 962 896 901 954 875 833 869 911 873 827 915 872 856 884 914 812 795 844 780 826 820 800 783 800 766 828 731 706 687 692 669 677 675 693 632 676 655 637 589 618 614 640 603 605 543 584 615 538 544 525 544 525 520 553 533 575 507 545 519 517 471 530 497 547 513 521 508 499 497 519 486 485 504 495 505 512 504 513 481 524 493 505 472 551 501 495 488 477 494 519 531 494 537 456 503 466 481 472 502 436 472 490 467 485 462 477 492 496 509 510 485 476 482 491 471 537 511 480 478 502 473 512 505 450 484 477 461 463 471 498 451 485 516 486 490 495 472 485 521 497 500 512 506 502 513 479 530 458 530 529 502 508 560 546 542 579 558 582 591 593 601 584 618 618 653 550 602 595 580 567 559 507 592 526 550 544 544 505 503 480 502 512 516 470 530 502 486 481 486 531 493 532 463 523 493 512 491 480 486 477 547 495 497 512 485 510 421 521 513 503 464 455 470 534 442 501 507 499 481 488 464 469 475 528 528 526 492 453 464 514 469 546 456 524 463 475 490 467 460 503 530 471 549 472 503 458 495 455 482 495 490 488 481 507 495 501 503 488 468 461 482 482 493 458 476 455 474 435 478 463 514 482 460 501 440 471 495 513 532 497 524 531 515 509 487 502 483 541 478 495 489 511 548 542 515 509 558 595 558 591 545 616 633 641 632 623 708 699 693 760 822 714 767 785 848 834 837 873 914 938 998 952 1036 1070 1071 1095 1191 1187 1246 1337 1409 1441 1525 1542 1542 1585 1577 1575 1580 1518 1411 1269 1228 1220 1205 1138 1088 1092 1029 1007 955 860 793 746 729 660 683 605 601 592 588 598 573 583 557 508 503 506 493 545 507 538 480 541 475 473 512 518 487 517 435 490 498 493 506 477 488 474 482 510 464 510 478 507 486 561 500 530 473 533 461 484 491 477 465 500 459 472 453 503 485 447 459 537 472 464 515 485 507 503 463 514 476 493 507 519 491 471 517 487 476 484 558 499 526 552 502 530 530 552 516 547 526 552 551 577 583 539 614 616 662 668 613 661 686 684 687 704 736 732 742 776 790 745 742 744 793 825 752 781 754 758 801 802 834 850 830 805 840 853 894 918 943 924 941 937 1008 972 954 986 966 959 1000 921 929 872 813 785 773 802 762 794 708 737 700 650 671 661 613 608 657 588 616 653 580 575 600 627 665 614 651 658 639 717 664 714 666 731 750 768 759 850 786 821 804 856 851 860 871 917 883 878 824 872 914 870 840 936 892 834 897 874 943 892 919 892 917 946 980 975 969 1012 1011 1021 1060 1067 1087 1027 1076 1081 1071 1048 1082 1159 1134 1154 1134 1116 1098 1116 1102 1136 1110 1189 1119 1192 1151 1147 1229 1159 1294 1272 1320 1305 1323 1391 1475 1470 1496 1626 1576 1568 1567 1674 1683 1719 1672 1772 1719 1720 1686 1715 1701 1763 1689 1659 1685 1603 1541 1589 1546 1566 1434 1400 1400 1328 1366 1363 1287 1279 1163 1185 1082 1043 1057 990 989 928 950 886 883 910 745 840 811 742 806 722 700 685 667 665 692 699 672 713 678 759 777 804 747 737 797 770 883 895 850 834 917 909 837 881 816 771 757 788 768 758 730 681 705 735 757 731 657 667 681 594 653 650 629 586 585 576 545 594 594 647 615 592 588 576 607 602 593 619 600 547 591 576 617 597 627 617 646 568 621 682 662 708 670 652 642 639 661 638 711 660 682 661 678 650 678 654 648 622 632 637 570 614 616 612 639 614 559 619 519 579 554 563 583 493 549 510 552 559 536 586 564 505 499 509 519 592 566 533 538 555 525 528 534 558 509 567 542 514 565 601 567 560 538 628 601 619 602 653 635 660 642 651 632 619 686 681 717 686 672 766 743 802 782 764 775 921 943 981 1033 1095 1166 1210 1316 1520 1545 1667 1882 2121 2433 2672 2878 2995 3441 3823 4128 4290 4693 4672 4931 5100 4867 4783 4567 4169 3824 3750 3541 3546 3281 3338 3244 3313 3062 2910 2896 2598 2372 2171 1966 1785 1641 1551 1363 1351 1238 1186 1096 1105 1057 1029 955 968 908 864 858 861 725 805 745 683 702 674 684 620 632 588 632 606 596 613 625 572 572 570 580 547 550 529 546 514 532 502 509 510 563 534 533 518 535 485 525 503 509 549 528 537 594 538 533 581 558 591 599 633 687 612 628 618 645 658 680 651 625 661 718 610 655 585 611 551 567 574 613 540 556 547 540 527 505 487 479 509 504 486 453 466 484 515 466 466 481 446 478 450 433 509 482 471 478 509 477 464 457 448 483 496 519 505 508 515 522 532 521 557 601 569 650 667 666 649 711 713 665 711 730 733 702 631 668 694 600 654 616 594 550 558 587 554 662 562 553 570 515 494 499 457 499 467 508 451 457 405 444 453 450 427 472 412 437 453 437 457 421 421 421 438 435 412 391 445 419 432 434 425 450 397 416 441 412 457 434 438 445 439 432 433 445 437 407 416 430 457 431 432 440 425 411 397 453 384 419 447 431 466 435 473 457 453 438 419 395 409 418 452 450 459 438 466 411 457 444 457 473 416 515 492 451 494 434 428 432 432 453 440 466 492 468 434 449 476 494 449 432 407 439 448 421 446 414 412 403 430 443 444 396 436 397 445 422 430 438 469 480 460 482 450 501 428 462 482 476 465 464 488 501 451 475 459 429 526 462 450 460 469 450 435 443 444 459 470 463 490 489 476 463 500 435 421 408 424 429 446 442 441 444 424 454 452 450 444 445 470 502 445 462 447 454 435 491 445 457 465 463 428 447 454 473 445 530 505 524 489 506 464 542 478 513 495 557 567 508 550 535 600 603 618 686 618 667 655 687 658 667 681 782 712 724 735 791 796 803 751 775 779 760 821 795 709 730 794 727 764 706 669 759 676 639 667 674 604 664 637 711 695 652 659 701 651 696 690 660 714 688 738 743 721 720 769 665 703 708 640 660 611 670 588 672 649 679 659 682 712 637 760 730 809 818 869 911 920 990 1004 997 1082 1077 1047 1074 1007 1001 985 910 975 921 891 938 897 941 861 857 905 845 851 779 837 764 744 759 688 755 693 701 693 713 696 730 710 624 613 633 684 636 647 601 622 571 548 633 637 579 631 577 556 572 521 551 483 494 471 488 483 524 459 497 468 443 490 475 476 440 437 464 434 442 461 436 444 413 395 433 434 452 429 440 403 410 405 392 396 424 426 389 417 398 457 395 435 466 448 416 429 408 407 406 400 434 365 417 436 417 410 399 422 409 394 430 427 388 417 422 400 405 435 406 442 438 426 412 433 449 459 404 417 444 438 437 427 455 453 458 489 487 477 486 497 504 498 497 570 535 566 535 579 568 563 583 530 532 558 553 520 545 522 554 572 561 538 535 550 553 555 528 534 462 510 486 487 493 482 516 517 495 480 491 503 472 501 505 475 442 512 490 488 455 490 459 449 499 485 450 480 433 489 471 458 462 447 419 490 434 425 428 446 422 468 440 428 424 445 417 492 431 440 483 464 433 487 441 458 467 480 508 494 536 522 510 527 568 532 541 541 515 563 508 565 524 572 537 520 566 544 547 562 543 522 546 576 541 525 592 570 586 600 572 544 598 584 572 577 627 590 572 615 624 659 649 699 664 696 711 681 700 715 728 800 787 841 868 914 959 1000 1016 922 975 971 1015 950 1009 1010 940 893 800 820 766 812 789 759 767 729 738 742 697 687 669 604 598 550 569 520 553 514 471 487 478 484 437 457 452 413 417 473 454 426 421 456 432 469 443 448 412 431 396 467 439 442 436 429 436 419 406 487 411 459 433 462 463 433 449 432 434 466 485 446 448 459 428 450 475 437 445 454 528 492 530 492 533 515 522 546 543 556 550 573 545 506 543 515 562 527 555 506 526 545 527 612 597 584 587 560 547 599 581 583 658 564 625 587 614 649 708 622 688 695 699 736 704 809 850 886 902 961 1016 1152 1259 1311 1521 1660 1794 2042 2314 2471 2671 2887 3025 3222 3477 3475 3546 3439 3262 3041 2858 2609 2458 2366 2175 2157 2191 2246 2191 2135 2117 2156 2064 1880 1877 1672 1482 1356 1192 1121 992 949 901 835 857 764 762 801 777 811 782 831 793 784 758 788 804 794 718 755 731 693 667 693 648 638 629 619 581 555 626 637 603 608 571 550 579 551 496 493 495 535 460 469 478 456 481 493 437 435 451 467 450 445 481 444 472 423 456 449 432 495 453 457 453 428 436 443 438 487 432 428 464 448 413 434 435 477 421 470 460 435 469 477 456 409 505 453 474 497 474 487 488 546 519 540 616 562 690 669 727 726 815 827 850 865 997 1050 1090 1135 1128 1203 1218 1259 1232 1278 1189 1145 1128 1068 974 926 970 937 944 960 859 935 888 842 835 847 811 760 778 703 657 591 576 544 548 519 523 513 493 438 509 486 427 469 439 415 431 428 454 448 414 443 398 406 422 411 426 393 407 385 373 390 370 382 389 426 395 419 415 382 412 416 377 433 397 422 418 418 405 406 412 419 410 408 417 383 422 387 385 440 441 407 437 433 387 411 386 392 404 400 440 432 440 385 449 437 453 401 396 453 400 475 447 460 410 413 426 466 421 467 452 466 422 439 484 433 524 505 499 526 535 553 544 600 602 623 726 723 773 812 852 922 935 1009 1032 1046 1009 1034 1029 1078 915 871 878 895 870 872 865 834 804 862 889 920 903 887 912 874 884 786 830 750 756 730 763 732 748 719 726 676 780 691 667 737 685 728 678 661 696 678 670 646 648 660 596 638 630 611 600 548 568 582 559 562 584 570 601 566 540 560 527 532 529 572 522 546 557 546 543 482 506 562 568 516 504 509 498 519 532 486 524 485 516 534 494 487 498 486 498 474 475 485 447 481 495 441 466 448 502 478 474 463 507 499 504 443 492 544 518 495 465 453 472 481 520 497 513 479 497 496 535 537 572 569 585 646 646 671 681 686 715 760 761 780 737 725 694 682 667 665 630 561 551 622 633 590 562 580 617 551 536 586 554 534 478 518 479 467 492 425 462 451 416 447 418 410 475 397 419 399 417 407 420 413 388 409 428 378 378 365 357 420 393 432 413 395 373 400 409 370 391 379 428 394 431 414 396 395 399 385 409 451 411 440 431 459 426 459 446 508 441 519 469 494 519 457 484 535 514 471 503 484 519 461 455 475 441 448 419 479 449 449 463 450 490 406 490 467 476 423 440 452 412 418 406 391 403 410 376 380 423 404 463 391 431 442 436 459 390 440 485 483 519 491 521 452 533 526 511 514 533 497 479 451 439 449 417 437 447 449 416 451 448 431 431 423 428 457 426 378 399 395 399 391 406 377 376 388 372 362 400 384 378 359 340 372 379 369 363 381 380 390 357 338 364 347 359 410 382 412 383 372 377 378 391 373 388 380 361 378 387 409 385 385 408 389 370 373 380 373 344 379 355 328 385 358 378 368 348 393 390 410 346 374 399 358 361 367 380 371 393 375 401 412 350 422 395 390 435 401 415 430 403 437 423 492 472 455 441 468 479 482 426 478 480 449 512 466 495 524 557 582 558 534 633 631 714 674 688 726 736 674 711 655 688 649 616 582 535 584 544 531 552 570 562 594 564 565 511 551 530 564 519 475 487 496 463 481 459 469 457 429 416 464 462 450 422 416 414 438 402 387 407 412 401 439 423 413 389 468 388 390 406 397 402 370 425 402 399 358 366 417 393 392 416 453 447 397 457 410 437 473 480 409 497 448 431 422 488 442 463 442 467 415 450 405 412 481 404 434 448 445 449 448 444 403 416 402 425 410 439 436 415 434 472 429 419 418 437 435 453 444 468 484 409 476 470 454 505 500 502 517 508 564 556 586 594 667 624 669 663 683 633 681 628 712 688 643 678 686 665 709 717 671 683 703 721 732 717 757 738 765 738 721 682 702 689 649 644 628 680 621 600 667 640 633 645 613 638 590 577 571 552 587 558 518 504 478 521 512 486 533 497 471 465 480 490 476 466 459 464 474 499 432 462 455 487 455 410 458 458 463 464 426 454 473 460 497 489 471 419 434 507 459 489 447 486 457 452 464 448 445 395 441 423 405 397 413 482 439 445 426 437 434 423 411 462 414 453 409 474 383 415 427 392 398 418 394 419 430 419 416 400 398 403 394 441 442 441 399 414 393 402 410 420 438 439 415 377 425 445 431 407 422 386 415 420 420 406 422 412 385 392 411 406 397 440 398 403 413 395 373 388 389 400 393 364 379 340 364 353 341 346 415 360 373 365 394 378 322 363 347 344 368 363 362 378 396 362 351 374 356 379 345 397 334 381 342 376 404 333 390 391 361 366 365 413 386 382 466 406 414 387 429 389 422 396 427 439 389 443 417 391 372 399 408 395 392 419 370 354 386 398 373 376 403 378 372 392 420 378 442 365 358 377 369 369 397 400 388 424 412 444 450 451 477 485 460 474 496 468 542 476 477 497 518 490 454 493 465 431 488 426 457 463 476 465 478 473 416 483 467 473 482 451 476 458 466 444 452 468 498 440 523 443 468 465 479 498 477 507 520 470 515 474 504 523 438 457 448 488 484 469 438 452 466 414 454 457 464 454 452 454 457 470 432 452 434 394 393 398 401 390 398 405 405 391 383 371 410 349 350 350 351 377 417 406 376 341 368 340 389 381 366 403 408 346 341 336 351 407 362 344 360 429 347 382 388 381 371 362 424 365 418 462 409 490 457 423 462 506 506 523 542 566 565 601 584 574 590 553 559 454 521 480 554 463 441 463 472 441 447 488 446 473 481 455 520 469 487 477 441 453 409 435 364 412 392 392 397 378 375 382 383 395 345 406 410 351 344 355 334 367 363 366 346 381 367 386 358 384 374 396 420 362 409 375 427 373 413 415 389 442 389 464 425 396 442 460 448 478 428 460 467 465 483 480 463 468 472 481 453 462 461 480 478 435 443 452 409 447 449 435 407 463 475 427 442 441 472 409 441 453 417 432 415 447 450 491 431 482 493 535 503 523 605 554 604 617 657 674 694 705 787 742 733 722 716 699 609 638 611 587 521 493 533 536 566 564 533 524 559 562 533 606 576 528 522 533 504 457 497 451 480 423 436 414 449 437 447 429 386 420 392 415 435 381 410 385 413 387 395 420 386 403 391 459 411 418 411 419 465 419 455 431 466 442 450 442 478 469 473 446 474 480 413 454 503 513 525 532 522 531 484 536 506 549 511 500 543 570 529 558 527 544 525 583 502 521 499 507 548 536 548 495 496 536 548 547 570 548 562 591 581 667 534 625 640 640 666 612 690 705 721 736 777 814 814 811 902 832 837 886 717 823 749 713 726 684 661 676 662 651 634 587 650 666 700 633 685 653 659 636 631 591 634 585 547 543 521 566 528 501 501 449 487 480 453 495 467 494 446 461 435 458 417 450 471 471 459 477 434 485 532 525 466 482 462 505 502 472 529 554 569 540 518 539 592 584 574 565 589 554 592 541 580 653 581 625 625 579 619 639 655 629 638 621 583 608 663 694 628 617 711 648 653 688 680 648 676 638 644 627 627 665 657 676 682 670 654 661 704 636 674 723 708 656 680 722 669 711 742 749 714 795 717 725 766 721 701 666 681 664 577 618 556 597 603 538 563 583 572 579 547 573 600 581 584 592 529 539 478 534 512 503 499 468 482 507 473 506 460 505 529 506 492 497 509 465 454 476 502 483 445 499 428 455 466 467 501 488 460 416 451 442 444 402 450 454 476 468 470 411 459 464 449 426 439 471 406 415 422 470 449 398 403 431 423 410 396 404 440 404 410 396 402 382 378 397 384 411 425 450 399 408 412 386 385 384 398 380 389 383 373 370 390 391 404 452 404 439 421 464 469 524 543 576 542 542 540 617 560 582 554 521 515 471 484 491 435 476 470 464 431 450 457 422 447 442 446 456 468 477 460 471 439 429 455 412 391 404 392 403 379 409 387 340 366 362 353 357 324 384 331 343 337 342 314 353 361 337 349 343 358 331 338 368 357 307 368 337 330 316 334 369 346 356 365 338 356 359 350 334 319 328 311 350 354 351 359 341 334 319 338 330 330 359 311 309 356 326 348 323 355 350 330 350 360 324 351 363 341 337 348 338 356 373 348 392 403 349 378 367 388 392 408 407 448 468 438 469 463 431 465 497 494 438 426 429 415 426 421 408 409 424 380 380 416 385 387 381 423 419 407 417 427 416 442 396 384 400 366 369 365 379 350 363 348 358 339 304 325 360 348 349 326 379 347 342 334 315 335 333 325 330 335 318 345 343 345 344 322 299 347 338 323 322 341 348 351 344 326 330 342 338 376 367 381 328 352 369 367 346 356 363 382 401 353 367 404 349 376 348 358 350 359 354 389 371 395 378 363 357 364 378 411 400 372 439 422 412 422 381 453 401 433 437 442 479 526 507 589 590 597 638 635 619 697 680 710 657 657 628 602 582 554 500 503 546 449 484 493 472 502 520 484 541 516 544 565 605 535 548 536 551 560 538 493 514 505 434 451 495 473 453 437 446 473 455 469 455 459 440 409 477 444 472 437 435 409 438 431 455 419 457 406 448 436 428 393 463 428 362 407 409 375 378 409 416 421 443 428 427 406 419 440 441 410 406 383 402 428 448 433 467 494 470 449 455 421 478 458 397 443 443 427 456 469 458 457 465 495 506 478 431 501 550 554 569 614 647 631 677 727 799 817 830 936 1044 1009 1029 1082 1041 933 956 903 883 819 757 715 692 635 592 597 630 656 658 695 646 665 708 662 720 707 709 752 674 730 608 674 592 550 550 497 466 452 466 472 399 431 405 395 402 417 392 373 431 367 393 369 339 421 371 381 368 360 385 298 377 373 355 357 370 350 331 330 348 388 355 367 365 344 339 361 388 359 419 373 349 340 336 365 332 341 346 380 364 361 339 351 330 343 339 347 315 340 350 360 302 354 314 392 358 371 338 359 369 395 342 389 319 375 396 369 393 406 350 414 360 379 365 386 381 388 370 362 336 366 349 344 383 302 344 311 346 322 345 368 349 358 393 389 372 338 382 362 355 393 369 344 383 382 377 331 369 338 353 366 368 393 333 351 373 395 408 348 345 371 378 331 374 380 355 380 385 387 408 402 379 383 413 346 331 352 362 327 371 381 381 403 391 383 370 383 332 363 383 377 361 373 396 368 367 379 386 326 378 394 388 384 413 388 383 432 402 404 382 434 399 438 424 407 407 403 419 444 386 417 427 448 474 445 459 430 514 508 538 584 617 616 706 718 727 743 822 839 859 866 908 836 807 736 695 676 621 577 578 589 529 563 494 516 523 573 586 555 569 624 592 676 616 662 621 623 572 557 550 505 524 479 462 440 448 423 406 410 393 366 408 399 375 385 371 347 395 329 361 372 368 366 362 352 338 370 393 347 354 379 348 357 355 380 348 333 350 396 332 395 429 403 366 351 357 354 370 364 350 355 363 412 364 384 349 377 357 378 362 383 405 356 401 345 390 374 407 372 361 326 377 367 372 409 343 349 355 370 378 369 397 403 376 384 441 417 409 428 417 444 426 407 401 444 387 388 396 400 401 392 371 383 369 357 384 369 378 357 420 348 346 383 392 394 391 327 366 390 362 420 355 375 354 348 339 343 365 347 353 363 354 328 362 357 354 330 319 310 336 333 356 345 317 353 350 321 360 312 329 326 292 342 320 294 340 312 337 341 326 318 329 360 352 335 309 340 351 314 353 324 317 367 343 368 352 348 333 337 338 371 340 350 370 364 332 357 370 348 339 328 337 379 391 389 401 351 394 387 415 375 424 399 414 459 432 463 460 479 467 501 514 554 570 563 523 575 533 568 538 561 557 534 523 510 488 505 482 476 475 484 491 526 517 559 496 570 516 513 529 493 513 492 514 535 460 476 456 496 470 455 432 507 471 468 433 434 454 419 411 399 429 447 425 440 413 447 402 387 417 434 383 412 385 404 414 374 368 358 363 372 381 386 396 383 354 349 347 383 372 382 348 385 370 388 356 382 340 349 350 358 372 379 356 349 350 366 403 376 380 366 366 366 409 350 392 388 344 390 399 396 388 387 440 395 431 473 439 461 528 526 593 566 652 602 633 589 629 593 614 594 637 567 533 532 486 491 457 495 452 527 456 520 445 505 443 515 487 543 496 542 519 505 488 482 508 523 513 511 475 472 491 491 460 457 469 415 477 468 428 429 440 438 439 415 406 366 397 371 401 442 400 423 429 370 384 428 401 415 417 359 412 436 449 403 385 414 417 408 409 413 437 424 434 442 413 436 444 372 413 401 444 429 445 428 424 420 398 427 407 415 386 362 411 369 406 350 366 396 377 425 395 401 352 411 384 391 376 395 396 407 401 430 424 461 380 365 416 413 414 393 385 383 399 372 371 364 346 346 337 397 365 375 411 388 371 368 399 394 382 348 366 353 382 365 362 358 374 365 356 347 309 366 343 383 336 355 362 375 336 307 344 360 370 348 374 332 332 348 326 333 349 348 333 354 350 323 354 346 380 346 310 333 337 361 339 356 368 331 352 327 328 321 387 342 381 331 373 335 347 363 355 363 361 356 313 350 355 322 327 369 330 373 349 379 366 351 365 360 383 381 343 357 407 352 370 399 389 459 431 434 422 430 460 472 496 510 559 535 557 543 565 530 582 506 572 493 508 432 490 463 443 465 408 438 396 443 423 443 438 467 460 477 432 449 429 428 483 516 461 475 417 442 392 457 383 403 421 389 446 393 354 410 378 401 397 363 378 344 348 335 376 333 340 331 334 354 360 344 347 343 351 331 345 338 333 365 317 374 341 341 350 374 378 354 329 352 365 329 333 343 355 333 320 360 366 321 356 352 360 368 371 366 354 369 383 383 374 375 358 359 327 380 331 342 333 357 358 316 393 333 355 348 381 342 322 335 342 329 337 362 313 371 347 339 327 328 344 312 342 341 304 351 342 350 323 319 328 330 305 334 298 321 329 313 358 362 328 358 353 323 334 347 344 362 346 317 332 287 327 331 340 349 368 320 326 345 329 350 361 329 348 331 316 361 358 343 334 336 352 345 336 349 337 320 359 313 345 335 362 362 358 345 350 319 329 376 322 396 347 343 345 338 352 357 339 348 356 349 369 368 347 363 317 391 343 352 365 375 390 380 383 364 351 388 375 374 376 386 410 411 389 441 398 428 449 439 497 486 536 552 540 585 619 571 627 649 611 589 596 547 597 546 529 503 501 478 480 459 463 455 500 476 493 523 516 510 515 525 513 575 586 537 548 586 569 646 590 575 517 548 532 537 487 530 490 480 529 515 535 456 520 490 495 482 480 464 432 478 400 475 445 468 454 473 453 486 468 449 445 439 439 435 438 434 465 462 455 426 453 477 399 460 396 432 446 449 400 423 426 425 438 443 430 420 391 401 383 412 415 459 412 422 407 463 483 460 443 416 450 429 444 503 508 460 536 517 539 531 645 607 634 691 675 762 738 765 773 765 810 830 835 736 715 705 678 678 644 578 576 558 574 536 533 581 550 518 598 544 573 597 602 623 624 595 627 662 639 661 657 586 603 609 604 558 555 554 542 507 478 483 485 443 468 459 458 410 462 451 412 424 436 446 463 419 417 441 422 429 429 421 408 394 387 385 398 387 428 419 412 413 379 377 453 404 412 349 394 392 343 367 368 388 412 368 385 348 397 351 406 402 371 341 383 409 377 347 367 402 350 400 377 356 361 399 350 436 421 399 413 472 442 438 425 483 456 513 521 522 543 579 583 584 556 589 552 532 437 547 461 457 434 452 416 418 429 413 407 401 388 442 402 409 422 442 455 459 449 442 477 472 472 519 474 430 443 444 438 442 429 411 402 401 377 377 364 334 363 383 408 322 375 335 358 344 382 336 416 359 369 329 373 340 367 362 329 360 354 358 321 337 356 354 341 313 350 361 352 357 347 324 328 329 372 365 339 350 346 330 352 374 386 342 348 321 376 350 363 366 366 341 345 393 362 334 351 363 380 377 371 371 373 396 402 408 404 432 402 403 437 455 452 489 500 480 493 476 465 489 495 480 467 404 373 384 436 397 374 380 379 403 367 389 379 377 385 379 375 370 406 374 418 418 417 429 434 447 401 435 420 391 365 421 417 419 390 413 414 416 393 408 427 367 391 383 405 373 380 405 372 357 331 350 356 357 381 351 337 341 349 383 333 333 337 314 330 327 365 336 386 377 370 370</counts>
			</dataPoints>
		</scan>
	</xrdMeasurement>
</xrdMeasurements>