File: dataset/precursor_mixture/ZnO_0p4006-In2O3_0p6008--8min.xrdml
<?xml version="1.0"?>
<xrdMeasurements xmlns="http://www.xrdml.com/XRDMeasurement/2.3" xmlns:xsi="http://www.w3.org/2001/XMLSchema-instance" xsi:schemaLocation="http://www.xrdml.com/XRDMeasurement/2.3 http://www.xrdml.com/XRDMeasurement/2.3/XRDMeasurement.xsd" status="Completed" recordIdentifier="{0B52E068-3A79-44BE-BCD8-71FCFC526B40}">
	<comment>
		<entry/>
	</comment>
	<sample type="To be analyzed">
		<id>ZnO_0p4006-In2O3_0p6008--8min</id>
		<name></name>
		<preparedBy></preparedBy>
	</sample>
	<xrdMeasurement measurementType="Scan" status="Completed" sampleMode="Reflection">
		<usedWavelength intended="K-Alpha 1">
			<kAlpha1 unit="Angstrom">1.5405980</kAlpha1>
			<kAlpha2 unit="Angstrom">1.5444260</kAlpha2>
			<kBeta unit="Angstrom">1.3922500</kBeta>
			<ratioKAlpha2KAlpha1>0.5000</ratioKAlpha2KAlpha1>
		</usedWavelength>
		<incidentBeamPath>
			<radius unit="mm">145.00</radius>
			<xRayTube id="1010048" name="Empyrean Cu LFF HR (9430 033 7310x)">
				<tension unit="kV">40.0</tension>
				<current unit="mA">15.0</current>
				<anodeMaterial>Cu</anodeMaterial>
				<focus type="Line">
					<length unit="mm">12.0</length>
					<width unit="mm">0.4</width>
					<takeOffAngle unit="deg">6.0</takeOffAngle>
				</focus>
			</xRayTube>
			<sollerSlit id="21010002" name="Soller slits 0.04 rad.">
				<opening unit="rad">0.0400</opening>
			</sollerSlit>
			<mask id="22031000" name="Fixed mask 13 mm">
				<width unit="mm">9.00</width>
			</mask>
			<divergenceSlit id="22120001" name="Divergence slit 1°" xsi:type="fixedDivergenceSlitType">
				<distanceToSample unit="mm">50.00</distanceToSample>
				<height unit="mm">1.52</height>
			</divergenceSlit>
		</incidentBeamPath>
		<sampleMovement xsi:type="spinningSampleMovementType">
			<spinnerRevolutionTime unit="seconds">1.0</spinnerRevolutionTime>
		</sampleMovement>
		<diffractedBeamPath>
			<radius unit="mm">145.00</radius>
			<antiScatterSlit id="22090040" name="AS slit 9 mm (PIXcel)" xsi:type="fixedAntiScatterSlitType">
				<height unit="mm">9.00</height>
			</antiScatterSlit>
			<sollerSlit id="21020003" name="Large Soller slits 0.04 rad.">
				<opening unit="rad">0.0400</opening>
			</sollerSlit>
			<filter id="20030001" name="Large beta-filter Nickel">
				<material>Ni</material>
				<thickness unit="mm">0.020</thickness>
			</filter>
			<detector id="7010019" name="PIXcel1D-Medipix3 detector" xsi:type="rtmsDetectorType">
				<phd unit="keV">
					<lowerLevel>4.02</lowerLevel>
					<upperLevel>11.27</upperLevel>
				</phd>
				<mode>Scanning</mode>
				<activeLength unit="deg">5.542</activeLength>
			</detector>
		</diffractedBeamPath>
		<scan appendNumber="0" mode="Continuous" scanAxis="Gonio" status="Completed">
			<header>
				<startTimeStamp>2024-11-14T13:43:29-08:00</startTimeStamp>
				<endTimeStamp>2024-11-14T13:51:36-08:00</endTimeStamp>
				<author>
					<name>AutomatedUser</name>
				</author>
				<source>
					<applicationSoftware version="1.7b (136)">PANalytical Aeris Instrument Suite</applicationSoftware>
					<instrumentControlSoftware version="3.2.00000000 20240306">AERIS</instrumentControlSoftware>
					<instrumentID>950485</instrumentID>
				</source>
			</header>
			<dataPoints>
				<positions axis="2Theta" unit="deg">
					<startPosition>10.00943322</startPosition>
					<endPosition>99.99442286</endPosition>
				</positions>
				<positions axis="Omega" unit="deg">
					<startPosition>5.00471661</startPosition>
					<endPosition>49.99721143</endPosition>
				</positions>
				<commonCountingTime unit="seconds">12.495</commonCountingTime>
				<counts unit="counts">2226 2195 2196 2226 2182 2233 2275 2177 2186 2209 2101 2180 2158 2202 2087 2218 2097 2239 2190 2197 2150 2242 2052 2143 2163 2134 2132 2129 2262 2157 2106 2153 2120 2187 2049 2201 2175 2202 2029 2129 2175 2058 2085 2061 2060 2106 2126 2098 2127 2131 2084 2113 2075 2088 2079 2117 2076 2066 2159 2043 2032 2004 2073 1993 1998 2082 2021 2060 2116 1938 2014 2011 2017 1946 2045 2059 2025 1995 1965 2038 2016 2001 1993 2076 1954 1971 2070 1933 2010 1969 2046 1970 1868 1997 2004 1946 1937 2018 1980 2038 1967 1923 2012 1868 2057 1902 1926 1864 1954 1934 1924 1925 1930 1935 1990 1859 1928 1912 1957 2037 1945 1855 1859 1909 1965 1933 1931 1848 1852 1914 1872 1833 1934 1905 1895 1917 1803 1943 1900 1827 1939 1783 1820 1907 1915 1907 1803 1789 1855 1826 1804 1895 1812 1811 1814 1818 1860 1803 1900 1873 1834 1756 1913 1786 1812 1791 1813 1806 1775 1811 1824 1760 1858 1760 1705 1828 1707 1678 1746 1739 1761 1787 1752 1655 1841 1767 1722 1779 1703 1783 1772 1809 1761 1739 1727 1811 1718 1689 1743 1792 1722 1661 1739 1733 1779 1660 1684 1782 1673 1741 1722 1667 1758 1691 1689 1677 1733 1714 1735 1671 1696 1709 1659 1687 1722 1703 1721 1642 1638 1699 1725 1634 1609 1643 1676 1673 1697 1684 1724 1636 1687 1627 1653 1668 1691 1671 1631 1576 1631 1625 1660 1613 1618 1658 1610 1692 1680 1607 1560 1596 1632 1623 1610 1617 1571 1641 1561 1599 1616 1592 1631 1636 1703 1609 1591 1616 1580 1661 1609 1624 1632 1589 1552 1624 1602 1553 1567 1632 1610 1599 1617 1571 1610 1578 1564 1578 1580 1612 1570 1677 1602 1623 1541 1479 1499 1527 1591 1554 1507 1592 1535 1594 1531 1600 1529 1528 1552 1529 1626 1541 1497 1492 1539 1462 1565 1551 1501 1482 1543 1468 1547 1486 1520 1487 1498 1488 1475 1498 1486 1454 1547 1380 1475 1482 1523 1509 1494 1500 1479 1577 1488 1449 1543 1476 1453 1406 1520 1506 1542 1481 1464 1461 1527 1491 1490 1449 1522 1435 1448 1448 1486 1514 1502 1452 1549 1434 1514 1483 1462 1445 1420 1469 1481 1497 1389 1455 1522 1474 1536 1445 1450 1477 1448 1506 1422 1487 1429 1405 1424 1445 1433 1404 1497 1426 1458 1405 1403 1405 1492 1411 1411 1415 1426 1461 1455 1482 1498 1482 1482 1490 1511 1402 1418 1488 1427 1440 1455 1461 1480 1469 1411 1445 1386 1459 1360 1348 1406 1486 1417 1370 1375 1407 1367 1432 1516 1410 1413 1324 1461 1480 1443 1465 1471 1449 1420 1397 1436 1426 1446 1409 1419 1412 1384 1423 1416 1418 1375 1493 1374 1376 1412 1346 1430 1362 1370 1374 1471 1356 1370 1452 1356 1398 1358 1392 1410 1401 1409 1354 1332 1344 1371 1385 1375 1355 1371 1415 1382 1450 1368 1371 1444 1337 1371 1431 1402 1382 1383 1354 1348 1376 1373 1373 1362 1363 1344 1350 1359 1329 1355 1384 1303 1374 1392 1401 1308 1332 1358 1339 1355 1387 1372 1340 1324 1403 1368 1337 1319 1337 1340 1334 1348 1232 1300 1373 1400 1332 1384 1340 1313 1345 1365 1357 1291 1328 1286 1341 1275 1324 1368 1335 1319 1356 1355 1326 1312 1285 1291 1347 1349 1303 1335 1409 1275 1329 1286 1286 1336 1277 1314 1307 1290 1252 1313 1339 1298 1355 1303 1295 1334 1314 1279 1317 1303 1368 1286 1283 1302 1288 1310 1336 1310 1402 1270 1329 1314 1317 1294 1284 1291 1273 1273 1336 1284 1277 1282 1235 1292 1261 1374 1244 1241 1248 1218 1235 1201 1290 1299 1265 1288 1245 1302 1311 1229 1252 1288 1276 1342 1278 1288 1254 1252 1361 1289 1316 1270 1295 1318 1256 1225 1200 1325 1286 1308 1315 1261 1282 1251 1310 1271 1366 1248 1301 1285 1216 1266 1302 1327 1276 1310 1295 1296 1286 1303 1242 1265 1265 1308 1279 1325 1317 1290 1212 1290 1179 1272 1211 1226 1278 1246 1212 1291 1304 1269 1296 1251 1275 1264 1296 1304 1255 1303 1228 1251 1286 1282 1337 1324 1291 1289 1310 1234 1303 1299 1247 1249 1277 1304 1209 1272 1267 1275 1249 1235 1171 1238 1227 1265 1228 1199 1263 1233 1195 1195 1209 1208 1208 1236 1207 1245 1276 1263 1231 1273 1144 1212 1232 1115 1214 1199 1261 1202 1240 1191 1196 1243 1187 1221 1198 1250 1171 1187 1190 1234 1183 1208 1242 1184 1152 1184 1180 1158 1216 1144 1154 1135 1198 1167 1187 1182 1163 1172 1204 1178 1208 1218 1208 1211 1152 1206 1140 1096 1140 1135 1151 1185 1227 1150 1242 1131 1250 1167 1178 1180 1159 1181 1234 1172 1156 1160 1159 1117 1124 1105 1162 1149 1154 1144 1186 1138 1164 1165 1088 1210 1125 1144 1165 1124 1163 1141 1114 1120 1146 1128 1135 1170 1130 1170 1145 1138 1196 1135 1188 1200 1148 1102 1145 1134 1123 1132 1120 1147 1145 1127 1115 1096 1103 1109 1116 1160 1118 1073 1097 1151 1108 1147 1225 1119 1110 1149 1127 1150 1175 1132 1133 1060 1048 1181 1116 1119 1085 1101 1089 1123 1134 1150 1128 1096 1211 1150 1129 1138 1093 1090 1063 1101 1130 1067 1106 1052 1108 1108 1102 1137 1156 1107 1148 1104 1062 1099 1164 1085 1068 1104 1084 1113 1120 1094 1079 1092 1079 1002 1004 997 1097 1076 1092 1062 1050 1056 1057 1129 1039 1098 1079 1072 1079 1040 1096 1085 1091 1112 1024 1054 1125 1014 1097 1057 1057 1109 1097 1015 1049 1083 982 1048 1073 1070 1042 1106 1069 1100 1003 1092 1087 1104 1090 1031 1044 1111 1060 1056 1042 1083 1065 978 1070 1103 1045 1099 1001 1099 997 1075 1024 1077 1071 1067 1103 960 968 1094 1029 1074 1007 1072 1012 1067 1043 1081 993 1050 1077 1063 1008 1059 964 1027 1104 1058 1138 1033 1014 1018 1007 1089 1056 1035 1043 1069 1039 1108 1096 1054 1128 1098 1115 1089 1095 1101 1112 1131 1091 1174 1130 1101 1155 1158 1215 1164 1247 1237 1258 1287 1292 1316 1382 1371 1437 1466 1526 1591 1667 1696 1795 1786 1984 2074 2091 2280 2349 2550 2682 2765 2909 3051 3154 3325 3375 3650 3590 3745 3714 3622 3555 3395 3425 3114 3006 2860 2672 2525 2168 2035 1855 1772 1617 1488 1460 1343 1298 1236 1184 1216 1156 1143 1137 1102 1132 1119 1066 1048 1131 1079 1063 1062 1086 1021 1092 1051 1114 1041 1029 1008 1004 996 1023 973 1096 970 1005 1004 964 1015 1020 1021 961 1011 1018 976 977 1047 1020 1003 964 976 1021 937 959 970 966 1010 941 958 970 968 933 933 955 964 971 969 965 962 986 989 934 1009 971 958 969 1003 903 942 942 934 919 976 976 939 941 975 963 1010 937 990 935 928 893 933 937 925 932 947 968 944 943 1036 864 943 910 916 975 924 940 946 938 981 900 871 944 904 913 991 994 954 859 934 913 893 951 920 893 903 918 881 943 891 935 900 904 889 921 894 912 895 891 844 908 907 918 894 926 904 893 902 861 902 937 922 919 922 931 909 898 900 963 881 896 946 896 954 888 922 844 829 944 937 947 912 890 913 837 863 962 937 875 873 878 894 898 899 924 886 912 839 839 863 912 907 890 952 877 865 880 847 910 835 915 879 885 805 931 888 890 932 908 820 921 862 874 898 887 921 890 900 880 899 899 882 867 900 934 865 852 871 900 846 875 878 831 921 889 888 854 866 845 894 832 902 851 858 925 834 903 841 920 882 829 873 836 858 840 861 853 842 831 927 901 848 815 830 829 879 848 901 865 838 819 858 833 880 854 798 857 775 872 864 843 875 813 878 828 887 883 900 933 834 854 841 842 844 797 857 814 847 835 822 860 787 769 838 862 781 835 872 790 807 807 902 779 835 876 820 838 825 819 828 810 805 829 817 823 764 862 753 796 799 857 802 823 796 822 781 798 785 853 802 827 829 816 850 845 803 813 810 830 773 775 894 827 768 815 788 760 805 771 808 815 825 795 825 820 759 844 816 766 815 824 819 807 806 820 821 797 811 830 762 788 782 803 782 832 753 771 754 774 838 800 827 722 818 767 801 761 809 839 799 847 800 835 806 795 800 796 718 840 811 775 794 776 787 786 815 811 716 773 791 818 813 753 821 795 787 797 748 779 762 799 713 767 756 846 793 824 782 768 755 767 767 717 799 759 797 808 765 715 819 754 733 724 771 774 792 798 790 788 748 803 734 743 757 789 754 733 810 749 768 766 756 762 762 727 734 757 748 792 790 796 701 756 753 764 732 721 792 770 799 814 778 779 783 732 802 785 793 765 700 724 712 724 751 739 778 758 838 741 800 743 723 797 733 734 712 773 770 729 792 752 806 761 772 758 774 783 761 737 794 760 773 783 762 817 833 830 902 856 860 799 781 799 827 835 836 906 778 803 731 794 813 793 742 807 791 785 795 733 747 795 750 765 738 723 754 707 766 760 758 724 746 726 732 730 722 764 701 747 751 705 738 728 717 761 686 731 730 744 761 778 747 726 710 719 748 746 724 767 748 724 790 724 771 763 772 697 789 731 711 707 755 689 697 724 719 752 736 772 706 693 689 722 713 749 735 678 735 724 736 698 720 671 754 696 746 714 778 785 722 722 711 699 731 695 746 720 743 773 767 666 807 754 726 733 742 720 688 766 742 755 696 701 678 737 744 677 711 728 728 671 720 734 708 681 758 774 713 733 709 693 710 708 733 716 759 746 715 722 692 737 709 719 714 707 712 722 735 710 778 787 747 715 769 709 719 787 793 770 777 769 759 767 776 834 779 801 795 820 824 838 855 872 845 920 817 919 880 909 893 973 902 904 895 923 951 958 876 976 926 906 1012 924 982 924 950 996 992 958 1022 995 1004 989 1024 1042 1043 1068 1138 1062 1144 1069 1082 1089 1123 1113 1107 1160 1256 1274 1280 1320 1237 1315 1314 1390 1463 1437 1461 1594 1557 1591 1693 1665 1697 1799 1757 1842 1908 1971 2167 2222 2341 2382 2584 2686 2887 3278 3396 3837 4115 4484 5045 5595 6228 6790 7783 8511 9575 11060 12151 13628 15327 17067 18867 20768 22626 24773 26337 27548 28917 28756 29221 28778 28031 27396 25959 24299 22443 20544 18533 16432 14616 12620 10965 9330 8143 7007 6033 5277 4588 4062 3649 3230 2975 2837 2504 2496 2321 2183 2145 2048 1980 1830 1835 1826 1805 1648 1656 1535 1496 1403 1402 1418 1314 1342 1369 1265 1250 1210 1187 1186 1141 1156 1092 1108 1084 1096 1096 1103 1119 1033 1084 1056 1098 1007 993 1065 1030 1088 1041 1031 1110 1019 1037 1055 1076 1072 1095 1057 1136 1094 1108 1228 1178 1285 1241 1296 1353 1407 1506 1524 1608 1701 1760 1884 2128 2409 2505 2780 2942 3190 3699 3989 4246 4481 4868 5062 5318 5560 5620 5845 5695 5530 5407 5458 5108 4856 4498 4308 3958 3566 3336 2785 2589 2446 2174 1926 1664 1579 1509 1439 1343 1122 1208 1103 1102 1091 1012 1012 1001 983 920 945 892 914 875 829 920 898 866 805 875 839 850 800 812 809 765 810 807 752 788 779 802 751 796 762 778 739 798 762 771 802 738 708 744 758 756 768 739 720 723 795 760 722 748 766 736 755 746 764 740 681 706 742 749 725 757 710 749 728 766 708 719 698 734 773 735 705 751 699 755 728 713 735 794 758 792 878 825 864 866 860 875 896 917 926 956 1029 1052 1024 1101 1056 1077 1048 1021 1103 988 993 1008 890 938 868 920 875 816 800 850 814 802 761 719 781 751 715 670 684 814 739 778 706 747 733 717 721 710 712 717 707 720 709 709 728 704 649 714 663 727 630 710 724 725 715 654 681 727 718 688 698 718 685 700 682 735 704 720 708 673 691 684 647 730 731 704 672 675 731 754 716 770 722 735 746 717 738 755 736 717 797 758 772 791 763 715 824 837 838 880 904 834 863 944 918 957 971 988 1135 1149 1242 1433 1554 1727 1720 2090 2336 2406 2751 2954 3133 3566 3650 3987 4211 4261 4487 4452 4174 4299 4017 3953 3773 3581 3218 3064 2740 2500 2252 2226 1871 1733 1559 1461 1316 1112 1151 1059 1014 1005 1024 937 901 902 866 903 934 828 871 900 855 816 862 832 894 882 817 883 875 904 851 885 782 865 904 901 890 885 900 914 976 957 985 1003 954 1025 1104 1087 1072 1099 1110 1141 1219 1152 1262 1222 1338 1363 1462 1575 1594 1798 1846 1943 2143 2256 2596 2733 3069 3360 3789 4244 4899 5351 5732 6520 6973 7568 8241 8532 8910 8979 9045 9043 8772 8218 8010 7805 7156 6731 6103 5389 5051 4660 4069 3588 3261 2927 2587 2302 1988 2019 1721 1691 1578 1411 1370 1414 1303 1306 1289 1260 1215 1239 1215 1211 1214 1194 1166 1193 1171 1184 1173 1254 1142 1239 1312 1276 1332 1304 1465 1523 1490 1585 1794 1848 1966 2134 2334 2464 2739 3106 3276 3694 4180 4769 5132 5693 6301 6942 7459 7916 8341 8762 8869 9035 8911 8735 8615 8226 8014 7535 6971 6619 6080 5467 4946 4535 3942 3547 3206 2773 2436 2339 1979 1842 1680 1560 1369 1371 1248 1196 1181 1086 1115 1032 1015 983 1000 923 942 891 886 827 866 855 877 799 844 777 765 761 758 731 723 715 738 705 739 680 697 741 681 705 678 696 671 680 678 688 658 665 625 754 662 680 639 653 630 643 719 659 671 675 652 633 688 694 648 641 670 677 640 672 599 670 681 685 663 663 648 660 676 645 686 660 671 642 707 703 715 659 698 676 703 766 738 748 797 839 895 884 900 1006 1005 1140 1220 1272 1379 1475 1597 1706 1863 1941 2061 2000 2078 2071 2259 2093 2034 1963 1858 1744 1743 1626 1518 1440 1297 1220 1203 1013 1016 949 910 872 820 748 741 702 666 685 678 692 665 657 649 603 584 627 683 630 639 606 610 622 599 644 572 634 556 606 564 583 563 596 590 591 590 554 591 519 563 588 550 558 559 551 625 542 589 559 539 565 570 528 600 575 576 598 531 555 544 549 593 516 566 533 537 589 567 547 536 546 538 548 595 537 534 576 576 559 563 576 561 499 549 546 567 558 552 564 506 500 547 525 504 567 559 567 532 575 515 516 545 571 528 551 534 562 542 480 548 521 526 538 528 498 509 489 518 523 509 528 531 525 540 550 523 561 528 590 544 552 487 529 523 550 484 576 511 574 502 564 528 517 522 511 507 536 551 535 513 516 500 512 568 534 533 592 581 579 566 588 604 540 561 550 647 558 652 664 667 684 761 733 807 766 812 782 834 840 810 835 815 798 843 792 802 731 758 718 713 652 663 621 595 639 590 593 577 522 536 514 521 530 517 501 511 566 550 501 540 511 567 470 496 485 515 504 480 520 484 507 482 492 528 506 488 522 476 470 476 470 511 518 467 495 472 501 507 464 475 473 474 486 479 515 476 508 483 480 497 503 493 516 499 510 506 526 476 471 479 493 509 497 474 470 500 490 460 514 522 483 503 459 502 499 500 512 471 502 495 488 482 457 514 481 483 471 506 502 515 483 490 511 539 533 515 493 520 520 513 527 505 457 493 495 465 478 495 488 511 451 535 516 521 493 531 551 528 555 498 499 566 499 518 475 581 523 515 515 499 540 524 539 563 544 546 513 551 520 577 562 609 596 601 601 610 642 673 674 713 696 805 766 753 874 930 1024 1093 1251 1378 1353 1555 1617 1712 1761 1766 1750 1704 1718 1735 1688 1593 1562 1478 1475 1328 1274 1169 1091 1064 1001 952 865 770 726 713 690 651 641 627 617 575 614 528 530 510 567 547 548 508 532 553 518 464 533 514 519 506 503 484 485 489 508 494 488 483 459 452 428 495 459 480 478 472 509 506 494 470 457 475 459 454 485 445 499 453 450 528 448 497 429 485 418 470 467 436 499 441 539 438 469 464 487 450 464 459 470 465 461 448 444 456 475 500 444 473 455 477 450 433 473 424 489 428 440 447 440 457 490 438 446 455 424 429 461 462 439 451 475 448 452 464 485 444 462 427 440 490 481 454 473 445 449 463 470 419 451 391 476 433 459 522 463 431 454 473 420 455 450 482 459 485 468 462 454 455 493 454 506 472 472 498 510 536 590 566 560 541 635 599 673 695 677 642 696 699 708 690 720 719 655 654 657 679 646 621 609 594 575 584 564 571 528 482 496 492 508 467 478 461 488 486 446 480 478 474 499 475 449 444 463 444 486 422 451 454 430 439 475 433 451 479 454 447 446 436 423 469 452 428 434 462 405 409 491 422 469 472 409 441 467 422 454 441 439 433 447 438 433 455 407 439 444 450 463 439 498 485 462 501 439 442 464 459 475 481 423 451 440 463 399 458 465 444 440 432 436 447 451 442 404 425 473 444 459 456 472 491 434 484 429 467 464 452 451 449 485 456 499 466 479 490 480 458 484 498 500 507 449 570 549 492 517 530 552 542 558 557 547 551 555 559 594 554 629 601 616 623 654 717 690 757 749 818 835 906 970 1055 1232 1340 1480 1662 1892 2089 2222 2413 2556 2655 2700 2714 2733 2687 2660 2541 2531 2406 2349 2175 2168 2083 1895 1824 1642 1510 1394 1328 1183 1135 1006 896 834 822 725 737 697 658 654 644 620 589 571 560 547 529 529 560 525 501 483 524 481 505 517 457 484 494 481 492 487 534 440 446 451 456 450 457 460 453 466 477 480 471 432 494 468 506 441 494 447 426 453 448 475 442 464 442 401 423 440 432 426 462 427 466 387 461 448 459 466 469 445 456 458 442 439 444 440 440 475 446 438 469 416 480 454 429 435 451 456 443 479 447 452 442 465 474 430 489 440 438 419 434 454 413 455 436 471 463 492 463 473 462 486 471 528 540 523 516 522 518 482 486 516 513 524 563 567 543 568 598 596 664 713 699 790 806 847 860 949 1124 1105 1233 1335 1516 1659 1645 1864 2040 2049 2171 2232 2130 2174 2051 2028 2038 1886 1925 1791 1651 1610 1614 1550 1413 1268 1237 1212 1095 984 956 873 731 763 639 634 637 604 591 611 545 501 515 495 610 522 483 497 470 521 504 501 441 478 467 463 436 426 435 442 383 455 452 393 472 439 442 418 465 478 446 454 408 455 427 447 434 492 411 445 406 419 394 439 415 413 422 394 415 450 392 387 393 420 397 412 446 441 446 399 432 440 423 415 404 414 433 458 424 414 437 451 409 419 449 445 444 433 479 396 432 390 458 415 394 416 409 438 407 430 444 475 409 428 403 436 420 450 423 419 489 457 468 481 424 530 463 488 455 489 471 486 491 522 512 588 560 592 593 610 653 641 715 729 817 863 958 1032 1058 1119 1070 1122 1080 1117 1008 1068 980 1020 957 1007 914 924 863 854 810 842 747 705 702 660 675 579 575 563 578 509 580 517 519 548 480 541 521 487 482 506 461 489 509 477 489 437 423 476 486 500 455 456 515 484 489 494 469 489 449 471 484 482 463 476 498 447 486 468 475 511 459 487 479 515 472 497 486 486 521 495 483 528 492 513 504 489 489 530 520 535 504 532 505 545 555 557 565 571 550 528 586 546 522 588 590 565 575 608 616 635 616 602 629 676 600 671 625 719 713 746 727 721 728 762 754 762 814 814 795 844 899 932 918 956 1013 959 1088 1028 1105 1109 1224 1286 1304 1406 1507 1513 1652 1734 1945 2078 2354 2567 2829 3289 3817 4362 4960 5514 6306 7328 8012 8818 9274 9443 9807 9924 9804 9445 9158 8838 8266 8072 7730 7459 7236 6915 6518 6140 5852 5468 5072 4554 4195 3842 3384 2905 2640 2313 2092 1763 1548 1534 1388 1311 1203 1157 1121 1079 1046 972 1017 881 857 820 874 826 834 778 772 692 699 683 736 652 683 606 626 637 630 584 627 569 593 583 635 558 545 535 582 539 500 525 542 508 508 532 538 504 541 524 481 523 519 524 507 483 464 504 468 507 465 449 465 491 481 470 479 495 462 463 435 501 453 471 453 475 468 475 482 460 453 445 474 446 445 449 449 461 438 496 493 472 524 406 476 431 436 468 443 425 479 482 456 477 473 472 508 484 464 493 468 506 485 529 512 510 548 590 622 629 581 679 732 743 833 859 954 912 1023 958 996 994 971 949 915 896 854 837 822 870 770 798 782 770 742 655 726 644 589 610 562 565 589 472 473 461 488 490 441 498 453 463 446 430 428 430 447 425 427 430 424 430 428 448 418 396 440 461 419 446 441 415 413 386 418 376 406 428 410 442 375 445 409 420 382 433 397 394 395 424 403 444 361 368 366 414 366 394 407 395 386 410 404 416 425 376 396 400 365 397 373 412 407 439 400 416 409 412 404 408 413 395 392 420 395 423 399 425 406 396 454 458 402 452 399 425 405 403 432 374 410 403 426 435 456 426 407 395 460 427 432 379 439 388 429 470 396 498 398 475 456 420 436 496 522 487 511 525 486 528 494 559 503 523 528 504 479 547 472 478 505 468 453 474 463 504 493 492 479 450 463 485 458 453 469 471 438 422 437 438 469 441 416 400 450 434 432 397 378 424 378 365 431 412 397 413 385 389 397 404 398 418 417 419 397 396 397 428 382 376 382 405 382 407 438 396 430 437 408 397 411 412 416 438 429 418 416 428 400 414 439 406 425 410 390 415 442 419 385 409 423 447 465 416 448 445 422 423 436 457 423 452 430 433 466 451 443 425 466 448 477 475 445 478 478 480 463 511 487 478 493 485 531 533 466 530 529 566 560 514 554 574 589 616 632 587 662 695 751 783 853 876 1022 1105 1264 1327 1423 1499 1594 1620 1640 1715 1640 1559 1560 1529 1448 1443 1387 1330 1350 1268 1224 1293 1210 1192 1160 1106 996 992 952 862 832 813 754 732 714 680 684 668 679 646 710 653 750 716 774 759 712 722 804 828 894 1053 1007 1087 1233 1331 1495 1704 1828 1989 2331 2471 2713 2888 3021 3089 3149 3116 3078 3006 2820 2696 2660 2416 2453 2284 2250 2259 2108 2186 2070 1931 1848 1730 1646 1478 1387 1246 1144 1022 1017 888 739 750 684 707 659 654 615 643 589 602 542 539 544 524 490 504 485 507 529 461 481 491 493 478 504 428 426 444 456 472 465 440 430 492 452 480 488 441 434 477 456 472 440 420 448 425 417 495 454 521 488 502 517 568 523 580 579 607 629 645 688 670 730 717 643 694 702 633 651 650 637 617 601 622 610 578 554 522 571 555 558 526 498 513 489 488 428 486 446 446 406 435 419 438 395 427 391 440 410 423 420 432 390 411 414 409 370 432 422 420 385 395 435 425 399 399 417 413 385 398 432 401 399 418 403 394 379 438 423 428 420 430 398 405 418 407 365 406 447 430 420 393 401 414 381 449 451 473 438 428 409 410 479 466 450 441 435 475 461 442 446 398 442 393 436 433 444 453 445 441 471 415 451 444 458 475 464 448 474 477 526 488 497 520 541 553 527 540 573 527 602 579 645 661 698 711 747 886 904 1040 1087 1157 1265 1374 1398 1443 1477 1389 1424 1326 1359 1253 1156 1114 1099 1114 1134 1135 1113 1072 1059 1021 988 978 929 857 803 814 727 705 614 598 604 648 556 566 508 523 540 459 496 483 461 455 535 499 513 481 518 499 504 482 509 517 455 489 494 460 505 479 479 469 478 504 491 470 468 498 499 506 496 460 461 493 467 502 468 493 498 531 497 512 517 529 481 558 549 538 521 567 546 574 581 557 534 566 542 593 607 596 598 631 645 693 622 685 628 677 676 681 717 736 739 771 796 757 814 790 878 905 962 968 968 1035 1078 1042 1115 1147 1175 1385 1407 1511 1676 1758 2030 2136 2352 2728 3059 3545 4005 4535 5152 5780 6198 6486 6782 6797 6704 6592 6413 6084 5828 5478 5201 4841 4512 4534 4372 4439 4335 4364 4259 4185 3950 3795 3365 3186 2922 2638 2249 2111 1839 1643 1477 1353 1282 1196 1105 1067 981 893 889 861 825 881 819 794 758 760 714 708 721 705 624 675 665 656 621 635 611 612 531 584 550 600 588 524 546 505 513 534 615 547 494 512 506 521 545 512 509 502 532 510 491 492 483 542 453 564 482 493 525 466 486 497 478 475 498 479 497 475 546 510 466 526 502 486 511 489 530 467 509 494 528 528 524 513 547 556 584 531 593 567 567 579 612 552 597 646 645 664 684 687 765 809 933 978 1040 1192 1343 1398 1534 1625 1684 1759 1771 1762 1735 1672 1665 1540 1408 1420 1415 1370 1338 1226 1245 1293 1295 1280 1241 1262 1142 1238 1137 1017 921 838 811 858 756 738 726 699 695 681 640 667 672 631 647 657 654 670 660 647 651 713 721 709 756 767 793 858 852 968 1019 1193 1269 1427 1556 1814 2018 2225 2324 2432 2647 2664 2698 2753 2599 2488 2331 2252 2008 1968 2031 1918 1782 1840 1821 1840 1734 1783 1673 1677 1657 1561 1486 1312 1314 1122 1125 971 907 807 755 708 698 660 619 600 615 608 629 605 581 564 630 599 543 533 588 565 544 566 545 581 600 598 530 598 580 587 659 628 670 730 730 742 841 820 925 988 1150 1195 1304 1401 1525 1580 1635 1642 1605 1560 1583 1526 1492 1367 1247 1274 1144 1151 1155 1108 1131 1105 1133 1067 1040 1066 1054 939 966 896 847 736 735 685 632 563 628 584 526 522 548 486 521 470 479 471 413 460 464 453 462 460 462 441 453 457 428 408 424 414 416 436 439 418 434 391 424 423 414 396 422 402 415 411 429 426 411 394 391 382 385 421 397 409 424 419 436 415 395 408 373 385 381 396 373 394 439 407 380 421 462 401 396 369 387 378 422 406 420 432 435 414 388 441 436 420 445 425 387 410 425 423 413 427 450 428 483 473 505 492 499 513 554 552 597 666 684 660 839 780 791 786 880 839 836 821 787 802 725 725 722 655 704 664 660 665 686 681 695 651 624 679 638 615 590 576 579 542 518 513 477 453 473 472 444 464 458 429 415 402 400 432 392 396 418 369 408 404 454 405 400 414 363 427 391 383 416 369 438 437 410 370 380 393 357 374 442 425 418 353 376 389 413 409 363 381 385 406 386 444 413 402 422 376 422 361 444 406 423 354 447 421 413 389 422 399 426 378 425 440 484 412 427 471 457 488 519 487 540 559 590 654 715 694 768 759 733 781 795 737 776 792 705 736 733 734 691 669 679 742 751 821 821 874 862 862 866 896 897 807 824 780 740 680 669 617 669 618 593 585 619 579 592 593 569 644 539 548 518 561 513 517 473 485 452 442 467 468 461 427 390 427 483 380 381 395 403 406 406 380 431 398 433 419 380 394 363 395 381 378 370 349 390 418 412 403 421 392 435 437 395 435 386 420 423 397 417 448 402 459 416 422 430 437 450 457 427 436 426 478 427 457 485 483 466 446 449 460 506 495 510 497 479 500 530 549 555 554 583 557 602 648 622 705 663 673 709 787 829 931 989 1078 1193 1342 1543 1670 1810 2001 2271 2358 2486 2523 2702 2759 2760 2702 2637 2500 2458 2366 2234 2250 2092 2102 1954 1870 1983 1933 1905 1954 1821 1812 1712 1680 1641 1566 1450 1389 1267 1137 1042 1040 985 826 828 776 722 672 585 589 582 565 559 544 531 529 501 496 486 476 499 473 452 446 479 432 443 450 455 466 426 452 457 406 482 428 446 460 447 501 454 439 425 447 485 454 417 469 429 447 448 505 476 444 476 462 536 479 538 559 519 559 581 577 674 697 721 731 797 890 962 1030 1034 1211 1260 1236 1326 1337 1383 1282 1227 1115 1129 1058 996 994 964 967 928 913 925 939 944 944 1051 984 953 962 905 904 892 845 827 786 778 851 857 864 817 837 805 841 782 850 719 704 699 671 598 642 627 596 574 570 635 568 598 563 592 607 606 540 536 541 534 499 469 477 438 421 394 413 397 414 400 401 414 392 357 367 384 394 376 356 391 397 364 379 376 379 367 396 384 337 392 389 354 368 367 323 353 353 381 330 378 362 357 319 351 351 389 366 339 359 372 339 361 322 338 312 333 343 353 326 363 333 346 364 363 349 354 360 359 366 286 357 327 332 338 349 365 353 379 356 358 317 344 321 321 339 351 339 353 309 338 349 344 342 356 358 351 376 360 344 325 315 373 314 328 346 352 333 343 321 332 351 347 333 335 364 331 336 355 312 315 322 324 348 336 339 345 353 322 304 320 340 335 347 326 317 396 335 320 312 343 322 321 350 354 331 304 368 353 327 349 357 299 345 313 312 337 349 369 348 355 310 327 344 304 371 324 326 400 315 334 349 364 331 345 297 383 326 352 364 365 303 352 315 326 346 320 363 302 299 332 290 322 334 355 325 327 342 316 317 317 309 370 316 349 354 330 361 343 335 303 350 375 372 362 311 375 336 363 335 382 337 334 349 365 293 344 325 330 331 320 349 348 339 317 331 355 330 331 329 346 355 375 345 356 346 358 380 363 338 348 392 419 368 419 407 424 453 468 483 514 465 513 475 512 500 479 438 521 457 416 463 439 392 372 404 420 379 421 436 434 405 402 396 398 380 411 389 433 421 356 362 349 331 343 361 345 340 343 355 314 363 315 374 326 379 362 363 351 294 369 337 327 317 337 338 347 340 336 324 357 368 360 366 356 385 353 399 368 365 350 384 397 393 342 356 395 364 380 373 396 381 410 394 411 429 390 438 430 464 481 561 514 532 564 579 658 695 760 811 804 813 829 825 839 837 772 743 702 641 644 597 615 633 621 570 572 595 624 669 595 631 628 639 608 595 560 503 534 529 466 448 428 406 421 475 430 395 420 372 405 360 397 379 392 377 326 354 391 350 375 354 398 390 374 393 378 364 371 332 344 337 349 377 358 366 353 367 361 373 377 355 359 379 342 349 394 346 400 345 341 353 380 378 368 369 389 420 342 400 361 395 385 380 369 368 371 394 403 399 368 429 405 405 433 415 406 429 448 431 460 430 495 512 467 515 518 593 578 627 627 746 786 852 892 1004 1013 1133 1155 1114 1175 1183 1055 1044 1002 922 862 772 793 729 781 744 737 728 723 789 779 789 792 788 784 742 722 665 655 639 632 564 500 505 486 469 472 468 456 381 381 408 418 380 433 389 417 374 358 386 399 364 410 379 379 413 386 382 340 396 380 408 374 384 342 336 316 371 346 360 371 353 390 348 435 382 375 365 353 366 383 377 376 372 379 372 382 351 435 382 383 433 421 426 387 394 418 390 389 390 401 386 411 420 361 419 431 390 443 432 450 441 478 441 515 500 512 521 653 609 709 715 823 815 972 1008 1064 1100 1096 1077 1084 1143 1072 1027 990 898 878 826 762 744 668 684 669 752 732 759 809 795 799 814 787 757 789 756 672 716 634 620 552 546 518 448 533 491 485 493 457 484 430 479 481 502 537 540 595 601 641 621 646 642 656 703 609 634 607 622 571 615 556 528 511 485 457 484 499 456 510 511 512 512 534 488 546 539 485 485 486 453 460 529 430 437 408 425 405 408 404 351 422 392 388 326 416 374 401 363 405 386 409 406 382 414 386 407 399 389 393 402 443 453 434 406 449 472 517 537 583 617 617 654 685 724 758 782 820 753 781 742 747 672 665 643 554 615 556 580 535 530 526 534 529 592 591 604 565 565 592 564 548 537 498 505 475 495 487 484 443 426 428 415 435 410 365 377 353 379 345 348 372 341 353 373 335 351 390 363 353 352 349 324 346 345 362 378 364 365 334 347 314 350 350 366 340 355 344 336 371 312 359 322 389 361 367 340 378 346 330 347 370 357 339 334 320 361 330 334 387 332 397 320 392 363 384 355 389 375 380 385 372 374 376 402 407 401 387 443 483 452 506 508 548 569 637 605 692 690 764 759 808 793 768 782 757 729 692 719 660 617 555 544 570 506 529 547 544 569 587 601 583 572 609 579 571 606 568 532 532 516 438 460 401 433 386 431 377 404 393 347 372 368 372 417 389 369 368 348 390 363 327 347 318 359 347 322 336 338 349 317 335 358 372 333 378 374 345 349 356 332 309 302 318 319 324 339 336 335 371 345 330 350 363 346 326 310 328 369 333 347 332 346 368 391 331 353 369 329 367 362 348 376 355 347 376 355 404 393 334 372 397 410 435 426 399 439 491 474 528 528 585 507 567 579 614 596 670 629 616 567 543 543 508 476 477 492 436 471 468 499 463 462 458 470 457 536 518 481 481 482 496 481 436 440 431 411 421 364 407 362 418 362 367 386 371 370 350 327 362 338 344 363 340 365 376 325 349 336 346 336 379 351 349 335 336 351 356 380 377 383 342 353 372 367 349 355 389 377 399 396 435 389 425 418 467 483 506 507 498 508 531 533 507 545 501 473 494 506 461 475 469 450 442 430 450 440 477 453 490 453 495 523 535 544 567 546 566 625 610 700 662 765 795 854 937 942 1017 986 1042 996 1002 1063 986 917 905 843 806 768 672 678 704 641 626 647 614 658 713 772 700 710 721 781 713 710 712 662 669 622 564 576 485 461 504 514 473 448 443 432 428 422 398 415 397 403 400 372 397 391 398 357 379 368 399 347 375 394 371 365 355 372 369 390 391 385 374 366 358 380 380 394 357 418 384 404 380 398 432 411 425 452 440 435 471 418 366 462 408 452 457 463 420 467 458 473 462 467 508 454 459 470 524 517 520 557 597 560 585 638 638 703 807 844 851 1000 1137 1213 1322 1439 1582 1652 1720 1773 1742 1749 1604 1699 1557 1431 1402 1302 1190 1063 1066 993 940 975 925 909 916 936 1017 1031 1096 1139 1157 1118 1197 1113 1083 1006 952 874 834 742 693 673 650 564 608 561 504 494 483 432 406 475 468 454 468 431 434 444 426 386 382 400 401 403 376 409 378 418 386 388 357 409 397 377 385 342 365 373 355 384 358 383 385 321 330 354 391 371 335 334 334 340 341 349 346 328 382 336 360 348 340 353 337 321 347 327 346 328 327 375 327 370 356 400 357 349 329 335 364 349 380 345 349 341 400 370 368 371 347 367 324 360 398 391 367 358 330 378 344 324 354 338 329 368 326 352 341 326 383 350 345 324 357 360 333 366 345 362 369 363 371 372 324 349 317 330 344 337 349 305 336 346 338 373 407 333 350 325 338 322 324 363 355 356 308 338 331 359 367 340 357 387 339 353 342 371 356 363 363 352 362 372 336 339 332 378 392 341 360 347 386 344 385 376 410 355 415 380 439 395 408 397 407 401 394 415 412 445 388 455 462 452 466 470 513 455 495 548 592 569 597 641 723 719 822 861 940 964 1039 1233 1257 1308 1365 1371 1429 1374 1241 1246 1176 1070 1021 971 907 840 765 769 750 724 783 750 771 785 823 820 904 866 901 934 932 912 906 842 777 785 682 689 694 594 578 516 511 497 476 436 465 442 445 397 386 398 397 446 402 387 385 370 377 325 378 403 356 362 414 364 375 329 370 364 371 371 355 392 364 363 352 362 361 355 370 319 379 352 358 366 375 370 326 335 383 352 370 347 341 355 349 350 329 335 365 356 398 350 337 365 325 336 370 337 345 371 376 382 375 401 410 427 426 455 473 469 497 452 463 542 515 580 565 554 476 515 480 457 453 443 441 419 442 413 384 389 384 442 400 391 444 450 405 415 419 409 438 422 445 414 446 406 398 400 389 375 380 381 392 374 350 347 371 345 349 338 330 331 321 345 346 346 302 353 330 368 299 350 334 341 325 341 328 325 342 355 320 320 317 348 326 338 343 355 341 352 351 327 350 341 351 335 325 338 362 339 339 334 333 318 343 359 308 363 314 376 314 351 387 375 353 350 365 383 377 387 372 412 398 394 379 393 412 410 394 440 436 442 453 507 531 517 543 587 555 583 564 524 541 490 502 514 430 417 445 393 409 432 441 409 421 472 477 430 456 423 449 481 467 459 484 483 492 424 407 419 418 425 387 385 391 406 399 377 340 369 386 380 346 337 357 339 350 349 341 347 401 359 366 358 377 377 391 343 389 404 346 384 373 387 411 394 380 375 381 398 337 410 356 445 391 385 416 408 449 442 430 403 475 437 478 441 474 476 506 563 550 623 601 684 685 757 833 905 878 975 1020 1009 1058 1045 991 988 996 910 937 898 882 899 861 848 879 895 969 943 1083 1057 1082 1043 1094 1072 1106 1039 1008 964 905 847 838 866 743 759 652 674 722 634 676 646 652 634 699 645 656 651 625 664 657 590 557 558 525 495 520 517 499 497 440 400 412 426 432 388 371 359 394 400 335 377 342 348 339 363 346 352 370 316 368 339 362 385 346 368 369 356 356 341 357 352 368 329 329 313 342 352 318 369 365 345 338 329 349 311 341 324 330 295 322 337 296 323 344 335 309 324 328 381 315 358 334 334 362 344 314 316 321 310 340 324 319 337 354 341 328 322 322 397 362 368 344 353 346 367 347 362 365 410 376 341 408 348 357 284 343 364 353 327 331 324 374 361 353 375 333 346 337 361 327 377 352 362 379 318 341 332 369 379 326 351 351 333 329 348 329 348 349 348 325 346 354 326 353 353 350 333 347 351 317 338 357 313 347 350 341 383 359 356 348 346 343 350 368 347 369 355 372 326 364 351 375 371 331 353 335 364 332 346 379 328 342 344 351 345 379 425 412 387 377 369 339 393 398 386 433 424 399 421 419 448 479 498 495 523 541 551 623 617 637 720 728 799 777 762 827 836 797 777 771 728 666 672 617 616 558 553 599 545 553 562 497 552 536 582 572 643 674 708 709 749 764 746 818 774 807 790 696 755 688 638 613 583 543 566 543 478 457 471 464 414 442 429 409 431 477 461 450 441 478 466 505 439 498 437 428 462 460 452 415 415 412 404 422 372 371 386 370 379 356 352 326 347 363 350 353 331 348 328 328 305 350 298 389 341 347 344 343 359 340 342 325 313 326 333 320 321 338 336 356 346 353 327 319 339 316 320 341 353 343 336 329 347 338 371 283 319 307 345 329 318 341 345 323 324 307 345 324 347 309 298 307 313 317 351 367 329 341 343 331 357 333 333 340 341 346 341 338 325 347 307 349 345 342 321 370 346 351 359 334 368 339 345 353 352 341 321 328 331 388 356 363 354 376 387 311 361 340 401 365 359 385 373 345 375 379 361 362 359 330 347 348 370 388 367 381 394 379 371 358 411 359 389 400 360 375 358 403 400 404 377 425 398 409 444 430 436 451 460 405 446 456 418 458 475 513 519 528 541 595 582 616 675 696 714 789 790 854 905 905 944 939 969 956 932 908 923 979 927 978 960 1012 1031 1100 1186 1152 1178 1134 1116 1093 1102 1014 979 951 892 855 948 847 811 782 845 777 761 740 741 666 710 691 659 740 731 737 750 778 727 800 739 678 660 669 661 663 596 565 544 546 493 501 506 463 459 423 476 461 471 396 433 415 416 408 432 417 426 411 397 412 407 404 415 376 407 403 439 388 394 386 397 451 404 418 394 423 432 432 464 444 460 452 455 496 445 457 527 507 547 527 578 495 577 594 632 679 701 770 845 855 922 1019 1059 1160 1180 1260 1209 1255 1172 1160 1195 1058 984 934 899 815 750 749 729 674 641 661 673 609 664 691 669 685 672 722 702 792 796 787 802 807 817 853 757 749 730 745 731 666 602 547 565 508 565 504 521 482 512 483 463 472 426 440 443 418 433 422 372 392 393 375 409 380 366 412 353 395 381 413 392 395 408 418 401 361 395 387 367 357 375 351 402 361 365 364 395 374 377 386 385 363 380 392 399 413 406 389 410 394 397 419 422 448 399 388 398 420 436 486 487 449 470 487 519 512 617 543 648 716 714 739 771 789 778 839 825 848 793 759 769 687 673 625 609 573 568 547 498 520 511 515 493 527 504 521 537 479 560 544 561 648 610 581 555 630 594 625 555 595 506 549 506 515 518 520 447 470 439 446 447 437 440 417 419 418 446 398 398 466 408 438 414 448 420 427 446 471 466 472 474 472 551 556 568 618 636 668 729 669 738 682 761 695 714 675 656 568 606 596 514 502 497 467 467 432 458 454 460 500 474 474 511 490 523 516 489 528 564 517 591 566 581 543 596 612 556 573 577 560 629 613 608 606 629 661 646 646 680 698 687 660 660 596 594 578 580 537 521 518 530 498 540 476 456 494 450 427 482 479 486 466 446 484 481 465 511 484 519 570 500 525 488 492 484 495 423 440 432 466 430 428 433 409 382 396 411 389 365 378 356 364 374 332 379 339 377 339 371 366 357 348 364 364 364 318 377 334</counts>
			</dataPoints>
		</scan>
	</xrdMeasurement>
</xrdMeasurements>