File: dataset/precursor_mixture/ZnO_0p4006-In2O3_0p6008--2min.xrdml
<?xml version="1.0"?>
<xrdMeasurements xmlns="http://www.xrdml.com/XRDMeasurement/2.3" xmlns:xsi="http://www.w3.org/2001/XMLSchema-instance" xsi:schemaLocation="http://www.xrdml.com/XRDMeasurement/2.3 http://www.xrdml.com/XRDMeasurement/2.3/XRDMeasurement.xsd" status="Completed" recordIdentifier="{069B2A05-E745-4685-8DAA-3FF84CC2C4C4}">
	<comment>
		<entry/>
	</comment>
	<sample type="To be analyzed">
		<id>ZnO_0p4006-In2O3_0p6008--2min</id>
		<name></name>
		<preparedBy></preparedBy>
	</sample>
	<xrdMeasurement measurementType="Scan" status="Completed" sampleMode="Reflection">
		<usedWavelength intended="K-Alpha 1">
			<kAlpha1 unit="Angstrom">1.5405980</kAlpha1>
			<kAlpha2 unit="Angstrom">1.5444260</kAlpha2>
			<kBeta unit="Angstrom">1.3922500</kBeta>
			<ratioKAlpha2KAlpha1>0.5000</ratioKAlpha2KAlpha1>
		</usedWavelength>
		<incidentBeamPath>
			<radius unit="mm">145.00</radius>
			<xRayTube id="1010048" name="Empyrean Cu LFF HR (9430 033 7310x)">
				<tension unit="kV">40.0</tension>
				<current unit="mA">15.0</current>
				<anodeMaterial>Cu</anodeMaterial>
				<focus type="Line">
					<length unit="mm">12.0</length>
					<width unit="mm">0.4</width>
					<takeOffAngle unit="deg">6.0</takeOffAngle>
				</focus>
			</xRayTube>
			<sollerSlit id="21010002" name="Soller slits 0.04 rad.">
				<opening unit="rad">0.0400</opening>
			</sollerSlit>
			<mask id="22031000" name="Fixed mask 13 mm">
				<width unit="mm">9.00</width>
			</mask>
			<divergenceSlit id="22120001" name="Divergence slit 1°" xsi:type="fixedDivergenceSlitType">
				<distanceToSample unit="mm">50.00</distanceToSample>
				<height unit="mm">1.52</height>
			</divergenceSlit>
		</incidentBeamPath>
		<sampleMovement xsi:type="spinningSampleMovementType">
			<spinnerRevolutionTime unit="seconds">1.0</spinnerRevolutionTime>
		</sampleMovement>
		<diffractedBeamPath>
			<radius unit="mm">145.00</radius>
			<antiScatterSlit id="22090040" name="AS slit 9 mm (PIXcel)" xsi:type="fixedAntiScatterSlitType">
				<height unit="mm">9.00</height>
			</antiScatterSlit>
			<sollerSlit id="21020003" name="Large Soller slits 0.04 rad.">
				<opening unit="rad">0.0400</opening>
			</sollerSlit>
			<filter id="20030001" name="Large beta-filter Nickel">
				<material>Ni</material>
				<thickness unit="mm">0.020</thickness>
			</filter>
			<detector id="7010019" name="PIXcel1D-Medipix3 detector" xsi:type="rtmsDetectorType">
				<phd unit="keV">
					<lowerLevel>4.02</lowerLevel>
					<upperLevel>11.27</upperLevel>
				</phd>
				<mode>Scanning</mode>
				<activeLength unit="deg">5.542</activeLength>
			</detector>
		</diffractedBeamPath>
		<scan appendNumber="0" mode="Continuous" scanAxis="Gonio" status="Completed">
			<header>
				<startTimeStamp>2024-11-14T13:52:10-08:00</startTimeStamp>
				<endTimeStamp>2024-11-14T13:54:15-08:00</endTimeStamp>
				<author>
					<name>AutomatedUser</name>
				</author>
				<source>
					<applicationSoftware version="1.7b (136)">PANalytical Aeris Instrument Suite</applicationSoftware>
					<instrumentControlSoftware version="3.2.00000000 20240306">AERIS</instrumentControlSoftware>
					<instrumentID>950485</instrumentID>
				</source>
			</header>
			<dataPoints>
				<positions axis="2Theta" unit="deg">
					<startPosition>10.02173288</startPosition>
					<endPosition>99.99585608</endPosition>
				</positions>
				<positions axis="Omega" unit="deg">
					<startPosition>5.01086644</startPosition>
					<endPosition>49.99792804</endPosition>
				</positions>
				<commonCountingTime unit="seconds">10.965</commonCountingTime>
				<counts unit="counts">1894 1860 1891 1856 1902 1908 1863 1802 1826 1824 1813 1758 1811 1795 1793 1727 1735 1752 1736 1715 1735 1715 1749 1682 1765 1774 1720 1629 1653 1645 1647 1578 1683 1612 1609 1681 1640 1637 1599 1585 1603 1572 1572 1529 1581 1516 1551 1475 1506 1510 1516 1455 1487 1408 1461 1493 1483 1432 1496 1464 1371 1491 1455 1365 1393 1395 1340 1457 1461 1409 1507 1355 1451 1425 1368 1362 1356 1357 1394 1291 1291 1408 1353 1336 1304 1269 1318 1323 1268 1250 1304 1271 1214 1274 1297 1264 1317 1253 1366 1253 1215 1245 1248 1258 1284 1244 1199 1258 1223 1300 1248 1222 1203 1248 1296 1249 1260 1129 1233 1206 1272 1272 1229 1198 1196 1254 1284 1151 1238 1187 1198 1148 1186 1217 1159 1188 1179 1226 1156 1139 1215 1158 1140 1160 1135 1146 1213 1206 1171 1216 1209 1113 1091 1117 1086 1222 1081 1156 1038 1097 1119 1068 1066 1053 1078 1121 1025 1044 1150 1178 1138 1147 1124 1151 1167 1082 1071 1130 1188 1050 1123 1048 1058 1001 1112 1106 1085 1055 1027 1018 1002 1037 1039 1039 1026 992 1022 1044 1051 1051 1032 1022 999 1050 1032 957 1048 976 1014 1025 965 991 1043 1023 908 982 1041 1028 928 989 977 994 1020 912 985 900 915 943 948 1014 946 937 981 985 963 982 991 966 931 898 926 938 854 864 921 895 953 837 923 929 967 906 917 991 946 953 938 950 956 1084 1119 1156 1261 1484 1823 2188 2682 3247 3164 2722 1901 1436 1134 1031 967 901 911 921 871 888 884 843 835 847 870 850 823 872 878 839 886 856 875 844 832 755 822 798 829 783 779 814 791 814 805 772 744 776 790 764 767 757 803 795 767 782 791 778 803 746 786 748 735 760 821 735 749 746 770 783 743 773 708 767 764 711 736 718 799 772 755 712 760 716 764 687 771 711 718 782 775 721 763 771 657 723 712 685 756 769 710 719 721 692 713 699 659 683 745 670 703 709 658 676 692 713 678 686 688 668 735 634 696 659 641 701 671 667 718 640 677 626 689 653 635 654 688 629 691 620 673 673 676 645 653 675 717 701 692 692 629 618 687 635 674 687 656 655 630 666 617 630 606 636 694 671 690 642 656 670 639 622 677 614 644 652 599 597 596 617 625 559 641 629 673 652 697 633 676 658 743 716 736 750 772 776 787 859 815 839 880 941 934 1092 1033 1127 1343 1480 1625 1893 2250 3092 4643 7217 11669 17587 24010 25392 21161 14303 8136 4419 2815 2110 1722 1573 1342 1204 1066 1021 968 927 915 904 922 912 909 926 1016 1316 1646 2511 3273 4465 4981 4545 3611 2602 1668 1168 909 851 846 787 752 735 686 688 646 645 635 617 649 625 680 694 647 716 628 660 690 670 768 904 959 933 859 793 726 708 633 666 636 604 603 577 611 589 615 598 618 604 600 670 629 645 638 693 747 749 894 1107 1540 2324 3281 3815 3452 2808 1942 1322 893 872 816 755 786 794 736 743 821 785 907 954 1056 1185 1601 2106 3182 5121 7094 7762 7007 5336 3474 2245 1519 1194 1129 1063 1068 1073 1008 1205 1380 1996 2966 4394 6372 7924 7528 6152 4386 2782 1697 1241 1001 915 776 725 680 642 612 580 591 567 584 596 569 565 597 534 534 582 556 627 577 690 787 872 1179 1640 1890 1780 1465 1115 820 682 653 604 549 568 549 515 501 484 461 510 473 501 485 501 502 463 497 445 426 420 435 511 512 440 436 452 483 476 480 421 438 429 485 444 454 496 457 457 478 507 558 565 689 739 716 628 630 536 476 477 439 445 414 435 418 435 424 424 440 437 400 402 485 423 432 419 400 398 429 447 418 405 432 442 419 408 436 426 399 404 447 417 465 488 505 582 691 871 1124 1484 1558 1395 1167 911 676 586 553 506 441 462 443 406 433 405 436 402 351 362 411 362 397 398 353 366 369 406 392 354 381 404 410 404 353 362 394 397 403 409 374 386 394 429 485 531 572 644 578 537 508 471 425 376 415 390 365 396 391 400 405 392 352 366 395 367 361 367 371 401 380 366 388 419 382 400 426 398 394 439 432 496 408 494 509 612 679 961 1493 2110 2387 2237 1827 1580 1119 791 594 491 502 451 457 378 372 435 415 389 383 354 382 410 407 361 344 399 369 386 393 394 389 384 377 380 404 429 450 466 434 496 577 609 943 1282 1757 1853 1685 1538 1228 958 658 548 536 438 395 431 411 404 363 375 376 351 332 369 366 347 354 351 369 347 342 384 377 391 395 399 328 367 400 359 410 437 568 722 899 967 888 781 713 649 514 474 467 424 413 407 367 393 402 428 393 380 447 432 416 422 443 447 466 475 506 576 586 627 663 663 756 816 1038 1202 1462 2075 3358 5759 8157 8516 7189 6069 5035 3448 2146 1406 999 895 791 703 647 573 530 497 455 514 483 406 452 437 387 414 416 464 414 407 404 410 410 404 412 368 423 430 454 596 714 792 858 714 680 604 569 450 402 391 388 371 372 342 373 372 341 341 362 330 343 353 319 341 340 330 340 354 344 310 383 371 349 333 371 358 348 402 454 515 487 448 368 423 441 366 405 382 348 335 363 349 345 335 337 347 377 317 348 386 324 347 371 397 366 371 404 433 373 428 406 466 492 601 751 1052 1410 1492 1281 1140 1048 853 709 653 607 594 641 798 1082 1635 2478 2748 2409 2127 1894 1621 1218 842 622 525 464 448 433 382 393 357 396 395 401 378 411 456 552 652 620 532 509 493 424 391 365 363 371 342 323 395 342 315 328 355 391 364 329 389 338 367 350 352 390 380 438 420 405 438 474 508 644 781 1152 1245 1070 964 908 831 711 562 481 445 474 444 400 416 359 341 403 421 408 444 440 420 458 434 515 531 583 620 707 727 837 963 1206 1745 2875 4767 6169 5599 4386 3957 3938 2949 2079 1244 920 826 690 603 560 531 464 441 456 475 436 481 468 442 429 432 407 443 467 501 440 477 533 586 679 998 1384 1579 1412 1157 1108 1183 949 765 633 565 596 599 685 684 965 1496 2125 2414 2062 1577 1541 1494 1248 895 681 577 478 465 493 496 502 574 640 782 1092 1457 1362 1106 953 1000 906 740 494 448 433 396 375 375 329 358 366 348 349 357 387 308 356 361 348 327 373 372 335 360 306 400 406 518 654 794 705 595 572 606 550 490 364 378 374 337 324 336 345 321 331 304 318 304 328 332 327 350 346 384 404 434 490 615 674 669 671 712 788 711 594 549 538 502 436 363 355 346 372 348 328 337 335 357 306 342 352 402 402 400 402 441 410 443 506 538 671 889 1348 2042 2450 2300 1924 1751 1647 1448 1171 980 692 538 511 411 381 378 392 345 388 347 383 394 401 406 417 553 738 1045 1164 1038 868 858 854 819 692 734 730 723 562 506 513 559 437 426 334 331 309 318 335 298 302 307 313 311 319 302 344 324 273 296 317 271 286 304 284 277 258 316 299 283 283 270 272 291 300 292 273 255 280 312 271 265 298 292 247 298 303 290 294 308 261 279 275 277 312 276 262 267 287 292 292 279 310 260 300 274 358 408 489 405 396 320 346 367 340 361 329 333 285 287 292 277 279 298 275 311 328 298 360 372 433 507 709 741 644 552 524 566 528 493 429 343 332 347 287 310 299 284 320 341 313 343 330 307 330 332 324 343 312 377 400 468 534 687 903 996 849 749 647 676 693 564 482 379 343 350 333 338 330 333 313 278 326 310 309 316 316 300 305 326 338 362 405 486 646 843 1011 969 725 620 654 706 666 591 455 419 398 466 558 604 496 471 404 467 459 412 418 348 361 315 316 321 332 342 371 432 562 657 642 558 430 456 494 515 476 383 329 328 325 294 309 307 293 282 326 296 285 275 288 312 303 313 332 359 334 409 406 523 669 676 617 507 481 490 537 438 384 342 307 347 292 288 298 285 291 306 285 295 324 321 273 290 286 280 308 331 324 350 429 581 565 464 420 401 424 427 409 389 317 344 331 302 317 322 300 314 349 327 308 372 426 436 474 372 383 396 429 426 518 693 928 859 780 650 583 639 590 589 508 387 386 337 344 332 332 286 320 331 328 336 335 363 363 391 415 405 412 486 621 767 1201 1568 1457 1161 911 768 943 1011 916 708 516 440 359 384 366 338 366 289 320 323 302 323 298 307 328 319 240 303 293 318 290 306 331 339 310 310 295 303 278 327 313 324 309 315 280 258 307 309 305 317 329 329 304 332 363 355 362 367 442 504 601 818 1224 1194 1083 748 617 662 801 774 763 553 406 412 337 361 345 309 337 317 293 311 316 301 300 312 269 292 324 295 336 326 404 437 424 423 317 361 333 385 387 350 312 353 289 280 269 302 318 285 286 302 316 263 291 297 294 317 284 353 330 369 409 475 473 433 402 377 349 368 377 365 349 303 299 301 296 301 346 291 356 297 331 349 350 410 454 435 681 851 893 858 788 764 897 947 898 724 624 550 589 538 511 412 364 333 310 315 318 303 291 283 332 315 273 303 273 278 301 279 278 288 298 269 305 317 309 312 290 280 318 312 339 312 268 292 266 249 303 272 255 297 293 307 269 310 332 319 325 313 351 392 415 457 626 715 679 575 476 480 485 600 642 676 612 468 409 398 405 379 404 392 335 307 309 338 300 256 295 281 255 302 301 272 287 284 270 288 260 276 288 264 278 271 293 287 283 276 270 305 274 309 281 305 310 289 322 350 351 325 351 374 362 396 525 609 790 785 836 810 923 983 908 780 653 654 614 637 623 608 514 418 380 345 309 337 345 340 345 352 341 382 419 423 523 634 933 1087 986 781 650 590 586 628 725 698 601 505 457 420 386 329 348 378 302 291 296 330 344 328 373 312 315 355 382 470 529 583 723 679 562 465 452 418 450 523 442 472 389 363 347 340 366 390 381 490 550 667 590 441 397 373 398 449 491 473 555 529 563 610 554 435 395 354 384 382 433 518 408 361 338 331 303 352 293 290 324</counts>
			</dataPoints>
		</scan>
	</xrdMeasurement>
</xrdMeasurements>