File: dataset/precursor_mixture/ZrO2_In2O3_K2SO4.12-min.xrdml
<?xml version="1.0"?>
<xrdMeasurements xmlns="http://www.xrdml.com/XRDMeasurement/2.2" xmlns:xsi="http://www.w3.org/2001/XMLSchema-instance" xsi:schemaLocation="http://www.xrdml.com/XRDMeasurement/2.2 http://www.xrdml.com/XRDMeasurement/2.2/XRDMeasurement.xsd" status="Completed" recordIdentifier="{5DC9CB64-E411-45A6-8951-53A26C3D2264}">
	<comment>
		<entry/>
	</comment>
	<sample type="To be analyzed">
		<id>dara-32-2</id>
		<name></name>
		<preparedBy></preparedBy>
	</sample>
	<xrdMeasurement measurementType="Scan" status="Completed" sampleMode="Reflection">
		<usedWavelength intended="K-Alpha 1">
			<kAlpha1 unit="Angstrom">1.5405980</kAlpha1>
			<kAlpha2 unit="Angstrom">1.5444260</kAlpha2>
			<kBeta unit="Angstrom">1.3922500</kBeta>
			<ratioKAlpha2KAlpha1>0.5000</ratioKAlpha2KAlpha1>
		</usedWavelength>
		<incidentBeamPath>
			<radius unit="mm">145.00</radius>
			<xRayTube id="1010048" name="Empyrean Cu LFF HR (9430 033 7310x) DK430614">
				<tension unit="kV">40.0</tension>
				<current unit="mA">15.0</current>
				<anodeMaterial>Cu</anodeMaterial>
				<focus type="Line">
					<length unit="mm">12.0</length>
					<width unit="mm">0.4</width>
					<takeOffAngle unit="deg">6.0</takeOffAngle>
				</focus>
			</xRayTube>
			<filter id="20010004" name="Beta-filter Nickel">
				<material>Ni</material>
				<thickness unit="mm">0.020</thickness>
			</filter>
			<sollerSlit id="21010002" name="Soller slits 0.04 rad.">
				<opening unit="rad">0.0400</opening>
			</sollerSlit>
			<mask id="22031000" name="Fixed mask 13 mm">
				<width unit="mm">9.00</width>
			</mask>
			<divergenceSlit id="22120001" name="Divergence slit 1°" xsi:type="fixedDivergenceSlitType">
				<distanceToSample unit="mm">50.00</distanceToSample>
				<height unit="mm">1.52</height>
			</divergenceSlit>
		</incidentBeamPath>
		<beamKnife id="29030100" name="Beam knife low"/>
		<sampleMovement xsi:type="spinningSampleMovementType">
			<spinnerRevolutionTime unit="seconds">1.0</spinnerRevolutionTime>
		</sampleMovement>
		<diffractedBeamPath>
			<radius unit="mm">145.00</radius>
			<antiScatterSlit id="22090040" name="AS slit 9 mm" xsi:type="fixedAntiScatterSlitType">
				<height unit="mm">9.00</height>
			</antiScatterSlit>
			<sollerSlit id="21020003" name="Large Soller slits 0.04 rad.">
				<opening unit="rad">0.0400</opening>
			</sollerSlit>
			<filter id="20030001" name="Large beta-filter Nickel">
				<material>Ni</material>
				<thickness unit="mm">0.020</thickness>
			</filter>
			<detector id="7010019" name="PIXcel1D-Medipix3 detector" xsi:type="rtmsDetectorType">
				<phd unit="keV">
					<lowerLevel>4.0</lowerLevel>
					<upperLevel>11.3</upperLevel>
				</phd>
				<mode>Scanning</mode>
				<activeLength unit="deg">5.020</activeLength>
			</detector>
		</diffractedBeamPath>
		<scan appendNumber="0" mode="Continuous" scanAxis="Gonio" status="Completed">
			<header>
				<startTimeStamp>2024-02-18T13:26:26-08:00</startTimeStamp>
				<endTimeStamp>2024-02-18T13:38:54-08:00</endTimeStamp>
				<author>
					<name>AutomatedUser</name>
				</author>
				<source>
					<applicationSoftware version="1.4b (28)">PANalytical Aeris Instrument Suite</applicationSoftware>
					<instrumentControlSoftware version="2.0.0 20210224">AERIS</instrumentControlSoftware>
					<instrumentID>950485</instrumentID>
				</source>
			</header>
			<dataPoints>
				<positions axis="2Theta" unit="deg">
					<startPosition>9.99043322</startPosition>
					<endPosition>100.09495370</endPosition>
				</positions>
				<positions axis="Omega" unit="deg">
					<startPosition>4.99521661</startPosition>
					<endPosition>50.04747685</endPosition>
				</positions>
				<commonCountingTime unit="seconds">18.249</commonCountingTime>
				<counts unit="counts">4481 4517 4655 4522 4529 4439 4557 4637 4584 4625 4562 4595 4541 4592 4512 4537 4521 4566 4411 4566 4505 4380 4414 4570 4390 4557 4511 4591 4569 4347 4504 4425 4526 4559 4441 4473 4444 4428 4466 4475 4520 4497 4501 4426 4396 4350 4504 4476 4475 4524 4508 4312 4434 4413 4516 4432 4572 4442 4325 4488 4411 4465 4421 4354 4475 4406 4414 4326 4261 4287 4386 4531 4346 4395 4300 4447 4407 4398 4303 4422 4311 4393 4335 4296 4454 4323 4219 4279 4290 4378 4416 4353 4400 4292 4361 4377 4401 4422 4197 4322 4259 4224 4309 4301 4336 4308 4413 4345 4287 4286 4351 4232 4227 4209 4192 4368 4254 4369 4344 4211 4181 4221 4234 4284 4252 4244 4176 4260 4165 4265 4215 4161 4401 4258 4353 4164 4214 4194 4122 4280 4212 4105 4262 4100 4207 4197 4312 4358 4071 4267 4233 4270 4159 4219 4213 4052 4103 4151 4167 4117 4083 4191 4195 4080 4189 4117 4130 4061 4189 4150 4094 4125 4343 4113 4123 3951 4113 4111 4079 4162 4237 4053 4265 4119 4012 4156 4028 4078 4075 4106 4159 3995 4109 4133 4100 4069 4214 4076 4143 3982 4165 4066 4016 4063 4117 4051 4058 4121 4127 4024 3993 4044 4047 4118 4049 4107 4027 4050 4044 4081 4059 4063 4059 3952 3995 4124 4011 4079 3992 4095 4106 4160 3949 4034 4007 4097 4064 4056 3925 4060 3992 3984 4011 3980 4034 4075 4009 4030 4052 4083 4064 4020 4059 3966 4049 3907 3955 3938 4078 3994 4013 4093 3911 3975 3902 4007 3991 4023 3927 4120 3882 3974 3932 3994 3848 4064 3971 3971 3963 3972 4021 3904 4039 4019 3992 3925 3946 3850 3939 3973 3881 3985 4033 3938 3946 3940 3933 4011 3838 3962 3895 3957 3930 4055 3908 4021 3913 3910 3989 4013 3895 3913 4012 3868 4013 3903 3837 3844 3858 3948 3926 3924 3972 3927 3939 3950 3902 3998 3935 3884 3828 3922 4007 3987 3920 3819 3896 3999 3906 3931 3913 3814 3959 3859 3942 3884 3903 3852 3826 3876 3939 3910 3874 3953 3893 3868 3854 3869 3890 3795 3879 3894 3924 3772 3767 3783 3858 3850 3787 3865 3909 3979 3913 3899 3923 3790 3815 3832 3935 3925 3810 3888 3708 3906 3785 3947 3874 3944 3907 3902 3849 3860 3816 3948 3842 3916 3890 3869 3886 3712 3777 3800 3974 3848 3847 3878 3851 3849 3826 3895 3823 3907 3995 3795 3949 3889 3935 3887 3737 3830 3996 3864 3828 3872 3782 3762 3881 3757 3836 3774 3830 3830 3828 3825 3934 3796 3827 3747 3872 3807 3883 3920 3766 3826 3815 3823 3723 3821 3783 3926 3772 3891 3780 3707 3895 3843 3814 3788 3785 3783 3852 3806 3835 3773 3849 3833 3901 3858 3858 3766 3739 3787 3741 3822 3921 3822 3759 3843 3725 3762 3878 3805 3800 3852 3811 3942 3762 3792 3867 3729 3815 3851 3763 3792 3804 3814 3838 3924 3781 3702 3796 3828 3756 3833 3658 3846 3747 3827 3827 3824 3876 3769 3810 3794 3717 3739 3705 3771 3840 3735 3767 3699 3888 3641 3875 3798 3841 3747 3725 3855 3709 3681 3853 3792 3737 3849 3824 3697 3781 3954 3848 3837 3798 3809 3591 3739 3712 3830 3775 3733 3747 3885 3733 3790 3825 3691 3804 3831 3696 3715 3747 3810 3876 3920 3828 3831 3864 3777 3826 3724 3748 3672 3739 3774 3793 3838 3868 3697 3710 3809 3663 3766 3819 3767 3901 3712 3784 3808 3836 3664 3719 3914 3695 3774 3781 3755 3657 3722 3742 3720 3792 3831 3713 3685 3720 3834 3861 3651 3759 3672 3801 3758 3727 3658 3745 3624 3625 3758 3816 3703 3742 3680 3756 3760 3644 3586 3889 3699 3640 3730 3760 3838 3653 3637 3760 3771 3805 3779 3731 3718 3800 3812 3731 3793 3671 3793 3671 3762 3819 3749 3806 3792 3794 3911 3752 3875 3823 3885 3771 3793 3807 3883 3840 3796 3924 3921 4032 3973 4005 3846 4037 4057 4132 4050 4048 4172 4148 4208 4260 4267 4402 4403 4296 4526 4459 4563 4583 4676 4596 4912 4923 4966 4826 4733 4964 4833 4888 4783 4841 4842 4799 4883 4776 4773 4907 5029 4907 4969 4644 4750 4746 4514 4527 4418 4325 4155 4156 4005 3969 4046 3923 3731 3825 3833 3823 3796 3786 3521 3688 3711 3705 3540 3614 3700 3670 3702 3513 3537 3616 3533 3738 3650 3562 3612 3658 3659 3526 3640 3726 3655 3629 3536 3561 3747 3452 3722 3550 3553 3579 3512 3552 3626 3624 3623 3498 3704 3618 3546 3639 3492 3455 3505 3590 3596 3703 3512 3566 3627 3658 3526 3514 3550 3551 3561 3575 3541 3555 3675 3602 3640 3680 3548 3491 3526 3577 3573 3473 3590 3548 3533 3567 3616 3563 3428 3556 3502 3530 3589 3597 3500 3630 3611 3652 3494 3631 3543 3561 3534 3631 3570 3533 3571 3620 3513 3579 3576 3536 3548 3489 3463 3570 3550 3550 3419 3577 3448 3671 3480 3600 3618 3614 3583 3617 3562 3528 3590 3515 3533 3428 3511 3491 3418 3542 3443 3494 3338 3419 3600 3382 3564 3608 3515 3571 3416 3388 3540 3521 3560 3486 3430 3475 3477 3570 3448 3491 3493 3439 3391 3447 3464 3499 3469 3475 3374 3467 3369 3442 3432 3575 3456 3442 3413 3344 3429 3509 3479 3366 3357 3424 3482 3454 3447 3466 3476 3583 3547 3321 3463 3358 3435 3397 3398 3454 3237 3360 3425 3289 3391 3333 3413 3416 3261 3434 3496 3419 3484 3429 3300 3511 3354 3375 3418 3401 3455 3362 3437 3329 3377 3455 3411 3431 3387 3460 3383 3343 3296 3397 3385 3493 3423 3329 3423 3317 3369 3272 3379 3374 3444 3414 3490 3408 3437 3435 3414 3309 3278 3403 3367 3524 3443 3404 3465 3358 3355 3547 3403 3382 3332 3397 3358 3483 3475 3438 3366 3397 3367 3407 3435 3346 3342 3375 3395 3566 3384 3350 3361 3365 3378 3403 3248 3418 3403 3311 3345 3421 3486 3348 3298 3446 3327 3476 3401 3377 3228 3369 3425 3358 3499 3493 3440 3474 3367 3467 3386 3501 3615 3564 3586 3783 3674 3722 3832 3837 3846 3924 4097 4205 4300 4460 4558 4724 4809 5132 5115 5194 5199 4871 5149 4970 4990 4829 4635 4546 4521 4302 4023 3986 3841 3663 3732 3614 3553 3343 3512 3417 3355 3374 3449 3337 3302 3377 3178 3395 3432 3366 3277 3425 3266 3321 3401 3323 3257 3448 3271 3337 3398 3377 3283 3227 3340 3383 3250 3275 3286 3210 3349 3207 3344 3422 3272 3231 3309 3434 3255 3369 3268 3238 3343 3315 3318 3310 3313 3274 3389 3349 3232 3182 3214 3255 3284 3342 3280 3366 3352 3280 3302 3305 3203 3252 3302 3433 3303 3236 3223 3244 3257 3258 3270 3317 3291 3265 3355 3256 3186 3236 3252 3153 3156 3302 3121 3195 3216 3221 3319 3221 3194 3227 3391 3295 3195 3169 3187 3124 3204 3338 3232 3347 3137 3325 3234 3250 3283 3188 3285 3300 3249 3220 3139 3264 3269 3228 3283 3160 3273 3246 3182 3263 3253 3333 3155 3244 3139 3249 3169 3261 3260 3107 3144 3189 3166 3318 3239 3278 3149 3320 3267 3122 3232 3262 3194 3283 3250 3206 3184 3159 3292 3362 3178 3251 3307 3439 3337 3314 3250 3266 3244 3315 3325 3280 3312 3260 3262 3329 3289 3290 3385 3328 3227 3184 3291 3235 3435 3141 3342 3387 3179 3346 3206 3383 3345 3345 3363 3412 3507 3343 3520 3618 3514 3643 3653 3729 3724 3755 3953 3967 4139 4252 4612 4719 4989 5189 5191 5649 5910 6187 6203 6138 5730 5624 5467 5393 5251 4865 4812 4719 4743 4677 4786 4726 4971 5035 5103 5457 5666 5748 5870 6043 6320 6553 6497 6693 6814 6456 6567 6416 6216 6024 5704 5753 5378 5062 5042 4652 4655 4487 4425 4352 4270 4373 4247 4224 4373 4404 4488 4528 4671 4699 4755 4849 4892 4933 5089 5108 5284 5531 5387 5516 5420 5449 5455 5346 5231 5164 4773 5003 4563 4380 4249 4268 4054 3965 3997 3855 3883 3561 3526 3639 3457 3549 3435 3578 3497 3438 3348 3459 3427 3395 3299 3294 3220 3353 3319 3211 3245 3415 3263 3190 3180 3283 3266 3276 3137 3286 3254 3324 3219 3273 3204 3164 3258 3226 3125 3258 3165 3170 3166 3295 3161 3281 3128 3232 3142 3207 3110 3215 3199 3270 3222 3264 3155 3264 3371 3295 3264 3307 3342 3276 3435 3419 3342 3472 3445 3642 3548 3486 3462 3426 3412 3402 3263 3291 3239 3177 3323 3245 3219 3258 3092 3156 3201 3164 3155 3180 3122 3170 3241 3063 3144 3054 3154 3123 3187 3193 3075 3156 3014 3080 3172 3092 3007 3123 3138 3011 3141 3150 3178 3194 3074 3131 2988 3082 3098 3021 2914 3106 3129 2972 3062 3155 3135 3128 3121 3120 3160 3093 3085 3103 3136 3269 3094 3108 2985 3078 3206 3082 3206 3095 3443 3304 3310 3352 3373 3475 3549 3566 3599 3690 3707 3755 3698 3548 3556 3410 3311 3397 3360 3211 3265 3210 3139 3215 3092 3170 3029 3207 3159 3046 3021 3136 3026 3208 3121 2991 3105 3058 3027 3075 3127 3118 3017 3042 3157 3068 3099 2988 2950 3125 3111 3032 3147 2949 3150 3085 2998 3107 3064 3206 3004 3076 3132 3034 3118 2913 3071 3044 3097 3041 3079 3035 3135 3065 3064 3174 3213 3176 3158 3044 3063 3161 3049 3030 3132 3168 3118 3120 3114 3174 3207 3130 3145 3213 3248 3154 3218 3172 3200 3191 3285 3216 3349 3218 3279 3234 3243 3268 3306 3350 3279 3340 3288 3286 3258 3273 3268 3372 3379 3374 3322 3339 3526 3502 3405 3408 3495 3448 3614 3461 3575 3521 3567 3623 3692 3659 3657 3663 3780 3863 3806 3824 3893 3879 4032 4018 4027 4087 4219 4331 4371 4424 4472 4628 4828 5011 5055 5025 5360 5426 5813 5979 6368 6612 7069 7322 7877 8387 8857 9728 10282 11502 12218 13266 14349 15335 16654 17777 19091 20336 21600 22569 22943 23903 23906 23145 22137 21247 20308 18979 17960 16559 15062 13832 12689 11860 10684 9887 9174 8441 8045 7707 7234 7001 6722 6448 6140 5835 5728 5369 5292 5191 4985 4672 4777 4474 4417 4421 4211 4227 4294 4101 4050 4015 3946 4024 3941 3917 3743 3658 3795 3593 3707 3651 3688 3628 3715 3551 3687 3575 3526 3422 3572 3566 3472 3339 3431 3433 3480 3521 3468 3589 3408 3429 3390 3400 3405 3399 3365 3499 3482 3585 3433 3630 3580 3764 3694 3887 3860 3789 3923 3879 3879 3776 3579 3633 3486 3629 3368 3373 3346 3390 3296 3307 3334 3331 3234 3324 3195 3356 3173 3352 3243 3271 3203 3336 3249 3307 3363 3340 3237 3215 3364 3310 3343 3311 3345 3405 3469 3566 3516 3542 3736 3719 3911 3988 4201 4309 4728 4837 5287 5570 6064 6478 6974 7292 7715 7892 8153 8308 8314 7992 8023 7545 6950 6384 5913 5659 5448 5029 4748 4310 4016 3948 3744 3578 3382 3457 3442 3391 3297 3416 3277 3281 3330 3325 3252 3404 3221 3165 3328 3284 3217 3335 3225 3237 3358 3297 3362 3250 3243 3268 3329 3259 3370 3328 3276 3281 3292 3288 3390 3357 3359 3303 3352 3394 3417 3429 3458 3447 3563 3469 3473 3485 3480 3484 3625 3627 3690 3810 3768 3925 3907 4029 4117 4224 4295 4787 4792 5140 5560 6019 6465 7137 7598 8366 9165 9990 11320 12396 13279 13707 13647 13210 12263 11153 10722 10232 9996 9572 9343 8849 8519 8347 8130 8062 8186 8536 8443 7920 7816 7263 6789 6667 6536 6198 6139 5763 5400 5181 4941 4801 4723 4625 4636 4728 4604 4803 4766 4921 4903 5114 5116 5372 5492 5790 5960 6303 6423 6759 7233 7487 7947 8398 9005 9661 10238 11040 11866 12660 13472 14023 14651 15646 16080 16544 16580 16705 16215 15473 14953 14136 13335 12685 12000 11047 10263 9590 8765 7981 7363 6937 6533 6002 5811 5532 5148 4946 4904 4656 4513 4533 4254 4266 4339 4187 4029 3858 3924 3849 3865 3587 3702 3785 3609 3662 3631 3487 3466 3478 3554 3424 3419 3387 3343 3301 3347 3413 3318 3418 3305 3370 3329 3301 3230 3214 3157 3233 3289 3289 3174 3276 3248 3149 3287 3233 3190 3327 3210 3164 3272 3189 3245 3417 3268 3257 3334 3448 3304 3445 3593 3554 3613 3679 3841 3830 3971 3937 3991 4049 4114 4084 4004 3906 4081 3981 3905 3707 3744 3708 3625 3626 3412 3396 3440 3349 3274 3098 3225 3119 3231 3194 3061 3139 2902 3026 2975 2945 2967 2915 2942 3097 2946 3013 2971 2918 2992 2997 2917 3010 2914 3004 3029 2921 2918 2991 2940 3042 2911 3003 2940 3051 3045 2974 3082 3134 2968 3004 2883 2988 2940 2945 2880 3032 3025 2875 2950 3067 2916 2904 3008 3018 3062 3007 3069 2965 3015 2886 2911 3010 3010 2930 2972 2913 2984 3116 3005 2979 3029 3135 2890 3058 3095 3017 3157 3089 3063 3252 3152 3210 3295 3339 3286 3403 3268 3340 3118 3169 3254 3149 3245 3209 3285 3163 3265 3213 3123 3251 3179 3300 3307 3218 3252 3326 3363 3417 3462 3415 3477 3484 3629 3651 3685 3664 3841 3953 4008 4045 4258 4381 4609 4733 4835 5203 5223 5482 5808 5941 6348 6476 6851 6980 7223 7490 7439 7200 7306 6930 6961 6617 6672 6483 6292 6078 6193 6060 5872 5856 5850 5688 5938 5853 6024 5890 6024 6100 5974 5730 5722 5694 5495 5436 5175 5147 4945 4908 4723 4632 4362 4386 4136 4096 4070 3948 3873 3761 3728 3706 3577 3669 3615 3719 3485 3539 3440 3440 3478 3440 3495 3466 3526 3510 3470 3279 3493 3510 3557 3449 3453 3476 3493 3516 3475 3542 3446 3524 3547 3675 3706 3669 3825 3752 3705 3780 3958 4016 3985 3994 4159 4195 4311 4529 4649 4690 4867 4990 5247 5326 5489 5767 6009 6318 6566 6802 7259 7388 7976 8096 8621 9045 9411 9783 10245 10459 10899 11466 11803 12348 12919 13224 13579 13588 13976 14408 14506 14748 15570 15376 15917 16065 15720 16106 15946 15576 15408 15270 14899 14373 13458 12707 11677 10965 10388 9791 9083 8731 8232 7526 6977 6680 6158 6008 5790 5554 5629 5491 5535 5535 5546 5344 5331 5233 5288 5375 5243 5086 4785 4743 4545 4370 4298 4168 4089 4055 3806 3717 3729 3453 3495 3442 3389 3393 3339 3242 3216 3193 3131 3104 3098 3120 3117 3071 3105 3136 3237 3011 3115 2990 3016 3118 2963 2988 3058 2983 3016 3002 2960 3010 3030 2977 2990 3029 2963 3036 2982 3101 2925 2882 2964 2998 2944 2928 2888 2925 2877 2943 2959 2922 2893 2889 3036 2943 3008 3042 2877 2967 2890 2870 2868 2909 2969 2910 2941 2905 2880 2920 2907 3016 2872 2967 2992 2955 3084 2885 2894 2968 3016 3062 3035 3059 3126 3155 3279 3278 3357 3323 3585 3756 4045 4314 4566 4891 5312 5569 5675 5875 5694 5439 5134 4823 4545 4605 4474 4497 4306 4243 3815 3639 3495 3257 3111 3095 3029 2967 3089 3094 2939 2966 3002 2930 2937 2923 3038 3082 3000 3029 3021 2998 2961 3069 2995 2997 2977 2926 3066 3043 3110 3212 3129 3236 3339 3377 3418 3399 3349 3508 3354 3380 3265 3289 3210 3286 3233 3362 3464 3499 3340 3450 3527 3592 3547 3711 3660 3648 3718 3576 3490 3494 3481 3389 3461 3465 3481 3401 3358 3260 3206 3136 3249 3160 3175 3120 3217 3314 3260 3227 3294 3240 3264 3338 3368 3383 3422 3416 3589 3550 3613 3532 3688 3711 3643 3752 3774 3891 3895 4141 4117 4213 4254 4280 4478 4547 4711 4757 4965 5038 5524 5443 5764 5808 6190 6599 7027 7168 7538 7837 8139 8723 9160 9423 9761 10353 10616 11091 11630 12091 12624 12797 13254 13332 13854 14080 13796 13744 13473 13289 12989 12655 12420 11806 11561 11213 11001 10364 9998 9759 9507 9205 8800 8596 8212 8095 7794 7667 7325 7216 6870 6670 6443 6176 6052 5941 5526 5273 5398 5080 4839 4857 4651 4431 4319 4248 4123 3903 4031 3833 3788 3718 3569 3600 3545 3396 3457 3481 3357 3365 3433 3304 3422 3308 3283 3237 3268 3204 3217 3323 3146 3268 3234 3250 3231 3157 3159 3034 3122 3143 3095 3085 3024 3032 3021 3155 3050 3072 3005 2993 2959 2955 2972 2952 2915 2962 2917 2913 2762 2930 2871 2864 2800 2983 2892 2918 2833 2801 2747 2856 2861 2886 2785 2846 2892 2921 2868 2858 2772 2832 2918 2979 2978 2936 2869 2905 2901 2956 2928 2929 2844 2889 2856 2899 2815 2911 2947 3031 3005 2968 2976 2889 3045 2856 2901 3010 3009 2942 2965 3059 3085 3105 3259 3207 3367 3308 3460 3555 3593 3569 3784 3864 3931 3947 3988 4025 3875 3874 3773 3701 3757 3684 3688 3759 3799 3702 3787 3852 3824 3911 3906 3926 4069 4113 4313 4306 4571 4708 4908 4935 5117 5040 4995 5244 5115 5188 5160 5045 5015 4972 4988 5127 5288 5214 5249 5009 4756 4730 4358 4307 4094 4075 4041 4076 4090 3928 3685 3854 3607 3675 3574 3575 3686 3526 3670 3610 3815 3803 3769 3804 3975 3917 3894 3768 3766 3846 3881 3714 3705 3842 3886 3815 3765 3671 3734 3692 3729 3747 3779 3853 3863 3806 3888 3669 3675 3677 3573 3621 3518 3552 3475 3427 3366 3341 3336 3249 3209 3117 3117 3037 3064 2951 2972 2921 2902 2968 2902 2946 2771 2999 2835 2844 2758 2846 2817 2844 2714 2772 2781 2693 2849 2774 2819 2774 2718 2771 2807 2810 2654 2669 2744 2757 2828 2686 2605 2623 2760 2709 2715 2657 2699 2672 2612 2717 2668 2633 2686 2777 2632 2702 2648 2577 2685 2705 2595 2803 2749 2698 2631 2775 2680 2656 2617 2574 2690 2606 2646 2729 2666 2666 2603 2522 2687 2639 2740 2689 2792 2791 2706 2770 2698 2690 2585 2624 2682 2737 2742 2720 2662 2671 2727 2750 2620 2691 2666 2678 2622 2650 2544 2764 2706 2712 2565 2726 2684 2684 2593 2687 2644 2697 2754 2691 2601 2677 2745 2619 2685 2685 2675 2785 2759 2853 2858 2853 2818 2826 2875 2973 3146 3275 3196 3193 3185 3230 3267 2998 3034 2966 3027 2997 3006 3138 3077 3113 3085 3154 3064 3103 3054 3340 3363 3426 3621 3857 3861 4291 4182 4084 3892 3671 3487 3377 3612 3721 3798 4162 4129 4392 4395 4435 4500 4277 4450 4310 4039 3749 3473 3469 3413 3464 3321 3444 3515 3432 3270 3123 3051 2879 2844 2721 2668 2696 2648 2745 2798 2717 2673 2643 2591 2705 2667 2663 2662 2666 2669 2579 2696 2753 2709 2712 2673 2720 2648 2666 2576 2569 2637 2619 2704 2621 2616 2774 2611 2621 2682 2636 2735 2671 2606 2633 2651 2622 2481 2633 2599 2617 2714 2665 2704 2579 2634 2653 2676 2686 2756 2693 2734 2602 2662 2639 2588 2633 2683 2737 2696 2605 2669 2754 2736 2674 2600 2651 2690 2779 2654 2748 2658 2634 2880 2682 2818 2767 2735 2815 2836 2894 2816 2859 2852 2949 2979 2945 2935 2911 3113 3143 3126 3098 3231 3184 3213 3471 3405 3456 3425 3656 3880 3744 3864 3890 3781 3851 3980 3640 3833 3631 3538 3612 3527 3489 3461 3494 3504 3285 3275 3273 3102 3205 3072 3048 2998 3040 2967 3051 2960 2946 2835 2963 3001 2957 2992 3105 3202 3168 3188 3327 3306 3451 3449 3410 3385 3172 3254 3192 3263 3282 3195 3329 3340 3469 3350 3445 3342 3376 3456 3433 3407 3564 3414 3640 3674 3651 3632 3799 3639 3804 3675 3623 3532 3494 3505 3515 3350 3455 3436 3488 3306 3194 3171 3129 3086 3044 2987 2893 2961 2996 2917 2871 2784 2797 2791 2766 2837 2732 2827 2870 2786 2753 2620 2809 2683 2684 2663 2804 2875 2742 2753 2657 2704 2672 2762 2688 2777 2749 2741 2722 2919 2825 2824 2965 2917 3056 2954 2953 2900 2919 2981 2807 2913 2897 2910 2953 2976 2856 2981 2916 2897 2793 2746 2904 2743 2697 2869 2766 2727 2754 2724 2739 2745 2766 2721 2671 2640 2800 2663 2735 2677 2770 2826 2797 2848 2830 2974 3081 3099 3111 3110 3277 3060 2905 2872 2769 2712 2861 2882 2815 2824 2862 2799 2804 2749 2707 2769 2670 2650 2598 2561 2438 2533 2634 2599 2491 2524 2675 2683 2594 2550 2552 2619 2602 2673 2569 2613 2505 2531 2597 2586 2552 2589 2587 2547 2595 2698 2631 2537 2667 2645 2635 2511 2561 2602 2480 2626 2576 2551 2561 2587 2551 2622 2577 2590 2592 2620 2607 2567 2518 2654 2600 2604 2560 2620 2521 2607 2607 2505 2598 2607 2551 2548 2557 2641 2537 2607 2582 2731 2632 2681 2660 2569 2593 2659 2683 2624 2663 2631 2564 2585 2661 2635 2607 2647 2710 2719 2610 2612 2522 2627 2668 2621 2636 2659 2688 2598 2752 2531 2684 2730 2741 2740 2794 2748 2795 2757 2832 2878 2968 3016 2984 3300 3368 3436 3331 3363 3305 3235 3172 3125 3092 3084 3009 2932 3133 3061 3137 3211 3065 3059 3018 2904 2938 2949 2929 2788 2973 3018 2904 3032 3061 3074 2921 2988 3037 3149 3123 3179 3306 3212 3331 3351 3388 3496 3631 3687 3731 3994 4154 4440 4710 5000 5193 5546 5432 5470 5606 5350 5297 5527 5312 5620 5836 5835 6002 6042 6109 5965 5796 5632 5511 5501 5385 5501 5280 5241 5327 5094 4983 4887 4940 4826 4701 4708 4535 4543 4493 4588 4575 4501 4367 4447 4481 4393 4423 4491 4318 4451 4589 4695 4691 5106 5080 5213 5570 5638 5830 6105 6041 6239 6022 6144 5928 5802 5648 5584 5298 5371 5354 5258 5093 5096 4898 4853 4657 4602 4356 4187 4113 3983 3871 3811 3681 3669 3680 3479 3510 3363 3447 3331 3356 3316 3416 3282 3214 3201 3270 3190 3251 3241 3082 3195 3194 3182 3296 3102 3200 3162 3152 3223 3312 3320 3362 3359 3415 3459 3508 3507 3649 3493 3694 3762 3738 3990 4024 4128 4242 4556 4611 4859 5134 5427 5670 5850 6168 6521 6503 6742 6877 6782 6891 6752 6314 6310 6038 6035 5935 5699 5706 5732 5556 5435 5314 5164 4992 4614 4602 4390 4333 4243 4087 4173 4056 4075 4068 4042 4020 3924 3952 4193 4121 4294 4281 4393 4540 4581 4743 4962 4927 5046 4916 5046 4784 4683 4685 4665 4488 4386 4601 4375 4387 4293 4270 4042 4007 3983 3820 3706 3633 3569 3598 3459 3433 3277 3196 3247 3281 3187 3167 3111 3059 3120 3161 3142 3149 3101 3088 2976 3062 3056 3050 3123 2952 3161 3073 3217 3125 3113 3139 3261 3298 3221 3592 3388 3518 3580 3575 3734 3812 3711 3736 3691 3693 3677 3553 3609 3420 3570 3507 3536 3457 3439 3396 3344 3302 3299 3349 3199 3282 3348 3303 3341 3215 3273 3209 3114 3058 3027 3014 2838 2969 2958 2915 2888 3035 2914 2904 2834 2795 2869 2687 2717 2729 2693 2780 2764 2717 2789 2688 2681 2573 2735 2579 2692 2689 2703 2683 2639 2585 2704 2663 2739 2605 2591 2685 2678 2667 2558 2709 2660 2648 2617 2677 2623 2651 2617 2560 2665 2739 2699 2725 2708 2695 2717 2886 2805 2863 2714 2751 2665 2808 2653 2654 2620 2642 2697 2657 2678 2676 2778 2821 2730 2606 2700 2527 2661 2644 2643 2517 2637 2620 2574 2614 2526 2640 2429 2590 2598 2541 2570 2637 2654 2544 2711 2548 2626 2545 2651 2528 2674 2536 2598 2672 2657 2618 2549 2595 2679 2596 2588 2648 2656 2591 2620 2672 2613 2586 2680 2646 2585 2626 2706 2604 2635 2588 2697 2618 2730 2727 2662 2660 2649 2658 2842 2659 2781 2649 2655 2602 2695 2646 2744 2804 2703 2791 2829 2775 2831 2819 2858 2826 2851 2947 2973 2993 3029 2976 3000 2939 3085 3173 2922 2963 3135 3146 3243 3209 3333 3222 3242 3361 3343 3428 3326 3447 3347 3413 3513 3623 3523 3446 3449 3498 3375 3398 3394 3421 3527 3459 3421 3284 3400 3413 3328 3248 3261 3164 3195 3134 3059 3147 3089 3219 3148 3099 3066 3112 3033 3104 3202 3179 3203 3198 3208 3356 3277 3334 3385 3353 3344 3440 3496 3593 3646 3672 3859 4001 4020 4265 4306 4539 4653 4722 4926 5020 4900 4953 4932 4875 4593 4437 4417 4359 4248 4260 4260 4305 4236 4179 4093 4064 3912 3777 3810 3600 3609 3475 3468 3424 3338 3240 3035 3109 3053 3081 3011 3069 3145 3231 3055 3147 3190 3106 3123 3146 3193 3210 3311 3378 3492 3600 3692 3542 3458 3332 3343 3136 3023 3136 3098 3004 3182 3182 3223 3296 3473 3201 3193 3100 3026 3095 2987 3063 3088 3156 3243 3240 3337 3450 3630 3753 3828 4038 3975 3929 3612 3468 3390 3246 3230 3235 3357 3405 3420 3461 3517 3655 3660 3557 3388 3484 3339 3350 3364 3489 3474 3665 3620 3772 3829 3871 4003 4012 4026 4163 4238 4397 4302 4352 4592 4654 4771 4680 4780 4795 4675 4666 4635 4564 4472 4504 4500 4420 4499 4423 4447 4470 4553 4558 4506 4571 4475 4350 4420 4352 4333 4154 4156 4143 3979 4042 3918 4048 3890 3949 3992 3900 3856 3863 3951 3882 3994 3932 3987 3999 4031 3963 4207 4114 3976 4094 4074 4010 3990 3878 3811 3818 3722 3788 3745 3592 3687 3724 3609 3567 3606 3497 3373 3438 3373 3411 3333 3153 3190 3135 3158 3116 3191 3123 3158 3237 3208 3093 3103 3036 3074 3012 3019 2989 2987 2968 2917 2934 2828 2923 3041 2981 3086 3046 2991 2925 2977 2802 2871 2773 2821 2895 2794 2841 2836 2830 2815 2829 2897 2888 2817 2861 2815 2843 2832 2801 2846 2762 2818 2777 2770 2779 2796 2870 2878 2814 2854 2751 2839 2940 2823 2941 2806 2901 2908 2920 2973 2916 2941 2936 2952 3025 2970 3124 3142 3235 3301 3351 3333 3592 3497 3519 3471 3473 3505 3498 3619 3712 3741 3679 3804 3995 3954 3965 3946 4015 3872 3728 3693 3672 3600 3512 3458 3573 3455 3478 3533 3501 3413 3424 3299 3183 3190 3163 3211 3056 3181 3070 2937 2857 2962 2950 3037 2969 2853 2986 2913 2896 2861 2870 2836 2935 2934 2853 2923 2925 2910 3040 2961 2916 2969 3022 3038 2977 3140 3108 3172 3225 3218 3280 3278 3331 3440 3505 3465 3571 3497 3493 3574 3382 3627 3568 3435 3523 3512 3518 3587 3608 3786 3690 3691 3750 3752 3716 3701 3692 3692 3715 3603 3756 3811 3985 3827 3936 3911 4063 4098 4011 4191 4239 4224 4304 4292 4414 4344 4227 4183 4226 4232 4112 4079 4111 4225 3988 3976 3893 3848 3873 3832 3709 3863 3813 3609 3783 3555 3540 3449 3438 3399 3350 3244 3275 3238 3162 3110 3233 3110 3261 3240 3319 3369 3273 3340 3186 3250 3210 3044 3041 2976 3122 3143 3184 3140 3001 3002 3079 2915 2931 2913 2958 2743 2783 2744 2778 2933 2840 2904 2806 2799 2704 2804 2737 2662 2623 2622 2715 2622 2682 2638 2633 2681 2630 2691 2578 2604 2672 2754 2698 2679 2675 2648 2697 2659 2741 2743 2773 2756 2748 2718 2721 2725 2716 2631 2723 2635 2755 2799 2757 2693 2681 2754 2749 2802 2895 2759 2854 2795 3007 3008 2910 2954 2989 3079 3126 3067 3140 2967 3139 3083 3209 3344 3269 3414 3449 3492 3620 3634 3715 3850 4001 4064 3996 4140 4064 4026 4032 3941 4044 3997 3879 3889 3879 3920 3915 3914 4079 4059 4178 3966 4036 3952 3987 3982 3961 3993 4028 4032 3990 3970 3838 3783 3732 3681 3648 3558 3617 3418 3471 3529 3447 3443 3398 3442 3421 3289 3300 3265 3335 3262 3113 3167 3157 3195 3029 3074 3045 3113 3038 3117 3056 2992 2970 2879 2925 2932 2944 2872 2880 2802 2898 2923 2880 2856 2802 2780 2750 2899 2718 2788 2703 2767 2757 2758 2636 2735 2728 2781 2763 2773 2684 2702 2650 2656 2758 2722 2651 2699 2611 2681 2761 2765 2807 2749 2674 2715 2765 2843 2727 2747 2838 2765 2678 2714 2707 2779 2935 2810 2973 2838 2826 2834 2902 2948 2945 2839 2928 2889 3064 3011 3104 3042 3171 3193 3182 3228 3405 3273 3440 3426 3403 3546 3666 3775 3884 4017 4011 4165 4083 4106 4296 4353 4323 4322 4402 4427 4654 4548 4645 4531 4721 4879 4980 4997 4967 5036 5055 4987 4944 4868 4745 4670 4700 4550 4552 4297 4369 4442 4348 4186 4283 4150 4326 4157 4007 3864 3928 3962 3747 3839 3725 3748 3776 3705 3691 3845 3873 3675 3767 3823 3650 3679 3776 3748 3834 3812 3750 3753 3895 3723 3700 3514 3602 3617 3553 3577 3377 3453 3542 3385 3358 3312 3338 3384 3150 3280 3264 3162 3154 2973 3067 2970 2923 2997 2960 2915 2871 2950 2849 2868 2859 2877 2908 2921 3003 2979 2899 2950 2868 2838 2897 2896 2905 2794 2915 2883 3015 2828 2949 2963 2943 2987 3105 3018 3188 3296 3174 3315 3283 3338 3369 3343 3593 3408 3574 3607 3495 3676 3661 3799 3724 3777 3880 3949 3955 4152 4166 4170 4143 4035 3969 3817 3851 3675 3665 3629 3533 3598 3500 3516 3568 3513 3518 3409 3314 3284 3213 3223 3217 3066 2959 2995 2906 2872 2882 2856 2832 2828 2831 2812 2773 2748 2801 2762 2737 2594 2701 2702 2609 2610 2618 2565 2676 2630 2739 2682 2623 2692 2709 2658 2651 2700 2605 2593 2682 2645 2610 2601 2533 2589 2611 2577 2551 2597 2694 2644 2599 2613 2630 2545 2605 2658 2673 2538 2596 2616 2584 2613 2706 2680 2569 2653 2635 2681 2581 2439 2693 2767 2718 2694 2708 2727 2633 2686 2741 2771 2619 2766 2843 2832 2840 2833 3014 2994 3023 3035 3383 3331 3369 3497 3506 3444 3372 3374 3173 3249 3123 3144 3130 3121 3139 3052 3220 3321 3295 3385 3408 3335 3366 3221 3230 3192 3044 3053 3004 2979 3071 3038 3019 3165 3033 3109 3129 3205 3169 3587 3423 3505 3525 3446 3517 3251 3097 2999 2994 2969 2887 3015 2916 2882 2915 3051 3064 2997 3170 3112 3024 2942 2768 2804 2798 2764 2805 2838 2724 2751 2736 2685 2771 2762 2825 2804 2816 2888 2912 2838 2935 2984 3227 3215 3310 3323 3540 3505 3374 3335 3113 3224 3037 2936 3053 3012 3084 2972 3014 3140 3206 3250 3202 3169 3272 3205 3186 3202 3057 3150 3130 3105 3149 2954 3153 3189 3257 3266 3244 3259 3414 3375 3360 3287 3501 3295 3478 3398 3426 3454 3520 3497 3450 3662 3748 3675 3610 3749 3784 3993 4073 4045 4128 4226 4211 4271 4302 4435 4353 4485 4602 4582 4595 4464 4733 4543 4380 4583 4586 4571 4445 4631 4518 4539 4446 4475 4435 4457 4279 4499 4404 4289 4444 4345 4372 4184 4188 4095 4087 4085 4024 4080 4103 4082 4107 4037 3901 3968 3923 3820 3916 3928 3881 3927 3907 4115 4054 4060 4065 4095 4189 4155 4274 4232 4247 4089 4100 4108 4006 4018 3918 3929 3901 3916 3874 3809 3807 3660 3745 3598 3762 3607 3721 3667 3584 3587 3408 3311 3292 3265 3032 3233 3141 3032 2991 2971 3001 2892 2960 2900 2951 2933 2888 2982 2863 2861 2754 2825 2750 2712 2739 2733 2760 2696 2841 2843 2757 2723 2767 2873 2897 3046 3065 3275 3239 3331 3169 3085 3003 2889 2768 2851 2741 2721 2656 2606 2704 2846 2793 2871 2880 2896 2982 3039 3070 2955 2936 2892 2890 2750 2850 2836 2821 2751 2682 2726 2753 2627 2704 2692 2678 2743 2665 2700 2728 2614 2682 2742 2808 2764 2758 2766 2696 2701 2702 2721 2690 2775 2729 2536 2792 2895 2855 2791 2833 2777 2897 2801 2952 2946 2892 2830 2947 2970 3066 2992 3000 3037 2980 3157 3014 3193 3184 3393 3175 3303 3265 3434 3447 3390 3437 3645 3513 3598 3565 3665 3612 3816 3526 3745 3717 3785 3750 3815 3810 3848 3990 3927 3960 3991 4049 4029 4029 3867 4013 3859 3846 3721 3761 3716 3681 3596 3602 3634 3429 3544 3489 3475 3361 3266 3355 3277 3245 3196 3323 3183 3236 3127 3081 3144 3058 3014 3009 2944 2938 2884 2834 2817 2825 2841 2741 2805 2786 2798 2740 2755 2736 2763 2699 2629 2659 2603 2723 2664 2627 2643 2765 2622 2645 2634 2715 2673 2578 2662 2765 2739 2699 2743 2753 2743 2761 2772 2856 2852 2833 2920 2931 2898 2893 2924 2856 2907 2896 2873 2759 2784 2825 2808 2768 2694 2781 2843 2712 2806 2775 2711 2676 2757 2676 2773 2684 2663 2710 2759 2659 2714 2636 2718 2650 2664 2595 2679 2779 2764 2885 2933 3002 3012 3186 3136 3117 3191 2978 3068 2805 2980 2791 2679 2774 2809 2690 2828 2712 2663 2776 2807 2865 2839 2987 2903 3002 2959 2836 2823 2645 2735 2700 2683 2557 2661 2599 2614 2666 2560 2614 2571 2597 2618 2626 2666 2638 2645 2592 2594 2595 2556 2599 2554 2520 2600 2518 2496 2566 2494 2640 2567 2520 2660 2578 2547 2361 2511 2500 2565 2602 2560 2648 2732 2578 2604 2638 2596 2575 2597 2626 2570 2577 2561 2587 2551 2558 2573 2606 2521 2562 2679 2675 2616 2674 2593 2535 2502 2526 2538 2496 2569 2506 2458 2502 2609 2515 2621 2558 2568 2632 2549 2582 2527 2574 2532 2594 2543 2484 2578 2500 2633 2500 2513 2619 2553 2595 2525 2593 2601 2679 2611 2609 2545 2585 2601 2579 2602 2657 2639 2686 2626 2656 2678 2654 2655 2608 2668 2668 2771 2692 2860 2707 2721 2846 2848 2776 2838 2908 2856 2882 2981 2970 2952 2959 2925 2966 2974 2970 2890 2953 2988 2935 3025 2962 3067 3190 3059 3151 3199 3184 3161 3052 3023 3107 2994 3106 3008 2968 2974 3010 3085 2977 2934 2819 2851 2842 2843 2834 2895 2892 2797 2892 2872 2848 2840 2767 2783 2755 2723 2738 2719 2752 2700 2728 2747 2687 2691 2643 2666 2669 2584 2626 2669 2660 2749 2726 2659 2607 2616 2738 2658 2683 2663 2742 2642 2772 2740 2762 2681 2738 2756 2838 2763 2747 2842 2737 2874 2829 2794 2757 2865 2883 2875 2859 2895 2860 2997 2948 2894 3122 2970 2869 2925 2901 2985 3035 2987 2988 2965 2991 2971 3157 3080 3189 3181 3133 3175 3129 3172 3321 3332 3275 3362 3378 3310 3367 3285 3368 3423 3285 3346 3288 3272 3201 3161 3253 3308 3210 3163 3288 3209 3173 3399 3374 3246 3269 3236 3045 3198 3122 3024 2971 2930 2894 2998 2890 2859 2880 2862 2766 2755 2726 2804 2809 2822 2778 2688 2658 2705 2573 2659 2697 2696 2640 2636 2588 2648 2642 2638 2627 2679 2485 2528 2528 2548 2557 2505 2650 2471 2596 2530 2523 2613 2567 2581 2600 2529 2508 2458 2537 2506 2426 2515 2525 2537 2458 2439 2619 2530 2404 2408 2479 2491 2533 2452 2464 2518 2428 2469 2553 2453 2600 2513 2589 2512 2531 2482 2575 2630 2729 2668 2647 2632 2608 2620 2553 2667 2531 2709 2651 2689 2744 2662 2771 2704 2748 2603 2642 2600 2541 2615 2655 2669 2658 2582 2565 2539 2557 2544 2562 2566 2633 2539 2566 2511 2534 2524 2539 2481 2446 2389 2524 2484 2468 2506 2609 2443 2380 2597 2537 2602 2531 2493 2507 2489 2582 2475 2514 2572 2510 2526 2426 2533 2432 2499 2581 2578 2570 2518 2611 2554 2574 2499 2449 2635 2609 2588 2551 2470 2554 2554 2562 2608 2645 2584 2622 2598 2657 2765 2694 2773 2712 2611 2750 2774 2869 2794 2877 2781 2797 2862 2941 2956 2930 3110 2982 2887 2908 2920 2983 3004 2967 2959 3095 3015 3138 2990 3184 3152 3190 3260 3036 3234 3344 3392 3494 3504 3411 3639 3570 3646 3476 3560 3644 3693 3614 3782 3712 3697 3620 3752 3734 3647 3637 3598 3627 3701 3576 3478 3658 3583 3554 3480 3604 3484 3597 3569 3646 3502 3412 3636 3490 3286 3397 3324 3343 3312 3461 3353 3150 3312 3255 3252 3171 3153 3086 3018 3027 2945 2932 2938 2939 2806 2718 2866 2969 2876 2854 2880 2893 2783 2927 2788 2722 2929 2787 2748 2779 2647 2660 2690 2678 2688 2593 2713 2574 2637 2587 2590 2623 2647 2609 2623 2623 2717 2716 2673 2673 2632 2612 2623 2555 2545 2516 2613 2564 2540 2616 2576 2564 2564 2757 2661 2699 2667 2616 2719 2677 2565 2580 2681 2579 2791 2590 2693 2690 2735 2700 2658 2665 2774 2810 2841 2959 2963 2868 2892 2857 2835 2894 2796 2795 2904 2858 2950 2903 2851 2875 2755 2872 2858 2844 2839 2847 2810 2775 2778 2828 2776 2795 2762 2822 2787 2821 2666 2819 2618 2757 2636 2825 2590 2646 2654 2620 2642 2593 2624 2681 2767 2711 2689 2679 2712 2708 2568 2640 2646 2522 2562 2617 2537 2574 2643 2489 2599 2583 2630 2607 2644 2543 2597 2579 2615 2726 2626 2546 2593 2649 2627 2588 2730 2599 2647 2718 2615 2590 2540 2640 2639 2661 2677 2691 2656 2595 2683 2684 2688 2697 2694 2732 2622 2626 2654 2625 2589 2664 2694 2684 2614 2691 2711 2638 2545 2538 2599 2646 2635 2775 2645 2633 2687 2625 2613 2555 2555 2547 2580 2587 2617 2527 2599 2601 2498 2591 2552 2449 2515 2539 2503 2566 2467 2582 2579 2517 2596 2436 2631 2496 2567 2520 2487 2591 2560 2499 2560 2507 2570 2482 2515 2583 2617 2539 2598 2562 2636 2598 2564 2601 2716 2663 2546 2573 2634 2546 2725 2609 2691 2577 2645 2470 2636 2606 2652 2538 2602 2590 2514 2711 2588 2580 2584 2587 2639 2577 2624 2648 2657 2549 2623 2639 2654 2580 2573 2628 2520 2552 2577 2602 2659 2626 2560 2530 2728 2579 2648 2714 2609 2570 2672 2686 2656 2660 2701 2718 2739 2780 2714 2800 2693 2726 2746 2654 2689 2791 2655 2796 2946 2705 2749 2723 2871 2897 2741 2781 2731 2750 2779 2729 2800 2852 2725 2705 2651 2722 2753 2774 2805 2692 2779 2713 2687 2706 2710 2691 2672 2584 2609 2575 2677 2558 2574 2545 2559 2598 2565 2491 2494 2593 2498 2530 2579 2521 2610 2632 2525 2465 2462 2537 2582 2476 2415 2560 2458 2532 2399 2547 2481 2478 2377 2525 2511 2457 2452 2525 2527 2436 2381 2408 2526 2526 2392 2489 2463 2426 2443 2426 2524 2427 2466 2476 2417 2518 2509 2568 2557 2566 2513 2528 2339 2520 2412 2502 2487 2461 2526 2387 2553 2456 2539 2551 2569 2563 2557 2502 2596 2533 2656 2593 2595 2496 2568 2600 2502 2569 2509 2636 2585 2621 2578 2679 2669 2728 2679 2614 2685 2665 2633 2663 2708 2612 2656 2585 2705 2518 2652 2540 2669 2620 2610 2634 2688 2556 2537 2620 2633 2645 2621 2652 2600 2589 2532 2482 2595 2597 2534 2536 2576 2552 2568 2619 2452 2533 2637 2668 2561 2507 2532 2586 2548 2560 2448 2561 2491 2513 2510 2457 2533 2503 2564 2554 2499 2427 2534 2606 2573 2501 2468 2575 2585 2533 2601 2551 2483 2527 2439 2607 2579 2504 2530 2578 2534 2473 2542 2558 2559 2552 2582 2588 2555 2656 2541 2631 2464 2660 2513 2531 2592 2526 2554 2505 2639 2575 2596 2657 2590 2505 2620 2628 2753 2656 2681 2686 2627 2697 2461 2586 2608 2663 2656 2649 2645 2633 2679 2714 2728 2707 2688 2795 2760 2849 2672 2724 2807 2680 2728 2685 2814 2649 2657 2762 2619 2663 2692 2638 2804 2722 2705 2807 2822 2824 2830 2972 2832 2844 2809 2866 2788 2726 2811 2699 2678 2707 2690 2724 2748 2672 2734 2672 2701 2762 2700 2746 2753 2856 2766 2934 2725 2807 2810 2749 2808 2761 2761 2771 2696 2728 2812 2775 2789 2894 2794 2797 3017 2832 2792 2841 2909 2902 2879 2870 2883 2963 3013 2987 3026 3011 2985 3023 3070 3046 3091 3081 3103 2944 3169 3059 3140 3112 3136 3100 3176 3105 3113 3104 2994 3119 3026 2989 3021 2918 3092 3089 2969 3035 3014 3095 3013 2981 3006 2938 2963 3048 2933 3044 3047 2972 2980 3032 2953 3016 2917 2962 2952 3013 2969 2971 3083 3078 3064 3077 3080 3088 3137 3201 3055 3163 3229 3113 3070 3101 3110 3021 3049 3018 3098 3047 3141 3118 2985 3123 3083 3151 3143 3160 3190 3233 3206 3186 2989 3062 3049 3036 3077 3069 3151 3000 3136 2973 2980 3067 2927 3014 2946 2999 3052 2887 3090 2954 2992 3021 2960 2916 3116 2981 3028 3032 3022 2918 3043 2977 3087 3079 3104 3202 3095 3042 3153 3050 3084 2923 3005 2995 2966 3017 3009 3118 3193 3061 3116 3233 3150 3121 3052 3078 3047 3096 3113 3092 3015 3105 2998 2949 2977 3075 2997 2967 3079 3005 3011 2985 2897 2904 3005 3056 2908 2969 2958 2818 2968 2882 2867 2763 2791 2761 2882 2712 2736 2784 2702 2731 2668 2801 2829 2735 2777 2805 2737 2761 2749 2767 2702 2714 2693 2685 2725 2724 2660 2730 2732 2686 2669 2712 2835 2691 2778 2822 2742 2827 2720 2800 2776 2771 2702 2565 2559 2725 2605 2748 2720 2679 2754 2816 2760 2804 2832 2870 2763 2737 2875 2752 2767 2738 2781 2771 2850 2741 2783 2716 2499 2763 2612 2755 2607 2598 2693 2659 2650 2544 2652 2629 2669 2632 2700 2668 2567 2616 2611 2611 2637 2674 2538 2632 2555 2575 2548 2629 2579 2614 2607 2516 2606 2649 2519 2557 2571 2534 2465 2515 2508 2457 2579 2485 2424 2481 2571 2539 2585 2437 2612 2544 2546 2592 2496 2533 2620 2491 2508 2424 2599 2609 2526 2481 2417 2424 2368 2482 2567 2429 2506 2560 2567 2562 2466 2533 2517 2518 2428 2457 2459 2493 2513 2529 2539 2477 2478 2500 2617 2428 2595 2441 2473 2488 2616 2586 2545 2617 2538 2570 2569 2618 2558 2638 2615 2605 2701 2695 2570 2645 2699 2642 2610 2617 2624 2530 2661 2682 2642 2683 2603 2718 2663 2600 2635 2619 2663 2617 2650 2594 2582 2604 2605 2636 2703 2585 2549 2608 2676 2650 2594 2662 2595 2544 2646 2545 2655 2549 2604 2605 2594 2578 2622 2544 2535 2688 2567 2562 2490 2534 2596 2556 2542 2533 2519 2549 2507 2502 2556 2614 2646 2654 2476 2686 2517 2570 2622 2636 2577 2663 2582 2612 2524 2595 2564 2633 2592 2598 2615 2620 2675 2622 2615 2554 2537 2524 2546 2537 2532 2614 2536 2595 2566 2630 2565 2550 2596 2564 2642 2647 2633 2610 2643 2694 2569 2645 2723 2621 2746 2710 2693 2686 2727 2733 2753 2734 2692 2773 2696 2732 2729 2772 2800 2844 2753 2725 2791 2640 2654 2697 2740 2707 2755 2665 2817 2728 2763 2722 2704 2743 2669 2754 2716 2647 2645 2720 2625 2655 2594 2626 2570 2582 2598 2727 2713 2640 2726 2625 2636 2712 2670 2720 2626 2630 2587 2702 2670 2700 2695 2674 2668 2778 2723 2696 2759 2683 2707 2771 2706 2678 2804 2801 2899 2797 2853 2880 2888 2795 2836 2907 2841 2936 2780 2894 2777 2884 2914 2820 2890 2837 2789 2713 2858 2802 2824 2855 2927 2872 2851 2877 2930 2965 2946 2901 2928 2924 2938 3020 3011 2942 3053 2905 3077 2917 3009 2879 2793 2770 2784 2815 2883 2797 2750 2730 2752 2738 2753 2866 2793 2756 2760 2731 2816 2743 2692 2711 2820 2662 2759 2743 2847 2751 2628 2757 2639 2665 2707 2720 2753 2709 2755 2665 2660 2707 2670 2618 2658 2566 2741 2624 2674 2711 2662 2719 2638 2701 2632 2796 2721 2734 2854 2784 2810 2790 2823 2820 2767 2799 2769 2884 2870 2806 2743 2812 2742 2738 2785 2930 2892 2791 2973 2889 2894 2977 2917 3014 2940 2959 2952 2816 2955 2906 2886 2916 2962 2920 2966 2911 2855 2974 2928 2971 2991 3065 3079 3099 3135 3112 3210 3160 3133 3276 3178 3158 3108 3099 3173 3158 3233 3117 3134 3038 3049 3097 2992 3051 3047 2963 3075 3041 3018 3041 3059 3002 3038 3023 2954 2956 2898 2926 2938 2922 2903 2874 2824 2758 2888 2867 2925 2891 2951 2894 2783 2767 2830 2818 2781 2769 2779 2779 2742 2708 2674 2656 2655 2663 2581 2655 2523 2670 2655 2657 2639 2576 2620 2629 2613 2659 2640 2657 2762 2740 2682 2549 2616 2672 2590 2650 2622 2635 2708 2595 2636 2655 2689 2653 2709 2660 2544 2527 2626 2598 2601 2574 2635 2619 2618 2606 2639 2670 2554 2585 2554 2742 2624 2557 2560 2576 2591 2504 2700 2528 2565 2530 2573 2562 2548 2451 2584 2456 2545 2538 2515 2643 2557 2598 2615 2607 2591 2546 2643 2583 2566 2685 2602 2546 2578 2604 2596 2669 2651 2579 2670 2573 2653 2574 2676 2569 2643 2572 2592 2606 2574 2571 2602 2590 2633 2494 2609 2619 2679 2639 2575 2644 2656 2585 2582 2550 2624 2638 2594 2622 2603 2640 2510 2653 2627 2644 2586 2529 2498 2603 2581 2589 2583 2624 2647 2704 2592 2654 2669 2679 2671 2673 2592 2621 2598 2655 2609 2602 2504 2641 2495 2507 2542 2580 2484 2580 2617 2528 2586 2411 2592 2529 2560 2594 2630 2526 2534 2563 2509 2562 2557 2498 2486 2545 2461 2468 2434 2414 2439 2506 2415 2554 2387 2452 2447 2397 2524 2331 2538 2466 2478 2440 2516 2441 2478 2423 2349 2419 2420 2445 2495 2554 2530 2486 2471 2396 2501 2435 2459 2404 2446 2354 2484 2307 2412 2381 2416 2453 2461 2431 2518 2470 2475 2423 2493 2481 2466 2492 2403 2522 2468 2493 2476 2462 2527 2360 2299 2482 2484 2494 2519 2511 2516 2471 2411 2390 2464 2459 2502 2433 2498 2502 2398 2561 2450 2545 2485 2371 2434 2466 2531 2451 2528 2425 2483 2507 2529 2441 2530 2472 2589 2460 2615 2419 2531 2441 2497 2451 2468 2488 2427 2535 2527 2430 2435 2481 2472 2536 2573 2498 2538 2516 2495 2495 2537 2551 2476 2532 2466 2510 2510 2602 2530 2633 2582 2622 2529 2580 2607 2588 2537 2633 2753 2601 2587 2602 2682 2635 2718 2756 2853 2707 2788 2722 2814 2816 2803 2806 2767 2774 2635 2754 2648 2608 2706 2695 2672 2537 2504 2547 2574 2684 2504 2519 2501 2607 2680 2619 2623 2642 2568 2661 2588 2806 2564 2668 2690 2644 2616 2566 2603 2557 2558 2573 2440 2542 2582 2637 2647 2607 2552 2630 2656 2522 2490 2488 2541 2451 2511 2458 2469 2517 2510 2477 2477 2551 2541 2626 2531 2511 2525 2565 2619 2594 2630 2665 2585 2604 2659 2682 2724 2514 2647 2667 2636 2637 2550 2699 2642 2657 2616 2758 2690 2665 2662 2701 2712 2732 2773 2650 2694 2696 2705 2640 2680 2675 2689 2797 2789 2795 2903 2850 2826 2814 2864 2818 2844 2761 2733 2875 2838 2764 2789 2813 2749 2839 2800 2884 2808 2877 2795 2720 2828 2702 2811 2796 2805 2836 2790 2847 2830 2752 2906 2681 2765 2751 2585 2751 2618 2766 2696 2701 2608 2705 2680 2700 2713 2673 2795 2730 2744 2812 2689 2771 2655 2642 2667 2845 2683 2759 2621 2672 2720 2670 2762 2531 2578 2617 2723 2610 2622 2684 2687 2541 2606 2529 2577 2613 2625 2637 2753 2593 2603 2694 2707 2716 2616 2702 2759 2652 2717 2713 2679 2710 2612 2783 2761 2643 2694 2725 2687 2667 2753 2725 2718 2806 2765 2721 2851 2881 2799 2860 2803 2827 2818 2871 2827 2852 2752 2832 2771 2780 2837 2739 2865 2863 2741 2777 2799 2815 2876 2849 2834 2922 2996 2928 2945 2856 3019 3031 2989 2919 2925 2942 2865 2964 2847 2994 2884 3012 2876 2934 2958 2904 2980 2895 2936 2901 2984 2884 2916 2876 2905 2726 2792 2887 2788 2801 2822 2903 2880 2885 2762 2851 2851 2878 2891 2786 2776 2797 2816 2908 2859 2912 2871 2997 2830 3000 2869 2908 2828 2762 2935 2777 2726 2771 2792 2754 2727 2780 2842 2778 2691 2709 2720 2706 2639 2708 2684 2746 2693 2764 2762 2739 2762 2782 2722 2840 2670 2796 2773 2738 2705 2736 2645 2725 2817 2673 2684 2579 2596 2636 2636 2569 2655 2593 2668 2609 2726 2721 2686 2528 2621 2574 2586 2663 2619 2661 2582 2608 2554 2603 2681 2558 2600 2714 2528 2642 2718 2706 2678 2693 2700 2702 2707 2772 2766 2773 2789 2753 2767 2693 2741 2875 2732 2771 2770 2845 2734 2682 2875 2766 2764 2824 2672 2828 2692 2711 2690 2727 2826 2813 2864 2786 2842 2868 2839 2907 2814 2906 2794 2905 2863 2899 2862 2894 2814 2907 2917 2845 2786 2898 2894 2903 2736 2821 2914 2903 2883 2852 2769 2868 2735 2852 2848 2914 2769 2740 2740 2757 2857 2828 2788 2743 2744 2747 2740 2790 2855 2800 2888 2857 2872 2761 2886 2773 2867 2883 2730 2772 2817 2797 2728 2844 2902 2762 2834 2758 2740 2871 2773 2857 2812 2687 2755 2707 2718 2776 2740 2652 2756 2829 2703 2672 2681 2736 2704 2731 2759 2794 2785 2873 2799 2875 2823 2751 2822 2819 2880 2852 2934 2784 2874 2789 2773 2873 2889 2892 2959 2925 2858 2847 2973 2943 3105 2926 2996 2976 2975 2952 3075 3059 3019 3027 3055 2904 2933 3040 2889 2918 2938 2879 2852 2970 2917 2874 2998 2963 2802 2861 2862 3056 2954 2988 2951 2926 2955 3001 2994 3060 2962 2939 2912 2818 2845 2980 2855 2884 2930 2848 2849 2853 2814 2780 2867 2843 2874 2658 2815 2837 2856 2818 2879 2816 2808 2811 2778 2677</counts>
			</dataPoints>
		</scan>
	</xrdMeasurement>
</xrdMeasurements>