File: dataset/precursor_mixture/ZrO2_In2O3_K2SO4.2-min.xrdml
<?xml version="1.0"?>
<xrdMeasurements xmlns="http://www.xrdml.com/XRDMeasurement/2.2" xmlns:xsi="http://www.w3.org/2001/XMLSchema-instance" xsi:schemaLocation="http://www.xrdml.com/XRDMeasurement/2.2 http://www.xrdml.com/XRDMeasurement/2.2/XRDMeasurement.xsd" status="Completed" recordIdentifier="{DA4128FC-3969-49D6-ABF3-4CBAF5B5236E}">
	<comment>
		<entry/>
	</comment>
	<sample type="To be analyzed">
		<id>dara-32-1</id>
		<name></name>
		<preparedBy></preparedBy>
	</sample>
	<xrdMeasurement measurementType="Scan" status="Completed" sampleMode="Reflection">
		<usedWavelength intended="K-Alpha 1">
			<kAlpha1 unit="Angstrom">1.5405980</kAlpha1>
			<kAlpha2 unit="Angstrom">1.5444260</kAlpha2>
			<kBeta unit="Angstrom">1.3922500</kBeta>
			<ratioKAlpha2KAlpha1>0.5000</ratioKAlpha2KAlpha1>
		</usedWavelength>
		<incidentBeamPath>
			<radius unit="mm">145.00</radius>
			<xRayTube id="1010048" name="Empyrean Cu LFF HR (9430 033 7310x) DK430614">
				<tension unit="kV">40.0</tension>
				<current unit="mA">15.0</current>
				<anodeMaterial>Cu</anodeMaterial>
				<focus type="Line">
					<length unit="mm">12.0</length>
					<width unit="mm">0.4</width>
					<takeOffAngle unit="deg">6.0</takeOffAngle>
				</focus>
			</xRayTube>
			<filter id="20010004" name="Beta-filter Nickel">
				<material>Ni</material>
				<thickness unit="mm">0.020</thickness>
			</filter>
			<sollerSlit id="21010002" name="Soller slits 0.04 rad.">
				<opening unit="rad">0.0400</opening>
			</sollerSlit>
			<mask id="22031000" name="Fixed mask 13 mm">
				<width unit="mm">9.00</width>
			</mask>
			<divergenceSlit id="22120001" name="Divergence slit 1°" xsi:type="fixedDivergenceSlitType">
				<distanceToSample unit="mm">50.00</distanceToSample>
				<height unit="mm">1.52</height>
			</divergenceSlit>
		</incidentBeamPath>
		<beamKnife id="29030100" name="Beam knife low"/>
		<sampleMovement xsi:type="spinningSampleMovementType">
			<spinnerRevolutionTime unit="seconds">1.0</spinnerRevolutionTime>
		</sampleMovement>
		<diffractedBeamPath>
			<radius unit="mm">145.00</radius>
			<antiScatterSlit id="22090040" name="AS slit 9 mm" xsi:type="fixedAntiScatterSlitType">
				<height unit="mm">9.00</height>
			</antiScatterSlit>
			<sollerSlit id="21020003" name="Large Soller slits 0.04 rad.">
				<opening unit="rad">0.0400</opening>
			</sollerSlit>
			<filter id="20030001" name="Large beta-filter Nickel">
				<material>Ni</material>
				<thickness unit="mm">0.020</thickness>
			</filter>
			<detector id="7010019" name="PIXcel1D-Medipix3 detector" xsi:type="rtmsDetectorType">
				<phd unit="keV">
					<lowerLevel>4.0</lowerLevel>
					<upperLevel>11.3</upperLevel>
				</phd>
				<mode>Scanning</mode>
				<activeLength unit="deg">1.021</activeLength>
			</detector>
		</diffractedBeamPath>
		<scan appendNumber="0" mode="Continuous" scanAxis="Gonio" status="Completed">
			<header>
				<startTimeStamp>2024-02-18T13:23:35-08:00</startTimeStamp>
				<endTimeStamp>2024-02-18T13:25:57-08:00</endTimeStamp>
				<author>
					<name>AutomatedUser</name>
				</author>
				<source>
					<applicationSoftware version="1.4b (28)">PANalytical Aeris Instrument Suite</applicationSoftware>
					<instrumentControlSoftware version="2.0.0 20210224">AERIS</instrumentControlSoftware>
					<instrumentID>950485</instrumentID>
				</source>
			</header>
			<dataPoints>
				<positions axis="2Theta" unit="deg">
					<startPosition>10.02173288</startPosition>
					<endPosition>139.98435528</endPosition>
				</positions>
				<positions axis="Omega" unit="deg">
					<startPosition>5.01086644</startPosition>
					<endPosition>69.99217764</endPosition>
				</positions>
				<commonCountingTime unit="seconds">1.551</commonCountingTime>
				<counts unit="counts">462 430 462 479 454 414 460 433 381 406 405 462 451 437 478 441 434 380 444 403 412 445 420 417 393 434 404 447 420 425 416 407 363 398 416 397 395 372 376 390 414 389 391 411 408 356 373 369 410 392 384 370 370 413 363 371 387 417 389 370 343 346 393 364 382 366 356 357 343 355 352 345 361 340 372 376 364 388 348 348 346 379 349 382 357 378 348 358 401 373 352 342 341 348 309 370 361 371 366 354 395 336 330 323 348 334 355 371 335 333 363 341 344 361 345 344 311 328 342 343 341 364 336 351 357 349 347 332 342 363 289 364 331 364 333 363 325 333 344 292 340 298 318 325 317 343 356 339 352 328 345 336 317 332 334 329 352 338 377 321 329 377 349 324 381 416 357 404 449 469 432 428 475 411 369 334 364 303 313 335 343 305 351 299 310 337 318 287 303 298 336 312 344 330 312 288 322 302 280 302 319 256 289 273 295 295 305 312 272 316 271 300 321 318 336 294 289 298 299 301 275 331 286 327 285 297 310 285 281 306 282 303 265 306 247 273 302 278 295 319 288 278 315 317 272 316 301 252 270 304 297 284 332 349 491 440 473 337 283 278 266 263 256 298 257 273 272 299 305 259 259 249 255 296 250 275 269 251 277 294 265 292 260 288 284 260 267 295 256 295 262 267 273 266 265 262 291 320 281 284 292 278 281 272 291 313 278 301 343 400 474 573 462 423 393 489 546 585 592 448 417 363 386 380 417 429 517 447 404 323 283 305 276 311 295 274 310 294 237 266 275 273 270 272 271 283 306 310 289 259 281 241 278 262 280 264 259 258 234 288 273 258 298 243 281 276 270 308 336 317 277 255 259 312 258 239 217 261 250 273 266 259 256 259 268 313 271 301 300 262 270 269 285 279 281 291 290 288 269 339 326 316 369 389 460 577 735 937 1227 1763 2061 1961 1359 897 662 608 457 382 390 344 338 300 293 324 268 280 278 265 293 296 300 339 308 315 270 288 309 285 293 291 308 323 354 370 503 708 706 573 435 338 292 270 282 317 254 235 303 293 320 290 300 290 332 338 303 381 451 763 1199 905 889 694 764 691 570 439 373 427 508 477 625 779 918 1278 1530 1355 1050 742 543 430 362 336 341 294 292 302 252 267 290 247 229 241 255 275 286 313 371 345 310 338 312 268 287 296 254 282 280 259 245 248 236 257 232 280 257 252 268 298 250 243 233 293 285 275 301 278 256 269 275 309 324 365 398 523 613 662 525 535 488 510 551 452 415 370 363 342 304 303 311 303 302 293 316 311 331 378 388 409 504 630 746 803 1015 1151 1235 1416 1434 1274 1058 808 604 468 481 493 423 384 406 289 297 286 247 265 253 289 270 242 247 214 243 262 291 235 287 278 287 254 276 239 296 317 426 547 421 431 316 258 279 267 267 261 272 283 298 323 271 268 338 316 292 262 333 281 266 297 315 307 320 340 340 410 416 446 607 677 898 1033 1170 1209 1062 985 870 736 649 626 520 421 387 334 319 338 303 263 306 242 268 249 261 241 263 246 251 258 222 226 259 257 281 253 252 245 244 283 250 305 276 362 343 318 336 300 321 423 432 470 432 480 449 357 348 291 325 320 356 313 358 323 342 320 324 296 257 246 245 260 276 243 243 249 239 203 229 231 225 240 250 234 227 203 242 219 250 240 206 219 234 211 206 214 229 271 238 190 246 301 293 283 230 261 316 338 341 335 345 407 368 285 346 276 203 245 255 207 237 223 231 246 229 200 246 208 221 209 188 232 223 229 236 234 204 249 254 248 291 294 357 310 324 318 295 269 263 225 254 292 321 344 309 295 260 314 324 321 316 273 259 249 259 269 247 238 236 222 240 259 224 251 231 262 261 237 218 220 213 231 229 254 249 292 229 220 238 246 238 232 246 237 208 223 227 222 272 234 224 200 212 179 230 215 227 218 194 242 247 206 223 233 194 257 308 290 244 255 255 272 272 245 267 272 288 326 442 496 459 535 548 472 440 435 388 383 385 365 403 465 575 533 522 440 391 340 329 291 286 252 255 249 260 272 298 318 353 382 483 613 545 529 477 423 353 347 352 313 385 381 437 383 370 330 304 306 275 268 267 247 240 267 269 317 340 268 305 307 284 321 254 271 308 275 216 219 249 217 212 224 213 234 219 242 200 244 220 224 257 221 232 214 215 242 209 219 219 199 208 230 222 231 236 233 219 251 241 271 222 249 277 282 227 277 287 337 305 267 260 283 295 261 230 286 261 306 351 358 367 430 399 409 409 364 319 278 256 267 274 248 305 298 249 267 294 255 253 273 378 325 246 297 338 306 333 307 362 350 404 424 417 388 370 343 363 318 343 349 361 331 358 342 352 322 292 250 262 311 234 251 255 257 264 259 223 259 246 243 268 255 240 263 257 230 281 285 305 317 281 354 346 280 299 280 274 241 253 209 283 236 264 244 271 300 298 291 308 341 276 270 308 347 349 355 351 380 291 308 308 299 255 284 285 254 251 256 257 218 220 246 212 213 230 252 228 224 215 245 234 238 232 274 281 280 319 290 304 315 349 334 319 323 332 313 300 319 272 294 308 284 279 244 270 218 253 225 214 202 255 256 220 224 230 235 244 234 228 247 251 291 263 348 323 344 357 421 463 443 411 384 354 367 368 315 322 341 351 325 330 262 309 277 266 292 246 279 239 245 267 239 286 261 295 304 318 357 337 368 328 329 285 313 289 253 264 223 249 216 207 241 208 214 236 198 212 209 214 259 219 206 199 263 275 264 336 272 245 306 291 290 264 261 273 339 292 235 261 273 247 236 221 251 241 267 310 296 253 235 251 299 229 241 254 280 303 331 303 301 380 369 397 380 418 407 375 367 395 280 367 341 344 344 360 365 382 314 322 320 273 276 236 279 238 240 255 219 210 207 304 251 253 243 258 255 237 202 216 219 204 240 239 240 259 253 273 257 253 269 263 297 337 344 319 359 385 360 299 303 294 285 276 289 237 239 225 210 237 227 231 233 215 251 234 259 230 249 231 219 209 202 234 222 285 261 273 267 256 254 205 230 211 242 205 240 229 216 224 239 223 217 224 218 208 226 247 205 177 221 225 219 207 211 219 221 244 212 201 259 259 234 223 245 245 238 254 284 240 262 242 237 256 250 247 196 214 245 219 210 226 220 253 231 232 271 255 251 218 247 261 267 230 284 286 299 277 273 253 267 243 249 231 228 241 205 222 234 216 222 219 224 220 230 206 223 242 197 212 213 220 234 239 238 232 227 184 214 262 200 186 214 225 205 228 204 206 233 207 219 223 232 214 205 245 266 236 227 245 347 312 323 307 316 311 276 337 313 347 299 277 254 289 275 279 255 243 262 215 221 208 239 231 216 239 210 228 242 205 218 229 271 248 230 234 216 239 192 196 187 219 227 223 241 225 206 249 245 238 198 198 199 245 206 198 213 206 220 207 218 217 209 225 215 206 225 225 230 247 241 226 224 223 218 233 204 228 230 226 264 203 204 229 238 244 245 226 253 207 240 211 236 240 200 217 214 236 236 211 209 208 223 206 222 220 231 194 196 251 206 223 191 200 212 253 208 179 246 210 217 231 215 227 229 204 216 211 248 219 226 248 182 246 234 189 224 195 231 232 221 221 252 219 236 202 236 252 219 253 251 244 251 259 208 251 210 243 247 254 208 234 249 231 215 223 250 259 282 235 265 289 260 283 245 239 250 258 239 275 199 250 266 267 291 274 212 245 240 267 297 252 283 247 265 279 270 237 262 242 282 268 265 262 273 262 266 246 265 233 254 234 264 233 229 211 233 278 232 261 214 221 215 200 243 253 213 225 236 210 232 204 222 244 195 199 199 206 214 228 216 236 198 217 245 213 205 194 217 195 224 228 201 213 202 210 245 216 193 210 243 215 239 245 228 214 215 242 204 219 208 228 211 208 216 239 203 239 231 220 277 240 218 217 223 211 224 227 199 237 243 241 232 229 223 220 230 227 231 243 236 259 242 267 235 292 294 268 232 257 235 222 223 265 230 225 237 259 252 218 267 218 249 235 261 243 219 239 235 248 243 259 261 272 254 277 267 255 237 233 244 234 203 232 227 236 206 252 209 222 231 243 194 241 244 239 197 190 226 197 186 237 224 242 226 205 233 224 217 264 249 215 194 212 229 215 222 261 229 210 258 212 239 191 210 211 188 224 229 248 195 225 186 198 182 192 203 205 209 205 212 217 182 203 193 191 227 205 210 199 204 210 217 253 193 205 202 202 200 194 199 212 260 212 207 210 256 231 199 210 219 246 251 235 187 186 227 252 199 226 228 213 231 198 229 217 227 231 256 218 249 235 249 236 232 238 270 220 221 245 229 264 256 242 261 217 188 224 262 211 238 236 242 222 234 218 235 262 220 235 261 208 242 219 255 228 253 248 248 261 254 268 235 240 220 235 242 280 254 252 233 244 242 235 223 230 215 212 238 220 221 198 197 236 225 217 194 232 233 254 251 227 197 229 242 213 245 284 248 221 269 242 223 221 221 238 242 249 241 216 283 229 269 224 219 229 268 229 244 277 256 272 250 251 241 250 237 228 232 238 232 252 234 217 257 227 225 246 246 219 236 263 219 252 233 233 239 244 223 210 211 235 223 227 218 252 221 244 251 231 231 250 232 269 218 211 245 250 218 237 241 246 244 242 204 210 194 222 238 202 205 230 214 211 212 200 206 239 193 199 227 228 217 203 231 214 203 201 216 215 200 215 227 248 234 238 230 230 247 259 230 206 226 266 238 235 233 295 236 224 217 223 236 240 228 205 220 259 218 199 245 241 218 204 214 219 212 218 202 210 204 215 183 218 223 199 212 193 230 219 180 202 211 217 198 237 213 211 231 190 250 206 195 233 244 208 213 217 219 224 182 225 210 240 220 208 227 235 240 249 239 221 214 242 233 220 239 256 206 241 218 207 241 263 263 247 251 221 229 223 218 216 218 180 223 223 231 191 215 188 224 222 232 241 226 234 224 243 246 235 236 226 235 260 195 229 207 241 240 216 225 223 209 208 238 248 225 253 241 232 220 218 238 234 238 232 224 237 215 198 244 235 216 223 205 250 240 236 277 261 252 239 258 276 229 244 239 270 233 237 236 259 264 282 238 263 253 293 245 271 260 252 239 214 293 224 267 241 235 230 248 241 227 238 257 232 234 242 251 257 247 260 254 234 211 227 264 229 224 221 219 230 241 248 242 247 213 246 241 218 225 230 201 208 239 237 205 219 234 274 237 235 202 213 264 229 229 242 242 260 202 192 201 230 232 239 243 222 240 267 243 239 230 213 215 238 220 238 257 244 206 230 215 203 187 210 194 209 203 226 229 204 216 249 243 205 212 236 196 237 221 209 227 243 198 223 202 229 232 226 227 212 232 223 249 259 211 244 196 207 208 224 213 225 237 204 220 245 246 245 222 240 215 218 218 200 239 223 192 235 289 246 220 214 248 216 227 230 216 244 197 237 202 241 201 244 223 255 249 207 254 217 244 260 230 229 241 245 200 219 216 231 242 237 248 227 226 225 211 221 224 218 224 228 216 189 229 227 204 219 229 216 234 263 261 244 226 232 193 214 224 235 238 259 227 274 234 276 232 268 248 261 285 269 284 273 261 279 253 262 259 261 276 264 274 300 271 271 236 263 256 262 247 241 241 237 250 203 239 230 221 208 228 218 226 250 232 224 206 220 198 189 216 209 224 239 238 214 210 233 235 225 208 234 251 225 218 242 224 234 214 256 237 194 217 191 204 231 229 208 213 243 218 209 248 217 227 228 219 219 215 222 231 237 235 245 218 190 254 227 220 237 233 234 199 224 225 207 211 224 200 232 222 215 228 248 227 220 236 220 250 209 243 224 206 201 217 253 230 242 239 227 207 190 210 218 213 226 249 214 220 224 233 244 251 231 251 236 239 214 223 240 218 267 213 245 235 243 258 242 214 245 210 214 247 212 213 239 227 235 224 248 213 222 237 232 216 221 248 244 235 228 251 231 294 242 263 268 286 256 227 251 249 238 234 249 240 251 218 225 223 239 243 242 228 226 239 269 246 203 249 228 209 244 240 216 212 223 244 263 239 222 223 199 206 222 227 214 230 232 206 252 234 228 241 226 231 224 229 227 255 250 230 240 254 223 247 221 237 261 253 273 225 219 247 264 273 260 276 259 262 235 237 241 248 242 245 207 242 236 234 239 215 266 230 246 247 259 261 239 221 219 211 247 249 247 248 206 239 219 231 219 254 223 218 225 240 252 237 242 265 211 239 237 230 230 291 260 218 248 236 262 243 249 245 235 267 224 250 205 241 222 253 217 243 226 274 245 261 240 227 254 216 226 239 235 245 258 230 277 237 216 197 220 233 218 238 243 215 216 224 238 225 225 219 199 228 202 210 227 225 211 221 201 209 213 185 234 225 249 209 204 227 202 201 243 212 210 224 243 216 217 244 204 250 280 232 234 235 225 240 220 216 256 275 239 248 217 250 244 251 245 234 255 237 266 209 218 243 252 222 225 205 211 243 223 213 237 218 278 216 211 225 227 248 261 249 233 227 257 265 238 245 261 224 242 239 245 272 255 207 237 251 238 259 223 257 285 237 241 209 242 249 236 242 254 257 222 258 223 225 236 236 220 240 214 233 249 270 249 289 218 237 250 295 269 274 232 239 299 265 239 242 245 217 248 269 254 238 237 250 234 280 234 258 227 225 210 226 257 271 233 254 288 232 252 250 269 280 254 243 284 245 253 252 272 222 264 262 253</counts>
			</dataPoints>
		</scan>
	</xrdMeasurement>
</xrdMeasurements>