File: notebooks/tutorial_data/GeO2-ZnO_700C_60min.xrdml
<?xml version="1.0"?>
<xrdMeasurements xmlns="http://www.xrdml.com/XRDMeasurement/2.2" xmlns:xsi="http://www.w3.org/2001/XMLSchema-instance" xsi:schemaLocation="http://www.xrdml.com/XRDMeasurement/2.2 http://www.xrdml.com/XRDMeasurement/2.2/XRDMeasurement.xsd" status="Completed" recordIdentifier="{4217401E-64F9-4D06-8A25-0E918AFDB01C}">
	<comment>
		<entry/>
	</comment>
	<sample type="To be analyzed">
		<id>PG_1651_1_64c1f013-e900-4bf0-8afd-b37edb028e0e</id>
		<name></name>
		<preparedBy></preparedBy>
	</sample>
	<xrdMeasurement measurementType="Scan" status="Completed" sampleMode="Reflection">
		<usedWavelength intended="K-Alpha 1">
			<kAlpha1 unit="Angstrom">1.5405980</kAlpha1>
			<kAlpha2 unit="Angstrom">1.5444260</kAlpha2>
			<kBeta unit="Angstrom">1.3922500</kBeta>
			<ratioKAlpha2KAlpha1>0.5000</ratioKAlpha2KAlpha1>
		</usedWavelength>
		<incidentBeamPath>
			<radius unit="mm">145.00</radius>
			<xRayTube id="1010048" name="Empyrean Cu LFF HR (9430 033 7310x) DK430614">
				<tension unit="kV">40.0</tension>
				<current unit="mA">15.0</current>
				<anodeMaterial>Cu</anodeMaterial>
				<focus type="Line">
					<length unit="mm">12.0</length>
					<width unit="mm">0.4</width>
					<takeOffAngle unit="deg">6.0</takeOffAngle>
				</focus>
			</xRayTube>
			<filter id="20010004" name="Beta-filter Nickel">
				<material>Ni</material>
				<thickness unit="mm">0.020</thickness>
			</filter>
			<sollerSlit id="21010002" name="Soller slits 0.04 rad.">
				<opening unit="rad">0.0400</opening>
			</sollerSlit>
			<mask id="22031000" name="Fixed mask 13 mm">
				<width unit="mm">9.00</width>
			</mask>
			<divergenceSlit id="22120001" name="Divergence slit 1°" xsi:type="fixedDivergenceSlitType">
				<distanceToSample unit="mm">50.00</distanceToSample>
				<height unit="mm">1.52</height>
			</divergenceSlit>
		</incidentBeamPath>
		<beamKnife id="29030100" name="Beam knife low"/>
		<sampleMovement xsi:type="spinningSampleMovementType">
			<spinnerRevolutionTime unit="seconds">1.0</spinnerRevolutionTime>
		</sampleMovement>
		<diffractedBeamPath>
			<radius unit="mm">145.00</radius>
			<antiScatterSlit id="22090040" name="AS slit 9 mm" xsi:type="fixedAntiScatterSlitType">
				<height unit="mm">9.00</height>
			</antiScatterSlit>
			<sollerSlit id="21020003" name="Large Soller slits 0.04 rad.">
				<opening unit="rad">0.0400</opening>
			</sollerSlit>
			<filter id="20030001" name="Large beta-filter Nickel">
				<material>Ni</material>
				<thickness unit="mm">0.020</thickness>
			</filter>
			<detector id="7010019" name="PIXcel1D-Medipix3 detector" xsi:type="rtmsDetectorType">
				<phd unit="keV">
					<lowerLevel>4.0</lowerLevel>
					<upperLevel>11.3</upperLevel>
				</phd>
				<mode>Scanning</mode>
				<activeLength unit="deg">5.542</activeLength>
			</detector>
		</diffractedBeamPath>
		<scan appendNumber="0" mode="Continuous" scanAxis="Gonio" status="Completed">
			<header>
				<startTimeStamp>2024-04-12T11:05:06-07:00</startTimeStamp>
				<endTimeStamp>2024-04-12T11:13:58-07:00</endTimeStamp>
				<author>
					<name>AutomatedUser</name>
				</author>
				<source>
					<applicationSoftware version="1.4b (28)">PANalytical Aeris Instrument Suite</applicationSoftware>
					<instrumentControlSoftware version="2.0.0 20210224">AERIS</instrumentControlSoftware>
					<instrumentID>950485</instrumentID>
				</source>
			</header>
			<dataPoints>
				<positions axis="2Theta" unit="deg">
					<startPosition>9.90343322</startPosition>
					<endPosition>100.09488522</endPosition>
				</positions>
				<positions axis="Omega" unit="deg">
					<startPosition>4.95171661</startPosition>
					<endPosition>50.04744261</endPosition>
				</positions>
				<commonCountingTime unit="seconds">13.770</commonCountingTime>
				<counts unit="counts">2488 2384 2492 2487 2468 2467 2441 2520 2457 2394 2484 2443 2396 2381 2417 2410 2388 2453 2424 2398 2476 2414 2465 2412 2409 2349 2421 2303 2336 2368 2311 2455 2388 2474 2349 2373 2344 2359 2393 2219 2304 2450 2244 2307 2302 2403 2292 2281 2211 2338 2282 2298 2332 2313 2398 2353 2325 2328 2328 2291 2290 2241 2263 2213 2197 2254 2213 2304 2230 2256 2287 2286 2311 2233 2206 2212 2271 2201 2150 2246 2165 2197 2158 2232 2231 2216 2192 2161 2164 2089 2163 2158 2131 2130 2232 2172 2158 2115 2121 2143 2205 2133 2059 2145 2193 2059 2114 2139 2043 2119 2063 2076 2165 2170 2011 2052 2031 2061 2051 2092 2154 2168 2034 2053 2079 1993 2030 2072 1996 1997 2064 2087 2102 2032 2094 1962 2020 2124 2001 2017 2078 1990 2070 1966 2016 1990 1999 2015 1993 1950 1990 2024 1996 2034 2051 2059 2020 2041 2012 1974 1937 1963 1974 1958 1986 1924 1920 1994 1908 1879 1967 2018 2009 1877 1938 1900 1982 1823 1947 1793 1871 1886 1923 1874 1890 1908 1923 1959 1926 1935 1912 1869 1850 1871 1914 1894 1849 1895 1907 1944 1821 1886 1843 1903 1912 1882 1866 1904 1881 2025 1921 2014 1899 1903 1887 1878 1935 1901 2043 1878 1949 1946 1923 1892 1949 1921 1932 1956 1936 1971 1936 2032 1930 1952 2048 2036 2104 2006 2052 2070 2016 2053 2016 2111 2205 2134 2241 2213 2276 2134 2339 2250 2195 2258 2337 2218 2264 2308 2368 2335 2409 2331 2308 2309 2259 2194 2239 2231 2166 2242 2138 2167 2089 2028 1978 2034 1941 1919 1902 1885 1865 1878 1808 1819 1816 1845 1702 1771 1651 1742 1676 1730 1652 1784 1723 1702 1691 1663 1717 1736 1679 1729 1716 1720 1669 1665 1729 1778 1669 1640 1674 1698 1720 1703 1672 1611 1703 1656 1731 1638 1660 1654 1625 1647 1683 1582 1754 1685 1626 1714 1582 1623 1589 1635 1645 1628 1560 1627 1655 1665 1588 1672 1598 1586 1569 1636 1591 1592 1650 1619 1636 1548 1610 1614 1547 1510 1600 1596 1556 1601 1551 1599 1538 1483 1521 1565 1606 1648 1591 1571 1621 1557 1591 1623 1588 1541 1579 1596 1510 1526 1593 1567 1559 1565 1570 1547 1530 1574 1542 1511 1541 1552 1511 1521 1508 1543 1521 1479 1442 1501 1571 1541 1505 1606 1483 1540 1522 1515 1484 1575 1547 1565 1470 1523 1549 1523 1501 1537 1499 1448 1530 1518 1503 1522 1513 1571 1442 1474 1517 1522 1482 1439 1505 1552 1478 1533 1483 1468 1468 1538 1490 1594 1489 1480 1469 1571 1449 1512 1441 1504 1479 1453 1520 1492 1467 1388 1425 1460 1412 1504 1411 1421 1494 1485 1552 1420 1480 1483 1479 1458 1489 1436 1462 1431 1411 1513 1488 1436 1466 1517 1438 1403 1429 1428 1423 1481 1429 1452 1479 1395 1419 1499 1419 1424 1432 1303 1423 1375 1418 1448 1410 1387 1411 1380 1347 1436 1409 1402 1451 1371 1397 1401 1444 1447 1476 1363 1467 1393 1421 1368 1456 1466 1393 1442 1404 1429 1412 1402 1404 1368 1363 1375 1444 1400 1364 1361 1388 1412 1407 1390 1395 1410 1334 1420 1368 1376 1414 1399 1387 1392 1378 1446 1356 1418 1387 1351 1358 1439 1420 1406 1428 1405 1369 1411 1320 1377 1384 1423 1386 1428 1358 1386 1382 1358 1392 1346 1336 1413 1338 1402 1372 1307 1337 1355 1366 1372 1319 1395 1421 1410 1432 1295 1414 1336 1380 1377 1335 1364 1325 1340 1365 1373 1403 1368 1410 1395 1368 1343 1376 1280 1333 1293 1323 1391 1341 1330 1348 1352 1282 1304 1390 1297 1386 1278 1333 1327 1357 1395 1348 1356 1334 1336 1295 1288 1312 1380 1329 1303 1294 1302 1319 1312 1296 1326 1333 1333 1267 1276 1341 1270 1277 1313 1217 1241 1328 1269 1276 1300 1256 1251 1370 1353 1251 1362 1320 1303 1318 1279 1274 1225 1252 1279 1227 1241 1227 1274 1247 1324 1235 1297 1292 1265 1241 1308 1209 1269 1333 1304 1279 1251 1226 1264 1277 1224 1339 1255 1241 1312 1354 1258 1307 1260 1249 1229 1232 1268 1201 1250 1224 1216 1222 1254 1294 1233 1202 1267 1266 1261 1239 1260 1183 1303 1258 1236 1205 1245 1261 1211 1192 1312 1121 1262 1308 1251 1227 1245 1204 1223 1278 1191 1211 1242 1290 1256 1201 1139 1206 1224 1249 1187 1202 1180 1187 1247 1278 1179 1189 1226 1193 1111 1198 1257 1133 1301 1289 1242 1163 1186 1253 1217 1198 1190 1251 1227 1206 1227 1233 1195 1227 1233 1152 1225 1155 1248 1203 1229 1130 1178 1157 1186 1188 1122 1172 1171 1193 1151 1224 1188 1190 1168 1184 1208 1265 1202 1141 1106 1166 1177 1187 1214 1205 1215 1182 1129 1169 1197 1187 1194 1161 1175 1146 1218 1200 1229 1167 1178 1160 1145 1150 1147 1176 1200 1171 1134 1190 1115 1166 1157 1194 1106 1115 1156 1168 1172 1127 1165 1152 1150 1123 1155 1156 1196 1104 1115 1150 1169 1118 1133 1152 1095 1226 1160 1171 1132 1120 1125 1184 1146 1154 1147 1132 1164 1096 1161 1187 1157 1152 1181 1154 1173 1098 1140 1139 1139 1152 1143 1134 1142 1163 1175 1162 1141 1068 1184 1155 1170 1100 1173 1097 1072 1110 1112 1165 1084 1120 1118 1169 1144 1143 1159 1202 1127 1122 1164 1213 1187 1175 1100 1185 1159 1140 1197 1200 1208 1190 1124 1175 1119 1220 1197 1205 1126 1157 1202 1142 1216 1204 1266 1199 1206 1259 1216 1204 1228 1242 1254 1219 1260 1260 1290 1241 1305 1350 1310 1365 1344 1359 1415 1371 1344 1406 1436 1451 1441 1522 1537 1557 1587 1571 1644 1700 1728 1797 1852 1908 1908 1970 1962 2102 2145 2199 2307 2316 2380 2563 2693 2750 2897 3085 3256 3470 3560 3767 4111 4354 4573 4810 5207 5611 5836 6136 6399 6692 7048 7347 7584 7844 7725 7727 7788 7249 6914 6450 5917 5400 4757 4299 3857 3413 3097 2778 2448 2215 2081 2131 1884 1842 1819 1719 1680 1590 1532 1471 1509 1512 1441 1436 1434 1430 1402 1334 1372 1316 1376 1339 1349 1323 1348 1408 1236 1348 1279 1317 1292 1266 1312 1304 1290 1372 1294 1375 1301 1293 1394 1319 1359 1401 1315 1388 1418 1390 1391 1438 1476 1373 1400 1391 1466 1487 1540 1493 1500 1548 1545 1606 1626 1585 1678 1735 1699 1776 1770 1833 1790 1895 1881 1983 1938 2017 2045 2050 2023 2105 2109 2191 2098 2141 2239 2101 2032 2091 2018 1957 1923 1889 1960 1822 1796 1683 1735 1615 1629 1612 1573 1505 1464 1484 1407 1447 1366 1324 1345 1307 1277 1238 1250 1253 1219 1145 1208 1210 1200 1169 1152 1170 1128 1159 1100 1038 1106 1128 1169 1163 1164 1066 1084 1067 1120 1080 1136 1141 1082 1042 1087 1082 1146 1072 1108 1098 1008 1103 1043 1011 1120 1099 1055 982 1086 1073 1069 1078 1017 1082 1015 1104 1040 1072 1085 1050 1038 966 1084 1043 1008 1123 1009 966 998 985 961 1021 1019 998 1045 1060 1047 1030 1035 1051 1014 1045 960 1051 1023 974 1020 1010 1046 1024 1057 1024 1007 986 974 1014 1061 1000 1052 1015 986 962 1023 984 1065 1051 989 1031 1040 1045 997 1015 983 1031 1011 991 1014 1045 959 1057 1089 1027 1078 1060 1012 1047 997 1112 1033 1061 1070 1051 1111 1053 1087 1066 1131 1027 1093 1081 1101 1114 1075 1061 1015 1087 1080 1066 1069 1090 1067 1066 974 1017 1000 996 1076 951 1057 1006 953 1039 980 1010 1049 1011 993 1015 987 973 1025 1001 994 1051 978 964 1010 958 1075 963 1021 970 1039 1038 994 971 1073 987 1002 1031 1020 981 1023 1049 1058 1023 1076 1046 1081 977 989 1006 1071 1048 1091 1033 961 1082 1038 1052 1020 1054 1018 1017 1068 1063 1061 1101 1068 1105 1055 1079 1049 1149 1058 1077 1050 1079 1097 1101 1156 1153 1136 1226 1155 1180 1168 1255 1239 1150 1228 1244 1262 1300 1291 1319 1342 1306 1344 1406 1377 1430 1452 1528 1541 1604 1534 1606 1630 1662 1717 1765 1711 1903 1956 2116 2117 2101 2279 2321 2416 2450 2523 2603 2684 2842 2970 3125 3273 3225 3318 3362 3563 3612 3648 3635 3883 3859 3960 3829 3868 3986 3931 3876 3792 3802 3619 3629 3548 3408 3442 3199 3243 3004 2955 2899 2813 2760 2676 2759 2636 2524 2531 2452 2400 2406 2342 2382 2301 2481 2330 2327 2421 2430 2550 2508 2582 2547 2708 2750 2909 2949 3000 3085 3118 3423 3390 3685 3739 3773 3948 4259 4496 4736 4930 5170 5413 5686 6085 6371 6827 7171 7868 8542 9116 9717 10628 11637 12502 13609 14880 16121 17959 19349 21389 23156 25508 27819 30147 32354 34664 37297 39245 41297 42288 43174 43078 41980 40504 38583 36119 32620 29446 26547 23453 20862 18009 15244 13200 11368 9887 8608 7579 6591 6014 5491 4944 4651 4303 3899 3694 3486 3287 3240 2980 2966 2756 2720 2656 2467 2473 2289 2265 2102 2090 2055 1994 1874 1826 1869 1679 1636 1666 1621 1549 1616 1598 1524 1487 1471 1436 1431 1408 1392 1411 1355 1299 1395 1299 1331 1339 1319 1257 1230 1318 1225 1321 1256 1266 1238 1190 1197 1279 1250 1136 1191 1185 1223 1163 1171 1104 1162 1181 1149 1145 1185 1148 1128 1184 1156 1095 1090 1126 1124 1114 1131 1124 1060 1132 1108 1037 1095 1060 1053 1033 1099 1102 1080 1098 1059 1083 1016 1002 1040 1016 1039 1037 1066 969 1025 1006 1011 990 1066 949 1016 1050 975 1004 1052 994 1012 1064 981 988 1021 1027 999 969 987 1059 906 966 1019 949 978 967 1030 953 1002 899 1039 959 957 978 992 943 958 949 930 970 944 1018 936 978 1013 939 1033 996 967 962 960 929 990 962 939 939 915 973 971 905 886 1033 994 974 995 922 993 953 909 1059 951 1027 924 923 932 933 937 966 981 927 927 999 934 943 961 930 901 943 968 902 930 921 990 911 982 1014 941 917 911 970 901 908 942 926 919 970 905 883 964 929 905 905 961 893 913 968 915 885 953 904 978 880 966 880 932 938 931 892 882 892 861 985 922 939 907 897 881 837 848 855 864 821 896 868 914 870 901 860 897 882 856 909 865 880 896 871 838 850 883 885 835 813 897 848 913 882 839 891 855 843 876 896 883 871 837 882 893 776 815 818 876 830 804 823 852 837 820 833 849 852 839 868 871 835 835 798 885 845 834 878 941 885 880 831 884 854 894 872 885 841 888 851 854 825 833 923 933 843 872 891 868 858 887 870 893 949 865 877 917 910 910 889 929 898 958 893 898 900 884 909 944 965 934 964 903 942 964 954 928 861 1026 916 1037 1003 970 973 940 962 1027 986 986 1000 1021 1061 1040 963 1031 1044 1048 1096 1015 1160 1080 1141 1143 1147 1165 1141 1211 1219 1323 1289 1308 1269 1308 1410 1417 1465 1409 1529 1592 1652 1722 1821 1762 1884 1972 2087 2172 2120 2220 2396 2495 2632 2701 2852 3005 3076 3226 3467 3501 3761 3872 4057 3994 4439 4330 4464 4520 4605 4844 4771 4828 4771 4626 4862 4686 4677 4512 4456 4291 4206 3957 3921 3783 3523 3418 3518 3106 2997 2949 2767 2605 2486 2425 2299 2225 2198 2003 1978 1879 1876 1795 1705 1655 1695 1582 1541 1553 1546 1506 1501 1469 1421 1410 1440 1553 1372 1425 1511 1483 1481 1413 1487 1513 1563 1529 1635 1616 1615 1720 1768 1819 1869 2015 2136 2037 2313 2342 2586 2724 2882 3089 3423 3773 4149 4541 4960 5340 6000 6808 7507 8373 9301 10309 11591 12445 13410 14520 14807 15371 15303 14674 13588 12352 11169 10375 9289 8707 7795 6641 5674 4881 3962 3394 2786 2488 2276 2010 1861 1735 1638 1597 1492 1505 1446 1393 1421 1321 1308 1343 1283 1181 1244 1200 1132 1163 1164 1154 1105 1088 1069 1027 1091 1085 1005 1020 1049 1049 1036 989 1059 1026 1041 937 1080 1046 1038 1056 1024 1010 980 1016 1034 974 1072 1076 1040 1025 1039 1085 1056 1096 1123 1100 1125 1131 1144 1180 1193 1182 1196 1200 1171 1164 1208 1241 1204 1177 1258 1274 1283 1259 1223 1306 1348 1440 1323 1486 1459 1510 1577 1556 1704 1675 1796 1737 1853 1808 1924 2020 2174 2158 2178 2357 2476 2608 2763 2739 2801 2973 3091 3252 3231 3504 3562 3688 3892 4241 4123 4244 4426 4533 4806 4669 4871 4874 4947 4969 4954 5086 5097 5180 4932 4850 4878 4557 4602 4289 4456 4209 4091 3877 3637 3624 3452 3333 3257 3090 2913 2793 2680 2659 2466 2466 2279 2328 2066 2033 1940 1908 1861 1761 1694 1629 1553 1628 1571 1486 1485 1412 1366 1402 1409 1321 1302 1253 1266 1179 1199 1244 1231 1270 1195 1305 1230 1220 1210 1173 1159 1217 1228 1212 1168 1214 1284 1291 1289 1273 1268 1296 1307 1299 1341 1392 1407 1358 1484 1625 1627 1664 1725 1786 1914 1962 2147 2265 2402 2658 2948 3130 3547 3839 4230 4732 5522 6186 6613 7550 8607 9315 10299 10996 11737 12073 12041 11510 10529 9592 8487 7705 7284 7023 6387 5659 5004 4047 3381 2733 2245 1969 1821 1623 1540 1411 1374 1249 1182 1186 1167 1202 1228 1101 1127 1076 1094 1117 1042 1023 1020 1023 978 1033 1003 978 984 955 953 935 957 998 962 915 975 947 971 923 959 1016 1012 984 906 1001 1027 1028 925 996 969 966 989 968 986 1022 1003 1029 1001 980 976 1001 983 951 963 969 979 964 1040 1017 1071 936 1020 1017 1021 1048 1137 1046 1066 1123 1068 1099 1103 1111 1086 1153 1154 1180 1209 1210 1190 1304 1274 1286 1361 1286 1389 1391 1490 1375 1499 1475 1570 1662 1642 1831 1883 1977 2042 2170 2254 2378 2439 2571 2769 2921 3116 3319 3562 3676 3974 4242 4497 4662 5087 5280 5589 5912 5954 6118 6366 6524 6547 6810 6672 6948 6966 7148 7411 7699 7845 8453 9041 9637 10388 11305 12407 13615 15517 17165 18658 20707 22345 24515 25670 26580 26653 25591 23684 21787 19724 17888 16793 15796 14761 13301 11982 10232 8530 6994 5767 4592 4038 3471 3158 2790 2609 2341 2322 2090 2158 1951 1803 1735 1708 1607 1642 1457 1495 1465 1481 1362 1304 1300 1290 1302 1193 1226 1220 1124 1146 1167 1164 1135 1092 1038 1107 1069 1039 1085 990 1043 1025 1032 1017 1000 1027 1015 975 1006 1051 975 991 980 977 1063 1023 982 1010 984 980 965 1016 944 988 958 1002 1048 1030 968 1043 1027 998 1033 1047 984 1056 1041 1047 1084 1050 1059 1007 1069 1039 1025 1047 1101 1093 1182 1151 1155 1189 1229 1232 1212 1320 1283 1306 1400 1408 1369 1434 1521 1506 1574 1592 1651 1698 1718 1772 1859 1858 1903 1922 2062 2160 2269 2393 2416 2507 2600 2751 2971 2944 3253 3287 3514 3519 3834 3966 4252 4365 4770 4879 5384 5744 5942 6347 6962 7344 7754 8488 8732 9399 9996 10349 10820 11060 11253 11147 11021 11036 10447 10034 9566 8953 8410 8013 7575 6813 6354 5825 5180 4796 4419 3948 3612 3208 3009 2787 2664 2446 2303 2193 2087 1961 1871 1697 1728 1679 1632 1608 1545 1450 1401 1437 1321 1260 1288 1268 1176 1199 1107 1199 1140 1146 1104 1042 1027 1045 1066 1054 1029 994 974 1010 982 995 1002 959 1003 936 965 937 983 906 962 899 919 934 925 888 934 974 909 899 949 920 961 984 994 897 944 948 1057 1017 1016 1004 1008 995 1018 987 1057 1081 1100 1087 1074 1158 1230 1201 1227 1270 1351 1372 1397 1495 1602 1632 1683 1742 1859 1957 2078 2285 2412 2536 2618 2906 3112 3305 3641 3766 3982 4295 4464 4833 4932 5140 5151 5249 5392 5189 5165 5081 4962 4567 4437 4132 3925 3714 3431 3299 3067 2787 2554 2388 2169 1983 1872 1730 1632 1555 1434 1383 1254 1163 1175 1128 1078 1011 1036 979 1016 952 1043 975 939 856 918 929 881 860 869 849 809 867 792 820 846 862 780 833 771 864 777 762 809 778 751 770 753 804 757 757 738 707 758 728 757 724 673 706 757 743 718 747 751 710 748 695 669 734 709 751 750 756 728 732 751 759 753 731 696 711 726 747 696 715 727 695 714 702 705 748 706 759 736 720 718 718 716 697 698 696 699 731 709 718 733 760 666 727 714 720 736 787 714 741 729 731 740 750 721 749 716 720 713 770 756 721 679 728 724 732 755 848 770 748 754 770 801 749 779 826 801 766 770 823 893 802 844 826 887 884 899 917 909 971 931 941 940 1053 1051 1062 1127 1073 1083 1161 1220 1196 1226 1298 1303 1387 1419 1517 1523 1650 1686 1827 1914 2027 2145 2320 2334 2543 2716 2900 3164 3347 3659 3849 4062 4466 4694 4950 5442 5637 5943 6126 6184 6517 6423 6577 6562 6479 6459 6255 5920 5812 5382 5156 4811 4609 4391 3996 3746 3493 3199 2898 2698 2526 2379 2130 1938 1831 1714 1605 1513 1461 1335 1320 1294 1258 1163 1104 1116 1050 1011 991 951 956 910 876 915 878 868 892 874 846 850 777 813 800 775 802 780 759 732 783 730 742 701 702 733 740 758 684 688 713 722 664 686 689 711 650 732 642 687 714 684 665 658 660 663 677 651 704 666 716 650 654 681 639 647 724 641 647 663 622 646 654 631 665 644 682 691 597 650 619 653 690 627 685 697 656 676 607 655 679 691 640 666 582 668 634 623 609 619 603 623 589 621 621 671 624 651 631 642 695 619 690 614 642 635 615 627 661 683 622 644 639 665 626 624 671 641 671 613 631 654 679 608 643 664 665 642 660 596 609 667 677 689 730 699 714 620 637 686 651 703 697 680 701 676 726 715 726 754 729 761 812 817 767 801 787 799 774 824 831 887 848 949 859 886 858 996 910 905 931 849 915 930 926 926 901 878 894 930 932 918 956 920 889 906 881 854 843 785 825 801 832 808 791 812 795 791 764 762 794 751 760 720 752 739 718 705 750 690 719 689 713 673 691 685 697 707 697 706 697 694 715 772 727 704 713 770 708 775 804 760 794 806 771 916 904 916 947 995 1078 1022 1072 1094 1137 1125 1168 1212 1228 1172 1188 1214 1212 1209 1140 1181 1136 1083 1128 1015 973 1002 941 910 923 854 814 863 837 723 800 774 718 750 734 701 685 655 669 725 719 677 638 660 626 600 594 581 616 607 610 655 613 644 651 627 636 661 603 628 647 593 614 628 663 575 640 665 686 699 676 687 652 664 673 682 672 698 699 717 735 707 726 826 744 796 762 765 810 791 857 839 781 828 871 896 897 930 898 929 932 958 884 943 915 932 925 941 939 961 899 938 960 936 983 977 947 867 913 838 886 865 832 790 830 841 819 796 839 739 796 793 731 718 758 722 745 741 786 743 716 666 719 685 693 667 653 709 690 698 693 641 665 655 650 663 665 663 683 667 672 679 690 704 667 658 678 627 672 627 663 635 670 627 633 653 655 679 650 656 674 598 658 646 672 682 678 634 658 679 648 671 660 660 691 693 687 710 727 705 729 672 785 714 719 763 736 780 805 814 847 815 801 855 842 853 908 888 934 920 900 911 1050 988 1053 1101 1097 1144 1141 1235 1276 1373 1356 1413 1504 1503 1714 1849 2039 2018 2206 2473 2615 2842 3253 3584 4104 4628 5081 5636 6012 6365 6875 6779 6712 6450 5955 5474 5183 4912 4708 4664 4737 4707 4633 4635 4334 4025 3714 3474 3030 2951 2716 2699 2625 2487 2486 2510 2429 2430 2370 2377 2310 2298 2228 2319 2332 2263 2174 2202 2145 2148 2104 2111 2065 2016 2001 1975 1955 1920 1877 1903 1851 1897 1848 1921 1860 1847 1922 1923 1899 1988 2088 2177 2206 2357 2396 2499 2620 2678 2893 2939 2952 3052 2958 2985 2944 3070 2882 2823 2827 2714 2667 2767 2723 2688 2715 2825 2787 2748 2806 2757 2811 2810 3001 3021 3147 3335 3540 3758 3954 4152 4320 4498 4690 4662 4742 4738 4720 4732 4615 4569 4350 4195 4071 3778 3719 3570 3337 3203 2963 2826 2574 2517 2302 2173 1947 1902 1681 1565 1499 1311 1199 1194 1190 1162 1085 992 1067 990 997 860 866 884 850 807 770 807 749 765 790 742 757 721 717 724 672 714 670 736 695 713 674 688 695 621 673 612 654 657 595 647 651 589 582 670 599 632 657 636 644 573 603 574 563 590 610 580 601 602 619 573 619 626 625 591 578 551 585 528 576 554 566 631 579 590 568 614 564 566 604 555 582 575 537 571 567 564 575 563 544 556 564 580 560 549 542 548 558 518 538 535 627 528 547 561 530 552 588 538 528 580 587 553 514 521 548 559 573 600 605 551 579 564 533 545 571 605 518 546 558 568 543 504 551 569 516 566 602 554 534 583 560 565 540 488 624 545 567 558 563 537 578 545 553 553 502 563 574 526 559 578 553 548 546 571 604 618 519 560 515 556 571 542 512 511 523 527 548 510 545 500 528 569 504 559 555 563 527 577 554 505 550 540 535 605 527 544 548 530 526 529 552 510 537 511 526 563 496 586 547 519 586 546 564 521 526 564 546 592 545 550 506 609 513 540 557 525 560 553 529 548 534 527 530 517 518 578 546 541 498 578 560 552 604 558 551 577 518 557 510 583 552 550 567 498 564 581 542 536 529 566 534 541 545 536 533 580 548 610 612 557 562 551 526 557 543 537 583 554 600 520 552 541 545 526 565 573 577 565 586 583 550 585 551 584 579 574 597 583 573 564 573 525 583 563 584 561 566 593 522 552 631 568 636 578 574 648 594 572 544 610 571 580 626 616 687 621 613 610 676 671 615 639 651 718 681 682 678 736 676 682 733 684 727 745 798 790 752 793 785 823 766 857 865 924 901 908 980 961 1031 1058 1051 1135 1137 1175 1298 1334 1411 1440 1586 1543 1731 1700 1795 1846 1916 1971 1945 1969 1992 1890 1801 1860 1941 1814 1867 1870 1887 1837 1915 1861 2070 1899 1995 2012 2115 2200 2163 2245 2352 2409 2440 2591 2555 2712 2729 2768 2601 2792 2739 2609 2523 2409 2386 2294 2230 2223 2119 2090 1919 1890 1814 1674 1700 1603 1503 1418 1416 1208 1203 1109 1044 1049 1021 1008 877 887 876 806 825 766 801 757 755 706 753 707 700 734 720 683 623 626 640 633 708 599 637 620 631 660 620 613 632 636 622 563 602 626 621 600 596 586 605 631 608 641 641 619 632 600 616 620 664 637 607 661 669 626 619 668 672 632 665 625 654 673 671 765 617 724 680 709 717 736 759 728 760 790 766 738 792 740 804 840 803 786 834 887 823 910 868 890 871 918 923 916 855 953 958 943 930 904 949 908 980 921 917 922 920 942 890 907 911 878 865 822 875 881 870 837 865 796 894 820 827 826 860 728 808 765 761 740 773 764 775 745 765 745 735 729 691 754 686 730 709 684 644 662 707 695 719 678 658 703 649 631 655 689 679 656 627 664 644 682 662 659 642 635 679 624 610 636 605 603 641 622 627 657 644 633 641 674 684 623 667 703 674 665 658 620 643 678 679 672 677 683 695 691 706 710 676 709 731 724 780 749 719 779 763 820 739 833 874 837 813 870 926 886 951 975 954 965 998 999 1066 1087 1091 1199 1201 1167 1278 1287 1370 1391 1464 1523 1479 1563 1631 1653 1736 1752 1840 1914 1976 1955 1964 2030 2078 2172 2197 2274 2267 2351 2314 2518 2547 2711 2830 2949 3208 3376 3650 4034 4485 5082 5575 6313 6986 7557 8323 9005 9138 9350 9168 8524 7763 6942 6126 5469 5197 4887 4909 4950 5104 5354 5251 5278 5021 4680 4137 3593 3079 2647 2225 1900 1775 1594 1482 1422 1300 1286 1157 1130 1129 1083 1015 1072 929 1022 875 860 835 844 847 839 818 819 801 771 773 728 747 763 750 711 765 744 719 687 681 692 702 695 684 758 699 695 732 688 662 712 681 682 691 729 718 664 643 701 665 733 687 744 669 673 686 698 652 680 697 673 736 670 689 667 717 695 749 742 714 726 732 736 755 791 731 800 754 794 779 811 856 879 802 854 850 941 839 948 899 948 992 954 978 994 1031 1069 1090 1087 1144 1121 1187 1112 1101 1188 1233 1133 1248 1203 1249 1298 1170 1223 1233 1235 1253 1178 1216 1215 1252 1170 1238 1257 1201 1202 1130 1160 1197 1194 1178 1145 1170 1178 1194 1142 1199 1162 1210 1217 1187 1236 1268 1311 1330 1362 1394 1457 1454 1482 1600 1583 1583 1814 1694 1946 1890 2007 2092 2261 2292 2499 2510 2800 2903 2989 3247 3263 3457 3632 3964 4036 4136 4526 4442 4587 4757 4725 4847 4822 4705 4795 4780 4549 4619 4335 4263 4073 4003 3861 3637 3622 3546 3413 3327 3088 3096 2896 2715 2564 2366 2296 2201 2188 2011 1908 1768 1695 1663 1571 1464 1407 1510 1362 1321 1371 1281 1252 1210 1200 1142 1190 1108 1140 1133 1106 1113 1097 1108 1124 1108 1133 1098 1068 1092 1137 1072 1093 1176 1051 1118 1002 1055 1096 1081 976 1076 1069 1080 1065 972 1091 954 992 1022 1003 984 916 923 913 896 928 930 844 850 874 889 842 883 886 841 850 833 791 807 834 807 813 829 787 751 727 704 722 758 726 705 764 732 738 696 680 732 690 703 710 697 656 704 641 608 653 627 602 638 668 608 615 642 643 648 668 637 611 624 647 639 651 593 676 622 639 613 616 616 602 638 644 643 602 645 625 617 660 620 634 628 615 650 639 624 623 595 593 625 604 621 651 635 606 604 599 645 592 636 632 613 605 622 607 593 594 620 615 585 633 617 620 610 667 612 588 637 620 576 602 636 641 584 609 605 670 617 655 609 626 633 620 667 630 694 646 653 653 665 654 652 673 681 652 648 677 710 714 734 689 677 717 689 739 760 766 809 780 799 803 771 870 882 876 935 920 945 976 1056 1083 1128 1196 1201 1339 1316 1401 1546 1555 1665 1720 1775 1772 1855 1850 1872 1998 1885 1813 1836 1839 1698 1659 1610 1617 1724 1550 1525 1514 1462 1483 1408 1299 1352 1307 1252 1232 1203 1127 1082 1056 998 1003 937 908 889 871 760 822 847 772 766 770 747 718 782 736 743 742 683 711 751 753 754 742 748 768 752 790 762 795 791 727 738 763 770 836 793 745 806 823 811 853 799 883 891 857 890 911 925 963 1001 970 1098 1070 1124 1084 1188 1125 1223 1248 1272 1330 1460 1426 1461 1622 1796 1843 2046 2239 2410 2705 2959 3430 3658 4266 4619 5311 6038 6579 7261 7637 7970 8027 7733 6896 6343 5243 4853 4330 4037 3882 3869 3749 3983 4138 4478 4551 4576 4540 4332 3907 3443 2956 2580 2133 1957 1675 1563 1379 1441 1248 1223 1141 1129 1075 1032 983 1014 970 937 999 981 937 889 889 896 926 911 847 797 879 904 907 835 898 841 795 796 830 852 957 900 888 866 885 928 888 881 917 929 902 940 935 957 979 999 1058 1034 1040 1110 1105 1136 1093 1082 1168 1206 1183 1224 1247 1246 1247 1269 1326 1320 1365 1440 1412 1413 1477 1447 1477 1522 1554 1656 1698 1566 1681 1715 1755 1631 1634 1712 1716 1746 1754 1784 1805 1786 1752 1771 1754 1842 1835 1718 1814 1712 1712 1671 1682 1710 1668 1631 1698 1618 1611 1571 1588 1535 1559 1525 1525 1406 1433 1298 1413 1403 1402 1398 1308 1277 1220 1223 1252 1211 1152 1211 1176 1244 1157 1084 1100 1133 1101 1038 1109 1066 1034 1034 995 946 929 959 985 931 918 939 928 929 894 883 912 919 856 875 865 853 818 849 932 838 881 863 812 804 844 846 798 853 874 875 883 790 866 797 847 828 890 846 854 837 861 943 880 875 871 985 896 935 885 901 930 916 978 952 1050 953 937 1036 1032 1118 1077 1127 1208 1165 1169 1193 1236 1332 1310 1307 1345 1435 1470 1524 1604 1694 1707 1748 1896 1969 2009 2094 2097 2306 2365 2553 2666 2837 2918 2942 3230 3385 3519 3648 3769 3879 3945 3986 4055 4019 4022 4072 4043 4157 4069 4101 4065 4135 3989 4159 4105 4227 4184 4317 4348 4555 4463 4470 4604 4517 4513 4461 4531 4376 4421 4340 4301 4193 4077 3965 3865 3833 3740 3640 3531 3428 3356 3198 3175 3227 3104 3157 2927 2946 2908 2922 2859 2800 2833 2818 2848 2987 2904 2799 2875 2735 2672 2560 2301 2147 2070 1897 1880 1782 1757 1786 1854 1811 1868 1852 1912 1832 1874 1866 1891 1713 1722 1677 1574 1549 1558 1523 1479 1521 1545 1590 1558 1602 1751 1702 1696 1811 1880 1823 1999 2016 2097 2134 2178 2239 2299 2322 2510 2511 2694 2736 2791 2870 2910 2999 2905 3093 3139 3146 3152 3069 3088 3113 3060 2972 2996 2931 2903 2814 2874 2842 2708 2726 2614 2631 2502 2587 2397 2385 2260 2214 2119 2073 2064 1888 1882 1809 1785 1710 1677 1621 1564 1577 1565 1530 1404 1394 1443 1331 1296 1347 1329 1282 1241 1234 1311 1247 1215 1289 1271 1244 1277 1227 1264 1280 1274 1267 1352 1285 1346 1292 1378 1444 1452 1461 1517 1639 1704 1845 1897 2041 2084 2348 2592 2825 3212 3480 3979 4445 4937 5505 6000 6264 6624 6964 6595 6305 5736 5206 4480 4109 3709 3392 3250 3203 3153 3470 3396 3711 3815 4043 4176 4055 3832 3678 3326 2959 2639 2382 2080 1895 1802 1658 1657 1503 1483 1434 1389 1423 1318 1400 1274 1322 1336 1358 1317 1351 1393 1399 1304 1353 1275 1400 1401 1384 1353 1348 1393 1393 1462 1349 1343 1380 1434 1356 1347 1371 1426 1453 1421 1436 1454 1420 1422 1425 1405 1382 1384 1388 1364 1463 1325 1382 1352 1417 1374 1352 1442 1364 1358 1449 1463 1496 1536 1559 1689 1682 1784 1861 1998 2186 2322 2580 2785 3015 3264 3558 3718 3780 3912 3565 3400 3155 2762 2551 2312 2112 1994 1940 1948 1917 1965 2003 2171 2236 2258 2288 2224 2138 2073 1881 1675 1602 1361 1276 1185 1072 1022 1002 980 955 939 932 904 848 877 845 921 866 839 821 889 817 768 817 779 759 828 833 833 822 869 838 833 839 849 855 897 873 885 903 913 956 979 929 1089 1018 1059 1135 1124 1202 1251 1187 1343 1415 1377 1536 1642 1659 1721 1830 1811 2019 2103 2173 2220 2221 2314 2331 2395 2365 2366 2268 2224 2063 2130 2093 1888 1832 1886 1812 1832 1784 1830 1726 1691 1677 1603 1632 1547 1479 1399 1382 1240 1306 1151 1104 1040 1020 1032 919 1001 830 879 769 760 793 790 797 742 739 680 688 675 695 683 661 636 690 684 677 700 667 640 620 680 627 628 618 659 600 607 619 609 618 639 568 586 558 641 600 573 586 575 559 559 607 580 571 539 582 543 574 560 537 578 562 608 576 554 547 526 573 601 576 566 589 572 596 596 541 550 562 575 582 568 534 604 535 532 601 549 570 538 558 592 572 546 550 529 565 594 564 562 617 582 594 562 565 550 540 531 546 610 552 532 551 560 575 575 537 557 549 539 556 534 556 554 560 571 572 575 553 551 570 570 554 551 599 519 508 534 509 589 547 577 575 544 505 545 567 581 549 531 551 573 531 516 575 516 541 495 541 523 544 528 510 580 549 555 565 567 576 546 584 554 579 512 562 570 574 552 549 579 561 598 504 596 596 599 625 586 597 606 575 640 616 641 674 706 753 729 774 822 920 984 1035 953 1037 1028 1025 993 971 838 834 721 751 754 740 709 704 695 686 715 770 796 768 805 729 770 750 779 719 722 660 633 612 622 589 590 571 605 586 563 569 552 547 578 597 520 583 596 560 565 577 570 542 593 563 588 638 555 571 580 600 612 620 595 561 589 615 632 572 579 619 610 626 604 649 648 621 665 653 662 678 729 702 704 709 739 770 713 811 779 775 783 820 845 832 881 889 887 933 996 985 1035 1044 1107 1132 1141 1269 1293 1265 1375 1369 1418 1352 1439 1509 1523 1514 1566 1530 1591 1629 1548 1577 1649 1579 1618 1508 1509 1465 1511 1427 1435 1401 1342 1312 1298 1291 1280 1259 1263 1169 1187 1193 1152 1159 1091 1043 1021 1014 951 921 954 953 863 859 833 832 810 759 793 711 685 708 695 663 623 664 670 710 663 652 647 593 640 605 613 602 664 614 575 640 581 619 611 577 593 595 549 560 576 562 608 586 614 591 555 565 540 560 543 550 561 534 537 512 472 527 520 481 560 536 533 558 523 566 545 565 571 550 511 551 547 506 532 532 567 541 564 509 542 508 532 556 539 553 569 519 574 538 524 521 525 488 536 524 565 523 557 541 537 529 597 547 558 537 572 608 578 554 531 567 602 583 550 550 570 594 557 546 524 587 581 567 572 565 567 516 566 588 557 558 530 575 556 555 625 581 589 573 575 635 613 626 614 589 612 626 544 600 614 585 606 604 590 586 609 615 596 635 619 608 628 616 636 599 600 612 608 626 673 644 639 610 698 635 599 662 696 669 675 702 708 762 701 701 715 690 756 749 763 810 723 822 778 746 849 822 837 797 758 877 822 792 819 789 813 794 771 839 750 820 803 746 799 782 841 753 805 761 756 783 721 750 785 775 806 811 758 782 783 745 791 838 812 801 816 827 825 809 850 861 828 850 922 879 974 1046 1056 1087 1163 1214 1309 1284 1349 1487 1600 1644 1689 1700 1683 1649 1611 1514 1385 1401 1376 1369 1247 1227 1282 1290 1372 1391 1401 1488 1495 1568 1609 1672 1641 1754 1664 1689 1508 1680 1594 1638 1581 1522 1533 1455 1540 1531 1462 1496 1452 1408 1386 1414 1459 1393 1394 1416 1327 1306 1348 1349 1389 1391 1408 1458 1444 1359 1389 1421 1451 1468 1524 1502 1433 1466 1448 1397 1494 1327 1372 1383 1380 1242 1253 1209 1209 1176 1185 1124 1080 1022 1127 1047 1003 1054 1013 1055 1040 950 1001 979 928 934 967 876 855 788 802 805 731 751 712 750 711 714 709 682 664 715 694 689 726 698 688 675 675 678 689 711 747 717 747 712 763 715 740 756 772 737 741 858 901 821 916 875 896 897 844 907 936 915 917 891 915 953 935 886 921 888 902 852 886 891 913 872 868 858 804 783 778 811 769 776 769 772 747 722 780 752 733 728 679 692 718 623 648 678 594 623 673 567 667 582 578 588 614 532 618 623 569 576 569 567 584 587 540 595 578 531 507 596 537 500 533 534 510 510 581 553 560 512 580 559 560 557 535 584 544 584 536 564 543 550 552 565 580 558 554 544 605 599 586 582 594 599 586 597 622 605 602 662 662 589 663 705 712 721 691 682 732 697 760 713 697 713 759 801 797 834 796 849 853 896 918 945 956 932 1029 1091 1078 1092 1128 1142 1205 1238 1179 1180 1261 1234 1295 1280 1327 1323 1295 1391 1397 1401 1371 1320 1309 1296 1234 1275 1289 1257 1276 1230 1261 1231 1129 1206 1140 1131 1115 1080 1122 1076 1181 1033 986 1035 1017 966 937 945 908 903 925 822 800 789 803 740 730 758 742 781 649 634 719 702 688 669 669 647 701 665 665 627 651 608 605 605 618 605 604 664 646 614 618 572 615 647 631 663 604 628 611 621 635 636 656 659 586 633 657 640 613 621 655 682 647 663 660 593 666 679 658 710 664 632 720 674 774 713 647 674 700 701 721 724 763 750 755 748 759 770 809 834 783 853 856 903 973 992 1041 1036 1089 1100 1099 1068 1081 1003 977 947 875 881 797 844 767 759 744 755 815 737 766 779 812 775 852 823 854 853 835 746 839 792 712 706 684 697 620 634 592 605 636 591 627 627 639 575 611 605 566 606 593 596 690 640 633 628 628 595 610 662 611 649 699 680 686 695 707 688 764 714 711 703 759 711 689 716 761 727 710 763 739 754 743 766 730 766 774 739 683 662 654 661 713 672 648 656 708 716 720 682 677 662 670 693 623 624 608 657 647 584 581 628 592 613 611 562 583 555 543 573 557 531 532 548 557 550 554 532 530 532 502 555 551 547 546 502 510 551 531 577 537 530 497 534 545 512 490 533 471 480 495 495 479 502 546 496 503 476 466 468 508 515 488 462 488 503 480 461 501 484 454 490 490 454 462 444 472 494 472 461 483 442 453 466 473 473 461 458 516 488 466 442 504 486 467 448 496 418 507 472 442 439 488 491 485 459 509 451 475 502 469 431 453 461 462 485 521 449 460 474 454 482 463 463 518 508 469 448 432 450 454 447 451 466 442 438 468 468 428 509 493 456 459 441 470 444 458 436 478 446 471 454 498 490 488 471 506 447 502 465 485 433 480 476 476 498 471 496 456 458 402 496 500 494 495 457 452 496 491 505 485 510 497 497 486 462 501 493 494 470 525 492 527 512 537 490 510 561 550 534 605 564 526 597 558 529 532 572 592 572 595 561 556 594 595 606 654 635 610 689 677 717 653 688 712 741 719 698 718 727 726 757 755 736 652 789 694 741 731 759 702 702 722 742 692 672 754 723 741 768 717 671 706 720 714 719 693 691 657 658 686 682 630 648 685 680 667 619 630 617 634 623 606 602 636 547 594 627 599 557 582 570 580 605 575 582 612 595 540 499 553 554 589 540 537 525 534 518 530 541 541 527 533 518 503 556 569 504 499 501 502 532 464 480 544 523 490 475 518 466 509 535 523 454 508 517 473 511 505 501 512 467 497 477 484 498 466 464 470 441 467 497 483 448 494 482 470 482 464 476 454 485 463 463 441 450 434 462 473 460 494 490 475 501 465 474 479 480 505 478 494 492 447 450 462 434 468 434 426 456 475 463 478 493 477 436 481 456 475 469 527 436 453 438 468 463 476 452 455 460 491 451 472 505 489 470 486 488 465 490 507 434 432 484 467 534 453 486 477 500 465 494 474 450 494 456 495 485 493 497 521 499 434 472 537 488 530 492 507 494 529 471 548 509 477 514 507 503 485 532 458 447 483 540 531 461 524 554 501 515 505 502 528 523 523 513 543 496 546 533 562 544 545 537 550 543 528 529 551 589 569 548 585 545 548 556 569 563 548 567 598 590 580 593 603 567 568 635 573 581 611 584 622 631 618 583 586 603 652 554 624 610 631 574 598 594 661 626 648 641 625 625 623 642 651 643 586 682 680 648 644 700 686 635 685 679 665 713 650 720 704 720 722 760 733 767 774 763 800 755 820 841 821 879 853 860 891 845 888 887 927 904 925 903 950 1015 962 970 970 924 977 966 941 933 981 884 931 964 903 942 847 875 874 854 812 920 780 839 796 883 887 769 822 791 834 789 758 749 787 805 779 736 737 794 745 751 737 732 724 692 696 683 724 684 706 664 726 682 738 683 637 674 706 697 689 659 711 696 736 695 679 771 768 765 766 795 908 786 854 813 886 959 1010 1021 1015 1096 1150 1255 1303 1385 1519 1697 1783 1935 2070 2279 2461 2520 2686 2758 2732 2697 2542 2400 2100 2085 1880 1702 1541 1495 1513 1399 1453 1335 1384 1386 1455 1380 1434 1509 1600 1584 1561 1611 1711 1682 1645 1666 1543 1517 1359 1315 1217 1128 1080 973 982 899 869 816 820 773 797 786 743 687 717 645 680 692 582 648 632 610 612 618 613 608 605 567 581 523 559 551 553 554 564 562 586 533 526 522 571 559 535 533 519 564 567 579 560 557 548 573 541 593 556 543 575 567 547 561 560 577 517 624 534 537 517 564 549 525 588 567 576 585 598 559 535 532 549 577 564 522 554 528 562 559 538 546 620 526 571 566 577 605 578 618 579 557 562 609 544 564 575 576 572 542 537 561 574 555 560 560 568 620 569 550 589 527 556 567 580 565 531 541 517 569 565 539 577 558 547 516 503 544 547 537 573 594 579 553 524 572 531 539 544 582 530 541 580 569 557 517 583 557 547 530 572 599 565 586 561 599 605 575 620 585 568 586 594 595 610 610 605 614 589 604 633 624 600 670 650 622 618 666 632 624 660 644 698 710 727 692 734 724 812 746 732 805 860 793 847 889 929 940 957 962 1008 996 1075 957 1069 1092 1064 1108 1121 1085 1095 1100 1169 1148 1154 1156 1086 1086 1039 1082 1049 1078 1016 1041 1014 1012 996 962 1049 1054 1015 1036 1028 1058 1011 998 995 1050 1093 1056 1072 1110 1079 1079 1149 1197 1130 1227 1232 1317 1338 1400 1360 1367 1377 1298 1315 1198 1173 1112 994 1023 983 979 928 959 938 1010 922 921 947 987 982 1048 1015 1088 1096 1088 1128 1073 1156 1144 1091 1138 1046 1020 965 993 989 957 923 952 852 869 856 849 803 857 850 789 853 743 810 781 735 724 787 739 754 726 741 723 787 738 755 719 739 746 721 727 735 694 667 660 667 669 663 671 616 638 606 628 585 618 655 581 580 628 601 566 605 626 577 596 564 574 583 541 544 522 540 573 560 574 560 570 546 531 591 520 540 584 513 494 553 578 529 555 514 523 567 561 593 562 505 517 582 483 525 528 517 524 500 505 514 499 532 523 542 524 547 518 527 569 524 529 530 541 506 508 544 536 532 533 564 540 550 572 561 509 558 531 571 590 582 597 609 563 606 598 564 518 567 595 570 593 596 611 672 625 586 612 609 607 606 690 621 630 660 636 659 640 614 649 639 676 717 668 644 720 655 684 710 686 658 699 724 758 757 779 778 795 818 849 820 822 905 986 1016 1019 1070 1059 1194 1287 1368 1473 1523 1699 1826 1879 2152 2229 2414 2454 2453 2498 2347 2231 2089 1987 1759 1669 1499 1399 1301 1325 1239 1241 1207 1228 1209 1275 1313 1312 1395 1411 1461 1523 1610 1680 1784 1825 1761 1802 1804 1716 1682 1627 1484 1396 1331 1194 1157 1087 1051 1110 1027 959 1011 986 951 888 901 920 865 872 807 878 816 838 833 828 811 761 759 758 771 771 784 750 761 745 739 714 727 699 698 656 762 737 675 692 692 649 660 663 661 675 681 619 641 641 657 584 628 666 586 614 632 678 624 651 616 622 652 624 654 598 652 616 622 654 655 639 656 653 638 697 647 651 633 641 644 722 676 651 683 697 675 696 722 741 717 716 719 739 771 774 773 801 819 823 839 879 829 875 907 899 946 922 932 950 962 1036 1035 966 1001 977 1012 1032 1011 963 1016 992 958 952 1006 988 974 954 1009 1032 873 951 931 982 1001 944 946 919 963 936 941 916 1000 916 910 942 936 899 913 890 934 797 893 848 836 807 828 791 820 768 785 732 795 793 760 716 785 688 712 721 730 739 748 766 719 674 722 684 663 699 706 734 700 706 676 665 670 621 645 672 692 622 702 673 637 656 640 616 637 661 641 668 670 641 635 606 606 578 590 661 671 663 616 618 636 668 601 642 669 615 621 626 678 622 630 624 606 594 614 644 644 655 659 606 704 636 683 688 697 694 645 647 720 749 685 717 786 764 780 769 813 833 886 851 909 946 1031 1030 1176 1190 1305 1371 1403 1427 1566 1630 1672 1613 1569 1526 1445 1415 1318 1177 1148 1073 1147 1036 1053 1010 1003 991 1008 1043 1015 982 1012 994 1097 1098 1134 1146 1229 1276 1288 1269 1390 1385 1423 1411 1346 1268 1325 1219 1251 1143 1108 1109 1159 1115 1164 1213 1206 1225 1241 1227 1277 1268 1292 1296 1245 1369 1340 1399 1397 1343 1450 1448 1405 1424 1406 1448 1428 1456 1354 1460 1502 1509 1449 1492 1459 1501 1465 1472 1420 1422 1480 1413 1450 1467 1411 1447 1389 1490 1368 1413 1462 1463 1405 1403 1404 1403 1323 1386 1351 1346 1326 1299 1328 1215 1252 1160 1208 1159 1138 1114 1042 1020 988 1060 1003 993 1019 973 977</counts>
			</dataPoints>
		</scan>
	</xrdMeasurement>
</xrdMeasurements>